{
  "version": 8,
  "blockIdVersion": 11,
  "anchorX": 1,
  "anchorY": 19,
  "anchorZ": 1,
  "blocks": [
    {
      "x": -20,
      "y": 21,
      "z": -10,
      "name": "Rock_Ice_Permafrost"
    },
    {
      "x": -20,
      "y": 22,
      "z": -10,
      "name": "Rock_Ice_Permafrost"
    },
    {
      "x": -20,
      "y": 23,
      "z": -10,
      "name": "Rock_Ice_Permafrost"
    },
    {
      "x": -20,
      "y": 24,
      "z": -10,
      "name": "Soil_Snow"
    },
    {
      "x": -20,
      "y": 20,
      "z": -9,
      "name": "Rock_Ice"
    },
    {
      "x": -20,
      "y": 21,
      "z": -9,
      "name": "Rock_Ice"
    },
    {
      "x": -20,
      "y": 22,
      "z": -9,
      "name": "Rock_Ice_Permafrost"
    },
    {
      "x": -20,
      "y": 23,
      "z": -9,
      "name": "Rock_Ice_Permafrost"
    },
    {
      "x": -20,
      "y": 24,
      "z": -9,
      "name": "Soil_Snow"
    },
    {
      "x": -20,
      "y": 20,
      "z": -8,
      "name": "Rock_Ice"
    },
    {
      "x": -20,
      "y": 21,
      "z": -8,
      "name": "Rock_Ice"
    },
    {
      "x": -20,
      "y": 22,
      "z": -8,
      "name": "Rock_Ice_Permafrost"
    },
    {
      "x": -20,
      "y": 23,
      "z": -8,
      "name": "Rock_Ice_Permafrost"
    },
    {
      "x": -20,
      "y": 24,
      "z": -8,
      "name": "Rock_Ice_Permafrost"
    },
    {
      "x": -20,
      "y": 25,
      "z": -8,
      "name": "Soil_Snow"
    },
    {
      "x": -20,
      "y": 20,
      "z": -7,
      "name": "Rock_Ice"
    },
    {
      "x": -20,
      "y": 21,
      "z": -7,
      "name": "Rock_Ice"
    },
    {
      "x": -20,
      "y": 22,
      "z": -7,
      "name": "Rock_Ice_Permafrost"
    },
    {
      "x": -20,
      "y": 23,
      "z": -7,
      "name": "Rock_Ice_Permafrost"
    },
    {
      "x": -20,
      "y": 24,
      "z": -7,
      "name": "Rock_Ice_Permafrost"
    },
    {
      "x": -20,
      "y": 25,
      "z": -7,
      "name": "Soil_Snow"
    },
    {
      "x": -20,
      "y": 20,
      "z": -6,
      "name": "Rock_Ice"
    },
    {
      "x": -20,
      "y": 21,
      "z": -6,
      "name": "Rock_Ice"
    },
    {
      "x": -20,
      "y": 22,
      "z": -6,
      "name": "Rock_Ice"
    },
    {
      "x": -20,
      "y": 23,
      "z": -6,
      "name": "Rock_Ice_Permafrost"
    },
    {
      "x": -20,
      "y": 24,
      "z": -6,
      "name": "Rock_Ice_Permafrost"
    },
    {
      "x": -20,
      "y": 25,
      "z": -6,
      "name": "Soil_Snow"
    },
    {
      "x": -20,
      "y": 21,
      "z": -5,
      "name": "Rock_Ice"
    },
    {
      "x": -20,
      "y": 22,
      "z": -5,
      "name": "Rock_Ice"
    },
    {
      "x": -19,
      "y": 21,
      "z": -12,
      "name": "Rock_Ice_Permafrost"
    },
    {
      "x": -19,
      "y": 22,
      "z": -12,
      "name": "Rock_Ice_Permafrost"
    },
    {
      "x": -19,
      "y": 23,
      "z": -12,
      "name": "Rock_Ice_Permafrost"
    },
    {
      "x": -19,
      "y": 24,
      "z": -12,
      "name": "Soil_Snow"
    },
    {
      "x": -19,
      "y": 19,
      "z": -11,
      "name": "Rock_Ice"
    },
    {
      "x": -19,
      "y": 20,
      "z": -11,
      "name": "Rock_Ice"
    },
    {
      "x": -19,
      "y": 21,
      "z": -11,
      "name": "Rock_Ice_Permafrost"
    },
    {
      "x": -19,
      "y": 22,
      "z": -11,
      "name": "Rock_Ice_Permafrost"
    },
    {
      "x": -19,
      "y": 23,
      "z": -11,
      "name": "Rock_Ice_Permafrost"
    },
    {
      "x": -19,
      "y": 24,
      "z": -11,
      "name": "Rock_Ice_Permafrost"
    },
    {
      "x": -19,
      "y": 25,
      "z": -11,
      "name": "Soil_Snow"
    },
    {
      "x": -19,
      "y": 18,
      "z": -10,
      "name": "Rock_Ice"
    },
    {
      "x": -19,
      "y": 19,
      "z": -10,
      "name": "Rock_Ice"
    },
    {
      "x": -19,
      "y": 20,
      "z": -10,
      "name": "Rock_Ice"
    },
    {
      "x": -19,
      "y": 21,
      "z": -10,
      "name": "Rock_Ice"
    },
    {
      "x": -19,
      "y": 22,
      "z": -10,
      "name": "Rock_Ice_Permafrost"
    },
    {
      "x": -19,
      "y": 23,
      "z": -10,
      "name": "Rock_Ice_Permafrost"
    },
    {
      "x": -19,
      "y": 24,
      "z": -10,
      "name": "Rock_Ice_Permafrost"
    },
    {
      "x": -19,
      "y": 25,
      "z": -10,
      "name": "Soil_Snow"
    },
    {
      "x": -19,
      "y": 18,
      "z": -9,
      "name": "Rock_Ice"
    },
    {
      "x": -19,
      "y": 19,
      "z": -9,
      "name": "Rock_Ice"
    },
    {
      "x": -19,
      "y": 20,
      "z": -9,
      "name": "Rock_Ice"
    },
    {
      "x": -19,
      "y": 21,
      "z": -9,
      "name": "Rock_Ice"
    },
    {
      "x": -19,
      "y": 22,
      "z": -9,
      "name": "Rock_Ice_Permafrost"
    },
    {
      "x": -19,
      "y": 23,
      "z": -9,
      "name": "Rock_Ice_Permafrost"
    },
    {
      "x": -19,
      "y": 24,
      "z": -9,
      "name": "Rock_Ice_Permafrost"
    },
    {
      "x": -19,
      "y": 25,
      "z": -9,
      "name": "Rock_Ice_Permafrost"
    },
    {
      "x": -19,
      "y": 26,
      "z": -9,
      "name": "Soil_Snow"
    },
    {
      "x": -19,
      "y": 18,
      "z": -8,
      "name": "Rock_Ice"
    },
    {
      "x": -19,
      "y": 19,
      "z": -8,
      "name": "Rock_Ice"
    },
    {
      "x": -19,
      "y": 20,
      "z": -8,
      "name": "Rock_Ice"
    },
    {
      "x": -19,
      "y": 21,
      "z": -8,
      "name": "Rock_Ice"
    },
    {
      "x": -19,
      "y": 22,
      "z": -8,
      "name": "Rock_Ice"
    },
    {
      "x": -19,
      "y": 23,
      "z": -8,
      "name": "Rock_Ice_Permafrost"
    },
    {
      "x": -19,
      "y": 24,
      "z": -8,
      "name": "Rock_Ice_Permafrost"
    },
    {
      "x": -19,
      "y": 25,
      "z": -8,
      "name": "Rock_Ice_Permafrost"
    },
    {
      "x": -19,
      "y": 26,
      "z": -8,
      "name": "Soil_Snow"
    },
    {
      "x": -19,
      "y": 18,
      "z": -7,
      "name": "Rock_Ice"
    },
    {
      "x": -19,
      "y": 19,
      "z": -7,
      "name": "Rock_Ice"
    },
    {
      "x": -19,
      "y": 20,
      "z": -7,
      "name": "Rock_Ice"
    },
    {
      "x": -19,
      "y": 21,
      "z": -7,
      "name": "Rock_Ice"
    },
    {
      "x": -19,
      "y": 22,
      "z": -7,
      "name": "Rock_Ice_Permafrost"
    },
    {
      "x": -19,
      "y": 23,
      "z": -7,
      "name": "Rock_Ice_Permafrost"
    },
    {
      "x": -19,
      "y": 24,
      "z": -7,
      "name": "Rock_Ice_Permafrost"
    },
    {
      "x": -19,
      "y": 25,
      "z": -7,
      "name": "Rock_Ice_Permafrost"
    },
    {
      "x": -19,
      "y": 26,
      "z": -7,
      "name": "Soil_Snow"
    },
    {
      "x": -19,
      "y": 18,
      "z": -6,
      "name": "Rock_Ice"
    },
    {
      "x": -19,
      "y": 19,
      "z": -6,
      "name": "Rock_Ice"
    },
    {
      "x": -19,
      "y": 20,
      "z": -6,
      "name": "Rock_Ice"
    },
    {
      "x": -19,
      "y": 21,
      "z": -6,
      "name": "Rock_Ice"
    },
    {
      "x": -19,
      "y": 22,
      "z": -6,
      "name": "Rock_Ice"
    },
    {
      "x": -19,
      "y": 23,
      "z": -6,
      "name": "Rock_Ice_Permafrost"
    },
    {
      "x": -19,
      "y": 24,
      "z": -6,
      "name": "Rock_Ice_Permafrost"
    },
    {
      "x": -19,
      "y": 25,
      "z": -6,
      "name": "Rock_Ice_Permafrost"
    },
    {
      "x": -19,
      "y": 26,
      "z": -6,
      "name": "Soil_Snow"
    },
    {
      "x": -19,
      "y": 19,
      "z": -5,
      "name": "Rock_Ice"
    },
    {
      "x": -19,
      "y": 20,
      "z": -5,
      "name": "Rock_Ice"
    },
    {
      "x": -19,
      "y": 21,
      "z": -5,
      "name": "Rock_Ice"
    },
    {
      "x": -19,
      "y": 22,
      "z": -5,
      "name": "Rock_Ice"
    },
    {
      "x": -19,
      "y": 23,
      "z": -5,
      "name": "Rock_Ice_Permafrost"
    },
    {
      "x": -19,
      "y": 24,
      "z": -5,
      "name": "Rock_Ice_Permafrost"
    },
    {
      "x": -19,
      "y": 25,
      "z": -5,
      "name": "Soil_Snow"
    },
    {
      "x": -19,
      "y": 20,
      "z": -4,
      "name": "Rock_Ice"
    },
    {
      "x": -19,
      "y": 21,
      "z": -4,
      "name": "Rock_Ice"
    },
    {
      "x": -19,
      "y": 22,
      "z": -4,
      "name": "Rock_Ice"
    },
    {
      "x": -19,
      "y": 23,
      "z": -4,
      "name": "Rock_Ice_Permafrost"
    },
    {
      "x": -19,
      "y": 24,
      "z": -4,
      "name": "Soil_Snow"
    },
    {
      "x": -19,
      "y": 21,
      "z": -3,
      "name": "Rock_Ice"
    },
    {
      "x": -19,
      "y": 22,
      "z": -3,
      "name": "Rock_Ice"
    },
    {
      "x": -19,
      "y": 23,
      "z": -3,
      "name": "Rock_Ice"
    },
    {
      "x": -19,
      "y": 24,
      "z": -3,
      "name": "Soil_Snow"
    },
    {
      "x": -19,
      "y": 22,
      "z": -2,
      "name": "Rock_Ice"
    },
    {
      "x": -19,
      "y": 23,
      "z": -2,
      "name": "Soil_Snow"
    },
    {
      "x": -18,
      "y": 20,
      "z": -12,
      "name": "Rock_Ice"
    },
    {
      "x": -18,
      "y": 21,
      "z": -12,
      "name": "Rock_Ice_Permafrost"
    },
    {
      "x": -18,
      "y": 22,
      "z": -12,
      "name": "Rock_Ice_Permafrost"
    },
    {
      "x": -18,
      "y": 23,
      "z": -12,
      "name": "Rock_Ice_Permafrost"
    },
    {
      "x": -18,
      "y": 24,
      "z": -12,
      "name": "Soil_Snow"
    },
    {
      "x": -18,
      "y": 18,
      "z": -11,
      "name": "Rock_Ice"
    },
    {
      "x": -18,
      "y": 19,
      "z": -11,
      "name": "Rock_Ice"
    },
    {
      "x": -18,
      "y": 20,
      "z": -11,
      "name": "Rock_Ice"
    },
    {
      "x": -18,
      "y": 21,
      "z": -11,
      "name": "Rock_Ice_Permafrost"
    },
    {
      "x": -18,
      "y": 22,
      "z": -11,
      "name": "Rock_Ice_Permafrost"
    },
    {
      "x": -18,
      "y": 23,
      "z": -11,
      "name": "Rock_Ice_Permafrost"
    },
    {
      "x": -18,
      "y": 24,
      "z": -11,
      "name": "Rock_Ice_Permafrost"
    },
    {
      "x": -18,
      "y": 25,
      "z": -11,
      "name": "Soil_Snow"
    },
    {
      "x": -18,
      "y": 17,
      "z": -10,
      "name": "Rock_Ice"
    },
    {
      "x": -18,
      "y": 18,
      "z": -10,
      "name": "Rock_Ice"
    },
    {
      "x": -18,
      "y": 19,
      "z": -10,
      "name": "Rock_Ice"
    },
    {
      "x": -18,
      "y": 20,
      "z": -10,
      "name": "Rock_Ice"
    },
    {
      "x": -18,
      "y": 21,
      "z": -10,
      "name": "Rock_Ice"
    },
    {
      "x": -18,
      "y": 22,
      "z": -10,
      "name": "Rock_Ice_Permafrost"
    },
    {
      "x": -18,
      "y": 23,
      "z": -10,
      "name": "Rock_Ice_Permafrost"
    },
    {
      "x": -18,
      "y": 24,
      "z": -10,
      "name": "Rock_Ice_Permafrost"
    },
    {
      "x": -18,
      "y": 25,
      "z": -10,
      "name": "Rock_Ice_Permafrost"
    },
    {
      "x": -18,
      "y": 26,
      "z": -10,
      "name": "Soil_Snow"
    },
    {
      "x": -18,
      "y": 17,
      "z": -9,
      "name": "Rock_Ice"
    },
    {
      "x": -18,
      "y": 18,
      "z": -9,
      "name": "Rock_Ice"
    },
    {
      "x": -18,
      "y": 19,
      "z": -9,
      "name": "Rock_Ice"
    },
    {
      "x": -18,
      "y": 20,
      "z": -9,
      "name": "Rock_Ice"
    },
    {
      "x": -18,
      "y": 21,
      "z": -9,
      "name": "Rock_Ice_Permafrost"
    },
    {
      "x": -18,
      "y": 22,
      "z": -9,
      "name": "Rock_Ice_Permafrost"
    },
    {
      "x": -18,
      "y": 23,
      "z": -9,
      "name": "Rock_Ice_Permafrost"
    },
    {
      "x": -18,
      "y": 24,
      "z": -9,
      "name": "Rock_Ice_Permafrost"
    },
    {
      "x": -18,
      "y": 25,
      "z": -9,
      "name": "Rock_Ice_Permafrost"
    },
    {
      "x": -18,
      "y": 26,
      "z": -9,
      "name": "Rock_Ice_Permafrost"
    },
    {
      "x": -18,
      "y": 27,
      "z": -9,
      "name": "Soil_Snow"
    },
    {
      "x": -18,
      "y": 17,
      "z": -8,
      "name": "Rock_Ice"
    },
    {
      "x": -18,
      "y": 18,
      "z": -8,
      "name": "Rock_Ice"
    },
    {
      "x": -18,
      "y": 19,
      "z": -8,
      "name": "Rock_Ice"
    },
    {
      "x": -18,
      "y": 20,
      "z": -8,
      "name": "Rock_Ice"
    },
    {
      "x": -18,
      "y": 21,
      "z": -8,
      "name": "Rock_Ice"
    },
    {
      "x": -18,
      "y": 22,
      "z": -8,
      "name": "Rock_Ice_Permafrost"
    },
    {
      "x": -18,
      "y": 23,
      "z": -8,
      "name": "Rock_Ice_Permafrost"
    },
    {
      "x": -18,
      "y": 24,
      "z": -8,
      "name": "Rock_Ice_Permafrost"
    },
    {
      "x": -18,
      "y": 25,
      "z": -8,
      "name": "Rock_Ice_Permafrost"
    },
    {
      "x": -18,
      "y": 26,
      "z": -8,
      "name": "Rock_Ice_Permafrost"
    },
    {
      "x": -18,
      "y": 27,
      "z": -8,
      "name": "Soil_Snow"
    },
    {
      "x": -18,
      "y": 17,
      "z": -7,
      "name": "Rock_Ice"
    },
    {
      "x": -18,
      "y": 18,
      "z": -7,
      "name": "Rock_Ice"
    },
    {
      "x": -18,
      "y": 19,
      "z": -7,
      "name": "Rock_Ice"
    },
    {
      "x": -18,
      "y": 20,
      "z": -7,
      "name": "Rock_Ice"
    },
    {
      "x": -18,
      "y": 21,
      "z": -7,
      "name": "Rock_Ice"
    },
    {
      "x": -18,
      "y": 22,
      "z": -7,
      "name": "Rock_Ice_Permafrost"
    },
    {
      "x": -18,
      "y": 23,
      "z": -7,
      "name": "Rock_Ice_Permafrost"
    },
    {
      "x": -18,
      "y": 24,
      "z": -7,
      "name": "Rock_Ice_Permafrost"
    },
    {
      "x": -18,
      "y": 25,
      "z": -7,
      "name": "Rock_Ice_Permafrost"
    },
    {
      "x": -18,
      "y": 26,
      "z": -7,
      "name": "Rock_Ice_Permafrost"
    },
    {
      "x": -18,
      "y": 27,
      "z": -7,
      "name": "Soil_Snow"
    },
    {
      "x": -18,
      "y": 17,
      "z": -6,
      "name": "Rock_Ice"
    },
    {
      "x": -18,
      "y": 18,
      "z": -6,
      "name": "Rock_Ice"
    },
    {
      "x": -18,
      "y": 19,
      "z": -6,
      "name": "Rock_Ice"
    },
    {
      "x": -18,
      "y": 20,
      "z": -6,
      "name": "Rock_Ice"
    },
    {
      "x": -18,
      "y": 21,
      "z": -6,
      "name": "Rock_Ice"
    },
    {
      "x": -18,
      "y": 22,
      "z": -6,
      "name": "Rock_Ice"
    },
    {
      "x": -18,
      "y": 23,
      "z": -6,
      "name": "Rock_Ice_Permafrost"
    },
    {
      "x": -18,
      "y": 24,
      "z": -6,
      "name": "Rock_Ice_Permafrost"
    },
    {
      "x": -18,
      "y": 25,
      "z": -6,
      "name": "Rock_Ice_Permafrost"
    },
    {
      "x": -18,
      "y": 26,
      "z": -6,
      "name": "Rock_Ice_Permafrost"
    },
    {
      "x": -18,
      "y": 27,
      "z": -6,
      "name": "Soil_Snow"
    },
    {
      "x": -18,
      "y": 18,
      "z": -5,
      "name": "Rock_Ice"
    },
    {
      "x": -18,
      "y": 19,
      "z": -5,
      "name": "Rock_Ice"
    },
    {
      "x": -18,
      "y": 20,
      "z": -5,
      "name": "Rock_Ice"
    },
    {
      "x": -18,
      "y": 21,
      "z": -5,
      "name": "Rock_Ice"
    },
    {
      "x": -18,
      "y": 22,
      "z": -5,
      "name": "Rock_Ice"
    },
    {
      "x": -18,
      "y": 23,
      "z": -5,
      "name": "Rock_Ice_Permafrost"
    },
    {
      "x": -18,
      "y": 24,
      "z": -5,
      "name": "Rock_Ice_Permafrost"
    },
    {
      "x": -18,
      "y": 25,
      "z": -5,
      "name": "Rock_Ice"
    },
    {
      "x": -18,
      "y": 26,
      "z": -5,
      "name": "Rock_Ice_Permafrost"
    },
    {
      "x": -18,
      "y": 27,
      "z": -5,
      "name": "Soil_Snow"
    },
    {
      "x": -18,
      "y": 18,
      "z": -4,
      "name": "Rock_Ice"
    },
    {
      "x": -18,
      "y": 19,
      "z": -4,
      "name": "Rock_Ice"
    },
    {
      "x": -18,
      "y": 20,
      "z": -4,
      "name": "Rock_Ice"
    },
    {
      "x": -18,
      "y": 21,
      "z": -4,
      "name": "Rock_Ice"
    },
    {
      "x": -18,
      "y": 22,
      "z": -4,
      "name": "Rock_Ice"
    },
    {
      "x": -18,
      "y": 23,
      "z": -4,
      "name": "Rock_Ice_Permafrost"
    },
    {
      "x": -18,
      "y": 24,
      "z": -4,
      "name": "Rock_Ice_Permafrost"
    },
    {
      "x": -18,
      "y": 25,
      "z": -4,
      "name": "Rock_Ice"
    },
    {
      "x": -18,
      "y": 26,
      "z": -4,
      "name": "Soil_Snow"
    },
    {
      "x": -18,
      "y": 19,
      "z": -3,
      "name": "Rock_Ice"
    },
    {
      "x": -18,
      "y": 20,
      "z": -3,
      "name": "Rock_Ice"
    },
    {
      "x": -18,
      "y": 21,
      "z": -3,
      "name": "Rock_Ice"
    },
    {
      "x": -18,
      "y": 22,
      "z": -3,
      "name": "Rock_Ice"
    },
    {
      "x": -18,
      "y": 23,
      "z": -3,
      "name": "Rock_Ice_Permafrost"
    },
    {
      "x": -18,
      "y": 24,
      "z": -3,
      "name": "Rock_Ice_Permafrost"
    },
    {
      "x": -18,
      "y": 25,
      "z": -3,
      "name": "Rock_Ice_Permafrost"
    },
    {
      "x": -18,
      "y": 26,
      "z": -3,
      "name": "Soil_Snow"
    },
    {
      "x": -18,
      "y": 21,
      "z": -2,
      "name": "Rock_Ice"
    },
    {
      "x": -18,
      "y": 22,
      "z": -2,
      "name": "Rock_Ice"
    },
    {
      "x": -18,
      "y": 23,
      "z": -2,
      "name": "Rock_Ice"
    },
    {
      "x": -18,
      "y": 24,
      "z": -2,
      "name": "Rock_Ice_Permafrost"
    },
    {
      "x": -18,
      "y": 25,
      "z": -2,
      "name": "Rock_Ice"
    },
    {
      "x": -18,
      "y": 26,
      "z": -2,
      "name": "Soil_Snow"
    },
    {
      "x": -18,
      "y": 22,
      "z": -1,
      "name": "Rock_Ice"
    },
    {
      "x": -18,
      "y": 23,
      "z": -1,
      "name": "Rock_Ice"
    },
    {
      "x": -18,
      "y": 24,
      "z": -1,
      "name": "Rock_Ice_Permafrost"
    },
    {
      "x": -18,
      "y": 25,
      "z": -1,
      "name": "Soil_Snow"
    },
    {
      "x": -18,
      "y": 23,
      "z": 0,
      "name": "Rock_Ice"
    },
    {
      "x": -18,
      "y": 24,
      "z": 0,
      "name": "Soil_Snow"
    },
    {
      "x": -17,
      "y": 21,
      "z": -13,
      "name": "Rock_Ice_Permafrost"
    },
    {
      "x": -17,
      "y": 22,
      "z": -13,
      "name": "Rock_Ice_Permafrost"
    },
    {
      "x": -17,
      "y": 23,
      "z": -13,
      "name": "Soil_Snow"
    },
    {
      "x": -17,
      "y": 19,
      "z": -12,
      "name": "Rock_Ice_Permafrost"
    },
    {
      "x": -17,
      "y": 20,
      "z": -12,
      "name": "Rock_Ice_Permafrost"
    },
    {
      "x": -17,
      "y": 21,
      "z": -12,
      "name": "Rock_Ice_Permafrost"
    },
    {
      "x": -17,
      "y": 22,
      "z": -12,
      "name": "Rock_Ice_Permafrost"
    },
    {
      "x": -17,
      "y": 23,
      "z": -12,
      "name": "Rock_Ice_Permafrost"
    },
    {
      "x": -17,
      "y": 24,
      "z": -12,
      "name": "Soil_Snow"
    },
    {
      "x": -17,
      "y": 18,
      "z": -11,
      "name": "Rock_Ice"
    },
    {
      "x": -17,
      "y": 19,
      "z": -11,
      "name": "Rock_Ice"
    },
    {
      "x": -17,
      "y": 20,
      "z": -11,
      "name": "Rock_Ice"
    },
    {
      "x": -17,
      "y": 21,
      "z": -11,
      "name": "Rock_Ice_Permafrost"
    },
    {
      "x": -17,
      "y": 22,
      "z": -11,
      "name": "Rock_Ice_Permafrost"
    },
    {
      "x": -17,
      "y": 23,
      "z": -11,
      "name": "Rock_Ice_Permafrost"
    },
    {
      "x": -17,
      "y": 24,
      "z": -11,
      "name": "Rock_Ice_Permafrost"
    },
    {
      "x": -17,
      "y": 25,
      "z": -11,
      "name": "Soil_Snow"
    },
    {
      "x": -17,
      "y": 17,
      "z": -10,
      "name": "Rock_Ice"
    },
    {
      "x": -17,
      "y": 18,
      "z": -10,
      "name": "Rock_Ice"
    },
    {
      "x": -17,
      "y": 19,
      "z": -10,
      "name": "Rock_Ice"
    },
    {
      "x": -17,
      "y": 20,
      "z": -10,
      "name": "Rock_Ice"
    },
    {
      "x": -17,
      "y": 21,
      "z": -10,
      "name": "Rock_Ice_Permafrost"
    },
    {
      "x": -17,
      "y": 22,
      "z": -10,
      "name": "Rock_Ice_Permafrost"
    },
    {
      "x": -17,
      "y": 23,
      "z": -10,
      "name": "Rock_Ice_Permafrost"
    },
    {
      "x": -17,
      "y": 24,
      "z": -10,
      "name": "Rock_Ice_Permafrost"
    },
    {
      "x": -17,
      "y": 25,
      "z": -10,
      "name": "Rock_Ice_Permafrost"
    },
    {
      "x": -17,
      "y": 26,
      "z": -10,
      "name": "Soil_Snow"
    },
    {
      "x": -17,
      "y": 16,
      "z": -9,
      "name": "Rock_Ice"
    },
    {
      "x": -17,
      "y": 17,
      "z": -9,
      "name": "Rock_Ice"
    },
    {
      "x": -17,
      "y": 18,
      "z": -9,
      "name": "Rock_Ice"
    },
    {
      "x": -17,
      "y": 19,
      "z": -9,
      "name": "Rock_Ice"
    },
    {
      "x": -17,
      "y": 20,
      "z": -9,
      "name": "Rock_Ice"
    },
    {
      "x": -17,
      "y": 21,
      "z": -9,
      "name": "Rock_Ice"
    },
    {
      "x": -17,
      "y": 22,
      "z": -9,
      "name": "Rock_Ice_Permafrost"
    },
    {
      "x": -17,
      "y": 23,
      "z": -9,
      "name": "Rock_Ice_Permafrost"
    },
    {
      "x": -17,
      "y": 24,
      "z": -9,
      "name": "Rock_Ice_Permafrost"
    },
    {
      "x": -17,
      "y": 25,
      "z": -9,
      "name": "Rock_Ice_Permafrost"
    },
    {
      "x": -17,
      "y": 26,
      "z": -9,
      "name": "Rock_Ice_Permafrost"
    },
    {
      "x": -17,
      "y": 27,
      "z": -9,
      "name": "Soil_Snow"
    },
    {
      "x": -17,
      "y": 15,
      "z": -8,
      "name": "Rock_Ice"
    },
    {
      "x": -17,
      "y": 16,
      "z": -8,
      "name": "Rock_Ice"
    },
    {
      "x": -17,
      "y": 17,
      "z": -8,
      "name": "Rock_Ice"
    },
    {
      "x": -17,
      "y": 18,
      "z": -8,
      "name": "Rock_Ice"
    },
    {
      "x": -17,
      "y": 19,
      "z": -8,
      "name": "Rock_Ice"
    },
    {
      "x": -17,
      "y": 20,
      "z": -8,
      "name": "Rock_Ice"
    },
    {
      "x": -17,
      "y": 21,
      "z": -8,
      "name": "Rock_Ice"
    },
    {
      "x": -17,
      "y": 22,
      "z": -8,
      "name": "Rock_Ice_Permafrost"
    },
    {
      "x": -17,
      "y": 23,
      "z": -8,
      "name": "Rock_Ice_Permafrost"
    },
    {
      "x": -17,
      "y": 24,
      "z": -8,
      "name": "Rock_Ice_Permafrost"
    },
    {
      "x": -17,
      "y": 25,
      "z": -8,
      "name": "Rock_Ice_Permafrost"
    },
    {
      "x": -17,
      "y": 26,
      "z": -8,
      "name": "Rock_Ice_Permafrost"
    },
    {
      "x": -17,
      "y": 27,
      "z": -8,
      "name": "Soil_Snow"
    },
    {
      "x": -17,
      "y": 16,
      "z": -7,
      "name": "Rock_Ice"
    },
    {
      "x": -17,
      "y": 17,
      "z": -7,
      "name": "Rock_Ice"
    },
    {
      "x": -17,
      "y": 18,
      "z": -7,
      "name": "Rock_Ice"
    },
    {
      "x": -17,
      "y": 19,
      "z": -7,
      "name": "Rock_Ice"
    },
    {
      "x": -17,
      "y": 20,
      "z": -7,
      "name": "Rock_Ice"
    },
    {
      "x": -17,
      "y": 21,
      "z": -7,
      "name": "Rock_Ice"
    },
    {
      "x": -17,
      "y": 22,
      "z": -7,
      "name": "Rock_Ice"
    },
    {
      "x": -17,
      "y": 23,
      "z": -7,
      "name": "Rock_Ice_Permafrost"
    },
    {
      "x": -17,
      "y": 24,
      "z": -7,
      "name": "Rock_Ice_Permafrost"
    },
    {
      "x": -17,
      "y": 25,
      "z": -7,
      "name": "Rock_Ice_Permafrost"
    },
    {
      "x": -17,
      "y": 26,
      "z": -7,
      "name": "Rock_Ice_Permafrost"
    },
    {
      "x": -17,
      "y": 27,
      "z": -7,
      "name": "Soil_Snow"
    },
    {
      "x": -17,
      "y": 16,
      "z": -6,
      "name": "Rock_Ice"
    },
    {
      "x": -17,
      "y": 17,
      "z": -6,
      "name": "Rock_Ice"
    },
    {
      "x": -17,
      "y": 18,
      "z": -6,
      "name": "Rock_Ice"
    },
    {
      "x": -17,
      "y": 19,
      "z": -6,
      "name": "Rock_Ice"
    },
    {
      "x": -17,
      "y": 20,
      "z": -6,
      "name": "Rock_Ice"
    },
    {
      "x": -17,
      "y": 21,
      "z": -6,
      "name": "Rock_Ice"
    },
    {
      "x": -17,
      "y": 22,
      "z": -6,
      "name": "Rock_Ice_Permafrost"
    },
    {
      "x": -17,
      "y": 23,
      "z": -6,
      "name": "Rock_Ice_Permafrost"
    },
    {
      "x": -17,
      "y": 24,
      "z": -6,
      "name": "Rock_Ice_Permafrost"
    },
    {
      "x": -17,
      "y": 25,
      "z": -6,
      "name": "Rock_Ice"
    },
    {
      "x": -17,
      "y": 26,
      "z": -6,
      "name": "Rock_Ice_Permafrost"
    },
    {
      "x": -17,
      "y": 27,
      "z": -6,
      "name": "Soil_Snow"
    },
    {
      "x": -17,
      "y": 16,
      "z": -5,
      "name": "Rock_Ice"
    },
    {
      "x": -17,
      "y": 17,
      "z": -5,
      "name": "Rock_Ice"
    },
    {
      "x": -17,
      "y": 18,
      "z": -5,
      "name": "Rock_Ice"
    },
    {
      "x": -17,
      "y": 19,
      "z": -5,
      "name": "Rock_Ice"
    },
    {
      "x": -17,
      "y": 20,
      "z": -5,
      "name": "Rock_Ice"
    },
    {
      "x": -17,
      "y": 21,
      "z": -5,
      "name": "Rock_Ice"
    },
    {
      "x": -17,
      "y": 22,
      "z": -5,
      "name": "Rock_Ice"
    },
    {
      "x": -17,
      "y": 23,
      "z": -5,
      "name": "Rock_Ice_Permafrost"
    },
    {
      "x": -17,
      "y": 24,
      "z": -5,
      "name": "Rock_Ice_Permafrost"
    },
    {
      "x": -17,
      "y": 25,
      "z": -5,
      "name": "Rock_Ice"
    },
    {
      "x": -17,
      "y": 26,
      "z": -5,
      "name": "Rock_Ice"
    },
    {
      "x": -17,
      "y": 27,
      "z": -5,
      "name": "Rock_Ice"
    },
    {
      "x": -17,
      "y": 28,
      "z": -5,
      "name": "Soil_Snow"
    },
    {
      "x": -17,
      "y": 17,
      "z": -4,
      "name": "Rock_Ice"
    },
    {
      "x": -17,
      "y": 18,
      "z": -4,
      "name": "Rock_Ice"
    },
    {
      "x": -17,
      "y": 19,
      "z": -4,
      "name": "Rock_Ice"
    },
    {
      "x": -17,
      "y": 20,
      "z": -4,
      "name": "Rock_Ice"
    },
    {
      "x": -17,
      "y": 21,
      "z": -4,
      "name": "Rock_Ice"
    },
    {
      "x": -17,
      "y": 22,
      "z": -4,
      "name": "Rock_Ice"
    },
    {
      "x": -17,
      "y": 23,
      "z": -4,
      "name": "Rock_Ice_Permafrost"
    },
    {
      "x": -17,
      "y": 24,
      "z": -4,
      "name": "Rock_Ice_Permafrost"
    },
    {
      "x": -17,
      "y": 25,
      "z": -4,
      "name": "Rock_Ice_Permafrost"
    },
    {
      "x": -17,
      "y": 26,
      "z": -4,
      "name": "Rock_Ice"
    },
    {
      "x": -17,
      "y": 27,
      "z": -4,
      "name": "Rock_Ice"
    },
    {
      "x": -17,
      "y": 28,
      "z": -4,
      "name": "Soil_Snow"
    },
    {
      "x": -17,
      "y": 18,
      "z": -3,
      "name": "Rock_Ice"
    },
    {
      "x": -17,
      "y": 19,
      "z": -3,
      "name": "Rock_Ice"
    },
    {
      "x": -17,
      "y": 20,
      "z": -3,
      "name": "Rock_Ice"
    },
    {
      "x": -17,
      "y": 21,
      "z": -3,
      "name": "Rock_Ice"
    },
    {
      "x": -17,
      "y": 22,
      "z": -3,
      "name": "Rock_Ice"
    },
    {
      "x": -17,
      "y": 23,
      "z": -3,
      "name": "Rock_Ice_Permafrost"
    },
    {
      "x": -17,
      "y": 24,
      "z": -3,
      "name": "Rock_Ice_Permafrost"
    },
    {
      "x": -17,
      "y": 25,
      "z": -3,
      "name": "Rock_Ice_Permafrost"
    },
    {
      "x": -17,
      "y": 26,
      "z": -3,
      "name": "Rock_Ice"
    },
    {
      "x": -17,
      "y": 27,
      "z": -3,
      "name": "Rock_Ice"
    },
    {
      "x": -17,
      "y": 28,
      "z": -3,
      "name": "Soil_Snow"
    },
    {
      "x": -17,
      "y": 19,
      "z": -2,
      "name": "Rock_Ice"
    },
    {
      "x": -17,
      "y": 20,
      "z": -2,
      "name": "Rock_Ice"
    },
    {
      "x": -17,
      "y": 21,
      "z": -2,
      "name": "Rock_Ice"
    },
    {
      "x": -17,
      "y": 22,
      "z": -2,
      "name": "Rock_Ice"
    },
    {
      "x": -17,
      "y": 23,
      "z": -2,
      "name": "Rock_Ice"
    },
    {
      "x": -17,
      "y": 24,
      "z": -2,
      "name": "Rock_Ice_Permafrost"
    },
    {
      "x": -17,
      "y": 25,
      "z": -2,
      "name": "Rock_Ice_Permafrost"
    },
    {
      "x": -17,
      "y": 26,
      "z": -2,
      "name": "Rock_Ice"
    },
    {
      "x": -17,
      "y": 27,
      "z": -2,
      "name": "Rock_Ice"
    },
    {
      "x": -17,
      "y": 28,
      "z": -2,
      "name": "Soil_Snow"
    },
    {
      "x": -17,
      "y": 20,
      "z": -1,
      "name": "Rock_Ice"
    },
    {
      "x": -17,
      "y": 21,
      "z": -1,
      "name": "Rock_Ice"
    },
    {
      "x": -17,
      "y": 22,
      "z": -1,
      "name": "Rock_Ice"
    },
    {
      "x": -17,
      "y": 23,
      "z": -1,
      "name": "Rock_Ice"
    },
    {
      "x": -17,
      "y": 24,
      "z": -1,
      "name": "Rock_Ice_Permafrost"
    },
    {
      "x": -17,
      "y": 25,
      "z": -1,
      "name": "Rock_Ice_Permafrost"
    },
    {
      "x": -17,
      "y": 26,
      "z": -1,
      "name": "Rock_Ice"
    },
    {
      "x": -17,
      "y": 27,
      "z": -1,
      "name": "Rock_Ice"
    },
    {
      "x": -17,
      "y": 28,
      "z": -1,
      "name": "Soil_Snow"
    },
    {
      "x": -17,
      "y": 22,
      "z": 0,
      "name": "Rock_Ice"
    },
    {
      "x": -17,
      "y": 23,
      "z": 0,
      "name": "Rock_Ice"
    },
    {
      "x": -17,
      "y": 24,
      "z": 0,
      "name": "Rock_Ice_Permafrost"
    },
    {
      "x": -17,
      "y": 25,
      "z": 0,
      "name": "Rock_Ice_Permafrost"
    },
    {
      "x": -17,
      "y": 26,
      "z": 0,
      "name": "Rock_Ice"
    },
    {
      "x": -17,
      "y": 27,
      "z": 0,
      "name": "Soil_Snow"
    },
    {
      "x": -17,
      "y": 24,
      "z": 1,
      "name": "Rock_Ice"
    },
    {
      "x": -17,
      "y": 25,
      "z": 1,
      "name": "Rock_Ice_Permafrost"
    },
    {
      "x": -17,
      "y": 26,
      "z": 1,
      "name": "Soil_Snow"
    },
    {
      "x": -17,
      "y": 25,
      "z": 2,
      "name": "Soil_Snow"
    },
    {
      "x": -16,
      "y": 20,
      "z": -13,
      "name": "Rock_Ice_Permafrost"
    },
    {
      "x": -16,
      "y": 21,
      "z": -13,
      "name": "Rock_Ice_Permafrost"
    },
    {
      "x": -16,
      "y": 22,
      "z": -13,
      "name": "Rock_Ice_Permafrost"
    },
    {
      "x": -16,
      "y": 23,
      "z": -13,
      "name": "Soil_Snow"
    },
    {
      "x": -16,
      "y": 18,
      "z": -12,
      "name": "Rock_Ice_Permafrost"
    },
    {
      "x": -16,
      "y": 19,
      "z": -12,
      "name": "Rock_Ice_Permafrost"
    },
    {
      "x": -16,
      "y": 20,
      "z": -12,
      "name": "Rock_Ice_Permafrost"
    },
    {
      "x": -16,
      "y": 21,
      "z": -12,
      "name": "Rock_Ice_Permafrost"
    },
    {
      "x": -16,
      "y": 22,
      "z": -12,
      "name": "Rock_Ice_Permafrost"
    },
    {
      "x": -16,
      "y": 23,
      "z": -12,
      "name": "Rock_Ice_Permafrost"
    },
    {
      "x": -16,
      "y": 24,
      "z": -12,
      "name": "Soil_Snow"
    },
    {
      "x": -16,
      "y": 17,
      "z": -11,
      "name": "Rock_Ice_Permafrost"
    },
    {
      "x": -16,
      "y": 18,
      "z": -11,
      "name": "Rock_Ice_Permafrost"
    },
    {
      "x": -16,
      "y": 19,
      "z": -11,
      "name": "Rock_Ice_Permafrost"
    },
    {
      "x": -16,
      "y": 20,
      "z": -11,
      "name": "Rock_Ice_Permafrost"
    },
    {
      "x": -16,
      "y": 21,
      "z": -11,
      "name": "Rock_Ice_Permafrost"
    },
    {
      "x": -16,
      "y": 22,
      "z": -11,
      "name": "Rock_Ice_Permafrost"
    },
    {
      "x": -16,
      "y": 23,
      "z": -11,
      "name": "Rock_Ice_Permafrost"
    },
    {
      "x": -16,
      "y": 24,
      "z": -11,
      "name": "Rock_Ice_Permafrost"
    },
    {
      "x": -16,
      "y": 25,
      "z": -11,
      "name": "Soil_Snow"
    },
    {
      "x": -16,
      "y": 16,
      "z": -10,
      "name": "Rock_Ice_Permafrost"
    },
    {
      "x": -16,
      "y": 17,
      "z": -10,
      "name": "Rock_Ice_Permafrost"
    },
    {
      "x": -16,
      "y": 18,
      "z": -10,
      "name": "Rock_Ice"
    },
    {
      "x": -16,
      "y": 19,
      "z": -10,
      "name": "Rock_Ice_Permafrost"
    },
    {
      "x": -16,
      "y": 20,
      "z": -10,
      "name": "Rock_Ice"
    },
    {
      "x": -16,
      "y": 21,
      "z": -10,
      "name": "Rock_Ice"
    },
    {
      "x": -16,
      "y": 22,
      "z": -10,
      "name": "Rock_Ice_Permafrost"
    },
    {
      "x": -16,
      "y": 23,
      "z": -10,
      "name": "Rock_Ice_Permafrost"
    },
    {
      "x": -16,
      "y": 24,
      "z": -10,
      "name": "Rock_Ice_Permafrost"
    },
    {
      "x": -16,
      "y": 25,
      "z": -10,
      "name": "Rock_Ice_Permafrost"
    },
    {
      "x": -16,
      "y": 26,
      "z": -10,
      "name": "Soil_Snow"
    },
    {
      "x": -16,
      "y": 15,
      "z": -9,
      "name": "Rock_Ice_Permafrost"
    },
    {
      "x": -16,
      "y": 16,
      "z": -9,
      "name": "Rock_Ice_Permafrost"
    },
    {
      "x": -16,
      "y": 17,
      "z": -9,
      "name": "Rock_Ice"
    },
    {
      "x": -16,
      "y": 18,
      "z": -9,
      "name": "Rock_Ice"
    },
    {
      "x": -16,
      "y": 19,
      "z": -9,
      "name": "Rock_Ice"
    },
    {
      "x": -16,
      "y": 20,
      "z": -9,
      "name": "Rock_Ice"
    },
    {
      "x": -16,
      "y": 21,
      "z": -9,
      "name": "Rock_Ice"
    },
    {
      "x": -16,
      "y": 22,
      "z": -9,
      "name": "Rock_Ice_Permafrost"
    },
    {
      "x": -16,
      "y": 23,
      "z": -9,
      "name": "Rock_Ice_Permafrost"
    },
    {
      "x": -16,
      "y": 24,
      "z": -9,
      "name": "Rock_Ice_Permafrost"
    },
    {
      "x": -16,
      "y": 25,
      "z": -9,
      "name": "Rock_Ice"
    },
    {
      "x": -16,
      "y": 26,
      "z": -9,
      "name": "Rock_Ice_Permafrost"
    },
    {
      "x": -16,
      "y": 27,
      "z": -9,
      "name": "Soil_Snow"
    },
    {
      "x": -16,
      "y": 14,
      "z": -8,
      "name": "Rock_Ice_Permafrost"
    },
    {
      "x": -16,
      "y": 15,
      "z": -8,
      "name": "Rock_Ice_Permafrost"
    },
    {
      "x": -16,
      "y": 16,
      "z": -8,
      "name": "Rock_Ice_Permafrost"
    },
    {
      "x": -16,
      "y": 17,
      "z": -8,
      "name": "Rock_Ice"
    },
    {
      "x": -16,
      "y": 18,
      "z": -8,
      "name": "Rock_Ice"
    },
    {
      "x": -16,
      "y": 19,
      "z": -8,
      "name": "Rock_Ice"
    },
    {
      "x": -16,
      "y": 20,
      "z": -8,
      "name": "Rock_Ice"
    },
    {
      "x": -16,
      "y": 21,
      "z": -8,
      "name": "Rock_Ice"
    },
    {
      "x": -16,
      "y": 22,
      "z": -8,
      "name": "Rock_Ice_Permafrost"
    },
    {
      "x": -16,
      "y": 23,
      "z": -8,
      "name": "Rock_Ice_Permafrost"
    },
    {
      "x": -16,
      "y": 24,
      "z": -8,
      "name": "Rock_Ice_Permafrost"
    },
    {
      "x": -16,
      "y": 25,
      "z": -8,
      "name": "Rock_Ice"
    },
    {
      "x": -16,
      "y": 26,
      "z": -8,
      "name": "Rock_Ice_Permafrost"
    },
    {
      "x": -16,
      "y": 27,
      "z": -8,
      "name": "Soil_Snow"
    },
    {
      "x": -16,
      "y": 15,
      "z": -7,
      "name": "Rock_Ice"
    },
    {
      "x": -16,
      "y": 16,
      "z": -7,
      "name": "Rock_Ice"
    },
    {
      "x": -16,
      "y": 17,
      "z": -7,
      "name": "Rock_Ice"
    },
    {
      "x": -16,
      "y": 18,
      "z": -7,
      "name": "Rock_Ice"
    },
    {
      "x": -16,
      "y": 19,
      "z": -7,
      "name": "Rock_Ice"
    },
    {
      "x": -16,
      "y": 20,
      "z": -7,
      "name": "Rock_Ice"
    },
    {
      "x": -16,
      "y": 21,
      "z": -7,
      "name": "Rock_Ice"
    },
    {
      "x": -16,
      "y": 22,
      "z": -7,
      "name": "Rock_Ice_Permafrost"
    },
    {
      "x": -16,
      "y": 23,
      "z": -7,
      "name": "Rock_Ice_Permafrost"
    },
    {
      "x": -16,
      "y": 24,
      "z": -7,
      "name": "Rock_Ice_Permafrost"
    },
    {
      "x": -16,
      "y": 25,
      "z": -7,
      "name": "Rock_Ice_Permafrost"
    },
    {
      "x": -16,
      "y": 26,
      "z": -7,
      "name": "Rock_Ice_Permafrost"
    },
    {
      "x": -16,
      "y": 27,
      "z": -7,
      "name": "Rock_Ice_Permafrost"
    },
    {
      "x": -16,
      "y": 28,
      "z": -7,
      "name": "Soil_Snow"
    },
    {
      "x": -16,
      "y": 15,
      "z": -6,
      "name": "Rock_Ice"
    },
    {
      "x": -16,
      "y": 16,
      "z": -6,
      "name": "Rock_Ice"
    },
    {
      "x": -16,
      "y": 17,
      "z": -6,
      "name": "Rock_Ice"
    },
    {
      "x": -16,
      "y": 18,
      "z": -6,
      "name": "Rock_Ice"
    },
    {
      "x": -16,
      "y": 19,
      "z": -6,
      "name": "Rock_Ice"
    },
    {
      "x": -16,
      "y": 20,
      "z": -6,
      "name": "Rock_Ice"
    },
    {
      "x": -16,
      "y": 21,
      "z": -6,
      "name": "Rock_Ice"
    },
    {
      "x": -16,
      "y": 22,
      "z": -6,
      "name": "Rock_Ice_Permafrost"
    },
    {
      "x": -16,
      "y": 23,
      "z": -6,
      "name": "Rock_Ice_Permafrost"
    },
    {
      "x": -16,
      "y": 24,
      "z": -6,
      "name": "Rock_Ice_Permafrost"
    },
    {
      "x": -16,
      "y": 25,
      "z": -6,
      "name": "Rock_Ice_Permafrost"
    },
    {
      "x": -16,
      "y": 26,
      "z": -6,
      "name": "Rock_Ice"
    },
    {
      "x": -16,
      "y": 27,
      "z": -6,
      "name": "Rock_Ice_Permafrost"
    },
    {
      "x": -16,
      "y": 28,
      "z": -6,
      "name": "Soil_Snow"
    },
    {
      "x": -16,
      "y": 15,
      "z": -5,
      "name": "Rock_Ice"
    },
    {
      "x": -16,
      "y": 16,
      "z": -5,
      "name": "Rock_Ice"
    },
    {
      "x": -16,
      "y": 17,
      "z": -5,
      "name": "Rock_Ice"
    },
    {
      "x": -16,
      "y": 18,
      "z": -5,
      "name": "Rock_Ice"
    },
    {
      "x": -16,
      "y": 19,
      "z": -5,
      "name": "Rock_Ice"
    },
    {
      "x": -16,
      "y": 20,
      "z": -5,
      "name": "Rock_Ice"
    },
    {
      "x": -16,
      "y": 21,
      "z": -5,
      "name": "Rock_Ice"
    },
    {
      "x": -16,
      "y": 22,
      "z": -5,
      "name": "Rock_Ice"
    },
    {
      "x": -16,
      "y": 23,
      "z": -5,
      "name": "Rock_Ice_Permafrost"
    },
    {
      "x": -16,
      "y": 24,
      "z": -5,
      "name": "Rock_Ice_Permafrost"
    },
    {
      "x": -16,
      "y": 25,
      "z": -5,
      "name": "Rock_Ice_Permafrost"
    },
    {
      "x": -16,
      "y": 26,
      "z": -5,
      "name": "Rock_Ice"
    },
    {
      "x": -16,
      "y": 27,
      "z": -5,
      "name": "Rock_Ice_Permafrost"
    },
    {
      "x": -16,
      "y": 28,
      "z": -5,
      "name": "Soil_Snow"
    },
    {
      "x": -16,
      "y": 16,
      "z": -4,
      "name": "Rock_Ice"
    },
    {
      "x": -16,
      "y": 17,
      "z": -4,
      "name": "Rock_Ice"
    },
    {
      "x": -16,
      "y": 18,
      "z": -4,
      "name": "Rock_Ice"
    },
    {
      "x": -16,
      "y": 19,
      "z": -4,
      "name": "Rock_Ice"
    },
    {
      "x": -16,
      "y": 20,
      "z": -4,
      "name": "Rock_Ice"
    },
    {
      "x": -16,
      "y": 21,
      "z": -4,
      "name": "Rock_Ice"
    },
    {
      "x": -16,
      "y": 22,
      "z": -4,
      "name": "Rock_Ice"
    },
    {
      "x": -16,
      "y": 23,
      "z": -4,
      "name": "Rock_Ice_Permafrost"
    },
    {
      "x": -16,
      "y": 24,
      "z": -4,
      "name": "Rock_Ice_Permafrost"
    },
    {
      "x": -16,
      "y": 25,
      "z": -4,
      "name": "Rock_Ice_Permafrost"
    },
    {
      "x": -16,
      "y": 26,
      "z": -4,
      "name": "Rock_Ice"
    },
    {
      "x": -16,
      "y": 27,
      "z": -4,
      "name": "Rock_Ice"
    },
    {
      "x": -16,
      "y": 28,
      "z": -4,
      "name": "Rock_Ice_Permafrost"
    },
    {
      "x": -16,
      "y": 29,
      "z": -4,
      "name": "Soil_Snow"
    },
    {
      "x": -16,
      "y": 16,
      "z": -3,
      "name": "Rock_Ice"
    },
    {
      "x": -16,
      "y": 17,
      "z": -3,
      "name": "Rock_Ice"
    },
    {
      "x": -16,
      "y": 18,
      "z": -3,
      "name": "Rock_Ice"
    },
    {
      "x": -16,
      "y": 19,
      "z": -3,
      "name": "Rock_Ice"
    },
    {
      "x": -16,
      "y": 20,
      "z": -3,
      "name": "Rock_Ice"
    },
    {
      "x": -16,
      "y": 21,
      "z": -3,
      "name": "Rock_Ice"
    },
    {
      "x": -16,
      "y": 22,
      "z": -3,
      "name": "Rock_Ice"
    },
    {
      "x": -16,
      "y": 23,
      "z": -3,
      "name": "Rock_Ice_Permafrost"
    },
    {
      "x": -16,
      "y": 24,
      "z": -3,
      "name": "Rock_Ice_Permafrost"
    },
    {
      "x": -16,
      "y": 25,
      "z": -3,
      "name": "Rock_Ice_Permafrost"
    },
    {
      "x": -16,
      "y": 26,
      "z": -3,
      "name": "Rock_Ice"
    },
    {
      "x": -16,
      "y": 27,
      "z": -3,
      "name": "Rock_Ice"
    },
    {
      "x": -16,
      "y": 28,
      "z": -3,
      "name": "Rock_Ice"
    },
    {
      "x": -16,
      "y": 29,
      "z": -3,
      "name": "Soil_Snow"
    },
    {
      "x": -16,
      "y": 17,
      "z": -2,
      "name": "Rock_Ice"
    },
    {
      "x": -16,
      "y": 18,
      "z": -2,
      "name": "Rock_Ice"
    },
    {
      "x": -16,
      "y": 19,
      "z": -2,
      "name": "Rock_Ice"
    },
    {
      "x": -16,
      "y": 20,
      "z": -2,
      "name": "Rock_Ice"
    },
    {
      "x": -16,
      "y": 21,
      "z": -2,
      "name": "Rock_Ice"
    },
    {
      "x": -16,
      "y": 22,
      "z": -2,
      "name": "Rock_Ice"
    },
    {
      "x": -16,
      "y": 23,
      "z": -2,
      "name": "Rock_Ice_Permafrost"
    },
    {
      "x": -16,
      "y": 24,
      "z": -2,
      "name": "Rock_Ice_Permafrost"
    },
    {
      "x": -16,
      "y": 25,
      "z": -2,
      "name": "Rock_Ice_Permafrost"
    },
    {
      "x": -16,
      "y": 26,
      "z": -2,
      "name": "Rock_Ice"
    },
    {
      "x": -16,
      "y": 27,
      "z": -2,
      "name": "Rock_Ice"
    },
    {
      "x": -16,
      "y": 28,
      "z": -2,
      "name": "Rock_Ice"
    },
    {
      "x": -16,
      "y": 29,
      "z": -2,
      "name": "Soil_Snow"
    },
    {
      "x": -16,
      "y": 19,
      "z": -1,
      "name": "Rock_Ice"
    },
    {
      "x": -16,
      "y": 20,
      "z": -1,
      "name": "Rock_Ice"
    },
    {
      "x": -16,
      "y": 21,
      "z": -1,
      "name": "Rock_Ice"
    },
    {
      "x": -16,
      "y": 22,
      "z": -1,
      "name": "Rock_Ice"
    },
    {
      "x": -16,
      "y": 23,
      "z": -1,
      "name": "Rock_Ice"
    },
    {
      "x": -16,
      "y": 24,
      "z": -1,
      "name": "Rock_Ice_Permafrost"
    },
    {
      "x": -16,
      "y": 25,
      "z": -1,
      "name": "Rock_Ice_Permafrost"
    },
    {
      "x": -16,
      "y": 26,
      "z": -1,
      "name": "Rock_Ice"
    },
    {
      "x": -16,
      "y": 27,
      "z": -1,
      "name": "Rock_Ice"
    },
    {
      "x": -16,
      "y": 28,
      "z": -1,
      "name": "Rock_Ice"
    },
    {
      "x": -16,
      "y": 29,
      "z": -1,
      "name": "Soil_Snow"
    },
    {
      "x": -16,
      "y": 21,
      "z": 0,
      "name": "Rock_Ice"
    },
    {
      "x": -16,
      "y": 22,
      "z": 0,
      "name": "Rock_Ice"
    },
    {
      "x": -16,
      "y": 23,
      "z": 0,
      "name": "Rock_Ice"
    },
    {
      "x": -16,
      "y": 24,
      "z": 0,
      "name": "Rock_Ice_Permafrost"
    },
    {
      "x": -16,
      "y": 25,
      "z": 0,
      "name": "Rock_Ice_Permafrost"
    },
    {
      "x": -16,
      "y": 26,
      "z": 0,
      "name": "Rock_Ice"
    },
    {
      "x": -16,
      "y": 27,
      "z": 0,
      "name": "Rock_Ice"
    },
    {
      "x": -16,
      "y": 28,
      "z": 0,
      "name": "Rock_Ice"
    },
    {
      "x": -16,
      "y": 29,
      "z": 0,
      "name": "Soil_Snow"
    },
    {
      "x": -16,
      "y": 23,
      "z": 1,
      "name": "Rock_Ice"
    },
    {
      "x": -16,
      "y": 24,
      "z": 1,
      "name": "Rock_Ice_Permafrost"
    },
    {
      "x": -16,
      "y": 25,
      "z": 1,
      "name": "Rock_Ice_Permafrost"
    },
    {
      "x": -16,
      "y": 26,
      "z": 1,
      "name": "Rock_Ice"
    },
    {
      "x": -16,
      "y": 27,
      "z": 1,
      "name": "Rock_Ice"
    },
    {
      "x": -16,
      "y": 28,
      "z": 1,
      "name": "Soil_Snow"
    },
    {
      "x": -16,
      "y": 24,
      "z": 2,
      "name": "Rock_Ice"
    },
    {
      "x": -16,
      "y": 25,
      "z": 2,
      "name": "Rock_Ice_Permafrost"
    },
    {
      "x": -16,
      "y": 26,
      "z": 2,
      "name": "Rock_Ice_Permafrost"
    },
    {
      "x": -16,
      "y": 27,
      "z": 2,
      "name": "Rock_Ice"
    },
    {
      "x": -16,
      "y": 28,
      "z": 2,
      "name": "Soil_Snow"
    },
    {
      "x": -16,
      "y": 25,
      "z": 3,
      "name": "Rock_Ice_Permafrost"
    },
    {
      "x": -16,
      "y": 26,
      "z": 3,
      "name": "Rock_Ice"
    },
    {
      "x": -16,
      "y": 27,
      "z": 3,
      "name": "Soil_Snow"
    },
    {
      "x": -15,
      "y": 19,
      "z": -13,
      "name": "Rock_Ice"
    },
    {
      "x": -15,
      "y": 20,
      "z": -13,
      "name": "Rock_Ice_Permafrost"
    },
    {
      "x": -15,
      "y": 21,
      "z": -13,
      "name": "Rock_Ice_Permafrost"
    },
    {
      "x": -15,
      "y": 22,
      "z": -13,
      "name": "Rock_Ice_Permafrost"
    },
    {
      "x": -15,
      "y": 23,
      "z": -13,
      "name": "Soil_Snow"
    },
    {
      "x": -15,
      "y": 17,
      "z": -12,
      "name": "Rock_Ice"
    },
    {
      "x": -15,
      "y": 18,
      "z": -12,
      "name": "Rock_Ice"
    },
    {
      "x": -15,
      "y": 19,
      "z": -12,
      "name": "Rock_Ice_Permafrost"
    },
    {
      "x": -15,
      "y": 20,
      "z": -12,
      "name": "Rock_Ice_Permafrost"
    },
    {
      "x": -15,
      "y": 21,
      "z": -12,
      "name": "Rock_Ice_Permafrost"
    },
    {
      "x": -15,
      "y": 22,
      "z": -12,
      "name": "Rock_Ice_Permafrost"
    },
    {
      "x": -15,
      "y": 23,
      "z": -12,
      "name": "Rock_Ice_Permafrost"
    },
    {
      "x": -15,
      "y": 24,
      "z": -12,
      "name": "Soil_Snow"
    },
    {
      "x": -15,
      "y": 16,
      "z": -11,
      "name": "Rock_Ice"
    },
    {
      "x": -15,
      "y": 17,
      "z": -11,
      "name": "Rock_Ice_Permafrost"
    },
    {
      "x": -15,
      "y": 18,
      "z": -11,
      "name": "Rock_Ice_Permafrost"
    },
    {
      "x": -15,
      "y": 19,
      "z": -11,
      "name": "Rock_Ice_Permafrost"
    },
    {
      "x": -15,
      "y": 20,
      "z": -11,
      "name": "Rock_Ice_Permafrost"
    },
    {
      "x": -15,
      "y": 21,
      "z": -11,
      "name": "Rock_Ice_Permafrost"
    },
    {
      "x": -15,
      "y": 22,
      "z": -11,
      "name": "Rock_Ice_Permafrost"
    },
    {
      "x": -15,
      "y": 23,
      "z": -11,
      "name": "Rock_Ice_Permafrost"
    },
    {
      "x": -15,
      "y": 24,
      "z": -11,
      "name": "Rock_Ice_Permafrost"
    },
    {
      "x": -15,
      "y": 25,
      "z": -11,
      "name": "Soil_Snow"
    },
    {
      "x": -15,
      "y": 15,
      "z": -10,
      "name": "Rock_Ice_Permafrost"
    },
    {
      "x": -15,
      "y": 16,
      "z": -10,
      "name": "Rock_Ice_Permafrost"
    },
    {
      "x": -15,
      "y": 17,
      "z": -10,
      "name": "Rock_Ice_Permafrost"
    },
    {
      "x": -15,
      "y": 18,
      "z": -10,
      "name": "Rock_Ice_Permafrost"
    },
    {
      "x": -15,
      "y": 19,
      "z": -10,
      "name": "Rock_Ice_Permafrost"
    },
    {
      "x": -15,
      "y": 20,
      "z": -10,
      "name": "Rock_Ice_Permafrost"
    },
    {
      "x": -15,
      "y": 21,
      "z": -10,
      "name": "Rock_Ice_Permafrost"
    },
    {
      "x": -15,
      "y": 22,
      "z": -10,
      "name": "Rock_Ice_Permafrost"
    },
    {
      "x": -15,
      "y": 23,
      "z": -10,
      "name": "Rock_Ice_Permafrost"
    },
    {
      "x": -15,
      "y": 24,
      "z": -10,
      "name": "Rock_Ice_Permafrost"
    },
    {
      "x": -15,
      "y": 25,
      "z": -10,
      "name": "Rock_Ice_Permafrost"
    },
    {
      "x": -15,
      "y": 26,
      "z": -10,
      "name": "Soil_Snow"
    },
    {
      "x": -15,
      "y": 14,
      "z": -9,
      "name": "Rock_Ice"
    },
    {
      "x": -15,
      "y": 15,
      "z": -9,
      "name": "Rock_Ice_Permafrost"
    },
    {
      "x": -15,
      "y": 16,
      "z": -9,
      "name": "Rock_Ice_Permafrost"
    },
    {
      "x": -15,
      "y": 17,
      "z": -9,
      "name": "Rock_Ice_Permafrost"
    },
    {
      "x": -15,
      "y": 18,
      "z": -9,
      "name": "Rock_Ice_Permafrost"
    },
    {
      "x": -15,
      "y": 19,
      "z": -9,
      "name": "Rock_Ice_Permafrost"
    },
    {
      "x": -15,
      "y": 20,
      "z": -9,
      "name": "Rock_Ice_Permafrost"
    },
    {
      "x": -15,
      "y": 21,
      "z": -9,
      "name": "Rock_Ice_Permafrost"
    },
    {
      "x": -15,
      "y": 22,
      "z": -9,
      "name": "Rock_Ice_Permafrost"
    },
    {
      "x": -15,
      "y": 23,
      "z": -9,
      "name": "Rock_Ice_Permafrost"
    },
    {
      "x": -15,
      "y": 24,
      "z": -9,
      "name": "Rock_Ice_Permafrost"
    },
    {
      "x": -15,
      "y": 25,
      "z": -9,
      "name": "Rock_Ice"
    },
    {
      "x": -15,
      "y": 26,
      "z": -9,
      "name": "Rock_Ice_Permafrost"
    },
    {
      "x": -15,
      "y": 27,
      "z": -9,
      "name": "Soil_Snow"
    },
    {
      "x": -15,
      "y": 13,
      "z": -8,
      "name": "Rock_Ice_Permafrost"
    },
    {
      "x": -15,
      "y": 14,
      "z": -8,
      "name": "Rock_Ice_Permafrost"
    },
    {
      "x": -15,
      "y": 15,
      "z": -8,
      "name": "Rock_Ice_Permafrost"
    },
    {
      "x": -15,
      "y": 16,
      "z": -8,
      "name": "Rock_Ice_Permafrost"
    },
    {
      "x": -15,
      "y": 17,
      "z": -8,
      "name": "Rock_Ice_Permafrost"
    },
    {
      "x": -15,
      "y": 18,
      "z": -8,
      "name": "Rock_Ice_Permafrost"
    },
    {
      "x": -15,
      "y": 19,
      "z": -8,
      "name": "Rock_Ice"
    },
    {
      "x": -15,
      "y": 20,
      "z": -8,
      "name": "Rock_Ice"
    },
    {
      "x": -15,
      "y": 21,
      "z": -8,
      "name": "Rock_Ice"
    },
    {
      "x": -15,
      "y": 22,
      "z": -8,
      "name": "Rock_Ice_Permafrost"
    },
    {
      "x": -15,
      "y": 23,
      "z": -8,
      "name": "Rock_Ice_Permafrost"
    },
    {
      "x": -15,
      "y": 24,
      "z": -8,
      "name": "Rock_Ice_Permafrost"
    },
    {
      "x": -15,
      "y": 25,
      "z": -8,
      "name": "Rock_Ice_Permafrost"
    },
    {
      "x": -15,
      "y": 26,
      "z": -8,
      "name": "Rock_Ice_Permafrost"
    },
    {
      "x": -15,
      "y": 27,
      "z": -8,
      "name": "Rock_Ice_Permafrost"
    },
    {
      "x": -15,
      "y": 28,
      "z": -8,
      "name": "Soil_Snow"
    },
    {
      "x": -15,
      "y": 13,
      "z": -7,
      "name": "Rock_Ice_Permafrost"
    },
    {
      "x": -15,
      "y": 14,
      "z": -7,
      "name": "Rock_Ice_Permafrost"
    },
    {
      "x": -15,
      "y": 15,
      "z": -7,
      "name": "Rock_Ice_Permafrost"
    },
    {
      "x": -15,
      "y": 16,
      "z": -7,
      "name": "Rock_Ice"
    },
    {
      "x": -15,
      "y": 17,
      "z": -7,
      "name": "Rock_Ice"
    },
    {
      "x": -15,
      "y": 18,
      "z": -7,
      "name": "Rock_Ice"
    },
    {
      "x": -15,
      "y": 19,
      "z": -7,
      "name": "Rock_Ice"
    },
    {
      "x": -15,
      "y": 20,
      "z": -7,
      "name": "Rock_Ice"
    },
    {
      "x": -15,
      "y": 21,
      "z": -7,
      "name": "Rock_Ice"
    },
    {
      "x": -15,
      "y": 22,
      "z": -7,
      "name": "Rock_Ice_Permafrost"
    },
    {
      "x": -15,
      "y": 23,
      "z": -7,
      "name": "Rock_Ice_Permafrost"
    },
    {
      "x": -15,
      "y": 24,
      "z": -7,
      "name": "Rock_Ice_Permafrost"
    },
    {
      "x": -15,
      "y": 25,
      "z": -7,
      "name": "Rock_Ice_Permafrost"
    },
    {
      "x": -15,
      "y": 26,
      "z": -7,
      "name": "Rock_Ice"
    },
    {
      "x": -15,
      "y": 27,
      "z": -7,
      "name": "Rock_Ice_Permafrost"
    },
    {
      "x": -15,
      "y": 28,
      "z": -7,
      "name": "Soil_Snow"
    },
    {
      "x": -15,
      "y": 13,
      "z": -6,
      "name": "Rock_Ice_Permafrost"
    },
    {
      "x": -15,
      "y": 14,
      "z": -6,
      "name": "Rock_Ice"
    },
    {
      "x": -15,
      "y": 15,
      "z": -6,
      "name": "Rock_Ice_Permafrost"
    },
    {
      "x": -15,
      "y": 16,
      "z": -6,
      "name": "Rock_Ice"
    },
    {
      "x": -15,
      "y": 17,
      "z": -6,
      "name": "Rock_Ice"
    },
    {
      "x": -15,
      "y": 18,
      "z": -6,
      "name": "Rock_Ice"
    },
    {
      "x": -15,
      "y": 19,
      "z": -6,
      "name": "Rock_Ice"
    },
    {
      "x": -15,
      "y": 20,
      "z": -6,
      "name": "Rock_Ice"
    },
    {
      "x": -15,
      "y": 21,
      "z": -6,
      "name": "Rock_Ice"
    },
    {
      "x": -15,
      "y": 22,
      "z": -6,
      "name": "Rock_Ice_Permafrost"
    },
    {
      "x": -15,
      "y": 23,
      "z": -6,
      "name": "Rock_Ice_Permafrost"
    },
    {
      "x": -15,
      "y": 24,
      "z": -6,
      "name": "Rock_Ice_Permafrost"
    },
    {
      "x": -15,
      "y": 25,
      "z": -6,
      "name": "Rock_Ice"
    },
    {
      "x": -15,
      "y": 26,
      "z": -6,
      "name": "Rock_Ice_Permafrost"
    },
    {
      "x": -15,
      "y": 27,
      "z": -6,
      "name": "Rock_Ice_Permafrost"
    },
    {
      "x": -15,
      "y": 28,
      "z": -6,
      "name": "Soil_Snow"
    },
    {
      "x": -15,
      "y": 14,
      "z": -5,
      "name": "Rock_Ice"
    },
    {
      "x": -15,
      "y": 15,
      "z": -5,
      "name": "Rock_Ice"
    },
    {
      "x": -15,
      "y": 16,
      "z": -5,
      "name": "Rock_Ice"
    },
    {
      "x": -15,
      "y": 17,
      "z": -5,
      "name": "Rock_Ice"
    },
    {
      "x": -15,
      "y": 18,
      "z": -5,
      "name": "Rock_Ice"
    },
    {
      "x": -15,
      "y": 19,
      "z": -5,
      "name": "Rock_Ice"
    },
    {
      "x": -15,
      "y": 20,
      "z": -5,
      "name": "Rock_Ice"
    },
    {
      "x": -15,
      "y": 21,
      "z": -5,
      "name": "Rock_Ice"
    },
    {
      "x": -15,
      "y": 22,
      "z": -5,
      "name": "Rock_Ice"
    },
    {
      "x": -15,
      "y": 23,
      "z": -5,
      "name": "Rock_Ice_Permafrost"
    },
    {
      "x": -15,
      "y": 24,
      "z": -5,
      "name": "Rock_Ice_Permafrost"
    },
    {
      "x": -15,
      "y": 25,
      "z": -5,
      "name": "Rock_Ice_Permafrost"
    },
    {
      "x": -15,
      "y": 26,
      "z": -5,
      "name": "Rock_Ice"
    },
    {
      "x": -15,
      "y": 27,
      "z": -5,
      "name": "Rock_Ice"
    },
    {
      "x": -15,
      "y": 28,
      "z": -5,
      "name": "Rock_Ice"
    },
    {
      "x": -15,
      "y": 29,
      "z": -5,
      "name": "Soil_Snow"
    },
    {
      "x": -15,
      "y": 14,
      "z": -4,
      "name": "Rock_Ice"
    },
    {
      "x": -15,
      "y": 15,
      "z": -4,
      "name": "Rock_Ice"
    },
    {
      "x": -15,
      "y": 16,
      "z": -4,
      "name": "Rock_Ice"
    },
    {
      "x": -15,
      "y": 17,
      "z": -4,
      "name": "Rock_Ice"
    },
    {
      "x": -15,
      "y": 18,
      "z": -4,
      "name": "Rock_Ice"
    },
    {
      "x": -15,
      "y": 19,
      "z": -4,
      "name": "Rock_Ice"
    },
    {
      "x": -15,
      "y": 20,
      "z": -4,
      "name": "Rock_Ice"
    },
    {
      "x": -15,
      "y": 21,
      "z": -4,
      "name": "Rock_Ice"
    },
    {
      "x": -15,
      "y": 22,
      "z": -4,
      "name": "Rock_Ice"
    },
    {
      "x": -15,
      "y": 23,
      "z": -4,
      "name": "Rock_Ice_Permafrost"
    },
    {
      "x": -15,
      "y": 24,
      "z": -4,
      "name": "Rock_Ice_Permafrost"
    },
    {
      "x": -15,
      "y": 25,
      "z": -4,
      "name": "Rock_Ice_Permafrost"
    },
    {
      "x": -15,
      "y": 26,
      "z": -4,
      "name": "Rock_Ice"
    },
    {
      "x": -15,
      "y": 27,
      "z": -4,
      "name": "Rock_Ice"
    },
    {
      "x": -15,
      "y": 28,
      "z": -4,
      "name": "Rock_Ice"
    },
    {
      "x": -15,
      "y": 29,
      "z": -4,
      "name": "Rock_Ice"
    },
    {
      "x": -15,
      "y": 30,
      "z": -4,
      "name": "Soil_Snow"
    },
    {
      "x": -15,
      "y": 15,
      "z": -3,
      "name": "Rock_Ice"
    },
    {
      "x": -15,
      "y": 16,
      "z": -3,
      "name": "Rock_Ice"
    },
    {
      "x": -15,
      "y": 17,
      "z": -3,
      "name": "Rock_Ice"
    },
    {
      "x": -15,
      "y": 18,
      "z": -3,
      "name": "Rock_Ice"
    },
    {
      "x": -15,
      "y": 19,
      "z": -3,
      "name": "Rock_Ice"
    },
    {
      "x": -15,
      "y": 20,
      "z": -3,
      "name": "Rock_Ice"
    },
    {
      "x": -15,
      "y": 21,
      "z": -3,
      "name": "Rock_Ice"
    },
    {
      "x": -15,
      "y": 22,
      "z": -3,
      "name": "Rock_Ice"
    },
    {
      "x": -15,
      "y": 23,
      "z": -3,
      "name": "Rock_Ice_Permafrost"
    },
    {
      "x": -15,
      "y": 24,
      "z": -3,
      "name": "Rock_Ice_Permafrost"
    },
    {
      "x": -15,
      "y": 25,
      "z": -3,
      "name": "Rock_Ice_Permafrost"
    },
    {
      "x": -15,
      "y": 26,
      "z": -3,
      "name": "Rock_Ice"
    },
    {
      "x": -15,
      "y": 27,
      "z": -3,
      "name": "Rock_Ice"
    },
    {
      "x": -15,
      "y": 28,
      "z": -3,
      "name": "Rock_Ice"
    },
    {
      "x": -15,
      "y": 29,
      "z": -3,
      "name": "Rock_Ice"
    },
    {
      "x": -15,
      "y": 30,
      "z": -3,
      "name": "Soil_Snow"
    },
    {
      "x": -15,
      "y": 16,
      "z": -2,
      "name": "Rock_Ice"
    },
    {
      "x": -15,
      "y": 17,
      "z": -2,
      "name": "Rock_Ice"
    },
    {
      "x": -15,
      "y": 18,
      "z": -2,
      "name": "Rock_Ice"
    },
    {
      "x": -15,
      "y": 19,
      "z": -2,
      "name": "Rock_Ice"
    },
    {
      "x": -15,
      "y": 20,
      "z": -2,
      "name": "Rock_Ice"
    },
    {
      "x": -15,
      "y": 21,
      "z": -2,
      "name": "Rock_Ice"
    },
    {
      "x": -15,
      "y": 22,
      "z": -2,
      "name": "Rock_Ice"
    },
    {
      "x": -15,
      "y": 23,
      "z": -2,
      "name": "Rock_Ice"
    },
    {
      "x": -15,
      "y": 24,
      "z": -2,
      "name": "Rock_Ice_Permafrost"
    },
    {
      "x": -15,
      "y": 25,
      "z": -2,
      "name": "Rock_Ice_Permafrost"
    },
    {
      "x": -15,
      "y": 26,
      "z": -2,
      "name": "Rock_Ice"
    },
    {
      "x": -15,
      "y": 27,
      "z": -2,
      "name": "Rock_Ice"
    },
    {
      "x": -15,
      "y": 28,
      "z": -2,
      "name": "Rock_Ice"
    },
    {
      "x": -15,
      "y": 29,
      "z": -2,
      "name": "Rock_Ice"
    },
    {
      "x": -15,
      "y": 30,
      "z": -2,
      "name": "Soil_Snow"
    },
    {
      "x": -15,
      "y": 17,
      "z": -1,
      "name": "Rock_Ice"
    },
    {
      "x": -15,
      "y": 18,
      "z": -1,
      "name": "Rock_Ice"
    },
    {
      "x": -15,
      "y": 19,
      "z": -1,
      "name": "Rock_Ice"
    },
    {
      "x": -15,
      "y": 20,
      "z": -1,
      "name": "Rock_Ice"
    },
    {
      "x": -15,
      "y": 21,
      "z": -1,
      "name": "Rock_Ice"
    },
    {
      "x": -15,
      "y": 22,
      "z": -1,
      "name": "Rock_Ice"
    },
    {
      "x": -15,
      "y": 23,
      "z": -1,
      "name": "Rock_Ice"
    },
    {
      "x": -15,
      "y": 24,
      "z": -1,
      "name": "Rock_Ice_Permafrost"
    },
    {
      "x": -15,
      "y": 25,
      "z": -1,
      "name": "Rock_Ice_Permafrost"
    },
    {
      "x": -15,
      "y": 26,
      "z": -1,
      "name": "Rock_Ice"
    },
    {
      "x": -15,
      "y": 27,
      "z": -1,
      "name": "Rock_Ice"
    },
    {
      "x": -15,
      "y": 28,
      "z": -1,
      "name": "Rock_Ice"
    },
    {
      "x": -15,
      "y": 29,
      "z": -1,
      "name": "Rock_Ice"
    },
    {
      "x": -15,
      "y": 30,
      "z": -1,
      "name": "Soil_Snow"
    },
    {
      "x": -15,
      "y": 19,
      "z": 0,
      "name": "Rock_Ice"
    },
    {
      "x": -15,
      "y": 20,
      "z": 0,
      "name": "Rock_Ice"
    },
    {
      "x": -15,
      "y": 21,
      "z": 0,
      "name": "Rock_Ice"
    },
    {
      "x": -15,
      "y": 22,
      "z": 0,
      "name": "Rock_Ice"
    },
    {
      "x": -15,
      "y": 23,
      "z": 0,
      "name": "Rock_Ice"
    },
    {
      "x": -15,
      "y": 24,
      "z": 0,
      "name": "Rock_Ice"
    },
    {
      "x": -15,
      "y": 25,
      "z": 0,
      "name": "Rock_Ice_Permafrost"
    },
    {
      "x": -15,
      "y": 26,
      "z": 0,
      "name": "Rock_Ice"
    },
    {
      "x": -15,
      "y": 27,
      "z": 0,
      "name": "Rock_Ice"
    },
    {
      "x": -15,
      "y": 28,
      "z": 0,
      "name": "Rock_Ice"
    },
    {
      "x": -15,
      "y": 29,
      "z": 0,
      "name": "Rock_Ice"
    },
    {
      "x": -15,
      "y": 30,
      "z": 0,
      "name": "Soil_Snow"
    },
    {
      "x": -15,
      "y": 21,
      "z": 1,
      "name": "Rock_Ice"
    },
    {
      "x": -15,
      "y": 22,
      "z": 1,
      "name": "Rock_Ice"
    },
    {
      "x": -15,
      "y": 23,
      "z": 1,
      "name": "Rock_Ice"
    },
    {
      "x": -15,
      "y": 24,
      "z": 1,
      "name": "Rock_Ice_Permafrost"
    },
    {
      "x": -15,
      "y": 25,
      "z": 1,
      "name": "Rock_Ice_Permafrost"
    },
    {
      "x": -15,
      "y": 26,
      "z": 1,
      "name": "Rock_Ice"
    },
    {
      "x": -15,
      "y": 27,
      "z": 1,
      "name": "Rock_Ice"
    },
    {
      "x": -15,
      "y": 28,
      "z": 1,
      "name": "Rock_Ice"
    },
    {
      "x": -15,
      "y": 29,
      "z": 1,
      "name": "Soil_Snow"
    },
    {
      "x": -15,
      "y": 23,
      "z": 2,
      "name": "Rock_Ice"
    },
    {
      "x": -15,
      "y": 24,
      "z": 2,
      "name": "Rock_Ice"
    },
    {
      "x": -15,
      "y": 25,
      "z": 2,
      "name": "Rock_Ice_Permafrost"
    },
    {
      "x": -15,
      "y": 26,
      "z": 2,
      "name": "Rock_Ice_Permafrost"
    },
    {
      "x": -15,
      "y": 27,
      "z": 2,
      "name": "Rock_Ice"
    },
    {
      "x": -15,
      "y": 28,
      "z": 2,
      "name": "Rock_Ice"
    },
    {
      "x": -15,
      "y": 29,
      "z": 2,
      "name": "Soil_Snow"
    },
    {
      "x": -15,
      "y": 25,
      "z": 3,
      "name": "Rock_Ice"
    },
    {
      "x": -15,
      "y": 26,
      "z": 3,
      "name": "Rock_Ice_Permafrost"
    },
    {
      "x": -15,
      "y": 27,
      "z": 3,
      "name": "Rock_Ice"
    },
    {
      "x": -15,
      "y": 28,
      "z": 3,
      "name": "Soil_Snow"
    },
    {
      "x": -15,
      "y": 26,
      "z": 4,
      "name": "Rock_Ice_Permafrost"
    },
    {
      "x": -15,
      "y": 27,
      "z": 4,
      "name": "Rock_Ice"
    },
    {
      "x": -15,
      "y": 28,
      "z": 4,
      "name": "Soil_Snow"
    },
    {
      "x": -14,
      "y": 18,
      "z": -13,
      "name": "Rock_Ice"
    },
    {
      "x": -14,
      "y": 19,
      "z": -13,
      "name": "Rock_Ice"
    },
    {
      "x": -14,
      "y": 20,
      "z": -13,
      "name": "Rock_Ice_Permafrost"
    },
    {
      "x": -14,
      "y": 21,
      "z": -13,
      "name": "Rock_Ice"
    },
    {
      "x": -14,
      "y": 22,
      "z": -13,
      "name": "Rock_Ice_Permafrost"
    },
    {
      "x": -14,
      "y": 23,
      "z": -13,
      "name": "Soil_Snow"
    },
    {
      "x": -14,
      "y": 16,
      "z": -12,
      "name": "Rock_Ice"
    },
    {
      "x": -14,
      "y": 17,
      "z": -12,
      "name": "Rock_Ice"
    },
    {
      "x": -14,
      "y": 18,
      "z": -12,
      "name": "Rock_Ice"
    },
    {
      "x": -14,
      "y": 19,
      "z": -12,
      "name": "Rock_Ice"
    },
    {
      "x": -14,
      "y": 20,
      "z": -12,
      "name": "Rock_Ice"
    },
    {
      "x": -14,
      "y": 21,
      "z": -12,
      "name": "Rock_Ice_Permafrost"
    },
    {
      "x": -14,
      "y": 22,
      "z": -12,
      "name": "Rock_Ice_Permafrost"
    },
    {
      "x": -14,
      "y": 23,
      "z": -12,
      "name": "Rock_Ice_Permafrost"
    },
    {
      "x": -14,
      "y": 24,
      "z": -12,
      "name": "Rock_Ice_Permafrost"
    },
    {
      "x": -14,
      "y": 25,
      "z": -12,
      "name": "Soil_Snow"
    },
    {
      "x": -14,
      "y": 15,
      "z": -11,
      "name": "Rock_Ice"
    },
    {
      "x": -14,
      "y": 16,
      "z": -11,
      "name": "Rock_Ice"
    },
    {
      "x": -14,
      "y": 17,
      "z": -11,
      "name": "Rock_Ice"
    },
    {
      "x": -14,
      "y": 18,
      "z": -11,
      "name": "Rock_Ice_Permafrost"
    },
    {
      "x": -14,
      "y": 19,
      "z": -11,
      "name": "Rock_Ice_Permafrost"
    },
    {
      "x": -14,
      "y": 20,
      "z": -11,
      "name": "Rock_Ice_Permafrost"
    },
    {
      "x": -14,
      "y": 21,
      "z": -11,
      "name": "Rock_Ice_Permafrost"
    },
    {
      "x": -14,
      "y": 22,
      "z": -11,
      "name": "Rock_Ice_Permafrost"
    },
    {
      "x": -14,
      "y": 23,
      "z": -11,
      "name": "Rock_Ice_Permafrost"
    },
    {
      "x": -14,
      "y": 24,
      "z": -11,
      "name": "Rock_Ice_Permafrost"
    },
    {
      "x": -14,
      "y": 25,
      "z": -11,
      "name": "Soil_Snow"
    },
    {
      "x": -14,
      "y": 14,
      "z": -10,
      "name": "Rock_Ice"
    },
    {
      "x": -14,
      "y": 15,
      "z": -10,
      "name": "Rock_Ice"
    },
    {
      "x": -14,
      "y": 16,
      "z": -10,
      "name": "Rock_Ice"
    },
    {
      "x": -14,
      "y": 17,
      "z": -10,
      "name": "Rock_Ice"
    },
    {
      "x": -14,
      "y": 18,
      "z": -10,
      "name": "Rock_Ice_Permafrost"
    },
    {
      "x": -14,
      "y": 19,
      "z": -10,
      "name": "Rock_Ice_Permafrost"
    },
    {
      "x": -14,
      "y": 20,
      "z": -10,
      "name": "Rock_Ice_Permafrost"
    },
    {
      "x": -14,
      "y": 21,
      "z": -10,
      "name": "Rock_Ice_Permafrost"
    },
    {
      "x": -14,
      "y": 22,
      "z": -10,
      "name": "Rock_Ice_Permafrost"
    },
    {
      "x": -14,
      "y": 23,
      "z": -10,
      "name": "Rock_Ice_Permafrost"
    },
    {
      "x": -14,
      "y": 24,
      "z": -10,
      "name": "Rock_Ice_Permafrost"
    },
    {
      "x": -14,
      "y": 25,
      "z": -10,
      "name": "Rock_Ice_Permafrost"
    },
    {
      "x": -14,
      "y": 26,
      "z": -10,
      "name": "Rock_Ice_Permafrost"
    },
    {
      "x": -14,
      "y": 27,
      "z": -10,
      "name": "Soil_Snow"
    },
    {
      "x": -14,
      "y": 13,
      "z": -9,
      "name": "Rock_Ice"
    },
    {
      "x": -14,
      "y": 14,
      "z": -9,
      "name": "Rock_Ice"
    },
    {
      "x": -14,
      "y": 15,
      "z": -9,
      "name": "Rock_Ice"
    },
    {
      "x": -14,
      "y": 16,
      "z": -9,
      "name": "Rock_Ice_Permafrost"
    },
    {
      "x": -14,
      "y": 17,
      "z": -9,
      "name": "Rock_Ice_Permafrost"
    },
    {
      "x": -14,
      "y": 18,
      "z": -9,
      "name": "Rock_Ice_Permafrost"
    },
    {
      "x": -14,
      "y": 19,
      "z": -9,
      "name": "Rock_Ice_Permafrost"
    },
    {
      "x": -14,
      "y": 20,
      "z": -9,
      "name": "Rock_Ice_Permafrost"
    },
    {
      "x": -14,
      "y": 21,
      "z": -9,
      "name": "Rock_Ice_Permafrost"
    },
    {
      "x": -14,
      "y": 22,
      "z": -9,
      "name": "Rock_Ice_Permafrost"
    },
    {
      "x": -14,
      "y": 23,
      "z": -9,
      "name": "Rock_Ice_Permafrost"
    },
    {
      "x": -14,
      "y": 24,
      "z": -9,
      "name": "Rock_Ice_Permafrost"
    },
    {
      "x": -14,
      "y": 25,
      "z": -9,
      "name": "Rock_Ice_Permafrost"
    },
    {
      "x": -14,
      "y": 26,
      "z": -9,
      "name": "Rock_Ice_Permafrost"
    },
    {
      "x": -14,
      "y": 27,
      "z": -9,
      "name": "Rock_Ice_Permafrost"
    },
    {
      "x": -14,
      "y": 28,
      "z": -9,
      "name": "Soil_Snow"
    },
    {
      "x": -14,
      "y": 13,
      "z": -8,
      "name": "Rock_Ice"
    },
    {
      "x": -14,
      "y": 14,
      "z": -8,
      "name": "Rock_Ice"
    },
    {
      "x": -14,
      "y": 15,
      "z": -8,
      "name": "Rock_Ice_Permafrost"
    },
    {
      "x": -14,
      "y": 16,
      "z": -8,
      "name": "Rock_Ice_Permafrost"
    },
    {
      "x": -14,
      "y": 17,
      "z": -8,
      "name": "Rock_Ice_Permafrost"
    },
    {
      "x": -14,
      "y": 18,
      "z": -8,
      "name": "Rock_Ice_Permafrost"
    },
    {
      "x": -14,
      "y": 19,
      "z": -8,
      "name": "Rock_Ice_Permafrost"
    },
    {
      "x": -14,
      "y": 20,
      "z": -8,
      "name": "Rock_Ice_Permafrost"
    },
    {
      "x": -14,
      "y": 21,
      "z": -8,
      "name": "Rock_Ice_Permafrost"
    },
    {
      "x": -14,
      "y": 22,
      "z": -8,
      "name": "Rock_Ice_Permafrost"
    },
    {
      "x": -14,
      "y": 23,
      "z": -8,
      "name": "Rock_Ice_Permafrost"
    },
    {
      "x": -14,
      "y": 24,
      "z": -8,
      "name": "Rock_Ice_Permafrost"
    },
    {
      "x": -14,
      "y": 25,
      "z": -8,
      "name": "Rock_Ice_Permafrost"
    },
    {
      "x": -14,
      "y": 26,
      "z": -8,
      "name": "Rock_Ice_Permafrost"
    },
    {
      "x": -14,
      "y": 27,
      "z": -8,
      "name": "Rock_Ice_Permafrost"
    },
    {
      "x": -14,
      "y": 28,
      "z": -8,
      "name": "Soil_Snow"
    },
    {
      "x": -14,
      "y": 12,
      "z": -7,
      "name": "Rock_Ice"
    },
    {
      "x": -14,
      "y": 13,
      "z": -7,
      "name": "Rock_Ice"
    },
    {
      "x": -14,
      "y": 14,
      "z": -7,
      "name": "Rock_Ice_Permafrost"
    },
    {
      "x": -14,
      "y": 15,
      "z": -7,
      "name": "Rock_Ice_Permafrost"
    },
    {
      "x": -14,
      "y": 16,
      "z": -7,
      "name": "Rock_Ice_Permafrost"
    },
    {
      "x": -14,
      "y": 17,
      "z": -7,
      "name": "Rock_Ice_Permafrost"
    },
    {
      "x": -14,
      "y": 18,
      "z": -7,
      "name": "Rock_Ice"
    },
    {
      "x": -14,
      "y": 19,
      "z": -7,
      "name": "Rock_Ice_Permafrost"
    },
    {
      "x": -14,
      "y": 20,
      "z": -7,
      "name": "Rock_Ice"
    },
    {
      "x": -14,
      "y": 21,
      "z": -7,
      "name": "Rock_Ice"
    },
    {
      "x": -14,
      "y": 22,
      "z": -7,
      "name": "Rock_Ice_Permafrost"
    },
    {
      "x": -14,
      "y": 23,
      "z": -7,
      "name": "Rock_Ice_Permafrost"
    },
    {
      "x": -14,
      "y": 24,
      "z": -7,
      "name": "Rock_Ice_Permafrost"
    },
    {
      "x": -14,
      "y": 25,
      "z": -7,
      "name": "Rock_Ice_Permafrost"
    },
    {
      "x": -14,
      "y": 26,
      "z": -7,
      "name": "Rock_Ice"
    },
    {
      "x": -14,
      "y": 27,
      "z": -7,
      "name": "Rock_Ice_Permafrost"
    },
    {
      "x": -14,
      "y": 28,
      "z": -7,
      "name": "Soil_Snow"
    },
    {
      "x": -14,
      "y": 11,
      "z": -6,
      "name": "Rock_Ice"
    },
    {
      "x": -14,
      "y": 12,
      "z": -6,
      "name": "Rock_Ice"
    },
    {
      "x": -14,
      "y": 13,
      "z": -6,
      "name": "Rock_Ice_Permafrost"
    },
    {
      "x": -14,
      "y": 14,
      "z": -6,
      "name": "Rock_Ice_Permafrost"
    },
    {
      "x": -14,
      "y": 15,
      "z": -6,
      "name": "Rock_Ice_Permafrost"
    },
    {
      "x": -14,
      "y": 16,
      "z": -6,
      "name": "Rock_Ice_Permafrost"
    },
    {
      "x": -14,
      "y": 17,
      "z": -6,
      "name": "Rock_Ice_Permafrost"
    },
    {
      "x": -14,
      "y": 18,
      "z": -6,
      "name": "Rock_Ice"
    },
    {
      "x": -14,
      "y": 19,
      "z": -6,
      "name": "Rock_Ice"
    },
    {
      "x": -14,
      "y": 20,
      "z": -6,
      "name": "Rock_Ice"
    },
    {
      "x": -14,
      "y": 21,
      "z": -6,
      "name": "Rock_Ice"
    },
    {
      "x": -14,
      "y": 22,
      "z": -6,
      "name": "Rock_Ice_Permafrost"
    },
    {
      "x": -14,
      "y": 23,
      "z": -6,
      "name": "Rock_Ice_Permafrost"
    },
    {
      "x": -14,
      "y": 24,
      "z": -6,
      "name": "Rock_Ice_Permafrost"
    },
    {
      "x": -14,
      "y": 25,
      "z": -6,
      "name": "Rock_Ice_Permafrost"
    },
    {
      "x": -14,
      "y": 26,
      "z": -6,
      "name": "Rock_Ice"
    },
    {
      "x": -14,
      "y": 27,
      "z": -6,
      "name": "Rock_Ice_Permafrost"
    },
    {
      "x": -14,
      "y": 28,
      "z": -6,
      "name": "Rock_Ice"
    },
    {
      "x": -14,
      "y": 29,
      "z": -6,
      "name": "Soil_Snow"
    },
    {
      "x": -14,
      "y": 11,
      "z": -5,
      "name": "Rock_Ice"
    },
    {
      "x": -14,
      "y": 12,
      "z": -5,
      "name": "Rock_Ice_Permafrost"
    },
    {
      "x": -14,
      "y": 13,
      "z": -5,
      "name": "Rock_Ice_Permafrost"
    },
    {
      "x": -14,
      "y": 14,
      "z": -5,
      "name": "Rock_Ice_Permafrost"
    },
    {
      "x": -14,
      "y": 15,
      "z": -5,
      "name": "Rock_Ice_Permafrost"
    },
    {
      "x": -14,
      "y": 16,
      "z": -5,
      "name": "Rock_Ice"
    },
    {
      "x": -14,
      "y": 17,
      "z": -5,
      "name": "Rock_Ice"
    },
    {
      "x": -14,
      "y": 18,
      "z": -5,
      "name": "Rock_Ice"
    },
    {
      "x": -14,
      "y": 19,
      "z": -5,
      "name": "Rock_Ice"
    },
    {
      "x": -14,
      "y": 20,
      "z": -5,
      "name": "Rock_Ice"
    },
    {
      "x": -14,
      "y": 21,
      "z": -5,
      "name": "Rock_Ice"
    },
    {
      "x": -14,
      "y": 22,
      "z": -5,
      "name": "Rock_Ice_Permafrost"
    },
    {
      "x": -14,
      "y": 23,
      "z": -5,
      "name": "Rock_Ice_Permafrost"
    },
    {
      "x": -14,
      "y": 24,
      "z": -5,
      "name": "Rock_Ice_Permafrost"
    },
    {
      "x": -14,
      "y": 25,
      "z": -5,
      "name": "Rock_Ice_Permafrost"
    },
    {
      "x": -14,
      "y": 26,
      "z": -5,
      "name": "Rock_Ice_Permafrost"
    },
    {
      "x": -14,
      "y": 27,
      "z": -5,
      "name": "Rock_Ice"
    },
    {
      "x": -14,
      "y": 28,
      "z": -5,
      "name": "Rock_Ice"
    },
    {
      "x": -14,
      "y": 29,
      "z": -5,
      "name": "Rock_Ice_Permafrost"
    },
    {
      "x": -14,
      "y": 30,
      "z": -5,
      "name": "Soil_Snow"
    },
    {
      "x": -14,
      "y": 12,
      "z": -4,
      "name": "Rock_Ice_Permafrost"
    },
    {
      "x": -14,
      "y": 13,
      "z": -4,
      "name": "Rock_Ice_Permafrost"
    },
    {
      "x": -14,
      "y": 14,
      "z": -4,
      "name": "Rock_Ice_Permafrost"
    },
    {
      "x": -14,
      "y": 15,
      "z": -4,
      "name": "Rock_Ice"
    },
    {
      "x": -14,
      "y": 16,
      "z": -4,
      "name": "Rock_Ice"
    },
    {
      "x": -14,
      "y": 17,
      "z": -4,
      "name": "Rock_Ice"
    },
    {
      "x": -14,
      "y": 18,
      "z": -4,
      "name": "Rock_Ice"
    },
    {
      "x": -14,
      "y": 19,
      "z": -4,
      "name": "Rock_Ice"
    },
    {
      "x": -14,
      "y": 20,
      "z": -4,
      "name": "Rock_Ice"
    },
    {
      "x": -14,
      "y": 21,
      "z": -4,
      "name": "Rock_Ice"
    },
    {
      "x": -14,
      "y": 22,
      "z": -4,
      "name": "Rock_Ice"
    },
    {
      "x": -14,
      "y": 23,
      "z": -4,
      "name": "Rock_Ice_Permafrost"
    },
    {
      "x": -14,
      "y": 24,
      "z": -4,
      "name": "Rock_Ice_Permafrost"
    },
    {
      "x": -14,
      "y": 25,
      "z": -4,
      "name": "Rock_Ice_Permafrost"
    },
    {
      "x": -14,
      "y": 26,
      "z": -4,
      "name": "Rock_Ice"
    },
    {
      "x": -14,
      "y": 27,
      "z": -4,
      "name": "Rock_Ice"
    },
    {
      "x": -14,
      "y": 28,
      "z": -4,
      "name": "Rock_Ice"
    },
    {
      "x": -14,
      "y": 29,
      "z": -4,
      "name": "Rock_Ice"
    },
    {
      "x": -14,
      "y": 30,
      "z": -4,
      "name": "Rock_Ice"
    },
    {
      "x": -14,
      "y": 31,
      "z": -4,
      "name": "Soil_Snow"
    },
    {
      "x": -14,
      "y": 13,
      "z": -3,
      "name": "Rock_Ice"
    },
    {
      "x": -14,
      "y": 14,
      "z": -3,
      "name": "Rock_Ice"
    },
    {
      "x": -14,
      "y": 15,
      "z": -3,
      "name": "Rock_Ice"
    },
    {
      "x": -14,
      "y": 16,
      "z": -3,
      "name": "Rock_Ice"
    },
    {
      "x": -14,
      "y": 17,
      "z": -3,
      "name": "Rock_Ice"
    },
    {
      "x": -14,
      "y": 18,
      "z": -3,
      "name": "Rock_Ice"
    },
    {
      "x": -14,
      "y": 19,
      "z": -3,
      "name": "Rock_Ice"
    },
    {
      "x": -14,
      "y": 20,
      "z": -3,
      "name": "Rock_Ice"
    },
    {
      "x": -14,
      "y": 21,
      "z": -3,
      "name": "Rock_Ice"
    },
    {
      "x": -14,
      "y": 22,
      "z": -3,
      "name": "Rock_Ice"
    },
    {
      "x": -14,
      "y": 23,
      "z": -3,
      "name": "Rock_Ice_Permafrost"
    },
    {
      "x": -14,
      "y": 24,
      "z": -3,
      "name": "Rock_Ice_Permafrost"
    },
    {
      "x": -14,
      "y": 25,
      "z": -3,
      "name": "Rock_Ice_Permafrost"
    },
    {
      "x": -14,
      "y": 26,
      "z": -3,
      "name": "Rock_Ice_Permafrost"
    },
    {
      "x": -14,
      "y": 27,
      "z": -3,
      "name": "Rock_Ice"
    },
    {
      "x": -14,
      "y": 28,
      "z": -3,
      "name": "Rock_Ice"
    },
    {
      "x": -14,
      "y": 29,
      "z": -3,
      "name": "Rock_Ice"
    },
    {
      "x": -14,
      "y": 30,
      "z": -3,
      "name": "Rock_Ice"
    },
    {
      "x": -14,
      "y": 31,
      "z": -3,
      "name": "Soil_Snow"
    },
    {
      "x": -14,
      "y": 14,
      "z": -2,
      "name": "Rock_Ice"
    },
    {
      "x": -14,
      "y": 15,
      "z": -2,
      "name": "Rock_Ice"
    },
    {
      "x": -14,
      "y": 16,
      "z": -2,
      "name": "Rock_Ice"
    },
    {
      "x": -14,
      "y": 17,
      "z": -2,
      "name": "Rock_Ice"
    },
    {
      "x": -14,
      "y": 18,
      "z": -2,
      "name": "Rock_Ice"
    },
    {
      "x": -14,
      "y": 19,
      "z": -2,
      "name": "Rock_Ice"
    },
    {
      "x": -14,
      "y": 20,
      "z": -2,
      "name": "Rock_Ice"
    },
    {
      "x": -14,
      "y": 21,
      "z": -2,
      "name": "Rock_Ice"
    },
    {
      "x": -14,
      "y": 22,
      "z": -2,
      "name": "Rock_Ice"
    },
    {
      "x": -14,
      "y": 23,
      "z": -2,
      "name": "Rock_Ice_Permafrost"
    },
    {
      "x": -14,
      "y": 24,
      "z": -2,
      "name": "Rock_Ice_Permafrost"
    },
    {
      "x": -14,
      "y": 25,
      "z": -2,
      "name": "Rock_Ice_Permafrost"
    },
    {
      "x": -14,
      "y": 26,
      "z": -2,
      "name": "Rock_Ice"
    },
    {
      "x": -14,
      "y": 27,
      "z": -2,
      "name": "Rock_Ice"
    },
    {
      "x": -14,
      "y": 28,
      "z": -2,
      "name": "Rock_Ice"
    },
    {
      "x": -14,
      "y": 29,
      "z": -2,
      "name": "Rock_Ice"
    },
    {
      "x": -14,
      "y": 30,
      "z": -2,
      "name": "Rock_Ice"
    },
    {
      "x": -14,
      "y": 31,
      "z": -2,
      "name": "Rock_Ice"
    },
    {
      "x": -14,
      "y": 32,
      "z": -2,
      "name": "Soil_Snow"
    },
    {
      "x": -14,
      "y": 16,
      "z": -1,
      "name": "Rock_Ice"
    },
    {
      "x": -14,
      "y": 17,
      "z": -1,
      "name": "Rock_Ice"
    },
    {
      "x": -14,
      "y": 18,
      "z": -1,
      "name": "Rock_Ice"
    },
    {
      "x": -14,
      "y": 19,
      "z": -1,
      "name": "Rock_Ice"
    },
    {
      "x": -14,
      "y": 20,
      "z": -1,
      "name": "Rock_Ice"
    },
    {
      "x": -14,
      "y": 21,
      "z": -1,
      "name": "Rock_Ice"
    },
    {
      "x": -14,
      "y": 22,
      "z": -1,
      "name": "Rock_Ice"
    },
    {
      "x": -14,
      "y": 23,
      "z": -1,
      "name": "Rock_Ice"
    },
    {
      "x": -14,
      "y": 24,
      "z": -1,
      "name": "Rock_Ice_Permafrost"
    },
    {
      "x": -14,
      "y": 25,
      "z": -1,
      "name": "Rock_Ice_Permafrost"
    },
    {
      "x": -14,
      "y": 26,
      "z": -1,
      "name": "Rock_Ice"
    },
    {
      "x": -14,
      "y": 27,
      "z": -1,
      "name": "Rock_Ice"
    },
    {
      "x": -14,
      "y": 28,
      "z": -1,
      "name": "Rock_Ice"
    },
    {
      "x": -14,
      "y": 29,
      "z": -1,
      "name": "Rock_Ice"
    },
    {
      "x": -14,
      "y": 30,
      "z": -1,
      "name": "Rock_Ice"
    },
    {
      "x": -14,
      "y": 31,
      "z": -1,
      "name": "Soil_Snow"
    },
    {
      "x": -14,
      "y": 17,
      "z": 0,
      "name": "Rock_Ice"
    },
    {
      "x": -14,
      "y": 18,
      "z": 0,
      "name": "Rock_Ice"
    },
    {
      "x": -14,
      "y": 19,
      "z": 0,
      "name": "Rock_Ice"
    },
    {
      "x": -14,
      "y": 20,
      "z": 0,
      "name": "Rock_Ice"
    },
    {
      "x": -14,
      "y": 21,
      "z": 0,
      "name": "Rock_Ice"
    },
    {
      "x": -14,
      "y": 22,
      "z": 0,
      "name": "Rock_Ice"
    },
    {
      "x": -14,
      "y": 23,
      "z": 0,
      "name": "Rock_Ice"
    },
    {
      "x": -14,
      "y": 24,
      "z": 0,
      "name": "Rock_Ice_Permafrost"
    },
    {
      "x": -14,
      "y": 25,
      "z": 0,
      "name": "Rock_Ice_Permafrost"
    },
    {
      "x": -14,
      "y": 26,
      "z": 0,
      "name": "Rock_Ice_Permafrost"
    },
    {
      "x": -14,
      "y": 27,
      "z": 0,
      "name": "Rock_Ice"
    },
    {
      "x": -14,
      "y": 28,
      "z": 0,
      "name": "Rock_Ice"
    },
    {
      "x": -14,
      "y": 29,
      "z": 0,
      "name": "Rock_Ice"
    },
    {
      "x": -14,
      "y": 30,
      "z": 0,
      "name": "Rock_Ice"
    },
    {
      "x": -14,
      "y": 31,
      "z": 0,
      "name": "Soil_Snow"
    },
    {
      "x": -14,
      "y": 19,
      "z": 1,
      "name": "Rock_Ice"
    },
    {
      "x": -14,
      "y": 20,
      "z": 1,
      "name": "Rock_Ice"
    },
    {
      "x": -14,
      "y": 21,
      "z": 1,
      "name": "Rock_Ice"
    },
    {
      "x": -14,
      "y": 22,
      "z": 1,
      "name": "Rock_Ice"
    },
    {
      "x": -14,
      "y": 23,
      "z": 1,
      "name": "Rock_Ice"
    },
    {
      "x": -14,
      "y": 24,
      "z": 1,
      "name": "Rock_Ice_Permafrost"
    },
    {
      "x": -14,
      "y": 25,
      "z": 1,
      "name": "Rock_Ice_Permafrost"
    },
    {
      "x": -14,
      "y": 26,
      "z": 1,
      "name": "Rock_Ice"
    },
    {
      "x": -14,
      "y": 27,
      "z": 1,
      "name": "Rock_Ice"
    },
    {
      "x": -14,
      "y": 28,
      "z": 1,
      "name": "Rock_Ice"
    },
    {
      "x": -14,
      "y": 29,
      "z": 1,
      "name": "Rock_Ice"
    },
    {
      "x": -14,
      "y": 30,
      "z": 1,
      "name": "Soil_Snow"
    },
    {
      "x": -14,
      "y": 22,
      "z": 2,
      "name": "Rock_Ice"
    },
    {
      "x": -14,
      "y": 23,
      "z": 2,
      "name": "Rock_Ice"
    },
    {
      "x": -14,
      "y": 24,
      "z": 2,
      "name": "Rock_Ice"
    },
    {
      "x": -14,
      "y": 25,
      "z": 2,
      "name": "Rock_Ice_Permafrost"
    },
    {
      "x": -14,
      "y": 26,
      "z": 2,
      "name": "Rock_Ice_Permafrost"
    },
    {
      "x": -14,
      "y": 27,
      "z": 2,
      "name": "Rock_Ice"
    },
    {
      "x": -14,
      "y": 28,
      "z": 2,
      "name": "Rock_Ice"
    },
    {
      "x": -14,
      "y": 29,
      "z": 2,
      "name": "Rock_Ice"
    },
    {
      "x": -14,
      "y": 30,
      "z": 2,
      "name": "Soil_Snow"
    },
    {
      "x": -14,
      "y": 24,
      "z": 3,
      "name": "Rock_Ice"
    },
    {
      "x": -14,
      "y": 25,
      "z": 3,
      "name": "Rock_Ice_Permafrost"
    },
    {
      "x": -14,
      "y": 26,
      "z": 3,
      "name": "Rock_Ice_Permafrost"
    },
    {
      "x": -14,
      "y": 27,
      "z": 3,
      "name": "Rock_Ice"
    },
    {
      "x": -14,
      "y": 28,
      "z": 3,
      "name": "Rock_Ice"
    },
    {
      "x": -14,
      "y": 29,
      "z": 3,
      "name": "Soil_Snow"
    },
    {
      "x": -14,
      "y": 26,
      "z": 4,
      "name": "Rock_Ice_Permafrost"
    },
    {
      "x": -14,
      "y": 27,
      "z": 4,
      "name": "Rock_Ice"
    },
    {
      "x": -14,
      "y": 28,
      "z": 4,
      "name": "Rock_Ice"
    },
    {
      "x": -14,
      "y": 29,
      "z": 4,
      "name": "Soil_Snow"
    },
    {
      "x": -14,
      "y": 27,
      "z": 5,
      "name": "Rock_Ice"
    },
    {
      "x": -14,
      "y": 28,
      "z": 5,
      "name": "Soil_Snow"
    },
    {
      "x": -13,
      "y": 20,
      "z": -14,
      "name": "Rock_Ice"
    },
    {
      "x": -13,
      "y": 21,
      "z": -14,
      "name": "Rock_Ice_Permafrost"
    },
    {
      "x": -13,
      "y": 22,
      "z": -14,
      "name": "Soil_Snow"
    },
    {
      "x": -13,
      "y": 17,
      "z": -13,
      "name": "Rock_Ice"
    },
    {
      "x": -13,
      "y": 18,
      "z": -13,
      "name": "Rock_Ice"
    },
    {
      "x": -13,
      "y": 19,
      "z": -13,
      "name": "Rock_Ice"
    },
    {
      "x": -13,
      "y": 20,
      "z": -13,
      "name": "Rock_Ice"
    },
    {
      "x": -13,
      "y": 21,
      "z": -13,
      "name": "Rock_Ice"
    },
    {
      "x": -13,
      "y": 22,
      "z": -13,
      "name": "Rock_Ice_Permafrost"
    },
    {
      "x": -13,
      "y": 23,
      "z": -13,
      "name": "Rock_Ice_Permafrost"
    },
    {
      "x": -13,
      "y": 24,
      "z": -13,
      "name": "Soil_Snow"
    },
    {
      "x": -13,
      "y": 16,
      "z": -12,
      "name": "Rock_Ice"
    },
    {
      "x": -13,
      "y": 17,
      "z": -12,
      "name": "Rock_Ice"
    },
    {
      "x": -13,
      "y": 18,
      "z": -12,
      "name": "Rock_Ice"
    },
    {
      "x": -13,
      "y": 19,
      "z": -12,
      "name": "Rock_Ice"
    },
    {
      "x": -13,
      "y": 20,
      "z": -12,
      "name": "Rock_Ice"
    },
    {
      "x": -13,
      "y": 21,
      "z": -12,
      "name": "Rock_Ice"
    },
    {
      "x": -13,
      "y": 22,
      "z": -12,
      "name": "Rock_Ice"
    },
    {
      "x": -13,
      "y": 23,
      "z": -12,
      "name": "Rock_Ice_Permafrost"
    },
    {
      "x": -13,
      "y": 24,
      "z": -12,
      "name": "Rock_Ice_Permafrost"
    },
    {
      "x": -13,
      "y": 25,
      "z": -12,
      "name": "Soil_Snow"
    },
    {
      "x": -13,
      "y": 15,
      "z": -11,
      "name": "Rock_Ice"
    },
    {
      "x": -13,
      "y": 16,
      "z": -11,
      "name": "Rock_Ice"
    },
    {
      "x": -13,
      "y": 17,
      "z": -11,
      "name": "Rock_Ice"
    },
    {
      "x": -13,
      "y": 18,
      "z": -11,
      "name": "Rock_Ice"
    },
    {
      "x": -13,
      "y": 19,
      "z": -11,
      "name": "Rock_Ice"
    },
    {
      "x": -13,
      "y": 20,
      "z": -11,
      "name": "Rock_Ice"
    },
    {
      "x": -13,
      "y": 21,
      "z": -11,
      "name": "Rock_Ice_Permafrost"
    },
    {
      "x": -13,
      "y": 22,
      "z": -11,
      "name": "Rock_Ice_Permafrost"
    },
    {
      "x": -13,
      "y": 23,
      "z": -11,
      "name": "Rock_Ice_Permafrost"
    },
    {
      "x": -13,
      "y": 24,
      "z": -11,
      "name": "Rock_Ice_Permafrost"
    },
    {
      "x": -13,
      "y": 25,
      "z": -11,
      "name": "Rock_Ice"
    },
    {
      "x": -13,
      "y": 26,
      "z": -11,
      "name": "Soil_Snow"
    },
    {
      "x": -13,
      "y": 14,
      "z": -10,
      "name": "Rock_Ice"
    },
    {
      "x": -13,
      "y": 15,
      "z": -10,
      "name": "Rock_Ice"
    },
    {
      "x": -13,
      "y": 16,
      "z": -10,
      "name": "Rock_Ice"
    },
    {
      "x": -13,
      "y": 17,
      "z": -10,
      "name": "Rock_Ice"
    },
    {
      "x": -13,
      "y": 18,
      "z": -10,
      "name": "Rock_Ice"
    },
    {
      "x": -13,
      "y": 19,
      "z": -10,
      "name": "Rock_Ice"
    },
    {
      "x": -13,
      "y": 20,
      "z": -10,
      "name": "Rock_Ice_Permafrost"
    },
    {
      "x": -13,
      "y": 21,
      "z": -10,
      "name": "Rock_Ice_Permafrost"
    },
    {
      "x": -13,
      "y": 22,
      "z": -10,
      "name": "Rock_Ice_Permafrost"
    },
    {
      "x": -13,
      "y": 23,
      "z": -10,
      "name": "Rock_Ice_Permafrost"
    },
    {
      "x": -13,
      "y": 24,
      "z": -10,
      "name": "Rock_Ice_Permafrost"
    },
    {
      "x": -13,
      "y": 25,
      "z": -10,
      "name": "Rock_Ice_Permafrost"
    },
    {
      "x": -13,
      "y": 26,
      "z": -10,
      "name": "Rock_Ice"
    },
    {
      "x": -13,
      "y": 27,
      "z": -10,
      "name": "Soil_Snow"
    },
    {
      "x": -13,
      "y": 13,
      "z": -9,
      "name": "Rock_Ice"
    },
    {
      "x": -13,
      "y": 14,
      "z": -9,
      "name": "Rock_Ice"
    },
    {
      "x": -13,
      "y": 15,
      "z": -9,
      "name": "Rock_Ice"
    },
    {
      "x": -13,
      "y": 16,
      "z": -9,
      "name": "Rock_Ice"
    },
    {
      "x": -13,
      "y": 17,
      "z": -9,
      "name": "Rock_Ice"
    },
    {
      "x": -13,
      "y": 18,
      "z": -9,
      "name": "Rock_Ice"
    },
    {
      "x": -13,
      "y": 19,
      "z": -9,
      "name": "Rock_Ice_Permafrost"
    },
    {
      "x": -13,
      "y": 20,
      "z": -9,
      "name": "Rock_Ice_Permafrost"
    },
    {
      "x": -13,
      "y": 21,
      "z": -9,
      "name": "Rock_Ice_Permafrost"
    },
    {
      "x": -13,
      "y": 22,
      "z": -9,
      "name": "Rock_Ice_Permafrost"
    },
    {
      "x": -13,
      "y": 23,
      "z": -9,
      "name": "Rock_Ice_Permafrost"
    },
    {
      "x": -13,
      "y": 24,
      "z": -9,
      "name": "Rock_Ice_Permafrost"
    },
    {
      "x": -13,
      "y": 25,
      "z": -9,
      "name": "Rock_Ice_Permafrost"
    },
    {
      "x": -13,
      "y": 26,
      "z": -9,
      "name": "Rock_Ice_Permafrost"
    },
    {
      "x": -13,
      "y": 27,
      "z": -9,
      "name": "Rock_Ice"
    },
    {
      "x": -13,
      "y": 28,
      "z": -9,
      "name": "Soil_Snow"
    },
    {
      "x": -13,
      "y": 13,
      "z": -8,
      "name": "Rock_Ice"
    },
    {
      "x": -13,
      "y": 14,
      "z": -8,
      "name": "Rock_Ice"
    },
    {
      "x": -13,
      "y": 15,
      "z": -8,
      "name": "Rock_Ice"
    },
    {
      "x": -13,
      "y": 16,
      "z": -8,
      "name": "Rock_Ice"
    },
    {
      "x": -13,
      "y": 17,
      "z": -8,
      "name": "Rock_Ice_Permafrost"
    },
    {
      "x": -13,
      "y": 18,
      "z": -8,
      "name": "Rock_Ice_Permafrost"
    },
    {
      "x": -13,
      "y": 19,
      "z": -8,
      "name": "Rock_Ice_Permafrost"
    },
    {
      "x": -13,
      "y": 20,
      "z": -8,
      "name": "Rock_Ice_Permafrost"
    },
    {
      "x": -13,
      "y": 21,
      "z": -8,
      "name": "Rock_Ice_Permafrost"
    },
    {
      "x": -13,
      "y": 22,
      "z": -8,
      "name": "Rock_Ice_Permafrost"
    },
    {
      "x": -13,
      "y": 23,
      "z": -8,
      "name": "Rock_Ice_Permafrost"
    },
    {
      "x": -13,
      "y": 24,
      "z": -8,
      "name": "Rock_Ice_Permafrost"
    },
    {
      "x": -13,
      "y": 25,
      "z": -8,
      "name": "Rock_Ice_Permafrost"
    },
    {
      "x": -13,
      "y": 26,
      "z": -8,
      "name": "Rock_Ice_Permafrost"
    },
    {
      "x": -13,
      "y": 27,
      "z": -8,
      "name": "Rock_Ice_Permafrost"
    },
    {
      "x": -13,
      "y": 28,
      "z": -8,
      "name": "Rock_Ice_Permafrost"
    },
    {
      "x": -13,
      "y": 29,
      "z": -8,
      "name": "Soil_Snow"
    },
    {
      "x": -13,
      "y": 12,
      "z": -7,
      "name": "Rock_Ice"
    },
    {
      "x": -13,
      "y": 13,
      "z": -7,
      "name": "Rock_Ice"
    },
    {
      "x": -13,
      "y": 14,
      "z": -7,
      "name": "Rock_Ice"
    },
    {
      "x": -13,
      "y": 15,
      "z": -7,
      "name": "Rock_Ice"
    },
    {
      "x": -13,
      "y": 16,
      "z": -7,
      "name": "Rock_Ice_Permafrost"
    },
    {
      "x": -13,
      "y": 17,
      "z": -7,
      "name": "Rock_Ice_Permafrost"
    },
    {
      "x": -13,
      "y": 18,
      "z": -7,
      "name": "Rock_Ice_Permafrost"
    },
    {
      "x": -13,
      "y": 19,
      "z": -7,
      "name": "Rock_Ice_Permafrost"
    },
    {
      "x": -13,
      "y": 20,
      "z": -7,
      "name": "Rock_Ice_Permafrost"
    },
    {
      "x": -13,
      "y": 21,
      "z": -7,
      "name": "Rock_Ice_Permafrost"
    },
    {
      "x": -13,
      "y": 22,
      "z": -7,
      "name": "Rock_Ice_Permafrost"
    },
    {
      "x": -13,
      "y": 23,
      "z": -7,
      "name": "Rock_Ice_Permafrost"
    },
    {
      "x": -13,
      "y": 24,
      "z": -7,
      "name": "Rock_Ice_Permafrost"
    },
    {
      "x": -13,
      "y": 25,
      "z": -7,
      "name": "Rock_Ice_Permafrost"
    },
    {
      "x": -13,
      "y": 26,
      "z": -7,
      "name": "Rock_Ice_Permafrost"
    },
    {
      "x": -13,
      "y": 27,
      "z": -7,
      "name": "Rock_Ice_Permafrost"
    },
    {
      "x": -13,
      "y": 28,
      "z": -7,
      "name": "Rock_Ice_Permafrost"
    },
    {
      "x": -13,
      "y": 29,
      "z": -7,
      "name": "Soil_Snow"
    },
    {
      "x": -13,
      "y": 11,
      "z": -6,
      "name": "Rock_Ice"
    },
    {
      "x": -13,
      "y": 12,
      "z": -6,
      "name": "Rock_Ice"
    },
    {
      "x": -13,
      "y": 13,
      "z": -6,
      "name": "Rock_Ice"
    },
    {
      "x": -13,
      "y": 14,
      "z": -6,
      "name": "Rock_Ice"
    },
    {
      "x": -13,
      "y": 15,
      "z": -6,
      "name": "Rock_Ice_Permafrost"
    },
    {
      "x": -13,
      "y": 16,
      "z": -6,
      "name": "Rock_Ice_Permafrost"
    },
    {
      "x": -13,
      "y": 17,
      "z": -6,
      "name": "Rock_Ice_Permafrost"
    },
    {
      "x": -13,
      "y": 18,
      "z": -6,
      "name": "Rock_Ice_Permafrost"
    },
    {
      "x": -13,
      "y": 19,
      "z": -6,
      "name": "Rock_Ice_Permafrost"
    },
    {
      "x": -13,
      "y": 20,
      "z": -6,
      "name": "Rock_Ice_Permafrost"
    },
    {
      "x": -13,
      "y": 21,
      "z": -6,
      "name": "Rock_Ice"
    },
    {
      "x": -13,
      "y": 22,
      "z": -6,
      "name": "Rock_Ice_Permafrost"
    },
    {
      "x": -13,
      "y": 23,
      "z": -6,
      "name": "Rock_Ice_Permafrost"
    },
    {
      "x": -13,
      "y": 24,
      "z": -6,
      "name": "Rock_Ice_Permafrost"
    },
    {
      "x": -13,
      "y": 25,
      "z": -6,
      "name": "Rock_Ice_Permafrost"
    },
    {
      "x": -13,
      "y": 26,
      "z": -6,
      "name": "Rock_Ice"
    },
    {
      "x": -13,
      "y": 27,
      "z": -6,
      "name": "Rock_Ice"
    },
    {
      "x": -13,
      "y": 28,
      "z": -6,
      "name": "Rock_Ice"
    },
    {
      "x": -13,
      "y": 29,
      "z": -6,
      "name": "Rock_Ice_Permafrost"
    },
    {
      "x": -13,
      "y": 30,
      "z": -6,
      "name": "Rock_Ice_Permafrost"
    },
    {
      "x": -13,
      "y": 31,
      "z": -6,
      "name": "Soil_Snow"
    },
    {
      "x": -13,
      "y": 11,
      "z": -5,
      "name": "Rock_Ice"
    },
    {
      "x": -13,
      "y": 12,
      "z": -5,
      "name": "Rock_Ice"
    },
    {
      "x": -13,
      "y": 13,
      "z": -5,
      "name": "Rock_Ice"
    },
    {
      "x": -13,
      "y": 14,
      "z": -5,
      "name": "Rock_Ice_Permafrost"
    },
    {
      "x": -13,
      "y": 15,
      "z": -5,
      "name": "Rock_Ice_Permafrost"
    },
    {
      "x": -13,
      "y": 16,
      "z": -5,
      "name": "Rock_Ice_Permafrost"
    },
    {
      "x": -13,
      "y": 17,
      "z": -5,
      "name": "Rock_Ice"
    },
    {
      "x": -13,
      "y": 18,
      "z": -5,
      "name": "Rock_Ice"
    },
    {
      "x": -13,
      "y": 19,
      "z": -5,
      "name": "Rock_Ice"
    },
    {
      "x": -13,
      "y": 20,
      "z": -5,
      "name": "Rock_Ice"
    },
    {
      "x": -13,
      "y": 21,
      "z": -5,
      "name": "Rock_Ice"
    },
    {
      "x": -13,
      "y": 22,
      "z": -5,
      "name": "Rock_Ice_Permafrost"
    },
    {
      "x": -13,
      "y": 23,
      "z": -5,
      "name": "Rock_Ice_Permafrost"
    },
    {
      "x": -13,
      "y": 24,
      "z": -5,
      "name": "Rock_Ice_Permafrost"
    },
    {
      "x": -13,
      "y": 25,
      "z": -5,
      "name": "Rock_Ice_Permafrost"
    },
    {
      "x": -13,
      "y": 26,
      "z": -5,
      "name": "Rock_Ice_Permafrost"
    },
    {
      "x": -13,
      "y": 27,
      "z": -5,
      "name": "Rock_Ice"
    },
    {
      "x": -13,
      "y": 28,
      "z": -5,
      "name": "Rock_Ice"
    },
    {
      "x": -13,
      "y": 29,
      "z": -5,
      "name": "Rock_Ice_Permafrost"
    },
    {
      "x": -13,
      "y": 30,
      "z": -5,
      "name": "Rock_Ice_Permafrost"
    },
    {
      "x": -13,
      "y": 31,
      "z": -5,
      "name": "Rock_Ice_Permafrost"
    },
    {
      "x": -13,
      "y": 32,
      "z": -5,
      "name": "Soil_Snow"
    },
    {
      "x": -13,
      "y": 11,
