{
  "version": 8,
  "blockIdVersion": 11,
  "anchorX": -1,
  "anchorY": 14,
  "anchorZ": 2,
  "blocks": [
    {
      "x": -21,
      "y": 20,
      "z": -8,
      "name": "Rock_Ice_Permafrost"
    },
    {
      "x": -21,
      "y": 21,
      "z": -8,
      "name": "Rock_Ice"
    },
    {
      "x": -21,
      "y": 22,
      "z": -8,
      "name": "Rock_Ice"
    },
    {
      "x": -21,
      "y": 23,
      "z": -8,
      "name": "Rock_Ice"
    },
    {
      "x": -21,
      "y": 24,
      "z": -8,
      "name": "Soil_Snow"
    },
    {
      "x": -21,
      "y": 22,
      "z": -7,
      "name": "Rock_Ice"
    },
    {
      "x": -21,
      "y": 23,
      "z": -7,
      "name": "Rock_Ice"
    },
    {
      "x": -21,
      "y": 24,
      "z": -7,
      "name": "Rock_Ice"
    },
    {
      "x": -21,
      "y": 25,
      "z": -7,
      "name": "Rock_Ice"
    },
    {
      "x": -21,
      "y": 26,
      "z": -7,
      "name": "Rock_Ice"
    },
    {
      "x": -21,
      "y": 27,
      "z": -7,
      "name": "Soil_Snow"
    },
    {
      "x": -21,
      "y": 23,
      "z": -6,
      "name": "Rock_Ice"
    },
    {
      "x": -21,
      "y": 24,
      "z": -6,
      "name": "Rock_Ice"
    },
    {
      "x": -21,
      "y": 25,
      "z": -6,
      "name": "Rock_Ice"
    },
    {
      "x": -21,
      "y": 26,
      "z": -6,
      "name": "Rock_Ice"
    },
    {
      "x": -21,
      "y": 27,
      "z": -6,
      "name": "Rock_Ice"
    },
    {
      "x": -21,
      "y": 28,
      "z": -6,
      "name": "Rock_Ice"
    },
    {
      "x": -21,
      "y": 29,
      "z": -6,
      "name": "Rock_Ice"
    },
    {
      "x": -21,
      "y": 30,
      "z": -6,
      "name": "Soil_Snow"
    },
    {
      "x": -21,
      "y": 24,
      "z": -5,
      "name": "Rock_Ice"
    },
    {
      "x": -21,
      "y": 25,
      "z": -5,
      "name": "Rock_Ice"
    },
    {
      "x": -21,
      "y": 26,
      "z": -5,
      "name": "Rock_Ice"
    },
    {
      "x": -21,
      "y": 27,
      "z": -5,
      "name": "Rock_Ice"
    },
    {
      "x": -21,
      "y": 28,
      "z": -5,
      "name": "Rock_Ice"
    },
    {
      "x": -21,
      "y": 29,
      "z": -5,
      "name": "Rock_Ice"
    },
    {
      "x": -21,
      "y": 30,
      "z": -5,
      "name": "Rock_Ice"
    },
    {
      "x": -21,
      "y": 31,
      "z": -5,
      "name": "Rock_Ice"
    },
    {
      "x": -21,
      "y": 32,
      "z": -5,
      "name": "Rock_Ice"
    },
    {
      "x": -21,
      "y": 33,
      "z": -5,
      "name": "Rock_Ice"
    },
    {
      "x": -21,
      "y": 25,
      "z": -4,
      "name": "Rock_Ice"
    },
    {
      "x": -21,
      "y": 26,
      "z": -4,
      "name": "Rock_Ice"
    },
    {
      "x": -21,
      "y": 27,
      "z": -4,
      "name": "Rock_Ice"
    },
    {
      "x": -21,
      "y": 28,
      "z": -4,
      "name": "Rock_Ice"
    },
    {
      "x": -21,
      "y": 29,
      "z": -4,
      "name": "Rock_Ice"
    },
    {
      "x": -21,
      "y": 30,
      "z": -4,
      "name": "Rock_Ice"
    },
    {
      "x": -21,
      "y": 31,
      "z": -4,
      "name": "Rock_Ice"
    },
    {
      "x": -21,
      "y": 32,
      "z": -4,
      "name": "Rock_Ice"
    },
    {
      "x": -21,
      "y": 33,
      "z": -4,
      "name": "Rock_Ice"
    },
    {
      "x": -21,
      "y": 34,
      "z": -4,
      "name": "Soil_Snow"
    },
    {
      "x": -21,
      "y": 24,
      "z": -3,
      "name": "Rock_Ice"
    },
    {
      "x": -21,
      "y": 25,
      "z": -3,
      "name": "Rock_Ice"
    },
    {
      "x": -21,
      "y": 26,
      "z": -3,
      "name": "Rock_Ice"
    },
    {
      "x": -21,
      "y": 27,
      "z": -3,
      "name": "Rock_Ice"
    },
    {
      "x": -21,
      "y": 28,
      "z": -3,
      "name": "Rock_Ice"
    },
    {
      "x": -21,
      "y": 29,
      "z": -3,
      "name": "Rock_Ice"
    },
    {
      "x": -21,
      "y": 30,
      "z": -3,
      "name": "Rock_Ice"
    },
    {
      "x": -21,
      "y": 31,
      "z": -3,
      "name": "Rock_Ice"
    },
    {
      "x": -21,
      "y": 32,
      "z": -3,
      "name": "Rock_Ice"
    },
    {
      "x": -21,
      "y": 33,
      "z": -3,
      "name": "Rock_Ice"
    },
    {
      "x": -21,
      "y": 34,
      "z": -3,
      "name": "Soil_Snow"
    },
    {
      "x": -21,
      "y": 24,
      "z": -2,
      "name": "Rock_Ice"
    },
    {
      "x": -21,
      "y": 25,
      "z": -2,
      "name": "Rock_Ice"
    },
    {
      "x": -21,
      "y": 26,
      "z": -2,
      "name": "Rock_Ice"
    },
    {
      "x": -21,
      "y": 27,
      "z": -2,
      "name": "Rock_Ice"
    },
    {
      "x": -21,
      "y": 28,
      "z": -2,
      "name": "Rock_Ice"
    },
    {
      "x": -21,
      "y": 29,
      "z": -2,
      "name": "Rock_Ice"
    },
    {
      "x": -21,
      "y": 30,
      "z": -2,
      "name": "Rock_Ice"
    },
    {
      "x": -21,
      "y": 31,
      "z": -2,
      "name": "Rock_Ice"
    },
    {
      "x": -21,
      "y": 32,
      "z": -2,
      "name": "Rock_Ice"
    },
    {
      "x": -21,
      "y": 33,
      "z": -2,
      "name": "Rock_Ice"
    },
    {
      "x": -21,
      "y": 34,
      "z": -2,
      "name": "Soil_Snow"
    },
    {
      "x": -21,
      "y": 24,
      "z": -1,
      "name": "Rock_Ice"
    },
    {
      "x": -21,
      "y": 25,
      "z": -1,
      "name": "Rock_Ice"
    },
    {
      "x": -21,
      "y": 26,
      "z": -1,
      "name": "Rock_Ice"
    },
    {
      "x": -21,
      "y": 27,
      "z": -1,
      "name": "Rock_Ice"
    },
    {
      "x": -21,
      "y": 28,
      "z": -1,
      "name": "Rock_Ice"
    },
    {
      "x": -21,
      "y": 29,
      "z": -1,
      "name": "Rock_Ice"
    },
    {
      "x": -21,
      "y": 30,
      "z": -1,
      "name": "Rock_Ice"
    },
    {
      "x": -21,
      "y": 31,
      "z": -1,
      "name": "Rock_Ice"
    },
    {
      "x": -21,
      "y": 32,
      "z": -1,
      "name": "Rock_Ice"
    },
    {
      "x": -21,
      "y": 33,
      "z": -1,
      "name": "Rock_Ice"
    },
    {
      "x": -21,
      "y": 34,
      "z": -1,
      "name": "Soil_Snow"
    },
    {
      "x": -21,
      "y": 25,
      "z": 0,
      "name": "Rock_Ice"
    },
    {
      "x": -21,
      "y": 26,
      "z": 0,
      "name": "Rock_Ice"
    },
    {
      "x": -21,
      "y": 27,
      "z": 0,
      "name": "Rock_Ice"
    },
    {
      "x": -21,
      "y": 28,
      "z": 0,
      "name": "Rock_Ice"
    },
    {
      "x": -21,
      "y": 29,
      "z": 0,
      "name": "Rock_Ice"
    },
    {
      "x": -21,
      "y": 30,
      "z": 0,
      "name": "Rock_Ice_Permafrost"
    },
    {
      "x": -21,
      "y": 31,
      "z": 0,
      "name": "Rock_Ice_Permafrost"
    },
    {
      "x": -21,
      "y": 32,
      "z": 0,
      "name": "Rock_Ice_Permafrost"
    },
    {
      "x": -21,
      "y": 33,
      "z": 0,
      "name": "Rock_Ice_Permafrost"
    },
    {
      "x": -21,
      "y": 34,
      "z": 0,
      "name": "Soil_Snow"
    },
    {
      "x": -21,
      "y": 25,
      "z": 1,
      "name": "Rock_Ice_Permafrost"
    },
    {
      "x": -21,
      "y": 26,
      "z": 1,
      "name": "Rock_Ice_Permafrost"
    },
    {
      "x": -21,
      "y": 27,
      "z": 1,
      "name": "Rock_Ice_Permafrost"
    },
    {
      "x": -21,
      "y": 28,
      "z": 1,
      "name": "Rock_Ice_Permafrost"
    },
    {
      "x": -21,
      "y": 29,
      "z": 1,
      "name": "Rock_Ice_Permafrost"
    },
    {
      "x": -21,
      "y": 30,
      "z": 1,
      "name": "Rock_Ice_Permafrost"
    },
    {
      "x": -21,
      "y": 31,
      "z": 1,
      "name": "Rock_Ice_Permafrost"
    },
    {
      "x": -21,
      "y": 32,
      "z": 1,
      "name": "Rock_Ice_Permafrost"
    },
    {
      "x": -21,
      "y": 33,
      "z": 1,
      "name": "Rock_Ice_Permafrost"
    },
    {
      "x": -21,
      "y": 34,
      "z": 1,
      "name": "Soil_Snow"
    },
    {
      "x": -21,
      "y": 26,
      "z": 2,
      "name": "Rock_Ice_Permafrost"
    },
    {
      "x": -21,
      "y": 27,
      "z": 2,
      "name": "Rock_Ice_Permafrost"
    },
    {
      "x": -21,
      "y": 28,
      "z": 2,
      "name": "Rock_Ice_Permafrost"
    },
    {
      "x": -21,
      "y": 29,
      "z": 2,
      "name": "Rock_Ice"
    },
    {
      "x": -21,
      "y": 30,
      "z": 2,
      "name": "Rock_Ice"
    },
    {
      "x": -21,
      "y": 31,
      "z": 2,
      "name": "Soil_Snow"
    },
    {
      "x": -21,
      "y": 27,
      "z": 5,
      "name": "Rock_Ice"
    },
    {
      "x": -21,
      "y": 28,
      "z": 5,
      "name": "Rock_Ice"
    },
    {
      "x": -21,
      "y": 29,
      "z": 5,
      "name": "Rock_Ice"
    },
    {
      "x": -21,
      "y": 30,
      "z": 5,
      "name": "Rock_Ice"
    },
    {
      "x": -21,
      "y": 31,
      "z": 5,
      "name": "Soil_Snow"
    },
    {
      "x": -21,
      "y": 26,
      "z": 6,
      "name": "Rock_Ice_Permafrost"
    },
    {
      "x": -21,
      "y": 27,
      "z": 6,
      "name": "Rock_Ice"
    },
    {
      "x": -21,
      "y": 28,
      "z": 6,
      "name": "Rock_Ice"
    },
    {
      "x": -21,
      "y": 29,
      "z": 6,
      "name": "Rock_Ice"
    },
    {
      "x": -21,
      "y": 30,
      "z": 6,
      "name": "Rock_Ice"
    },
    {
      "x": -21,
      "y": 31,
      "z": 6,
      "name": "Soil_Snow"
    },
    {
      "x": -21,
      "y": 25,
      "z": 7,
      "name": "Rock_Ice"
    },
    {
      "x": -21,
      "y": 26,
      "z": 7,
      "name": "Rock_Ice_Permafrost"
    },
    {
      "x": -21,
      "y": 27,
      "z": 7,
      "name": "Rock_Ice"
    },
    {
      "x": -21,
      "y": 28,
      "z": 7,
      "name": "Rock_Ice"
    },
    {
      "x": -21,
      "y": 29,
      "z": 7,
      "name": "Rock_Ice"
    },
    {
      "x": -21,
      "y": 30,
      "z": 7,
      "name": "Soil_Snow"
    },
    {
      "x": -21,
      "y": 24,
      "z": 8,
      "name": "Rock_Ice"
    },
    {
      "x": -21,
      "y": 25,
      "z": 8,
      "name": "Rock_Ice_Permafrost"
    },
    {
      "x": -21,
      "y": 26,
      "z": 8,
      "name": "Rock_Ice_Permafrost"
    },
    {
      "x": -21,
      "y": 27,
      "z": 8,
      "name": "Rock_Ice"
    },
    {
      "x": -21,
      "y": 28,
      "z": 8,
      "name": "Rock_Ice"
    },
    {
      "x": -21,
      "y": 29,
      "z": 8,
      "name": "Soil_Snow"
    },
    {
      "x": -21,
      "y": 24,
      "z": 9,
      "name": "Rock_Ice"
    },
    {
      "x": -21,
      "y": 25,
      "z": 9,
      "name": "Rock_Ice"
    },
    {
      "x": -21,
      "y": 26,
      "z": 9,
      "name": "Rock_Ice_Permafrost"
    },
    {
      "x": -21,
      "y": 27,
      "z": 9,
      "name": "Soil_Snow"
    },
    {
      "x": -20,
      "y": 20,
      "z": -9,
      "name": "Rock_Ice"
    },
    {
      "x": -20,
      "y": 21,
      "z": -9,
      "name": "Rock_Ice"
    },
    {
      "x": -20,
      "y": 22,
      "z": -9,
      "name": "Rock_Ice"
    },
    {
      "x": -20,
      "y": 23,
      "z": -9,
      "name": "Rock_Ice"
    },
    {
      "x": -20,
      "y": 24,
      "z": -9,
      "name": "Soil_Snow"
    },
    {
      "x": -20,
      "y": 19,
      "z": -8,
      "name": "Rock_Ice_Permafrost"
    },
    {
      "x": -20,
      "y": 20,
      "z": -8,
      "name": "Rock_Ice"
    },
    {
      "x": -20,
      "y": 21,
      "z": -8,
      "name": "Rock_Ice"
    },
    {
      "x": -20,
      "y": 22,
      "z": -8,
      "name": "Rock_Ice"
    },
    {
      "x": -20,
      "y": 23,
      "z": -8,
      "name": "Rock_Ice"
    },
    {
      "x": -20,
      "y": 24,
      "z": -8,
      "name": "Rock_Ice"
    },
    {
      "x": -20,
      "y": 25,
      "z": -8,
      "name": "Rock_Ice"
    },
    {
      "x": -20,
      "y": 26,
      "z": -8,
      "name": "Rock_Ice"
    },
    {
      "x": -20,
      "y": 27,
      "z": -8,
      "name": "Rock_Ice"
    },
    {
      "x": -20,
      "y": 28,
      "z": -8,
      "name": "Soil_Snow"
    },
    {
      "x": -20,
      "y": 20,
      "z": -7,
      "name": "Rock_Ice"
    },
    {
      "x": -20,
      "y": 21,
      "z": -7,
      "name": "Rock_Ice"
    },
    {
      "x": -20,
      "y": 22,
      "z": -7,
      "name": "Rock_Ice"
    },
    {
      "x": -20,
      "y": 23,
      "z": -7,
      "name": "Rock_Ice"
    },
    {
      "x": -20,
      "y": 24,
      "z": -7,
      "name": "Rock_Ice"
    },
    {
      "x": -20,
      "y": 25,
      "z": -7,
      "name": "Rock_Ice"
    },
    {
      "x": -20,
      "y": 26,
      "z": -7,
      "name": "Rock_Ice"
    },
    {
      "x": -20,
      "y": 27,
      "z": -7,
      "name": "Rock_Ice"
    },
    {
      "x": -20,
      "y": 28,
      "z": -7,
      "name": "Rock_Ice"
    },
    {
      "x": -20,
      "y": 29,
      "z": -7,
      "name": "Rock_Ice"
    },
    {
      "x": -20,
      "y": 30,
      "z": -7,
      "name": "Rock_Ice"
    },
    {
      "x": -20,
      "y": 31,
      "z": -7,
      "name": "Rock_Ice"
    },
    {
      "x": -20,
      "y": 32,
      "z": -7,
      "name": "Rock_Ice"
    },
    {
      "x": -20,
      "y": 21,
      "z": -6,
      "name": "Rock_Ice"
    },
    {
      "x": -20,
      "y": 22,
      "z": -6,
      "name": "Rock_Ice"
    },
    {
      "x": -20,
      "y": 23,
      "z": -6,
      "name": "Rock_Ice"
    },
    {
      "x": -20,
      "y": 24,
      "z": -6,
      "name": "Rock_Ice"
    },
    {
      "x": -20,
      "y": 25,
      "z": -6,
      "name": "Rock_Ice"
    },
    {
      "x": -20,
      "y": 26,
      "z": -6,
      "name": "Rock_Ice"
    },
    {
      "x": -20,
      "y": 27,
      "z": -6,
      "name": "Rock_Ice"
    },
    {
      "x": -20,
      "y": 28,
      "z": -6,
      "name": "Rock_Ice"
    },
    {
      "x": -20,
      "y": 29,
      "z": -6,
      "name": "Rock_Ice"
    },
    {
      "x": -20,
      "y": 30,
      "z": -6,
      "name": "Rock_Ice"
    },
    {
      "x": -20,
      "y": 31,
      "z": -6,
      "name": "Rock_Ice"
    },
    {
      "x": -20,
      "y": 32,
      "z": -6,
      "name": "Rock_Ice"
    },
    {
      "x": -20,
      "y": 33,
      "z": -6,
      "name": "Rock_Ice"
    },
    {
      "x": -20,
      "y": 34,
      "z": -6,
      "name": "Rock_Ice"
    },
    {
      "x": -20,
      "y": 35,
      "z": -6,
      "name": "Rock_Ice"
    },
    {
      "x": -20,
      "y": 36,
      "z": -6,
      "name": "Rock_Ice_Permafrost"
    },
    {
      "x": -20,
      "y": 37,
      "z": -6,
      "name": "Rock_Ice"
    },
    {
      "x": -20,
      "y": 38,
      "z": -6,
      "name": "Soil_Snow"
    },
    {
      "x": -20,
      "y": 21,
      "z": -5,
      "name": "Rock_Ice"
    },
    {
      "x": -20,
      "y": 22,
      "z": -5,
      "name": "Rock_Ice"
    },
    {
      "x": -20,
      "y": 23,
      "z": -5,
      "name": "Rock_Ice"
    },
    {
      "x": -20,
      "y": 24,
      "z": -5,
      "name": "Rock_Ice"
    },
    {
      "x": -20,
      "y": 25,
      "z": -5,
      "name": "Rock_Ice"
    },
    {
      "x": -20,
      "y": 26,
      "z": -5,
      "name": "Rock_Ice"
    },
    {
      "x": -20,
      "y": 27,
      "z": -5,
      "name": "Rock_Ice"
    },
    {
      "x": -20,
      "y": 28,
      "z": -5,
      "name": "Rock_Ice"
    },
    {
      "x": -20,
      "y": 29,
      "z": -5,
      "name": "Rock_Ice"
    },
    {
      "x": -20,
      "y": 30,
      "z": -5,
      "name": "Rock_Ice"
    },
    {
      "x": -20,
      "y": 31,
      "z": -5,
      "name": "Rock_Ice"
    },
    {
      "x": -20,
      "y": 32,
      "z": -5,
      "name": "Rock_Ice"
    },
    {
      "x": -20,
      "y": 33,
      "z": -5,
      "name": "Rock_Ice"
    },
    {
      "x": -20,
      "y": 34,
      "z": -5,
      "name": "Rock_Ice"
    },
    {
      "x": -20,
      "y": 35,
      "z": -5,
      "name": "Rock_Ice"
    },
    {
      "x": -20,
      "y": 36,
      "z": -5,
      "name": "Rock_Ice_Permafrost"
    },
    {
      "x": -20,
      "y": 37,
      "z": -5,
      "name": "Rock_Ice"
    },
    {
      "x": -20,
      "y": 38,
      "z": -5,
      "name": "Soil_Snow"
    },
    {
      "x": -20,
      "y": 21,
      "z": -4,
      "name": "Rock_Ice"
    },
    {
      "x": -20,
      "y": 22,
      "z": -4,
      "name": "Rock_Ice"
    },
    {
      "x": -20,
      "y": 23,
      "z": -4,
      "name": "Rock_Ice"
    },
    {
      "x": -20,
      "y": 24,
      "z": -4,
      "name": "Rock_Ice"
    },
    {
      "x": -20,
      "y": 25,
      "z": -4,
      "name": "Rock_Ice"
    },
    {
      "x": -20,
      "y": 26,
      "z": -4,
      "name": "Rock_Ice"
    },
    {
      "x": -20,
      "y": 27,
      "z": -4,
      "name": "Rock_Ice"
    },
    {
      "x": -20,
      "y": 28,
      "z": -4,
      "name": "Rock_Ice"
    },
    {
      "x": -20,
      "y": 29,
      "z": -4,
      "name": "Rock_Ice"
    },
    {
      "x": -20,
      "y": 30,
      "z": -4,
      "name": "Rock_Ice"
    },
    {
      "x": -20,
      "y": 31,
      "z": -4,
      "name": "Rock_Ice"
    },
    {
      "x": -20,
      "y": 32,
      "z": -4,
      "name": "Rock_Ice"
    },
    {
      "x": -20,
      "y": 33,
      "z": -4,
      "name": "Rock_Ice"
    },
    {
      "x": -20,
      "y": 34,
      "z": -4,
      "name": "Rock_Ice"
    },
    {
      "x": -20,
      "y": 35,
      "z": -4,
      "name": "Rock_Ice"
    },
    {
      "x": -20,
      "y": 36,
      "z": -4,
      "name": "Rock_Ice_Permafrost"
    },
    {
      "x": -20,
      "y": 37,
      "z": -4,
      "name": "Rock_Ice"
    },
    {
      "x": -20,
      "y": 38,
      "z": -4,
      "name": "Soil_Snow"
    },
    {
      "x": -20,
      "y": 21,
      "z": -3,
      "name": "Rock_Ice"
    },
    {
      "x": -20,
      "y": 22,
      "z": -3,
      "name": "Rock_Ice"
    },
    {
      "x": -20,
      "y": 23,
      "z": -3,
      "name": "Rock_Ice"
    },
    {
      "x": -20,
      "y": 24,
      "z": -3,
      "name": "Rock_Ice"
    },
    {
      "x": -20,
      "y": 25,
      "z": -3,
      "name": "Rock_Ice"
    },
    {
      "x": -20,
      "y": 26,
      "z": -3,
      "name": "Rock_Ice"
    },
    {
      "x": -20,
      "y": 27,
      "z": -3,
      "name": "Rock_Ice"
    },
    {
      "x": -20,
      "y": 28,
      "z": -3,
      "name": "Rock_Ice"
    },
    {
      "x": -20,
      "y": 29,
      "z": -3,
      "name": "Rock_Ice"
    },
    {
      "x": -20,
      "y": 30,
      "z": -3,
      "name": "Rock_Ice"
    },
    {
      "x": -20,
      "y": 31,
      "z": -3,
      "name": "Rock_Ice"
    },
    {
      "x": -20,
      "y": 32,
      "z": -3,
      "name": "Rock_Ice"
    },
    {
      "x": -20,
      "y": 33,
      "z": -3,
      "name": "Rock_Ice"
    },
    {
      "x": -20,
      "y": 34,
      "z": -3,
      "name": "Rock_Ice"
    },
    {
      "x": -20,
      "y": 35,
      "z": -3,
      "name": "Rock_Ice"
    },
    {
      "x": -20,
      "y": 36,
      "z": -3,
      "name": "Rock_Ice"
    },
    {
      "x": -20,
      "y": 37,
      "z": -3,
      "name": "Rock_Ice"
    },
    {
      "x": -20,
      "y": 38,
      "z": -3,
      "name": "Soil_Snow"
    },
    {
      "x": -20,
      "y": 21,
      "z": -2,
      "name": "Rock_Ice"
    },
    {
      "x": -20,
      "y": 22,
      "z": -2,
      "name": "Rock_Ice"
    },
    {
      "x": -20,
      "y": 23,
      "z": -2,
      "name": "Rock_Ice"
    },
    {
      "x": -20,
      "y": 24,
      "z": -2,
      "name": "Rock_Ice"
    },
    {
      "x": -20,
      "y": 25,
      "z": -2,
      "name": "Rock_Ice"
    },
    {
      "x": -20,
      "y": 26,
      "z": -2,
      "name": "Rock_Ice"
    },
    {
      "x": -20,
      "y": 27,
      "z": -2,
      "name": "Rock_Ice"
    },
    {
      "x": -20,
      "y": 28,
      "z": -2,
      "name": "Rock_Ice"
    },
    {
      "x": -20,
      "y": 29,
      "z": -2,
      "name": "Rock_Ice"
    },
    {
      "x": -20,
      "y": 30,
      "z": -2,
      "name": "Rock_Ice"
    },
    {
      "x": -20,
      "y": 31,
      "z": -2,
      "name": "Rock_Ice"
    },
    {
      "x": -20,
      "y": 32,
      "z": -2,
      "name": "Rock_Ice"
    },
    {
      "x": -20,
      "y": 33,
      "z": -2,
      "name": "Rock_Ice"
    },
    {
      "x": -20,
      "y": 34,
      "z": -2,
      "name": "Rock_Ice"
    },
    {
      "x": -20,
      "y": 35,
      "z": -2,
      "name": "Rock_Ice_Permafrost"
    },
    {
      "x": -20,
      "y": 36,
      "z": -2,
      "name": "Rock_Ice_Permafrost"
    },
    {
      "x": -20,
      "y": 37,
      "z": -2,
      "name": "Soil_Snow"
    },
    {
      "x": -20,
      "y": 21,
      "z": -1,
      "name": "Rock_Ice_Permafrost"
    },
    {
      "x": -20,
      "y": 22,
      "z": -1,
      "name": "Rock_Ice"
    },
    {
      "x": -20,
      "y": 23,
      "z": -1,
      "name": "Rock_Ice"
    },
    {
      "x": -20,
      "y": 24,
      "z": -1,
      "name": "Rock_Ice"
    },
    {
      "x": -20,
      "y": 25,
      "z": -1,
      "name": "Rock_Ice"
    },
    {
      "x": -20,
      "y": 26,
      "z": -1,
      "name": "Rock_Ice"
    },
    {
      "x": -20,
      "y": 27,
      "z": -1,
      "name": "Rock_Ice"
    },
    {
      "x": -20,
      "y": 28,
      "z": -1,
      "name": "Rock_Ice"
    },
    {
      "x": -20,
      "y": 29,
      "z": -1,
      "name": "Rock_Ice"
    },
    {
      "x": -20,
      "y": 30,
      "z": -1,
      "name": "Rock_Ice"
    },
    {
      "x": -20,
      "y": 31,
      "z": -1,
      "name": "Rock_Ice"
    },
    {
      "x": -20,
      "y": 32,
      "z": -1,
      "name": "Rock_Ice_Permafrost"
    },
    {
      "x": -20,
      "y": 33,
      "z": -1,
      "name": "Rock_Ice"
    },
    {
      "x": -20,
      "y": 34,
      "z": -1,
      "name": "Rock_Ice_Permafrost"
    },
    {
      "x": -20,
      "y": 35,
      "z": -1,
      "name": "Rock_Ice_Permafrost"
    },
    {
      "x": -20,
      "y": 36,
      "z": -1,
      "name": "Rock_Ice_Permafrost"
    },
    {
      "x": -20,
      "y": 37,
      "z": -1,
      "name": "Soil_Snow"
    },
    {
      "x": -20,
      "y": 21,
      "z": 0,
      "name": "Rock_Ice_Permafrost"
    },
    {
      "x": -20,
      "y": 22,
      "z": 0,
      "name": "Rock_Ice_Permafrost"
    },
    {
      "x": -20,
      "y": 23,
      "z": 0,
      "name": "Rock_Ice_Permafrost"
    },
    {
      "x": -20,
      "y": 24,
      "z": 0,
      "name": "Rock_Ice_Permafrost"
    },
    {
      "x": -20,
      "y": 25,
      "z": 0,
      "name": "Rock_Ice_Permafrost"
    },
    {
      "x": -20,
      "y": 26,
      "z": 0,
      "name": "Rock_Ice_Permafrost"
    },
    {
      "x": -20,
      "y": 27,
      "z": 0,
      "name": "Rock_Ice_Permafrost"
    },
    {
      "x": -20,
      "y": 28,
      "z": 0,
      "name": "Rock_Ice_Permafrost"
    },
    {
      "x": -20,
      "y": 29,
      "z": 0,
      "name": "Rock_Ice_Permafrost"
    },
    {
      "x": -20,
      "y": 30,
      "z": 0,
      "name": "Rock_Ice_Permafrost"
    },
    {
      "x": -20,
      "y": 31,
      "z": 0,
      "name": "Rock_Ice_Permafrost"
    },
    {
      "x": -20,
      "y": 32,
      "z": 0,
      "name": "Rock_Ice_Permafrost"
    },
    {
      "x": -20,
      "y": 33,
      "z": 0,
      "name": "Rock_Ice_Permafrost"
    },
    {
      "x": -20,
      "y": 34,
      "z": 0,
      "name": "Rock_Ice_Permafrost"
    },
    {
      "x": -20,
      "y": 35,
      "z": 0,
      "name": "Rock_Ice_Permafrost"
    },
    {
      "x": -20,
      "y": 36,
      "z": 0,
      "name": "Soil_Snow"
    },
    {
      "x": -20,
      "y": 21,
      "z": 1,
      "name": "Rock_Ice_Permafrost"
    },
    {
      "x": -20,
      "y": 22,
      "z": 1,
      "name": "Rock_Ice_Permafrost"
    },
    {
      "x": -20,
      "y": 23,
      "z": 1,
      "name": "Rock_Ice_Permafrost"
    },
    {
      "x": -20,
      "y": 24,
      "z": 1,
      "name": "Rock_Ice_Permafrost"
    },
    {
      "x": -20,
      "y": 25,
      "z": 1,
      "name": "Rock_Ice_Permafrost"
    },
    {
      "x": -20,
      "y": 26,
      "z": 1,
      "name": "Rock_Ice_Permafrost"
    },
    {
      "x": -20,
      "y": 27,
      "z": 1,
      "name": "Rock_Ice_Permafrost"
    },
    {
      "x": -20,
      "y": 28,
      "z": 1,
      "name": "Rock_Ice_Permafrost"
    },
    {
      "x": -20,
      "y": 29,
      "z": 1,
      "name": "Rock_Ice_Permafrost"
    },
    {
      "x": -20,
      "y": 30,
      "z": 1,
      "name": "Rock_Ice"
    },
    {
      "x": -20,
      "y": 31,
      "z": 1,
      "name": "Rock_Ice"
    },
    {
      "x": -20,
      "y": 32,
      "z": 1,
      "name": "Rock_Ice"
    },
    {
      "x": -20,
      "y": 33,
      "z": 1,
      "name": "Rock_Ice_Permafrost"
    },
    {
      "x": -20,
      "y": 34,
      "z": 1,
      "name": "Rock_Ice_Permafrost"
    },
    {
      "x": -20,
      "y": 35,
      "z": 1,
      "name": "Soil_Snow"
    },
    {
      "x": -20,
      "y": 22,
      "z": 2,
      "name": "Rock_Ice_Permafrost"
    },
    {
      "x": -20,
      "y": 23,
      "z": 2,
      "name": "Rock_Ice_Permafrost"
    },
    {
      "x": -20,
      "y": 24,
      "z": 2,
      "name": "Rock_Ice_Permafrost"
    },
    {
      "x": -20,
      "y": 25,
      "z": 2,
      "name": "Rock_Ice_Permafrost"
    },
    {
      "x": -20,
      "y": 26,
      "z": 2,
      "name": "Rock_Ice_Permafrost"
    },
    {
      "x": -20,
      "y": 27,
      "z": 2,
      "name": "Rock_Ice"
    },
    {
      "x": -20,
      "y": 28,
      "z": 2,
      "name": "Rock_Ice"
    },
    {
      "x": -20,
      "y": 29,
      "z": 2,
      "name": "Rock_Ice"
    },
    {
      "x": -20,
      "y": 30,
      "z": 2,
      "name": "Rock_Ice"
    },
    {
      "x": -20,
      "y": 31,
      "z": 2,
      "name": "Rock_Ice"
    },
    {
      "x": -20,
      "y": 32,
      "z": 2,
      "name": "Soil_Snow"
    },
    {
      "x": -20,
      "y": 23,
      "z": 3,
      "name": "Rock_Ice_Permafrost"
    },
    {
      "x": -20,
      "y": 24,
      "z": 3,
      "name": "Rock_Ice_Permafrost"
    },
    {
      "x": -20,
      "y": 25,
      "z": 3,
      "name": "Rock_Ice_Permafrost"
    },
    {
      "x": -20,
      "y": 26,
      "z": 3,
      "name": "Rock_Ice_Permafrost"
    },
    {
      "x": -20,
      "y": 27,
      "z": 3,
      "name": "Rock_Ice"
    },
    {
      "x": -20,
      "y": 28,
      "z": 3,
      "name": "Rock_Ice"
    },
    {
      "x": -20,
      "y": 29,
      "z": 3,
      "name": "Rock_Ice"
    },
    {
      "x": -20,
      "y": 30,
      "z": 3,
      "name": "Rock_Ice"
    },
    {
      "x": -20,
      "y": 31,
      "z": 3,
      "name": "Soil_Snow"
    },
    {
      "x": -20,
      "y": 23,
      "z": 4,
      "name": "Rock_Ice_Permafrost"
    },
    {
      "x": -20,
      "y": 24,
      "z": 4,
      "name": "Rock_Ice_Permafrost"
    },
    {
      "x": -20,
      "y": 25,
      "z": 4,
      "name": "Rock_Ice_Permafrost"
    },
    {
      "x": -20,
      "y": 26,
      "z": 4,
      "name": "Rock_Ice"
    },
    {
      "x": -20,
      "y": 27,
      "z": 4,
      "name": "Rock_Ice"
    },
    {
      "x": -20,
      "y": 28,
      "z": 4,
      "name": "Rock_Ice"
    },
    {
      "x": -20,
      "y": 29,
      "z": 4,
      "name": "Rock_Ice"
    },
    {
      "x": -20,
      "y": 30,
      "z": 4,
      "name": "Rock_Ice"
    },
    {
      "x": -20,
      "y": 31,
      "z": 4,
      "name": "Rock_Ice"
    },
    {
      "x": -20,
      "y": 32,
      "z": 4,
      "name": "Rock_Ice"
    },
    {
      "x": -20,
      "y": 33,
      "z": 4,
      "name": "Rock_Ice"
    },
    {
      "x": -20,
      "y": 34,
      "z": 4,
      "name": "Rock_Ice"
    },
    {
      "x": -20,
      "y": 35,
      "z": 4,
      "name": "Soil_Snow"
    },
    {
      "x": -20,
      "y": 23,
      "z": 5,
      "name": "Rock_Ice_Permafrost"
    },
    {
      "x": -20,
      "y": 24,
      "z": 5,
      "name": "Rock_Ice_Permafrost"
    },
    {
      "x": -20,
      "y": 25,
      "z": 5,
      "name": "Rock_Ice_Permafrost"
    },
    {
      "x": -20,
      "y": 26,
      "z": 5,
      "name": "Rock_Ice"
    },
    {
      "x": -20,
      "y": 27,
      "z": 5,
      "name": "Rock_Ice"
    },
    {
      "x": -20,
      "y": 28,
      "z": 5,
      "name": "Rock_Ice"
    },
    {
      "x": -20,
      "y": 29,
      "z": 5,
      "name": "Rock_Ice"
    },
    {
      "x": -20,
      "y": 30,
      "z": 5,
      "name": "Rock_Ice"
    },
    {
      "x": -20,
      "y": 31,
      "z": 5,
      "name": "Rock_Ice"
    },
    {
      "x": -20,
      "y": 32,
      "z": 5,
      "name": "Rock_Ice"
    },
    {
      "x": -20,
      "y": 33,
      "z": 5,
      "name": "Rock_Ice"
    },
    {
      "x": -20,
      "y": 34,
      "z": 5,
      "name": "Rock_Ice"
    },
    {
      "x": -20,
      "y": 35,
      "z": 5,
      "name": "Soil_Snow"
    },
    {
      "x": -20,
      "y": 22,
      "z": 6,
      "name": "Rock_Ice"
    },
    {
      "x": -20,
      "y": 23,
      "z": 6,
      "name": "Rock_Ice_Permafrost"
    },
    {
      "x": -20,
      "y": 24,
      "z": 6,
      "name": "Rock_Ice_Permafrost"
    },
    {
      "x": -20,
      "y": 25,
      "z": 6,
      "name": "Rock_Ice_Permafrost"
    },
    {
      "x": -20,
      "y": 26,
      "z": 6,
      "name": "Rock_Ice"
    },
    {
      "x": -20,
      "y": 27,
      "z": 6,
      "name": "Rock_Ice"
    },
    {
      "x": -20,
      "y": 28,
      "z": 6,
      "name": "Rock_Ice"
    },
    {
      "x": -20,
      "y": 29,
      "z": 6,
      "name": "Rock_Ice"
    },
    {
      "x": -20,
      "y": 30,
      "z": 6,
      "name": "Rock_Ice"
    },
    {
      "x": -20,
      "y": 31,
      "z": 6,
      "name": "Rock_Ice"
    },
    {
      "x": -20,
      "y": 32,
      "z": 6,
      "name": "Rock_Ice"
    },
    {
      "x": -20,
      "y": 33,
      "z": 6,
      "name": "Rock_Ice"
    },
    {
      "x": -20,
      "y": 34,
      "z": 6,
      "name": "Soil_Snow"
    },
    {
      "x": -20,
      "y": 21,
      "z": 7,
      "name": "Rock_Ice"
    },
    {
      "x": -20,
      "y": 22,
      "z": 7,
      "name": "Rock_Ice"
    },
    {
      "x": -20,
      "y": 23,
      "z": 7,
      "name": "Rock_Ice"
    },
    {
      "x": -20,
      "y": 24,
      "z": 7,
      "name": "Rock_Ice_Permafrost"
    },
    {
      "x": -20,
      "y": 25,
      "z": 7,
      "name": "Rock_Ice_Permafrost"
    },
    {
      "x": -20,
      "y": 26,
      "z": 7,
      "name": "Rock_Ice_Permafrost"
    },
    {
      "x": -20,
      "y": 27,
      "z": 7,
      "name": "Rock_Ice"
    },
    {
      "x": -20,
      "y": 28,
      "z": 7,
      "name": "Rock_Ice"
    },
    {
      "x": -20,
      "y": 29,
      "z": 7,
      "name": "Rock_Ice"
    },
    {
      "x": -20,
      "y": 30,
      "z": 7,
      "name": "Rock_Ice"
    },
    {
      "x": -20,
      "y": 31,
      "z": 7,
      "name": "Rock_Ice"
    },
    {
      "x": -20,
      "y": 32,
      "z": 7,
      "name": "Soil_Snow"
    },
    {
      "x": -20,
      "y": 21,
      "z": 8,
      "name": "Rock_Ice"
    },
    {
      "x": -20,
      "y": 22,
      "z": 8,
      "name": "Rock_Ice"
    },
    {
      "x": -20,
      "y": 23,
      "z": 8,
      "name": "Rock_Ice"
    },
    {
      "x": -20,
      "y": 24,
      "z": 8,
      "name": "Rock_Ice_Permafrost"
    },
    {
      "x": -20,
      "y": 25,
      "z": 8,
      "name": "Rock_Ice_Permafrost"
    },
    {
      "x": -20,
      "y": 26,
      "z": 8,
      "name": "Rock_Ice"
    },
    {
      "x": -20,
      "y": 27,
      "z": 8,
      "name": "Rock_Ice"
    },
    {
      "x": -20,
      "y": 28,
      "z": 8,
      "name": "Rock_Ice"
    },
    {
      "x": -20,
      "y": 29,
      "z": 8,
      "name": "Rock_Ice"
    },
    {
      "x": -20,
      "y": 30,
      "z": 8,
      "name": "Rock_Ice"
    },
    {
      "x": -20,
      "y": 31,
      "z": 8,
      "name": "Rock_Ice"
    },
    {
      "x": -20,
      "y": 32,
      "z": 8,
      "name": "Soil_Snow"
    },
    {
      "x": -20,
      "y": 21,
      "z": 9,
      "name": "Rock_Ice"
    },
    {
      "x": -20,
      "y": 22,
      "z": 9,
      "name": "Rock_Ice"
    },
    {
      "x": -20,
      "y": 23,
      "z": 9,
      "name": "Rock_Ice"
    },
    {
      "x": -20,
      "y": 24,
      "z": 9,
      "name": "Rock_Ice"
    },
    {
      "x": -20,
      "y": 25,
      "z": 9,
      "name": "Rock_Ice_Permafrost"
    },
    {
      "x": -20,
      "y": 26,
      "z": 9,
      "name": "Rock_Ice_Permafrost"
    },
    {
      "x": -20,
      "y": 27,
      "z": 9,
      "name": "Rock_Ice"
    },
    {
      "x": -20,
      "y": 28,
      "z": 9,
      "name": "Rock_Ice"
    },
    {
      "x": -20,
      "y": 29,
      "z": 9,
      "name": "Rock_Ice"
    },
    {
      "x": -20,
      "y": 30,
      "z": 9,
      "name": "Rock_Ice"
    },
    {
      "x": -20,
      "y": 31,
      "z": 9,
      "name": "Rock_Ice"
    },
    {
      "x": -20,
      "y": 32,
      "z": 9,
      "name": "Soil_Snow"
    },
    {
      "x": -20,
      "y": 22,
      "z": 10,
      "name": "Rock_Ice"
    },
    {
      "x": -20,
      "y": 23,
      "z": 10,
      "name": "Rock_Ice"
    },
    {
      "x": -20,
      "y": 24,
      "z": 10,
      "name": "Rock_Ice"
    },
    {
      "x": -20,
      "y": 25,
      "z": 10,
      "name": "Rock_Ice_Permafrost"
    },
    {
      "x": -20,
      "y": 26,
      "z": 10,
      "name": "Rock_Ice_Permafrost"
    },
    {
      "x": -20,
      "y": 27,
      "z": 10,
      "name": "Rock_Ice"
    },
    {
      "x": -20,
      "y": 28,
      "z": 10,
      "name": "Rock_Ice"
    },
    {
      "x": -20,
      "y": 29,
      "z": 10,
      "name": "Rock_Ice"
    },
    {
      "x": -20,
      "y": 30,
      "z": 10,
      "name": "Soil_Snow"
    },
    {
      "x": -19,
      "y": 23,
      "z": -10,
      "name": "Rock_Ice"
    },
    {
      "x": -19,
      "y": 24,
      "z": -10,
      "name": "Rock_Ice"
    },
    {
      "x": -19,
      "y": 25,
      "z": -10,
      "name": "Rock_Ice"
    },
    {
      "x": -19,
      "y": 38,
      "z": -10,
      "name": "Rock_Ice"
    },
    {
      "x": -19,
      "y": 39,
      "z": -10,
      "name": "Rock_Ice"
    },
    {
      "x": -19,
      "y": 40,
      "z": -10,
      "name": "Rock_Ice"
    },
    {
      "x": -19,
      "y": 41,
      "z": -10,
      "name": "Rock_Ice"
    },
    {
      "x": -19,
      "y": 42,
      "z": -10,
      "name": "Rock_Ice"
    },
    {
      "x": -19,
      "y": 43,
      "z": -10,
      "name": "Soil_Snow"
    },
    {
      "x": -19,
      "y": 17,
      "z": -9,
      "name": "Rock_Ice"
    },
    {
      "x": -19,
      "y": 18,
      "z": -9,
      "name": "Rock_Ice_Permafrost"
    },
    {
      "x": -19,
      "y": 19,
      "z": -9,
      "name": "Rock_Ice"
    },
    {
      "x": -19,
      "y": 20,
      "z": -9,
      "name": "Rock_Ice"
    },
    {
      "x": -19,
      "y": 21,
      "z": -9,
      "name": "Rock_Ice"
    },
    {
      "x": -19,
      "y": 22,
      "z": -9,
      "name": "Rock_Ice"
    },
    {
      "x": -19,
      "y": 23,
      "z": -9,
      "name": "Rock_Ice"
    },
    {
      "x": -19,
      "y": 24,
      "z": -9,
      "name": "Rock_Ice"
    },
    {
      "x": -19,
      "y": 25,
      "z": -9,
      "name": "Rock_Ice"
    },
    {
      "x": -19,
      "y": 26,
      "z": -9,
      "name": "Rock_Ice"
    },
    {
      "x": -19,
      "y": 27,
      "z": -9,
      "name": "Rock_Ice"
    },
    {
      "x": -19,
      "y": 28,
      "z": -9,
      "name": "Rock_Ice"
    },
    {
      "x": -19,
      "y": 29,
      "z": -9,
      "name": "Rock_Ice"
    },
    {
      "x": -19,
      "y": 30,
      "z": -9,
      "name": "Rock_Ice"
    },
    {
      "x": -19,
      "y": 31,
      "z": -9,
      "name": "Rock_Ice"
    },
    {
      "x": -19,
      "y": 32,
      "z": -9,
      "name": "Rock_Ice"
    },
    {
      "x": -19,
      "y": 33,
      "z": -9,
      "name": "Rock_Ice_Permafrost"
    },
    {
      "x": -19,
      "y": 34,
      "z": -9,
      "name": "Rock_Ice_Permafrost"
    },
    {
      "x": -19,
      "y": 35,
      "z": -9,
      "name": "Rock_Ice_Permafrost"
    },
    {
      "x": -19,
      "y": 36,
      "z": -9,
      "name": "Rock_Ice_Permafrost"
    },
    {
      "x": -19,
      "y": 37,
      "z": -9,
      "name": "Rock_Ice"
    },
    {
      "x": -19,
      "y": 38,
      "z": -9,
      "name": "Rock_Ice"
    },
    {
      "x": -19,
      "y": 39,
      "z": -9,
      "name": "Rock_Ice_Permafrost"
    },
    {
      "x": -19,
      "y": 40,
      "z": -9,
      "name": "Rock_Ice_Permafrost"
    },
    {
      "x": -19,
      "y": 41,
      "z": -9,
      "name": "Rock_Ice_Permafrost"
    },
    {
      "x": -19,
      "y": 42,
      "z": -9,
      "name": "Rock_Ice"
    },
    {
      "x": -19,
      "y": 43,
      "z": -9,
      "name": "Soil_Snow"
    },
    {
      "x": -19,
      "y": 18,
      "z": -8,
      "name": "Rock_Ice_Permafrost"
    },
    {
      "x": -19,
      "y": 19,
      "z": -8,
      "name": "Rock_Ice"
    },
    {
      "x": -19,
      "y": 20,
      "z": -8,
      "name": "Rock_Ice"
    },
    {
      "x": -19,
      "y": 21,
      "z": -8,
      "name": "Rock_Ice"
    },
    {
      "x": -19,
      "y": 22,
      "z": -8,
      "name": "Rock_Ice"
    },
    {
      "x": -19,
      "y": 23,
      "z": -8,
      "name": "Rock_Ice"
    },
    {
      "x": -19,
      "y": 24,
      "z": -8,
      "name": "Rock_Ice"
    },
    {
      "x": -19,
      "y": 25,
      "z": -8,
      "name": "Rock_Ice"
    },
    {
      "x": -19,
      "y": 26,
      "z": -8,
      "name": "Rock_Ice"
    },
    {
      "x": -19,
      "y": 27,
      "z": -8,
      "name": "Rock_Ice"
    },
    {
      "x": -19,
      "y": 28,
      "z": -8,
      "name": "Rock_Ice"
    },
    {
      "x": -19,
      "y": 29,
      "z": -8,
      "name": "Rock_Ice"
    },
    {
      "x": -19,
      "y": 30,
      "z": -8,
      "name": "Rock_Ice"
    },
    {
      "x": -19,
      "y": 31,
      "z": -8,
      "name": "Rock_Ice"
    },
    {
      "x": -19,
      "y": 32,
      "z": -8,
      "name": "Rock_Ice"
    },
    {
      "x": -19,
      "y": 33,
      "z": -8,
      "name": "Rock_Ice"
    },
    {
      "x": -19,
      "y": 34,
      "z": -8,
      "name": "Rock_Ice"
    },
    {
      "x": -19,
      "y": 35,
      "z": -8,
      "name": "Rock_Ice_Permafrost"
    },
    {
      "x": -19,
      "y": 36,
      "z": -8,
      "name": "Rock_Ice_Permafrost"
    },
    {
      "x": -19,
      "y": 37,
      "z": -8,
      "name": "Rock_Ice_Permafrost"
    },
    {
      "x": -19,
      "y": 38,
      "z": -8,
      "name": "Rock_Ice_Permafrost"
    },
    {
      "x": -19,
      "y": 39,
      "z": -8,
      "name": "Rock_Ice_Permafrost"
    },
    {
      "x": -19,
      "y": 40,
      "z": -8,
      "name": "Rock_Ice_Permafrost"
    },
    {
      "x": -19,
      "y": 41,
      "z": -8,
      "name": "Rock_Ice_Permafrost"
    },
    {
      "x": -19,
      "y": 42,
      "z": -8,
      "name": "Soil_Snow"
    },
    {
      "x": -19,
      "y": 18,
      "z": -7,
      "name": "Rock_Ice_Permafrost"
    },
    {
      "x": -19,
      "y": 19,
      "z": -7,
      "name": "Rock_Ice"
    },
    {
      "x": -19,
      "y": 20,
      "z": -7,
      "name": "Rock_Ice"
    },
    {
      "x": -19,
      "y": 21,
      "z": -7,
      "name": "Rock_Ice"
    },
    {
      "x": -19,
      "y": 22,
      "z": -7,
      "name": "Rock_Ice"
    },
    {
      "x": -19,
      "y": 23,
      "z": -7,
      "name": "Rock_Ice"
    },
    {
      "x": -19,
      "y": 24,
      "z": -7,
      "name": "Rock_Ice"
    },
    {
      "x": -19,
      "y": 25,
      "z": -7,
      "name": "Rock_Ice"
    },
    {
      "x": -19,
      "y": 26,
      "z": -7,
      "name": "Rock_Ice"
    },
    {
      "x": -19,
      "y": 27,
      "z": -7,
      "name": "Rock_Ice"
    },
    {
      "x": -19,
      "y": 28,
      "z": -7,
      "name": "Rock_Ice"
    },
    {
      "x": -19,
      "y": 29,
      "z": -7,
      "name": "Rock_Ice"
    },
    {
      "x": -19,
      "y": 30,
      "z": -7,
      "name": "Rock_Ice"
    },
    {
      "x": -19,
      "y": 31,
      "z": -7,
      "name": "Rock_Ice"
    },
    {
      "x": -19,
      "y": 32,
      "z": -7,
      "name": "Rock_Ice"
    },
    {
      "x": -19,
      "y": 33,
      "z": -7,
      "name": "Rock_Ice"
    },
    {
      "x": -19,
      "y": 34,
      "z": -7,
      "name": "Rock_Ice_Permafrost"
    },
    {
      "x": -19,
      "y": 35,
      "z": -7,
      "name": "Rock_Ice_Permafrost"
    },
    {
      "x": -19,
      "y": 36,
      "z": -7,
      "name": "Rock_Ice_Permafrost"
    },
    {
      "x": -19,
      "y": 37,
      "z": -7,
      "name": "Rock_Ice"
    },
    {
      "x": -19,
      "y": 38,
      "z": -7,
      "name": "Rock_Ice"
    },
    {
      "x": -19,
      "y": 39,
      "z": -7,
      "name": "Rock_Ice"
    },
    {
      "x": -19,
      "y": 40,
      "z": -7,
      "name": "Rock_Ice_Permafrost"
    },
    {
      "x": -19,
      "y": 41,
      "z": -7,
      "name": "Rock_Ice"
    },
    {
      "x": -19,
      "y": 42,
      "z": -7,
      "name": "Soil_Snow"
    },
    {
      "x": -19,
      "y": 19,
      "z": -6,
      "name": "Rock_Ice"
    },
    {
      "x": -19,
      "y": 20,
      "z": -6,
      "name": "Rock_Ice"
    },
    {
      "x": -19,
      "y": 21,
      "z": -6,
      "name": "Rock_Ice"
    },
    {
      "x": -19,
      "y": 22,
      "z": -6,
      "name": "Rock_Ice"
    },
    {
      "x": -19,
      "y": 23,
      "z": -6,
      "name": "Rock_Ice"
    },
    {
      "x": -19,
      "y": 24,
      "z": -6,
      "name": "Rock_Ice"
    },
    {
      "x": -19,
      "y": 25,
      "z": -6,
      "name": "Rock_Ice"
    },
    {
      "x": -19,
      "y": 26,
      "z": -6,
      "name": "Rock_Ice"
    },
    {
      "x": -19,
      "y": 27,
      "z": -6,
      "name": "Rock_Ice"
    },
    {
      "x": -19,
      "y": 28,
      "z": -6,
      "name": "Rock_Ice"
    },
    {
      "x": -19,
      "y": 29,
      "z": -6,
      "name": "Rock_Ice"
    },
    {
      "x": -19,
      "y": 30,
      "z": -6,
      "name": "Rock_Ice"
    },
    {
      "x": -19,
      "y": 31,
      "z": -6,
      "name": "Rock_Ice"
    },
    {
      "x": -19,
      "y": 32,
      "z": -6,
      "name": "Rock_Ice"
    },
    {
      "x": -19,
      "y": 33,
      "z": -6,
      "name": "Rock_Ice"
    },
    {
      "x": -19,
      "y": 34,
      "z": -6,
      "name": "Rock_Ice"
    },
    {
      "x": -19,
      "y": 35,
      "z": -6,
      "name": "Rock_Ice_Permafrost"
    },
    {
      "x": -19,
      "y": 36,
      "z": -6,
      "name": "Rock_Ice_Permafrost"
    },
    {
      "x": -19,
      "y": 37,
      "z": -6,
      "name": "Rock_Ice"
    },
    {
      "x": -19,
      "y": 38,
      "z": -6,
      "name": "Rock_Ice"
    },
    {
      "x": -19,
      "y": 39,
      "z": -6,
      "name": "Rock_Ice"
    },
    {
      "x": -19,
      "y": 40,
      "z": -6,
      "name": "Rock_Ice"
    },
    {
      "x": -19,
      "y": 41,
      "z": -6,
      "name": "Rock_Ice"
    },
    {
      "x": -19,
      "y": 42,
      "z": -6,
      "name": "Soil_Snow"
    },
    {
      "x": -19,
      "y": 19,
      "z": -5,
      "name": "Rock_Ice"
    },
    {
      "x": -19,
      "y": 20,
      "z": -5,
      "name": "Rock_Ice"
    },
    {
      "x": -19,
      "y": 21,
      "z": -5,
      "name": "Rock_Ice"
    },
    {
      "x": -19,
      "y": 22,
      "z": -5,
      "name": "Rock_Ice"
    },
    {
      "x": -19,
      "y": 23,
      "z": -5,
      "name": "Rock_Ice"
    },
    {
      "x": -19,
      "y": 24,
      "z": -5,
      "name": "Rock_Ice"
    },
    {
      "x": -19,
      "y": 25,
      "z": -5,
      "name": "Rock_Ice"
    },
    {
      "x": -19,
      "y": 26,
      "z": -5,
      "name": "Rock_Ice"
    },
    {
      "x": -19,
      "y": 27,
      "z": -5,
      "name": "Rock_Ice"
    },
    {
      "x": -19,
      "y": 28,
      "z": -5,
      "name": "Rock_Ice"
    },
    {
      "x": -19,
      "y": 29,
      "z": -5,
      "name": "Rock_Ice"
    },
    {
      "x": -19,
      "y": 30,
      "z": -5,
      "name": "Rock_Ice"
    },
    {
      "x": -19,
      "y": 31,
      "z": -5,
      "name": "Rock_Ice"
    },
    {
      "x": -19,
      "y": 32,
      "z": -5,
      "name": "Rock_Ice"
    },
    {
      "x": -19,
      "y": 33,
      "z": -5,
      "name": "Rock_Ice"
    },
    {
      "x": -19,
      "y": 34,
      "z": -5,
      "name": "Rock_Ice_Permafrost"
    },
    {
      "x": -19,
      "y": 35,
      "z": -5,
      "name": "Rock_Ice_Permafrost"
    },
    {
      "x": -19,
      "y": 36,
      "z": -5,
      "name": "Rock_Ice_Permafrost"
    },
    {
      "x": -19,
      "y": 37,
      "z": -5,
      "name": "Rock_Ice"
    },
    {
      "x": -19,
      "y": 38,
      "z": -5,
      "name": "Rock_Ice"
    },
    {
      "x": -19,
      "y": 39,
      "z": -5,
      "name": "Rock_Ice"
    },
    {
      "x": -19,
      "y": 40,
      "z": -5,
      "name": "Rock_Ice"
    },
    {
      "x": -19,
      "y": 41,
      "z": -5,
      "name": "Soil_Snow"
    },
    {
      "x": -19,
      "y": 19,
      "z": -4,
      "name": "Rock_Ice"
    },
    {
      "x": -19,
      "y": 20,
      "z": -4,
      "name": "Rock_Ice"
    },
    {
      "x": -19,
      "y": 21,
      "z": -4,
      "name": "Rock_Ice"
    },
    {
      "x": -19,
      "y": 22,
      "z": -4,
      "name": "Rock_Ice"
    },
    {
      "x": -19,
      "y": 23,
      "z": -4,
      "name": "Rock_Ice"
    },
    {
      "x": -19,
      "y": 24,
      "z": -4,
      "name": "Rock_Ice"
    },
    {
      "x": -19,
      "y": 25,
      "z": -4,
      "name": "Rock_Ice"
    },
    {
      "x": -19,
      "y": 26,
      "z": -4,
      "name": "Rock_Ice"
    },
    {
      "x": -19,
      "y": 27,
      "z": -4,
      "name": "Rock_Ice"
    },
    {
      "x": -19,
      "y": 28,
      "z": -4,
      "name": "Rock_Ice"
    },
    {
      "x": -19,
      "y": 29,
      "z": -4,
      "name": "Rock_Ice"
    },
    {
      "x": -19,
      "y": 30,
      "z": -4,
      "name": "Rock_Ice"
    },
    {
      "x": -19,
      "y": 31,
      "z": -4,
      "name": "Rock_Ice"
    },
    {
      "x": -19,
      "y": 32,
      "z": -4,
      "name": "Rock_Ice"
    },
    {
      "x": -19,
      "y": 33,
      "z": -4,
      "name": "Rock_Ice"
    },
    {
      "x": -19,
      "y": 34,
      "z": -4,
      "name": "Rock_Ice"
    },
    {
      "x": -19,
      "y": 35,
      "z": -4,
      "name": "Rock_Ice_Permafrost"
    },
    {
      "x": -19,
      "y": 36,
      "z": -4,
      "name": "Rock_Ice_Permafrost"
    },
    {
      "x": -19,
      "y": 37,
      "z": -4,
      "name": "Rock_Ice"
    },
    {
      "x": -19,
      "y": 38,
      "z": -4,
      "name": "Rock_Ice"
    },
    {
      "x": -19,
      "y": 39,
      "z": -4,
      "name": "Rock_Ice"
    },
    {
      "x": -19,
      "y": 40,
      "z": -4,
      "name": "Soil_Snow"
    },
    {
      "x": -19,
      "y": 19,
      "z": -3,
      "name": "Rock_Ice_Permafrost"
    },
    {
      "x": -19,
      "y": 20,
      "z": -3,
      "name": "Rock_Ice"
    },
    {
      "x": -19,
      "y": 21,
      "z": -3,
      "name": "Rock_Ice"
    },
    {
      "x": -19,
      "y": 22,
      "z": -3,
      "name": "Rock_Ice"
    },
    {
      "x": -19,
      "y": 23,
      "z": -3,
      "name": "Rock_Ice"
    },
    {
      "x": -19,
      "y": 24,
      "z": -3,
      "name": "Rock_Ice"
    },
    {
      "x": -19,
      "y": 25,
      "z": -3,
      "name": "Rock_Ice"
    },
    {
      "x": -19,
      "y": 26,
      "z": -3,
      "name": "Rock_Ice"
    },
    {
      "x": -19,
      "y": 27,
      "z": -3,
      "name": "Rock_Ice"
    },
    {
      "x": -19,
      "y": 28,
      "z": -3,
      "name": "Rock_Ice"
    },
    {
      "x": -19,
      "y": 29,
      "z": -3,
      "name": "Rock_Ice"
    },
    {
      "x": -19,
      "y": 30,
      "z": -3,
      "name": "Rock_Ice"
    },
    {
      "x": -19,
      "y": 31,
      "z": -3,
      "name": "Rock_Ice"
    },
    {
      "x": -19,
      "y": 32,
      "z": -3,
      "name": "Rock_Ice"
    },
    {
      "x": -19,
      "y": 33,
      "z": -3,
      "name": "Rock_Ice"
    },
    {
      "x": -19,
      "y": 34,
      "z": -3,
      "name": "Rock_Ice_Permafrost"
    },
    {
      "x": -19,
      "y": 35,
      "z": -3,
      "name": "Rock_Ice_Permafrost"
    },
    {
      "x": -19,
      "y": 36,
      "z": -3,
      "name": "Rock_Ice_Permafrost"
    },
    {
      "x": -19,
      "y": 37,
      "z": -3,
      "name": "Rock_Ice"
    },
    {
      "x": -19,
      "y": 38,
      "z": -3,
      "name": "Rock_Ice"
    },
    {
      "x": -19,
      "y": 39,
      "z": -3,
      "name": "Rock_Ice"
    },
    {
      "x": -19,
      "y": 40,
      "z": -3,
      "name": "Soil_Snow"
    },
    {
      "x": -19,
      "y": 19,
      "z": -2,
      "name": "Rock_Ice_Permafrost"
    },
    {
      "x": -19,
      "y": 20,
      "z": -2,
      "name": "Rock_Ice_Permafrost"
    },
    {
      "x": -19,
      "y": 21,
      "z": -2,
      "name": "Rock_Ice"
    },
    {
      "x": -19,
      "y": 22,
      "z": -2,
      "name": "Rock_Ice"
    },
    {
      "x": -19,
      "y": 23,
      "z": -2,
      "name": "Rock_Ice"
    },
    {
      "x": -19,
      "y": 24,
      "z": -2,
      "name": "Rock_Ice"
    },
    {
      "x": -19,
      "y": 25,
      "z": -2,
      "name": "Rock_Ice"
    },
    {
      "x": -19,
      "y": 26,
      "z": -2,
      "name": "Rock_Ice"
    },
    {
      "x": -19,
      "y": 27,
      "z": -2,
      "name": "Rock_Ice"
    },
    {
      "x": -19,
      "y": 28,
      "z": -2,
      "name": "Rock_Ice"
    },
    {
      "x": -19,
      "y": 29,
      "z": -2,
      "name": "Rock_Ice"
    },
    {
      "x": -19,
      "y": 30,
      "z": -2,
      "name": "Rock_Ice"
    },
    {
      "x": -19,
      "y": 31,
      "z": -2,
      "name": "Rock_Ice"
    },
    {
      "x": -19,
      "y": 32,
      "z": -2,
      "name": "Rock_Ice_Permafrost"
    },
    {
      "x": -19,
      "y": 33,
      "z": -2,
      "name": "Rock_Ice_Permafrost"
    },
    {
      "x": -19,
      "y": 34,
      "z": -2,
      "name": "Rock_Ice_Permafrost"
    },
    {
      "x": -19,
      "y": 35,
      "z": -2,
      "name": "Rock_Ice_Permafrost"
    },
    {
      "x": -19,
      "y": 36,
      "z": -2,
      "name": "Rock_Ice_Permafrost"
    },
    {
      "x": -19,
      "y": 37,
      "z": -2,
      "name": "Rock_Ice_Permafrost"
    },
    {
      "x": -19,
      "y": 38,
      "z": -2,
      "name": "Rock_Ice"
    },
    {
      "x": -19,
      "y": 39,
      "z": -2,
      "name": "Soil_Snow"
    },
    {
      "x": -19,
      "y": 19,
      "z": -1,
      "name": "Rock_Ice_Permafrost"
    },
    {
      "x": -19,
      "y": 20,
      "z": -1,
      "name": "Rock_Ice_Permafrost"
    },
    {
      "x": -19,
      "y": 21,
      "z": -1,
      "name": "Rock_Ice_Permafrost"
    },
    {
      "x": -19,
      "y": 22,
      "z": -1,
      "name": "Rock_Ice"
    },
    {
      "x": -19,
      "y": 23,
      "z": -1,
      "name": "Rock_Ice"
    },
    {
      "x": -19,
      "y": 24,
      "z": -1,
      "name": "Rock_Ice"
    },
    {
      "x": -19,
      "y": 25,
      "z": -1,
      "name": "Rock_Ice"
    },
    {
      "x": -19,
      "y": 26,
      "z": -1,
      "name": "Rock_Ice"
    },
    {
      "x": -19,
      "y": 27,
      "z": -1,
      "name": "Rock_Ice"
    },
    {
      "x": -19,
      "y": 28,
      "z": -1,
      "name": "Rock_Ice"
    },
    {
      "x": -19,
      "y": 29,
      "z": -1,
      "name": "Rock_Ice_Permafrost"
    },
    {
      "x": -19,
      "y": 30,
      "z": -1,
      "name": "Rock_Ice_Permafrost"
    },
    {
      "x": -19,
      "y": 31,
      "z": -1,
      "name": "Rock_Ice_Permafrost"
    },
    {
      "x": -19,
      "y": 32,
      "z": -1,
      "name": "Rock_Ice_Permafrost"
    },
    {
      "x": -19,
      "y": 33,
      "z": -1,
      "name": "Rock_Ice_Permafrost"
    },
    {
      "x": -19,
      "y": 34,
      "z": -1,
      "name": "Rock_Ice_Permafrost"
    },
    {
      "x": -19,
      "y": 35,
      "z": -1,
      "name": "Rock_Ice_Permafrost"
    },
    {
      "x": -19,
      "y": 36,
      "z": -1,
      "name": "Rock_Ice_Permafrost"
    },
    {
      "x": -19,
      "y": 37,
      "z": -1,
      "name": "Rock_Ice_Permafrost"
    },
    {
      "x": -19,
      "y": 38,
      "z": -1,
      "name": "Soil_Snow"
    },
    {
      "x": -19,
      "y": 19,
      "z": 0,
      "name": "Rock_Ice"
    },
    {
      "x": -19,
      "y": 20,
      "z": 0,
      "name": "Rock_Ice_Permafrost"
    },
    {
      "x": -19,
      "y": 21,
      "z": 0,
      "name": "Rock_Ice_Permafrost"
    },
    {
      "x": -19,
      "y": 22,
      "z": 0,
      "name": "Rock_Ice_Permafrost"
    },
    {
      "x": -19,
      "y": 23,
      "z": 0,
      "name": "Rock_Ice_Permafrost"
    },
    {
      "x": -19,
      "y": 24,
      "z": 0,
      "name": "Rock_Ice_Permafrost"
    },
    {
      "x": -19,
      "y": 25,
      "z": 0,
      "name": "Rock_Ice_Permafrost"
    },
    {
      "x": -19,
      "y": 26,
      "z": 0,
      "name": "Rock_Ice_Permafrost"
    },
    {
      "x": -19,
      "y": 27,
      "z": 0,
      "name": "Rock_Ice_Permafrost"
    },
    {
      "x": -19,
      "y": 28,
      "z": 0,
      "name": "Rock_Ice_Permafrost"
    },
    {
      "x": -19,
      "y": 29,
      "z": 0,
      "name": "Rock_Ice_Permafrost"
    },
    {
      "x": -19,
      "y": 30,
      "z": 0,
      "name": "Rock_Ice_Permafrost"
    },
    {
      "x": -19,
      "y": 31,
      "z": 0,
      "name": "Rock_Ice_Permafrost"
    },
    {
      "x": -19,
      "y": 32,
      "z": 0,
      "name": "Rock_Ice_Permafrost"
    },
    {
      "x": -19,
      "y": 33,
      "z": 0,
      "name": "Rock_Ice_Permafrost"
    },
    {
      "x": -19,
      "y": 34,
      "z": 0,
      "name": "Rock_Ice_Permafrost"
    },
    {
      "x": -19,
      "y": 35,
      "z": 0,
      "name": "Rock_Ice_Permafrost"
    },
    {
      "x": -19,
      "y": 36,
      "z": 0,
      "name": "Rock_Ice_Permafrost"
    },
    {
      "x": -19,
      "y": 37,
      "z": 0,
      "name": "Soil_Snow"
    },
    {
      "x": -19,
      "y": 19,
      "z": 1,
      "name": "Rock_Ice_Permafrost"
    },
    {
      "x": -19,
      "y": 20,
      "z": 1,
      "name": "Rock_Ice_Permafrost"
    },
    {
      "x": -19,
      "y": 21,
      "z": 1,
      "name": "Rock_Ice_Permafrost"
    },
    {
      "x": -19,
      "y": 22,
      "z": 1,
      "name": "Rock_Ice_Permafrost"
    },
    {
      "x": -19,
      "y": 23,
      "z": 1,
      "name": "Rock_Ice_Permafrost"
    },
    {
      "x": -19,
      "y": 24,
      "z": 1,
      "name": "Rock_Ice_Permafrost"
    },
    {
      "x": -19,
      "y": 25,
      "z": 1,
      "name": "Rock_Ice_Permafrost"
    },
    {
      "x": -19,
      "y": 26,
      "z": 1,
      "name": "Rock_Ice_Permafrost"
    },
    {
      "x": -19,
      "y": 27,
      "z": 1,
      "name": "Rock_Ice_Permafrost"
    },
    {
      "x": -19,
      "y": 28,
      "z": 1,
      "name": "Rock_Ice"
    },
    {
      "x": -19,
      "y": 29,
      "z": 1,
      "name": "Rock_Ice"
    },
    {
      "x": -19,
      "y": 30,
      "z": 1,
      "name": "Rock_Ice"
    },
    {
      "x": -19,
      "y": 31,
      "z": 1,
      "name": "Rock_Ice"
    },
    {
      "x": -19,
      "y": 32,
      "z": 1,
      "name": "Rock_Ice_Permafrost"
    },
    {
      "x": -19,
      "y": 33,
      "z": 1,
      "name": "Rock_Ice_Permafrost"
    },
    {
      "x": -19,
      "y": 34,
      "z": 1,
      "name": "Rock_Ice_Permafrost"
    },
    {
      "x": -19,
      "y": 35,
      "z": 1,
      "name": "Rock_Ice_Permafrost"
    },
    {
      "x": -19,
      "y": 36,
      "z": 1,
      "name": "Soil_Snow"
    },
    {
      "x": -19,
      "y": 19,
      "z": 2,
      "name": "Rock_Ice_Permafrost"
    },
    {
      "x": -19,
      "y": 20,
      "z": 2,
      "name": "Rock_Ice_Permafrost"
    },
    {
      "x": -19,
      "y": 21,
      "z": 2,
      "name": "Rock_Ice_Permafrost"
    },
    {
      "x": -19,
      "y": 22,
      "z": 2,
      "name": "Rock_Ice_Permafrost"
    },
    {
      "x": -19,
      "y": 23,
      "z": 2,
      "name": "Rock_Ice"
    },
    {
      "x": -19,
      "y": 24,
      "z": 2,
      "name": "Rock_Ice_Permafrost"
    },
    {
      "x": -19,
      "y": 25,
      "z": 2,
      "name": "Rock_Ice_Permafrost"
    },
    {
      "x": -19,
      "y": 26,
      "z": 2,
      "name": "Rock_Ice"
    },
    {
      "x": -19,
      "y": 27,
      "z": 2,
      "name": "Rock_Ice"
    },
    {
      "x": -19,
      "y": 28,
      "z": 2,
      "name": "Rock_Ice"
    },
    {
      "x": -19,
      "y": 29,
      "z": 2,
      "name": "Rock_Ice"
    },
    {
      "x": -19,
      "y": 30,
      "z": 2,
      "name": "Rock_Ice"
    },
    {
      "x": -19,
      "y": 31,
      "z": 2,
      "name": "Rock_Ice"
    },
    {
      "x": -19,
      "y": 32,
      "z": 2,
      "name": "Rock_Ice"
    },
    {
      "x": -19,
      "y": 33,
      "z": 2,
      "name": "Rock_Ice_Permafrost"
    },
    {
      "x": -19,
      "y": 34,
      "z": 2,
      "name": "Rock_Ice_Permafrost"
    },
    {
      "x": -19,
      "y": 20,
      "z": 3,
      "name": "Rock_Ice_Permafrost"
    },
    {
      "x": -19,
      "y": 21,
      "z": 3,
      "name": "Rock_Ice_Permafrost"
    },
    {
      "x": -19,
      "y": 22,
      "z": 3,
      "name": "Rock_Ice_Permafrost"
    },
    {
      "x": -19,
      "y": 23,
      "z": 3,
      "name": "Rock_Ice_Permafrost"
    },
    {
      "x": -19,
      "y": 24,
      "z": 3,
      "name": "Rock_Ice_Permafrost"
    },
    {
      "x": -19,
      "y": 25,
      "z": 3,
      "name": "Rock_Ice_Permafrost"
    },
    {
      "x": -19,
      "y": 26,
      "z": 3,
      "name": "Rock_Ice"
    },
    {
      "x": -19,
      "y": 27,
      "z": 3,
      "name": "Rock_Ice"
    },
    {
      "x": -19,
      "y": 28,
      "z": 3,
      "name": "Rock_Ice"
    },
    {
      "x": -19,
      "y": 29,
      "z": 3,
      "name": "Rock_Ice"
    },
    {
      "x": -19,
      "y": 30,
      "z": 3,
      "name": "Rock_Ice"
    },
    {
      "x": -19,
      "y": 31,
      "z": 3,
      "name": "Rock_Ice"
    },
    {
      "x": -19,
      "y": 32,
      "z": 3,
      "name": "Rock_Ice"
    },
    {
      "x": -19,
      "y": 33,
      "z": 3,
      "name": "Rock_Ice"
    },
    {
      "x": -19,
      "y": 34,
      "z": 3,
      "name": "Rock_Ice_Permafrost"
    },
    {
      "x": -19,
      "y": 35,
      "z": 3,
      "name": "Rock_Ice_Permafrost"
    },
    {
      "x": -19,
      "y": 36,
      "z": 3,
      "name": "Soil_Snow"
    },
    {
      "x": -19,
      "y": 21,
      "z": 4,
      "name": "Rock_Ice_Permafrost"
    },
    {
      "x": -19,
      "y": 22,
      "z": 4,
      "name": "Rock_Ice_Permafrost"
    },
    {
      "x": -19,
      "y": 23,
      "z": 4,
      "name": "Rock_Ice_Permafrost"
    },
    {
      "x": -19,
      "y": 24,
      "z": 4,
      "name": "Rock_Ice_Permafrost"
    },
    {
      "x": -19,
      "y": 25,
      "z": 4,
      "name": "Rock_Ice"
    },
    {
      "x": -19,
      "y": 26,
      "z": 4,
      "name": "Rock_Ice"
    },
    {
      "x": -19,
      "y": 27,
      "z": 4,
      "name": "Rock_Ice"
    },
    {
      "x": -19,
      "y": 28,
      "z": 4,
      "name": "Rock_Ice"
    },
    {
      "x": -19,
      "y": 29,
      "z": 4,
      "name": "Rock_Ice"
    },
    {
      "x": -19,
      "y": 30,
      "z": 4,
      "name": "Rock_Ice"
    },
    {
      "x": -19,
      "y": 31,
      "z": 4,
      "name": "Rock_Ice"
    },
    {
      "x": -19,
      "y": 32,
      "z": 4,
      "name": "Rock_Ice"
    },
    {
      "x": -19,
      "y": 33,
      "z": 4,
      "name": "Rock_Ice"
    },
    {
      "x": -19,
      "y": 34,
      "z": 4,
      "name": "Rock_Ice"
    },
    {
      "x": -19,
      "y": 35,
      "z": 4,
      "name": "Rock_Ice_Permafrost"
    },
    {
      "x": -19,
      "y": 36,
      "z": 4,
      "name": "Soil_Snow"
    },
    {
      "x": -19,
      "y": 20,
      "z": 5,
      "name": "Rock_Ice"
    },
    {
      "x": -19,
      "y": 21,
      "z": 5,
      "name": "Rock_Ice"
    },
    {
      "x": -19,
      "y": 22,
      "z": 5,
      "name": "Rock_Ice"
    },
    {
      "x": -19,
      "y": 23,
      "z": 5,
      "name": "Rock_Ice"
    },
    {
      "x": -19,
      "y": 24,
      "z": 5,
      "name": "Rock_Ice_Permafrost"
    },
    {
      "x": -19,
      "y": 25,
      "z": 5,
      "name": "Rock_Ice"
    },
    {
      "x": -19,
      "y": 26,
      "z": 5,
      "name": "Rock_Ice"
    },
    {
      "x": -19,
      "y": 27,
      "z": 5,
      "name": "Rock_Ice"
    },
    {
      "x": -19,
      "y": 28,
      "z": 5,
      "name": "Rock_Ice"
    },
    {
      "x": -19,
      "y": 29,
      "z": 5,
      "name": "Rock_Ice"
    },
    {
      "x": -19,
      "y": 30,
      "z": 5,
      "name": "Rock_Ice"
    },
    {
      "x": -19,
      "y": 31,
      "z": 5,
      "name": "Rock_Ice"
    },
    {
      "x": -19,
      "y": 32,
      "z": 5,
      "name": "Rock_Ice"
    },
    {
      "x": -19,
      "y": 33,
      "z": 5,
      "name": "Rock_Ice"
    },
    {
      "x": -19,
      "y": 34,
      "z": 5,
      "name": "Rock_Ice"
    },
    {
      "x": -19,
      "y": 35,
      "z": 5,
      "name": "Rock_Ice"
    },
    {
      "x": -19,
      "y": 36,
      "z": 5,
      "name": "Soil_Snow"
    },
    {
      "x": -19,
      "y": 19,
      "z": 6,
      "name": "Rock_Ice"
    },
    {
      "x": -19,
      "y": 20,
      "z": 6,
      "name": "Rock_Ice"
    },
    {
      "x": -19,
      "y": 21,
      "z": 6,
      "name": "Rock_Ice"
    },
    {
      "x": -19,
      "y": 22,
      "z": 6,
      "name": "Rock_Ice"
    },
    {
      "x": -19,
      "y": 23,
      "z": 6,
      "name": "Rock_Ice"
    },
    {
      "x": -19,
      "y": 24,
      "z": 6,
      "name": "Rock_Ice_Permafrost"
    },
    {
      "x": -19,
      "y": 25,
      "z": 6,
      "name": "Rock_Ice"
    },
    {
      "x": -19,
      "y": 26,
      "z": 6,
      "name": "Rock_Ice"
    },
    {
      "x": -19,
      "y": 27,
      "z": 6,
      "name": "Rock_Ice"
    },
    {
      "x": -19,
      "y": 28,
      "z": 6,
      "name": "Rock_Ice"
    },
    {
      "x": -19,
      "y": 29,
      "z": 6,
      "name": "Rock_Ice"
    },
    {
      "x": -19,
      "y": 30,
      "z": 6,
      "name": "Rock_Ice"
    },
    {
      "x": -19,
      "y": 31,
      "z": 6,
      "name": "Rock_Ice"
    },
    {
      "x": -19,
      "y": 32,
      "z": 6,
      "name": "Rock_Ice"
    },
    {
      "x": -19,
      "y": 33,
      "z": 6,
      "name": "Rock_Ice"
    },
    {
      "x": -19,
      "y": 34,
      "z": 6,
      "name": "Rock_Ice"
    },
    {
      "x": -19,
      "y": 35,
      "z": 6,
      "name": "Soil_Snow"
    },
    {
      "x": -19,
      "y": 19,
      "z": 7,
      "name": "Rock_Ice"
    },
    {
      "x": -19,
      "y": 20,
      "z": 7,
      "name": "Rock_Ice"
    },
    {
      "x": -19,
      "y": 21,
      "z": 7,
      "name": "Rock_Ice"
    },
    {
      "x": -19,
      "y": 22,
      "z": 7,
      "name": "Rock_Ice"
    },
    {
      "x": -19,
      "y": 23,
      "z": 7,
      "name": "Rock_Ice"
    },
    {
      "x": -19,
      "y": 24,
      "z": 7,
      "name": "Rock_Ice_Permafrost"
    },
    {
      "x": -19,
      "y": 25,
      "z": 7,
      "name": "Rock_Ice_Permafrost"
    },
    {
      "x": -19,
      "y": 26,
      "z": 7,
      "name": "Rock_Ice"
    },
    {
      "x": -19,
      "y": 27,
      "z": 7,
      "name": "Rock_Ice"
    },
    {
      "x": -19,
      "y": 28,
      "z": 7,
      "name": "Rock_Ice"
    },
    {
      "x": -19,
      "y": 29,
      "z": 7,
      "name": "Rock_Ice"
    },
    {
      "x": -19,
      "y": 30,
      "z": 7,
      "name": "Rock_Ice"
    },
    {
      "x": -19,
      "y": 31,
      "z": 7,
      "name": "Rock_Ice"
    },
    {
      "x": -19,
      "y": 32,
      "z": 7,
      "name": "Rock_Ice"
    },
    {
      "x": -19,
      "y": 33,
      "z": 7,
      "name": "Rock_Ice"
    },
    {
      "x": -19,
      "y": 34,
      "z": 7,
      "name": "Rock_Ice"
    },
    {
      "x": -19,
      "y": 35,
      "z": 7,
      "name": "Soil_Snow"
    },
    {
      "x": -19,
      "y": 19,
      "z": 8,
      "name": "Rock_Ice"
    },
    {
      "x": -19,
      "y": 20,
      "z": 8,
      "name": "Rock_Ice"
    },
    {
      "x": -19,
      "y": 21,
      "z": 8,
      "name": "Rock_Ice"
    },
    {
      "x": -19,
      "y": 22,
      "z": 8,
      "name": "Rock_Ice"
    },
    {
      "x": -19,
      "y": 23,
      "z": 8,
      "name": "Rock_Ice"
    },
    {
      "x": -19,
      "y": 24,
      "z": 8,
      "name": "Rock_Ice_Permafrost"
    },
    {
      "x": -19,
      "y": 25,
      "z": 8,
      "name": "Rock_Ice_Permafrost"
    },
    {
      "x": -19,
      "y": 26,
      "z": 8,
      "name": "Rock_Ice"
    },
    {
      "x": -19,
      "y": 27,
      "z": 8,
      "name": "Rock_Ice"
    },
    {
      "x": -19,
      "y": 28,
      "z": 8,
      "name": "Rock_Ice"
    },
    {
      "x": -19,
      "y": 29,
      "z": 8,
      "name": "Rock_Ice"
    },
    {
      "x": -19,
      "y": 30,
      "z": 8,
      "name": "Rock_Ice"
    },
    {
      "x": -19,
      "y": 31,
      "z": 8,
      "name": "Rock_Ice"
    },
    {
      "x": -19,
      "y": 32,
      "z": 8,
      "name": "Rock_Ice"
    },
    {
      "x": -19,
      "y": 33,
      "z": 8,
      "name": "Rock_Ice"
    },
    {
      "x": -19,
      "y": 34,
      "z": 8,
      "name": "Rock_Ice"
    },
    {
      "x": -19,
      "y": 35,
      "z": 8,
      "name": "Soil_Snow"
    },
    {
      "x": -19,
      "y": 18,
      "z": 9,
      "name": "Rock_Ice"
    },
    {
      "x": -19,
      "y": 19,
      "z": 9,
      "name": "Rock_Ice"
    },
    {
      "x": -19,
      "y": 20,
      "z": 9,
      "name": "Rock_Ice"
    },
    {
      "x": -19,
      "y": 21,
      "z": 9,
      "name": "Rock_Ice"
    },
    {
      "x": -19,
      "y": 22,
      "z": 9,
      "name": "Rock_Ice"
    },
    {
      "x": -19,
      "y": 23,
      "z": 9,
      "name": "Rock_Ice_Permafrost"
    },
    {
      "x": -19,
      "y": 24,
      "z": 9,
      "name": "Rock_Ice_Permafrost"
    },
    {
      "x": -19,
      "y": 25,
      "z": 9,
      "name": "Rock_Ice_Permafrost"
    },
    {
      "x": -19,
      "y": 26,
      "z": 9,
      "name": "Rock_Ice"
    },
    {
      "x": -19,
      "y": 27,
      "z": 9,
      "name": "Rock_Ice"
    },
    {
      "x": -19,
      "y": 28,
      "z": 9,
      "name": "Rock_Ice"
    },
    {
      "x": -19,
      "y": 29,
      "z": 9,
      "name": "Rock_Ice"
    },
    {
      "x": -19,
      "y": 30,
      "z": 9,
      "name": "Rock_Ice"
    },
    {
      "x": -19,
      "y": 31,
      "z": 9,
      "name": "Rock_Ice"
    },
    {
      "x": -19,
      "y": 32,
      "z": 9,
      "name": "Rock_Ice"
    },
    {
      "x": -19,
      "y": 33,
      "z": 9,
      "name": "Rock_Ice"
    },
    {
      "x": -19,
      "y": 34,
      "z": 9,
      "name": "Rock_Ice"
    },
    {
      "x": -19,
      "y": 35,
      "z": 9,
      "name": "Soil_Snow"
    },
    {
      "x": -19,
      "y": 19,
      "z": 10,
      "name": "Rock_Ice"
    },
    {
      "x": -19,
      "y": 20,
      "z": 10,
      "name": "Rock_Ice"
    },
    {
      "x": -19,
      "y": 21,
      "z": 10,
      "name": "Rock_Ice"
    },
    {
      "x": -19,
      "y": 22,
      "z": 10,
      "name": "Rock_Ice"
    },
    {
      "x": -19,
      "y": 23,
      "z": 10,
      "name": "Rock_Ice_Permafrost"
    },
    {
      "x": -19,
      "y": 24,
      "z": 10,
      "name": "Rock_Ice_Permafrost"
    },
    {
      "x": -19,
      "y": 25,
      "z": 10,
      "name": "Rock_Ice_Permafrost"
    },
    {
      "x": -19,
      "y": 26,
      "z": 10,
      "name": "Rock_Ice"
    },
    {
      "x": -19,
      "y": 27,
      "z": 10,
      "name": "Rock_Ice"
    },
    {
      "x": -19,
      "y": 28,
      "z": 10,
      "name": "Rock_Ice"
    },
    {
      "x": -19,
      "y": 29,
      "z": 10,
      "name": "Rock_Ice"
    },
    {
      "x": -19,
      "y": 30,
      "z": 10,
      "name": "Rock_Ice"
    },
    {
      "x": -19,
      "y": 31,
      "z": 10,
      "name": "Rock_Ice"
    },
    {
      "x": -19,
      "y": 32,
      "z": 10,
      "name": "Soil_Snow"
    },
    {
      "x": -19,
      "y": 22,
      "z": 11,
      "name": "Rock_Ice"
    },
    {
      "x": -19,
      "y": 23,
      "z": 11,
      "name": "Rock_Ice"
    },
    {
      "x": -19,
      "y": 24,
      "z": 11,
      "name": "Rock_Ice_Permafrost"
    },
    {
      "x": -19,
      "y": 25,
      "z": 11,
      "name": "Rock_Ice_Permafrost"
    },
    {
      "x": -19,
      "y": 26,
      "z": 11,
      "name": "Rock_Ice_Permafrost"
    },
    {
      "x": -19,
      "y": 27,
      "z": 11,
      "name": "Rock_Ice"
    },
    {
      "x": -19,
      "y": 28,
      "z": 11,
      "name": "Rock_Ice"
    },
    {
      "x": -19,
      "y": 29,
      "z": 11,
      "name": "Rock_Ice"
    },
    {
      "x": -19,
      "y": 30,
      "z": 11,
      "name": "Rock_Ice"
    },
    {
      "x": -19,
      "y": 31,
      "z": 11,
      "name": "Soil_Snow"
    },
    {
      "x": -18,
      "y": 41,
      "z": -12,
      "name": "Rock_Ice"
    },
    {
      "x": -18,
      "y": 42,
      "z": -12,
      "name": "Rock_Ice"
    },
    {
      "x": -18,
      "y": 43,
      "z": -12,
      "name": "Soil_Snow"
    },
    {
      "x": -18,
      "y": 22,
      "z": -11,
      "name": "Rock_Ice"
    },
    {
      "x": -18,
      "y": 23,
      "z": -11,
      "name": "Rock_Ice"
    },
    {
      "x": -18,
      "y": 24,
      "z": -11,
      "name": "Rock_Ice"
    },
    {
      "x": -18,
      "y": 25,
      "z": -11,
      "name": "Rock_Ice"
    },
    {
      "x": -18,
      "y": 26,
      "z": -11,
      "name": "Rock_Ice"
    },
    {
      "x": -18,
      "y": 27,
      "z": -11,
      "name": "Rock_Ice"
    },
    {
      "x": -18,
      "y": 28,
      "z": -11,
      "name": "Rock_Ice"
    },
    {
      "x": -18,
      "y": 29,
      "z": -11,
      "name": "Rock_Ice"
    },
    {
      "x": -18,
      "y": 30,
      "z": -11,
      "name": "Rock_Ice_Permafrost"
    },
    {
      "x": -18,
      "y": 36,
      "z": -11,
      "name": "Rock_Ice"
    },
    {
      "x": -18,
      "y": 37,
      "z": -11,
      "name": "Rock_Ice"
    },
    {
      "x": -18,
      "y": 38,
      "z": -11,
      "name": "Rock_Ice"
    },
    {
      "x": -18,
      "y": 39,
      "z": -11,
      "name": "Rock_Ice"
    },
    {
      "x": -18,
      "y": 40,
      "z": -11,
      "name": "Rock_Ice"
    },
    {
      "x": -18,
      "y": 41,
      "z": -11,
      "name": "Rock_Ice"
    },
    {
      "x": -18,
      "y": 42,
      "z": -11,
      "name": "Rock_Ice"
    },
    {
      "x": -18,
      "y": 43,
      "z": -11,
      "name": "Rock_Ice"
    },
    {
      "x": -18,
      "y": 44,
      "z": -11,
      "name": "Soil_Snow"
    },
    {
      "x": -18,
      "y": 19,
      "z": -10,
      "name": "Rock_Ice"
    },
    {
      "x": -18,
      "y": 20,
      "z": -10,
      "name": "Rock_Ice"
    },
    {
      "x": -18,
      "y": 21,
      "z": -10,
      "name": "Rock_Ice"
    },
    {
      "x": -18,
      "y": 22,
      "z": -10,
      "name": "Rock_Ice"
    },
    {
      "x": -18,
      "y": 23,
      "z": -10,
      "name": "Rock_Ice"
    },
    {
      "x": -18,
      "y": 24,
      "z": -10,
      "name": "Rock_Ice"
    },
    {
      "x": -18,
      "y": 25,
      "z": -10,
      "name": "Rock_Ice"
    },
    {
      "x": -18,
      "y": 26,
      "z": -10,
      "name": "Rock_Ice"
    },
    {
      "x": -18,
      "y": 27,
      "z": -10,
      "name": "Rock_Ice"
    },
    {
      "x": -18,
      "y": 28,
      "z": -10,
      "name": "Rock_Ice"
    },
    {
      "x": -18,
      "y": 29,
      "z": -10,
      "name": "Rock_Ice"
    },
    {
      "x": -18,
      "y": 30,
      "z": -10,
      "name": "Rock_Ice"
    },
    {
      "x": -18,
      "y": 31,
      "z": -10,
      "name": "Rock_Ice_Permafrost"
    },
    {
      "x": -18,
      "y": 32,
      "z": -10,
      "name": "Rock_Ice_Permafrost"
    },
    {
      "x": -18,
      "y": 33,
      "z": -10,
      "name": "Rock_Ice_Permafrost"
    },
    {
      "x": -18,
      "y": 34,
      "z": -10,
      "name": "Rock_Ice"
    },
    {
      "x": -18,
      "y": 35,
      "z": -10,
      "name": "Rock_Ice"
    },
    {
      "x": -18,
      "y": 36,
      "z": -10,
      "name": "Rock_Ice"
    },
    {
      "x": -18,
      "y": 37,
      "z": -10,
      "name": "Rock_Ice_Permafrost"
    },
    {
      "x": -18,
      "y": 38,
      "z": -10,
      "name": "Rock_Ice_Permafrost"
    },
    {
      "x": -18,
      "y": 39,
      "z": -10,
      "name": "Rock_Ice"
    },
    {
      "x": -18,
      "y": 40,
      "z": -10,
      "name": "Rock_Ice"
    },
    {
      "x": -18,
      "y": 41,
      "z": -10,
      "name": "Rock_Ice_Permafrost"
    },
    {
      "x": -18,
      "y": 42,
      "z": -10,
      "name": "Rock_Ice"
    },
    {
      "x": -18,
      "y": 43,
      "z": -10,
      "name": "Rock_Ice"
    },
    {
      "x": -18,
      "y": 44,
      "z": -10,
      "name": "Rock_Ice"
    },
    {
      "x": -18,
      "y": 45,
      "z": -10,
      "name": "Soil_Snow"
    },
    {
      "x": -18,
      "y": 16,
      "z": -9,
      "name": "Rock_Ice"
    },
    {
      "x": -18,
      "y": 17,
      "z": -9,
      "name": "Rock_Ice_Permafrost"
    },
    {
      "x": -18,
      "y": 18,
      "z": -9,
      "name": "Rock_Ice_Permafrost"
    },
    {
      "x": -18,
      "y": 19,
      "z": -9,
      "name": "Rock_Ice"
    },
    {
      "x": -18,
      "y": 20,
      "z": -9,
      "name": "Rock_Ice"
    },
    {
      "x": -18,
      "y": 21,
      "z": -9,
      "name": "Rock_Ice"
    },
    {
      "x": -18,
      "y": 22,
      "z": -9,
      "name": "Rock_Ice"
    },
    {
      "x": -18,
      "y": 23,
      "z": -9,
      "name": "Rock_Ice"
    },
    {
      "x": -18,
      "y": 24,
      "z": -9,
      "name": "Rock_Ice"
    },
    {
      "x": -18,
      "y": 25,
      "z": -9,
      "name": "Rock_Ice"
    },
    {
      "x": -18,
      "y": 26,
      "z": -9,
      "name": "Rock_Ice"
    },
    {
      "x": -18,
      "y": 27,
      "z": -9,
      "name": "Rock_Ice"
    },
    {
      "x": -18,
      "y": 28,
      "z": -9,
      "name": "Rock_Ice"
    },
    {
      "x": -18,
      "y": 29,
      "z": -9,
      "name": "Rock_Ice"
    },
    {
      "x": -18,
      "y": 30,
      "z": -9,
      "name": "Rock_Ice"
    },
    {
      "x": -18,
      "y": 31,
      "z": -9,
      "name": "Rock_Ice"
    },
    {
      "x": -18,
      "y": 32,
      "z": -9,
      "name": "Rock_Ice"
    },
    {
      "x": -18,
      "y": 33,
      "z": -9,
      "name": "Rock_Ice_Permafrost"
    },
    {
      "x": -18,
      "y": 34,
      "z": -9,
      "name": "Rock_Ice_Permafrost"
    },
    {
      "x": -18,
      "y": 35,
      "z": -9,
      "name": "Rock_Ice_Permafrost"
    },
    {
      "x": -18,
      "y": 36,
      "z": -9,
      "name": "Rock_Ice_Permafrost"
    },
    {
      "x": -18,
      "y": 37,
      "z": -9,
      "name": "Rock_Ice_Permafrost"
    },
    {
      "x": -18,
      "y": 38,
      "z": -9,
      "name": "Rock_Ice_Permafrost"
    },
    {
      "x": -18,
      "y": 39,
      "z": -9,
      "name": "Rock_Ice_Permafrost"
    },
    {
      "x": -18,
      "y": 40,
      "z": -9,
      "name": "Rock_Ice_Permafrost"
    },
    {
      "x": -18,
      "y": 41,
      "z": -9,
      "name": "Rock_Ice_Permafrost"
    },
    {
      "x": -18,
      "y": 42,
      "z": -9,
      "name": "Rock_Ice_Permafrost"
    },
    {
      "x": -18,
      "y": 43,
      "z": -9,
      "name": "Rock_Ice_Permafrost"
    },
    {
      "x": -18,
      "y": 44,
      "z": -9,
      "name": "Rock_Ice"
    },
    {
      "x": -18,
      "y": 45,
      "z": -9,
      "name": "Soil_Snow"
    },
    {
      "x": -18,
      "y": 17,
      "z": -8,
      "name": "Rock_Ice_Permafrost"
    },
    {
      "x": -18,
      "y": 18,
      "z": -8,
      "name": "Rock_Ice"
    },
    {
      "x": -18,
      "y": 19,
      "z": -8,
      "name": "Rock_Ice"
    },
    {
      "x": -18,
      "y": 20,
      "z": -8,
      "name": "Rock_Ice"
    },
    {
      "x": -18,
      "y": 21,
      "z": -8,
      "name": "Rock_Ice"
    },
    {
      "x": -18,
      "y": 22,
      "z": -8,
      "name": "Rock_Ice"
    },
    {
      "x": -18,
      "y": 23,
      "z": -8,
      "name": "Rock_Ice"
    },
    {
      "x": -18,
      "y": 24,
      "z": -8,
      "name": "Rock_Ice"
    },
    {
      "x": -18,
      "y": 25,
      "z": -8,
      "name": "Rock_Ice"
    },
    {
      "x": -18,
      "y": 26,
      "z": -8,
      "name": "Rock_Ice"
    },
    {
      "x": -18,
      "y": 27,
      "z": -8,
      "name": "Rock_Ice"
    },
    {
      "x": -18,
      "y": 28,
      "z": -8,
      "name": "Rock_Ice"
    },
    {
      "x": -18,
      "y": 29,
      "z": -8,
      "name": "Rock_Ice"
    },
    {
      "x": -18,
      "y": 30,
      "z": -8,
      "name": "Rock_Ice"
    },
    {
      "x": -18,
      "y": 31,
      "z": -8,
      "name": "Rock_Ice"
    },
    {
      "x": -18,
      "y": 32,
      "z": -8,
      "name": "Rock_Ice_Permafrost"
    },
    {
      "x": -18,
      "y": 33,
      "z": -8,
      "name": "Rock_Ice_Permafrost"
    },
    {
      "x": -18,
      "y": 34,
      "z": -8,
      "name": "Rock_Ice_Permafrost"
    },
    {
      "x": -18,
      "y": 35,
      "z": -8,
      "name": "Rock_Ice_Permafrost"
    },
    {
      "x": -18,
      "y": 36,
      "z": -8,
      "name": "Rock_Ice_Permafrost"
    },
    {
      "x": -18,
      "y": 37,
      "z": -8,
      "name": "Rock_Ice"
    },
    {
      "x": -18,
      "y": 38,
      "z": -8,
      "name": "Rock_Ice"
    },
    {
      "x": -18,
      "y": 39,
      "z": -8,
      "name": "Rock_Ice"
    },
    {
      "x": -18,
      "y": 40,
      "z": -8,
      "name": "Rock_Ice_Permafrost"
    },
    {
      "x": -18,
      "y": 41,
      "z": -8,
      "name": "Rock_Ice"
    },
    {
      "x": -18,
      "y": 42,
      "z": -8,
      "name": "Rock_Ice"
    },
    {
      "x": -18,
      "y": 43,
      "z": -8,
      "name": "Rock_Ice"
    },
    {
      "x": -18,
      "y": 44,
      "z": -8,
      "name": "Rock_Ice"
    },
    {
      "x": -18,
      "y": 45,
      "z": -8,
      "name": "Soil_Snow"
    },
    {
      "x": -18,
      "y": 17,
      "z": -7,
      "name": "Rock_Ice_Permafrost"
    },
    {
      "x": -18,
      "y": 18,
      "z": -7,
      "name": "Rock_Ice_Permafrost"
    },
    {
      "x": -18,
      "y": 19,
      "z": -7,
      "name": "Rock_Ice"
    },
    {
      "x": -18,
      "y": 20,
      "z": -7,
      "name": "Rock_Ice"
    },
    {
      "x": -18,
      "y": 21,
      "z": -7,
      "name": "Rock_Ice"
    },
    {
      "x": -18,
      "y": 22,
      "z": -7,
      "name": "Rock_Ice"
    },
    {
      "x": -18,
      "y": 23,
      "z": -7,
      "name": "Rock_Ice"
    },
    {
      "x": -18,
      "y": 24,
      "z": -7,
      "name": "Rock_Ice"
    },
    {
      "x": -18,
      "y": 25,
      "z": -7,
      "name": "Rock_Ice"
    },
    {
      "x": -18,
      "y": 26,
      "z": -7,
      "name": "Rock_Ice"
    },
    {
      "x": -18,
      "y": 27,
      "z": -7,
      "name": "Rock_Ice"
    },
    {
      "x": -18,
      "y": 28,
      "z": -7,
      "name": "Rock_Ice"
    },
    {
      "x": -18,
      "y": 29,
      "z": -7,
      "name": "Rock_Ice"
    },
    {
      "x": -18,
      "y": 30,
      "z": -7,
      "name": "Rock_Ice"
    },
    {
      "x": -18,
      "y": 31,
      "z": -7,
      "name": "Rock_Ice"
    },
    {
      "x": -18,
      "y": 32,
      "z": -7,
      "name": "Rock_Ice"
    },
    {
      "x": -18,
      "y": 33,
      "z": -7,
      "name": "Rock_Ice_Permafrost"
    },
    {
      "x": -18,
      "y": 34,
      "z": -7,
      "name": "Rock_Ice_Permafrost"
    },
    {
      "x": -18,
      "y": 35,
      "z": -7,
      "name": "Rock_Ice_Permafrost"
    },
    {
      "x": -18,
      "y": 36,
      "z": -7,
      "name": "Rock_Ice"
    },
    {
      "x": -18,
      "y": 37,
      "z": -7,
      "name": "Rock_Ice"
    },
    {
      "x": -18,
      "y": 38,
      "z": -7,
      "name": "Rock_Ice"
    },
    {
      "x": -18,
      "y": 39,
      "z": -7,
      "name": "Rock_Ice"
    },
    {
      "x": -18,
      "y": 40,
      "z": -7,
      "name": "Rock_Ice"
    },
    {
      "x": -18,
      "y": 41,
      "z": -7,
      "name": "Rock_Ice"
    },
    {
      "x": -18,
      "y": 42,
      "z": -7,
      "name": "Rock_Ice"
    },
    {
      "x": -18,
      "y": 43,
      "z": -7,
      "name": "Rock_Ice"
    },
    {
      "x": -18,
      "y": 44,
      "z": -7,
      "name": "Soil_Snow"
    },
    {
      "x": -18,
      "y": 17,
      "z": -6,
      "name": "Rock_Ice_Permafrost"
    },
    {
      "x": -18,
      "y": 18,
      "z": -6,
      "name": "Rock_Ice"
    },
    {
      "x": -18,
      "y": 19,
      "z": -6,
      "name": "Rock_Ice"
    },
    {
      "x": -18,
      "y": 20,
      "z": -6,
      "name": "Rock_Ice"
    },
    {
      "x": -18,
      "y": 21,
      "z": -6,
      "name": "Rock_Ice"
    },
    {
      "x": -18,
      "y": 22,
      "z": -6,
      "name": "Rock_Ice"
    },
    {
      "x": -18,
      "y": 23,
      "z": -6,
      "name": "Rock_Ice"
    },
    {
      "x": -18,
      "y": 24,
      "z": -6,
      "name": "Rock_Ice"
    },
    {
      "x": -18,
      "y": 25,
      "z": -6,
      "name": "Rock_Ice"
    },
    {
      "x": -18,
      "y": 26,
      "z": -6,
      "name": "Rock_Ice"
    },
    {
      "x": -18,
      "y": 27,
      "z": -6,
      "name": "Rock_Ice"
    },
    {
      "x": -18,
      "y": 28,
      "z": -6,
      "name": "Rock_Ice"
    },
    {
      "x": -18,
      "y": 29,
      "z": -6,
      "name": "Rock_Ice"
    },
    {
      "x": -18,
      "y": 30,
      "z": -6,
      "name": "Rock_Ice"
    },
    {
      "x": -18,
      "y": 31,
      "z": -6,
      "name": "Rock_Ice"
    },
    {
      "x": -18,
      "y": 32,
      "z": -6,
      "name": "Rock_Ice"
    },
    {
      "x": -18,
      "y": 33,
      "z": -6,
      "name": "Rock_Ice_Permafrost"
    },
    {
      "x": -18,
      "y": 34,
      "z": -6,
      "name": "Rock_Ice_Permafrost"
    },
    {
      "x": -18,
      "y": 35,
      "z": -6,
      "name": "Rock_Ice_Permafrost"
    },
    {
      "x": -18,
      "y": 36,
      "z": -6,
      "name": "Rock_Ice"
    },
    {
      "x": -18,
      "y": 37,
      "z": -6,
      "name": "Rock_Ice"
    },
    {
      "x": -18,
      "y": 38,
      "z": -6,
      "name": "Rock_Ice"
    },
    {
      "x": -18,
      "y": 39,
      "z": -6,
      "name": "Rock_Ice"
    },
    {
      "x": -18,
      "y": 40,
      "z": -6,
      "name": "Rock_Ice"
    },
    {
      "x": -18,
      "y": 41,
      "z": -6,
      "name": "Rock_Ice"
    },
    {
      "x": -18,
      "y": 42,
      "z": -6,
      "name": "Rock_Ice"
    },
    {
      "x": -18,
      "y": 43,
      "z": -6,
      "name": "Rock_Ice"
    },
    {
      "x": -18,
      "y": 44,
      "z": -6,
      "name": "Soil_Snow"
    },
    {
      "x": -18,
      "y": 17,
      "z": -5,
      "name": "Rock_Ice_Permafrost"
    },
    {
      "x": -18,
      "y": 18,
      "z": -5,
      "name": "Rock_Ice"
    },
    {
      "x": -18,
      "y": 19,
      "z": -5,
      "name": "Rock_Ice"
    },
    {
      "x": -18,
      "y": 20,
      "z": -5,
      "name": "Rock_Ice"
    },
    {
      "x": -18,
      "y": 21,
      "z": -5,
      "name": "Rock_Ice"
    },
    {
      "x": -18,
      "y": 22,
      "z": -5,
      "name": "Rock_Ice"
    },
    {
      "x": -18,
      "y": 23,
      "z": -5,
      "name": "Rock_Ice"
    },
    {
      "x": -18,
      "y": 24,
      "z": -5,
      "name": "Rock_Ice"
    },
    {
      "x": -18,
      "y": 25,
      "z": -5,
      "name": "Rock_Ice"
    },
    {
      "x": -18,
      "y": 26,
      "z": -5,
      "name": "Rock_Ice"
    },
    {
      "x": -18,
      "y": 27,
      "z": -5,
      "name": "Rock_Ice"
    },
    {
      "x": -18,
      "y": 28,
      "z": -5,
      "name": "Rock_Ice"
    },
    {
      "x": -18,
      "y": 29,
      "z": -5,
      "name": "Rock_Ice"
    },
    {
      "x": -18,
      "y": 30,
      "z": -5,
      "name": "Rock_Ice"
    },
    {
      "x": -18,
      "y": 31,
      "z": -5,
      "name": "Rock_Ice"
    },
    {
      "x": -18,
      "y": 32,
      "z": -5,
      "name": "Rock_Ice"
    },
    {
      "x": -18,
      "y": 33,
      "z": -5,
      "name": "Rock_Ice_Permafrost"
    },
    {
      "x": -18,
      "y": 34,
      "z": -5,
      "name": "Rock_Ice_Permafrost"
    },
    {
      "x": -18,
      "y": 35,
      "z": -5,
      "name": "Rock_Ice_Permafrost"
    },
    {
      "x": -18,
      "y": 36,
      "z": -5,
      "name": "Rock_Ice"
    },
    {
      "x": -18,
      "y": 37,
      "z": -5,
      "name": "Rock_Ice"
    },
    {
      "x": -18,
      "y": 38,
      "z": -5,
      "name": "Rock_Ice"
    },
    {
      "x": -18,
      "y": 39,
      "z": -5,
      "name": "Rock_Ice"
    },
    {
      "x": -18,
      "y": 40,
      "z": -5,
      "name": "Rock_Ice"
    },
    {
      "x": -18,
      "y": 41,
      "z": -5,
      "name": "Rock_Ice"
    },
    {
      "x": -18,
      "y": 42,
      "z": -5,
      "name": "Rock_Ice"
    },
    {
      "x": -18,
      "y": 43,
      "z": -5,
      "name": "Rock_Ice"
    },
    {
      "x": -18,
      "y": 44,
      "z": -5,
      "name": "Rock_Ice"
    },
    {
      "x": -18,
      "y": 45,
      "z": -5,
      "name": "Soil_Snow"
    },
    {
      "x": -18,
      "y": 17,
      "z": -4,
      "name": "Rock_Ice_Permafrost"
    },
    {
      "x": -18,
      "y": 18,
      "z": -4,
      "name": "Rock_Ice_Permafrost"
    },
    {
      "x": -18,
      "y": 19,
      "z": -4,
      "name": "Rock_Ice"
    },
    {
      "x": -18,
      "y": 20,
      "z": -4,
      "name": "Rock_Ice"
    },
    {
      "x": -18,
      "y": 21,
      "z": -4,
      "name": "Rock_Ice"
    },
    {
      "x": -18,
      "y": 22,
      "z": -4,
      "name": "Rock_Ice"
    },
    {
      "x": -18,
      "y": 23,
      "z": -4,
      "name": "Rock_Ice"
    },
    {
      "x": -18,
      "y": 24,
      "z": -4,
      "name": "Rock_Ice"
    },
    {
      "x": -18,
      "y": 25,
      "z": -4,
      "name": "Rock_Ice"
    },
    {
      "x": -18,
      "y": 26,
      "z": -4,
      "name": "Rock_Ice"
    },
    {
      "x": -18,
      "y": 27,
      "z": -4,
      "name": "Rock_Ice"
    },
    {
      "x": -18,
      "y": 28,
      "z": -4,
      "name": "Rock_Ice"
    },
    {
      "x": -18,
      "y": 29,
      "z": -4,
      "name": "Rock_Ice"
    },
    {
      "x": -18,
      "y": 30,
      "z": -4,
      "name": "Rock_Ice"
    },
    {
      "x": -18,
      "y": 31,
      "z": -4,
      "name": "Rock_Ice"
    },
    {
      "x": -18,
      "y": 32,
      "z": -4,
      "name": "Rock_Ice"
    },
    {
      "x": -18,
      "y": 33,
      "z": -4,
      "name": "Rock_Ice_Permafrost"
    },
    {
      "x": -18,
      "y": 34,
      "z": -4,
      "name": "Rock_Ice_Permafrost"
    },
    {
      "x": -18,
      "y": 35,
      "z": -4,
      "name": "Rock_Ice_Permafrost"
    },
    {
      "x": -18,
      "y": 36,
      "z": -4,
      "name": "Rock_Ice_Permafrost"
    },
    {
      "x": -18,
      "y": 37,
      "z": -4,
      "name": "Rock_Ice"
    },
    {
      "x": -18,
      "y": 38,
      "z": -4,
      "name": "Rock_Ice"
    },
    {
      "x": -18,
      "y": 39,
      "z": -4,
      "name": "Rock_Ice"
    },
    {
      "x": -18,
      "y": 40,
      "z": -4,
      "name": "Rock_Ice"
    },
    {
      "x": -18,
      "y": 41,
      "z": -4,
      "name": "Rock_Ice"
    },
    {
      "x": -18,
      "y": 42,
      "z": -4,
      "name": "Rock_Ice"
    },
    {
      "x": -18,
      "y": 43,
      "z": -4,
      "name": "Soil_Snow"
    },
    {
      "x": -18,
      "y": 17,
      "z": -3,
      "name": "Rock_Ice_Permafrost"
    },
    {
      "x": -18,
      "y": 18,
      "z": -3,
      "name": "Rock_Ice_Permafrost"
    },
    {
      "x": -18,
      "y": 19,
      "z": -3,
      "name": "Rock_Ice"
    },
    {
      "x": -18,
      "y": 20,
      "z": -3,
      "name": "Rock_Ice"
    },
    {
      "x": -18,
      "y": 21,
      "z": -3,
      "name": "Rock_Ice"
    },
    {
      "x": -18,
      "y": 22,
      "z": -3,
      "name": "Rock_Ice"
    },
    {
      "x": -18,
      "y": 23,
      "z": -3,
      "name": "Rock_Ice"
    },
    {
      "x": -18,
      "y": 24,
      "z": -3,
      "name": "Rock_Ice"
    },
    {
      "x": -18,
      "y": 25,
      "z": -3,
      "name": "Rock_Ice"
    },
    {
      "x": -18,
      "y": 26,
      "z": -3,
      "name": "Rock_Ice"
    },
    {
      "x": -18,
      "y": 27,
      "z": -3,
      "name": "Rock_Ice"
    },
    {
      "x": -18,
      "y": 28,
      "z": -3,
      "name": "Rock_Ice"
    },
    {
      "x": -18,
      "y": 29,
      "z": -3,
      "name": "Rock_Ice"
    },
    {
      "x": -18,
      "y": 30,
      "z": -3,
      "name": "Rock_Ice"
    },
    {
      "x": -18,
      "y": 31,
      "z": -3,
      "name": "Rock_Ice"
    },
    {
      "x": -18,
      "y": 32,
      "z": -3,
      "name": "Rock_Ice_Permafrost"
    },
    {
      "x": -18,
      "y": 33,
      "z": -3,
      "name": "Rock_Ice_Permafrost"
    },
    {
      "x": -18,
      "y": 34,
      "z": -3,
      "name": "Rock_Ice_Permafrost"
    },
    {
      "x": -18,
      "y": 35,
      "z": -3,
      "name": "Rock_Ice_Permafrost"
    },
    {
      "x": -18,
      "y": 36,
      "z": -3,
      "name": "Rock_Ice_Permafrost"
    },
    {
      "x": -18,
      "y": 37,
      "z": -3,
      "name": "Rock_Ice"
    },
    {
      "x": -18,
      "y": 38,
      "z": -3,
      "name": "Rock_Ice"
    },
    {
      "x": -18,
      "y": 39,
      "z": -3,
      "name": "Rock_Ice"
    },
    {
      "x": -18,
      "y": 40,
      "z": -3,
      "name": "Rock_Ice"
    },
    {
      "x": -18,
      "y": 41,
      "z": -3,
      "name": "Rock_Ice"
    },
    {
      "x": -18,
      "y": 42,
      "z": -3,
      "name": "Soil_Snow"
    },
    {
      "x": -18,
      "y": 17,
      "z": -2,
      "name": "Rock_Ice_Permafrost"
    },
    {
      "x": -18,
      "y": 18,
      "z": -2,
      "name": "Rock_Ice_Permafrost"
    },
    {
      "x": -18,
      "y": 19,
      "z": -2,
      "name": "Rock_Ice_Permafrost"
    },
    {
      "x": -18,
      "y": 20,
      "z": -2,
      "name": "Rock_Ice"
    },
    {
      "x": -18,
      "y": 21,
      "z": -2,
      "name": "Rock_Ice_Permafrost"
    },
    {
      "x": -18,
      "y": 22,
      "z": -2,
      "name": "Rock_Ice"
    },
    {
      "x": -18,
      "y": 23,
      "z": -2,
      "name": "Rock_Ice"
    },
    {
      "x": -18,
      "y": 24,
      "z": -2,
      "name": "Rock_Ice"
    },
    {
      "x": -18,
      "y": 25,
      "z": -2,
      "name": "Rock_Ice"
    },
    {
      "x": -18,
      "y": 26,
      "z": -2,
      "name": "Rock_Ice"
    },
    {
      "x": -18,
      "y": 27,
      "z": -2,
      "name": "Rock_Ice"
    },
    {
      "x": -18,
      "y": 28,
      "z": -2,
      "name": "Rock_Ice"
    },
    {
      "x": -18,
      "y": 29,
      "z": -2,
      "name": "Rock_Ice_Permafrost"
    },
    {
      "x": -18,
      "y": 30,
      "z": -2,
      "name": "Rock_Ice_Permafrost"
    },
    {
      "x": -18,
      "y": 31,
      "z": -2,
      "name": "Rock_Ice_Permafrost"
    },
    {
      "x": -18,
      "y": 32,
      "z": -2,
      "name": "Rock_Ice_Permafrost"
    },
    {
      "x": -18,
      "y": 33,
      "z": -2,
      "name": "Rock_Ice_Permafrost"
    },
    {
      "x": -18,
      "y": 34,
      "z": -2,
      "name": "Rock_Ice_Permafrost"
    },
    {
      "x": -18,
      "y": 35,
      "z": -2,
      "name": "Rock_Ice_Permafrost"
    },
    {
      "x": -18,
      "y": 36,
      "z": -2,
      "name": "Rock_Ice_Permafrost"
    },
    {
      "x": -18,
      "y": 37,
      "z": -2,
      "name": "Rock_Ice_Permafrost"
    },
    {
      "x": -18,
      "y": 38,
      "z": -2,
      "name": "Rock_Ice"
    },
    {
      "x": -18,
      "y": 39,
      "z": -2,
      "name": "Rock_Ice"
    },
    {
      "x": -18,
      "y": 40,
      "z": -2,
      "name": "Rock_Ice"
    },
    {
      "x": -18,
      "y": 41,
      "z": -2,
      "name": "Soil_Snow"
    },
    {
      "x": -18,
      "y": 17,
      "z": -1,
      "name": "Rock_Ice_Permafrost"
    },
    {
      "x": -18,
      "y": 18,
      "z": -1,
      "name": "Rock_Ice_Permafrost"
    },
    {
      "x": -18,
      "y": 19,
      "z": -1,
      "name": "Rock_Ice_Permafrost"
    },
    {
      "x": -18,
      "y": 20,
      "z": -1,
      "name": "Rock_Ice_Permafrost"
    },
    {
      "x": -18,
      "y": 21,
      "z": -1,
      "name": "Rock_Ice_Permafrost"
    },
    {
      "x": -18,
      "y": 22,
      "z": -1,
      "name": "Rock_Ice_Permafrost"
    },
    {
      "x": -18,
      "y": 23,
      "z": -1,
      "name": "Rock_Ice"
    },
    {
      "x": -18,
      "y": 24,
      "z": -1,
      "name": "Rock_Ice"
    },
    {
      "x": -18,
      "y": 25,
      "z": -1,
      "name": "Rock_Ice_Permafrost"
    },
    {
      "x": -18,
      "y": 26,
      "z": -1,
      "name": "Rock_Ice"
    },
    {
      "x": -18,
      "y": 27,
      "z": -1,
      "name": "Rock_Ice_Permafrost"
    },
    {
      "x": -18,
      "y": 28,
      "z": -1,
      "name": "Rock_Ice_Permafrost"
    },
    {
      "x": -18,
      "y": 29,
      "z": -1,
      "name": "Rock_Ice_Permafrost"
    },
    {
      "x": -18,
      "y": 30,
      "z": -1,
      "name": "Rock_Ice_Permafrost"
    },
    {
      "x": -18,
      "y": 31,
      "z": -1,
      "name": "Rock_Ice_Permafrost"
    },
    {
      "x": -18,
      "y": 32,
      "z": -1,
      "name": "Rock_Ice_Permafrost"
    },
    {
      "x": -18,
      "y": 33,
      "z": -1,
      "name": "Rock_Ice_Permafrost"
    },
    {
      "x": -18,
      "y": 34,
      "z": -1,
      "name": "Rock_Ice_Permafrost"
    },
    {
      "x": -18,
      "y": 35,
      "z": -1,
      "name": "Rock_Ice"
    },
    {
      "x": -18,
      "y": 36,
      "z": -1,
      "name": "Rock_Ice"
    },
    {
      "x": -18,
      "y": 37,
      "z": -1,
      "name": "Rock_Ice_Permafrost"
    },
    {
      "x": -18,
      "y": 38,
      "z": -1,
      "name": "Rock_Ice_Permafrost"
    },
    {
      "x": -18,
      "y": 39,
      "z": -1,
      "name": "Rock_Ice"
    },
    {
      "x": -18,
      "y": 40,
      "z": -1,
      "name": "Soil_Snow"
    },
    {
      "x": -18,
      "y": 17,
      "z": 0,
      "name": "Rock_Ice_Permafrost"
    },
    {
      "x": -18,
      "y": 18,
      "z": 0,
      "name": "Rock_Ice_Permafrost"
    },
    {
      "x": -18,
      "y": 19,
      "z": 0,
      "name": "Rock_Ice_Permafrost"
    },
    {
      "x": -18,
      "y": 20,
      "z": 0,
      "name": "Rock_Ice_Permafrost"
    },
    {
      "x": -18,
      "y": 21,
      "z": 0,
      "name": "Rock_Ice_Permafrost"
    },
    {
      "x": -18,
      "y": 22,
      "z": 0,
      "name": "Rock_Ice_Permafrost"
    },
    {
      "x": -18,
      "y": 23,
      "z": 0,
      "name": "Rock_Ice_Permafrost"
    },
    {
      "x": -18,
      "y": 24,
      "z": 0,
      "name": "Rock_Ice_Permafrost"
    },
    {
      "x": -18,
      "y": 25,
      "z": 0,
      "name": "Rock_Ice_Permafrost"
    },
    {
      "x": -18,
      "y": 26,
      "z": 0,
      "name": "Rock_Ice_Permafrost"
    },
    {
      "x": -18,
      "y": 27,
      "z": 0,
      "name": "Rock_Ice_Permafrost"
    },
    {
      "x": -18,
      "y": 28,
      "z": 0,
      "name": "Rock_Ice"
    },
    {
      "x": -18,
      "y": 29,
      "z": 0,
      "name": "Rock_Ice"
    },
    {
      "x": -18,
      "y": 30,
      "z": 0,
      "name": "Rock_Ice"
    },
    {
      "x": -18,
      "y": 31,
      "z": 0,
      "name": "Rock_Ice_Permafrost"
    },
    {
      "x": -18,
      "y": 32,
      "z": 0,
      "name": "Rock_Ice_Permafrost"
    },
    {
      "x": -18,
      "y": 33,
      "z": 0,
      "name": "Rock_Ice_Permafrost"
    },
    {
      "x": -18,
      "y": 34,
      "z": 0,
      "name": "Rock_Ice_Permafrost"
    },
    {
      "x": -18,
      "y": 35,
      "z": 0,
      "name": "Rock_Ice"
    },
    {
      "x": -18,
      "y": 36,
      "z": 0,
      "name": "Rock_Ice"
    },
    {
      "x": -18,
      "y": 37,
      "z": 0,
      "name": "Rock_Ice"
    },
    {
      "x": -18,
      "y": 38,
      "z": 0,
      "name": "Soil_Snow"
    },
    {
      "x": -18,
      "y": 17,
      "z": 1,
      "name": "Rock_Ice_Permafrost"
    },
    {
      "x": -18,
      "y": 18,
      "z": 1,
      "name": "Rock_Ice_Permafrost"
    },
    {
      "x": -18,
      "y": 19,
      "z": 1,
      "name": "Rock_Ice_Permafrost"
    },
    {
      "x": -18,
      "y": 20,
      "z": 1,
      "name": "Rock_Ice_Permafrost"
    },
    {
      "x": -18,
      "y": 21,
      "z": 1,
      "name": "Rock_Ice_Permafrost"
    },
    {
      "x": -18,
      "y": 22,
      "z": 1,
      "name": "Rock_Ice_Permafrost"
    },
    {
      "x": -18,
      "y": 23,
      "z": 1,
      "name": "Rock_Ice_Permafrost"
    },
    {
      "x": -18,
      "y": 24,
      "z": 1,
      "name": "Rock_Ice_Permafrost"
    },
    {
      "x": -18,
      "y": 25,
      "z": 1,
      "name": "Rock_Ice"
    },
    {
      "x": -18,
      "y": 26,
      "z": 1,
      "name": "Rock_Ice"
    },
    {
      "x": -18,
      "y": 27,
      "z": 1,
      "name": "Rock_Ice"
    },
    {
      "x": -18,
      "y": 28,
      "z": 1,
      "name": "Rock_Ice"
    },
    {
      "x": -18,
      "y": 29,
      "z": 1,
      "name": "Rock_Ice"
    },
    {
      "x": -18,
      "y": 30,
      "z": 1,
      "name": "Rock_Ice"
    },
    {
      "x": -18,
      "y": 31,
      "z": 1,
      "name": "Rock_Ice"
    },
    {
      "x": -18,
      "y": 32,
      "z": 1,
      "name": "Rock_Ice_Permafrost"
    },
    {
      "x": -18,
      "y": 33,
      "z": 1,
      "name": "Rock_Ice_Permafrost"
    },
    {
      "x": -18,
      "y": 34,
      "z": 1,
      "name": "Rock_Ice_Permafrost"
    },
    {
      "x": -18,
      "y": 35,
      "z": 1,
      "name": "Rock_Ice"
    },
    {
      "x": -18,
      "y": 36,
      "z": 1,
      "name": "Soil_Snow"
    },
    {
      "x": -18,
      "y": 17,
      "z": 2,
      "name": "Rock_Ice_Permafrost"
    },
    {
      "x": -18,
      "y": 18,
      "z": 2,
      "name": "Rock_Ice_Permafrost"
    },
    {
      "x": -18,
      "y": 19,
      "z": 2,
      "name": "Rock_Ice_Permafrost"
    },
    {
      "x": -18,
      "y": 20,
      "z": 2,
      "name": "Rock_Ice_Permafrost"
    },
    {
      "x": -18,
      "y": 21,
      "z": 2,
      "name": "Rock_Ice_Permafrost"
    },
    {
      "x": -18,
      "y": 22,
      "z": 2,
      "name": "Rock_Ice_Permafrost"
    },
    {
      "x": -18,
      "y": 23,
      "z": 2,
