{
  "version": 8,
  "blockIdVersion": 11,
  "anchorX": -2,
  "anchorY": 13,
  "anchorZ": -1,
  "blocks": [
    {
      "x": -21,
      "y": 31,
      "z": -2,
      "name": "Soil_Snow"
    },
    {
      "x": -21,
      "y": 31,
      "z": -1,
      "name": "Soil_Snow"
    },
    {
      "x": -20,
      "y": 30,
      "z": -3,
      "name": "Rock_Ice_Permafrost"
    },
    {
      "x": -20,
      "y": 31,
      "z": -3,
      "name": "Soil_Snow"
    },
    {
      "x": -20,
      "y": 29,
      "z": -2,
      "name": "Rock_Ice"
    },
    {
      "x": -20,
      "y": 30,
      "z": -2,
      "name": "Rock_Ice"
    },
    {
      "x": -20,
      "y": 31,
      "z": -2,
      "name": "Rock_Ice"
    },
    {
      "x": -20,
      "y": 32,
      "z": -2,
      "name": "Soil_Snow"
    },
    {
      "x": -20,
      "y": 28,
      "z": -1,
      "name": "Rock_Ice_Permafrost"
    },
    {
      "x": -20,
      "y": 29,
      "z": -1,
      "name": "Rock_Ice"
    },
    {
      "x": -20,
      "y": 30,
      "z": -1,
      "name": "Rock_Ice"
    },
    {
      "x": -20,
      "y": 31,
      "z": -1,
      "name": "Rock_Ice"
    },
    {
      "x": -20,
      "y": 32,
      "z": -1,
      "name": "Soil_Snow"
    },
    {
      "x": -20,
      "y": 28,
      "z": 0,
      "name": "Rock_Ice"
    },
    {
      "x": -20,
      "y": 29,
      "z": 0,
      "name": "Rock_Ice"
    },
    {
      "x": -20,
      "y": 30,
      "z": 0,
      "name": "Rock_Ice"
    },
    {
      "x": -20,
      "y": 31,
      "z": 0,
      "name": "Rock_Ice"
    },
    {
      "x": -20,
      "y": 32,
      "z": 0,
      "name": "Soil_Snow"
    },
    {
      "x": -20,
      "y": 28,
      "z": 1,
      "name": "Rock_Ice"
    },
    {
      "x": -20,
      "y": 29,
      "z": 1,
      "name": "Rock_Ice"
    },
    {
      "x": -20,
      "y": 30,
      "z": 1,
      "name": "Rock_Ice"
    },
    {
      "x": -20,
      "y": 31,
      "z": 1,
      "name": "Soil_Snow"
    },
    {
      "x": -20,
      "y": 28,
      "z": 2,
      "name": "Rock_Ice"
    },
    {
      "x": -20,
      "y": 29,
      "z": 2,
      "name": "Rock_Ice"
    },
    {
      "x": -20,
      "y": 30,
      "z": 2,
      "name": "Soil_Snow"
    },
    {
      "x": -19,
      "y": 25,
      "z": -4,
      "name": "Rock_Ice"
    },
    {
      "x": -19,
      "y": 26,
      "z": -4,
      "name": "Rock_Ice"
    },
    {
      "x": -19,
      "y": 27,
      "z": -4,
      "name": "Rock_Ice"
    },
    {
      "x": -19,
      "y": 28,
      "z": -4,
      "name": "Rock_Ice"
    },
    {
      "x": -19,
      "y": 29,
      "z": -4,
      "name": "Rock_Ice"
    },
    {
      "x": -19,
      "y": 30,
      "z": -4,
      "name": "Rock_Ice_Permafrost"
    },
    {
      "x": -19,
      "y": 31,
      "z": -4,
      "name": "Rock_Ice_Permafrost"
    },
    {
      "x": -19,
      "y": 32,
      "z": -4,
      "name": "Rock_Ice"
    },
    {
      "x": -19,
      "y": 33,
      "z": -4,
      "name": "Soil_Snow"
    },
    {
      "x": -19,
      "y": 25,
      "z": -3,
      "name": "Rock_Ice"
    },
    {
      "x": -19,
      "y": 26,
      "z": -3,
      "name": "Rock_Ice"
    },
    {
      "x": -19,
      "y": 27,
      "z": -3,
      "name": "Rock_Ice"
    },
    {
      "x": -19,
      "y": 28,
      "z": -3,
      "name": "Rock_Ice_Permafrost"
    },
    {
      "x": -19,
      "y": 29,
      "z": -3,
      "name": "Rock_Ice_Permafrost"
    },
    {
      "x": -19,
      "y": 30,
      "z": -3,
      "name": "Rock_Ice_Permafrost"
    },
    {
      "x": -19,
      "y": 31,
      "z": -3,
      "name": "Rock_Ice"
    },
    {
      "x": -19,
      "y": 32,
      "z": -3,
      "name": "Rock_Ice"
    },
    {
      "x": -19,
      "y": 33,
      "z": -3,
      "name": "Rock_Ice"
    },
    {
      "x": -19,
      "y": 34,
      "z": -3,
      "name": "Soil_Snow"
    },
    {
      "x": -19,
      "y": 26,
      "z": -2,
      "name": "Rock_Ice"
    },
    {
      "x": -19,
      "y": 27,
      "z": -2,
      "name": "Rock_Ice"
    },
    {
      "x": -19,
      "y": 28,
      "z": -2,
      "name": "Rock_Ice_Permafrost"
    },
    {
      "x": -19,
      "y": 29,
      "z": -2,
      "name": "Rock_Ice_Permafrost"
    },
    {
      "x": -19,
      "y": 30,
      "z": -2,
      "name": "Rock_Ice"
    },
    {
      "x": -19,
      "y": 31,
      "z": -2,
      "name": "Rock_Ice"
    },
    {
      "x": -19,
      "y": 32,
      "z": -2,
      "name": "Rock_Ice"
    },
    {
      "x": -19,
      "y": 33,
      "z": -2,
      "name": "Rock_Ice"
    },
    {
      "x": -19,
      "y": 34,
      "z": -2,
      "name": "Soil_Snow"
    },
    {
      "x": -19,
      "y": 26,
      "z": -1,
      "name": "Rock_Ice"
    },
    {
      "x": -19,
      "y": 27,
      "z": -1,
      "name": "Rock_Ice_Permafrost"
    },
    {
      "x": -19,
      "y": 28,
      "z": -1,
      "name": "Rock_Ice_Permafrost"
    },
    {
      "x": -19,
      "y": 29,
      "z": -1,
      "name": "Rock_Ice"
    },
    {
      "x": -19,
      "y": 30,
      "z": -1,
      "name": "Rock_Ice"
    },
    {
      "x": -19,
      "y": 31,
      "z": -1,
      "name": "Rock_Ice"
    },
    {
      "x": -19,
      "y": 32,
      "z": -1,
      "name": "Rock_Ice"
    },
    {
      "x": -19,
      "y": 33,
      "z": -1,
      "name": "Rock_Ice"
    },
    {
      "x": -19,
      "y": 34,
      "z": -1,
      "name": "Soil_Snow"
    },
    {
      "x": -19,
      "y": 26,
      "z": 0,
      "name": "Rock_Ice_Permafrost"
    },
    {
      "x": -19,
      "y": 27,
      "z": 0,
      "name": "Rock_Ice_Permafrost"
    },
    {
      "x": -19,
      "y": 28,
      "z": 0,
      "name": "Rock_Ice_Permafrost"
    },
    {
      "x": -19,
      "y": 29,
      "z": 0,
      "name": "Rock_Ice"
    },
    {
      "x": -19,
      "y": 30,
      "z": 0,
      "name": "Rock_Ice"
    },
    {
      "x": -19,
      "y": 31,
      "z": 0,
      "name": "Rock_Ice"
    },
    {
      "x": -19,
      "y": 32,
      "z": 0,
      "name": "Rock_Ice"
    },
    {
      "x": -19,
      "y": 33,
      "z": 0,
      "name": "Soil_Snow"
    },
    {
      "x": -19,
      "y": 26,
      "z": 1,
      "name": "Rock_Ice_Permafrost"
    },
    {
      "x": -19,
      "y": 27,
      "z": 1,
      "name": "Rock_Ice_Permafrost"
    },
    {
      "x": -19,
      "y": 28,
      "z": 1,
      "name": "Rock_Ice"
    },
    {
      "x": -19,
      "y": 29,
      "z": 1,
      "name": "Rock_Ice"
    },
    {
      "x": -19,
      "y": 30,
      "z": 1,
      "name": "Rock_Ice"
    },
    {
      "x": -19,
      "y": 31,
      "z": 1,
      "name": "Rock_Ice"
    },
    {
      "x": -19,
      "y": 32,
      "z": 1,
      "name": "Soil_Snow"
    },
    {
      "x": -19,
      "y": 26,
      "z": 2,
      "name": "Rock_Ice_Permafrost"
    },
    {
      "x": -19,
      "y": 27,
      "z": 2,
      "name": "Rock_Ice"
    },
    {
      "x": -19,
      "y": 28,
      "z": 2,
      "name": "Rock_Ice"
    },
    {
      "x": -19,
      "y": 29,
      "z": 2,
      "name": "Rock_Ice"
    },
    {
      "x": -19,
      "y": 30,
      "z": 2,
      "name": "Rock_Ice"
    },
    {
      "x": -19,
      "y": 31,
      "z": 2,
      "name": "Rock_Ice"
    },
    {
      "x": -19,
      "y": 32,
      "z": 2,
      "name": "Soil_Snow"
    },
    {
      "x": -19,
      "y": 26,
      "z": 3,
      "name": "Rock_Ice"
    },
    {
      "x": -19,
      "y": 27,
      "z": 3,
      "name": "Rock_Ice"
    },
    {
      "x": -19,
      "y": 28,
      "z": 3,
      "name": "Rock_Ice"
    },
    {
      "x": -19,
      "y": 29,
      "z": 3,
      "name": "Rock_Ice"
    },
    {
      "x": -19,
      "y": 30,
      "z": 3,
      "name": "Soil_Snow"
    },
    {
      "x": -19,
      "y": 27,
      "z": 4,
      "name": "Rock_Ice"
    },
    {
      "x": -19,
      "y": 28,
      "z": 4,
      "name": "Rock_Ice"
    },
    {
      "x": -19,
      "y": 29,
      "z": 4,
      "name": "Soil_Snow"
    },
    {
      "x": -18,
      "y": 14,
      "z": -5,
      "name": "Rock_Ice"
    },
    {
      "x": -18,
      "y": 15,
      "z": -5,
      "name": "Rock_Ice"
    },
    {
      "x": -18,
      "y": 16,
      "z": -5,
      "name": "Rock_Ice"
    },
    {
      "x": -18,
      "y": 25,
      "z": -5,
      "name": "Rock_Ice"
    },
    {
      "x": -18,
      "y": 26,
      "z": -5,
      "name": "Rock_Ice"
    },
    {
      "x": -18,
      "y": 27,
      "z": -5,
      "name": "Rock_Ice"
    },
    {
      "x": -18,
      "y": 28,
      "z": -5,
      "name": "Rock_Ice"
    },
    {
      "x": -18,
      "y": 29,
      "z": -5,
      "name": "Rock_Ice"
    },
    {
      "x": -18,
      "y": 30,
      "z": -5,
      "name": "Rock_Ice"
    },
    {
      "x": -18,
      "y": 31,
      "z": -5,
      "name": "Rock_Ice_Permafrost"
    },
    {
      "x": -18,
      "y": 32,
      "z": -5,
      "name": "Rock_Ice_Permafrost"
    },
    {
      "x": -18,
      "y": 33,
      "z": -5,
      "name": "Soil_Snow"
    },
    {
      "x": -18,
      "y": 21,
      "z": -4,
      "name": "Rock_Ice"
    },
    {
      "x": -18,
      "y": 22,
      "z": -4,
      "name": "Rock_Ice"
    },
    {
      "x": -18,
      "y": 23,
      "z": -4,
      "name": "Rock_Ice"
    },
    {
      "x": -18,
      "y": 24,
      "z": -4,
      "name": "Rock_Ice"
    },
    {
      "x": -18,
      "y": 25,
      "z": -4,
      "name": "Rock_Ice"
    },
    {
      "x": -18,
      "y": 26,
      "z": -4,
      "name": "Rock_Ice"
    },
    {
      "x": -18,
      "y": 27,
      "z": -4,
      "name": "Rock_Ice"
    },
    {
      "x": -18,
      "y": 28,
      "z": -4,
      "name": "Rock_Ice"
    },
    {
      "x": -18,
      "y": 29,
      "z": -4,
      "name": "Rock_Ice"
    },
    {
      "x": -18,
      "y": 30,
      "z": -4,
      "name": "Rock_Ice_Permafrost"
    },
    {
      "x": -18,
      "y": 31,
      "z": -4,
      "name": "Rock_Ice_Permafrost"
    },
    {
      "x": -18,
      "y": 32,
      "z": -4,
      "name": "Rock_Ice"
    },
    {
      "x": -18,
      "y": 33,
      "z": -4,
      "name": "Rock_Ice"
    },
    {
      "x": -18,
      "y": 34,
      "z": -4,
      "name": "Soil_Snow"
    },
    {
      "x": -18,
      "y": 21,
      "z": -3,
      "name": "Rock_Ice"
    },
    {
      "x": -18,
      "y": 22,
      "z": -3,
      "name": "Rock_Ice"
    },
    {
      "x": -18,
      "y": 23,
      "z": -3,
      "name": "Rock_Ice"
    },
    {
      "x": -18,
      "y": 24,
      "z": -3,
      "name": "Rock_Ice"
    },
    {
      "x": -18,
      "y": 25,
      "z": -3,
      "name": "Rock_Ice"
    },
    {
      "x": -18,
      "y": 26,
      "z": -3,
      "name": "Rock_Ice"
    },
    {
      "x": -18,
      "y": 27,
      "z": -3,
      "name": "Rock_Ice"
    },
    {
      "x": -18,
      "y": 28,
      "z": -3,
      "name": "Rock_Ice"
    },
    {
      "x": -18,
      "y": 29,
      "z": -3,
      "name": "Rock_Ice_Permafrost"
    },
    {
      "x": -18,
      "y": 30,
      "z": -3,
      "name": "Rock_Ice_Permafrost"
    },
    {
      "x": -18,
      "y": 31,
      "z": -3,
      "name": "Rock_Ice"
    },
    {
      "x": -18,
      "y": 32,
      "z": -3,
      "name": "Rock_Ice"
    },
    {
      "x": -18,
      "y": 33,
      "z": -3,
      "name": "Rock_Ice"
    },
    {
      "x": -18,
      "y": 34,
      "z": -3,
      "name": "Rock_Ice"
    },
    {
      "x": -18,
      "y": 35,
      "z": -3,
      "name": "Rock_Ice"
    },
    {
      "x": -18,
      "y": 36,
      "z": -3,
      "name": "Rock_Ice"
    },
    {
      "x": -18,
      "y": 37,
      "z": -3,
      "name": "Soil_Snow"
    },
    {
      "x": -18,
      "y": 20,
      "z": -2,
      "name": "Rock_Ice"
    },
    {
      "x": -18,
      "y": 21,
      "z": -2,
      "name": "Rock_Ice"
    },
    {
      "x": -18,
      "y": 22,
      "z": -2,
      "name": "Rock_Ice"
    },
    {
      "x": -18,
      "y": 23,
      "z": -2,
      "name": "Rock_Ice"
    },
    {
      "x": -18,
      "y": 24,
      "z": -2,
      "name": "Rock_Ice"
    },
    {
      "x": -18,
      "y": 25,
      "z": -2,
      "name": "Rock_Ice"
    },
    {
      "x": -18,
      "y": 26,
      "z": -2,
      "name": "Rock_Ice"
    },
    {
      "x": -18,
      "y": 27,
      "z": -2,
      "name": "Rock_Ice"
    },
    {
      "x": -18,
      "y": 28,
      "z": -2,
      "name": "Rock_Ice_Permafrost"
    },
    {
      "x": -18,
      "y": 29,
      "z": -2,
      "name": "Rock_Ice_Permafrost"
    },
    {
      "x": -18,
      "y": 30,
      "z": -2,
      "name": "Rock_Ice"
    },
    {
      "x": -18,
      "y": 31,
      "z": -2,
      "name": "Rock_Ice"
    },
    {
      "x": -18,
      "y": 32,
      "z": -2,
      "name": "Rock_Ice"
    },
    {
      "x": -18,
      "y": 33,
      "z": -2,
      "name": "Rock_Ice"
    },
    {
      "x": -18,
      "y": 34,
      "z": -2,
      "name": "Rock_Ice"
    },
    {
      "x": -18,
      "y": 35,
      "z": -2,
      "name": "Rock_Ice"
    },
    {
      "x": -18,
      "y": 36,
      "z": -2,
      "name": "Rock_Ice"
    },
    {
      "x": -18,
      "y": 37,
      "z": -2,
      "name": "Soil_Snow"
    },
    {
      "x": -18,
      "y": 21,
      "z": -1,
      "name": "Rock_Ice"
    },
    {
      "x": -18,
      "y": 22,
      "z": -1,
      "name": "Rock_Ice"
    },
    {
      "x": -18,
      "y": 23,
      "z": -1,
      "name": "Rock_Ice"
    },
    {
      "x": -18,
      "y": 24,
      "z": -1,
      "name": "Rock_Ice"
    },
    {
      "x": -18,
      "y": 25,
      "z": -1,
      "name": "Rock_Ice"
    },
    {
      "x": -18,
      "y": 26,
      "z": -1,
      "name": "Rock_Ice"
    },
    {
      "x": -18,
      "y": 27,
      "z": -1,
      "name": "Rock_Ice_Permafrost"
    },
    {
      "x": -18,
      "y": 28,
      "z": -1,
      "name": "Rock_Ice_Permafrost"
    },
    {
      "x": -18,
      "y": 29,
      "z": -1,
      "name": "Rock_Ice"
    },
    {
      "x": -18,
      "y": 30,
      "z": -1,
      "name": "Rock_Ice"
    },
    {
      "x": -18,
      "y": 31,
      "z": -1,
      "name": "Rock_Ice"
    },
    {
      "x": -18,
      "y": 32,
      "z": -1,
      "name": "Rock_Ice"
    },
    {
      "x": -18,
      "y": 33,
      "z": -1,
      "name": "Rock_Ice"
    },
    {
      "x": -18,
      "y": 34,
      "z": -1,
      "name": "Rock_Ice"
    },
    {
      "x": -18,
      "y": 35,
      "z": -1,
      "name": "Rock_Ice"
    },
    {
      "x": -18,
      "y": 36,
      "z": -1,
      "name": "Soil_Snow"
    },
    {
      "x": -18,
      "y": 23,
      "z": 0,
      "name": "Rock_Ice"
    },
    {
      "x": -18,
      "y": 24,
      "z": 0,
      "name": "Rock_Ice"
    },
    {
      "x": -18,
      "y": 25,
      "z": 0,
      "name": "Rock_Ice"
    },
    {
      "x": -18,
      "y": 26,
      "z": 0,
      "name": "Rock_Ice_Permafrost"
    },
    {
      "x": -18,
      "y": 27,
      "z": 0,
      "name": "Rock_Ice_Permafrost"
    },
    {
      "x": -18,
      "y": 28,
      "z": 0,
      "name": "Rock_Ice"
    },
    {
      "x": -18,
      "y": 29,
      "z": 0,
      "name": "Rock_Ice"
    },
    {
      "x": -18,
      "y": 30,
      "z": 0,
      "name": "Rock_Ice"
    },
    {
      "x": -18,
      "y": 31,
      "z": 0,
      "name": "Rock_Ice"
    },
    {
      "x": -18,
      "y": 32,
      "z": 0,
      "name": "Rock_Ice"
    },
    {
      "x": -18,
      "y": 33,
      "z": 0,
      "name": "Rock_Ice"
    },
    {
      "x": -18,
      "y": 34,
      "z": 0,
      "name": "Rock_Ice"
    },
    {
      "x": -18,
      "y": 35,
      "z": 0,
      "name": "Soil_Snow"
    },
    {
      "x": -18,
      "y": 23,
      "z": 1,
      "name": "Rock_Ice"
    },
    {
      "x": -18,
      "y": 24,
      "z": 1,
      "name": "Rock_Ice"
    },
    {
      "x": -18,
      "y": 25,
      "z": 1,
      "name": "Rock_Ice"
    },
    {
      "x": -18,
      "y": 26,
      "z": 1,
      "name": "Rock_Ice_Permafrost"
    },
    {
      "x": -18,
      "y": 27,
      "z": 1,
      "name": "Rock_Ice_Permafrost"
    },
    {
      "x": -18,
      "y": 28,
      "z": 1,
      "name": "Rock_Ice"
    },
    {
      "x": -18,
      "y": 29,
      "z": 1,
      "name": "Rock_Ice"
    },
    {
      "x": -18,
      "y": 30,
      "z": 1,
      "name": "Rock_Ice"
    },
    {
      "x": -18,
      "y": 31,
      "z": 1,
      "name": "Rock_Ice"
    },
    {
      "x": -18,
      "y": 32,
      "z": 1,
      "name": "Rock_Ice"
    },
    {
      "x": -18,
      "y": 33,
      "z": 1,
      "name": "Rock_Ice"
    },
    {
      "x": -18,
      "y": 34,
      "z": 1,
      "name": "Soil_Snow"
    },
    {
      "x": -18,
      "y": 23,
      "z": 2,
      "name": "Rock_Ice"
    },
    {
      "x": -18,
      "y": 24,
      "z": 2,
      "name": "Rock_Ice_Permafrost"
    },
    {
      "x": -18,
      "y": 25,
      "z": 2,
      "name": "Rock_Ice_Permafrost"
    },
    {
      "x": -18,
      "y": 26,
      "z": 2,
      "name": "Rock_Ice_Permafrost"
    },
    {
      "x": -18,
      "y": 27,
      "z": 2,
      "name": "Rock_Ice"
    },
    {
      "x": -18,
      "y": 28,
      "z": 2,
      "name": "Rock_Ice"
    },
    {
      "x": -18,
      "y": 29,
      "z": 2,
      "name": "Rock_Ice"
    },
    {
      "x": -18,
      "y": 30,
      "z": 2,
      "name": "Rock_Ice"
    },
    {
      "x": -18,
      "y": 31,
      "z": 2,
      "name": "Rock_Ice"
    },
    {
      "x": -18,
      "y": 32,
      "z": 2,
      "name": "Rock_Ice"
    },
    {
      "x": -18,
      "y": 33,
      "z": 2,
      "name": "Soil_Snow"
    },
    {
      "x": -18,
      "y": 24,
      "z": 3,
      "name": "Rock_Ice_Permafrost"
    },
    {
      "x": -18,
      "y": 25,
      "z": 3,
      "name": "Rock_Ice_Permafrost"
    },
    {
      "x": -18,
      "y": 26,
      "z": 3,
      "name": "Rock_Ice_Permafrost"
    },
    {
      "x": -18,
      "y": 27,
      "z": 3,
      "name": "Rock_Ice"
    },
    {
      "x": -18,
      "y": 28,
      "z": 3,
      "name": "Rock_Ice"
    },
    {
      "x": -18,
      "y": 29,
      "z": 3,
      "name": "Rock_Ice"
    },
    {
      "x": -18,
      "y": 30,
      "z": 3,
      "name": "Rock_Ice"
    },
    {
      "x": -18,
      "y": 31,
      "z": 3,
      "name": "Rock_Ice"
    },
    {
      "x": -18,
      "y": 32,
      "z": 3,
      "name": "Soil_Snow"
    },
    {
      "x": -18,
      "y": 25,
      "z": 4,
      "name": "Rock_Ice_Permafrost"
    },
    {
      "x": -18,
      "y": 26,
      "z": 4,
      "name": "Rock_Ice"
    },
    {
      "x": -18,
      "y": 27,
      "z": 4,
      "name": "Rock_Ice"
    },
    {
      "x": -18,
      "y": 28,
      "z": 4,
      "name": "Rock_Ice"
    },
    {
      "x": -18,
      "y": 29,
      "z": 4,
      "name": "Rock_Ice"
    },
    {
      "x": -18,
      "y": 30,
      "z": 4,
      "name": "Soil_Snow"
    },
    {
      "x": -18,
      "y": 25,
      "z": 5,
      "name": "Rock_Ice"
    },
    {
      "x": -18,
      "y": 26,
      "z": 5,
      "name": "Rock_Ice"
    },
    {
      "x": -18,
      "y": 27,
      "z": 5,
      "name": "Rock_Ice"
    },
    {
      "x": -18,
      "y": 28,
      "z": 5,
      "name": "Soil_Snow"
    },
    {
      "x": -18,
      "y": 26,
      "z": 6,
      "name": "Rock_Ice"
    },
    {
      "x": -18,
      "y": 27,
      "z": 6,
      "name": "Soil_Snow"
    },
    {
      "x": -17,
      "y": 27,
      "z": -6,
      "name": "Rock_Ice"
    },
    {
      "x": -17,
      "y": 28,
      "z": -6,
      "name": "Rock_Ice"
    },
    {
      "x": -17,
      "y": 29,
      "z": -6,
      "name": "Rock_Ice"
    },
    {
      "x": -17,
      "y": 30,
      "z": -6,
      "name": "Rock_Ice"
    },
    {
      "x": -17,
      "y": 31,
      "z": -6,
      "name": "Rock_Ice"
    },
    {
      "x": -17,
      "y": 32,
      "z": -6,
      "name": "Rock_Ice_Permafrost"
    },
    {
      "x": -17,
      "y": 33,
      "z": -6,
      "name": "Soil_Snow"
    },
    {
      "x": -17,
      "y": 13,
      "z": -5,
      "name": "Rock_Ice"
    },
    {
      "x": -17,
      "y": 14,
      "z": -5,
      "name": "Rock_Ice"
    },
    {
      "x": -17,
      "y": 15,
      "z": -5,
      "name": "Rock_Ice"
    },
    {
      "x": -17,
      "y": 16,
      "z": -5,
      "name": "Rock_Ice"
    },
    {
      "x": -17,
      "y": 23,
      "z": -5,
      "name": "Rock_Ice"
    },
    {
      "x": -17,
      "y": 24,
      "z": -5,
      "name": "Rock_Ice"
    },
    {
      "x": -17,
      "y": 25,
      "z": -5,
      "name": "Rock_Ice"
    },
    {
      "x": -17,
      "y": 26,
      "z": -5,
      "name": "Rock_Ice"
    },
    {
      "x": -17,
      "y": 27,
      "z": -5,
      "name": "Rock_Ice"
    },
    {
      "x": -17,
      "y": 28,
      "z": -5,
      "name": "Rock_Ice"
    },
    {
      "x": -17,
      "y": 29,
      "z": -5,
      "name": "Rock_Ice"
    },
    {
      "x": -17,
      "y": 30,
      "z": -5,
      "name": "Rock_Ice"
    },
    {
      "x": -17,
      "y": 31,
      "z": -5,
      "name": "Rock_Ice_Permafrost"
    },
    {
      "x": -17,
      "y": 32,
      "z": -5,
      "name": "Rock_Ice_Permafrost"
    },
    {
      "x": -17,
      "y": 33,
      "z": -5,
      "name": "Rock_Ice"
    },
    {
      "x": -17,
      "y": 34,
      "z": -5,
      "name": "Soil_Snow"
    },
    {
      "x": -17,
      "y": 12,
      "z": -4,
      "name": "Rock_Ice"
    },
    {
      "x": -17,
      "y": 13,
      "z": -4,
      "name": "Rock_Ice"
    },
    {
      "x": -17,
      "y": 14,
      "z": -4,
      "name": "Rock_Ice"
    },
    {
      "x": -17,
      "y": 15,
      "z": -4,
      "name": "Rock_Ice"
    },
    {
      "x": -17,
      "y": 16,
      "z": -4,
      "name": "Rock_Ice"
    },
    {
      "x": -17,
      "y": 17,
      "z": -4,
      "name": "Rock_Ice_Permafrost"
    },
    {
      "x": -17,
      "y": 18,
      "z": -4,
      "name": "Rock_Ice_Permafrost"
    },
    {
      "x": -17,
      "y": 19,
      "z": -4,
      "name": "Rock_Ice"
    },
    {
      "x": -17,
      "y": 20,
      "z": -4,
      "name": "Rock_Ice"
    },
    {
      "x": -17,
      "y": 21,
      "z": -4,
      "name": "Rock_Ice"
    },
    {
      "x": -17,
      "y": 22,
      "z": -4,
      "name": "Rock_Ice"
    },
    {
      "x": -17,
      "y": 23,
      "z": -4,
      "name": "Rock_Ice"
    },
    {
      "x": -17,
      "y": 24,
      "z": -4,
      "name": "Rock_Ice"
    },
    {
      "x": -17,
      "y": 25,
      "z": -4,
      "name": "Rock_Ice"
    },
    {
      "x": -17,
      "y": 26,
      "z": -4,
      "name": "Rock_Ice"
    },
    {
      "x": -17,
      "y": 27,
      "z": -4,
      "name": "Rock_Ice"
    },
    {
      "x": -17,
      "y": 28,
      "z": -4,
      "name": "Rock_Ice"
    },
    {
      "x": -17,
      "y": 29,
      "z": -4,
      "name": "Rock_Ice"
    },
    {
      "x": -17,
      "y": 30,
      "z": -4,
      "name": "Rock_Ice_Permafrost"
    },
    {
      "x": -17,
      "y": 31,
      "z": -4,
      "name": "Rock_Ice_Permafrost"
    },
    {
      "x": -17,
      "y": 32,
      "z": -4,
      "name": "Rock_Ice"
    },
    {
      "x": -17,
      "y": 33,
      "z": -4,
      "name": "Rock_Ice"
    },
    {
      "x": -17,
      "y": 34,
      "z": -4,
      "name": "Rock_Ice"
    },
    {
      "x": -17,
      "y": 35,
      "z": -4,
      "name": "Soil_Snow"
    },
    {
      "x": -17,
      "y": 18,
      "z": -3,
      "name": "Rock_Ice"
    },
    {
      "x": -17,
      "y": 19,
      "z": -3,
      "name": "Rock_Ice"
    },
    {
      "x": -17,
      "y": 20,
      "z": -3,
      "name": "Rock_Ice"
    },
    {
      "x": -17,
      "y": 21,
      "z": -3,
      "name": "Rock_Ice"
    },
    {
      "x": -17,
      "y": 22,
      "z": -3,
      "name": "Rock_Ice"
    },
    {
      "x": -17,
      "y": 23,
      "z": -3,
      "name": "Rock_Ice"
    },
    {
      "x": -17,
      "y": 24,
      "z": -3,
      "name": "Rock_Ice"
    },
    {
      "x": -17,
      "y": 25,
      "z": -3,
      "name": "Rock_Ice"
    },
    {
      "x": -17,
      "y": 26,
      "z": -3,
      "name": "Rock_Ice"
    },
    {
      "x": -17,
      "y": 27,
      "z": -3,
      "name": "Rock_Ice"
    },
    {
      "x": -17,
      "y": 28,
      "z": -3,
      "name": "Rock_Ice"
    },
    {
      "x": -17,
      "y": 29,
      "z": -3,
      "name": "Rock_Ice_Permafrost"
    },
    {
      "x": -17,
      "y": 30,
      "z": -3,
      "name": "Rock_Ice_Permafrost"
    },
    {
      "x": -17,
      "y": 31,
      "z": -3,
      "name": "Rock_Ice_Permafrost"
    },
    {
      "x": -17,
      "y": 32,
      "z": -3,
      "name": "Rock_Ice"
    },
    {
      "x": -17,
      "y": 33,
      "z": -3,
      "name": "Rock_Ice"
    },
    {
      "x": -17,
      "y": 34,
      "z": -3,
      "name": "Rock_Ice"
    },
    {
      "x": -17,
      "y": 35,
      "z": -3,
      "name": "Rock_Ice"
    },
    {
      "x": -17,
      "y": 36,
      "z": -3,
      "name": "Rock_Ice"
    },
    {
      "x": -17,
      "y": 37,
      "z": -3,
      "name": "Soil_Snow"
    },
    {
      "x": -17,
      "y": 17,
      "z": -2,
      "name": "Rock_Ice_Permafrost"
    },
    {
      "x": -17,
      "y": 18,
      "z": -2,
      "name": "Rock_Ice"
    },
    {
      "x": -17,
      "y": 19,
      "z": -2,
      "name": "Rock_Ice"
    },
    {
      "x": -17,
      "y": 20,
      "z": -2,
      "name": "Rock_Ice"
    },
    {
      "x": -17,
      "y": 21,
      "z": -2,
      "name": "Rock_Ice"
    },
    {
      "x": -17,
      "y": 22,
      "z": -2,
      "name": "Rock_Ice"
    },
    {
      "x": -17,
      "y": 23,
      "z": -2,
      "name": "Rock_Ice"
    },
    {
      "x": -17,
      "y": 24,
      "z": -2,
      "name": "Rock_Ice"
    },
    {
      "x": -17,
      "y": 25,
      "z": -2,
      "name": "Rock_Ice"
    },
    {
      "x": -17,
      "y": 26,
      "z": -2,
      "name": "Rock_Ice"
    },
    {
      "x": -17,
      "y": 27,
      "z": -2,
      "name": "Rock_Ice"
    },
    {
      "x": -17,
      "y": 28,
      "z": -2,
      "name": "Rock_Ice_Permafrost"
    },
    {
      "x": -17,
      "y": 29,
      "z": -2,
      "name": "Rock_Ice_Permafrost"
    },
    {
      "x": -17,
      "y": 30,
      "z": -2,
      "name": "Rock_Ice"
    },
    {
      "x": -17,
      "y": 31,
      "z": -2,
      "name": "Rock_Ice"
    },
    {
      "x": -17,
      "y": 32,
      "z": -2,
      "name": "Rock_Ice"
    },
    {
      "x": -17,
      "y": 33,
      "z": -2,
      "name": "Rock_Ice"
    },
    {
      "x": -17,
      "y": 34,
      "z": -2,
      "name": "Rock_Ice"
    },
    {
      "x": -17,
      "y": 35,
      "z": -2,
      "name": "Rock_Ice"
    },
    {
      "x": -17,
      "y": 36,
      "z": -2,
      "name": "Rock_Ice"
    },
    {
      "x": -17,
      "y": 37,
      "z": -2,
      "name": "Rock_Ice"
    },
    {
      "x": -17,
      "y": 38,
      "z": -2,
      "name": "Soil_Snow"
    },
    {
      "x": -17,
      "y": 16,
      "z": -1,
      "name": "Rock_Ice_Permafrost"
    },
    {
      "x": -17,
      "y": 17,
      "z": -1,
      "name": "Rock_Ice"
    },
    {
      "x": -17,
      "y": 18,
      "z": -1,
      "name": "Rock_Ice"
    },
    {
      "x": -17,
      "y": 19,
      "z": -1,
      "name": "Rock_Ice"
    },
    {
      "x": -17,
      "y": 20,
      "z": -1,
      "name": "Rock_Ice"
    },
    {
      "x": -17,
      "y": 21,
      "z": -1,
      "name": "Rock_Ice"
    },
    {
      "x": -17,
      "y": 22,
      "z": -1,
      "name": "Rock_Ice"
    },
    {
      "x": -17,
      "y": 23,
      "z": -1,
      "name": "Rock_Ice"
    },
    {
      "x": -17,
      "y": 24,
      "z": -1,
      "name": "Rock_Ice"
    },
    {
      "x": -17,
      "y": 25,
      "z": -1,
      "name": "Rock_Ice"
    },
    {
      "x": -17,
      "y": 26,
      "z": -1,
      "name": "Rock_Ice"
    },
    {
      "x": -17,
      "y": 27,
      "z": -1,
      "name": "Rock_Ice"
    },
    {
      "x": -17,
      "y": 28,
      "z": -1,
      "name": "Rock_Ice_Permafrost"
    },
    {
      "x": -17,
      "y": 29,
      "z": -1,
      "name": "Rock_Ice"
    },
    {
      "x": -17,
      "y": 30,
      "z": -1,
      "name": "Rock_Ice"
    },
    {
      "x": -17,
      "y": 31,
      "z": -1,
      "name": "Rock_Ice"
    },
    {
      "x": -17,
      "y": 32,
      "z": -1,
      "name": "Rock_Ice"
    },
    {
      "x": -17,
      "y": 33,
      "z": -1,
      "name": "Rock_Ice"
    },
    {
      "x": -17,
      "y": 34,
      "z": -1,
      "name": "Rock_Ice"
    },
    {
      "x": -17,
      "y": 35,
      "z": -1,
      "name": "Rock_Ice"
    },
    {
      "x": -17,
      "y": 36,
      "z": -1,
      "name": "Rock_Ice"
    },
    {
      "x": -17,
      "y": 37,
      "z": -1,
      "name": "Rock_Ice"
    },
    {
      "x": -17,
      "y": 38,
      "z": -1,
      "name": "Soil_Snow"
    },
    {
      "x": -17,
      "y": 16,
      "z": 0,
      "name": "Rock_Ice_Permafrost"
    },
    {
      "x": -17,
      "y": 17,
      "z": 0,
      "name": "Rock_Ice_Permafrost"
    },
    {
      "x": -17,
      "y": 18,
      "z": 0,
      "name": "Rock_Ice"
    },
    {
      "x": -17,
      "y": 19,
      "z": 0,
      "name": "Rock_Ice"
    },
    {
      "x": -17,
      "y": 20,
      "z": 0,
      "name": "Rock_Ice"
    },
    {
      "x": -17,
      "y": 21,
      "z": 0,
      "name": "Rock_Ice"
    },
    {
      "x": -17,
      "y": 22,
      "z": 0,
      "name": "Rock_Ice"
    },
    {
      "x": -17,
      "y": 23,
      "z": 0,
      "name": "Rock_Ice"
    },
    {
      "x": -17,
      "y": 24,
      "z": 0,
      "name": "Rock_Ice"
    },
    {
      "x": -17,
      "y": 25,
      "z": 0,
      "name": "Rock_Ice"
    },
    {
      "x": -17,
      "y": 26,
      "z": 0,
      "name": "Rock_Ice"
    },
    {
      "x": -17,
      "y": 27,
      "z": 0,
      "name": "Rock_Ice_Permafrost"
    },
    {
      "x": -17,
      "y": 28,
      "z": 0,
      "name": "Rock_Ice_Permafrost"
    },
    {
      "x": -17,
      "y": 29,
      "z": 0,
      "name": "Rock_Ice"
    },
    {
      "x": -17,
      "y": 30,
      "z": 0,
      "name": "Rock_Ice"
    },
    {
      "x": -17,
      "y": 31,
      "z": 0,
      "name": "Rock_Ice"
    },
    {
      "x": -17,
      "y": 32,
      "z": 0,
      "name": "Rock_Ice"
    },
    {
      "x": -17,
      "y": 33,
      "z": 0,
      "name": "Rock_Ice"
    },
    {
      "x": -17,
      "y": 34,
      "z": 0,
      "name": "Rock_Ice"
    },
    {
      "x": -17,
      "y": 35,
      "z": 0,
      "name": "Rock_Ice"
    },
    {
      "x": -17,
      "y": 36,
      "z": 0,
      "name": "Rock_Ice"
    },
    {
      "x": -17,
      "y": 37,
      "z": 0,
      "name": "Soil_Snow"
    },
    {
      "x": -17,
      "y": 18,
      "z": 1,
      "name": "Rock_Ice"
    },
    {
      "x": -17,
      "y": 19,
      "z": 1,
      "name": "Rock_Ice"
    },
    {
      "x": -17,
      "y": 20,
      "z": 1,
      "name": "Rock_Ice"
    },
    {
      "x": -17,
      "y": 21,
      "z": 1,
      "name": "Rock_Ice"
    },
    {
      "x": -17,
      "y": 22,
      "z": 1,
      "name": "Rock_Ice"
    },
    {
      "x": -17,
      "y": 23,
      "z": 1,
      "name": "Rock_Ice"
    },
    {
      "x": -17,
      "y": 24,
      "z": 1,
      "name": "Rock_Ice"
    },
    {
      "x": -17,
      "y": 25,
      "z": 1,
      "name": "Rock_Ice_Permafrost"
    },
    {
      "x": -17,
      "y": 26,
      "z": 1,
      "name": "Rock_Ice_Permafrost"
    },
    {
      "x": -17,
      "y": 27,
      "z": 1,
      "name": "Rock_Ice_Permafrost"
    },
    {
      "x": -17,
      "y": 28,
      "z": 1,
      "name": "Rock_Ice"
    },
    {
      "x": -17,
      "y": 29,
      "z": 1,
      "name": "Rock_Ice"
    },
    {
      "x": -17,
      "y": 30,
      "z": 1,
      "name": "Rock_Ice"
    },
    {
      "x": -17,
      "y": 31,
      "z": 1,
      "name": "Rock_Ice"
    },
    {
      "x": -17,
      "y": 32,
      "z": 1,
      "name": "Rock_Ice"
    },
    {
      "x": -17,
      "y": 33,
      "z": 1,
      "name": "Rock_Ice"
    },
    {
      "x": -17,
      "y": 34,
      "z": 1,
      "name": "Rock_Ice"
    },
    {
      "x": -17,
      "y": 35,
      "z": 1,
      "name": "Soil_Snow"
    },
    {
      "x": -17,
      "y": 19,
      "z": 2,
      "name": "Rock_Ice"
    },
    {
      "x": -17,
      "y": 20,
      "z": 2,
      "name": "Rock_Ice"
    },
    {
      "x": -17,
      "y": 21,
      "z": 2,
      "name": "Rock_Ice"
    },
    {
      "x": -17,
      "y": 22,
      "z": 2,
      "name": "Rock_Ice"
    },
    {
      "x": -17,
      "y": 23,
      "z": 2,
      "name": "Rock_Ice"
    },
    {
      "x": -17,
      "y": 24,
      "z": 2,
      "name": "Rock_Ice"
    },
    {
      "x": -17,
      "y": 25,
      "z": 2,
      "name": "Rock_Ice_Permafrost"
    },
    {
      "x": -17,
      "y": 26,
      "z": 2,
      "name": "Rock_Ice_Permafrost"
    },
    {
      "x": -17,
      "y": 27,
      "z": 2,
      "name": "Rock_Ice"
    },
    {
      "x": -17,
      "y": 28,
      "z": 2,
      "name": "Rock_Ice"
    },
    {
      "x": -17,
      "y": 29,
      "z": 2,
      "name": "Rock_Ice"
    },
    {
      "x": -17,
      "y": 30,
      "z": 2,
      "name": "Rock_Ice"
    },
    {
      "x": -17,
      "y": 31,
      "z": 2,
      "name": "Rock_Ice"
    },
    {
      "x": -17,
      "y": 32,
      "z": 2,
      "name": "Rock_Ice"
    },
    {
      "x": -17,
      "y": 33,
      "z": 2,
      "name": "Rock_Ice"
    },
    {
      "x": -17,
      "y": 34,
      "z": 2,
      "name": "Soil_Snow"
    },
    {
      "x": -17,
      "y": 21,
      "z": 3,
      "name": "Rock_Ice"
    },
    {
      "x": -17,
      "y": 22,
      "z": 3,
      "name": "Rock_Ice"
    },
    {
      "x": -17,
      "y": 23,
      "z": 3,
      "name": "Rock_Ice"
    },
    {
      "x": -17,
      "y": 24,
      "z": 3,
      "name": "Rock_Ice_Permafrost"
    },
    {
      "x": -17,
      "y": 25,
      "z": 3,
      "name": "Rock_Ice_Permafrost"
    },
    {
      "x": -17,
      "y": 26,
      "z": 3,
      "name": "Rock_Ice_Permafrost"
    },
    {
      "x": -17,
      "y": 27,
      "z": 3,
      "name": "Rock_Ice"
    },
    {
      "x": -17,
      "y": 28,
      "z": 3,
      "name": "Rock_Ice"
    },
    {
      "x": -17,
      "y": 29,
      "z": 3,
      "name": "Rock_Ice"
    },
    {
      "x": -17,
      "y": 30,
      "z": 3,
      "name": "Rock_Ice"
    },
    {
      "x": -17,
      "y": 31,
      "z": 3,
      "name": "Rock_Ice"
    },
    {
      "x": -17,
      "y": 32,
      "z": 3,
      "name": "Rock_Ice"
    },
    {
      "x": -17,
      "y": 33,
      "z": 3,
      "name": "Soil_Snow"
    },
    {
      "x": -17,
      "y": 21,
      "z": 4,
      "name": "Rock_Ice"
    },
    {
      "x": -17,
      "y": 22,
      "z": 4,
      "name": "Rock_Ice"
    },
    {
      "x": -17,
      "y": 23,
      "z": 4,
      "name": "Rock_Ice_Permafrost"
    },
    {
      "x": -17,
      "y": 24,
      "z": 4,
      "name": "Rock_Ice_Permafrost"
    },
    {
      "x": -17,
      "y": 25,
      "z": 4,
      "name": "Rock_Ice_Permafrost"
    },
    {
      "x": -17,
      "y": 26,
      "z": 4,
      "name": "Rock_Ice"
    },
    {
      "x": -17,
      "y": 27,
      "z": 4,
      "name": "Rock_Ice"
    },
    {
      "x": -17,
      "y": 28,
      "z": 4,
      "name": "Rock_Ice"
    },
    {
      "x": -17,
      "y": 29,
      "z": 4,
      "name": "Rock_Ice"
    },
    {
      "x": -17,
      "y": 30,
      "z": 4,
      "name": "Rock_Ice"
    },
    {
      "x": -17,
      "y": 31,
      "z": 4,
      "name": "Rock_Ice"
    },
    {
      "x": -17,
      "y": 32,
      "z": 4,
      "name": "Soil_Snow"
    },
    {
      "x": -17,
      "y": 22,
      "z": 5,
      "name": "Rock_Ice"
    },
    {
      "x": -17,
      "y": 23,
      "z": 5,
      "name": "Rock_Ice_Permafrost"
    },
    {
      "x": -17,
      "y": 24,
      "z": 5,
      "name": "Rock_Ice_Permafrost"
    },
    {
      "x": -17,
      "y": 25,
      "z": 5,
      "name": "Rock_Ice_Permafrost"
    },
    {
      "x": -17,
      "y": 26,
      "z": 5,
      "name": "Rock_Ice"
    },
    {
      "x": -17,
      "y": 27,
      "z": 5,
      "name": "Rock_Ice"
    },
    {
      "x": -17,
      "y": 28,
      "z": 5,
      "name": "Rock_Ice"
    },
    {
      "x": -17,
      "y": 29,
      "z": 5,
      "name": "Rock_Ice"
    },
    {
      "x": -17,
      "y": 30,
      "z": 5,
      "name": "Soil_Snow"
    },
    {
      "x": -17,
      "y": 23,
      "z": 6,
      "name": "Rock_Ice_Permafrost"
    },
    {
      "x": -17,
      "y": 24,
      "z": 6,
      "name": "Rock_Ice_Permafrost"
    },
    {
      "x": -17,
      "y": 25,
      "z": 6,
      "name": "Rock_Ice"
    },
    {
      "x": -17,
      "y": 26,
      "z": 6,
      "name": "Rock_Ice"
    },
    {
      "x": -17,
      "y": 27,
      "z": 6,
      "name": "Rock_Ice"
    },
    {
      "x": -17,
      "y": 28,
      "z": 6,
      "name": "Soil_Snow"
    },
    {
      "x": -17,
      "y": 25,
      "z": 7,
      "name": "Rock_Ice_Permafrost"
    },
    {
      "x": -17,
      "y": 26,
      "z": 7,
      "name": "Soil_Snow"
    },
    {
      "x": -16,
      "y": 27,
      "z": -7,
      "name": "Rock_Ice"
    },
    {
      "x": -16,
      "y": 28,
      "z": -7,
      "name": "Rock_Ice"
    },
    {
      "x": -16,
      "y": 29,
      "z": -7,
      "name": "Rock_Ice"
    },
    {
      "x": -16,
      "y": 30,
      "z": -7,
      "name": "Rock_Ice"
    },
    {
      "x": -16,
      "y": 31,
      "z": -7,
      "name": "Rock_Ice"
    },
    {
      "x": -16,
      "y": 32,
      "z": -7,
      "name": "Rock_Ice"
    },
    {
      "x": -16,
      "y": 33,
      "z": -7,
      "name": "Soil_Snow"
    },
    {
      "x": -16,
      "y": 15,
      "z": -6,
      "name": "Rock_Ice"
    },
    {
      "x": -16,
      "y": 24,
      "z": -6,
      "name": "Rock_Ice"
    },
    {
      "x": -16,
      "y": 25,
      "z": -6,
      "name": "Rock_Ice"
    },
    {
      "x": -16,
      "y": 26,
      "z": -6,
      "name": "Rock_Ice"
    },
    {
      "x": -16,
      "y": 27,
      "z": -6,
      "name": "Rock_Ice"
    },
    {
      "x": -16,
      "y": 28,
      "z": -6,
      "name": "Rock_Ice"
    },
    {
      "x": -16,
      "y": 29,
      "z": -6,
      "name": "Rock_Ice"
    },
    {
      "x": -16,
      "y": 30,
      "z": -6,
      "name": "Rock_Ice"
    },
    {
      "x": -16,
      "y": 31,
      "z": -6,
      "name": "Rock_Ice"
    },
    {
      "x": -16,
      "y": 32,
      "z": -6,
      "name": "Rock_Ice"
    },
    {
      "x": -16,
      "y": 33,
      "z": -6,
      "name": "Rock_Ice_Permafrost"
    },
    {
      "x": -16,
      "y": 34,
      "z": -6,
      "name": "Soil_Snow"
    },
    {
      "x": -16,
      "y": 11,
      "z": -5,
      "name": "Rock_Ice"
    },
    {
      "x": -16,
      "y": 12,
      "z": -5,
      "name": "Rock_Ice"
    },
    {
      "x": -16,
      "y": 13,
      "z": -5,
      "name": "Rock_Ice"
    },
    {
      "x": -16,
      "y": 14,
      "z": -5,
      "name": "Rock_Ice"
    },
    {
      "x": -16,
      "y": 15,
      "z": -5,
      "name": "Rock_Ice"
    },
    {
      "x": -16,
      "y": 16,
      "z": -5,
      "name": "Rock_Ice"
    },
    {
      "x": -16,
      "y": 20,
      "z": -5,
      "name": "Rock_Ice"
    },
    {
      "x": -16,
      "y": 21,
      "z": -5,
      "name": "Rock_Ice"
    },
    {
      "x": -16,
      "y": 22,
      "z": -5,
      "name": "Rock_Ice"
    },
    {
      "x": -16,
      "y": 23,
      "z": -5,
      "name": "Rock_Ice"
    },
    {
      "x": -16,
      "y": 24,
      "z": -5,
      "name": "Rock_Ice"
    },
    {
      "x": -16,
      "y": 25,
      "z": -5,
      "name": "Rock_Ice"
    },
    {
      "x": -16,
      "y": 26,
      "z": -5,
      "name": "Rock_Ice"
    },
    {
      "x": -16,
      "y": 27,
      "z": -5,
      "name": "Rock_Ice"
    },
    {
      "x": -16,
      "y": 28,
      "z": -5,
      "name": "Rock_Ice"
    },
    {
      "x": -16,
      "y": 29,
      "z": -5,
      "name": "Rock_Ice"
    },
    {
      "x": -16,
      "y": 30,
      "z": -5,
      "name": "Rock_Ice"
    },
    {
      "x": -16,
      "y": 31,
      "z": -5,
      "name": "Rock_Ice"
    },
    {
      "x": -16,
      "y": 32,
      "z": -5,
      "name": "Rock_Ice_Permafrost"
    },
    {
      "x": -16,
      "y": 33,
      "z": -5,
      "name": "Rock_Ice_Permafrost"
    },
    {
      "x": -16,
      "y": 34,
      "z": -5,
      "name": "Soil_Snow"
    },
    {
      "x": -16,
      "y": 8,
      "z": -4,
      "name": "Rock_Ice_Permafrost"
    },
    {
      "x": -16,
      "y": 9,
      "z": -4,
      "name": "Rock_Ice_Permafrost"
    },
    {
      "x": -16,
      "y": 10,
      "z": -4,
      "name": "Rock_Ice"
    },
    {
      "x": -16,
      "y": 11,
      "z": -4,
      "name": "Rock_Ice"
    },
    {
      "x": -16,
      "y": 12,
      "z": -4,
      "name": "Rock_Ice"
    },
    {
      "x": -16,
      "y": 13,
      "z": -4,
      "name": "Rock_Ice"
    },
    {
      "x": -16,
      "y": 14,
      "z": -4,
      "name": "Rock_Ice"
    },
    {
      "x": -16,
      "y": 15,
      "z": -4,
      "name": "Rock_Ice"
    },
    {
      "x": -16,
      "y": 16,
      "z": -4,
      "name": "Rock_Ice"
    },
    {
      "x": -16,
      "y": 17,
      "z": -4,
      "name": "Rock_Ice_Permafrost"
    },
    {
      "x": -16,
      "y": 18,
      "z": -4,
      "name": "Rock_Ice_Permafrost"
    },
    {
      "x": -16,
      "y": 19,
      "z": -4,
      "name": "Rock_Ice"
    },
    {
      "x": -16,
      "y": 20,
      "z": -4,
      "name": "Rock_Ice"
    },
    {
      "x": -16,
      "y": 21,
      "z": -4,
      "name": "Rock_Ice"
    },
    {
      "x": -16,
      "y": 22,
      "z": -4,
      "name": "Rock_Ice"
    },
    {
      "x": -16,
      "y": 23,
      "z": -4,
      "name": "Rock_Ice"
    },
    {
      "x": -16,
      "y": 24,
      "z": -4,
      "name": "Rock_Ice"
    },
    {
      "x": -16,
      "y": 25,
      "z": -4,
      "name": "Rock_Ice"
    },
    {
      "x": -16,
      "y": 26,
      "z": -4,
      "name": "Rock_Ice"
    },
    {
      "x": -16,
      "y": 27,
      "z": -4,
      "name": "Rock_Ice"
    },
    {
      "x": -16,
      "y": 28,
      "z": -4,
      "name": "Rock_Ice"
    },
    {
      "x": -16,
      "y": 29,
      "z": -4,
      "name": "Rock_Ice"
    },
    {
      "x": -16,
      "y": 30,
      "z": -4,
      "name": "Rock_Ice"
    },
    {
      "x": -16,
      "y": 31,
      "z": -4,
      "name": "Rock_Ice_Permafrost"
    },
    {
      "x": -16,
      "y": 32,
      "z": -4,
      "name": "Rock_Ice_Permafrost"
    },
    {
      "x": -16,
      "y": 33,
      "z": -4,
      "name": "Rock_Ice"
    },
    {
      "x": -16,
      "y": 34,
      "z": -4,
      "name": "Rock_Ice"
    },
    {
      "x": -16,
      "y": 35,
      "z": -4,
      "name": "Soil_Snow"
    },
    {
      "x": -16,
      "y": 9,
      "z": -3,
      "name": "Rock_Ice_Permafrost"
    },
    {
      "x": -16,
      "y": 10,
      "z": -3,
      "name": "Rock_Ice"
    },
    {
      "x": -16,
      "y": 11,
      "z": -3,
      "name": "Rock_Ice"
    },
    {
      "x": -16,
      "y": 12,
      "z": -3,
      "name": "Rock_Ice"
    },
    {
      "x": -16,
      "y": 13,
      "z": -3,
      "name": "Rock_Ice"
    },
    {
      "x": -16,
      "y": 14,
      "z": -3,
      "name": "Rock_Ice"
    },
    {
      "x": -16,
      "y": 15,
      "z": -3,
      "name": "Rock_Ice"
    },
    {
      "x": -16,
      "y": 16,
      "z": -3,
      "name": "Rock_Ice"
    },
    {
      "x": -16,
      "y": 17,
      "z": -3,
      "name": "Rock_Ice_Permafrost"
    },
    {
      "x": -16,
      "y": 18,
      "z": -3,
      "name": "Rock_Ice_Permafrost"
    },
    {
      "x": -16,
      "y": 19,
      "z": -3,
      "name": "Rock_Ice"
    },
    {
      "x": -16,
      "y": 20,
      "z": -3,
      "name": "Rock_Ice"
    },
    {
      "x": -16,
      "y": 21,
      "z": -3,
      "name": "Rock_Ice"
    },
    {
      "x": -16,
      "y": 22,
      "z": -3,
      "name": "Rock_Ice"
    },
    {
      "x": -16,
      "y": 23,
      "z": -3,
      "name": "Rock_Ice"
    },
    {
      "x": -16,
      "y": 24,
      "z": -3,
      "name": "Rock_Ice"
    },
    {
      "x": -16,
      "y": 25,
      "z": -3,
      "name": "Rock_Ice"
    },
    {
      "x": -16,
      "y": 26,
      "z": -3,
      "name": "Rock_Ice"
    },
    {
      "x": -16,
      "y": 27,
      "z": -3,
      "name": "Rock_Ice"
    },
    {
      "x": -16,
      "y": 28,
      "z": -3,
      "name": "Rock_Ice"
    },
    {
      "x": -16,
      "y": 29,
      "z": -3,
      "name": "Rock_Ice"
    },
    {
      "x": -16,
      "y": 30,
      "z": -3,
      "name": "Rock_Ice_Permafrost"
    },
    {
      "x": -16,
      "y": 31,
      "z": -3,
      "name": "Rock_Ice_Permafrost"
    },
    {
      "x": -16,
      "y": 32,
      "z": -3,
      "name": "Rock_Ice"
    },
    {
      "x": -16,
      "y": 33,
      "z": -3,
      "name": "Rock_Ice"
    },
    {
      "x": -16,
      "y": 34,
      "z": -3,
      "name": "Rock_Ice"
    },
    {
      "x": -16,
      "y": 35,
      "z": -3,
      "name": "Rock_Ice"
    },
    {
      "x": -16,
      "y": 36,
      "z": -3,
      "name": "Soil_Snow"
    },
    {
      "x": -16,
      "y": 14,
      "z": -2,
      "name": "Rock_Ice"
    },
    {
      "x": -16,
      "y": 15,
      "z": -2,
      "name": "Rock_Ice"
    },
    {
      "x": -16,
      "y": 16,
      "z": -2,
      "name": "Rock_Ice_Permafrost"
    },
    {
      "x": -16,
      "y": 17,
      "z": -2,
      "name": "Rock_Ice_Permafrost"
    },
    {
      "x": -16,
      "y": 18,
      "z": -2,
      "name": "Rock_Ice"
    },
    {
      "x": -16,
      "y": 19,
      "z": -2,
      "name": "Rock_Ice"
    },
    {
      "x": -16,
      "y": 20,
      "z": -2,
      "name": "Rock_Ice"
    },
    {
      "x": -16,
      "y": 21,
      "z": -2,
      "name": "Rock_Ice"
    },
    {
      "x": -16,
      "y": 22,
      "z": -2,
      "name": "Rock_Ice"
    },
    {
      "x": -16,
      "y": 23,
      "z": -2,
      "name": "Rock_Ice"
    },
    {
      "x": -16,
      "y": 24,
      "z": -2,
      "name": "Rock_Ice"
    },
    {
      "x": -16,
      "y": 25,
      "z": -2,
      "name": "Rock_Ice"
    },
    {
      "x": -16,
      "y": 26,
      "z": -2,
      "name": "Rock_Ice"
    },
    {
      "x": -16,
      "y": 27,
      "z": -2,
      "name": "Rock_Ice"
    },
    {
      "x": -16,
      "y": 28,
      "z": -2,
      "name": "Rock_Ice_Permafrost"
    },
    {
      "x": -16,
      "y": 29,
      "z": -2,
      "name": "Rock_Ice_Permafrost"
    },
    {
      "x": -16,
      "y": 30,
      "z": -2,
      "name": "Rock_Ice_Permafrost"
    },
    {
      "x": -16,
      "y": 31,
      "z": -2,
      "name": "Rock_Ice"
    },
    {
      "x": -16,
      "y": 32,
      "z": -2,
      "name": "Rock_Ice"
    },
    {
      "x": -16,
      "y": 33,
      "z": -2,
      "name": "Rock_Ice"
    },
    {
      "x": -16,
      "y": 34,
      "z": -2,
      "name": "Rock_Ice"
    },
    {
      "x": -16,
      "y": 35,
      "z": -2,
      "name": "Rock_Ice"
    },
    {
      "x": -16,
      "y": 36,
      "z": -2,
      "name": "Rock_Ice"
    },
    {
      "x": -16,
      "y": 37,
      "z": -2,
      "name": "Soil_Snow"
    },
    {
      "x": -16,
      "y": 14,
      "z": -1,
      "name": "Rock_Ice"
    },
    {
      "x": -16,
      "y": 15,
      "z": -1,
      "name": "Rock_Ice"
    },
    {
      "x": -16,
      "y": 16,
      "z": -1,
      "name": "Rock_Ice_Permafrost"
    },
    {
      "x": -16,
      "y": 17,
      "z": -1,
      "name": "Rock_Ice_Permafrost"
    },
    {
      "x": -16,
      "y": 18,
      "z": -1,
      "name": "Rock_Ice"
    },
    {
      "x": -16,
      "y": 19,
      "z": -1,
      "name": "Rock_Ice"
    },
    {
      "x": -16,
      "y": 20,
      "z": -1,
      "name": "Rock_Ice"
    },
    {
      "x": -16,
      "y": 21,
      "z": -1,
      "name": "Rock_Ice"
    },
    {
      "x": -16,
      "y": 22,
      "z": -1,
      "name": "Rock_Ice"
    },
    {
      "x": -16,
      "y": 23,
      "z": -1,
      "name": "Rock_Ice"
    },
    {
      "x": -16,
      "y": 24,
      "z": -1,
      "name": "Rock_Ice"
    },
    {
      "x": -16,
      "y": 25,
      "z": -1,
      "name": "Rock_Ice"
    },
    {
      "x": -16,
      "y": 26,
      "z": -1,
      "name": "Rock_Ice"
    },
    {
      "x": -16,
      "y": 27,
      "z": -1,
      "name": "Rock_Ice"
    },
    {
      "x": -16,
      "y": 28,
      "z": -1,
      "name": "Rock_Ice_Permafrost"
    },
    {
      "x": -16,
      "y": 29,
      "z": -1,
      "name": "Rock_Ice_Permafrost"
    },
    {
      "x": -16,
      "y": 30,
      "z": -1,
      "name": "Rock_Ice"
    },
    {
      "x": -16,
      "y": 31,
      "z": -1,
      "name": "Rock_Ice"
    },
    {
      "x": -16,
      "y": 32,
      "z": -1,
      "name": "Rock_Ice"
    },
    {
      "x": -16,
      "y": 33,
      "z": -1,
      "name": "Rock_Ice"
    },
    {
      "x": -16,
      "y": 34,
      "z": -1,
      "name": "Rock_Ice"
    },
    {
      "x": -16,
      "y": 35,
      "z": -1,
      "name": "Rock_Ice"
    },
    {
      "x": -16,
      "y": 36,
      "z": -1,
      "name": "Rock_Ice"
    },
    {
      "x": -16,
      "y": 37,
      "z": -1,
      "name": "Soil_Snow"
    },
    {
      "x": -16,
      "y": 13,
      "z": 0,
      "name": "Rock_Ice"
    },
    {
      "x": -16,
      "y": 14,
      "z": 0,
      "name": "Rock_Ice"
    },
    {
      "x": -16,
      "y": 15,
      "z": 0,
      "name": "Rock_Ice_Permafrost"
    },
    {
      "x": -16,
      "y": 16,
      "z": 0,
      "name": "Rock_Ice_Permafrost"
    },
    {
      "x": -16,
      "y": 17,
      "z": 0,
      "name": "Rock_Ice_Permafrost"
    },
    {
      "x": -16,
      "y": 18,
      "z": 0,
      "name": "Rock_Ice"
    },
    {
      "x": -16,
      "y": 19,
      "z": 0,
      "name": "Rock_Ice"
    },
    {
      "x": -16,
      "y": 20,
      "z": 0,
      "name": "Rock_Ice"
    },
    {
      "x": -16,
      "y": 21,
      "z": 0,
      "name": "Rock_Ice"
    },
    {
      "x": -16,
      "y": 22,
      "z": 0,
      "name": "Rock_Ice"
    },
    {
      "x": -16,
      "y": 23,
      "z": 0,
      "name": "Rock_Ice"
    },
    {
      "x": -16,
      "y": 24,
      "z": 0,
      "name": "Rock_Ice"
    },
    {
      "x": -16,
      "y": 25,
      "z": 0,
      "name": "Rock_Ice"
    },
    {
      "x": -16,
      "y": 26,
      "z": 0,
      "name": "Rock_Ice"
    },
    {
      "x": -16,
      "y": 27,
      "z": 0,
      "name": "Rock_Ice_Permafrost"
    },
    {
      "x": -16,
      "y": 28,
      "z": 0,
      "name": "Rock_Ice_Permafrost"
    },
    {
      "x": -16,
      "y": 29,
      "z": 0,
      "name": "Rock_Ice"
    },
    {
      "x": -16,
      "y": 30,
      "z": 0,
      "name": "Rock_Ice"
    },
    {
      "x": -16,
      "y": 31,
      "z": 0,
      "name": "Rock_Ice"
    },
    {
      "x": -16,
      "y": 32,
      "z": 0,
      "name": "Rock_Ice"
    },
    {
      "x": -16,
      "y": 33,
      "z": 0,
      "name": "Rock_Ice"
    },
    {
      "x": -16,
      "y": 34,
      "z": 0,
      "name": "Rock_Ice"
    },
    {
      "x": -16,
      "y": 35,
      "z": 0,
      "name": "Rock_Ice"
    },
    {
      "x": -16,
      "y": 36,
      "z": 0,
      "name": "Rock_Ice"
    },
    {
      "x": -16,
      "y": 37,
      "z": 0,
      "name": "Rock_Ice"
    },
    {
      "x": -16,
      "y": 38,
      "z": 0,
      "name": "Soil_Snow"
    },
    {
      "x": -16,
      "y": 12,
      "z": 1,
      "name": "Rock_Ice"
    },
    {
      "x": -16,
      "y": 13,
      "z": 1,
      "name": "Rock_Ice"
    },
    {
      "x": -16,
      "y": 14,
      "z": 1,
      "name": "Rock_Ice"
    },
    {
      "x": -16,
      "y": 15,
      "z": 1,
      "name": "Rock_Ice"
    },
    {
      "x": -16,
      "y": 16,
      "z": 1,
      "name": "Rock_Ice_Permafrost"
    },
    {
      "x": -16,
      "y": 17,
      "z": 1,
      "name": "Rock_Ice_Permafrost"
    },
    {
      "x": -16,
      "y": 18,
      "z": 1,
      "name": "Rock_Ice"
    },
    {
      "x": -16,
      "y": 19,
      "z": 1,
      "name": "Rock_Ice"
    },
    {
      "x": -16,
      "y": 20,
      "z": 1,
      "name": "Rock_Ice"
    },
    {
      "x": -16,
      "y": 21,
      "z": 1,
      "name": "Rock_Ice"
    },
    {
      "x": -16,
      "y": 22,
      "z": 1,
      "name": "Rock_Ice"
    },
    {
      "x": -16,
      "y": 23,
      "z": 1,
      "name": "Rock_Ice"
    },
    {
      "x": -16,
      "y": 24,
      "z": 1,
      "name": "Rock_Ice"
    },
    {
      "x": -16,
      "y": 25,
      "z": 1,
      "name": "Rock_Ice"
    },
    {
      "x": -16,
      "y": 26,
      "z": 1,
      "name": "Rock_Ice_Permafrost"
    },
    {
      "x": -16,
      "y": 27,
      "z": 1,
      "name": "Rock_Ice_Permafrost"
    },
    {
      "x": -16,
      "y": 28,
      "z": 1,
      "name": "Rock_Ice"
    },
    {
      "x": -16,
      "y": 29,
      "z": 1,
      "name": "Rock_Ice"
    },
    {
      "x": -16,
      "y": 30,
      "z": 1,
      "name": "Rock_Ice"
    },
    {
      "x": -16,
      "y": 31,
      "z": 1,
      "name": "Rock_Ice"
    },
    {
      "x": -16,
      "y": 32,
      "z": 1,
      "name": "Rock_Ice"
    },
    {
      "x": -16,
      "y": 33,
      "z": 1,
      "name": "Rock_Ice"
    },
    {
      "x": -16,
      "y": 34,
      "z": 1,
      "name": "Rock_Ice"
    },
    {
      "x": -16,
      "y": 35,
      "z": 1,
      "name": "Rock_Ice"
    },
    {
      "x": -16,
      "y": 36,
      "z": 1,
      "name": "Rock_Ice"
    },
    {
      "x": -16,
      "y": 37,
      "z": 1,
      "name": "Soil_Snow"
    },
    {
      "x": -16,
      "y": 13,
      "z": 2,
      "name": "Rock_Ice"
    },
    {
      "x": -16,
      "y": 14,
      "z": 2,
      "name": "Rock_Ice"
    },
    {
      "x": -16,
      "y": 15,
      "z": 2,
      "name": "Rock_Ice_Permafrost"
    },
    {
      "x": -16,
      "y": 16,
      "z": 2,
      "name": "Rock_Ice_Permafrost"
    },
    {
      "x": -16,
      "y": 17,
      "z": 2,
      "name": "Rock_Ice"
    },
    {
      "x": -16,
      "y": 18,
      "z": 2,
      "name": "Rock_Ice"
    },
    {
      "x": -16,
      "y": 19,
      "z": 2,
      "name": "Rock_Ice"
    },
    {
      "x": -16,
      "y": 20,
      "z": 2,
      "name": "Rock_Ice"
    },
    {
      "x": -16,
      "y": 21,
      "z": 2,
      "name": "Rock_Ice"
    },
    {
      "x": -16,
      "y": 22,
      "z": 2,
      "name": "Rock_Ice"
    },
    {
      "x": -16,
      "y": 23,
      "z": 2,
      "name": "Rock_Ice"
    },
    {
      "x": -16,
      "y": 24,
      "z": 2,
      "name": "Rock_Ice"
    },
    {
      "x": -16,
      "y": 25,
      "z": 2,
      "name": "Rock_Ice_Permafrost"
    },
    {
      "x": -16,
      "y": 26,
      "z": 2,
      "name": "Rock_Ice_Permafrost"
    },
    {
      "x": -16,
      "y": 27,
      "z": 2,
      "name": "Rock_Ice_Permafrost"
    },
    {
      "x": -16,
      "y": 28,
      "z": 2,
      "name": "Rock_Ice"
    },
    {
      "x": -16,
      "y": 29,
      "z": 2,
      "name": "Rock_Ice"
    },
    {
      "x": -16,
      "y": 30,
      "z": 2,
      "name": "Rock_Ice"
    },
    {
      "x": -16,
      "y": 31,
      "z": 2,
      "name": "Rock_Ice"
    },
    {
      "x": -16,
      "y": 32,
      "z": 2,
      "name": "Rock_Ice"
    },
    {
      "x": -16,
      "y": 33,
      "z": 2,
      "name": "Rock_Ice"
    },
    {
      "x": -16,
      "y": 34,
      "z": 2,
      "name": "Rock_Ice"
    },
    {
      "x": -16,
      "y": 35,
      "z": 2,
      "name": "Soil_Snow"
    },
    {
      "x": -16,
      "y": 13,
      "z": 3,
      "name": "Rock_Ice"
    },
    {
      "x": -16,
      "y": 14,
      "z": 3,
      "name": "Rock_Ice_Permafrost"
    },
    {
      "x": -16,
      "y": 15,
      "z": 3,
      "name": "Rock_Ice_Permafrost"
    },
    {
      "x": -16,
      "y": 16,
      "z": 3,
      "name": "Rock_Ice_Permafrost"
    },
    {
      "x": -16,
      "y": 17,
      "z": 3,
      "name": "Rock_Ice_Permafrost"
    },
    {
      "x": -16,
      "y": 18,
      "z": 3,
      "name": "Rock_Ice"
    },
    {
      "x": -16,
      "y": 19,
      "z": 3,
      "name": "Rock_Ice"
    },
    {
      "x": -16,
      "y": 20,
      "z": 3,
      "name": "Rock_Ice"
    },
    {
      "x": -16,
      "y": 21,
      "z": 3,
      "name": "Rock_Ice"
    },
    {
      "x": -16,
      "y": 22,
      "z": 3,
      "name": "Rock_Ice"
    },
    {
      "x": -16,
      "y": 23,
      "z": 3,
      "name": "Rock_Ice"
    },
    {
      "x": -16,
      "y": 24,
      "z": 3,
      "name": "Rock_Ice_Permafrost"
    },
    {
      "x": -16,
      "y": 25,
      "z": 3,
      "name": "Rock_Ice_Permafrost"
    },
    {
      "x": -16,
      "y": 26,
      "z": 3,
      "name": "Rock_Ice_Permafrost"
    },
    {
      "x": -16,
      "y": 27,
      "z": 3,
      "name": "Rock_Ice"
    },
    {
      "x": -16,
      "y": 28,
      "z": 3,
      "name": "Rock_Ice"
    },
    {
      "x": -16,
      "y": 29,
      "z": 3,
      "name": "Rock_Ice"
    },
    {
      "x": -16,
      "y": 30,
      "z": 3,
      "name": "Rock_Ice"
    },
    {
      "x": -16,
      "y": 31,
      "z": 3,
      "name": "Rock_Ice"
    },
    {
      "x": -16,
      "y": 32,
      "z": 3,
      "name": "Rock_Ice"
    },
    {
      "x": -16,
      "y": 33,
      "z": 3,
      "name": "Rock_Ice"
    },
    {
      "x": -16,
      "y": 34,
      "z": 3,
      "name": "Soil_Snow"
    },
    {
      "x": -16,
      "y": 14,
      "z": 4,
      "name": "Rock_Ice"
    },
    {
      "x": -16,
      "y": 15,
      "z": 4,
      "name": "Rock_Ice_Permafrost"
    },
    {
      "x": -16,
      "y": 16,
      "z": 4,
      "name": "Rock_Ice_Permafrost"
    },
    {
      "x": -16,
      "y": 17,
      "z": 4,
      "name": "Rock_Ice"
    },
    {
      "x": -16,
      "y": 18,
      "z": 4,
      "name": "Rock_Ice"
    },
    {
      "x": -16,
      "y": 19,
      "z": 4,
      "name": "Rock_Ice"
    },
    {
      "x": -16,
      "y": 20,
      "z": 4,
      "name": "Rock_Ice"
    },
    {
      "x": -16,
      "y": 21,
      "z": 4,
      "name": "Rock_Ice"
    },
    {
      "x": -16,
      "y": 22,
      "z": 4,
      "name": "Rock_Ice"
    },
    {
      "x": -16,
      "y": 23,
      "z": 4,
      "name": "Rock_Ice"
    },
    {
      "x": -16,
      "y": 24,
      "z": 4,
      "name": "Rock_Ice_Permafrost"
    },
    {
      "x": -16,
      "y": 25,
      "z": 4,
      "name": "Rock_Ice_Permafrost"
    },
    {
      "x": -16,
      "y": 26,
      "z": 4,
      "name": "Rock_Ice_Permafrost"
    },
    {
      "x": -16,
      "y": 27,
      "z": 4,
      "name": "Rock_Ice"
    },
    {
      "x": -16,
      "y": 28,
      "z": 4,
      "name": "Rock_Ice"
    },
    {
      "x": -16,
      "y": 29,
      "z": 4,
      "name": "Rock_Ice"
    },
    {
      "x": -16,
      "y": 30,
      "z": 4,
      "name": "Rock_Ice"
    },
    {
      "x": -16,
      "y": 31,
      "z": 4,
      "name": "Rock_Ice"
    },
    {
      "x": -16,
      "y": 32,
      "z": 4,
      "name": "Rock_Ice"
    },
    {
      "x": -16,
      "y": 33,
      "z": 4,
      "name": "Soil_Snow"
    },
    {
      "x": -16,
      "y": 15,
      "z": 5,
      "name": "Rock_Ice_Permafrost"
    },
    {
      "x": -16,
      "y": 16,
      "z": 5,
      "name": "Rock_Ice_Permafrost"
    },
    {
      "x": -16,
      "y": 17,
      "z": 5,
      "name": "Rock_Ice"
    },
    {
      "x": -16,
      "y": 18,
      "z": 5,
      "name": "Rock_Ice"
    },
    {
      "x": -16,
      "y": 19,
      "z": 5,
      "name": "Rock_Ice"
    },
    {
      "x": -16,
      "y": 20,
      "z": 5,
      "name": "Rock_Ice"
    },
    {
      "x": -16,
      "y": 21,
      "z": 5,
      "name": "Rock_Ice"
    },
    {
      "x": -16,
      "y": 22,
      "z": 5,
      "name": "Rock_Ice"
    },
    {
      "x": -16,
      "y": 23,
      "z": 5,
      "name": "Rock_Ice_Permafrost"
    },
    {
      "x": -16,
      "y": 24,
      "z": 5,
      "name": "Rock_Ice_Permafrost"
    },
    {
      "x": -16,
      "y": 25,
      "z": 5,
      "name": "Rock_Ice_Permafrost"
    },
    {
      "x": -16,
      "y": 26,
      "z": 5,
      "name": "Rock_Ice"
    },
    {
      "x": -16,
      "y": 27,
      "z": 5,
      "name": "Rock_Ice"
    },
    {
      "x": -16,
      "y": 28,
      "z": 5,
      "name": "Rock_Ice"
    },
    {
      "x": -16,
      "y": 29,
      "z": 5,
      "name": "Rock_Ice"
    },
    {
      "x": -16,
      "y": 30,
      "z": 5,
      "name": "Rock_Ice"
    },
    {
      "x": -16,
      "y": 31,
      "z": 5,
      "name": "Soil_Snow"
    },
    {
      "x": -16,
      "y": 19,
      "z": 6,
      "name": "Rock_Ice"
    },
    {
      "x": -16,
      "y": 20,
      "z": 6,
      "name": "Rock_Ice"
    },
    {
      "x": -16,
      "y": 21,
      "z": 6,
      "name": "Rock_Ice"
    },
    {
      "x": -16,
      "y": 22,
      "z": 6,
      "name": "Rock_Ice"
    },
    {
      "x": -16,
      "y": 23,
      "z": 6,
      "name": "Rock_Ice_Permafrost"
    },
    {
      "x": -16,
      "y": 24,
      "z": 6,
      "name": "Rock_Ice_Permafrost"
    },
    {
      "x": -16,
      "y": 25,
      "z": 6,
      "name": "Rock_Ice_Permafrost"
    },
    {
      "x": -16,
      "y": 26,
      "z": 6,
      "name": "Rock_Ice"
    },
    {
      "x": -16,
      "y": 27,
      "z": 6,
      "name": "Rock_Ice"
    },
    {
      "x": -16,
      "y": 28,
      "z": 6,
      "name": "Rock_Ice"
    },
    {
      "x": -16,
      "y": 29,
      "z": 6,
      "name": "Soil_Snow"
    },
    {
      "x": -16,
      "y": 21,
      "z": 7,
      "name": "Rock_Ice_Permafrost"
    },
    {
      "x": -16,
      "y": 22,
      "z": 7,
      "name": "Rock_Ice_Permafrost"
    },
    {
      "x": -16,
      "y": 23,
      "z": 7,
      "name": "Rock_Ice_Permafrost"
    },
    {
      "x": -16,
      "y": 24,
      "z": 7,
      "name": "Rock_Ice_Permafrost"
    },
    {
      "x": -16,
      "y": 25,
      "z": 7,
      "name": "Rock_Ice_Permafrost"
    },
    {
      "x": -16,
      "y": 26,
      "z": 7,
      "name": "Rock_Ice"
    },
    {
      "x": -16,
      "y": 27,
      "z": 7,
      "name": "Soil_Snow"
    },
    {
      "x": -16,
      "y": 23,
      "z": 8,
      "name": "Rock_Ice_Permafrost"
    },
    {
      "x": -16,
      "y": 24,
      "z": 8,
      "name": "Rock_Ice_Permafrost"
    },
    {
      "x": -16,
      "y": 25,
      "z": 8,
      "name": "Rock_Ice"
    },
    {
      "x": -16,
      "y": 26,
      "z": 8,
      "name": "Soil_Snow"
    },
    {
      "x": -16,
      "y": 24,
      "z": 9,
      "name": "Rock_Ice_Permafrost"
    },
    {
      "x": -15,
      "y": 33,
      "z": -8,
      "name": "Rock_Ice"
    },
    {
      "x": -15,
      "y": 34,
      "z": -8,
      "name": "Soil_Snow"
    },
    {
      "x": -15,
      "y": 25,
      "z": -7,
      "name": "Rock_Ice"
    },
    {
      "x": -15,
      "y": 26,
      "z": -7,
      "name": "Rock_Ice"
    },
    {
      "x": -15,
      "y": 27,
      "z": -7,
      "name": "Rock_Ice"
    },
    {
      "x": -15,
      "y": 28,
      "z": -7,
      "name": "Rock_Ice"
    },
    {
      "x": -15,
      "y": 29,
      "z": -7,
      "name": "Rock_Ice"
    },
    {
      "x": -15,
      "y": 30,
      "z": -7,
      "name": "Rock_Ice"
    },
    {
      "x": -15,
      "y": 31,
      "z": -7,
      "name": "Rock_Ice"
    },
    {
      "x": -15,
      "y": 32,
      "z": -7,
      "name": "Rock_Ice"
    },
    {
      "x": -15,
      "y": 33,
      "z": -7,
      "name": "Rock_Ice"
    },
    {
      "x": -15,
      "y": 34,
      "z": -7,
      "name": "Soil_Snow"
    },
    {
      "x": -15,
      "y": 13,
      "z": -6,
      "name": "Rock_Ice"
    },
    {
      "x": -15,
      "y": 14,
      "z": -6,
      "name": "Rock_Ice"
    },
    {
      "x": -15,
      "y": 15,
      "z": -6,
      "name": "Rock_Ice"
    },
    {
      "x": -15,
      "y": 22,
      "z": -6,
      "name": "Rock_Ice"
    },
    {
      "x": -15,
      "y": 23,
      "z": -6,
      "name": "Rock_Ice"
    },
    {
      "x": -15,
      "y": 24,
      "z": -6,
      "name": "Rock_Ice"
    },
    {
      "x": -15,
      "y": 25,
      "z": -6,
      "name": "Rock_Ice"
    },
    {
      "x": -15,
      "y": 26,
      "z": -6,
      "name": "Rock_Ice"
    },
    {
      "x": -15,
      "y": 27,
      "z": -6,
      "name": "Rock_Ice"
    },
    {
      "x": -15,
      "y": 28,
      "z": -6,
      "name": "Rock_Ice"
    },
    {
      "x": -15,
      "y": 29,
      "z": -6,
      "name": "Rock_Ice"
    },
    {
      "x": -15,
      "y": 30,
      "z": -6,
      "name": "Rock_Ice"
    },
    {
      "x": -15,
      "y": 31,
      "z": -6,
      "name": "Rock_Ice"
    },
    {
      "x": -15,
      "y": 32,
      "z": -6,
      "name": "Rock_Ice"
    },
    {
      "x": -15,
      "y": 33,
      "z": -6,
      "name": "Rock_Ice_Permafrost"
    },
    {
      "x": -15,
      "y": 34,
      "z": -6,
      "name": "Rock_Ice_Permafrost"
    },
    {
      "x": -15,
      "y": 35,
      "z": -6,
      "name": "Soil_Snow"
    },
    {
      "x": -15,
      "y": 9,
      "z": -5,
      "name": "Rock_Ice_Permafrost"
    },
    {
      "x": -15,
      "y": 10,
      "z": -5,
      "name": "Rock_Ice_Permafrost"
    },
    {
      "x": -15,
      "y": 11,
      "z": -5,
      "name": "Rock_Ice_Permafrost"
    },
    {
      "x": -15,
      "y": 12,
      "z": -5,
      "name": "Rock_Ice"
    },
    {
      "x": -15,
      "y": 13,
      "z": -5,
      "name": "Rock_Ice"
    },
    {
      "x": -15,
      "y": 14,
      "z": -5,
      "name": "Rock_Ice"
    },
    {
      "x": -15,
      "y": 15,
      "z": -5,
      "name": "Rock_Ice"
    },
    {
      "x": -15,
      "y": 16,
      "z": -5,
      "name": "Rock_Ice"
    },
    {
      "x": -15,
      "y": 18,
      "z": -5,
      "name": "Rock_Ice_Permafrost"
    },
    {
      "x": -15,
      "y": 19,
      "z": -5,
      "name": "Rock_Ice"
    },
    {
      "x": -15,
      "y": 20,
      "z": -5,
      "name": "Rock_Ice"
    },
    {
      "x": -15,
      "y": 21,
      "z": -5,
      "name": "Rock_Ice"
    },
    {
      "x": -15,
      "y": 22,
      "z": -5,
      "name": "Rock_Ice"
    },
    {
      "x": -15,
      "y": 23,
      "z": -5,
      "name": "Rock_Ice"
    },
    {
      "x": -15,
      "y": 24,
      "z": -5,
      "name": "Rock_Ice"
    },
    {
      "x": -15,
      "y": 25,
      "z": -5,
      "name": "Rock_Ice"
    },
    {
      "x": -15,
      "y": 26,
      "z": -5,
      "name": "Rock_Ice"
    },
    {
      "x": -15,
      "y": 27,
      "z": -5,
      "name": "Rock_Ice"
    },
    {
      "x": -15,
      "y": 28,
      "z": -5,
      "name": "Rock_Ice"
    },
    {
      "x": -15,
      "y": 29,
      "z": -5,
      "name": "Rock_Ice"
    },
    {
      "x": -15,
      "y": 30,
      "z": -5,
      "name": "Rock_Ice"
    },
    {
      "x": -15,
      "y": 31,
      "z": -5,
      "name": "Rock_Ice"
    },
    {
      "x": -15,
      "y": 32,
      "z": -5,
      "name": "Rock_Ice_Permafrost"
    },
    {
      "x": -15,
      "y": 33,
      "z": -5,
      "name": "Rock_Ice_Permafrost"
    },
    {
      "x": -15,
      "y": 34,
      "z": -5,
      "name": "Rock_Ice"
    },
    {
      "x": -15,
      "y": 35,
      "z": -5,
      "name": "Soil_Snow"
    },
    {
      "x": -15,
      "y": 6,
      "z": -4,
      "name": "Rock_Ice_Permafrost"
    },
    {
      "x": -15,
      "y": 7,
      "z": -4,
      "name": "Rock_Ice_Permafrost"
    },
    {
      "x": -15,
      "y": 8,
      "z": -4,
      "name": "Rock_Ice_Permafrost"
    },
    {
      "x": -15,
      "y": 9,
      "z": -4,
      "name": "Rock_Ice_Permafrost"
    },
    {
      "x": -15,
      "y": 10,
      "z": -4,
      "name": "Rock_Ice_Permafrost"
    },
    {
      "x": -15,
      "y": 11,
      "z": -4,
      "name": "Rock_Ice"
    },
    {
      "x": -15,
      "y": 12,
      "z": -4,
      "name": "Rock_Ice"
    },
    {
      "x": -15,
      "y": 13,
      "z": -4,
      "name": "Rock_Ice"
    },
    {
      "x": -15,
      "y": 14,
      "z": -4,
      "name": "Rock_Ice"
    },
    {
      "x": -15,
      "y": 15,
      "z": -4,
      "name": "Rock_Ice"
    },
    {
      "x": -15,
      "y": 16,
      "z": -4,
      "name": "Rock_Ice"
    },
    {
      "x": -15,
      "y": 17,
      "z": -4,
      "name": "Rock_Ice_Permafrost"
    },
    {
      "x": -15,
      "y": 18,
      "z": -4,
      "name": "Rock_Ice_Permafrost"
    },
    {
      "x": -15,
      "y": 19,
      "z": -4,
      "name": "Rock_Ice"
    },
    {
      "x": -15,
      "y": 20,
      "z": -4,
      "name": "Rock_Ice"
    },
    {
      "x": -15,
      "y": 21,
      "z": -4,
      "name": "Rock_Ice"
    },
    {
      "x": -15,
      "y": 22,
      "z": -4,
      "name": "Rock_Ice"
    },
    {
      "x": -15,
      "y": 23,
      "z": -4,
      "name": "Rock_Ice"
    },
    {
      "x": -15,
      "y": 24,
      "z": -4,
      "name": "Rock_Ice"
    },
    {
      "x": -15,
      "y": 25,
      "z": -4,
      "name": "Rock_Ice"
    },
    {
      "x": -15,
      "y": 26,
      "z": -4,
      "name": "Rock_Ice"
    },
    {
      "x": -15,
      "y": 27,
      "z": -4,
      "name": "Rock_Ice"
    },
    {
      "x": -15,
      "y": 28,
      "z": -4,
      "name": "Rock_Ice"
    },
    {
      "x": -15,
      "y": 29,
      "z": -4,
      "name": "Rock_Ice"
    },
    {
      "x": -15,
      "y": 30,
      "z": -4,
      "name": "Rock_Ice"
    },
    {
      "x": -15,
      "y": 31,
      "z": -4,
      "name": "Rock_Ice_Permafrost"
    },
    {
      "x": -15,
      "y": 32,
      "z": -4,
      "name": "Rock_Ice_Permafrost"
    },
    {
      "x": -15,
      "y": 33,
      "z": -4,
      "name": "Rock_Ice"
    },
    {
      "x": -15,
      "y": 34,
      "z": -4,
      "name": "Rock_Ice"
    },
    {
      "x": -15,
      "y": 35,
      "z": -4,
      "name": "Soil_Snow"
    },
    {
      "x": -15,
      "y": 6,
      "z": -3,
      "name": "Rock_Ice"
    },
    {
      "x": -15,
      "y": 7,
      "z": -3,
      "name": "Rock_Ice_Permafrost"
    },
    {
      "x": -15,
      "y": 8,
      "z": -3,
      "name": "Rock_Ice_Permafrost"
    },
    {
      "x": -15,
      "y": 9,
      "z": -3,
      "name": "Rock_Ice_Permafrost"
    },
    {
      "x": -15,
      "y": 10,
      "z": -3,
      "name": "Rock_Ice_Permafrost"
    },
    {
      "x": -15,
      "y": 11,
      "z": -3,
      "name": "Rock_Ice"
    },
    {
      "x": -15,
      "y": 12,
      "z": -3,
      "name": "Rock_Ice"
    },
    {
      "x": -15,
      "y": 13,
      "z": -3,
      "name": "Rock_Ice"
    },
    {
      "x": -15,
      "y": 14,
      "z": -3,
      "name": "Rock_Ice"
    },
    {
      "x": -15,
      "y": 15,
      "z": -3,
      "name": "Rock_Ice"
    },
    {
      "x": -15,
      "y": 16,
      "z": -3,
      "name": "Rock_Ice"
    },
    {
      "x": -15,
      "y": 17,
      "z": -3,
      "name": "Rock_Ice_Permafrost"
    },
    {
      "x": -15,
      "y": 18,
      "z": -3,
      "name": "Rock_Ice_Permafrost"
    },
    {
      "x": -15,
      "y": 19,
      "z": -3,
      "name": "Rock_Ice"
    },
    {
      "x": -15,
      "y": 20,
      "z": -3,
      "name": "Rock_Ice"
    },
    {
      "x": -15,
      "y": 21,
      "z": -3,
      "name": "Rock_Ice"
    },
    {
      "x": -15,
      "y": 22,
      "z": -3,
      "name": "Rock_Ice"
    },
    {
      "x": -15,
      "y": 23,
      "z": -3,
      "name": "Rock_Ice"
    },
    {
      "x": -15,
      "y": 24,
      "z": -3,
      "name": "Rock_Ice"
    },
    {
      "x": -15,
      "y": 25,
      "z": -3,
      "name": "Rock_Ice"
    },
    {
      "x": -15,
      "y": 26,
      "z": -3,
      "name": "Rock_Ice"
    },
    {
      "x": -15,
      "y": 27,
      "z": -3,
      "name": "Rock_Ice"
    },
    {
      "x": -15,
      "y": 28,
      "z": -3,
      "name": "Rock_Ice"
    },
    {
      "x": -15,
      "y": 29,
      "z": -3,
      "name": "Rock_Ice"
    },
    {
      "x": -15,
      "y": 30,
      "z": -3,
      "name": "Rock_Ice_Permafrost"
    },
    {
      "x": -15,
      "y": 31,
      "z": -3,
      "name": "Rock_Ice_Permafrost"
    },
    {
      "x": -15,
      "y": 32,
      "z": -3,
      "name": "Rock_Ice"
    },
    {
      "x": -15,
      "y": 33,
      "z": -3,
      "name": "Rock_Ice"
    },
    {
      "x": -15,
      "y": 34,
      "z": -3,
      "name": "Rock_Ice"
    },
    {
      "x": -15,
      "y": 35,
      "z": -3,
      "name": "Soil_Snow"
    },
    {
      "x": -15,
      "y": 6,
      "z": -2,
      "name": "Rock_Ice"
    },
    {
      "x": -15,
      "y": 7,
      "z": -2,
      "name": "Rock_Ice_Permafrost"
    },
    {
      "x": -15,
      "y": 8,
      "z": -2,
      "name": "Rock_Ice_Permafrost"
    },
    {
      "x": -15,
      "y": 9,
      "z": -2,
      "name": "Rock_Ice_Permafrost"
    },
    {
      "x": -15,
      "y": 10,
      "z": -2,
      "name": "Rock_Ice_Permafrost"
    },
    {
      "x": -15,
      "y": 11,
      "z": -2,
      "name": "Rock_Ice_Permafrost"
    },
    {
      "x": -15,
      "y": 12,
      "z": -2,
      "name": "Rock_Ice"
    },
    {
      "x": -15,
      "y": 13,
      "z": -2,
      "name": "Rock_Ice"
    },
    {
      "x": -15,
      "y": 14,
      "z": -2,
      "name": "Rock_Ice"
    },
    {
      "x": -15,
      "y": 15,
      "z": -2,
      "name": "Rock_Ice"
    },
    {
      "x": -15,
      "y": 16,
      "z": -2,
      "name": "Rock_Ice"
    },
    {
      "x": -15,
      "y": 17,
      "z": -2,
      "name": "Rock_Ice_Permafrost"
    },
    {
      "x": -15,
      "y": 18,
      "z": -2,
      "name": "Rock_Ice"
    },
    {
      "x": -15,
      "y": 19,
      "z": -2,
      "name": "Rock_Ice"
    },
    {
      "x": -15,
      "y": 20,
      "z": -2,
      "name": "Rock_Ice"
    },
    {
      "x": -15,
      "y": 21,
      "z": -2,
      "name": "Rock_Ice"
    },
    {
      "x": -15,
      "y": 22,
      "z": -2,
      "name": "Rock_Ice"
    },
    {
      "x": -15,
      "y": 23,
      "z": -2,
      "name": "Rock_Ice"
    },
    {
      "x": -15,
      "y": 24,
      "z": -2,
      "name": "Rock_Ice"
    },
    {
      "x": -15,
      "y": 25,
      "z": -2,
      "name": "Rock_Ice"
    },
    {
      "x": -15,
      "y": 26,
      "z": -2,
      "name": "Rock_Ice"
    },
    {
      "x": -15,
      "y": 27,
      "z": -2,
      "name": "Rock_Ice"
    },
    {
      "x": -15,
      "y": 28,
      "z": -2,
      "name": "Rock_Ice"
    },
    {
      "x": -15,
      "y": 29,
      "z": -2,
      "name": "Rock_Ice_Permafrost"
    },
    {
      "x": -15,
      "y": 30,
      "z": -2,
      "name": "Rock_Ice_Permafrost"
    },
    {
      "x": -15,
      "y": 31,
      "z": -2,
      "name": "Rock_Ice"
    },
    {
      "x": -15,
      "y": 32,
      "z": -2,
      "name": "Rock_Ice"
    },
    {
      "x": -15,
      "y": 33,
      "z": -2,
      "name": "Rock_Ice"
    },
    {
      "x": -15,
      "y": 34,
      "z": -2,
      "name": "Rock_Ice"
    },
    {
      "x": -15,
      "y": 35,
      "z": -2,
      "name": "Rock_Ice"
    },
    {
      "x": -15,
      "y": 36,
      "z": -2,
      "name": "Soil_Snow"
    },
    {
      "x": -15,
      "y": 6,
      "z": -1,
      "name": "Rock_Ice_Permafrost"
    },
    {
      "x": -15,
      "y": 7,
      "z": -1,
      "name": "Rock_Ice_Permafrost"
    },
    {
      "x": -15,
      "y": 8,
      "z": -1,
      "name": "Rock_Ice_Permafrost"
    },
    {
      "x": -15,
      "y": 11,
      "z": -1,
      "name": "Rock_Ice_Permafrost"
    },
    {
      "x": -15,
      "y": 12,
      "z": -1,
      "name": "Rock_Ice"
    },
    {
      "x": -15,
      "y": 13,
      "z": -1,
      "name": "Rock_Ice"
    },
    {
      "x": -15,
      "y": 14,
      "z": -1,
      "name": "Rock_Ice"
    },
    {
      "x": -15,
      "y": 15,
      "z": -1,
      "name": "Rock_Ice"
    },
    {
      "x": -15,
      "y": 16,
      "z": -1,
      "name": "Rock_Ice_Permafrost"
    },
    {
      "x": -15,
      "y": 17,
      "z": -1,
      "name": "Rock_Ice_Permafrost"
    },
    {
      "x": -15,
      "y": 18,
      "z": -1,
      "name": "Rock_Ice"
    },
    {
      "x": -15,
      "y": 19,
      "z": -1,
      "name": "Rock_Ice"
    },
    {
      "x": -15,
      "y": 20,
      "z": -1,
      "name": "Rock_Ice"
    },
    {
      "x": -15,
      "y": 21,
      "z": -1,
      "name": "Rock_Ice"
    },
    {
      "x": -15,
      "y": 22,
      "z": -1,
      "name": "Rock_Ice"
    },
    {
      "x": -15,
      "y": 23,
      "z": -1,
      "name": "Rock_Ice"
    },
    {
      "x": -15,
      "y": 24,
      "z": -1,
      "name": "Rock_Ice"
    },
    {
      "x": -15,
      "y": 25,
      "z": -1,
      "name": "Rock_Ice"
    },
    {
      "x": -15,
      "y": 26,
      "z": -1,
      "name": "Rock_Ice"
    },
    {
      "x": -15,
      "y": 27,
      "z": -1,
      "name": "Rock_Ice"
    },
    {
      "x": -15,
      "y": 28,
      "z": -1,
      "name": "Rock_Ice_Permafrost"
    },
    {
      "x": -15,
      "y": 29,
      "z": -1,
      "name": "Rock_Ice_Permafrost"
    },
    {
      "x": -15,
      "y": 30,
      "z": -1,
      "name": "Rock_Ice"
    },
    {
      "x": -15,
      "y": 31,
      "z": -1,
      "name": "Rock_Ice"
    },
    {
      "x": -15,
      "y": 32,
      "z": -1,
      "name": "Rock_Ice"
    },
    {
      "x": -15,
      "y": 33,
      "z": -1,
      "name": "Rock_Ice"
    },
    {
      "x": -15,
      "y": 34,
      "z": -1,
      "name": "Rock_Ice"
    },
    {
      "x": -15,
      "y": 35,
      "z": -1,
      "name": "Rock_Ice"
    },
    {
      "x": -15,
      "y": 36,
      "z": -1,
      "name": "Soil_Snow"
    },
    {
      "x": -15,
      "y": 11,
      "z": 0,
      "name": "Rock_Ice"
    },
    {
      "x": -15,
      "y": 12,
      "z": 0,
      "name": "Rock_Ice"
    },
    {
      "x": -15,
      "y": 13,
      "z": 0,
      "name": "Rock_Ice"
    },
    {
      "x": -15,
      "y": 14,
      "z": 0,
      "name": "Rock_Ice"
    },
    {
      "x": -15,
      "y": 15,
      "z": 0,
      "name": "Rock_Ice"
    },
    {
      "x": -15,
      "y": 16,
      "z": 0,
      "name": "Rock_Ice_Permafrost"
    },
    {
      "x": -15,
      "y": 17,
      "z": 0,
      "name": "Rock_Ice_Permafrost"
    },
    {
      "x": -15,
      "y": 18,
      "z": 0,
      "name": "Rock_Ice"
    },
    {
      "x": -15,
      "y": 19,
      "z": 0,
      "name": "Rock_Ice"
    },
    {
      "x": -15,
      "y": 20,
      "z": 0,
      "name": "Rock_Ice"
    },
    {
      "x": -15,
      "y": 21,
      "z": 0,
      "name": "Rock_Ice"
    },
    {
      "x": -15,
      "y": 22,
      "z": 0,
      "name": "Rock_Ice"
    },
    {
      "x": -15,
      "y": 23,
      "z": 0,
      "name": "Rock_Ice"
    },
    {
      "x": -15,
      "y": 24,
      "z": 0,
      "name": "Rock_Ice"
    },
    {
      "x": -15,
      "y": 25,
      "z": 0,
      "name": "Rock_Ice"
    },
    {
      "x": -15,
      "y": 26,
      "z": 0,
      "name": "Rock_Ice"
    },
    {
      "x": -15,
      "y": 27,
      "z": 0,
      "name": "Rock_Ice_Permafrost"
    },
    {
      "x": -15,
      "y": 28,
      "z": 0,
      "name": "Rock_Ice_Permafrost"
    },
    {
      "x": -15,
      "y": 29,
      "z": 0,
      "name": "Rock_Ice"
    },
    {
      "x": -15,
      "y": 30,
      "z": 0,
      "name": "Rock_Ice"
    },
    {
      "x": -15,
      "y": 31,
      "z": 0,
      "name": "Rock_Ice"
    },
    {
      "x": -15,
      "y": 32,
      "z": 0,
      "name": "Rock_Ice"
    },
    {
      "x": -15,
      "y": 33,
      "z": 0,
      "name": "Rock_Ice"
    },
    {
      "x": -15,
      "y": 34,
      "z": 0,
      "name": "Rock_Ice"
    },
    {
      "x": -15,
      "y": 35,
      "z": 0,
      "name": "Rock_Ice"
    },
    {
      "x": -15,
      "y": 36,
      "z": 0,
      "name": "Soil_Snow"
    },
    {
      "x": -15,
      "y": 10,
      "z": 1,
      "name": "Rock_Ice_Permafrost"
    },
    {
      "x": -15,
      "y": 11,
      "z": 1,
      "name": "Rock_Ice_Permafrost"
    },
    {
      "x": -15,
      "y": 12,
      "z": 1,
      "name": "Rock_Ice"
    },
    {
      "x": -15,
      "y": 13,
      "z": 1,
      "name": "Rock_Ice"
    },
    {
      "x": -15,
      "y": 14,
      "z": 1,
      "name": "Rock_Ice"
    },
    {
      "x": -15,
      "y": 15,
      "z": 1,
      "name": "Rock_Ice"
    },
    {
      "x": -15,
      "y": 16,
      "z": 1,
      "name": "Rock_Ice_Permafrost"
    },
    {
      "x": -15,
      "y": 17,
      "z": 1,
      "name": "Rock_Ice_Permafrost"
    },
    {
      "x": -15,
      "y": 18,
      "z": 1,
      "name": "Rock_Ice"
    },
    {
      "x": -15,
      "y": 19,
      "z": 1,
      "name": "Rock_Ice"
    },
    {
      "x": -15,
      "y": 20,
      "z": 1,
      "name": "Rock_Ice"
    },
    {
      "x": -15,
      "y": 21,
      "z": 1,
      "name": "Rock_Ice"
    },
    {
      "x": -15,
      "y": 22,
      "z": 1,
      "name": "Rock_Ice"
    },
    {
      "x": -15,
      "y": 23,
      "z": 1,
      "name": "Rock_Ice"
    },
    {
      "x": -15,
      "y": 24,
      "z": 1,
      "name": "Rock_Ice"
    },
    {
      "x": -15,
      "y": 25,
      "z": 1,
      "name": "Rock_Ice"
    },
    {
      "x": -15,
      "y": 26,
      "z": 1,
      "name": "Rock_Ice_Permafrost"
    },
    {
      "x": -15,
      "y": 27,
      "z": 1,
      "name": "Rock_Ice_Permafrost"
    },
    {
      "x": -15,
      "y": 28,
      "z": 1,
      "name": "Rock_Ice"
    },
    {
      "x": -15,
      "y": 29,
      "z": 1,
      "name": "Rock_Ice"
    },
    {
      "x": -15,
      "y": 30,
      "z": 1,
      "name": "Rock_Ice"
    },
    {
      "x": -15,
      "y": 31,
      "z": 1,
      "name": "Rock_Ice"
    },
    {
      "x": -15,
      "y": 32,
      "z": 1,
      "name": "Rock_Ice"
    },
    {
      "x": -15,
      "y": 33,
      "z": 1,
      "name": "Rock_Ice"
    },
    {
      "x": -15,
      "y": 34,
      "z": 1,
      "name": "Rock_Ice"
    },
    {
      "x": -15,
      "y": 35,
      "z": 1,
      "name": "Rock_Ice"
    },
    {
      "x": -15,
      "y": 36,
      "z": 1,
      "name": "Rock_Ice"
    },
    {
      "x": -15,
      "y": 37,
      "z": 1,
      "name": "Soil_Snow"
    },
    {
      "x": -15,
      "y": 9,
      "z": 2,
      "name": "Rock_Ice_Permafrost"
    },
    {
      "x": -15,
      "y": 10,
      "z": 2,
      "name": "Rock_Ice_Permafrost"
    },
    {
      "x": -15,
      "y": 11,
      "z": 2,
      "name": "Rock_Ice_Permafrost"
    },
    {
      "x": -15,
      "y": 12,
      "z": 2,
      "name": "Rock_Ice"
    },
    {
      "x": -15,
      "y": 13,
      "z": 2,
      "name": "Rock_Ice"
    },
    {
      "x": -15,
      "y": 14,
      "z": 2,
      "name": "Rock_Ice"
    },
    {
      "x": -15,
      "y": 15,
      "z": 2,
      "name": "Rock_Ice_Permafrost"
    },
    {
      "x": -15,
      "y": 16,
      "z": 2,
      "name": "Rock_Ice_Permafrost"
    },
    {
      "x": -15,
      "y": 17,
      "z": 2,
      "name": "Rock_Ice"
    },
    {
      "x": -15,
      "y": 18,
      "z": 2,
      "name": "Rock_Ice"
    },
    {
      "x": -15,
      "y": 19,
      "z": 2,
      "name": "Rock_Ice"
    },
    {
      "x": -15,
      "y": 20,
      "z": 2,
      "name": "Rock_Ice"
    },
    {
      "x": -15,
      "y": 21,
      "z": 2,
      "name": "Rock_Ice"
    },
    {
      "x": -15,
      "y": 22,
      "z": 2,
      "name": "Rock_Ice"
    },
    {
      "x": -15,
      "y": 23,
      "z": 2,
      "name": "Rock_Ice"
    },
    {
      "x": -15,
      "y": 24,
      "z": 2,
      "name": "Rock_Ice"
    },
    {
      "x": -15,
      "y": 25,
      "z": 2,
      "name": "Rock_Ice_Permafrost"
    },
    {
      "x": -15,
      "y": 26,
      "z": 2,
      "name": "Rock_Ice_Permafrost"
    },
    {
      "x": -15,
      "y": 27,
      "z": 2,
      "name": "Rock_Ice_Permafrost"
    },
    {
      "x": -15,
      "y": 28,
      "z": 2,
      "name": "Rock_Ice"
    },
    {
      "x": -15,
      "y": 29,
      "z": 2,
      "name": "Rock_Ice"
    },
    {
      "x": -15,
      "y": 30,
      "z": 2,
      "name": "Rock_Ice"
    },
    {
      "x": -15,
      "y": 31,
      "z": 2,
      "name": "Rock_Ice"
    },
    {
      "x": -15,
      "y": 32,
      "z": 2,
      "name": "Rock_Ice"
    },
    {
      "x": -15,
      "y": 33,
      "z": 2,
      "name": "Rock_Ice"
    },
    {
      "x": -15,
      "y": 34,
      "z": 2,
      "name": "Rock_Ice"
    },
    {
      "x": -15,
      "y": 35,
      "z": 2,
      "name": "Rock_Ice"
    },
    {
      "x": -15,
      "y": 36,
      "z": 2,
      "name": "Soil_Snow"
    },
    {
      "x": -15,
      "y": 8,
      "z": 3,
      "name": "Rock_Ice"
    },
    {
      "x": -15,
      "y": 9,
      "z": 3,
      "name": "Rock_Ice_Permafrost"
    },
    {
      "x": -15,
      "y": 10,
      "z": 3,
      "name": "Rock_Ice_Permafrost"
    },
    {
      "x": -15,
      "y": 11,
      "z": 3,
      "name": "Rock_Ice_Permafrost"
    },
    {
      "x": -15,
      "y": 12,
      "z": 3,
      "name": "Rock_Ice"
    },
    {
      "x": -15,
      "y": 13,
      "z": 3,
      "name": "Rock_Ice"
    },
    {
      "x": -15,
      "y": 14,
      "z": 3,
      "name": "Rock_Ice"
    },
    {
      "x": -15,
      "y": 15,
      "z": 3,
      "name": "Rock_Ice_Permafrost"
    },
    {
      "x": -15,
      "y": 16,
      "z": 3,
      "name": "Rock_Ice_Permafrost"
    },
    {
      "x": -15,
      "y": 17,
      "z": 3,
      "name": "Rock_Ice"
    },
    {
      "x": -15,
      "y": 18,
      "z": 3,
      "name": "Rock_Ice"
    },
    {
      "x": -15,
      "y": 19,
      "z": 3,
      "name": "Rock_Ice"
    },
    {
      "x": -15,
      "y": 20,
      "z": 3,
      "name": "Rock_Ice"
    },
    {
      "x": -15,
      "y": 21,
      "z": 3,
      "name": "Rock_Ice"
    },
    {
      "x": -15,
      "y": 22,
      "z": 3,
      "name": "Rock_Ice"
    },
    {
      "x": -15,
      "y": 23,
      "z": 3,
      "name": "Rock_Ice"
    },
    {
      "x": -15,
      "y": 24,
      "z": 3,
      "name": "Rock_Ice"
    },
    {
      "x": -15,
      "y": 25,
      "z": 3,
      "name": "Rock_Ice_Permafrost"
    },
    {
      "x": -15,
      "y": 26,
      "z": 3,
      "name": "Rock_Ice_Permafrost"
    },
    {
      "x": -15,
      "y": 27,
      "z": 3,
      "name": "Rock_Ice"
    },
    {
      "x": -15,
      "y": 28,
      "z": 3,
      "name": "Rock_Ice"
    },
    {
      "x": -15,
      "y": 29,
      "z": 3,
      "name": "Rock_Ice"
    },
    {
      "x": -15,
      "y": 30,
      "z": 3,
      "name": "Rock_Ice"
    },
    {
      "x": -15,
      "y": 31,
      "z": 3,
      "name": "Rock_Ice"
    },
    {
      "x": -15,
      "y": 32,
      "z": 3,
      "name": "Rock_Ice"
    },
    {
      "x": -15,
      "y": 33,
      "z": 3,
      "name": "Rock_Ice"
    },
    {
      "x": -15,
      "y": 34,
      "z": 3,
      "name": "Rock_Ice"
    },
    {
      "x": -15,
      "y": 35,
      "z": 3,
      "name": "Soil_Snow"
    },
    {
      "x": -15,
      "y": 8,
      "z": 4,
      "name": "Rock_Ice"
    },
    {
      "x": -15,
      "y": 9,
      "z": 4,
      "name": "Rock_Ice_Permafrost"
    },
    {
      "x": -15,
      "y": 10,
      "z": 4,
      "name": "Rock_Ice_Permafrost"
    },
    {
      "x": -15,
      "y": 11,
      "z": 4,
      "name": "Rock_Ice_Permafrost"
    },
    {
      "x": -15,
      "y": 12,
      "z": 4,
      "name": "Rock_Ice"
    },
    {
      "x": -15,
      "y": 13,
      "z": 4,
      "name": "Rock_Ice_Permafrost"
    },
    {
      "x": -15,
      "y": 14,
      "z": 4,
      "name": "Rock_Ice_Permafrost"
    },
    {
      "x": -15,
      "y": 15,
      "z": 4,
      "name": "Rock_Ice_Permafrost"
    },
    {
      "x": -15,
      "y": 16,
      "z": 4,
      "name": "Rock_Ice_Permafrost"
    },
    {
      "x": -15,
      "y": 17,
      "z": 4,
      "name": "Rock_Ice"
    },
    {
      "x": -15,
      "y": 18,
      "z": 4,
      "name": "Rock_Ice"
    },
    {
      "x": -15,
      "y": 19,
      "z": 4,
      "name": "Rock_Ice"
    },
    {
      "x": -15,
      "y": 20,
      "z": 4,
      "name": "Rock_Ice"
    },
    {
      "x": -15,
      "y": 21,
      "z": 4,
      "name": "Rock_Ice"
    },
    {
      "x": -15,
      "y": 22,
      "z": 4,
      "name": "Rock_Ice"
    },
    {
      "x": -15,
      "y": 23,
      "z": 4,
      "name": "Rock_Ice_Permafrost"
    },
    {
      "x": -15,
      "y": 24,
      "z": 4,
      "name": "Rock_Ice_Permafrost"
    },
    {
      "x": -15,
      "y": 25,
      "z": 4,
      "name": "Rock_Ice_Permafrost"
    },
    {
      "x": -15,
      "y": 26,
      "z": 4,
      "name": "Rock_Ice_Permafrost"
    },
    {
      "x": -15,
      "y": 27,
      "z": 4,
      "name": "Rock_Ice"
    },
    {
      "x": -15,
      "y": 28,
      "z": 4,
      "name": "Rock_Ice"
    },
    {
      "x": -15,
      "y": 29,
      "z": 4,
      "name": "Rock_Ice"
    },
    {
      "x": -15,
      "y": 30,
      "z": 4,
      "name": "Rock_Ice"
    },
    {
      "x": -15,
      "y": 31,
      "z": 4,
      "name": "Rock_Ice"
    },
    {
      "x": -15,
      "y": 32,
      "z": 4,
      "name": "Rock_Ice"
    },
    {
      "x": -15,
      "y": 33,
      "z": 4,
      "name": "Rock_Ice"
    },
    {
      "x": -15,
      "y": 34,
      "z": 4,
      "name": "Soil_Snow"
    },
    {
      "x": -15,
      "y": 6,
      "z": 5,
      "name": "Rock_Ice"
    },
    {
      "x": -15,
      "y": 7,
      "z": 5,
      "name": "Rock_Ice_Permafrost"
    },
    {
      "x": -15,
      "y": 8,
      "z": 5,
      "name": "Rock_Ice_Permafrost"
    },
    {
      "x": -15,
      "y": 9,
      "z": 5,
      "name": "Rock_Ice_Permafrost"
    },
    {
      "x": -15,
      "y": 10,
      "z": 5,
      "name": "Rock_Ice_Permafrost"
    },
    {
      "x": -15,
      "y": 11,
      "z": 5,
      "name": "Rock_Ice_Permafrost"
    },
    {
      "x": -15,
      "y": 12,
      "z": 5,
      "name": "Rock_Ice_Permafrost"
    },
    {
      "x": -15,
      "y": 13,
      "z": 5,
      "name": "Rock_Ice"
    },
    {
      "x": -15,
      "y": 14,
      "z": 5,
      "name": "Rock_Ice"
    },
    {
      "x": -15,
      "y": 15,
      "z": 5,
      "name": "Rock_Ice_Permafrost"
    },
    {
      "x": -15,
      "y": 16,
      "z": 5,
      "name": "Rock_Ice_Permafrost"
    },
    {
      "x": -15,
      "y": 17,
      "z": 5,
      "name": "Rock_Ice"
    },
    {
      "x": -15,
      "y": 18,
      "z": 5,
      "name": "Rock_Ice"
    },
    {
      "x": -15,
      "y": 19,
      "z": 5,
      "name": "Rock_Ice"
    },
    {
      "x": -15,
      "y": 20,
      "z": 5,
      "name": "Rock_Ice"
    },
    {
      "x": -15,
      "y": 21,
      "z": 5,
      "name": "Rock_Ice"
    },
    {
      "x": -15,
      "y": 22,
      "z": 5,
      "name": "Rock_Ice_Permafrost"
    },
    {
      "x": -15,
      "y": 23,
      "z": 5,
      "name": "Rock_Ice_Permafrost"
    },
    {
      "x": -15,
      "y": 24,
      "z": 5,
      "name": "Rock_Ice_Permafrost"
    },
    {
      "x": -15,
      "y": 25,
      "z": 5,
      "name": "Rock_Ice_Permafrost"
    },
    {
      "x": -15,
      "y": 26,
      "z": 5,
      "name": "Rock_Ice"
    },
    {
      "x": -15,
      "y": 27,
      "z": 5,
      "name": "Rock_Ice"
    },
    {
      "x": -15,
      "y": 28,
      "z": 5,
      "name": "Rock_Ice"
    },
    {
      "x": -15,
      "y": 29,
      "z": 5,
      "name": "Rock_Ice"
    },
    {
      "x": -15,
      "y": 30,
      "z": 5,
      "name": "Rock_Ice"
    },
    {
      "x": -15,
      "y": 31,
      "z": 5,
      "name": "Rock_Ice"
    },
    {
      "x": -15,
      "y": 32,
      "z": 5,
      "name": "Soil_Snow"
    },
    {
      "x": -15,
      "y": 5,
      "z": 6,
      "name": "Rock_Ice"
    },
    {
      "x": -15,
      "y": 6,
      "z": 6,
      "name": "Rock_Ice_Permafrost"
    },
    {
      "x": -15,
      "y": 7,
      "z": 6,
      "name": "Rock_Ice_Permafrost"
    },
    {
      "x": -15,
      "y": 8,
      "z": 6,
      "name": "Rock_Ice_Permafrost"
    },
    {
      "x": -15,
      "y": 9,
      "z": 6,
      "name": "Rock_Ice_Permafrost"
    },
    {
      "x": -15,
      "y": 10,
      "z": 6,
      "name": "Rock_Ice_Permafrost"
    },
    {
      "x": -15,
      "y": 11,
      "z": 6,
      "name": "Rock_Ice_Permafrost"
    },
    {
      "x": -15,
      "y": 12,
      "z": 6,
      "name": "Rock_Ice_Permafrost"
    },
    {
      "x": -15,
      "y": 13,
      "z": 6,
      "name": "Rock_Ice_Permafrost"
    },
    {
      "x": -15,
      "y": 14,
      "z": 6,
      "name": "Rock_Ice_Permafrost"
    },
    {
      "x": -15,
      "y": 15,
      "z": 6,
      "name": "Rock_Ice_Permafrost"
    },
    {
      "x": -15,
      "y": 16,
      "z": 6,
      "name": "Rock_Ice_Permafrost"
    },
    {
      "x": -15,
      "y": 17,
      "z": 6,
      "name": "Rock_Ice"
    },
    {
      "x": -15,
      "y": 18,
      "z": 6,
      "name": "Rock_Ice"
    },
    {
      "x": -15,
      "y": 19,
      "z": 6,
      "name": "Rock_Ice"
    },
    {
      "x": -15,
      "y": 20,
      "z": 6,
      "name": "Rock_Ice"
    },
    {
      "x": -15,
      "y": 21,
      "z": 6,
      "name": "Rock_Ice"
    },
    {
      "x": -15,
      "y": 22,
      "z": 6,
      "name": "Rock_Ice_Permafrost"
    },
    {
      "x": -15,
      "y": 23,
      "z": 6,
      "name": "Rock_Ice_Permafrost"
    },
    {
      "x": -15,
      "y": 24,
      "z": 6,
      "name": "Rock_Ice_Permafrost"
    },
    {
      "x": -15,
      "y": 25,
      "z": 6,
      "name": "Rock_Ice"
    },
    {
      "x": -15,
      "y": 26,
      "z": 6,
      "name": "Rock_Ice"
    },
    {
      "x": -15,
      "y": 27,
      "z": 6,
      "name": "Rock_Ice"
    },
    {
      "x": -15,
      "y": 28,
      "z": 6,
      "name": "Rock_Ice"
    },
    {
      "x": -15,
      "y": 29,
      "z": 6,
      "name": "Rock_Ice"
    },
    {
      "x": -15,
      "y": 30,
      "z": 6,
      "name": "Rock_Ice"
    },
    {
      "x": -15,
      "y": 31,
      "z": 6,
      "name": "Soil_Snow"
    },
    {
      "x": -15,
      "y": 5,
      "z": 7,
      "name": "Rock_Ice"
    },
    {
      "x": -15,
      "y": 6,
      "z": 7,
      "name": "Rock_Ice_Permafrost"
    },
    {
      "x": -15,
      "y": 7,
      "z": 7,
      "name": "Rock_Ice_Permafrost"
    },
    {
      "x": -15,
      "y": 8,
      "z": 7,
      "name": "Rock_Ice_Permafrost"
    },
    {
      "x": -15,
      "y": 9,
      "z": 7,
      "name": "Rock_Ice_Permafrost"
    },
    {
      "x": -15,
      "y": 10,
      "z": 7,
      "name": "Rock_Ice_Permafrost"
    },
    {
      "x": -15,
      "y": 11,
      "z": 7,
      "name": "Rock_Ice_Permafrost"
    },
    {
      "x": -15,
      "y": 12,
      "z": 7,
      "name": "Rock_Ice_Permafrost"
    },
    {
      "x": -15,
      "y": 13,
      "z": 7,
      "name": "Rock_Ice_Permafrost"
    },
    {
      "x": -15,
      "y": 14,
      "z": 7,
      "name": "Rock_Ice_Permafrost"
    },
    {
      "x": -15,
      "y": 15,
      "z": 7,
      "name": "Rock_Ice_Permafrost"
    },
    {
      "x": -15,
      "y": 16,
      "z": 7,
      "name": "Rock_Ice_Permafrost"
    },
    {
      "x": -15,
      "y": 17,
      "z": 7,
      "name": "Rock_Ice_Permafrost"
    },
    {
      "x": -15,
      "y": 18,
      "z": 7,
      "name": "Rock_Ice_Permafrost"
    },
    {
      "x": -15,
      "y": 19,
      "z": 7,
      "name": "Rock_Ice_Permafrost"
    },
    {
      "x": -15,
      "y": 20,
      "z": 7,
      "name": "Rock_Ice_Permafrost"
    },
    {
      "x": -15,
      "y": 21,
      "z": 7,
      "name": "Rock_Ice_Permafrost"
    },
    {
      "x": -15,
      "y": 22,
      "z": 7,
      "name": "Rock_Ice_Permafrost"
    },
    {
      "x": -15,
      "y": 23,
      "z": 7,
      "name": "Rock_Ice_Permafrost"
    },
    {
      "x": -15,
      "y": 24,
      "z": 7,
      "name": "Rock_Ice_Permafrost"
    },
    {
      "x": -15,
      "y": 25,
      "z": 7,
      "name": "Rock_Ice"
    },
    {
      "x": -15,
      "y": 26,
      "z": 7,
      "name": "Rock_Ice_Permafrost"
    },
    {
      "x": -15,
      "y": 27,
      "z": 7,
      "name": "Rock_Ice"
    },
    {
      "x": -15,
      "y": 28,
      "z": 7,
      "name": "Soil_Snow"
    },
    {
      "x": -15,
      "y": 4,
      "z": 8,
      "name": "Rock_Ice"
    },
    {
      "x": -15,
      "y": 5,
      "z": 8,
      "name": "Rock_Ice_Permafrost"
    },
    {
      "x": -15,
      "y": 6,
      "z": 8,
      "name": "Rock_Ice_Permafrost"
    },
    {
      "x": -15,
      "y": 7,
      "z": 8,
      "name": "Rock_Ice_Permafrost"
    },
    {
      "x": -15,
      "y": 8,
      "z": 8,
      "name": "Rock_Ice_Permafrost"
    },
    {
      "x": -15,
      "y": 9,
      "z": 8,
      "name": "Rock_Ice_Permafrost"
    },
    {
      "x": -15,
      "y": 10,
      "z": 8,
      "name": "Rock_Ice"
    },
    {
      "x": -15,
      "y": 11,
      "z": 8,
      "name": "Rock_Ice_Permafrost"
    },
    {
      "x": -15,
      "y": 12,
      "z": 8,
      "name": "Rock_Ice_Permafrost"
    },
    {
      "x": -15,
      "y": 13,
      "z": 8,
      "name": "Rock_Ice_Permafrost"
    },
    {
      "x": -15,
      "y": 14,
      "z": 8,
      "name": "Rock_Ice_Permafrost"
    },
    {
      "x": -15,
      "y": 15,
      "z": 8,
      "name": "Rock_Ice_Permafrost"
    },
    {
      "x": -15,
      "y": 16,
      "z": 8,
      "name": "Rock_Ice_Permafrost"
    },
    {
      "x": -15,
      "y": 17,
      "z": 8,
      "name": "Rock_Ice_Permafrost"
    },
    {
      "x": -15,
      "y": 18,
      "z": 8,
      "name": "Rock_Ice_Permafrost"
    },
    {
      "x": -15,
      "y": 19,
      "z": 8,
      "name": "Rock_Ice_Permafrost"
    },
    {
      "x": -15,
      "y": 20,
      "z": 8,
      "name": "Rock_Ice_Permafrost"
    },
    {
      "x": -15,
      "y": 21,
      "z": 8,
      "name": "Rock_Ice_Permafrost"
    },
    {
      "x": -15,
      "y": 22,
      "z": 8,
      "name": "Rock_Ice_Permafrost"
    },
    {
      "x": -15,
      "y": 23,
      "z": 8,
      "name": "Rock_Ice_Permafrost"
    },
    {
      "x": -15,
      "y": 24,
      "z": 8,
      "name": "Rock_Ice_Permafrost"
    },
    {
      "x": -15,
      "y": 25,
      "z": 8,
      "name": "Rock_Ice_Permafrost"
    },
    {
      "x": -15,
      "y": 26,
      "z": 8,
      "name": "Rock_Ice"
    },
    {
      "x": -15,
      "y": 27,
      "z": 8,
      "name": "Soil_Snow"
    },
    {
      "x": -15,
      "y": 3,
      "z": 9,
      "name": "Rock_Ice"
    },
    {
      "x": -15,
      "y": 4,
      "z": 9,
      "name": "Rock_Ice_Permafrost"
    },
    {
      "x": -15,
      "y": 5,
      "z": 9,
      "name": "Rock_Ice_Permafrost"
    },
    {
      "x": -15,
      "y": 6,
      "z": 9,
      "name": "Rock_Ice_Permafrost"
    },
    {
      "x": -15,
      "y": 7,
      "z": 9,
      "name": "Rock_Ice_Permafrost"
    },
    {
      "x": -15,
      "y": 8,
      "z": 9,
      "name": "Rock_Ice_Permafrost"
    },
    {
      "x": -15,
      "y": 9,
      "z": 9,
      "name": "Rock_Ice_Permafrost"
    },
    {
      "x": -15,
