{
  "version": 8,
  "blockIdVersion": 11,
  "anchorX": -4,
  "anchorY": 22,
  "anchorZ": -1,
  "blocks": [
    {
      "x": -47,
      "y": 30,
      "z": -5,
      "name": "Rock_Ice_Permafrost"
    },
    {
      "x": -47,
      "y": 31,
      "z": -5,
      "name": "Rock_Ice"
    },
    {
      "x": -46,
      "y": 30,
      "z": -8,
      "name": "Soil_Snow"
    },
    {
      "x": -46,
      "y": 29,
      "z": -7,
      "name": "Rock_Ice"
    },
    {
      "x": -46,
      "y": 30,
      "z": -7,
      "name": "Rock_Ice"
    },
    {
      "x": -46,
      "y": 31,
      "z": -7,
      "name": "Soil_Snow"
    },
    {
      "x": -46,
      "y": 29,
      "z": -6,
      "name": "Rock_Ice"
    },
    {
      "x": -46,
      "y": 30,
      "z": -6,
      "name": "Rock_Ice"
    },
    {
      "x": -46,
      "y": 31,
      "z": -6,
      "name": "Rock_Ice"
    },
    {
      "x": -46,
      "y": 32,
      "z": -6,
      "name": "Soil_Snow"
    },
    {
      "x": -46,
      "y": 28,
      "z": -5,
      "name": "Rock_Ice"
    },
    {
      "x": -46,
      "y": 29,
      "z": -5,
      "name": "Rock_Ice"
    },
    {
      "x": -46,
      "y": 30,
      "z": -5,
      "name": "Rock_Ice"
    },
    {
      "x": -46,
      "y": 31,
      "z": -5,
      "name": "Rock_Ice"
    },
    {
      "x": -46,
      "y": 32,
      "z": -5,
      "name": "Rock_Ice"
    },
    {
      "x": -46,
      "y": 33,
      "z": -5,
      "name": "Soil_Snow"
    },
    {
      "x": -46,
      "y": 28,
      "z": -4,
      "name": "Rock_Ice_Permafrost"
    },
    {
      "x": -46,
      "y": 29,
      "z": -4,
      "name": "Rock_Ice_Permafrost"
    },
    {
      "x": -46,
      "y": 30,
      "z": -4,
      "name": "Rock_Ice"
    },
    {
      "x": -46,
      "y": 31,
      "z": -4,
      "name": "Rock_Ice_Permafrost"
    },
    {
      "x": -46,
      "y": 32,
      "z": -4,
      "name": "Rock_Ice"
    },
    {
      "x": -46,
      "y": 33,
      "z": -4,
      "name": "Rock_Ice_Permafrost"
    },
    {
      "x": -46,
      "y": 30,
      "z": -3,
      "name": "Rock_Ice_Permafrost"
    },
    {
      "x": -46,
      "y": 31,
      "z": -3,
      "name": "Rock_Ice"
    },
    {
      "x": -46,
      "y": 32,
      "z": -3,
      "name": "Soil_Snow"
    },
    {
      "x": -45,
      "y": 30,
      "z": -10,
      "name": "Soil_Snow"
    },
    {
      "x": -45,
      "y": 29,
      "z": -9,
      "name": "Rock_Ice"
    },
    {
      "x": -45,
      "y": 30,
      "z": -9,
      "name": "Rock_Ice"
    },
    {
      "x": -45,
      "y": 31,
      "z": -9,
      "name": "Soil_Snow"
    },
    {
      "x": -45,
      "y": 20,
      "z": -8,
      "name": "Rock_Ice_Permafrost"
    },
    {
      "x": -45,
      "y": 28,
      "z": -8,
      "name": "Rock_Ice"
    },
    {
      "x": -45,
      "y": 29,
      "z": -8,
      "name": "Rock_Ice"
    },
    {
      "x": -45,
      "y": 30,
      "z": -8,
      "name": "Rock_Ice"
    },
    {
      "x": -45,
      "y": 31,
      "z": -8,
      "name": "Rock_Ice"
    },
    {
      "x": -45,
      "y": 32,
      "z": -8,
      "name": "Soil_Snow"
    },
    {
      "x": -45,
      "y": 21,
      "z": -7,
      "name": "Rock_Ice_Permafrost"
    },
    {
      "x": -45,
      "y": 22,
      "z": -7,
      "name": "Rock_Ice"
    },
    {
      "x": -45,
      "y": 27,
      "z": -7,
      "name": "Rock_Ice"
    },
    {
      "x": -45,
      "y": 28,
      "z": -7,
      "name": "Rock_Ice"
    },
    {
      "x": -45,
      "y": 29,
      "z": -7,
      "name": "Rock_Ice"
    },
    {
      "x": -45,
      "y": 30,
      "z": -7,
      "name": "Rock_Ice"
    },
    {
      "x": -45,
      "y": 31,
      "z": -7,
      "name": "Rock_Ice"
    },
    {
      "x": -45,
      "y": 32,
      "z": -7,
      "name": "Rock_Ice"
    },
    {
      "x": -45,
      "y": 33,
      "z": -7,
      "name": "Soil_Snow"
    },
    {
      "x": -45,
      "y": 23,
      "z": -6,
      "name": "Rock_Ice_Permafrost"
    },
    {
      "x": -45,
      "y": 24,
      "z": -6,
      "name": "Rock_Ice"
    },
    {
      "x": -45,
      "y": 25,
      "z": -6,
      "name": "Rock_Ice"
    },
    {
      "x": -45,
      "y": 26,
      "z": -6,
      "name": "Rock_Ice"
    },
    {
      "x": -45,
      "y": 27,
      "z": -6,
      "name": "Rock_Ice"
    },
    {
      "x": -45,
      "y": 28,
      "z": -6,
      "name": "Rock_Ice"
    },
    {
      "x": -45,
      "y": 29,
      "z": -6,
      "name": "Rock_Ice"
    },
    {
      "x": -45,
      "y": 30,
      "z": -6,
      "name": "Rock_Ice"
    },
    {
      "x": -45,
      "y": 31,
      "z": -6,
      "name": "Rock_Ice"
    },
    {
      "x": -45,
      "y": 32,
      "z": -6,
      "name": "Rock_Ice"
    },
    {
      "x": -45,
      "y": 33,
      "z": -6,
      "name": "Rock_Ice"
    },
    {
      "x": -45,
      "y": 34,
      "z": -6,
      "name": "Rock_Ice"
    },
    {
      "x": -45,
      "y": 35,
      "z": -6,
      "name": "Rock_Ice"
    },
    {
      "x": -45,
      "y": 24,
      "z": -5,
      "name": "Rock_Ice_Permafrost"
    },
    {
      "x": -45,
      "y": 25,
      "z": -5,
      "name": "Rock_Ice_Permafrost"
    },
    {
      "x": -45,
      "y": 26,
      "z": -5,
      "name": "Rock_Ice"
    },
    {
      "x": -45,
      "y": 27,
      "z": -5,
      "name": "Rock_Ice"
    },
    {
      "x": -45,
      "y": 28,
      "z": -5,
      "name": "Rock_Ice"
    },
    {
      "x": -45,
      "y": 29,
      "z": -5,
      "name": "Rock_Ice"
    },
    {
      "x": -45,
      "y": 30,
      "z": -5,
      "name": "Rock_Ice"
    },
    {
      "x": -45,
      "y": 31,
      "z": -5,
      "name": "Rock_Ice"
    },
    {
      "x": -45,
      "y": 32,
      "z": -5,
      "name": "Rock_Ice"
    },
    {
      "x": -45,
      "y": 33,
      "z": -5,
      "name": "Rock_Ice"
    },
    {
      "x": -45,
      "y": 34,
      "z": -5,
      "name": "Rock_Ice"
    },
    {
      "x": -45,
      "y": 35,
      "z": -5,
      "name": "Soil_Snow"
    },
    {
      "x": -45,
      "y": 27,
      "z": -4,
      "name": "Rock_Ice_Permafrost"
    },
    {
      "x": -45,
      "y": 28,
      "z": -4,
      "name": "Rock_Ice_Permafrost"
    },
    {
      "x": -45,
      "y": 29,
      "z": -4,
      "name": "Rock_Ice_Permafrost"
    },
    {
      "x": -45,
      "y": 30,
      "z": -4,
      "name": "Rock_Ice_Permafrost"
    },
    {
      "x": -45,
      "y": 31,
      "z": -4,
      "name": "Rock_Ice"
    },
    {
      "x": -45,
      "y": 32,
      "z": -4,
      "name": "Rock_Ice"
    },
    {
      "x": -45,
      "y": 33,
      "z": -4,
      "name": "Rock_Ice_Permafrost"
    },
    {
      "x": -45,
      "y": 34,
      "z": -4,
      "name": "Rock_Ice"
    },
    {
      "x": -45,
      "y": 35,
      "z": -4,
      "name": "Soil_Snow"
    },
    {
      "x": -45,
      "y": 28,
      "z": -3,
      "name": "Rock_Ice_Permafrost"
    },
    {
      "x": -45,
      "y": 29,
      "z": -3,
      "name": "Rock_Ice_Permafrost"
    },
    {
      "x": -45,
      "y": 30,
      "z": -3,
      "name": "Rock_Ice_Permafrost"
    },
    {
      "x": -45,
      "y": 31,
      "z": -3,
      "name": "Rock_Ice_Permafrost"
    },
    {
      "x": -45,
      "y": 32,
      "z": -3,
      "name": "Rock_Ice_Permafrost"
    },
    {
      "x": -45,
      "y": 33,
      "z": -3,
      "name": "Rock_Ice"
    },
    {
      "x": -45,
      "y": 34,
      "z": -3,
      "name": "Soil_Snow"
    },
    {
      "x": -45,
      "y": 30,
      "z": -2,
      "name": "Rock_Ice_Permafrost"
    },
    {
      "x": -45,
      "y": 31,
      "z": -2,
      "name": "Rock_Ice"
    },
    {
      "x": -45,
      "y": 32,
      "z": -2,
      "name": "Rock_Ice_Permafrost"
    },
    {
      "x": -44,
      "y": 18,
      "z": -13,
      "name": "Soil_Snow"
    },
    {
      "x": -44,
      "y": 18,
      "z": -12,
      "name": "Rock_Ice"
    },
    {
      "x": -44,
      "y": 19,
      "z": -12,
      "name": "Soil_Snow"
    },
    {
      "x": -44,
      "y": 18,
      "z": -11,
      "name": "Rock_Ice_Permafrost"
    },
    {
      "x": -44,
      "y": 19,
      "z": -11,
      "name": "Rock_Ice_Permafrost"
    },
    {
      "x": -44,
      "y": 20,
      "z": -11,
      "name": "Rock_Ice"
    },
    {
      "x": -44,
      "y": 30,
      "z": -11,
      "name": "Soil_Snow"
    },
    {
      "x": -44,
      "y": 18,
      "z": -10,
      "name": "Rock_Ice_Permafrost"
    },
    {
      "x": -44,
      "y": 19,
      "z": -10,
      "name": "Rock_Ice_Permafrost"
    },
    {
      "x": -44,
      "y": 20,
      "z": -10,
      "name": "Rock_Ice_Permafrost"
    },
    {
      "x": -44,
      "y": 21,
      "z": -10,
      "name": "Rock_Ice"
    },
    {
      "x": -44,
      "y": 22,
      "z": -10,
      "name": "Rock_Ice"
    },
    {
      "x": -44,
      "y": 29,
      "z": -10,
      "name": "Rock_Ice"
    },
    {
      "x": -44,
      "y": 30,
      "z": -10,
      "name": "Rock_Ice"
    },
    {
      "x": -44,
      "y": 31,
      "z": -10,
      "name": "Soil_Snow"
    },
    {
      "x": -44,
      "y": 19,
      "z": -9,
      "name": "Rock_Ice_Permafrost"
    },
    {
      "x": -44,
      "y": 20,
      "z": -9,
      "name": "Rock_Ice_Permafrost"
    },
    {
      "x": -44,
      "y": 21,
      "z": -9,
      "name": "Rock_Ice_Permafrost"
    },
    {
      "x": -44,
      "y": 22,
      "z": -9,
      "name": "Rock_Ice"
    },
    {
      "x": -44,
      "y": 23,
      "z": -9,
      "name": "Rock_Ice"
    },
    {
      "x": -44,
      "y": 24,
      "z": -9,
      "name": "Rock_Ice"
    },
    {
      "x": -44,
      "y": 27,
      "z": -9,
      "name": "Rock_Ice"
    },
    {
      "x": -44,
      "y": 28,
      "z": -9,
      "name": "Rock_Ice"
    },
    {
      "x": -44,
      "y": 29,
      "z": -9,
      "name": "Rock_Ice"
    },
    {
      "x": -44,
      "y": 30,
      "z": -9,
      "name": "Rock_Ice"
    },
    {
      "x": -44,
      "y": 31,
      "z": -9,
      "name": "Rock_Ice"
    },
    {
      "x": -44,
      "y": 32,
      "z": -9,
      "name": "Soil_Snow"
    },
    {
      "x": -44,
      "y": 20,
      "z": -8,
      "name": "Rock_Ice_Permafrost"
    },
    {
      "x": -44,
      "y": 21,
      "z": -8,
      "name": "Rock_Ice_Permafrost"
    },
    {
      "x": -44,
      "y": 22,
      "z": -8,
      "name": "Rock_Ice_Permafrost"
    },
    {
      "x": -44,
      "y": 23,
      "z": -8,
      "name": "Rock_Ice"
    },
    {
      "x": -44,
      "y": 24,
      "z": -8,
      "name": "Rock_Ice"
    },
    {
      "x": -44,
      "y": 25,
      "z": -8,
      "name": "Rock_Ice"
    },
    {
      "x": -44,
      "y": 26,
      "z": -8,
      "name": "Rock_Ice"
    },
    {
      "x": -44,
      "y": 27,
      "z": -8,
      "name": "Rock_Ice"
    },
    {
      "x": -44,
      "y": 28,
      "z": -8,
      "name": "Rock_Ice"
    },
    {
      "x": -44,
      "y": 29,
      "z": -8,
      "name": "Rock_Ice"
    },
    {
      "x": -44,
      "y": 30,
      "z": -8,
      "name": "Rock_Ice"
    },
    {
      "x": -44,
      "y": 31,
      "z": -8,
      "name": "Rock_Ice"
    },
    {
      "x": -44,
      "y": 32,
      "z": -8,
      "name": "Rock_Ice"
    },
    {
      "x": -44,
      "y": 33,
      "z": -8,
      "name": "Soil_Snow"
    },
    {
      "x": -44,
      "y": 20,
      "z": -7,
      "name": "Rock_Ice_Permafrost"
    },
    {
      "x": -44,
      "y": 21,
      "z": -7,
      "name": "Rock_Ice_Permafrost"
    },
    {
      "x": -44,
      "y": 22,
      "z": -7,
      "name": "Rock_Ice_Permafrost"
    },
    {
      "x": -44,
      "y": 23,
      "z": -7,
      "name": "Rock_Ice"
    },
    {
      "x": -44,
      "y": 24,
      "z": -7,
      "name": "Rock_Ice"
    },
    {
      "x": -44,
      "y": 25,
      "z": -7,
      "name": "Rock_Ice"
    },
    {
      "x": -44,
      "y": 26,
      "z": -7,
      "name": "Rock_Ice"
    },
    {
      "x": -44,
      "y": 27,
      "z": -7,
      "name": "Rock_Ice"
    },
    {
      "x": -44,
      "y": 28,
      "z": -7,
      "name": "Rock_Ice"
    },
    {
      "x": -44,
      "y": 29,
      "z": -7,
      "name": "Rock_Ice"
    },
    {
      "x": -44,
      "y": 30,
      "z": -7,
      "name": "Rock_Ice"
    },
    {
      "x": -44,
      "y": 31,
      "z": -7,
      "name": "Rock_Ice"
    },
    {
      "x": -44,
      "y": 32,
      "z": -7,
      "name": "Rock_Ice"
    },
    {
      "x": -44,
      "y": 33,
      "z": -7,
      "name": "Rock_Ice"
    },
    {
      "x": -44,
      "y": 34,
      "z": -7,
      "name": "Rock_Ice"
    },
    {
      "x": -44,
      "y": 35,
      "z": -7,
      "name": "Rock_Ice"
    },
    {
      "x": -44,
      "y": 36,
      "z": -7,
      "name": "Soil_Snow"
    },
    {
      "x": -44,
      "y": 21,
      "z": -6,
      "name": "Rock_Ice_Permafrost"
    },
    {
      "x": -44,
      "y": 22,
      "z": -6,
      "name": "Rock_Ice_Permafrost"
    },
    {
      "x": -44,
      "y": 23,
      "z": -6,
      "name": "Rock_Ice_Permafrost"
    },
    {
      "x": -44,
      "y": 24,
      "z": -6,
      "name": "Rock_Ice_Permafrost"
    },
    {
      "x": -44,
      "y": 25,
      "z": -6,
      "name": "Rock_Ice"
    },
    {
      "x": -44,
      "y": 26,
      "z": -6,
      "name": "Rock_Ice"
    },
    {
      "x": -44,
      "y": 27,
      "z": -6,
      "name": "Rock_Ice"
    },
    {
      "x": -44,
      "y": 28,
      "z": -6,
      "name": "Rock_Ice"
    },
    {
      "x": -44,
      "y": 29,
      "z": -6,
      "name": "Rock_Ice"
    },
    {
      "x": -44,
      "y": 30,
      "z": -6,
      "name": "Rock_Ice"
    },
    {
      "x": -44,
      "y": 31,
      "z": -6,
      "name": "Rock_Ice"
    },
    {
      "x": -44,
      "y": 32,
      "z": -6,
      "name": "Rock_Ice"
    },
    {
      "x": -44,
      "y": 33,
      "z": -6,
      "name": "Rock_Ice"
    },
    {
      "x": -44,
      "y": 34,
      "z": -6,
      "name": "Rock_Ice"
    },
    {
      "x": -44,
      "y": 35,
      "z": -6,
      "name": "Rock_Ice"
    },
    {
      "x": -44,
      "y": 36,
      "z": -6,
      "name": "Soil_Snow"
    },
    {
      "x": -44,
      "y": 22,
      "z": -5,
      "name": "Rock_Ice_Permafrost"
    },
    {
      "x": -44,
      "y": 23,
      "z": -5,
      "name": "Rock_Ice_Permafrost"
    },
    {
      "x": -44,
      "y": 24,
      "z": -5,
      "name": "Rock_Ice_Permafrost"
    },
    {
      "x": -44,
      "y": 25,
      "z": -5,
      "name": "Rock_Ice_Permafrost"
    },
    {
      "x": -44,
      "y": 26,
      "z": -5,
      "name": "Rock_Ice"
    },
    {
      "x": -44,
      "y": 27,
      "z": -5,
      "name": "Rock_Ice"
    },
    {
      "x": -44,
      "y": 28,
      "z": -5,
      "name": "Rock_Ice"
    },
    {
      "x": -44,
      "y": 29,
      "z": -5,
      "name": "Rock_Ice"
    },
    {
      "x": -44,
      "y": 30,
      "z": -5,
      "name": "Rock_Ice"
    },
    {
      "x": -44,
      "y": 31,
      "z": -5,
      "name": "Rock_Ice"
    },
    {
      "x": -44,
      "y": 32,
      "z": -5,
      "name": "Rock_Ice"
    },
    {
      "x": -44,
      "y": 33,
      "z": -5,
      "name": "Rock_Ice"
    },
    {
      "x": -44,
      "y": 34,
      "z": -5,
      "name": "Rock_Ice"
    },
    {
      "x": -44,
      "y": 35,
      "z": -5,
      "name": "Rock_Ice_Permafrost"
    },
    {
      "x": -44,
      "y": 36,
      "z": -5,
      "name": "Soil_Snow"
    },
    {
      "x": -44,
      "y": 24,
      "z": -4,
      "name": "Rock_Ice_Permafrost"
    },
    {
      "x": -44,
      "y": 25,
      "z": -4,
      "name": "Rock_Ice"
    },
    {
      "x": -44,
      "y": 26,
      "z": -4,
      "name": "Rock_Ice"
    },
    {
      "x": -44,
      "y": 27,
      "z": -4,
      "name": "Rock_Ice_Permafrost"
    },
    {
      "x": -44,
      "y": 28,
      "z": -4,
      "name": "Rock_Ice_Permafrost"
    },
    {
      "x": -44,
      "y": 29,
      "z": -4,
      "name": "Rock_Ice"
    },
    {
      "x": -44,
      "y": 30,
      "z": -4,
      "name": "Rock_Ice"
    },
    {
      "x": -44,
      "y": 31,
      "z": -4,
      "name": "Rock_Ice_Permafrost"
    },
    {
      "x": -44,
      "y": 32,
      "z": -4,
      "name": "Rock_Ice_Permafrost"
    },
    {
      "x": -44,
      "y": 33,
      "z": -4,
      "name": "Rock_Ice_Permafrost"
    },
    {
      "x": -44,
      "y": 34,
      "z": -4,
      "name": "Rock_Ice_Permafrost"
    },
    {
      "x": -44,
      "y": 35,
      "z": -4,
      "name": "Rock_Ice"
    },
    {
      "x": -44,
      "y": 36,
      "z": -4,
      "name": "Soil_Snow"
    },
    {
      "x": -44,
      "y": 26,
      "z": -3,
      "name": "Rock_Ice_Permafrost"
    },
    {
      "x": -44,
      "y": 27,
      "z": -3,
      "name": "Rock_Ice_Permafrost"
    },
    {
      "x": -44,
      "y": 28,
      "z": -3,
      "name": "Rock_Ice_Permafrost"
    },
    {
      "x": -44,
      "y": 29,
      "z": -3,
      "name": "Rock_Ice_Permafrost"
    },
    {
      "x": -44,
      "y": 30,
      "z": -3,
      "name": "Rock_Ice_Permafrost"
    },
    {
      "x": -44,
      "y": 31,
      "z": -3,
      "name": "Rock_Ice_Permafrost"
    },
    {
      "x": -44,
      "y": 32,
      "z": -3,
      "name": "Rock_Ice_Permafrost"
    },
    {
      "x": -44,
      "y": 33,
      "z": -3,
      "name": "Rock_Ice_Permafrost"
    },
    {
      "x": -44,
      "y": 34,
      "z": -3,
      "name": "Rock_Ice_Permafrost"
    },
    {
      "x": -44,
      "y": 35,
      "z": -3,
      "name": "Soil_Snow"
    },
    {
      "x": -44,
      "y": 28,
      "z": -2,
      "name": "Rock_Ice"
    },
    {
      "x": -44,
      "y": 29,
      "z": -2,
      "name": "Rock_Ice"
    },
    {
      "x": -44,
      "y": 30,
      "z": -2,
      "name": "Rock_Ice_Permafrost"
    },
    {
      "x": -44,
      "y": 31,
      "z": -2,
      "name": "Rock_Ice_Permafrost"
    },
    {
      "x": -44,
      "y": 32,
      "z": -2,
      "name": "Rock_Ice_Permafrost"
    },
    {
      "x": -44,
      "y": 33,
      "z": -2,
      "name": "Rock_Ice_Permafrost"
    },
    {
      "x": -44,
      "y": 34,
      "z": -2,
      "name": "Rock_Ice_Permafrost"
    },
    {
      "x": -44,
      "y": 35,
      "z": -2,
      "name": "Soil_Snow"
    },
    {
      "x": -44,
      "y": 29,
      "z": -1,
      "name": "Rock_Ice"
    },
    {
      "x": -44,
      "y": 30,
      "z": -1,
      "name": "Rock_Ice"
    },
    {
      "x": -44,
      "y": 31,
      "z": -1,
      "name": "Rock_Ice"
    },
    {
      "x": -44,
      "y": 32,
      "z": -1,
      "name": "Rock_Ice"
    },
    {
      "x": -43,
      "y": 17,
      "z": -16,
      "name": "Soil_Snow"
    },
    {
      "x": -43,
      "y": 16,
      "z": -15,
      "name": "Rock_Ice_Permafrost"
    },
    {
      "x": -43,
      "y": 17,
      "z": -15,
      "name": "Rock_Ice"
    },
    {
      "x": -43,
      "y": 18,
      "z": -15,
      "name": "Soil_Snow"
    },
    {
      "x": -43,
      "y": 16,
      "z": -14,
      "name": "Rock_Ice_Permafrost"
    },
    {
      "x": -43,
      "y": 17,
      "z": -14,
      "name": "Rock_Ice_Permafrost"
    },
    {
      "x": -43,
      "y": 18,
      "z": -14,
      "name": "Rock_Ice"
    },
    {
      "x": -43,
      "y": 19,
      "z": -14,
      "name": "Soil_Snow"
    },
    {
      "x": -43,
      "y": 17,
      "z": -13,
      "name": "Rock_Ice_Permafrost"
    },
    {
      "x": -43,
      "y": 18,
      "z": -13,
      "name": "Rock_Ice"
    },
    {
      "x": -43,
      "y": 19,
      "z": -13,
      "name": "Rock_Ice"
    },
    {
      "x": -43,
      "y": 20,
      "z": -13,
      "name": "Soil_Snow"
    },
    {
      "x": -43,
      "y": 17,
      "z": -12,
      "name": "Rock_Ice_Permafrost"
    },
    {
      "x": -43,
      "y": 18,
      "z": -12,
      "name": "Rock_Ice_Permafrost"
    },
    {
      "x": -43,
      "y": 19,
      "z": -12,
      "name": "Rock_Ice"
    },
    {
      "x": -43,
      "y": 20,
      "z": -12,
      "name": "Rock_Ice"
    },
    {
      "x": -43,
      "y": 21,
      "z": -12,
      "name": "Rock_Ice"
    },
    {
      "x": -43,
      "y": 22,
      "z": -12,
      "name": "Soil_Snow"
    },
    {
      "x": -43,
      "y": 18,
      "z": -11,
      "name": "Rock_Ice_Permafrost"
    },
    {
      "x": -43,
      "y": 19,
      "z": -11,
      "name": "Rock_Ice_Permafrost"
    },
    {
      "x": -43,
      "y": 20,
      "z": -11,
      "name": "Rock_Ice"
    },
    {
      "x": -43,
      "y": 21,
      "z": -11,
      "name": "Rock_Ice"
    },
    {
      "x": -43,
      "y": 22,
      "z": -11,
      "name": "Rock_Ice"
    },
    {
      "x": -43,
      "y": 23,
      "z": -11,
      "name": "Rock_Ice"
    },
    {
      "x": -43,
      "y": 29,
      "z": -11,
      "name": "Rock_Ice"
    },
    {
      "x": -43,
      "y": 30,
      "z": -11,
      "name": "Soil_Snow"
    },
    {
      "x": -43,
      "y": 18,
      "z": -10,
      "name": "Rock_Ice_Permafrost"
    },
    {
      "x": -43,
      "y": 19,
      "z": -10,
      "name": "Rock_Ice_Permafrost"
    },
    {
      "x": -43,
      "y": 20,
      "z": -10,
      "name": "Rock_Ice_Permafrost"
    },
    {
      "x": -43,
      "y": 21,
      "z": -10,
      "name": "Rock_Ice"
    },
    {
      "x": -43,
      "y": 22,
      "z": -10,
      "name": "Rock_Ice"
    },
    {
      "x": -43,
      "y": 23,
      "z": -10,
      "name": "Rock_Ice"
    },
    {
      "x": -43,
      "y": 24,
      "z": -10,
      "name": "Rock_Ice"
    },
    {
      "x": -43,
      "y": 25,
      "z": -10,
      "name": "Rock_Ice"
    },
    {
      "x": -43,
      "y": 26,
      "z": -10,
      "name": "Rock_Ice"
    },
    {
      "x": -43,
      "y": 27,
      "z": -10,
      "name": "Rock_Ice"
    },
    {
      "x": -43,
      "y": 28,
      "z": -10,
      "name": "Rock_Ice"
    },
    {
      "x": -43,
      "y": 29,
      "z": -10,
      "name": "Rock_Ice"
    },
    {
      "x": -43,
      "y": 30,
      "z": -10,
      "name": "Rock_Ice"
    },
    {
      "x": -43,
      "y": 31,
      "z": -10,
      "name": "Soil_Snow"
    },
    {
      "x": -43,
      "y": 19,
      "z": -9,
      "name": "Rock_Ice_Permafrost"
    },
    {
      "x": -43,
      "y": 20,
      "z": -9,
      "name": "Rock_Ice_Permafrost"
    },
    {
      "x": -43,
      "y": 21,
      "z": -9,
      "name": "Rock_Ice"
    },
    {
      "x": -43,
      "y": 22,
      "z": -9,
      "name": "Rock_Ice"
    },
    {
      "x": -43,
      "y": 23,
      "z": -9,
      "name": "Rock_Ice"
    },
    {
      "x": -43,
      "y": 24,
      "z": -9,
      "name": "Rock_Ice"
    },
    {
      "x": -43,
      "y": 25,
      "z": -9,
      "name": "Rock_Ice"
    },
    {
      "x": -43,
      "y": 26,
      "z": -9,
      "name": "Rock_Ice"
    },
    {
      "x": -43,
      "y": 27,
      "z": -9,
      "name": "Rock_Ice"
    },
    {
      "x": -43,
      "y": 28,
      "z": -9,
      "name": "Rock_Ice"
    },
    {
      "x": -43,
      "y": 29,
      "z": -9,
      "name": "Rock_Ice"
    },
    {
      "x": -43,
      "y": 30,
      "z": -9,
      "name": "Rock_Ice"
    },
    {
      "x": -43,
      "y": 31,
      "z": -9,
      "name": "Rock_Ice"
    },
    {
      "x": -43,
      "y": 32,
      "z": -9,
      "name": "Rock_Ice"
    },
    {
      "x": -43,
      "y": 33,
      "z": -9,
      "name": "Soil_Snow"
    },
    {
      "x": -43,
      "y": 19,
      "z": -8,
      "name": "Rock_Ice_Permafrost"
    },
    {
      "x": -43,
      "y": 20,
      "z": -8,
      "name": "Rock_Ice_Permafrost"
    },
    {
      "x": -43,
      "y": 21,
      "z": -8,
      "name": "Rock_Ice_Permafrost"
    },
    {
      "x": -43,
      "y": 22,
      "z": -8,
      "name": "Rock_Ice"
    },
    {
      "x": -43,
      "y": 23,
      "z": -8,
      "name": "Rock_Ice"
    },
    {
      "x": -43,
      "y": 24,
      "z": -8,
      "name": "Rock_Ice"
    },
    {
      "x": -43,
      "y": 25,
      "z": -8,
      "name": "Rock_Ice"
    },
    {
      "x": -43,
      "y": 26,
      "z": -8,
      "name": "Rock_Ice"
    },
    {
      "x": -43,
      "y": 27,
      "z": -8,
      "name": "Rock_Ice"
    },
    {
      "x": -43,
      "y": 28,
      "z": -8,
      "name": "Rock_Ice"
    },
    {
      "x": -43,
      "y": 29,
      "z": -8,
      "name": "Rock_Ice"
    },
    {
      "x": -43,
      "y": 30,
      "z": -8,
      "name": "Rock_Ice"
    },
    {
      "x": -43,
      "y": 31,
      "z": -8,
      "name": "Rock_Ice"
    },
    {
      "x": -43,
      "y": 32,
      "z": -8,
      "name": "Rock_Ice"
    },
    {
      "x": -43,
      "y": 33,
      "z": -8,
      "name": "Rock_Ice"
    },
    {
      "x": -43,
      "y": 34,
      "z": -8,
      "name": "Rock_Ice"
    },
    {
      "x": -43,
      "y": 35,
      "z": -8,
      "name": "Rock_Ice"
    },
    {
      "x": -43,
      "y": 36,
      "z": -8,
      "name": "Rock_Ice"
    },
    {
      "x": -43,
      "y": 37,
      "z": -8,
      "name": "Rock_Ice"
    },
    {
      "x": -43,
      "y": 20,
      "z": -7,
      "name": "Rock_Ice_Permafrost"
    },
    {
      "x": -43,
      "y": 21,
      "z": -7,
      "name": "Rock_Ice_Permafrost"
    },
    {
      "x": -43,
      "y": 22,
      "z": -7,
      "name": "Rock_Ice_Permafrost"
    },
    {
      "x": -43,
      "y": 23,
      "z": -7,
      "name": "Rock_Ice_Permafrost"
    },
    {
      "x": -43,
      "y": 24,
      "z": -7,
      "name": "Rock_Ice"
    },
    {
      "x": -43,
      "y": 25,
      "z": -7,
      "name": "Rock_Ice"
    },
    {
      "x": -43,
      "y": 26,
      "z": -7,
      "name": "Rock_Ice"
    },
    {
      "x": -43,
      "y": 27,
      "z": -7,
      "name": "Rock_Ice"
    },
    {
      "x": -43,
      "y": 28,
      "z": -7,
      "name": "Rock_Ice"
    },
    {
      "x": -43,
      "y": 29,
      "z": -7,
      "name": "Rock_Ice"
    },
    {
      "x": -43,
      "y": 30,
      "z": -7,
      "name": "Rock_Ice"
    },
    {
      "x": -43,
      "y": 31,
      "z": -7,
      "name": "Rock_Ice"
    },
    {
      "x": -43,
      "y": 32,
      "z": -7,
      "name": "Rock_Ice"
    },
    {
      "x": -43,
      "y": 33,
      "z": -7,
      "name": "Rock_Ice"
    },
    {
      "x": -43,
      "y": 34,
      "z": -7,
      "name": "Rock_Ice"
    },
    {
      "x": -43,
      "y": 35,
      "z": -7,
      "name": "Rock_Ice"
    },
    {
      "x": -43,
      "y": 36,
      "z": -7,
      "name": "Rock_Ice"
    },
    {
      "x": -43,
      "y": 37,
      "z": -7,
      "name": "Soil_Snow"
    },
    {
      "x": -43,
      "y": 21,
      "z": -6,
      "name": "Rock_Ice_Permafrost"
    },
    {
      "x": -43,
      "y": 22,
      "z": -6,
      "name": "Rock_Ice_Permafrost"
    },
    {
      "x": -43,
      "y": 23,
      "z": -6,
      "name": "Rock_Ice_Permafrost"
    },
    {
      "x": -43,
      "y": 24,
      "z": -6,
      "name": "Rock_Ice"
    },
    {
      "x": -43,
      "y": 25,
      "z": -6,
      "name": "Rock_Ice"
    },
    {
      "x": -43,
      "y": 26,
      "z": -6,
      "name": "Rock_Ice"
    },
    {
      "x": -43,
      "y": 27,
      "z": -6,
      "name": "Rock_Ice"
    },
    {
      "x": -43,
      "y": 28,
      "z": -6,
      "name": "Rock_Ice"
    },
    {
      "x": -43,
      "y": 29,
      "z": -6,
      "name": "Rock_Ice"
    },
    {
      "x": -43,
      "y": 30,
      "z": -6,
      "name": "Rock_Ice"
    },
    {
      "x": -43,
      "y": 31,
      "z": -6,
      "name": "Rock_Ice"
    },
    {
      "x": -43,
      "y": 32,
      "z": -6,
      "name": "Rock_Ice"
    },
    {
      "x": -43,
      "y": 33,
      "z": -6,
      "name": "Rock_Ice"
    },
    {
      "x": -43,
      "y": 34,
      "z": -6,
      "name": "Rock_Ice"
    },
    {
      "x": -43,
      "y": 35,
      "z": -6,
      "name": "Rock_Ice"
    },
    {
      "x": -43,
      "y": 36,
      "z": -6,
      "name": "Rock_Ice"
    },
    {
      "x": -43,
      "y": 37,
      "z": -6,
      "name": "Soil_Snow"
    },
    {
      "x": -43,
      "y": 22,
      "z": -5,
      "name": "Rock_Ice_Permafrost"
    },
    {
      "x": -43,
      "y": 23,
      "z": -5,
      "name": "Rock_Ice_Permafrost"
    },
    {
      "x": -43,
      "y": 24,
      "z": -5,
      "name": "Rock_Ice_Permafrost"
    },
    {
      "x": -43,
      "y": 25,
      "z": -5,
      "name": "Rock_Ice"
    },
    {
      "x": -43,
      "y": 26,
      "z": -5,
      "name": "Rock_Ice"
    },
    {
      "x": -43,
      "y": 27,
      "z": -5,
      "name": "Rock_Ice"
    },
    {
      "x": -43,
      "y": 28,
      "z": -5,
      "name": "Rock_Ice"
    },
    {
      "x": -43,
      "y": 29,
      "z": -5,
      "name": "Rock_Ice"
    },
    {
      "x": -43,
      "y": 30,
      "z": -5,
      "name": "Rock_Ice"
    },
    {
      "x": -43,
      "y": 31,
      "z": -5,
      "name": "Rock_Ice"
    },
    {
      "x": -43,
      "y": 32,
      "z": -5,
      "name": "Rock_Ice"
    },
    {
      "x": -43,
      "y": 33,
      "z": -5,
      "name": "Rock_Ice"
    },
    {
      "x": -43,
      "y": 34,
      "z": -5,
      "name": "Rock_Ice"
    },
    {
      "x": -43,
      "y": 35,
      "z": -5,
      "name": "Rock_Ice_Permafrost"
    },
    {
      "x": -43,
      "y": 36,
      "z": -5,
      "name": "Rock_Ice"
    },
    {
      "x": -43,
      "y": 37,
      "z": -5,
      "name": "Soil_Snow"
    },
    {
      "x": -43,
      "y": 23,
      "z": -4,
      "name": "Rock_Ice_Permafrost"
    },
    {
      "x": -43,
      "y": 24,
      "z": -4,
      "name": "Rock_Ice_Permafrost"
    },
    {
      "x": -43,
      "y": 25,
      "z": -4,
      "name": "Rock_Ice_Permafrost"
    },
    {
      "x": -43,
      "y": 26,
      "z": -4,
      "name": "Rock_Ice_Permafrost"
    },
    {
      "x": -43,
      "y": 27,
      "z": -4,
      "name": "Rock_Ice"
    },
    {
      "x": -43,
      "y": 28,
      "z": -4,
      "name": "Rock_Ice"
    },
    {
      "x": -43,
      "y": 29,
      "z": -4,
      "name": "Rock_Ice_Permafrost"
    },
    {
      "x": -43,
      "y": 30,
      "z": -4,
      "name": "Rock_Ice"
    },
    {
      "x": -43,
      "y": 31,
      "z": -4,
      "name": "Rock_Ice"
    },
    {
      "x": -43,
      "y": 32,
      "z": -4,
      "name": "Rock_Ice_Permafrost"
    },
    {
      "x": -43,
      "y": 33,
      "z": -4,
      "name": "Rock_Ice_Permafrost"
    },
    {
      "x": -43,
      "y": 34,
      "z": -4,
      "name": "Rock_Ice"
    },
    {
      "x": -43,
      "y": 35,
      "z": -4,
      "name": "Rock_Ice_Permafrost"
    },
    {
      "x": -43,
      "y": 36,
      "z": -4,
      "name": "Rock_Ice"
    },
    {
      "x": -43,
      "y": 37,
      "z": -4,
      "name": "Soil_Snow"
    },
    {
      "x": -43,
      "y": 24,
      "z": -3,
      "name": "Rock_Ice_Permafrost"
    },
    {
      "x": -43,
      "y": 25,
      "z": -3,
      "name": "Rock_Ice_Permafrost"
    },
    {
      "x": -43,
      "y": 26,
      "z": -3,
      "name": "Rock_Ice_Permafrost"
    },
    {
      "x": -43,
      "y": 27,
      "z": -3,
      "name": "Rock_Ice_Permafrost"
    },
    {
      "x": -43,
      "y": 28,
      "z": -3,
      "name": "Rock_Ice_Permafrost"
    },
    {
      "x": -43,
      "y": 29,
      "z": -3,
      "name": "Rock_Ice_Permafrost"
    },
    {
      "x": -43,
      "y": 30,
      "z": -3,
      "name": "Rock_Ice_Permafrost"
    },
    {
      "x": -43,
      "y": 31,
      "z": -3,
      "name": "Rock_Ice_Permafrost"
    },
    {
      "x": -43,
      "y": 32,
      "z": -3,
      "name": "Rock_Ice_Permafrost"
    },
    {
      "x": -43,
      "y": 33,
      "z": -3,
      "name": "Rock_Ice_Permafrost"
    },
    {
      "x": -43,
      "y": 34,
      "z": -3,
      "name": "Rock_Ice_Permafrost"
    },
    {
      "x": -43,
      "y": 35,
      "z": -3,
      "name": "Rock_Ice"
    },
    {
      "x": -43,
      "y": 36,
      "z": -3,
      "name": "Soil_Snow"
    },
    {
      "x": -43,
      "y": 25,
      "z": -2,
      "name": "Rock_Ice_Permafrost"
    },
    {
      "x": -43,
      "y": 26,
      "z": -2,
      "name": "Rock_Ice"
    },
    {
      "x": -43,
      "y": 27,
      "z": -2,
      "name": "Rock_Ice"
    },
    {
      "x": -43,
      "y": 28,
      "z": -2,
      "name": "Rock_Ice"
    },
    {
      "x": -43,
      "y": 29,
      "z": -2,
      "name": "Rock_Ice_Permafrost"
    },
    {
      "x": -43,
      "y": 30,
      "z": -2,
      "name": "Rock_Ice_Permafrost"
    },
    {
      "x": -43,
      "y": 31,
      "z": -2,
      "name": "Rock_Ice_Permafrost"
    },
    {
      "x": -43,
      "y": 32,
      "z": -2,
      "name": "Rock_Ice_Permafrost"
    },
    {
      "x": -43,
      "y": 33,
      "z": -2,
      "name": "Rock_Ice_Permafrost"
    },
    {
      "x": -43,
      "y": 34,
      "z": -2,
      "name": "Rock_Ice_Permafrost"
    },
    {
      "x": -43,
      "y": 35,
      "z": -2,
      "name": "Soil_Snow"
    },
    {
      "x": -43,
      "y": 27,
      "z": -1,
      "name": "Rock_Ice"
    },
    {
      "x": -43,
      "y": 28,
      "z": -1,
      "name": "Rock_Ice"
    },
    {
      "x": -43,
      "y": 29,
      "z": -1,
      "name": "Rock_Ice_Permafrost"
    },
    {
      "x": -43,
      "y": 30,
      "z": -1,
      "name": "Rock_Ice_Permafrost"
    },
    {
      "x": -43,
      "y": 31,
      "z": -1,
      "name": "Rock_Ice_Permafrost"
    },
    {
      "x": -43,
      "y": 32,
      "z": -1,
      "name": "Rock_Ice_Permafrost"
    },
    {
      "x": -43,
      "y": 33,
      "z": -1,
      "name": "Rock_Ice"
    },
    {
      "x": -43,
      "y": 34,
      "z": -1,
      "name": "Rock_Ice_Permafrost"
    },
    {
      "x": -43,
      "y": 28,
      "z": 0,
      "name": "Rock_Ice"
    },
    {
      "x": -43,
      "y": 29,
      "z": 0,
      "name": "Rock_Ice"
    },
    {
      "x": -43,
      "y": 30,
      "z": 0,
      "name": "Rock_Ice"
    },
    {
      "x": -43,
      "y": 31,
      "z": 0,
      "name": "Rock_Ice"
    },
    {
      "x": -43,
      "y": 32,
      "z": 0,
      "name": "Rock_Ice"
    },
    {
      "x": -42,
      "y": 16,
      "z": -18,
      "name": "Rock_Ice"
    },
    {
      "x": -42,
      "y": 17,
      "z": -18,
      "name": "Soil_Snow"
    },
    {
      "x": -42,
      "y": 15,
      "z": -17,
      "name": "Rock_Ice_Permafrost"
    },
    {
      "x": -42,
      "y": 16,
      "z": -17,
      "name": "Rock_Ice_Permafrost"
    },
    {
      "x": -42,
      "y": 17,
      "z": -17,
      "name": "Rock_Ice"
    },
    {
      "x": -42,
      "y": 18,
      "z": -17,
      "name": "Soil_Snow"
    },
    {
      "x": -42,
      "y": 16,
      "z": -16,
      "name": "Rock_Ice_Permafrost"
    },
    {
      "x": -42,
      "y": 17,
      "z": -16,
      "name": "Rock_Ice"
    },
    {
      "x": -42,
      "y": 18,
      "z": -16,
      "name": "Rock_Ice"
    },
    {
      "x": -42,
      "y": 19,
      "z": -16,
      "name": "Soil_Snow"
    },
    {
      "x": -42,
      "y": 16,
      "z": -15,
      "name": "Rock_Ice_Permafrost"
    },
    {
      "x": -42,
      "y": 17,
      "z": -15,
      "name": "Rock_Ice_Permafrost"
    },
    {
      "x": -42,
      "y": 18,
      "z": -15,
      "name": "Rock_Ice"
    },
    {
      "x": -42,
      "y": 19,
      "z": -15,
      "name": "Rock_Ice"
    },
    {
      "x": -42,
      "y": 20,
      "z": -15,
      "name": "Soil_Snow"
    },
    {
      "x": -42,
      "y": 16,
      "z": -14,
      "name": "Rock_Ice_Permafrost"
    },
    {
      "x": -42,
      "y": 17,
      "z": -14,
      "name": "Rock_Ice_Permafrost"
    },
    {
      "x": -42,
      "y": 18,
      "z": -14,
      "name": "Rock_Ice"
    },
    {
      "x": -42,
      "y": 19,
      "z": -14,
      "name": "Rock_Ice"
    },
    {
      "x": -42,
      "y": 20,
      "z": -14,
      "name": "Rock_Ice"
    },
    {
      "x": -42,
      "y": 21,
      "z": -14,
      "name": "Soil_Snow"
    },
    {
      "x": -42,
      "y": 16,
      "z": -13,
      "name": "Rock_Ice_Permafrost"
    },
    {
      "x": -42,
      "y": 17,
      "z": -13,
      "name": "Rock_Ice_Permafrost"
    },
    {
      "x": -42,
      "y": 18,
      "z": -13,
      "name": "Rock_Ice"
    },
    {
      "x": -42,
      "y": 19,
      "z": -13,
      "name": "Rock_Ice"
    },
    {
      "x": -42,
      "y": 20,
      "z": -13,
      "name": "Rock_Ice"
    },
    {
      "x": -42,
      "y": 21,
      "z": -13,
      "name": "Rock_Ice"
    },
    {
      "x": -42,
      "y": 22,
      "z": -13,
      "name": "Soil_Snow"
    },
    {
      "x": -42,
      "y": 17,
      "z": -12,
      "name": "Rock_Ice_Permafrost"
    },
    {
      "x": -42,
      "y": 18,
      "z": -12,
      "name": "Rock_Ice_Permafrost"
    },
    {
      "x": -42,
      "y": 19,
      "z": -12,
      "name": "Rock_Ice_Permafrost"
    },
    {
      "x": -42,
      "y": 20,
      "z": -12,
      "name": "Rock_Ice"
    },
    {
      "x": -42,
      "y": 21,
      "z": -12,
      "name": "Rock_Ice"
    },
    {
      "x": -42,
      "y": 22,
      "z": -12,
      "name": "Rock_Ice"
    },
    {
      "x": -42,
      "y": 23,
      "z": -12,
      "name": "Rock_Ice"
    },
    {
      "x": -42,
      "y": 24,
      "z": -12,
      "name": "Rock_Ice"
    },
    {
      "x": -42,
      "y": 29,
      "z": -12,
      "name": "Rock_Ice"
    },
    {
      "x": -42,
      "y": 30,
      "z": -12,
      "name": "Soil_Snow"
    },
    {
      "x": -42,
      "y": 17,
      "z": -11,
      "name": "Rock_Ice"
    },
    {
      "x": -42,
      "y": 18,
      "z": -11,
      "name": "Rock_Ice_Permafrost"
    },
    {
      "x": -42,
      "y": 19,
      "z": -11,
      "name": "Rock_Ice_Permafrost"
    },
    {
      "x": -42,
      "y": 20,
      "z": -11,
      "name": "Rock_Ice"
    },
    {
      "x": -42,
      "y": 21,
      "z": -11,
      "name": "Rock_Ice"
    },
    {
      "x": -42,
      "y": 22,
      "z": -11,
      "name": "Rock_Ice"
    },
    {
      "x": -42,
      "y": 23,
      "z": -11,
      "name": "Rock_Ice"
    },
    {
      "x": -42,
      "y": 24,
      "z": -11,
      "name": "Rock_Ice"
    },
    {
      "x": -42,
      "y": 25,
      "z": -11,
      "name": "Rock_Ice"
    },
    {
      "x": -42,
      "y": 26,
      "z": -11,
      "name": "Rock_Ice"
    },
    {
      "x": -42,
      "y": 27,
      "z": -11,
      "name": "Rock_Ice"
    },
    {
      "x": -42,
      "y": 28,
      "z": -11,
      "name": "Rock_Ice"
    },
    {
      "x": -42,
      "y": 29,
      "z": -11,
      "name": "Rock_Ice"
    },
    {
      "x": -42,
      "y": 30,
      "z": -11,
      "name": "Rock_Ice"
    },
    {
      "x": -42,
      "y": 31,
      "z": -11,
      "name": "Soil_Snow"
    },
    {
      "x": -42,
      "y": 18,
      "z": -10,
      "name": "Rock_Ice_Permafrost"
    },
    {
      "x": -42,
      "y": 19,
      "z": -10,
      "name": "Rock_Ice_Permafrost"
    },
    {
      "x": -42,
      "y": 20,
      "z": -10,
      "name": "Rock_Ice"
    },
    {
      "x": -42,
      "y": 21,
      "z": -10,
      "name": "Rock_Ice"
    },
    {
      "x": -42,
      "y": 22,
      "z": -10,
      "name": "Rock_Ice"
    },
    {
      "x": -42,
      "y": 23,
      "z": -10,
      "name": "Rock_Ice"
    },
    {
      "x": -42,
      "y": 24,
      "z": -10,
      "name": "Rock_Ice"
    },
    {
      "x": -42,
      "y": 25,
      "z": -10,
      "name": "Rock_Ice"
    },
    {
      "x": -42,
      "y": 26,
      "z": -10,
      "name": "Rock_Ice"
    },
    {
      "x": -42,
      "y": 27,
      "z": -10,
      "name": "Rock_Ice"
    },
    {
      "x": -42,
      "y": 28,
      "z": -10,
      "name": "Rock_Ice"
    },
    {
      "x": -42,
      "y": 29,
      "z": -10,
      "name": "Rock_Ice"
    },
    {
      "x": -42,
      "y": 30,
      "z": -10,
      "name": "Rock_Ice"
    },
    {
      "x": -42,
      "y": 31,
      "z": -10,
      "name": "Rock_Ice"
    },
    {
      "x": -42,
      "y": 32,
      "z": -10,
      "name": "Soil_Snow"
    },
    {
      "x": -42,
      "y": 18,
      "z": -9,
      "name": "Rock_Ice_Permafrost"
    },
    {
      "x": -42,
      "y": 19,
      "z": -9,
      "name": "Rock_Ice_Permafrost"
    },
    {
      "x": -42,
      "y": 20,
      "z": -9,
      "name": "Rock_Ice_Permafrost"
    },
    {
      "x": -42,
      "y": 21,
      "z": -9,
      "name": "Rock_Ice"
    },
    {
      "x": -42,
      "y": 22,
      "z": -9,
      "name": "Rock_Ice"
    },
    {
      "x": -42,
      "y": 23,
      "z": -9,
      "name": "Rock_Ice"
    },
    {
      "x": -42,
      "y": 24,
      "z": -9,
      "name": "Rock_Ice"
    },
    {
      "x": -42,
      "y": 25,
      "z": -9,
      "name": "Rock_Ice"
    },
    {
      "x": -42,
      "y": 26,
      "z": -9,
      "name": "Rock_Ice"
    },
    {
      "x": -42,
      "y": 27,
      "z": -9,
      "name": "Rock_Ice"
    },
    {
      "x": -42,
      "y": 28,
      "z": -9,
      "name": "Rock_Ice"
    },
    {
      "x": -42,
      "y": 29,
      "z": -9,
      "name": "Rock_Ice"
    },
    {
      "x": -42,
      "y": 30,
      "z": -9,
      "name": "Rock_Ice"
    },
    {
      "x": -42,
      "y": 31,
      "z": -9,
      "name": "Rock_Ice"
    },
    {
      "x": -42,
      "y": 32,
      "z": -9,
      "name": "Rock_Ice"
    },
    {
      "x": -42,
      "y": 33,
      "z": -9,
      "name": "Rock_Ice"
    },
    {
      "x": -42,
      "y": 34,
      "z": -9,
      "name": "Soil_Snow"
    },
    {
      "x": -42,
      "y": 19,
      "z": -8,
      "name": "Rock_Ice_Permafrost"
    },
    {
      "x": -42,
      "y": 20,
      "z": -8,
      "name": "Rock_Ice_Permafrost"
    },
    {
      "x": -42,
      "y": 21,
      "z": -8,
      "name": "Rock_Ice_Permafrost"
    },
    {
      "x": -42,
      "y": 22,
      "z": -8,
      "name": "Rock_Ice"
    },
    {
      "x": -42,
      "y": 23,
      "z": -8,
      "name": "Rock_Ice"
    },
    {
      "x": -42,
      "y": 24,
      "z": -8,
      "name": "Rock_Ice"
    },
    {
      "x": -42,
      "y": 25,
      "z": -8,
      "name": "Rock_Ice"
    },
    {
      "x": -42,
      "y": 26,
      "z": -8,
      "name": "Rock_Ice"
    },
    {
      "x": -42,
      "y": 27,
      "z": -8,
      "name": "Rock_Ice"
    },
    {
      "x": -42,
      "y": 28,
      "z": -8,
      "name": "Rock_Ice"
    },
    {
      "x": -42,
      "y": 29,
      "z": -8,
      "name": "Rock_Ice"
    },
    {
      "x": -42,
      "y": 30,
      "z": -8,
      "name": "Rock_Ice"
    },
    {
      "x": -42,
      "y": 31,
      "z": -8,
      "name": "Rock_Ice"
    },
    {
      "x": -42,
      "y": 32,
      "z": -8,
      "name": "Rock_Ice"
    },
    {
      "x": -42,
      "y": 33,
      "z": -8,
      "name": "Rock_Ice"
    },
    {
      "x": -42,
      "y": 34,
      "z": -8,
      "name": "Rock_Ice"
    },
    {
      "x": -42,
      "y": 35,
      "z": -8,
      "name": "Rock_Ice"
    },
    {
      "x": -42,
      "y": 36,
      "z": -8,
      "name": "Rock_Ice"
    },
    {
      "x": -42,
      "y": 37,
      "z": -8,
      "name": "Rock_Ice"
    },
    {
      "x": -42,
      "y": 38,
      "z": -8,
      "name": "Soil_Snow"
    },
    {
      "x": -42,
      "y": 20,
      "z": -7,
      "name": "Rock_Ice_Permafrost"
    },
    {
      "x": -42,
      "y": 21,
      "z": -7,
      "name": "Rock_Ice_Permafrost"
    },
    {
      "x": -42,
      "y": 22,
      "z": -7,
      "name": "Rock_Ice_Permafrost"
    },
    {
      "x": -42,
      "y": 23,
      "z": -7,
      "name": "Rock_Ice"
    },
    {
      "x": -42,
      "y": 24,
      "z": -7,
      "name": "Rock_Ice"
    },
    {
      "x": -42,
      "y": 25,
      "z": -7,
      "name": "Rock_Ice"
    },
    {
      "x": -42,
      "y": 26,
      "z": -7,
      "name": "Rock_Ice"
    },
    {
      "x": -42,
      "y": 27,
      "z": -7,
      "name": "Rock_Ice"
    },
    {
      "x": -42,
      "y": 28,
      "z": -7,
      "name": "Rock_Ice"
    },
    {
      "x": -42,
      "y": 29,
      "z": -7,
      "name": "Rock_Ice"
    },
    {
      "x": -42,
      "y": 30,
      "z": -7,
      "name": "Rock_Ice"
    },
    {
      "x": -42,
      "y": 31,
      "z": -7,
      "name": "Rock_Ice"
    },
    {
      "x": -42,
      "y": 32,
      "z": -7,
      "name": "Rock_Ice"
    },
    {
      "x": -42,
      "y": 33,
      "z": -7,
      "name": "Rock_Ice"
    },
    {
      "x": -42,
      "y": 34,
      "z": -7,
      "name": "Rock_Ice"
    },
    {
      "x": -42,
      "y": 35,
      "z": -7,
      "name": "Rock_Ice"
    },
    {
      "x": -42,
      "y": 36,
      "z": -7,
      "name": "Rock_Ice"
    },
    {
      "x": -42,
      "y": 37,
      "z": -7,
      "name": "Rock_Ice"
    },
    {
      "x": -42,
      "y": 38,
      "z": -7,
      "name": "Soil_Snow"
    },
    {
      "x": -42,
      "y": 20,
      "z": -6,
      "name": "Rock_Ice"
    },
    {
      "x": -42,
      "y": 21,
      "z": -6,
      "name": "Rock_Ice_Permafrost"
    },
    {
      "x": -42,
      "y": 22,
      "z": -6,
      "name": "Rock_Ice_Permafrost"
    },
    {
      "x": -42,
      "y": 23,
      "z": -6,
      "name": "Rock_Ice_Permafrost"
    },
    {
      "x": -42,
      "y": 24,
      "z": -6,
      "name": "Rock_Ice"
    },
    {
      "x": -42,
      "y": 25,
      "z": -6,
      "name": "Rock_Ice"
    },
    {
      "x": -42,
      "y": 26,
      "z": -6,
      "name": "Rock_Ice"
    },
    {
      "x": -42,
      "y": 27,
      "z": -6,
      "name": "Rock_Ice"
    },
    {
      "x": -42,
      "y": 28,
      "z": -6,
      "name": "Rock_Ice"
    },
    {
      "x": -42,
      "y": 29,
      "z": -6,
      "name": "Rock_Ice"
    },
    {
      "x": -42,
      "y": 30,
      "z": -6,
      "name": "Rock_Ice"
    },
    {
      "x": -42,
      "y": 31,
      "z": -6,
      "name": "Rock_Ice"
    },
    {
      "x": -42,
      "y": 32,
      "z": -6,
      "name": "Rock_Ice"
    },
    {
      "x": -42,
      "y": 33,
      "z": -6,
      "name": "Rock_Ice"
    },
    {
      "x": -42,
      "y": 34,
      "z": -6,
      "name": "Rock_Ice"
    },
    {
      "x": -42,
      "y": 35,
      "z": -6,
      "name": "Rock_Ice"
    },
    {
      "x": -42,
      "y": 36,
      "z": -6,
      "name": "Rock_Ice"
    },
    {
      "x": -42,
      "y": 37,
      "z": -6,
      "name": "Rock_Ice"
    },
    {
      "x": -42,
      "y": 38,
      "z": -6,
      "name": "Soil_Snow"
    },
    {
      "x": -42,
      "y": 21,
      "z": -5,
      "name": "Rock_Ice"
    },
    {
      "x": -42,
      "y": 22,
      "z": -5,
      "name": "Rock_Ice_Permafrost"
    },
    {
      "x": -42,
      "y": 23,
      "z": -5,
      "name": "Rock_Ice_Permafrost"
    },
    {
      "x": -42,
      "y": 24,
      "z": -5,
      "name": "Rock_Ice_Permafrost"
    },
    {
      "x": -42,
      "y": 25,
      "z": -5,
      "name": "Rock_Ice"
    },
    {
      "x": -42,
      "y": 26,
      "z": -5,
      "name": "Rock_Ice"
    },
    {
      "x": -42,
      "y": 27,
      "z": -5,
      "name": "Rock_Ice"
    },
    {
      "x": -42,
      "y": 28,
      "z": -5,
      "name": "Rock_Ice"
    },
    {
      "x": -42,
      "y": 29,
      "z": -5,
      "name": "Rock_Ice"
    },
    {
      "x": -42,
      "y": 30,
      "z": -5,
      "name": "Rock_Ice"
    },
    {
      "x": -42,
      "y": 31,
      "z": -5,
      "name": "Rock_Ice"
    },
    {
      "x": -42,
      "y": 32,
      "z": -5,
      "name": "Rock_Ice"
    },
    {
      "x": -42,
      "y": 33,
      "z": -5,
      "name": "Rock_Ice"
    },
    {
      "x": -42,
      "y": 34,
      "z": -5,
      "name": "Rock_Ice"
    },
    {
      "x": -42,
      "y": 35,
      "z": -5,
      "name": "Rock_Ice"
    },
    {
      "x": -42,
      "y": 36,
      "z": -5,
      "name": "Rock_Ice_Permafrost"
    },
    {
      "x": -42,
      "y": 37,
      "z": -5,
      "name": "Rock_Ice"
    },
    {
      "x": -42,
      "y": 38,
      "z": -5,
      "name": "Rock_Ice_Permafrost"
    },
    {
      "x": -42,
      "y": 22,
      "z": -4,
      "name": "Rock_Ice"
    },
    {
      "x": -42,
      "y": 23,
      "z": -4,
      "name": "Rock_Ice_Permafrost"
    },
    {
      "x": -42,
      "y": 24,
      "z": -4,
      "name": "Rock_Ice_Permafrost"
    },
    {
      "x": -42,
      "y": 25,
      "z": -4,
      "name": "Rock_Ice_Permafrost"
    },
    {
      "x": -42,
      "y": 26,
      "z": -4,
      "name": "Rock_Ice_Permafrost"
    },
    {
      "x": -42,
      "y": 27,
      "z": -4,
      "name": "Rock_Ice"
    },
    {
      "x": -42,
      "y": 28,
      "z": -4,
      "name": "Rock_Ice"
    },
    {
      "x": -42,
      "y": 29,
      "z": -4,
      "name": "Rock_Ice"
    },
    {
      "x": -42,
      "y": 30,
      "z": -4,
      "name": "Rock_Ice"
    },
    {
      "x": -42,
      "y": 31,
      "z": -4,
      "name": "Rock_Ice"
    },
    {
      "x": -42,
      "y": 32,
      "z": -4,
      "name": "Rock_Ice"
    },
    {
      "x": -42,
      "y": 33,
      "z": -4,
      "name": "Rock_Ice"
    },
    {
      "x": -42,
      "y": 34,
      "z": -4,
      "name": "Rock_Ice"
    },
    {
      "x": -42,
      "y": 35,
      "z": -4,
      "name": "Rock_Ice_Permafrost"
    },
    {
      "x": -42,
      "y": 36,
      "z": -4,
      "name": "Rock_Ice_Permafrost"
    },
    {
      "x": -42,
      "y": 37,
      "z": -4,
      "name": "Rock_Ice"
    },
    {
      "x": -42,
      "y": 38,
      "z": -4,
      "name": "Soil_Snow"
    },
    {
      "x": -42,
      "y": 23,
      "z": -3,
      "name": "Rock_Ice"
    },
    {
      "x": -42,
      "y": 24,
      "z": -3,
      "name": "Rock_Ice"
    },
    {
      "x": -42,
      "y": 25,
      "z": -3,
      "name": "Rock_Ice_Permafrost"
    },
    {
      "x": -42,
      "y": 26,
      "z": -3,
      "name": "Rock_Ice_Permafrost"
    },
    {
      "x": -42,
      "y": 27,
      "z": -3,
      "name": "Rock_Ice_Permafrost"
    },
    {
      "x": -42,
      "y": 28,
      "z": -3,
      "name": "Rock_Ice_Permafrost"
    },
    {
      "x": -42,
      "y": 29,
      "z": -3,
      "name": "Rock_Ice_Permafrost"
    },
    {
      "x": -42,
      "y": 30,
      "z": -3,
      "name": "Rock_Ice_Permafrost"
    },
    {
      "x": -42,
      "y": 31,
      "z": -3,
      "name": "Rock_Ice_Permafrost"
    },
    {
      "x": -42,
      "y": 32,
      "z": -3,
      "name": "Rock_Ice_Permafrost"
    },
    {
      "x": -42,
      "y": 33,
      "z": -3,
      "name": "Rock_Ice_Permafrost"
    },
    {
      "x": -42,
      "y": 34,
      "z": -3,
      "name": "Rock_Ice_Permafrost"
    },
    {
      "x": -42,
      "y": 35,
      "z": -3,
      "name": "Rock_Ice_Permafrost"
    },
    {
      "x": -42,
      "y": 36,
      "z": -3,
      "name": "Rock_Ice"
    },
    {
      "x": -42,
      "y": 37,
      "z": -3,
      "name": "Soil_Snow"
    },
    {
      "x": -42,
      "y": 25,
      "z": -2,
      "name": "Rock_Ice_Permafrost"
    },
    {
      "x": -42,
      "y": 26,
      "z": -2,
      "name": "Rock_Ice_Permafrost"
    },
    {
      "x": -42,
      "y": 27,
      "z": -2,
      "name": "Rock_Ice_Permafrost"
    },
    {
      "x": -42,
      "y": 28,
      "z": -2,
      "name": "Rock_Ice_Permafrost"
    },
    {
      "x": -42,
      "y": 29,
      "z": -2,
      "name": "Rock_Ice_Permafrost"
    },
    {
      "x": -42,
      "y": 30,
      "z": -2,
      "name": "Rock_Ice_Permafrost"
    },
    {
      "x": -42,
      "y": 31,
      "z": -2,
      "name": "Rock_Ice_Permafrost"
    },
    {
      "x": -42,
      "y": 32,
      "z": -2,
      "name": "Rock_Ice_Permafrost"
    },
    {
      "x": -42,
      "y": 33,
      "z": -2,
      "name": "Rock_Ice_Permafrost"
    },
    {
      "x": -42,
      "y": 34,
      "z": -2,
      "name": "Rock_Ice_Permafrost"
    },
    {
      "x": -42,
      "y": 35,
      "z": -2,
      "name": "Rock_Ice"
    },
    {
      "x": -42,
      "y": 36,
      "z": -2,
      "name": "Soil_Snow"
    },
    {
      "x": -42,
      "y": 26,
      "z": -1,
      "name": "Rock_Ice"
    },
    {
      "x": -42,
      "y": 27,
      "z": -1,
      "name": "Rock_Ice"
    },
    {
      "x": -42,
      "y": 28,
      "z": -1,
      "name": "Rock_Ice_Permafrost"
    },
    {
      "x": -42,
      "y": 29,
      "z": -1,
      "name": "Rock_Ice_Permafrost"
    },
    {
      "x": -42,
      "y": 30,
      "z": -1,
      "name": "Rock_Ice_Permafrost"
    },
    {
      "x": -42,
      "y": 31,
      "z": -1,
      "name": "Rock_Ice_Permafrost"
    },
    {
      "x": -42,
      "y": 32,
      "z": -1,
      "name": "Rock_Ice_Permafrost"
    },
    {
      "x": -42,
      "y": 33,
      "z": -1,
      "name": "Rock_Ice"
    },
    {
      "x": -42,
      "y": 34,
      "z": -1,
      "name": "Rock_Ice_Permafrost"
    },
    {
      "x": -42,
      "y": 35,
      "z": -1,
      "name": "Rock_Ice"
    },
    {
      "x": -42,
      "y": 36,
      "z": -1,
      "name": "Soil_Snow"
    },
    {
      "x": -42,
      "y": 27,
      "z": 0,
      "name": "Rock_Ice"
    },
    {
      "x": -42,
      "y": 28,
      "z": 0,
      "name": "Rock_Ice"
    },
    {
      "x": -42,
      "y": 29,
      "z": 0,
      "name": "Rock_Ice"
    },
    {
      "x": -42,
      "y": 30,
      "z": 0,
      "name": "Rock_Ice"
    },
    {
      "x": -42,
      "y": 31,
      "z": 0,
      "name": "Rock_Ice_Permafrost"
    },
    {
      "x": -42,
      "y": 32,
      "z": 0,
      "name": "Rock_Ice"
    },
    {
      "x": -42,
      "y": 33,
      "z": 0,
      "name": "Rock_Ice"
    },
    {
      "x": -42,
      "y": 34,
      "z": 0,
      "name": "Rock_Ice"
    },
    {
      "x": -42,
      "y": 29,
      "z": 1,
      "name": "Rock_Ice"
    },
    {
      "x": -42,
      "y": 30,
      "z": 1,
      "name": "Rock_Ice"
    },
    {
      "x": -42,
      "y": 31,
      "z": 1,
      "name": "Rock_Ice"
    },
    {
      "x": -42,
      "y": 32,
      "z": 1,
      "name": "Soil_Snow"
    },
    {
      "x": -41,
      "y": 16,
      "z": -20,
      "name": "Soil_Snow"
    },
    {
      "x": -41,
      "y": 15,
      "z": -19,
      "name": "Rock_Ice_Permafrost"
    },
    {
      "x": -41,
      "y": 16,
      "z": -19,
      "name": "Rock_Ice"
    },
    {
      "x": -41,
      "y": 17,
      "z": -19,
      "name": "Soil_Snow"
    },
    {
      "x": -41,
      "y": 15,
      "z": -18,
      "name": "Rock_Ice_Permafrost"
    },
    {
      "x": -41,
      "y": 16,
      "z": -18,
      "name": "Rock_Ice_Permafrost"
    },
    {
      "x": -41,
      "y": 17,
      "z": -18,
      "name": "Rock_Ice"
    },
    {
      "x": -41,
      "y": 18,
      "z": -18,
      "name": "Soil_Snow"
    },
    {
      "x": -41,
      "y": 15,
      "z": -17,
      "name": "Rock_Ice"
    },
    {
      "x": -41,
      "y": 16,
      "z": -17,
      "name": "Rock_Ice_Permafrost"
    },
    {
      "x": -41,
      "y": 17,
      "z": -17,
      "name": "Rock_Ice"
    },
    {
      "x": -41,
      "y": 18,
      "z": -17,
      "name": "Rock_Ice"
    },
    {
      "x": -41,
      "y": 19,
      "z": -17,
      "name": "Soil_Snow"
    },
    {
      "x": -41,
      "y": 15,
      "z": -16,
      "name": "Rock_Ice_Permafrost"
    },
    {
      "x": -41,
      "y": 16,
      "z": -16,
      "name": "Rock_Ice_Permafrost"
    },
    {
      "x": -41,
      "y": 17,
      "z": -16,
      "name": "Rock_Ice"
    },
    {
      "x": -41,
      "y": 18,
      "z": -16,
      "name": "Rock_Ice"
    },
    {
      "x": -41,
      "y": 19,
      "z": -16,
      "name": "Rock_Ice"
    },
    {
      "x": -41,
      "y": 20,
      "z": -16,
      "name": "Soil_Snow"
    },
    {
      "x": -41,
      "y": 16,
      "z": -15,
      "name": "Rock_Ice_Permafrost"
    },
    {
      "x": -41,
      "y": 17,
      "z": -15,
      "name": "Rock_Ice_Permafrost"
    },
    {
      "x": -41,
      "y": 18,
      "z": -15,
      "name": "Rock_Ice"
    },
    {
      "x": -41,
      "y": 19,
      "z": -15,
      "name": "Rock_Ice"
    },
    {
      "x": -41,
      "y": 20,
      "z": -15,
      "name": "Rock_Ice"
    },
    {
      "x": -41,
      "y": 21,
      "z": -15,
      "name": "Soil_Snow"
    },
    {
      "x": -41,
      "y": 16,
      "z": -14,
      "name": "Rock_Ice_Permafrost"
    },
    {
      "x": -41,
      "y": 17,
      "z": -14,
      "name": "Rock_Ice_Permafrost"
    },
    {
      "x": -41,
      "y": 18,
      "z": -14,
      "name": "Rock_Ice_Permafrost"
    },
    {
      "x": -41,
      "y": 19,
      "z": -14,
      "name": "Rock_Ice"
    },
    {
      "x": -41,
      "y": 20,
      "z": -14,
      "name": "Rock_Ice"
    },
    {
      "x": -41,
      "y": 21,
      "z": -14,
      "name": "Rock_Ice"
    },
    {
      "x": -41,
      "y": 22,
      "z": -14,
      "name": "Soil_Snow"
    },
    {
      "x": -41,
      "y": 16,
      "z": -13,
      "name": "Rock_Ice_Permafrost"
    },
    {
      "x": -41,
      "y": 17,
      "z": -13,
      "name": "Rock_Ice_Permafrost"
    },
    {
      "x": -41,
      "y": 18,
      "z": -13,
      "name": "Rock_Ice_Permafrost"
    },
    {
      "x": -41,
      "y": 19,
      "z": -13,
      "name": "Rock_Ice"
    },
    {
      "x": -41,
      "y": 20,
      "z": -13,
      "name": "Rock_Ice"
    },
    {
      "x": -41,
      "y": 21,
      "z": -13,
      "name": "Rock_Ice"
    },
    {
      "x": -41,
      "y": 22,
      "z": -13,
      "name": "Rock_Ice"
    },
    {
      "x": -41,
      "y": 23,
      "z": -13,
      "name": "Rock_Ice"
    },
    {
      "x": -41,
      "y": 24,
      "z": -13,
      "name": "Soil_Snow"
    },
    {
      "x": -41,
      "y": 16,
      "z": -12,
      "name": "Rock_Ice_Permafrost"
    },
    {
      "x": -41,
      "y": 17,
      "z": -12,
      "name": "Rock_Ice_Permafrost"
    },
    {
      "x": -41,
      "y": 18,
      "z": -12,
      "name": "Rock_Ice"
    },
    {
      "x": -41,
      "y": 19,
      "z": -12,
      "name": "Rock_Ice"
    },
    {
      "x": -41,
      "y": 20,
      "z": -12,
      "name": "Rock_Ice"
    },
    {
      "x": -41,
      "y": 21,
      "z": -12,
      "name": "Rock_Ice"
    },
    {
      "x": -41,
      "y": 22,
      "z": -12,
      "name": "Rock_Ice"
    },
    {
      "x": -41,
      "y": 23,
      "z": -12,
      "name": "Rock_Ice"
    },
    {
      "x": -41,
      "y": 24,
      "z": -12,
      "name": "Rock_Ice"
    },
    {
      "x": -41,
      "y": 25,
      "z": -12,
      "name": "Rock_Ice"
    },
    {
      "x": -41,
      "y": 26,
      "z": -12,
      "name": "Rock_Ice"
    },
    {
      "x": -41,
      "y": 27,
      "z": -12,
      "name": "Rock_Ice"
    },
    {
      "x": -41,
      "y": 28,
      "z": -12,
      "name": "Rock_Ice"
    },
    {
      "x": -41,
      "y": 29,
      "z": -12,
      "name": "Rock_Ice"
    },
    {
      "x": -41,
      "y": 30,
      "z": -12,
      "name": "Soil_Snow"
    },
    {
      "x": -41,
      "y": 17,
      "z": -11,
      "name": "Rock_Ice_Permafrost"
    },
    {
      "x": -41,
      "y": 18,
      "z": -11,
      "name": "Rock_Ice_Permafrost"
    },
    {
      "x": -41,
      "y": 19,
      "z": -11,
      "name": "Rock_Ice_Permafrost"
    },
    {
      "x": -41,
      "y": 20,
      "z": -11,
      "name": "Rock_Ice"
    },
    {
      "x": -41,
      "y": 21,
      "z": -11,
      "name": "Rock_Ice"
    },
    {
      "x": -41,
      "y": 22,
      "z": -11,
      "name": "Rock_Ice"
    },
    {
      "x": -41,
      "y": 23,
      "z": -11,
      "name": "Rock_Ice"
    },
    {
      "x": -41,
      "y": 24,
      "z": -11,
      "name": "Rock_Ice"
    },
    {
      "x": -41,
      "y": 25,
      "z": -11,
      "name": "Rock_Ice"
    },
    {
      "x": -41,
      "y": 26,
      "z": -11,
      "name": "Rock_Ice"
    },
    {
      "x": -41,
      "y": 27,
      "z": -11,
      "name": "Rock_Ice"
    },
    {
      "x": -41,
      "y": 28,
      "z": -11,
      "name": "Rock_Ice"
    },
    {
      "x": -41,
      "y": 29,
      "z": -11,
      "name": "Rock_Ice"
    },
    {
      "x": -41,
      "y": 30,
      "z": -11,
      "name": "Rock_Ice"
    },
    {
      "x": -41,
      "y": 31,
      "z": -11,
      "name": "Soil_Snow"
    },
    {
      "x": -41,
      "y": 17,
      "z": -10,
      "name": "Rock_Ice_Permafrost"
    },
    {
      "x": -41,
      "y": 18,
      "z": -10,
      "name": "Rock_Ice_Permafrost"
    },
    {
      "x": -41,
      "y": 19,
      "z": -10,
      "name": "Rock_Ice_Permafrost"
    },
    {
      "x": -41,
      "y": 20,
      "z": -10,
      "name": "Rock_Ice_Permafrost"
    },
    {
      "x": -41,
      "y": 21,
      "z": -10,
      "name": "Rock_Ice"
    },
    {
      "x": -41,
      "y": 22,
      "z": -10,
      "name": "Rock_Ice"
    },
    {
      "x": -41,
      "y": 23,
      "z": -10,
      "name": "Rock_Ice"
    },
    {
      "x": -41,
      "y": 24,
      "z": -10,
      "name": "Rock_Ice"
    },
    {
      "x": -41,
      "y": 25,
      "z": -10,
      "name": "Rock_Ice"
    },
    {
      "x": -41,
      "y": 26,
      "z": -10,
      "name": "Rock_Ice"
    },
    {
      "x": -41,
      "y": 27,
      "z": -10,
      "name": "Rock_Ice"
    },
    {
      "x": -41,
      "y": 28,
      "z": -10,
      "name": "Rock_Ice"
    },
    {
      "x": -41,
      "y": 29,
      "z": -10,
      "name": "Rock_Ice"
    },
    {
      "x": -41,
      "y": 30,
      "z": -10,
      "name": "Rock_Ice"
    },
    {
      "x": -41,
      "y": 31,
      "z": -10,
      "name": "Rock_Ice"
    },
    {
      "x": -41,
      "y": 32,
      "z": -10,
      "name": "Rock_Ice"
    },
    {
      "x": -41,
      "y": 33,
      "z": -10,
      "name": "Soil_Snow"
    },
    {
      "x": -41,
      "y": 18,
      "z": -9,
      "name": "Rock_Ice_Permafrost"
    },
    {
      "x": -41,
      "y": 19,
      "z": -9,
      "name": "Rock_Ice_Permafrost"
    },
    {
      "x": -41,
      "y": 20,
      "z": -9,
      "name": "Rock_Ice_Permafrost"
    },
    {
      "x": -41,
      "y": 21,
      "z": -9,
      "name": "Rock_Ice"
    },
    {
      "x": -41,
      "y": 22,
      "z": -9,
      "name": "Rock_Ice"
    },
    {
      "x": -41,
      "y": 23,
      "z": -9,
      "name": "Rock_Ice"
    },
    {
      "x": -41,
      "y": 24,
      "z": -9,
      "name": "Rock_Ice"
    },
    {
      "x": -41,
      "y": 25,
      "z": -9,
      "name": "Rock_Ice"
    },
    {
      "x": -41,
      "y": 26,
      "z": -9,
      "name": "Rock_Ice"
    },
    {
      "x": -41,
      "y": 27,
      "z": -9,
      "name": "Rock_Ice"
    },
    {
      "x": -41,
      "y": 28,
      "z": -9,
      "name": "Rock_Ice"
    },
    {
      "x": -41,
      "y": 29,
      "z": -9,
      "name": "Rock_Ice"
    },
    {
      "x": -41,
      "y": 30,
      "z": -9,
      "name": "Rock_Ice"
    },
    {
      "x": -41,
      "y": 31,
      "z": -9,
      "name": "Rock_Ice"
    },
    {
      "x": -41,
      "y": 32,
      "z": -9,
      "name": "Rock_Ice"
    },
    {
      "x": -41,
      "y": 33,
      "z": -9,
      "name": "Rock_Ice"
    },
    {
      "x": -41,
      "y": 34,
      "z": -9,
      "name": "Rock_Ice"
    },
    {
      "x": -41,
      "y": 35,
      "z": -9,
      "name": "Rock_Ice"
    },
    {
      "x": -41,
      "y": 36,
      "z": -9,
      "name": "Rock_Ice"
    },
    {
      "x": -41,
      "y": 37,
      "z": -9,
      "name": "Rock_Ice"
    },
    {
      "x": -41,
      "y": 38,
      "z": -9,
      "name": "Soil_Snow"
    },
    {
      "x": -41,
      "y": 19,
      "z": -8,
      "name": "Rock_Ice_Permafrost"
    },
    {
      "x": -41,
      "y": 20,
      "z": -8,
      "name": "Rock_Ice_Permafrost"
    },
    {
      "x": -41,
      "y": 21,
      "z": -8,
      "name": "Rock_Ice_Permafrost"
    },
    {
      "x": -41,
      "y": 22,
      "z": -8,
      "name": "Rock_Ice_Permafrost"
    },
    {
      "x": -41,
      "y": 23,
      "z": -8,
      "name": "Rock_Ice"
    },
    {
      "x": -41,
      "y": 24,
      "z": -8,
      "name": "Rock_Ice"
    },
    {
      "x": -41,
      "y": 25,
      "z": -8,
      "name": "Rock_Ice"
    },
    {
      "x": -41,
      "y": 26,
      "z": -8,
      "name": "Rock_Ice"
    },
    {
      "x": -41,
      "y": 27,
      "z": -8,
      "name": "Rock_Ice"
    },
    {
      "x": -41,
      "y": 28,
      "z": -8,
      "name": "Rock_Ice"
    },
    {
      "x": -41,
      "y": 29,
      "z": -8,
      "name": "Rock_Ice"
    },
    {
      "x": -41,
      "y": 30,
      "z": -8,
      "name": "Rock_Ice"
    },
    {
      "x": -41,
      "y": 31,
      "z": -8,
      "name": "Rock_Ice"
    },
    {
      "x": -41,
      "y": 32,
      "z": -8,
      "name": "Rock_Ice"
    },
    {
      "x": -41,
      "y": 33,
      "z": -8,
      "name": "Rock_Ice"
    },
    {
      "x": -41,
      "y": 34,
      "z": -8,
      "name": "Rock_Ice"
    },
    {
      "x": -41,
      "y": 35,
      "z": -8,
      "name": "Rock_Ice"
    },
    {
      "x": -41,
      "y": 36,
      "z": -8,
      "name": "Rock_Ice"
    },
    {
      "x": -41,
      "y": 37,
      "z": -8,
      "name": "Rock_Ice"
    },
    {
      "x": -41,
      "y": 38,
      "z": -8,
      "name": "Rock_Ice"
    },
    {
      "x": -41,
      "y": 39,
      "z": -8,
      "name": "Soil_Snow"
    },
    {
      "x": -41,
      "y": 19,
      "z": -7,
      "name": "Rock_Ice"
    },
    {
      "x": -41,
      "y": 20,
      "z": -7,
      "name": "Rock_Ice_Permafrost"
    },
    {
      "x": -41,
      "y": 21,
      "z": -7,
      "name": "Rock_Ice_Permafrost"
    },
    {
      "x": -41,
      "y": 22,
      "z": -7,
      "name": "Rock_Ice_Permafrost"
    },
    {
      "x": -41,
      "y": 23,
      "z": -7,
      "name": "Rock_Ice"
    },
    {
      "x": -41,
      "y": 24,
      "z": -7,
      "name": "Rock_Ice"
    },
    {
      "x": -41,
      "y": 25,
      "z": -7,
      "name": "Rock_Ice"
    },
    {
      "x": -41,
      "y": 26,
      "z": -7,
      "name": "Rock_Ice"
    },
    {
      "x": -41,
      "y": 27,
      "z": -7,
      "name": "Rock_Ice"
    },
    {
      "x": -41,
      "y": 28,
      "z": -7,
      "name": "Rock_Ice"
    },
    {
      "x": -41,
      "y": 29,
      "z": -7,
      "name": "Rock_Ice"
    },
    {
      "x": -41,
      "y": 30,
      "z": -7,
      "name": "Rock_Ice"
    },
    {
      "x": -41,
      "y": 31,
      "z": -7,
      "name": "Rock_Ice"
    },
    {
      "x": -41,
      "y": 32,
      "z": -7,
      "name": "Rock_Ice"
    },
    {
      "x": -41,
      "y": 33,
      "z": -7,
      "name": "Rock_Ice"
    },
    {
      "x": -41,
      "y": 34,
      "z": -7,
      "name": "Rock_Ice"
    },
    {
      "x": -41,
      "y": 35,
      "z": -7,
      "name": "Rock_Ice"
    },
    {
      "x": -41,
      "y": 36,
      "z": -7,
      "name": "Rock_Ice"
    },
    {
      "x": -41,
      "y": 37,
      "z": -7,
      "name": "Rock_Ice"
    },
    {
      "x": -41,
      "y": 38,
      "z": -7,
      "name": "Rock_Ice"
    },
    {
      "x": -41,
      "y": 39,
      "z": -7,
      "name": "Soil_Snow"
    },
    {
      "x": -41,
      "y": 20,
      "z": -6,
      "name": "Rock_Ice"
    },
    {
      "x": -41,
      "y": 21,
      "z": -6,
      "name": "Rock_Ice_Permafrost"
    },
    {
      "x": -41,
      "y": 22,
      "z": -6,
      "name": "Rock_Ice_Permafrost"
    },
    {
      "x": -41,
      "y": 23,
      "z": -6,
      "name": "Rock_Ice_Permafrost"
    },
    {
      "x": -41,
      "y": 24,
      "z": -6,
      "name": "Rock_Ice_Permafrost"
    },
    {
      "x": -41,
      "y": 25,
      "z": -6,
      "name": "Rock_Ice"
    },
    {
      "x": -41,
      "y": 26,
      "z": -6,
      "name": "Rock_Ice"
    },
    {
      "x": -41,
      "y": 27,
      "z": -6,
      "name": "Rock_Ice"
    },
    {
      "x": -41,
      "y": 28,
      "z": -6,
      "name": "Rock_Ice"
    },
    {
      "x": -41,
      "y": 29,
      "z": -6,
      "name": "Rock_Ice"
    },
    {
      "x": -41,
      "y": 30,
      "z": -6,
      "name": "Rock_Ice"
    },
    {
      "x": -41,
      "y": 31,
      "z": -6,
      "name": "Rock_Ice"
    },
    {
      "x": -41,
      "y": 32,
      "z": -6,
      "name": "Rock_Ice"
    },
    {
      "x": -41,
      "y": 33,
      "z": -6,
      "name": "Rock_Ice"
    },
    {
      "x": -41,
      "y": 34,
      "z": -6,
      "name": "Rock_Ice"
    },
    {
      "x": -41,
      "y": 35,
      "z": -6,
      "name": "Rock_Ice"
    },
    {
      "x": -41,
      "y": 36,
      "z": -6,
      "name": "Rock_Ice_Permafrost"
    },
    {
      "x": -41,
      "y": 37,
      "z": -6,
      "name": "Rock_Ice_Permafrost"
    },
    {
      "x": -41,
      "y": 38,
      "z": -6,
      "name": "Rock_Ice"
    },
    {
      "x": -41,
      "y": 39,
      "z": -6,
      "name": "Rock_Ice_Permafrost"
    },
    {
      "x": -41,
      "y": 21,
      "z": -5,
      "name": "Rock_Ice_Permafrost"
    },
    {
      "x": -41,
      "y": 22,
      "z": -5,
      "name": "Rock_Ice_Permafrost"
    },
    {
      "x": -41,
      "y": 23,
      "z": -5,
      "name": "Rock_Ice_Permafrost"
    },
    {
      "x": -41,
      "y": 24,
      "z": -5,
      "name": "Rock_Ice_Permafrost"
    },
    {
      "x": -41,
      "y": 25,
      "z": -5,
      "name": "Rock_Ice_Permafrost"
    },
    {
      "x": -41,
      "y": 26,
      "z": -5,
      "name": "Rock_Ice"
    },
    {
      "x": -41,
      "y": 27,
      "z": -5,
      "name": "Rock_Ice"
    },
    {
      "x": -41,
      "y": 28,
      "z": -5,
      "name": "Rock_Ice"
    },
    {
      "x": -41,
      "y": 29,
      "z": -5,
      "name": "Rock_Ice"
    },
    {
      "x": -41,
      "y": 30,
      "z": -5,
      "name": "Rock_Ice"
    },
    {
      "x": -41,
      "y": 31,
      "z": -5,
      "name": "Rock_Ice"
    },
    {
      "x": -41,
      "y": 32,
      "z": -5,
      "name": "Rock_Ice"
    },
    {
      "x": -41,
      "y": 33,
      "z": -5,
      "name": "Rock_Ice"
    },
    {
      "x": -41,
      "y": 34,
      "z": -5,
      "name": "Rock_Ice"
    },
    {
      "x": -41,
      "y": 35,
      "z": -5,
      "name": "Rock_Ice_Permafrost"
    },
    {
      "x": -41,
      "y": 36,
      "z": -5,
      "name": "Rock_Ice"
    },
    {
      "x": -41,
      "y": 37,
      "z": -5,
      "name": "Rock_Ice_Permafrost"
    },
    {
      "x": -41,
      "y": 38,
      "z": -5,
      "name": "Rock_Ice_Permafrost"
    },
    {
      "x": -41,
      "y": 39,
      "z": -5,
      "name": "Rock_Ice"
    },
    {
      "x": -41,
      "y": 40,
      "z": -5,
      "name": "Soil_Snow"
    },
    {
      "x": -41,
      "y": 22,
      "z": -4,
      "name": "Rock_Ice"
    },
    {
      "x": -41,
      "y": 23,
      "z": -4,
      "name": "Rock_Ice_Permafrost"
    },
    {
      "x": -41,
      "y": 24,
      "z": -4,
      "name": "Rock_Ice_Permafrost"
    },
    {
      "x": -41,
      "y": 25,
      "z": -4,
      "name": "Rock_Ice_Permafrost"
    },
    {
      "x": -41,
      "y": 26,
      "z": -4,
      "name": "Rock_Ice_Permafrost"
    },
    {
      "x": -41,
      "y": 27,
      "z": -4,
      "name": "Rock_Ice"
    },
    {
      "x": -41,
      "y": 28,
      "z": -4,
      "name": "Rock_Ice"
    },
    {
      "x": -41,
      "y": 29,
      "z": -4,
      "name": "Rock_Ice"
    },
    {
      "x": -41,
      "y": 30,
      "z": -4,
      "name": "Rock_Ice"
    },
    {
      "x": -41,
      "y": 31,
      "z": -4,
      "name": "Rock_Ice"
    },
    {
      "x": -41,
      "y": 32,
      "z": -4,
      "name": "Rock_Ice"
    },
    {
      "x": -41,
      "y": 33,
      "z": -4,
      "name": "Rock_Ice"
    },
    {
      "x": -41,
      "y": 34,
      "z": -4,
      "name": "Rock_Ice"
    },
    {
      "x": -41,
      "y": 35,
      "z": -4,
      "name": "Rock_Ice_Permafrost"
    },
    {
      "x": -41,
      "y": 36,
      "z": -4,
      "name": "Rock_Ice_Permafrost"
    },
    {
      "x": -41,
      "y": 37,
      "z": -4,
      "name": "Rock_Ice_Permafrost"
    },
    {
      "x": -41,
      "y": 38,
      "z": -4,
      "name": "Rock_Ice"
    },
    {
      "x": -41,
      "y": 39,
      "z": -4,
      "name": "Soil_Snow"
    },
    {
      "x": -41,
      "y": 23,
      "z": -3,
      "name": "Rock_Ice"
    },
    {
      "x": -41,
      "y": 24,
      "z": -3,
      "name": "Rock_Ice"
    },
    {
      "x": -41,
      "y": 25,
      "z": -3,
      "name": "Rock_Ice_Permafrost"
    },
    {
      "x": -41,
      "y": 26,
      "z": -3,
      "name": "Rock_Ice_Permafrost"
    },
    {
      "x": -41,
      "y": 27,
      "z": -3,
      "name": "Rock_Ice_Permafrost"
    },
    {
      "x": -41,
      "y": 28,
      "z": -3,
      "name": "Rock_Ice_Permafrost"
    },
    {
      "x": -41,
      "y": 29,
      "z": -3,
      "name": "Rock_Ice_Permafrost"
    },
    {
      "x": -41,
      "y": 30,
      "z": -3,
      "name": "Rock_Ice"
    },
    {
      "x": -41,
      "y": 31,
      "z": -3,
      "name": "Rock_Ice_Permafrost"
    },
    {
      "x": -41,
      "y": 32,
      "z": -3,
      "name": "Rock_Ice_Permafrost"
    },
    {
      "x": -41,
      "y": 33,
      "z": -3,
      "name": "Rock_Ice_Permafrost"
    },
    {
      "x": -41,
      "y": 34,
      "z": -3,
      "name": "Rock_Ice_Permafrost"
    },
    {
      "x": -41,
      "y": 35,
      "z": -3,
      "name": "Rock_Ice_Permafrost"
    },
    {
      "x": -41,
      "y": 36,
      "z": -3,
      "name": "Rock_Ice_Permafrost"
    },
    {
      "x": -41,
      "y": 37,
      "z": -3,
      "name": "Rock_Ice"
    },
    {
      "x": -41,
      "y": 38,
      "z": -3,
      "name": "Soil_Snow"
    },
    {
      "x": -41,
      "y": 24,
      "z": -2,
      "name": "Rock_Ice"
    },
    {
      "x": -41,
      "y": 25,
      "z": -2,
      "name": "Rock_Ice_Permafrost"
    },
    {
      "x": -41,
      "y": 26,
      "z": -2,
      "name": "Rock_Ice_Permafrost"
    },
    {
      "x": -41,
      "y": 27,
      "z": -2,
      "name": "Rock_Ice_Permafrost"
    },
    {
      "x": -41,
      "y": 28,
      "z": -2,
      "name": "Rock_Ice_Permafrost"
    },
    {
      "x": -41,
      "y": 29,
      "z": -2,
      "name": "Rock_Ice_Permafrost"
    },
    {
      "x": -41,
      "y": 30,
      "z": -2,
      "name": "Rock_Ice_Permafrost"
    },
    {
      "x": -41,
      "y": 31,
      "z": -2,
      "name": "Rock_Ice_Permafrost"
    },
    {
      "x": -41,
      "y": 32,
      "z": -2,
      "name": "Rock_Ice_Permafrost"
    },
    {
      "x": -41,
      "y": 33,
      "z": -2,
      "name": "Rock_Ice_Permafrost"
    },
    {
      "x": -41,
      "y": 34,
      "z": -2,
      "name": "Rock_Ice_Permafrost"
    },
    {
      "x": -41,
      "y": 35,
      "z": -2,
      "name": "Rock_Ice_Permafrost"
    },
    {
      "x": -41,
      "y": 36,
      "z": -2,
      "name": "Rock_Ice"
    },
    {
      "x": -41,
      "y": 37,
      "z": -2,
      "name": "Soil_Snow"
    },
    {
      "x": -41,
      "y": 25,
      "z": -1,
      "name": "Rock_Ice"
    },
    {
      "x": -41,
      "y": 26,
      "z": -1,
      "name": "Rock_Ice"
    },
    {
      "x": -41,
      "y": 27,
      "z": -1,
      "name": "Rock_Ice_Permafrost"
    },
    {
      "x": -41,
      "y": 28,
      "z": -1,
      "name": "Rock_Ice_Permafrost"
    },
    {
      "x": -41,
      "y": 29,
      "z": -1,
      "name": "Rock_Ice_Permafrost"
    },
    {
      "x": -41,
      "y": 30,
      "z": -1,
      "name": "Rock_Ice_Permafrost"
    },
    {
      "x": -41,
      "y": 31,
      "z": -1,
      "name": "Rock_Ice_Permafrost"
    },
    {
      "x": -41,
      "y": 32,
      "z": -1,
      "name": "Rock_Ice_Permafrost"
    },
    {
      "x": -41,
      "y": 33,
      "z": -1,
      "name": "Rock_Ice_Permafrost"
    },
    {
      "x": -41,
      "y": 34,
      "z": -1,
      "name": "Rock_Ice_Permafrost"
    },
    {
      "x": -41,
      "y": 35,
      "z": -1,
      "name": "Rock_Ice"
    },
    {
      "x": -41,
      "y": 36,
      "z": -1,
      "name": "Soil_Snow"
    },
    {
      "x": -41,
      "y": 26,
      "z": 0,
      "name": "Rock_Ice"
    },
    {
      "x": -41,
      "y": 27,
      "z": 0,
      "name": "Rock_Ice"
    },
    {
      "x": -41,
      "y": 28,
      "z": 0,
      "name": "Rock_Ice_Permafrost"
    },
    {
      "x": -41,
      "y": 29,
      "z": 0,
      "name": "Rock_Ice"
    },
    {
      "x": -41,
      "y": 30,
      "z": 0,
      "name": "Rock_Ice_Permafrost"
    },
    {
      "x": -41,
      "y": 31,
      "z": 0,
      "name": "Rock_Ice"
    },
    {
      "x": -41,
      "y": 32,
      "z": 0,
      "name": "Rock_Ice"
    },
    {
      "x": -41,
      "y": 33,
      "z": 0,
      "name": "Rock_Ice"
    },
    {
      "x": -41,
      "y": 34,
      "z": 0,
      "name": "Rock_Ice"
    },
    {
      "x": -41,
      "y": 35,
      "z": 0,
      "name": "Rock_Ice"
    },
    {
      "x": -41,
      "y": 36,
      "z": 0,
      "name": "Soil_Snow"
    },
    {
      "x": -41,
      "y": 27,
      "z": 1,
      "name": "Rock_Ice"
    },
    {
      "x": -41,
      "y": 28,
      "z": 1,
      "name": "Rock_Ice"
    },
    {
      "x": -41,
      "y": 29,
      "z": 1,
      "name": "Rock_Ice"
    },
    {
      "x": -41,
      "y": 30,
      "z": 1,
      "name": "Rock_Ice"
    },
    {
      "x": -41,
      "y": 31,
      "z": 1,
      "name": "Rock_Ice"
    },
    {
      "x": -41,
      "y": 32,
      "z": 1,
      "name": "Rock_Ice"
    },
    {
      "x": -41,
      "y": 33,
      "z": 1,
      "name": "Rock_Ice"
    },
    {
      "x": -41,
      "y": 34,
      "z": 1,
      "name": "Rock_Ice"
    },
    {
      "x": -41,
      "y": 28,
      "z": 2,
      "name": "Rock_Ice"
    },
    {
      "x": -41,
      "y": 29,
      "z": 2,
      "name": "Rock_Ice"
    },
    {
      "x": -41,
      "y": 30,
      "z": 2,
      "name": "Rock_Ice"
    },
    {
      "x": -41,
      "y": 31,
      "z": 2,
      "name": "Rock_Ice"
    },
    {
      "x": -41,
      "y": 32,
      "z": 2,
      "name": "Soil_Snow"
    },
    {
      "x": -40,
      "y": 15,
      "z": -21,
      "name": "Rock_Ice"
    },
    {
      "x": -40,
      "y": 16,
      "z": -21,
      "name": "Rock_Ice"
    },
    {
      "x": -40,
      "y": 17,
      "z": -21,
      "name": "Soil_Snow"
    },
    {
      "x": -40,
      "y": 15,
      "z": -20,
      "name": "Rock_Ice_Permafrost"
    },
    {
      "x": -40,
      "y": 16,
      "z": -20,
      "name": "Rock_Ice"
    },
    {
      "x": -40,
      "y": 17,
      "z": -20,
      "name": "Rock_Ice"
    },
    {
      "x": -40,
      "y": 18,
      "z": -20,
      "name": "Soil_Snow"
    },
    {
      "x": -40,
      "y": 15,
      "z": -19,
      "name": "Rock_Ice_Permafrost"
    },
    {
      "x": -40,
      "y": 16,
      "z": -19,
      "name": "Rock_Ice"
    },
    {
      "x": -40,
      "y": 17,
      "z": -19,
      "name": "Rock_Ice"
    },
    {
      "x": -40,
      "y": 18,
      "z": -19,
      "name": "Rock_Ice"
    },
    {
      "x": -40,
      "y": 19,
      "z": -19,
      "name": "Soil_Snow"
    },
    {
      "x": -40,
      "y": 15,
      "z": -18,
      "name": "Rock_Ice_Permafrost"
    },
    {
      "x": -40,
      "y": 16,
      "z": -18,
      "name": "Rock_Ice_Permafrost"
    },
    {
      "x": -40,
      "y": 17,
      "z": -18,
      "name": "Rock_Ice"
    },
    {
      "x": -40,
      "y": 18,
      "z": -18,
      "name": "Rock_Ice"
    },
    {
      "x": -40,
      "y": 19,
      "z": -18,
      "name": "Rock_Ice"
    },
    {
      "x": -40,
      "y": 20,
      "z": -18,
      "name": "Soil_Snow"
    },
    {
      "x": -40,
      "y": 15,
      "z": -17,
      "name": "Rock_Ice_Permafrost"
    },
    {
      "x": -40,
      "y": 16,
      "z": -17,
      "name": "Rock_Ice"
    },
    {
      "x": -40,
      "y": 17,
      "z": -17,
      "name": "Rock_Ice"
    },
    {
      "x": -40,
      "y": 18,
      "z": -17,
      "name": "Rock_Ice"
    },
    {
      "x": -40,
      "y": 19,
      "z": -17,
      "name": "Rock_Ice"
    },
    {
      "x": -40,
      "y": 20,
      "z": -17,
      "name": "Rock_Ice"
    },
    {
      "x": -40,
      "y": 21,
      "z": -17,
      "name": "Soil_Snow"
    },
    {
      "x": -40,
      "y": 15,
      "z": -16,
      "name": "Rock_Ice_Permafrost"
    },
    {
      "x": -40,
      "y": 16,
      "z": -16,
      "name": "Rock_Ice"
    },
    {
      "x": -40,
      "y": 17,
      "z": -16,
      "name": "Rock_Ice"
    },
    {
      "x": -40,
      "y": 18,
      "z": -16,
      "name": "Rock_Ice"
    },
    {
      "x": -40,
      "y": 19,
      "z": -16,
      "name": "Rock_Ice"
    },
    {
      "x": -40,
      "y": 20,
      "z": -16,
      "name": "Rock_Ice"
    },
    {
      "x": -40,
      "y": 21,
      "z": -16,
      "name": "Soil_Snow"
    },
    {
      "x": -40,
      "y": 15,
      "z": -15,
      "name": "Rock_Ice_Permafrost"
    },
    {
      "x": -40,
      "y": 16,
      "z": -15,
      "name": "Rock_Ice_Permafrost"
    },
    {
      "x": -40,
      "y": 17,
      "z": -15,
      "name": "Rock_Ice_Permafrost"
    },
    {
      "x": -40,
      "y": 18,
      "z": -15,
      "name": "Rock_Ice"
    },
    {
      "x": -40,
      "y": 19,
      "z": -15,
      "name": "Rock_Ice"
    },
    {
      "x": -40,
      "y": 20,
      "z": -15,
      "name": "Rock_Ice"
    },
    {
      "x": -40,
      "y": 21,
      "z": -15,
      "name": "Rock_Ice"
    },
    {
      "x": -40,
      "y": 22,
      "z": -15,
      "name": "Soil_Snow"
    },
    {
      "x": -40,
      "y": 16,
      "z": -14,
      "name": "Rock_Ice_Permafrost"
    },
    {
      "x": -40,
      "y": 17,
      "z": -14,
      "name": "Rock_Ice_Permafrost"
    },
    {
      "x": -40,
      "y": 18,
      "z": -14,
      "name": "Rock_Ice_Permafrost"
    },
    {
      "x": -40,
      "y": 19,
      "z": -14,
      "name": "Rock_Ice"
    },
    {
      "x": -40,
      "y": 20,
      "z": -14,
      "name": "Rock_Ice"
    },
    {
      "x": -40,
      "y": 21,
      "z": -14,
      "name": "Rock_Ice"
    },
    {
      "x": -40,
      "y": 22,
      "z": -14,
      "name": "Rock_Ice"
    },
    {
      "x": -40,
      "y": 23,
      "z": -14,
      "name": "Rock_Ice"
    },
    {
      "x": -40,
      "y": 24,
      "z": -14,
      "name": "Soil_Snow"
    },
    {
      "x": -40,
      "y": 16,
      "z": -13,
      "name": "Rock_Ice"
    },
    {
      "x": -40,
      "y": 17,
      "z": -13,
      "name": "Rock_Ice_Permafrost"
    },
    {
      "x": -40,
      "y": 18,
      "z": -13,
      "name": "Rock_Ice_Permafrost"
    },
    {
      "x": -40,
      "y": 19,
      "z": -13,
      "name": "Rock_Ice"
    },
    {
      "x": -40,
      "y": 20,
      "z": -13,
      "name": "Rock_Ice"
    },
    {
      "x": -40,
      "y": 21,
      "z": -13,
      "name": "Rock_Ice"
    },
    {
      "x": -40,
      "y": 22,
      "z": -13,
      "name": "Rock_Ice"
    },
    {
      "x": -40,
      "y": 23,
      "z": -13,
      "name": "Rock_Ice"
    },
    {
      "x": -40,
      "y": 24,
      "z": -13,
      "name": "Rock_Ice"
    },
    {
      "x": -40,
      "y": 25,
      "z": -13,
      "name": "Rock_Ice"
    },
    {
      "x": -40,
      "y": 26,
      "z": -13,
      "name": "Rock_Ice"
    },
    {
      "x": -40,
      "y": 27,
      "z": -13,
      "name": "Rock_Ice"
    },
    {
      "x": -40,
      "y": 28,
      "z": -13,
      "name": "Rock_Ice"
    },
    {
      "x": -40,
      "y": 29,
      "z": -13,
      "name": "Rock_Ice"
    },
    {
      "x": -40,
      "y": 30,
      "z": -13,
      "name": "Soil_Snow"
    },
    {
      "x": -40,
      "y": 16,
      "z": -12,
      "name": "Rock_Ice_Permafrost"
    },
    {
      "x": -40,
      "y": 17,
      "z": -12,
      "name": "Rock_Ice_Permafrost"
    },
    {
      "x": -40,
      "y": 18,
      "z": -12,
      "name": "Rock_Ice"
    },
    {
      "x": -40,
      "y": 19,
      "z": -12,
      "name": "Rock_Ice_Permafrost"
    },
    {
      "x": -40,
      "y": 20,
      "z": -12,
      "name": "Rock_Ice"
    },
    {
      "x": -40,
      "y": 21,
      "z": -12,
      "name": "Rock_Ice"
    },
    {
      "x": -40,
      "y": 22,
      "z": -12,
      "name": "Rock_Ice"
    },
    {
      "x": -40,
      "y": 23,
      "z": -12,
      "name": "Rock_Ice"
    },
    {
      "x": -40,
      "y": 24,
      "z": -12,
      "name": "Rock_Ice"
    },
    {
      "x": -40,
      "y": 25,
      "z": -12,
      "name": "Rock_Ice"
    },
    {
      "x": -40,
      "y": 26,
      "z": -12,
      "name": "Rock_Ice"
    },
    {
      "x": -40,
      "y": 27,
      "z": -12,
      "name": "Rock_Ice"
    },
    {
      "x": -40,
      "y": 28,
      "z": -12,
      "name": "Rock_Ice"
    },
    {
      "x": -40,
      "y": 29,
      "z": -12,
      "name": "Rock_Ice"
    },
    {
      "x": -40,
      "y": 30,
      "z": -12,
      "name": "Rock_Ice"
    },
    {
      "x": -40,
      "y": 31,
      "z": -12,
      "name": "Soil_Snow"
    },
    {
      "x": -40,
      "y": 17,
      "z": -11,
      "name": "Rock_Ice"
    },
    {
      "x": -40,
      "y": 18,
      "z": -11,
      "name": "Rock_Ice_Permafrost"
    },
    {
      "x": -40,
      "y": 19,
      "z": -11,
      "name": "Rock_Ice"
    },
    {
      "x": -40,
      "y": 20,
      "z": -11,
      "name": "Rock_Ice_Permafrost"
    },
    {
      "x": -40,
      "y": 21,
      "z": -11,
      "name": "Rock_Ice"
    },
    {
      "x": -40,
      "y": 22,
      "z": -11,
      "name": "Rock_Ice"
    },
    {
      "x": -40,
      "y": 23,
      "z": -11,
      "name": "Rock_Ice"
    },
    {
      "x": -40,
      "y": 24,
      "z": -11,
      "name": "Rock_Ice"
    },
    {
      "x": -40,
      "y": 25,
      "z": -11,
      "name": "Rock_Ice"
    },
    {
      "x": -40,
      "y": 26,
      "z": -11,
      "name": "Rock_Ice"
    },
    {
      "x": -40,
      "y": 27,
      "z": -11,
      "name": "Rock_Ice"
    },
    {
      "x": -40,
      "y": 28,
      "z": -11,
      "name": "Rock_Ice"
    },
    {
      "x": -40,
      "y": 29,
      "z": -11,
      "name": "Rock_Ice"
    },
    {
      "x": -40,
      "y": 30,
      "z": -11,
      "name": "Rock_Ice"
    },
    {
      "x": -40,
      "y": 31,
      "z": -11,
      "name": "Rock_Ice"
    },
    {
      "x": -40,
      "y": 32,
      "z": -11,
      "name": "Soil_Snow"
    },
    {
      "x": -40,
      "y": 17,
      "z": -10,
      "name": "Rock_Ice_Permafrost"
    },
    {
      "x": -40,
      "y": 18,
      "z": -10,
      "name": "Rock_Ice_Permafrost"
    },
    {
      "x": -40,
      "y": 19,
      "z": -10,
      "name": "Rock_Ice_Permafrost"
    },
    {
      "x": -40,
      "y": 20,
      "z": -10,
      "name": "Rock_Ice_Permafrost"
    },
    {
      "x": -40,
      "y": 21,
      "z": -10,
      "name": "Rock_Ice_Permafrost"
    },
    {
      "x": -40,
      "y": 22,
      "z": -10,
      "name": "Rock_Ice"
    },
    {
      "x": -40,
      "y": 23,
      "z": -10,
      "name": "Rock_Ice"
    },
    {
      "x": -40,
      "y": 24,
      "z": -10,
      "name": "Rock_Ice"
    },
    {
      "x": -40,
      "y": 25,
      "z": -10,
      "name": "Rock_Ice"
    },
    {
      "x": -40,
      "y": 26,
      "z": -10,
      "name": "Rock_Ice"
    },
    {
      "x": -40,
      "y": 27,
      "z": -10,
      "name": "Rock_Ice"
    },
    {
      "x": -40,
      "y": 28,
      "z": -10,
      "name": "Rock_Ice"
    },
    {
      "x": -40,
      "y": 29,
      "z": -10,
      "name": "Rock_Ice"
    },
    {
      "x": -40,
      "y": 30,
      "z": -10,
      "name": "Rock_Ice"
    },
    {
      "x": -40,
      "y": 31,
      "z": -10,
      "name": "Rock_Ice"
    },
    {
      "x": -40,
      "y": 32,
      "z": -10,
      "name": "Rock_Ice"
    },
    {
      "x": -40,
      "y": 33,
      "z": -10,
      "name": "Rock_Ice"
    },
    {
      "x": -40,
      "y": 34,
      "z": -10,
      "name": "Rock_Ice"
    },
    {
      "x": -40,
      "y": 35,
      "z": -10,
      "name": "Soil_Snow"
    },
    {
      "x": -40,
      "y": 18,
      "z": -9,
      "name": "Rock_Ice_Permafrost"
    },
    {
      "x": -40,
      "y": 19,
      "z": -9,
      "name": "Rock_Ice_Permafrost"
    },
    {
      "x": -40,
      "y": 20,
      "z": -9,
      "name": "Rock_Ice_Permafrost"
    },
    {
      "x": -40,
      "y": 21,
      "z": -9,
      "name": "Rock_Ice_Permafrost"
    },
    {
      "x": -40,
      "y": 22,
      "z": -9,
      "name": "Rock_Ice"
    },
    {
      "x": -40,
      "y": 23,
      "z": -9,
      "name": "Rock_Ice"
    },
    {
      "x": -40,
      "y": 24,
      "z": -9,
      "name": "Rock_Ice"
    },
    {
      "x": -40,
      "y": 25,
      "z": -9,
      "name": "Rock_Ice"
    },
    {
      "x": -40,
      "y": 26,
      "z": -9,
      "name": "Rock_Ice"
    },
    {
      "x": -40,
      "y": 27,
      "z": -9,
      "name": "Rock_Ice"
    },
    {
      "x": -40,
      "y": 28,
      "z": -9,
      "name": "Rock_Ice"
    },
    {
      "x": -40,
      "y": 29,
      "z": -9,
      "name": "Rock_Ice"
    },
    {
      "x": -40,
      "y": 30,
      "z": -9,
      "name": "Rock_Ice"
    },
    {
      "x": -40,
      "y": 31,
      "z": -9,
      "name": "Rock_Ice"
    },
    {
      "x": -40,
      "y": 32,
      "z": -9,
      "name": "Rock_Ice"
    },
    {
      "x": -40,
      "y": 33,
      "z": -9,
      "name": "Rock_Ice"
    },
    {
      "x": -40,
      "y": 34,
      "z": -9,
      "name": "Rock_Ice"
    },
    {
      "x": -40,
      "y": 35,
      "z": -9,
      "name": "Rock_Ice"
    },
    {
      "x": -40,
      "y": 36,
      "z": -9,
      "name": "Rock_Ice"
    },
    {
      "x": -40,
      "y": 37,
      "z": -9,
      "name": "Rock_Ice"
    },
    {
      "x": -40,
      "y": 38,
      "z": -9,
      "name": "Rock_Ice"
    },
    {
      "x": -40,
      "y": 39,
      "z": -9,
      "name": "Soil_Snow"
    },
    {
      "x": -40,
      "y": 18,
      "z": -8,
      "name": "Rock_Ice"
    },
    {
      "x": -40,
      "y": 19,
      "z": -8,
      "name": "Rock_Ice"
    },
    {
      "x": -40,
      "y": 20,
      "z": -8,
      "name": "Rock_Ice_Permafrost"
    },
    {
      "x": -40,
      "y": 21,
      "z": -8,
      "name": "Rock_Ice_Permafrost"
    },
    {
      "x": -40,
      "y": 22,
      "z": -8,
      "name": "Rock_Ice_Permafrost"
    },
    {
      "x": -40,
      "y": 23,
      "z": -8,
      "name": "Rock_Ice"
    },
    {
      "x": -40,
      "y": 24,
      "z": -8,
      "name": "Rock_Ice"
    },
    {
      "x": -40,
      "y": 25,
      "z": -8,
      "name": "Rock_Ice"
    },
    {
      "x": -40,
      "y": 26,
      "z": -8,
      "name": "Rock_Ice"
    },
    {
      "x": -40,
      "y": 27,
      "z": -8,
      "name": "Rock_Ice"
    },
    {
      "x": -40,
      "y": 28,
      "z": -8,
      "name": "Rock_Ice"
    },
    {
      "x": -40,
      "y": 29,
      "z": -8,
      "name": "Rock_Ice"
    },
    {
      "x": -40,
      "y": 30,
      "z": -8,
      "name": "Rock_Ice"
    },
    {
      "x": -40,
      "y": 31,
      "z": -8,
      "name": "Rock_Ice"
    },
    {
      "x": -40,
      "y": 32,
      "z": -8,
      "name": "Rock_Ice"
    },
    {
      "x": -40,
      "y": 33,
      "z": -8,
      "name": "Rock_Ice"
    },
    {
      "x": -40,
      "y": 34,
      "z": -8,
      "name": "Rock_Ice"
    },
    {
      "x": -40,
      "y": 35,
      "z": -8,
      "name": "Rock_Ice"
    },
    {
      "x": -40,
      "y": 36,
      "z": -8,
      "name": "Rock_Ice"
    },
    {
      "x": -40,
      "y": 37,
      "z": -8,
      "name": "Rock_Ice"
    },
    {
      "x": -40,
      "y": 38,
      "z": -8,
      "name": "Rock_Ice"
    },
    {
      "x": -40,
      "y": 39,
      "z": -8,
      "name": "Soil_Snow"
    },
    {
      "x": -40,
      "y": 19,
      "z": -7,
      "name": "Rock_Ice"
    },
    {
      "x": -40,
      "y": 20,
      "z": -7,
      "name": "Rock_Ice_Permafrost"
    },
    {
      "x": -40,
      "y": 21,
      "z": -7,
      "name": "Rock_Ice_Permafrost"
    },
    {
      "x": -40,
      "y": 22,
      "z": -7,
      "name": "Rock_Ice_Permafrost"
    },
    {
      "x": -40,
      "y": 23,
      "z": -7,
      "name": "Rock_Ice"
    },
    {
      "x": -40,
      "y": 24,
      "z": -7,
      "name": "Rock_Ice"
    },
    {
      "x": -40,
      "y": 25,
      "z": -7,
      "name": "Rock_Ice"
    },
    {
      "x": -40,
      "y": 26,
      "z": -7,
      "name": "Rock_Ice"
    },
    {
      "x": -40,
      "y": 27,
      "z": -7,
      "name": "Rock_Ice"
    },
    {
      "x": -40,
      "y": 28,
      "z": -7,
      "name": "Rock_Ice"
    },
    {
      "x": -40,
      "y": 29,
      "z": -7,
      "name": "Rock_Ice"
    },
    {
      "x": -40,
      "y": 30,
      "z": -7,
      "name": "Rock_Ice"
    },
    {
      "x": -40,
      "y": 31,
      "z": -7,
      "name": "Rock_Ice"
    },
    {
      "x": -40,
      "y": 32,
      "z": -7,
      "name": "Rock_Ice"
    },
    {
      "x": -40,
      "y": 33,
      "z": -7,
      "name": "Rock_Ice"
    },
    {
      "x": -40,
      "y": 34,
      "z": -7,
      "name": "Rock_Ice"
    },
    {
      "x": -40,
      "y": 35,
      "z": -7,
      "name": "Rock_Ice"
    },
    {
      "x": -40,
      "y": 36,
      "z": -7,
      "name": "Rock_Ice"
    },
    {
      "x": -40,
      "y": 37,
      "z": -7,
      "name": "Rock_Ice"
    },
    {
      "x": -40,
      "y": 38,
      "z": -7,
      "name": "Rock_Ice_Permafrost"
    },
    {
      "x": -40,
      "y": 39,
      "z": -7,
      "name": "Rock_Ice"
    },
    {
      "x": -40,
      "y": 40,
      "z": -7,
      "name": "Rock_Ice_Permafrost"
    },
    {
      "x": -40,
      "y": 20,
      "z": -6,
      "name": "Rock_Ice"
    },
    {
      "x": -40,
      "y": 21,
      "z": -6,
      "name": "Rock_Ice_Permafrost"
    },
    {
      "x": -40,
      "y": 22,
      "z": -6,
      "name": "Rock_Ice_Permafrost"
    },
    {
      "x": -40,
      "y": 23,
      "z": -6,
      "name": "Rock_Ice_Permafrost"
    },
    {
      "x": -40,
      "y": 24,
      "z": -6,
      "name": "Rock_Ice"
    },
    {
      "x": -40,
      "y": 25,
      "z": -6,
      "name": "Rock_Ice"
    },
    {
      "x": -40,
      "y": 26,
      "z": -6,
      "name": "Rock_Ice"
    },
    {
      "x": -40,
      "y": 27,
      "z": -6,
      "name": "Rock_Ice"
    },
    {
      "x": -40,
      "y": 28,
      "z": -6,
      "name": "Rock_Ice"
    },
    {
      "x": -40,
      "y": 29,
      "z": -6,
      "name": "Rock_Ice"
    },
    {
      "x": -40,
      "y": 30,
      "z": -6,
      "name": "Rock_Ice"
    },
    {
      "x": -40,
      "y": 31,
      "z": -6,
      "name": "Rock_Ice"
    },
    {
      "x": -40,
      "y": 32,
      "z": -6,
      "name": "Rock_Ice"
    },
    {
      "x": -40,
      "y": 33,
      "z": -6,
      "name": "Rock_Ice"
    },
    {
      "x": -40,
      "y": 34,
      "z": -6,
      "name": "Rock_Ice"
    },
    {
      "x": -40,
      "y": 35,
      "z": -6,
      "name": "Rock_Ice"
    },
    {
      "x": -40,
      "y": 36,
      "z": -6,
      "name": "Rock_Ice"
    },
    {
      "x": -40,
      "y": 37,
      "z": -6,
      "name": "Rock_Ice_Permafrost"
    },
    {
      "x": -40,
      "y": 38,
      "z": -6,
      "name": "Rock_Ice_Permafrost"
    },
    {
      "x": -40,
      "y": 39,
      "z": -6,
      "name": "Rock_Ice_Permafrost"
    },
    {
      "x": -40,
      "y": 40,
      "z": -6,
      "name": "Rock_Ice"
    },
    {
      "x": -40,
      "y": 41,
      "z": -6,
      "name": "Soil_Snow"
    },
    {
      "x": -40,
      "y": 20,
      "z": -5,
      "name": "Rock_Ice"
    },
    {
      "x": -40,
      "y": 21,
      "z": -5,
      "name": "Rock_Ice_Permafrost"
    },
    {
      "x": -40,
      "y": 22,
      "z": -5,
      "name": "Rock_Ice_Permafrost"
    },
    {
      "x": -40,
      "y": 23,
      "z": -5,
      "name": "Rock_Ice_Permafrost"
    },
    {
      "x": -40,
      "y": 24,
      "z": -5,
      "name": "Rock_Ice_Permafrost"
    },
    {
      "x": -40,
      "y": 25,
      "z": -5,
      "name": "Rock_Ice"
    },
    {
      "x": -40,
      "y": 26,
      "z": -5,
      "name": "Rock_Ice"
    },
    {
      "x": -40,
      "y": 27,
      "z": -5,
      "name": "Rock_Ice"
    },
    {
      "x": -40,
      "y": 28,
      "z": -5,
      "name": "Rock_Ice"
    },
    {
      "x": -40,
      "y": 29,
      "z": -5,
      "name": "Rock_Ice"
    },
    {
      "x": -40,
      "y": 30,
      "z": -5,
      "name": "Rock_Ice"
    },
    {
      "x": -40,
      "y": 31,
      "z": -5,
      "name": "Rock_Ice"
    },
    {
      "x": -40,
      "y": 32,
      "z": -5,
      "name": "Rock_Ice"
    },
    {
      "x": -40,
      "y": 33,
      "z": -5,
      "name": "Rock_Ice"
    },
    {
      "x": -40,
      "y": 34,
      "z": -5,
      "name": "Rock_Ice"
    },
    {
      "x": -40,
      "y": 35,
      "z": -5,
      "name": "Rock_Ice"
    },
    {
      "x": -40,
      "y": 36,
      "z": -5,
      "name": "Rock_Ice"
    },
    {
      "x": -40,
      "y": 37,
      "z": -5,
      "name": "Rock_Ice_Permafrost"
    },
    {
      "x": -40,
      "y": 38,
      "z": -5,
      "name": "Rock_Ice_Permafrost"
    },
    {
      "x": -40,
      "y": 39,
      "z": -5,
      "name": "Rock_Ice"
    },
    {
      "x": -40,
      "y": 40,
      "z": -5,
      "name": "Soil_Snow"
    },
    {
      "x": -40,
      "y": 21,
      "z": -4,
      "name": "Rock_Ice"
    },
    {
      "x": -40,
      "y": 22,
      "z": -4,
      "name": "Rock_Ice"
    },
    {
      "x": -40,
      "y": 23,
      "z": -4,
      "name": "Rock_Ice_Permafrost"
    },
    {
      "x": -40,
      "y": 24,
      "z": -4,
      "name": "Rock_Ice_Permafrost"
    },
    {
      "x": -40,
      "y": 25,
      "z": -4,
      "name": "Rock_Ice_Permafrost"
    },
    {
      "x": -40,
      "y": 26,
      "z": -4,
      "name": "Rock_Ice_Permafrost"
    },
    {
      "x": -40,
      "y": 27,
      "z": -4,
      "name": "Rock_Ice"
    },
    {
      "x": -40,
      "y": 28,
      "z": -4,
      "name": "Rock_Ice"
    },
    {
      "x": -40,
      "y": 29,
      "z": -4,
      "name": "Rock_Ice"
    },
    {
      "x": -40,
      "y": 30,
      "z": -4,
      "name": "Rock_Ice"
    },
    {
      "x": -40,
      "y": 31,
      "z": -4,
      "name": "Rock_Ice"
    },
    {
      "x": -40,
      "y": 32,
      "z": -4,
      "name": "Rock_Ice"
    },
    {
      "x": -40,
      "y": 33,
      "z": -4,
      "name": "Rock_Ice"
    },
    {
      "x": -40,
      "y": 34,
      "z": -4,
      "name": "Rock_Ice"
    },
    {
      "x": -40,
      "y": 35,
      "z": -4,
      "name": "Rock_Ice_Permafrost"
    },
    {
      "x": -40,
      "y": 36,
      "z": -4,
      "name": "Rock_Ice_Permafrost"
    },
    {
      "x": -40,
      "y": 37,
      "z": -4,
      "name": "Rock_Ice_Permafrost"
    },
    {
      "x": -40,
      "y": 38,
      "z": -4,
      "name": "Rock_Ice"
    },
    {
      "x": -40,
      "y": 39,
      "z": -4,
      "name": "Soil_Snow"
    },
    {
      "x": -40,
      "y": 22,
      "z": -3,
      "name": "Rock_Ice"
    },
    {
      "x": -40,
      "y": 23,
      "z": -3,
      "name": "Rock_Ice"
    },
    {
      "x": -40,
      "y": 24,
      "z": -3,
      "name": "Rock_Ice_Permafrost"
    },
    {
      "x": -40,
      "y": 25,
      "z": -3,
      "name": "Rock_Ice_Permafrost"
    },
    {
      "x": -40,
      "y": 26,
      "z": -3,
      "name": "Rock_Ice_Permafrost"
    },
    {
      "x": -40,
      "y": 27,
