{
  "version": 8,
  "blockIdVersion": 11,
  "anchorX": 0,
  "anchorY": 66,
  "anchorZ": 7,
  "blocks": [
    {
      "x": -40,
      "y": 44,
      "z": -27,
      "name": "Rock_Ice"
    },
    {
      "x": -40,
      "y": 44,
      "z": -26,
      "name": "Rock_Ice"
    },
    {
      "x": -40,
      "y": 45,
      "z": -26,
      "name": "Soil_Snow"
    },
    {
      "x": -40,
      "y": 44,
      "z": -25,
      "name": "Rock_Ice"
    },
    {
      "x": -40,
      "y": 45,
      "z": -25,
      "name": "Rock_Ice"
    },
    {
      "x": -40,
      "y": 46,
      "z": -25,
      "name": "Soil_Snow"
    },
    {
      "x": -40,
      "y": 44,
      "z": -24,
      "name": "Rock_Ice"
    },
    {
      "x": -40,
      "y": 45,
      "z": -24,
      "name": "Rock_Ice"
    },
    {
      "x": -40,
      "y": 46,
      "z": -24,
      "name": "Soil_Snow"
    },
    {
      "x": -39,
      "y": 44,
      "z": -29,
      "name": "Soil_Snow"
    },
    {
      "x": -39,
      "y": 44,
      "z": -28,
      "name": "Rock_Ice"
    },
    {
      "x": -39,
      "y": 45,
      "z": -28,
      "name": "Soil_Snow"
    },
    {
      "x": -39,
      "y": 44,
      "z": -27,
      "name": "Rock_Ice"
    },
    {
      "x": -39,
      "y": 45,
      "z": -27,
      "name": "Rock_Ice_Permafrost"
    },
    {
      "x": -39,
      "y": 46,
      "z": -27,
      "name": "Rock_Ice"
    },
    {
      "x": -39,
      "y": 47,
      "z": -27,
      "name": "Soil_Snow"
    },
    {
      "x": -39,
      "y": 44,
      "z": -26,
      "name": "Rock_Ice"
    },
    {
      "x": -39,
      "y": 45,
      "z": -26,
      "name": "Rock_Ice_Permafrost"
    },
    {
      "x": -39,
      "y": 46,
      "z": -26,
      "name": "Rock_Ice"
    },
    {
      "x": -39,
      "y": 47,
      "z": -26,
      "name": "Rock_Ice"
    },
    {
      "x": -39,
      "y": 48,
      "z": -26,
      "name": "Soil_Snow"
    },
    {
      "x": -39,
      "y": 44,
      "z": -25,
      "name": "Rock_Ice"
    },
    {
      "x": -39,
      "y": 45,
      "z": -25,
      "name": "Rock_Ice"
    },
    {
      "x": -39,
      "y": 46,
      "z": -25,
      "name": "Rock_Ice"
    },
    {
      "x": -39,
      "y": 47,
      "z": -25,
      "name": "Rock_Ice"
    },
    {
      "x": -39,
      "y": 48,
      "z": -25,
      "name": "Soil_Snow"
    },
    {
      "x": -39,
      "y": 44,
      "z": -24,
      "name": "Rock_Ice"
    },
    {
      "x": -39,
      "y": 45,
      "z": -24,
      "name": "Rock_Ice"
    },
    {
      "x": -39,
      "y": 46,
      "z": -24,
      "name": "Rock_Ice"
    },
    {
      "x": -39,
      "y": 47,
      "z": -24,
      "name": "Rock_Ice"
    },
    {
      "x": -39,
      "y": 48,
      "z": -24,
      "name": "Rock_Ice"
    },
    {
      "x": -39,
      "y": 49,
      "z": -24,
      "name": "Soil_Snow"
    },
    {
      "x": -39,
      "y": 44,
      "z": -23,
      "name": "Rock_Ice"
    },
    {
      "x": -39,
      "y": 45,
      "z": -23,
      "name": "Rock_Ice"
    },
    {
      "x": -39,
      "y": 46,
      "z": -23,
      "name": "Rock_Ice"
    },
    {
      "x": -39,
      "y": 47,
      "z": -23,
      "name": "Rock_Ice"
    },
    {
      "x": -39,
      "y": 48,
      "z": -23,
      "name": "Rock_Ice"
    },
    {
      "x": -39,
      "y": 49,
      "z": -23,
      "name": "Rock_Ice"
    },
    {
      "x": -39,
      "y": 50,
      "z": -23,
      "name": "Soil_Snow"
    },
    {
      "x": -39,
      "y": 44,
      "z": -22,
      "name": "Rock_Ice"
    },
    {
      "x": -39,
      "y": 45,
      "z": -22,
      "name": "Rock_Ice"
    },
    {
      "x": -39,
      "y": 46,
      "z": -22,
      "name": "Rock_Ice"
    },
    {
      "x": -39,
      "y": 47,
      "z": -22,
      "name": "Rock_Ice"
    },
    {
      "x": -39,
      "y": 48,
      "z": -22,
      "name": "Rock_Ice"
    },
    {
      "x": -39,
      "y": 49,
      "z": -22,
      "name": "Rock_Ice"
    },
    {
      "x": -39,
      "y": 50,
      "z": -22,
      "name": "Soil_Snow"
    },
    {
      "x": -39,
      "y": 46,
      "z": -21,
      "name": "Rock_Ice"
    },
    {
      "x": -39,
      "y": 47,
      "z": -21,
      "name": "Rock_Ice_Permafrost"
    },
    {
      "x": -39,
      "y": 48,
      "z": -21,
      "name": "Rock_Ice_Permafrost"
    },
    {
      "x": -39,
      "y": 49,
      "z": -21,
      "name": "Rock_Ice"
    },
    {
      "x": -39,
      "y": 50,
      "z": -21,
      "name": "Rock_Ice"
    },
    {
      "x": -39,
      "y": 51,
      "z": -21,
      "name": "Rock_Ice_Permafrost"
    },
    {
      "x": -39,
      "y": 49,
      "z": -20,
      "name": "Rock_Ice_Permafrost"
    },
    {
      "x": -39,
      "y": 50,
      "z": -20,
      "name": "Rock_Ice"
    },
    {
      "x": -39,
      "y": 51,
      "z": -20,
      "name": "Rock_Ice"
    },
    {
      "x": -39,
      "y": 52,
      "z": -20,
      "name": "Rock_Ice"
    },
    {
      "x": -39,
      "y": 51,
      "z": -19,
      "name": "Rock_Ice_Permafrost"
    },
    {
      "x": -39,
      "y": 52,
      "z": -19,
      "name": "Rock_Ice_Permafrost"
    },
    {
      "x": -39,
      "y": 53,
      "z": -19,
      "name": "Rock_Ice"
    },
    {
      "x": -38,
      "y": 44,
      "z": -30,
      "name": "Soil_Snow"
    },
    {
      "x": -38,
      "y": 44,
      "z": -29,
      "name": "Rock_Ice_Permafrost"
    },
    {
      "x": -38,
      "y": 45,
      "z": -29,
      "name": "Rock_Ice"
    },
    {
      "x": -38,
      "y": 46,
      "z": -29,
      "name": "Soil_Snow"
    },
    {
      "x": -38,
      "y": 44,
      "z": -28,
      "name": "Rock_Ice"
    },
    {
      "x": -38,
      "y": 45,
      "z": -28,
      "name": "Rock_Ice"
    },
    {
      "x": -38,
      "y": 46,
      "z": -28,
      "name": "Rock_Ice"
    },
    {
      "x": -38,
      "y": 47,
      "z": -28,
      "name": "Rock_Ice_Permafrost"
    },
    {
      "x": -38,
      "y": 44,
      "z": -27,
      "name": "Rock_Ice"
    },
    {
      "x": -38,
      "y": 45,
      "z": -27,
      "name": "Rock_Ice_Permafrost"
    },
    {
      "x": -38,
      "y": 46,
      "z": -27,
      "name": "Rock_Ice"
    },
    {
      "x": -38,
      "y": 47,
      "z": -27,
      "name": "Rock_Ice"
    },
    {
      "x": -38,
      "y": 48,
      "z": -27,
      "name": "Rock_Ice"
    },
    {
      "x": -38,
      "y": 49,
      "z": -27,
      "name": "Soil_Snow"
    },
    {
      "x": -38,
      "y": 44,
      "z": -26,
      "name": "Rock_Ice"
    },
    {
      "x": -38,
      "y": 45,
      "z": -26,
      "name": "Rock_Ice"
    },
    {
      "x": -38,
      "y": 46,
      "z": -26,
      "name": "Rock_Ice"
    },
    {
      "x": -38,
      "y": 47,
      "z": -26,
      "name": "Rock_Ice"
    },
    {
      "x": -38,
      "y": 48,
      "z": -26,
      "name": "Rock_Ice_Permafrost"
    },
    {
      "x": -38,
      "y": 49,
      "z": -26,
      "name": "Rock_Ice"
    },
    {
      "x": -38,
      "y": 50,
      "z": -26,
      "name": "Rock_Ice_Permafrost"
    },
    {
      "x": -38,
      "y": 44,
      "z": -25,
      "name": "Rock_Ice"
    },
    {
      "x": -38,
      "y": 45,
      "z": -25,
      "name": "Rock_Ice"
    },
    {
      "x": -38,
      "y": 46,
      "z": -25,
      "name": "Rock_Ice"
    },
    {
      "x": -38,
      "y": 47,
      "z": -25,
      "name": "Rock_Ice"
    },
    {
      "x": -38,
      "y": 48,
      "z": -25,
      "name": "Rock_Ice"
    },
    {
      "x": -38,
      "y": 49,
      "z": -25,
      "name": "Rock_Ice"
    },
    {
      "x": -38,
      "y": 50,
      "z": -25,
      "name": "Rock_Ice_Permafrost"
    },
    {
      "x": -38,
      "y": 51,
      "z": -25,
      "name": "Rock_Ice"
    },
    {
      "x": -38,
      "y": 52,
      "z": -25,
      "name": "Soil_Snow"
    },
    {
      "x": -38,
      "y": 44,
      "z": -24,
      "name": "Rock_Ice"
    },
    {
      "x": -38,
      "y": 45,
      "z": -24,
      "name": "Rock_Ice"
    },
    {
      "x": -38,
      "y": 46,
      "z": -24,
      "name": "Rock_Ice"
    },
    {
      "x": -38,
      "y": 47,
      "z": -24,
      "name": "Rock_Ice"
    },
    {
      "x": -38,
      "y": 48,
      "z": -24,
      "name": "Rock_Ice"
    },
    {
      "x": -38,
      "y": 49,
      "z": -24,
      "name": "Rock_Ice"
    },
    {
      "x": -38,
      "y": 50,
      "z": -24,
      "name": "Rock_Ice"
    },
    {
      "x": -38,
      "y": 51,
      "z": -24,
      "name": "Rock_Ice_Permafrost"
    },
    {
      "x": -38,
      "y": 52,
      "z": -24,
      "name": "Rock_Ice"
    },
    {
      "x": -38,
      "y": 53,
      "z": -24,
      "name": "Soil_Snow"
    },
    {
      "x": -38,
      "y": 44,
      "z": -23,
      "name": "Rock_Ice"
    },
    {
      "x": -38,
      "y": 45,
      "z": -23,
      "name": "Rock_Ice"
    },
    {
      "x": -38,
      "y": 46,
      "z": -23,
      "name": "Rock_Ice"
    },
    {
      "x": -38,
      "y": 47,
      "z": -23,
      "name": "Rock_Ice"
    },
    {
      "x": -38,
      "y": 48,
      "z": -23,
      "name": "Rock_Ice"
    },
    {
      "x": -38,
      "y": 49,
      "z": -23,
      "name": "Rock_Ice"
    },
    {
      "x": -38,
      "y": 50,
      "z": -23,
      "name": "Rock_Ice"
    },
    {
      "x": -38,
      "y": 51,
      "z": -23,
      "name": "Soil_Snow"
    },
    {
      "x": -38,
      "y": 44,
      "z": -22,
      "name": "Rock_Ice"
    },
    {
      "x": -38,
      "y": 45,
      "z": -22,
      "name": "Rock_Ice"
    },
    {
      "x": -38,
      "y": 46,
      "z": -22,
      "name": "Rock_Ice"
    },
    {
      "x": -38,
      "y": 47,
      "z": -22,
      "name": "Rock_Ice"
    },
    {
      "x": -38,
      "y": 48,
      "z": -22,
      "name": "Rock_Ice"
    },
    {
      "x": -38,
      "y": 49,
      "z": -22,
      "name": "Rock_Ice"
    },
    {
      "x": -38,
      "y": 50,
      "z": -22,
      "name": "Rock_Ice"
    },
    {
      "x": -38,
      "y": 51,
      "z": -22,
      "name": "Rock_Ice"
    },
    {
      "x": -38,
      "y": 52,
      "z": -22,
      "name": "Soil_Snow"
    },
    {
      "x": -38,
      "y": 44,
      "z": -21,
      "name": "Rock_Ice"
    },
    {
      "x": -38,
      "y": 45,
      "z": -21,
      "name": "Rock_Ice"
    },
    {
      "x": -38,
      "y": 46,
      "z": -21,
      "name": "Rock_Ice"
    },
    {
      "x": -38,
      "y": 47,
      "z": -21,
      "name": "Rock_Ice"
    },
    {
      "x": -38,
      "y": 48,
      "z": -21,
      "name": "Rock_Ice"
    },
    {
      "x": -38,
      "y": 49,
      "z": -21,
      "name": "Rock_Ice"
    },
    {
      "x": -38,
      "y": 50,
      "z": -21,
      "name": "Rock_Ice"
    },
    {
      "x": -38,
      "y": 51,
      "z": -21,
      "name": "Rock_Ice"
    },
    {
      "x": -38,
      "y": 52,
      "z": -21,
      "name": "Rock_Ice"
    },
    {
      "x": -38,
      "y": 53,
      "z": -21,
      "name": "Rock_Ice"
    },
    {
      "x": -38,
      "y": 46,
      "z": -20,
      "name": "Rock_Ice"
    },
    {
      "x": -38,
      "y": 47,
      "z": -20,
      "name": "Rock_Ice"
    },
    {
      "x": -38,
      "y": 48,
      "z": -20,
      "name": "Rock_Ice"
    },
    {
      "x": -38,
      "y": 49,
      "z": -20,
      "name": "Rock_Ice"
    },
    {
      "x": -38,
      "y": 50,
      "z": -20,
      "name": "Rock_Ice"
    },
    {
      "x": -38,
      "y": 51,
      "z": -20,
      "name": "Rock_Ice"
    },
    {
      "x": -38,
      "y": 52,
      "z": -20,
      "name": "Rock_Ice"
    },
    {
      "x": -38,
      "y": 53,
      "z": -20,
      "name": "Rock_Ice"
    },
    {
      "x": -38,
      "y": 54,
      "z": -20,
      "name": "Rock_Ice"
    },
    {
      "x": -38,
      "y": 48,
      "z": -19,
      "name": "Rock_Ice"
    },
    {
      "x": -38,
      "y": 49,
      "z": -19,
      "name": "Rock_Ice"
    },
    {
      "x": -38,
      "y": 50,
      "z": -19,
      "name": "Rock_Ice"
    },
    {
      "x": -38,
      "y": 51,
      "z": -19,
      "name": "Rock_Ice"
    },
    {
      "x": -38,
      "y": 52,
      "z": -19,
      "name": "Rock_Ice"
    },
    {
      "x": -38,
      "y": 53,
      "z": -19,
      "name": "Rock_Ice"
    },
    {
      "x": -38,
      "y": 54,
      "z": -19,
      "name": "Rock_Ice"
    },
    {
      "x": -38,
      "y": 55,
      "z": -19,
      "name": "Rock_Ice"
    },
    {
      "x": -38,
      "y": 50,
      "z": -18,
      "name": "Rock_Ice"
    },
    {
      "x": -38,
      "y": 51,
      "z": -18,
      "name": "Rock_Ice"
    },
    {
      "x": -38,
      "y": 52,
      "z": -18,
      "name": "Rock_Ice"
    },
    {
      "x": -38,
      "y": 53,
      "z": -18,
      "name": "Rock_Ice"
    },
    {
      "x": -38,
      "y": 54,
      "z": -18,
      "name": "Rock_Ice"
    },
    {
      "x": -38,
      "y": 55,
      "z": -18,
      "name": "Rock_Ice"
    },
    {
      "x": -38,
      "y": 56,
      "z": -18,
      "name": "Rock_Ice"
    },
    {
      "x": -38,
      "y": 57,
      "z": -18,
      "name": "Rock_Ice"
    },
    {
      "x": -38,
      "y": 52,
      "z": -17,
      "name": "Rock_Ice_Permafrost"
    },
    {
      "x": -38,
      "y": 53,
      "z": -17,
      "name": "Rock_Ice_Permafrost"
    },
    {
      "x": -38,
      "y": 54,
      "z": -17,
      "name": "Rock_Ice"
    },
    {
      "x": -38,
      "y": 55,
      "z": -17,
      "name": "Rock_Ice"
    },
    {
      "x": -38,
      "y": 56,
      "z": -17,
      "name": "Rock_Ice"
    },
    {
      "x": -38,
      "y": 57,
      "z": -17,
      "name": "Rock_Ice"
    },
    {
      "x": -38,
      "y": 58,
      "z": -17,
      "name": "Rock_Ice_Permafrost"
    },
    {
      "x": -38,
      "y": 55,
      "z": -16,
      "name": "Rock_Ice_Permafrost"
    },
    {
      "x": -38,
      "y": 56,
      "z": -16,
      "name": "Rock_Ice"
    },
    {
      "x": -38,
      "y": 57,
      "z": -16,
      "name": "Rock_Ice_Permafrost"
    },
    {
      "x": -38,
      "y": 58,
      "z": -16,
      "name": "Rock_Ice_Permafrost"
    },
    {
      "x": -38,
      "y": 59,
      "z": -16,
      "name": "Rock_Ice_Permafrost"
    },
    {
      "x": -38,
      "y": 57,
      "z": -15,
      "name": "Rock_Ice"
    },
    {
      "x": -38,
      "y": 58,
      "z": -15,
      "name": "Rock_Ice_Permafrost"
    },
    {
      "x": -38,
      "y": 59,
      "z": -15,
      "name": "Rock_Ice_Permafrost"
    },
    {
      "x": -37,
      "y": 44,
      "z": -31,
      "name": "Soil_Snow"
    },
    {
      "x": -37,
      "y": 44,
      "z": -30,
      "name": "Rock_Ice_Permafrost"
    },
    {
      "x": -37,
      "y": 45,
      "z": -30,
      "name": "Soil_Snow"
    },
    {
      "x": -37,
      "y": 44,
      "z": -29,
      "name": "Rock_Ice"
    },
    {
      "x": -37,
      "y": 45,
      "z": -29,
      "name": "Rock_Ice_Permafrost"
    },
    {
      "x": -37,
      "y": 46,
      "z": -29,
      "name": "Rock_Ice_Permafrost"
    },
    {
      "x": -37,
      "y": 47,
      "z": -29,
      "name": "Soil_Snow"
    },
    {
      "x": -37,
      "y": 44,
      "z": -28,
      "name": "Rock_Ice"
    },
    {
      "x": -37,
      "y": 45,
      "z": -28,
      "name": "Rock_Ice"
    },
    {
      "x": -37,
      "y": 46,
      "z": -28,
      "name": "Rock_Ice_Permafrost"
    },
    {
      "x": -37,
      "y": 47,
      "z": -28,
      "name": "Rock_Ice"
    },
    {
      "x": -37,
      "y": 48,
      "z": -28,
      "name": "Soil_Snow"
    },
    {
      "x": -37,
      "y": 44,
      "z": -27,
      "name": "Rock_Ice"
    },
    {
      "x": -37,
      "y": 45,
      "z": -27,
      "name": "Rock_Ice"
    },
    {
      "x": -37,
      "y": 46,
      "z": -27,
      "name": "Rock_Ice"
    },
    {
      "x": -37,
      "y": 47,
      "z": -27,
      "name": "Rock_Ice_Permafrost"
    },
    {
      "x": -37,
      "y": 48,
      "z": -27,
      "name": "Rock_Ice"
    },
    {
      "x": -37,
      "y": 49,
      "z": -27,
      "name": "Rock_Ice"
    },
    {
      "x": -37,
      "y": 50,
      "z": -27,
      "name": "Soil_Snow"
    },
    {
      "x": -37,
      "y": 44,
      "z": -26,
      "name": "Rock_Ice"
    },
    {
      "x": -37,
      "y": 45,
      "z": -26,
      "name": "Rock_Ice"
    },
    {
      "x": -37,
      "y": 46,
      "z": -26,
      "name": "Rock_Ice"
    },
    {
      "x": -37,
      "y": 47,
      "z": -26,
      "name": "Rock_Ice"
    },
    {
      "x": -37,
      "y": 48,
      "z": -26,
      "name": "Rock_Ice_Permafrost"
    },
    {
      "x": -37,
      "y": 49,
      "z": -26,
      "name": "Rock_Ice_Permafrost"
    },
    {
      "x": -37,
      "y": 50,
      "z": -26,
      "name": "Rock_Ice"
    },
    {
      "x": -37,
      "y": 51,
      "z": -26,
      "name": "Rock_Ice_Permafrost"
    },
    {
      "x": -37,
      "y": 44,
      "z": -25,
      "name": "Rock_Ice"
    },
    {
      "x": -37,
      "y": 45,
      "z": -25,
      "name": "Rock_Ice"
    },
    {
      "x": -37,
      "y": 46,
      "z": -25,
      "name": "Rock_Ice"
    },
    {
      "x": -37,
      "y": 47,
      "z": -25,
      "name": "Rock_Ice"
    },
    {
      "x": -37,
      "y": 48,
      "z": -25,
      "name": "Rock_Ice"
    },
    {
      "x": -37,
      "y": 49,
      "z": -25,
      "name": "Rock_Ice"
    },
    {
      "x": -37,
      "y": 50,
      "z": -25,
      "name": "Rock_Ice_Permafrost"
    },
    {
      "x": -37,
      "y": 51,
      "z": -25,
      "name": "Rock_Ice_Permafrost"
    },
    {
      "x": -37,
      "y": 52,
      "z": -25,
      "name": "Rock_Ice"
    },
    {
      "x": -37,
      "y": 53,
      "z": -25,
      "name": "Soil_Snow"
    },
    {
      "x": -37,
      "y": 44,
      "z": -24,
      "name": "Rock_Ice"
    },
    {
      "x": -37,
      "y": 45,
      "z": -24,
      "name": "Rock_Ice"
    },
    {
      "x": -37,
      "y": 46,
      "z": -24,
      "name": "Rock_Ice"
    },
    {
      "x": -37,
      "y": 47,
      "z": -24,
      "name": "Rock_Ice"
    },
    {
      "x": -37,
      "y": 48,
      "z": -24,
      "name": "Rock_Ice"
    },
    {
      "x": -37,
      "y": 49,
      "z": -24,
      "name": "Rock_Ice"
    },
    {
      "x": -37,
      "y": 50,
      "z": -24,
      "name": "Rock_Ice"
    },
    {
      "x": -37,
      "y": 51,
      "z": -24,
      "name": "Rock_Ice"
    },
    {
      "x": -37,
      "y": 52,
      "z": -24,
      "name": "Rock_Ice_Permafrost"
    },
    {
      "x": -37,
      "y": 53,
      "z": -24,
      "name": "Rock_Ice"
    },
    {
      "x": -37,
      "y": 54,
      "z": -24,
      "name": "Rock_Ice_Permafrost"
    },
    {
      "x": -37,
      "y": 44,
      "z": -23,
      "name": "Rock_Ice"
    },
    {
      "x": -37,
      "y": 45,
      "z": -23,
      "name": "Rock_Ice"
    },
    {
      "x": -37,
      "y": 46,
      "z": -23,
      "name": "Rock_Ice"
    },
    {
      "x": -37,
      "y": 47,
      "z": -23,
      "name": "Rock_Ice"
    },
    {
      "x": -37,
      "y": 48,
      "z": -23,
      "name": "Rock_Ice"
    },
    {
      "x": -37,
      "y": 49,
      "z": -23,
      "name": "Rock_Ice"
    },
    {
      "x": -37,
      "y": 50,
      "z": -23,
      "name": "Rock_Ice"
    },
    {
      "x": -37,
      "y": 51,
      "z": -23,
      "name": "Rock_Ice"
    },
    {
      "x": -37,
      "y": 52,
      "z": -23,
      "name": "Rock_Ice"
    },
    {
      "x": -37,
      "y": 53,
      "z": -23,
      "name": "Rock_Ice"
    },
    {
      "x": -37,
      "y": 54,
      "z": -23,
      "name": "Rock_Ice"
    },
    {
      "x": -37,
      "y": 55,
      "z": -23,
      "name": "Soil_Snow"
    },
    {
      "x": -37,
      "y": 44,
      "z": -22,
      "name": "Rock_Ice"
    },
    {
      "x": -37,
      "y": 45,
      "z": -22,
      "name": "Rock_Ice"
    },
    {
      "x": -37,
      "y": 46,
      "z": -22,
      "name": "Rock_Ice"
    },
    {
      "x": -37,
      "y": 47,
      "z": -22,
      "name": "Rock_Ice"
    },
    {
      "x": -37,
      "y": 48,
      "z": -22,
      "name": "Rock_Ice"
    },
    {
      "x": -37,
      "y": 49,
      "z": -22,
      "name": "Rock_Ice"
    },
    {
      "x": -37,
      "y": 50,
      "z": -22,
      "name": "Rock_Ice"
    },
    {
      "x": -37,
      "y": 51,
      "z": -22,
      "name": "Rock_Ice"
    },
    {
      "x": -37,
      "y": 52,
      "z": -22,
      "name": "Rock_Ice"
    },
    {
      "x": -37,
      "y": 53,
      "z": -22,
      "name": "Rock_Ice"
    },
    {
      "x": -37,
      "y": 54,
      "z": -22,
      "name": "Rock_Ice"
    },
    {
      "x": -37,
      "y": 55,
      "z": -22,
      "name": "Soil_Snow"
    },
    {
      "x": -37,
      "y": 44,
      "z": -21,
      "name": "Rock_Ice"
    },
    {
      "x": -37,
      "y": 45,
      "z": -21,
      "name": "Rock_Ice"
    },
    {
      "x": -37,
      "y": 46,
      "z": -21,
      "name": "Rock_Ice"
    },
    {
      "x": -37,
      "y": 47,
      "z": -21,
      "name": "Rock_Ice"
    },
    {
      "x": -37,
      "y": 48,
      "z": -21,
      "name": "Rock_Ice"
    },
    {
      "x": -37,
      "y": 49,
      "z": -21,
      "name": "Rock_Ice"
    },
    {
      "x": -37,
      "y": 50,
      "z": -21,
      "name": "Rock_Ice"
    },
    {
      "x": -37,
      "y": 51,
      "z": -21,
      "name": "Rock_Ice"
    },
    {
      "x": -37,
      "y": 52,
      "z": -21,
      "name": "Rock_Ice"
    },
    {
      "x": -37,
      "y": 53,
      "z": -21,
      "name": "Rock_Ice"
    },
    {
      "x": -37,
      "y": 54,
      "z": -21,
      "name": "Soil_Snow"
    },
    {
      "x": -37,
      "y": 44,
      "z": -20,
      "name": "Rock_Ice"
    },
    {
      "x": -37,
      "y": 45,
      "z": -20,
      "name": "Rock_Ice"
    },
    {
      "x": -37,
      "y": 46,
      "z": -20,
      "name": "Rock_Ice"
    },
    {
      "x": -37,
      "y": 47,
      "z": -20,
      "name": "Rock_Ice"
    },
    {
      "x": -37,
      "y": 48,
      "z": -20,
      "name": "Rock_Ice"
    },
    {
      "x": -37,
      "y": 49,
      "z": -20,
      "name": "Rock_Ice"
    },
    {
      "x": -37,
      "y": 50,
      "z": -20,
      "name": "Rock_Ice"
    },
    {
      "x": -37,
      "y": 51,
      "z": -20,
      "name": "Rock_Ice"
    },
    {
      "x": -37,
      "y": 52,
      "z": -20,
      "name": "Rock_Ice"
    },
    {
      "x": -37,
      "y": 53,
      "z": -20,
      "name": "Rock_Ice"
    },
    {
      "x": -37,
      "y": 54,
      "z": -20,
      "name": "Rock_Ice"
    },
    {
      "x": -37,
      "y": 55,
      "z": -20,
      "name": "Rock_Ice"
    },
    {
      "x": -37,
      "y": 56,
      "z": -20,
      "name": "Soil_Snow"
    },
    {
      "x": -37,
      "y": 46,
      "z": -19,
      "name": "Rock_Ice"
    },
    {
      "x": -37,
      "y": 47,
      "z": -19,
      "name": "Rock_Ice"
    },
    {
      "x": -37,
      "y": 48,
      "z": -19,
      "name": "Rock_Ice"
    },
    {
      "x": -37,
      "y": 49,
      "z": -19,
      "name": "Rock_Ice"
    },
    {
      "x": -37,
      "y": 50,
      "z": -19,
      "name": "Rock_Ice"
    },
    {
      "x": -37,
      "y": 51,
      "z": -19,
      "name": "Rock_Ice"
    },
    {
      "x": -37,
      "y": 52,
      "z": -19,
      "name": "Rock_Ice"
    },
    {
      "x": -37,
      "y": 53,
      "z": -19,
      "name": "Rock_Ice"
    },
    {
      "x": -37,
      "y": 54,
      "z": -19,
      "name": "Rock_Ice"
    },
    {
      "x": -37,
      "y": 55,
      "z": -19,
      "name": "Rock_Ice"
    },
    {
      "x": -37,
      "y": 56,
      "z": -19,
      "name": "Rock_Ice"
    },
    {
      "x": -37,
      "y": 57,
      "z": -19,
      "name": "Soil_Snow"
    },
    {
      "x": -37,
      "y": 48,
      "z": -18,
      "name": "Rock_Ice"
    },
    {
      "x": -37,
      "y": 49,
      "z": -18,
      "name": "Rock_Ice"
    },
    {
      "x": -37,
      "y": 50,
      "z": -18,
      "name": "Rock_Ice"
    },
    {
      "x": -37,
      "y": 51,
      "z": -18,
      "name": "Rock_Ice"
    },
    {
      "x": -37,
      "y": 52,
      "z": -18,
      "name": "Rock_Ice"
    },
    {
      "x": -37,
      "y": 53,
      "z": -18,
      "name": "Rock_Ice"
    },
    {
      "x": -37,
      "y": 54,
      "z": -18,
      "name": "Rock_Ice"
    },
    {
      "x": -37,
      "y": 55,
      "z": -18,
      "name": "Rock_Ice"
    },
    {
      "x": -37,
      "y": 56,
      "z": -18,
      "name": "Rock_Ice"
    },
    {
      "x": -37,
      "y": 57,
      "z": -18,
      "name": "Rock_Ice"
    },
    {
      "x": -37,
      "y": 58,
      "z": -18,
      "name": "Rock_Ice"
    },
    {
      "x": -37,
      "y": 50,
      "z": -17,
      "name": "Rock_Ice"
    },
    {
      "x": -37,
      "y": 51,
      "z": -17,
      "name": "Rock_Ice"
    },
    {
      "x": -37,
      "y": 52,
      "z": -17,
      "name": "Rock_Ice"
    },
    {
      "x": -37,
      "y": 53,
      "z": -17,
      "name": "Rock_Ice"
    },
    {
      "x": -37,
      "y": 54,
      "z": -17,
      "name": "Rock_Ice"
    },
    {
      "x": -37,
      "y": 55,
      "z": -17,
      "name": "Rock_Ice"
    },
    {
      "x": -37,
      "y": 56,
      "z": -17,
      "name": "Rock_Ice"
    },
    {
      "x": -37,
      "y": 57,
      "z": -17,
      "name": "Rock_Ice"
    },
    {
      "x": -37,
      "y": 58,
      "z": -17,
      "name": "Rock_Ice"
    },
    {
      "x": -37,
      "y": 59,
      "z": -17,
      "name": "Rock_Ice"
    },
    {
      "x": -37,
      "y": 52,
      "z": -16,
      "name": "Rock_Ice"
    },
    {
      "x": -37,
      "y": 53,
      "z": -16,
      "name": "Rock_Ice"
    },
    {
      "x": -37,
      "y": 54,
      "z": -16,
      "name": "Rock_Ice"
    },
    {
      "x": -37,
      "y": 55,
      "z": -16,
      "name": "Rock_Ice"
    },
    {
      "x": -37,
      "y": 56,
      "z": -16,
      "name": "Rock_Ice"
    },
    {
      "x": -37,
      "y": 57,
      "z": -16,
      "name": "Rock_Ice"
    },
    {
      "x": -37,
      "y": 58,
      "z": -16,
      "name": "Rock_Ice"
    },
    {
      "x": -37,
      "y": 59,
      "z": -16,
      "name": "Rock_Ice"
    },
    {
      "x": -37,
      "y": 60,
      "z": -16,
      "name": "Rock_Ice"
    },
    {
      "x": -37,
      "y": 54,
      "z": -15,
      "name": "Rock_Ice"
    },
    {
      "x": -37,
      "y": 55,
      "z": -15,
      "name": "Rock_Ice"
    },
    {
      "x": -37,
      "y": 56,
      "z": -15,
      "name": "Rock_Ice"
    },
    {
      "x": -37,
      "y": 57,
      "z": -15,
      "name": "Rock_Ice"
    },
    {
      "x": -37,
      "y": 58,
      "z": -15,
      "name": "Rock_Ice"
    },
    {
      "x": -37,
      "y": 59,
      "z": -15,
      "name": "Rock_Ice"
    },
    {
      "x": -37,
      "y": 60,
      "z": -15,
      "name": "Rock_Ice"
    },
    {
      "x": -37,
      "y": 61,
      "z": -15,
      "name": "Rock_Ice"
    },
    {
      "x": -37,
      "y": 56,
      "z": -14,
      "name": "Rock_Ice"
    },
    {
      "x": -37,
      "y": 57,
      "z": -14,
      "name": "Rock_Ice"
    },
    {
      "x": -37,
      "y": 58,
      "z": -14,
      "name": "Rock_Ice"
    },
    {
      "x": -37,
      "y": 59,
      "z": -14,
      "name": "Rock_Ice"
    },
    {
      "x": -37,
      "y": 60,
      "z": -14,
      "name": "Rock_Ice"
    },
    {
      "x": -37,
      "y": 61,
      "z": -14,
      "name": "Rock_Ice"
    },
    {
      "x": -37,
      "y": 62,
      "z": -14,
      "name": "Rock_Ice"
    },
    {
      "x": -37,
      "y": 59,
      "z": -13,
      "name": "Rock_Ice"
    },
    {
      "x": -37,
      "y": 60,
      "z": -13,
      "name": "Rock_Ice"
    },
    {
      "x": -37,
      "y": 61,
      "z": -13,
      "name": "Rock_Ice"
    },
    {
      "x": -37,
      "y": 62,
      "z": -13,
      "name": "Rock_Ice"
    },
    {
      "x": -37,
      "y": 63,
      "z": -13,
      "name": "Rock_Ice"
    },
    {
      "x": -37,
      "y": 61,
      "z": -12,
      "name": "Rock_Ice"
    },
    {
      "x": -37,
      "y": 62,
      "z": -12,
      "name": "Rock_Ice_Permafrost"
    },
    {
      "x": -37,
      "y": 63,
      "z": -12,
      "name": "Rock_Ice"
    },
    {
      "x": -37,
      "y": 64,
      "z": -12,
      "name": "Rock_Ice"
    },
    {
      "x": -36,
      "y": 44,
      "z": -31,
      "name": "Rock_Ice"
    },
    {
      "x": -36,
      "y": 45,
      "z": -31,
      "name": "Soil_Snow"
    },
    {
      "x": -36,
      "y": 44,
      "z": -30,
      "name": "Rock_Ice_Permafrost"
    },
    {
      "x": -36,
      "y": 45,
      "z": -30,
      "name": "Rock_Ice"
    },
    {
      "x": -36,
      "y": 46,
      "z": -30,
      "name": "Soil_Snow"
    },
    {
      "x": -36,
      "y": 44,
      "z": -29,
      "name": "Rock_Ice"
    },
    {
      "x": -36,
      "y": 45,
      "z": -29,
      "name": "Rock_Ice_Permafrost"
    },
    {
      "x": -36,
      "y": 46,
      "z": -29,
      "name": "Rock_Ice_Permafrost"
    },
    {
      "x": -36,
      "y": 47,
      "z": -29,
      "name": "Rock_Ice"
    },
    {
      "x": -36,
      "y": 48,
      "z": -29,
      "name": "Soil_Snow"
    },
    {
      "x": -36,
      "y": 44,
      "z": -28,
      "name": "Rock_Ice"
    },
    {
      "x": -36,
      "y": 45,
      "z": -28,
      "name": "Rock_Ice"
    },
    {
      "x": -36,
      "y": 46,
      "z": -28,
      "name": "Rock_Ice_Permafrost"
    },
    {
      "x": -36,
      "y": 47,
      "z": -28,
      "name": "Rock_Ice_Permafrost"
    },
    {
      "x": -36,
      "y": 48,
      "z": -28,
      "name": "Rock_Ice"
    },
    {
      "x": -36,
      "y": 49,
      "z": -28,
      "name": "Soil_Snow"
    },
    {
      "x": -36,
      "y": 44,
      "z": -27,
      "name": "Rock_Ice"
    },
    {
      "x": -36,
      "y": 45,
      "z": -27,
      "name": "Rock_Ice"
    },
    {
      "x": -36,
      "y": 46,
      "z": -27,
      "name": "Rock_Ice"
    },
    {
      "x": -36,
      "y": 47,
      "z": -27,
      "name": "Rock_Ice"
    },
    {
      "x": -36,
      "y": 48,
      "z": -27,
      "name": "Rock_Ice_Permafrost"
    },
    {
      "x": -36,
      "y": 49,
      "z": -27,
      "name": "Rock_Ice_Permafrost"
    },
    {
      "x": -36,
      "y": 50,
      "z": -27,
      "name": "Rock_Ice_Permafrost"
    },
    {
      "x": -36,
      "y": 51,
      "z": -27,
      "name": "Soil_Snow"
    },
    {
      "x": -36,
      "y": 44,
      "z": -26,
      "name": "Rock_Ice"
    },
    {
      "x": -36,
      "y": 45,
      "z": -26,
      "name": "Rock_Ice"
    },
    {
      "x": -36,
      "y": 46,
      "z": -26,
      "name": "Rock_Ice"
    },
    {
      "x": -36,
      "y": 47,
      "z": -26,
      "name": "Rock_Ice"
    },
    {
      "x": -36,
      "y": 48,
      "z": -26,
      "name": "Rock_Ice"
    },
    {
      "x": -36,
      "y": 49,
      "z": -26,
      "name": "Rock_Ice"
    },
    {
      "x": -36,
      "y": 50,
      "z": -26,
      "name": "Rock_Ice_Permafrost"
    },
    {
      "x": -36,
      "y": 51,
      "z": -26,
      "name": "Rock_Ice"
    },
    {
      "x": -36,
      "y": 52,
      "z": -26,
      "name": "Soil_Snow"
    },
    {
      "x": -36,
      "y": 44,
      "z": -25,
      "name": "Rock_Ice"
    },
    {
      "x": -36,
      "y": 45,
      "z": -25,
      "name": "Rock_Ice"
    },
    {
      "x": -36,
      "y": 46,
      "z": -25,
      "name": "Rock_Ice"
    },
    {
      "x": -36,
      "y": 47,
      "z": -25,
      "name": "Rock_Ice"
    },
    {
      "x": -36,
      "y": 48,
      "z": -25,
      "name": "Rock_Ice"
    },
    {
      "x": -36,
      "y": 49,
      "z": -25,
      "name": "Rock_Ice"
    },
    {
      "x": -36,
      "y": 50,
      "z": -25,
      "name": "Rock_Ice"
    },
    {
      "x": -36,
      "y": 51,
      "z": -25,
      "name": "Rock_Ice"
    },
    {
      "x": -36,
      "y": 52,
      "z": -25,
      "name": "Rock_Ice"
    },
    {
      "x": -36,
      "y": 53,
      "z": -25,
      "name": "Rock_Ice_Permafrost"
    },
    {
      "x": -36,
      "y": 44,
      "z": -24,
      "name": "Rock_Ice"
    },
    {
      "x": -36,
      "y": 45,
      "z": -24,
      "name": "Rock_Ice"
    },
    {
      "x": -36,
      "y": 46,
      "z": -24,
      "name": "Rock_Ice"
    },
    {
      "x": -36,
      "y": 47,
      "z": -24,
      "name": "Rock_Ice"
    },
    {
      "x": -36,
      "y": 48,
      "z": -24,
      "name": "Rock_Ice"
    },
    {
      "x": -36,
      "y": 49,
      "z": -24,
      "name": "Rock_Ice"
    },
    {
      "x": -36,
      "y": 50,
      "z": -24,
      "name": "Rock_Ice"
    },
    {
      "x": -36,
      "y": 51,
      "z": -24,
      "name": "Rock_Ice"
    },
    {
      "x": -36,
      "y": 52,
      "z": -24,
      "name": "Rock_Ice"
    },
    {
      "x": -36,
      "y": 53,
      "z": -24,
      "name": "Rock_Ice"
    },
    {
      "x": -36,
      "y": 54,
      "z": -24,
      "name": "Rock_Ice"
    },
    {
      "x": -36,
      "y": 55,
      "z": -24,
      "name": "Soil_Snow"
    },
    {
      "x": -36,
      "y": 44,
      "z": -23,
      "name": "Rock_Ice"
    },
    {
      "x": -36,
      "y": 45,
      "z": -23,
      "name": "Rock_Ice"
    },
    {
      "x": -36,
      "y": 46,
      "z": -23,
      "name": "Rock_Ice"
    },
    {
      "x": -36,
      "y": 47,
      "z": -23,
      "name": "Rock_Ice"
    },
    {
      "x": -36,
      "y": 48,
      "z": -23,
      "name": "Rock_Ice"
    },
    {
      "x": -36,
      "y": 49,
      "z": -23,
      "name": "Rock_Ice"
    },
    {
      "x": -36,
      "y": 50,
      "z": -23,
      "name": "Rock_Ice"
    },
    {
      "x": -36,
      "y": 51,
      "z": -23,
      "name": "Rock_Ice"
    },
    {
      "x": -36,
      "y": 52,
      "z": -23,
      "name": "Rock_Ice"
    },
    {
      "x": -36,
      "y": 53,
      "z": -23,
      "name": "Rock_Ice"
    },
    {
      "x": -36,
      "y": 54,
      "z": -23,
      "name": "Rock_Ice"
    },
    {
      "x": -36,
      "y": 55,
      "z": -23,
      "name": "Rock_Ice"
    },
    {
      "x": -36,
      "y": 56,
      "z": -23,
      "name": "Rock_Ice_Permafrost"
    },
    {
      "x": -36,
      "y": 44,
      "z": -22,
      "name": "Rock_Ice"
    },
    {
      "x": -36,
      "y": 45,
      "z": -22,
      "name": "Rock_Ice"
    },
    {
      "x": -36,
      "y": 46,
      "z": -22,
      "name": "Rock_Ice"
    },
    {
      "x": -36,
      "y": 47,
      "z": -22,
      "name": "Rock_Ice"
    },
    {
      "x": -36,
      "y": 48,
      "z": -22,
      "name": "Rock_Ice"
    },
    {
      "x": -36,
      "y": 49,
      "z": -22,
      "name": "Rock_Ice"
    },
    {
      "x": -36,
      "y": 50,
      "z": -22,
      "name": "Rock_Ice"
    },
    {
      "x": -36,
      "y": 51,
      "z": -22,
      "name": "Rock_Ice"
    },
    {
      "x": -36,
      "y": 52,
      "z": -22,
      "name": "Rock_Ice"
    },
    {
      "x": -36,
      "y": 53,
      "z": -22,
      "name": "Rock_Ice"
    },
    {
      "x": -36,
      "y": 54,
      "z": -22,
      "name": "Rock_Ice"
    },
    {
      "x": -36,
      "y": 55,
      "z": -22,
      "name": "Rock_Ice"
    },
    {
      "x": -36,
      "y": 56,
      "z": -22,
      "name": "Rock_Ice"
    },
    {
      "x": -36,
      "y": 57,
      "z": -22,
      "name": "Soil_Snow"
    },
    {
      "x": -36,
      "y": 44,
      "z": -21,
      "name": "Rock_Ice"
    },
    {
      "x": -36,
      "y": 45,
      "z": -21,
      "name": "Rock_Ice"
    },
    {
      "x": -36,
      "y": 46,
      "z": -21,
      "name": "Rock_Ice"
    },
    {
      "x": -36,
      "y": 47,
      "z": -21,
      "name": "Rock_Ice"
    },
    {
      "x": -36,
      "y": 48,
      "z": -21,
      "name": "Rock_Ice"
    },
    {
      "x": -36,
      "y": 49,
      "z": -21,
      "name": "Rock_Ice"
    },
    {
      "x": -36,
      "y": 50,
      "z": -21,
      "name": "Rock_Ice"
    },
    {
      "x": -36,
      "y": 51,
      "z": -21,
      "name": "Rock_Ice"
    },
    {
      "x": -36,
      "y": 52,
      "z": -21,
      "name": "Rock_Ice"
    },
    {
      "x": -36,
      "y": 53,
      "z": -21,
      "name": "Rock_Ice"
    },
    {
      "x": -36,
      "y": 54,
      "z": -21,
      "name": "Rock_Ice"
    },
    {
      "x": -36,
      "y": 55,
      "z": -21,
      "name": "Rock_Ice"
    },
    {
      "x": -36,
      "y": 56,
      "z": -21,
      "name": "Rock_Ice"
    },
    {
      "x": -36,
      "y": 57,
      "z": -21,
      "name": "Soil_Snow"
    },
    {
      "x": -36,
      "y": 44,
      "z": -20,
      "name": "Rock_Ice"
    },
    {
      "x": -36,
      "y": 45,
      "z": -20,
      "name": "Rock_Ice"
    },
    {
      "x": -36,
      "y": 46,
      "z": -20,
      "name": "Rock_Ice"
    },
    {
      "x": -36,
      "y": 47,
      "z": -20,
      "name": "Rock_Ice"
    },
    {
      "x": -36,
      "y": 48,
      "z": -20,
      "name": "Rock_Ice"
    },
    {
      "x": -36,
      "y": 49,
      "z": -20,
      "name": "Rock_Ice"
    },
    {
      "x": -36,
      "y": 50,
      "z": -20,
      "name": "Rock_Ice"
    },
    {
      "x": -36,
      "y": 51,
      "z": -20,
      "name": "Rock_Ice"
    },
    {
      "x": -36,
      "y": 52,
      "z": -20,
      "name": "Rock_Ice"
    },
    {
      "x": -36,
      "y": 53,
      "z": -20,
      "name": "Rock_Ice"
    },
    {
      "x": -36,
      "y": 54,
      "z": -20,
      "name": "Rock_Ice"
    },
    {
      "x": -36,
      "y": 55,
      "z": -20,
      "name": "Rock_Ice"
    },
    {
      "x": -36,
      "y": 56,
      "z": -20,
      "name": "Rock_Ice"
    },
    {
      "x": -36,
      "y": 57,
      "z": -20,
      "name": "Soil_Snow"
    },
    {
      "x": -36,
      "y": 44,
      "z": -19,
      "name": "Rock_Ice"
    },
    {
      "x": -36,
      "y": 45,
      "z": -19,
      "name": "Rock_Ice"
    },
    {
      "x": -36,
      "y": 46,
      "z": -19,
      "name": "Rock_Ice"
    },
    {
      "x": -36,
      "y": 47,
      "z": -19,
      "name": "Rock_Ice"
    },
    {
      "x": -36,
      "y": 48,
      "z": -19,
      "name": "Rock_Ice"
    },
    {
      "x": -36,
      "y": 49,
      "z": -19,
      "name": "Rock_Ice"
    },
    {
      "x": -36,
      "y": 50,
      "z": -19,
      "name": "Rock_Ice"
    },
    {
      "x": -36,
      "y": 51,
      "z": -19,
      "name": "Rock_Ice"
    },
    {
      "x": -36,
      "y": 52,
      "z": -19,
      "name": "Rock_Ice"
    },
    {
      "x": -36,
      "y": 53,
      "z": -19,
      "name": "Rock_Ice"
    },
    {
      "x": -36,
      "y": 54,
      "z": -19,
      "name": "Rock_Ice"
    },
    {
      "x": -36,
      "y": 55,
      "z": -19,
      "name": "Rock_Ice"
    },
    {
      "x": -36,
      "y": 56,
      "z": -19,
      "name": "Rock_Ice"
    },
    {
      "x": -36,
      "y": 57,
      "z": -19,
      "name": "Rock_Ice"
    },
    {
      "x": -36,
      "y": 58,
      "z": -19,
      "name": "Soil_Snow"
    },
    {
      "x": -36,
      "y": 46,
      "z": -18,
      "name": "Rock_Ice"
    },
    {
      "x": -36,
      "y": 47,
      "z": -18,
      "name": "Rock_Ice"
    },
    {
      "x": -36,
      "y": 48,
      "z": -18,
      "name": "Rock_Ice"
    },
    {
      "x": -36,
      "y": 49,
      "z": -18,
      "name": "Rock_Ice"
    },
    {
      "x": -36,
      "y": 50,
      "z": -18,
      "name": "Rock_Ice"
    },
    {
      "x": -36,
      "y": 51,
      "z": -18,
      "name": "Rock_Ice"
    },
    {
      "x": -36,
      "y": 52,
      "z": -18,
      "name": "Rock_Ice"
    },
    {
      "x": -36,
      "y": 53,
      "z": -18,
      "name": "Rock_Ice"
    },
    {
      "x": -36,
      "y": 54,
      "z": -18,
      "name": "Rock_Ice"
    },
    {
      "x": -36,
      "y": 55,
      "z": -18,
      "name": "Rock_Ice"
    },
    {
      "x": -36,
      "y": 56,
      "z": -18,
      "name": "Rock_Ice"
    },
    {
      "x": -36,
      "y": 57,
      "z": -18,
      "name": "Rock_Ice"
    },
    {
      "x": -36,
      "y": 58,
      "z": -18,
      "name": "Rock_Ice"
    },
    {
      "x": -36,
      "y": 59,
      "z": -18,
      "name": "Soil_Snow"
    },
    {
      "x": -36,
      "y": 48,
      "z": -17,
      "name": "Rock_Ice"
    },
    {
      "x": -36,
      "y": 49,
      "z": -17,
      "name": "Rock_Ice"
    },
    {
      "x": -36,
      "y": 50,
      "z": -17,
      "name": "Rock_Ice"
    },
    {
      "x": -36,
      "y": 51,
      "z": -17,
      "name": "Rock_Ice"
    },
    {
      "x": -36,
      "y": 52,
      "z": -17,
      "name": "Rock_Ice"
    },
    {
      "x": -36,
      "y": 53,
      "z": -17,
      "name": "Rock_Ice"
    },
    {
      "x": -36,
      "y": 54,
      "z": -17,
      "name": "Rock_Ice"
    },
    {
      "x": -36,
      "y": 55,
      "z": -17,
      "name": "Rock_Ice"
    },
    {
      "x": -36,
      "y": 56,
      "z": -17,
      "name": "Rock_Ice"
    },
    {
      "x": -36,
      "y": 57,
      "z": -17,
      "name": "Rock_Ice"
    },
    {
      "x": -36,
      "y": 58,
      "z": -17,
      "name": "Rock_Ice"
    },
    {
      "x": -36,
      "y": 59,
      "z": -17,
      "name": "Rock_Ice"
    },
    {
      "x": -36,
      "y": 60,
      "z": -17,
      "name": "Soil_Snow"
    },
    {
      "x": -36,
      "y": 50,
      "z": -16,
      "name": "Rock_Ice"
    },
    {
      "x": -36,
      "y": 51,
      "z": -16,
      "name": "Rock_Ice"
    },
    {
      "x": -36,
      "y": 52,
      "z": -16,
      "name": "Rock_Ice"
    },
    {
      "x": -36,
      "y": 53,
      "z": -16,
      "name": "Rock_Ice"
    },
    {
      "x": -36,
      "y": 54,
      "z": -16,
      "name": "Rock_Ice"
    },
    {
      "x": -36,
      "y": 55,
      "z": -16,
      "name": "Rock_Ice"
    },
    {
      "x": -36,
      "y": 56,
      "z": -16,
      "name": "Rock_Ice"
    },
    {
      "x": -36,
      "y": 57,
      "z": -16,
      "name": "Rock_Ice"
    },
    {
      "x": -36,
      "y": 58,
      "z": -16,
      "name": "Rock_Ice"
    },
    {
      "x": -36,
      "y": 59,
      "z": -16,
      "name": "Rock_Ice"
    },
    {
      "x": -36,
      "y": 60,
      "z": -16,
      "name": "Rock_Ice"
    },
    {
      "x": -36,
      "y": 61,
      "z": -16,
      "name": "Rock_Ice"
    },
    {
      "x": -36,
      "y": 62,
      "z": -16,
      "name": "Soil_Snow"
    },
    {
      "x": -36,
      "y": 52,
      "z": -15,
      "name": "Rock_Ice"
    },
    {
      "x": -36,
      "y": 53,
      "z": -15,
      "name": "Rock_Ice"
    },
    {
      "x": -36,
      "y": 54,
      "z": -15,
      "name": "Rock_Ice"
    },
    {
      "x": -36,
      "y": 55,
      "z": -15,
      "name": "Rock_Ice"
    },
    {
      "x": -36,
      "y": 56,
      "z": -15,
      "name": "Rock_Ice"
    },
    {
      "x": -36,
      "y": 57,
      "z": -15,
      "name": "Rock_Ice"
    },
    {
      "x": -36,
      "y": 58,
      "z": -15,
      "name": "Rock_Ice"
    },
    {
      "x": -36,
      "y": 59,
      "z": -15,
      "name": "Rock_Ice"
    },
    {
      "x": -36,
      "y": 60,
      "z": -15,
      "name": "Rock_Ice"
    },
    {
      "x": -36,
      "y": 61,
      "z": -15,
      "name": "Rock_Ice"
    },
    {
      "x": -36,
      "y": 62,
      "z": -15,
      "name": "Rock_Ice"
    },
    {
      "x": -36,
      "y": 63,
      "z": -15,
      "name": "Soil_Snow"
    },
    {
      "x": -36,
      "y": 54,
      "z": -14,
      "name": "Rock_Ice"
    },
    {
      "x": -36,
      "y": 55,
      "z": -14,
      "name": "Rock_Ice"
    },
    {
      "x": -36,
      "y": 56,
      "z": -14,
      "name": "Rock_Ice"
    },
    {
      "x": -36,
      "y": 57,
      "z": -14,
      "name": "Rock_Ice"
    },
    {
      "x": -36,
      "y": 58,
      "z": -14,
      "name": "Rock_Ice"
    },
    {
      "x": -36,
      "y": 59,
      "z": -14,
      "name": "Rock_Ice"
    },
    {
      "x": -36,
      "y": 60,
      "z": -14,
      "name": "Rock_Ice"
    },
    {
      "x": -36,
      "y": 61,
      "z": -14,
      "name": "Rock_Ice"
    },
    {
      "x": -36,
      "y": 62,
      "z": -14,
      "name": "Rock_Ice"
    },
    {
      "x": -36,
      "y": 63,
      "z": -14,
      "name": "Rock_Ice"
    },
    {
      "x": -36,
      "y": 64,
      "z": -14,
      "name": "Soil_Snow"
    },
    {
      "x": -36,
      "y": 56,
      "z": -13,
      "name": "Rock_Ice"
    },
    {
      "x": -36,
      "y": 57,
      "z": -13,
      "name": "Rock_Ice"
    },
    {
      "x": -36,
      "y": 58,
      "z": -13,
      "name": "Rock_Ice"
    },
    {
      "x": -36,
      "y": 59,
      "z": -13,
      "name": "Rock_Ice"
    },
    {
      "x": -36,
      "y": 60,
      "z": -13,
      "name": "Rock_Ice"
    },
    {
      "x": -36,
      "y": 61,
      "z": -13,
      "name": "Rock_Ice"
    },
    {
      "x": -36,
      "y": 62,
      "z": -13,
      "name": "Rock_Ice"
    },
    {
      "x": -36,
      "y": 63,
      "z": -13,
      "name": "Rock_Ice"
    },
    {
      "x": -36,
      "y": 64,
      "z": -13,
      "name": "Rock_Ice"
    },
    {
      "x": -36,
      "y": 65,
      "z": -13,
      "name": "Soil_Snow"
    },
    {
      "x": -36,
      "y": 59,
      "z": -12,
      "name": "Rock_Ice"
    },
    {
      "x": -36,
      "y": 60,
      "z": -12,
      "name": "Rock_Ice"
    },
    {
      "x": -36,
      "y": 61,
      "z": -12,
      "name": "Rock_Ice"
    },
    {
      "x": -36,
      "y": 62,
      "z": -12,
      "name": "Rock_Ice"
    },
    {
      "x": -36,
      "y": 63,
      "z": -12,
      "name": "Rock_Ice"
    },
    {
      "x": -36,
      "y": 64,
      "z": -12,
      "name": "Rock_Ice"
    },
    {
      "x": -36,
      "y": 65,
      "z": -12,
      "name": "Rock_Ice"
    },
    {
      "x": -36,
      "y": 66,
      "z": -12,
      "name": "Rock_Ice"
    },
    {
      "x": -36,
      "y": 61,
      "z": -11,
      "name": "Rock_Ice"
    },
    {
      "x": -36,
      "y": 62,
      "z": -11,
      "name": "Rock_Ice"
    },
    {
      "x": -36,
      "y": 63,
      "z": -11,
      "name": "Rock_Ice"
    },
    {
      "x": -36,
      "y": 64,
      "z": -11,
      "name": "Rock_Ice"
    },
    {
      "x": -36,
      "y": 65,
      "z": -11,
      "name": "Rock_Ice"
    },
    {
      "x": -36,
      "y": 66,
      "z": -11,
      "name": "Rock_Ice"
    },
    {
      "x": -36,
      "y": 67,
      "z": -11,
      "name": "Rock_Ice"
    },
    {
      "x": -36,
      "y": 63,
      "z": -10,
      "name": "Rock_Ice_Permafrost"
    },
    {
      "x": -36,
      "y": 64,
      "z": -10,
      "name": "Rock_Ice"
    },
    {
      "x": -36,
      "y": 65,
      "z": -10,
      "name": "Rock_Ice"
    },
    {
      "x": -36,
      "y": 66,
      "z": -10,
      "name": "Rock_Ice"
    },
    {
      "x": -36,
      "y": 67,
      "z": -10,
      "name": "Rock_Ice"
    },
    {
      "x": -36,
      "y": 68,
      "z": -10,
      "name": "Rock_Ice"
    },
    {
      "x": -36,
      "y": 66,
      "z": -9,
      "name": "Rock_Ice"
    },
    {
      "x": -36,
      "y": 67,
      "z": -9,
      "name": "Rock_Ice"
    },
    {
      "x": -36,
      "y": 68,
      "z": -9,
      "name": "Rock_Ice_Permafrost"
    },
    {
      "x": -35,
      "y": 44,
      "z": -32,
      "name": "Soil_Snow"
    },
    {
      "x": -35,
      "y": 44,
      "z": -31,
      "name": "Rock_Ice"
    },
    {
      "x": -35,
      "y": 45,
      "z": -31,
      "name": "Soil_Snow"
    },
    {
      "x": -35,
      "y": 44,
      "z": -30,
      "name": "Rock_Ice"
    },
    {
      "x": -35,
      "y": 45,
      "z": -30,
      "name": "Rock_Ice_Permafrost"
    },
    {
      "x": -35,
      "y": 46,
      "z": -30,
      "name": "Rock_Ice"
    },
    {
      "x": -35,
      "y": 47,
      "z": -30,
      "name": "Soil_Snow"
    },
    {
      "x": -35,
      "y": 44,
      "z": -29,
      "name": "Rock_Ice"
    },
    {
      "x": -35,
      "y": 45,
      "z": -29,
      "name": "Rock_Ice_Permafrost"
    },
    {
      "x": -35,
      "y": 46,
      "z": -29,
      "name": "Rock_Ice_Permafrost"
    },
    {
      "x": -35,
      "y": 47,
      "z": -29,
      "name": "Rock_Ice_Permafrost"
    },
    {
      "x": -35,
      "y": 48,
      "z": -29,
      "name": "Soil_Snow"
    },
    {
      "x": -35,
      "y": 44,
      "z": -28,
      "name": "Rock_Ice"
    },
    {
      "x": -35,
      "y": 45,
      "z": -28,
      "name": "Rock_Ice"
    },
    {
      "x": -35,
      "y": 46,
      "z": -28,
      "name": "Rock_Ice"
    },
    {
      "x": -35,
      "y": 47,
      "z": -28,
      "name": "Rock_Ice"
    },
    {
      "x": -35,
      "y": 48,
      "z": -28,
      "name": "Rock_Ice_Permafrost"
    },
    {
      "x": -35,
      "y": 49,
      "z": -28,
      "name": "Rock_Ice"
    },
    {
      "x": -35,
      "y": 50,
      "z": -28,
      "name": "Soil_Snow"
    },
    {
      "x": -35,
      "y": 44,
      "z": -27,
      "name": "Rock_Ice"
    },
    {
      "x": -35,
      "y": 45,
      "z": -27,
      "name": "Rock_Ice"
    },
    {
      "x": -35,
      "y": 46,
      "z": -27,
      "name": "Rock_Ice"
    },
    {
      "x": -35,
      "y": 47,
      "z": -27,
      "name": "Rock_Ice"
    },
    {
      "x": -35,
      "y": 48,
      "z": -27,
      "name": "Rock_Ice_Permafrost"
    },
    {
      "x": -35,
      "y": 49,
      "z": -27,
      "name": "Rock_Ice_Permafrost"
    },
    {
      "x": -35,
      "y": 50,
      "z": -27,
      "name": "Rock_Ice"
    },
    {
      "x": -35,
      "y": 51,
      "z": -27,
      "name": "Soil_Snow"
    },
    {
      "x": -35,
      "y": 44,
      "z": -26,
      "name": "Rock_Ice"
    },
    {
      "x": -35,
      "y": 45,
      "z": -26,
      "name": "Rock_Ice"
    },
    {
      "x": -35,
      "y": 46,
      "z": -26,
      "name": "Rock_Ice"
    },
    {
      "x": -35,
      "y": 47,
      "z": -26,
      "name": "Rock_Ice"
    },
    {
      "x": -35,
      "y": 48,
      "z": -26,
      "name": "Rock_Ice"
    },
    {
      "x": -35,
      "y": 49,
      "z": -26,
      "name": "Rock_Ice"
    },
    {
      "x": -35,
      "y": 50,
      "z": -26,
      "name": "Rock_Ice_Permafrost"
    },
    {
      "x": -35,
      "y": 51,
      "z": -26,
      "name": "Rock_Ice"
    },
    {
      "x": -35,
      "y": 52,
      "z": -26,
      "name": "Rock_Ice_Permafrost"
    },
    {
      "x": -35,
      "y": 53,
      "z": -26,
      "name": "Soil_Snow"
    },
    {
      "x": -35,
      "y": 44,
      "z": -25,
      "name": "Rock_Ice"
    },
    {
      "x": -35,
      "y": 45,
      "z": -25,
      "name": "Rock_Ice"
    },
    {
      "x": -35,
      "y": 46,
      "z": -25,
      "name": "Rock_Ice"
    },
    {
      "x": -35,
      "y": 47,
      "z": -25,
      "name": "Rock_Ice"
    },
    {
      "x": -35,
      "y": 48,
      "z": -25,
      "name": "Rock_Ice"
    },
    {
      "x": -35,
      "y": 49,
      "z": -25,
      "name": "Rock_Ice"
    },
    {
      "x": -35,
      "y": 50,
      "z": -25,
      "name": "Rock_Ice"
    },
    {
      "x": -35,
      "y": 51,
      "z": -25,
      "name": "Rock_Ice"
    },
    {
      "x": -35,
      "y": 52,
      "z": -25,
      "name": "Rock_Ice"
    },
    {
      "x": -35,
      "y": 53,
      "z": -25,
      "name": "Rock_Ice"
    },
    {
      "x": -35,
      "y": 54,
      "z": -25,
      "name": "Soil_Snow"
    },
    {
      "x": -35,
      "y": 44,
      "z": -24,
      "name": "Rock_Ice"
    },
    {
      "x": -35,
      "y": 45,
      "z": -24,
      "name": "Rock_Ice"
    },
    {
      "x": -35,
      "y": 46,
      "z": -24,
      "name": "Rock_Ice"
    },
    {
      "x": -35,
      "y": 47,
      "z": -24,
      "name": "Rock_Ice"
    },
    {
      "x": -35,
      "y": 48,
      "z": -24,
      "name": "Rock_Ice"
    },
    {
      "x": -35,
      "y": 49,
      "z": -24,
      "name": "Rock_Ice"
    },
    {
      "x": -35,
      "y": 50,
      "z": -24,
      "name": "Rock_Ice"
    },
    {
      "x": -35,
      "y": 51,
      "z": -24,
      "name": "Rock_Ice"
    },
    {
      "x": -35,
      "y": 52,
      "z": -24,
      "name": "Rock_Ice"
    },
    {
      "x": -35,
      "y": 53,
      "z": -24,
      "name": "Rock_Ice_Permafrost"
    },
    {
      "x": -35,
      "y": 54,
      "z": -24,
      "name": "Rock_Ice"
    },
    {
      "x": -35,
      "y": 55,
      "z": -24,
      "name": "Rock_Ice_Permafrost"
    },
    {
      "x": -35,
      "y": 44,
      "z": -23,
      "name": "Rock_Ice"
    },
    {
      "x": -35,
      "y": 45,
      "z": -23,
      "name": "Rock_Ice"
    },
    {
      "x": -35,
      "y": 46,
      "z": -23,
      "name": "Rock_Ice"
    },
    {
      "x": -35,
      "y": 47,
      "z": -23,
      "name": "Rock_Ice"
    },
    {
      "x": -35,
      "y": 48,
      "z": -23,
      "name": "Rock_Ice"
    },
    {
      "x": -35,
      "y": 49,
      "z": -23,
      "name": "Rock_Ice"
    },
    {
      "x": -35,
      "y": 50,
      "z": -23,
      "name": "Rock_Ice"
    },
    {
      "x": -35,
      "y": 51,
      "z": -23,
      "name": "Rock_Ice"
    },
    {
      "x": -35,
      "y": 52,
      "z": -23,
      "name": "Rock_Ice"
    },
    {
      "x": -35,
      "y": 53,
      "z": -23,
      "name": "Rock_Ice"
    },
    {
      "x": -35,
      "y": 54,
      "z": -23,
      "name": "Rock_Ice"
    },
    {
      "x": -35,
      "y": 55,
      "z": -23,
      "name": "Rock_Ice"
    },
    {
      "x": -35,
      "y": 56,
      "z": -23,
      "name": "Rock_Ice"
    },
    {
      "x": -35,
      "y": 57,
      "z": -23,
      "name": "Soil_Snow"
    },
    {
      "x": -35,
      "y": 44,
      "z": -22,
      "name": "Rock_Ice"
    },
    {
      "x": -35,
      "y": 45,
      "z": -22,
      "name": "Rock_Ice"
    },
    {
      "x": -35,
      "y": 46,
      "z": -22,
      "name": "Rock_Ice"
    },
    {
      "x": -35,
      "y": 47,
      "z": -22,
      "name": "Rock_Ice"
    },
    {
      "x": -35,
      "y": 48,
      "z": -22,
      "name": "Rock_Ice"
    },
    {
      "x": -35,
      "y": 49,
      "z": -22,
      "name": "Rock_Ice"
    },
    {
      "x": -35,
      "y": 50,
      "z": -22,
      "name": "Rock_Ice"
    },
    {
      "x": -35,
      "y": 51,
      "z": -22,
      "name": "Rock_Ice"
    },
    {
      "x": -35,
      "y": 52,
      "z": -22,
      "name": "Rock_Ice"
    },
    {
      "x": -35,
      "y": 53,
      "z": -22,
      "name": "Rock_Ice"
    },
    {
      "x": -35,
      "y": 54,
      "z": -22,
      "name": "Rock_Ice"
    },
    {
      "x": -35,
      "y": 55,
      "z": -22,
      "name": "Rock_Ice"
    },
    {
      "x": -35,
      "y": 56,
      "z": -22,
      "name": "Rock_Ice_Permafrost"
    },
    {
      "x": -35,
      "y": 57,
      "z": -22,
      "name": "Rock_Ice"
    },
    {
      "x": -35,
      "y": 58,
      "z": -22,
      "name": "Rock_Ice_Permafrost"
    },
    {
      "x": -35,
      "y": 44,
      "z": -21,
      "name": "Rock_Ice"
    },
    {
      "x": -35,
      "y": 45,
      "z": -21,
      "name": "Rock_Ice"
    },
    {
      "x": -35,
      "y": 46,
      "z": -21,
      "name": "Rock_Ice"
    },
    {
      "x": -35,
      "y": 47,
      "z": -21,
      "name": "Rock_Ice"
    },
    {
      "x": -35,
      "y": 48,
      "z": -21,
      "name": "Rock_Ice"
    },
    {
      "x": -35,
      "y": 49,
      "z": -21,
      "name": "Rock_Ice"
    },
    {
      "x": -35,
      "y": 50,
      "z": -21,
      "name": "Rock_Ice"
    },
    {
      "x": -35,
      "y": 51,
      "z": -21,
      "name": "Rock_Ice"
    },
    {
      "x": -35,
      "y": 52,
      "z": -21,
      "name": "Rock_Ice"
    },
    {
      "x": -35,
      "y": 53,
      "z": -21,
      "name": "Rock_Ice"
    },
    {
      "x": -35,
      "y": 54,
      "z": -21,
      "name": "Rock_Ice"
    },
    {
      "x": -35,
      "y": 55,
      "z": -21,
      "name": "Rock_Ice"
    },
    {
      "x": -35,
      "y": 56,
      "z": -21,
      "name": "Rock_Ice"
    },
    {
      "x": -35,
      "y": 57,
      "z": -21,
      "name": "Rock_Ice"
    },
    {
      "x": -35,
      "y": 58,
      "z": -21,
      "name": "Rock_Ice"
    },
    {
      "x": -35,
      "y": 59,
      "z": -21,
      "name": "Soil_Snow"
    },
    {
      "x": -35,
      "y": 44,
      "z": -20,
      "name": "Rock_Ice"
    },
    {
      "x": -35,
      "y": 45,
      "z": -20,
      "name": "Rock_Ice"
    },
    {
      "x": -35,
      "y": 46,
      "z": -20,
      "name": "Rock_Ice"
    },
    {
      "x": -35,
      "y": 47,
      "z": -20,
      "name": "Rock_Ice"
    },
    {
      "x": -35,
      "y": 48,
      "z": -20,
      "name": "Rock_Ice"
    },
    {
      "x": -35,
      "y": 49,
      "z": -20,
      "name": "Rock_Ice"
    },
    {
      "x": -35,
      "y": 50,
      "z": -20,
      "name": "Rock_Ice"
    },
    {
      "x": -35,
      "y": 51,
      "z": -20,
      "name": "Rock_Ice"
    },
    {
      "x": -35,
      "y": 52,
      "z": -20,
      "name": "Rock_Ice"
    },
    {
      "x": -35,
      "y": 53,
      "z": -20,
      "name": "Rock_Ice"
    },
    {
      "x": -35,
      "y": 54,
      "z": -20,
      "name": "Rock_Ice"
    },
    {
      "x": -35,
      "y": 55,
      "z": -20,
      "name": "Rock_Ice"
    },
    {
      "x": -35,
      "y": 56,
      "z": -20,
      "name": "Rock_Ice"
    },
    {
      "x": -35,
      "y": 57,
      "z": -20,
      "name": "Rock_Ice"
    },
    {
      "x": -35,
      "y": 58,
      "z": -20,
      "name": "Rock_Ice"
    },
    {
      "x": -35,
      "y": 59,
      "z": -20,
      "name": "Soil_Snow"
    },
    {
      "x": -35,
      "y": 44,
      "z": -19,
      "name": "Rock_Ice"
    },
    {
      "x": -35,
      "y": 45,
      "z": -19,
      "name": "Rock_Ice"
    },
    {
      "x": -35,
      "y": 46,
      "z": -19,
      "name": "Rock_Ice"
    },
    {
      "x": -35,
      "y": 47,
      "z": -19,
      "name": "Rock_Ice"
    },
    {
      "x": -35,
      "y": 48,
      "z": -19,
      "name": "Rock_Ice"
    },
    {
      "x": -35,
      "y": 49,
      "z": -19,
      "name": "Rock_Ice"
    },
    {
      "x": -35,
      "y": 50,
      "z": -19,
      "name": "Rock_Ice"
    },
    {
      "x": -35,
      "y": 51,
      "z": -19,
      "name": "Rock_Ice"
    },
    {
      "x": -35,
      "y": 52,
      "z": -19,
      "name": "Rock_Ice"
    },
    {
      "x": -35,
      "y": 53,
      "z": -19,
      "name": "Rock_Ice"
    },
    {
      "x": -35,
      "y": 54,
      "z": -19,
      "name": "Rock_Ice"
    },
    {
      "x": -35,
      "y": 55,
      "z": -19,
      "name": "Rock_Ice"
    },
    {
      "x": -35,
      "y": 56,
      "z": -19,
      "name": "Rock_Ice"
    },
    {
      "x": -35,
      "y": 57,
      "z": -19,
      "name": "Rock_Ice"
    },
    {
      "x": -35,
      "y": 58,
      "z": -19,
      "name": "Rock_Ice"
    },
    {
      "x": -35,
      "y": 59,
      "z": -19,
      "name": "Rock_Ice"
    },
    {
      "x": -35,
      "y": 60,
      "z": -19,
      "name": "Soil_Snow"
    },
    {
      "x": -35,
      "y": 44,
      "z": -18,
      "name": "Rock_Ice"
    },
    {
      "x": -35,
      "y": 45,
      "z": -18,
      "name": "Rock_Ice"
    },
    {
      "x": -35,
      "y": 46,
      "z": -18,
      "name": "Rock_Ice"
    },
    {
      "x": -35,
      "y": 47,
      "z": -18,
      "name": "Rock_Ice"
    },
    {
      "x": -35,
      "y": 48,
      "z": -18,
      "name": "Rock_Ice"
    },
    {
      "x": -35,
      "y": 49,
      "z": -18,
      "name": "Rock_Ice"
    },
    {
      "x": -35,
      "y": 50,
      "z": -18,
      "name": "Rock_Ice"
    },
    {
      "x": -35,
      "y": 51,
      "z": -18,
      "name": "Rock_Ice"
    },
    {
      "x": -35,
      "y": 52,
      "z": -18,
      "name": "Rock_Ice"
    },
    {
      "x": -35,
      "y": 53,
      "z": -18,
      "name": "Rock_Ice"
    },
    {
      "x": -35,
      "y": 54,
      "z": -18,
      "name": "Rock_Ice"
    },
    {
      "x": -35,
      "y": 55,
      "z": -18,
      "name": "Rock_Ice"
    },
    {
      "x": -35,
      "y": 56,
      "z": -18,
      "name": "Rock_Ice"
    },
    {
      "x": -35,
      "y": 57,
      "z": -18,
      "name": "Rock_Ice"
    },
    {
      "x": -35,
      "y": 58,
      "z": -18,
      "name": "Rock_Ice"
    },
    {
      "x": -35,
      "y": 59,
      "z": -18,
      "name": "Rock_Ice"
    },
    {
      "x": -35,
      "y": 60,
      "z": -18,
      "name": "Rock_Ice"
    },
    {
      "x": -35,
      "y": 61,
      "z": -18,
      "name": "Soil_Snow"
    },
    {
      "x": -35,
      "y": 45,
      "z": -17,
      "name": "Rock_Ice"
    },
    {
      "x": -35,
      "y": 46,
      "z": -17,
      "name": "Rock_Ice"
    },
    {
      "x": -35,
      "y": 47,
      "z": -17,
      "name": "Rock_Ice"
    },
    {
      "x": -35,
      "y": 48,
      "z": -17,
      "name": "Rock_Ice"
    },
    {
      "x": -35,
      "y": 49,
      "z": -17,
      "name": "Rock_Ice"
    },
    {
      "x": -35,
      "y": 50,
      "z": -17,
      "name": "Rock_Ice"
    },
    {
      "x": -35,
      "y": 51,
      "z": -17,
      "name": "Rock_Ice"
    },
    {
      "x": -35,
      "y": 52,
      "z": -17,
      "name": "Rock_Ice"
    },
    {
      "x": -35,
      "y": 53,
      "z": -17,
      "name": "Rock_Ice"
    },
    {
      "x": -35,
      "y": 54,
      "z": -17,
      "name": "Rock_Ice"
    },
    {
      "x": -35,
      "y": 55,
      "z": -17,
      "name": "Rock_Ice"
    },
    {
      "x": -35,
      "y": 56,
      "z": -17,
      "name": "Rock_Ice"
    },
    {
      "x": -35,
      "y": 57,
      "z": -17,
      "name": "Rock_Ice"
    },
    {
      "x": -35,
      "y": 58,
      "z": -17,
      "name": "Rock_Ice"
    },
    {
      "x": -35,
      "y": 59,
      "z": -17,
      "name": "Rock_Ice"
    },
    {
      "x": -35,
      "y": 60,
      "z": -17,
      "name": "Rock_Ice"
    },
    {
      "x": -35,
      "y": 61,
      "z": -17,
      "name": "Rock_Ice"
    },
    {
      "x": -35,
      "y": 62,
      "z": -17,
      "name": "Soil_Snow"
    },
    {
      "x": -35,
      "y": 47,
      "z": -16,
      "name": "Rock_Ice"
    },
    {
      "x": -35,
      "y": 48,
      "z": -16,
      "name": "Rock_Ice"
    },
    {
      "x": -35,
      "y": 49,
      "z": -16,
      "name": "Rock_Ice"
    },
    {
      "x": -35,
      "y": 50,
      "z": -16,
      "name": "Rock_Ice"
    },
    {
      "x": -35,
      "y": 51,
      "z": -16,
      "name": "Rock_Ice"
    },
    {
      "x": -35,
      "y": 52,
      "z": -16,
      "name": "Rock_Ice"
    },
    {
      "x": -35,
      "y": 53,
      "z": -16,
      "name": "Rock_Ice"
    },
    {
      "x": -35,
      "y": 54,
      "z": -16,
      "name": "Rock_Ice"
    },
    {
      "x": -35,
      "y": 55,
      "z": -16,
      "name": "Rock_Ice"
    },
    {
      "x": -35,
      "y": 56,
      "z": -16,
      "name": "Rock_Ice"
    },
    {
      "x": -35,
      "y": 57,
      "z": -16,
      "name": "Rock_Ice"
    },
    {
      "x": -35,
      "y": 58,
      "z": -16,
      "name": "Rock_Ice"
    },
    {
      "x": -35,
      "y": 59,
      "z": -16,
      "name": "Rock_Ice"
    },
    {
      "x": -35,
      "y": 60,
      "z": -16,
      "name": "Rock_Ice"
    },
    {
      "x": -35,
      "y": 61,
      "z": -16,
      "name": "Rock_Ice"
    },
    {
      "x": -35,
      "y": 62,
      "z": -16,
      "name": "Soil_Snow"
    },
    {
      "x": -35,
      "y": 50,
      "z": -15,
      "name": "Rock_Ice"
    },
    {
      "x": -35,
      "y": 51,
      "z": -15,
      "name": "Rock_Ice"
    },
    {
      "x": -35,
      "y": 52,
      "z": -15,
      "name": "Rock_Ice"
    },
    {
      "x": -35,
      "y": 53,
      "z": -15,
      "name": "Rock_Ice"
    },
    {
      "x": -35,
      "y": 54,
      "z": -15,
      "name": "Rock_Ice"
    },
    {
      "x": -35,
      "y": 55,
      "z": -15,
      "name": "Rock_Ice"
    },
    {
      "x": -35,
      "y": 56,
      "z": -15,
      "name": "Rock_Ice"
    },
    {
      "x": -35,
      "y": 57,
      "z": -15,
      "name": "Rock_Ice"
    },
    {
      "x": -35,
      "y": 58,
      "z": -15,
      "name": "Rock_Ice"
    },
    {
      "x": -35,
      "y": 59,
      "z": -15,
      "name": "Rock_Ice"
    },
    {
      "x": -35,
      "y": 60,
      "z": -15,
      "name": "Rock_Ice"
    },
    {
      "x": -35,
      "y": 61,
      "z": -15,
      "name": "Rock_Ice"
    },
    {
      "x": -35,
      "y": 62,
      "z": -15,
      "name": "Rock_Ice"
    },
    {
      "x": -35,
      "y": 63,
      "z": -15,
      "name": "Rock_Ice"
    },
    {
      "x": -35,
      "y": 64,
      "z": -15,
      "name": "Soil_Snow"
    },
    {
      "x": -35,
      "y": 52,
      "z": -14,
      "name": "Rock_Ice"
    },
    {
      "x": -35,
      "y": 53,
      "z": -14,
      "name": "Rock_Ice"
    },
    {
      "x": -35,
      "y": 54,
      "z": -14,
      "name": "Rock_Ice"
    },
    {
      "x": -35,
      "y": 55,
      "z": -14,
      "name": "Rock_Ice"
    },
    {
      "x": -35,
      "y": 56,
      "z": -14,
      "name": "Rock_Ice"
    },
    {
      "x": -35,
      "y": 57,
      "z": -14,
      "name": "Rock_Ice"
    },
    {
      "x": -35,
      "y": 58,
      "z": -14,
      "name": "Rock_Ice"
    },
    {
      "x": -35,
      "y": 59,
      "z": -14,
      "name": "Rock_Ice"
    },
    {
      "x": -35,
      "y": 60,
      "z": -14,
      "name": "Rock_Ice"
    },
    {
      "x": -35,
      "y": 61,
      "z": -14,
      "name": "Rock_Ice"
    },
    {
      "x": -35,
      "y": 62,
      "z": -14,
      "name": "Rock_Ice"
    },
    {
      "x": -35,
      "y": 63,
      "z": -14,
      "name": "Rock_Ice"
    },
    {
      "x": -35,
      "y": 64,
      "z": -14,
      "name": "Rock_Ice"
    },
    {
      "x": -35,
      "y": 65,
      "z": -14,
      "name": "Soil_Snow"
    },
    {
      "x": -35,
      "y": 54,
      "z": -13,
      "name": "Rock_Ice"
    },
    {
      "x": -35,
      "y": 55,
      "z": -13,
      "name": "Rock_Ice"
    },
    {
      "x": -35,
      "y": 56,
      "z": -13,
      "name": "Rock_Ice"
    },
    {
      "x": -35,
      "y": 57,
      "z": -13,
      "name": "Rock_Ice"
    },
    {
      "x": -35,
      "y": 58,
      "z": -13,
      "name": "Rock_Ice"
    },
    {
      "x": -35,
      "y": 59,
      "z": -13,
      "name": "Rock_Ice"
    },
    {
      "x": -35,
      "y": 60,
      "z": -13,
      "name": "Rock_Ice"
    },
    {
      "x": -35,
      "y": 61,
      "z": -13,
      "name": "Rock_Ice"
    },
    {
      "x": -35,
      "y": 62,
      "z": -13,
      "name": "Rock_Ice"
    },
    {
      "x": -35,
      "y": 63,
      "z": -13,
      "name": "Rock_Ice"
    },
    {
      "x": -35,
      "y": 64,
      "z": -13,
      "name": "Rock_Ice"
    },
    {
      "x": -35,
      "y": 65,
      "z": -13,
      "name": "Rock_Ice"
    },
    {
      "x": -35,
      "y": 66,
      "z": -13,
      "name": "Soil_Snow"
    },
    {
      "x": -35,
      "y": 57,
      "z": -12,
      "name": "Rock_Ice"
    },
    {
      "x": -35,
      "y": 58,
      "z": -12,
      "name": "Rock_Ice"
    },
    {
      "x": -35,
      "y": 59,
      "z": -12,
      "name": "Rock_Ice"
    },
    {
      "x": -35,
      "y": 60,
      "z": -12,
      "name": "Rock_Ice"
    },
    {
      "x": -35,
      "y": 61,
      "z": -12,
      "name": "Rock_Ice"
    },
    {
      "x": -35,
      "y": 62,
      "z": -12,
      "name": "Rock_Ice"
    },
    {
      "x": -35,
      "y": 63,
      "z": -12,
      "name": "Rock_Ice"
    },
    {
      "x": -35,
      "y": 64,
      "z": -12,
      "name": "Rock_Ice"
    },
    {
      "x": -35,
      "y": 65,
      "z": -12,
      "name": "Rock_Ice"
    },
    {
      "x": -35,
      "y": 66,
      "z": -12,
      "name": "Rock_Ice"
    },
    {
      "x": -35,
      "y": 67,
      "z": -12,
      "name": "Soil_Snow"
    },
    {
      "x": -35,
      "y": 59,
      "z": -11,
      "name": "Rock_Ice"
    },
    {
      "x": -35,
      "y": 60,
      "z": -11,
      "name": "Rock_Ice"
    },
    {
      "x": -35,
      "y": 61,
      "z": -11,
      "name": "Rock_Ice"
    },
    {
      "x": -35,
      "y": 62,
      "z": -11,
      "name": "Rock_Ice"
    },
    {
      "x": -35,
      "y": 63,
      "z": -11,
      "name": "Rock_Ice"
    },
    {
      "x": -35,
      "y": 64,
      "z": -11,
      "name": "Rock_Ice"
    },
    {
      "x": -35,
      "y": 65,
      "z": -11,
      "name": "Rock_Ice"
    },
    {
      "x": -35,
      "y": 66,
      "z": -11,
      "name": "Rock_Ice"
    },
    {
      "x": -35,
      "y": 67,
      "z": -11,
      "name": "Rock_Ice"
    },
    {
      "x": -35,
      "y": 68,
      "z": -11,
      "name": "Soil_Snow"
    },
    {
      "x": -35,
      "y": 61,
      "z": -10,
      "name": "Rock_Ice"
    },
    {
      "x": -35,
      "y": 62,
      "z": -10,
      "name": "Rock_Ice"
    },
    {
      "x": -35,
      "y": 63,
      "z": -10,
      "name": "Rock_Ice"
    },
    {
      "x": -35,
      "y": 64,
      "z": -10,
      "name": "Rock_Ice"
    },
    {
      "x": -35,
      "y": 65,
      "z": -10,
      "name": "Rock_Ice"
    },
    {
      "x": -35,
      "y": 66,
      "z": -10,
      "name": "Rock_Ice"
    },
    {
      "x": -35,
      "y": 67,
      "z": -10,
      "name": "Rock_Ice"
    },
    {
      "x": -35,
      "y": 68,
      "z": -10,
      "name": "Rock_Ice"
    },
    {
      "x": -35,
      "y": 69,
      "z": -10,
      "name": "Soil_Snow"
    },
    {
      "x": -35,
      "y": 63,
      "z": -9,
      "name": "Rock_Ice"
    },
    {
      "x": -35,
      "y": 64,
      "z": -9,
      "name": "Rock_Ice"
    },
    {
      "x": -35,
      "y": 65,
      "z": -9,
      "name": "Rock_Ice"
    },
    {
      "x": -35,
      "y": 66,
      "z": -9,
      "name": "Rock_Ice"
    },
    {
      "x": -35,
      "y": 67,
      "z": -9,
      "name": "Rock_Ice"
    },
    {
      "x": -35,
      "y": 68,
      "z": -9,
      "name": "Rock_Ice"
    },
    {
      "x": -35,
      "y": 69,
      "z": -9,
      "name": "Rock_Ice"
    },
    {
      "x": -35,
      "y": 70,
      "z": -9,
      "name": "Soil_Snow"
    },
    {
      "x": -35,
      "y": 66,
      "z": -8,
      "name": "Rock_Ice"
    },
    {
      "x": -35,
      "y": 67,
      "z": -8,
      "name": "Rock_Ice_Permafrost"
    },
    {
      "x": -35,
      "y": 68,
      "z": -8,
      "name": "Rock_Ice_Permafrost"
    },
    {
      "x": -35,
      "y": 69,
      "z": -8,
      "name": "Rock_Ice"
    },
    {
      "x": -35,
      "y": 70,
      "z": -8,
      "name": "Rock_Ice_Permafrost"
    },
    {
      "x": -35,
      "y": 71,
      "z": -8,
      "name": "Rock_Ice_Permafrost"
    },
    {
      "x": -35,
      "y": 69,
      "z": -7,
      "name": "Rock_Ice"
    },
    {
      "x": -35,
      "y": 70,
      "z": -7,
      "name": "Rock_Ice_Permafrost"
    },
    {
      "x": -35,
      "y": 71,
      "z": -7,
      "name": "Rock_Ice"
    },
    {
      "x": -34,
      "y": 44,
      "z": -32,
      "name": "Soil_Snow"
    },
    {
      "x": -34,
      "y": 44,
      "z": -31,
      "name": "Rock_Ice_Permafrost"
    },
    {
      "x": -34,
      "y": 45,
      "z": -31,
      "name": "Rock_Ice"
    },
    {
      "x": -34,
      "y": 46,
      "z": -31,
      "name": "Soil_Snow"
    },
    {
      "x": -34,
      "y": 44,
      "z": -30,
      "name": "Rock_Ice"
    },
    {
      "x": -34,
      "y": 45,
      "z": -30,
      "name": "Rock_Ice_Permafrost"
    },
    {
      "x": -34,
      "y": 46,
      "z": -30,
      "name": "Rock_Ice"
    },
    {
      "x": -34,
      "y": 47,
      "z": -30,
      "name": "Soil_Snow"
    },
    {
      "x": -34,
      "y": 44,
      "z": -29,
      "name": "Rock_Ice"
    },
    {
      "x": -34,
      "y": 45,
      "z": -29,
      "name": "Rock_Ice_Permafrost"
    },
    {
      "x": -34,
      "y": 46,
      "z": -29,
      "name": "Rock_Ice_Permafrost"
    },
    {
      "x": -34,
      "y": 47,
      "z": -29,
      "name": "Rock_Ice_Permafrost"
    },
    {
      "x": -34,
      "y": 48,
      "z": -29,
      "name": "Rock_Ice"
    },
    {
      "x": -34,
      "y": 49,
      "z": -29,
      "name": "Soil_Snow"
    },
    {
      "x": -34,
      "y": 44,
      "z": -28,
      "name": "Rock_Ice"
    },
    {
      "x": -34,
      "y": 45,
      "z": -28,
      "name": "Rock_Ice"
    },
    {
      "x": -34,
      "y": 46,
      "z": -28,
      "name": "Rock_Ice"
    },
    {
      "x": -34,
      "y": 47,
      "z": -28,
      "name": "Rock_Ice"
    },
    {
      "x": -34,
      "y": 48,
      "z": -28,
      "name": "Rock_Ice_Permafrost"
    },
    {
      "x": -34,
      "y": 49,
      "z": -28,
      "name": "Rock_Ice_Permafrost"
    },
    {
      "x": -34,
      "y": 50,
      "z": -28,
      "name": "Soil_Snow"
    },
    {
      "x": -34,
      "y": 44,
      "z": -27,
      "name": "Rock_Ice"
    },
    {
      "x": -34,
      "y": 45,
      "z": -27,
      "name": "Rock_Ice"
    },
    {
      "x": -34,
      "y": 46,
      "z": -27,
      "name": "Rock_Ice"
    },
    {
      "x": -34,
      "y": 47,
      "z": -27,
      "name": "Rock_Ice"
    },
    {
      "x": -34,
      "y": 48,
      "z": -27,
      "name": "Rock_Ice"
    },
    {
      "x": -34,
      "y": 49,
      "z": -27,
      "name": "Rock_Ice"
    },
    {
      "x": -34,
      "y": 50,
      "z": -27,
      "name": "Rock_Ice_Permafrost"
    },
    {
      "x": -34,
      "y": 51,
      "z": -27,
      "name": "Rock_Ice"
    },
    {
      "x": -34,
      "y": 52,
      "z": -27,
      "name": "Soil_Snow"
    },
    {
      "x": -34,
      "y": 44,
      "z": -26,
      "name": "Rock_Ice"
    },
    {
      "x": -34,
      "y": 45,
      "z": -26,
      "name": "Rock_Ice"
    },
    {
      "x": -34,
      "y": 46,
      "z": -26,
      "name": "Rock_Ice"
    },
    {
      "x": -34,
      "y": 47,
      "z": -26,
      "name": "Rock_Ice"
    },
    {
      "x": -34,
      "y": 48,
      "z": -26,
      "name": "Rock_Ice"
    },
    {
      "x": -34,
      "y": 49,
      "z": -26,
      "name": "Rock_Ice"
    },
    {
      "x": -34,
      "y": 50,
      "z": -26,
      "name": "Rock_Ice"
    },
    {
      "x": -34,
      "y": 51,
      "z": -26,
      "name": "Rock_Ice"
    },
    {
      "x": -34,
      "y": 52,
      "z": -26,
      "name": "Rock_Ice"
    },
    {
      "x": -34,
      "y": 53,
      "z": -26,
      "name": "Soil_Snow"
    },
    {
      "x": -34,
      "y": 44,
      "z": -25,
      "name": "Rock_Ice"
    },
    {
      "x": -34,
      "y": 45,
      "z": -25,
      "name": "Rock_Ice"
    },
    {
      "x": -34,
      "y": 46,
      "z": -25,
      "name": "Rock_Ice"
    },
    {
      "x": -34,
      "y": 47,
      "z": -25,
      "name": "Rock_Ice"
    },
    {
      "x": -34,
      "y": 48,
      "z": -25,
      "name": "Rock_Ice"
    },
    {
      "x": -34,
      "y": 49,
      "z": -25,
      "name": "Rock_Ice"
    },
    {
      "x": -34,
      "y": 50,
      "z": -25,
      "name": "Rock_Ice"
    },
    {
      "x": -34,
      "y": 51,
      "z": -25,
      "name": "Rock_Ice"
    },
    {
      "x": -34,
      "y": 52,
      "z": -25,
      "name": "Rock_Ice"
    },
    {
      "x": -34,
      "y": 53,
      "z": -25,
      "name": "Rock_Ice"
    },
    {
      "x": -34,
      "y": 54,
      "z": -25,
      "name": "Soil_Snow"
    },
    {
      "x": -34,
      "y": 44,
      "z": -24,
      "name": "Rock_Ice"
    },
    {
      "x": -34,
      "y": 45,
      "z": -24,
      "name": "Rock_Ice"
    },
    {
      "x": -34,
      "y": 46,
      "z": -24,
      "name": "Rock_Ice"
    },
    {
      "x": -34,
      "y": 47,
      "z": -24,
      "name": "Rock_Ice"
    },
    {
      "x": -34,
      "y": 48,
      "z": -24,
      "name": "Rock_Ice"
    },
    {
      "x": -34,
      "y": 49,
      "z": -24,
      "name": "Rock_Ice"
    },
    {
      "x": -34,
      "y": 50,
      "z": -24,
      "name": "Rock_Ice"
    },
    {
      "x": -34,
      "y": 51,
      "z": -24,
      "name": "Rock_Ice"
    },
    {
      "x": -34,
      "y": 52,
      "z": -24,
      "name": "Rock_Ice"
    },
    {
      "x": -34,
      "y": 53,
      "z": -24,
      "name": "Rock_Ice"
    },
    {
      "x": -34,
      "y": 54,
      "z": -24,
      "name": "Rock_Ice"
    },
    {
      "x": -34,
      "y": 55,
      "z": -24,
      "name": "Rock_Ice"
    },
    {
      "x": -34,
      "y": 56,
      "z": -24,
      "name": "Soil_Snow"
    },
    {
      "x": -34,
      "y": 44,
      "z": -23,
      "name": "Rock_Ice"
    },
    {
      "x": -34,
      "y": 45,
      "z": -23,
      "name": "Rock_Ice"
    },
    {
      "x": -34,
      "y": 46,
      "z": -23,
      "name": "Rock_Ice"
    },
    {
      "x": -34,
      "y": 47,
      "z": -23,
      "name": "Rock_Ice"
    },
    {
      "x": -34,
      "y": 48,
      "z": -23,
      "name": "Rock_Ice"
    },
    {
      "x": -34,
      "y": 49,
      "z": -23,
      "name": "Rock_Ice"
    },
    {
      "x": -34,
      "y": 50,
      "z": -23,
      "name": "Rock_Ice"
    },
    {
      "x": -34,
      "y": 51,
      "z": -23,
      "name": "Rock_Ice"
    },
    {
      "x": -34,
      "y": 52,
      "z": -23,
      "name": "Rock_Ice"
    },
    {
      "x": -34,
      "y": 53,
      "z": -23,
      "name": "Rock_Ice"
    },
    {
      "x": -34,
      "y": 54,
      "z": -23,
      "name": "Rock_Ice"
    },
    {
      "x": -34,
      "y": 55,
      "z": -23,
      "name": "Rock_Ice"
    },
    {
      "x": -34,
      "y": 56,
      "z": -23,
      "name": "Rock_Ice"
    },
    {
      "x": -34,
      "y": 57,
      "z": -23,
      "name": "Soil_Snow"
    },
    {
      "x": -34,
      "y": 44,
      "z": -22,
      "name": "Rock_Ice"
    },
    {
      "x": -34,
      "y": 45,
      "z": -22,
      "name": "Rock_Ice"
    },
    {
      "x": -34,
      "y": 46,
      "z": -22,
      "name": "Rock_Ice"
    },
    {
      "x": -34,
      "y": 47,
      "z": -22,
      "name": "Rock_Ice"
    },
    {
      "x": -34,
      "y": 48,
      "z": -22,
      "name": "Rock_Ice"
    },
    {
      "x": -34,
      "y": 49,
      "z": -22,
      "name": "Rock_Ice"
    },
    {
      "x": -34,
      "y": 50,
      "z": -22,
      "name": "Rock_Ice"
    },
    {
      "x": -34,
      "y": 51,
      "z": -22,
      "name": "Rock_Ice"
    },
    {
      "x": -34,
      "y": 52,
      "z": -22,
      "name": "Rock_Ice"
    },
    {
      "x": -34,
      "y": 53,
      "z": -22,
      "name": "Rock_Ice"
    },
    {
      "x": -34,
      "y": 54,
      "z": -22,
      "name": "Rock_Ice"
    },
    {
      "x": -34,
      "y": 55,
      "z": -22,
      "name": "Rock_Ice"
    },
    {
      "x": -34,
      "y": 56,
      "z": -22,
      "name": "Rock_Ice"
    },
    {
      "x": -34,
      "y": 57,
      "z": -22,
      "name": "Rock_Ice"
    },
    {
      "x": -34,
      "y": 58,
      "z": -22,
      "name": "Soil_Snow"
    },
    {
      "x": -34,
      "y": 44,
      "z": -21,
      "name": "Rock_Ice"
    },
    {
      "x": -34,
      "y": 45,
      "z": -21,
      "name": "Rock_Ice"
    },
    {
      "x": -34,
      "y": 46,
      "z": -21,
      "name": "Rock_Ice"
    },
    {
      "x": -34,
      "y": 47,
      "z": -21,
      "name": "Rock_Ice"
    },
    {
      "x": -34,
      "y": 48,
      "z": -21,
      "name": "Rock_Ice"
    },
    {
      "x": -34,
      "y": 49,
      "z": -21,
      "name": "Rock_Ice"
    },
    {
      "x": -34,
      "y": 50,
      "z": -21,
      "name": "Rock_Ice"
    },
    {
      "x": -34,
      "y": 51,
      "z": -21,
      "name": "Rock_Ice"
    },
    {
      "x": -34,
      "y": 52,
      "z": -21,
      "name": "Rock_Ice"
    },
    {
      "x": -34,
      "y": 53,
      "z": -21,
      "name": "Rock_Ice"
    },
    {
      "x": -34,
      "y": 54,
      "z": -21,
      "name": "Rock_Ice"
    },
    {
      "x": -34,
      "y": 55,
      "z": -21,
      "name": "Rock_Ice"
    },
    {
      "x": -34,
      "y": 56,
      "z": -21,
      "name": "Rock_Ice"
    },
    {
      "x": -34,
      "y": 57,
      "z": -21,
      "name": "Rock_Ice"
    },
    {
      "x": -34,
      "y": 58,
      "z": -21,
      "name": "Rock_Ice"
    },
    {
      "x": -34,
      "y": 59,
      "z": -21,
      "name": "Rock_Ice"
    },
    {
      "x": -34,
      "y": 60,
      "z": -21,
      "name": "Soil_Snow"
    },
    {
      "x": -34,
      "y": 44,
      "z": -20,
      "name": "Rock_Ice"
    },
    {
      "x": -34,
      "y": 45,
      "z": -20,
      "name": "Rock_Ice"
    },
    {
      "x": -34,
      "y": 46,
      "z": -20,
      "name": "Rock_Ice"
    },
    {
      "x": -34,
      "y": 47,
      "z": -20,
      "name": "Rock_Ice"
    },
    {
      "x": -34,
      "y": 48,
      "z": -20,
      "name": "Rock_Ice"
    },
    {
      "x": -34,
      "y": 49,
      "z": -20,
      "name": "Rock_Ice"
    },
    {
      "x": -34,
      "y": 50,
      "z": -20,
      "name": "Rock_Ice"
    },
    {
      "x": -34,
      "y": 51,
      "z": -20,
      "name": "Rock_Ice"
    },
    {
      "x": -34,
      "y": 52,
      "z": -20,
      "name": "Rock_Ice"
    },
    {
      "x": -34,
      "y": 53,
      "z": -20,
      "name": "Rock_Ice"
    },
    {
      "x": -34,
      "y": 54,
      "z": -20,
      "name": "Rock_Ice"
    },
    {
      "x": -34,
      "y": 55,
      "z": -20,
      "name": "Rock_Ice"
    },
    {
      "x": -34,
      "y": 56,
      "z": -20,
      "name": "Rock_Ice"
    },
    {
      "x": -34,
      "y": 57,
      "z": -20,
      "name": "Rock_Ice"
    },
    {
      "x": -34,
      "y": 58,
      "z": -20,
      "name": "Rock_Ice"
    },
    {
      "x": -34,
      "y": 59,
      "z": -20,
      "name": "Rock_Ice"
    },
    {
      "x": -34,
      "y": 60,
      "z": -20,
      "name": "Rock_Ice"
    },
    {
      "x": -34,
      "y": 61,
      "z": -20,
      "name": "Rock_Ice_Permafrost"
    },
    {
      "x": -34,
      "y": 44,
      "z": -19,
      "name": "Rock_Ice"
    },
    {
      "x": -34,
      "y": 45,
      "z": -19,
      "name": "Rock_Ice"
    },
    {
      "x": -34,
      "y": 46,
      "z": -19,
      "name": "Rock_Ice"
    },
    {
      "x": -34,
      "y": 47,
      "z": -19,
      "name": "Rock_Ice"
    },
    {
      "x": -34,
      "y": 48,
      "z": -19,
      "name": "Rock_Ice"
    },
    {
      "x": -34,
      "y": 49,
      "z": -19,
      "name": "Rock_Ice"
    },
    {
      "x": -34,
      "y": 50,
      "z": -19,
      "name": "Rock_Ice"
    },
    {
      "x": -34,
      "y": 51,
      "z": -19,
      "name": "Rock_Ice"
    },
    {
      "x": -34,
      "y": 52,
      "z": -19,
      "name": "Rock_Ice"
    },
    {
      "x": -34,
      "y": 53,
      "z": -19,
      "name": "Rock_Ice"
    },
    {
      "x": -34,
      "y": 54,
      "z": -19,
      "name": "Rock_Ice"
    },
    {
      "x": -34,
      "y": 55,
      "z": -19,
      "name": "Rock_Ice"
    },
    {
      "x": -34,
      "y": 56,
      "z": -19,
      "name": "Rock_Ice"
    },
    {
      "x": -34,
      "y": 57,
      "z": -19,
      "name": "Rock_Ice"
    },
    {
      "x": -34,
      "y": 58,
      "z": -19,
      "name": "Rock_Ice"
    },
    {
      "x": -34,
      "y": 59,
      "z": -19,
      "name": "Rock_Ice"
    },
    {
      "x": -34,
      "y": 60,
      "z": -19,
      "name": "Rock_Ice"
    },
    {
      "x": -34,
      "y": 61,
      "z": -19,
      "name": "Soil_Snow"
    },
    {
      "x": -34,
      "y": 44,
      "z": -18,
      "name": "Rock_Ice"
    },
    {
      "x": -34,
      "y": 45,
      "z": -18,
      "name": "Rock_Ice"
    },
    {
      "x": -34,
      "y": 46,
      "z": -18,
      "name": "Rock_Ice"
    },
    {
      "x": -34,
      "y": 47,
      "z": -18,
      "name": "Rock_Ice"
    },
    {
      "x": -34,
      "y": 48,
      "z": -18,
      "name": "Rock_Ice"
    },
    {
      "x": -34,
      "y": 49,
      "z": -18,
      "name": "Rock_Ice"
    },
    {
      "x": -34,
      "y": 50,
      "z": -18,
      "name": "Rock_Ice"
    },
    {
      "x": -34,
      "y": 51,
      "z": -18,
      "name": "Rock_Ice"
    },
    {
      "x": -34,
      "y": 52,
      "z": -18,
      "name": "Rock_Ice"
    },
    {
      "x": -34,
      "y": 53,
      "z": -18,
      "name": "Rock_Ice"
    },
    {
      "x": -34,
      "y": 54,
      "z": -18,
      "name": "Rock_Ice"
    },
    {
      "x": -34,
      "y": 55,
      "z": -18,
      "name": "Rock_Ice"
    },
    {
      "x": -34,
      "y": 56,
      "z": -18,
      "name": "Rock_Ice"
    },
    {
      "x": -34,
      "y": 57,
      "z": -18,
      "name": "Rock_Ice"
    },
    {
      "x": -34,
      "y": 58,
      "z": -18,
      "name": "Rock_Ice"
    },
    {
      "x": -34,
      "y": 59,
      "z": -18,
      "name": "Rock_Ice"
    },
    {
      "x": -34,
      "y": 60,
      "z": -18,
      "name": "Rock_Ice"
    },
    {
      "x": -34,
      "y": 61,
      "z": -18,
      "name": "Rock_Ice"
    },
    {
      "x": -34,
      "y": 62,
      "z": -18,
      "name": "Soil_Snow"
    },
    {
      "x": -34,
      "y": 44,
      "z": -17,
      "name": "Rock_Ice"
    },
    {
      "x": -34,
      "y": 45,
      "z": -17,
      "name": "Rock_Ice"
    },
    {
      "x": -34,
      "y": 46,
      "z": -17,
      "name": "Rock_Ice"
    },
    {
      "x": -34,
      "y": 47,
      "z": -17,
      "name": "Rock_Ice"
    },
    {
      "x": -34,
      "y": 48,
      "z": -17,
      "name": "Rock_Ice"
    },
    {
      "x": -34,
      "y": 49,
      "z": -17,
      "name": "Rock_Ice"
    },
    {
      "x": -34,
      "y": 50,
      "z": -17,
      "name": "Rock_Ice"
    },
    {
      "x": -34,
      "y": 51,
      "z": -17,
      "name": "Rock_Ice"
    },
    {
      "x": -34,
      "y": 52,
      "z": -17,
      "name": "Rock_Ice"
    },
    {
      "x": -34,
      "y": 53,
      "z": -17,
      "name": "Rock_Ice"
    },
    {
      "x": -34,
      "y": 54,
      "z": -17,
      "name": "Rock_Ice"
    },
    {
      "x": -34,
      "y": 55,
      "z": -17,
      "name": "Rock_Ice"
    },
    {
      "x": -34,
      "y": 56,
      "z": -17,
      "name": "Rock_Ice"
    },
    {
      "x": -34,
      "y": 57,
      "z": -17,
      "name": "Rock_Ice"
    },
    {
      "x": -34,
      "y": 58,
      "z": -17,
      "name": "Rock_Ice"
    },
    {
      "x": -34,
      "y": 59,
      "z": -17,
      "name": "Rock_Ice"
    },
    {
      "x": -34,
      "y": 60,
      "z": -17,
      "name": "Rock_Ice"
    },
    {
      "x": -34,
      "y": 61,
      "z": -17,
      "name": "Rock_Ice"
    },
    {
      "x": -34,
      "y": 62,
      "z": -17,
      "name": "Rock_Ice"
    },
    {
      "x": -34,
      "y": 63,
      "z": -17,
      "name": "Soil_Snow"
    },
    {
      "x": -34,
      "y": 44,
      "z": -16,
      "name": "Rock_Ice"
    },
    {
      "x": -34,
      "y": 45,
      "z": -16,
      "name": "Rock_Ice"
    },
    {
      "x": -34,
      "y": 46,
      "z": -16,
      "name": "Rock_Ice"
    },
    {
      "x": -34,
      "y": 47,
      "z": -16,
      "name": "Rock_Ice"
    },
    {
      "x": -34,
      "y": 48,
      "z": -16,
      "name": "Rock_Ice"
    },
    {
      "x": -34,
      "y": 49,
      "z": -16,
      "name": "Rock_Ice"
    },
    {
      "x": -34,
      "y": 50,
      "z": -16,
      "name": "Rock_Ice"
    },
    {
      "x": -34,
      "y": 51,
      "z": -16,
      "name": "Rock_Ice"
    },
    {
      "x": -34,
      "y": 52,
      "z": -16,
      "name": "Rock_Ice"
    },
    {
      "x": -34,
      "y": 53,
      "z": -16,
      "name": "Rock_Ice"
    },
    {
      "x": -34,
      "y": 54,
      "z": -16,
      "name": "Rock_Ice"
    },
    {
      "x": -34,
      "y": 55,
      "z": -16,
      "name": "Rock_Ice"
    },
    {
      "x": -34,
      "y": 56,
      "z": -16,
      "name": "Rock_Ice"
    },
    {
      "x": -34,
      "y": 57,
      "z": -16,
      "name": "Rock_Ice"
    },
    {
      "x": -34,
      "y": 58,
      "z": -16,
      "name": "Rock_Ice"
    },
    {
      "x": -34,
      "y": 59,
      "z": -16,
      "name": "Rock_Ice"
    },
    {
      "x": -34,
      "y": 60,
      "z": -16,
      "name": "Rock_Ice"
    },
    {
      "x": -34,
      "y": 61,
      "z": -16,
      "name": "Rock_Ice"
    },
    {
      "x": -34,
      "y": 62,
      "z": -16,
      "name": "Rock_Ice"
    },
    {
      "x": -34,
      "y": 63,
      "z": -16,
      "name": "Rock_Ice"
    },
    {
      "x": -34,
      "y": 64,
      "z": -16,
      "name": "Soil_Snow"
    },
    {
      "x": -34,
      "y": 44,
      "z": -15,
      "name": "Rock_Ice"
    },
    {
      "x": -34,
      "y": 45,
      "z": -15,
      "name": "Rock_Ice"
    },
    {
      "x": -34,
      "y": 46,
      "z": -15,
      "name": "Rock_Ice"
    },
    {
      "x": -34,
      "y": 47,
      "z": -15,
      "name": "Rock_Ice"
    },
    {
      "x": -34,
      "y": 48,
      "z": -15,
      "name": "Rock_Ice"
    },
    {
      "x": -34,
      "y": 49,
      "z": -15,
      "name": "Rock_Ice"
    },
    {
      "x": -34,
      "y": 50,
      "z": -15,
      "name": "Rock_Ice"
    },
    {
      "x": -34,
      "y": 51,
      "z": -15,
      "name": "Rock_Ice"
    },
    {
      "x": -34,
      "y": 52,
      "z": -15,
      "name": "Rock_Ice"
    },
    {
      "x": -34,
      "y": 53,
      "z": -15,
      "name": "Rock_Ice"
    },
    {
      "x": -34,
      "y": 54,
      "z": -15,
      "name": "Rock_Ice"
    },
    {
      "x": -34,
      "y": 55,
      "z": -15,
      "name": "Rock_Ice"
    },
    {
      "x": -34,
      "y": 56,
      "z": -15,
      "name": "Rock_Ice"
    },
    {
      "x": -34,
      "y": 57,
      "z": -15,
      "name": "Rock_Ice"
    },
    {
      "x": -34,
      "y": 58,
      "z": -15,
      "name": "Rock_Ice"
    },
    {
      "x": -34,
      "y": 59,
      "z": -15,
      "name": "Rock_Ice"
    },
    {
      "x": -34,
      "y": 60,
      "z": -15,
      "name": "Rock_Ice"
    },
    {
      "x": -34,
      "y": 61,
      "z": -15,
      "name": "Rock_Ice"
    },
    {
      "x": -34,
      "y": 62,
      "z": -15,
      "name": "Rock_Ice"
    },
    {
      "x": -34,
      "y": 63,
      "z": -15,
      "name": "Rock_Ice"
    },
    {
      "x": -34,
      "y": 64,
      "z": -15,
      "name": "Rock_Ice"
    },
    {
      "x": -34,
      "y": 65,
      "z": -15,
      "name": "Soil_Snow"
    },
    {
      "x": -34,
      "y": 45,
      "z": -14,
      "name": "Rock_Ice"
    },
    {
      "x": -34,
      "y": 46,
      "z": -14,
      "name": "Rock_Ice"
    },
    {
      "x": -34,
      "y": 47,
      "z": -14,
      "name": "Rock_Ice"
    },
    {
      "x": -34,
      "y": 48,
      "z": -14,
      "name": "Rock_Ice"
    },
    {
      "x": -34,
      "y": 49,
      "z": -14,
      "name": "Rock_Ice"
    },
    {
      "x": -34,
      "y": 50,
      "z": -14,
      "name": "Rock_Ice"
    },
    {
      "x": -34,
      "y": 51,
      "z": -14,
      "name": "Rock_Ice"
    },
    {
      "x": -34,
      "y": 52,
      "z": -14,
      "name": "Rock_Ice"
    },
    {
      "x": -34,
      "y": 53,
      "z": -14,
      "name": "Rock_Ice"
    },
    {
      "x": -34,
      "y": 54,
      "z": -14,
      "name": "Rock_Ice"
    },
    {
      "x": -34,
      "y": 55,
      "z": -14,
      "name": "Rock_Ice"
    },
    {
      "x": -34,
      "y": 56,
      "z": -14,
      "name": "Rock_Ice"
    },
    {
      "x": -34,
      "y": 57,
      "z": -14,
      "name": "Rock_Ice"
    },
    {
      "x": -34,
      "y": 58,
      "z": -14,
      "name": "Rock_Ice"
    },
    {
      "x": -34,
      "y": 59,
      "z": -14,
      "name": "Rock_Ice"
    },
    {
      "x": -34,
      "y": 60,
      "z": -14,
      "name": "Rock_Ice"
    },
    {
      "x": -34,
      "y": 61,
      "z": -14,
      "name": "Rock_Ice"
    },
    {
      "x": -34,
      "y": 62,
      "z": -14,
      "name": "Rock_Ice"
    },
    {
      "x": -34,
      "y": 63,
      "z": -14,
      "name": "Rock_Ice"
    },
    {
      "x": -34,
      "y": 64,
      "z": -14,
      "name": "Rock_Ice"
    },
    {
      "x": -34,
      "y": 65,
      "z": -14,
      "name": "Rock_Ice"
    },
    {
      "x": -34,
      "y": 66,
      "z": -14,
      "name": "Soil_Snow"
    },
    {
      "x": -34,
      "y": 47,
      "z": -13,
      "name": "Rock_Ice_Permafrost"
    },
    {
      "x": -34,
      "y": 48,
      "z": -13,
      "name": "Rock_Ice"
    },
    {
      "x": -34,
      "y": 49,
      "z": -13,
      "name": "Rock_Ice"
    },
    {
      "x": -34,
      "y": 50,
      "z": -13,
      "name": "Rock_Ice"
    },
    {
      "x": -34,
      "y": 51,
      "z": -13,
      "name": "Rock_Ice"
    },
    {
      "x": -34,
      "y": 52,
      "z": -13,
      "name": "Rock_Ice"
    },
    {
      "x": -34,
      "y": 53,
      "z": -13,
      "name": "Rock_Ice"
    },
    {
      "x": -34,
      "y": 54,
      "z": -13,
      "name": "Rock_Ice"
    },
    {
      "x": -34,
      "y": 55,
      "z": -13,
      "name": "Rock_Ice"
    },
    {
      "x": -34,
      "y": 56,
      "z": -13,
      "name": "Rock_Ice"
    },
    {
      "x": -34,
      "y": 57,
      "z": -13,
      "name": "Rock_Ice"
    },
    {
      "x": -34,
      "y": 58,
      "z": -13,
      "name": "Rock_Ice"
    },
    {
      "x": -34,
      "y": 59,
      "z": -13,
      "name": "Rock_Ice"
    },
    {
      "x": -34,
      "y": 60,
      "z": -13,
      "name": "Rock_Ice"
    },
    {
      "x": -34,
      "y": 61,
      "z": -13,
      "name": "Rock_Ice"
    },
    {
      "x": -34,
      "y": 62,
      "z": -13,
      "name": "Rock_Ice"
    },
    {
      "x": -34,
      "y": 63,
      "z": -13,
      "name": "Rock_Ice"
    },
    {
      "x": -34,
      "y": 64,
      "z": -13,
      "name": "Rock_Ice"
    },
    {
      "x": -34,
      "y": 65,
      "z": -13,
      "name": "Rock_Ice"
    },
    {
      "x": -34,
      "y": 66,
      "z": -13,
      "name": "Rock_Ice"
    },
    {
      "x": -34,
      "y": 67,
      "z": -13,
      "name": "Soil_Snow"
    },
    {
      "x": -34,
      "y": 52,
      "z": -12,
      "name": "Rock_Ice"
    },
    {
      "x": -34,
      "y": 53,
      "z": -12,
      "name": "Rock_Ice"
    },
    {
      "x": -34,
      "y": 54,
      "z": -12,
      "name": "Rock_Ice"
    },
    {
      "x": -34,
      "y": 55,
      "z": -12,
      "name": "Rock_Ice"
    },
    {
      "x": -34,
      "y": 56,
      "z": -12,
      "name": "Rock_Ice"
    },
    {
      "x": -34,
      "y": 57,
      "z": -12,
      "name": "Rock_Ice"
    },
    {
      "x": -34,
      "y": 58,
      "z": -12,
      "name": "Rock_Ice"
    },
    {
      "x": -34,
      "y": 59,
      "z": -12,
      "name": "Rock_Ice"
    },
    {
      "x": -34,
      "y": 60,
      "z": -12,
      "name": "Rock_Ice"
    },
    {
      "x": -34,
      "y": 61,
      "z": -12,
      "name": "Rock_Ice"
    },
    {
      "x": -34,
      "y": 62,
      "z": -12,
      "name": "Rock_Ice"
    },
    {
      "x": -34,
      "y": 63,
      "z": -12,
      "name": "Rock_Ice"
    },
    {
      "x": -34,
      "y": 64,
      "z": -12,
      "name": "Rock_Ice"
    },
    {
      "x": -34,
      "y": 65,
      "z": -12,
      "name": "Rock_Ice"
    },
    {
      "x": -34,
      "y": 66,
      "z": -12,
      "name": "Rock_Ice"
    },
    {
      "x": -34,
      "y": 67,
      "z": -12,
      "name": "Rock_Ice"
    },
    {
      "x": -34,
      "y": 68,
      "z": -12,
      "name": "Soil_Snow"
    },
    {
      "x": -34,
      "y": 55,
      "z": -11,
      "name": "Rock_Ice"
    },
    {
      "x": -34,
      "y": 56,
      "z": -11,
      "name": "Rock_Ice"
    },
    {
      "x": -34,
      "y": 57,
      "z": -11,
      "name": "Rock_Ice"
    },
    {
      "x": -34,
      "y": 58,
      "z": -11,
      "name": "Rock_Ice"
    },
    {
      "x": -34,
      "y": 59,
      "z": -11,
      "name": "Rock_Ice"
    },
    {
      "x": -34,
      "y": 60,
      "z": -11,
      "name": "Rock_Ice"
    },
    {
      "x": -34,
      "y": 61,
      "z": -11,
      "name": "Rock_Ice"
    },
    {
      "x": -34,
      "y": 62,
      "z": -11,
      "name": "Rock_Ice"
    },
    {
      "x": -34,
      "y": 63,
      "z": -11,
      "name": "Rock_Ice"
    },
    {
      "x": -34,
      "y": 64,
      "z": -11,
      "name": "Rock_Ice"
    },
    {
      "x": -34,
      "y": 65,
      "z": -11,
      "name": "Rock_Ice"
    },
    {
      "x": -34,
      "y": 66,
      "z": -11,
      "name": "Rock_Ice"
    },
    {
      "x": -34,
      "y": 67,
      "z": -11,
      "name": "Rock_Ice"
    },
    {
      "x": -34,
      "y": 68,
      "z": -11,
      "name": "Rock_Ice"
    },
    {
      "x": -34,
      "y": 69,
      "z": -11,
      "name": "Soil_Snow"
    },
    {
      "x": -34,
      "y": 58,
      "z": -10,
      "name": "Rock_Ice"
    },
    {
      "x": -34,
      "y": 59,
      "z": -10,
      "name": "Rock_Ice"
    },
    {
      "x": -34,
      "y": 60,
      "z": -10,
      "name": "Rock_Ice"
    },
    {
      "x": -34,
      "y": 61,
      "z": -10,
      "name": "Rock_Ice"
    },
    {
      "x": -34,
      "y": 62,
      "z": -10,
      "name": "Rock_Ice"
    },
    {
      "x": -34,
      "y": 63,
      "z": -10,
      "name": "Rock_Ice"
    },
    {
      "x": -34,
      "y": 64,
      "z": -10,
      "name": "Rock_Ice"
    },
    {
      "x": -34,
      "y": 65,
      "z": -10,
      "name": "Rock_Ice"
    },
    {
      "x": -34,
      "y": 66,
      "z": -10,
      "name": "Rock_Ice"
    },
    {
      "x": -34,
      "y": 67,
      "z": -10,
      "name": "Rock_Ice"
    },
    {
      "x": -34,
      "y": 68,
      "z": -10,
      "name": "Rock_Ice"
    },
    {
      "x": -34,
      "y": 69,
      "z": -10,
      "name": "Rock_Ice"
    },
    {
      "x": -34,
      "y": 70,
      "z": -10,
      "name": "Soil_Snow"
    },
    {
      "x": -34,
      "y": 61,
      "z": -9,
      "name": "Rock_Ice"
    },
    {
      "x": -34,
      "y": 62,
      "z": -9,
      "name": "Rock_Ice"
    },
    {
      "x": -34,
      "y": 63,
      "z": -9,
      "name": "Rock_Ice"
    },
    {
      "x": -34,
      "y": 64,
      "z": -9,
      "name": "Rock_Ice"
    },
    {
      "x": -34,
      "y": 65,
      "z": -9,
      "name": "Rock_Ice"
    },
    {
      "x": -34,
      "y": 66,
      "z": -9,
      "name": "Rock_Ice"
    },
    {
      "x": -34,
      "y": 67,
      "z": -9,
      "name": "Rock_Ice"
    },
    {
      "x": -34,
      "y": 68,
      "z": -9,
      "name": "Rock_Ice"
    },
    {
      "x": -34,
      "y": 69,
      "z": -9,
      "name": "Rock_Ice"
    },
    {
      "x": -34,
      "y": 70,
      "z": -9,
      "name": "Rock_Ice"
    },
    {
      "x": -34,
      "y": 71,
      "z": -9,
      "name": "Rock_Ice"
    },
    {
      "x": -34,
      "y": 72,
      "z": -9,
      "name": "Soil_Snow"
    },
    {
      "x": -34,
      "y": 63,
      "z": -8,
      "name": "Rock_Ice"
    },
    {
      "x": -34,
      "y": 64,
      "z": -8,
      "name": "Rock_Ice"
    },
    {
      "x": -34,
      "y": 65,
      "z": -8,
      "name": "Rock_Ice"
    },
    {
      "x": -34,
      "y": 66,
      "z": -8,
      "name": "Rock_Ice"
    },
    {
      "x": -34,
      "y": 67,
      "z": -8,
      "name": "Rock_Ice"
    },
    {
      "x": -34,
      "y": 68,
      "z": -8,
      "name": "Rock_Ice"
    },
    {
      "x": -34,
      "y": 69,
      "z": -8,
      "name": "Rock_Ice"
    },
    {
      "x": -34,
      "y": 70,
