{
  "version": 8,
  "blockIdVersion": 11,
  "anchorX": 2,
  "anchorY": 36,
  "anchorZ": -1,
  "blocks": [
    {
      "x": -48,
      "y": 43,
      "z": -23,
      "name": "Soil_Snow"
    },
    {
      "x": -47,
      "y": 43,
      "z": -24,
      "name": "Rock_Ice"
    },
    {
      "x": -47,
      "y": 44,
      "z": -24,
      "name": "Soil_Snow"
    },
    {
      "x": -47,
      "y": 43,
      "z": -23,
      "name": "Rock_Ice"
    },
    {
      "x": -47,
      "y": 44,
      "z": -23,
      "name": "Soil_Snow"
    },
    {
      "x": -47,
      "y": 3,
      "z": 13,
      "name": "Soil_Snow"
    },
    {
      "x": -47,
      "y": 2,
      "z": 14,
      "name": "Rock_Ice_Permafrost"
    },
    {
      "x": -47,
      "y": 3,
      "z": 14,
      "name": "Soil_Snow"
    },
    {
      "x": -47,
      "y": 2,
      "z": 15,
      "name": "Rock_Ice"
    },
    {
      "x": -47,
      "y": 3,
      "z": 15,
      "name": "Soil_Snow"
    },
    {
      "x": -47,
      "y": 2,
      "z": 16,
      "name": "Rock_Ice_Permafrost"
    },
    {
      "x": -47,
      "y": 3,
      "z": 16,
      "name": "Soil_Snow"
    },
    {
      "x": -47,
      "y": 2,
      "z": 17,
      "name": "Rock_Ice_Permafrost"
    },
    {
      "x": -47,
      "y": 3,
      "z": 17,
      "name": "Soil_Snow"
    },
    {
      "x": -47,
      "y": 2,
      "z": 18,
      "name": "Rock_Ice_Permafrost"
    },
    {
      "x": -47,
      "y": 3,
      "z": 18,
      "name": "Rock_Ice_Permafrost"
    },
    {
      "x": -47,
      "y": 4,
      "z": 18,
      "name": "Soil_Snow"
    },
    {
      "x": -47,
      "y": 2,
      "z": 19,
      "name": "Rock_Ice_Permafrost"
    },
    {
      "x": -47,
      "y": 3,
      "z": 19,
      "name": "Rock_Ice_Permafrost"
    },
    {
      "x": -47,
      "y": 4,
      "z": 19,
      "name": "Soil_Snow"
    },
    {
      "x": -47,
      "y": 2,
      "z": 20,
      "name": "Rock_Ice_Permafrost"
    },
    {
      "x": -47,
      "y": 3,
      "z": 20,
      "name": "Soil_Snow"
    },
    {
      "x": -47,
      "y": 2,
      "z": 21,
      "name": "Rock_Ice_Permafrost"
    },
    {
      "x": -47,
      "y": 3,
      "z": 21,
      "name": "Soil_Snow"
    },
    {
      "x": -46,
      "y": 42,
      "z": -25,
      "name": "Rock_Ice"
    },
    {
      "x": -46,
      "y": 43,
      "z": -25,
      "name": "Soil_Snow"
    },
    {
      "x": -46,
      "y": 42,
      "z": -24,
      "name": "Rock_Ice_Permafrost"
    },
    {
      "x": -46,
      "y": 43,
      "z": -24,
      "name": "Rock_Ice"
    },
    {
      "x": -46,
      "y": 44,
      "z": -24,
      "name": "Rock_Ice_Permafrost"
    },
    {
      "x": -46,
      "y": 43,
      "z": -23,
      "name": "Rock_Ice_Permafrost"
    },
    {
      "x": -46,
      "y": 44,
      "z": -23,
      "name": "Rock_Ice"
    },
    {
      "x": -46,
      "y": 45,
      "z": -23,
      "name": "Soil_Snow"
    },
    {
      "x": -46,
      "y": 43,
      "z": -22,
      "name": "Rock_Ice_Permafrost"
    },
    {
      "x": -46,
      "y": 44,
      "z": -22,
      "name": "Soil_Snow"
    },
    {
      "x": -46,
      "y": 2,
      "z": 9,
      "name": "Rock_Ice"
    },
    {
      "x": -46,
      "y": 3,
      "z": 9,
      "name": "Rock_Ice"
    },
    {
      "x": -46,
      "y": 4,
      "z": 9,
      "name": "Rock_Ice_Permafrost"
    },
    {
      "x": -46,
      "y": 5,
      "z": 9,
      "name": "Soil_Snow"
    },
    {
      "x": -46,
      "y": 2,
      "z": 10,
      "name": "Rock_Ice"
    },
    {
      "x": -46,
      "y": 3,
      "z": 10,
      "name": "Rock_Ice_Permafrost"
    },
    {
      "x": -46,
      "y": 4,
      "z": 10,
      "name": "Rock_Ice_Permafrost"
    },
    {
      "x": -46,
      "y": 5,
      "z": 10,
      "name": "Soil_Snow"
    },
    {
      "x": -46,
      "y": 2,
      "z": 11,
      "name": "Rock_Ice"
    },
    {
      "x": -46,
      "y": 3,
      "z": 11,
      "name": "Rock_Ice"
    },
    {
      "x": -46,
      "y": 4,
      "z": 11,
      "name": "Rock_Ice_Permafrost"
    },
    {
      "x": -46,
      "y": 5,
      "z": 11,
      "name": "Rock_Ice_Permafrost"
    },
    {
      "x": -46,
      "y": 6,
      "z": 11,
      "name": "Soil_Snow"
    },
    {
      "x": -46,
      "y": 2,
      "z": 12,
      "name": "Rock_Ice"
    },
    {
      "x": -46,
      "y": 3,
      "z": 12,
      "name": "Rock_Ice_Permafrost"
    },
    {
      "x": -46,
      "y": 4,
      "z": 12,
      "name": "Rock_Ice"
    },
    {
      "x": -46,
      "y": 5,
      "z": 12,
      "name": "Rock_Ice_Permafrost"
    },
    {
      "x": -46,
      "y": 6,
      "z": 12,
      "name": "Soil_Snow"
    },
    {
      "x": -46,
      "y": 2,
      "z": 13,
      "name": "Rock_Ice"
    },
    {
      "x": -46,
      "y": 3,
      "z": 13,
      "name": "Rock_Ice_Permafrost"
    },
    {
      "x": -46,
      "y": 4,
      "z": 13,
      "name": "Rock_Ice"
    },
    {
      "x": -46,
      "y": 5,
      "z": 13,
      "name": "Rock_Ice_Permafrost"
    },
    {
      "x": -46,
      "y": 6,
      "z": 13,
      "name": "Soil_Snow"
    },
    {
      "x": -46,
      "y": 2,
      "z": 14,
      "name": "Rock_Ice_Permafrost"
    },
    {
      "x": -46,
      "y": 3,
      "z": 14,
      "name": "Rock_Ice_Permafrost"
    },
    {
      "x": -46,
      "y": 4,
      "z": 14,
      "name": "Rock_Ice_Permafrost"
    },
    {
      "x": -46,
      "y": 5,
      "z": 14,
      "name": "Rock_Ice_Permafrost"
    },
    {
      "x": -46,
      "y": 6,
      "z": 14,
      "name": "Soil_Snow"
    },
    {
      "x": -46,
      "y": 1,
      "z": 15,
      "name": "Rock_Ice"
    },
    {
      "x": -46,
      "y": 2,
      "z": 15,
      "name": "Rock_Ice_Permafrost"
    },
    {
      "x": -46,
      "y": 3,
      "z": 15,
      "name": "Rock_Ice_Permafrost"
    },
    {
      "x": -46,
      "y": 4,
      "z": 15,
      "name": "Rock_Ice"
    },
    {
      "x": -46,
      "y": 5,
      "z": 15,
      "name": "Rock_Ice_Permafrost"
    },
    {
      "x": -46,
      "y": 6,
      "z": 15,
      "name": "Rock_Ice_Permafrost"
    },
    {
      "x": -46,
      "y": 7,
      "z": 15,
      "name": "Soil_Snow"
    },
    {
      "x": -46,
      "y": 1,
      "z": 16,
      "name": "Rock_Ice"
    },
    {
      "x": -46,
      "y": 2,
      "z": 16,
      "name": "Rock_Ice_Permafrost"
    },
    {
      "x": -46,
      "y": 3,
      "z": 16,
      "name": "Rock_Ice_Permafrost"
    },
    {
      "x": -46,
      "y": 4,
      "z": 16,
      "name": "Rock_Ice_Permafrost"
    },
    {
      "x": -46,
      "y": 5,
      "z": 16,
      "name": "Rock_Ice_Permafrost"
    },
    {
      "x": -46,
      "y": 6,
      "z": 16,
      "name": "Rock_Ice_Permafrost"
    },
    {
      "x": -46,
      "y": 7,
      "z": 16,
      "name": "Soil_Snow"
    },
    {
      "x": -46,
      "y": 1,
      "z": 17,
      "name": "Rock_Ice"
    },
    {
      "x": -46,
      "y": 2,
      "z": 17,
      "name": "Rock_Ice_Permafrost"
    },
    {
      "x": -46,
      "y": 3,
      "z": 17,
      "name": "Rock_Ice_Permafrost"
    },
    {
      "x": -46,
      "y": 4,
      "z": 17,
      "name": "Rock_Ice_Permafrost"
    },
    {
      "x": -46,
      "y": 5,
      "z": 17,
      "name": "Rock_Ice_Permafrost"
    },
    {
      "x": -46,
      "y": 6,
      "z": 17,
      "name": "Soil_Snow"
    },
    {
      "x": -46,
      "y": 1,
      "z": 18,
      "name": "Rock_Ice"
    },
    {
      "x": -46,
      "y": 2,
      "z": 18,
      "name": "Rock_Ice_Permafrost"
    },
    {
      "x": -46,
      "y": 3,
      "z": 18,
      "name": "Rock_Ice_Permafrost"
    },
    {
      "x": -46,
      "y": 4,
      "z": 18,
      "name": "Rock_Ice_Permafrost"
    },
    {
      "x": -46,
      "y": 5,
      "z": 18,
      "name": "Rock_Ice_Permafrost"
    },
    {
      "x": -46,
      "y": 6,
      "z": 18,
      "name": "Soil_Snow"
    },
    {
      "x": -46,
      "y": 1,
      "z": 19,
      "name": "Rock_Ice_Permafrost"
    },
    {
      "x": -46,
      "y": 2,
      "z": 19,
      "name": "Rock_Ice_Permafrost"
    },
    {
      "x": -46,
      "y": 3,
      "z": 19,
      "name": "Rock_Ice_Permafrost"
    },
    {
      "x": -46,
      "y": 4,
      "z": 19,
      "name": "Rock_Ice_Permafrost"
    },
    {
      "x": -46,
      "y": 5,
      "z": 19,
      "name": "Soil_Snow"
    },
    {
      "x": -46,
      "y": 1,
      "z": 20,
      "name": "Rock_Ice_Permafrost"
    },
    {
      "x": -46,
      "y": 2,
      "z": 20,
      "name": "Rock_Ice_Permafrost"
    },
    {
      "x": -46,
      "y": 3,
      "z": 20,
      "name": "Rock_Ice_Permafrost"
    },
    {
      "x": -46,
      "y": 4,
      "z": 20,
      "name": "Rock_Ice_Permafrost"
    },
    {
      "x": -46,
      "y": 5,
      "z": 20,
      "name": "Soil_Snow"
    },
    {
      "x": -46,
      "y": 1,
      "z": 21,
      "name": "Rock_Ice_Permafrost"
    },
    {
      "x": -46,
      "y": 2,
      "z": 21,
      "name": "Rock_Ice_Permafrost"
    },
    {
      "x": -46,
      "y": 3,
      "z": 21,
      "name": "Rock_Ice_Permafrost"
    },
    {
      "x": -46,
      "y": 4,
      "z": 21,
      "name": "Rock_Ice_Permafrost"
    },
    {
      "x": -46,
      "y": 5,
      "z": 21,
      "name": "Soil_Snow"
    },
    {
      "x": -46,
      "y": 1,
      "z": 22,
      "name": "Rock_Ice_Permafrost"
    },
    {
      "x": -46,
      "y": 2,
      "z": 22,
      "name": "Rock_Ice_Permafrost"
    },
    {
      "x": -46,
      "y": 3,
      "z": 22,
      "name": "Rock_Ice"
    },
    {
      "x": -46,
      "y": 4,
      "z": 22,
      "name": "Soil_Snow"
    },
    {
      "x": -46,
      "y": 0,
      "z": 23,
      "name": "Rock_Ice_Permafrost"
    },
    {
      "x": -46,
      "y": 1,
      "z": 23,
      "name": "Rock_Ice_Permafrost"
    },
    {
      "x": -46,
      "y": 2,
      "z": 23,
      "name": "Rock_Ice"
    },
    {
      "x": -46,
      "y": 3,
      "z": 23,
      "name": "Soil_Snow"
    },
    {
      "x": -46,
      "y": 1,
      "z": 24,
      "name": "Soil_Snow"
    },
    {
      "x": -45,
      "y": 41,
      "z": -26,
      "name": "Rock_Ice"
    },
    {
      "x": -45,
      "y": 42,
      "z": -26,
      "name": "Soil_Snow"
    },
    {
      "x": -45,
      "y": 41,
      "z": -25,
      "name": "Rock_Ice"
    },
    {
      "x": -45,
      "y": 42,
      "z": -25,
      "name": "Rock_Ice"
    },
    {
      "x": -45,
      "y": 43,
      "z": -25,
      "name": "Soil_Snow"
    },
    {
      "x": -45,
      "y": 42,
      "z": -24,
      "name": "Rock_Ice_Permafrost"
    },
    {
      "x": -45,
      "y": 43,
      "z": -24,
      "name": "Rock_Ice_Permafrost"
    },
    {
      "x": -45,
      "y": 44,
      "z": -24,
      "name": "Rock_Ice"
    },
    {
      "x": -45,
      "y": 45,
      "z": -24,
      "name": "Soil_Snow"
    },
    {
      "x": -45,
      "y": 42,
      "z": -23,
      "name": "Rock_Ice"
    },
    {
      "x": -45,
      "y": 43,
      "z": -23,
      "name": "Rock_Ice_Permafrost"
    },
    {
      "x": -45,
      "y": 44,
      "z": -23,
      "name": "Rock_Ice"
    },
    {
      "x": -45,
      "y": 45,
      "z": -23,
      "name": "Rock_Ice"
    },
    {
      "x": -45,
      "y": 46,
      "z": -23,
      "name": "Soil_Snow"
    },
    {
      "x": -45,
      "y": 43,
      "z": -22,
      "name": "Rock_Ice"
    },
    {
      "x": -45,
      "y": 44,
      "z": -22,
      "name": "Rock_Ice"
    },
    {
      "x": -45,
      "y": 45,
      "z": -22,
      "name": "Soil_Snow"
    },
    {
      "x": -45,
      "y": 3,
      "z": 6,
      "name": "Rock_Ice"
    },
    {
      "x": -45,
      "y": 6,
      "z": 6,
      "name": "Rock_Ice"
    },
    {
      "x": -45,
      "y": 7,
      "z": 6,
      "name": "Soil_Snow"
    },
    {
      "x": -45,
      "y": 3,
      "z": 7,
      "name": "Rock_Ice"
    },
    {
      "x": -45,
      "y": 4,
      "z": 7,
      "name": "Rock_Ice"
    },
    {
      "x": -45,
      "y": 5,
      "z": 7,
      "name": "Rock_Ice"
    },
    {
      "x": -45,
      "y": 6,
      "z": 7,
      "name": "Rock_Ice_Permafrost"
    },
    {
      "x": -45,
      "y": 7,
      "z": 7,
      "name": "Soil_Snow"
    },
    {
      "x": -45,
      "y": 3,
      "z": 8,
      "name": "Rock_Ice"
    },
    {
      "x": -45,
      "y": 4,
      "z": 8,
      "name": "Rock_Ice"
    },
    {
      "x": -45,
      "y": 5,
      "z": 8,
      "name": "Rock_Ice"
    },
    {
      "x": -45,
      "y": 6,
      "z": 8,
      "name": "Rock_Ice"
    },
    {
      "x": -45,
      "y": 7,
      "z": 8,
      "name": "Soil_Snow"
    },
    {
      "x": -45,
      "y": 2,
      "z": 9,
      "name": "Rock_Ice"
    },
    {
      "x": -45,
      "y": 3,
      "z": 9,
      "name": "Rock_Ice"
    },
    {
      "x": -45,
      "y": 4,
      "z": 9,
      "name": "Rock_Ice"
    },
    {
      "x": -45,
      "y": 5,
      "z": 9,
      "name": "Rock_Ice"
    },
    {
      "x": -45,
      "y": 6,
      "z": 9,
      "name": "Rock_Ice_Permafrost"
    },
    {
      "x": -45,
      "y": 7,
      "z": 9,
      "name": "Soil_Snow"
    },
    {
      "x": -45,
      "y": 2,
      "z": 10,
      "name": "Rock_Ice_Permafrost"
    },
    {
      "x": -45,
      "y": 3,
      "z": 10,
      "name": "Rock_Ice"
    },
    {
      "x": -45,
      "y": 4,
      "z": 10,
      "name": "Rock_Ice"
    },
    {
      "x": -45,
      "y": 5,
      "z": 10,
      "name": "Rock_Ice"
    },
    {
      "x": -45,
      "y": 6,
      "z": 10,
      "name": "Rock_Ice_Permafrost"
    },
    {
      "x": -45,
      "y": 7,
      "z": 10,
      "name": "Rock_Ice"
    },
    {
      "x": -45,
      "y": 8,
      "z": 10,
      "name": "Soil_Snow"
    },
    {
      "x": -45,
      "y": 2,
      "z": 11,
      "name": "Rock_Ice_Permafrost"
    },
    {
      "x": -45,
      "y": 3,
      "z": 11,
      "name": "Rock_Ice"
    },
    {
      "x": -45,
      "y": 4,
      "z": 11,
      "name": "Rock_Ice"
    },
    {
      "x": -45,
      "y": 5,
      "z": 11,
      "name": "Rock_Ice"
    },
    {
      "x": -45,
      "y": 6,
      "z": 11,
      "name": "Rock_Ice_Permafrost"
    },
    {
      "x": -45,
      "y": 7,
      "z": 11,
      "name": "Rock_Ice"
    },
    {
      "x": -45,
      "y": 8,
      "z": 11,
      "name": "Soil_Snow"
    },
    {
      "x": -45,
      "y": 2,
      "z": 12,
      "name": "Rock_Ice"
    },
    {
      "x": -45,
      "y": 3,
      "z": 12,
      "name": "Rock_Ice_Permafrost"
    },
    {
      "x": -45,
      "y": 4,
      "z": 12,
      "name": "Rock_Ice"
    },
    {
      "x": -45,
      "y": 5,
      "z": 12,
      "name": "Rock_Ice_Permafrost"
    },
    {
      "x": -45,
      "y": 6,
      "z": 12,
      "name": "Rock_Ice_Permafrost"
    },
    {
      "x": -45,
      "y": 7,
      "z": 12,
      "name": "Rock_Ice"
    },
    {
      "x": -45,
      "y": 8,
      "z": 12,
      "name": "Soil_Snow"
    },
    {
      "x": -45,
      "y": 2,
      "z": 13,
      "name": "Rock_Ice_Permafrost"
    },
    {
      "x": -45,
      "y": 3,
      "z": 13,
      "name": "Rock_Ice_Permafrost"
    },
    {
      "x": -45,
      "y": 4,
      "z": 13,
      "name": "Rock_Ice"
    },
    {
      "x": -45,
      "y": 5,
      "z": 13,
      "name": "Rock_Ice"
    },
    {
      "x": -45,
      "y": 6,
      "z": 13,
      "name": "Rock_Ice_Permafrost"
    },
    {
      "x": -45,
      "y": 7,
      "z": 13,
      "name": "Rock_Ice"
    },
    {
      "x": -45,
      "y": 8,
      "z": 13,
      "name": "Soil_Snow"
    },
    {
      "x": -45,
      "y": 2,
      "z": 14,
      "name": "Rock_Ice"
    },
    {
      "x": -45,
      "y": 3,
      "z": 14,
      "name": "Rock_Ice_Permafrost"
    },
    {
      "x": -45,
      "y": 4,
      "z": 14,
      "name": "Rock_Ice_Permafrost"
    },
    {
      "x": -45,
      "y": 5,
      "z": 14,
      "name": "Rock_Ice"
    },
    {
      "x": -45,
      "y": 6,
      "z": 14,
      "name": "Rock_Ice_Permafrost"
    },
    {
      "x": -45,
      "y": 7,
      "z": 14,
      "name": "Rock_Ice_Permafrost"
    },
    {
      "x": -45,
      "y": 8,
      "z": 14,
      "name": "Soil_Snow"
    },
    {
      "x": -45,
      "y": 2,
      "z": 15,
      "name": "Rock_Ice"
    },
    {
      "x": -45,
      "y": 3,
      "z": 15,
      "name": "Rock_Ice_Permafrost"
    },
    {
      "x": -45,
      "y": 4,
      "z": 15,
      "name": "Rock_Ice_Permafrost"
    },
    {
      "x": -45,
      "y": 5,
      "z": 15,
      "name": "Rock_Ice_Permafrost"
    },
    {
      "x": -45,
      "y": 6,
      "z": 15,
      "name": "Rock_Ice_Permafrost"
    },
    {
      "x": -45,
      "y": 7,
      "z": 15,
      "name": "Rock_Ice_Permafrost"
    },
    {
      "x": -45,
      "y": 8,
      "z": 15,
      "name": "Soil_Snow"
    },
    {
      "x": -45,
      "y": 2,
      "z": 16,
      "name": "Rock_Ice"
    },
    {
      "x": -45,
      "y": 3,
      "z": 16,
      "name": "Rock_Ice_Permafrost"
    },
    {
      "x": -45,
      "y": 4,
      "z": 16,
      "name": "Rock_Ice_Permafrost"
    },
    {
      "x": -45,
      "y": 5,
      "z": 16,
      "name": "Rock_Ice_Permafrost"
    },
    {
      "x": -45,
      "y": 6,
      "z": 16,
      "name": "Rock_Ice_Permafrost"
    },
    {
      "x": -45,
      "y": 7,
      "z": 16,
      "name": "Rock_Ice_Permafrost"
    },
    {
      "x": -45,
      "y": 8,
      "z": 16,
      "name": "Soil_Snow"
    },
    {
      "x": -45,
      "y": 1,
      "z": 17,
      "name": "Rock_Ice"
    },
    {
      "x": -45,
      "y": 2,
      "z": 17,
      "name": "Rock_Ice_Permafrost"
    },
    {
      "x": -45,
      "y": 3,
      "z": 17,
      "name": "Rock_Ice_Permafrost"
    },
    {
      "x": -45,
      "y": 4,
      "z": 17,
      "name": "Rock_Ice_Permafrost"
    },
    {
      "x": -45,
      "y": 5,
      "z": 17,
      "name": "Rock_Ice_Permafrost"
    },
    {
      "x": -45,
      "y": 6,
      "z": 17,
      "name": "Rock_Ice_Permafrost"
    },
    {
      "x": -45,
      "y": 7,
      "z": 17,
      "name": "Rock_Ice_Permafrost"
    },
    {
      "x": -45,
      "y": 8,
      "z": 17,
      "name": "Soil_Snow"
    },
    {
      "x": -45,
      "y": 1,
      "z": 18,
      "name": "Rock_Ice"
    },
    {
      "x": -45,
      "y": 2,
      "z": 18,
      "name": "Rock_Ice"
    },
    {
      "x": -45,
      "y": 3,
      "z": 18,
      "name": "Rock_Ice_Permafrost"
    },
    {
      "x": -45,
      "y": 4,
      "z": 18,
      "name": "Rock_Ice_Permafrost"
    },
    {
      "x": -45,
      "y": 5,
      "z": 18,
      "name": "Rock_Ice_Permafrost"
    },
    {
      "x": -45,
      "y": 6,
      "z": 18,
      "name": "Rock_Ice_Permafrost"
    },
    {
      "x": -45,
      "y": 7,
      "z": 18,
      "name": "Soil_Snow"
    },
    {
      "x": -45,
      "y": 1,
      "z": 19,
      "name": "Rock_Ice"
    },
    {
      "x": -45,
      "y": 2,
      "z": 19,
      "name": "Rock_Ice_Permafrost"
    },
    {
      "x": -45,
      "y": 3,
      "z": 19,
      "name": "Rock_Ice_Permafrost"
    },
    {
      "x": -45,
      "y": 4,
      "z": 19,
      "name": "Rock_Ice_Permafrost"
    },
    {
      "x": -45,
      "y": 5,
      "z": 19,
      "name": "Rock_Ice_Permafrost"
    },
    {
      "x": -45,
      "y": 6,
      "z": 19,
      "name": "Rock_Ice_Permafrost"
    },
    {
      "x": -45,
      "y": 7,
      "z": 19,
      "name": "Soil_Snow"
    },
    {
      "x": -45,
      "y": 1,
      "z": 20,
      "name": "Rock_Ice_Permafrost"
    },
    {
      "x": -45,
      "y": 2,
      "z": 20,
      "name": "Rock_Ice_Permafrost"
    },
    {
      "x": -45,
      "y": 3,
      "z": 20,
      "name": "Rock_Ice_Permafrost"
    },
    {
      "x": -45,
      "y": 4,
      "z": 20,
      "name": "Rock_Ice_Permafrost"
    },
    {
      "x": -45,
      "y": 5,
      "z": 20,
      "name": "Rock_Ice_Permafrost"
    },
    {
      "x": -45,
      "y": 6,
      "z": 20,
      "name": "Rock_Ice_Permafrost"
    },
    {
      "x": -45,
      "y": 7,
      "z": 20,
      "name": "Soil_Snow"
    },
    {
      "x": -45,
      "y": 1,
      "z": 21,
      "name": "Rock_Ice_Permafrost"
    },
    {
      "x": -45,
      "y": 2,
      "z": 21,
      "name": "Rock_Ice_Permafrost"
    },
    {
      "x": -45,
      "y": 3,
      "z": 21,
      "name": "Rock_Ice_Permafrost"
    },
    {
      "x": -45,
      "y": 4,
      "z": 21,
      "name": "Rock_Ice_Permafrost"
    },
    {
      "x": -45,
      "y": 5,
      "z": 21,
      "name": "Rock_Ice"
    },
    {
      "x": -45,
      "y": 6,
      "z": 21,
      "name": "Soil_Snow"
    },
    {
      "x": -45,
      "y": 1,
      "z": 22,
      "name": "Rock_Ice_Permafrost"
    },
    {
      "x": -45,
      "y": 2,
      "z": 22,
      "name": "Rock_Ice_Permafrost"
    },
    {
      "x": -45,
      "y": 3,
      "z": 22,
      "name": "Rock_Ice_Permafrost"
    },
    {
      "x": -45,
      "y": 4,
      "z": 22,
      "name": "Rock_Ice_Permafrost"
    },
    {
      "x": -45,
      "y": 5,
      "z": 22,
      "name": "Rock_Ice"
    },
    {
      "x": -45,
      "y": 6,
      "z": 22,
      "name": "Soil_Snow"
    },
    {
      "x": -45,
      "y": 1,
      "z": 23,
      "name": "Rock_Ice_Permafrost"
    },
    {
      "x": -45,
      "y": 2,
      "z": 23,
      "name": "Rock_Ice_Permafrost"
    },
    {
      "x": -45,
      "y": 3,
      "z": 23,
      "name": "Rock_Ice_Permafrost"
    },
    {
      "x": -45,
      "y": 4,
      "z": 23,
      "name": "Rock_Ice"
    },
    {
      "x": -45,
      "y": 5,
      "z": 23,
      "name": "Soil_Snow"
    },
    {
      "x": -45,
      "y": 1,
      "z": 24,
      "name": "Rock_Ice_Permafrost"
    },
    {
      "x": -45,
      "y": 2,
      "z": 24,
      "name": "Rock_Ice_Permafrost"
    },
    {
      "x": -45,
      "y": 3,
      "z": 24,
      "name": "Rock_Ice_Permafrost"
    },
    {
      "x": -45,
      "y": 4,
      "z": 24,
      "name": "Rock_Ice"
    },
    {
      "x": -45,
      "y": 5,
      "z": 24,
      "name": "Soil_Snow"
    },
    {
      "x": -45,
      "y": 1,
      "z": 25,
      "name": "Rock_Ice_Permafrost"
    },
    {
      "x": -45,
      "y": 2,
      "z": 25,
      "name": "Rock_Ice"
    },
    {
      "x": -45,
      "y": 3,
      "z": 25,
      "name": "Soil_Snow"
    },
    {
      "x": -44,
      "y": 41,
      "z": -26,
      "name": "Rock_Ice"
    },
    {
      "x": -44,
      "y": 42,
      "z": -26,
      "name": "Soil_Snow"
    },
    {
      "x": -44,
      "y": 41,
      "z": -25,
      "name": "Rock_Ice_Permafrost"
    },
    {
      "x": -44,
      "y": 42,
      "z": -25,
      "name": "Rock_Ice_Permafrost"
    },
    {
      "x": -44,
      "y": 43,
      "z": -25,
      "name": "Rock_Ice"
    },
    {
      "x": -44,
      "y": 44,
      "z": -25,
      "name": "Soil_Snow"
    },
    {
      "x": -44,
      "y": 42,
      "z": -24,
      "name": "Rock_Ice"
    },
    {
      "x": -44,
      "y": 43,
      "z": -24,
      "name": "Rock_Ice"
    },
    {
      "x": -44,
      "y": 44,
      "z": -24,
      "name": "Rock_Ice"
    },
    {
      "x": -44,
      "y": 45,
      "z": -24,
      "name": "Soil_Snow"
    },
    {
      "x": -44,
      "y": 42,
      "z": -23,
      "name": "Rock_Ice"
    },
    {
      "x": -44,
      "y": 43,
      "z": -23,
      "name": "Rock_Ice"
    },
    {
      "x": -44,
      "y": 44,
      "z": -23,
      "name": "Rock_Ice_Permafrost"
    },
    {
      "x": -44,
      "y": 45,
      "z": -23,
      "name": "Rock_Ice_Permafrost"
    },
    {
      "x": -44,
      "y": 46,
      "z": -23,
      "name": "Rock_Ice"
    },
    {
      "x": -44,
      "y": 47,
      "z": -23,
      "name": "Rock_Ice_Permafrost"
    },
    {
      "x": -44,
      "y": 43,
      "z": -22,
      "name": "Rock_Ice"
    },
    {
      "x": -44,
      "y": 44,
      "z": -22,
      "name": "Rock_Ice"
    },
    {
      "x": -44,
      "y": 45,
      "z": -22,
      "name": "Rock_Ice"
    },
    {
      "x": -44,
      "y": 46,
      "z": -22,
      "name": "Soil_Snow"
    },
    {
      "x": -44,
      "y": 3,
      "z": 4,
      "name": "Rock_Ice"
    },
    {
      "x": -44,
      "y": 4,
      "z": 4,
      "name": "Rock_Ice"
    },
    {
      "x": -44,
      "y": 7,
      "z": 4,
      "name": "Rock_Ice"
    },
    {
      "x": -44,
      "y": 8,
      "z": 4,
      "name": "Rock_Ice"
    },
    {
      "x": -44,
      "y": 3,
      "z": 5,
      "name": "Rock_Ice"
    },
    {
      "x": -44,
      "y": 4,
      "z": 5,
      "name": "Rock_Ice"
    },
    {
      "x": -44,
      "y": 5,
      "z": 5,
      "name": "Rock_Ice"
    },
    {
      "x": -44,
      "y": 6,
      "z": 5,
      "name": "Rock_Ice"
    },
    {
      "x": -44,
      "y": 7,
      "z": 5,
      "name": "Rock_Ice"
    },
    {
      "x": -44,
      "y": 8,
      "z": 5,
      "name": "Soil_Snow"
    },
    {
      "x": -44,
      "y": 3,
      "z": 6,
      "name": "Rock_Ice"
    },
    {
      "x": -44,
      "y": 4,
      "z": 6,
      "name": "Rock_Ice"
    },
    {
      "x": -44,
      "y": 5,
      "z": 6,
      "name": "Rock_Ice"
    },
    {
      "x": -44,
      "y": 6,
      "z": 6,
      "name": "Rock_Ice"
    },
    {
      "x": -44,
      "y": 7,
      "z": 6,
      "name": "Rock_Ice"
    },
    {
      "x": -44,
      "y": 8,
      "z": 6,
      "name": "Rock_Ice"
    },
    {
      "x": -44,
      "y": 9,
      "z": 6,
      "name": "Soil_Snow"
    },
    {
      "x": -44,
      "y": 3,
      "z": 7,
      "name": "Rock_Ice_Permafrost"
    },
    {
      "x": -44,
      "y": 4,
      "z": 7,
      "name": "Rock_Ice"
    },
    {
      "x": -44,
      "y": 5,
      "z": 7,
      "name": "Rock_Ice"
    },
    {
      "x": -44,
      "y": 6,
      "z": 7,
      "name": "Rock_Ice"
    },
    {
      "x": -44,
      "y": 7,
      "z": 7,
      "name": "Rock_Ice"
    },
    {
      "x": -44,
      "y": 8,
      "z": 7,
      "name": "Rock_Ice"
    },
    {
      "x": -44,
      "y": 9,
      "z": 7,
      "name": "Soil_Snow"
    },
    {
      "x": -44,
      "y": 3,
      "z": 8,
      "name": "Rock_Ice_Permafrost"
    },
    {
      "x": -44,
      "y": 4,
      "z": 8,
      "name": "Rock_Ice"
    },
    {
      "x": -44,
      "y": 5,
      "z": 8,
      "name": "Rock_Ice"
    },
    {
      "x": -44,
      "y": 6,
      "z": 8,
      "name": "Rock_Ice"
    },
    {
      "x": -44,
      "y": 7,
      "z": 8,
      "name": "Rock_Ice"
    },
    {
      "x": -44,
      "y": 8,
      "z": 8,
      "name": "Rock_Ice"
    },
    {
      "x": -44,
      "y": 9,
      "z": 8,
      "name": "Soil_Snow"
    },
    {
      "x": -44,
      "y": 3,
      "z": 9,
      "name": "Rock_Ice"
    },
    {
      "x": -44,
      "y": 4,
      "z": 9,
      "name": "Rock_Ice_Permafrost"
    },
    {
      "x": -44,
      "y": 5,
      "z": 9,
      "name": "Rock_Ice"
    },
    {
      "x": -44,
      "y": 6,
      "z": 9,
      "name": "Rock_Ice"
    },
    {
      "x": -44,
      "y": 7,
      "z": 9,
      "name": "Rock_Ice_Permafrost"
    },
    {
      "x": -44,
      "y": 8,
      "z": 9,
      "name": "Rock_Ice_Permafrost"
    },
    {
      "x": -44,
      "y": 9,
      "z": 9,
      "name": "Rock_Ice"
    },
    {
      "x": -44,
      "y": 2,
      "z": 10,
      "name": "Rock_Ice"
    },
    {
      "x": -44,
      "y": 3,
      "z": 10,
      "name": "Rock_Ice_Permafrost"
    },
    {
      "x": -44,
      "y": 4,
      "z": 10,
      "name": "Rock_Ice"
    },
    {
      "x": -44,
      "y": 5,
      "z": 10,
      "name": "Rock_Ice"
    },
    {
      "x": -44,
      "y": 6,
      "z": 10,
      "name": "Rock_Ice"
    },
    {
      "x": -44,
      "y": 7,
      "z": 10,
      "name": "Rock_Ice_Permafrost"
    },
    {
      "x": -44,
      "y": 8,
      "z": 10,
      "name": "Rock_Ice"
    },
    {
      "x": -44,
      "y": 9,
      "z": 10,
      "name": "Rock_Ice"
    },
    {
      "x": -44,
      "y": 10,
      "z": 10,
      "name": "Soil_Snow"
    },
    {
      "x": -44,
      "y": 2,
      "z": 11,
      "name": "Rock_Ice_Permafrost"
    },
    {
      "x": -44,
      "y": 3,
      "z": 11,
      "name": "Rock_Ice_Permafrost"
    },
    {
      "x": -44,
      "y": 4,
      "z": 11,
      "name": "Rock_Ice"
    },
    {
      "x": -44,
      "y": 5,
      "z": 11,
      "name": "Rock_Ice"
    },
    {
      "x": -44,
      "y": 6,
      "z": 11,
      "name": "Rock_Ice"
    },
    {
      "x": -44,
      "y": 7,
      "z": 11,
      "name": "Rock_Ice_Permafrost"
    },
    {
      "x": -44,
      "y": 8,
      "z": 11,
      "name": "Rock_Ice_Permafrost"
    },
    {
      "x": -44,
      "y": 9,
      "z": 11,
      "name": "Rock_Ice"
    },
    {
      "x": -44,
      "y": 10,
      "z": 11,
      "name": "Soil_Snow"
    },
    {
      "x": -44,
      "y": 2,
      "z": 12,
      "name": "Rock_Ice_Permafrost"
    },
    {
      "x": -44,
      "y": 3,
      "z": 12,
      "name": "Rock_Ice_Permafrost"
    },
    {
      "x": -44,
      "y": 4,
      "z": 12,
      "name": "Rock_Ice"
    },
    {
      "x": -44,
      "y": 5,
      "z": 12,
      "name": "Rock_Ice"
    },
    {
      "x": -44,
      "y": 6,
      "z": 12,
      "name": "Rock_Ice_Permafrost"
    },
    {
      "x": -44,
      "y": 7,
      "z": 12,
      "name": "Rock_Ice_Permafrost"
    },
    {
      "x": -44,
      "y": 8,
      "z": 12,
      "name": "Rock_Ice_Permafrost"
    },
    {
      "x": -44,
      "y": 9,
      "z": 12,
      "name": "Rock_Ice_Permafrost"
    },
    {
      "x": -44,
      "y": 10,
      "z": 12,
      "name": "Soil_Snow"
    },
    {
      "x": -44,
      "y": 2,
      "z": 13,
      "name": "Rock_Ice_Permafrost"
    },
    {
      "x": -44,
      "y": 3,
      "z": 13,
      "name": "Rock_Ice_Permafrost"
    },
    {
      "x": -44,
      "y": 4,
      "z": 13,
      "name": "Rock_Ice_Permafrost"
    },
    {
      "x": -44,
      "y": 5,
      "z": 13,
      "name": "Rock_Ice"
    },
    {
      "x": -44,
      "y": 6,
      "z": 13,
      "name": "Rock_Ice_Permafrost"
    },
    {
      "x": -44,
      "y": 7,
      "z": 13,
      "name": "Rock_Ice_Permafrost"
    },
    {
      "x": -44,
      "y": 8,
      "z": 13,
      "name": "Rock_Ice_Permafrost"
    },
    {
      "x": -44,
      "y": 9,
      "z": 13,
      "name": "Rock_Ice"
    },
    {
      "x": -44,
      "y": 10,
      "z": 13,
      "name": "Soil_Snow"
    },
    {
      "x": -44,
      "y": 2,
      "z": 14,
      "name": "Rock_Ice_Permafrost"
    },
    {
      "x": -44,
      "y": 3,
      "z": 14,
      "name": "Rock_Ice_Permafrost"
    },
    {
      "x": -44,
      "y": 4,
      "z": 14,
      "name": "Rock_Ice_Permafrost"
    },
    {
      "x": -44,
      "y": 5,
      "z": 14,
      "name": "Rock_Ice_Permafrost"
    },
    {
      "x": -44,
      "y": 6,
      "z": 14,
      "name": "Rock_Ice_Permafrost"
    },
    {
      "x": -44,
      "y": 7,
      "z": 14,
      "name": "Rock_Ice_Permafrost"
    },
    {
      "x": -44,
      "y": 8,
      "z": 14,
      "name": "Rock_Ice_Permafrost"
    },
    {
      "x": -44,
      "y": 9,
      "z": 14,
      "name": "Soil_Snow"
    },
    {
      "x": -44,
      "y": 2,
      "z": 15,
      "name": "Rock_Ice_Permafrost"
    },
    {
      "x": -44,
      "y": 3,
      "z": 15,
      "name": "Rock_Ice_Permafrost"
    },
    {
      "x": -44,
      "y": 4,
      "z": 15,
      "name": "Rock_Ice_Permafrost"
    },
    {
      "x": -44,
      "y": 5,
      "z": 15,
      "name": "Rock_Ice"
    },
    {
      "x": -44,
      "y": 6,
      "z": 15,
      "name": "Rock_Ice_Permafrost"
    },
    {
      "x": -44,
      "y": 7,
      "z": 15,
      "name": "Rock_Ice_Permafrost"
    },
    {
      "x": -44,
      "y": 8,
      "z": 15,
      "name": "Rock_Ice_Permafrost"
    },
    {
      "x": -44,
      "y": 9,
      "z": 15,
      "name": "Soil_Snow"
    },
    {
      "x": -44,
      "y": 2,
      "z": 16,
      "name": "Rock_Ice_Permafrost"
    },
    {
      "x": -44,
      "y": 3,
      "z": 16,
      "name": "Rock_Ice_Permafrost"
    },
    {
      "x": -44,
      "y": 4,
      "z": 16,
      "name": "Rock_Ice_Permafrost"
    },
    {
      "x": -44,
      "y": 5,
      "z": 16,
      "name": "Rock_Ice_Permafrost"
    },
    {
      "x": -44,
      "y": 6,
      "z": 16,
      "name": "Rock_Ice_Permafrost"
    },
    {
      "x": -44,
      "y": 7,
      "z": 16,
      "name": "Rock_Ice_Permafrost"
    },
    {
      "x": -44,
      "y": 8,
      "z": 16,
      "name": "Rock_Ice_Permafrost"
    },
    {
      "x": -44,
      "y": 9,
      "z": 16,
      "name": "Soil_Snow"
    },
    {
      "x": -44,
      "y": 2,
      "z": 17,
      "name": "Rock_Ice"
    },
    {
      "x": -44,
      "y": 3,
      "z": 17,
      "name": "Rock_Ice_Permafrost"
    },
    {
      "x": -44,
      "y": 4,
      "z": 17,
      "name": "Rock_Ice_Permafrost"
    },
    {
      "x": -44,
      "y": 5,
      "z": 17,
      "name": "Rock_Ice_Permafrost"
    },
    {
      "x": -44,
      "y": 6,
      "z": 17,
      "name": "Rock_Ice_Permafrost"
    },
    {
      "x": -44,
      "y": 7,
      "z": 17,
      "name": "Rock_Ice_Permafrost"
    },
    {
      "x": -44,
      "y": 8,
      "z": 17,
      "name": "Rock_Ice"
    },
    {
      "x": -44,
      "y": 9,
      "z": 17,
      "name": "Soil_Snow"
    },
    {
      "x": -44,
      "y": 2,
      "z": 18,
      "name": "Rock_Ice_Permafrost"
    },
    {
      "x": -44,
      "y": 3,
      "z": 18,
      "name": "Rock_Ice_Permafrost"
    },
    {
      "x": -44,
      "y": 4,
      "z": 18,
      "name": "Rock_Ice_Permafrost"
    },
    {
      "x": -44,
      "y": 5,
      "z": 18,
      "name": "Rock_Ice_Permafrost"
    },
    {
      "x": -44,
      "y": 6,
      "z": 18,
      "name": "Rock_Ice_Permafrost"
    },
    {
      "x": -44,
      "y": 7,
      "z": 18,
      "name": "Rock_Ice_Permafrost"
    },
    {
      "x": -44,
      "y": 8,
      "z": 18,
      "name": "Rock_Ice_Permafrost"
    },
    {
      "x": -44,
      "y": 9,
      "z": 18,
      "name": "Soil_Snow"
    },
    {
      "x": -44,
      "y": 1,
      "z": 19,
      "name": "Rock_Ice_Permafrost"
    },
    {
      "x": -44,
      "y": 2,
      "z": 19,
      "name": "Rock_Ice"
    },
    {
      "x": -44,
      "y": 3,
      "z": 19,
      "name": "Rock_Ice_Permafrost"
    },
    {
      "x": -44,
      "y": 4,
      "z": 19,
      "name": "Rock_Ice_Permafrost"
    },
    {
      "x": -44,
      "y": 5,
      "z": 19,
      "name": "Rock_Ice_Permafrost"
    },
    {
      "x": -44,
      "y": 6,
      "z": 19,
      "name": "Rock_Ice_Permafrost"
    },
    {
      "x": -44,
      "y": 7,
      "z": 19,
      "name": "Rock_Ice_Permafrost"
    },
    {
      "x": -44,
      "y": 8,
      "z": 19,
      "name": "Soil_Snow"
    },
    {
      "x": -44,
      "y": 1,
      "z": 20,
      "name": "Rock_Ice_Permafrost"
    },
    {
      "x": -44,
      "y": 2,
      "z": 20,
      "name": "Rock_Ice_Permafrost"
    },
    {
      "x": -44,
      "y": 3,
      "z": 20,
      "name": "Rock_Ice_Permafrost"
    },
    {
      "x": -44,
      "y": 4,
      "z": 20,
      "name": "Rock_Ice_Permafrost"
    },
    {
      "x": -44,
      "y": 5,
      "z": 20,
      "name": "Rock_Ice_Permafrost"
    },
    {
      "x": -44,
      "y": 6,
      "z": 20,
      "name": "Rock_Ice_Permafrost"
    },
    {
      "x": -44,
      "y": 7,
      "z": 20,
      "name": "Rock_Ice"
    },
    {
      "x": -44,
      "y": 8,
      "z": 20,
      "name": "Soil_Snow"
    },
    {
      "x": -44,
      "y": 1,
      "z": 21,
      "name": "Rock_Ice_Permafrost"
    },
    {
      "x": -44,
      "y": 2,
      "z": 21,
      "name": "Rock_Ice_Permafrost"
    },
    {
      "x": -44,
      "y": 3,
      "z": 21,
      "name": "Rock_Ice_Permafrost"
    },
    {
      "x": -44,
      "y": 4,
      "z": 21,
      "name": "Rock_Ice_Permafrost"
    },
    {
      "x": -44,
      "y": 5,
      "z": 21,
      "name": "Rock_Ice_Permafrost"
    },
    {
      "x": -44,
      "y": 6,
      "z": 21,
      "name": "Rock_Ice_Permafrost"
    },
    {
      "x": -44,
      "y": 7,
      "z": 21,
      "name": "Rock_Ice"
    },
    {
      "x": -44,
      "y": 8,
      "z": 21,
      "name": "Soil_Snow"
    },
    {
      "x": -44,
      "y": 1,
      "z": 22,
      "name": "Rock_Ice_Permafrost"
    },
    {
      "x": -44,
      "y": 2,
      "z": 22,
      "name": "Rock_Ice_Permafrost"
    },
    {
      "x": -44,
      "y": 3,
      "z": 22,
      "name": "Rock_Ice_Permafrost"
    },
    {
      "x": -44,
      "y": 4,
      "z": 22,
      "name": "Rock_Ice_Permafrost"
    },
    {
      "x": -44,
      "y": 5,
      "z": 22,
      "name": "Rock_Ice_Permafrost"
    },
    {
      "x": -44,
      "y": 6,
      "z": 22,
      "name": "Rock_Ice"
    },
    {
      "x": -44,
      "y": 7,
      "z": 22,
      "name": "Soil_Snow"
    },
    {
      "x": -44,
      "y": 1,
      "z": 23,
      "name": "Rock_Ice_Permafrost"
    },
    {
      "x": -44,
      "y": 2,
      "z": 23,
      "name": "Rock_Ice_Permafrost"
    },
    {
      "x": -44,
      "y": 3,
      "z": 23,
      "name": "Rock_Ice_Permafrost"
    },
    {
      "x": -44,
      "y": 4,
      "z": 23,
      "name": "Rock_Ice_Permafrost"
    },
    {
      "x": -44,
      "y": 5,
      "z": 23,
      "name": "Rock_Ice_Permafrost"
    },
    {
      "x": -44,
      "y": 6,
      "z": 23,
      "name": "Rock_Ice"
    },
    {
      "x": -44,
      "y": 7,
      "z": 23,
      "name": "Soil_Snow"
    },
    {
      "x": -44,
      "y": 1,
      "z": 24,
      "name": "Rock_Ice_Permafrost"
    },
    {
      "x": -44,
      "y": 2,
      "z": 24,
      "name": "Rock_Ice_Permafrost"
    },
    {
      "x": -44,
      "y": 3,
      "z": 24,
      "name": "Rock_Ice_Permafrost"
    },
    {
      "x": -44,
      "y": 4,
      "z": 24,
      "name": "Rock_Ice_Permafrost"
    },
    {
      "x": -44,
      "y": 5,
      "z": 24,
      "name": "Rock_Ice_Permafrost"
    },
    {
      "x": -44,
      "y": 6,
      "z": 24,
      "name": "Rock_Ice"
    },
    {
      "x": -44,
      "y": 7,
      "z": 24,
      "name": "Soil_Snow"
    },
    {
      "x": -44,
      "y": 1,
      "z": 25,
      "name": "Rock_Ice_Permafrost"
    },
    {
      "x": -44,
      "y": 2,
      "z": 25,
      "name": "Rock_Ice_Permafrost"
    },
    {
      "x": -44,
      "y": 3,
      "z": 25,
      "name": "Rock_Ice_Permafrost"
    },
    {
      "x": -44,
      "y": 4,
      "z": 25,
      "name": "Rock_Ice_Permafrost"
    },
    {
      "x": -44,
      "y": 5,
      "z": 25,
      "name": "Rock_Ice"
    },
    {
      "x": -44,
      "y": 6,
      "z": 25,
      "name": "Soil_Snow"
    },
    {
      "x": -44,
      "y": 1,
      "z": 26,
      "name": "Rock_Ice_Permafrost"
    },
    {
      "x": -44,
      "y": 2,
      "z": 26,
      "name": "Rock_Ice_Permafrost"
    },
    {
      "x": -44,
      "y": 3,
      "z": 26,
      "name": "Rock_Ice"
    },
    {
      "x": -44,
      "y": 4,
      "z": 26,
      "name": "Soil_Snow"
    },
    {
      "x": -43,
      "y": 39,
      "z": -28,
      "name": "Soil_Snow"
    },
    {
      "x": -43,
      "y": 40,
      "z": -27,
      "name": "Rock_Ice"
    },
    {
      "x": -43,
      "y": 41,
      "z": -27,
      "name": "Soil_Snow"
    },
    {
      "x": -43,
      "y": 40,
      "z": -26,
      "name": "Rock_Ice"
    },
    {
      "x": -43,
      "y": 41,
      "z": -26,
      "name": "Rock_Ice"
    },
    {
      "x": -43,
      "y": 42,
      "z": -26,
      "name": "Rock_Ice"
    },
    {
      "x": -43,
      "y": 43,
      "z": -26,
      "name": "Soil_Snow"
    },
    {
      "x": -43,
      "y": 41,
      "z": -25,
      "name": "Rock_Ice_Permafrost"
    },
    {
      "x": -43,
      "y": 42,
      "z": -25,
      "name": "Rock_Ice_Permafrost"
    },
    {
      "x": -43,
      "y": 43,
      "z": -25,
      "name": "Rock_Ice"
    },
    {
      "x": -43,
      "y": 44,
      "z": -25,
      "name": "Soil_Snow"
    },
    {
      "x": -43,
      "y": 41,
      "z": -24,
      "name": "Rock_Ice"
    },
    {
      "x": -43,
      "y": 42,
      "z": -24,
      "name": "Rock_Ice"
    },
    {
      "x": -43,
      "y": 43,
      "z": -24,
      "name": "Rock_Ice"
    },
    {
      "x": -43,
      "y": 44,
      "z": -24,
      "name": "Rock_Ice_Permafrost"
    },
    {
      "x": -43,
      "y": 45,
      "z": -24,
      "name": "Rock_Ice"
    },
    {
      "x": -43,
      "y": 46,
      "z": -24,
      "name": "Soil_Snow"
    },
    {
      "x": -43,
      "y": 42,
      "z": -23,
      "name": "Rock_Ice"
    },
    {
      "x": -43,
      "y": 43,
      "z": -23,
      "name": "Rock_Ice_Permafrost"
    },
    {
      "x": -43,
      "y": 44,
      "z": -23,
      "name": "Rock_Ice"
    },
    {
      "x": -43,
      "y": 45,
      "z": -23,
      "name": "Rock_Ice_Permafrost"
    },
    {
      "x": -43,
      "y": 46,
      "z": -23,
      "name": "Rock_Ice_Permafrost"
    },
    {
      "x": -43,
      "y": 47,
      "z": -23,
      "name": "Rock_Ice"
    },
    {
      "x": -43,
      "y": 48,
      "z": -23,
      "name": "Rock_Ice_Permafrost"
    },
    {
      "x": -43,
      "y": 43,
      "z": -22,
      "name": "Rock_Ice"
    },
    {
      "x": -43,
      "y": 44,
      "z": -22,
      "name": "Rock_Ice"
    },
    {
      "x": -43,
      "y": 45,
      "z": -22,
      "name": "Rock_Ice"
    },
    {
      "x": -43,
      "y": 46,
      "z": -22,
      "name": "Rock_Ice"
    },
    {
      "x": -43,
      "y": 47,
      "z": -22,
      "name": "Soil_Snow"
    },
    {
      "x": -43,
      "y": 4,
      "z": -1,
      "name": "Soil_Snow"
    },
    {
      "x": -43,
      "y": 4,
      "z": 0,
      "name": "Rock_Ice"
    },
    {
      "x": -43,
      "y": 5,
      "z": 0,
      "name": "Soil_Snow"
    },
    {
      "x": -43,
      "y": 4,
      "z": 1,
      "name": "Rock_Ice_Permafrost"
    },
    {
      "x": -43,
      "y": 5,
      "z": 1,
      "name": "Soil_Snow"
    },
    {
      "x": -43,
      "y": 4,
      "z": 2,
      "name": "Rock_Ice"
    },
    {
      "x": -43,
      "y": 5,
      "z": 2,
      "name": "Rock_Ice"
    },
    {
      "x": -43,
      "y": 6,
      "z": 2,
      "name": "Rock_Ice"
    },
    {
      "x": -43,
      "y": 4,
      "z": 3,
      "name": "Rock_Ice"
    },
    {
      "x": -43,
      "y": 5,
      "z": 3,
      "name": "Rock_Ice"
    },
    {
      "x": -43,
      "y": 6,
      "z": 3,
      "name": "Rock_Ice"
    },
    {
      "x": -43,
      "y": 7,
      "z": 3,
      "name": "Rock_Ice"
    },
    {
      "x": -43,
      "y": 8,
      "z": 3,
      "name": "Rock_Ice"
    },
    {
      "x": -43,
      "y": 9,
      "z": 3,
      "name": "Rock_Ice"
    },
    {
      "x": -43,
      "y": 4,
      "z": 4,
      "name": "Rock_Ice"
    },
    {
      "x": -43,
      "y": 5,
      "z": 4,
      "name": "Rock_Ice"
    },
    {
      "x": -43,
      "y": 6,
      "z": 4,
      "name": "Rock_Ice"
    },
    {
      "x": -43,
      "y": 7,
      "z": 4,
      "name": "Rock_Ice"
    },
    {
      "x": -43,
      "y": 8,
      "z": 4,
      "name": "Rock_Ice"
    },
    {
      "x": -43,
      "y": 9,
      "z": 4,
      "name": "Rock_Ice"
    },
    {
      "x": -43,
      "y": 10,
      "z": 4,
      "name": "Soil_Snow"
    },
    {
      "x": -43,
      "y": 3,
      "z": 5,
      "name": "Rock_Ice"
    },
    {
      "x": -43,
      "y": 4,
      "z": 5,
      "name": "Rock_Ice"
    },
    {
      "x": -43,
      "y": 5,
      "z": 5,
      "name": "Rock_Ice"
    },
    {
      "x": -43,
      "y": 6,
      "z": 5,
      "name": "Rock_Ice"
    },
    {
      "x": -43,
      "y": 7,
      "z": 5,
      "name": "Rock_Ice"
    },
    {
      "x": -43,
      "y": 8,
      "z": 5,
      "name": "Rock_Ice"
    },
    {
      "x": -43,
      "y": 9,
      "z": 5,
      "name": "Rock_Ice"
    },
    {
      "x": -43,
      "y": 10,
      "z": 5,
      "name": "Soil_Snow"
    },
    {
      "x": -43,
      "y": 3,
      "z": 6,
      "name": "Rock_Ice"
    },
    {
      "x": -43,
      "y": 4,
      "z": 6,
      "name": "Rock_Ice"
    },
    {
      "x": -43,
      "y": 5,
      "z": 6,
      "name": "Rock_Ice"
    },
    {
      "x": -43,
      "y": 6,
      "z": 6,
      "name": "Rock_Ice"
    },
    {
      "x": -43,
      "y": 7,
      "z": 6,
      "name": "Rock_Ice"
    },
    {
      "x": -43,
      "y": 8,
      "z": 6,
      "name": "Rock_Ice"
    },
    {
      "x": -43,
      "y": 9,
      "z": 6,
      "name": "Rock_Ice"
    },
    {
      "x": -43,
      "y": 10,
      "z": 6,
      "name": "Soil_Snow"
    },
    {
      "x": -43,
      "y": 3,
      "z": 7,
      "name": "Rock_Ice_Permafrost"
    },
    {
      "x": -43,
      "y": 4,
      "z": 7,
      "name": "Rock_Ice_Permafrost"
    },
    {
      "x": -43,
      "y": 5,
      "z": 7,
      "name": "Rock_Ice"
    },
    {
      "x": -43,
      "y": 6,
      "z": 7,
      "name": "Rock_Ice"
    },
    {
      "x": -43,
      "y": 7,
      "z": 7,
      "name": "Rock_Ice"
    },
    {
      "x": -43,
      "y": 8,
      "z": 7,
      "name": "Rock_Ice"
    },
    {
      "x": -43,
      "y": 9,
      "z": 7,
      "name": "Rock_Ice"
    },
    {
      "x": -43,
      "y": 10,
      "z": 7,
      "name": "Soil_Snow"
    },
    {
      "x": -43,
      "y": 3,
      "z": 8,
      "name": "Rock_Ice_Permafrost"
    },
    {
      "x": -43,
      "y": 4,
      "z": 8,
      "name": "Rock_Ice"
    },
    {
      "x": -43,
      "y": 5,
      "z": 8,
      "name": "Rock_Ice"
    },
    {
      "x": -43,
      "y": 6,
      "z": 8,
      "name": "Rock_Ice"
    },
    {
      "x": -43,
      "y": 7,
      "z": 8,
      "name": "Rock_Ice"
    },
    {
      "x": -43,
      "y": 8,
      "z": 8,
      "name": "Rock_Ice"
    },
    {
      "x": -43,
      "y": 9,
      "z": 8,
      "name": "Rock_Ice"
    },
    {
      "x": -43,
      "y": 10,
      "z": 8,
      "name": "Rock_Ice"
    },
    {
      "x": -43,
      "y": 3,
      "z": 9,
      "name": "Rock_Ice_Permafrost"
    },
    {
      "x": -43,
      "y": 4,
      "z": 9,
      "name": "Rock_Ice"
    },
    {
      "x": -43,
      "y": 5,
      "z": 9,
      "name": "Rock_Ice"
    },
    {
      "x": -43,
      "y": 6,
      "z": 9,
      "name": "Rock_Ice"
    },
    {
      "x": -43,
      "y": 7,
      "z": 9,
      "name": "Rock_Ice"
    },
    {
      "x": -43,
      "y": 8,
      "z": 9,
      "name": "Rock_Ice"
    },
    {
      "x": -43,
      "y": 9,
      "z": 9,
      "name": "Rock_Ice"
    },
    {
      "x": -43,
      "y": 10,
      "z": 9,
      "name": "Rock_Ice"
    },
    {
      "x": -43,
      "y": 11,
      "z": 9,
      "name": "Soil_Snow"
    },
    {
      "x": -43,
      "y": 3,
      "z": 10,
      "name": "Rock_Ice"
    },
    {
      "x": -43,
      "y": 4,
      "z": 10,
      "name": "Rock_Ice_Permafrost"
    },
    {
      "x": -43,
      "y": 5,
      "z": 10,
      "name": "Rock_Ice"
    },
    {
      "x": -43,
      "y": 6,
      "z": 10,
      "name": "Rock_Ice"
    },
    {
      "x": -43,
      "y": 7,
      "z": 10,
      "name": "Rock_Ice"
    },
    {
      "x": -43,
      "y": 8,
      "z": 10,
      "name": "Rock_Ice_Permafrost"
    },
    {
      "x": -43,
      "y": 9,
      "z": 10,
      "name": "Rock_Ice"
    },
    {
      "x": -43,
      "y": 10,
      "z": 10,
      "name": "Rock_Ice"
    },
    {
      "x": -43,
      "y": 11,
      "z": 10,
      "name": "Soil_Snow"
    },
    {
      "x": -43,
      "y": 3,
      "z": 11,
      "name": "Rock_Ice_Permafrost"
    },
    {
      "x": -43,
      "y": 4,
      "z": 11,
      "name": "Rock_Ice_Permafrost"
    },
    {
      "x": -43,
      "y": 5,
      "z": 11,
      "name": "Rock_Ice"
    },
    {
      "x": -43,
      "y": 6,
      "z": 11,
      "name": "Rock_Ice"
    },
    {
      "x": -43,
      "y": 7,
      "z": 11,
      "name": "Rock_Ice_Permafrost"
    },
    {
      "x": -43,
      "y": 8,
      "z": 11,
      "name": "Rock_Ice_Permafrost"
    },
    {
      "x": -43,
      "y": 9,
      "z": 11,
      "name": "Rock_Ice_Permafrost"
    },
    {
      "x": -43,
      "y": 10,
      "z": 11,
      "name": "Rock_Ice_Permafrost"
    },
    {
      "x": -43,
      "y": 11,
      "z": 11,
      "name": "Soil_Snow"
    },
    {
      "x": -43,
      "y": 2,
      "z": 12,
      "name": "Rock_Ice_Permafrost"
    },
    {
      "x": -43,
      "y": 3,
      "z": 12,
      "name": "Rock_Ice_Permafrost"
    },
    {
      "x": -43,
      "y": 4,
      "z": 12,
      "name": "Rock_Ice_Permafrost"
    },
    {
      "x": -43,
      "y": 5,
      "z": 12,
      "name": "Rock_Ice"
    },
    {
      "x": -43,
      "y": 6,
      "z": 12,
      "name": "Rock_Ice"
    },
    {
      "x": -43,
      "y": 7,
      "z": 12,
      "name": "Rock_Ice"
    },
    {
      "x": -43,
      "y": 8,
      "z": 12,
      "name": "Rock_Ice_Permafrost"
    },
    {
      "x": -43,
      "y": 9,
      "z": 12,
      "name": "Rock_Ice_Permafrost"
    },
    {
      "x": -43,
      "y": 10,
      "z": 12,
      "name": "Rock_Ice_Permafrost"
    },
    {
      "x": -43,
      "y": 11,
      "z": 12,
      "name": "Soil_Snow"
    },
    {
      "x": -43,
      "y": 2,
      "z": 13,
      "name": "Rock_Ice_Permafrost"
    },
    {
      "x": -43,
      "y": 3,
      "z": 13,
      "name": "Rock_Ice_Permafrost"
    },
    {
      "x": -43,
      "y": 4,
      "z": 13,
      "name": "Rock_Ice"
    },
    {
      "x": -43,
      "y": 5,
      "z": 13,
      "name": "Rock_Ice_Permafrost"
    },
    {
      "x": -43,
      "y": 6,
      "z": 13,
      "name": "Rock_Ice"
    },
    {
      "x": -43,
      "y": 7,
      "z": 13,
      "name": "Rock_Ice_Permafrost"
    },
    {
      "x": -43,
      "y": 8,
      "z": 13,
      "name": "Rock_Ice_Permafrost"
    },
    {
      "x": -43,
      "y": 9,
      "z": 13,
      "name": "Rock_Ice_Permafrost"
    },
    {
      "x": -43,
      "y": 10,
      "z": 13,
      "name": "Rock_Ice_Permafrost"
    },
    {
      "x": -43,
      "y": 11,
      "z": 13,
      "name": "Soil_Snow"
    },
    {
      "x": -43,
      "y": 2,
      "z": 14,
      "name": "Rock_Ice_Permafrost"
    },
    {
      "x": -43,
      "y": 3,
      "z": 14,
      "name": "Rock_Ice_Permafrost"
    },
    {
      "x": -43,
      "y": 4,
      "z": 14,
      "name": "Rock_Ice_Permafrost"
    },
    {
      "x": -43,
      "y": 5,
      "z": 14,
      "name": "Rock_Ice_Permafrost"
    },
    {
      "x": -43,
      "y": 6,
      "z": 14,
      "name": "Rock_Ice"
    },
    {
      "x": -43,
      "y": 7,
      "z": 14,
      "name": "Rock_Ice_Permafrost"
    },
    {
      "x": -43,
      "y": 8,
      "z": 14,
      "name": "Rock_Ice_Permafrost"
    },
    {
      "x": -43,
      "y": 9,
      "z": 14,
      "name": "Rock_Ice_Permafrost"
    },
    {
      "x": -43,
      "y": 10,
      "z": 14,
      "name": "Rock_Ice_Permafrost"
    },
    {
      "x": -43,
      "y": 11,
      "z": 14,
      "name": "Soil_Snow"
    },
    {
      "x": -43,
      "y": 2,
      "z": 15,
      "name": "Rock_Ice"
    },
    {
      "x": -43,
      "y": 3,
      "z": 15,
      "name": "Rock_Ice_Permafrost"
    },
    {
      "x": -43,
      "y": 4,
      "z": 15,
      "name": "Rock_Ice_Permafrost"
    },
    {
      "x": -43,
      "y": 5,
      "z": 15,
      "name": "Rock_Ice_Permafrost"
    },
    {
      "x": -43,
      "y": 6,
      "z": 15,
      "name": "Rock_Ice"
    },
    {
      "x": -43,
      "y": 7,
      "z": 15,
      "name": "Rock_Ice_Permafrost"
    },
    {
      "x": -43,
      "y": 8,
      "z": 15,
      "name": "Rock_Ice_Permafrost"
    },
    {
      "x": -43,
      "y": 9,
      "z": 15,
      "name": "Rock_Ice_Permafrost"
    },
    {
      "x": -43,
      "y": 10,
      "z": 15,
      "name": "Rock_Ice"
    },
    {
      "x": -43,
      "y": 11,
      "z": 15,
      "name": "Soil_Snow"
    },
    {
      "x": -43,
      "y": 2,
      "z": 16,
      "name": "Rock_Ice_Permafrost"
    },
    {
      "x": -43,
      "y": 3,
      "z": 16,
      "name": "Rock_Ice_Permafrost"
    },
    {
      "x": -43,
      "y": 4,
      "z": 16,
      "name": "Rock_Ice_Permafrost"
    },
    {
      "x": -43,
      "y": 5,
      "z": 16,
      "name": "Rock_Ice_Permafrost"
    },
    {
      "x": -43,
      "y": 6,
      "z": 16,
      "name": "Rock_Ice"
    },
    {
      "x": -43,
      "y": 7,
      "z": 16,
      "name": "Rock_Ice_Permafrost"
    },
    {
      "x": -43,
      "y": 8,
      "z": 16,
      "name": "Rock_Ice_Permafrost"
    },
    {
      "x": -43,
      "y": 9,
      "z": 16,
      "name": "Rock_Ice_Permafrost"
    },
    {
      "x": -43,
      "y": 10,
      "z": 16,
      "name": "Soil_Snow"
    },
    {
      "x": -43,
      "y": 2,
      "z": 17,
      "name": "Rock_Ice_Permafrost"
    },
    {
      "x": -43,
      "y": 3,
      "z": 17,
      "name": "Rock_Ice_Permafrost"
    },
    {
      "x": -43,
      "y": 4,
      "z": 17,
      "name": "Rock_Ice_Permafrost"
    },
    {
      "x": -43,
      "y": 5,
      "z": 17,
      "name": "Rock_Ice_Permafrost"
    },
    {
      "x": -43,
      "y": 6,
      "z": 17,
      "name": "Rock_Ice_Permafrost"
    },
    {
      "x": -43,
      "y": 7,
      "z": 17,
      "name": "Rock_Ice_Permafrost"
    },
    {
      "x": -43,
      "y": 8,
      "z": 17,
      "name": "Rock_Ice_Permafrost"
    },
    {
      "x": -43,
      "y": 9,
      "z": 17,
      "name": "Rock_Ice_Permafrost"
    },
    {
      "x": -43,
      "y": 10,
      "z": 17,
      "name": "Soil_Snow"
    },
    {
      "x": -43,
      "y": 2,
      "z": 18,
      "name": "Rock_Ice_Permafrost"
    },
    {
      "x": -43,
      "y": 3,
      "z": 18,
      "name": "Rock_Ice_Permafrost"
    },
    {
      "x": -43,
      "y": 4,
      "z": 18,
      "name": "Rock_Ice_Permafrost"
    },
    {
      "x": -43,
      "y": 5,
      "z": 18,
      "name": "Rock_Ice_Permafrost"
    },
    {
      "x": -43,
      "y": 6,
      "z": 18,
      "name": "Rock_Ice_Permafrost"
    },
    {
      "x": -43,
      "y": 7,
      "z": 18,
      "name": "Rock_Ice_Permafrost"
    },
    {
      "x": -43,
      "y": 8,
      "z": 18,
      "name": "Rock_Ice_Permafrost"
    },
    {
      "x": -43,
      "y": 9,
      "z": 18,
      "name": "Rock_Ice_Permafrost"
    },
    {
      "x": -43,
      "y": 10,
      "z": 18,
      "name": "Soil_Snow"
    },
    {
      "x": -43,
      "y": 2,
      "z": 19,
      "name": "Rock_Ice_Permafrost"
    },
    {
      "x": -43,
      "y": 3,
      "z": 19,
      "name": "Rock_Ice_Permafrost"
    },
    {
      "x": -43,
      "y": 4,
      "z": 19,
      "name": "Rock_Ice"
    },
    {
      "x": -43,
      "y": 5,
      "z": 19,
      "name": "Rock_Ice_Permafrost"
    },
    {
      "x": -43,
      "y": 6,
      "z": 19,
      "name": "Rock_Ice_Permafrost"
    },
    {
      "x": -43,
      "y": 7,
      "z": 19,
      "name": "Rock_Ice_Permafrost"
    },
    {
      "x": -43,
      "y": 8,
      "z": 19,
      "name": "Rock_Ice_Permafrost"
    },
    {
      "x": -43,
      "y": 9,
      "z": 19,
      "name": "Rock_Ice_Permafrost"
    },
    {
      "x": -43,
      "y": 10,
      "z": 19,
      "name": "Soil_Snow"
    },
    {
      "x": -43,
      "y": 2,
      "z": 20,
      "name": "Rock_Ice_Permafrost"
    },
    {
      "x": -43,
      "y": 3,
      "z": 20,
      "name": "Rock_Ice_Permafrost"
    },
    {
      "x": -43,
      "y": 4,
      "z": 20,
      "name": "Rock_Ice_Permafrost"
    },
    {
      "x": -43,
      "y": 5,
      "z": 20,
      "name": "Rock_Ice_Permafrost"
    },
    {
      "x": -43,
      "y": 6,
      "z": 20,
      "name": "Rock_Ice_Permafrost"
    },
    {
      "x": -43,
      "y": 7,
      "z": 20,
      "name": "Rock_Ice_Permafrost"
    },
    {
      "x": -43,
      "y": 8,
      "z": 20,
      "name": "Rock_Ice"
    },
    {
      "x": -43,
      "y": 9,
      "z": 20,
      "name": "Rock_Ice"
    },
    {
      "x": -43,
      "y": 10,
      "z": 20,
      "name": "Rock_Ice"
    },
    {
      "x": -43,
      "y": 2,
      "z": 21,
      "name": "Rock_Ice_Permafrost"
    },
    {
      "x": -43,
      "y": 3,
      "z": 21,
      "name": "Rock_Ice_Permafrost"
    },
    {
      "x": -43,
      "y": 4,
      "z": 21,
      "name": "Rock_Ice_Permafrost"
    },
    {
      "x": -43,
      "y": 5,
      "z": 21,
      "name": "Rock_Ice_Permafrost"
    },
    {
      "x": -43,
      "y": 6,
      "z": 21,
      "name": "Rock_Ice_Permafrost"
    },
    {
      "x": -43,
      "y": 7,
      "z": 21,
      "name": "Rock_Ice_Permafrost"
    },
    {
      "x": -43,
      "y": 8,
      "z": 21,
      "name": "Rock_Ice"
    },
    {
      "x": -43,
      "y": 9,
      "z": 21,
      "name": "Soil_Snow"
    },
    {
      "x": -43,
      "y": 1,
      "z": 22,
      "name": "Rock_Ice_Permafrost"
    },
    {
      "x": -43,
      "y": 2,
      "z": 22,
      "name": "Rock_Ice_Permafrost"
    },
    {
      "x": -43,
      "y": 3,
      "z": 22,
      "name": "Rock_Ice_Permafrost"
    },
    {
      "x": -43,
      "y": 4,
      "z": 22,
      "name": "Rock_Ice_Permafrost"
    },
    {
      "x": -43,
      "y": 5,
      "z": 22,
      "name": "Rock_Ice_Permafrost"
    },
    {
      "x": -43,
      "y": 6,
      "z": 22,
      "name": "Rock_Ice_Permafrost"
    },
    {
      "x": -43,
      "y": 7,
      "z": 22,
      "name": "Rock_Ice_Permafrost"
    },
    {
      "x": -43,
      "y": 8,
      "z": 22,
      "name": "Rock_Ice"
    },
    {
      "x": -43,
      "y": 9,
      "z": 22,
      "name": "Rock_Ice"
    },
    {
      "x": -43,
      "y": 1,
      "z": 23,
      "name": "Rock_Ice_Permafrost"
    },
    {
      "x": -43,
      "y": 2,
      "z": 23,
      "name": "Rock_Ice_Permafrost"
    },
    {
      "x": -43,
      "y": 3,
      "z": 23,
      "name": "Rock_Ice_Permafrost"
    },
    {
      "x": -43,
      "y": 4,
      "z": 23,
      "name": "Rock_Ice_Permafrost"
    },
    {
      "x": -43,
      "y": 5,
      "z": 23,
      "name": "Rock_Ice_Permafrost"
    },
    {
      "x": -43,
      "y": 6,
      "z": 23,
      "name": "Rock_Ice_Permafrost"
    },
    {
      "x": -43,
      "y": 7,
      "z": 23,
      "name": "Rock_Ice_Permafrost"
    },
    {
      "x": -43,
      "y": 8,
      "z": 23,
      "name": "Rock_Ice"
    },
    {
      "x": -43,
      "y": 9,
      "z": 23,
      "name": "Rock_Ice"
    },
    {
      "x": -43,
      "y": 1,
      "z": 24,
      "name": "Rock_Ice_Permafrost"
    },
    {
      "x": -43,
      "y": 2,
      "z": 24,
      "name": "Rock_Ice_Permafrost"
    },
    {
      "x": -43,
      "y": 3,
      "z": 24,
      "name": "Rock_Ice_Permafrost"
    },
    {
      "x": -43,
      "y": 4,
      "z": 24,
      "name": "Rock_Ice_Permafrost"
    },
    {
      "x": -43,
      "y": 5,
      "z": 24,
      "name": "Rock_Ice_Permafrost"
    },
    {
      "x": -43,
      "y": 6,
      "z": 24,
      "name": "Rock_Ice_Permafrost"
    },
    {
      "x": -43,
      "y": 7,
      "z": 24,
      "name": "Rock_Ice"
    },
    {
      "x": -43,
      "y": 8,
      "z": 24,
      "name": "Soil_Snow"
    },
    {
      "x": -43,
      "y": 1,
      "z": 25,
      "name": "Rock_Ice_Permafrost"
    },
    {
      "x": -43,
      "y": 2,
      "z": 25,
      "name": "Rock_Ice_Permafrost"
    },
    {
      "x": -43,
      "y": 3,
      "z": 25,
      "name": "Rock_Ice_Permafrost"
    },
    {
      "x": -43,
      "y": 4,
      "z": 25,
      "name": "Rock_Ice_Permafrost"
    },
    {
      "x": -43,
      "y": 5,
      "z": 25,
      "name": "Rock_Ice_Permafrost"
    },
    {
      "x": -43,
      "y": 6,
      "z": 25,
      "name": "Rock_Ice_Permafrost"
    },
    {
      "x": -43,
      "y": 7,
      "z": 25,
      "name": "Rock_Ice"
    },
    {
      "x": -43,
      "y": 8,
      "z": 25,
      "name": "Soil_Snow"
    },
    {
      "x": -43,
      "y": 1,
      "z": 26,
      "name": "Rock_Ice_Permafrost"
    },
    {
      "x": -43,
      "y": 2,
      "z": 26,
      "name": "Rock_Ice_Permafrost"
    },
    {
      "x": -43,
      "y": 3,
      "z": 26,
      "name": "Rock_Ice_Permafrost"
    },
    {
      "x": -43,
      "y": 4,
      "z": 26,
      "name": "Rock_Ice_Permafrost"
    },
    {
      "x": -43,
      "y": 5,
      "z": 26,
      "name": "Rock_Ice"
    },
    {
      "x": -43,
      "y": 6,
      "z": 26,
      "name": "Soil_Snow"
    },
    {
      "x": -43,
      "y": 1,
      "z": 27,
      "name": "Rock_Ice_Permafrost"
    },
    {
      "x": -43,
      "y": 2,
      "z": 27,
      "name": "Rock_Ice_Permafrost"
    },
    {
      "x": -43,
      "y": 3,
      "z": 27,
      "name": "Rock_Ice"
    },
    {
      "x": -43,
      "y": 4,
      "z": 27,
      "name": "Soil_Snow"
    },
    {
      "x": -42,
      "y": 38,
      "z": -29,
      "name": "Soil_Snow"
    },
    {
      "x": -42,
      "y": 39,
      "z": -28,
      "name": "Rock_Ice"
    },
    {
      "x": -42,
      "y": 40,
      "z": -28,
      "name": "Soil_Snow"
    },
    {
      "x": -42,
      "y": 39,
      "z": -27,
      "name": "Rock_Ice"
    },
    {
      "x": -42,
      "y": 40,
      "z": -27,
      "name": "Rock_Ice_Permafrost"
    },
    {
      "x": -42,
      "y": 41,
      "z": -27,
      "name": "Rock_Ice"
    },
    {
      "x": -42,
      "y": 42,
      "z": -27,
      "name": "Soil_Snow"
    },
    {
      "x": -42,
      "y": 40,
      "z": -26,
      "name": "Rock_Ice"
    },
    {
      "x": -42,
      "y": 41,
      "z": -26,
      "name": "Rock_Ice_Permafrost"
    },
    {
      "x": -42,
      "y": 42,
      "z": -26,
      "name": "Rock_Ice"
    },
    {
      "x": -42,
      "y": 43,
      "z": -26,
      "name": "Soil_Snow"
    },
    {
      "x": -42,
      "y": 41,
      "z": -25,
      "name": "Rock_Ice"
    },
    {
      "x": -42,
      "y": 42,
      "z": -25,
      "name": "Rock_Ice_Permafrost"
    },
    {
      "x": -42,
      "y": 43,
      "z": -25,
      "name": "Rock_Ice_Permafrost"
    },
    {
      "x": -42,
      "y": 44,
      "z": -25,
      "name": "Rock_Ice_Permafrost"
    },
    {
      "x": -42,
      "y": 45,
      "z": -25,
      "name": "Soil_Snow"
    },
    {
      "x": -42,
      "y": 41,
      "z": -24,
      "name": "Rock_Ice"
    },
    {
      "x": -42,
      "y": 42,
      "z": -24,
      "name": "Rock_Ice"
    },
    {
      "x": -42,
      "y": 43,
      "z": -24,
      "name": "Rock_Ice_Permafrost"
    },
    {
      "x": -42,
      "y": 44,
      "z": -24,
      "name": "Rock_Ice_Permafrost"
    },
    {
      "x": -42,
      "y": 45,
      "z": -24,
      "name": "Rock_Ice_Permafrost"
    },
    {
      "x": -42,
      "y": 46,
      "z": -24,
      "name": "Rock_Ice_Permafrost"
    },
    {
      "x": -42,
      "y": 47,
      "z": -24,
      "name": "Soil_Snow"
    },
    {
      "x": -42,
      "y": 42,
      "z": -23,
      "name": "Rock_Ice"
    },
    {
      "x": -42,
      "y": 43,
      "z": -23,
      "name": "Rock_Ice"
    },
    {
      "x": -42,
      "y": 44,
      "z": -23,
      "name": "Rock_Ice_Permafrost"
    },
    {
      "x": -42,
      "y": 45,
      "z": -23,
      "name": "Rock_Ice"
    },
    {
      "x": -42,
      "y": 46,
      "z": -23,
      "name": "Rock_Ice_Permafrost"
    },
    {
      "x": -42,
      "y": 47,
      "z": -23,
      "name": "Rock_Ice"
    },
    {
      "x": -42,
      "y": 48,
      "z": -23,
      "name": "Rock_Ice_Permafrost"
    },
    {
      "x": -42,
      "y": 43,
      "z": -22,
      "name": "Rock_Ice"
    },
    {
      "x": -42,
      "y": 44,
      "z": -22,
      "name": "Rock_Ice"
    },
    {
      "x": -42,
      "y": 45,
      "z": -22,
      "name": "Rock_Ice"
    },
    {
      "x": -42,
      "y": 46,
      "z": -22,
      "name": "Rock_Ice"
    },
    {
      "x": -42,
      "y": 47,
      "z": -22,
      "name": "Rock_Ice"
    },
    {
      "x": -42,
      "y": 48,
      "z": -22,
      "name": "Soil_Snow"
    },
    {
      "x": -42,
      "y": 46,
      "z": -21,
      "name": "Rock_Ice"
    },
    {
      "x": -42,
      "y": 47,
      "z": -21,
      "name": "Soil_Snow"
    },
    {
      "x": -42,
      "y": 6,
      "z": -5,
      "name": "Soil_Snow"
    },
    {
      "x": -42,
      "y": 6,
      "z": -4,
      "name": "Soil_Snow"
    },
    {
      "x": -42,
      "y": 5,
      "z": -3,
      "name": "Rock_Ice"
    },
    {
      "x": -42,
      "y": 6,
      "z": -3,
      "name": "Soil_Snow"
    },
    {
      "x": -42,
      "y": 4,
      "z": -2,
      "name": "Rock_Ice"
    },
    {
      "x": -42,
      "y": 5,
      "z": -2,
      "name": "Rock_Ice"
    },
    {
      "x": -42,
      "y": 6,
      "z": -2,
      "name": "Soil_Snow"
    },
    {
      "x": -42,
      "y": 4,
      "z": -1,
      "name": "Rock_Ice"
    },
    {
      "x": -42,
      "y": 5,
      "z": -1,
      "name": "Rock_Ice_Permafrost"
    },
    {
      "x": -42,
      "y": 6,
      "z": -1,
      "name": "Rock_Ice"
    },
    {
      "x": -42,
      "y": 7,
      "z": -1,
      "name": "Soil_Snow"
    },
    {
      "x": -42,
      "y": 4,
      "z": 0,
      "name": "Rock_Ice"
    },
    {
      "x": -42,
      "y": 5,
      "z": 0,
      "name": "Rock_Ice"
    },
    {
      "x": -42,
      "y": 6,
      "z": 0,
      "name": "Rock_Ice"
    },
    {
      "x": -42,
      "y": 7,
      "z": 0,
      "name": "Soil_Snow"
    },
    {
      "x": -42,
      "y": 4,
      "z": 1,
      "name": "Rock_Ice"
    },
    {
      "x": -42,
      "y": 5,
      "z": 1,
      "name": "Rock_Ice_Permafrost"
    },
    {
      "x": -42,
      "y": 6,
      "z": 1,
      "name": "Rock_Ice"
    },
    {
      "x": -42,
      "y": 7,
      "z": 1,
      "name": "Rock_Ice"
    },
    {
      "x": -42,
      "y": 8,
      "z": 1,
      "name": "Soil_Snow"
    },
    {
      "x": -42,
      "y": 4,
      "z": 2,
      "name": "Rock_Ice_Permafrost"
    },
    {
      "x": -42,
      "y": 5,
      "z": 2,
      "name": "Rock_Ice"
    },
    {
      "x": -42,
      "y": 6,
      "z": 2,
      "name": "Rock_Ice"
    },
    {
      "x": -42,
      "y": 7,
      "z": 2,
      "name": "Rock_Ice"
    },
    {
      "x": -42,
      "y": 8,
      "z": 2,
      "name": "Rock_Ice"
    },
    {
      "x": -42,
      "y": 9,
      "z": 2,
      "name": "Rock_Ice"
    },
    {
      "x": -42,
      "y": 10,
      "z": 2,
      "name": "Soil_Snow"
    },
    {
      "x": -42,
      "y": 4,
      "z": 3,
      "name": "Rock_Ice"
    },
    {
      "x": -42,
      "y": 5,
      "z": 3,
      "name": "Rock_Ice"
    },
    {
      "x": -42,
      "y": 6,
      "z": 3,
      "name": "Rock_Ice"
    },
    {
      "x": -42,
      "y": 7,
      "z": 3,
      "name": "Rock_Ice"
    },
    {
      "x": -42,
      "y": 8,
      "z": 3,
      "name": "Rock_Ice"
    },
    {
      "x": -42,
      "y": 9,
      "z": 3,
      "name": "Rock_Ice"
    },
    {
      "x": -42,
      "y": 10,
      "z": 3,
      "name": "Rock_Ice"
    },
    {
      "x": -42,
      "y": 4,
      "z": 4,
      "name": "Rock_Ice_Permafrost"
    },
    {
      "x": -42,
      "y": 5,
      "z": 4,
      "name": "Rock_Ice"
    },
    {
      "x": -42,
      "y": 6,
      "z": 4,
      "name": "Rock_Ice"
    },
    {
      "x": -42,
      "y": 7,
      "z": 4,
      "name": "Rock_Ice"
    },
    {
      "x": -42,
      "y": 8,
      "z": 4,
      "name": "Rock_Ice"
    },
    {
      "x": -42,
      "y": 9,
      "z": 4,
      "name": "Rock_Ice"
    },
    {
      "x": -42,
      "y": 10,
      "z": 4,
      "name": "Rock_Ice_Permafrost"
    },
    {
      "x": -42,
      "y": 11,
      "z": 4,
      "name": "Soil_Snow"
    },
    {
      "x": -42,
      "y": 4,
      "z": 5,
      "name": "Rock_Ice"
    },
    {
      "x": -42,
      "y": 5,
      "z": 5,
      "name": "Rock_Ice"
    },
    {
      "x": -42,
      "y": 6,
      "z": 5,
      "name": "Rock_Ice"
    },
    {
      "x": -42,
      "y": 7,
      "z": 5,
      "name": "Rock_Ice"
    },
    {
      "x": -42,
      "y": 8,
      "z": 5,
      "name": "Rock_Ice"
    },
    {
      "x": -42,
      "y": 9,
      "z": 5,
      "name": "Rock_Ice"
    },
    {
      "x": -42,
      "y": 10,
      "z": 5,
      "name": "Rock_Ice"
    },
    {
      "x": -42,
      "y": 11,
      "z": 5,
      "name": "Soil_Snow"
    },
    {
      "x": -42,
      "y": 3,
      "z": 6,
      "name": "Rock_Ice_Permafrost"
    },
    {
      "x": -42,
      "y": 4,
      "z": 6,
      "name": "Rock_Ice"
    },
    {
      "x": -42,
      "y": 5,
      "z": 6,
      "name": "Rock_Ice"
    },
    {
      "x": -42,
      "y": 6,
      "z": 6,
      "name": "Rock_Ice"
    },
    {
      "x": -42,
      "y": 7,
      "z": 6,
      "name": "Rock_Ice"
    },
    {
      "x": -42,
      "y": 8,
      "z": 6,
      "name": "Rock_Ice"
    },
    {
      "x": -42,
      "y": 9,
      "z": 6,
      "name": "Rock_Ice"
    },
    {
      "x": -42,
      "y": 10,
      "z": 6,
      "name": "Rock_Ice_Permafrost"
    },
    {
      "x": -42,
      "y": 11,
      "z": 6,
      "name": "Soil_Snow"
    },
    {
      "x": -42,
      "y": 3,
      "z": 7,
      "name": "Rock_Ice_Permafrost"
    },
    {
      "x": -42,
      "y": 4,
      "z": 7,
      "name": "Rock_Ice"
    },
    {
      "x": -42,
      "y": 5,
      "z": 7,
      "name": "Rock_Ice"
    },
    {
      "x": -42,
      "y": 6,
      "z": 7,
      "name": "Rock_Ice"
    },
    {
      "x": -42,
      "y": 7,
      "z": 7,
      "name": "Rock_Ice"
    },
    {
      "x": -42,
      "y": 8,
      "z": 7,
      "name": "Rock_Ice"
    },
    {
      "x": -42,
      "y": 9,
      "z": 7,
      "name": "Rock_Ice"
    },
    {
      "x": -42,
      "y": 10,
      "z": 7,
      "name": "Rock_Ice"
    },
    {
      "x": -42,
      "y": 11,
      "z": 7,
      "name": "Soil_Snow"
    },
    {
      "x": -42,
      "y": 3,
      "z": 8,
      "name": "Rock_Ice_Permafrost"
    },
    {
      "x": -42,
      "y": 4,
      "z": 8,
      "name": "Rock_Ice"
    },
    {
      "x": -42,
      "y": 5,
      "z": 8,
      "name": "Rock_Ice"
    },
    {
      "x": -42,
      "y": 6,
      "z": 8,
      "name": "Rock_Ice"
    },
    {
      "x": -42,
      "y": 7,
      "z": 8,
      "name": "Rock_Ice"
    },
    {
      "x": -42,
      "y": 8,
      "z": 8,
      "name": "Rock_Ice"
    },
    {
      "x": -42,
      "y": 9,
      "z": 8,
      "name": "Rock_Ice"
    },
    {
      "x": -42,
      "y": 10,
      "z": 8,
      "name": "Rock_Ice"
    },
    {
      "x": -42,
      "y": 11,
      "z": 8,
      "name": "Rock_Ice_Permafrost"
    },
    {
      "x": -42,
      "y": 12,
      "z": 8,
      "name": "Soil_Snow"
    },
    {
      "x": -42,
      "y": 3,
      "z": 9,
      "name": "Rock_Ice_Permafrost"
    },
    {
      "x": -42,
      "y": 4,
      "z": 9,
      "name": "Rock_Ice_Permafrost"
    },
    {
      "x": -42,
      "y": 5,
      "z": 9,
      "name": "Rock_Ice_Permafrost"
    },
    {
      "x": -42,
      "y": 6,
      "z": 9,
      "name": "Rock_Ice"
    },
    {
      "x": -42,
      "y": 7,
      "z": 9,
      "name": "Rock_Ice"
    },
    {
      "x": -42,
      "y": 8,
      "z": 9,
      "name": "Rock_Ice"
    },
    {
      "x": -42,
      "y": 9,
      "z": 9,
      "name": "Rock_Ice"
    },
    {
      "x": -42,
      "y": 10,
      "z": 9,
      "name": "Rock_Ice"
    },
    {
      "x": -42,
      "y": 11,
      "z": 9,
      "name": "Rock_Ice_Permafrost"
    },
    {
      "x": -42,
      "y": 12,
      "z": 9,
      "name": "Soil_Snow"
    },
    {
      "x": -42,
      "y": 3,
      "z": 10,
      "name": "Rock_Ice_Permafrost"
    },
    {
      "x": -42,
      "y": 4,
      "z": 10,
      "name": "Rock_Ice_Permafrost"
    },
    {
      "x": -42,
      "y": 5,
      "z": 10,
      "name": "Rock_Ice"
    },
    {
      "x": -42,
      "y": 6,
      "z": 10,
      "name": "Rock_Ice"
    },
    {
      "x": -42,
      "y": 7,
      "z": 10,
      "name": "Rock_Ice"
    },
    {
      "x": -42,
      "y": 8,
      "z": 10,
      "name": "Rock_Ice_Permafrost"
    },
    {
      "x": -42,
      "y": 9,
      "z": 10,
      "name": "Rock_Ice_Permafrost"
    },
    {
      "x": -42,
      "y": 10,
      "z": 10,
      "name": "Rock_Ice_Permafrost"
    },
    {
      "x": -42,
      "y": 11,
      "z": 10,
      "name": "Rock_Ice_Permafrost"
    },
    {
      "x": -42,
      "y": 12,
      "z": 10,
      "name": "Soil_Snow"
    },
    {
      "x": -42,
      "y": 3,
      "z": 11,
      "name": "Rock_Ice_Permafrost"
    },
    {
      "x": -42,
      "y": 4,
      "z": 11,
      "name": "Rock_Ice_Permafrost"
    },
    {
      "x": -42,
      "y": 5,
      "z": 11,
      "name": "Rock_Ice"
    },
    {
      "x": -42,
      "y": 6,
      "z": 11,
      "name": "Rock_Ice_Permafrost"
    },
    {
      "x": -42,
      "y": 7,
      "z": 11,
      "name": "Rock_Ice"
    },
    {
      "x": -42,
      "y": 8,
      "z": 11,
      "name": "Rock_Ice_Permafrost"
    },
    {
      "x": -42,
      "y": 9,
      "z": 11,
      "name": "Rock_Ice_Permafrost"
    },
    {
      "x": -42,
      "y": 10,
      "z": 11,
      "name": "Rock_Ice_Permafrost"
    },
    {
      "x": -42,
      "y": 11,
      "z": 11,
      "name": "Rock_Ice"
    },
    {
      "x": -42,
      "y": 12,
      "z": 11,
      "name": "Soil_Snow"
    },
    {
      "x": -42,
      "y": 3,
      "z": 12,
      "name": "Rock_Ice_Permafrost"
    },
    {
      "x": -42,
      "y": 4,
      "z": 12,
      "name": "Rock_Ice_Permafrost"
    },
    {
      "x": -42,
      "y": 5,
      "z": 12,
      "name": "Rock_Ice_Permafrost"
    },
    {
      "x": -42,
      "y": 6,
      "z": 12,
      "name": "Rock_Ice"
    },
    {
      "x": -42,
      "y": 7,
      "z": 12,
      "name": "Rock_Ice"
    },
    {
      "x": -42,
      "y": 8,
      "z": 12,
      "name": "Rock_Ice"
    },
    {
      "x": -42,
      "y": 9,
      "z": 12,
      "name": "Rock_Ice_Permafrost"
    },
    {
      "x": -42,
      "y": 10,
      "z": 12,
      "name": "Rock_Ice_Permafrost"
    },
    {
      "x": -42,
      "y": 11,
      "z": 12,
      "name": "Rock_Ice_Permafrost"
    },
    {
      "x": -42,
      "y": 12,
      "z": 12,
      "name": "Soil_Snow"
    },
    {
      "x": -42,
      "y": 3,
      "z": 13,
      "name": "Rock_Ice_Permafrost"
    },
    {
      "x": -42,
      "y": 4,
      "z": 13,
      "name": "Rock_Ice_Permafrost"
    },
    {
      "x": -42,
      "y": 5,
      "z": 13,
      "name": "Rock_Ice_Permafrost"
    },
    {
      "x": -42,
      "y": 6,
      "z": 13,
      "name": "Rock_Ice_Permafrost"
    },
    {
      "x": -42,
      "y": 7,
      "z": 13,
      "name": "Rock_Ice"
    },
    {
      "x": -42,
      "y": 8,
      "z": 13,
      "name": "Rock_Ice_Permafrost"
    },
    {
      "x": -42,
      "y": 9,
      "z": 13,
      "name": "Rock_Ice_Permafrost"
    },
    {
      "x": -42,
      "y": 10,
      "z": 13,
      "name": "Rock_Ice_Permafrost"
    },
    {
      "x": -42,
      "y": 11,
      "z": 13,
      "name": "Rock_Ice_Permafrost"
    },
    {
      "x": -42,
      "y": 12,
      "z": 13,
      "name": "Soil_Snow"
    },
    {
      "x": -42,
      "y": 2,
      "z": 14,
      "name": "Rock_Ice_Permafrost"
    },
    {
      "x": -42,
      "y": 3,
      "z": 14,
      "name": "Rock_Ice_Permafrost"
    },
    {
      "x": -42,
      "y": 4,
      "z": 14,
      "name": "Rock_Ice_Permafrost"
    },
    {
      "x": -42,
      "y": 5,
      "z": 14,
      "name": "Rock_Ice_Permafrost"
    },
    {
      "x": -42,
      "y": 6,
      "z": 14,
      "name": "Rock_Ice_Permafrost"
    },
    {
      "x": -42,
      "y": 7,
      "z": 14,
      "name": "Rock_Ice_Permafrost"
    },
    {
      "x": -42,
      "y": 8,
      "z": 14,
      "name": "Rock_Ice"
    },
    {
      "x": -42,
      "y": 9,
      "z": 14,
      "name": "Rock_Ice_Permafrost"
    },
    {
      "x": -42,
      "y": 10,
      "z": 14,
      "name": "Rock_Ice_Permafrost"
    },
    {
      "x": -42,
      "y": 11,
      "z": 14,
      "name": "Rock_Ice_Permafrost"
    },
    {
      "x": -42,
      "y": 12,
      "z": 14,
      "name": "Soil_Snow"
    },
    {
      "x": -42,
      "y": 2,
      "z": 15,
      "name": "Rock_Ice_Permafrost"
    },
    {
      "x": -42,
      "y": 3,
      "z": 15,
      "name": "Rock_Ice_Permafrost"
    },
    {
      "x": -42,
      "y": 4,
      "z": 15,
      "name": "Rock_Ice_Permafrost"
    },
    {
      "x": -42,
      "y": 5,
      "z": 15,
      "name": "Rock_Ice_Permafrost"
    },
    {
      "x": -42,
      "y": 6,
      "z": 15,
      "name": "Rock_Ice_Permafrost"
    },
    {
      "x": -42,
      "y": 7,
      "z": 15,
      "name": "Rock_Ice_Permafrost"
    },
    {
      "x": -42,
      "y": 8,
      "z": 15,
      "name": "Rock_Ice_Permafrost"
    },
    {
      "x": -42,
      "y": 9,
      "z": 15,
      "name": "Rock_Ice_Permafrost"
    },
    {
      "x": -42,
      "y": 10,
      "z": 15,
      "name": "Rock_Ice_Permafrost"
    },
    {
      "x": -42,
      "y": 11,
      "z": 15,
      "name": "Rock_Ice"
    },
    {
      "x": -42,
      "y": 12,
      "z": 15,
      "name": "Soil_Snow"
    },
    {
      "x": -42,
      "y": 2,
      "z": 16,
      "name": "Rock_Ice_Permafrost"
    },
    {
      "x": -42,
      "y": 3,
      "z": 16,
      "name": "Rock_Ice_Permafrost"
    },
    {
      "x": -42,
      "y": 4,
      "z": 16,
      "name": "Rock_Ice_Permafrost"
    },
    {
      "x": -42,
      "y": 5,
      "z": 16,
      "name": "Rock_Ice_Permafrost"
    },
    {
      "x": -42,
      "y": 6,
      "z": 16,
      "name": "Rock_Ice_Permafrost"
    },
    {
      "x": -42,
      "y": 7,
      "z": 16,
      "name": "Rock_Ice_Permafrost"
    },
    {
      "x": -42,
      "y": 8,
      "z": 16,
      "name": "Rock_Ice_Permafrost"
    },
    {
      "x": -42,
      "y": 9,
      "z": 16,
      "name": "Rock_Ice_Permafrost"
    },
    {
      "x": -42,
      "y": 10,
      "z": 16,
      "name": "Rock_Ice_Permafrost"
    },
    {
      "x": -42,
      "y": 11,
      "z": 16,
      "name": "Rock_Ice_Permafrost"
    },
    {
      "x": -42,
      "y": 12,
      "z": 16,
      "name": "Soil_Snow"
    },
    {
      "x": -42,
      "y": 2,
      "z": 17,
      "name": "Rock_Ice"
    },
    {
      "x": -42,
      "y": 3,
      "z": 17,
      "name": "Rock_Ice"
    },
    {
      "x": -42,
      "y": 4,
      "z": 17,
      "name": "Rock_Ice_Permafrost"
    },
    {
      "x": -42,
      "y": 5,
      "z": 17,
      "name": "Rock_Ice_Permafrost"
    },
    {
      "x": -42,
      "y": 6,
      "z": 17,
      "name": "Rock_Ice_Permafrost"
    },
    {
      "x": -42,
      "y": 7,
      "z": 17,
      "name": "Rock_Ice_Permafrost"
    },
    {
      "x": -42,
      "y": 8,
      "z": 17,
      "name": "Rock_Ice_Permafrost"
    },
    {
      "x": -42,
      "y": 9,
      "z": 17,
      "name": "Rock_Ice_Permafrost"
    },
    {
      "x": -42,
      "y": 10,
      "z": 17,
      "name": "Rock_Ice_Permafrost"
    },
    {
      "x": -42,
      "y": 11,
      "z": 17,
      "name": "Soil_Snow"
    },
    {
      "x": -42,
      "y": 2,
      "z": 18,
      "name": "Rock_Ice_Permafrost"
    },
    {
      "x": -42,
      "y": 3,
      "z": 18,
      "name": "Rock_Ice_Permafrost"
    },
    {
      "x": -42,
      "y": 4,
      "z": 18,
      "name": "Rock_Ice_Permafrost"
    },
    {
      "x": -42,
      "y": 5,
      "z": 18,
      "name": "Rock_Ice_Permafrost"
    },
    {
      "x": -42,
      "y": 6,
      "z": 18,
      "name": "Rock_Ice_Permafrost"
    },
    {
      "x": -42,
      "y": 7,
      "z": 18,
      "name": "Rock_Ice_Permafrost"
    },
    {
      "x": -42,
      "y": 8,
      "z": 18,
      "name": "Rock_Ice_Permafrost"
    },
    {
      "x": -42,
      "y": 9,
      "z": 18,
      "name": "Rock_Ice_Permafrost"
    },
    {
      "x": -42,
      "y": 10,
      "z": 18,
      "name": "Rock_Ice"
    },
    {
      "x": -42,
      "y": 11,
      "z": 18,
      "name": "Soil_Snow"
    },
    {
      "x": -42,
      "y": 2,
      "z": 19,
      "name": "Rock_Ice_Permafrost"
    },
    {
      "x": -42,
      "y": 3,
      "z": 19,
      "name": "Rock_Ice_Permafrost"
    },
    {
      "x": -42,
      "y": 4,
      "z": 19,
      "name": "Rock_Ice_Permafrost"
    },
    {
      "x": -42,
      "y": 5,
      "z": 19,
      "name": "Rock_Ice_Permafrost"
    },
    {
      "x": -42,
      "y": 6,
      "z": 19,
      "name": "Rock_Ice_Permafrost"
    },
    {
      "x": -42,
      "y": 7,
      "z": 19,
      "name": "Rock_Ice_Permafrost"
    },
    {
      "x": -42,
      "y": 8,
      "z": 19,
      "name": "Rock_Ice_Permafrost"
    },
    {
      "x": -42,
      "y": 9,
      "z": 19,
      "name": "Rock_Ice_Permafrost"
    },
    {
      "x": -42,
      "y": 10,
      "z": 19,
      "name": "Rock_Ice"
    },
    {
      "x": -42,
      "y": 11,
      "z": 19,
      "name": "Rock_Ice"
    },
    {
      "x": -42,
      "y": 2,
      "z": 20,
      "name": "Rock_Ice_Permafrost"
    },
    {
      "x": -42,
      "y": 3,
      "z": 20,
      "name": "Rock_Ice_Permafrost"
    },
    {
      "x": -42,
      "y": 4,
      "z": 20,
      "name": "Rock_Ice_Permafrost"
    },
    {
      "x": -42,
      "y": 5,
      "z": 20,
      "name": "Rock_Ice_Permafrost"
    },
    {
      "x": -42,
      "y": 6,
      "z": 20,
      "name": "Rock_Ice_Permafrost"
    },
    {
      "x": -42,
      "y": 7,
      "z": 20,
      "name": "Rock_Ice_Permafrost"
    },
    {
      "x": -42,
      "y": 8,
      "z": 20,
      "name": "Rock_Ice_Permafrost"
    },
    {
      "x": -42,
      "y": 9,
      "z": 20,
      "name": "Rock_Ice_Permafrost"
    },
    {
      "x": -42,
      "y": 10,
      "z": 20,
      "name": "Rock_Ice"
    },
    {
      "x": -42,
      "y": 11,
      "z": 20,
      "name": "Rock_Ice"
    },
    {
      "x": -42,
      "y": 2,
      "z": 21,
      "name": "Rock_Ice_Permafrost"
    },
    {
      "x": -42,
      "y": 3,
      "z": 21,
      "name": "Rock_Ice_Permafrost"
    },
    {
      "x": -42,
      "y": 4,
      "z": 21,
      "name": "Rock_Ice_Permafrost"
    },
    {
      "x": -42,
      "y": 5,
      "z": 21,
      "name": "Rock_Ice_Permafrost"
    },
    {
      "x": -42,
      "y": 6,
      "z": 21,
      "name": "Rock_Ice_Permafrost"
    },
    {
      "x": -42,
      "y": 7,
      "z": 21,
      "name": "Rock_Ice_Permafrost"
    },
    {
      "x": -42,
      "y": 8,
      "z": 21,
      "name": "Rock_Ice"
    },
    {
      "x": -42,
      "y": 9,
      "z": 21,
      "name": "Rock_Ice_Permafrost"
    },
    {
      "x": -42,
      "y": 10,
      "z": 21,
      "name": "Rock_Ice_Permafrost"
    },
    {
      "x": -42,
      "y": 11,
      "z": 21,
      "name": "Rock_Ice"
    },
    {
      "x": -42,
      "y": 2,
      "z": 22,
      "name": "Rock_Ice_Permafrost"
    },
    {
      "x": -42,
      "y": 3,
      "z": 22,
      "name": "Rock_Ice_Permafrost"
    },
    {
      "x": -42,
      "y": 4,
      "z": 22,
      "name": "Rock_Ice_Permafrost"
    },
    {
      "x": -42,
      "y": 5,
      "z": 22,
      "name": "Rock_Ice_Permafrost"
    },
    {
      "x": -42,
      "y": 6,
      "z": 22,
      "name": "Rock_Ice_Permafrost"
    },
    {
      "x": -42,
      "y": 7,
      "z": 22,
      "name": "Rock_Ice_Permafrost"
    },
    {
      "x": -42,
      "y": 8,
      "z": 22,
      "name": "Rock_Ice_Permafrost"
    },
    {
      "x": -42,
      "y": 9,
      "z": 22,
      "name": "Rock_Ice_Permafrost"
    },
    {
      "x": -42,
      "y": 10,
      "z": 22,
      "name": "Rock_Ice"
    },
    {
      "x": -42,
      "y": 11,
      "z": 22,
      "name": "Soil_Snow"
    },
    {
      "x": -42,
      "y": 2,
      "z": 23,
      "name": "Rock_Ice_Permafrost"
    },
    {
      "x": -42,
      "y": 3,
      "z": 23,
      "name": "Rock_Ice_Permafrost"
    },
    {
      "x": -42,
      "y": 4,
      "z": 23,
      "name": "Rock_Ice_Permafrost"
    },
    {
      "x": -42,
      "y": 5,
      "z": 23,
      "name": "Rock_Ice_Permafrost"
    },
    {
      "x": -42,
      "y": 6,
      "z": 23,
      "name": "Rock_Ice_Permafrost"
    },
    {
      "x": -42,
      "y": 7,
      "z": 23,
      "name": "Rock_Ice_Permafrost"
    },
    {
      "x": -42,
      "y": 8,
      "z": 23,
      "name": "Rock_Ice_Permafrost"
    },
    {
      "x": -42,
      "y": 9,
      "z": 23,
      "name": "Rock_Ice"
    },
    {
      "x": -42,
      "y": 10,
      "z": 23,
      "name": "Rock_Ice"
    },
    {
      "x": -42,
      "y": 2,
      "z": 24,
      "name": "Rock_Ice_Permafrost"
    },
    {
      "x": -42,
      "y": 3,
      "z": 24,
      "name": "Rock_Ice_Permafrost"
    },
    {
      "x": -42,
      "y": 4,
      "z": 24,
      "name": "Rock_Ice_Permafrost"
    },
    {
      "x": -42,
      "y": 5,
      "z": 24,
      "name": "Rock_Ice_Permafrost"
    },
    {
      "x": -42,
      "y": 6,
      "z": 24,
      "name": "Rock_Ice_Permafrost"
    },
    {
      "x": -42,
      "y": 7,
      "z": 24,
      "name": "Rock_Ice_Permafrost"
    },
    {
      "x": -42,
      "y": 8,
      "z": 24,
      "name": "Rock_Ice_Permafrost"
    },
    {
      "x": -42,
      "y": 9,
      "z": 24,
      "name": "Rock_Ice"
    },
    {
      "x": -42,
      "y": 10,
      "z": 24,
      "name": "Rock_Ice_Permafrost"
    },
    {
      "x": -42,
      "y": 2,
      "z": 25,
      "name": "Rock_Ice_Permafrost"
    },
    {
      "x": -42,
      "y": 3,
      "z": 25,
      "name": "Rock_Ice_Permafrost"
    },
    {
      "x": -42,
      "y": 4,
      "z": 25,
      "name": "Rock_Ice_Permafrost"
    },
    {
      "x": -42,
      "y": 5,
      "z": 25,
      "name": "Rock_Ice_Permafrost"
    },
    {
      "x": -42,
      "y": 6,
      "z": 25,
      "name": "Rock_Ice_Permafrost"
    },
    {
      "x": -42,
      "y": 7,
      "z": 25,
      "name": "Rock_Ice_Permafrost"
    },
    {
      "x": -42,
      "y": 8,
      "z": 25,
      "name": "Rock_Ice"
    },
    {
      "x": -42,
      "y": 9,
      "z": 25,
      "name": "Soil_Snow"
    },
    {
      "x": -42,
      "y": 2,
      "z": 26,
      "name": "Rock_Ice_Permafrost"
    },
    {
      "x": -42,
      "y": 3,
      "z": 26,
      "name": "Rock_Ice_Permafrost"
    },
    {
      "x": -42,
      "y": 4,
      "z": 26,
      "name": "Rock_Ice_Permafrost"
    },
    {
      "x": -42,
      "y": 5,
      "z": 26,
      "name": "Rock_Ice_Permafrost"
    },
    {
      "x": -42,
      "y": 6,
      "z": 26,
      "name": "Rock_Ice_Permafrost"
    },
    {
      "x": -42,
      "y": 7,
      "z": 26,
      "name": "Rock_Ice"
    },
    {
      "x": -42,
      "y": 8,
      "z": 26,
      "name": "Soil_Snow"
    },
    {
      "x": -42,
      "y": 2,
      "z": 27,
      "name": "Rock_Ice_Permafrost"
    },
    {
      "x": -42,
      "y": 3,
      "z": 27,
      "name": "Rock_Ice_Permafrost"
    },
    {
      "x": -42,
      "y": 4,
      "z": 27,
      "name": "Rock_Ice_Permafrost"
    },
    {
      "x": -42,
      "y": 5,
      "z": 27,
      "name": "Rock_Ice"
    },
    {
      "x": -42,
      "y": 6,
      "z": 27,
      "name": "Rock_Ice_Permafrost"
    },
    {
      "x": -42,
      "y": 2,
      "z": 28,
      "name": "Rock_Ice_Permafrost"
    },
    {
      "x": -42,
      "y": 3,
      "z": 28,
      "name": "Rock_Ice"
    },
    {
      "x": -42,
      "y": 4,
      "z": 28,
      "name": "Soil_Snow"
    },
    {
      "x": -41,
      "y": 37,
      "z": -30,
      "name": "Rock_Ice_Permafrost"
    },
    {
      "x": -41,
      "y": 37,
      "z": -29,
      "name": "Rock_Ice"
    },
    {
      "x": -41,
      "y": 38,
      "z": -29,
      "name": "Rock_Ice"
    },
    {
      "x": -41,
      "y": 39,
      "z": -29,
      "name": "Rock_Ice_Permafrost"
    },
    {
      "x": -41,
      "y": 38,
      "z": -28,
      "name": "Rock_Ice"
    },
    {
      "x": -41,
      "y": 39,
      "z": -28,
      "name": "Rock_Ice_Permafrost"
    },
    {
      "x": -41,
      "y": 40,
      "z": -28,
      "name": "Rock_Ice_Permafrost"
    },
    {
      "x": -41,
      "y": 41,
      "z": -28,
      "name": "Soil_Snow"
    },
    {
      "x": -41,
      "y": 39,
      "z": -27,
      "name": "Rock_Ice"
    },
    {
      "x": -41,
      "y": 40,
      "z": -27,
      "name": "Rock_Ice_Permafrost"
    },
    {
      "x": -41,
      "y": 41,
      "z": -27,
      "name": "Rock_Ice"
    },
    {
      "x": -41,
      "y": 42,
      "z": -27,
      "name": "Soil_Snow"
    },
    {
      "x": -41,
      "y": 40,
      "z": -26,
      "name": "Rock_Ice"
    },
    {
      "x": -41,
      "y": 41,
      "z": -26,
      "name": "Rock_Ice_Permafrost"
    },
    {
      "x": -41,
      "y": 42,
      "z": -26,
      "name": "Rock_Ice_Permafrost"
    },
    {
      "x": -41,
      "y": 43,
      "z": -26,
      "name": "Rock_Ice"
    },
    {
      "x": -41,
      "y": 44,
      "z": -26,
      "name": "Soil_Snow"
    },
    {
      "x": -41,
      "y": 40,
      "z": -25,
      "name": "Rock_Ice"
    },
    {
      "x": -41,
      "y": 41,
      "z": -25,
      "name": "Rock_Ice"
    },
    {
      "x": -41,
      "y": 42,
      "z": -25,
      "name": "Rock_Ice_Permafrost"
    },
    {
      "x": -41,
      "y": 43,
      "z": -25,
      "name": "Rock_Ice_Permafrost"
    },
    {
      "x": -41,
      "y": 44,
      "z": -25,
      "name": "Rock_Ice"
    },
    {
      "x": -41,
      "y": 45,
      "z": -25,
      "name": "Soil_Snow"
    },
    {
      "x": -41,
      "y": 41,
      "z": -24,
      "name": "Rock_Ice"
    },
    {
      "x": -41,
      "y": 42,
      "z": -24,
      "name": "Rock_Ice"
    },
    {
      "x": -41,
      "y": 43,
      "z": -24,
      "name": "Rock_Ice_Permafrost"
    },
    {
      "x": -41,
      "y": 44,
      "z": -24,
      "name": "Rock_Ice"
    },
    {
      "x": -41,
      "y": 45,
      "z": -24,
      "name": "Rock_Ice_Permafrost"
    },
    {
      "x": -41,
      "y": 46,
      "z": -24,
      "name": "Rock_Ice"
    },
    {
      "x": -41,
      "y": 47,
      "z": -24,
      "name": "Rock_Ice_Permafrost"
    },
    {
      "x": -41,
      "y": 42,
      "z": -23,
      "name": "Rock_Ice"
    },
    {
      "x": -41,
      "y": 43,
      "z": -23,
      "name": "Rock_Ice"
    },
    {
      "x": -41,
      "y": 44,
      "z": -23,
      "name": "Rock_Ice_Permafrost"
    },
    {
      "x": -41,
      "y": 45,
      "z": -23,
      "name": "Rock_Ice"
    },
    {
      "x": -41,
      "y": 46,
      "z": -23,
      "name": "Rock_Ice_Permafrost"
    },
    {
      "x": -41,
      "y": 47,
      "z": -23,
      "name": "Rock_Ice"
    },
    {
      "x": -41,
      "y": 48,
      "z": -23,
      "name": "Rock_Ice"
    },
    {
      "x": -41,
      "y": 49,
      "z": -23,
      "name": "Rock_Ice_Permafrost"
    },
    {
      "x": -41,
      "y": 43,
      "z": -22,
      "name": "Rock_Ice"
    },
    {
      "x": -41,
      "y": 44,
      "z": -22,
      "name": "Rock_Ice"
    },
    {
      "x": -41,
      "y": 45,
      "z": -22,
      "name": "Rock_Ice"
    },
    {
      "x": -41,
      "y": 46,
      "z": -22,
      "name": "Rock_Ice"
    },
    {
      "x": -41,
      "y": 47,
      "z": -22,
      "name": "Rock_Ice"
    },
    {
      "x": -41,
      "y": 48,
      "z": -22,
      "name": "Rock_Ice_Permafrost"
    },
    {
      "x": -41,
      "y": 49,
      "z": -22,
      "name": "Rock_Ice"
    },
    {
      "x": -41,
      "y": 50,
      "z": -22,
      "name": "Soil_Snow"
    },
    {
      "x": -41,
      "y": 46,
      "z": -21,
      "name": "Rock_Ice"
    },
    {
      "x": -41,
      "y": 47,
      "z": -21,
      "name": "Rock_Ice"
    },
    {
      "x": -41,
      "y": 48,
      "z": -21,
      "name": "Soil_Snow"
    },
    {
      "x": -41,
      "y": 7,
      "z": -7,
      "name": "Soil_Snow"
    },
    {
      "x": -41,
      "y": 6,
      "z": -6,
      "name": "Rock_Ice"
    },
    {
      "x": -41,
      "y": 7,
      "z": -6,
      "name": "Soil_Snow"
    },
    {
      "x": -41,
      "y": 6,
      "z": -5,
      "name": "Rock_Ice"
    },
    {
      "x": -41,
      "y": 7,
      "z": -5,
      "name": "Soil_Snow"
    },
    {
      "x": -41,
      "y": 6,
      "z": -4,
      "name": "Rock_Ice"
    },
    {
      "x": -41,
      "y": 7,
      "z": -4,
      "name": "Rock_Ice"
    },
    {
      "x": -41,
      "y": 8,
      "z": -4,
      "name": "Soil_Snow"
    },
    {
      "x": -41,
      "y": 5,
      "z": -3,
      "name": "Rock_Ice"
    },
    {
      "x": -41,
      "y": 6,
      "z": -3,
      "name": "Rock_Ice"
    },
    {
      "x": -41,
      "y": 7,
      "z": -3,
      "name": "Rock_Ice"
    },
    {
      "x": -41,
      "y": 8,
      "z": -3,
      "name": "Soil_Snow"
    },
    {
      "x": -41,
      "y": 5,
      "z": -2,
      "name": "Rock_Ice"
    },
    {
      "x": -41,
      "y": 6,
      "z": -2,
      "name": "Rock_Ice"
    },
    {
      "x": -41,
      "y": 7,
      "z": -2,
      "name": "Rock_Ice"
    },
    {
      "x": -41,
      "y": 8,
      "z": -2,
      "name": "Soil_Snow"
    },
    {
      "x": -41,
      "y": 5,
      "z": -1,
      "name": "Rock_Ice_Permafrost"
    },
    {
      "x": -41,
      "y": 6,
      "z": -1,
      "name": "Rock_Ice"
    },
    {
      "x": -41,
      "y": 7,
      "z": -1,
      "name": "Rock_Ice"
    },
    {
      "x": -41,
      "y": 8,
      "z": -1,
      "name": "Soil_Snow"
    },
    {
      "x": -41,
      "y": 4,
      "z": 0,
      "name": "Rock_Ice"
    },
    {
      "x": -41,
      "y": 5,
      "z": 0,
      "name": "Rock_Ice_Permafrost"
    },
    {
      "x": -41,
      "y": 6,
      "z": 0,
      "name": "Rock_Ice"
    },
    {
      "x": -41,
      "y": 7,
      "z": 0,
      "name": "Rock_Ice"
    },
    {
      "x": -41,
      "y": 8,
      "z": 0,
      "name": "Rock_Ice"
    },
    {
      "x": -41,
      "y": 9,
      "z": 0,
      "name": "Soil_Snow"
    },
    {
      "x": -41,
      "y": 4,
      "z": 1,
      "name": "Rock_Ice"
    },
    {
      "x": -41,
      "y": 5,
      "z": 1,
      "name": "Rock_Ice_Permafrost"
    },
    {
      "x": -41,
      "y": 6,
      "z": 1,
      "name": "Rock_Ice"
    },
    {
      "x": -41,
      "y": 7,
      "z": 1,
      "name": "Rock_Ice"
    },
    {
      "x": -41,
      "y": 8,
      "z": 1,
      "name": "Rock_Ice"
    },
    {
      "x": -41,
      "y": 9,
      "z": 1,
      "name": "Rock_Ice"
    },
    {
      "x": -41,
      "y": 10,
      "z": 1,
      "name": "Rock_Ice"
    },
    {
      "x": -41,
      "y": 11,
      "z": 1,
      "name": "Soil_Snow"
    },
    {
      "x": -41,
      "y": 4,
      "z": 2,
      "name": "Rock_Ice"
    },
    {
      "x": -41,
      "y": 5,
      "z": 2,
      "name": "Rock_Ice_Permafrost"
    },
    {
      "x": -41,
      "y": 6,
      "z": 2,
      "name": "Rock_Ice"
    },
    {
      "x": -41,
      "y": 7,
      "z": 2,
      "name": "Rock_Ice"
    },
    {
      "x": -41,
      "y": 8,
      "z": 2,
      "name": "Rock_Ice"
    },
    {
      "x": -41,
      "y": 9,
      "z": 2,
      "name": "Rock_Ice"
    },
    {
      "x": -41,
      "y": 10,
      "z": 2,
      "name": "Rock_Ice"
    },
    {
      "x": -41,
      "y": 11,
      "z": 2,
      "name": "Rock_Ice"
    },
    {
      "x": -41,
      "y": 4,
      "z": 3,
      "name": "Rock_Ice_Permafrost"
    },
    {
      "x": -41,
      "y": 5,
      "z": 3,
      "name": "Rock_Ice"
    },
    {
      "x": -41,
      "y": 6,
      "z": 3,
      "name": "Rock_Ice"
    },
    {
      "x": -41,
      "y": 7,
      "z": 3,
      "name": "Rock_Ice"
    },
    {
      "x": -41,
      "y": 8,
      "z": 3,
      "name": "Rock_Ice"
    },
    {
      "x": -41,
      "y": 9,
      "z": 3,
      "name": "Rock_Ice"
    },
    {
      "x": -41,
      "y": 10,
      "z": 3,
      "name": "Rock_Ice"
    },
    {
      "x": -41,
      "y": 11,
      "z": 3,
      "name": "Rock_Ice_Permafrost"
    },
    {
      "x": -41,
      "y": 12,
      "z": 3,
      "name": "Soil_Snow"
    },
    {
      "x": -41,
      "y": 4,
      "z": 4,
      "name": "Rock_Ice_Permafrost"
    },
    {
      "x": -41,
      "y": 5,
      "z": 4,
      "name": "Rock_Ice"
    },
    {
      "x": -41,
      "y": 6,
      "z": 4,
      "name": "Rock_Ice"
    },
    {
      "x": -41,
      "y": 7,
      "z": 4,
      "name": "Rock_Ice"
    },
    {
      "x": -41,
      "y": 8,
      "z": 4,
      "name": "Rock_Ice"
    },
    {
      "x": -41,
      "y": 9,
      "z": 4,
      "name": "Rock_Ice"
    },
    {
      "x": -41,
      "y": 10,
      "z": 4,
      "name": "Rock_Ice"
    },
    {
      "x": -41,
      "y": 11,
      "z": 4,
      "name": "Rock_Ice_Permafrost"
    },
    {
      "x": -41,
      "y": 12,
      "z": 4,
      "name": "Soil_Snow"
    },
    {
      "x": -41,
      "y": 4,
      "z": 5,
      "name": "Rock_Ice_Permafrost"
    },
    {
      "x": -41,
      "y": 5,
      "z": 5,
      "name": "Rock_Ice"
    },
    {
      "x": -41,
      "y": 6,
      "z": 5,
      "name": "Rock_Ice"
    },
    {
      "x": -41,
      "y": 7,
      "z": 5,
      "name": "Rock_Ice"
    },
    {
      "x": -41,
      "y": 8,
      "z": 5,
      "name": "Rock_Ice"
    },
    {
      "x": -41,
      "y": 9,
      "z": 5,
      "name": "Rock_Ice"
    },
    {
      "x": -41,
      "y": 10,
      "z": 5,
      "name": "Rock_Ice"
    },
    {
      "x": -41,
      "y": 11,
      "z": 5,
      "name": "Rock_Ice_Permafrost"
    },
    {
      "x": -41,
      "y": 12,
      "z": 5,
      "name": "Soil_Snow"
    },
    {
      "x": -41,
      "y": 4,
      "z": 6,
      "name": "Rock_Ice_Permafrost"
    },
    {
      "x": -41,
      "y": 5,
      "z": 6,
      "name": "Rock_Ice"
    },
    {
      "x": -41,
      "y": 6,
      "z": 6,
      "name": "Rock_Ice"
    },
    {
      "x": -41,
      "y": 7,
      "z": 6,
      "name": "Rock_Ice"
    },
    {
      "x": -41,
      "y": 8,
      "z": 6,
      "name": "Rock_Ice"
    },
    {
      "x": -41,
      "y": 9,
      "z": 6,
      "name": "Rock_Ice"
    },
    {
      "x": -41,
      "y": 10,
      "z": 6,
      "name": "Rock_Ice"
    },
    {
      "x": -41,
      "y": 11,
      "z": 6,
      "name": "Rock_Ice"
    },
    {
      "x": -41,
      "y": 12,
      "z": 6,
      "name": "Soil_Snow"
    },
    {
      "x": -41,
      "y": 4,
      "z": 7,
      "name": "Rock_Ice_Permafrost"
    },
    {
      "x": -41,
      "y": 5,
      "z": 7,
      "name": "Rock_Ice_Permafrost"
    },
    {
      "x": -41,
      "y": 6,
      "z": 7,
      "name": "Rock_Ice"
    },
    {
      "x": -41,
      "y": 7,
      "z": 7,
      "name": "Rock_Ice"
    },
    {
      "x": -41,
      "y": 8,
      "z": 7,
      "name": "Rock_Ice"
    },
    {
      "x": -41,
      "y": 9,
      "z": 7,
      "name": "Rock_Ice"
    },
    {
      "x": -41,
      "y": 10,
      "z": 7,
      "name": "Rock_Ice"
    },
    {
      "x": -41,
      "y": 11,
      "z": 7,
      "name": "Rock_Ice"
    },
    {
      "x": -41,
      "y": 12,
      "z": 7,
      "name": "Rock_Ice"
    },
    {
      "x": -41,
      "y": 13,
      "z": 7,
      "name": "Soil_Snow"
    },
    {
      "x": -41,
      "y": 3,
      "z": 8,
      "name": "Rock_Ice_Permafrost"
    },
    {
      "x": -41,
      "y": 4,
      "z": 8,
      "name": "Rock_Ice"
    },
    {
      "x": -41,
      "y": 5,
      "z": 8,
      "name": "Rock_Ice_Permafrost"
    },
    {
      "x": -41,
      "y": 6,
      "z": 8,
      "name": "Rock_Ice"
    },
    {
      "x": -41,
      "y": 7,
      "z": 8,
      "name": "Rock_Ice"
    },
    {
      "x": -41,
      "y": 8,
      "z": 8,
      "name": "Rock_Ice"
