{
  "version": 8,
  "blockIdVersion": 11,
  "anchorX": 14,
  "anchorY": 45,
  "anchorZ": -7,
  "blocks": [
    {
      "x": -51,
      "y": 43,
      "z": -26,
      "name": "Rock_Ice"
    },
    {
      "x": -51,
      "y": 44,
      "z": -26,
      "name": "Rock_Ice_Permafrost"
    },
    {
      "x": -51,
      "y": 41,
      "z": -25,
      "name": "Rock_Ice"
    },
    {
      "x": -51,
      "y": 42,
      "z": -25,
      "name": "Rock_Ice_Permafrost"
    },
    {
      "x": -51,
      "y": 43,
      "z": -25,
      "name": "Rock_Ice"
    },
    {
      "x": -51,
      "y": 44,
      "z": -25,
      "name": "Soil_Snow"
    },
    {
      "x": -51,
      "y": 40,
      "z": -24,
      "name": "Rock_Ice"
    },
    {
      "x": -51,
      "y": 41,
      "z": -24,
      "name": "Rock_Ice_Permafrost"
    },
    {
      "x": -51,
      "y": 42,
      "z": -24,
      "name": "Rock_Ice"
    },
    {
      "x": -51,
      "y": 43,
      "z": -24,
      "name": "Soil_Snow"
    },
    {
      "x": -51,
      "y": 40,
      "z": -23,
      "name": "Rock_Ice"
    },
    {
      "x": -51,
      "y": 41,
      "z": -23,
      "name": "Rock_Ice_Permafrost"
    },
    {
      "x": -51,
      "y": 42,
      "z": -23,
      "name": "Rock_Ice"
    },
    {
      "x": -51,
      "y": 43,
      "z": -23,
      "name": "Soil_Snow"
    },
    {
      "x": -51,
      "y": 40,
      "z": -22,
      "name": "Rock_Ice"
    },
    {
      "x": -51,
      "y": 41,
      "z": -22,
      "name": "Rock_Ice"
    },
    {
      "x": -51,
      "y": 42,
      "z": -22,
      "name": "Soil_Snow"
    },
    {
      "x": -51,
      "y": 40,
      "z": -21,
      "name": "Rock_Ice_Permafrost"
    },
    {
      "x": -51,
      "y": 41,
      "z": -21,
      "name": "Rock_Ice"
    },
    {
      "x": -51,
      "y": 42,
      "z": -21,
      "name": "Soil_Snow"
    },
    {
      "x": -51,
      "y": 40,
      "z": -20,
      "name": "Rock_Ice"
    },
    {
      "x": -51,
      "y": 41,
      "z": -20,
      "name": "Soil_Snow"
    },
    {
      "x": -51,
      "y": 40,
      "z": -19,
      "name": "Soil_Snow"
    },
    {
      "x": -50,
      "y": 39,
      "z": -30,
      "name": "Rock_Ice"
    },
    {
      "x": -50,
      "y": 40,
      "z": -30,
      "name": "Rock_Ice_Permafrost"
    },
    {
      "x": -50,
      "y": 41,
      "z": -30,
      "name": "Rock_Ice_Permafrost"
    },
    {
      "x": -50,
      "y": 42,
      "z": -30,
      "name": "Rock_Ice"
    },
    {
      "x": -50,
      "y": 43,
      "z": -30,
      "name": "Rock_Ice_Permafrost"
    },
    {
      "x": -50,
      "y": 44,
      "z": -30,
      "name": "Rock_Ice"
    },
    {
      "x": -50,
      "y": 45,
      "z": -30,
      "name": "Soil_Snow"
    },
    {
      "x": -50,
      "y": 37,
      "z": -29,
      "name": "Rock_Ice"
    },
    {
      "x": -50,
      "y": 38,
      "z": -29,
      "name": "Rock_Ice_Permafrost"
    },
    {
      "x": -50,
      "y": 39,
      "z": -29,
      "name": "Rock_Ice"
    },
    {
      "x": -50,
      "y": 40,
      "z": -29,
      "name": "Rock_Ice"
    },
    {
      "x": -50,
      "y": 41,
      "z": -29,
      "name": "Rock_Ice"
    },
    {
      "x": -50,
      "y": 42,
      "z": -29,
      "name": "Rock_Ice_Permafrost"
    },
    {
      "x": -50,
      "y": 43,
      "z": -29,
      "name": "Rock_Ice"
    },
    {
      "x": -50,
      "y": 44,
      "z": -29,
      "name": "Rock_Ice_Permafrost"
    },
    {
      "x": -50,
      "y": 45,
      "z": -29,
      "name": "Rock_Ice"
    },
    {
      "x": -50,
      "y": 46,
      "z": -29,
      "name": "Soil_Snow"
    },
    {
      "x": -50,
      "y": 36,
      "z": -28,
      "name": "Rock_Ice"
    },
    {
      "x": -50,
      "y": 37,
      "z": -28,
      "name": "Rock_Ice"
    },
    {
      "x": -50,
      "y": 38,
      "z": -28,
      "name": "Rock_Ice"
    },
    {
      "x": -50,
      "y": 39,
      "z": -28,
      "name": "Rock_Ice"
    },
    {
      "x": -50,
      "y": 40,
      "z": -28,
      "name": "Rock_Ice"
    },
    {
      "x": -50,
      "y": 41,
      "z": -28,
      "name": "Rock_Ice"
    },
    {
      "x": -50,
      "y": 42,
      "z": -28,
      "name": "Rock_Ice"
    },
    {
      "x": -50,
      "y": 43,
      "z": -28,
      "name": "Rock_Ice_Permafrost"
    },
    {
      "x": -50,
      "y": 44,
      "z": -28,
      "name": "Rock_Ice_Permafrost"
    },
    {
      "x": -50,
      "y": 45,
      "z": -28,
      "name": "Rock_Ice"
    },
    {
      "x": -50,
      "y": 46,
      "z": -28,
      "name": "Rock_Ice_Permafrost"
    },
    {
      "x": -50,
      "y": 36,
      "z": -27,
      "name": "Rock_Ice"
    },
    {
      "x": -50,
      "y": 37,
      "z": -27,
      "name": "Rock_Ice"
    },
    {
      "x": -50,
      "y": 38,
      "z": -27,
      "name": "Rock_Ice"
    },
    {
      "x": -50,
      "y": 39,
      "z": -27,
      "name": "Rock_Ice"
    },
    {
      "x": -50,
      "y": 40,
      "z": -27,
      "name": "Rock_Ice"
    },
    {
      "x": -50,
      "y": 41,
      "z": -27,
      "name": "Rock_Ice"
    },
    {
      "x": -50,
      "y": 42,
      "z": -27,
      "name": "Rock_Ice_Permafrost"
    },
    {
      "x": -50,
      "y": 43,
      "z": -27,
      "name": "Rock_Ice_Permafrost"
    },
    {
      "x": -50,
      "y": 44,
      "z": -27,
      "name": "Rock_Ice_Permafrost"
    },
    {
      "x": -50,
      "y": 45,
      "z": -27,
      "name": "Rock_Ice_Permafrost"
    },
    {
      "x": -50,
      "y": 46,
      "z": -27,
      "name": "Rock_Ice_Permafrost"
    },
    {
      "x": -50,
      "y": 47,
      "z": -27,
      "name": "Rock_Ice_Permafrost"
    },
    {
      "x": -50,
      "y": 35,
      "z": -26,
      "name": "Rock_Ice"
    },
    {
      "x": -50,
      "y": 36,
      "z": -26,
      "name": "Rock_Ice"
    },
    {
      "x": -50,
      "y": 37,
      "z": -26,
      "name": "Rock_Ice"
    },
    {
      "x": -50,
      "y": 38,
      "z": -26,
      "name": "Rock_Ice"
    },
    {
      "x": -50,
      "y": 39,
      "z": -26,
      "name": "Rock_Ice"
    },
    {
      "x": -50,
      "y": 40,
      "z": -26,
      "name": "Rock_Ice"
    },
    {
      "x": -50,
      "y": 41,
      "z": -26,
      "name": "Rock_Ice"
    },
    {
      "x": -50,
      "y": 42,
      "z": -26,
      "name": "Rock_Ice_Permafrost"
    },
    {
      "x": -50,
      "y": 43,
      "z": -26,
      "name": "Rock_Ice_Permafrost"
    },
    {
      "x": -50,
      "y": 44,
      "z": -26,
      "name": "Rock_Ice_Permafrost"
    },
    {
      "x": -50,
      "y": 45,
      "z": -26,
      "name": "Rock_Ice"
    },
    {
      "x": -50,
      "y": 46,
      "z": -26,
      "name": "Rock_Ice_Permafrost"
    },
    {
      "x": -50,
      "y": 35,
      "z": -25,
      "name": "Rock_Ice"
    },
    {
      "x": -50,
      "y": 36,
      "z": -25,
      "name": "Rock_Ice"
    },
    {
      "x": -50,
      "y": 37,
      "z": -25,
      "name": "Rock_Ice"
    },
    {
      "x": -50,
      "y": 38,
      "z": -25,
      "name": "Rock_Ice"
    },
    {
      "x": -50,
      "y": 39,
      "z": -25,
      "name": "Rock_Ice"
    },
    {
      "x": -50,
      "y": 40,
      "z": -25,
      "name": "Rock_Ice"
    },
    {
      "x": -50,
      "y": 41,
      "z": -25,
      "name": "Rock_Ice_Permafrost"
    },
    {
      "x": -50,
      "y": 42,
      "z": -25,
      "name": "Rock_Ice_Permafrost"
    },
    {
      "x": -50,
      "y": 43,
      "z": -25,
      "name": "Rock_Ice_Permafrost"
    },
    {
      "x": -50,
      "y": 44,
      "z": -25,
      "name": "Rock_Ice_Permafrost"
    },
    {
      "x": -50,
      "y": 45,
      "z": -25,
      "name": "Rock_Ice"
    },
    {
      "x": -50,
      "y": 46,
      "z": -25,
      "name": "Soil_Snow"
    },
    {
      "x": -50,
      "y": 35,
      "z": -24,
      "name": "Rock_Ice"
    },
    {
      "x": -50,
      "y": 36,
      "z": -24,
      "name": "Rock_Ice"
    },
    {
      "x": -50,
      "y": 37,
      "z": -24,
      "name": "Rock_Ice"
    },
    {
      "x": -50,
      "y": 38,
      "z": -24,
      "name": "Rock_Ice"
    },
    {
      "x": -50,
      "y": 39,
      "z": -24,
      "name": "Rock_Ice"
    },
    {
      "x": -50,
      "y": 40,
      "z": -24,
      "name": "Rock_Ice"
    },
    {
      "x": -50,
      "y": 41,
      "z": -24,
      "name": "Rock_Ice_Permafrost"
    },
    {
      "x": -50,
      "y": 42,
      "z": -24,
      "name": "Rock_Ice_Permafrost"
    },
    {
      "x": -50,
      "y": 43,
      "z": -24,
      "name": "Rock_Ice_Permafrost"
    },
    {
      "x": -50,
      "y": 44,
      "z": -24,
      "name": "Rock_Ice_Permafrost"
    },
    {
      "x": -50,
      "y": 45,
      "z": -24,
      "name": "Rock_Ice"
    },
    {
      "x": -50,
      "y": 46,
      "z": -24,
      "name": "Soil_Snow"
    },
    {
      "x": -50,
      "y": 35,
      "z": -23,
      "name": "Rock_Ice"
    },
    {
      "x": -50,
      "y": 36,
      "z": -23,
      "name": "Rock_Ice"
    },
    {
      "x": -50,
      "y": 37,
      "z": -23,
      "name": "Rock_Ice"
    },
    {
      "x": -50,
      "y": 38,
      "z": -23,
      "name": "Rock_Ice"
    },
    {
      "x": -50,
      "y": 39,
      "z": -23,
      "name": "Rock_Ice"
    },
    {
      "x": -50,
      "y": 40,
      "z": -23,
      "name": "Rock_Ice_Permafrost"
    },
    {
      "x": -50,
      "y": 41,
      "z": -23,
      "name": "Rock_Ice_Permafrost"
    },
    {
      "x": -50,
      "y": 42,
      "z": -23,
      "name": "Rock_Ice_Permafrost"
    },
    {
      "x": -50,
      "y": 43,
      "z": -23,
      "name": "Rock_Ice_Permafrost"
    },
    {
      "x": -50,
      "y": 44,
      "z": -23,
      "name": "Rock_Ice"
    },
    {
      "x": -50,
      "y": 45,
      "z": -23,
      "name": "Soil_Snow"
    },
    {
      "x": -50,
      "y": 36,
      "z": -22,
      "name": "Rock_Ice"
    },
    {
      "x": -50,
      "y": 37,
      "z": -22,
      "name": "Rock_Ice"
    },
    {
      "x": -50,
      "y": 38,
      "z": -22,
      "name": "Rock_Ice"
    },
    {
      "x": -50,
      "y": 39,
      "z": -22,
      "name": "Rock_Ice"
    },
    {
      "x": -50,
      "y": 40,
      "z": -22,
      "name": "Rock_Ice"
    },
    {
      "x": -50,
      "y": 41,
      "z": -22,
      "name": "Rock_Ice_Permafrost"
    },
    {
      "x": -50,
      "y": 42,
      "z": -22,
      "name": "Rock_Ice_Permafrost"
    },
    {
      "x": -50,
      "y": 43,
      "z": -22,
      "name": "Rock_Ice"
    },
    {
      "x": -50,
      "y": 44,
      "z": -22,
      "name": "Soil_Snow"
    },
    {
      "x": -50,
      "y": 36,
      "z": -21,
      "name": "Rock_Ice"
    },
    {
      "x": -50,
      "y": 37,
      "z": -21,
      "name": "Rock_Ice"
    },
    {
      "x": -50,
      "y": 38,
      "z": -21,
      "name": "Rock_Ice"
    },
    {
      "x": -50,
      "y": 39,
      "z": -21,
      "name": "Rock_Ice"
    },
    {
      "x": -50,
      "y": 40,
      "z": -21,
      "name": "Rock_Ice_Permafrost"
    },
    {
      "x": -50,
      "y": 41,
      "z": -21,
      "name": "Rock_Ice_Permafrost"
    },
    {
      "x": -50,
      "y": 42,
      "z": -21,
      "name": "Rock_Ice_Permafrost"
    },
    {
      "x": -50,
      "y": 43,
      "z": -21,
      "name": "Rock_Ice"
    },
    {
      "x": -50,
      "y": 44,
      "z": -21,
      "name": "Soil_Snow"
    },
    {
      "x": -50,
      "y": 37,
      "z": -20,
      "name": "Rock_Ice"
    },
    {
      "x": -50,
      "y": 38,
      "z": -20,
      "name": "Rock_Ice"
    },
    {
      "x": -50,
      "y": 39,
      "z": -20,
      "name": "Rock_Ice"
    },
    {
      "x": -50,
      "y": 40,
      "z": -20,
      "name": "Rock_Ice_Permafrost"
    },
    {
      "x": -50,
      "y": 41,
      "z": -20,
      "name": "Rock_Ice_Permafrost"
    },
    {
      "x": -50,
      "y": 42,
      "z": -20,
      "name": "Rock_Ice"
    },
    {
      "x": -50,
      "y": 43,
      "z": -20,
      "name": "Soil_Snow"
    },
    {
      "x": -50,
      "y": 37,
      "z": -19,
      "name": "Rock_Ice"
    },
    {
      "x": -50,
      "y": 38,
      "z": -19,
      "name": "Rock_Ice"
    },
    {
      "x": -50,
      "y": 39,
      "z": -19,
      "name": "Rock_Ice"
    },
    {
      "x": -50,
      "y": 40,
      "z": -19,
      "name": "Rock_Ice_Permafrost"
    },
    {
      "x": -50,
      "y": 41,
      "z": -19,
      "name": "Rock_Ice"
    },
    {
      "x": -50,
      "y": 42,
      "z": -19,
      "name": "Soil_Snow"
    },
    {
      "x": -50,
      "y": 38,
      "z": -18,
      "name": "Rock_Ice"
    },
    {
      "x": -50,
      "y": 39,
      "z": -18,
      "name": "Rock_Ice_Permafrost"
    },
    {
      "x": -50,
      "y": 40,
      "z": -18,
      "name": "Rock_Ice"
    },
    {
      "x": -50,
      "y": 41,
      "z": -18,
      "name": "Soil_Snow"
    },
    {
      "x": -50,
      "y": 38,
      "z": -17,
      "name": "Rock_Ice"
    },
    {
      "x": -50,
      "y": 39,
      "z": -17,
      "name": "Rock_Ice"
    },
    {
      "x": -50,
      "y": 40,
      "z": -17,
      "name": "Soil_Snow"
    },
    {
      "x": -50,
      "y": 39,
      "z": -16,
      "name": "Rock_Ice"
    },
    {
      "x": -50,
      "y": 39,
      "z": -15,
      "name": "Soil_Snow"
    },
    {
      "x": -49,
      "y": 39,
      "z": -32,
      "name": "Rock_Ice_Permafrost"
    },
    {
      "x": -49,
      "y": 40,
      "z": -32,
      "name": "Rock_Ice_Permafrost"
    },
    {
      "x": -49,
      "y": 41,
      "z": -32,
      "name": "Rock_Ice_Permafrost"
    },
    {
      "x": -49,
      "y": 42,
      "z": -32,
      "name": "Rock_Ice_Permafrost"
    },
    {
      "x": -49,
      "y": 43,
      "z": -32,
      "name": "Rock_Ice_Permafrost"
    },
    {
      "x": -49,
      "y": 44,
      "z": -32,
      "name": "Rock_Ice_Permafrost"
    },
    {
      "x": -49,
      "y": 45,
      "z": -32,
      "name": "Rock_Ice_Permafrost"
    },
    {
      "x": -49,
      "y": 46,
      "z": -32,
      "name": "Rock_Ice"
    },
    {
      "x": -49,
      "y": 47,
      "z": -32,
      "name": "Soil_Snow"
    },
    {
      "x": -49,
      "y": 35,
      "z": -31,
      "name": "Rock_Ice"
    },
    {
      "x": -49,
      "y": 36,
      "z": -31,
      "name": "Rock_Ice_Permafrost"
    },
    {
      "x": -49,
      "y": 37,
      "z": -31,
      "name": "Rock_Ice_Permafrost"
    },
    {
      "x": -49,
      "y": 38,
      "z": -31,
      "name": "Rock_Ice_Permafrost"
    },
    {
      "x": -49,
      "y": 39,
      "z": -31,
      "name": "Rock_Ice_Permafrost"
    },
    {
      "x": -49,
      "y": 40,
      "z": -31,
      "name": "Rock_Ice_Permafrost"
    },
    {
      "x": -49,
      "y": 41,
      "z": -31,
      "name": "Rock_Ice"
    },
    {
      "x": -49,
      "y": 42,
      "z": -31,
      "name": "Rock_Ice_Permafrost"
    },
    {
      "x": -49,
      "y": 43,
      "z": -31,
      "name": "Rock_Ice_Permafrost"
    },
    {
      "x": -49,
      "y": 44,
      "z": -31,
      "name": "Rock_Ice_Permafrost"
    },
    {
      "x": -49,
      "y": 45,
      "z": -31,
      "name": "Rock_Ice_Permafrost"
    },
    {
      "x": -49,
      "y": 46,
      "z": -31,
      "name": "Rock_Ice_Permafrost"
    },
    {
      "x": -49,
      "y": 47,
      "z": -31,
      "name": "Rock_Ice"
    },
    {
      "x": -49,
      "y": 48,
      "z": -31,
      "name": "Rock_Ice_Permafrost"
    },
    {
      "x": -49,
      "y": 33,
      "z": -30,
      "name": "Rock_Ice_Permafrost"
    },
    {
      "x": -49,
      "y": 34,
      "z": -30,
      "name": "Rock_Ice_Permafrost"
    },
    {
      "x": -49,
      "y": 35,
      "z": -30,
      "name": "Rock_Ice"
    },
    {
      "x": -49,
      "y": 36,
      "z": -30,
      "name": "Rock_Ice_Permafrost"
    },
    {
      "x": -49,
      "y": 37,
      "z": -30,
      "name": "Rock_Ice"
    },
    {
      "x": -49,
      "y": 38,
      "z": -30,
      "name": "Rock_Ice_Permafrost"
    },
    {
      "x": -49,
      "y": 39,
      "z": -30,
      "name": "Rock_Ice_Permafrost"
    },
    {
      "x": -49,
      "y": 40,
      "z": -30,
      "name": "Rock_Ice_Permafrost"
    },
    {
      "x": -49,
      "y": 41,
      "z": -30,
      "name": "Rock_Ice_Permafrost"
    },
    {
      "x": -49,
      "y": 42,
      "z": -30,
      "name": "Rock_Ice_Permafrost"
    },
    {
      "x": -49,
      "y": 43,
      "z": -30,
      "name": "Rock_Ice_Permafrost"
    },
    {
      "x": -49,
      "y": 44,
      "z": -30,
      "name": "Rock_Ice_Permafrost"
    },
    {
      "x": -49,
      "y": 45,
      "z": -30,
      "name": "Rock_Ice_Permafrost"
    },
    {
      "x": -49,
      "y": 46,
      "z": -30,
      "name": "Rock_Ice_Permafrost"
    },
    {
      "x": -49,
      "y": 47,
      "z": -30,
      "name": "Rock_Ice"
    },
    {
      "x": -49,
      "y": 48,
      "z": -30,
      "name": "Rock_Ice_Permafrost"
    },
    {
      "x": -49,
      "y": 32,
      "z": -29,
      "name": "Rock_Ice_Permafrost"
    },
    {
      "x": -49,
      "y": 33,
      "z": -29,
      "name": "Rock_Ice_Permafrost"
    },
    {
      "x": -49,
      "y": 34,
      "z": -29,
      "name": "Rock_Ice_Permafrost"
    },
    {
      "x": -49,
      "y": 35,
      "z": -29,
      "name": "Rock_Ice_Permafrost"
    },
    {
      "x": -49,
      "y": 36,
      "z": -29,
      "name": "Rock_Ice_Permafrost"
    },
    {
      "x": -49,
      "y": 37,
      "z": -29,
      "name": "Rock_Ice"
    },
    {
      "x": -49,
      "y": 38,
      "z": -29,
      "name": "Rock_Ice"
    },
    {
      "x": -49,
      "y": 39,
      "z": -29,
      "name": "Rock_Ice"
    },
    {
      "x": -49,
      "y": 40,
      "z": -29,
      "name": "Rock_Ice"
    },
    {
      "x": -49,
      "y": 41,
      "z": -29,
      "name": "Rock_Ice_Permafrost"
    },
    {
      "x": -49,
      "y": 42,
      "z": -29,
      "name": "Rock_Ice_Permafrost"
    },
    {
      "x": -49,
      "y": 43,
      "z": -29,
      "name": "Rock_Ice_Permafrost"
    },
    {
      "x": -49,
      "y": 44,
      "z": -29,
      "name": "Rock_Ice_Permafrost"
    },
    {
      "x": -49,
      "y": 45,
      "z": -29,
      "name": "Rock_Ice_Permafrost"
    },
    {
      "x": -49,
      "y": 46,
      "z": -29,
      "name": "Rock_Ice_Permafrost"
    },
    {
      "x": -49,
      "y": 47,
      "z": -29,
      "name": "Rock_Ice_Permafrost"
    },
    {
      "x": -49,
      "y": 48,
      "z": -29,
      "name": "Rock_Ice_Permafrost"
    },
    {
      "x": -49,
      "y": 49,
      "z": -29,
      "name": "Rock_Ice_Permafrost"
    },
    {
      "x": -49,
      "y": 31,
      "z": -28,
      "name": "Rock_Ice_Permafrost"
    },
    {
      "x": -49,
      "y": 32,
      "z": -28,
      "name": "Rock_Ice_Permafrost"
    },
    {
      "x": -49,
      "y": 33,
      "z": -28,
      "name": "Rock_Ice"
    },
    {
      "x": -49,
      "y": 34,
      "z": -28,
      "name": "Rock_Ice"
    },
    {
      "x": -49,
      "y": 35,
      "z": -28,
      "name": "Rock_Ice"
    },
    {
      "x": -49,
      "y": 36,
      "z": -28,
      "name": "Rock_Ice"
    },
    {
      "x": -49,
      "y": 37,
      "z": -28,
      "name": "Rock_Ice"
    },
    {
      "x": -49,
      "y": 38,
      "z": -28,
      "name": "Rock_Ice"
    },
    {
      "x": -49,
      "y": 39,
      "z": -28,
      "name": "Rock_Ice"
    },
    {
      "x": -49,
      "y": 40,
      "z": -28,
      "name": "Rock_Ice"
    },
    {
      "x": -49,
      "y": 41,
      "z": -28,
      "name": "Rock_Ice"
    },
    {
      "x": -49,
      "y": 42,
      "z": -28,
      "name": "Rock_Ice_Permafrost"
    },
    {
      "x": -49,
      "y": 43,
      "z": -28,
      "name": "Rock_Ice_Permafrost"
    },
    {
      "x": -49,
      "y": 44,
      "z": -28,
      "name": "Rock_Ice_Permafrost"
    },
    {
      "x": -49,
      "y": 45,
      "z": -28,
      "name": "Rock_Ice_Permafrost"
    },
    {
      "x": -49,
      "y": 46,
      "z": -28,
      "name": "Rock_Ice_Permafrost"
    },
    {
      "x": -49,
      "y": 47,
      "z": -28,
      "name": "Rock_Ice_Permafrost"
    },
    {
      "x": -49,
      "y": 48,
      "z": -28,
      "name": "Rock_Ice_Permafrost"
    },
    {
      "x": -49,
      "y": 49,
      "z": -28,
      "name": "Soil_Snow"
    },
    {
      "x": -49,
      "y": 32,
      "z": -27,
      "name": "Rock_Ice"
    },
    {
      "x": -49,
      "y": 33,
      "z": -27,
      "name": "Rock_Ice"
    },
    {
      "x": -49,
      "y": 34,
      "z": -27,
      "name": "Rock_Ice"
    },
    {
      "x": -49,
      "y": 35,
      "z": -27,
      "name": "Rock_Ice"
    },
    {
      "x": -49,
      "y": 36,
      "z": -27,
      "name": "Rock_Ice"
    },
    {
      "x": -49,
      "y": 37,
      "z": -27,
      "name": "Rock_Ice"
    },
    {
      "x": -49,
      "y": 38,
      "z": -27,
      "name": "Rock_Ice"
    },
    {
      "x": -49,
      "y": 39,
      "z": -27,
      "name": "Rock_Ice"
    },
    {
      "x": -49,
      "y": 40,
      "z": -27,
      "name": "Rock_Ice"
    },
    {
      "x": -49,
      "y": 41,
      "z": -27,
      "name": "Rock_Ice_Permafrost"
    },
    {
      "x": -49,
      "y": 42,
      "z": -27,
      "name": "Rock_Ice_Permafrost"
    },
    {
      "x": -49,
      "y": 43,
      "z": -27,
      "name": "Rock_Ice_Permafrost"
    },
    {
      "x": -49,
      "y": 44,
      "z": -27,
      "name": "Rock_Ice_Permafrost"
    },
    {
      "x": -49,
      "y": 45,
      "z": -27,
      "name": "Rock_Ice_Permafrost"
    },
    {
      "x": -49,
      "y": 46,
      "z": -27,
      "name": "Rock_Ice_Permafrost"
    },
    {
      "x": -49,
      "y": 47,
      "z": -27,
      "name": "Rock_Ice"
    },
    {
      "x": -49,
      "y": 48,
      "z": -27,
      "name": "Soil_Snow"
    },
    {
      "x": -49,
      "y": 32,
      "z": -26,
      "name": "Rock_Ice"
    },
    {
      "x": -49,
      "y": 33,
      "z": -26,
      "name": "Rock_Ice"
    },
    {
      "x": -49,
      "y": 34,
      "z": -26,
      "name": "Rock_Ice"
    },
    {
      "x": -49,
      "y": 35,
      "z": -26,
      "name": "Rock_Ice"
    },
    {
      "x": -49,
      "y": 36,
      "z": -26,
      "name": "Rock_Ice"
    },
    {
      "x": -49,
      "y": 37,
      "z": -26,
      "name": "Rock_Ice"
    },
    {
      "x": -49,
      "y": 38,
      "z": -26,
      "name": "Rock_Ice"
    },
    {
      "x": -49,
      "y": 39,
      "z": -26,
      "name": "Rock_Ice_Permafrost"
    },
    {
      "x": -49,
      "y": 40,
      "z": -26,
      "name": "Rock_Ice"
    },
    {
      "x": -49,
      "y": 41,
      "z": -26,
      "name": "Rock_Ice_Permafrost"
    },
    {
      "x": -49,
      "y": 42,
      "z": -26,
      "name": "Rock_Ice_Permafrost"
    },
    {
      "x": -49,
      "y": 43,
      "z": -26,
      "name": "Rock_Ice_Permafrost"
    },
    {
      "x": -49,
      "y": 44,
      "z": -26,
      "name": "Rock_Ice_Permafrost"
    },
    {
      "x": -49,
      "y": 45,
      "z": -26,
      "name": "Rock_Ice_Permafrost"
    },
    {
      "x": -49,
      "y": 46,
      "z": -26,
      "name": "Rock_Ice_Permafrost"
    },
    {
      "x": -49,
      "y": 47,
      "z": -26,
      "name": "Rock_Ice"
    },
    {
      "x": -49,
      "y": 48,
      "z": -26,
      "name": "Soil_Snow"
    },
    {
      "x": -49,
      "y": 32,
      "z": -25,
      "name": "Rock_Ice"
    },
    {
      "x": -49,
      "y": 33,
      "z": -25,
      "name": "Rock_Ice"
    },
    {
      "x": -49,
      "y": 34,
      "z": -25,
      "name": "Rock_Ice"
    },
    {
      "x": -49,
      "y": 35,
      "z": -25,
      "name": "Rock_Ice"
    },
    {
      "x": -49,
      "y": 36,
      "z": -25,
      "name": "Rock_Ice"
    },
    {
      "x": -49,
      "y": 37,
      "z": -25,
      "name": "Rock_Ice"
    },
    {
      "x": -49,
      "y": 38,
      "z": -25,
      "name": "Rock_Ice"
    },
    {
      "x": -49,
      "y": 39,
      "z": -25,
      "name": "Rock_Ice"
    },
    {
      "x": -49,
      "y": 40,
      "z": -25,
      "name": "Rock_Ice_Permafrost"
    },
    {
      "x": -49,
      "y": 41,
      "z": -25,
      "name": "Rock_Ice_Permafrost"
    },
    {
      "x": -49,
      "y": 42,
      "z": -25,
      "name": "Rock_Ice_Permafrost"
    },
    {
      "x": -49,
      "y": 43,
      "z": -25,
      "name": "Rock_Ice_Permafrost"
    },
    {
      "x": -49,
      "y": 44,
      "z": -25,
      "name": "Rock_Ice_Permafrost"
    },
    {
      "x": -49,
      "y": 45,
      "z": -25,
      "name": "Rock_Ice_Permafrost"
    },
    {
      "x": -49,
      "y": 46,
      "z": -25,
      "name": "Rock_Ice"
    },
    {
      "x": -49,
      "y": 47,
      "z": -25,
      "name": "Soil_Snow"
    },
    {
      "x": -49,
      "y": 32,
      "z": -24,
      "name": "Rock_Ice"
    },
    {
      "x": -49,
      "y": 33,
      "z": -24,
      "name": "Rock_Ice"
    },
    {
      "x": -49,
      "y": 34,
      "z": -24,
      "name": "Rock_Ice"
    },
    {
      "x": -49,
      "y": 35,
      "z": -24,
      "name": "Rock_Ice"
    },
    {
      "x": -49,
      "y": 36,
      "z": -24,
      "name": "Rock_Ice"
    },
    {
      "x": -49,
      "y": 37,
      "z": -24,
      "name": "Rock_Ice"
    },
    {
      "x": -49,
      "y": 38,
      "z": -24,
      "name": "Rock_Ice"
    },
    {
      "x": -49,
      "y": 39,
      "z": -24,
      "name": "Rock_Ice"
    },
    {
      "x": -49,
      "y": 40,
      "z": -24,
      "name": "Rock_Ice"
    },
    {
      "x": -49,
      "y": 41,
      "z": -24,
      "name": "Rock_Ice_Permafrost"
    },
    {
      "x": -49,
      "y": 42,
      "z": -24,
      "name": "Rock_Ice_Permafrost"
    },
    {
      "x": -49,
      "y": 43,
      "z": -24,
      "name": "Rock_Ice_Permafrost"
    },
    {
      "x": -49,
      "y": 44,
      "z": -24,
      "name": "Rock_Ice"
    },
    {
      "x": -49,
      "y": 45,
      "z": -24,
      "name": "Rock_Ice_Permafrost"
    },
    {
      "x": -49,
      "y": 46,
      "z": -24,
      "name": "Rock_Ice"
    },
    {
      "x": -49,
      "y": 47,
      "z": -24,
      "name": "Soil_Snow"
    },
    {
      "x": -49,
      "y": 33,
      "z": -23,
      "name": "Rock_Ice"
    },
    {
      "x": -49,
      "y": 34,
      "z": -23,
      "name": "Rock_Ice"
    },
    {
      "x": -49,
      "y": 35,
      "z": -23,
      "name": "Rock_Ice"
    },
    {
      "x": -49,
      "y": 36,
      "z": -23,
      "name": "Rock_Ice"
    },
    {
      "x": -49,
      "y": 37,
      "z": -23,
      "name": "Rock_Ice"
    },
    {
      "x": -49,
      "y": 38,
      "z": -23,
      "name": "Rock_Ice"
    },
    {
      "x": -49,
      "y": 39,
      "z": -23,
      "name": "Rock_Ice"
    },
    {
      "x": -49,
      "y": 40,
      "z": -23,
      "name": "Rock_Ice_Permafrost"
    },
    {
      "x": -49,
      "y": 41,
      "z": -23,
      "name": "Rock_Ice_Permafrost"
    },
    {
      "x": -49,
      "y": 42,
      "z": -23,
      "name": "Rock_Ice_Permafrost"
    },
    {
      "x": -49,
      "y": 43,
      "z": -23,
      "name": "Rock_Ice_Permafrost"
    },
    {
      "x": -49,
      "y": 44,
      "z": -23,
      "name": "Rock_Ice_Permafrost"
    },
    {
      "x": -49,
      "y": 45,
      "z": -23,
      "name": "Rock_Ice"
    },
    {
      "x": -49,
      "y": 46,
      "z": -23,
      "name": "Soil_Snow"
    },
    {
      "x": -49,
      "y": 33,
      "z": -22,
      "name": "Rock_Ice"
    },
    {
      "x": -49,
      "y": 34,
      "z": -22,
      "name": "Rock_Ice"
    },
    {
      "x": -49,
      "y": 35,
      "z": -22,
      "name": "Rock_Ice"
    },
    {
      "x": -49,
      "y": 36,
      "z": -22,
      "name": "Rock_Ice"
    },
    {
      "x": -49,
      "y": 37,
      "z": -22,
      "name": "Rock_Ice"
    },
    {
      "x": -49,
      "y": 38,
      "z": -22,
      "name": "Rock_Ice"
    },
    {
      "x": -49,
      "y": 39,
      "z": -22,
      "name": "Rock_Ice_Permafrost"
    },
    {
      "x": -49,
      "y": 40,
      "z": -22,
      "name": "Rock_Ice_Permafrost"
    },
    {
      "x": -49,
      "y": 41,
      "z": -22,
      "name": "Rock_Ice_Permafrost"
    },
    {
      "x": -49,
      "y": 42,
      "z": -22,
      "name": "Rock_Ice_Permafrost"
    },
    {
      "x": -49,
      "y": 43,
      "z": -22,
      "name": "Rock_Ice_Permafrost"
    },
    {
      "x": -49,
      "y": 44,
      "z": -22,
      "name": "Rock_Ice"
    },
    {
      "x": -49,
      "y": 45,
      "z": -22,
      "name": "Soil_Snow"
    },
    {
      "x": -49,
      "y": 33,
      "z": -21,
      "name": "Rock_Ice"
    },
    {
      "x": -49,
      "y": 34,
      "z": -21,
      "name": "Rock_Ice"
    },
    {
      "x": -49,
      "y": 35,
      "z": -21,
      "name": "Rock_Ice"
    },
    {
      "x": -49,
      "y": 36,
      "z": -21,
      "name": "Rock_Ice"
    },
    {
      "x": -49,
      "y": 37,
      "z": -21,
      "name": "Rock_Ice"
    },
    {
      "x": -49,
      "y": 38,
      "z": -21,
      "name": "Rock_Ice"
    },
    {
      "x": -49,
      "y": 39,
      "z": -21,
      "name": "Rock_Ice"
    },
    {
      "x": -49,
      "y": 40,
      "z": -21,
      "name": "Rock_Ice_Permafrost"
    },
    {
      "x": -49,
      "y": 41,
      "z": -21,
      "name": "Rock_Ice_Permafrost"
    },
    {
      "x": -49,
      "y": 42,
      "z": -21,
      "name": "Rock_Ice_Permafrost"
    },
    {
      "x": -49,
      "y": 43,
      "z": -21,
      "name": "Rock_Ice_Permafrost"
    },
    {
      "x": -49,
      "y": 44,
      "z": -21,
      "name": "Rock_Ice"
    },
    {
      "x": -49,
      "y": 45,
      "z": -21,
      "name": "Soil_Snow"
    },
    {
      "x": -49,
      "y": 34,
      "z": -20,
      "name": "Rock_Ice"
    },
    {
      "x": -49,
      "y": 35,
      "z": -20,
      "name": "Rock_Ice"
    },
    {
      "x": -49,
      "y": 36,
      "z": -20,
      "name": "Rock_Ice"
    },
    {
      "x": -49,
      "y": 37,
      "z": -20,
      "name": "Rock_Ice"
    },
    {
      "x": -49,
      "y": 38,
      "z": -20,
      "name": "Rock_Ice"
    },
    {
      "x": -49,
      "y": 39,
      "z": -20,
      "name": "Rock_Ice"
    },
    {
      "x": -49,
      "y": 40,
      "z": -20,
      "name": "Rock_Ice_Permafrost"
    },
    {
      "x": -49,
      "y": 41,
      "z": -20,
      "name": "Rock_Ice"
    },
    {
      "x": -49,
      "y": 42,
      "z": -20,
      "name": "Rock_Ice_Permafrost"
    },
    {
      "x": -49,
      "y": 43,
      "z": -20,
      "name": "Rock_Ice"
    },
    {
      "x": -49,
      "y": 44,
      "z": -20,
      "name": "Soil_Snow"
    },
    {
      "x": -49,
      "y": 34,
      "z": -19,
      "name": "Rock_Ice"
    },
    {
      "x": -49,
      "y": 35,
      "z": -19,
      "name": "Rock_Ice"
    },
    {
      "x": -49,
      "y": 36,
      "z": -19,
      "name": "Rock_Ice"
    },
    {
      "x": -49,
      "y": 37,
      "z": -19,
      "name": "Rock_Ice"
    },
    {
      "x": -49,
      "y": 38,
      "z": -19,
      "name": "Rock_Ice"
    },
    {
      "x": -49,
      "y": 39,
      "z": -19,
      "name": "Rock_Ice_Permafrost"
    },
    {
      "x": -49,
      "y": 40,
      "z": -19,
      "name": "Rock_Ice_Permafrost"
    },
    {
      "x": -49,
      "y": 41,
      "z": -19,
      "name": "Rock_Ice_Permafrost"
    },
    {
      "x": -49,
      "y": 42,
      "z": -19,
      "name": "Rock_Ice"
    },
    {
      "x": -49,
      "y": 43,
      "z": -19,
      "name": "Soil_Snow"
    },
    {
      "x": -49,
      "y": 35,
      "z": -18,
      "name": "Rock_Ice"
    },
    {
      "x": -49,
      "y": 36,
      "z": -18,
      "name": "Rock_Ice"
    },
    {
      "x": -49,
      "y": 37,
      "z": -18,
      "name": "Rock_Ice"
    },
    {
      "x": -49,
      "y": 38,
      "z": -18,
      "name": "Rock_Ice_Permafrost"
    },
    {
      "x": -49,
      "y": 39,
      "z": -18,
      "name": "Rock_Ice_Permafrost"
    },
    {
      "x": -49,
      "y": 40,
      "z": -18,
      "name": "Rock_Ice_Permafrost"
    },
    {
      "x": -49,
      "y": 41,
      "z": -18,
      "name": "Rock_Ice"
    },
    {
      "x": -49,
      "y": 42,
      "z": -18,
      "name": "Soil_Snow"
    },
    {
      "x": -49,
      "y": 36,
      "z": -17,
      "name": "Rock_Ice"
    },
    {
      "x": -49,
      "y": 37,
      "z": -17,
      "name": "Rock_Ice"
    },
    {
      "x": -49,
      "y": 38,
      "z": -17,
      "name": "Rock_Ice"
    },
    {
      "x": -49,
      "y": 39,
      "z": -17,
      "name": "Rock_Ice_Permafrost"
    },
    {
      "x": -49,
      "y": 40,
      "z": -17,
      "name": "Rock_Ice_Permafrost"
    },
    {
      "x": -49,
      "y": 41,
      "z": -17,
      "name": "Rock_Ice"
    },
    {
      "x": -49,
      "y": 42,
      "z": -17,
      "name": "Soil_Snow"
    },
    {
      "x": -49,
      "y": 37,
      "z": -16,
      "name": "Rock_Ice"
    },
    {
      "x": -49,
      "y": 38,
      "z": -16,
      "name": "Rock_Ice_Permafrost"
    },
    {
      "x": -49,
      "y": 39,
      "z": -16,
      "name": "Rock_Ice_Permafrost"
    },
    {
      "x": -49,
      "y": 40,
      "z": -16,
      "name": "Rock_Ice"
    },
    {
      "x": -49,
      "y": 41,
      "z": -16,
      "name": "Soil_Snow"
    },
    {
      "x": -49,
      "y": 38,
      "z": -15,
      "name": "Rock_Ice_Permafrost"
    },
    {
      "x": -49,
      "y": 39,
      "z": -15,
      "name": "Rock_Ice"
    },
    {
      "x": -49,
      "y": 40,
      "z": -15,
      "name": "Soil_Snow"
    },
    {
      "x": -49,
      "y": 38,
      "z": -14,
      "name": "Rock_Ice"
    },
    {
      "x": -49,
      "y": 39,
      "z": -14,
      "name": "Soil_Snow"
    },
    {
      "x": -48,
      "y": 44,
      "z": -34,
      "name": "Rock_Ice"
    },
    {
      "x": -48,
      "y": 45,
      "z": -34,
      "name": "Soil_Snow"
    },
    {
      "x": -48,
      "y": 37,
      "z": -33,
      "name": "Rock_Ice_Permafrost"
    },
    {
      "x": -48,
      "y": 38,
      "z": -33,
      "name": "Rock_Ice_Permafrost"
    },
    {
      "x": -48,
      "y": 39,
      "z": -33,
      "name": "Rock_Ice_Permafrost"
    },
    {
      "x": -48,
      "y": 40,
      "z": -33,
      "name": "Rock_Ice_Permafrost"
    },
    {
      "x": -48,
      "y": 41,
      "z": -33,
      "name": "Rock_Ice_Permafrost"
    },
    {
      "x": -48,
      "y": 42,
      "z": -33,
      "name": "Rock_Ice"
    },
    {
      "x": -48,
      "y": 43,
      "z": -33,
      "name": "Rock_Ice_Permafrost"
    },
    {
      "x": -48,
      "y": 44,
      "z": -33,
      "name": "Rock_Ice_Permafrost"
    },
    {
      "x": -48,
      "y": 45,
      "z": -33,
      "name": "Rock_Ice_Permafrost"
    },
    {
      "x": -48,
      "y": 46,
      "z": -33,
      "name": "Rock_Ice_Permafrost"
    },
    {
      "x": -48,
      "y": 47,
      "z": -33,
      "name": "Rock_Ice_Permafrost"
    },
    {
      "x": -48,
      "y": 48,
      "z": -33,
      "name": "Rock_Ice"
    },
    {
      "x": -48,
      "y": 49,
      "z": -33,
      "name": "Soil_Snow"
    },
    {
      "x": -48,
      "y": 35,
      "z": -32,
      "name": "Rock_Ice_Permafrost"
    },
    {
      "x": -48,
      "y": 36,
      "z": -32,
      "name": "Rock_Ice_Permafrost"
    },
    {
      "x": -48,
      "y": 37,
      "z": -32,
      "name": "Rock_Ice_Permafrost"
    },
    {
      "x": -48,
      "y": 38,
      "z": -32,
      "name": "Rock_Ice_Permafrost"
    },
    {
      "x": -48,
      "y": 39,
      "z": -32,
      "name": "Rock_Ice_Permafrost"
    },
    {
      "x": -48,
      "y": 40,
      "z": -32,
      "name": "Rock_Ice_Permafrost"
    },
    {
      "x": -48,
      "y": 41,
      "z": -32,
      "name": "Rock_Ice_Permafrost"
    },
    {
      "x": -48,
      "y": 42,
      "z": -32,
      "name": "Rock_Ice_Permafrost"
    },
    {
      "x": -48,
      "y": 43,
      "z": -32,
      "name": "Rock_Ice_Permafrost"
    },
    {
      "x": -48,
      "y": 44,
      "z": -32,
      "name": "Rock_Ice_Permafrost"
    },
    {
      "x": -48,
      "y": 45,
      "z": -32,
      "name": "Rock_Ice_Permafrost"
    },
    {
      "x": -48,
      "y": 46,
      "z": -32,
      "name": "Rock_Ice_Permafrost"
    },
    {
      "x": -48,
      "y": 47,
      "z": -32,
      "name": "Rock_Ice_Permafrost"
    },
    {
      "x": -48,
      "y": 48,
      "z": -32,
      "name": "Rock_Ice_Permafrost"
    },
    {
      "x": -48,
      "y": 49,
      "z": -32,
      "name": "Rock_Ice_Permafrost"
    },
    {
      "x": -48,
      "y": 50,
      "z": -32,
      "name": "Soil_Snow"
    },
    {
      "x": -48,
      "y": 33,
      "z": -31,
      "name": "Rock_Ice"
    },
    {
      "x": -48,
      "y": 34,
      "z": -31,
      "name": "Rock_Ice_Permafrost"
    },
    {
      "x": -48,
      "y": 35,
      "z": -31,
      "name": "Rock_Ice_Permafrost"
    },
    {
      "x": -48,
      "y": 36,
      "z": -31,
      "name": "Rock_Ice_Permafrost"
    },
    {
      "x": -48,
      "y": 37,
      "z": -31,
      "name": "Rock_Ice"
    },
    {
      "x": -48,
      "y": 38,
      "z": -31,
      "name": "Rock_Ice_Permafrost"
    },
    {
      "x": -48,
      "y": 39,
      "z": -31,
      "name": "Rock_Ice_Permafrost"
    },
    {
      "x": -48,
      "y": 40,
      "z": -31,
      "name": "Rock_Ice_Permafrost"
    },
    {
      "x": -48,
      "y": 41,
      "z": -31,
      "name": "Rock_Ice_Permafrost"
    },
    {
      "x": -48,
      "y": 42,
      "z": -31,
      "name": "Rock_Ice_Permafrost"
    },
    {
      "x": -48,
      "y": 43,
      "z": -31,
      "name": "Rock_Ice_Permafrost"
    },
    {
      "x": -48,
      "y": 44,
      "z": -31,
      "name": "Rock_Ice_Permafrost"
    },
    {
      "x": -48,
      "y": 45,
      "z": -31,
      "name": "Rock_Ice_Permafrost"
    },
    {
      "x": -48,
      "y": 46,
      "z": -31,
      "name": "Rock_Ice_Permafrost"
    },
    {
      "x": -48,
      "y": 47,
      "z": -31,
      "name": "Rock_Ice_Permafrost"
    },
    {
      "x": -48,
      "y": 48,
      "z": -31,
      "name": "Rock_Ice_Permafrost"
    },
    {
      "x": -48,
      "y": 49,
      "z": -31,
      "name": "Rock_Ice_Permafrost"
    },
    {
      "x": -48,
      "y": 50,
      "z": -31,
      "name": "Soil_Snow"
    },
    {
      "x": -48,
      "y": 32,
      "z": -30,
      "name": "Rock_Ice"
    },
    {
      "x": -48,
      "y": 33,
      "z": -30,
      "name": "Rock_Ice_Permafrost"
    },
    {
      "x": -48,
      "y": 34,
      "z": -30,
      "name": "Rock_Ice_Permafrost"
    },
    {
      "x": -48,
      "y": 35,
      "z": -30,
      "name": "Rock_Ice_Permafrost"
    },
    {
      "x": -48,
      "y": 36,
      "z": -30,
      "name": "Rock_Ice_Permafrost"
    },
    {
      "x": -48,
      "y": 37,
      "z": -30,
      "name": "Rock_Ice_Permafrost"
    },
    {
      "x": -48,
      "y": 38,
      "z": -30,
      "name": "Rock_Ice_Permafrost"
    },
    {
      "x": -48,
      "y": 39,
      "z": -30,
      "name": "Rock_Ice_Permafrost"
    },
    {
      "x": -48,
      "y": 40,
      "z": -30,
      "name": "Rock_Ice_Permafrost"
    },
    {
      "x": -48,
      "y": 41,
      "z": -30,
      "name": "Rock_Ice"
    },
    {
      "x": -48,
      "y": 42,
      "z": -30,
      "name": "Rock_Ice_Permafrost"
    },
    {
      "x": -48,
      "y": 43,
      "z": -30,
      "name": "Rock_Ice_Permafrost"
    },
    {
      "x": -48,
      "y": 44,
      "z": -30,
      "name": "Rock_Ice_Permafrost"
    },
    {
      "x": -48,
      "y": 45,
      "z": -30,
      "name": "Rock_Ice_Permafrost"
    },
    {
      "x": -48,
      "y": 46,
      "z": -30,
      "name": "Rock_Ice_Permafrost"
    },
    {
      "x": -48,
      "y": 47,
      "z": -30,
      "name": "Rock_Ice_Permafrost"
    },
    {
      "x": -48,
      "y": 48,
      "z": -30,
      "name": "Rock_Ice_Permafrost"
    },
    {
      "x": -48,
      "y": 49,
      "z": -30,
      "name": "Rock_Ice_Permafrost"
    },
    {
      "x": -48,
      "y": 50,
      "z": -30,
      "name": "Soil_Snow"
    },
    {
      "x": -48,
      "y": 31,
      "z": -29,
      "name": "Rock_Ice_Permafrost"
    },
    {
      "x": -48,
      "y": 32,
      "z": -29,
      "name": "Rock_Ice_Permafrost"
    },
    {
      "x": -48,
      "y": 33,
      "z": -29,
      "name": "Rock_Ice_Permafrost"
    },
    {
      "x": -48,
      "y": 34,
      "z": -29,
      "name": "Rock_Ice_Permafrost"
    },
    {
      "x": -48,
      "y": 35,
      "z": -29,
      "name": "Rock_Ice_Permafrost"
    },
    {
      "x": -48,
      "y": 36,
      "z": -29,
      "name": "Rock_Ice"
    },
    {
      "x": -48,
      "y": 37,
      "z": -29,
      "name": "Rock_Ice_Permafrost"
    },
    {
      "x": -48,
      "y": 38,
      "z": -29,
      "name": "Rock_Ice"
    },
    {
      "x": -48,
      "y": 39,
      "z": -29,
      "name": "Rock_Ice_Permafrost"
    },
    {
      "x": -48,
      "y": 40,
      "z": -29,
      "name": "Rock_Ice_Permafrost"
    },
    {
      "x": -48,
      "y": 41,
      "z": -29,
      "name": "Rock_Ice_Permafrost"
    },
    {
      "x": -48,
      "y": 42,
      "z": -29,
      "name": "Rock_Ice_Permafrost"
    },
    {
      "x": -48,
      "y": 43,
      "z": -29,
      "name": "Rock_Ice_Permafrost"
    },
    {
      "x": -48,
      "y": 44,
      "z": -29,
      "name": "Rock_Ice_Permafrost"
    },
    {
      "x": -48,
      "y": 45,
      "z": -29,
      "name": "Rock_Ice_Permafrost"
    },
    {
      "x": -48,
      "y": 46,
      "z": -29,
      "name": "Rock_Ice_Permafrost"
    },
    {
      "x": -48,
      "y": 47,
      "z": -29,
      "name": "Rock_Ice_Permafrost"
    },
    {
      "x": -48,
      "y": 48,
      "z": -29,
      "name": "Rock_Ice_Permafrost"
    },
    {
      "x": -48,
      "y": 49,
      "z": -29,
      "name": "Rock_Ice"
    },
    {
      "x": -48,
      "y": 50,
      "z": -29,
      "name": "Soil_Snow"
    },
    {
      "x": -48,
      "y": 30,
      "z": -28,
      "name": "Rock_Ice_Permafrost"
    },
    {
      "x": -48,
      "y": 31,
      "z": -28,
      "name": "Rock_Ice_Permafrost"
    },
    {
      "x": -48,
      "y": 32,
      "z": -28,
      "name": "Rock_Ice_Permafrost"
    },
    {
      "x": -48,
      "y": 33,
      "z": -28,
      "name": "Rock_Ice_Permafrost"
    },
    {
      "x": -48,
      "y": 34,
      "z": -28,
      "name": "Rock_Ice_Permafrost"
    },
    {
      "x": -48,
      "y": 35,
      "z": -28,
      "name": "Rock_Ice"
    },
    {
      "x": -48,
      "y": 36,
      "z": -28,
      "name": "Rock_Ice"
    },
    {
      "x": -48,
      "y": 37,
      "z": -28,
      "name": "Rock_Ice"
    },
    {
      "x": -48,
      "y": 38,
      "z": -28,
      "name": "Rock_Ice"
    },
    {
      "x": -48,
      "y": 39,
      "z": -28,
      "name": "Rock_Ice"
    },
    {
      "x": -48,
      "y": 40,
      "z": -28,
      "name": "Rock_Ice_Permafrost"
    },
    {
      "x": -48,
      "y": 41,
      "z": -28,
      "name": "Rock_Ice_Permafrost"
    },
    {
      "x": -48,
      "y": 42,
      "z": -28,
      "name": "Rock_Ice_Permafrost"
    },
    {
      "x": -48,
      "y": 43,
      "z": -28,
      "name": "Rock_Ice_Permafrost"
    },
    {
      "x": -48,
      "y": 44,
      "z": -28,
      "name": "Rock_Ice_Permafrost"
    },
    {
      "x": -48,
      "y": 45,
      "z": -28,
      "name": "Rock_Ice_Permafrost"
    },
    {
      "x": -48,
      "y": 46,
      "z": -28,
      "name": "Rock_Ice_Permafrost"
    },
    {
      "x": -48,
      "y": 47,
      "z": -28,
      "name": "Rock_Ice_Permafrost"
    },
    {
      "x": -48,
      "y": 48,
      "z": -28,
      "name": "Rock_Ice"
    },
    {
      "x": -48,
      "y": 49,
      "z": -28,
      "name": "Soil_Snow"
    },
    {
      "x": -48,
      "y": 29,
      "z": -27,
      "name": "Rock_Ice_Permafrost"
    },
    {
      "x": -48,
      "y": 30,
      "z": -27,
      "name": "Rock_Ice_Permafrost"
    },
    {
      "x": -48,
      "y": 31,
      "z": -27,
      "name": "Rock_Ice_Permafrost"
    },
    {
      "x": -48,
      "y": 32,
      "z": -27,
      "name": "Rock_Ice_Permafrost"
    },
    {
      "x": -48,
      "y": 33,
      "z": -27,
      "name": "Rock_Ice_Permafrost"
    },
    {
      "x": -48,
      "y": 34,
      "z": -27,
      "name": "Rock_Ice"
    },
    {
      "x": -48,
      "y": 35,
      "z": -27,
      "name": "Rock_Ice"
    },
    {
      "x": -48,
      "y": 36,
      "z": -27,
      "name": "Rock_Ice"
    },
    {
      "x": -48,
      "y": 37,
      "z": -27,
      "name": "Rock_Ice"
    },
    {
      "x": -48,
      "y": 38,
      "z": -27,
      "name": "Rock_Ice_Permafrost"
    },
    {
      "x": -48,
      "y": 39,
      "z": -27,
      "name": "Rock_Ice_Permafrost"
    },
    {
      "x": -48,
      "y": 40,
      "z": -27,
      "name": "Rock_Ice"
    },
    {
      "x": -48,
      "y": 41,
      "z": -27,
      "name": "Rock_Ice_Permafrost"
    },
    {
      "x": -48,
      "y": 42,
      "z": -27,
      "name": "Rock_Ice_Permafrost"
    },
    {
      "x": -48,
      "y": 43,
      "z": -27,
      "name": "Rock_Ice_Permafrost"
    },
    {
      "x": -48,
      "y": 44,
      "z": -27,
      "name": "Rock_Ice_Permafrost"
    },
    {
      "x": -48,
      "y": 45,
      "z": -27,
      "name": "Rock_Ice_Permafrost"
    },
    {
      "x": -48,
      "y": 46,
      "z": -27,
      "name": "Rock_Ice_Permafrost"
    },
    {
      "x": -48,
      "y": 47,
      "z": -27,
      "name": "Rock_Ice_Permafrost"
    },
    {
      "x": -48,
      "y": 48,
      "z": -27,
      "name": "Rock_Ice"
    },
    {
      "x": -48,
      "y": 49,
      "z": -27,
      "name": "Soil_Snow"
    },
    {
      "x": -48,
      "y": 29,
      "z": -26,
      "name": "Rock_Ice_Permafrost"
    },
    {
      "x": -48,
      "y": 30,
      "z": -26,
      "name": "Rock_Ice_Permafrost"
    },
    {
      "x": -48,
      "y": 31,
      "z": -26,
      "name": "Rock_Ice_Permafrost"
    },
    {
      "x": -48,
      "y": 32,
      "z": -26,
      "name": "Rock_Ice"
    },
    {
      "x": -48,
      "y": 33,
      "z": -26,
      "name": "Rock_Ice"
    },
    {
      "x": -48,
      "y": 34,
      "z": -26,
      "name": "Rock_Ice"
    },
    {
      "x": -48,
      "y": 35,
      "z": -26,
      "name": "Rock_Ice"
    },
    {
      "x": -48,
      "y": 36,
      "z": -26,
      "name": "Rock_Ice"
    },
    {
      "x": -48,
      "y": 37,
      "z": -26,
      "name": "Rock_Ice"
    },
    {
      "x": -48,
      "y": 38,
      "z": -26,
      "name": "Rock_Ice_Permafrost"
    },
    {
      "x": -48,
      "y": 39,
      "z": -26,
      "name": "Rock_Ice"
    },
    {
      "x": -48,
      "y": 40,
      "z": -26,
      "name": "Rock_Ice_Permafrost"
    },
    {
      "x": -48,
      "y": 41,
      "z": -26,
      "name": "Rock_Ice_Permafrost"
    },
    {
      "x": -48,
      "y": 42,
      "z": -26,
      "name": "Rock_Ice_Permafrost"
    },
    {
      "x": -48,
      "y": 43,
      "z": -26,
      "name": "Rock_Ice_Permafrost"
    },
    {
      "x": -48,
      "y": 44,
      "z": -26,
      "name": "Rock_Ice_Permafrost"
    },
    {
      "x": -48,
      "y": 45,
      "z": -26,
      "name": "Rock_Ice_Permafrost"
    },
    {
      "x": -48,
      "y": 46,
      "z": -26,
      "name": "Rock_Ice_Permafrost"
    },
    {
      "x": -48,
      "y": 47,
      "z": -26,
      "name": "Rock_Ice_Permafrost"
    },
    {
      "x": -48,
      "y": 48,
      "z": -26,
      "name": "Rock_Ice"
    },
    {
      "x": -48,
      "y": 49,
      "z": -26,
      "name": "Soil_Snow"
    },
    {
      "x": -48,
      "y": 30,
      "z": -25,
      "name": "Rock_Ice"
    },
    {
      "x": -48,
      "y": 31,
      "z": -25,
      "name": "Rock_Ice"
    },
    {
      "x": -48,
      "y": 32,
      "z": -25,
      "name": "Rock_Ice"
    },
    {
      "x": -48,
      "y": 33,
      "z": -25,
      "name": "Rock_Ice"
    },
    {
      "x": -48,
      "y": 34,
      "z": -25,
      "name": "Rock_Ice"
    },
    {
      "x": -48,
      "y": 35,
      "z": -25,
      "name": "Rock_Ice"
    },
    {
      "x": -48,
      "y": 36,
      "z": -25,
      "name": "Rock_Ice"
    },
    {
      "x": -48,
      "y": 37,
      "z": -25,
      "name": "Rock_Ice"
    },
    {
      "x": -48,
      "y": 38,
      "z": -25,
      "name": "Rock_Ice"
    },
    {
      "x": -48,
      "y": 39,
      "z": -25,
      "name": "Rock_Ice"
    },
    {
      "x": -48,
      "y": 40,
      "z": -25,
      "name": "Rock_Ice_Permafrost"
    },
    {
      "x": -48,
      "y": 41,
      "z": -25,
      "name": "Rock_Ice_Permafrost"
    },
    {
      "x": -48,
      "y": 42,
      "z": -25,
      "name": "Rock_Ice_Permafrost"
    },
    {
      "x": -48,
      "y": 43,
      "z": -25,
      "name": "Rock_Ice"
    },
    {
      "x": -48,
      "y": 44,
      "z": -25,
      "name": "Rock_Ice_Permafrost"
    },
    {
      "x": -48,
      "y": 45,
      "z": -25,
      "name": "Rock_Ice_Permafrost"
    },
    {
      "x": -48,
      "y": 46,
      "z": -25,
      "name": "Rock_Ice"
    },
    {
      "x": -48,
      "y": 47,
      "z": -25,
      "name": "Rock_Ice"
    },
    {
      "x": -48,
      "y": 48,
      "z": -25,
      "name": "Soil_Snow"
    },
    {
      "x": -48,
      "y": 31,
      "z": -24,
      "name": "Rock_Ice"
    },
    {
      "x": -48,
      "y": 32,
      "z": -24,
      "name": "Rock_Ice"
    },
    {
      "x": -48,
      "y": 33,
      "z": -24,
      "name": "Rock_Ice"
    },
    {
      "x": -48,
      "y": 34,
      "z": -24,
      "name": "Rock_Ice"
    },
    {
      "x": -48,
      "y": 35,
      "z": -24,
      "name": "Rock_Ice"
    },
    {
      "x": -48,
      "y": 36,
      "z": -24,
      "name": "Rock_Ice"
    },
    {
      "x": -48,
      "y": 37,
      "z": -24,
      "name": "Rock_Ice"
    },
    {
      "x": -48,
      "y": 38,
      "z": -24,
      "name": "Rock_Ice"
    },
    {
      "x": -48,
      "y": 39,
      "z": -24,
      "name": "Rock_Ice_Permafrost"
    },
    {
      "x": -48,
      "y": 40,
      "z": -24,
      "name": "Rock_Ice_Permafrost"
    },
    {
      "x": -48,
      "y": 41,
      "z": -24,
      "name": "Rock_Ice_Permafrost"
    },
    {
      "x": -48,
      "y": 42,
      "z": -24,
      "name": "Rock_Ice_Permafrost"
    },
    {
      "x": -48,
      "y": 43,
      "z": -24,
      "name": "Rock_Ice"
    },
    {
      "x": -48,
      "y": 44,
      "z": -24,
      "name": "Rock_Ice_Permafrost"
    },
    {
      "x": -48,
      "y": 45,
      "z": -24,
      "name": "Rock_Ice_Permafrost"
    },
    {
      "x": -48,
      "y": 46,
      "z": -24,
      "name": "Rock_Ice"
    },
    {
      "x": -48,
      "y": 47,
      "z": -24,
      "name": "Rock_Ice"
    },
    {
      "x": -48,
      "y": 48,
      "z": -24,
      "name": "Soil_Snow"
    },
    {
      "x": -48,
      "y": 31,
      "z": -23,
      "name": "Rock_Ice"
    },
    {
      "x": -48,
      "y": 32,
      "z": -23,
      "name": "Rock_Ice"
    },
    {
      "x": -48,
      "y": 33,
      "z": -23,
      "name": "Rock_Ice"
    },
    {
      "x": -48,
      "y": 34,
      "z": -23,
      "name": "Rock_Ice"
    },
    {
      "x": -48,
      "y": 35,
      "z": -23,
      "name": "Rock_Ice"
    },
    {
      "x": -48,
      "y": 36,
      "z": -23,
      "name": "Rock_Ice"
    },
    {
      "x": -48,
      "y": 37,
      "z": -23,
      "name": "Rock_Ice"
    },
    {
      "x": -48,
      "y": 38,
      "z": -23,
      "name": "Rock_Ice"
    },
    {
      "x": -48,
      "y": 39,
      "z": -23,
      "name": "Rock_Ice"
    },
    {
      "x": -48,
      "y": 40,
      "z": -23,
      "name": "Rock_Ice_Permafrost"
    },
    {
      "x": -48,
      "y": 41,
      "z": -23,
      "name": "Rock_Ice_Permafrost"
    },
    {
      "x": -48,
      "y": 42,
      "z": -23,
      "name": "Rock_Ice_Permafrost"
    },
    {
      "x": -48,
      "y": 43,
      "z": -23,
      "name": "Rock_Ice_Permafrost"
    },
    {
      "x": -48,
      "y": 44,
      "z": -23,
      "name": "Rock_Ice_Permafrost"
    },
    {
      "x": -48,
      "y": 45,
      "z": -23,
      "name": "Rock_Ice_Permafrost"
    },
    {
      "x": -48,
      "y": 46,
      "z": -23,
      "name": "Rock_Ice"
    },
    {
      "x": -48,
      "y": 47,
      "z": -23,
      "name": "Soil_Snow"
    },
    {
      "x": -48,
      "y": 31,
      "z": -22,
      "name": "Rock_Ice"
    },
    {
      "x": -48,
      "y": 32,
      "z": -22,
      "name": "Rock_Ice"
    },
    {
      "x": -48,
      "y": 33,
      "z": -22,
      "name": "Rock_Ice"
    },
    {
      "x": -48,
      "y": 34,
      "z": -22,
      "name": "Rock_Ice"
    },
    {
      "x": -48,
      "y": 35,
      "z": -22,
      "name": "Rock_Ice"
    },
    {
      "x": -48,
      "y": 36,
      "z": -22,
      "name": "Rock_Ice"
    },
    {
      "x": -48,
      "y": 37,
      "z": -22,
      "name": "Rock_Ice"
    },
    {
      "x": -48,
      "y": 38,
      "z": -22,
      "name": "Rock_Ice"
    },
    {
      "x": -48,
      "y": 39,
      "z": -22,
      "name": "Rock_Ice"
    },
    {
      "x": -48,
      "y": 40,
      "z": -22,
      "name": "Rock_Ice"
    },
    {
      "x": -48,
      "y": 41,
      "z": -22,
      "name": "Rock_Ice"
    },
    {
      "x": -48,
      "y": 42,
      "z": -22,
      "name": "Rock_Ice"
    },
    {
      "x": -48,
      "y": 43,
      "z": -22,
      "name": "Rock_Ice_Permafrost"
    },
    {
      "x": -48,
      "y": 44,
      "z": -22,
      "name": "Rock_Ice_Permafrost"
    },
    {
      "x": -48,
      "y": 45,
      "z": -22,
      "name": "Rock_Ice"
    },
    {
      "x": -48,
      "y": 46,
      "z": -22,
      "name": "Soil_Snow"
    },
    {
      "x": -48,
      "y": 32,
      "z": -21,
      "name": "Rock_Ice"
    },
    {
      "x": -48,
      "y": 33,
      "z": -21,
      "name": "Rock_Ice"
    },
    {
      "x": -48,
      "y": 34,
      "z": -21,
      "name": "Rock_Ice"
    },
    {
      "x": -48,
      "y": 35,
      "z": -21,
      "name": "Rock_Ice"
    },
    {
      "x": -48,
      "y": 36,
      "z": -21,
      "name": "Rock_Ice"
    },
    {
      "x": -48,
      "y": 37,
      "z": -21,
      "name": "Rock_Ice"
    },
    {
      "x": -48,
      "y": 38,
      "z": -21,
      "name": "Rock_Ice"
    },
    {
      "x": -48,
      "y": 39,
      "z": -21,
      "name": "Rock_Ice_Permafrost"
    },
    {
      "x": -48,
      "y": 40,
      "z": -21,
      "name": "Rock_Ice_Permafrost"
    },
    {
      "x": -48,
      "y": 41,
      "z": -21,
      "name": "Rock_Ice_Permafrost"
    },
    {
      "x": -48,
      "y": 42,
      "z": -21,
      "name": "Rock_Ice_Permafrost"
    },
    {
      "x": -48,
      "y": 43,
      "z": -21,
      "name": "Rock_Ice"
    },
    {
      "x": -48,
      "y": 44,
      "z": -21,
      "name": "Rock_Ice"
    },
    {
      "x": -48,
      "y": 45,
      "z": -21,
      "name": "Soil_Snow"
    },
    {
      "x": -48,
      "y": 32,
      "z": -20,
      "name": "Rock_Ice"
    },
    {
      "x": -48,
      "y": 33,
      "z": -20,
      "name": "Rock_Ice"
    },
    {
      "x": -48,
      "y": 34,
      "z": -20,
      "name": "Rock_Ice"
    },
    {
      "x": -48,
      "y": 35,
      "z": -20,
      "name": "Rock_Ice"
    },
    {
      "x": -48,
      "y": 36,
      "z": -20,
      "name": "Rock_Ice"
    },
    {
      "x": -48,
      "y": 37,
      "z": -20,
      "name": "Rock_Ice"
    },
    {
      "x": -48,
      "y": 38,
      "z": -20,
      "name": "Rock_Ice"
    },
    {
      "x": -48,
      "y": 39,
      "z": -20,
      "name": "Rock_Ice_Permafrost"
    },
    {
      "x": -48,
      "y": 40,
      "z": -20,
      "name": "Rock_Ice_Permafrost"
    },
    {
      "x": -48,
      "y": 41,
      "z": -20,
      "name": "Rock_Ice_Permafrost"
    },
    {
      "x": -48,
      "y": 42,
      "z": -20,
      "name": "Rock_Ice_Permafrost"
    },
    {
      "x": -48,
      "y": 43,
      "z": -20,
      "name": "Rock_Ice"
    },
    {
      "x": -48,
      "y": 44,
      "z": -20,
      "name": "Rock_Ice"
    },
    {
      "x": -48,
      "y": 45,
      "z": -20,
      "name": "Soil_Snow"
    },
    {
      "x": -48,
      "y": 32,
      "z": -19,
      "name": "Rock_Ice"
    },
    {
      "x": -48,
      "y": 33,
      "z": -19,
      "name": "Rock_Ice"
    },
    {
      "x": -48,
      "y": 34,
      "z": -19,
      "name": "Rock_Ice"
    },
    {
      "x": -48,
      "y": 35,
      "z": -19,
      "name": "Rock_Ice"
    },
    {
      "x": -48,
      "y": 36,
      "z": -19,
      "name": "Rock_Ice"
    },
    {
      "x": -48,
      "y": 37,
      "z": -19,
      "name": "Rock_Ice"
    },
    {
      "x": -48,
      "y": 38,
      "z": -19,
      "name": "Rock_Ice"
    },
    {
      "x": -48,
      "y": 39,
      "z": -19,
      "name": "Rock_Ice_Permafrost"
    },
    {
      "x": -48,
      "y": 40,
      "z": -19,
      "name": "Rock_Ice_Permafrost"
    },
    {
      "x": -48,
      "y": 41,
      "z": -19,
      "name": "Rock_Ice_Permafrost"
    },
    {
      "x": -48,
      "y": 42,
      "z": -19,
      "name": "Rock_Ice_Permafrost"
    },
    {
      "x": -48,
      "y": 43,
      "z": -19,
      "name": "Rock_Ice"
    },
    {
      "x": -48,
      "y": 44,
      "z": -19,
      "name": "Soil_Snow"
    },
    {
      "x": -48,
      "y": 33,
      "z": -18,
      "name": "Rock_Ice"
    },
    {
      "x": -48,
      "y": 34,
      "z": -18,
      "name": "Rock_Ice"
    },
    {
      "x": -48,
      "y": 35,
      "z": -18,
      "name": "Rock_Ice"
    },
    {
      "x": -48,
      "y": 36,
      "z": -18,
      "name": "Rock_Ice"
    },
    {
      "x": -48,
      "y": 37,
      "z": -18,
      "name": "Rock_Ice"
    },
    {
      "x": -48,
      "y": 38,
      "z": -18,
      "name": "Rock_Ice_Permafrost"
    },
    {
      "x": -48,
      "y": 39,
      "z": -18,
      "name": "Rock_Ice_Permafrost"
    },
    {
      "x": -48,
      "y": 40,
      "z": -18,
      "name": "Rock_Ice_Permafrost"
    },
    {
      "x": -48,
      "y": 41,
      "z": -18,
      "name": "Rock_Ice_Permafrost"
    },
    {
      "x": -48,
      "y": 42,
      "z": -18,
      "name": "Rock_Ice"
    },
    {
      "x": -48,
      "y": 43,
      "z": -18,
      "name": "Soil_Snow"
    },
    {
      "x": -48,
      "y": 33,
      "z": -17,
      "name": "Rock_Ice"
    },
    {
      "x": -48,
      "y": 34,
      "z": -17,
      "name": "Rock_Ice"
    },
    {
      "x": -48,
      "y": 35,
      "z": -17,
      "name": "Rock_Ice"
    },
    {
      "x": -48,
      "y": 36,
      "z": -17,
      "name": "Rock_Ice"
    },
    {
      "x": -48,
      "y": 37,
      "z": -17,
      "name": "Rock_Ice"
    },
    {
      "x": -48,
      "y": 38,
      "z": -17,
      "name": "Rock_Ice"
    },
    {
      "x": -48,
      "y": 39,
      "z": -17,
      "name": "Rock_Ice_Permafrost"
    },
    {
      "x": -48,
      "y": 40,
      "z": -17,
      "name": "Rock_Ice"
    },
    {
      "x": -48,
      "y": 41,
      "z": -17,
      "name": "Rock_Ice"
    },
    {
      "x": -48,
      "y": 42,
      "z": -17,
      "name": "Soil_Snow"
    },
    {
      "x": -48,
      "y": 34,
      "z": -16,
      "name": "Rock_Ice"
    },
    {
      "x": -48,
      "y": 35,
      "z": -16,
      "name": "Rock_Ice"
    },
    {
      "x": -48,
      "y": 36,
      "z": -16,
      "name": "Rock_Ice"
    },
    {
      "x": -48,
      "y": 37,
      "z": -16,
      "name": "Rock_Ice"
    },
    {
      "x": -48,
      "y": 38,
      "z": -16,
      "name": "Rock_Ice"
    },
    {
      "x": -48,
      "y": 39,
      "z": -16,
      "name": "Rock_Ice_Permafrost"
    },
    {
      "x": -48,
      "y": 40,
      "z": -16,
      "name": "Rock_Ice_Permafrost"
    },
    {
      "x": -48,
      "y": 41,
      "z": -16,
      "name": "Rock_Ice"
    },
    {
      "x": -48,
      "y": 42,
      "z": -16,
      "name": "Soil_Snow"
    },
    {
      "x": -48,
      "y": 35,
      "z": -15,
      "name": "Rock_Ice"
    },
    {
      "x": -48,
      "y": 36,
      "z": -15,
      "name": "Rock_Ice"
    },
    {
      "x": -48,
      "y": 37,
      "z": -15,
      "name": "Rock_Ice"
    },
    {
      "x": -48,
      "y": 38,
      "z": -15,
      "name": "Rock_Ice_Permafrost"
    },
    {
      "x": -48,
      "y": 39,
      "z": -15,
      "name": "Rock_Ice_Permafrost"
    },
    {
      "x": -48,
      "y": 40,
      "z": -15,
      "name": "Rock_Ice"
    },
    {
      "x": -48,
      "y": 41,
      "z": -15,
      "name": "Soil_Snow"
    },
    {
      "x": -48,
      "y": 36,
      "z": -14,
      "name": "Rock_Ice"
    },
    {
      "x": -48,
      "y": 37,
      "z": -14,
      "name": "Rock_Ice"
    },
    {
      "x": -48,
      "y": 38,
      "z": -14,
      "name": "Rock_Ice"
    },
    {
      "x": -48,
      "y": 39,
      "z": -14,
      "name": "Rock_Ice"
    },
    {
      "x": -48,
      "y": 40,
      "z": -14,
      "name": "Soil_Snow"
    },
    {
      "x": -48,
      "y": 37,
      "z": -13,
      "name": "Rock_Ice"
    },
    {
      "x": -48,
      "y": 38,
      "z": -13,
      "name": "Rock_Ice"
    },
    {
      "x": -48,
      "y": 39,
      "z": -13,
      "name": "Soil_Snow"
    },
    {
      "x": -48,
      "y": 38,
      "z": -12,
      "name": "Rock_Ice"
    },
    {
      "x": -48,
      "y": 39,
      "z": -12,
      "name": "Soil_Snow"
    },
    {
      "x": -47,
      "y": 41,
      "z": -35,
      "name": "Rock_Ice_Permafrost"
    },
    {
      "x": -47,
      "y": 42,
      "z": -35,
      "name": "Rock_Ice_Permafrost"
    },
    {
      "x": -47,
      "y": 43,
      "z": -35,
      "name": "Rock_Ice"
    },
    {
      "x": -47,
      "y": 44,
      "z": -35,
      "name": "Rock_Ice"
    },
    {
      "x": -47,
      "y": 45,
      "z": -35,
      "name": "Rock_Ice"
    },
    {
      "x": -47,
      "y": 46,
      "z": -35,
      "name": "Soil_Snow"
    },
    {
      "x": -47,
      "y": 38,
      "z": -34,
      "name": "Rock_Ice"
    },
    {
      "x": -47,
      "y": 39,
      "z": -34,
      "name": "Rock_Ice_Permafrost"
    },
    {
      "x": -47,
      "y": 40,
      "z": -34,
      "name": "Rock_Ice"
    },
    {
      "x": -47,
      "y": 41,
      "z": -34,
      "name": "Rock_Ice_Permafrost"
    },
    {
      "x": -47,
      "y": 42,
      "z": -34,
      "name": "Rock_Ice_Permafrost"
    },
    {
      "x": -47,
      "y": 43,
      "z": -34,
      "name": "Rock_Ice_Permafrost"
    },
    {
      "x": -47,
      "y": 44,
      "z": -34,
      "name": "Rock_Ice_Permafrost"
    },
    {
      "x": -47,
      "y": 45,
      "z": -34,
      "name": "Rock_Ice_Permafrost"
    },
    {
      "x": -47,
      "y": 46,
      "z": -34,
      "name": "Rock_Ice_Permafrost"
    },
    {
      "x": -47,
      "y": 47,
      "z": -34,
      "name": "Rock_Ice_Permafrost"
    },
    {
      "x": -47,
      "y": 48,
      "z": -34,
      "name": "Rock_Ice_Permafrost"
    },
    {
      "x": -47,
      "y": 49,
      "z": -34,
      "name": "Rock_Ice"
    },
    {
      "x": -47,
      "y": 50,
      "z": -34,
      "name": "Soil_Snow"
    },
    {
      "x": -47,
      "y": 37,
      "z": -33,
      "name": "Rock_Ice"
    },
    {
      "x": -47,
      "y": 38,
      "z": -33,
      "name": "Rock_Ice_Permafrost"
    },
    {
      "x": -47,
      "y": 39,
      "z": -33,
      "name": "Rock_Ice_Permafrost"
    },
    {
      "x": -47,
      "y": 40,
      "z": -33,
      "name": "Rock_Ice_Permafrost"
    },
    {
      "x": -47,
      "y": 41,
      "z": -33,
      "name": "Rock_Ice_Permafrost"
    },
    {
      "x": -47,
      "y": 42,
      "z": -33,
      "name": "Rock_Ice_Permafrost"
    },
    {
      "x": -47,
      "y": 43,
      "z": -33,
      "name": "Rock_Ice"
    },
    {
      "x": -47,
      "y": 44,
      "z": -33,
      "name": "Rock_Ice_Permafrost"
    },
    {
      "x": -47,
      "y": 45,
      "z": -33,
      "name": "Rock_Ice_Permafrost"
    },
    {
      "x": -47,
      "y": 46,
      "z": -33,
      "name": "Rock_Ice_Permafrost"
    },
    {
      "x": -47,
      "y": 47,
      "z": -33,
      "name": "Rock_Ice_Permafrost"
    },
    {
      "x": -47,
      "y": 48,
      "z": -33,
      "name": "Rock_Ice_Permafrost"
    },
    {
      "x": -47,
      "y": 49,
      "z": -33,
      "name": "Rock_Ice_Permafrost"
    },
    {
      "x": -47,
      "y": 50,
      "z": -33,
      "name": "Rock_Ice"
    },
    {
      "x": -47,
      "y": 51,
      "z": -33,
      "name": "Soil_Snow"
    },
    {
      "x": -47,
      "y": 35,
      "z": -32,
      "name": "Rock_Ice_Permafrost"
    },
    {
      "x": -47,
      "y": 36,
      "z": -32,
      "name": "Rock_Ice_Permafrost"
    },
    {
      "x": -47,
      "y": 37,
      "z": -32,
      "name": "Rock_Ice_Permafrost"
    },
    {
      "x": -47,
      "y": 38,
      "z": -32,
      "name": "Rock_Ice_Permafrost"
    },
    {
      "x": -47,
      "y": 39,
      "z": -32,
      "name": "Rock_Ice_Permafrost"
    },
    {
      "x": -47,
      "y": 40,
      "z": -32,
      "name": "Rock_Ice_Permafrost"
    },
    {
      "x": -47,
      "y": 41,
      "z": -32,
      "name": "Rock_Ice"
    },
    {
      "x": -47,
      "y": 42,
      "z": -32,
      "name": "Rock_Ice_Permafrost"
    },
    {
      "x": -47,
      "y": 43,
      "z": -32,
      "name": "Rock_Ice_Permafrost"
    },
    {
      "x": -47,
      "y": 44,
      "z": -32,
      "name": "Rock_Ice_Permafrost"
    },
    {
      "x": -47,
      "y": 45,
      "z": -32,
      "name": "Rock_Ice_Permafrost"
    },
    {
      "x": -47,
      "y": 46,
      "z": -32,
      "name": "Rock_Ice_Permafrost"
    },
    {
      "x": -47,
      "y": 47,
      "z": -32,
      "name": "Rock_Ice_Permafrost"
    },
    {
      "x": -47,
      "y": 48,
      "z": -32,
      "name": "Rock_Ice_Permafrost"
    },
    {
      "x": -47,
      "y": 49,
      "z": -32,
      "name": "Rock_Ice_Permafrost"
    },
    {
      "x": -47,
      "y": 50,
      "z": -32,
      "name": "Rock_Ice"
    },
    {
      "x": -47,
      "y": 51,
      "z": -32,
      "name": "Soil_Snow"
    },
    {
      "x": -47,
      "y": 33,
      "z": -31,
      "name": "Rock_Ice"
    },
    {
      "x": -47,
      "y": 34,
      "z": -31,
      "name": "Rock_Ice_Permafrost"
    },
    {
      "x": -47,
      "y": 35,
      "z": -31,
      "name": "Rock_Ice"
    },
    {
      "x": -47,
      "y": 36,
      "z": -31,
      "name": "Rock_Ice_Permafrost"
    },
    {
      "x": -47,
      "y": 37,
      "z": -31,
      "name": "Rock_Ice_Permafrost"
    },
    {
      "x": -47,
      "y": 38,
      "z": -31,
      "name": "Rock_Ice_Permafrost"
    },
    {
      "x": -47,
      "y": 39,
      "z": -31,
      "name": "Rock_Ice_Permafrost"
    },
    {
      "x": -47,
      "y": 40,
      "z": -31,
      "name": "Rock_Ice_Permafrost"
    },
    {
      "x": -47,
      "y": 41,
      "z": -31,
      "name": "Rock_Ice_Permafrost"
    },
    {
      "x": -47,
      "y": 42,
      "z": -31,
      "name": "Rock_Ice_Permafrost"
    },
    {
      "x": -47,
      "y": 43,
      "z": -31,
      "name": "Rock_Ice_Permafrost"
    },
    {
      "x": -47,
      "y": 44,
      "z": -31,
      "name": "Rock_Ice_Permafrost"
    },
    {
      "x": -47,
      "y": 45,
      "z": -31,
      "name": "Rock_Ice_Permafrost"
    },
    {
      "x": -47,
      "y": 46,
      "z": -31,
      "name": "Rock_Ice_Permafrost"
    },
    {
      "x": -47,
      "y": 47,
      "z": -31,
      "name": "Rock_Ice_Permafrost"
    },
    {
      "x": -47,
      "y": 48,
      "z": -31,
      "name": "Rock_Ice_Permafrost"
    },
    {
      "x": -47,
      "y": 49,
      "z": -31,
      "name": "Rock_Ice_Permafrost"
    },
    {
      "x": -47,
      "y": 50,
      "z": -31,
      "name": "Rock_Ice"
    },
    {
      "x": -47,
      "y": 51,
      "z": -31,
      "name": "Soil_Snow"
    },
    {
      "x": -47,
      "y": 32,
      "z": -30,
      "name": "Rock_Ice_Permafrost"
    },
    {
      "x": -47,
      "y": 33,
      "z": -30,
      "name": "Rock_Ice_Permafrost"
    },
    {
      "x": -47,
      "y": 34,
      "z": -30,
      "name": "Rock_Ice_Permafrost"
    },
    {
      "x": -47,
      "y": 35,
      "z": -30,
      "name": "Rock_Ice_Permafrost"
    },
    {
      "x": -47,
      "y": 36,
      "z": -30,
      "name": "Rock_Ice_Permafrost"
    },
    {
      "x": -47,
      "y": 37,
      "z": -30,
      "name": "Rock_Ice_Permafrost"
    },
    {
      "x": -47,
      "y": 38,
      "z": -30,
      "name": "Rock_Ice"
    },
    {
      "x": -47,
      "y": 39,
      "z": -30,
      "name": "Rock_Ice_Permafrost"
    },
    {
      "x": -47,
      "y": 40,
      "z": -30,
      "name": "Rock_Ice_Permafrost"
    },
    {
      "x": -47,
      "y": 41,
      "z": -30,
      "name": "Rock_Ice_Permafrost"
    },
    {
      "x": -47,
      "y": 42,
      "z": -30,
      "name": "Rock_Ice_Permafrost"
    },
    {
      "x": -47,
      "y": 43,
      "z": -30,
      "name": "Rock_Ice_Permafrost"
    },
    {
      "x": -47,
      "y": 44,
      "z": -30,
      "name": "Rock_Ice_Permafrost"
    },
    {
      "x": -47,
      "y": 45,
      "z": -30,
      "name": "Rock_Ice_Permafrost"
    },
    {
      "x": -47,
      "y": 46,
      "z": -30,
      "name": "Rock_Ice_Permafrost"
    },
    {
      "x": -47,
      "y": 47,
      "z": -30,
      "name": "Rock_Ice_Permafrost"
    },
    {
      "x": -47,
      "y": 48,
      "z": -30,
      "name": "Rock_Ice_Permafrost"
    },
    {
      "x": -47,
      "y": 49,
      "z": -30,
      "name": "Rock_Ice_Permafrost"
    },
    {
      "x": -47,
      "y": 50,
      "z": -30,
      "name": "Rock_Ice_Permafrost"
    },
    {
      "x": -47,
      "y": 51,
      "z": -30,
      "name": "Rock_Ice_Permafrost"
    },
    {
      "x": -47,
      "y": 31,
      "z": -29,
      "name": "Rock_Ice_Permafrost"
    },
    {
      "x": -47,
      "y": 32,
      "z": -29,
      "name": "Rock_Ice_Permafrost"
    },
    {
      "x": -47,
      "y": 33,
      "z": -29,
      "name": "Rock_Ice_Permafrost"
    },
    {
      "x": -47,
      "y": 34,
      "z": -29,
      "name": "Rock_Ice_Permafrost"
    },
    {
      "x": -47,
      "y": 35,
      "z": -29,
      "name": "Rock_Ice_Permafrost"
    },
    {
      "x": -47,
      "y": 36,
      "z": -29,
      "name": "Rock_Ice_Permafrost"
    },
    {
      "x": -47,
      "y": 37,
      "z": -29,
      "name": "Rock_Ice"
    },
    {
      "x": -47,
      "y": 38,
      "z": -29,
      "name": "Rock_Ice_Permafrost"
    },
    {
      "x": -47,
      "y": 39,
      "z": -29,
      "name": "Rock_Ice_Permafrost"
    },
    {
      "x": -47,
      "y": 40,
      "z": -29,
      "name": "Rock_Ice_Permafrost"
    },
    {
      "x": -47,
      "y": 41,
      "z": -29,
      "name": "Rock_Ice_Permafrost"
    },
    {
      "x": -47,
      "y": 42,
      "z": -29,
      "name": "Rock_Ice_Permafrost"
    },
    {
      "x": -47,
      "y": 43,
      "z": -29,
      "name": "Rock_Ice_Permafrost"
    },
    {
      "x": -47,
      "y": 44,
      "z": -29,
      "name": "Rock_Ice_Permafrost"
    },
    {
      "x": -47,
      "y": 45,
      "z": -29,
      "name": "Rock_Ice_Permafrost"
    },
    {
      "x": -47,
      "y": 46,
      "z": -29,
      "name": "Rock_Ice_Permafrost"
    },
    {
      "x": -47,
      "y": 47,
      "z": -29,
      "name": "Rock_Ice_Permafrost"
    },
    {
      "x": -47,
      "y": 48,
      "z": -29,
      "name": "Rock_Ice_Permafrost"
    },
    {
      "x": -47,
      "y": 49,
      "z": -29,
      "name": "Rock_Ice_Permafrost"
    },
    {
      "x": -47,
      "y": 50,
      "z": -29,
      "name": "Rock_Ice"
    },
    {
      "x": -47,
      "y": 51,
      "z": -29,
      "name": "Rock_Ice_Permafrost"
    },
    {
      "x": -47,
      "y": 30,
      "z": -28,
      "name": "Rock_Ice_Permafrost"
    },
    {
      "x": -47,
      "y": 31,
      "z": -28,
      "name": "Rock_Ice_Permafrost"
    },
    {
      "x": -47,
      "y": 32,
      "z": -28,
      "name": "Rock_Ice_Permafrost"
    },
    {
      "x": -47,
      "y": 33,
      "z": -28,
      "name": "Rock_Ice_Permafrost"
    },
    {
      "x": -47,
      "y": 34,
      "z": -28,
      "name": "Rock_Ice_Permafrost"
    },
    {
      "x": -47,
      "y": 35,
      "z": -28,
      "name": "Rock_Ice_Permafrost"
    },
    {
      "x": -47,
      "y": 36,
      "z": -28,
      "name": "Rock_Ice_Permafrost"
    },
    {
      "x": -47,
      "y": 37,
      "z": -28,
      "name": "Rock_Ice_Permafrost"
    },
    {
      "x": -47,
      "y": 38,
      "z": -28,
      "name": "Rock_Ice_Permafrost"
    },
    {
      "x": -47,
      "y": 39,
      "z": -28,
      "name": "Rock_Ice_Permafrost"
    },
    {
      "x": -47,
      "y": 40,
      "z": -28,
      "name": "Rock_Ice"
    },
    {
      "x": -47,
      "y": 41,
      "z": -28,
      "name": "Rock_Ice_Permafrost"
    },
    {
      "x": -47,
      "y": 42,
      "z": -28,
      "name": "Rock_Ice_Permafrost"
    },
    {
      "x": -47,
      "y": 43,
      "z": -28,
      "name": "Rock_Ice_Permafrost"
    },
    {
      "x": -47,
      "y": 44,
      "z": -28,
      "name": "Rock_Ice_Permafrost"
    },
    {
      "x": -47,
      "y": 45,
      "z": -28,
      "name": "Rock_Ice_Permafrost"
    },
    {
      "x": -47,
      "y": 46,
      "z": -28,
      "name": "Rock_Ice_Permafrost"
    },
    {
      "x": -47,
      "y": 47,
      "z": -28,
      "name": "Rock_Ice_Permafrost"
    },
    {
      "x": -47,
      "y": 48,
      "z": -28,
      "name": "Rock_Ice"
    },
    {
      "x": -47,
      "y": 49,
      "z": -28,
      "name": "Rock_Ice"
    },
    {
      "x": -47,
      "y": 50,
      "z": -28,
      "name": "Soil_Snow"
    },
    {
      "x": -47,
      "y": 29,
      "z": -27,
      "name": "Rock_Ice_Permafrost"
    },
    {
      "x": -47,
      "y": 30,
      "z": -27,
      "name": "Rock_Ice_Permafrost"
    },
    {
      "x": -47,
      "y": 31,
      "z": -27,
      "name": "Rock_Ice_Permafrost"
    },
    {
      "x": -47,
      "y": 32,
      "z": -27,
      "name": "Rock_Ice_Permafrost"
    },
    {
      "x": -47,
      "y": 33,
      "z": -27,
      "name": "Rock_Ice_Permafrost"
    },
    {
      "x": -47,
      "y": 34,
      "z": -27,
      "name": "Rock_Ice_Permafrost"
    },
    {
      "x": -47,
      "y": 35,
      "z": -27,
      "name": "Rock_Ice"
    },
    {
      "x": -47,
      "y": 36,
      "z": -27,
      "name": "Rock_Ice_Permafrost"
    },
    {
      "x": -47,
      "y": 37,
      "z": -27,
      "name": "Rock_Ice"
    },
    {
      "x": -47,
      "y": 38,
      "z": -27,
      "name": "Rock_Ice"
    },
    {
      "x": -47,
      "y": 39,
      "z": -27,
      "name": "Rock_Ice"
    },
    {
      "x": -47,
      "y": 40,
      "z": -27,
      "name": "Rock_Ice_Permafrost"
    },
    {
      "x": -47,
      "y": 41,
      "z": -27,
      "name": "Rock_Ice_Permafrost"
    },
    {
      "x": -47,
      "y": 42,
      "z": -27,
      "name": "Rock_Ice_Permafrost"
    },
    {
      "x": -47,
      "y": 43,
      "z": -27,
      "name": "Rock_Ice_Permafrost"
    },
    {
      "x": -47,
      "y": 44,
      "z": -27,
      "name": "Rock_Ice_Permafrost"
    },
    {
      "x": -47,
      "y": 45,
      "z": -27,
      "name": "Rock_Ice_Permafrost"
    },
    {
      "x": -47,
      "y": 46,
      "z": -27,
      "name": "Rock_Ice_Permafrost"
    },
    {
      "x": -47,
      "y": 47,
      "z": -27,
      "name": "Rock_Ice_Permafrost"
    },
    {
      "x": -47,
      "y": 48,
      "z": -27,
      "name": "Rock_Ice_Permafrost"
    },
    {
      "x": -47,
      "y": 49,
      "z": -27,
      "name": "Rock_Ice"
    },
    {
      "x": -47,
      "y": 50,
      "z": -27,
      "name": "Soil_Snow"
    },
    {
      "x": -47,
      "y": 28,
      "z": -26,
      "name": "Rock_Ice_Permafrost"
    },
    {
      "x": -47,
      "y": 29,
      "z": -26,
      "name": "Rock_Ice_Permafrost"
    },
    {
      "x": -47,
      "y": 30,
      "z": -26,
      "name": "Rock_Ice_Permafrost"
    },
    {
      "x": -47,
      "y": 31,
      "z": -26,
      "name": "Rock_Ice_Permafrost"
    },
    {
      "x": -47,
      "y": 32,
      "z": -26,
      "name": "Rock_Ice_Permafrost"
    },
    {
      "x": -47,
      "y": 33,
      "z": -26,
      "name": "Rock_Ice_Permafrost"
    },
    {
      "x": -47,
      "y": 34,
      "z": -26,
      "name": "Rock_Ice"
    },
    {
      "x": -47,
      "y": 35,
      "z": -26,
      "name": "Rock_Ice"
    },
    {
      "x": -47,
      "y": 36,
      "z": -26,
      "name": "Rock_Ice"
    },
    {
      "x": -47,
      "y": 37,
      "z": -26,
      "name": "Rock_Ice"
    },
    {
      "x": -47,
      "y": 38,
      "z": -26,
      "name": "Rock_Ice"
    },
    {
      "x": -47,
      "y": 39,
      "z": -26,
      "name": "Rock_Ice"
    },
    {
      "x": -47,
      "y": 40,
      "z": -26,
      "name": "Rock_Ice_Permafrost"
    },
    {
      "x": -47,
      "y": 41,
      "z": -26,
      "name": "Rock_Ice_Permafrost"
    },
    {
      "x": -47,
      "y": 42,
      "z": -26,
      "name": "Rock_Ice_Permafrost"
    },
    {
      "x": -47,
      "y": 43,
      "z": -26,
      "name": "Rock_Ice_Permafrost"
    },
    {
      "x": -47,
      "y": 44,
      "z": -26,
      "name": "Rock_Ice_Permafrost"
    },
    {
      "x": -47,
      "y": 45,
      "z": -26,
      "name": "Rock_Ice_Permafrost"
    },
    {
      "x": -47,
      "y": 46,
      "z": -26,
      "name": "Rock_Ice_Permafrost"
    },
    {
      "x": -47,
      "y": 47,
      "z": -26,
      "name": "Rock_Ice"
    },
    {
      "x": -47,
      "y": 48,
      "z": -26,
      "name": "Rock_Ice"
    },
    {
      "x": -47,
      "y": 49,
      "z": -26,
      "name": "Soil_Snow"
    },
    {
      "x": -47,
      "y": 28,
      "z": -25,
      "name": "Rock_Ice_Permafrost"
    },
    {
      "x": -47,
      "y": 29,
      "z": -25,
      "name": "Rock_Ice_Permafrost"
    },
    {
      "x": -47,
      "y": 30,
      "z": -25,
      "name": "Rock_Ice_Permafrost"
    },
    {
      "x": -47,
      "y": 31,
      "z": -25,
      "name": "Rock_Ice"
    },
    {
      "x": -47,
      "y": 32,
      "z": -25,
      "name": "Rock_Ice"
    },
    {
      "x": -47,
      "y": 33,
      "z": -25,
      "name": "Rock_Ice"
    },
    {
      "x": -47,
      "y": 34,
      "z": -25,
      "name": "Rock_Ice"
    },
    {
      "x": -47,
      "y": 35,
      "z": -25,
      "name": "Rock_Ice"
    },
    {
      "x": -47,
      "y": 36,
      "z": -25,
      "name": "Rock_Ice"
    },
    {
      "x": -47,
      "y": 37,
      "z": -25,
      "name": "Rock_Ice"
    },
    {
      "x": -47,
      "y": 38,
      "z": -25,
      "name": "Rock_Ice_Permafrost"
    },
    {
      "x": -47,
      "y": 39,
      "z": -25,
      "name": "Rock_Ice"
    },
    {
      "x": -47,
      "y": 40,
      "z": -25,
      "name": "Rock_Ice_Permafrost"
    },
    {
      "x": -47,
      "y": 41,
      "z": -25,
      "name": "Rock_Ice_Permafrost"
    },
    {
      "x": -47,
      "y": 42,
      "z": -25,
      "name": "Rock_Ice_Permafrost"
    },
    {
      "x": -47,
      "y": 43,
      "z": -25,
      "name": "Rock_Ice"
    },
    {
      "x": -47,
      "y": 44,
      "z": -25,
      "name": "Rock_Ice_Permafrost"
    },
    {
      "x": -47,
      "y": 45,
      "z": -25,
      "name": "Rock_Ice_Permafrost"
    },
    {
      "x": -47,
      "y": 46,
      "z": -25,
      "name": "Rock_Ice"
    },
    {
      "x": -47,
      "y": 47,
      "z": -25,
      "name": "Rock_Ice"
    },
    {
      "x": -47,
      "y": 48,
      "z": -25,
      "name": "Rock_Ice"
    },
    {
      "x": -47,
      "y": 49,
      "z": -25,
      "name": "Soil_Snow"
    },
    {
      "x": -47,
      "y": 28,
      "z": -24,
      "name": "Rock_Ice_Permafrost"
    },
    {
      "x": -47,
      "y": 29,
      "z": -24,
      "name": "Rock_Ice_Permafrost"
    },
    {
      "x": -47,
      "y": 30,
      "z": -24,
      "name": "Rock_Ice"
    },
    {
      "x": -47,
      "y": 31,
      "z": -24,
      "name": "Rock_Ice"
    },
    {
      "x": -47,
      "y": 32,
      "z": -24,
      "name": "Rock_Ice"
    },
    {
      "x": -47,
      "y": 33,
      "z": -24,
      "name": "Rock_Ice"
    },
    {
      "x": -47,
      "y": 34,
      "z": -24,
      "name": "Rock_Ice"
    },
    {
      "x": -47,
      "y": 35,
      "z": -24,
      "name": "Rock_Ice"
    },
    {
      "x": -47,
      "y": 36,
      "z": -24,
      "name": "Rock_Ice"
    },
    {
      "x": -47,
      "y": 37,
      "z": -24,
      "name": "Rock_Ice"
    },
    {
      "x": -47,
      "y": 38,
      "z": -24,
      "name": "Rock_Ice"
    },
    {
      "x": -47,
      "y": 39,
      "z": -24,
      "name": "Rock_Ice"
    },
    {
      "x": -47,
      "y": 40,
      "z": -24,
      "name": "Rock_Ice_Permafrost"
    },
    {
      "x": -47,
      "y": 41,
      "z": -24,
      "name": "Rock_Ice"
    },
    {
      "x": -47,
      "y": 42,
      "z": -24,
      "name": "Rock_Ice_Permafrost"
    },
    {
      "x": -47,
      "y": 43,
      "z": -24,
      "name": "Rock_Ice_Permafrost"
    },
    {
      "x": -47,
      "y": 44,
      "z": -24,
      "name": "Rock_Ice"
    },
    {
      "x": -47,
      "y": 45,
      "z": -24,
      "name": "Rock_Ice"
    },
    {
      "x": -47,
      "y": 46,
      "z": -24,
      "name": "Rock_Ice"
    },
    {
      "x": -47,
      "y": 47,
      "z": -24,
      "name": "Rock_Ice"
    },
    {
      "x": -47,
      "y": 48,
      "z": -24,
      "name": "Soil_Snow"
    },
    {
      "x": -47,
      "y": 29,
      "z": -23,
      "name": "Rock_Ice"
    },
    {
      "x": -47,
      "y": 30,
      "z": -23,
      "name": "Rock_Ice"
    },
    {
      "x": -47,
      "y": 31,
      "z": -23,
      "name": "Rock_Ice"
    },
    {
      "x": -47,
      "y": 32,
      "z": -23,
      "name": "Rock_Ice"
    },
    {
      "x": -47,
      "y": 33,
      "z": -23,
      "name": "Rock_Ice"
    },
    {
      "x": -47,
      "y": 34,
      "z": -23,
      "name": "Rock_Ice"
    },
    {
      "x": -47,
      "y": 35,
      "z": -23,
      "name": "Rock_Ice"
    },
    {
      "x": -47,
      "y": 36,
      "z": -23,
      "name": "Rock_Ice"
    },
    {
      "x": -47,
      "y": 37,
      "z": -23,
      "name": "Rock_Ice"
    },
    {
      "x": -47,
      "y": 38,
      "z": -23,
      "name": "Rock_Ice"
    },
    {
      "x": -47,
      "y": 39,
      "z": -23,
      "name": "Rock_Ice_Permafrost"
    },
    {
      "x": -47,
      "y": 40,
      "z": -23,
      "name": "Rock_Ice_Permafrost"
    },
    {
      "x": -47,
      "y": 41,
      "z": -23,
      "name": "Rock_Ice_Permafrost"
    },
    {
      "x": -47,
      "y": 42,
      "z": -23,
      "name": "Rock_Ice_Permafrost"
    },
    {
      "x": -47,
      "y": 43,
      "z": -23,
      "name": "Rock_Ice_Permafrost"
    },
    {
      "x": -47,
      "y": 44,
      "z": -23,
      "name": "Rock_Ice"
    },
    {
      "x": -47,
      "y": 45,
      "z": -23,
      "name": "Rock_Ice"
    },
    {
      "x": -47,
      "y": 46,
      "z": -23,
      "name": "Rock_Ice"
    },
    {
      "x": -47,
      "y": 47,
      "z": -23,
      "name": "Rock_Ice"
    },
    {
      "x": -47,
      "y": 48,
      "z": -23,
      "name": "Soil_Snow"
    },
    {
      "x": -47,
      "y": 30,
      "z": -22,
      "name": "Rock_Ice"
    },
    {
      "x": -47,
      "y": 31,
      "z": -22,
      "name": "Rock_Ice"
    },
    {
      "x": -47,
      "y": 32,
      "z": -22,
      "name": "Rock_Ice"
    },
    {
      "x": -47,
      "y": 33,
      "z": -22,
      "name": "Rock_Ice"
    },
    {
      "x": -47,
      "y": 34,
      "z": -22,
      "name": "Rock_Ice"
    },
    {
      "x": -47,
      "y": 35,
      "z": -22,
      "name": "Rock_Ice"
    },
    {
      "x": -47,
      "y": 36,
      "z": -22,
      "name": "Rock_Ice"
    },
    {
      "x": -47,
      "y": 37,
      "z": -22,
      "name": "Rock_Ice"
    },
    {
      "x": -47,
      "y": 38,
      "z": -22,
      "name": "Rock_Ice"
    },
    {
      "x": -47,
      "y": 39,
      "z": -22,
      "name": "Rock_Ice_Permafrost"
    },
    {
      "x": -47,
      "y": 40,
      "z": -22,
      "name": "Rock_Ice_Permafrost"
    },
    {
      "x": -47,
      "y": 41,
      "z": -22,
      "name": "Rock_Ice_Permafrost"
    },
    {
      "x": -47,
      "y": 42,
      "z": -22,
      "name": "Rock_Ice_Permafrost"
    },
    {
      "x": -47,
      "y": 43,
      "z": -22,
      "name": "Rock_Ice_Permafrost"
    },
    {
      "x": -47,
      "y": 44,
      "z": -22,
      "name": "Rock_Ice"
    },
    {
      "x": -47,
      "y": 45,
      "z": -22,
      "name": "Rock_Ice"
    },
    {
      "x": -47,
      "y": 46,
      "z": -22,
      "name": "Rock_Ice"
    },
    {
      "x": -47,
      "y": 47,
      "z": -22,
      "name": "Soil_Snow"
    },
    {
      "x": -47,
      "y": 30,
      "z": -21,
      "name": "Rock_Ice"
    },
    {
      "x": -47,
      "y": 31,
      "z": -21,
      "name": "Rock_Ice"
    },
    {
      "x": -47,
      "y": 32,
      "z": -21,
      "name": "Rock_Ice"
    },
    {
      "x": -47,
      "y": 33,
      "z": -21,
      "name": "Rock_Ice"
    },
    {
      "x": -47,
      "y": 34,
      "z": -21,
      "name": "Rock_Ice"
    },
    {
      "x": -47,
      "y": 35,
      "z": -21,
      "name": "Rock_Ice"
    },
    {
      "x": -47,
      "y": 36,
      "z": -21,
      "name": "Rock_Ice"
    },
    {
      "x": -47,
      "y": 37,
      "z": -21,
      "name": "Rock_Ice"
    },
    {
      "x": -47,
      "y": 38,
      "z": -21,
      "name": "Rock_Ice"
    },
    {
      "x": -47,
      "y": 39,
      "z": -21,
      "name": "Rock_Ice_Permafrost"
    },
    {
      "x": -47,
      "y": 40,
      "z": -21,
      "name": "Rock_Ice_Permafrost"
    },
    {
      "x": -47,
      "y": 41,
      "z": -21,
      "name": "Rock_Ice"
    },
    {
      "x": -47,
      "y": 42,
      "z": -21,
      "name": "Rock_Ice_Permafrost"
    },
    {
      "x": -47,
      "y": 43,
      "z": -21,
      "name": "Rock_Ice"
    },
    {
      "x": -47,
      "y": 44,
      "z": -21,
      "name": "Rock_Ice"
    },
    {
      "x": -47,
      "y": 45,
      "z": -21,
      "name": "Rock_Ice"
    },
    {
      "x": -47,
      "y": 46,
      "z": -21,
      "name": "Soil_Snow"
    },
    {
      "x": -47,
      "y": 31,
      "z": -20,
      "name": "Rock_Ice"
    },
    {
      "x": -47,
      "y": 32,
      "z": -20,
      "name": "Rock_Ice"
    },
    {
      "x": -47,
      "y": 33,
      "z": -20,
      "name": "Rock_Ice"
    },
    {
      "x": -47,
      "y": 34,
      "z": -20,
      "name": "Rock_Ice"
    },
    {
      "x": -47,
      "y": 35,
      "z": -20,
      "name": "Rock_Ice"
    },
    {
      "x": -47,
      "y": 36,
      "z": -20,
      "name": "Rock_Ice"
    },
    {
      "x": -47,
      "y": 37,
      "z": -20,
      "name": "Rock_Ice"
    },
    {
      "x": -47,
      "y": 38,
      "z": -20,
      "name": "Rock_Ice_Permafrost"
    },
    {
      "x": -47,
      "y": 39,
      "z": -20,
      "name": "Rock_Ice_Permafrost"
    },
    {
      "x": -47,
      "y": 40,
      "z": -20,
      "name": "Rock_Ice_Permafrost"
    },
    {
      "x": -47,
      "y": 41,
      "z": -20,
      "name": "Rock_Ice"
    },
    {
      "x": -47,
      "y": 42,
      "z": -20,
      "name": "Rock_Ice_Permafrost"
    },
    {
      "x": -47,
      "y": 43,
      "z": -20,
      "name": "Rock_Ice_Permafrost"
    },
    {
      "x": -47,
      "y": 44,
      "z": -20,
      "name": "Rock_Ice"
    },
    {
      "x": -47,
      "y": 45,
      "z": -20,
      "name": "Rock_Ice"
    },
    {
      "x": -47,
      "y": 46,
      "z": -20,
      "name": "Soil_Snow"
    },
    {
      "x": -47,
      "y": 31,
      "z": -19,
      "name": "Rock_Ice"
    },
    {
      "x": -47,
      "y": 32,
      "z": -19,
      "name": "Rock_Ice"
    },
    {
      "x": -47,
      "y": 33,
      "z": -19,
      "name": "Rock_Ice"
    },
    {
      "x": -47,
      "y": 34,
      "z": -19,
      "name": "Rock_Ice"
    },
    {
      "x": -47,
      "y": 35,
      "z": -19,
      "name": "Rock_Ice"
    },
    {
      "x": -47,
      "y": 36,
      "z": -19,
      "name": "Rock_Ice"
    },
    {
      "x": -47,
      "y": 37,
      "z": -19,
      "name": "Rock_Ice"
    },
    {
      "x": -47,
      "y": 38,
      "z": -19,
      "name": "Rock_Ice_Permafrost"
    },
    {
      "x": -47,
      "y": 39,
      "z": -19,
      "name": "Rock_Ice_Permafrost"
    },
    {
      "x": -47,
      "y": 40,
      "z": -19,
      "name": "Rock_Ice_Permafrost"
    },
    {
      "x": -47,
      "y": 41,
      "z": -19,
      "name": "Rock_Ice_Permafrost"
    },
    {
      "x": -47,
      "y": 42,
      "z": -19,
      "name": "Rock_Ice_Permafrost"
    },
    {
      "x": -47,
      "y": 43,
      "z": -19,
      "name": "Rock_Ice"
    },
    {
      "x": -47,
      "y": 44,
      "z": -19,
      "name": "Rock_Ice"
    },
    {
      "x": -47,
      "y": 45,
      "z": -19,
      "name": "Soil_Snow"
    },
    {
      "x": -47,
      "y": 32,
      "z": -18,
      "name": "Rock_Ice"
    },
    {
      "x": -47,
      "y": 33,
      "z": -18,
      "name": "Rock_Ice"
    },
    {
      "x": -47,
      "y": 34,
      "z": -18,
      "name": "Rock_Ice"
    },
    {
      "x": -47,
      "y": 35,
      "z": -18,
      "name": "Rock_Ice"
    },
    {
      "x": -47,
      "y": 36,
      "z": -18,
      "name": "Rock_Ice"
    },
    {
      "x": -47,
      "y": 37,
      "z": -18,
      "name": "Rock_Ice"
    },
    {
      "x": -47,
      "y": 38,
      "z": -18,
      "name": "Rock_Ice"
    },
    {
      "x": -47,
      "y": 39,
      "z": -18,
      "name": "Rock_Ice"
    },
    {
      "x": -47,
      "y": 40,
      "z": -18,
      "name": "Rock_Ice_Permafrost"
    },
    {
      "x": -47,
      "y": 41,
      "z": -18,
      "name": "Rock_Ice_Permafrost"
    },
    {
      "x": -47,
      "y": 42,
      "z": -18,
      "name": "Rock_Ice_Permafrost"
    },
    {
      "x": -47,
      "y": 43,
      "z": -18,
      "name": "Rock_Ice"
    },
    {
      "x": -47,
      "y": 44,
      "z": -18,
      "name": "Soil_Snow"
    },
    {
      "x": -47,
      "y": 32,
      "z": -17,
      "name": "Rock_Ice"
    },
    {
      "x": -47,
      "y": 33,
      "z": -17,
      "name": "Rock_Ice"
    },
    {
      "x": -47,
      "y": 34,
      "z": -17,
      "name": "Rock_Ice"
    },
    {
      "x": -47,
      "y": 35,
      "z": -17,
      "name": "Rock_Ice"
    },
    {
      "x": -47,
      "y": 36,
      "z": -17,
      "name": "Rock_Ice"
    },
    {
      "x": -47,
      "y": 37,
      "z": -17,
      "name": "Rock_Ice"
    },
    {
      "x": -47,
      "y": 38,
      "z": -17,
      "name": "Rock_Ice"
    },
    {
      "x": -47,
      "y": 39,
      "z": -17,
      "name": "Rock_Ice"
    },
    {
      "x": -47,
      "y": 40,
      "z": -17,
      "name": "Rock_Ice_Permafrost"
    },
    {
      "x": -47,
      "y": 41,
      "z": -17,
      "name": "Rock_Ice_Permafrost"
    },
    {
      "x": -47,
      "y": 42,
      "z": -17,
      "name": "Rock_Ice"
    },
    {
      "x": -47,
      "y": 43,
      "z": -17,
      "name": "Soil_Snow"
    },
    {
      "x": -47,
      "y": 33,
      "z": -16,
      "name": "Rock_Ice"
    },
    {
      "x": -47,
      "y": 34,
      "z": -16,
      "name": "Rock_Ice"
    },
    {
      "x": -47,
      "y": 35,
      "z": -16,
      "name": "Rock_Ice"
    },
    {
      "x": -47,
      "y": 36,
      "z": -16,
      "name": "Rock_Ice"
    },
    {
      "x": -47,
      "y": 37,
      "z": -16,
      "name": "Rock_Ice"
    },
    {
      "x": -47,
      "y": 38,
      "z": -16,
      "name": "Rock_Ice_Permafrost"
    },
    {
      "x": -47,
      "y": 39,
      "z": -16,
      "name": "Rock_Ice_Permafrost"
    },
    {
      "x": -47,
      "y": 40,
      "z": -16,
      "name": "Rock_Ice_Permafrost"
    },
    {
      "x": -47,
      "y": 41,
      "z": -16,
      "name": "Rock_Ice"
    },
    {
      "x": -47,
      "y": 42,
      "z": -16,
      "name": "Soil_Snow"
    },
    {
      "x": -47,
      "y": 33,
      "z": -15,
      "name": "Rock_Ice"
    },
    {
      "x": -47,
      "y": 34,
      "z": -15,
      "name": "Rock_Ice"
    },
    {
      "x": -47,
      "y": 35,
      "z": -15,
      "name": "Rock_Ice"
    },
    {
      "x": -47,
      "y": 36,
      "z": -15,
      "name": "Rock_Ice"
    },
    {
      "x": -47,
      "y": 37,
      "z": -15,
      "name": "Rock_Ice"
    },
    {
      "x": -47,
      "y": 38,
      "z": -15,
      "name": "Rock_Ice_Permafrost"
    },
    {
      "x": -47,
      "y": 39,
      "z": -15,
      "name": "Rock_Ice_Permafrost"
    },
    {
      "x": -47,
      "y": 40,
      "z": -15,
      "name": "Rock_Ice"
    },
    {
      "x": -47,
      "y": 41,
      "z": -15,
      "name": "Rock_Ice"
    },
    {
      "x": -47,
      "y": 42,
      "z": -15,
      "name": "Soil_Snow"
    },
    {
      "x": -47,
      "y": 34,
      "z": -14,
      "name": "Rock_Ice"
    },
    {
      "x": -47,
      "y": 35,
      "z": -14,
      "name": "Rock_Ice"
    },
    {
      "x": -47,
      "y": 36,
      "z": -14,
      "name": "Rock_Ice"
    },
    {
      "x": -47,
      "y": 37,
      "z": -14,
      "name": "Rock_Ice"
    },
    {
      "x": -47,
      "y": 38,
      "z": -14,
      "name": "Rock_Ice_Permafrost"
    },
    {
      "x": -47,
      "y": 39,
      "z": -14,
      "name": "Rock_Ice_Permafrost"
    },
    {
      "x": -47,
      "y": 40,
      "z": -14,
      "name": "Rock_Ice"
    },
    {
      "x": -47,
      "y": 41,
      "z": -14,
      "name": "Soil_Snow"
    },
    {
      "x": -47,
      "y": 35,
      "z": -13,
      "name": "Rock_Ice"
    },
    {
      "x": -47,
      "y": 36,
      "z": -13,
      "name": "Rock_Ice"
    },
    {
      "x": -47,
      "y": 37,
      "z": -13,
      "name": "Rock_Ice"
    },
    {
      "x": -47,
      "y": 38,
      "z": -13,
      "name": "Rock_Ice_Permafrost"
    },
    {
      "x": -47,
      "y": 39,
      "z": -13,
      "name": "Rock_Ice_Permafrost"
    },
    {
      "x": -47,
      "y": 40,
      "z": -13,
      "name": "Rock_Ice"
    },
    {
      "x": -47,
      "y": 41,
      "z": -13,
      "name": "Soil_Snow"
    },
    {
      "x": -47,
      "y": 37,
      "z": -12,
      "name": "Rock_Ice"
    },
    {
      "x": -47,
      "y": 38,
      "z": -12,
      "name": "Rock_Ice_Permafrost"
    },
    {
      "x": -47,
      "y": 39,
      "z": -12,
      "name": "Rock_Ice"
    },
    {
      "x": -47,
      "y": 40,
      "z": -12,
      "name": "Soil_Snow"
    },
    {
      "x": -47,
      "y": 38,
      "z": -11,
      "name": "Rock_Ice"
    },
    {
      "x": -47,
      "y": 39,
      "z": -11,
      "name": "Soil_Snow"
    },
    {
      "x": -47,
      "y": 38,
      "z": -10,
      "name": "Soil_Snow"
    },
    {
      "x": -46,
      "y": 43,
      "z": -36,
      "name": "Rock_Ice"
    },
    {
      "x": -46,
      "y": 44,
      "z": -36,
      "name": "Rock_Ice_Permafrost"
    },
    {
      "x": -46,
      "y": 45,
      "z": -36,
      "name": "Rock_Ice_Permafrost"
    },
    {
      "x": -46,
      "y": 46,
      "z": -36,
      "name": "Rock_Ice_Permafrost"
    },
    {
      "x": -46,
      "y": 47,
      "z": -36,
      "name": "Soil_Snow"
    },
    {
      "x": -46,
      "y": 40,
      "z": -35,
      "name": "Rock_Ice"
    },
    {
      "x": -46,
      "y": 41,
      "z": -35,
      "name": "Rock_Ice"
    },
    {
      "x": -46,
      "y": 42,
      "z": -35,
      "name": "Rock_Ice"
    },
    {
      "x": -46,
      "y": 43,
      "z": -35,
      "name": "Rock_Ice_Permafrost"
    },
    {
      "x": -46,
      "y": 44,
      "z": -35,
      "name": "Rock_Ice_Permafrost"
    },
    {
      "x": -46,
      "y": 45,
      "z": -35,
      "name": "Rock_Ice_Permafrost"
    },
    {
      "x": -46,
      "y": 46,
      "z": -35,
      "name": "Rock_Ice_Permafrost"
    },
    {
      "x": -46,
      "y": 47,
      "z": -35,
      "name": "Rock_Ice_Permafrost"
    },
    {
      "x": -46,
      "y": 48,
      "z": -35,
      "name": "Rock_Ice_Permafrost"
    },
    {
      "x": -46,
      "y": 49,
      "z": -35,
      "name": "Rock_Ice_Permafrost"
    },
    {
      "x": -46,
      "y": 50,
      "z": -35,
      "name": "Rock_Ice_Permafrost"
    },
    {
      "x": -46,
      "y": 51,
      "z": -35,
      "name": "Soil_Snow"
    },
    {
      "x": -46,
      "y": 38,
      "z": -34,
      "name": "Rock_Ice"
    },
    {
      "x": -46,
      "y": 39,
      "z": -34,
      "name": "Rock_Ice"
    },
    {
      "x": -46,
      "y": 40,
      "z": -34,
      "name": "Rock_Ice"
    },
    {
      "x": -46,
      "y": 41,
      "z": -34,
      "name": "Rock_Ice_Permafrost"
    },
    {
      "x": -46,
      "y": 42,
      "z": -34,
      "name": "Rock_Ice_Permafrost"
    },
    {
      "x": -46,
      "y": 43,
      "z": -34,
      "name": "Rock_Ice_Permafrost"
    },
    {
      "x": -46,
      "y": 44,
      "z": -34,
      "name": "Rock_Ice_Permafrost"
    },
    {
      "x": -46,
      "y": 45,
      "z": -34,
      "name": "Rock_Ice"
    },
    {
      "x": -46,
      "y": 46,
      "z": -34,
      "name": "Rock_Ice_Permafrost"
    },
    {
      "x": -46,
      "y": 47,
      "z": -34,
      "name": "Rock_Ice_Permafrost"
    },
    {
      "x": -46,
      "y": 48,
      "z": -34,
      "name": "Rock_Ice_Permafrost"
    },
    {
      "x": -46,
      "y": 49,
      "z": -34,
      "name": "Rock_Ice_Permafrost"
    },
    {
      "x": -46,
      "y": 50,
      "z": -34,
      "name": "Rock_Ice"
    },
    {
      "x": -46,
      "y": 51,
      "z": -34,
      "name": "Soil_Snow"
    },
    {
      "x": -46,
      "y": 36,
      "z": -33,
      "name": "Rock_Ice"
    },
    {
      "x": -46,
      "y": 37,
      "z": -33,
      "name": "Rock_Ice"
    },
    {
      "x": -46,
      "y": 38,
      "z": -33,
      "name": "Rock_Ice"
    },
    {
      "x": -46,
      "y": 39,
      "z": -33,
      "name": "Rock_Ice_Permafrost"
    },
    {
      "x": -46,
      "y": 40,
      "z": -33,
      "name": "Rock_Ice_Permafrost"
    },
    {
      "x": -46,
      "y": 41,
      "z": -33,
      "name": "Rock_Ice_Permafrost"
    },
    {
      "x": -46,
      "y": 42,
      "z": -33,
      "name": "Rock_Ice_Permafrost"
    },
    {
      "x": -46,
      "y": 43,
      "z": -33,
      "name": "Rock_Ice_Permafrost"
    },
    {
      "x": -46,
      "y": 44,
      "z": -33,
      "name": "Rock_Ice_Permafrost"
    },
    {
      "x": -46,
      "y": 45,
      "z": -33,
      "name": "Rock_Ice_Permafrost"
    },
    {
      "x": -46,
      "y": 46,
      "z": -33,
      "name": "Rock_Ice_Permafrost"
    },
    {
      "x": -46,
      "y": 47,
      "z": -33,
      "name": "Rock_Ice_Permafrost"
    },
    {
      "x": -46,
      "y": 48,
      "z": -33,
      "name": "Rock_Ice_Permafrost"
    },
    {
      "x": -46,
      "y": 49,
      "z": -33,
      "name": "Rock_Ice_Permafrost"
    },
    {
      "x": -46,
      "y": 50,
      "z": -33,
      "name": "Rock_Ice_Permafrost"
    },
    {
      "x": -46,
      "y": 51,
      "z": -33,
      "name": "Rock_Ice"
    },
    {
      "x": -46,
      "y": 52,
      "z": -33,
      "name": "Soil_Snow"
    },
    {
      "x": -46,
      "y": 35,
      "z": -32,
      "name": "Rock_Ice"
    },
    {
