{
  "version": 8,
  "blockIdVersion": 11,
  "anchorX": 2,
  "anchorY": 29,
  "anchorZ": -1,
  "blocks": [
    {
      "x": -38,
      "y": 54,
      "z": -9,
      "name": "Soil_Snow"
    },
    {
      "x": -38,
      "y": 73,
      "z": 2,
      "name": "Rock_Ice"
    },
    {
      "x": -38,
      "y": 74,
      "z": 2,
      "name": "Soil_Snow"
    },
    {
      "x": -38,
      "y": 72,
      "z": 3,
      "name": "Rock_Ice"
    },
    {
      "x": -38,
      "y": 73,
      "z": 3,
      "name": "Rock_Ice"
    },
    {
      "x": -38,
      "y": 74,
      "z": 3,
      "name": "Soil_Snow"
    },
    {
      "x": -38,
      "y": 72,
      "z": 4,
      "name": "Rock_Ice"
    },
    {
      "x": -38,
      "y": 73,
      "z": 4,
      "name": "Rock_Ice"
    },
    {
      "x": -38,
      "y": 74,
      "z": 4,
      "name": "Soil_Snow"
    },
    {
      "x": -38,
      "y": 71,
      "z": 5,
      "name": "Rock_Ice"
    },
    {
      "x": -38,
      "y": 72,
      "z": 5,
      "name": "Rock_Ice"
    },
    {
      "x": -38,
      "y": 73,
      "z": 5,
      "name": "Rock_Ice"
    },
    {
      "x": -38,
      "y": 74,
      "z": 5,
      "name": "Soil_Snow"
    },
    {
      "x": -38,
      "y": 70,
      "z": 6,
      "name": "Rock_Ice"
    },
    {
      "x": -38,
      "y": 71,
      "z": 6,
      "name": "Rock_Ice"
    },
    {
      "x": -38,
      "y": 72,
      "z": 6,
      "name": "Rock_Ice"
    },
    {
      "x": -38,
      "y": 73,
      "z": 6,
      "name": "Rock_Ice"
    },
    {
      "x": -38,
      "y": 74,
      "z": 6,
      "name": "Soil_Snow"
    },
    {
      "x": -38,
      "y": 70,
      "z": 7,
      "name": "Rock_Ice"
    },
    {
      "x": -38,
      "y": 71,
      "z": 7,
      "name": "Rock_Ice"
    },
    {
      "x": -38,
      "y": 72,
      "z": 7,
      "name": "Rock_Ice"
    },
    {
      "x": -38,
      "y": 73,
      "z": 7,
      "name": "Rock_Ice"
    },
    {
      "x": -38,
      "y": 74,
      "z": 7,
      "name": "Soil_Snow"
    },
    {
      "x": -38,
      "y": 70,
      "z": 8,
      "name": "Rock_Ice"
    },
    {
      "x": -38,
      "y": 71,
      "z": 8,
      "name": "Rock_Ice"
    },
    {
      "x": -38,
      "y": 72,
      "z": 8,
      "name": "Rock_Ice"
    },
    {
      "x": -38,
      "y": 73,
      "z": 8,
      "name": "Rock_Ice"
    },
    {
      "x": -38,
      "y": 74,
      "z": 8,
      "name": "Soil_Snow"
    },
    {
      "x": -38,
      "y": 69,
      "z": 9,
      "name": "Rock_Ice"
    },
    {
      "x": -38,
      "y": 70,
      "z": 9,
      "name": "Rock_Ice"
    },
    {
      "x": -38,
      "y": 71,
      "z": 9,
      "name": "Rock_Ice"
    },
    {
      "x": -38,
      "y": 72,
      "z": 9,
      "name": "Rock_Ice"
    },
    {
      "x": -38,
      "y": 73,
      "z": 9,
      "name": "Rock_Ice"
    },
    {
      "x": -38,
      "y": 74,
      "z": 9,
      "name": "Rock_Ice"
    },
    {
      "x": -38,
      "y": 69,
      "z": 10,
      "name": "Rock_Ice"
    },
    {
      "x": -38,
      "y": 70,
      "z": 10,
      "name": "Rock_Ice"
    },
    {
      "x": -38,
      "y": 71,
      "z": 10,
      "name": "Rock_Ice"
    },
    {
      "x": -38,
      "y": 72,
      "z": 10,
      "name": "Rock_Ice"
    },
    {
      "x": -38,
      "y": 73,
      "z": 10,
      "name": "Rock_Ice"
    },
    {
      "x": -38,
      "y": 74,
      "z": 10,
      "name": "Rock_Ice"
    },
    {
      "x": -38,
      "y": 69,
      "z": 11,
      "name": "Rock_Ice"
    },
    {
      "x": -38,
      "y": 70,
      "z": 11,
      "name": "Rock_Ice"
    },
    {
      "x": -38,
      "y": 71,
      "z": 11,
      "name": "Rock_Ice"
    },
    {
      "x": -38,
      "y": 72,
      "z": 11,
      "name": "Rock_Ice"
    },
    {
      "x": -38,
      "y": 73,
      "z": 11,
      "name": "Rock_Ice"
    },
    {
      "x": -38,
      "y": 74,
      "z": 11,
      "name": "Rock_Ice"
    },
    {
      "x": -38,
      "y": 69,
      "z": 12,
      "name": "Rock_Ice"
    },
    {
      "x": -38,
      "y": 70,
      "z": 12,
      "name": "Rock_Ice"
    },
    {
      "x": -38,
      "y": 71,
      "z": 12,
      "name": "Rock_Ice"
    },
    {
      "x": -38,
      "y": 72,
      "z": 12,
      "name": "Rock_Ice"
    },
    {
      "x": -38,
      "y": 73,
      "z": 12,
      "name": "Soil_Snow"
    },
    {
      "x": -38,
      "y": 68,
      "z": 16,
      "name": "Rock_Ice"
    },
    {
      "x": -38,
      "y": 69,
      "z": 16,
      "name": "Rock_Ice"
    },
    {
      "x": -38,
      "y": 70,
      "z": 16,
      "name": "Rock_Ice"
    },
    {
      "x": -38,
      "y": 71,
      "z": 16,
      "name": "Rock_Ice"
    },
    {
      "x": -38,
      "y": 72,
      "z": 16,
      "name": "Soil_Snow"
    },
    {
      "x": -38,
      "y": 69,
      "z": 17,
      "name": "Rock_Ice"
    },
    {
      "x": -38,
      "y": 70,
      "z": 17,
      "name": "Rock_Ice"
    },
    {
      "x": -38,
      "y": 71,
      "z": 17,
      "name": "Rock_Ice"
    },
    {
      "x": -38,
      "y": 72,
      "z": 17,
      "name": "Soil_Snow"
    },
    {
      "x": -37,
      "y": 53,
      "z": -10,
      "name": "Rock_Ice"
    },
    {
      "x": -37,
      "y": 54,
      "z": -10,
      "name": "Rock_Ice"
    },
    {
      "x": -37,
      "y": 55,
      "z": -10,
      "name": "Rock_Ice"
    },
    {
      "x": -37,
      "y": 56,
      "z": -10,
      "name": "Soil_Snow"
    },
    {
      "x": -37,
      "y": 51,
      "z": -9,
      "name": "Rock_Ice_Permafrost"
    },
    {
      "x": -37,
      "y": 52,
      "z": -9,
      "name": "Rock_Ice_Permafrost"
    },
    {
      "x": -37,
      "y": 53,
      "z": -9,
      "name": "Rock_Ice_Permafrost"
    },
    {
      "x": -37,
      "y": 54,
      "z": -9,
      "name": "Rock_Ice"
    },
    {
      "x": -37,
      "y": 55,
      "z": -9,
      "name": "Rock_Ice"
    },
    {
      "x": -37,
      "y": 56,
      "z": -9,
      "name": "Soil_Snow"
    },
    {
      "x": -37,
      "y": 51,
      "z": -8,
      "name": "Rock_Ice_Permafrost"
    },
    {
      "x": -37,
      "y": 52,
      "z": -8,
      "name": "Rock_Ice_Permafrost"
    },
    {
      "x": -37,
      "y": 53,
      "z": -8,
      "name": "Rock_Ice_Permafrost"
    },
    {
      "x": -37,
      "y": 54,
      "z": -8,
      "name": "Rock_Ice"
    },
    {
      "x": -37,
      "y": 55,
      "z": -8,
      "name": "Soil_Snow"
    },
    {
      "x": -37,
      "y": 51,
      "z": -7,
      "name": "Rock_Ice"
    },
    {
      "x": -37,
      "y": 52,
      "z": -7,
      "name": "Rock_Ice_Permafrost"
    },
    {
      "x": -37,
      "y": 53,
      "z": -7,
      "name": "Rock_Ice_Permafrost"
    },
    {
      "x": -37,
      "y": 54,
      "z": -7,
      "name": "Rock_Ice_Permafrost"
    },
    {
      "x": -37,
      "y": 55,
      "z": -7,
      "name": "Soil_Snow"
    },
    {
      "x": -37,
      "y": 51,
      "z": -6,
      "name": "Rock_Ice"
    },
    {
      "x": -37,
      "y": 52,
      "z": -6,
      "name": "Rock_Ice"
    },
    {
      "x": -37,
      "y": 53,
      "z": -6,
      "name": "Rock_Ice"
    },
    {
      "x": -37,
      "y": 54,
      "z": -6,
      "name": "Rock_Ice"
    },
    {
      "x": -37,
      "y": 51,
      "z": -5,
      "name": "Rock_Ice"
    },
    {
      "x": -37,
      "y": 52,
      "z": -5,
      "name": "Rock_Ice"
    },
    {
      "x": -37,
      "y": 53,
      "z": -5,
      "name": "Soil_Snow"
    },
    {
      "x": -37,
      "y": 52,
      "z": -4,
      "name": "Soil_Snow"
    },
    {
      "x": -37,
      "y": 71,
      "z": -1,
      "name": "Soil_Snow"
    },
    {
      "x": -37,
      "y": 71,
      "z": 0,
      "name": "Rock_Ice"
    },
    {
      "x": -37,
      "y": 72,
      "z": 0,
      "name": "Rock_Ice"
    },
    {
      "x": -37,
      "y": 73,
      "z": 0,
      "name": "Soil_Snow"
    },
    {
      "x": -37,
      "y": 71,
      "z": 1,
      "name": "Rock_Ice"
    },
    {
      "x": -37,
      "y": 72,
      "z": 1,
      "name": "Rock_Ice"
    },
    {
      "x": -37,
      "y": 73,
      "z": 1,
      "name": "Rock_Ice"
    },
    {
      "x": -37,
      "y": 74,
      "z": 1,
      "name": "Soil_Snow"
    },
    {
      "x": -37,
      "y": 70,
      "z": 2,
      "name": "Rock_Ice"
    },
    {
      "x": -37,
      "y": 71,
      "z": 2,
      "name": "Rock_Ice"
    },
    {
      "x": -37,
      "y": 72,
      "z": 2,
      "name": "Rock_Ice"
    },
    {
      "x": -37,
      "y": 73,
      "z": 2,
      "name": "Rock_Ice"
    },
    {
      "x": -37,
      "y": 74,
      "z": 2,
      "name": "Soil_Snow"
    },
    {
      "x": -37,
      "y": 70,
      "z": 3,
      "name": "Rock_Ice"
    },
    {
      "x": -37,
      "y": 71,
      "z": 3,
      "name": "Rock_Ice"
    },
    {
      "x": -37,
      "y": 72,
      "z": 3,
      "name": "Rock_Ice"
    },
    {
      "x": -37,
      "y": 73,
      "z": 3,
      "name": "Rock_Ice"
    },
    {
      "x": -37,
      "y": 74,
      "z": 3,
      "name": "Rock_Ice"
    },
    {
      "x": -37,
      "y": 75,
      "z": 3,
      "name": "Soil_Snow"
    },
    {
      "x": -37,
      "y": 69,
      "z": 4,
      "name": "Rock_Ice"
    },
    {
      "x": -37,
      "y": 70,
      "z": 4,
      "name": "Rock_Ice"
    },
    {
      "x": -37,
      "y": 71,
      "z": 4,
      "name": "Rock_Ice"
    },
    {
      "x": -37,
      "y": 72,
      "z": 4,
      "name": "Rock_Ice"
    },
    {
      "x": -37,
      "y": 73,
      "z": 4,
      "name": "Rock_Ice"
    },
    {
      "x": -37,
      "y": 74,
      "z": 4,
      "name": "Soil_Snow"
    },
    {
      "x": -37,
      "y": 68,
      "z": 5,
      "name": "Rock_Ice"
    },
    {
      "x": -37,
      "y": 69,
      "z": 5,
      "name": "Rock_Ice"
    },
    {
      "x": -37,
      "y": 70,
      "z": 5,
      "name": "Rock_Ice"
    },
    {
      "x": -37,
      "y": 71,
      "z": 5,
      "name": "Rock_Ice"
    },
    {
      "x": -37,
      "y": 72,
      "z": 5,
      "name": "Rock_Ice"
    },
    {
      "x": -37,
      "y": 73,
      "z": 5,
      "name": "Rock_Ice"
    },
    {
      "x": -37,
      "y": 74,
      "z": 5,
      "name": "Soil_Snow"
    },
    {
      "x": -37,
      "y": 68,
      "z": 6,
      "name": "Rock_Ice"
    },
    {
      "x": -37,
      "y": 69,
      "z": 6,
      "name": "Rock_Ice"
    },
    {
      "x": -37,
      "y": 70,
      "z": 6,
      "name": "Rock_Ice"
    },
    {
      "x": -37,
      "y": 71,
      "z": 6,
      "name": "Rock_Ice"
    },
    {
      "x": -37,
      "y": 72,
      "z": 6,
      "name": "Rock_Ice"
    },
    {
      "x": -37,
      "y": 73,
      "z": 6,
      "name": "Rock_Ice"
    },
    {
      "x": -37,
      "y": 74,
      "z": 6,
      "name": "Soil_Snow"
    },
    {
      "x": -37,
      "y": 67,
      "z": 7,
      "name": "Rock_Ice"
    },
    {
      "x": -37,
      "y": 68,
      "z": 7,
      "name": "Rock_Ice"
    },
    {
      "x": -37,
      "y": 69,
      "z": 7,
      "name": "Rock_Ice"
    },
    {
      "x": -37,
      "y": 70,
      "z": 7,
      "name": "Rock_Ice"
    },
    {
      "x": -37,
      "y": 71,
      "z": 7,
      "name": "Rock_Ice"
    },
    {
      "x": -37,
      "y": 72,
      "z": 7,
      "name": "Rock_Ice"
    },
    {
      "x": -37,
      "y": 73,
      "z": 7,
      "name": "Rock_Ice"
    },
    {
      "x": -37,
      "y": 74,
      "z": 7,
      "name": "Soil_Snow"
    },
    {
      "x": -37,
      "y": 67,
      "z": 8,
      "name": "Rock_Ice"
    },
    {
      "x": -37,
      "y": 68,
      "z": 8,
      "name": "Rock_Ice"
    },
    {
      "x": -37,
      "y": 69,
      "z": 8,
      "name": "Rock_Ice"
    },
    {
      "x": -37,
      "y": 70,
      "z": 8,
      "name": "Rock_Ice"
    },
    {
      "x": -37,
      "y": 71,
      "z": 8,
      "name": "Rock_Ice"
    },
    {
      "x": -37,
      "y": 72,
      "z": 8,
      "name": "Rock_Ice"
    },
    {
      "x": -37,
      "y": 73,
      "z": 8,
      "name": "Rock_Ice"
    },
    {
      "x": -37,
      "y": 74,
      "z": 8,
      "name": "Soil_Snow"
    },
    {
      "x": -37,
      "y": 66,
      "z": 9,
      "name": "Rock_Ice"
    },
    {
      "x": -37,
      "y": 67,
      "z": 9,
      "name": "Rock_Ice"
    },
    {
      "x": -37,
      "y": 68,
      "z": 9,
      "name": "Rock_Ice"
    },
    {
      "x": -37,
      "y": 69,
      "z": 9,
      "name": "Rock_Ice"
    },
    {
      "x": -37,
      "y": 70,
      "z": 9,
      "name": "Rock_Ice"
    },
    {
      "x": -37,
      "y": 71,
      "z": 9,
      "name": "Rock_Ice"
    },
    {
      "x": -37,
      "y": 72,
      "z": 9,
      "name": "Rock_Ice"
    },
    {
      "x": -37,
      "y": 73,
      "z": 9,
      "name": "Rock_Ice"
    },
    {
      "x": -37,
      "y": 74,
      "z": 9,
      "name": "Soil_Snow"
    },
    {
      "x": -37,
      "y": 66,
      "z": 10,
      "name": "Rock_Ice"
    },
    {
      "x": -37,
      "y": 67,
      "z": 10,
      "name": "Rock_Ice"
    },
    {
      "x": -37,
      "y": 68,
      "z": 10,
      "name": "Rock_Ice"
    },
    {
      "x": -37,
      "y": 69,
      "z": 10,
      "name": "Rock_Ice"
    },
    {
      "x": -37,
      "y": 70,
      "z": 10,
      "name": "Rock_Ice"
    },
    {
      "x": -37,
      "y": 71,
      "z": 10,
      "name": "Rock_Ice"
    },
    {
      "x": -37,
      "y": 72,
      "z": 10,
      "name": "Rock_Ice"
    },
    {
      "x": -37,
      "y": 73,
      "z": 10,
      "name": "Rock_Ice"
    },
    {
      "x": -37,
      "y": 74,
      "z": 10,
      "name": "Soil_Snow"
    },
    {
      "x": -37,
      "y": 65,
      "z": 11,
      "name": "Rock_Ice"
    },
    {
      "x": -37,
      "y": 66,
      "z": 11,
      "name": "Rock_Ice"
    },
    {
      "x": -37,
      "y": 67,
      "z": 11,
      "name": "Rock_Ice"
    },
    {
      "x": -37,
      "y": 68,
      "z": 11,
      "name": "Rock_Ice"
    },
    {
      "x": -37,
      "y": 69,
      "z": 11,
      "name": "Rock_Ice"
    },
    {
      "x": -37,
      "y": 70,
      "z": 11,
      "name": "Rock_Ice"
    },
    {
      "x": -37,
      "y": 71,
      "z": 11,
      "name": "Rock_Ice"
    },
    {
      "x": -37,
      "y": 72,
      "z": 11,
      "name": "Rock_Ice"
    },
    {
      "x": -37,
      "y": 73,
      "z": 11,
      "name": "Rock_Ice"
    },
    {
      "x": -37,
      "y": 74,
      "z": 11,
      "name": "Soil_Snow"
    },
    {
      "x": -37,
      "y": 66,
      "z": 12,
      "name": "Rock_Ice"
    },
    {
      "x": -37,
      "y": 67,
      "z": 12,
      "name": "Rock_Ice"
    },
    {
      "x": -37,
      "y": 68,
      "z": 12,
      "name": "Rock_Ice"
    },
    {
      "x": -37,
      "y": 69,
      "z": 12,
      "name": "Rock_Ice"
    },
    {
      "x": -37,
      "y": 70,
      "z": 12,
      "name": "Rock_Ice"
    },
    {
      "x": -37,
      "y": 71,
      "z": 12,
      "name": "Rock_Ice"
    },
    {
      "x": -37,
      "y": 72,
      "z": 12,
      "name": "Rock_Ice"
    },
    {
      "x": -37,
      "y": 73,
      "z": 12,
      "name": "Rock_Ice"
    },
    {
      "x": -37,
      "y": 74,
      "z": 12,
      "name": "Soil_Snow"
    },
    {
      "x": -37,
      "y": 68,
      "z": 13,
      "name": "Rock_Ice"
    },
    {
      "x": -37,
      "y": 69,
      "z": 13,
      "name": "Rock_Ice"
    },
    {
      "x": -37,
      "y": 70,
      "z": 13,
      "name": "Rock_Ice"
    },
    {
      "x": -37,
      "y": 71,
      "z": 13,
      "name": "Rock_Ice"
    },
    {
      "x": -37,
      "y": 72,
      "z": 13,
      "name": "Rock_Ice"
    },
    {
      "x": -37,
      "y": 70,
      "z": 14,
      "name": "Rock_Ice"
    },
    {
      "x": -37,
      "y": 71,
      "z": 14,
      "name": "Soil_Snow"
    },
    {
      "x": -37,
      "y": 67,
      "z": 15,
      "name": "Rock_Ice"
    },
    {
      "x": -37,
      "y": 68,
      "z": 15,
      "name": "Rock_Ice"
    },
    {
      "x": -37,
      "y": 69,
      "z": 15,
      "name": "Rock_Ice"
    },
    {
      "x": -37,
      "y": 70,
      "z": 15,
      "name": "Rock_Ice"
    },
    {
      "x": -37,
      "y": 71,
      "z": 15,
      "name": "Rock_Ice"
    },
    {
      "x": -37,
      "y": 72,
      "z": 15,
      "name": "Rock_Ice"
    },
    {
      "x": -37,
      "y": 66,
      "z": 16,
      "name": "Rock_Ice"
    },
    {
      "x": -37,
      "y": 67,
      "z": 16,
      "name": "Rock_Ice"
    },
    {
      "x": -37,
      "y": 68,
      "z": 16,
      "name": "Rock_Ice"
    },
    {
      "x": -37,
      "y": 69,
      "z": 16,
      "name": "Rock_Ice"
    },
    {
      "x": -37,
      "y": 70,
      "z": 16,
      "name": "Rock_Ice"
    },
    {
      "x": -37,
      "y": 71,
      "z": 16,
      "name": "Rock_Ice"
    },
    {
      "x": -37,
      "y": 72,
      "z": 16,
      "name": "Rock_Ice"
    },
    {
      "x": -37,
      "y": 73,
      "z": 16,
      "name": "Rock_Ice"
    },
    {
      "x": -37,
      "y": 66,
      "z": 17,
      "name": "Rock_Ice"
    },
    {
      "x": -37,
      "y": 67,
      "z": 17,
      "name": "Rock_Ice"
    },
    {
      "x": -37,
      "y": 68,
      "z": 17,
      "name": "Rock_Ice"
    },
    {
      "x": -37,
      "y": 69,
      "z": 17,
      "name": "Rock_Ice"
    },
    {
      "x": -37,
      "y": 70,
      "z": 17,
      "name": "Rock_Ice"
    },
    {
      "x": -37,
      "y": 71,
      "z": 17,
      "name": "Rock_Ice"
    },
    {
      "x": -37,
      "y": 72,
      "z": 17,
      "name": "Rock_Ice"
    },
    {
      "x": -37,
      "y": 73,
      "z": 17,
      "name": "Soil_Snow"
    },
    {
      "x": -37,
      "y": 67,
      "z": 18,
      "name": "Rock_Ice_Permafrost"
    },
    {
      "x": -37,
      "y": 68,
      "z": 18,
      "name": "Rock_Ice"
    },
    {
      "x": -37,
      "y": 69,
      "z": 18,
      "name": "Rock_Ice"
    },
    {
      "x": -37,
      "y": 70,
      "z": 18,
      "name": "Rock_Ice"
    },
    {
      "x": -37,
      "y": 71,
      "z": 18,
      "name": "Rock_Ice"
    },
    {
      "x": -37,
      "y": 72,
      "z": 18,
      "name": "Rock_Ice"
    },
    {
      "x": -37,
      "y": 73,
      "z": 18,
      "name": "Rock_Ice"
    },
    {
      "x": -37,
      "y": 67,
      "z": 19,
      "name": "Rock_Ice_Permafrost"
    },
    {
      "x": -37,
      "y": 68,
      "z": 19,
      "name": "Rock_Ice_Permafrost"
    },
    {
      "x": -37,
      "y": 69,
      "z": 19,
      "name": "Rock_Ice_Permafrost"
    },
    {
      "x": -37,
      "y": 70,
      "z": 19,
      "name": "Rock_Ice_Permafrost"
    },
    {
      "x": -37,
      "y": 71,
      "z": 19,
      "name": "Rock_Ice"
    },
    {
      "x": -37,
      "y": 72,
      "z": 19,
      "name": "Soil_Snow"
    },
    {
      "x": -37,
      "y": 68,
      "z": 20,
      "name": "Rock_Ice_Permafrost"
    },
    {
      "x": -37,
      "y": 69,
      "z": 20,
      "name": "Rock_Ice_Permafrost"
    },
    {
      "x": -37,
      "y": 70,
      "z": 20,
      "name": "Rock_Ice_Permafrost"
    },
    {
      "x": -37,
      "y": 71,
      "z": 20,
      "name": "Rock_Ice"
    },
    {
      "x": -37,
      "y": 72,
      "z": 20,
      "name": "Soil_Snow"
    },
    {
      "x": -37,
      "y": 70,
      "z": 21,
      "name": "Rock_Ice_Permafrost"
    },
    {
      "x": -37,
      "y": 71,
      "z": 21,
      "name": "Rock_Ice_Permafrost"
    },
    {
      "x": -36,
      "y": 54,
      "z": -11,
      "name": "Rock_Ice"
    },
    {
      "x": -36,
      "y": 55,
      "z": -11,
      "name": "Rock_Ice"
    },
    {
      "x": -36,
      "y": 56,
      "z": -11,
      "name": "Soil_Snow"
    },
    {
      "x": -36,
      "y": 52,
      "z": -10,
      "name": "Rock_Ice"
    },
    {
      "x": -36,
      "y": 53,
      "z": -10,
      "name": "Rock_Ice"
    },
    {
      "x": -36,
      "y": 54,
      "z": -10,
      "name": "Rock_Ice"
    },
    {
      "x": -36,
      "y": 55,
      "z": -10,
      "name": "Rock_Ice"
    },
    {
      "x": -36,
      "y": 56,
      "z": -10,
      "name": "Rock_Ice"
    },
    {
      "x": -36,
      "y": 57,
      "z": -10,
      "name": "Rock_Ice"
    },
    {
      "x": -36,
      "y": 58,
      "z": -10,
      "name": "Soil_Snow"
    },
    {
      "x": -36,
      "y": 50,
      "z": -9,
      "name": "Rock_Ice_Permafrost"
    },
    {
      "x": -36,
      "y": 51,
      "z": -9,
      "name": "Rock_Ice"
    },
    {
      "x": -36,
      "y": 52,
      "z": -9,
      "name": "Rock_Ice"
    },
    {
      "x": -36,
      "y": 53,
      "z": -9,
      "name": "Rock_Ice"
    },
    {
      "x": -36,
      "y": 54,
      "z": -9,
      "name": "Rock_Ice"
    },
    {
      "x": -36,
      "y": 55,
      "z": -9,
      "name": "Rock_Ice"
    },
    {
      "x": -36,
      "y": 56,
      "z": -9,
      "name": "Rock_Ice"
    },
    {
      "x": -36,
      "y": 57,
      "z": -9,
      "name": "Soil_Snow"
    },
    {
      "x": -36,
      "y": 49,
      "z": -8,
      "name": "Rock_Ice_Permafrost"
    },
    {
      "x": -36,
      "y": 50,
      "z": -8,
      "name": "Rock_Ice_Permafrost"
    },
    {
      "x": -36,
      "y": 51,
      "z": -8,
      "name": "Rock_Ice_Permafrost"
    },
    {
      "x": -36,
      "y": 52,
      "z": -8,
      "name": "Rock_Ice_Permafrost"
    },
    {
      "x": -36,
      "y": 53,
      "z": -8,
      "name": "Rock_Ice_Permafrost"
    },
    {
      "x": -36,
      "y": 54,
      "z": -8,
      "name": "Rock_Ice"
    },
    {
      "x": -36,
      "y": 55,
      "z": -8,
      "name": "Rock_Ice"
    },
    {
      "x": -36,
      "y": 56,
      "z": -8,
      "name": "Rock_Ice"
    },
    {
      "x": -36,
      "y": 57,
      "z": -8,
      "name": "Soil_Snow"
    },
    {
      "x": -36,
      "y": 49,
      "z": -7,
      "name": "Rock_Ice_Permafrost"
    },
    {
      "x": -36,
      "y": 50,
      "z": -7,
      "name": "Rock_Ice_Permafrost"
    },
    {
      "x": -36,
      "y": 51,
      "z": -7,
      "name": "Rock_Ice_Permafrost"
    },
    {
      "x": -36,
      "y": 52,
      "z": -7,
      "name": "Rock_Ice_Permafrost"
    },
    {
      "x": -36,
      "y": 53,
      "z": -7,
      "name": "Rock_Ice_Permafrost"
    },
    {
      "x": -36,
      "y": 54,
      "z": -7,
      "name": "Rock_Ice_Permafrost"
    },
    {
      "x": -36,
      "y": 55,
      "z": -7,
      "name": "Rock_Ice"
    },
    {
      "x": -36,
      "y": 56,
      "z": -7,
      "name": "Soil_Snow"
    },
    {
      "x": -36,
      "y": 49,
      "z": -6,
      "name": "Rock_Ice_Permafrost"
    },
    {
      "x": -36,
      "y": 50,
      "z": -6,
      "name": "Rock_Ice"
    },
    {
      "x": -36,
      "y": 51,
      "z": -6,
      "name": "Rock_Ice_Permafrost"
    },
    {
      "x": -36,
      "y": 52,
      "z": -6,
      "name": "Rock_Ice"
    },
    {
      "x": -36,
      "y": 53,
      "z": -6,
      "name": "Rock_Ice"
    },
    {
      "x": -36,
      "y": 54,
      "z": -6,
      "name": "Rock_Ice_Permafrost"
    },
    {
      "x": -36,
      "y": 55,
      "z": -6,
      "name": "Rock_Ice"
    },
    {
      "x": -36,
      "y": 56,
      "z": -6,
      "name": "Soil_Snow"
    },
    {
      "x": -36,
      "y": 49,
      "z": -5,
      "name": "Rock_Ice"
    },
    {
      "x": -36,
      "y": 50,
      "z": -5,
      "name": "Rock_Ice"
    },
    {
      "x": -36,
      "y": 51,
      "z": -5,
      "name": "Rock_Ice"
    },
    {
      "x": -36,
      "y": 52,
      "z": -5,
      "name": "Rock_Ice"
    },
    {
      "x": -36,
      "y": 53,
      "z": -5,
      "name": "Rock_Ice"
    },
    {
      "x": -36,
      "y": 54,
      "z": -5,
      "name": "Rock_Ice"
    },
    {
      "x": -36,
      "y": 55,
      "z": -5,
      "name": "Rock_Ice"
    },
    {
      "x": -36,
      "y": 49,
      "z": -4,
      "name": "Rock_Ice"
    },
    {
      "x": -36,
      "y": 50,
      "z": -4,
      "name": "Rock_Ice"
    },
    {
      "x": -36,
      "y": 51,
      "z": -4,
      "name": "Rock_Ice"
    },
    {
      "x": -36,
      "y": 52,
      "z": -4,
      "name": "Rock_Ice"
    },
    {
      "x": -36,
      "y": 53,
      "z": -4,
      "name": "Rock_Ice"
    },
    {
      "x": -36,
      "y": 54,
      "z": -4,
      "name": "Rock_Ice"
    },
    {
      "x": -36,
      "y": 55,
      "z": -4,
      "name": "Rock_Ice"
    },
    {
      "x": -36,
      "y": 49,
      "z": -3,
      "name": "Rock_Ice"
    },
    {
      "x": -36,
      "y": 50,
      "z": -3,
      "name": "Rock_Ice"
    },
    {
      "x": -36,
      "y": 51,
      "z": -3,
      "name": "Rock_Ice"
    },
    {
      "x": -36,
      "y": 52,
      "z": -3,
      "name": "Rock_Ice"
    },
    {
      "x": -36,
      "y": 53,
      "z": -3,
      "name": "Rock_Ice"
    },
    {
      "x": -36,
      "y": 54,
      "z": -3,
      "name": "Rock_Ice"
    },
    {
      "x": -36,
      "y": 69,
      "z": -3,
      "name": "Rock_Ice"
    },
    {
      "x": -36,
      "y": 70,
      "z": -3,
      "name": "Rock_Ice"
    },
    {
      "x": -36,
      "y": 49,
      "z": -2,
      "name": "Rock_Ice"
    },
    {
      "x": -36,
      "y": 50,
      "z": -2,
      "name": "Rock_Ice"
    },
    {
      "x": -36,
      "y": 51,
      "z": -2,
      "name": "Rock_Ice"
    },
    {
      "x": -36,
      "y": 52,
      "z": -2,
      "name": "Rock_Ice"
    },
    {
      "x": -36,
      "y": 53,
      "z": -2,
      "name": "Rock_Ice"
    },
    {
      "x": -36,
      "y": 69,
      "z": -2,
      "name": "Rock_Ice_Permafrost"
    },
    {
      "x": -36,
      "y": 70,
      "z": -2,
      "name": "Rock_Ice"
    },
    {
      "x": -36,
      "y": 71,
      "z": -2,
      "name": "Rock_Ice"
    },
    {
      "x": -36,
      "y": 49,
      "z": -1,
      "name": "Rock_Ice"
    },
    {
      "x": -36,
      "y": 50,
      "z": -1,
      "name": "Rock_Ice"
    },
    {
      "x": -36,
      "y": 51,
      "z": -1,
      "name": "Rock_Ice"
    },
    {
      "x": -36,
      "y": 52,
      "z": -1,
      "name": "Rock_Ice"
    },
    {
      "x": -36,
      "y": 53,
      "z": -1,
      "name": "Rock_Ice"
    },
    {
      "x": -36,
      "y": 69,
      "z": -1,
      "name": "Rock_Ice"
    },
    {
      "x": -36,
      "y": 70,
      "z": -1,
      "name": "Rock_Ice_Permafrost"
    },
    {
      "x": -36,
      "y": 71,
      "z": -1,
      "name": "Rock_Ice_Permafrost"
    },
    {
      "x": -36,
      "y": 72,
      "z": -1,
      "name": "Rock_Ice"
    },
    {
      "x": -36,
      "y": 73,
      "z": -1,
      "name": "Rock_Ice"
    },
    {
      "x": -36,
      "y": 49,
      "z": 0,
      "name": "Rock_Ice"
    },
    {
      "x": -36,
      "y": 50,
      "z": 0,
      "name": "Rock_Ice"
    },
    {
      "x": -36,
      "y": 51,
      "z": 0,
      "name": "Rock_Ice"
    },
    {
      "x": -36,
      "y": 52,
      "z": 0,
      "name": "Rock_Ice"
    },
    {
      "x": -36,
      "y": 53,
      "z": 0,
      "name": "Rock_Ice"
    },
    {
      "x": -36,
      "y": 68,
      "z": 0,
      "name": "Rock_Ice"
    },
    {
      "x": -36,
      "y": 69,
      "z": 0,
      "name": "Rock_Ice"
    },
    {
      "x": -36,
      "y": 70,
      "z": 0,
      "name": "Rock_Ice"
    },
    {
      "x": -36,
      "y": 71,
      "z": 0,
      "name": "Rock_Ice"
    },
    {
      "x": -36,
      "y": 72,
      "z": 0,
      "name": "Rock_Ice"
    },
    {
      "x": -36,
      "y": 73,
      "z": 0,
      "name": "Soil_Snow"
    },
    {
      "x": -36,
      "y": 49,
      "z": 1,
      "name": "Rock_Ice"
    },
    {
      "x": -36,
      "y": 50,
      "z": 1,
      "name": "Rock_Ice"
    },
    {
      "x": -36,
      "y": 51,
      "z": 1,
      "name": "Rock_Ice"
    },
    {
      "x": -36,
      "y": 52,
      "z": 1,
      "name": "Rock_Ice"
    },
    {
      "x": -36,
      "y": 53,
      "z": 1,
      "name": "Rock_Ice"
    },
    {
      "x": -36,
      "y": 68,
      "z": 1,
      "name": "Rock_Ice"
    },
    {
      "x": -36,
      "y": 69,
      "z": 1,
      "name": "Rock_Ice"
    },
    {
      "x": -36,
      "y": 70,
      "z": 1,
      "name": "Rock_Ice"
    },
    {
      "x": -36,
      "y": 71,
      "z": 1,
      "name": "Rock_Ice"
    },
    {
      "x": -36,
      "y": 72,
      "z": 1,
      "name": "Rock_Ice"
    },
    {
      "x": -36,
      "y": 73,
      "z": 1,
      "name": "Rock_Ice"
    },
    {
      "x": -36,
      "y": 74,
      "z": 1,
      "name": "Soil_Snow"
    },
    {
      "x": -36,
      "y": 49,
      "z": 2,
      "name": "Rock_Ice"
    },
    {
      "x": -36,
      "y": 50,
      "z": 2,
      "name": "Rock_Ice"
    },
    {
      "x": -36,
      "y": 51,
      "z": 2,
      "name": "Rock_Ice"
    },
    {
      "x": -36,
      "y": 52,
      "z": 2,
      "name": "Rock_Ice"
    },
    {
      "x": -36,
      "y": 53,
      "z": 2,
      "name": "Rock_Ice"
    },
    {
      "x": -36,
      "y": 67,
      "z": 2,
      "name": "Rock_Ice"
    },
    {
      "x": -36,
      "y": 68,
      "z": 2,
      "name": "Rock_Ice"
    },
    {
      "x": -36,
      "y": 69,
      "z": 2,
      "name": "Rock_Ice"
    },
    {
      "x": -36,
      "y": 70,
      "z": 2,
      "name": "Rock_Ice"
    },
    {
      "x": -36,
      "y": 71,
      "z": 2,
      "name": "Rock_Ice"
    },
    {
      "x": -36,
      "y": 72,
      "z": 2,
      "name": "Rock_Ice"
    },
    {
      "x": -36,
      "y": 73,
      "z": 2,
      "name": "Rock_Ice"
    },
    {
      "x": -36,
      "y": 74,
      "z": 2,
      "name": "Rock_Ice"
    },
    {
      "x": -36,
      "y": 75,
      "z": 2,
      "name": "Soil_Snow"
    },
    {
      "x": -36,
      "y": 49,
      "z": 3,
      "name": "Rock_Ice"
    },
    {
      "x": -36,
      "y": 50,
      "z": 3,
      "name": "Rock_Ice"
    },
    {
      "x": -36,
      "y": 51,
      "z": 3,
      "name": "Rock_Ice"
    },
    {
      "x": -36,
      "y": 52,
      "z": 3,
      "name": "Rock_Ice"
    },
    {
      "x": -36,
      "y": 53,
      "z": 3,
      "name": "Rock_Ice"
    },
    {
      "x": -36,
      "y": 54,
      "z": 3,
      "name": "Rock_Ice"
    },
    {
      "x": -36,
      "y": 66,
      "z": 3,
      "name": "Rock_Ice"
    },
    {
      "x": -36,
      "y": 67,
      "z": 3,
      "name": "Rock_Ice"
    },
    {
      "x": -36,
      "y": 68,
      "z": 3,
      "name": "Rock_Ice"
    },
    {
      "x": -36,
      "y": 69,
      "z": 3,
      "name": "Rock_Ice"
    },
    {
      "x": -36,
      "y": 70,
      "z": 3,
      "name": "Rock_Ice"
    },
    {
      "x": -36,
      "y": 71,
      "z": 3,
      "name": "Rock_Ice"
    },
    {
      "x": -36,
      "y": 72,
      "z": 3,
      "name": "Rock_Ice"
    },
    {
      "x": -36,
      "y": 73,
      "z": 3,
      "name": "Rock_Ice"
    },
    {
      "x": -36,
      "y": 74,
      "z": 3,
      "name": "Rock_Ice"
    },
    {
      "x": -36,
      "y": 75,
      "z": 3,
      "name": "Soil_Snow"
    },
    {
      "x": -36,
      "y": 49,
      "z": 4,
      "name": "Rock_Ice"
    },
    {
      "x": -36,
      "y": 50,
      "z": 4,
      "name": "Rock_Ice"
    },
    {
      "x": -36,
      "y": 51,
      "z": 4,
      "name": "Rock_Ice"
    },
    {
      "x": -36,
      "y": 52,
      "z": 4,
      "name": "Rock_Ice"
    },
    {
      "x": -36,
      "y": 53,
      "z": 4,
      "name": "Rock_Ice"
    },
    {
      "x": -36,
      "y": 54,
      "z": 4,
      "name": "Rock_Ice"
    },
    {
      "x": -36,
      "y": 55,
      "z": 4,
      "name": "Rock_Ice"
    },
    {
      "x": -36,
      "y": 66,
      "z": 4,
      "name": "Rock_Ice"
    },
    {
      "x": -36,
      "y": 67,
      "z": 4,
      "name": "Rock_Ice"
    },
    {
      "x": -36,
      "y": 68,
      "z": 4,
      "name": "Rock_Ice"
    },
    {
      "x": -36,
      "y": 69,
      "z": 4,
      "name": "Rock_Ice"
    },
    {
      "x": -36,
      "y": 70,
      "z": 4,
      "name": "Rock_Ice"
    },
    {
      "x": -36,
      "y": 71,
      "z": 4,
      "name": "Rock_Ice"
    },
    {
      "x": -36,
      "y": 72,
      "z": 4,
      "name": "Rock_Ice"
    },
    {
      "x": -36,
      "y": 73,
      "z": 4,
      "name": "Rock_Ice"
    },
    {
      "x": -36,
      "y": 74,
      "z": 4,
      "name": "Rock_Ice"
    },
    {
      "x": -36,
      "y": 75,
      "z": 4,
      "name": "Soil_Snow"
    },
    {
      "x": -36,
      "y": 48,
      "z": 5,
      "name": "Rock_Ice"
    },
    {
      "x": -36,
      "y": 49,
      "z": 5,
      "name": "Rock_Ice"
    },
    {
      "x": -36,
      "y": 50,
      "z": 5,
      "name": "Rock_Ice"
    },
    {
      "x": -36,
      "y": 51,
      "z": 5,
      "name": "Rock_Ice"
    },
    {
      "x": -36,
      "y": 52,
      "z": 5,
      "name": "Rock_Ice"
    },
    {
      "x": -36,
      "y": 53,
      "z": 5,
      "name": "Rock_Ice"
    },
    {
      "x": -36,
      "y": 54,
      "z": 5,
      "name": "Rock_Ice"
    },
    {
      "x": -36,
      "y": 55,
      "z": 5,
      "name": "Rock_Ice"
    },
    {
      "x": -36,
      "y": 56,
      "z": 5,
      "name": "Rock_Ice"
    },
    {
      "x": -36,
      "y": 65,
      "z": 5,
      "name": "Rock_Ice"
    },
    {
      "x": -36,
      "y": 66,
      "z": 5,
      "name": "Rock_Ice"
    },
    {
      "x": -36,
      "y": 67,
      "z": 5,
      "name": "Rock_Ice"
    },
    {
      "x": -36,
      "y": 68,
      "z": 5,
      "name": "Rock_Ice"
    },
    {
      "x": -36,
      "y": 69,
      "z": 5,
      "name": "Rock_Ice"
    },
    {
      "x": -36,
      "y": 70,
      "z": 5,
      "name": "Rock_Ice"
    },
    {
      "x": -36,
      "y": 71,
      "z": 5,
      "name": "Rock_Ice"
    },
    {
      "x": -36,
      "y": 72,
      "z": 5,
      "name": "Rock_Ice"
    },
    {
      "x": -36,
      "y": 73,
      "z": 5,
      "name": "Rock_Ice"
    },
    {
      "x": -36,
      "y": 74,
      "z": 5,
      "name": "Rock_Ice"
    },
    {
      "x": -36,
      "y": 75,
      "z": 5,
      "name": "Soil_Snow"
    },
    {
      "x": -36,
      "y": 48,
      "z": 6,
      "name": "Rock_Ice_Permafrost"
    },
    {
      "x": -36,
      "y": 49,
      "z": 6,
      "name": "Rock_Ice"
    },
    {
      "x": -36,
      "y": 50,
      "z": 6,
      "name": "Rock_Ice"
    },
    {
      "x": -36,
      "y": 51,
      "z": 6,
      "name": "Rock_Ice"
    },
    {
      "x": -36,
      "y": 52,
      "z": 6,
      "name": "Rock_Ice"
    },
    {
      "x": -36,
      "y": 53,
      "z": 6,
      "name": "Rock_Ice"
    },
    {
      "x": -36,
      "y": 54,
      "z": 6,
      "name": "Rock_Ice"
    },
    {
      "x": -36,
      "y": 55,
      "z": 6,
      "name": "Rock_Ice"
    },
    {
      "x": -36,
      "y": 56,
      "z": 6,
      "name": "Rock_Ice"
    },
    {
      "x": -36,
      "y": 57,
      "z": 6,
      "name": "Rock_Ice"
    },
    {
      "x": -36,
      "y": 58,
      "z": 6,
      "name": "Rock_Ice"
    },
    {
      "x": -36,
      "y": 59,
      "z": 6,
      "name": "Rock_Ice"
    },
    {
      "x": -36,
      "y": 60,
      "z": 6,
      "name": "Rock_Ice"
    },
    {
      "x": -36,
      "y": 61,
      "z": 6,
      "name": "Rock_Ice"
    },
    {
      "x": -36,
      "y": 62,
      "z": 6,
      "name": "Rock_Ice"
    },
    {
      "x": -36,
      "y": 63,
      "z": 6,
      "name": "Rock_Ice"
    },
    {
      "x": -36,
      "y": 64,
      "z": 6,
      "name": "Rock_Ice"
    },
    {
      "x": -36,
      "y": 65,
      "z": 6,
      "name": "Rock_Ice"
    },
    {
      "x": -36,
      "y": 66,
      "z": 6,
      "name": "Rock_Ice"
    },
    {
      "x": -36,
      "y": 67,
      "z": 6,
      "name": "Rock_Ice"
    },
    {
      "x": -36,
      "y": 68,
      "z": 6,
      "name": "Rock_Ice"
    },
    {
      "x": -36,
      "y": 69,
      "z": 6,
      "name": "Rock_Ice"
    },
    {
      "x": -36,
      "y": 70,
      "z": 6,
      "name": "Rock_Ice"
    },
    {
      "x": -36,
      "y": 71,
      "z": 6,
      "name": "Rock_Ice"
    },
    {
      "x": -36,
      "y": 72,
      "z": 6,
      "name": "Rock_Ice"
    },
    {
      "x": -36,
      "y": 73,
      "z": 6,
      "name": "Rock_Ice"
    },
    {
      "x": -36,
      "y": 74,
      "z": 6,
      "name": "Rock_Ice"
    },
    {
      "x": -36,
      "y": 75,
      "z": 6,
      "name": "Soil_Snow"
    },
    {
      "x": -36,
      "y": 49,
      "z": 7,
      "name": "Rock_Ice"
    },
    {
      "x": -36,
      "y": 50,
      "z": 7,
      "name": "Rock_Ice"
    },
    {
      "x": -36,
      "y": 51,
      "z": 7,
      "name": "Rock_Ice"
    },
    {
      "x": -36,
      "y": 52,
      "z": 7,
      "name": "Rock_Ice"
    },
    {
      "x": -36,
      "y": 53,
      "z": 7,
      "name": "Rock_Ice"
    },
    {
      "x": -36,
      "y": 54,
      "z": 7,
      "name": "Rock_Ice"
    },
    {
      "x": -36,
      "y": 55,
      "z": 7,
      "name": "Rock_Ice"
    },
    {
      "x": -36,
      "y": 56,
      "z": 7,
      "name": "Rock_Ice"
    },
    {
      "x": -36,
      "y": 57,
      "z": 7,
      "name": "Rock_Ice"
    },
    {
      "x": -36,
      "y": 58,
      "z": 7,
      "name": "Rock_Ice"
    },
    {
      "x": -36,
      "y": 59,
      "z": 7,
      "name": "Rock_Ice"
    },
    {
      "x": -36,
      "y": 60,
      "z": 7,
      "name": "Rock_Ice"
    },
    {
      "x": -36,
      "y": 61,
      "z": 7,
      "name": "Rock_Ice"
    },
    {
      "x": -36,
      "y": 62,
      "z": 7,
      "name": "Rock_Ice"
    },
    {
      "x": -36,
      "y": 63,
      "z": 7,
      "name": "Rock_Ice"
    },
    {
      "x": -36,
      "y": 64,
      "z": 7,
      "name": "Rock_Ice"
    },
    {
      "x": -36,
      "y": 65,
      "z": 7,
      "name": "Rock_Ice"
    },
    {
      "x": -36,
      "y": 66,
      "z": 7,
      "name": "Rock_Ice"
    },
    {
      "x": -36,
      "y": 67,
      "z": 7,
      "name": "Rock_Ice"
    },
    {
      "x": -36,
      "y": 68,
      "z": 7,
      "name": "Rock_Ice"
    },
    {
      "x": -36,
      "y": 69,
      "z": 7,
      "name": "Rock_Ice"
    },
    {
      "x": -36,
      "y": 70,
      "z": 7,
      "name": "Rock_Ice"
    },
    {
      "x": -36,
      "y": 71,
      "z": 7,
      "name": "Rock_Ice"
    },
    {
      "x": -36,
      "y": 72,
      "z": 7,
      "name": "Rock_Ice"
    },
    {
      "x": -36,
      "y": 73,
      "z": 7,
      "name": "Rock_Ice"
    },
    {
      "x": -36,
      "y": 74,
      "z": 7,
      "name": "Rock_Ice"
    },
    {
      "x": -36,
      "y": 75,
      "z": 7,
      "name": "Soil_Snow"
    },
    {
      "x": -36,
      "y": 50,
      "z": 8,
      "name": "Rock_Ice"
    },
    {
      "x": -36,
      "y": 51,
      "z": 8,
      "name": "Rock_Ice_Permafrost"
    },
    {
      "x": -36,
      "y": 52,
      "z": 8,
      "name": "Rock_Ice"
    },
    {
      "x": -36,
      "y": 53,
      "z": 8,
      "name": "Rock_Ice"
    },
    {
      "x": -36,
      "y": 54,
      "z": 8,
      "name": "Rock_Ice"
    },
    {
      "x": -36,
      "y": 55,
      "z": 8,
      "name": "Rock_Ice"
    },
    {
      "x": -36,
      "y": 56,
      "z": 8,
      "name": "Rock_Ice"
    },
    {
      "x": -36,
      "y": 57,
      "z": 8,
      "name": "Rock_Ice"
    },
    {
      "x": -36,
      "y": 58,
      "z": 8,
      "name": "Rock_Ice"
    },
    {
      "x": -36,
      "y": 59,
      "z": 8,
      "name": "Rock_Ice"
    },
    {
      "x": -36,
      "y": 60,
      "z": 8,
      "name": "Rock_Ice"
    },
    {
      "x": -36,
      "y": 61,
      "z": 8,
      "name": "Rock_Ice"
    },
    {
      "x": -36,
      "y": 62,
      "z": 8,
      "name": "Rock_Ice"
    },
    {
      "x": -36,
      "y": 63,
      "z": 8,
      "name": "Rock_Ice"
    },
    {
      "x": -36,
      "y": 64,
      "z": 8,
      "name": "Rock_Ice"
    },
    {
      "x": -36,
      "y": 65,
      "z": 8,
      "name": "Rock_Ice"
    },
    {
      "x": -36,
      "y": 66,
      "z": 8,
      "name": "Rock_Ice"
    },
    {
      "x": -36,
      "y": 67,
      "z": 8,
      "name": "Rock_Ice"
    },
    {
      "x": -36,
      "y": 68,
      "z": 8,
      "name": "Rock_Ice"
    },
    {
      "x": -36,
      "y": 69,
      "z": 8,
      "name": "Rock_Ice"
    },
    {
      "x": -36,
      "y": 70,
      "z": 8,
      "name": "Rock_Ice"
    },
    {
      "x": -36,
      "y": 71,
      "z": 8,
      "name": "Rock_Ice"
    },
    {
      "x": -36,
      "y": 72,
      "z": 8,
      "name": "Rock_Ice"
    },
    {
      "x": -36,
      "y": 73,
      "z": 8,
      "name": "Rock_Ice"
    },
    {
      "x": -36,
      "y": 74,
      "z": 8,
      "name": "Rock_Ice"
    },
    {
      "x": -36,
      "y": 75,
      "z": 8,
      "name": "Soil_Snow"
    },
    {
      "x": -36,
      "y": 51,
      "z": 9,
      "name": "Rock_Ice_Permafrost"
    },
    {
      "x": -36,
      "y": 52,
      "z": 9,
      "name": "Rock_Ice_Permafrost"
    },
    {
      "x": -36,
      "y": 53,
      "z": 9,
      "name": "Rock_Ice_Permafrost"
    },
    {
      "x": -36,
      "y": 54,
      "z": 9,
      "name": "Rock_Ice"
    },
    {
      "x": -36,
      "y": 55,
      "z": 9,
      "name": "Rock_Ice"
    },
    {
      "x": -36,
      "y": 56,
      "z": 9,
      "name": "Rock_Ice"
    },
    {
      "x": -36,
      "y": 57,
      "z": 9,
      "name": "Rock_Ice"
    },
    {
      "x": -36,
      "y": 58,
      "z": 9,
      "name": "Rock_Ice"
    },
    {
      "x": -36,
      "y": 59,
      "z": 9,
      "name": "Rock_Ice"
    },
    {
      "x": -36,
      "y": 60,
      "z": 9,
      "name": "Rock_Ice"
    },
    {
      "x": -36,
      "y": 61,
      "z": 9,
      "name": "Rock_Ice"
    },
    {
      "x": -36,
      "y": 62,
      "z": 9,
      "name": "Rock_Ice"
    },
    {
      "x": -36,
      "y": 63,
      "z": 9,
      "name": "Rock_Ice"
    },
    {
      "x": -36,
      "y": 64,
      "z": 9,
      "name": "Rock_Ice"
    },
    {
      "x": -36,
      "y": 65,
      "z": 9,
      "name": "Rock_Ice"
    },
    {
      "x": -36,
      "y": 66,
      "z": 9,
      "name": "Rock_Ice"
    },
    {
      "x": -36,
      "y": 67,
      "z": 9,
      "name": "Rock_Ice"
    },
    {
      "x": -36,
      "y": 68,
      "z": 9,
      "name": "Rock_Ice"
    },
    {
      "x": -36,
      "y": 69,
      "z": 9,
      "name": "Rock_Ice"
    },
    {
      "x": -36,
      "y": 70,
      "z": 9,
      "name": "Rock_Ice"
    },
    {
      "x": -36,
      "y": 71,
      "z": 9,
      "name": "Rock_Ice"
    },
    {
      "x": -36,
      "y": 72,
      "z": 9,
      "name": "Rock_Ice"
    },
    {
      "x": -36,
      "y": 73,
      "z": 9,
      "name": "Rock_Ice"
    },
    {
      "x": -36,
      "y": 74,
      "z": 9,
      "name": "Rock_Ice"
    },
    {
      "x": -36,
      "y": 75,
      "z": 9,
      "name": "Soil_Snow"
    },
    {
      "x": -36,
      "y": 52,
      "z": 10,
      "name": "Rock_Ice_Permafrost"
    },
    {
      "x": -36,
      "y": 53,
      "z": 10,
      "name": "Rock_Ice_Permafrost"
    },
    {
      "x": -36,
      "y": 54,
      "z": 10,
      "name": "Rock_Ice"
    },
    {
      "x": -36,
      "y": 55,
      "z": 10,
      "name": "Rock_Ice_Permafrost"
    },
    {
      "x": -36,
      "y": 56,
      "z": 10,
      "name": "Rock_Ice"
    },
    {
      "x": -36,
      "y": 57,
      "z": 10,
      "name": "Rock_Ice"
    },
    {
      "x": -36,
      "y": 58,
      "z": 10,
      "name": "Rock_Ice"
    },
    {
      "x": -36,
      "y": 59,
      "z": 10,
      "name": "Rock_Ice"
    },
    {
      "x": -36,
      "y": 60,
      "z": 10,
      "name": "Rock_Ice"
    },
    {
      "x": -36,
      "y": 61,
      "z": 10,
      "name": "Rock_Ice"
    },
    {
      "x": -36,
      "y": 62,
      "z": 10,
      "name": "Rock_Ice"
    },
    {
      "x": -36,
      "y": 63,
      "z": 10,
      "name": "Rock_Ice"
    },
    {
      "x": -36,
      "y": 64,
      "z": 10,
      "name": "Rock_Ice"
    },
    {
      "x": -36,
      "y": 65,
      "z": 10,
      "name": "Rock_Ice"
    },
    {
      "x": -36,
      "y": 66,
      "z": 10,
      "name": "Rock_Ice"
    },
    {
      "x": -36,
      "y": 67,
      "z": 10,
      "name": "Rock_Ice"
    },
    {
      "x": -36,
      "y": 68,
      "z": 10,
      "name": "Rock_Ice"
    },
    {
      "x": -36,
      "y": 69,
      "z": 10,
      "name": "Rock_Ice"
    },
    {
      "x": -36,
      "y": 70,
      "z": 10,
      "name": "Rock_Ice"
    },
    {
      "x": -36,
      "y": 71,
      "z": 10,
      "name": "Rock_Ice"
    },
    {
      "x": -36,
      "y": 72,
      "z": 10,
      "name": "Rock_Ice"
    },
    {
      "x": -36,
      "y": 73,
      "z": 10,
      "name": "Rock_Ice"
    },
    {
      "x": -36,
      "y": 74,
      "z": 10,
      "name": "Rock_Ice"
    },
    {
      "x": -36,
      "y": 75,
      "z": 10,
      "name": "Soil_Snow"
    },
    {
      "x": -36,
      "y": 56,
      "z": 11,
      "name": "Rock_Ice_Permafrost"
    },
    {
      "x": -36,
      "y": 57,
      "z": 11,
      "name": "Rock_Ice"
    },
    {
      "x": -36,
      "y": 58,
      "z": 11,
      "name": "Rock_Ice"
    },
    {
      "x": -36,
      "y": 59,
      "z": 11,
      "name": "Rock_Ice"
    },
    {
      "x": -36,
      "y": 60,
      "z": 11,
      "name": "Rock_Ice"
    },
    {
      "x": -36,
      "y": 61,
      "z": 11,
      "name": "Rock_Ice"
    },
    {
      "x": -36,
      "y": 62,
      "z": 11,
      "name": "Rock_Ice"
    },
    {
      "x": -36,
      "y": 63,
      "z": 11,
      "name": "Rock_Ice"
    },
    {
      "x": -36,
      "y": 64,
      "z": 11,
      "name": "Rock_Ice"
    },
    {
      "x": -36,
      "y": 65,
      "z": 11,
      "name": "Rock_Ice"
    },
    {
      "x": -36,
      "y": 66,
      "z": 11,
      "name": "Rock_Ice"
    },
    {
      "x": -36,
      "y": 67,
      "z": 11,
      "name": "Rock_Ice"
    },
    {
      "x": -36,
      "y": 68,
      "z": 11,
      "name": "Rock_Ice"
    },
    {
      "x": -36,
      "y": 69,
      "z": 11,
      "name": "Rock_Ice"
    },
    {
      "x": -36,
      "y": 70,
      "z": 11,
      "name": "Rock_Ice"
    },
    {
      "x": -36,
      "y": 71,
      "z": 11,
      "name": "Rock_Ice"
    },
    {
      "x": -36,
      "y": 72,
      "z": 11,
      "name": "Rock_Ice"
    },
    {
      "x": -36,
      "y": 73,
      "z": 11,
      "name": "Rock_Ice"
    },
    {
      "x": -36,
      "y": 74,
      "z": 11,
      "name": "Rock_Ice"
    },
    {
      "x": -36,
      "y": 75,
      "z": 11,
      "name": "Soil_Snow"
    },
    {
      "x": -36,
      "y": 61,
      "z": 12,
      "name": "Rock_Ice"
    },
    {
      "x": -36,
      "y": 62,
      "z": 12,
      "name": "Rock_Ice"
    },
    {
      "x": -36,
      "y": 63,
      "z": 12,
      "name": "Rock_Ice"
    },
    {
      "x": -36,
      "y": 64,
      "z": 12,
      "name": "Rock_Ice"
    },
    {
      "x": -36,
      "y": 65,
      "z": 12,
      "name": "Rock_Ice"
    },
    {
      "x": -36,
      "y": 66,
      "z": 12,
      "name": "Rock_Ice"
    },
    {
      "x": -36,
      "y": 67,
      "z": 12,
      "name": "Rock_Ice"
    },
    {
      "x": -36,
      "y": 68,
      "z": 12,
      "name": "Rock_Ice"
    },
    {
      "x": -36,
      "y": 69,
      "z": 12,
      "name": "Rock_Ice"
    },
    {
      "x": -36,
      "y": 70,
      "z": 12,
      "name": "Rock_Ice"
    },
    {
      "x": -36,
      "y": 71,
      "z": 12,
      "name": "Rock_Ice"
    },
    {
      "x": -36,
      "y": 72,
      "z": 12,
      "name": "Rock_Ice"
    },
    {
      "x": -36,
      "y": 73,
      "z": 12,
      "name": "Rock_Ice"
    },
    {
      "x": -36,
      "y": 74,
      "z": 12,
      "name": "Soil_Snow"
    },
    {
      "x": -36,
      "y": 64,
      "z": 13,
      "name": "Rock_Ice"
    },
    {
      "x": -36,
      "y": 65,
      "z": 13,
      "name": "Rock_Ice"
    },
    {
      "x": -36,
      "y": 66,
      "z": 13,
      "name": "Rock_Ice"
    },
    {
      "x": -36,
      "y": 67,
      "z": 13,
      "name": "Rock_Ice"
    },
    {
      "x": -36,
      "y": 68,
      "z": 13,
      "name": "Rock_Ice"
    },
    {
      "x": -36,
      "y": 69,
      "z": 13,
      "name": "Rock_Ice"
    },
    {
      "x": -36,
      "y": 70,
      "z": 13,
      "name": "Rock_Ice"
    },
    {
      "x": -36,
      "y": 71,
      "z": 13,
      "name": "Rock_Ice"
    },
    {
      "x": -36,
      "y": 72,
      "z": 13,
      "name": "Rock_Ice"
    },
    {
      "x": -36,
      "y": 73,
      "z": 13,
      "name": "Soil_Snow"
    },
    {
      "x": -36,
      "y": 66,
      "z": 14,
      "name": "Rock_Ice"
    },
    {
      "x": -36,
      "y": 67,
      "z": 14,
      "name": "Rock_Ice"
    },
    {
      "x": -36,
      "y": 68,
      "z": 14,
      "name": "Rock_Ice"
    },
    {
      "x": -36,
      "y": 69,
      "z": 14,
      "name": "Rock_Ice"
    },
    {
      "x": -36,
      "y": 70,
      "z": 14,
      "name": "Rock_Ice"
    },
    {
      "x": -36,
      "y": 71,
      "z": 14,
      "name": "Rock_Ice"
    },
    {
      "x": -36,
      "y": 72,
      "z": 14,
      "name": "Rock_Ice"
    },
    {
      "x": -36,
      "y": 64,
      "z": 15,
      "name": "Rock_Ice"
    },
    {
      "x": -36,
      "y": 65,
      "z": 15,
      "name": "Rock_Ice"
    },
    {
      "x": -36,
      "y": 66,
      "z": 15,
      "name": "Rock_Ice"
    },
    {
      "x": -36,
      "y": 67,
      "z": 15,
      "name": "Rock_Ice"
    },
    {
      "x": -36,
      "y": 68,
      "z": 15,
      "name": "Rock_Ice"
    },
    {
      "x": -36,
      "y": 69,
      "z": 15,
      "name": "Rock_Ice"
    },
    {
      "x": -36,
      "y": 70,
      "z": 15,
      "name": "Rock_Ice"
    },
    {
      "x": -36,
      "y": 71,
      "z": 15,
      "name": "Rock_Ice"
    },
    {
      "x": -36,
      "y": 72,
      "z": 15,
      "name": "Rock_Ice"
    },
    {
      "x": -36,
      "y": 62,
      "z": 16,
      "name": "Rock_Ice"
    },
    {
      "x": -36,
      "y": 63,
      "z": 16,
      "name": "Rock_Ice_Permafrost"
    },
    {
      "x": -36,
      "y": 64,
      "z": 16,
      "name": "Rock_Ice"
    },
    {
      "x": -36,
      "y": 65,
      "z": 16,
      "name": "Rock_Ice"
    },
    {
      "x": -36,
      "y": 66,
      "z": 16,
      "name": "Rock_Ice"
    },
    {
      "x": -36,
      "y": 67,
      "z": 16,
      "name": "Rock_Ice"
    },
    {
      "x": -36,
      "y": 68,
      "z": 16,
      "name": "Rock_Ice"
    },
    {
      "x": -36,
      "y": 69,
      "z": 16,
      "name": "Rock_Ice"
    },
    {
      "x": -36,
      "y": 70,
      "z": 16,
      "name": "Rock_Ice"
    },
    {
      "x": -36,
      "y": 71,
      "z": 16,
      "name": "Rock_Ice"
    },
    {
      "x": -36,
      "y": 72,
      "z": 16,
      "name": "Rock_Ice"
    },
    {
      "x": -36,
      "y": 73,
      "z": 16,
      "name": "Rock_Ice"
    },
    {
      "x": -36,
      "y": 63,
      "z": 17,
      "name": "Rock_Ice"
    },
    {
      "x": -36,
      "y": 64,
      "z": 17,
      "name": "Rock_Ice_Permafrost"
    },
    {
      "x": -36,
      "y": 65,
      "z": 17,
      "name": "Rock_Ice_Permafrost"
    },
    {
      "x": -36,
      "y": 66,
      "z": 17,
      "name": "Rock_Ice"
    },
    {
      "x": -36,
      "y": 67,
      "z": 17,
      "name": "Rock_Ice"
    },
    {
      "x": -36,
      "y": 68,
      "z": 17,
      "name": "Rock_Ice"
    },
    {
      "x": -36,
      "y": 69,
      "z": 17,
      "name": "Rock_Ice"
    },
    {
      "x": -36,
      "y": 70,
      "z": 17,
      "name": "Rock_Ice"
    },
    {
      "x": -36,
      "y": 71,
      "z": 17,
      "name": "Rock_Ice"
    },
    {
      "x": -36,
      "y": 72,
      "z": 17,
      "name": "Rock_Ice"
    },
    {
      "x": -36,
      "y": 73,
      "z": 17,
      "name": "Rock_Ice"
    },
    {
      "x": -36,
      "y": 74,
      "z": 17,
      "name": "Rock_Ice"
    },
    {
      "x": -36,
      "y": 64,
      "z": 18,
      "name": "Rock_Ice_Permafrost"
    },
    {
      "x": -36,
      "y": 65,
      "z": 18,
      "name": "Rock_Ice_Permafrost"
    },
    {
      "x": -36,
      "y": 66,
      "z": 18,
      "name": "Rock_Ice_Permafrost"
    },
    {
      "x": -36,
      "y": 67,
      "z": 18,
      "name": "Rock_Ice_Permafrost"
    },
    {
      "x": -36,
      "y": 68,
      "z": 18,
      "name": "Rock_Ice_Permafrost"
    },
    {
      "x": -36,
      "y": 69,
      "z": 18,
      "name": "Rock_Ice_Permafrost"
    },
    {
      "x": -36,
      "y": 70,
      "z": 18,
      "name": "Rock_Ice_Permafrost"
    },
    {
      "x": -36,
      "y": 71,
      "z": 18,
      "name": "Rock_Ice"
    },
    {
      "x": -36,
      "y": 72,
      "z": 18,
      "name": "Rock_Ice"
    },
    {
      "x": -36,
      "y": 73,
      "z": 18,
      "name": "Rock_Ice"
    },
    {
      "x": -36,
      "y": 65,
      "z": 19,
      "name": "Rock_Ice_Permafrost"
    },
    {
      "x": -36,
      "y": 66,
      "z": 19,
      "name": "Rock_Ice_Permafrost"
    },
    {
      "x": -36,
      "y": 67,
      "z": 19,
      "name": "Rock_Ice_Permafrost"
    },
    {
      "x": -36,
      "y": 68,
      "z": 19,
      "name": "Rock_Ice_Permafrost"
    },
    {
      "x": -36,
      "y": 69,
      "z": 19,
      "name": "Rock_Ice_Permafrost"
    },
    {
      "x": -36,
      "y": 70,
      "z": 19,
      "name": "Rock_Ice_Permafrost"
    },
    {
      "x": -36,
      "y": 71,
      "z": 19,
      "name": "Rock_Ice_Permafrost"
    },
    {
      "x": -36,
      "y": 72,
      "z": 19,
      "name": "Rock_Ice"
    },
    {
      "x": -36,
      "y": 73,
      "z": 19,
      "name": "Soil_Snow"
    },
    {
      "x": -36,
      "y": 66,
      "z": 20,
      "name": "Rock_Ice_Permafrost"
    },
    {
      "x": -36,
      "y": 67,
      "z": 20,
      "name": "Rock_Ice_Permafrost"
    },
    {
      "x": -36,
      "y": 68,
      "z": 20,
      "name": "Rock_Ice_Permafrost"
    },
    {
      "x": -36,
      "y": 69,
      "z": 20,
      "name": "Rock_Ice_Permafrost"
    },
    {
      "x": -36,
      "y": 70,
      "z": 20,
      "name": "Rock_Ice_Permafrost"
    },
    {
      "x": -36,
      "y": 71,
      "z": 20,
      "name": "Rock_Ice_Permafrost"
    },
    {
      "x": -36,
      "y": 72,
      "z": 20,
      "name": "Rock_Ice_Permafrost"
    },
    {
      "x": -36,
      "y": 73,
      "z": 20,
      "name": "Rock_Ice_Permafrost"
    },
    {
      "x": -36,
      "y": 67,
      "z": 21,
      "name": "Rock_Ice"
    },
    {
      "x": -36,
      "y": 68,
      "z": 21,
      "name": "Rock_Ice"
    },
    {
      "x": -36,
      "y": 69,
      "z": 21,
      "name": "Rock_Ice"
    },
    {
      "x": -36,
      "y": 70,
      "z": 21,
      "name": "Rock_Ice"
    },
    {
      "x": -36,
      "y": 71,
      "z": 21,
      "name": "Rock_Ice"
    },
    {
      "x": -36,
      "y": 72,
      "z": 21,
      "name": "Rock_Ice_Permafrost"
    },
    {
      "x": -36,
      "y": 69,
      "z": 22,
      "name": "Rock_Ice"
    },
    {
      "x": -36,
      "y": 70,
      "z": 22,
      "name": "Rock_Ice"
    },
    {
      "x": -36,
      "y": 71,
      "z": 22,
      "name": "Rock_Ice"
    },
    {
      "x": -35,
      "y": 54,
      "z": -12,
      "name": "Rock_Ice"
    },
    {
      "x": -35,
      "y": 55,
      "z": -12,
      "name": "Rock_Ice"
    },
    {
      "x": -35,
      "y": 56,
      "z": -12,
      "name": "Soil_Snow"
    },
    {
      "x": -35,
      "y": 52,
      "z": -11,
      "name": "Rock_Ice"
    },
    {
      "x": -35,
      "y": 53,
      "z": -11,
      "name": "Rock_Ice"
    },
    {
      "x": -35,
      "y": 54,
      "z": -11,
      "name": "Rock_Ice"
    },
    {
      "x": -35,
      "y": 55,
      "z": -11,
      "name": "Rock_Ice"
    },
    {
      "x": -35,
      "y": 56,
      "z": -11,
      "name": "Rock_Ice"
    },
    {
      "x": -35,
      "y": 57,
      "z": -11,
      "name": "Rock_Ice"
    },
    {
      "x": -35,
      "y": 58,
      "z": -11,
      "name": "Rock_Ice"
    },
    {
      "x": -35,
      "y": 50,
      "z": -10,
      "name": "Rock_Ice"
    },
    {
      "x": -35,
      "y": 51,
      "z": -10,
      "name": "Rock_Ice"
    },
    {
      "x": -35,
      "y": 52,
      "z": -10,
      "name": "Rock_Ice"
    },
    {
      "x": -35,
      "y": 53,
      "z": -10,
      "name": "Rock_Ice"
    },
    {
      "x": -35,
      "y": 54,
      "z": -10,
      "name": "Rock_Ice"
    },
    {
      "x": -35,
      "y": 55,
      "z": -10,
      "name": "Rock_Ice"
    },
    {
      "x": -35,
      "y": 56,
      "z": -10,
      "name": "Rock_Ice"
    },
    {
      "x": -35,
      "y": 57,
      "z": -10,
      "name": "Rock_Ice"
    },
    {
      "x": -35,
      "y": 58,
      "z": -10,
      "name": "Rock_Ice"
    },
    {
      "x": -35,
      "y": 59,
      "z": -10,
      "name": "Rock_Ice"
    },
    {
      "x": -35,
      "y": 49,
      "z": -9,
      "name": "Rock_Ice"
    },
    {
      "x": -35,
      "y": 50,
      "z": -9,
      "name": "Rock_Ice"
    },
    {
      "x": -35,
      "y": 51,
      "z": -9,
      "name": "Rock_Ice"
    },
    {
      "x": -35,
      "y": 52,
      "z": -9,
      "name": "Rock_Ice"
    },
    {
      "x": -35,
      "y": 53,
      "z": -9,
      "name": "Rock_Ice"
    },
    {
      "x": -35,
      "y": 54,
      "z": -9,
      "name": "Rock_Ice"
    },
    {
      "x": -35,
      "y": 55,
      "z": -9,
      "name": "Rock_Ice"
    },
    {
      "x": -35,
      "y": 56,
      "z": -9,
      "name": "Rock_Ice"
    },
    {
      "x": -35,
      "y": 57,
      "z": -9,
      "name": "Rock_Ice"
    },
    {
      "x": -35,
      "y": 58,
      "z": -9,
      "name": "Rock_Ice"
    },
    {
      "x": -35,
      "y": 59,
      "z": -9,
      "name": "Soil_Snow"
    },
    {
      "x": -35,
      "y": 47,
      "z": -8,
      "name": "Rock_Ice_Permafrost"
    },
    {
      "x": -35,
      "y": 48,
      "z": -8,
      "name": "Rock_Ice_Permafrost"
    },
    {
      "x": -35,
      "y": 49,
      "z": -8,
      "name": "Rock_Ice_Permafrost"
    },
    {
      "x": -35,
      "y": 50,
      "z": -8,
      "name": "Rock_Ice"
    },
    {
      "x": -35,
      "y": 51,
      "z": -8,
      "name": "Rock_Ice"
    },
    {
      "x": -35,
      "y": 52,
      "z": -8,
      "name": "Rock_Ice"
    },
    {
      "x": -35,
      "y": 53,
      "z": -8,
      "name": "Rock_Ice"
    },
    {
      "x": -35,
      "y": 54,
      "z": -8,
      "name": "Rock_Ice"
    },
    {
      "x": -35,
      "y": 55,
      "z": -8,
      "name": "Rock_Ice"
    },
    {
      "x": -35,
      "y": 56,
      "z": -8,
      "name": "Rock_Ice"
    },
    {
      "x": -35,
      "y": 57,
      "z": -8,
      "name": "Rock_Ice"
    },
    {
      "x": -35,
      "y": 58,
      "z": -8,
      "name": "Soil_Snow"
    },
    {
      "x": -35,
      "y": 47,
      "z": -7,
      "name": "Rock_Ice_Permafrost"
    },
    {
      "x": -35,
      "y": 48,
      "z": -7,
      "name": "Rock_Ice_Permafrost"
    },
    {
      "x": -35,
      "y": 49,
      "z": -7,
      "name": "Rock_Ice_Permafrost"
    },
    {
      "x": -35,
      "y": 50,
      "z": -7,
      "name": "Rock_Ice_Permafrost"
    },
    {
      "x": -35,
      "y": 51,
      "z": -7,
      "name": "Rock_Ice_Permafrost"
    },
    {
      "x": -35,
      "y": 52,
      "z": -7,
      "name": "Rock_Ice_Permafrost"
    },
    {
      "x": -35,
      "y": 53,
      "z": -7,
      "name": "Rock_Ice"
    },
    {
      "x": -35,
      "y": 54,
      "z": -7,
      "name": "Rock_Ice"
    },
    {
      "x": -35,
      "y": 55,
      "z": -7,
      "name": "Rock_Ice"
    },
    {
      "x": -35,
      "y": 56,
      "z": -7,
      "name": "Rock_Ice"
    },
    {
      "x": -35,
      "y": 57,
      "z": -7,
      "name": "Rock_Ice"
    },
    {
      "x": -35,
      "y": 58,
      "z": -7,
      "name": "Soil_Snow"
    },
    {
      "x": -35,
      "y": 47,
      "z": -6,
      "name": "Rock_Ice_Permafrost"
    },
    {
      "x": -35,
      "y": 48,
      "z": -6,
      "name": "Rock_Ice_Permafrost"
    },
    {
      "x": -35,
      "y": 49,
      "z": -6,
      "name": "Rock_Ice_Permafrost"
    },
    {
      "x": -35,
      "y": 50,
      "z": -6,
      "name": "Rock_Ice_Permafrost"
    },
    {
      "x": -35,
      "y": 51,
      "z": -6,
      "name": "Rock_Ice_Permafrost"
    },
    {
      "x": -35,
      "y": 52,
      "z": -6,
      "name": "Rock_Ice_Permafrost"
    },
    {
      "x": -35,
      "y": 53,
      "z": -6,
      "name": "Rock_Ice_Permafrost"
    },
    {
      "x": -35,
      "y": 54,
      "z": -6,
      "name": "Rock_Ice_Permafrost"
    },
    {
      "x": -35,
      "y": 55,
      "z": -6,
      "name": "Rock_Ice_Permafrost"
    },
    {
      "x": -35,
      "y": 56,
      "z": -6,
      "name": "Rock_Ice_Permafrost"
    },
    {
      "x": -35,
      "y": 57,
      "z": -6,
      "name": "Rock_Ice"
    },
    {
      "x": -35,
      "y": 58,
      "z": -6,
      "name": "Soil_Snow"
    },
    {
      "x": -35,
      "y": 47,
      "z": -5,
      "name": "Rock_Ice"
    },
    {
      "x": -35,
      "y": 48,
      "z": -5,
      "name": "Rock_Ice_Permafrost"
    },
    {
      "x": -35,
      "y": 49,
      "z": -5,
      "name": "Rock_Ice_Permafrost"
    },
    {
      "x": -35,
      "y": 50,
      "z": -5,
      "name": "Rock_Ice"
    },
    {
      "x": -35,
      "y": 51,
      "z": -5,
      "name": "Rock_Ice"
    },
    {
      "x": -35,
      "y": 52,
      "z": -5,
      "name": "Rock_Ice"
    },
    {
      "x": -35,
      "y": 53,
      "z": -5,
      "name": "Rock_Ice"
    },
    {
      "x": -35,
      "y": 54,
      "z": -5,
      "name": "Rock_Ice"
    },
    {
      "x": -35,
      "y": 55,
      "z": -5,
      "name": "Rock_Ice_Permafrost"
    },
    {
      "x": -35,
      "y": 56,
      "z": -5,
      "name": "Rock_Ice"
    },
    {
      "x": -35,
      "y": 57,
      "z": -5,
      "name": "Soil_Snow"
    },
    {
      "x": -35,
      "y": 47,
      "z": -4,
      "name": "Rock_Ice"
    },
    {
      "x": -35,
      "y": 48,
      "z": -4,
      "name": "Rock_Ice"
    },
    {
      "x": -35,
      "y": 49,
      "z": -4,
      "name": "Rock_Ice"
    },
    {
      "x": -35,
      "y": 50,
      "z": -4,
      "name": "Rock_Ice"
    },
    {
      "x": -35,
      "y": 51,
      "z": -4,
      "name": "Rock_Ice"
    },
    {
      "x": -35,
      "y": 52,
      "z": -4,
      "name": "Rock_Ice"
    },
    {
      "x": -35,
      "y": 53,
      "z": -4,
      "name": "Rock_Ice"
    },
    {
      "x": -35,
      "y": 54,
      "z": -4,
      "name": "Rock_Ice"
    },
    {
      "x": -35,
      "y": 55,
      "z": -4,
      "name": "Rock_Ice"
    },
    {
      "x": -35,
      "y": 56,
      "z": -4,
      "name": "Rock_Ice"
    },
    {
      "x": -35,
      "y": 57,
      "z": -4,
      "name": "Rock_Ice"
    },
    {
      "x": -35,
      "y": 68,
      "z": -4,
      "name": "Rock_Ice"
    },
    {
      "x": -35,
      "y": 69,
      "z": -4,
      "name": "Soil_Snow"
    },
    {
      "x": -35,
      "y": 47,
      "z": -3,
      "name": "Rock_Ice"
    },
    {
      "x": -35,
      "y": 48,
      "z": -3,
      "name": "Rock_Ice"
    },
    {
      "x": -35,
      "y": 49,
      "z": -3,
      "name": "Rock_Ice"
    },
    {
      "x": -35,
      "y": 50,
      "z": -3,
      "name": "Rock_Ice"
    },
    {
      "x": -35,
      "y": 51,
      "z": -3,
      "name": "Rock_Ice"
    },
    {
      "x": -35,
      "y": 52,
      "z": -3,
      "name": "Rock_Ice"
    },
    {
      "x": -35,
      "y": 53,
      "z": -3,
      "name": "Rock_Ice"
    },
    {
      "x": -35,
      "y": 54,
      "z": -3,
      "name": "Rock_Ice"
    },
    {
      "x": -35,
      "y": 55,
      "z": -3,
      "name": "Rock_Ice"
    },
    {
      "x": -35,
      "y": 56,
      "z": -3,
      "name": "Rock_Ice"
    },
    {
      "x": -35,
      "y": 67,
      "z": -3,
      "name": "Rock_Ice"
    },
    {
      "x": -35,
      "y": 68,
      "z": -3,
      "name": "Rock_Ice"
    },
    {
      "x": -35,
      "y": 69,
      "z": -3,
      "name": "Rock_Ice"
    },
    {
      "x": -35,
      "y": 70,
      "z": -3,
      "name": "Rock_Ice"
    },
    {
      "x": -35,
      "y": 71,
      "z": -3,
      "name": "Soil_Snow"
    },
    {
      "x": -35,
      "y": 47,
      "z": -2,
      "name": "Rock_Ice"
    },
    {
      "x": -35,
      "y": 48,
      "z": -2,
      "name": "Rock_Ice"
    },
    {
      "x": -35,
      "y": 49,
      "z": -2,
      "name": "Rock_Ice"
    },
    {
      "x": -35,
      "y": 50,
      "z": -2,
      "name": "Rock_Ice"
    },
    {
      "x": -35,
      "y": 51,
      "z": -2,
      "name": "Rock_Ice"
    },
    {
      "x": -35,
      "y": 52,
      "z": -2,
      "name": "Rock_Ice"
    },
    {
      "x": -35,
      "y": 53,
      "z": -2,
      "name": "Rock_Ice"
    },
    {
      "x": -35,
      "y": 54,
      "z": -2,
      "name": "Rock_Ice"
    },
    {
      "x": -35,
      "y": 55,
      "z": -2,
      "name": "Rock_Ice"
    },
    {
      "x": -35,
      "y": 56,
      "z": -2,
      "name": "Rock_Ice"
    },
    {
      "x": -35,
      "y": 67,
      "z": -2,
      "name": "Rock_Ice"
    },
    {
      "x": -35,
      "y": 68,
      "z": -2,
      "name": "Rock_Ice"
    },
    {
      "x": -35,
      "y": 69,
      "z": -2,
      "name": "Rock_Ice"
    },
    {
      "x": -35,
      "y": 70,
      "z": -2,
      "name": "Rock_Ice"
    },
    {
      "x": -35,
      "y": 71,
      "z": -2,
      "name": "Rock_Ice"
    },
    {
      "x": -35,
      "y": 72,
      "z": -2,
      "name": "Rock_Ice"
    },
    {
      "x": -35,
      "y": 73,
      "z": -2,
      "name": "Soil_Snow"
    },
    {
      "x": -35,
      "y": 47,
      "z": -1,
      "name": "Rock_Ice"
    },
    {
      "x": -35,
      "y": 48,
      "z": -1,
      "name": "Rock_Ice"
    },
    {
      "x": -35,
      "y": 49,
      "z": -1,
      "name": "Rock_Ice"
    },
    {
      "x": -35,
      "y": 50,
      "z": -1,
      "name": "Rock_Ice"
    },
    {
      "x": -35,
      "y": 51,
      "z": -1,
      "name": "Rock_Ice"
    },
    {
      "x": -35,
      "y": 52,
      "z": -1,
      "name": "Rock_Ice"
    },
    {
      "x": -35,
      "y": 53,
      "z": -1,
      "name": "Rock_Ice"
    },
    {
      "x": -35,
      "y": 54,
      "z": -1,
      "name": "Rock_Ice"
    },
    {
      "x": -35,
      "y": 55,
      "z": -1,
      "name": "Rock_Ice"
    },
    {
      "x": -35,
      "y": 56,
      "z": -1,
      "name": "Rock_Ice"
    },
    {
      "x": -35,
      "y": 66,
      "z": -1,
      "name": "Rock_Ice"
    },
    {
      "x": -35,
      "y": 67,
      "z": -1,
      "name": "Rock_Ice_Permafrost"
    },
    {
      "x": -35,
      "y": 68,
      "z": -1,
      "name": "Rock_Ice_Permafrost"
    },
    {
      "x": -35,
      "y": 69,
      "z": -1,
      "name": "Rock_Ice_Permafrost"
    },
    {
      "x": -35,
      "y": 70,
      "z": -1,
      "name": "Rock_Ice_Permafrost"
    },
    {
      "x": -35,
      "y": 71,
      "z": -1,
      "name": "Rock_Ice"
    },
    {
      "x": -35,
      "y": 72,
      "z": -1,
      "name": "Rock_Ice"
    },
    {
      "x": -35,
      "y": 73,
      "z": -1,
      "name": "Rock_Ice"
    },
    {
      "x": -35,
      "y": 47,
      "z": 0,
      "name": "Rock_Ice"
    },
    {
      "x": -35,
      "y": 48,
      "z": 0,
      "name": "Rock_Ice"
    },
    {
      "x": -35,
      "y": 49,
      "z": 0,
      "name": "Rock_Ice"
    },
    {
      "x": -35,
      "y": 50,
      "z": 0,
      "name": "Rock_Ice"
    },
    {
      "x": -35,
      "y": 51,
      "z": 0,
      "name": "Rock_Ice"
    },
    {
      "x": -35,
      "y": 52,
      "z": 0,
      "name": "Rock_Ice"
    },
    {
      "x": -35,
      "y": 53,
      "z": 0,
      "name": "Rock_Ice"
    },
    {
      "x": -35,
      "y": 54,
      "z": 0,
      "name": "Rock_Ice"
    },
    {
      "x": -35,
      "y": 55,
      "z": 0,
      "name": "Rock_Ice"
    },
    {
      "x": -35,
      "y": 56,
      "z": 0,
      "name": "Rock_Ice"
    },
    {
      "x": -35,
      "y": 57,
      "z": 0,
      "name": "Rock_Ice"
    },
    {
      "x": -35,
      "y": 65,
      "z": 0,
      "name": "Rock_Ice"
    },
    {
      "x": -35,
      "y": 66,
      "z": 0,
      "name": "Rock_Ice"
    },
    {
      "x": -35,
      "y": 67,
      "z": 0,
      "name": "Rock_Ice"
    },
    {
      "x": -35,
      "y": 68,
      "z": 0,
      "name": "Rock_Ice"
    },
    {
      "x": -35,
      "y": 69,
      "z": 0,
      "name": "Rock_Ice_Permafrost"
    },
    {
      "x": -35,
      "y": 70,
      "z": 0,
      "name": "Rock_Ice_Permafrost"
    },
    {
      "x": -35,
      "y": 71,
      "z": 0,
      "name": "Rock_Ice_Permafrost"
    },
    {
      "x": -35,
      "y": 72,
      "z": 0,
      "name": "Rock_Ice_Permafrost"
    },
    {
      "x": -35,
      "y": 73,
      "z": 0,
      "name": "Rock_Ice"
    },
    {
      "x": -35,
      "y": 74,
      "z": 0,
      "name": "Rock_Ice"
    },
    {
      "x": -35,
      "y": 47,
      "z": 1,
      "name": "Rock_Ice"
    },
    {
      "x": -35,
      "y": 48,
      "z": 1,
      "name": "Rock_Ice"
    },
    {
      "x": -35,
      "y": 49,
      "z": 1,
      "name": "Rock_Ice"
    },
    {
      "x": -35,
      "y": 50,
      "z": 1,
      "name": "Rock_Ice"
    },
    {
      "x": -35,
      "y": 51,
      "z": 1,
      "name": "Rock_Ice"
    },
    {
      "x": -35,
      "y": 52,
      "z": 1,
      "name": "Rock_Ice"
    },
    {
      "x": -35,
      "y": 53,
      "z": 1,
      "name": "Rock_Ice"
    },
    {
      "x": -35,
      "y": 54,
      "z": 1,
      "name": "Rock_Ice"
    },
    {
      "x": -35,
      "y": 55,
      "z": 1,
      "name": "Rock_Ice"
    },
    {
      "x": -35,
      "y": 56,
      "z": 1,
      "name": "Rock_Ice"
    },
    {
      "x": -35,
      "y": 57,
      "z": 1,
      "name": "Rock_Ice"
    },
    {
      "x": -35,
      "y": 58,
      "z": 1,
      "name": "Rock_Ice"
    },
    {
      "x": -35,
      "y": 59,
      "z": 1,
      "name": "Rock_Ice"
    },
    {
      "x": -35,
      "y": 63,
      "z": 1,
      "name": "Rock_Ice"
    },
    {
      "x": -35,
      "y": 64,
      "z": 1,
      "name": "Rock_Ice"
    },
    {
      "x": -35,
      "y": 65,
      "z": 1,
      "name": "Rock_Ice"
    },
    {
      "x": -35,
      "y": 66,
      "z": 1,
      "name": "Rock_Ice"
    },
    {
      "x": -35,
      "y": 67,
      "z": 1,
      "name": "Rock_Ice"
    },
    {
      "x": -35,
      "y": 68,
      "z": 1,
      "name": "Rock_Ice"
    },
    {
      "x": -35,
      "y": 69,
      "z": 1,
      "name": "Rock_Ice"
    },
    {
      "x": -35,
      "y": 70,
      "z": 1,
      "name": "Rock_Ice"
    },
    {
      "x": -35,
      "y": 71,
      "z": 1,
      "name": "Rock_Ice_Permafrost"
    },
    {
      "x": -35,
      "y": 72,
      "z": 1,
      "name": "Rock_Ice_Permafrost"
    },
    {
      "x": -35,
      "y": 73,
      "z": 1,
      "name": "Rock_Ice"
    },
    {
      "x": -35,
      "y": 74,
      "z": 1,
      "name": "Soil_Snow"
    },
    {
      "x": -35,
      "y": 47,
      "z": 2,
      "name": "Rock_Ice"
    },
    {
      "x": -35,
      "y": 48,
      "z": 2,
      "name": "Rock_Ice"
    },
    {
      "x": -35,
      "y": 49,
      "z": 2,
      "name": "Rock_Ice"
    },
    {
      "x": -35,
      "y": 50,
      "z": 2,
      "name": "Rock_Ice"
    },
    {
      "x": -35,
      "y": 51,
      "z": 2,
      "name": "Rock_Ice"
    },
    {
      "x": -35,
      "y": 52,
      "z": 2,
      "name": "Rock_Ice"
    },
    {
      "x": -35,
      "y": 53,
      "z": 2,
      "name": "Rock_Ice"
    },
    {
      "x": -35,
      "y": 54,
      "z": 2,
      "name": "Rock_Ice"
    },
    {
      "x": -35,
      "y": 55,
      "z": 2,
      "name": "Rock_Ice"
    },
    {
      "x": -35,
      "y": 56,
      "z": 2,
      "name": "Rock_Ice"
    },
    {
      "x": -35,
      "y": 57,
      "z": 2,
      "name": "Rock_Ice"
    },
    {
      "x": -35,
      "y": 58,
      "z": 2,
      "name": "Rock_Ice"
    },
    {
      "x": -35,
      "y": 59,
      "z": 2,
      "name": "Rock_Ice"
    },
    {
      "x": -35,
      "y": 60,
      "z": 2,
      "name": "Rock_Ice"
    },
    {
      "x": -35,
      "y": 61,
      "z": 2,
      "name": "Rock_Ice"
    },
    {
      "x": -35,
      "y": 62,
      "z": 2,
      "name": "Rock_Ice"
    },
    {
      "x": -35,
      "y": 63,
      "z": 2,
      "name": "Rock_Ice"
    },
    {
      "x": -35,
      "y": 64,
      "z": 2,
      "name": "Rock_Ice"
    },
    {
      "x": -35,
      "y": 65,
      "z": 2,
      "name": "Rock_Ice"
    },
    {
      "x": -35,
      "y": 66,
      "z": 2,
      "name": "Rock_Ice"
    },
    {
      "x": -35,
      "y": 67,
      "z": 2,
      "name": "Rock_Ice"
    },
    {
      "x": -35,
      "y": 68,
      "z": 2,
      "name": "Rock_Ice"
    },
    {
      "x": -35,
      "y": 69,
      "z": 2,
      "name": "Rock_Ice"
    },
    {
      "x": -35,
      "y": 70,
      "z": 2,
      "name": "Rock_Ice"
    },
    {
      "x": -35,
      "y": 71,
      "z": 2,
      "name": "Rock_Ice"
    },
    {
      "x": -35,
      "y": 72,
      "z": 2,
      "name": "Rock_Ice"
    },
    {
      "x": -35,
      "y": 73,
      "z": 2,
      "name": "Rock_Ice_Permafrost"
    },
    {
      "x": -35,
      "y": 74,
      "z": 2,
      "name": "Rock_Ice"
    },
    {
      "x": -35,
      "y": 75,
      "z": 2,
      "name": "Soil_Snow"
    },
    {
      "x": -35,
      "y": 47,
      "z": 3,
      "name": "Rock_Ice"
    },
    {
      "x": -35,
      "y": 48,
      "z": 3,
      "name": "Rock_Ice"
    },
    {
      "x": -35,
      "y": 49,
      "z": 3,
      "name": "Rock_Ice"
    },
    {
      "x": -35,
      "y": 50,
      "z": 3,
      "name": "Rock_Ice"
    },
    {
      "x": -35,
      "y": 51,
      "z": 3,
      "name": "Rock_Ice"
    },
    {
      "x": -35,
      "y": 52,
      "z": 3,
      "name": "Rock_Ice"
    },
    {
      "x": -35,
      "y": 53,
      "z": 3,
      "name": "Rock_Ice"
    },
    {
      "x": -35,
      "y": 54,
      "z": 3,
      "name": "Rock_Ice"
    },
    {
      "x": -35,
      "y": 55,
      "z": 3,
      "name": "Rock_Ice"
    },
    {
      "x": -35,
      "y": 56,
      "z": 3,
      "name": "Rock_Ice"
    },
    {
      "x": -35,
      "y": 57,
      "z": 3,
      "name": "Rock_Ice"
    },
    {
      "x": -35,
      "y": 58,
      "z": 3,
      "name": "Rock_Ice"
    },
    {
      "x": -35,
      "y": 59,
      "z": 3,
      "name": "Rock_Ice"
    },
    {
      "x": -35,
      "y": 60,
      "z": 3,
      "name": "Rock_Ice"
    },
    {
      "x": -35,
      "y": 61,
      "z": 3,
      "name": "Rock_Ice"
    },
    {
      "x": -35,
      "y": 62,
      "z": 3,
      "name": "Rock_Ice"
    },
    {
      "x": -35,
      "y": 63,
      "z": 3,
      "name": "Rock_Ice"
    },
    {
      "x": -35,
      "y": 64,
      "z": 3,
      "name": "Rock_Ice"
    },
    {
      "x": -35,
      "y": 65,
      "z": 3,
      "name": "Rock_Ice"
    },
    {
      "x": -35,
      "y": 66,
      "z": 3,
      "name": "Rock_Ice"
    },
    {
      "x": -35,
      "y": 67,
      "z": 3,
      "name": "Rock_Ice"
    },
    {
      "x": -35,
      "y": 68,
      "z": 3,
      "name": "Rock_Ice"
    },
    {
      "x": -35,
      "y": 69,
      "z": 3,
      "name": "Rock_Ice"
    },
    {
      "x": -35,
      "y": 70,
      "z": 3,
      "name": "Rock_Ice"
    },
    {
      "x": -35,
      "y": 71,
      "z": 3,
      "name": "Rock_Ice"
    },
    {
      "x": -35,
      "y": 72,
      "z": 3,
      "name": "Rock_Ice"
    },
    {
      "x": -35,
      "y": 73,
      "z": 3,
      "name": "Rock_Ice"
    },
    {
      "x": -35,
      "y": 74,
      "z": 3,
      "name": "Rock_Ice"
    },
    {
      "x": -35,
      "y": 75,
      "z": 3,
      "name": "Rock_Ice"
    },
    {
      "x": -35,
      "y": 76,
      "z": 3,
      "name": "Soil_Snow"
    },
    {
      "x": -35,
      "y": 47,
      "z": 4,
      "name": "Rock_Ice"
    },
    {
      "x": -35,
      "y": 48,
      "z": 4,
      "name": "Rock_Ice"
    },
    {
      "x": -35,
      "y": 49,
      "z": 4,
      "name": "Rock_Ice"
    },
    {
      "x": -35,
      "y": 50,
      "z": 4,
      "name": "Rock_Ice"
    },
    {
      "x": -35,
      "y": 51,
      "z": 4,
      "name": "Rock_Ice"
    },
    {
      "x": -35,
      "y": 52,
      "z": 4,
      "name": "Rock_Ice"
    },
    {
      "x": -35,
      "y": 53,
      "z": 4,
      "name": "Rock_Ice"
    },
    {
      "x": -35,
      "y": 54,
      "z": 4,
      "name": "Rock_Ice"
    },
    {
      "x": -35,
      "y": 55,
      "z": 4,
      "name": "Rock_Ice"
    },
    {
      "x": -35,
      "y": 56,
      "z": 4,
      "name": "Rock_Ice"
    },
    {
      "x": -35,
      "y": 57,
      "z": 4,
      "name": "Rock_Ice"
    },
    {
      "x": -35,
      "y": 58,
      "z": 4,
      "name": "Rock_Ice"
    },
    {
      "x": -35,
      "y": 59,
      "z": 4,
      "name": "Rock_Ice"
    },
    {
      "x": -35,
      "y": 60,
      "z": 4,
      "name": "Rock_Ice"
    },
    {
      "x": -35,
      "y": 61,
      "z": 4,
      "name": "Rock_Ice"
    },
    {
      "x": -35,
      "y": 62,
      "z": 4,
      "name": "Rock_Ice"
    },
    {
      "x": -35,
      "y": 63,
      "z": 4,
      "name": "Rock_Ice"
    },
    {
      "x": -35,
      "y": 64,
      "z": 4,
      "name": "Rock_Ice"
    },
    {
      "x": -35,
      "y": 65,
      "z": 4,
      "name": "Rock_Ice"
    },
    {
      "x": -35,
      "y": 66,
      "z": 4,
      "name": "Rock_Ice"
    },
    {
      "x": -35,
      "y": 67,
      "z": 4,
      "name": "Rock_Ice"
    },
    {
      "x": -35,
      "y": 68,
      "z": 4,
      "name": "Rock_Ice"
    },
    {
      "x": -35,
      "y": 69,
      "z": 4,
      "name": "Rock_Ice"
    },
    {
      "x": -35,
      "y": 70,
      "z": 4,
      "name": "Rock_Ice"
    },
    {
      "x": -35,
      "y": 71,
      "z": 4,
      "name": "Rock_Ice"
    },
    {
      "x": -35,
      "y": 72,
      "z": 4,
      "name": "Rock_Ice"
    },
    {
      "x": -35,
      "y": 73,
      "z": 4,
      "name": "Rock_Ice"
    },
    {
      "x": -35,
      "y": 74,
      "z": 4,
      "name": "Rock_Ice"
    },
    {
      "x": -35,
      "y": 75,
      "z": 4,
      "name": "Rock_Ice"
    },
    {
      "x": -35,
      "y": 76,
      "z": 4,
      "name": "Soil_Snow"
    },
    {
      "x": -35,
      "y": 46,
      "z": 5,
      "name": "Rock_Ice"
    },
    {
      "x": -35,
      "y": 47,
      "z": 5,
      "name": "Rock_Ice"
    },
    {
      "x": -35,
      "y": 48,
      "z": 5,
      "name": "Rock_Ice"
    },
    {
      "x": -35,
      "y": 49,
      "z": 5,
      "name": "Rock_Ice"
    },
    {
      "x": -35,
      "y": 50,
      "z": 5,
      "name": "Rock_Ice"
    },
    {
      "x": -35,
      "y": 51,
      "z": 5,
      "name": "Rock_Ice"
    },
    {
      "x": -35,
      "y": 52,
      "z": 5,
      "name": "Rock_Ice"
    },
    {
      "x": -35,
      "y": 53,
      "z": 5,
      "name": "Rock_Ice"
    },
    {
      "x": -35,
      "y": 54,
      "z": 5,
      "name": "Rock_Ice"
    },
    {
      "x": -35,
      "y": 55,
      "z": 5,
      "name": "Rock_Ice"
    },
    {
      "x": -35,
      "y": 56,
      "z": 5,
      "name": "Rock_Ice"
    },
    {
      "x": -35,
      "y": 57,
      "z": 5,
      "name": "Rock_Ice"
    },
    {
      "x": -35,
      "y": 58,
      "z": 5,
      "name": "Rock_Ice"
    },
    {
      "x": -35,
      "y": 59,
      "z": 5,
      "name": "Rock_Ice"
    },
    {
      "x": -35,
      "y": 60,
      "z": 5,
      "name": "Rock_Ice"
    },
    {
      "x": -35,
      "y": 61,
      "z": 5,
      "name": "Rock_Ice"
    },
    {
      "x": -35,
      "y": 62,
      "z": 5,
      "name": "Rock_Ice"
    },
    {
      "x": -35,
      "y": 63,
      "z": 5,
      "name": "Rock_Ice"
    },
    {
      "x": -35,
      "y": 64,
      "z": 5,
      "name": "Rock_Ice"
    },
    {
      "x": -35,
      "y": 65,
      "z": 5,
      "name": "Rock_Ice"
    },
    {
      "x": -35,
      "y": 66,
      "z": 5,
      "name": "Rock_Ice"
    },
    {
      "x": -35,
      "y": 67,
      "z": 5,
      "name": "Rock_Ice"
    },
    {
      "x": -35,
      "y": 68,
      "z": 5,
      "name": "Rock_Ice"
    },
    {
      "x": -35,
      "y": 69,
      "z": 5,
      "name": "Rock_Ice"
    },
    {
      "x": -35,
      "y": 70,
      "z": 5,
      "name": "Rock_Ice"
    },
    {
      "x": -35,
      "y": 71,
      "z": 5,
      "name": "Rock_Ice"
    },
    {
      "x": -35,
      "y": 72,
      "z": 5,
      "name": "Rock_Ice"
    },
    {
      "x": -35,
      "y": 73,
      "z": 5,
      "name": "Rock_Ice"
    },
    {
      "x": -35,
      "y": 74,
      "z": 5,
      "name": "Rock_Ice"
    },
    {
      "x": -35,
      "y": 75,
      "z": 5,
      "name": "Rock_Ice"
    },
    {
      "x": -35,
      "y": 76,
      "z": 5,
      "name": "Soil_Snow"
    },
    {
      "x": -35,
      "y": 46,
      "z": 6,
      "name": "Rock_Ice"
    },
    {
      "x": -35,
      "y": 47,
      "z": 6,
      "name": "Rock_Ice"
    },
    {
      "x": -35,
      "y": 48,
      "z": 6,
      "name": "Rock_Ice"
    },
    {
      "x": -35,
      "y": 49,
      "z": 6,
      "name": "Rock_Ice"
    },
    {
      "x": -35,
      "y": 50,
      "z": 6,
      "name": "Rock_Ice"
    },
    {
      "x": -35,
      "y": 51,
      "z": 6,
      "name": "Rock_Ice"
    },
    {
      "x": -35,
      "y": 52,
      "z": 6,
      "name": "Rock_Ice"
    },
    {
      "x": -35,
      "y": 53,
      "z": 6,
      "name": "Rock_Ice"
    },
    {
      "x": -35,
      "y": 54,
      "z": 6,
      "name": "Rock_Ice"
    },
    {
      "x": -35,
      "y": 55,
      "z": 6,
      "name": "Rock_Ice"
    },
    {
      "x": -35,
      "y": 56,
      "z": 6,
      "name": "Rock_Ice"
    },
    {
      "x": -35,
      "y": 57,
      "z": 6,
      "name": "Rock_Ice"
    },
    {
      "x": -35,
      "y": 58,
      "z": 6,
      "name": "Rock_Ice"
    },
    {
      "x": -35,
      "y": 59,
      "z": 6,
      "name": "Rock_Ice"
    },
    {
      "x": -35,
      "y": 60,
      "z": 6,
      "name": "Rock_Ice"
    },
    {
      "x": -35,
      "y": 61,
      "z": 6,
      "name": "Rock_Ice"
    },
    {
      "x": -35,
      "y": 62,
      "z": 6,
      "name": "Rock_Ice"
    },
    {
      "x": -35,
      "y": 63,
      "z": 6,
      "name": "Rock_Ice"
    },
    {
      "x": -35,
      "y": 64,
      "z": 6,
      "name": "Rock_Ice"
    },
    {
      "x": -35,
      "y": 65,
      "z": 6,
      "name": "Rock_Ice"
    },
    {
      "x": -35,
      "y": 66,
      "z": 6,
      "name": "Rock_Ice"
    },
    {
      "x": -35,
      "y": 67,
      "z": 6,
      "name": "Rock_Ice"
    },
    {
      "x": -35,
      "y": 68,
      "z": 6,
      "name": "Rock_Ice"
    },
    {
      "x": -35,
      "y": 69,
      "z": 6,
      "name": "Rock_Ice"
    },
    {
      "x": -35,
      "y": 70,
      "z": 6,
      "name": "Rock_Ice"
    },
    {
      "x": -35,
      "y": 71,
      "z": 6,
      "name": "Rock_Ice"
    },
    {
      "x": -35,
      "y": 72,
      "z": 6,
      "name": "Rock_Ice"
    },
    {
      "x": -35,
      "y": 73,
      "z": 6,
      "name": "Rock_Ice"
    },
    {
      "x": -35,
      "y": 74,
      "z": 6,
      "name": "Rock_Ice"
    },
    {
      "x": -35,
      "y": 75,
      "z": 6,
      "name": "Rock_Ice"
    },
    {
      "x": -35,
      "y": 76,
      "z": 6,
      "name": "Soil_Snow"
    },
    {
      "x": -35,
      "y": 47,
      "z": 7,
      "name": "Rock_Ice_Permafrost"
    },
    {
      "x": -35,
      "y": 48,
      "z": 7,
      "name": "Rock_Ice"
    },
    {
      "x": -35,
      "y": 49,
      "z": 7,
      "name": "Rock_Ice"
    },
    {
      "x": -35,
      "y": 50,
      "z": 7,
      "name": "Rock_Ice"
    },
    {
      "x": -35,
      "y": 51,
      "z": 7,
      "name": "Rock_Ice"
    },
    {
      "x": -35,
      "y": 52,
      "z": 7,
      "name": "Rock_Ice"
    },
    {
      "x": -35,
      "y": 53,
      "z": 7,
      "name": "Rock_Ice"
    },
    {
      "x": -35,
      "y": 54,
      "z": 7,
      "name": "Rock_Ice"
    },
    {
      "x": -35,
      "y": 55,
      "z": 7,
      "name": "Rock_Ice"
    },
    {
      "x": -35,
      "y": 56,
      "z": 7,
      "name": "Rock_Ice"
    },
    {
      "x": -35,
      "y": 57,
      "z": 7,
      "name": "Rock_Ice"
    },
    {
      "x": -35,
      "y": 58,
      "z": 7,
      "name": "Rock_Ice"
    },
    {
      "x": -35,
      "y": 59,
      "z": 7,
      "name": "Rock_Ice"
    },
    {
      "x": -35,
      "y": 60,
      "z": 7,
      "name": "Rock_Ice"
    },
    {
      "x": -35,
      "y": 61,
      "z": 7,
      "name": "Rock_Ice"
    },
    {
      "x": -35,
      "y": 62,
      "z": 7,
      "name": "Rock_Ice"
    },
    {
      "x": -35,
      "y": 63,
      "z": 7,
      "name": "Rock_Ice"
    },
    {
      "x": -35,
      "y": 64,
      "z": 7,
      "name": "Rock_Ice"
    },
    {
      "x": -35,
      "y": 65,
      "z": 7,
      "name": "Rock_Ice"
    },
    {
      "x": -35,
      "y": 66,
      "z": 7,
      "name": "Rock_Ice"
    },
    {
      "x": -35,
      "y": 67,
      "z": 7,
      "name": "Rock_Ice"
    },
    {
      "x": -35,
      "y": 68,
      "z": 7,
      "name": "Rock_Ice"
    },
    {
      "x": -35,
      "y": 69,
      "z": 7,
      "name": "Rock_Ice"
    },
    {
      "x": -35,
      "y": 70,
      "z": 7,
      "name": "Rock_Ice"
    },
    {
      "x": -35,
      "y": 71,
      "z": 7,
      "name": "Rock_Ice"
    },
    {
      "x": -35,
      "y": 72,
      "z": 7,
      "name": "Rock_Ice"
    },
    {
      "x": -35,
      "y": 73,
      "z": 7,
      "name": "Rock_Ice"
    },
    {
      "x": -35,
      "y": 74,
      "z": 7,
      "name": "Rock_Ice"
    },
    {
      "x": -35,
      "y": 75,
      "z": 7,
      "name": "Rock_Ice"
    },
    {
      "x": -35,
      "y": 76,
      "z": 7,
      "name": "Soil_Snow"
    },
    {
      "x": -35,
      "y": 47,
      "z": 8,
      "name": "Rock_Ice_Permafrost"
    },
    {
      "x": -35,
      "y": 48,
      "z": 8,
      "name": "Rock_Ice_Permafrost"
    },
    {
      "x": -35,
      "y": 49,
      "z": 8,
      "name": "Rock_Ice_Permafrost"
    },
    {
      "x": -35,
      "y": 50,
      "z": 8,
      "name": "Rock_Ice_Permafrost"
    },
    {
      "x": -35,
      "y": 51,
      "z": 8,
      "name": "Rock_Ice"
    },
    {
      "x": -35,
      "y": 52,
      "z": 8,
      "name": "Rock_Ice"
    },
    {
      "x": -35,
      "y": 53,
      "z": 8,
      "name": "Rock_Ice"
    },
    {
      "x": -35,
      "y": 54,
      "z": 8,
      "name": "Rock_Ice"
    },
    {
      "x": -35,
      "y": 55,
      "z": 8,
      "name": "Rock_Ice"
    },
    {
      "x": -35,
      "y": 56,
      "z": 8,
      "name": "Rock_Ice"
    },
    {
      "x": -35,
      "y": 57,
      "z": 8,
      "name": "Rock_Ice"
    },
    {
      "x": -35,
      "y": 58,
      "z": 8,
      "name": "Rock_Ice"
    },
    {
      "x": -35,
      "y": 59,
      "z": 8,
      "name": "Rock_Ice"
    },
    {
      "x": -35,
      "y": 60,
      "z": 8,
      "name": "Rock_Ice"
    },
    {
      "x": -35,
      "y": 61,
      "z": 8,
      "name": "Rock_Ice"
    },
    {
      "x": -35,
      "y": 62,
      "z": 8,
      "name": "Rock_Ice"
    },
    {
      "x": -35,
      "y": 63,
      "z": 8,
      "name": "Rock_Ice"
    },
    {
      "x": -35,
      "y": 64,
      "z": 8,
      "name": "Rock_Ice"
    },
    {
      "x": -35,
      "y": 65,
      "z": 8,
      "name": "Rock_Ice"
    },
    {
      "x": -35,
      "y": 66,
      "z": 8,
      "name": "Rock_Ice"
    },
    {
      "x": -35,
      "y": 67,
      "z": 8,
      "name": "Rock_Ice"
    },
    {
      "x": -35,
      "y": 68,
      "z": 8,
      "name": "Rock_Ice"
    },
    {
      "x": -35,
      "y": 69,
      "z": 8,
      "name": "Rock_Ice"
    },
    {
      "x": -35,
      "y": 70,
      "z": 8,
      "name": "Rock_Ice"
    },
    {
      "x": -35,
      "y": 71,
      "z": 8,
      "name": "Rock_Ice"
    },
    {
      "x": -35,
      "y": 72,
      "z": 8,
      "name": "Rock_Ice"
    },
    {
      "x": -35,
      "y": 73,
      "z": 8,
      "name": "Rock_Ice"
    },
    {
      "x": -35,
      "y": 74,
      "z": 8,
      "name": "Rock_Ice"
    },
    {
      "x": -35,
      "y": 75,
      "z": 8,
      "name": "Rock_Ice"
    },
    {
      "x": -35,
      "y": 76,
      "z": 8,
      "name": "Soil_Snow"
    },
    {
      "x": -35,
      "y": 47,
      "z": 9,
      "name": "Rock_Ice_Permafrost"
    },
    {
      "x": -35,
      "y": 48,
      "z": 9,
      "name": "Rock_Ice_Permafrost"
    },
    {
      "x": -35,
      "y": 49,
      "z": 9,
      "name": "Rock_Ice_Permafrost"
    },
    {
      "x": -35,
      "y": 50,
      "z": 9,
      "name": "Rock_Ice_Permafrost"
    },
    {
      "x": -35,
      "y": 51,
      "z": 9,
      "name": "Rock_Ice"
    },
    {
      "x": -35,
      "y": 52,
      "z": 9,
      "name": "Rock_Ice"
    },
    {
      "x": -35,
      "y": 53,
      "z": 9,
      "name": "Rock_Ice"
    },
    {
      "x": -35,
      "y": 54,
      "z": 9,
      "name": "Rock_Ice"
    },
    {
      "x": -35,
      "y": 55,
      "z": 9,
      "name": "Rock_Ice"
    },
    {
      "x": -35,
      "y": 56,
      "z": 9,
      "name": "Rock_Ice"
    },
    {
      "x": -35,
      "y": 57,
      "z": 9,
      "name": "Rock_Ice"
    },
    {
      "x": -35,
      "y": 58,
      "z": 9,
      "name": "Rock_Ice"
    },
    {
      "x": -35,
      "y": 59,
      "z": 9,
      "name": "Rock_Ice"
    },
    {
      "x": -35,
      "y": 60,
      "z": 9,
      "name": "Rock_Ice"
    },
    {
      "x": -35,
      "y": 61,
      "z": 9,
      "name": "Rock_Ice"
    },
    {
      "x": -35,
      "y": 62,
      "z": 9,
      "name": "Rock_Ice"
    },
    {
      "x": -35,
      "y": 63,
      "z": 9,
      "name": "Rock_Ice"
    },
    {
      "x": -35,
      "y": 64,
      "z": 9,
      "name": "Rock_Ice"
    },
    {
      "x": -35,
      "y": 65,
      "z": 9,
      "name": "Rock_Ice"
    },
    {
      "x": -35,
      "y": 66,
      "z": 9,
      "name": "Rock_Ice"
    },
    {
      "x": -35,
      "y": 67,
      "z": 9,
      "name": "Rock_Ice"
    },
    {
      "x": -35,
      "y": 68,
      "z": 9,
      "name": "Rock_Ice"
    },
    {
      "x": -35,
      "y": 69,
      "z": 9,
      "name": "Rock_Ice"
    },
    {
      "x": -35,
      "y": 70,
      "z": 9,
      "name": "Rock_Ice"
    },
    {
      "x": -35,
      "y": 71,
      "z": 9,
      "name": "Rock_Ice"
    },
    {
      "x": -35,
      "y": 72,
      "z": 9,
      "name": "Rock_Ice"
    },
    {
      "x": -35,
      "y": 73,
      "z": 9,
      "name": "Rock_Ice"
    },
    {
      "x": -35,
      "y": 74,
      "z": 9,
      "name": "Rock_Ice"
    },
    {
      "x": -35,
      "y": 75,
      "z": 9,
      "name": "Rock_Ice"
    },
    {
      "x": -35,
      "y": 76,
      "z": 9,
      "name": "Soil_Snow"
    },
    {
      "x": -35,
      "y": 48,
      "z": 10,
      "name": "Rock_Ice_Permafrost"
    },
    {
      "x": -35,
      "y": 49,
      "z": 10,
      "name": "Rock_Ice_Permafrost"
    },
    {
      "x": -35,
      "y": 50,
      "z": 10,
      "name": "Rock_Ice_Permafrost"
    },
    {
      "x": -35,
      "y": 51,
      "z": 10,
      "name": "Rock_Ice_Permafrost"
    },
    {
      "x": -35,
      "y": 52,
      "z": 10,
      "name": "Rock_Ice_Permafrost"
    },
    {
      "x": -35,
      "y": 53,
      "z": 10,
      "name": "Rock_Ice"
    },
    {
      "x": -35,
      "y": 54,
      "z": 10,
      "name": "Rock_Ice"
    },
    {
      "x": -35,
      "y": 55,
      "z": 10,
      "name": "Rock_Ice"
    },
    {
      "x": -35,
      "y": 56,
      "z": 10,
      "name": "Rock_Ice"
    },
    {
      "x": -35,
      "y": 57,
      "z": 10,
      "name": "Rock_Ice"
    },
    {
      "x": -35,
      "y": 58,
      "z": 10,
      "name": "Rock_Ice"
    },
    {
      "x": -35,
      "y": 59,
      "z": 10,
      "name": "Rock_Ice"
    },
    {
      "x": -35,
      "y": 60,
      "z": 10,
      "name": "Rock_Ice"
    },
    {
      "x": -35,
      "y": 61,
      "z": 10,
      "name": "Rock_Ice"
    },
    {
      "x": -35,
      "y": 62,
      "z": 10,
      "name": "Rock_Ice"
    },
    {
      "x": -35,
      "y": 63,
      "z": 10,
      "name": "Rock_Ice"
    },
    {
      "x": -35,
      "y": 64,
      "z": 10,
      "name": "Rock_Ice"
    },
    {
      "x": -35,
      "y": 65,
      "z": 10,
      "name": "Rock_Ice"
    },
    {
      "x": -35,
      "y": 66,
      "z": 10,
      "name": "Rock_Ice"
    },
    {
      "x": -35,
      "y": 67,
      "z": 10,
      "name": "Rock_Ice"
    },
    {
      "x": -35,
      "y": 68,
      "z": 10,
      "name": "Rock_Ice"
    },
    {
      "x": -35,
      "y": 69,
      "z": 10,
      "name": "Rock_Ice"
    },
    {
      "x": -35,
      "y": 70,
      "z": 10,
      "name": "Rock_Ice"
    },
    {
      "x": -35,
      "y": 71,
      "z": 10,
      "name": "Rock_Ice"
    },
    {
      "x": -35,
      "y": 72,
      "z": 10,
      "name": "Rock_Ice"
    },
    {
      "x": -35,
      "y": 73,
      "z": 10,
      "name": "Rock_Ice"
    },
    {
      "x": -35,
      "y": 74,
      "z": 10,
      "name": "Rock_Ice"
    },
    {
      "x": -35,
      "y": 75,
      "z": 10,
      "name": "Rock_Ice"
    },
    {
      "x": -35,
      "y": 76,
      "z": 10,
      "name": "Soil_Snow"
    },
    {
      "x": -35,
      "y": 51,
      "z": 11,
      "name": "Rock_Ice_Permafrost"
    },
    {
      "x": -35,
      "y": 52,
      "z": 11,
      "name": "Rock_Ice_Permafrost"
    },
    {
      "x": -35,
      "y": 53,
      "z": 11,
      "name": "Rock_Ice"
    },
    {
      "x": -35,
      "y": 54,
      "z": 11,
      "name": "Rock_Ice_Permafrost"
    },
    {
      "x": -35,
      "y": 55,
      "z": 11,
      "name": "Rock_Ice_Permafrost"
    },
    {
      "x": -35,
      "y": 56,
      "z": 11,
      "name": "Rock_Ice"
    },
    {
      "x": -35,
      "y": 57,
      "z": 11,
      "name": "Rock_Ice"
    },
    {
      "x": -35,
      "y": 58,
      "z": 11,
      "name": "Rock_Ice"
    },
    {
      "x": -35,
      "y": 59,
      "z": 11,
      "name": "Rock_Ice"
    },
    {
      "x": -35,
      "y": 60,
      "z": 11,
      "name": "Rock_Ice"
    },
    {
      "x": -35,
      "y": 61,
      "z": 11,
      "name": "Rock_Ice"
    },
    {
      "x": -35,
      "y": 62,
      "z": 11,
      "name": "Rock_Ice"
    },
    {
      "x": -35,
      "y": 63,
      "z": 11,
      "name": "Rock_Ice"
    },
    {
      "x": -35,
      "y": 64,
      "z": 11,
      "name": "Rock_Ice"
    },
    {
      "x": -35,
      "y": 65,
      "z": 11,
      "name": "Rock_Ice"
    },
    {
      "x": -35,
      "y": 66,
      "z": 11,
      "name": "Rock_Ice"
    },
    {
      "x": -35,
      "y": 67,
      "z": 11,
      "name": "Rock_Ice"
    },
    {
      "x": -35,
      "y": 68,
      "z": 11,
      "name": "Rock_Ice"
    },
    {
      "x": -35,
      "y": 69,
      "z": 11,
      "name": "Rock_Ice"
    },
    {
      "x": -35,
      "y": 70,
      "z": 11,
      "name": "Rock_Ice"
    },
    {
      "x": -35,
      "y": 71,
      "z": 11,
      "name": "Rock_Ice"
    },
    {
      "x": -35,
      "y": 72,
      "z": 11,
      "name": "Rock_Ice"
    },
    {
      "x": -35,
      "y": 73,
      "z": 11,
      "name": "Rock_Ice"
    },
    {
      "x": -35,
      "y": 74,
      "z": 11,
      "name": "Rock_Ice"
    },
    {
      "x": -35,
      "y": 75,
      "z": 11,
      "name": "Rock_Ice"
    },
    {
      "x": -35,
      "y": 76,
      "z": 11,
      "name": "Soil_Snow"
    },
    {
      "x": -35,
      "y": 55,
      "z": 12,
      "name": "Rock_Ice_Permafrost"
    },
    {
      "x": -35,
      "y": 56,
      "z": 12,
      "name": "Rock_Ice"
    },
    {
      "x": -35,
      "y": 57,
      "z": 12,
      "name": "Rock_Ice"
    },
    {
      "x": -35,
      "y": 58,
      "z": 12,
      "name": "Rock_Ice"
    },
    {
      "x": -35,
      "y": 59,
      "z": 12,
      "name": "Rock_Ice"
    },
    {
      "x": -35,
      "y": 60,
      "z": 12,
      "name": "Rock_Ice"
    },
    {
      "x": -35,
      "y": 61,
      "z": 12,
      "name": "Rock_Ice"
    },
    {
      "x": -35,
      "y": 62,
      "z": 12,
      "name": "Rock_Ice"
    },
    {
      "x": -35,
      "y": 63,
      "z": 12,
      "name": "Rock_Ice"
    },
    {
      "x": -35,
      "y": 64,
      "z": 12,
      "name": "Rock_Ice"
    },
    {
      "x": -35,
      "y": 65,
      "z": 12,
      "name": "Rock_Ice"
    },
    {
      "x": -35,
      "y": 66,
      "z": 12,
      "name": "Rock_Ice"
    },
    {
      "x": -35,
      "y": 67,
      "z": 12,
      "name": "Rock_Ice"
    },
    {
      "x": -35,
      "y": 68,
      "z": 12,
      "name": "Rock_Ice"
    },
    {
      "x": -35,
      "y": 69,
      "z": 12,
      "name": "Rock_Ice"
    },
    {
      "x": -35,
      "y": 70,
      "z": 12,
      "name": "Rock_Ice"
    },
    {
      "x": -35,
      "y": 71,
      "z": 12,
      "name": "Rock_Ice"
    },
    {
      "x": -35,
      "y": 72,
      "z": 12,
      "name": "Rock_Ice"
    },
    {
      "x": -35,
      "y": 73,
      "z": 12,
      "name": "Rock_Ice"
    },
    {
      "x": -35,
      "y": 74,
      "z": 12,
      "name": "Rock_Ice"
    },
    {
      "x": -35,
      "y": 75,
      "z": 12,
      "name": "Soil_Snow"
    },
    {
      "x": -35,
      "y": 60,
      "z": 13,
      "name": "Rock_Ice"
    },
    {
      "x": -35,
      "y": 61,
      "z": 13,
      "name": "Rock_Ice"
    },
    {
      "x": -35,
      "y": 62,
      "z": 13,
      "name": "Rock_Ice"
    },
    {
      "x": -35,
      "y": 63,
      "z": 13,
      "name": "Rock_Ice"
    },
    {
      "x": -35,
      "y": 64,
      "z": 13,
      "name": "Rock_Ice"
    },
    {
      "x": -35,
      "y": 65,
      "z": 13,
      "name": "Rock_Ice"
    },
    {
      "x": -35,
      "y": 66,
      "z": 13,
      "name": "Rock_Ice"
    },
    {
      "x": -35,
      "y": 67,
      "z": 13,
      "name": "Rock_Ice"
    },
    {
      "x": -35,
      "y": 68,
      "z": 13,
      "name": "Rock_Ice"
    },
    {
      "x": -35,
      "y": 69,
      "z": 13,
      "name": "Rock_Ice"
    },
    {
      "x": -35,
      "y": 70,
      "z": 13,
      "name": "Rock_Ice"
    },
    {
      "x": -35,
      "y": 71,
      "z": 13,
      "name": "Rock_Ice"
    },
    {
      "x": -35,
      "y": 72,
      "z": 13,
      "name": "Rock_Ice"
    },
    {
      "x": -35,
      "y": 73,
      "z": 13,
      "name": "Rock_Ice"
    },
    {
      "x": -35,
      "y": 74,
      "z": 13,
      "name": "Soil_Snow"
    },
    {
      "x": -35,
      "y": 62,
      "z": 14,
      "name": "Rock_Ice"
    },
    {
      "x": -35,
      "y": 63,
      "z": 14,
      "name": "Rock_Ice"
    },
    {
      "x": -35,
      "y": 64,
      "z": 14,
      "name": "Rock_Ice"
    },
    {
      "x": -35,
      "y": 65,
      "z": 14,
      "name": "Rock_Ice"
    },
    {
      "x": -35,
      "y": 66,
      "z": 14,
      "name": "Rock_Ice"
    },
    {
      "x": -35,
      "y": 67,
      "z": 14,
      "name": "Rock_Ice"
    },
    {
      "x": -35,
      "y": 68,
      "z": 14,
      "name": "Rock_Ice"
    },
    {
      "x": -35,
      "y": 69,
