{
  "version": 8,
  "blockIdVersion": 11,
  "anchorX": 5,
  "anchorY": 4,
  "anchorZ": 3,
  "blocks": [
    {
      "x": 2,
      "y": 3,
      "z": 3,
      "name": "Plant_Bramble_Moss_Twisted"
    },
    {
      "x": 2,
      "y": 4,
      "z": 3,
      "name": "Plant_Bramble_Moss_Twisted"
    },
    {
      "x": 2,
      "y": 5,
      "z": 3,
      "name": "Plant_Bramble_Moss_Twisted"
    },
    {
      "x": 2,
      "y": 3,
      "z": 4,
      "name": "Plant_Bramble_Moss_Twisted"
    },
    {
      "x": 2,
      "y": 4,
      "z": 4,
      "name": "Plant_Bramble_Moss_Twisted"
    },
    {
      "x": 3,
      "y": 3,
      "z": 2,
      "name": "Plant_Bramble_Moss_Twisted"
    },
    {
      "x": 3,
      "y": 4,
      "z": 2,
      "name": "Plant_Bramble_Moss_Twisted"
    },
    {
      "x": 3,
      "y": 2,
      "z": 3,
      "name": "Plant_Bramble_Moss_Twisted"
    },
    {
      "x": 3,
      "y": 3,
      "z": 3,
      "name": "Plant_Bramble_Moss_Twisted"
    },
    {
      "x": 3,
      "y": 4,
      "z": 3,
      "name": "Plant_Bramble_Moss_Twisted"
    },
    {
      "x": 3,
      "y": 5,
      "z": 3,
      "name": "Plant_Bramble_Moss_Twisted"
    },
    {
      "x": 3,
      "y": 2,
      "z": 4,
      "name": "Plant_Bramble_Moss_Twisted"
    },
    {
      "x": 3,
      "y": 3,
      "z": 4,
      "name": "Plant_Bramble_Moss_Twisted"
    },
    {
      "x": 3,
      "y": 4,
      "z": 4,
      "name": "Plant_Bramble_Moss_Twisted"
    },
    {
      "x": 3,
      "y": 5,
      "z": 4,
      "name": "Plant_Bramble_Moss_Twisted"
    },
    {
      "x": 3,
      "y": 3,
      "z": 5,
      "name": "Plant_Bramble_Moss_Twisted"
    },
    {
      "x": 3,
      "y": 4,
      "z": 5,
      "name": "Plant_Bramble_Moss_Twisted"
    },
    {
      "x": 3,
      "y": 5,
      "z": 5,
      "name": "Plant_Bramble_Moss_Twisted"
    },
    {
      "x": 3,
      "y": 5,
      "z": 6,
      "name": "Plant_Bramble_Moss_Twisted"
    },
    {
      "x": 4,
      "y": 3,
      "z": 1,
      "name": "Plant_Bramble_Moss_Twisted"
    },
    {
      "x": 4,
      "y": 4,
      "z": 1,
      "name": "Plant_Bramble_Moss_Twisted"
    },
    {
      "x": 4,
      "y": 2,
      "z": 2,
      "name": "Plant_Bramble_Moss_Twisted"
    },
    {
      "x": 4,
      "y": 3,
      "z": 2,
      "name": "Plant_Bramble_Moss_Twisted"
    },
    {
      "x": 4,
      "y": 4,
      "z": 2,
      "name": "Plant_Bramble_Moss_Twisted"
    },
    {
      "x": 4,
      "y": 5,
      "z": 2,
      "name": "Plant_Bramble_Moss_Twisted"
    },
    {
      "x": 4,
      "y": 2,
      "z": 3,
      "name": "Plant_Bramble_Moss_Twisted"
    },
    {
      "x": 4,
      "y": 3,
      "z": 3,
      "name": "Plant_Bramble_Moss_Twisted"
    },
    {
      "x": 4,
      "y": 4,
      "z": 3,
      "name": "Plant_Bramble_Moss_Twisted"
    },
    {
      "x": 4,
      "y": 5,
      "z": 3,
      "name": "Plant_Bramble_Moss_Twisted"
    },
    {
      "x": 4,
      "y": 6,
      "z": 3,
      "name": "Plant_Bramble_Moss_Twisted"
    },
    {
      "x": 4,
      "y": 2,
      "z": 4,
      "name": "Plant_Bramble_Moss_Twisted"
    },
    {
      "x": 4,
      "y": 3,
      "z": 4,
      "name": "Plant_Bramble_Moss_Twisted"
    },
    {
      "x": 4,
      "y": 4,
      "z": 4,
      "name": "Plant_Bramble_Moss_Twisted"
    },
    {
      "x": 4,
      "y": 5,
      "z": 4,
      "name": "Plant_Bramble_Moss_Twisted"
    },
    {
      "x": 4,
      "y": 6,
      "z": 4,
      "name": "Plant_Bramble_Moss_Twisted"
    },
    {
      "x": 4,
      "y": 2,
      "z": 5,
      "name": "Plant_Bramble_Moss_Twisted"
    },
    {
      "x": 4,
      "y": 3,
      "z": 5,
      "name": "Plant_Bramble_Moss_Twisted"
    },
    {
      "x": 4,
      "y": 4,
      "z": 5,
      "name": "Plant_Bramble_Moss_Twisted"
    },
    {
      "x": 4,
      "y": 5,
      "z": 5,
      "name": "Plant_Bramble_Moss_Twisted"
    },
    {
      "x": 4,
      "y": 6,
      "z": 5,
      "name": "Plant_Bramble_Moss_Twisted"
    },
    {
      "x": 4,
      "y": 4,
      "z": 6,
      "name": "Plant_Bramble_Moss_Twisted"
    },
    {
      "x": 4,
      "y": 5,
      "z": 6,
      "name": "Plant_Bramble_Moss_Twisted"
    },
    {
      "x": 4,
      "y": 6,
      "z": 6,
      "name": "Plant_Bramble_Moss_Twisted"
    },
    {
      "x": 4,
      "y": 5,
      "z": 7,
      "name": "Plant_Bramble_Moss_Twisted"
    },
    {
      "x": 5,
      "y": 3,
      "z": 1,
      "name": "Plant_Bramble_Moss_Twisted"
    },
    {
      "x": 5,
      "y": 4,
      "z": 1,
      "name": "Plant_Bramble_Moss_Twisted"
    },
    {
      "x": 5,
      "y": 5,
      "z": 1,
      "name": "Plant_Bramble_Moss_Twisted"
    },
    {
      "x": 5,
      "y": 2,
      "z": 2,
      "name": "Plant_Bramble_Moss_Twisted"
    },
    {
      "x": 5,
      "y": 3,
      "z": 2,
      "name": "Plant_Bramble_Moss_Twisted"
    },
    {
      "x": 5,
      "y": 4,
      "z": 2,
      "name": "Plant_Bramble_Moss_Twisted"
    },
    {
      "x": 5,
      "y": 5,
      "z": 2,
      "name": "Plant_Bramble_Moss_Twisted"
    },
    {
      "x": 5,
      "y": 6,
      "z": 2,
      "name": "Plant_Bramble_Moss_Twisted"
    },
    {
      "x": 5,
      "y": 2,
      "z": 3,
      "name": "Plant_Bramble_Moss_Twisted"
    },
    {
      "x": 5,
      "y": 3,
      "z": 3,
      "name": "Plant_Bramble_Moss_Twisted"
    },
    {
      "x": 5,
      "y": 4,
      "z": 3,
      "name": "Plant_Bramble_Moss_Twisted"
    },
    {
      "x": 5,
      "y": 5,
      "z": 3,
      "name": "Plant_Bramble_Moss_Twisted"
    },
    {
      "x": 5,
      "y": 6,
      "z": 3,
      "name": "Plant_Bramble_Moss_Twisted"
    },
    {
      "x": 5,
      "y": 2,
      "z": 4,
      "name": "Plant_Bramble_Moss_Twisted"
    },
    {
      "x": 5,
      "y": 3,
      "z": 4,
      "name": "Plant_Bramble_Moss_Twisted"
    },
    {
      "x": 5,
      "y": 4,
      "z": 4,
      "name": "Plant_Bramble_Moss_Twisted"
    },
    {
      "x": 5,
      "y": 5,
      "z": 4,
      "name": "Plant_Bramble_Moss_Twisted"
    },
    {
      "x": 5,
      "y": 6,
      "z": 4,
      "name": "Plant_Bramble_Moss_Twisted"
    },
    {
      "x": 5,
      "y": 3,
      "z": 5,
      "name": "Plant_Bramble_Moss_Twisted"
    },
    {
      "x": 5,
      "y": 4,
      "z": 5,
      "name": "Plant_Bramble_Moss_Twisted"
    },
    {
      "x": 5,
      "y": 5,
      "z": 5,
      "name": "Plant_Bramble_Moss_Twisted"
    },
    {
      "x": 5,
      "y": 6,
      "z": 5,
      "name": "Plant_Bramble_Moss_Twisted"
    },
    {
      "x": 5,
      "y": 4,
      "z": 6,
      "name": "Plant_Bramble_Moss_Twisted"
    },
    {
      "x": 5,
      "y": 5,
      "z": 6,
      "name": "Plant_Bramble_Moss_Twisted"
    },
    {
      "x": 6,
      "y": 3,
      "z": 1,
      "name": "Plant_Bramble_Moss_Twisted"
    },
    {
      "x": 6,
      "y": 4,
      "z": 1,
      "name": "Plant_Bramble_Moss_Twisted"
    },
    {
      "x": 6,
      "y": 5,
      "z": 1,
      "name": "Plant_Bramble_Moss_Twisted"
    },
    {
      "x": 6,
      "y": 3,
      "z": 2,
      "name": "Plant_Bramble_Moss_Twisted"
    },
    {
      "x": 6,
      "y": 4,
      "z": 2,
      "name": "Plant_Bramble_Moss_Twisted"
    },
    {
      "x": 6,
      "y": 5,
      "z": 2,
      "name": "Plant_Bramble_Moss_Twisted"
    },
    {
      "x": 6,
      "y": 6,
      "z": 2,
      "name": "Plant_Bramble_Moss_Twisted"
    },
    {
      "x": 6,
      "y": 2,
      "z": 3,
      "name": "Plant_Bramble_Moss_Twisted"
    },
    {
      "x": 6,
      "y": 3,
      "z": 3,
      "name": "Plant_Bramble_Moss_Twisted"
    },
    {
      "x": 6,
      "y": 4,
      "z": 3,
      "name": "Plant_Bramble_Moss_Twisted"
    },
    {
      "x": 6,
      "y": 5,
      "z": 3,
      "name": "Plant_Bramble_Moss_Twisted"
    },
    {
      "x": 6,
      "y": 6,
      "z": 3,
      "name": "Plant_Bramble_Moss_Twisted"
    },
    {
      "x": 6,
      "y": 3,
      "z": 4,
      "name": "Plant_Bramble_Moss_Twisted"
    },
    {
      "x": 6,
      "y": 4,
      "z": 4,
      "name": "Plant_Bramble_Moss_Twisted"
    },
    {
      "x": 6,
      "y": 5,
      "z": 4,
      "name": "Plant_Bramble_Moss_Twisted"
    },
    {
      "x": 6,
      "y": 6,
      "z": 4,
      "name": "Plant_Bramble_Moss_Twisted"
    },
    {
      "x": 6,
      "y": 3,
      "z": 5,
      "name": "Plant_Bramble_Moss_Twisted"
    },
    {
      "x": 6,
      "y": 4,
      "z": 5,
      "name": "Plant_Bramble_Moss_Twisted"
    },
    {
      "x": 6,
      "y": 5,
      "z": 5,
      "name": "Plant_Bramble_Moss_Twisted"
    },
    {
      "x": 6,
      "y": 4,
      "z": 6,
      "name": "Plant_Bramble_Moss_Twisted"
    },
    {
      "x": 6,
      "y": 5,
      "z": 6,
      "name": "Plant_Bramble_Moss_Twisted"
    },
    {
      "x": 7,
      "y": 4,
      "z": 1,
      "name": "Plant_Bramble_Moss_Twisted"
    },
    {
      "x": 7,
      "y": 5,
      "z": 1,
      "name": "Plant_Bramble_Moss_Twisted"
    },
    {
      "x": 7,
      "y": 3,
      "z": 2,
      "name": "Plant_Bramble_Moss_Twisted"
    },
    {
      "x": 7,
      "y": 4,
      "z": 2,
      "name": "Plant_Bramble_Moss_Twisted"
    },
    {
      "x": 7,
      "y": 5,
      "z": 2,
      "name": "Plant_Bramble_Moss_Twisted"
    },
    {
      "x": 7,
      "y": 3,
      "z": 3,
      "name": "Plant_Bramble_Moss_Twisted"
    },
    {
      "x": 7,
      "y": 4,
      "z": 3,
      "name": "Plant_Bramble_Moss_Twisted"
    },
    {
      "x": 7,
      "y": 5,
      "z": 3,
      "name": "Plant_Bramble_Moss_Twisted"
    },
    {
      "x": 7,
      "y": 6,
      "z": 3,
      "name": "Plant_Bramble_Moss_Twisted"
    },
    {
      "x": 7,
      "y": 4,
      "z": 4,
      "name": "Plant_Bramble_Moss_Twisted"
    },
    {
      "x": 7,
      "y": 5,
      "z": 4,
      "name": "Plant_Bramble_Moss_Twisted"
    },
    {
      "x": 7,
      "y": 4,
      "z": 5,
      "name": "Plant_Bramble_Moss_Twisted"
    },
    {
      "x": 8,
      "y": 4,
      "z": 2,
      "name": "Plant_Bramble_Moss_Twisted"
    },
    {
      "x": 8,
      "y": 4,
      "z": 3,
      "name": "Plant_Bramble_Moss_Twisted"
    },
    {
      "x": 8,
      "y": 5,
      "z": 3,
      "name": "Plant_Bramble_Moss_Twisted"
    }
  ]
}