{
  "version": 8,
  "blockIdVersion": 11,
  "anchorX": 4,
  "anchorY": 2,
  "anchorZ": 6,
  "blocks": [
    {
      "x": 1,
      "y": 1,
      "z": 3,
      "name": "Plant_Bramble_Moss_Twisted"
    },
    {
      "x": 1,
      "y": 2,
      "z": 3,
      "name": "Plant_Bramble_Moss_Twisted"
    },
    {
      "x": 1,
      "y": 3,
      "z": 3,
      "name": "Plant_Bramble_Moss_Twisted"
    },
    {
      "x": 1,
      "y": 1,
      "z": 4,
      "name": "Plant_Bramble_Moss_Twisted"
    },
    {
      "x": 1,
      "y": 2,
      "z": 4,
      "name": "Plant_Bramble_Moss_Twisted"
    },
    {
      "x": 1,
      "y": 3,
      "z": 4,
      "name": "Plant_Bramble_Moss_Twisted"
    },
    {
      "x": 1,
      "y": 1,
      "z": 5,
      "name": "Plant_Bramble_Moss_Twisted"
    },
    {
      "x": 1,
      "y": 2,
      "z": 5,
      "name": "Plant_Bramble_Moss_Twisted"
    },
    {
      "x": 2,
      "y": 2,
      "z": 3,
      "name": "Plant_Bramble_Moss_Twisted"
    },
    {
      "x": 2,
      "y": 3,
      "z": 3,
      "name": "Plant_Bramble_Moss_Twisted"
    },
    {
      "x": 2,
      "y": 1,
      "z": 4,
      "name": "Plant_Bramble_Moss_Twisted"
    },
    {
      "x": 2,
      "y": 2,
      "z": 4,
      "name": "Plant_Bramble_Moss_Twisted"
    },
    {
      "x": 2,
      "y": 3,
      "z": 4,
      "name": "Plant_Bramble_Moss_Twisted"
    },
    {
      "x": 2,
      "y": 0,
      "z": 5,
      "name": "Plant_Bramble_Moss_Twisted"
    },
    {
      "x": 2,
      "y": 1,
      "z": 5,
      "name": "Plant_Bramble_Moss_Twisted"
    },
    {
      "x": 2,
      "y": 2,
      "z": 5,
      "name": "Plant_Bramble_Moss_Twisted"
    },
    {
      "x": 2,
      "y": 3,
      "z": 5,
      "name": "Plant_Bramble_Moss_Twisted"
    },
    {
      "x": 2,
      "y": 1,
      "z": 6,
      "name": "Plant_Bramble_Moss_Twisted"
    },
    {
      "x": 2,
      "y": 2,
      "z": 6,
      "name": "Plant_Bramble_Moss_Twisted"
    },
    {
      "x": 2,
      "y": 3,
      "z": 6,
      "name": "Plant_Bramble_Moss_Twisted"
    },
    {
      "x": 2,
      "y": 1,
      "z": 7,
      "name": "Plant_Bramble_Moss_Twisted"
    },
    {
      "x": 2,
      "y": 2,
      "z": 7,
      "name": "Plant_Bramble_Moss_Twisted"
    },
    {
      "x": 2,
      "y": 3,
      "z": 7,
      "name": "Plant_Bramble_Moss_Twisted"
    },
    {
      "x": 2,
      "y": 2,
      "z": 8,
      "name": "Plant_Bramble_Moss_Twisted"
    },
    {
      "x": 2,
      "y": 3,
      "z": 8,
      "name": "Plant_Bramble_Moss_Twisted"
    },
    {
      "x": 3,
      "y": 2,
      "z": 2,
      "name": "Plant_Bramble_Moss_Twisted"
    },
    {
      "x": 3,
      "y": 3,
      "z": 2,
      "name": "Plant_Bramble_Moss_Twisted"
    },
    {
      "x": 3,
      "y": 1,
      "z": 3,
      "name": "Plant_Bramble_Moss_Twisted"
    },
    {
      "x": 3,
      "y": 2,
      "z": 3,
      "name": "Plant_Bramble_Moss_Twisted"
    },
    {
      "x": 3,
      "y": 3,
      "z": 3,
      "name": "Plant_Bramble_Moss_Twisted"
    },
    {
      "x": 3,
      "y": 4,
      "z": 3,
      "name": "Plant_Bramble_Moss_Twisted"
    },
    {
      "x": 3,
      "y": 0,
      "z": 4,
      "name": "Plant_Bramble_Moss_Twisted"
    },
    {
      "x": 3,
      "y": 1,
      "z": 4,
      "name": "Plant_Bramble_Moss_Twisted"
    },
    {
      "x": 3,
      "y": 2,
      "z": 4,
      "name": "Plant_Bramble_Moss_Twisted"
    },
    {
      "x": 3,
      "y": 3,
      "z": 4,
      "name": "Plant_Bramble_Moss_Twisted"
    },
    {
      "x": 3,
      "y": 4,
      "z": 4,
      "name": "Plant_Bramble_Moss_Twisted"
    },
    {
      "x": 3,
      "y": 0,
      "z": 5,
      "name": "Plant_Bramble_Moss_Twisted"
    },
    {
      "x": 3,
      "y": 1,
      "z": 5,
      "name": "Plant_Bramble_Moss_Twisted"
    },
    {
      "x": 3,
      "y": 2,
      "z": 5,
      "name": "Plant_Bramble_Moss_Twisted"
    },
    {
      "x": 3,
      "y": 3,
      "z": 5,
      "name": "Plant_Bramble_Moss_Twisted"
    },
    {
      "x": 3,
      "y": 4,
      "z": 5,
      "name": "Plant_Bramble_Moss_Twisted"
    },
    {
      "x": 3,
      "y": 0,
      "z": 6,
      "name": "Plant_Bramble_Moss_Twisted"
    },
    {
      "x": 3,
      "y": 1,
      "z": 6,
      "name": "Plant_Bramble_Moss_Twisted"
    },
    {
      "x": 3,
      "y": 2,
      "z": 6,
      "name": "Plant_Bramble_Moss_Twisted"
    },
    {
      "x": 3,
      "y": 3,
      "z": 6,
      "name": "Plant_Bramble_Moss_Twisted"
    },
    {
      "x": 3,
      "y": 4,
      "z": 6,
      "name": "Plant_Bramble_Moss_Twisted"
    },
    {
      "x": 3,
      "y": 0,
      "z": 7,
      "name": "Plant_Bramble_Moss_Twisted"
    },
    {
      "x": 3,
      "y": 1,
      "z": 7,
      "name": "Plant_Bramble_Moss_Twisted"
    },
    {
      "x": 3,
      "y": 2,
      "z": 7,
      "name": "Plant_Bramble_Moss_Twisted"
    },
    {
      "x": 3,
      "y": 3,
      "z": 7,
      "name": "Plant_Bramble_Moss_Twisted"
    },
    {
      "x": 3,
      "y": 4,
      "z": 7,
      "name": "Plant_Bramble_Moss_Twisted"
    },
    {
      "x": 3,
      "y": 1,
      "z": 8,
      "name": "Plant_Bramble_Moss_Twisted"
    },
    {
      "x": 3,
      "y": 2,
      "z": 8,
      "name": "Plant_Bramble_Moss_Twisted"
    },
    {
      "x": 3,
      "y": 3,
      "z": 8,
      "name": "Plant_Bramble_Moss_Twisted"
    },
    {
      "x": 3,
      "y": 4,
      "z": 8,
      "name": "Plant_Bramble_Moss_Twisted"
    },
    {
      "x": 3,
      "y": 2,
      "z": 9,
      "name": "Plant_Bramble_Moss_Twisted"
    },
    {
      "x": 3,
      "y": 3,
      "z": 9,
      "name": "Plant_Bramble_Moss_Twisted"
    },
    {
      "x": 4,
      "y": 1,
      "z": 2,
      "name": "Plant_Bramble_Moss_Twisted"
    },
    {
      "x": 4,
      "y": 2,
      "z": 2,
      "name": "Plant_Bramble_Moss_Twisted"
    },
    {
      "x": 4,
      "y": 3,
      "z": 2,
      "name": "Plant_Bramble_Moss_Twisted"
    },
    {
      "x": 4,
      "y": 1,
      "z": 3,
      "name": "Plant_Bramble_Moss_Twisted"
    },
    {
      "x": 4,
      "y": 2,
      "z": 3,
      "name": "Plant_Bramble_Moss_Twisted"
    },
    {
      "x": 4,
      "y": 3,
      "z": 3,
      "name": "Plant_Bramble_Moss_Twisted"
    },
    {
      "x": 4,
      "y": 0,
      "z": 4,
      "name": "Plant_Bramble_Moss_Twisted"
    },
    {
      "x": 4,
      "y": 1,
      "z": 4,
      "name": "Plant_Bramble_Moss_Twisted"
    },
    {
      "x": 4,
      "y": 2,
      "z": 4,
      "name": "Plant_Bramble_Moss_Twisted"
    },
    {
      "x": 4,
      "y": 3,
      "z": 4,
      "name": "Plant_Bramble_Moss_Twisted"
    },
    {
      "x": 4,
      "y": 4,
      "z": 4,
      "name": "Plant_Bramble_Moss_Twisted"
    },
    {
      "x": 4,
      "y": 0,
      "z": 5,
      "name": "Plant_Bramble_Moss_Twisted"
    },
    {
      "x": 4,
      "y": 1,
      "z": 5,
      "name": "Plant_Bramble_Moss_Twisted"
    },
    {
      "x": 4,
      "y": 2,
      "z": 5,
      "name": "Plant_Bramble_Moss_Twisted"
    },
    {
      "x": 4,
      "y": 3,
      "z": 5,
      "name": "Plant_Bramble_Moss_Twisted"
    },
    {
      "x": 4,
      "y": 4,
      "z": 5,
      "name": "Plant_Bramble_Moss_Twisted"
    },
    {
      "x": 4,
      "y": 0,
      "z": 6,
      "name": "Plant_Bramble_Moss_Twisted"
    },
    {
      "x": 4,
      "y": 1,
      "z": 6,
      "name": "Plant_Bramble_Moss_Twisted"
    },
    {
      "x": 4,
      "y": 2,
      "z": 6,
      "name": "Plant_Bramble_Moss_Twisted"
    },
    {
      "x": 4,
      "y": 3,
      "z": 6,
      "name": "Plant_Bramble_Moss_Twisted"
    },
    {
      "x": 4,
      "y": 4,
      "z": 6,
      "name": "Plant_Bramble_Moss_Twisted"
    },
    {
      "x": 4,
      "y": 0,
      "z": 7,
      "name": "Plant_Bramble_Moss_Twisted"
    },
    {
      "x": 4,
      "y": 1,
      "z": 7,
      "name": "Plant_Bramble_Moss_Twisted"
    },
    {
      "x": 4,
      "y": 2,
      "z": 7,
      "name": "Plant_Bramble_Moss_Twisted"
    },
    {
      "x": 4,
      "y": 3,
      "z": 7,
      "name": "Plant_Bramble_Moss_Twisted"
    },
    {
      "x": 4,
      "y": 4,
      "z": 7,
      "name": "Plant_Bramble_Moss_Twisted"
    },
    {
      "x": 4,
      "y": 5,
      "z": 7,
      "name": "Plant_Bramble_Moss_Twisted"
    },
    {
      "x": 4,
      "y": 0,
      "z": 8,
      "name": "Plant_Bramble_Moss_Twisted"
    },
    {
      "x": 4,
      "y": 1,
      "z": 8,
      "name": "Plant_Bramble_Moss_Twisted"
    },
    {
      "x": 4,
      "y": 2,
      "z": 8,
      "name": "Plant_Bramble_Moss_Twisted"
    },
    {
      "x": 4,
      "y": 3,
      "z": 8,
      "name": "Plant_Bramble_Moss_Twisted"
    },
    {
      "x": 4,
      "y": 4,
      "z": 8,
      "name": "Plant_Bramble_Moss_Twisted"
    },
    {
      "x": 4,
      "y": 5,
      "z": 8,
      "name": "Plant_Bramble_Moss_Twisted"
    },
    {
      "x": 4,
      "y": 1,
      "z": 9,
      "name": "Plant_Bramble_Moss_Twisted"
    },
    {
      "x": 4,
      "y": 2,
      "z": 9,
      "name": "Plant_Bramble_Moss_Twisted"
    },
    {
      "x": 4,
      "y": 3,
      "z": 9,
      "name": "Plant_Bramble_Moss_Twisted"
    },
    {
      "x": 4,
      "y": 4,
      "z": 9,
      "name": "Plant_Bramble_Moss_Twisted"
    },
    {
      "x": 4,
      "y": 2,
      "z": 10,
      "name": "Plant_Bramble_Moss_Twisted"
    },
    {
      "x": 4,
      "y": 3,
      "z": 10,
      "name": "Plant_Bramble_Moss_Twisted"
    },
    {
      "x": 5,
      "y": 1,
      "z": 3,
      "name": "Plant_Bramble_Moss_Twisted"
    },
    {
      "x": 5,
      "y": 2,
      "z": 3,
      "name": "Plant_Bramble_Moss_Twisted"
    },
    {
      "x": 5,
      "y": 0,
      "z": 4,
      "name": "Plant_Bramble_Moss_Twisted"
    },
    {
      "x": 5,
      "y": 1,
      "z": 4,
      "name": "Plant_Bramble_Moss_Twisted"
    },
    {
      "x": 5,
      "y": 2,
      "z": 4,
      "name": "Plant_Bramble_Moss_Twisted"
    },
    {
      "x": 5,
      "y": 3,
      "z": 4,
      "name": "Plant_Bramble_Moss_Twisted"
    },
    {
      "x": 5,
      "y": 1,
      "z": 5,
      "name": "Plant_Bramble_Moss_Twisted"
    },
    {
      "x": 5,
      "y": 2,
      "z": 5,
      "name": "Plant_Bramble_Moss_Twisted"
    },
    {
      "x": 5,
      "y": 3,
      "z": 5,
      "name": "Plant_Bramble_Moss_Twisted"
    },
    {
      "x": 5,
      "y": 4,
      "z": 5,
      "name": "Plant_Bramble_Moss_Twisted"
    },
    {
      "x": 5,
      "y": 1,
      "z": 6,
      "name": "Plant_Bramble_Moss_Twisted"
    },
    {
      "x": 5,
      "y": 2,
      "z": 6,
      "name": "Plant_Bramble_Moss_Twisted"
    },
    {
      "x": 5,
      "y": 3,
      "z": 6,
      "name": "Plant_Bramble_Moss_Twisted"
    },
    {
      "x": 5,
      "y": 4,
      "z": 6,
      "name": "Plant_Bramble_Moss_Twisted"
    },
    {
      "x": 5,
      "y": 0,
      "z": 7,
      "name": "Plant_Bramble_Moss_Twisted"
    },
    {
      "x": 5,
      "y": 1,
      "z": 7,
      "name": "Plant_Bramble_Moss_Twisted"
    },
    {
      "x": 5,
      "y": 2,
      "z": 7,
      "name": "Plant_Bramble_Moss_Twisted"
    },
    {
      "x": 5,
      "y": 3,
      "z": 7,
      "name": "Plant_Bramble_Moss_Twisted"
    },
    {
      "x": 5,
      "y": 4,
      "z": 7,
      "name": "Plant_Bramble_Moss_Twisted"
    },
    {
      "x": 5,
      "y": 1,
      "z": 8,
      "name": "Plant_Bramble_Moss_Twisted"
    },
    {
      "x": 5,
      "y": 2,
      "z": 8,
      "name": "Plant_Bramble_Moss_Twisted"
    },
    {
      "x": 5,
      "y": 3,
      "z": 8,
      "name": "Plant_Bramble_Moss_Twisted"
    },
    {
      "x": 5,
      "y": 4,
      "z": 8,
      "name": "Plant_Bramble_Moss_Twisted"
    },
    {
      "x": 5,
      "y": 5,
      "z": 8,
      "name": "Plant_Bramble_Moss_Twisted"
    },
    {
      "x": 5,
      "y": 2,
      "z": 9,
      "name": "Plant_Bramble_Moss_Twisted"
    },
    {
      "x": 5,
      "y": 3,
      "z": 9,
      "name": "Plant_Bramble_Moss_Twisted"
    },
    {
      "x": 5,
      "y": 4,
      "z": 9,
      "name": "Plant_Bramble_Moss_Twisted"
    },
    {
      "x": 6,
      "y": 3,
      "z": 6,
      "name": "Plant_Bramble_Moss_Twisted"
    },
    {
      "x": 6,
      "y": 1,
      "z": 7,
      "name": "Plant_Bramble_Moss_Twisted"
    },
    {
      "x": 6,
      "y": 2,
      "z": 7,
      "name": "Plant_Bramble_Moss_Twisted"
    },
    {
      "x": 6,
      "y": 3,
      "z": 7,
      "name": "Plant_Bramble_Moss_Twisted"
    },
    {
      "x": 6,
      "y": 2,
      "z": 8,
      "name": "Plant_Bramble_Moss_Twisted"
    },
    {
      "x": 6,
      "y": 3,
      "z": 8,
      "name": "Plant_Bramble_Moss_Twisted"
    },
    {
      "x": 6,
      "y": 4,
      "z": 8,
      "name": "Plant_Bramble_Moss_Twisted"
    }
  ]
}