{
  "version": 8,
  "blockIdVersion": 11,
  "anchorX": 7,
  "anchorY": 2,
  "anchorZ": 5,
  "blocks": [
    {
      "x": 4,
      "y": 3,
      "z": 3,
      "name": "Plant_Bramble_Moss_Twisted"
    },
    {
      "x": 5,
      "y": 1,
      "z": 3,
      "name": "Plant_Bramble_Moss_Twisted"
    },
    {
      "x": 5,
      "y": 3,
      "z": 3,
      "name": "Plant_Bramble_Moss_Twisted"
    },
    {
      "x": 5,
      "y": 1,
      "z": 4,
      "name": "Plant_Bramble_Moss_Twisted"
    },
    {
      "x": 5,
      "y": 2,
      "z": 4,
      "name": "Plant_Bramble_Moss_Twisted"
    },
    {
      "x": 5,
      "y": 3,
      "z": 4,
      "name": "Plant_Bramble_Moss_Twisted"
    },
    {
      "x": 5,
      "y": 4,
      "z": 4,
      "name": "Plant_Bramble_Moss_Twisted"
    },
    {
      "x": 5,
      "y": 1,
      "z": 5,
      "name": "Plant_Bramble_Moss_Twisted"
    },
    {
      "x": 5,
      "y": 2,
      "z": 5,
      "name": "Plant_Bramble_Moss_Twisted"
    },
    {
      "x": 5,
      "y": 3,
      "z": 5,
      "name": "Plant_Bramble_Moss_Twisted"
    },
    {
      "x": 5,
      "y": 1,
      "z": 6,
      "name": "Plant_Bramble_Moss_Twisted"
    },
    {
      "x": 5,
      "y": 2,
      "z": 6,
      "name": "Plant_Bramble_Moss_Twisted"
    },
    {
      "x": 5,
      "y": 3,
      "z": 6,
      "name": "Plant_Bramble_Moss_Twisted"
    },
    {
      "x": 5,
      "y": 1,
      "z": 7,
      "name": "Plant_Bramble_Moss_Twisted"
    },
    {
      "x": 5,
      "y": 3,
      "z": 7,
      "name": "Plant_Bramble_Moss_Twisted"
    },
    {
      "x": 5,
      "y": 3,
      "z": 8,
      "name": "Plant_Bramble_Moss_Twisted"
    },
    {
      "x": 6,
      "y": 2,
      "z": 2,
      "name": "Plant_Bramble_Moss_Twisted"
    },
    {
      "x": 6,
      "y": 3,
      "z": 2,
      "name": "Plant_Bramble_Moss_Twisted"
    },
    {
      "x": 6,
      "y": 0,
      "z": 3,
      "name": "Plant_Bramble_Moss_Twisted"
    },
    {
      "x": 6,
      "y": 1,
      "z": 3,
      "name": "Plant_Bramble_Moss_Twisted"
    },
    {
      "x": 6,
      "y": 2,
      "z": 3,
      "name": "Plant_Bramble_Moss_Twisted"
    },
    {
      "x": 6,
      "y": 3,
      "z": 3,
      "name": "Plant_Bramble_Moss_Twisted"
    },
    {
      "x": 6,
      "y": 4,
      "z": 3,
      "name": "Plant_Bramble_Moss_Twisted"
    },
    {
      "x": 6,
      "y": 0,
      "z": 4,
      "name": "Plant_Bramble_Moss_Twisted"
    },
    {
      "x": 6,
      "y": 1,
      "z": 4,
      "name": "Plant_Bramble_Moss_Twisted"
    },
    {
      "x": 6,
      "y": 2,
      "z": 4,
      "name": "Plant_Bramble_Moss_Twisted"
    },
    {
      "x": 6,
      "y": 3,
      "z": 4,
      "name": "Plant_Bramble_Moss_Twisted"
    },
    {
      "x": 6,
      "y": 4,
      "z": 4,
      "name": "Plant_Bramble_Moss_Twisted"
    },
    {
      "x": 6,
      "y": 5,
      "z": 4,
      "name": "Plant_Bramble_Moss_Twisted"
    },
    {
      "x": 6,
      "y": 0,
      "z": 5,
      "name": "Plant_Bramble_Moss_Twisted"
    },
    {
      "x": 6,
      "y": 1,
      "z": 5,
      "name": "Plant_Bramble_Moss_Twisted"
    },
    {
      "x": 6,
      "y": 2,
      "z": 5,
      "name": "Plant_Bramble_Moss_Twisted"
    },
    {
      "x": 6,
      "y": 3,
      "z": 5,
      "name": "Plant_Bramble_Moss_Twisted"
    },
    {
      "x": 6,
      "y": 4,
      "z": 5,
      "name": "Plant_Bramble_Moss_Twisted"
    },
    {
      "x": 6,
      "y": 0,
      "z": 6,
      "name": "Plant_Bramble_Moss_Twisted"
    },
    {
      "x": 6,
      "y": 1,
      "z": 6,
      "name": "Plant_Bramble_Moss_Twisted"
    },
    {
      "x": 6,
      "y": 2,
      "z": 6,
      "name": "Plant_Bramble_Moss_Twisted"
    },
    {
      "x": 6,
      "y": 3,
      "z": 6,
      "name": "Plant_Bramble_Moss_Twisted"
    },
    {
      "x": 6,
      "y": 4,
      "z": 6,
      "name": "Plant_Bramble_Moss_Twisted"
    },
    {
      "x": 6,
      "y": 1,
      "z": 7,
      "name": "Plant_Bramble_Moss_Twisted"
    },
    {
      "x": 6,
      "y": 2,
      "z": 7,
      "name": "Plant_Bramble_Moss_Twisted"
    },
    {
      "x": 6,
      "y": 3,
      "z": 7,
      "name": "Plant_Bramble_Moss_Twisted"
    },
    {
      "x": 6,
      "y": 4,
      "z": 7,
      "name": "Plant_Bramble_Moss_Twisted"
    },
    {
      "x": 6,
      "y": 1,
      "z": 8,
      "name": "Plant_Bramble_Moss_Twisted"
    },
    {
      "x": 6,
      "y": 2,
      "z": 8,
      "name": "Plant_Bramble_Moss_Twisted"
    },
    {
      "x": 6,
      "y": 3,
      "z": 8,
      "name": "Plant_Bramble_Moss_Twisted"
    },
    {
      "x": 6,
      "y": 4,
      "z": 8,
      "name": "Plant_Bramble_Moss_Twisted"
    },
    {
      "x": 6,
      "y": 3,
      "z": 9,
      "name": "Plant_Bramble_Moss_Twisted"
    },
    {
      "x": 7,
      "y": 2,
      "z": 1,
      "name": "Plant_Bramble_Moss_Twisted"
    },
    {
      "x": 7,
      "y": 1,
      "z": 2,
      "name": "Plant_Bramble_Moss_Twisted"
    },
    {
      "x": 7,
      "y": 2,
      "z": 2,
      "name": "Plant_Bramble_Moss_Twisted"
    },
    {
      "x": 7,
      "y": 3,
      "z": 2,
      "name": "Plant_Bramble_Moss_Twisted"
    },
    {
      "x": 7,
      "y": 4,
      "z": 2,
      "name": "Plant_Bramble_Moss_Twisted"
    },
    {
      "x": 7,
      "y": 1,
      "z": 3,
      "name": "Plant_Bramble_Moss_Twisted"
    },
    {
      "x": 7,
      "y": 2,
      "z": 3,
      "name": "Plant_Bramble_Moss_Twisted"
    },
    {
      "x": 7,
      "y": 3,
      "z": 3,
      "name": "Plant_Bramble_Moss_Twisted"
    },
    {
      "x": 7,
      "y": 4,
      "z": 3,
      "name": "Plant_Bramble_Moss_Twisted"
    },
    {
      "x": 7,
      "y": 5,
      "z": 3,
      "name": "Plant_Bramble_Moss_Twisted"
    },
    {
      "x": 7,
      "y": 0,
      "z": 4,
      "name": "Plant_Bramble_Moss_Twisted"
    },
    {
      "x": 7,
      "y": 1,
      "z": 4,
      "name": "Plant_Bramble_Moss_Twisted"
    },
    {
      "x": 7,
      "y": 2,
      "z": 4,
      "name": "Plant_Bramble_Moss_Twisted"
    },
    {
      "x": 7,
      "y": 3,
      "z": 4,
      "name": "Plant_Bramble_Moss_Twisted"
    },
    {
      "x": 7,
      "y": 4,
      "z": 4,
      "name": "Plant_Bramble_Moss_Twisted"
    },
    {
      "x": 7,
      "y": 5,
      "z": 4,
      "name": "Plant_Bramble_Moss_Twisted"
    },
    {
      "x": 7,
      "y": 0,
      "z": 5,
      "name": "Plant_Bramble_Moss_Twisted"
    },
    {
      "x": 7,
      "y": 1,
      "z": 5,
      "name": "Plant_Bramble_Moss_Twisted"
    },
    {
      "x": 7,
      "y": 2,
      "z": 5,
      "name": "Plant_Bramble_Moss_Twisted"
    },
    {
      "x": 7,
      "y": 3,
      "z": 5,
      "name": "Plant_Bramble_Moss_Twisted"
    },
    {
      "x": 7,
      "y": 4,
      "z": 5,
      "name": "Plant_Bramble_Moss_Twisted"
    },
    {
      "x": 7,
      "y": 5,
      "z": 5,
      "name": "Plant_Bramble_Moss_Twisted"
    },
    {
      "x": 7,
      "y": 0,
      "z": 6,
      "name": "Plant_Bramble_Moss_Twisted"
    },
    {
      "x": 7,
      "y": 1,
      "z": 6,
      "name": "Plant_Bramble_Moss_Twisted"
    },
    {
      "x": 7,
      "y": 2,
      "z": 6,
      "name": "Plant_Bramble_Moss_Twisted"
    },
    {
      "x": 7,
      "y": 3,
      "z": 6,
      "name": "Plant_Bramble_Moss_Twisted"
    },
    {
      "x": 7,
      "y": 4,
      "z": 6,
      "name": "Plant_Bramble_Moss_Twisted"
    },
    {
      "x": 7,
      "y": 5,
      "z": 6,
      "name": "Plant_Bramble_Moss_Twisted"
    },
    {
      "x": 7,
      "y": 1,
      "z": 7,
      "name": "Plant_Bramble_Moss_Twisted"
    },
    {
      "x": 7,
      "y": 2,
      "z": 7,
      "name": "Plant_Bramble_Moss_Twisted"
    },
    {
      "x": 7,
      "y": 3,
      "z": 7,
      "name": "Plant_Bramble_Moss_Twisted"
    },
    {
      "x": 7,
      "y": 4,
      "z": 7,
      "name": "Plant_Bramble_Moss_Twisted"
    },
    {
      "x": 7,
      "y": 5,
      "z": 7,
      "name": "Plant_Bramble_Moss_Twisted"
    },
    {
      "x": 7,
      "y": 1,
      "z": 8,
      "name": "Plant_Bramble_Moss_Twisted"
    },
    {
      "x": 7,
      "y": 2,
      "z": 8,
      "name": "Plant_Bramble_Moss_Twisted"
    },
    {
      "x": 7,
      "y": 3,
      "z": 8,
      "name": "Plant_Bramble_Moss_Twisted"
    },
    {
      "x": 7,
      "y": 4,
      "z": 8,
      "name": "Plant_Bramble_Moss_Twisted"
    },
    {
      "x": 7,
      "y": 2,
      "z": 9,
      "name": "Plant_Bramble_Moss_Twisted"
    },
    {
      "x": 7,
      "y": 3,
      "z": 9,
      "name": "Plant_Bramble_Moss_Twisted"
    },
    {
      "x": 7,
      "y": 4,
      "z": 9,
      "name": "Plant_Bramble_Moss_Twisted"
    },
    {
      "x": 8,
      "y": 2,
      "z": 1,
      "name": "Plant_Bramble_Moss_Twisted"
    },
    {
      "x": 8,
      "y": 3,
      "z": 1,
      "name": "Plant_Bramble_Moss_Twisted"
    },
    {
      "x": 8,
      "y": 2,
      "z": 2,
      "name": "Plant_Bramble_Moss_Twisted"
    },
    {
      "x": 8,
      "y": 3,
      "z": 2,
      "name": "Plant_Bramble_Moss_Twisted"
    },
    {
      "x": 8,
      "y": 4,
      "z": 2,
      "name": "Plant_Bramble_Moss_Twisted"
    },
    {
      "x": 8,
      "y": 1,
      "z": 3,
      "name": "Plant_Bramble_Moss_Twisted"
    },
    {
      "x": 8,
      "y": 2,
      "z": 3,
      "name": "Plant_Bramble_Moss_Twisted"
    },
    {
      "x": 8,
      "y": 3,
      "z": 3,
      "name": "Plant_Bramble_Moss_Twisted"
    },
    {
      "x": 8,
      "y": 4,
      "z": 3,
      "name": "Plant_Bramble_Moss_Twisted"
    },
    {
      "x": 8,
      "y": 1,
      "z": 4,
      "name": "Plant_Bramble_Moss_Twisted"
    },
    {
      "x": 8,
      "y": 2,
      "z": 4,
      "name": "Plant_Bramble_Moss_Twisted"
    },
    {
      "x": 8,
      "y": 3,
      "z": 4,
      "name": "Plant_Bramble_Moss_Twisted"
    },
    {
      "x": 8,
      "y": 4,
      "z": 4,
      "name": "Plant_Bramble_Moss_Twisted"
    },
    {
      "x": 8,
      "y": 0,
      "z": 5,
      "name": "Plant_Bramble_Moss_Twisted"
    },
    {
      "x": 8,
      "y": 1,
      "z": 5,
      "name": "Plant_Bramble_Moss_Twisted"
    },
    {
      "x": 8,
      "y": 2,
      "z": 5,
      "name": "Plant_Bramble_Moss_Twisted"
    },
    {
      "x": 8,
      "y": 3,
      "z": 5,
      "name": "Plant_Bramble_Moss_Twisted"
    },
    {
      "x": 8,
      "y": 4,
      "z": 5,
      "name": "Plant_Bramble_Moss_Twisted"
    },
    {
      "x": 8,
      "y": 1,
      "z": 6,
      "name": "Plant_Bramble_Moss_Twisted"
    },
    {
      "x": 8,
      "y": 2,
      "z": 6,
      "name": "Plant_Bramble_Moss_Twisted"
    },
    {
      "x": 8,
      "y": 3,
      "z": 6,
      "name": "Plant_Bramble_Moss_Twisted"
    },
    {
      "x": 8,
      "y": 4,
      "z": 6,
      "name": "Plant_Bramble_Moss_Twisted"
    },
    {
      "x": 8,
      "y": 1,
      "z": 7,
      "name": "Plant_Bramble_Moss_Twisted"
    },
    {
      "x": 8,
      "y": 2,
      "z": 7,
      "name": "Plant_Bramble_Moss_Twisted"
    },
    {
      "x": 8,
      "y": 3,
      "z": 7,
      "name": "Plant_Bramble_Moss_Twisted"
    },
    {
      "x": 8,
      "y": 4,
      "z": 7,
      "name": "Plant_Bramble_Moss_Twisted"
    },
    {
      "x": 8,
      "y": 5,
      "z": 7,
      "name": "Plant_Bramble_Moss_Twisted"
    },
    {
      "x": 8,
      "y": 1,
      "z": 8,
      "name": "Plant_Bramble_Moss_Twisted"
    },
    {
      "x": 8,
      "y": 2,
      "z": 8,
      "name": "Plant_Bramble_Moss_Twisted"
    },
    {
      "x": 8,
      "y": 3,
      "z": 8,
      "name": "Plant_Bramble_Moss_Twisted"
    },
    {
      "x": 8,
      "y": 4,
      "z": 8,
      "name": "Plant_Bramble_Moss_Twisted"
    },
    {
      "x": 8,
      "y": 3,
      "z": 9,
      "name": "Plant_Bramble_Moss_Twisted"
    },
    {
      "x": 9,
      "y": 3,
      "z": 2,
      "name": "Plant_Bramble_Moss_Twisted"
    },
    {
      "x": 9,
      "y": 2,
      "z": 3,
      "name": "Plant_Bramble_Moss_Twisted"
    },
    {
      "x": 9,
      "y": 3,
      "z": 3,
      "name": "Plant_Bramble_Moss_Twisted"
    },
    {
      "x": 9,
      "y": 4,
      "z": 3,
      "name": "Plant_Bramble_Moss_Twisted"
    },
    {
      "x": 9,
      "y": 2,
      "z": 4,
      "name": "Plant_Bramble_Moss_Twisted"
    },
    {
      "x": 9,
      "y": 3,
      "z": 4,
      "name": "Plant_Bramble_Moss_Twisted"
    },
    {
      "x": 9,
      "y": 1,
      "z": 5,
      "name": "Plant_Bramble_Moss_Twisted"
    },
    {
      "x": 9,
      "y": 2,
      "z": 5,
      "name": "Plant_Bramble_Moss_Twisted"
    },
    {
      "x": 9,
      "y": 2,
      "z": 6,
      "name": "Plant_Bramble_Moss_Twisted"
    },
    {
      "x": 9,
      "y": 3,
      "z": 6,
      "name": "Plant_Bramble_Moss_Twisted"
    },
    {
      "x": 9,
      "y": 1,
      "z": 7,
      "name": "Plant_Bramble_Moss_Twisted"
    },
    {
      "x": 9,
      "y": 2,
      "z": 7,
      "name": "Plant_Bramble_Moss_Twisted"
    },
    {
      "x": 9,
      "y": 3,
      "z": 7,
      "name": "Plant_Bramble_Moss_Twisted"
    },
    {
      "x": 9,
      "y": 4,
      "z": 7,
      "name": "Plant_Bramble_Moss_Twisted"
    },
    {
      "x": 9,
      "y": 3,
      "z": 8,
      "name": "Plant_Bramble_Moss_Twisted"
    },
    {
      "x": 10,
      "y": 3,
      "z": 3,
      "name": "Plant_Bramble_Moss_Twisted"
    }
  ]
}