{
  "version": 8,
  "blockIdVersion": 11,
  "anchorX": -11,
  "anchorY": 18,
  "anchorZ": -4,
  "blocks": [
    {
      "x": -52,
      "y": 31,
      "z": 11,
      "name": "Rock_Ice"
    },
    {
      "x": -52,
      "y": 32,
      "z": 11,
      "name": "Rock_Ice"
    },
    {
      "x": -52,
      "y": 33,
      "z": 11,
      "name": "Soil_Snow"
    },
    {
      "x": -52,
      "y": 31,
      "z": 12,
      "name": "Rock_Ice"
    },
    {
      "x": -52,
      "y": 32,
      "z": 12,
      "name": "Rock_Ice"
    },
    {
      "x": -52,
      "y": 33,
      "z": 12,
      "name": "Rock_Ice"
    },
    {
      "x": -52,
      "y": 34,
      "z": 12,
      "name": "Rock_Ice"
    },
    {
      "x": -52,
      "y": 35,
      "z": 12,
      "name": "Rock_Ice"
    },
    {
      "x": -52,
      "y": 36,
      "z": 12,
      "name": "Soil_Snow"
    },
    {
      "x": -52,
      "y": 30,
      "z": 13,
      "name": "Rock_Ice"
    },
    {
      "x": -52,
      "y": 31,
      "z": 13,
      "name": "Rock_Ice"
    },
    {
      "x": -52,
      "y": 32,
      "z": 13,
      "name": "Rock_Ice"
    },
    {
      "x": -52,
      "y": 33,
      "z": 13,
      "name": "Rock_Ice"
    },
    {
      "x": -52,
      "y": 34,
      "z": 13,
      "name": "Rock_Ice"
    },
    {
      "x": -52,
      "y": 35,
      "z": 13,
      "name": "Rock_Ice"
    },
    {
      "x": -52,
      "y": 36,
      "z": 13,
      "name": "Rock_Ice"
    },
    {
      "x": -52,
      "y": 37,
      "z": 13,
      "name": "Soil_Snow"
    },
    {
      "x": -52,
      "y": 29,
      "z": 14,
      "name": "Rock_Ice"
    },
    {
      "x": -52,
      "y": 30,
      "z": 14,
      "name": "Rock_Ice"
    },
    {
      "x": -52,
      "y": 31,
      "z": 14,
      "name": "Rock_Ice"
    },
    {
      "x": -52,
      "y": 32,
      "z": 14,
      "name": "Rock_Ice"
    },
    {
      "x": -52,
      "y": 33,
      "z": 14,
      "name": "Rock_Ice"
    },
    {
      "x": -52,
      "y": 34,
      "z": 14,
      "name": "Rock_Ice"
    },
    {
      "x": -52,
      "y": 35,
      "z": 14,
      "name": "Rock_Ice_Permafrost"
    },
    {
      "x": -52,
      "y": 36,
      "z": 14,
      "name": "Rock_Ice"
    },
    {
      "x": -52,
      "y": 37,
      "z": 14,
      "name": "Rock_Ice"
    },
    {
      "x": -52,
      "y": 38,
      "z": 14,
      "name": "Soil_Snow"
    },
    {
      "x": -52,
      "y": 29,
      "z": 15,
      "name": "Rock_Ice"
    },
    {
      "x": -52,
      "y": 30,
      "z": 15,
      "name": "Rock_Ice"
    },
    {
      "x": -52,
      "y": 31,
      "z": 15,
      "name": "Rock_Ice"
    },
    {
      "x": -52,
      "y": 32,
      "z": 15,
      "name": "Rock_Ice"
    },
    {
      "x": -52,
      "y": 33,
      "z": 15,
      "name": "Rock_Ice"
    },
    {
      "x": -52,
      "y": 34,
      "z": 15,
      "name": "Rock_Ice_Permafrost"
    },
    {
      "x": -52,
      "y": 35,
      "z": 15,
      "name": "Rock_Ice"
    },
    {
      "x": -52,
      "y": 36,
      "z": 15,
      "name": "Rock_Ice_Permafrost"
    },
    {
      "x": -52,
      "y": 37,
      "z": 15,
      "name": "Rock_Ice"
    },
    {
      "x": -52,
      "y": 38,
      "z": 15,
      "name": "Soil_Snow"
    },
    {
      "x": -52,
      "y": 29,
      "z": 16,
      "name": "Rock_Ice"
    },
    {
      "x": -52,
      "y": 30,
      "z": 16,
      "name": "Rock_Ice"
    },
    {
      "x": -52,
      "y": 31,
      "z": 16,
      "name": "Rock_Ice"
    },
    {
      "x": -52,
      "y": 32,
      "z": 16,
      "name": "Rock_Ice"
    },
    {
      "x": -52,
      "y": 33,
      "z": 16,
      "name": "Rock_Ice"
    },
    {
      "x": -52,
      "y": 34,
      "z": 16,
      "name": "Rock_Ice"
    },
    {
      "x": -52,
      "y": 35,
      "z": 16,
      "name": "Rock_Ice_Permafrost"
    },
    {
      "x": -52,
      "y": 36,
      "z": 16,
      "name": "Rock_Ice_Permafrost"
    },
    {
      "x": -52,
      "y": 37,
      "z": 16,
      "name": "Rock_Ice"
    },
    {
      "x": -52,
      "y": 38,
      "z": 16,
      "name": "Soil_Snow"
    },
    {
      "x": -52,
      "y": 28,
      "z": 17,
      "name": "Rock_Ice"
    },
    {
      "x": -52,
      "y": 29,
      "z": 17,
      "name": "Rock_Ice"
    },
    {
      "x": -52,
      "y": 30,
      "z": 17,
      "name": "Rock_Ice"
    },
    {
      "x": -52,
      "y": 31,
      "z": 17,
      "name": "Rock_Ice"
    },
    {
      "x": -52,
      "y": 32,
      "z": 17,
      "name": "Rock_Ice"
    },
    {
      "x": -52,
      "y": 33,
      "z": 17,
      "name": "Rock_Ice"
    },
    {
      "x": -52,
      "y": 34,
      "z": 17,
      "name": "Rock_Ice_Permafrost"
    },
    {
      "x": -52,
      "y": 35,
      "z": 17,
      "name": "Rock_Ice_Permafrost"
    },
    {
      "x": -52,
      "y": 36,
      "z": 17,
      "name": "Rock_Ice"
    },
    {
      "x": -52,
      "y": 37,
      "z": 17,
      "name": "Rock_Ice_Permafrost"
    },
    {
      "x": -52,
      "y": 28,
      "z": 18,
      "name": "Rock_Ice"
    },
    {
      "x": -52,
      "y": 29,
      "z": 18,
      "name": "Rock_Ice"
    },
    {
      "x": -52,
      "y": 30,
      "z": 18,
      "name": "Rock_Ice"
    },
    {
      "x": -52,
      "y": 31,
      "z": 18,
      "name": "Rock_Ice"
    },
    {
      "x": -52,
      "y": 32,
      "z": 18,
      "name": "Rock_Ice"
    },
    {
      "x": -52,
      "y": 33,
      "z": 18,
      "name": "Rock_Ice"
    },
    {
      "x": -52,
      "y": 34,
      "z": 18,
      "name": "Rock_Ice_Permafrost"
    },
    {
      "x": -52,
      "y": 35,
      "z": 18,
      "name": "Rock_Ice"
    },
    {
      "x": -52,
      "y": 36,
      "z": 18,
      "name": "Rock_Ice_Permafrost"
    },
    {
      "x": -52,
      "y": 28,
      "z": 19,
      "name": "Rock_Ice"
    },
    {
      "x": -52,
      "y": 29,
      "z": 19,
      "name": "Rock_Ice"
    },
    {
      "x": -52,
      "y": 30,
      "z": 19,
      "name": "Rock_Ice"
    },
    {
      "x": -52,
      "y": 31,
      "z": 19,
      "name": "Rock_Ice"
    },
    {
      "x": -52,
      "y": 32,
      "z": 19,
      "name": "Rock_Ice_Permafrost"
    },
    {
      "x": -52,
      "y": 33,
      "z": 19,
      "name": "Rock_Ice"
    },
    {
      "x": -52,
      "y": 34,
      "z": 19,
      "name": "Soil_Snow"
    },
    {
      "x": -52,
      "y": 28,
      "z": 20,
      "name": "Rock_Ice"
    },
    {
      "x": -52,
      "y": 29,
      "z": 20,
      "name": "Rock_Ice"
    },
    {
      "x": -52,
      "y": 30,
      "z": 20,
      "name": "Rock_Ice"
    },
    {
      "x": -52,
      "y": 31,
      "z": 20,
      "name": "Rock_Ice"
    },
    {
      "x": -52,
      "y": 32,
      "z": 20,
      "name": "Rock_Ice"
    },
    {
      "x": -52,
      "y": 33,
      "z": 20,
      "name": "Rock_Ice_Permafrost"
    },
    {
      "x": -52,
      "y": 29,
      "z": 21,
      "name": "Rock_Ice"
    },
    {
      "x": -52,
      "y": 30,
      "z": 21,
      "name": "Rock_Ice"
    },
    {
      "x": -51,
      "y": 32,
      "z": 8,
      "name": "Rock_Ice"
    },
    {
      "x": -51,
      "y": 33,
      "z": 8,
      "name": "Soil_Snow"
    },
    {
      "x": -51,
      "y": 31,
      "z": 9,
      "name": "Rock_Ice"
    },
    {
      "x": -51,
      "y": 32,
      "z": 9,
      "name": "Rock_Ice"
    },
    {
      "x": -51,
      "y": 33,
      "z": 9,
      "name": "Rock_Ice"
    },
    {
      "x": -51,
      "y": 34,
      "z": 9,
      "name": "Rock_Ice"
    },
    {
      "x": -51,
      "y": 35,
      "z": 9,
      "name": "Soil_Snow"
    },
    {
      "x": -51,
      "y": 30,
      "z": 10,
      "name": "Rock_Ice"
    },
    {
      "x": -51,
      "y": 31,
      "z": 10,
      "name": "Rock_Ice"
    },
    {
      "x": -51,
      "y": 32,
      "z": 10,
      "name": "Rock_Ice"
    },
    {
      "x": -51,
      "y": 33,
      "z": 10,
      "name": "Rock_Ice"
    },
    {
      "x": -51,
      "y": 34,
      "z": 10,
      "name": "Rock_Ice"
    },
    {
      "x": -51,
      "y": 35,
      "z": 10,
      "name": "Rock_Ice"
    },
    {
      "x": -51,
      "y": 36,
      "z": 10,
      "name": "Rock_Ice"
    },
    {
      "x": -51,
      "y": 37,
      "z": 10,
      "name": "Soil_Snow"
    },
    {
      "x": -51,
      "y": 29,
      "z": 11,
      "name": "Rock_Ice"
    },
    {
      "x": -51,
      "y": 30,
      "z": 11,
      "name": "Rock_Ice"
    },
    {
      "x": -51,
      "y": 31,
      "z": 11,
      "name": "Rock_Ice"
    },
    {
      "x": -51,
      "y": 32,
      "z": 11,
      "name": "Rock_Ice"
    },
    {
      "x": -51,
      "y": 33,
      "z": 11,
      "name": "Rock_Ice"
    },
    {
      "x": -51,
      "y": 34,
      "z": 11,
      "name": "Rock_Ice"
    },
    {
      "x": -51,
      "y": 35,
      "z": 11,
      "name": "Rock_Ice"
    },
    {
      "x": -51,
      "y": 36,
      "z": 11,
      "name": "Rock_Ice"
    },
    {
      "x": -51,
      "y": 37,
      "z": 11,
      "name": "Rock_Ice"
    },
    {
      "x": -51,
      "y": 38,
      "z": 11,
      "name": "Soil_Snow"
    },
    {
      "x": -51,
      "y": 28,
      "z": 12,
      "name": "Rock_Ice"
    },
    {
      "x": -51,
      "y": 29,
      "z": 12,
      "name": "Rock_Ice"
    },
    {
      "x": -51,
      "y": 30,
      "z": 12,
      "name": "Rock_Ice"
    },
    {
      "x": -51,
      "y": 31,
      "z": 12,
      "name": "Rock_Ice"
    },
    {
      "x": -51,
      "y": 32,
      "z": 12,
      "name": "Rock_Ice"
    },
    {
      "x": -51,
      "y": 33,
      "z": 12,
      "name": "Rock_Ice"
    },
    {
      "x": -51,
      "y": 34,
      "z": 12,
      "name": "Rock_Ice"
    },
    {
      "x": -51,
      "y": 35,
      "z": 12,
      "name": "Rock_Ice"
    },
    {
      "x": -51,
      "y": 36,
      "z": 12,
      "name": "Rock_Ice"
    },
    {
      "x": -51,
      "y": 37,
      "z": 12,
      "name": "Rock_Ice"
    },
    {
      "x": -51,
      "y": 38,
      "z": 12,
      "name": "Rock_Ice"
    },
    {
      "x": -51,
      "y": 39,
      "z": 12,
      "name": "Soil_Snow"
    },
    {
      "x": -51,
      "y": 27,
      "z": 13,
      "name": "Rock_Ice"
    },
    {
      "x": -51,
      "y": 28,
      "z": 13,
      "name": "Rock_Ice"
    },
    {
      "x": -51,
      "y": 29,
      "z": 13,
      "name": "Rock_Ice"
    },
    {
      "x": -51,
      "y": 30,
      "z": 13,
      "name": "Rock_Ice"
    },
    {
      "x": -51,
      "y": 31,
      "z": 13,
      "name": "Rock_Ice"
    },
    {
      "x": -51,
      "y": 32,
      "z": 13,
      "name": "Rock_Ice"
    },
    {
      "x": -51,
      "y": 33,
      "z": 13,
      "name": "Rock_Ice"
    },
    {
      "x": -51,
      "y": 34,
      "z": 13,
      "name": "Rock_Ice"
    },
    {
      "x": -51,
      "y": 35,
      "z": 13,
      "name": "Rock_Ice"
    },
    {
      "x": -51,
      "y": 36,
      "z": 13,
      "name": "Rock_Ice"
    },
    {
      "x": -51,
      "y": 37,
      "z": 13,
      "name": "Rock_Ice_Permafrost"
    },
    {
      "x": -51,
      "y": 38,
      "z": 13,
      "name": "Rock_Ice"
    },
    {
      "x": -51,
      "y": 39,
      "z": 13,
      "name": "Soil_Snow"
    },
    {
      "x": -51,
      "y": 26,
      "z": 14,
      "name": "Rock_Ice"
    },
    {
      "x": -51,
      "y": 27,
      "z": 14,
      "name": "Rock_Ice"
    },
    {
      "x": -51,
      "y": 28,
      "z": 14,
      "name": "Rock_Ice"
    },
    {
      "x": -51,
      "y": 29,
      "z": 14,
      "name": "Rock_Ice"
    },
    {
      "x": -51,
      "y": 30,
      "z": 14,
      "name": "Rock_Ice"
    },
    {
      "x": -51,
      "y": 31,
      "z": 14,
      "name": "Rock_Ice"
    },
    {
      "x": -51,
      "y": 32,
      "z": 14,
      "name": "Rock_Ice"
    },
    {
      "x": -51,
      "y": 33,
      "z": 14,
      "name": "Rock_Ice"
    },
    {
      "x": -51,
      "y": 34,
      "z": 14,
      "name": "Rock_Ice"
    },
    {
      "x": -51,
      "y": 35,
      "z": 14,
      "name": "Rock_Ice_Permafrost"
    },
    {
      "x": -51,
      "y": 36,
      "z": 14,
      "name": "Rock_Ice_Permafrost"
    },
    {
      "x": -51,
      "y": 37,
      "z": 14,
      "name": "Rock_Ice_Permafrost"
    },
    {
      "x": -51,
      "y": 38,
      "z": 14,
      "name": "Rock_Ice_Permafrost"
    },
    {
      "x": -51,
      "y": 39,
      "z": 14,
      "name": "Rock_Ice"
    },
    {
      "x": -51,
      "y": 40,
      "z": 14,
      "name": "Soil_Snow"
    },
    {
      "x": -51,
      "y": 26,
      "z": 15,
      "name": "Rock_Ice"
    },
    {
      "x": -51,
      "y": 27,
      "z": 15,
      "name": "Rock_Ice"
    },
    {
      "x": -51,
      "y": 28,
      "z": 15,
      "name": "Rock_Ice"
    },
    {
      "x": -51,
      "y": 29,
      "z": 15,
      "name": "Rock_Ice"
    },
    {
      "x": -51,
      "y": 30,
      "z": 15,
      "name": "Rock_Ice"
    },
    {
      "x": -51,
      "y": 31,
      "z": 15,
      "name": "Rock_Ice"
    },
    {
      "x": -51,
      "y": 32,
      "z": 15,
      "name": "Rock_Ice"
    },
    {
      "x": -51,
      "y": 33,
      "z": 15,
      "name": "Rock_Ice"
    },
    {
      "x": -51,
      "y": 34,
      "z": 15,
      "name": "Rock_Ice"
    },
    {
      "x": -51,
      "y": 35,
      "z": 15,
      "name": "Rock_Ice"
    },
    {
      "x": -51,
      "y": 36,
      "z": 15,
      "name": "Rock_Ice_Permafrost"
    },
    {
      "x": -51,
      "y": 37,
      "z": 15,
      "name": "Rock_Ice_Permafrost"
    },
    {
      "x": -51,
      "y": 38,
      "z": 15,
      "name": "Rock_Ice"
    },
    {
      "x": -51,
      "y": 39,
      "z": 15,
      "name": "Soil_Snow"
    },
    {
      "x": -51,
      "y": 26,
      "z": 16,
      "name": "Rock_Ice"
    },
    {
      "x": -51,
      "y": 27,
      "z": 16,
      "name": "Rock_Ice"
    },
    {
      "x": -51,
      "y": 28,
      "z": 16,
      "name": "Rock_Ice"
    },
    {
      "x": -51,
      "y": 29,
      "z": 16,
      "name": "Rock_Ice"
    },
    {
      "x": -51,
      "y": 30,
      "z": 16,
      "name": "Rock_Ice"
    },
    {
      "x": -51,
      "y": 31,
      "z": 16,
      "name": "Rock_Ice"
    },
    {
      "x": -51,
      "y": 32,
      "z": 16,
      "name": "Rock_Ice"
    },
    {
      "x": -51,
      "y": 33,
      "z": 16,
      "name": "Rock_Ice"
    },
    {
      "x": -51,
      "y": 34,
      "z": 16,
      "name": "Rock_Ice_Permafrost"
    },
    {
      "x": -51,
      "y": 35,
      "z": 16,
      "name": "Rock_Ice_Permafrost"
    },
    {
      "x": -51,
      "y": 36,
      "z": 16,
      "name": "Rock_Ice_Permafrost"
    },
    {
      "x": -51,
      "y": 37,
      "z": 16,
      "name": "Rock_Ice"
    },
    {
      "x": -51,
      "y": 38,
      "z": 16,
      "name": "Soil_Snow"
    },
    {
      "x": -51,
      "y": 25,
      "z": 17,
      "name": "Rock_Ice"
    },
    {
      "x": -51,
      "y": 26,
      "z": 17,
      "name": "Rock_Ice"
    },
    {
      "x": -51,
      "y": 27,
      "z": 17,
      "name": "Rock_Ice"
    },
    {
      "x": -51,
      "y": 28,
      "z": 17,
      "name": "Rock_Ice"
    },
    {
      "x": -51,
      "y": 29,
      "z": 17,
      "name": "Rock_Ice"
    },
    {
      "x": -51,
      "y": 30,
      "z": 17,
      "name": "Rock_Ice"
    },
    {
      "x": -51,
      "y": 31,
      "z": 17,
      "name": "Rock_Ice"
    },
    {
      "x": -51,
      "y": 32,
      "z": 17,
      "name": "Rock_Ice"
    },
    {
      "x": -51,
      "y": 33,
      "z": 17,
      "name": "Rock_Ice"
    },
    {
      "x": -51,
      "y": 34,
      "z": 17,
      "name": "Rock_Ice_Permafrost"
    },
    {
      "x": -51,
      "y": 35,
      "z": 17,
      "name": "Rock_Ice_Permafrost"
    },
    {
      "x": -51,
      "y": 36,
      "z": 17,
      "name": "Rock_Ice_Permafrost"
    },
    {
      "x": -51,
      "y": 37,
      "z": 17,
      "name": "Soil_Snow"
    },
    {
      "x": -51,
      "y": 25,
      "z": 18,
      "name": "Rock_Ice"
    },
    {
      "x": -51,
      "y": 26,
      "z": 18,
      "name": "Rock_Ice"
    },
    {
      "x": -51,
      "y": 27,
      "z": 18,
      "name": "Rock_Ice"
    },
    {
      "x": -51,
      "y": 28,
      "z": 18,
      "name": "Rock_Ice"
    },
    {
      "x": -51,
      "y": 29,
      "z": 18,
      "name": "Rock_Ice"
    },
    {
      "x": -51,
      "y": 30,
      "z": 18,
      "name": "Rock_Ice"
    },
    {
      "x": -51,
      "y": 31,
      "z": 18,
      "name": "Rock_Ice"
    },
    {
      "x": -51,
      "y": 32,
      "z": 18,
      "name": "Rock_Ice"
    },
    {
      "x": -51,
      "y": 33,
      "z": 18,
      "name": "Rock_Ice"
    },
    {
      "x": -51,
      "y": 34,
      "z": 18,
      "name": "Rock_Ice_Permafrost"
    },
    {
      "x": -51,
      "y": 35,
      "z": 18,
      "name": "Rock_Ice_Permafrost"
    },
    {
      "x": -51,
      "y": 36,
      "z": 18,
      "name": "Soil_Snow"
    },
    {
      "x": -51,
      "y": 25,
      "z": 19,
      "name": "Rock_Ice"
    },
    {
      "x": -51,
      "y": 26,
      "z": 19,
      "name": "Rock_Ice"
    },
    {
      "x": -51,
      "y": 27,
      "z": 19,
      "name": "Rock_Ice"
    },
    {
      "x": -51,
      "y": 28,
      "z": 19,
      "name": "Rock_Ice"
    },
    {
      "x": -51,
      "y": 29,
      "z": 19,
      "name": "Rock_Ice"
    },
    {
      "x": -51,
      "y": 30,
      "z": 19,
      "name": "Rock_Ice_Permafrost"
    },
    {
      "x": -51,
      "y": 31,
      "z": 19,
      "name": "Rock_Ice_Permafrost"
    },
    {
      "x": -51,
      "y": 32,
      "z": 19,
      "name": "Rock_Ice"
    },
    {
      "x": -51,
      "y": 33,
      "z": 19,
      "name": "Rock_Ice_Permafrost"
    },
    {
      "x": -51,
      "y": 34,
      "z": 19,
      "name": "Rock_Ice"
    },
    {
      "x": -51,
      "y": 35,
      "z": 19,
      "name": "Soil_Snow"
    },
    {
      "x": -51,
      "y": 25,
      "z": 20,
      "name": "Rock_Ice_Permafrost"
    },
    {
      "x": -51,
      "y": 26,
      "z": 20,
      "name": "Rock_Ice"
    },
    {
      "x": -51,
      "y": 27,
      "z": 20,
      "name": "Rock_Ice"
    },
    {
      "x": -51,
      "y": 28,
      "z": 20,
      "name": "Rock_Ice_Permafrost"
    },
    {
      "x": -51,
      "y": 29,
      "z": 20,
      "name": "Rock_Ice_Permafrost"
    },
    {
      "x": -51,
      "y": 30,
      "z": 20,
      "name": "Rock_Ice_Permafrost"
    },
    {
      "x": -51,
      "y": 31,
      "z": 20,
      "name": "Rock_Ice"
    },
    {
      "x": -51,
      "y": 32,
      "z": 20,
      "name": "Rock_Ice"
    },
    {
      "x": -51,
      "y": 33,
      "z": 20,
      "name": "Soil_Snow"
    },
    {
      "x": -51,
      "y": 25,
      "z": 21,
      "name": "Rock_Ice_Permafrost"
    },
    {
      "x": -51,
      "y": 26,
      "z": 21,
      "name": "Rock_Ice_Permafrost"
    },
    {
      "x": -51,
      "y": 27,
      "z": 21,
      "name": "Rock_Ice_Permafrost"
    },
    {
      "x": -51,
      "y": 28,
      "z": 21,
      "name": "Rock_Ice"
    },
    {
      "x": -51,
      "y": 29,
      "z": 21,
      "name": "Rock_Ice"
    },
    {
      "x": -51,
      "y": 30,
      "z": 21,
      "name": "Rock_Ice"
    },
    {
      "x": -50,
      "y": 32,
      "z": 6,
      "name": "Rock_Ice"
    },
    {
      "x": -50,
      "y": 33,
      "z": 6,
      "name": "Soil_Snow"
    },
    {
      "x": -50,
      "y": 30,
      "z": 7,
      "name": "Rock_Ice"
    },
    {
      "x": -50,
      "y": 31,
      "z": 7,
      "name": "Rock_Ice"
    },
    {
      "x": -50,
      "y": 32,
      "z": 7,
      "name": "Rock_Ice"
    },
    {
      "x": -50,
      "y": 33,
      "z": 7,
      "name": "Rock_Ice"
    },
    {
      "x": -50,
      "y": 34,
      "z": 7,
      "name": "Rock_Ice"
    },
    {
      "x": -50,
      "y": 35,
      "z": 7,
      "name": "Soil_Snow"
    },
    {
      "x": -50,
      "y": 29,
      "z": 8,
      "name": "Rock_Ice"
    },
    {
      "x": -50,
      "y": 30,
      "z": 8,
      "name": "Rock_Ice"
    },
    {
      "x": -50,
      "y": 31,
      "z": 8,
      "name": "Rock_Ice"
    },
    {
      "x": -50,
      "y": 32,
      "z": 8,
      "name": "Rock_Ice"
    },
    {
      "x": -50,
      "y": 33,
      "z": 8,
      "name": "Rock_Ice"
    },
    {
      "x": -50,
      "y": 34,
      "z": 8,
      "name": "Rock_Ice"
    },
    {
      "x": -50,
      "y": 35,
      "z": 8,
      "name": "Rock_Ice"
    },
    {
      "x": -50,
      "y": 36,
      "z": 8,
      "name": "Rock_Ice"
    },
    {
      "x": -50,
      "y": 37,
      "z": 8,
      "name": "Soil_Snow"
    },
    {
      "x": -50,
      "y": 28,
      "z": 9,
      "name": "Rock_Ice"
    },
    {
      "x": -50,
      "y": 29,
      "z": 9,
      "name": "Rock_Ice"
    },
    {
      "x": -50,
      "y": 30,
      "z": 9,
      "name": "Rock_Ice"
    },
    {
      "x": -50,
      "y": 31,
      "z": 9,
      "name": "Rock_Ice"
    },
    {
      "x": -50,
      "y": 32,
      "z": 9,
      "name": "Rock_Ice"
    },
    {
      "x": -50,
      "y": 33,
      "z": 9,
      "name": "Rock_Ice"
    },
    {
      "x": -50,
      "y": 34,
      "z": 9,
      "name": "Rock_Ice"
    },
    {
      "x": -50,
      "y": 35,
      "z": 9,
      "name": "Rock_Ice"
    },
    {
      "x": -50,
      "y": 36,
      "z": 9,
      "name": "Rock_Ice"
    },
    {
      "x": -50,
      "y": 37,
      "z": 9,
      "name": "Rock_Ice"
    },
    {
      "x": -50,
      "y": 38,
      "z": 9,
      "name": "Soil_Snow"
    },
    {
      "x": -50,
      "y": 27,
      "z": 10,
      "name": "Rock_Ice"
    },
    {
      "x": -50,
      "y": 28,
      "z": 10,
      "name": "Rock_Ice"
    },
    {
      "x": -50,
      "y": 29,
      "z": 10,
      "name": "Rock_Ice"
    },
    {
      "x": -50,
      "y": 30,
      "z": 10,
      "name": "Rock_Ice"
    },
    {
      "x": -50,
      "y": 31,
      "z": 10,
      "name": "Rock_Ice"
    },
    {
      "x": -50,
      "y": 32,
      "z": 10,
      "name": "Rock_Ice"
    },
    {
      "x": -50,
      "y": 33,
      "z": 10,
      "name": "Rock_Ice"
    },
    {
      "x": -50,
      "y": 34,
      "z": 10,
      "name": "Rock_Ice"
    },
    {
      "x": -50,
      "y": 35,
      "z": 10,
      "name": "Rock_Ice"
    },
    {
      "x": -50,
      "y": 36,
      "z": 10,
      "name": "Rock_Ice"
    },
    {
      "x": -50,
      "y": 37,
      "z": 10,
      "name": "Rock_Ice_Permafrost"
    },
    {
      "x": -50,
      "y": 38,
      "z": 10,
      "name": "Rock_Ice"
    },
    {
      "x": -50,
      "y": 39,
      "z": 10,
      "name": "Soil_Snow"
    },
    {
      "x": -50,
      "y": 26,
      "z": 11,
      "name": "Rock_Ice"
    },
    {
      "x": -50,
      "y": 27,
      "z": 11,
      "name": "Rock_Ice"
    },
    {
      "x": -50,
      "y": 28,
      "z": 11,
      "name": "Rock_Ice"
    },
    {
      "x": -50,
      "y": 29,
      "z": 11,
      "name": "Rock_Ice"
    },
    {
      "x": -50,
      "y": 30,
      "z": 11,
      "name": "Rock_Ice"
    },
    {
      "x": -50,
      "y": 31,
      "z": 11,
      "name": "Rock_Ice"
    },
    {
      "x": -50,
      "y": 32,
      "z": 11,
      "name": "Rock_Ice"
    },
    {
      "x": -50,
      "y": 33,
      "z": 11,
      "name": "Rock_Ice"
    },
    {
      "x": -50,
      "y": 34,
      "z": 11,
      "name": "Rock_Ice"
    },
    {
      "x": -50,
      "y": 35,
      "z": 11,
      "name": "Rock_Ice"
    },
    {
      "x": -50,
      "y": 36,
      "z": 11,
      "name": "Rock_Ice_Permafrost"
    },
    {
      "x": -50,
      "y": 37,
      "z": 11,
      "name": "Rock_Ice"
    },
    {
      "x": -50,
      "y": 38,
      "z": 11,
      "name": "Rock_Ice_Permafrost"
    },
    {
      "x": -50,
      "y": 39,
      "z": 11,
      "name": "Rock_Ice"
    },
    {
      "x": -50,
      "y": 40,
      "z": 11,
      "name": "Soil_Snow"
    },
    {
      "x": -50,
      "y": 25,
      "z": 12,
      "name": "Rock_Ice"
    },
    {
      "x": -50,
      "y": 26,
      "z": 12,
      "name": "Rock_Ice"
    },
    {
      "x": -50,
      "y": 27,
      "z": 12,
      "name": "Rock_Ice"
    },
    {
      "x": -50,
      "y": 28,
      "z": 12,
      "name": "Rock_Ice"
    },
    {
      "x": -50,
      "y": 29,
      "z": 12,
      "name": "Rock_Ice"
    },
    {
      "x": -50,
      "y": 30,
      "z": 12,
      "name": "Rock_Ice"
    },
    {
      "x": -50,
      "y": 31,
      "z": 12,
      "name": "Rock_Ice"
    },
    {
      "x": -50,
      "y": 32,
      "z": 12,
      "name": "Rock_Ice"
    },
    {
      "x": -50,
      "y": 33,
      "z": 12,
      "name": "Rock_Ice"
    },
    {
      "x": -50,
      "y": 34,
      "z": 12,
      "name": "Rock_Ice"
    },
    {
      "x": -50,
      "y": 35,
      "z": 12,
      "name": "Rock_Ice"
    },
    {
      "x": -50,
      "y": 36,
      "z": 12,
      "name": "Rock_Ice"
    },
    {
      "x": -50,
      "y": 37,
      "z": 12,
      "name": "Rock_Ice_Permafrost"
    },
    {
      "x": -50,
      "y": 38,
      "z": 12,
      "name": "Rock_Ice_Permafrost"
    },
    {
      "x": -50,
      "y": 39,
      "z": 12,
      "name": "Rock_Ice"
    },
    {
      "x": -50,
      "y": 40,
      "z": 12,
      "name": "Soil_Snow"
    },
    {
      "x": -50,
      "y": 25,
      "z": 13,
      "name": "Rock_Ice"
    },
    {
      "x": -50,
      "y": 26,
      "z": 13,
      "name": "Rock_Ice"
    },
    {
      "x": -50,
      "y": 27,
      "z": 13,
      "name": "Rock_Ice"
    },
    {
      "x": -50,
      "y": 28,
      "z": 13,
      "name": "Rock_Ice"
    },
    {
      "x": -50,
      "y": 29,
      "z": 13,
      "name": "Rock_Ice"
    },
    {
      "x": -50,
      "y": 30,
      "z": 13,
      "name": "Rock_Ice"
    },
    {
      "x": -50,
      "y": 31,
      "z": 13,
      "name": "Rock_Ice"
    },
    {
      "x": -50,
      "y": 32,
      "z": 13,
      "name": "Rock_Ice"
    },
    {
      "x": -50,
      "y": 33,
      "z": 13,
      "name": "Rock_Ice"
    },
    {
      "x": -50,
      "y": 34,
      "z": 13,
      "name": "Rock_Ice"
    },
    {
      "x": -50,
      "y": 35,
      "z": 13,
      "name": "Rock_Ice"
    },
    {
      "x": -50,
      "y": 36,
      "z": 13,
      "name": "Rock_Ice"
    },
    {
      "x": -50,
      "y": 37,
      "z": 13,
      "name": "Rock_Ice_Permafrost"
    },
    {
      "x": -50,
      "y": 38,
      "z": 13,
      "name": "Rock_Ice_Permafrost"
    },
    {
      "x": -50,
      "y": 39,
      "z": 13,
      "name": "Rock_Ice_Permafrost"
    },
    {
      "x": -50,
      "y": 40,
      "z": 13,
      "name": "Rock_Ice_Permafrost"
    },
    {
      "x": -50,
      "y": 41,
      "z": 13,
      "name": "Soil_Snow"
    },
    {
      "x": -50,
      "y": 24,
      "z": 14,
      "name": "Rock_Ice"
    },
    {
      "x": -50,
      "y": 25,
      "z": 14,
      "name": "Rock_Ice"
    },
    {
      "x": -50,
      "y": 26,
      "z": 14,
      "name": "Rock_Ice"
    },
    {
      "x": -50,
      "y": 27,
      "z": 14,
      "name": "Rock_Ice"
    },
    {
      "x": -50,
      "y": 28,
      "z": 14,
      "name": "Rock_Ice"
    },
    {
      "x": -50,
      "y": 29,
      "z": 14,
      "name": "Rock_Ice"
    },
    {
      "x": -50,
      "y": 30,
      "z": 14,
      "name": "Rock_Ice"
    },
    {
      "x": -50,
      "y": 31,
      "z": 14,
      "name": "Rock_Ice"
    },
    {
      "x": -50,
      "y": 32,
      "z": 14,
      "name": "Rock_Ice"
    },
    {
      "x": -50,
      "y": 33,
      "z": 14,
      "name": "Rock_Ice"
    },
    {
      "x": -50,
      "y": 34,
      "z": 14,
      "name": "Rock_Ice"
    },
    {
      "x": -50,
      "y": 35,
      "z": 14,
      "name": "Rock_Ice"
    },
    {
      "x": -50,
      "y": 36,
      "z": 14,
      "name": "Rock_Ice_Permafrost"
    },
    {
      "x": -50,
      "y": 37,
      "z": 14,
      "name": "Rock_Ice_Permafrost"
    },
    {
      "x": -50,
      "y": 38,
      "z": 14,
      "name": "Rock_Ice_Permafrost"
    },
    {
      "x": -50,
      "y": 39,
      "z": 14,
      "name": "Rock_Ice"
    },
    {
      "x": -50,
      "y": 40,
      "z": 14,
      "name": "Soil_Snow"
    },
    {
      "x": -50,
      "y": 24,
      "z": 15,
      "name": "Rock_Ice"
    },
    {
      "x": -50,
      "y": 25,
      "z": 15,
      "name": "Rock_Ice"
    },
    {
      "x": -50,
      "y": 26,
      "z": 15,
      "name": "Rock_Ice"
    },
    {
      "x": -50,
      "y": 27,
      "z": 15,
      "name": "Rock_Ice"
    },
    {
      "x": -50,
      "y": 28,
      "z": 15,
      "name": "Rock_Ice"
    },
    {
      "x": -50,
      "y": 29,
      "z": 15,
      "name": "Rock_Ice"
    },
    {
      "x": -50,
      "y": 30,
      "z": 15,
      "name": "Rock_Ice"
    },
    {
      "x": -50,
      "y": 31,
      "z": 15,
      "name": "Rock_Ice"
    },
    {
      "x": -50,
      "y": 32,
      "z": 15,
      "name": "Rock_Ice"
    },
    {
      "x": -50,
      "y": 33,
      "z": 15,
      "name": "Rock_Ice"
    },
    {
      "x": -50,
      "y": 34,
      "z": 15,
      "name": "Rock_Ice"
    },
    {
      "x": -50,
      "y": 35,
      "z": 15,
      "name": "Rock_Ice"
    },
    {
      "x": -50,
      "y": 36,
      "z": 15,
      "name": "Rock_Ice_Permafrost"
    },
    {
      "x": -50,
      "y": 37,
      "z": 15,
      "name": "Rock_Ice_Permafrost"
    },
    {
      "x": -50,
      "y": 38,
      "z": 15,
      "name": "Rock_Ice"
    },
    {
      "x": -50,
      "y": 39,
      "z": 15,
      "name": "Soil_Snow"
    },
    {
      "x": -50,
      "y": 23,
      "z": 16,
      "name": "Rock_Ice"
    },
    {
      "x": -50,
      "y": 24,
      "z": 16,
      "name": "Rock_Ice"
    },
    {
      "x": -50,
      "y": 25,
      "z": 16,
      "name": "Rock_Ice"
    },
    {
      "x": -50,
      "y": 26,
      "z": 16,
      "name": "Rock_Ice"
    },
    {
      "x": -50,
      "y": 27,
      "z": 16,
      "name": "Rock_Ice"
    },
    {
      "x": -50,
      "y": 28,
      "z": 16,
      "name": "Rock_Ice"
    },
    {
      "x": -50,
      "y": 29,
      "z": 16,
      "name": "Rock_Ice"
    },
    {
      "x": -50,
      "y": 30,
      "z": 16,
      "name": "Rock_Ice"
    },
    {
      "x": -50,
      "y": 31,
      "z": 16,
      "name": "Rock_Ice"
    },
    {
      "x": -50,
      "y": 32,
      "z": 16,
      "name": "Rock_Ice"
    },
    {
      "x": -50,
      "y": 33,
      "z": 16,
      "name": "Rock_Ice"
    },
    {
      "x": -50,
      "y": 34,
      "z": 16,
      "name": "Rock_Ice"
    },
    {
      "x": -50,
      "y": 35,
      "z": 16,
      "name": "Rock_Ice_Permafrost"
    },
    {
      "x": -50,
      "y": 36,
      "z": 16,
      "name": "Rock_Ice_Permafrost"
    },
    {
      "x": -50,
      "y": 37,
      "z": 16,
      "name": "Rock_Ice"
    },
    {
      "x": -50,
      "y": 38,
      "z": 16,
      "name": "Soil_Snow"
    },
    {
      "x": -50,
      "y": 23,
      "z": 17,
      "name": "Rock_Ice"
    },
    {
      "x": -50,
      "y": 24,
      "z": 17,
      "name": "Rock_Ice"
    },
    {
      "x": -50,
      "y": 25,
      "z": 17,
      "name": "Rock_Ice"
    },
    {
      "x": -50,
      "y": 26,
      "z": 17,
      "name": "Rock_Ice"
    },
    {
      "x": -50,
      "y": 27,
      "z": 17,
      "name": "Rock_Ice"
    },
    {
      "x": -50,
      "y": 28,
      "z": 17,
      "name": "Rock_Ice"
    },
    {
      "x": -50,
      "y": 29,
      "z": 17,
      "name": "Rock_Ice"
    },
    {
      "x": -50,
      "y": 30,
      "z": 17,
      "name": "Rock_Ice"
    },
    {
      "x": -50,
      "y": 31,
      "z": 17,
      "name": "Rock_Ice"
    },
    {
      "x": -50,
      "y": 32,
      "z": 17,
      "name": "Rock_Ice"
    },
    {
      "x": -50,
      "y": 33,
      "z": 17,
      "name": "Rock_Ice"
    },
    {
      "x": -50,
      "y": 34,
      "z": 17,
      "name": "Rock_Ice"
    },
    {
      "x": -50,
      "y": 35,
      "z": 17,
      "name": "Rock_Ice"
    },
    {
      "x": -50,
      "y": 36,
      "z": 17,
      "name": "Rock_Ice"
    },
    {
      "x": -50,
      "y": 37,
      "z": 17,
      "name": "Soil_Snow"
    },
    {
      "x": -50,
      "y": 23,
      "z": 18,
      "name": "Rock_Ice"
    },
    {
      "x": -50,
      "y": 24,
      "z": 18,
      "name": "Rock_Ice"
    },
    {
      "x": -50,
      "y": 25,
      "z": 18,
      "name": "Rock_Ice"
    },
    {
      "x": -50,
      "y": 26,
      "z": 18,
      "name": "Rock_Ice"
    },
    {
      "x": -50,
      "y": 27,
      "z": 18,
      "name": "Rock_Ice"
    },
    {
      "x": -50,
      "y": 28,
      "z": 18,
      "name": "Rock_Ice"
    },
    {
      "x": -50,
      "y": 29,
      "z": 18,
      "name": "Rock_Ice"
    },
    {
      "x": -50,
      "y": 30,
      "z": 18,
      "name": "Rock_Ice"
    },
    {
      "x": -50,
      "y": 31,
      "z": 18,
      "name": "Rock_Ice"
    },
    {
      "x": -50,
      "y": 32,
      "z": 18,
      "name": "Rock_Ice"
    },
    {
      "x": -50,
      "y": 33,
      "z": 18,
      "name": "Rock_Ice"
    },
    {
      "x": -50,
      "y": 34,
      "z": 18,
      "name": "Rock_Ice_Permafrost"
    },
    {
      "x": -50,
      "y": 35,
      "z": 18,
      "name": "Rock_Ice"
    },
    {
      "x": -50,
      "y": 36,
      "z": 18,
      "name": "Soil_Snow"
    },
    {
      "x": -50,
      "y": 23,
      "z": 19,
      "name": "Rock_Ice"
    },
    {
      "x": -50,
      "y": 24,
      "z": 19,
      "name": "Rock_Ice"
    },
    {
      "x": -50,
      "y": 25,
      "z": 19,
      "name": "Rock_Ice"
    },
    {
      "x": -50,
      "y": 26,
      "z": 19,
      "name": "Rock_Ice"
    },
    {
      "x": -50,
      "y": 27,
      "z": 19,
      "name": "Rock_Ice"
    },
    {
      "x": -50,
      "y": 28,
      "z": 19,
      "name": "Rock_Ice"
    },
    {
      "x": -50,
      "y": 29,
      "z": 19,
      "name": "Rock_Ice"
    },
    {
      "x": -50,
      "y": 30,
      "z": 19,
      "name": "Rock_Ice_Permafrost"
    },
    {
      "x": -50,
      "y": 31,
      "z": 19,
      "name": "Rock_Ice"
    },
    {
      "x": -50,
      "y": 32,
      "z": 19,
      "name": "Rock_Ice_Permafrost"
    },
    {
      "x": -50,
      "y": 33,
      "z": 19,
      "name": "Rock_Ice"
    },
    {
      "x": -50,
      "y": 34,
      "z": 19,
      "name": "Rock_Ice_Permafrost"
    },
    {
      "x": -50,
      "y": 35,
      "z": 19,
      "name": "Rock_Ice"
    },
    {
      "x": -50,
      "y": 36,
      "z": 19,
      "name": "Soil_Snow"
    },
    {
      "x": -50,
      "y": 23,
      "z": 20,
      "name": "Rock_Ice"
    },
    {
      "x": -50,
      "y": 24,
      "z": 20,
      "name": "Rock_Ice"
    },
    {
      "x": -50,
      "y": 25,
      "z": 20,
      "name": "Rock_Ice"
    },
    {
      "x": -50,
      "y": 26,
      "z": 20,
      "name": "Rock_Ice_Permafrost"
    },
    {
      "x": -50,
      "y": 27,
      "z": 20,
      "name": "Rock_Ice"
    },
    {
      "x": -50,
      "y": 28,
      "z": 20,
      "name": "Rock_Ice_Permafrost"
    },
    {
      "x": -50,
      "y": 29,
      "z": 20,
      "name": "Rock_Ice"
    },
    {
      "x": -50,
      "y": 30,
      "z": 20,
      "name": "Rock_Ice"
    },
    {
      "x": -50,
      "y": 31,
      "z": 20,
      "name": "Rock_Ice"
    },
    {
      "x": -50,
      "y": 32,
      "z": 20,
      "name": "Rock_Ice"
    },
    {
      "x": -50,
      "y": 33,
      "z": 20,
      "name": "Rock_Ice"
    },
    {
      "x": -50,
      "y": 34,
      "z": 20,
      "name": "Soil_Snow"
    },
    {
      "x": -50,
      "y": 23,
      "z": 21,
      "name": "Rock_Ice_Permafrost"
    },
    {
      "x": -50,
      "y": 24,
      "z": 21,
      "name": "Rock_Ice"
    },
    {
      "x": -50,
      "y": 25,
      "z": 21,
      "name": "Rock_Ice_Permafrost"
    },
    {
      "x": -50,
      "y": 26,
      "z": 21,
      "name": "Rock_Ice"
    },
    {
      "x": -50,
      "y": 27,
      "z": 21,
      "name": "Rock_Ice"
    },
    {
      "x": -50,
      "y": 28,
      "z": 21,
      "name": "Rock_Ice"
    },
    {
      "x": -50,
      "y": 29,
      "z": 21,
      "name": "Rock_Ice"
    },
    {
      "x": -50,
      "y": 30,
      "z": 21,
      "name": "Rock_Ice"
    },
    {
      "x": -50,
      "y": 31,
      "z": 21,
      "name": "Soil_Snow"
    },
    {
      "x": -50,
      "y": 26,
      "z": 22,
      "name": "Rock_Ice"
    },
    {
      "x": -50,
      "y": 27,
      "z": 22,
      "name": "Rock_Ice"
    },
    {
      "x": -50,
      "y": 28,
      "z": 22,
      "name": "Rock_Ice"
    },
    {
      "x": -50,
      "y": 29,
      "z": 22,
      "name": "Soil_Snow"
    },
    {
      "x": -49,
      "y": 33,
      "z": 3,
      "name": "Soil_Snow"
    },
    {
      "x": -49,
      "y": 31,
      "z": 4,
      "name": "Rock_Ice"
    },
    {
      "x": -49,
      "y": 32,
      "z": 4,
      "name": "Rock_Ice"
    },
    {
      "x": -49,
      "y": 33,
      "z": 4,
      "name": "Rock_Ice"
    },
    {
      "x": -49,
      "y": 34,
      "z": 4,
      "name": "Soil_Snow"
    },
    {
      "x": -49,
      "y": 29,
      "z": 5,
      "name": "Rock_Ice"
    },
    {
      "x": -49,
      "y": 30,
      "z": 5,
      "name": "Rock_Ice"
    },
    {
      "x": -49,
      "y": 31,
      "z": 5,
      "name": "Rock_Ice"
    },
    {
      "x": -49,
      "y": 32,
      "z": 5,
      "name": "Rock_Ice"
    },
    {
      "x": -49,
      "y": 33,
      "z": 5,
      "name": "Rock_Ice"
    },
    {
      "x": -49,
      "y": 34,
      "z": 5,
      "name": "Rock_Ice"
    },
    {
      "x": -49,
      "y": 35,
      "z": 5,
      "name": "Soil_Snow"
    },
    {
      "x": -49,
      "y": 28,
      "z": 6,
      "name": "Rock_Ice"
    },
    {
      "x": -49,
      "y": 29,
      "z": 6,
      "name": "Rock_Ice"
    },
    {
      "x": -49,
      "y": 30,
      "z": 6,
      "name": "Rock_Ice"
    },
    {
      "x": -49,
      "y": 31,
      "z": 6,
      "name": "Rock_Ice"
    },
    {
      "x": -49,
      "y": 32,
      "z": 6,
      "name": "Rock_Ice"
    },
    {
      "x": -49,
      "y": 33,
      "z": 6,
      "name": "Rock_Ice"
    },
    {
      "x": -49,
      "y": 34,
      "z": 6,
      "name": "Rock_Ice"
    },
    {
      "x": -49,
      "y": 35,
      "z": 6,
      "name": "Rock_Ice"
    },
    {
      "x": -49,
      "y": 36,
      "z": 6,
      "name": "Soil_Snow"
    },
    {
      "x": -49,
      "y": 26,
      "z": 7,
      "name": "Rock_Ice"
    },
    {
      "x": -49,
      "y": 27,
      "z": 7,
      "name": "Rock_Ice"
    },
    {
      "x": -49,
      "y": 28,
      "z": 7,
      "name": "Rock_Ice"
    },
    {
      "x": -49,
      "y": 29,
      "z": 7,
      "name": "Rock_Ice"
    },
    {
      "x": -49,
      "y": 30,
      "z": 7,
      "name": "Rock_Ice"
    },
    {
      "x": -49,
      "y": 31,
      "z": 7,
      "name": "Rock_Ice"
    },
    {
      "x": -49,
      "y": 32,
      "z": 7,
      "name": "Rock_Ice"
    },
    {
      "x": -49,
      "y": 33,
      "z": 7,
      "name": "Rock_Ice"
    },
    {
      "x": -49,
      "y": 34,
      "z": 7,
      "name": "Rock_Ice"
    },
    {
      "x": -49,
      "y": 35,
      "z": 7,
      "name": "Rock_Ice"
    },
    {
      "x": -49,
      "y": 36,
      "z": 7,
      "name": "Rock_Ice"
    },
    {
      "x": -49,
      "y": 37,
      "z": 7,
      "name": "Rock_Ice"
    },
    {
      "x": -49,
      "y": 38,
      "z": 7,
      "name": "Soil_Snow"
    },
    {
      "x": -49,
      "y": 26,
      "z": 8,
      "name": "Rock_Ice"
    },
    {
      "x": -49,
      "y": 27,
      "z": 8,
      "name": "Rock_Ice"
    },
    {
      "x": -49,
      "y": 28,
      "z": 8,
      "name": "Rock_Ice"
    },
    {
      "x": -49,
      "y": 29,
      "z": 8,
      "name": "Rock_Ice"
    },
    {
      "x": -49,
      "y": 30,
      "z": 8,
      "name": "Rock_Ice"
    },
    {
      "x": -49,
      "y": 31,
      "z": 8,
      "name": "Rock_Ice"
    },
    {
      "x": -49,
      "y": 32,
      "z": 8,
      "name": "Rock_Ice"
    },
    {
      "x": -49,
      "y": 33,
      "z": 8,
      "name": "Rock_Ice"
    },
    {
      "x": -49,
      "y": 34,
      "z": 8,
      "name": "Rock_Ice"
    },
    {
      "x": -49,
      "y": 35,
      "z": 8,
      "name": "Rock_Ice"
    },
    {
      "x": -49,
      "y": 36,
      "z": 8,
      "name": "Rock_Ice"
    },
    {
      "x": -49,
      "y": 37,
      "z": 8,
      "name": "Rock_Ice"
    },
    {
      "x": -49,
      "y": 38,
      "z": 8,
      "name": "Rock_Ice"
    },
    {
      "x": -49,
      "y": 39,
      "z": 8,
      "name": "Soil_Snow"
    },
    {
      "x": -49,
      "y": 25,
      "z": 9,
      "name": "Rock_Ice"
    },
    {
      "x": -49,
      "y": 26,
      "z": 9,
      "name": "Rock_Ice"
    },
    {
      "x": -49,
      "y": 27,
      "z": 9,
      "name": "Rock_Ice"
    },
    {
      "x": -49,
      "y": 28,
      "z": 9,
      "name": "Rock_Ice"
    },
    {
      "x": -49,
      "y": 29,
      "z": 9,
      "name": "Rock_Ice"
    },
    {
      "x": -49,
      "y": 30,
      "z": 9,
      "name": "Rock_Ice"
    },
    {
      "x": -49,
      "y": 31,
      "z": 9,
      "name": "Rock_Ice"
    },
    {
      "x": -49,
      "y": 32,
      "z": 9,
      "name": "Rock_Ice"
    },
    {
      "x": -49,
      "y": 33,
      "z": 9,
      "name": "Rock_Ice"
    },
    {
      "x": -49,
      "y": 34,
      "z": 9,
      "name": "Rock_Ice"
    },
    {
      "x": -49,
      "y": 35,
      "z": 9,
      "name": "Rock_Ice"
    },
    {
      "x": -49,
      "y": 36,
      "z": 9,
      "name": "Rock_Ice"
    },
    {
      "x": -49,
      "y": 37,
      "z": 9,
      "name": "Rock_Ice"
    },
    {
      "x": -49,
      "y": 38,
      "z": 9,
      "name": "Rock_Ice_Permafrost"
    },
    {
      "x": -49,
      "y": 39,
      "z": 9,
      "name": "Rock_Ice"
    },
    {
      "x": -49,
      "y": 40,
      "z": 9,
      "name": "Soil_Snow"
    },
    {
      "x": -49,
      "y": 24,
      "z": 10,
      "name": "Rock_Ice"
    },
    {
      "x": -49,
      "y": 25,
      "z": 10,
      "name": "Rock_Ice"
    },
    {
      "x": -49,
      "y": 26,
      "z": 10,
      "name": "Rock_Ice"
    },
    {
      "x": -49,
      "y": 27,
      "z": 10,
      "name": "Rock_Ice"
    },
    {
      "x": -49,
      "y": 28,
      "z": 10,
      "name": "Rock_Ice"
    },
    {
      "x": -49,
      "y": 29,
      "z": 10,
      "name": "Rock_Ice"
    },
    {
      "x": -49,
      "y": 30,
      "z": 10,
      "name": "Rock_Ice"
    },
    {
      "x": -49,
      "y": 31,
      "z": 10,
      "name": "Rock_Ice"
    },
    {
      "x": -49,
      "y": 32,
      "z": 10,
      "name": "Rock_Ice"
    },
    {
      "x": -49,
      "y": 33,
      "z": 10,
      "name": "Rock_Ice"
    },
    {
      "x": -49,
      "y": 34,
      "z": 10,
      "name": "Rock_Ice"
    },
    {
      "x": -49,
      "y": 35,
      "z": 10,
      "name": "Rock_Ice"
    },
    {
      "x": -49,
      "y": 36,
      "z": 10,
      "name": "Rock_Ice"
    },
    {
      "x": -49,
      "y": 37,
      "z": 10,
      "name": "Rock_Ice_Permafrost"
    },
    {
      "x": -49,
      "y": 38,
      "z": 10,
      "name": "Rock_Ice_Permafrost"
    },
    {
      "x": -49,
      "y": 39,
      "z": 10,
      "name": "Rock_Ice"
    },
    {
      "x": -49,
      "y": 40,
      "z": 10,
      "name": "Soil_Snow"
    },
    {
      "x": -49,
      "y": 23,
      "z": 11,
      "name": "Rock_Ice"
    },
    {
      "x": -49,
      "y": 24,
      "z": 11,
      "name": "Rock_Ice"
    },
    {
      "x": -49,
      "y": 25,
      "z": 11,
      "name": "Rock_Ice"
    },
    {
      "x": -49,
      "y": 26,
      "z": 11,
      "name": "Rock_Ice"
    },
    {
      "x": -49,
      "y": 27,
      "z": 11,
      "name": "Rock_Ice"
    },
    {
      "x": -49,
      "y": 28,
      "z": 11,
      "name": "Rock_Ice"
    },
    {
      "x": -49,
      "y": 29,
      "z": 11,
      "name": "Rock_Ice"
    },
    {
      "x": -49,
      "y": 30,
      "z": 11,
      "name": "Rock_Ice"
    },
    {
      "x": -49,
      "y": 31,
      "z": 11,
      "name": "Rock_Ice"
    },
    {
      "x": -49,
      "y": 32,
      "z": 11,
      "name": "Rock_Ice"
    },
    {
      "x": -49,
      "y": 33,
      "z": 11,
      "name": "Rock_Ice"
    },
    {
      "x": -49,
      "y": 34,
      "z": 11,
      "name": "Rock_Ice"
    },
    {
      "x": -49,
      "y": 35,
      "z": 11,
      "name": "Rock_Ice"
    },
    {
      "x": -49,
      "y": 36,
      "z": 11,
      "name": "Rock_Ice"
    },
    {
      "x": -49,
      "y": 37,
      "z": 11,
      "name": "Rock_Ice"
    },
    {
      "x": -49,
      "y": 38,
      "z": 11,
      "name": "Rock_Ice_Permafrost"
    },
    {
      "x": -49,
      "y": 39,
      "z": 11,
      "name": "Rock_Ice_Permafrost"
    },
    {
      "x": -49,
      "y": 40,
      "z": 11,
      "name": "Rock_Ice"
    },
    {
      "x": -49,
      "y": 41,
      "z": 11,
      "name": "Soil_Snow"
    },
    {
      "x": -49,
      "y": 23,
      "z": 12,
      "name": "Rock_Ice"
    },
    {
      "x": -49,
      "y": 24,
      "z": 12,
      "name": "Rock_Ice"
    },
    {
      "x": -49,
      "y": 25,
      "z": 12,
      "name": "Rock_Ice"
    },
    {
      "x": -49,
      "y": 26,
      "z": 12,
      "name": "Rock_Ice"
    },
    {
      "x": -49,
      "y": 27,
      "z": 12,
      "name": "Rock_Ice"
    },
    {
      "x": -49,
      "y": 28,
      "z": 12,
      "name": "Rock_Ice"
    },
    {
      "x": -49,
      "y": 29,
      "z": 12,
      "name": "Rock_Ice"
    },
    {
      "x": -49,
      "y": 30,
      "z": 12,
      "name": "Rock_Ice"
    },
    {
      "x": -49,
      "y": 31,
      "z": 12,
      "name": "Rock_Ice"
    },
    {
      "x": -49,
      "y": 32,
      "z": 12,
      "name": "Rock_Ice"
    },
    {
      "x": -49,
      "y": 33,
      "z": 12,
      "name": "Rock_Ice"
    },
    {
      "x": -49,
      "y": 34,
      "z": 12,
      "name": "Rock_Ice"
    },
    {
      "x": -49,
      "y": 35,
      "z": 12,
      "name": "Rock_Ice"
    },
    {
      "x": -49,
      "y": 36,
      "z": 12,
      "name": "Rock_Ice"
    },
    {
      "x": -49,
      "y": 37,
      "z": 12,
      "name": "Rock_Ice_Permafrost"
    },
    {
      "x": -49,
      "y": 38,
      "z": 12,
      "name": "Rock_Ice_Permafrost"
    },
    {
      "x": -49,
      "y": 39,
      "z": 12,
      "name": "Rock_Ice_Permafrost"
    },
    {
      "x": -49,
      "y": 40,
      "z": 12,
      "name": "Rock_Ice"
    },
    {
      "x": -49,
      "y": 41,
      "z": 12,
      "name": "Soil_Snow"
    },
    {
      "x": -49,
      "y": 22,
      "z": 13,
      "name": "Rock_Ice"
    },
    {
      "x": -49,
      "y": 23,
      "z": 13,
      "name": "Rock_Ice"
    },
    {
      "x": -49,
      "y": 24,
      "z": 13,
      "name": "Rock_Ice"
    },
    {
      "x": -49,
      "y": 25,
      "z": 13,
      "name": "Rock_Ice"
    },
    {
      "x": -49,
      "y": 26,
      "z": 13,
      "name": "Rock_Ice"
    },
    {
      "x": -49,
      "y": 27,
      "z": 13,
      "name": "Rock_Ice"
    },
    {
      "x": -49,
      "y": 28,
      "z": 13,
      "name": "Rock_Ice"
    },
    {
      "x": -49,
      "y": 29,
      "z": 13,
      "name": "Rock_Ice"
    },
    {
      "x": -49,
      "y": 30,
      "z": 13,
      "name": "Rock_Ice"
    },
    {
      "x": -49,
      "y": 31,
      "z": 13,
      "name": "Rock_Ice"
    },
    {
      "x": -49,
      "y": 32,
      "z": 13,
      "name": "Rock_Ice"
    },
    {
      "x": -49,
      "y": 33,
      "z": 13,
      "name": "Rock_Ice"
    },
    {
      "x": -49,
      "y": 34,
      "z": 13,
      "name": "Rock_Ice"
    },
    {
      "x": -49,
      "y": 35,
      "z": 13,
      "name": "Rock_Ice_Permafrost"
    },
    {
      "x": -49,
      "y": 36,
      "z": 13,
      "name": "Rock_Ice"
    },
    {
      "x": -49,
      "y": 37,
      "z": 13,
      "name": "Rock_Ice_Permafrost"
    },
    {
      "x": -49,
      "y": 38,
      "z": 13,
      "name": "Rock_Ice_Permafrost"
    },
    {
      "x": -49,
      "y": 39,
      "z": 13,
      "name": "Rock_Ice_Permafrost"
    },
    {
      "x": -49,
      "y": 40,
      "z": 13,
      "name": "Rock_Ice"
    },
    {
      "x": -49,
      "y": 41,
      "z": 13,
      "name": "Rock_Ice_Permafrost"
    },
    {
      "x": -49,
      "y": 22,
      "z": 14,
      "name": "Rock_Ice"
    },
    {
      "x": -49,
      "y": 23,
      "z": 14,
      "name": "Rock_Ice"
    },
    {
      "x": -49,
      "y": 24,
      "z": 14,
      "name": "Rock_Ice"
    },
    {
      "x": -49,
      "y": 25,
      "z": 14,
      "name": "Rock_Ice"
    },
    {
      "x": -49,
      "y": 26,
      "z": 14,
      "name": "Rock_Ice"
    },
    {
      "x": -49,
      "y": 27,
      "z": 14,
      "name": "Rock_Ice"
    },
    {
      "x": -49,
      "y": 28,
      "z": 14,
      "name": "Rock_Ice"
    },
    {
      "x": -49,
      "y": 29,
      "z": 14,
      "name": "Rock_Ice"
    },
    {
      "x": -49,
      "y": 30,
      "z": 14,
      "name": "Rock_Ice"
    },
    {
      "x": -49,
      "y": 31,
      "z": 14,
      "name": "Rock_Ice"
    },
    {
      "x": -49,
      "y": 32,
      "z": 14,
      "name": "Rock_Ice"
    },
    {
      "x": -49,
      "y": 33,
      "z": 14,
      "name": "Rock_Ice"
    },
    {
      "x": -49,
      "y": 34,
      "z": 14,
      "name": "Rock_Ice"
    },
    {
      "x": -49,
      "y": 35,
      "z": 14,
      "name": "Rock_Ice"
    },
    {
      "x": -49,
      "y": 36,
      "z": 14,
      "name": "Rock_Ice_Permafrost"
    },
    {
      "x": -49,
      "y": 37,
      "z": 14,
      "name": "Rock_Ice_Permafrost"
    },
    {
      "x": -49,
      "y": 38,
      "z": 14,
      "name": "Rock_Ice_Permafrost"
    },
    {
      "x": -49,
      "y": 39,
      "z": 14,
      "name": "Rock_Ice"
    },
    {
      "x": -49,
      "y": 40,
      "z": 14,
      "name": "Soil_Snow"
    },
    {
      "x": -49,
      "y": 22,
      "z": 15,
      "name": "Rock_Ice"
    },
    {
      "x": -49,
      "y": 23,
      "z": 15,
      "name": "Rock_Ice"
    },
    {
      "x": -49,
      "y": 24,
      "z": 15,
      "name": "Rock_Ice"
    },
    {
      "x": -49,
      "y": 25,
      "z": 15,
      "name": "Rock_Ice"
    },
    {
      "x": -49,
      "y": 26,
      "z": 15,
      "name": "Rock_Ice"
    },
    {
      "x": -49,
      "y": 27,
      "z": 15,
      "name": "Rock_Ice"
    },
    {
      "x": -49,
      "y": 28,
      "z": 15,
      "name": "Rock_Ice"
    },
    {
      "x": -49,
      "y": 29,
      "z": 15,
      "name": "Rock_Ice"
    },
    {
      "x": -49,
      "y": 30,
      "z": 15,
      "name": "Rock_Ice"
    },
    {
      "x": -49,
      "y": 31,
      "z": 15,
      "name": "Rock_Ice"
    },
    {
      "x": -49,
      "y": 32,
      "z": 15,
      "name": "Rock_Ice"
    },
    {
      "x": -49,
      "y": 33,
      "z": 15,
      "name": "Rock_Ice"
    },
    {
      "x": -49,
      "y": 34,
      "z": 15,
      "name": "Rock_Ice"
    },
    {
      "x": -49,
      "y": 35,
      "z": 15,
      "name": "Rock_Ice"
    },
    {
      "x": -49,
      "y": 36,
      "z": 15,
      "name": "Rock_Ice"
    },
    {
      "x": -49,
      "y": 37,
      "z": 15,
      "name": "Rock_Ice_Permafrost"
    },
    {
      "x": -49,
      "y": 38,
      "z": 15,
      "name": "Rock_Ice"
    },
    {
      "x": -49,
      "y": 39,
      "z": 15,
      "name": "Soil_Snow"
    },
    {
      "x": -49,
      "y": 21,
      "z": 16,
      "name": "Rock_Ice"
    },
    {
      "x": -49,
      "y": 22,
      "z": 16,
      "name": "Rock_Ice"
    },
    {
      "x": -49,
      "y": 23,
      "z": 16,
      "name": "Rock_Ice"
    },
    {
      "x": -49,
      "y": 24,
      "z": 16,
      "name": "Rock_Ice"
    },
    {
      "x": -49,
      "y": 25,
      "z": 16,
      "name": "Rock_Ice"
    },
    {
      "x": -49,
      "y": 26,
      "z": 16,
      "name": "Rock_Ice"
    },
    {
      "x": -49,
      "y": 27,
      "z": 16,
      "name": "Rock_Ice"
    },
    {
      "x": -49,
      "y": 28,
      "z": 16,
      "name": "Rock_Ice"
    },
    {
      "x": -49,
      "y": 29,
      "z": 16,
      "name": "Rock_Ice"
    },
    {
      "x": -49,
      "y": 30,
      "z": 16,
      "name": "Rock_Ice"
    },
    {
      "x": -49,
      "y": 31,
      "z": 16,
      "name": "Rock_Ice"
    },
    {
      "x": -49,
      "y": 32,
      "z": 16,
      "name": "Rock_Ice"
    },
    {
      "x": -49,
      "y": 33,
      "z": 16,
      "name": "Rock_Ice"
    },
    {
      "x": -49,
      "y": 34,
      "z": 16,
      "name": "Rock_Ice"
    },
    {
      "x": -49,
      "y": 35,
      "z": 16,
      "name": "Rock_Ice"
    },
    {
      "x": -49,
      "y": 36,
      "z": 16,
      "name": "Rock_Ice"
    },
    {
      "x": -49,
      "y": 37,
      "z": 16,
      "name": "Rock_Ice"
    },
    {
      "x": -49,
      "y": 38,
      "z": 16,
      "name": "Soil_Snow"
    },
    {
      "x": -49,
      "y": 21,
      "z": 17,
      "name": "Rock_Ice"
    },
    {
      "x": -49,
      "y": 22,
      "z": 17,
      "name": "Rock_Ice"
    },
    {
      "x": -49,
      "y": 23,
      "z": 17,
      "name": "Rock_Ice"
    },
    {
      "x": -49,
      "y": 24,
      "z": 17,
      "name": "Rock_Ice"
    },
    {
      "x": -49,
      "y": 25,
      "z": 17,
      "name": "Rock_Ice"
    },
    {
      "x": -49,
      "y": 26,
      "z": 17,
      "name": "Rock_Ice"
    },
    {
      "x": -49,
      "y": 27,
      "z": 17,
      "name": "Rock_Ice"
    },
    {
      "x": -49,
      "y": 28,
      "z": 17,
      "name": "Rock_Ice"
    },
    {
      "x": -49,
      "y": 29,
      "z": 17,
      "name": "Rock_Ice"
    },
    {
      "x": -49,
      "y": 30,
      "z": 17,
      "name": "Rock_Ice"
    },
    {
      "x": -49,
      "y": 31,
      "z": 17,
      "name": "Rock_Ice"
    },
    {
      "x": -49,
      "y": 32,
      "z": 17,
      "name": "Rock_Ice"
    },
    {
      "x": -49,
      "y": 33,
      "z": 17,
      "name": "Rock_Ice"
    },
    {
      "x": -49,
      "y": 34,
      "z": 17,
      "name": "Rock_Ice"
    },
    {
      "x": -49,
      "y": 35,
      "z": 17,
      "name": "Rock_Ice"
    },
    {
      "x": -49,
      "y": 36,
      "z": 17,
      "name": "Rock_Ice"
    },
    {
      "x": -49,
      "y": 37,
      "z": 17,
      "name": "Soil_Snow"
    },
    {
      "x": -49,
      "y": 21,
      "z": 18,
      "name": "Rock_Ice"
    },
    {
      "x": -49,
      "y": 22,
      "z": 18,
      "name": "Rock_Ice"
    },
    {
      "x": -49,
      "y": 23,
      "z": 18,
      "name": "Rock_Ice"
    },
    {
      "x": -49,
      "y": 24,
      "z": 18,
      "name": "Rock_Ice"
    },
    {
      "x": -49,
      "y": 25,
      "z": 18,
      "name": "Rock_Ice"
    },
    {
      "x": -49,
      "y": 26,
      "z": 18,
      "name": "Rock_Ice"
    },
    {
      "x": -49,
      "y": 27,
      "z": 18,
      "name": "Rock_Ice"
    },
    {
      "x": -49,
      "y": 28,
      "z": 18,
      "name": "Rock_Ice"
    },
    {
      "x": -49,
      "y": 29,
      "z": 18,
      "name": "Rock_Ice"
    },
    {
      "x": -49,
      "y": 30,
      "z": 18,
      "name": "Rock_Ice"
    },
    {
      "x": -49,
      "y": 31,
      "z": 18,
      "name": "Rock_Ice_Permafrost"
    },
    {
      "x": -49,
      "y": 32,
      "z": 18,
      "name": "Rock_Ice"
    },
    {
      "x": -49,
      "y": 33,
      "z": 18,
      "name": "Rock_Ice"
    },
    {
      "x": -49,
      "y": 34,
      "z": 18,
      "name": "Rock_Ice"
    },
    {
      "x": -49,
      "y": 35,
      "z": 18,
      "name": "Rock_Ice"
    },
    {
      "x": -49,
      "y": 36,
      "z": 18,
      "name": "Soil_Snow"
    },
    {
      "x": -49,
      "y": 21,
      "z": 19,
      "name": "Rock_Ice"
    },
    {
      "x": -49,
      "y": 22,
      "z": 19,
      "name": "Rock_Ice"
    },
    {
      "x": -49,
      "y": 23,
      "z": 19,
      "name": "Rock_Ice"
    },
    {
      "x": -49,
      "y": 24,
      "z": 19,
      "name": "Rock_Ice"
    },
    {
      "x": -49,
      "y": 25,
      "z": 19,
      "name": "Rock_Ice"
    },
    {
      "x": -49,
      "y": 26,
      "z": 19,
      "name": "Rock_Ice"
    },
    {
      "x": -49,
      "y": 27,
      "z": 19,
      "name": "Rock_Ice"
    },
    {
      "x": -49,
      "y": 28,
      "z": 19,
      "name": "Rock_Ice"
    },
    {
      "x": -49,
      "y": 29,
      "z": 19,
      "name": "Rock_Ice"
    },
    {
      "x": -49,
      "y": 30,
      "z": 19,
      "name": "Rock_Ice"
    },
    {
      "x": -49,
      "y": 31,
      "z": 19,
      "name": "Rock_Ice"
    },
    {
      "x": -49,
      "y": 32,
      "z": 19,
      "name": "Rock_Ice"
    },
    {
      "x": -49,
      "y": 33,
      "z": 19,
      "name": "Rock_Ice"
    },
    {
      "x": -49,
      "y": 34,
      "z": 19,
      "name": "Rock_Ice_Permafrost"
    },
    {
      "x": -49,
      "y": 35,
      "z": 19,
      "name": "Rock_Ice"
    },
    {
      "x": -49,
      "y": 36,
      "z": 19,
      "name": "Soil_Snow"
    },
    {
      "x": -49,
      "y": 21,
      "z": 20,
      "name": "Rock_Ice"
    },
    {
      "x": -49,
      "y": 22,
      "z": 20,
      "name": "Rock_Ice"
    },
    {
      "x": -49,
      "y": 23,
      "z": 20,
      "name": "Rock_Ice"
    },
    {
      "x": -49,
      "y": 24,
      "z": 20,
      "name": "Rock_Ice"
    },
    {
      "x": -49,
      "y": 25,
      "z": 20,
      "name": "Rock_Ice_Permafrost"
    },
    {
      "x": -49,
      "y": 26,
      "z": 20,
      "name": "Rock_Ice_Permafrost"
    },
    {
      "x": -49,
      "y": 27,
      "z": 20,
      "name": "Rock_Ice"
    },
    {
      "x": -49,
      "y": 28,
      "z": 20,
      "name": "Rock_Ice"
    },
    {
      "x": -49,
      "y": 29,
      "z": 20,
      "name": "Rock_Ice"
    },
    {
      "x": -49,
      "y": 30,
      "z": 20,
      "name": "Rock_Ice"
    },
    {
      "x": -49,
      "y": 31,
      "z": 20,
      "name": "Rock_Ice"
    },
    {
      "x": -49,
      "y": 32,
      "z": 20,
      "name": "Rock_Ice"
    },
    {
      "x": -49,
      "y": 33,
      "z": 20,
      "name": "Rock_Ice"
    },
    {
      "x": -49,
      "y": 34,
      "z": 20,
      "name": "Rock_Ice"
    },
    {
      "x": -49,
      "y": 35,
      "z": 20,
      "name": "Soil_Snow"
    },
    {
      "x": -49,
      "y": 21,
      "z": 21,
      "name": "Rock_Ice_Permafrost"
    },
    {
      "x": -49,
      "y": 22,
      "z": 21,
      "name": "Rock_Ice"
    },
    {
      "x": -49,
      "y": 23,
      "z": 21,
      "name": "Rock_Ice"
    },
    {
      "x": -49,
      "y": 24,
      "z": 21,
      "name": "Rock_Ice"
    },
    {
      "x": -49,
      "y": 25,
      "z": 21,
      "name": "Rock_Ice"
    },
    {
      "x": -49,
      "y": 26,
      "z": 21,
      "name": "Rock_Ice"
    },
    {
      "x": -49,
      "y": 27,
      "z": 21,
      "name": "Rock_Ice"
    },
    {
      "x": -49,
      "y": 28,
      "z": 21,
      "name": "Rock_Ice"
    },
    {
      "x": -49,
      "y": 29,
      "z": 21,
      "name": "Rock_Ice"
    },
    {
      "x": -49,
      "y": 30,
      "z": 21,
      "name": "Rock_Ice"
    },
    {
      "x": -49,
      "y": 31,
      "z": 21,
      "name": "Rock_Ice"
    },
    {
      "x": -49,
      "y": 32,
      "z": 21,
      "name": "Soil_Snow"
    },
    {
      "x": -49,
      "y": 23,
      "z": 22,
      "name": "Rock_Ice"
    },
    {
      "x": -49,
      "y": 24,
      "z": 22,
      "name": "Rock_Ice"
    },
    {
      "x": -49,
      "y": 25,
      "z": 22,
      "name": "Rock_Ice"
    },
    {
      "x": -49,
      "y": 26,
      "z": 22,
      "name": "Rock_Ice"
    },
    {
      "x": -49,
      "y": 27,
      "z": 22,
      "name": "Rock_Ice"
    },
    {
      "x": -49,
      "y": 28,
      "z": 22,
      "name": "Rock_Ice"
    },
    {
      "x": -49,
      "y": 29,
      "z": 22,
      "name": "Rock_Ice"
    },
    {
      "x": -49,
      "y": 30,
      "z": 22,
      "name": "Rock_Ice"
    },
    {
      "x": -48,
      "y": 33,
      "z": 1,
      "name": "Soil_Snow"
    },
    {
      "x": -48,
      "y": 29,
      "z": 2,
      "name": "Rock_Ice"
    },
    {
      "x": -48,
      "y": 30,
      "z": 2,
      "name": "Rock_Ice"
    },
    {
      "x": -48,
      "y": 31,
      "z": 2,
      "name": "Rock_Ice"
    },
    {
      "x": -48,
      "y": 32,
      "z": 2,
      "name": "Rock_Ice"
    },
    {
      "x": -48,
      "y": 33,
      "z": 2,
      "name": "Rock_Ice"
    },
    {
      "x": -48,
      "y": 34,
      "z": 2,
      "name": "Soil_Snow"
    },
    {
      "x": -48,
      "y": 27,
      "z": 3,
      "name": "Rock_Ice"
    },
    {
      "x": -48,
      "y": 28,
      "z": 3,
      "name": "Rock_Ice"
    },
    {
      "x": -48,
      "y": 29,
      "z": 3,
      "name": "Rock_Ice"
    },
    {
      "x": -48,
      "y": 30,
      "z": 3,
      "name": "Rock_Ice"
    },
    {
      "x": -48,
      "y": 31,
      "z": 3,
      "name": "Rock_Ice"
    },
    {
      "x": -48,
      "y": 32,
      "z": 3,
      "name": "Rock_Ice"
    },
    {
      "x": -48,
      "y": 33,
      "z": 3,
      "name": "Rock_Ice"
    },
    {
      "x": -48,
      "y": 34,
      "z": 3,
      "name": "Rock_Ice"
    },
    {
      "x": -48,
      "y": 35,
      "z": 3,
      "name": "Soil_Snow"
    },
    {
      "x": -48,
      "y": 26,
      "z": 4,
      "name": "Rock_Ice"
    },
    {
      "x": -48,
      "y": 27,
      "z": 4,
      "name": "Rock_Ice"
    },
    {
      "x": -48,
      "y": 28,
      "z": 4,
      "name": "Rock_Ice"
    },
    {
      "x": -48,
      "y": 29,
      "z": 4,
      "name": "Rock_Ice"
    },
    {
      "x": -48,
      "y": 30,
      "z": 4,
      "name": "Rock_Ice"
    },
    {
      "x": -48,
      "y": 31,
      "z": 4,
      "name": "Rock_Ice"
    },
    {
      "x": -48,
      "y": 32,
      "z": 4,
      "name": "Rock_Ice"
    },
    {
      "x": -48,
      "y": 33,
      "z": 4,
      "name": "Rock_Ice"
    },
    {
      "x": -48,
      "y": 34,
      "z": 4,
      "name": "Rock_Ice"
    },
    {
      "x": -48,
      "y": 35,
      "z": 4,
      "name": "Rock_Ice"
    },
    {
      "x": -48,
      "y": 36,
      "z": 4,
      "name": "Soil_Snow"
    },
    {
      "x": -48,
      "y": 25,
      "z": 5,
      "name": "Rock_Ice"
    },
    {
      "x": -48,
      "y": 26,
      "z": 5,
      "name": "Rock_Ice"
    },
    {
      "x": -48,
      "y": 27,
      "z": 5,
      "name": "Rock_Ice"
    },
    {
      "x": -48,
      "y": 28,
      "z": 5,
      "name": "Rock_Ice"
    },
    {
      "x": -48,
      "y": 29,
      "z": 5,
      "name": "Rock_Ice"
    },
    {
      "x": -48,
      "y": 30,
      "z": 5,
      "name": "Rock_Ice"
    },
    {
      "x": -48,
      "y": 31,
      "z": 5,
      "name": "Rock_Ice"
    },
    {
      "x": -48,
      "y": 32,
      "z": 5,
      "name": "Rock_Ice"
    },
    {
      "x": -48,
      "y": 33,
      "z": 5,
      "name": "Rock_Ice"
    },
    {
      "x": -48,
      "y": 34,
      "z": 5,
      "name": "Rock_Ice"
    },
    {
      "x": -48,
      "y": 35,
      "z": 5,
      "name": "Rock_Ice"
    },
    {
      "x": -48,
      "y": 36,
      "z": 5,
      "name": "Rock_Ice"
    },
    {
      "x": -48,
      "y": 37,
      "z": 5,
      "name": "Soil_Snow"
    },
    {
      "x": -48,
      "y": 24,
      "z": 6,
      "name": "Rock_Ice"
    },
    {
      "x": -48,
      "y": 25,
      "z": 6,
      "name": "Rock_Ice"
    },
    {
      "x": -48,
      "y": 26,
      "z": 6,
      "name": "Rock_Ice"
    },
    {
      "x": -48,
      "y": 27,
      "z": 6,
      "name": "Rock_Ice"
    },
    {
      "x": -48,
      "y": 28,
      "z": 6,
      "name": "Rock_Ice"
    },
    {
      "x": -48,
      "y": 29,
      "z": 6,
      "name": "Rock_Ice"
    },
    {
      "x": -48,
      "y": 30,
      "z": 6,
      "name": "Rock_Ice"
    },
    {
      "x": -48,
      "y": 31,
      "z": 6,
      "name": "Rock_Ice"
    },
    {
      "x": -48,
      "y": 32,
      "z": 6,
      "name": "Rock_Ice"
    },
    {
      "x": -48,
      "y": 33,
      "z": 6,
      "name": "Rock_Ice"
    },
    {
      "x": -48,
      "y": 34,
      "z": 6,
      "name": "Rock_Ice"
    },
    {
      "x": -48,
      "y": 35,
      "z": 6,
      "name": "Rock_Ice"
    },
    {
      "x": -48,
      "y": 36,
      "z": 6,
      "name": "Rock_Ice"
    },
    {
      "x": -48,
      "y": 37,
      "z": 6,
      "name": "Rock_Ice"
    },
    {
      "x": -48,
      "y": 38,
      "z": 6,
      "name": "Soil_Snow"
    },
    {
      "x": -48,
      "y": 24,
      "z": 7,
      "name": "Rock_Ice"
    },
    {
      "x": -48,
      "y": 25,
      "z": 7,
      "name": "Rock_Ice"
    },
    {
      "x": -48,
      "y": 26,
      "z": 7,
      "name": "Rock_Ice"
    },
    {
      "x": -48,
      "y": 27,
      "z": 7,
      "name": "Rock_Ice"
    },
    {
      "x": -48,
      "y": 28,
      "z": 7,
      "name": "Rock_Ice"
    },
    {
      "x": -48,
      "y": 29,
      "z": 7,
      "name": "Rock_Ice"
    },
    {
      "x": -48,
      "y": 30,
      "z": 7,
      "name": "Rock_Ice"
    },
    {
      "x": -48,
      "y": 31,
      "z": 7,
      "name": "Rock_Ice"
    },
    {
      "x": -48,
      "y": 32,
      "z": 7,
      "name": "Rock_Ice"
    },
    {
      "x": -48,
      "y": 33,
      "z": 7,
      "name": "Rock_Ice"
    },
    {
      "x": -48,
      "y": 34,
      "z": 7,
      "name": "Rock_Ice"
    },
    {
      "x": -48,
      "y": 35,
      "z": 7,
      "name": "Rock_Ice"
    },
    {
      "x": -48,
      "y": 36,
      "z": 7,
      "name": "Rock_Ice"
    },
    {
      "x": -48,
      "y": 37,
      "z": 7,
      "name": "Rock_Ice"
    },
    {
      "x": -48,
      "y": 38,
      "z": 7,
      "name": "Rock_Ice"
    },
    {
      "x": -48,
      "y": 39,
      "z": 7,
      "name": "Soil_Snow"
    },
    {
      "x": -48,
      "y": 23,
      "z": 8,
      "name": "Rock_Ice"
    },
    {
      "x": -48,
      "y": 24,
      "z": 8,
      "name": "Rock_Ice"
    },
    {
      "x": -48,
      "y": 25,
      "z": 8,
      "name": "Rock_Ice"
    },
    {
      "x": -48,
      "y": 26,
      "z": 8,
      "name": "Rock_Ice"
    },
    {
      "x": -48,
      "y": 27,
      "z": 8,
      "name": "Rock_Ice"
    },
    {
      "x": -48,
      "y": 28,
      "z": 8,
      "name": "Rock_Ice"
    },
    {
      "x": -48,
      "y": 29,
      "z": 8,
      "name": "Rock_Ice"
    },
    {
      "x": -48,
      "y": 30,
      "z": 8,
      "name": "Rock_Ice"
    },
    {
      "x": -48,
      "y": 31,
      "z": 8,
      "name": "Rock_Ice"
    },
    {
      "x": -48,
      "y": 32,
      "z": 8,
      "name": "Rock_Ice"
    },
    {
      "x": -48,
      "y": 33,
      "z": 8,
      "name": "Rock_Ice"
    },
    {
      "x": -48,
      "y": 34,
      "z": 8,
      "name": "Rock_Ice"
    },
    {
      "x": -48,
      "y": 35,
      "z": 8,
      "name": "Rock_Ice"
    },
    {
      "x": -48,
      "y": 36,
      "z": 8,
      "name": "Rock_Ice"
    },
    {
      "x": -48,
      "y": 37,
      "z": 8,
      "name": "Rock_Ice"
    },
    {
      "x": -48,
      "y": 38,
      "z": 8,
      "name": "Rock_Ice"
    },
    {
      "x": -48,
      "y": 39,
      "z": 8,
      "name": "Rock_Ice"
    },
    {
      "x": -48,
      "y": 40,
      "z": 8,
      "name": "Soil_Snow"
    },
    {
      "x": -48,
      "y": 22,
      "z": 9,
      "name": "Rock_Ice"
    },
    {
      "x": -48,
      "y": 23,
      "z": 9,
      "name": "Rock_Ice"
    },
    {
      "x": -48,
      "y": 24,
      "z": 9,
      "name": "Rock_Ice"
    },
    {
      "x": -48,
      "y": 25,
      "z": 9,
      "name": "Rock_Ice"
    },
    {
      "x": -48,
      "y": 26,
      "z": 9,
      "name": "Rock_Ice"
    },
    {
      "x": -48,
      "y": 27,
      "z": 9,
      "name": "Rock_Ice"
    },
    {
      "x": -48,
      "y": 28,
      "z": 9,
      "name": "Rock_Ice"
    },
    {
      "x": -48,
      "y": 29,
      "z": 9,
      "name": "Rock_Ice"
    },
    {
      "x": -48,
      "y": 30,
      "z": 9,
      "name": "Rock_Ice"
    },
    {
      "x": -48,
      "y": 31,
      "z": 9,
      "name": "Rock_Ice"
    },
    {
      "x": -48,
      "y": 32,
      "z": 9,
      "name": "Rock_Ice"
    },
    {
      "x": -48,
      "y": 33,
      "z": 9,
      "name": "Rock_Ice"
    },
    {
      "x": -48,
      "y": 34,
      "z": 9,
      "name": "Rock_Ice"
    },
    {
      "x": -48,
      "y": 35,
      "z": 9,
      "name": "Rock_Ice"
    },
    {
      "x": -48,
      "y": 36,
      "z": 9,
      "name": "Rock_Ice"
    },
    {
      "x": -48,
      "y": 37,
      "z": 9,
      "name": "Rock_Ice"
    },
    {
      "x": -48,
      "y": 38,
      "z": 9,
      "name": "Rock_Ice"
    },
    {
      "x": -48,
      "y": 39,
      "z": 9,
      "name": "Rock_Ice"
    },
    {
      "x": -48,
      "y": 40,
      "z": 9,
      "name": "Rock_Ice"
    },
    {
      "x": -48,
      "y": 41,
      "z": 9,
      "name": "Soil_Snow"
    },
    {
      "x": -48,
      "y": 22,
      "z": 10,
      "name": "Rock_Ice"
    },
    {
      "x": -48,
      "y": 23,
      "z": 10,
      "name": "Rock_Ice"
    },
    {
      "x": -48,
      "y": 24,
      "z": 10,
      "name": "Rock_Ice"
    },
    {
      "x": -48,
      "y": 25,
      "z": 10,
      "name": "Rock_Ice"
    },
    {
      "x": -48,
      "y": 26,
      "z": 10,
      "name": "Rock_Ice"
    },
    {
      "x": -48,
      "y": 27,
      "z": 10,
      "name": "Rock_Ice"
    },
    {
      "x": -48,
      "y": 28,
      "z": 10,
      "name": "Rock_Ice"
    },
    {
      "x": -48,
      "y": 29,
      "z": 10,
      "name": "Rock_Ice"
    },
    {
      "x": -48,
      "y": 30,
      "z": 10,
      "name": "Rock_Ice"
    },
    {
      "x": -48,
      "y": 31,
      "z": 10,
      "name": "Rock_Ice"
    },
    {
      "x": -48,
      "y": 32,
      "z": 10,
      "name": "Rock_Ice"
    },
    {
      "x": -48,
      "y": 33,
      "z": 10,
      "name": "Rock_Ice"
    },
    {
      "x": -48,
      "y": 34,
      "z": 10,
      "name": "Rock_Ice"
    },
    {
      "x": -48,
      "y": 35,
      "z": 10,
      "name": "Rock_Ice"
    },
    {
      "x": -48,
      "y": 36,
      "z": 10,
      "name": "Rock_Ice"
    },
    {
      "x": -48,
      "y": 37,
      "z": 10,
      "name": "Rock_Ice"
    },
    {
      "x": -48,
      "y": 38,
      "z": 10,
      "name": "Rock_Ice"
    },
    {
      "x": -48,
      "y": 39,
      "z": 10,
      "name": "Rock_Ice_Permafrost"
    },
    {
      "x": -48,
      "y": 40,
      "z": 10,
      "name": "Rock_Ice"
    },
    {
      "x": -48,
      "y": 41,
      "z": 10,
      "name": "Rock_Ice_Permafrost"
    },
    {
      "x": -48,
      "y": 21,
      "z": 11,
      "name": "Rock_Ice"
    },
    {
      "x": -48,
      "y": 22,
      "z": 11,
      "name": "Rock_Ice"
    },
    {
      "x": -48,
      "y": 23,
      "z": 11,
      "name": "Rock_Ice"
    },
    {
      "x": -48,
      "y": 24,
      "z": 11,
      "name": "Rock_Ice"
    },
    {
      "x": -48,
      "y": 25,
      "z": 11,
      "name": "Rock_Ice"
    },
    {
      "x": -48,
      "y": 26,
      "z": 11,
      "name": "Rock_Ice"
    },
    {
      "x": -48,
      "y": 27,
      "z": 11,
      "name": "Rock_Ice"
    },
    {
      "x": -48,
      "y": 28,
      "z": 11,
      "name": "Rock_Ice"
    },
    {
      "x": -48,
      "y": 29,
      "z": 11,
      "name": "Rock_Ice"
    },
    {
      "x": -48,
      "y": 30,
      "z": 11,
      "name": "Rock_Ice"
    },
    {
      "x": -48,
      "y": 31,
      "z": 11,
      "name": "Rock_Ice"
    },
    {
      "x": -48,
      "y": 32,
      "z": 11,
      "name": "Rock_Ice"
    },
    {
      "x": -48,
      "y": 33,
      "z": 11,
      "name": "Rock_Ice"
    },
    {
      "x": -48,
      "y": 34,
      "z": 11,
      "name": "Rock_Ice"
    },
    {
      "x": -48,
      "y": 35,
      "z": 11,
      "name": "Rock_Ice"
    },
    {
      "x": -48,
      "y": 36,
      "z": 11,
      "name": "Rock_Ice"
    },
    {
      "x": -48,
      "y": 37,
      "z": 11,
      "name": "Rock_Ice"
    },
    {
      "x": -48,
      "y": 38,
      "z": 11,
      "name": "Rock_Ice"
    },
    {
      "x": -48,
      "y": 39,
      "z": 11,
      "name": "Rock_Ice_Permafrost"
    },
    {
      "x": -48,
      "y": 40,
      "z": 11,
      "name": "Rock_Ice_Permafrost"
    },
    {
      "x": -48,
      "y": 41,
      "z": 11,
      "name": "Rock_Ice"
    },
    {
      "x": -48,
      "y": 42,
      "z": 11,
      "name": "Soil_Snow"
    },
    {
      "x": -48,
      "y": 21,
      "z": 12,
      "name": "Rock_Ice"
    },
    {
      "x": -48,
      "y": 22,
      "z": 12,
      "name": "Rock_Ice"
    },
    {
      "x": -48,
      "y": 23,
      "z": 12,
      "name": "Rock_Ice"
    },
    {
      "x": -48,
      "y": 24,
      "z": 12,
      "name": "Rock_Ice"
    },
    {
      "x": -48,
      "y": 25,
      "z": 12,
      "name": "Rock_Ice"
    },
    {
      "x": -48,
      "y": 26,
      "z": 12,
      "name": "Rock_Ice"
    },
    {
      "x": -48,
      "y": 27,
      "z": 12,
      "name": "Rock_Ice"
    },
    {
      "x": -48,
      "y": 28,
      "z": 12,
      "name": "Rock_Ice"
    },
    {
      "x": -48,
      "y": 29,
      "z": 12,
      "name": "Rock_Ice"
    },
    {
      "x": -48,
      "y": 30,
      "z": 12,
      "name": "Rock_Ice"
    },
    {
      "x": -48,
      "y": 31,
      "z": 12,
      "name": "Rock_Ice"
    },
    {
      "x": -48,
      "y": 32,
      "z": 12,
      "name": "Rock_Ice"
    },
    {
      "x": -48,
      "y": 33,
      "z": 12,
      "name": "Rock_Ice"
    },
    {
      "x": -48,
      "y": 34,
      "z": 12,
      "name": "Rock_Ice"
    },
    {
      "x": -48,
      "y": 35,
      "z": 12,
      "name": "Rock_Ice"
    },
    {
      "x": -48,
      "y": 36,
      "z": 12,
      "name": "Rock_Ice_Permafrost"
    },
    {
      "x": -48,
      "y": 37,
      "z": 12,
      "name": "Rock_Ice"
    },
    {
      "x": -48,
      "y": 38,
      "z": 12,
      "name": "Rock_Ice_Permafrost"
    },
    {
      "x": -48,
      "y": 39,
      "z": 12,
      "name": "Rock_Ice_Permafrost"
    },
    {
      "x": -48,
      "y": 40,
      "z": 12,
      "name": "Rock_Ice_Permafrost"
    },
    {
      "x": -48,
      "y": 41,
      "z": 12,
      "name": "Rock_Ice"
    },
    {
      "x": -48,
      "y": 42,
      "z": 12,
      "name": "Soil_Snow"
    },
    {
      "x": -48,
      "y": 20,
      "z": 13,
      "name": "Rock_Ice"
    },
    {
      "x": -48,
      "y": 21,
      "z": 13,
      "name": "Rock_Ice"
    },
    {
      "x": -48,
      "y": 22,
      "z": 13,
      "name": "Rock_Ice"
    },
    {
      "x": -48,
      "y": 23,
      "z": 13,
      "name": "Rock_Ice"
    },
    {
      "x": -48,
      "y": 24,
      "z": 13,
      "name": "Rock_Ice"
    },
    {
      "x": -48,
      "y": 25,
      "z": 13,
      "name": "Rock_Ice"
    },
    {
      "x": -48,
      "y": 26,
      "z": 13,
      "name": "Rock_Ice"
    },
    {
      "x": -48,
      "y": 27,
      "z": 13,
      "name": "Rock_Ice"
    },
    {
      "x": -48,
      "y": 28,
      "z": 13,
      "name": "Rock_Ice"
    },
    {
      "x": -48,
      "y": 29,
      "z": 13,
      "name": "Rock_Ice"
    },
    {
      "x": -48,
      "y": 30,
      "z": 13,
      "name": "Rock_Ice"
    },
    {
      "x": -48,
      "y": 31,
      "z": 13,
      "name": "Rock_Ice"
    },
    {
      "x": -48,
      "y": 32,
      "z": 13,
      "name": "Rock_Ice"
    },
    {
      "x": -48,
      "y": 33,
      "z": 13,
      "name": "Rock_Ice"
    },
    {
      "x": -48,
      "y": 34,
      "z": 13,
      "name": "Rock_Ice"
    },
    {
      "x": -48,
      "y": 35,
      "z": 13,
      "name": "Rock_Ice"
    },
    {
      "x": -48,
      "y": 36,
      "z": 13,
      "name": "Rock_Ice"
    },
    {
      "x": -48,
      "y": 37,
      "z": 13,
      "name": "Rock_Ice_Permafrost"
    },
    {
      "x": -48,
      "y": 38,
      "z": 13,
      "name": "Rock_Ice_Permafrost"
    },
    {
      "x": -48,
      "y": 39,
      "z": 13,
      "name": "Rock_Ice"
    },
    {
      "x": -48,
      "y": 40,
      "z": 13,
      "name": "Rock_Ice"
    },
    {
      "x": -48,
      "y": 41,
      "z": 13,
      "name": "Soil_Snow"
    },
    {
      "x": -48,
      "y": 20,
      "z": 14,
      "name": "Rock_Ice"
    },
    {
      "x": -48,
      "y": 21,
      "z": 14,
      "name": "Rock_Ice"
    },
    {
      "x": -48,
      "y": 22,
      "z": 14,
      "name": "Rock_Ice"
    },
    {
      "x": -48,
      "y": 23,
      "z": 14,
      "name": "Rock_Ice"
    },
    {
      "x": -48,
      "y": 24,
      "z": 14,
      "name": "Rock_Ice"
    },
    {
      "x": -48,
      "y": 25,
      "z": 14,
      "name": "Rock_Ice"
    },
    {
      "x": -48,
      "y": 26,
      "z": 14,
      "name": "Rock_Ice"
    },
    {
      "x": -48,
      "y": 27,
      "z": 14,
      "name": "Rock_Ice"
    },
    {
      "x": -48,
      "y": 28,
      "z": 14,
      "name": "Rock_Ice"
    },
    {
      "x": -48,
      "y": 29,
      "z": 14,
      "name": "Rock_Ice"
    },
    {
      "x": -48,
      "y": 30,
      "z": 14,
      "name": "Rock_Ice"
    },
    {
      "x": -48,
      "y": 31,
      "z": 14,
      "name": "Rock_Ice"
    },
    {
      "x": -48,
      "y": 32,
      "z": 14,
      "name": "Rock_Ice"
    },
    {
      "x": -48,
      "y": 33,
      "z": 14,
      "name": "Rock_Ice"
    },
    {
      "x": -48,
      "y": 34,
      "z": 14,
      "name": "Rock_Ice"
    },
    {
      "x": -48,
      "y": 35,
      "z": 14,
      "name": "Rock_Ice"
    },
    {
      "x": -48,
      "y": 36,
      "z": 14,
      "name": "Rock_Ice"
    },
    {
      "x": -48,
      "y": 37,
      "z": 14,
      "name": "Rock_Ice"
    },
    {
      "x": -48,
      "y": 38,
      "z": 14,
      "name": "Rock_Ice_Permafrost"
    },
    {
      "x": -48,
      "y": 39,
      "z": 14,
      "name": "Rock_Ice"
    },
    {
      "x": -48,
      "y": 40,
      "z": 14,
      "name": "Soil_Snow"
    },
    {
      "x": -48,
      "y": 20,
      "z": 15,
      "name": "Rock_Ice"
    },
    {
      "x": -48,
      "y": 21,
      "z": 15,
      "name": "Rock_Ice"
    },
    {
      "x": -48,
      "y": 22,
      "z": 15,
      "name": "Rock_Ice"
    },
    {
      "x": -48,
      "y": 23,
      "z": 15,
      "name": "Rock_Ice"
    },
    {
      "x": -48,
      "y": 24,
      "z": 15,
      "name": "Rock_Ice"
    },
    {
      "x": -48,
      "y": 25,
      "z": 15,
      "name": "Rock_Ice"
    },
    {
      "x": -48,
      "y": 26,
      "z": 15,
      "name": "Rock_Ice"
    },
    {
      "x": -48,
      "y": 27,
      "z": 15,
      "name": "Rock_Ice"
    },
    {
      "x": -48,
      "y": 28,
      "z": 15,
      "name": "Rock_Ice"
    },
    {
      "x": -48,
      "y": 29,
      "z": 15,
      "name": "Rock_Ice"
    },
    {
      "x": -48,
      "y": 30,
      "z": 15,
      "name": "Rock_Ice"
    },
    {
      "x": -48,
      "y": 31,
      "z": 15,
      "name": "Rock_Ice"
    },
    {
      "x": -48,
      "y": 32,
      "z": 15,
      "name": "Rock_Ice"
    },
    {
      "x": -48,
      "y": 33,
      "z": 15,
      "name": "Rock_Ice"
    },
    {
      "x": -48,
      "y": 34,
      "z": 15,
      "name": "Rock_Ice"
    },
    {
      "x": -48,
      "y": 35,
      "z": 15,
      "name": "Rock_Ice"
    },
    {
      "x": -48,
      "y": 36,
      "z": 15,
      "name": "Rock_Ice"
    },
    {
      "x": -48,
      "y": 37,
      "z": 15,
      "name": "Rock_Ice"
    },
    {
      "x": -48,
      "y": 38,
      "z": 15,
      "name": "Rock_Ice"
    },
    {
      "x": -48,
      "y": 39,
      "z": 15,
      "name": "Soil_Snow"
    },
    {
      "x": -48,
      "y": 19,
      "z": 16,
      "name": "Rock_Ice"
    },
    {
      "x": -48,
      "y": 20,
      "z": 16,
      "name": "Rock_Ice"
    },
    {
      "x": -48,
      "y": 21,
      "z": 16,
      "name": "Rock_Ice"
    },
    {
      "x": -48,
      "y": 22,
      "z": 16,
      "name": "Rock_Ice"
    },
    {
      "x": -48,
      "y": 23,
      "z": 16,
      "name": "Rock_Ice"
    },
    {
      "x": -48,
      "y": 24,
      "z": 16,
      "name": "Rock_Ice"
    },
    {
      "x": -48,
      "y": 25,
      "z": 16,
      "name": "Rock_Ice"
    },
    {
      "x": -48,
      "y": 26,
      "z": 16,
      "name": "Rock_Ice"
    },
    {
      "x": -48,
      "y": 27,
      "z": 16,
      "name": "Rock_Ice"
    },
    {
      "x": -48,
      "y": 28,
      "z": 16,
      "name": "Rock_Ice"
    },
    {
      "x": -48,
      "y": 29,
      "z": 16,
      "name": "Rock_Ice"
    },
    {
      "x": -48,
      "y": 30,
      "z": 16,
      "name": "Rock_Ice"
    },
    {
      "x": -48,
      "y": 31,
      "z": 16,
      "name": "Rock_Ice"
    },
    {
      "x": -48,
      "y": 32,
      "z": 16,
      "name": "Rock_Ice"
    },
    {
      "x": -48,
      "y": 33,
      "z": 16,
      "name": "Rock_Ice"
    },
    {
      "x": -48,
      "y": 34,
      "z": 16,
      "name": "Rock_Ice"
    },
    {
      "x": -48,
      "y": 35,
      "z": 16,
      "name": "Rock_Ice"
    },
    {
      "x": -48,
      "y": 36,
      "z": 16,
      "name": "Rock_Ice"
    },
    {
      "x": -48,
      "y": 37,
      "z": 16,
      "name": "Rock_Ice"
    },
    {
      "x": -48,
      "y": 38,
      "z": 16,
      "name": "Soil_Snow"
    },
    {
      "x": -48,
      "y": 19,
      "z": 17,
      "name": "Rock_Ice"
    },
    {
      "x": -48,
      "y": 20,
      "z": 17,
      "name": "Rock_Ice"
    },
    {
      "x": -48,
      "y": 21,
      "z": 17,
      "name": "Rock_Ice"
    },
    {
      "x": -48,
      "y": 22,
      "z": 17,
      "name": "Rock_Ice"
    },
    {
      "x": -48,
      "y": 23,
      "z": 17,
      "name": "Rock_Ice"
    },
    {
      "x": -48,
      "y": 24,
      "z": 17,
      "name": "Rock_Ice"
    },
    {
      "x": -48,
      "y": 25,
      "z": 17,
      "name": "Rock_Ice"
    },
    {
      "x": -48,
      "y": 26,
      "z": 17,
      "name": "Rock_Ice"
    },
    {
      "x": -48,
      "y": 27,
      "z": 17,
      "name": "Rock_Ice"
    },
    {
      "x": -48,
      "y": 28,
      "z": 17,
      "name": "Rock_Ice"
    },
    {
      "x": -48,
      "y": 29,
      "z": 17,
      "name": "Rock_Ice"
    },
    {
      "x": -48,
      "y": 30,
      "z": 17,
      "name": "Rock_Ice"
    },
    {
      "x": -48,
      "y": 31,
      "z": 17,
      "name": "Rock_Ice"
    },
    {
      "x": -48,
      "y": 32,
      "z": 17,
      "name": "Rock_Ice"
    },
    {
      "x": -48,
      "y": 33,
      "z": 17,
      "name": "Rock_Ice"
    },
    {
      "x": -48,
      "y": 34,
      "z": 17,
      "name": "Rock_Ice"
    },
    {
      "x": -48,
      "y": 35,
      "z": 17,
      "name": "Rock_Ice"
    },
    {
      "x": -48,
      "y": 36,
      "z": 17,
      "name": "Rock_Ice"
    },
    {
      "x": -48,
      "y": 37,
      "z": 17,
      "name": "Soil_Snow"
    },
    {
      "x": -48,
      "y": 19,
      "z": 18,
      "name": "Rock_Ice"
    },
    {
      "x": -48,
      "y": 20,
      "z": 18,
      "name": "Rock_Ice"
    },
    {
      "x": -48,
      "y": 21,
      "z": 18,
      "name": "Rock_Ice"
    },
    {
      "x": -48,
      "y": 22,
      "z": 18,
      "name": "Rock_Ice"
    },
    {
      "x": -48,
      "y": 23,
      "z": 18,
      "name": "Rock_Ice"
    },
    {
      "x": -48,
      "y": 24,
      "z": 18,
      "name": "Rock_Ice"
    },
    {
      "x": -48,
      "y": 25,
      "z": 18,
      "name": "Rock_Ice"
    },
    {
      "x": -48,
      "y": 26,
      "z": 18,
      "name": "Rock_Ice"
    },
    {
      "x": -48,
      "y": 27,
      "z": 18,
      "name": "Rock_Ice"
    },
    {
      "x": -48,
      "y": 28,
      "z": 18,
      "name": "Rock_Ice"
    },
    {
      "x": -48,
      "y": 29,
      "z": 18,
      "name": "Rock_Ice"
    },
    {
      "x": -48,
      "y": 30,
      "z": 18,
      "name": "Rock_Ice"
    },
    {
      "x": -48,
      "y": 31,
      "z": 18,
      "name": "Rock_Ice"
    },
    {
      "x": -48,
      "y": 32,
      "z": 18,
      "name": "Rock_Ice"
    },
    {
      "x": -48,
      "y": 33,
      "z": 18,
      "name": "Rock_Ice"
    },
    {
      "x": -48,
      "y": 34,
      "z": 18,
      "name": "Rock_Ice"
    },
    {
      "x": -48,
      "y": 35,
      "z": 18,
      "name": "Rock_Ice"
    },
    {
      "x": -48,
      "y": 36,
      "z": 18,
      "name": "Rock_Ice"
    },
    {
      "x": -48,
      "y": 37,
      "z": 18,
      "name": "Soil_Snow"
    },
    {
      "x": -48,
      "y": 19,
      "z": 19,
      "name": "Rock_Ice"
    },
    {
      "x": -48,
      "y": 20,
      "z": 19,
      "name": "Rock_Ice_Permafrost"
    },
    {
      "x": -48,
      "y": 21,
      "z": 19,
      "name": "Rock_Ice_Permafrost"
    },
    {
      "x": -48,
      "y": 22,
      "z": 19,
      "name": "Rock_Ice"
    },
    {
      "x": -48,
      "y": 23,
      "z": 19,
      "name": "Rock_Ice"
    },
    {
      "x": -48,
      "y": 24,
      "z": 19,
      "name": "Rock_Ice"
    },
    {
      "x": -48,
      "y": 25,
      "z": 19,
      "name": "Rock_Ice_Permafrost"
    },
    {
      "x": -48,
      "y": 26,
      "z": 19,
      "name": "Rock_Ice_Permafrost"
    },
    {
      "x": -48,
      "y": 27,
      "z": 19,
      "name": "Rock_Ice"
    },
    {
      "x": -48,
      "y": 28,
      "z": 19,
      "name": "Rock_Ice"
    },
    {
      "x": -48,
      "y": 29,
      "z": 19,
      "name": "Rock_Ice"
    },
    {
      "x": -48,
      "y": 30,
      "z": 19,
      "name": "Rock_Ice"
    },
    {
      "x": -48,
      "y": 31,
      "z": 19,
      "name": "Rock_Ice"
    },
    {
      "x": -48,
      "y": 32,
      "z": 19,
      "name": "Rock_Ice"
    },
    {
      "x": -48,
      "y": 33,
      "z": 19,
      "name": "Rock_Ice"
    },
    {
      "x": -48,
      "y": 34,
      "z": 19,
      "name": "Rock_Ice"
    },
    {
      "x": -48,
      "y": 35,
      "z": 19,
      "name": "Rock_Ice"
    },
    {
      "x": -48,
      "y": 36,
      "z": 19,
      "name": "Rock_Ice"
    },
    {
      "x": -48,
      "y": 37,
      "z": 19,
      "name": "Soil_Snow"
    },
    {
      "x": -48,
      "y": 19,
      "z": 20,
      "name": "Rock_Ice"
    },
    {
      "x": -48,
      "y": 20,
      "z": 20,
      "name": "Rock_Ice"
    },
    {
      "x": -48,
      "y": 21,
      "z": 20,
      "name": "Rock_Ice_Permafrost"
    },
    {
      "x": -48,
      "y": 22,
      "z": 20,
      "name": "Rock_Ice"
    },
    {
      "x": -48,
      "y": 23,
      "z": 20,
      "name": "Rock_Ice_Permafrost"
    },
    {
      "x": -48,
      "y": 24,
      "z": 20,
      "name": "Rock_Ice_Permafrost"
    },
    {
      "x": -48,
      "y": 25,
      "z": 20,
      "name": "Rock_Ice"
    },
    {
      "x": -48,
      "y": 26,
      "z": 20,
      "name": "Rock_Ice"
    },
    {
      "x": -48,
      "y": 27,
      "z": 20,
      "name": "Rock_Ice"
    },
    {
      "x": -48,
      "y": 28,
      "z": 20,
      "name": "Rock_Ice"
    },
    {
      "x": -48,
      "y": 29,
      "z": 20,
      "name": "Rock_Ice"
    },
    {
      "x": -48,
      "y": 30,
      "z": 20,
      "name": "Rock_Ice"
    },
    {
      "x": -48,
      "y": 31,
      "z": 20,
      "name": "Rock_Ice"
    },
    {
      "x": -48,
      "y": 32,
      "z": 20,
      "name": "Rock_Ice"
    },
    {
      "x": -48,
      "y": 33,
      "z": 20,
      "name": "Rock_Ice"
    },
    {
      "x": -48,
      "y": 34,
      "z": 20,
      "name": "Rock_Ice"
    },
    {
      "x": -48,
      "y": 35,
      "z": 20,
      "name": "Soil_Snow"
    },
    {
      "x": -48,
      "y": 19,
      "z": 21,
      "name": "Rock_Ice_Permafrost"
    },
    {
      "x": -48,
      "y": 20,
      "z": 21,
      "name": "Rock_Ice_Permafrost"
    },
    {
      "x": -48,
      "y": 21,
      "z": 21,
      "name": "Rock_Ice"
    },
    {
      "x": -48,
      "y": 22,
      "z": 21,
      "name": "Rock_Ice_Permafrost"
    },
    {
      "x": -48,
      "y": 23,
      "z": 21,
      "name": "Rock_Ice"
    },
    {
      "x": -48,
      "y": 24,
      "z": 21,
      "name": "Rock_Ice"
    },
    {
      "x": -48,
      "y": 25,
      "z": 21,
      "name": "Rock_Ice"
    },
    {
      "x": -48,
      "y": 26,
      "z": 21,
      "name": "Rock_Ice"
    },
    {
      "x": -48,
      "y": 27,
      "z": 21,
      "name": "Rock_Ice"
    },
    {
      "x": -48,
      "y": 28,
      "z": 21,
      "name": "Rock_Ice"
    },
    {
      "x": -48,
      "y": 29,
      "z": 21,
      "name": "Rock_Ice"
    },
    {
      "x": -48,
      "y": 30,
      "z": 21,
      "name": "Rock_Ice"
    },
    {
      "x": -48,
      "y": 31,
      "z": 21,
      "name": "Rock_Ice"
    },
    {
      "x": -48,
      "y": 32,
      "z": 21,
      "name": "Rock_Ice"
    },
    {
      "x": -48,
      "y": 33,
      "z": 21,
      "name": "Rock_Ice"
    },
    {
      "x": -48,
      "y": 21,
      "z": 22,
      "name": "Rock_Ice"
    },
    {
      "x": -48,
      "y": 22,
      "z": 22,
      "name": "Rock_Ice"
    },
    {
      "x": -48,
      "y": 23,
      "z": 22,
      "name": "Rock_Ice"
    },
    {
      "x": -48,
      "y": 24,
      "z": 22,
      "name": "Rock_Ice"
    },
    {
      "x": -48,
      "y": 25,
      "z": 22,
      "name": "Rock_Ice"
    },
    {
      "x": -48,
      "y": 26,
      "z": 22,
      "name": "Rock_Ice"
    },
    {
      "x": -48,
      "y": 27,
      "z": 22,
      "name": "Rock_Ice"
    },
    {
      "x": -48,
      "y": 28,
      "z": 22,
      "name": "Rock_Ice"
    },
    {
      "x": -48,
      "y": 29,
      "z": 22,
      "name": "Rock_Ice"
    },
    {
      "x": -48,
      "y": 30,
      "z": 22,
      "name": "Rock_Ice"
    },
    {
      "x": -48,
      "y": 31,
      "z": 22,
      "name": "Rock_Ice"
    },
    {
      "x": -48,
      "y": 25,
      "z": 23,
      "name": "Rock_Ice"
    },
    {
      "x": -48,
      "y": 26,
      "z": 23,
      "name": "Rock_Ice"
    },
    {
      "x": -48,
      "y": 27,
      "z": 23,
      "name": "Rock_Ice"
    },
    {
      "x": -48,
      "y": 28,
      "z": 23,
      "name": "Rock_Ice"
    },
    {
      "x": -48,
      "y": 29,
      "z": 23,
      "name": "Rock_Ice"
    },
    {
      "x": -47,
      "y": 27,
      "z": -7,
      "name": "Rock_Ice_Permafrost"
    },
    {
      "x": -47,
      "y": 28,
      "z": -7,
      "name": "Rock_Ice_Permafrost"
    },
    {
      "x": -47,
      "y": 29,
      "z": -7,
      "name": "Rock_Ice_Permafrost"
    },
    {
      "x": -47,
      "y": 30,
      "z": -7,
      "name": "Rock_Ice_Permafrost"
    },
    {
      "x": -47,
      "y": 31,
      "z": -7,
      "name": "Rock_Ice_Permafrost"
    },
    {
      "x": -47,
      "y": 32,
      "z": -7,
      "name": "Soil_Snow"
    },
    {
      "x": -47,
      "y": 28,
      "z": -6,
      "name": "Rock_Ice_Permafrost"
    },
    {
      "x": -47,
      "y": 29,
      "z": -6,
      "name": "Rock_Ice"
    },
    {
      "x": -47,
      "y": 30,
      "z": -6,
      "name": "Rock_Ice"
    },
    {
      "x": -47,
      "y": 29,
      "z": -5,
      "name": "Rock_Ice"
    },
    {
      "x": -47,
      "y": 30,
      "z": -5,
      "name": "Rock_Ice"
    },
    {
      "x": -47,
      "y": 29,
      "z": -4,
      "name": "Rock_Ice"
    },
    {
      "x": -47,
      "y": 30,
      "z": -4,
      "name": "Rock_Ice"
    },
    {
      "x": -47,
      "y": 28,
      "z": -3,
      "name": "Rock_Ice"
    },
    {
      "x": -47,
      "y": 29,
      "z": -3,
      "name": "Rock_Ice"
    },
    {
      "x": -47,
      "y": 30,
      "z": -3,
      "name": "Rock_Ice"
    },
    {
      "x": -47,
      "y": 27,
      "z": -2,
      "name": "Rock_Ice"
    },
    {
      "x": -47,
      "y": 28,
      "z": -2,
      "name": "Rock_Ice"
    },
    {
      "x": -47,
      "y": 29,
      "z": -2,
      "name": "Rock_Ice"
    },
    {
      "x": -47,
      "y": 30,
      "z": -2,
      "name": "Rock_Ice"
    },
    {
      "x": -47,
      "y": 31,
      "z": -2,
      "name": "Rock_Ice"
    },
    {
      "x": -47,
      "y": 32,
      "z": -2,
      "name": "Rock_Ice"
    },
    {
      "x": -47,
      "y": 33,
      "z": -2,
      "name": "Soil_Snow"
    },
    {
      "x": -47,
      "y": 27,
      "z": -1,
      "name": "Rock_Ice"
    },
    {
      "x": -47,
      "y": 28,
      "z": -1,
      "name": "Rock_Ice"
    },
    {
      "x": -47,
      "y": 29,
      "z": -1,
      "name": "Rock_Ice"
    },
    {
      "x": -47,
      "y": 30,
      "z": -1,
      "name": "Rock_Ice"
    },
    {
      "x": -47,
      "y": 31,
      "z": -1,
      "name": "Rock_Ice"
    },
    {
      "x": -47,
      "y": 32,
      "z": -1,
      "name": "Rock_Ice"
    },
    {
      "x": -47,
      "y": 33,
      "z": -1,
      "name": "Rock_Ice"
    },
    {
      "x": -47,
      "y": 34,
      "z": -1,
      "name": "Soil_Snow"
    },
    {
      "x": -47,
      "y": 26,
      "z": 0,
      "name": "Rock_Ice"
    },
    {
      "x": -47,
      "y": 27,
      "z": 0,
      "name": "Rock_Ice"
    },
    {
      "x": -47,
      "y": 28,
      "z": 0,
      "name": "Rock_Ice"
    },
    {
      "x": -47,
      "y": 29,
      "z": 0,
      "name": "Rock_Ice"
    },
    {
      "x": -47,
      "y": 30,
      "z": 0,
      "name": "Rock_Ice"
    },
    {
      "x": -47,
      "y": 31,
      "z": 0,
      "name": "Rock_Ice"
    },
    {
      "x": -47,
      "y": 32,
      "z": 0,
      "name": "Rock_Ice"
    },
    {
      "x": -47,
      "y": 33,
      "z": 0,
      "name": "Rock_Ice"
    },
    {
      "x": -47,
      "y": 34,
      "z": 0,
      "name": "Rock_Ice"
    },
    {
      "x": -47,
      "y": 35,
      "z": 0,
      "name": "Soil_Snow"
    },
    {
      "x": -47,
      "y": 25,
      "z": 1,
      "name": "Rock_Ice"
    },
    {
      "x": -47,
      "y": 26,
      "z": 1,
      "name": "Rock_Ice"
    },
    {
      "x": -47,
      "y": 27,
      "z": 1,
      "name": "Rock_Ice"
    },
    {
      "x": -47,
      "y": 28,
      "z": 1,
      "name": "Rock_Ice"
    },
    {
      "x": -47,
      "y": 29,
      "z": 1,
      "name": "Rock_Ice"
    },
    {
      "x": -47,
      "y": 30,
      "z": 1,
      "name": "Rock_Ice"
    },
    {
      "x": -47,
      "y": 31,
      "z": 1,
      "name": "Rock_Ice"
    },
    {
      "x": -47,
      "y": 32,
      "z": 1,
      "name": "Rock_Ice"
    },
    {
      "x": -47,
      "y": 33,
      "z": 1,
      "name": "Rock_Ice"
    },
    {
      "x": -47,
      "y": 34,
      "z": 1,
      "name": "Rock_Ice"
    },
    {
      "x": -47,
      "y": 35,
      "z": 1,
      "name": "Soil_Snow"
    },
    {
      "x": -47,
      "y": 24,
      "z": 2,
      "name": "Rock_Ice"
    },
    {
      "x": -47,
      "y": 25,
      "z": 2,
      "name": "Rock_Ice"
    },
    {
      "x": -47,
      "y": 26,
      "z": 2,
      "name": "Rock_Ice"
    },
    {
      "x": -47,
      "y": 27,
      "z": 2,
      "name": "Rock_Ice"
    },
    {
      "x": -47,
      "y": 28,
      "z": 2,
      "name": "Rock_Ice"
    },
    {
      "x": -47,
      "y": 29,
      "z": 2,
      "name": "Rock_Ice"
    },
    {
      "x": -47,
      "y": 30,
      "z": 2,
      "name": "Rock_Ice"
    },
    {
      "x": -47,
      "y": 31,
      "z": 2,
      "name": "Rock_Ice"
    },
    {
      "x": -47,
      "y": 32,
      "z": 2,
      "name": "Rock_Ice"
    },
    {
      "x": -47,
      "y": 33,
      "z": 2,
      "name": "Rock_Ice"
    },
    {
      "x": -47,
      "y": 34,
      "z": 2,
      "name": "Rock_Ice"
    },
    {
      "x": -47,
      "y": 35,
      "z": 2,
      "name": "Rock_Ice"
    },
    {
      "x": -47,
      "y": 36,
      "z": 2,
      "name": "Soil_Snow"
    },
    {
      "x": -47,
      "y": 24,
      "z": 3,
      "name": "Rock_Ice"
    },
    {
      "x": -47,
      "y": 25,
      "z": 3,
      "name": "Rock_Ice"
    },
    {
      "x": -47,
      "y": 26,
      "z": 3,
      "name": "Rock_Ice"
    },
    {
      "x": -47,
      "y": 27,
      "z": 3,
      "name": "Rock_Ice"
    },
    {
      "x": -47,
      "y": 28,
      "z": 3,
      "name": "Rock_Ice"
    },
    {
      "x": -47,
      "y": 29,
      "z": 3,
      "name": "Rock_Ice"
    },
    {
      "x": -47,
      "y": 30,
      "z": 3,
      "name": "Rock_Ice"
    },
    {
      "x": -47,
      "y": 31,
      "z": 3,
      "name": "Rock_Ice"
    },
    {
      "x": -47,
      "y": 32,
      "z": 3,
      "name": "Rock_Ice"
    },
    {
      "x": -47,
      "y": 33,
      "z": 3,
      "name": "Rock_Ice"
    },
    {
      "x": -47,
      "y": 34,
      "z": 3,
      "name": "Rock_Ice"
    },
    {
      "x": -47,
      "y": 35,
      "z": 3,
      "name": "Rock_Ice"
    },
    {
      "x": -47,
      "y": 36,
      "z": 3,
      "name": "Soil_Snow"
    },
    {
      "x": -47,
      "y": 23,
      "z": 4,
      "name": "Rock_Ice"
    },
    {
      "x": -47,
      "y": 24,
      "z": 4,
      "name": "Rock_Ice"
    },
    {
      "x": -47,
      "y": 25,
      "z": 4,
      "name": "Rock_Ice"
    },
    {
      "x": -47,
      "y": 26,
      "z": 4,
      "name": "Rock_Ice"
    },
    {
      "x": -47,
      "y": 27,
      "z": 4,
      "name": "Rock_Ice"
    },
    {
      "x": -47,
      "y": 28,
      "z": 4,
      "name": "Rock_Ice"
    },
    {
      "x": -47,
      "y": 29,
      "z": 4,
      "name": "Rock_Ice"
    },
    {
      "x": -47,
      "y": 30,
      "z": 4,
      "name": "Rock_Ice"
    },
    {
      "x": -47,
      "y": 31,
      "z": 4,
      "name": "Rock_Ice"
    },
    {
      "x": -47,
      "y": 32,
      "z": 4,
      "name": "Rock_Ice"
    },
    {
      "x": -47,
      "y": 33,
      "z": 4,
      "name": "Rock_Ice"
    },
    {
      "x": -47,
      "y": 34,
      "z": 4,
      "name": "Rock_Ice"
    },
    {
      "x": -47,
      "y": 35,
      "z": 4,
      "name": "Rock_Ice"
    },
    {
      "x": -47,
      "y": 36,
      "z": 4,
      "name": "Rock_Ice"
    },
    {
      "x": -47,
      "y": 37,
      "z": 4,
      "name": "Soil_Snow"
    },
    {
      "x": -47,
      "y": 22,
      "z": 5,
      "name": "Rock_Ice"
    },
    {
      "x": -47,
      "y": 23,
      "z": 5,
      "name": "Rock_Ice"
    },
    {
      "x": -47,
      "y": 24,
      "z": 5,
      "name": "Rock_Ice"
    },
    {
      "x": -47,
      "y": 25,
      "z": 5,
      "name": "Rock_Ice"
    },
    {
      "x": -47,
      "y": 26,
      "z": 5,
      "name": "Rock_Ice"
    },
    {
      "x": -47,
      "y": 27,
      "z": 5,
      "name": "Rock_Ice"
    },
    {
      "x": -47,
      "y": 28,
      "z": 5,
      "name": "Rock_Ice"
    },
    {
      "x": -47,
      "y": 29,
      "z": 5,
      "name": "Rock_Ice"
    },
    {
      "x": -47,
      "y": 30,
      "z": 5,
      "name": "Rock_Ice"
    },
    {
      "x": -47,
      "y": 31,
      "z": 5,
      "name": "Rock_Ice"
    },
    {
      "x": -47,
      "y": 32,
      "z": 5,
      "name": "Rock_Ice"
    },
    {
      "x": -47,
      "y": 33,
      "z": 5,
      "name": "Rock_Ice"
    },
    {
      "x": -47,
      "y": 34,
      "z": 5,
      "name": "Rock_Ice"
    },
    {
      "x": -47,
      "y": 35,
      "z": 5,
      "name": "Rock_Ice"
    },
    {
      "x": -47,
      "y": 36,
      "z": 5,
      "name": "Rock_Ice"
    },
    {
