{
  "version": 8,
  "blockIdVersion": 11,
  "anchorX": 0,
  "anchorY": 34,
  "anchorZ": -5,
  "blocks": [
    {
      "x": -43,
      "y": 30,
      "z": 22,
      "name": "Rock_Ice_Permafrost"
    },
    {
      "x": -43,
      "y": 29,
      "z": 23,
      "name": "Rock_Ice_Permafrost"
    },
    {
      "x": -43,
      "y": 30,
      "z": 23,
      "name": "Rock_Ice_Permafrost"
    },
    {
      "x": -43,
      "y": 31,
      "z": 23,
      "name": "Soil_Snow"
    },
    {
      "x": -43,
      "y": 28,
      "z": 24,
      "name": "Rock_Ice_Permafrost"
    },
    {
      "x": -43,
      "y": 29,
      "z": 24,
      "name": "Rock_Ice_Permafrost"
    },
    {
      "x": -43,
      "y": 30,
      "z": 24,
      "name": "Rock_Ice_Permafrost"
    },
    {
      "x": -43,
      "y": 31,
      "z": 24,
      "name": "Soil_Snow"
    },
    {
      "x": -43,
      "y": 28,
      "z": 25,
      "name": "Rock_Ice_Permafrost"
    },
    {
      "x": -43,
      "y": 29,
      "z": 25,
      "name": "Rock_Ice_Permafrost"
    },
    {
      "x": -43,
      "y": 30,
      "z": 25,
      "name": "Rock_Ice_Permafrost"
    },
    {
      "x": -43,
      "y": 31,
      "z": 25,
      "name": "Soil_Snow"
    },
    {
      "x": -43,
      "y": 27,
      "z": 26,
      "name": "Rock_Ice_Permafrost"
    },
    {
      "x": -43,
      "y": 28,
      "z": 26,
      "name": "Rock_Ice_Permafrost"
    },
    {
      "x": -43,
      "y": 29,
      "z": 26,
      "name": "Rock_Ice"
    },
    {
      "x": -43,
      "y": 30,
      "z": 26,
      "name": "Soil_Snow"
    },
    {
      "x": -43,
      "y": 26,
      "z": 27,
      "name": "Rock_Ice_Permafrost"
    },
    {
      "x": -43,
      "y": 27,
      "z": 27,
      "name": "Rock_Ice_Permafrost"
    },
    {
      "x": -43,
      "y": 28,
      "z": 27,
      "name": "Rock_Ice_Permafrost"
    },
    {
      "x": -43,
      "y": 29,
      "z": 27,
      "name": "Rock_Ice"
    },
    {
      "x": -43,
      "y": 30,
      "z": 27,
      "name": "Soil_Snow"
    },
    {
      "x": -43,
      "y": 26,
      "z": 28,
      "name": "Rock_Ice_Permafrost"
    },
    {
      "x": -43,
      "y": 27,
      "z": 28,
      "name": "Rock_Ice_Permafrost"
    },
    {
      "x": -43,
      "y": 28,
      "z": 28,
      "name": "Rock_Ice_Permafrost"
    },
    {
      "x": -43,
      "y": 29,
      "z": 28,
      "name": "Rock_Ice"
    },
    {
      "x": -43,
      "y": 30,
      "z": 28,
      "name": "Rock_Ice_Permafrost"
    },
    {
      "x": -43,
      "y": 26,
      "z": 29,
      "name": "Rock_Ice_Permafrost"
    },
    {
      "x": -43,
      "y": 27,
      "z": 29,
      "name": "Rock_Ice_Permafrost"
    },
    {
      "x": -43,
      "y": 28,
      "z": 29,
      "name": "Rock_Ice"
    },
    {
      "x": -43,
      "y": 29,
      "z": 29,
      "name": "Soil_Snow"
    },
    {
      "x": -43,
      "y": 26,
      "z": 30,
      "name": "Rock_Ice_Permafrost"
    },
    {
      "x": -43,
      "y": 27,
      "z": 30,
      "name": "Rock_Ice"
    },
    {
      "x": -43,
      "y": 28,
      "z": 30,
      "name": "Soil_Snow"
    },
    {
      "x": -43,
      "y": 27,
      "z": 31,
      "name": "Soil_Snow"
    },
    {
      "x": -42,
      "y": 31,
      "z": 19,
      "name": "Soil_Snow"
    },
    {
      "x": -42,
      "y": 30,
      "z": 20,
      "name": "Rock_Ice_Permafrost"
    },
    {
      "x": -42,
      "y": 31,
      "z": 20,
      "name": "Rock_Ice_Permafrost"
    },
    {
      "x": -42,
      "y": 32,
      "z": 20,
      "name": "Soil_Snow"
    },
    {
      "x": -42,
      "y": 29,
      "z": 21,
      "name": "Rock_Ice_Permafrost"
    },
    {
      "x": -42,
      "y": 30,
      "z": 21,
      "name": "Rock_Ice_Permafrost"
    },
    {
      "x": -42,
      "y": 31,
      "z": 21,
      "name": "Rock_Ice_Permafrost"
    },
    {
      "x": -42,
      "y": 32,
      "z": 21,
      "name": "Rock_Ice_Permafrost"
    },
    {
      "x": -42,
      "y": 33,
      "z": 21,
      "name": "Soil_Snow"
    },
    {
      "x": -42,
      "y": 28,
      "z": 22,
      "name": "Rock_Ice_Permafrost"
    },
    {
      "x": -42,
      "y": 29,
      "z": 22,
      "name": "Rock_Ice_Permafrost"
    },
    {
      "x": -42,
      "y": 30,
      "z": 22,
      "name": "Rock_Ice_Permafrost"
    },
    {
      "x": -42,
      "y": 31,
      "z": 22,
      "name": "Rock_Ice_Permafrost"
    },
    {
      "x": -42,
      "y": 32,
      "z": 22,
      "name": "Rock_Ice_Permafrost"
    },
    {
      "x": -42,
      "y": 33,
      "z": 22,
      "name": "Soil_Snow"
    },
    {
      "x": -42,
      "y": 27,
      "z": 23,
      "name": "Rock_Ice_Permafrost"
    },
    {
      "x": -42,
      "y": 28,
      "z": 23,
      "name": "Rock_Ice_Permafrost"
    },
    {
      "x": -42,
      "y": 29,
      "z": 23,
      "name": "Rock_Ice_Permafrost"
    },
    {
      "x": -42,
      "y": 30,
      "z": 23,
      "name": "Rock_Ice_Permafrost"
    },
    {
      "x": -42,
      "y": 31,
      "z": 23,
      "name": "Rock_Ice_Permafrost"
    },
    {
      "x": -42,
      "y": 32,
      "z": 23,
      "name": "Rock_Ice_Permafrost"
    },
    {
      "x": -42,
      "y": 33,
      "z": 23,
      "name": "Soil_Snow"
    },
    {
      "x": -42,
      "y": 26,
      "z": 24,
      "name": "Rock_Ice_Permafrost"
    },
    {
      "x": -42,
      "y": 27,
      "z": 24,
      "name": "Rock_Ice_Permafrost"
    },
    {
      "x": -42,
      "y": 28,
      "z": 24,
      "name": "Rock_Ice_Permafrost"
    },
    {
      "x": -42,
      "y": 29,
      "z": 24,
      "name": "Rock_Ice_Permafrost"
    },
    {
      "x": -42,
      "y": 30,
      "z": 24,
      "name": "Rock_Ice_Permafrost"
    },
    {
      "x": -42,
      "y": 31,
      "z": 24,
      "name": "Rock_Ice_Permafrost"
    },
    {
      "x": -42,
      "y": 32,
      "z": 24,
      "name": "Soil_Snow"
    },
    {
      "x": -42,
      "y": 26,
      "z": 25,
      "name": "Rock_Ice_Permafrost"
    },
    {
      "x": -42,
      "y": 27,
      "z": 25,
      "name": "Rock_Ice_Permafrost"
    },
    {
      "x": -42,
      "y": 28,
      "z": 25,
      "name": "Rock_Ice_Permafrost"
    },
    {
      "x": -42,
      "y": 29,
      "z": 25,
      "name": "Rock_Ice_Permafrost"
    },
    {
      "x": -42,
      "y": 30,
      "z": 25,
      "name": "Rock_Ice_Permafrost"
    },
    {
      "x": -42,
      "y": 31,
      "z": 25,
      "name": "Rock_Ice"
    },
    {
      "x": -42,
      "y": 32,
      "z": 25,
      "name": "Soil_Snow"
    },
    {
      "x": -42,
      "y": 25,
      "z": 26,
      "name": "Rock_Ice_Permafrost"
    },
    {
      "x": -42,
      "y": 26,
      "z": 26,
      "name": "Rock_Ice_Permafrost"
    },
    {
      "x": -42,
      "y": 27,
      "z": 26,
      "name": "Rock_Ice_Permafrost"
    },
    {
      "x": -42,
      "y": 28,
      "z": 26,
      "name": "Rock_Ice_Permafrost"
    },
    {
      "x": -42,
      "y": 29,
      "z": 26,
      "name": "Rock_Ice_Permafrost"
    },
    {
      "x": -42,
      "y": 30,
      "z": 26,
      "name": "Rock_Ice_Permafrost"
    },
    {
      "x": -42,
      "y": 31,
      "z": 26,
      "name": "Rock_Ice"
    },
    {
      "x": -42,
      "y": 32,
      "z": 26,
      "name": "Soil_Snow"
    },
    {
      "x": -42,
      "y": 24,
      "z": 27,
      "name": "Rock_Ice_Permafrost"
    },
    {
      "x": -42,
      "y": 25,
      "z": 27,
      "name": "Rock_Ice"
    },
    {
      "x": -42,
      "y": 26,
      "z": 27,
      "name": "Rock_Ice_Permafrost"
    },
    {
      "x": -42,
      "y": 27,
      "z": 27,
      "name": "Rock_Ice_Permafrost"
    },
    {
      "x": -42,
      "y": 28,
      "z": 27,
      "name": "Rock_Ice_Permafrost"
    },
    {
      "x": -42,
      "y": 29,
      "z": 27,
      "name": "Rock_Ice_Permafrost"
    },
    {
      "x": -42,
      "y": 30,
      "z": 27,
      "name": "Rock_Ice_Permafrost"
    },
    {
      "x": -42,
      "y": 31,
      "z": 27,
      "name": "Rock_Ice"
    },
    {
      "x": -42,
      "y": 32,
      "z": 27,
      "name": "Soil_Snow"
    },
    {
      "x": -42,
      "y": 24,
      "z": 28,
      "name": "Rock_Ice_Permafrost"
    },
    {
      "x": -42,
      "y": 25,
      "z": 28,
      "name": "Rock_Ice_Permafrost"
    },
    {
      "x": -42,
      "y": 26,
      "z": 28,
      "name": "Rock_Ice"
    },
    {
      "x": -42,
      "y": 27,
      "z": 28,
      "name": "Rock_Ice_Permafrost"
    },
    {
      "x": -42,
      "y": 28,
      "z": 28,
      "name": "Rock_Ice_Permafrost"
    },
    {
      "x": -42,
      "y": 29,
      "z": 28,
      "name": "Rock_Ice_Permafrost"
    },
    {
      "x": -42,
      "y": 30,
      "z": 28,
      "name": "Rock_Ice_Permafrost"
    },
    {
      "x": -42,
      "y": 31,
      "z": 28,
      "name": "Rock_Ice"
    },
    {
      "x": -42,
      "y": 32,
      "z": 28,
      "name": "Soil_Snow"
    },
    {
      "x": -42,
      "y": 25,
      "z": 29,
      "name": "Rock_Ice_Permafrost"
    },
    {
      "x": -42,
      "y": 26,
      "z": 29,
      "name": "Rock_Ice_Permafrost"
    },
    {
      "x": -42,
      "y": 27,
      "z": 29,
      "name": "Rock_Ice_Permafrost"
    },
    {
      "x": -42,
      "y": 28,
      "z": 29,
      "name": "Rock_Ice_Permafrost"
    },
    {
      "x": -42,
      "y": 29,
      "z": 29,
      "name": "Rock_Ice_Permafrost"
    },
    {
      "x": -42,
      "y": 30,
      "z": 29,
      "name": "Rock_Ice_Permafrost"
    },
    {
      "x": -42,
      "y": 31,
      "z": 29,
      "name": "Rock_Ice_Permafrost"
    },
    {
      "x": -42,
      "y": 25,
      "z": 30,
      "name": "Rock_Ice_Permafrost"
    },
    {
      "x": -42,
      "y": 26,
      "z": 30,
      "name": "Rock_Ice_Permafrost"
    },
    {
      "x": -42,
      "y": 27,
      "z": 30,
      "name": "Rock_Ice_Permafrost"
    },
    {
      "x": -42,
      "y": 28,
      "z": 30,
      "name": "Rock_Ice"
    },
    {
      "x": -42,
      "y": 29,
      "z": 30,
      "name": "Soil_Snow"
    },
    {
      "x": -42,
      "y": 25,
      "z": 31,
      "name": "Rock_Ice_Permafrost"
    },
    {
      "x": -42,
      "y": 26,
      "z": 31,
      "name": "Rock_Ice_Permafrost"
    },
    {
      "x": -42,
      "y": 27,
      "z": 31,
      "name": "Rock_Ice"
    },
    {
      "x": -42,
      "y": 28,
      "z": 31,
      "name": "Soil_Snow"
    },
    {
      "x": -42,
      "y": 25,
      "z": 32,
      "name": "Rock_Ice_Permafrost"
    },
    {
      "x": -42,
      "y": 26,
      "z": 32,
      "name": "Rock_Ice"
    },
    {
      "x": -42,
      "y": 27,
      "z": 32,
      "name": "Soil_Snow"
    },
    {
      "x": -42,
      "y": 25,
      "z": 33,
      "name": "Rock_Ice"
    },
    {
      "x": -42,
      "y": 26,
      "z": 33,
      "name": "Soil_Snow"
    },
    {
      "x": -42,
      "y": 25,
      "z": 34,
      "name": "Soil_Snow"
    },
    {
      "x": -41,
      "y": 31,
      "z": 17,
      "name": "Rock_Ice_Permafrost"
    },
    {
      "x": -41,
      "y": 32,
      "z": 17,
      "name": "Rock_Ice_Permafrost"
    },
    {
      "x": -41,
      "y": 33,
      "z": 17,
      "name": "Soil_Snow"
    },
    {
      "x": -41,
      "y": 30,
      "z": 18,
      "name": "Rock_Ice_Permafrost"
    },
    {
      "x": -41,
      "y": 31,
      "z": 18,
      "name": "Rock_Ice_Permafrost"
    },
    {
      "x": -41,
      "y": 32,
      "z": 18,
      "name": "Rock_Ice_Permafrost"
    },
    {
      "x": -41,
      "y": 33,
      "z": 18,
      "name": "Rock_Ice_Permafrost"
    },
    {
      "x": -41,
      "y": 34,
      "z": 18,
      "name": "Soil_Snow"
    },
    {
      "x": -41,
      "y": 29,
      "z": 19,
      "name": "Rock_Ice_Permafrost"
    },
    {
      "x": -41,
      "y": 30,
      "z": 19,
      "name": "Rock_Ice_Permafrost"
    },
    {
      "x": -41,
      "y": 31,
      "z": 19,
      "name": "Rock_Ice_Permafrost"
    },
    {
      "x": -41,
      "y": 32,
      "z": 19,
      "name": "Rock_Ice_Permafrost"
    },
    {
      "x": -41,
      "y": 33,
      "z": 19,
      "name": "Rock_Ice_Permafrost"
    },
    {
      "x": -41,
      "y": 34,
      "z": 19,
      "name": "Soil_Snow"
    },
    {
      "x": -41,
      "y": 28,
      "z": 20,
      "name": "Rock_Ice"
    },
    {
      "x": -41,
      "y": 29,
      "z": 20,
      "name": "Rock_Ice_Permafrost"
    },
    {
      "x": -41,
      "y": 30,
      "z": 20,
      "name": "Rock_Ice_Permafrost"
    },
    {
      "x": -41,
      "y": 31,
      "z": 20,
      "name": "Rock_Ice_Permafrost"
    },
    {
      "x": -41,
      "y": 32,
      "z": 20,
      "name": "Rock_Ice_Permafrost"
    },
    {
      "x": -41,
      "y": 33,
      "z": 20,
      "name": "Rock_Ice_Permafrost"
    },
    {
      "x": -41,
      "y": 34,
      "z": 20,
      "name": "Rock_Ice_Permafrost"
    },
    {
      "x": -41,
      "y": 35,
      "z": 20,
      "name": "Soil_Snow"
    },
    {
      "x": -41,
      "y": 27,
      "z": 21,
      "name": "Rock_Ice_Permafrost"
    },
    {
      "x": -41,
      "y": 28,
      "z": 21,
      "name": "Rock_Ice_Permafrost"
    },
    {
      "x": -41,
      "y": 29,
      "z": 21,
      "name": "Rock_Ice_Permafrost"
    },
    {
      "x": -41,
      "y": 30,
      "z": 21,
      "name": "Rock_Ice_Permafrost"
    },
    {
      "x": -41,
      "y": 31,
      "z": 21,
      "name": "Rock_Ice_Permafrost"
    },
    {
      "x": -41,
      "y": 32,
      "z": 21,
      "name": "Rock_Ice_Permafrost"
    },
    {
      "x": -41,
      "y": 33,
      "z": 21,
      "name": "Rock_Ice_Permafrost"
    },
    {
      "x": -41,
      "y": 34,
      "z": 21,
      "name": "Rock_Ice_Permafrost"
    },
    {
      "x": -41,
      "y": 35,
      "z": 21,
      "name": "Soil_Snow"
    },
    {
      "x": -41,
      "y": 26,
      "z": 22,
      "name": "Rock_Ice_Permafrost"
    },
    {
      "x": -41,
      "y": 27,
      "z": 22,
      "name": "Rock_Ice"
    },
    {
      "x": -41,
      "y": 28,
      "z": 22,
      "name": "Rock_Ice_Permafrost"
    },
    {
      "x": -41,
      "y": 29,
      "z": 22,
      "name": "Rock_Ice_Permafrost"
    },
    {
      "x": -41,
      "y": 30,
      "z": 22,
      "name": "Rock_Ice_Permafrost"
    },
    {
      "x": -41,
      "y": 31,
      "z": 22,
      "name": "Rock_Ice_Permafrost"
    },
    {
      "x": -41,
      "y": 32,
      "z": 22,
      "name": "Rock_Ice_Permafrost"
    },
    {
      "x": -41,
      "y": 33,
      "z": 22,
      "name": "Rock_Ice_Permafrost"
    },
    {
      "x": -41,
      "y": 34,
      "z": 22,
      "name": "Soil_Snow"
    },
    {
      "x": -41,
      "y": 25,
      "z": 23,
      "name": "Rock_Ice_Permafrost"
    },
    {
      "x": -41,
      "y": 26,
      "z": 23,
      "name": "Rock_Ice_Permafrost"
    },
    {
      "x": -41,
      "y": 27,
      "z": 23,
      "name": "Rock_Ice_Permafrost"
    },
    {
      "x": -41,
      "y": 28,
      "z": 23,
      "name": "Rock_Ice_Permafrost"
    },
    {
      "x": -41,
      "y": 29,
      "z": 23,
      "name": "Rock_Ice_Permafrost"
    },
    {
      "x": -41,
      "y": 30,
      "z": 23,
      "name": "Rock_Ice_Permafrost"
    },
    {
      "x": -41,
      "y": 31,
      "z": 23,
      "name": "Rock_Ice_Permafrost"
    },
    {
      "x": -41,
      "y": 32,
      "z": 23,
      "name": "Rock_Ice_Permafrost"
    },
    {
      "x": -41,
      "y": 33,
      "z": 23,
      "name": "Rock_Ice_Permafrost"
    },
    {
      "x": -41,
      "y": 34,
      "z": 23,
      "name": "Soil_Snow"
    },
    {
      "x": -41,
      "y": 25,
      "z": 24,
      "name": "Rock_Ice_Permafrost"
    },
    {
      "x": -41,
      "y": 26,
      "z": 24,
      "name": "Rock_Ice_Permafrost"
    },
    {
      "x": -41,
      "y": 27,
      "z": 24,
      "name": "Rock_Ice_Permafrost"
    },
    {
      "x": -41,
      "y": 28,
      "z": 24,
      "name": "Rock_Ice_Permafrost"
    },
    {
      "x": -41,
      "y": 29,
      "z": 24,
      "name": "Rock_Ice_Permafrost"
    },
    {
      "x": -41,
      "y": 30,
      "z": 24,
      "name": "Rock_Ice_Permafrost"
    },
    {
      "x": -41,
      "y": 31,
      "z": 24,
      "name": "Rock_Ice_Permafrost"
    },
    {
      "x": -41,
      "y": 32,
      "z": 24,
      "name": "Rock_Ice_Permafrost"
    },
    {
      "x": -41,
      "y": 33,
      "z": 24,
      "name": "Rock_Ice"
    },
    {
      "x": -41,
      "y": 34,
      "z": 24,
      "name": "Soil_Snow"
    },
    {
      "x": -41,
      "y": 24,
      "z": 25,
      "name": "Rock_Ice_Permafrost"
    },
    {
      "x": -41,
      "y": 25,
      "z": 25,
      "name": "Rock_Ice_Permafrost"
    },
    {
      "x": -41,
      "y": 26,
      "z": 25,
      "name": "Rock_Ice_Permafrost"
    },
    {
      "x": -41,
      "y": 27,
      "z": 25,
      "name": "Rock_Ice_Permafrost"
    },
    {
      "x": -41,
      "y": 28,
      "z": 25,
      "name": "Rock_Ice_Permafrost"
    },
    {
      "x": -41,
      "y": 29,
      "z": 25,
      "name": "Rock_Ice_Permafrost"
    },
    {
      "x": -41,
      "y": 30,
      "z": 25,
      "name": "Rock_Ice_Permafrost"
    },
    {
      "x": -41,
      "y": 31,
      "z": 25,
      "name": "Rock_Ice_Permafrost"
    },
    {
      "x": -41,
      "y": 32,
      "z": 25,
      "name": "Rock_Ice_Permafrost"
    },
    {
      "x": -41,
      "y": 33,
      "z": 25,
      "name": "Rock_Ice"
    },
    {
      "x": -41,
      "y": 34,
      "z": 25,
      "name": "Soil_Snow"
    },
    {
      "x": -41,
      "y": 24,
      "z": 26,
      "name": "Rock_Ice_Permafrost"
    },
    {
      "x": -41,
      "y": 25,
      "z": 26,
      "name": "Rock_Ice_Permafrost"
    },
    {
      "x": -41,
      "y": 26,
      "z": 26,
      "name": "Rock_Ice_Permafrost"
    },
    {
      "x": -41,
      "y": 27,
      "z": 26,
      "name": "Rock_Ice"
    },
    {
      "x": -41,
      "y": 28,
      "z": 26,
      "name": "Rock_Ice_Permafrost"
    },
    {
      "x": -41,
      "y": 29,
      "z": 26,
      "name": "Rock_Ice_Permafrost"
    },
    {
      "x": -41,
      "y": 30,
      "z": 26,
      "name": "Rock_Ice_Permafrost"
    },
    {
      "x": -41,
      "y": 31,
      "z": 26,
      "name": "Rock_Ice_Permafrost"
    },
    {
      "x": -41,
      "y": 32,
      "z": 26,
      "name": "Rock_Ice"
    },
    {
      "x": -41,
      "y": 33,
      "z": 26,
      "name": "Soil_Snow"
    },
    {
      "x": -41,
      "y": 23,
      "z": 27,
      "name": "Rock_Ice"
    },
    {
      "x": -41,
      "y": 24,
      "z": 27,
      "name": "Rock_Ice_Permafrost"
    },
    {
      "x": -41,
      "y": 25,
      "z": 27,
      "name": "Rock_Ice_Permafrost"
    },
    {
      "x": -41,
      "y": 26,
      "z": 27,
      "name": "Rock_Ice"
    },
    {
      "x": -41,
      "y": 27,
      "z": 27,
      "name": "Rock_Ice"
    },
    {
      "x": -41,
      "y": 28,
      "z": 27,
      "name": "Rock_Ice_Permafrost"
    },
    {
      "x": -41,
      "y": 29,
      "z": 27,
      "name": "Rock_Ice_Permafrost"
    },
    {
      "x": -41,
      "y": 30,
      "z": 27,
      "name": "Rock_Ice_Permafrost"
    },
    {
      "x": -41,
      "y": 31,
      "z": 27,
      "name": "Rock_Ice_Permafrost"
    },
    {
      "x": -41,
      "y": 32,
      "z": 27,
      "name": "Rock_Ice"
    },
    {
      "x": -41,
      "y": 33,
      "z": 27,
      "name": "Soil_Snow"
    },
    {
      "x": -41,
      "y": 24,
      "z": 28,
      "name": "Rock_Ice_Permafrost"
    },
    {
      "x": -41,
      "y": 25,
      "z": 28,
      "name": "Rock_Ice_Permafrost"
    },
    {
      "x": -41,
      "y": 26,
      "z": 28,
      "name": "Rock_Ice_Permafrost"
    },
    {
      "x": -41,
      "y": 27,
      "z": 28,
      "name": "Rock_Ice_Permafrost"
    },
    {
      "x": -41,
      "y": 28,
      "z": 28,
      "name": "Rock_Ice_Permafrost"
    },
    {
      "x": -41,
      "y": 29,
      "z": 28,
      "name": "Rock_Ice_Permafrost"
    },
    {
      "x": -41,
      "y": 30,
      "z": 28,
      "name": "Rock_Ice_Permafrost"
    },
    {
      "x": -41,
      "y": 31,
      "z": 28,
      "name": "Rock_Ice_Permafrost"
    },
    {
      "x": -41,
      "y": 32,
      "z": 28,
      "name": "Rock_Ice"
    },
    {
      "x": -41,
      "y": 33,
      "z": 28,
      "name": "Soil_Snow"
    },
    {
      "x": -41,
      "y": 24,
      "z": 29,
      "name": "Rock_Ice_Permafrost"
    },
    {
      "x": -41,
      "y": 25,
      "z": 29,
      "name": "Rock_Ice_Permafrost"
    },
    {
      "x": -41,
      "y": 26,
      "z": 29,
      "name": "Rock_Ice_Permafrost"
    },
    {
      "x": -41,
      "y": 27,
      "z": 29,
      "name": "Rock_Ice_Permafrost"
    },
    {
      "x": -41,
      "y": 28,
      "z": 29,
      "name": "Rock_Ice_Permafrost"
    },
    {
      "x": -41,
      "y": 29,
      "z": 29,
      "name": "Rock_Ice_Permafrost"
    },
    {
      "x": -41,
      "y": 30,
      "z": 29,
      "name": "Rock_Ice_Permafrost"
    },
    {
      "x": -41,
      "y": 31,
      "z": 29,
      "name": "Rock_Ice_Permafrost"
    },
    {
      "x": -41,
      "y": 32,
      "z": 29,
      "name": "Rock_Ice"
    },
    {
      "x": -41,
      "y": 33,
      "z": 29,
      "name": "Rock_Ice_Permafrost"
    },
    {
      "x": -41,
      "y": 24,
      "z": 30,
      "name": "Rock_Ice_Permafrost"
    },
    {
      "x": -41,
      "y": 25,
      "z": 30,
      "name": "Rock_Ice"
    },
    {
      "x": -41,
      "y": 26,
      "z": 30,
      "name": "Rock_Ice_Permafrost"
    },
    {
      "x": -41,
      "y": 27,
      "z": 30,
      "name": "Rock_Ice"
    },
    {
      "x": -41,
      "y": 28,
      "z": 30,
      "name": "Rock_Ice_Permafrost"
    },
    {
      "x": -41,
      "y": 29,
      "z": 30,
      "name": "Rock_Ice_Permafrost"
    },
    {
      "x": -41,
      "y": 30,
      "z": 30,
      "name": "Rock_Ice"
    },
    {
      "x": -41,
      "y": 31,
      "z": 30,
      "name": "Rock_Ice_Permafrost"
    },
    {
      "x": -41,
      "y": 24,
      "z": 31,
      "name": "Rock_Ice_Permafrost"
    },
    {
      "x": -41,
      "y": 25,
      "z": 31,
      "name": "Rock_Ice_Permafrost"
    },
    {
      "x": -41,
      "y": 26,
      "z": 31,
      "name": "Rock_Ice_Permafrost"
    },
    {
      "x": -41,
      "y": 27,
      "z": 31,
      "name": "Rock_Ice_Permafrost"
    },
    {
      "x": -41,
      "y": 28,
      "z": 31,
      "name": "Rock_Ice_Permafrost"
    },
    {
      "x": -41,
      "y": 29,
      "z": 31,
      "name": "Rock_Ice"
    },
    {
      "x": -41,
      "y": 30,
      "z": 31,
      "name": "Soil_Snow"
    },
    {
      "x": -41,
      "y": 24,
      "z": 32,
      "name": "Rock_Ice_Permafrost"
    },
    {
      "x": -41,
      "y": 25,
      "z": 32,
      "name": "Rock_Ice_Permafrost"
    },
    {
      "x": -41,
      "y": 26,
      "z": 32,
      "name": "Rock_Ice"
    },
    {
      "x": -41,
      "y": 27,
      "z": 32,
      "name": "Rock_Ice_Permafrost"
    },
    {
      "x": -41,
      "y": 28,
      "z": 32,
      "name": "Rock_Ice"
    },
    {
      "x": -41,
      "y": 29,
      "z": 32,
      "name": "Soil_Snow"
    },
    {
      "x": -41,
      "y": 25,
      "z": 33,
      "name": "Rock_Ice_Permafrost"
    },
    {
      "x": -41,
      "y": 26,
      "z": 33,
      "name": "Rock_Ice_Permafrost"
    },
    {
      "x": -41,
      "y": 27,
      "z": 33,
      "name": "Rock_Ice"
    },
    {
      "x": -41,
      "y": 28,
      "z": 33,
      "name": "Soil_Snow"
    },
    {
      "x": -41,
      "y": 25,
      "z": 34,
      "name": "Rock_Ice_Permafrost"
    },
    {
      "x": -41,
      "y": 26,
      "z": 34,
      "name": "Rock_Ice"
    },
    {
      "x": -41,
      "y": 27,
      "z": 34,
      "name": "Soil_Snow"
    },
    {
      "x": -41,
      "y": 25,
      "z": 35,
      "name": "Soil_Snow"
    },
    {
      "x": -40,
      "y": 33,
      "z": 14,
      "name": "Soil_Snow"
    },
    {
      "x": -40,
      "y": 31,
      "z": 15,
      "name": "Rock_Ice_Permafrost"
    },
    {
      "x": -40,
      "y": 32,
      "z": 15,
      "name": "Rock_Ice_Permafrost"
    },
    {
      "x": -40,
      "y": 33,
      "z": 15,
      "name": "Rock_Ice_Permafrost"
    },
    {
      "x": -40,
      "y": 34,
      "z": 15,
      "name": "Soil_Snow"
    },
    {
      "x": -40,
      "y": 30,
      "z": 16,
      "name": "Rock_Ice_Permafrost"
    },
    {
      "x": -40,
      "y": 31,
      "z": 16,
      "name": "Rock_Ice_Permafrost"
    },
    {
      "x": -40,
      "y": 32,
      "z": 16,
      "name": "Rock_Ice_Permafrost"
    },
    {
      "x": -40,
      "y": 33,
      "z": 16,
      "name": "Rock_Ice_Permafrost"
    },
    {
      "x": -40,
      "y": 34,
      "z": 16,
      "name": "Rock_Ice_Permafrost"
    },
    {
      "x": -40,
      "y": 35,
      "z": 16,
      "name": "Soil_Snow"
    },
    {
      "x": -40,
      "y": 29,
      "z": 17,
      "name": "Rock_Ice_Permafrost"
    },
    {
      "x": -40,
      "y": 30,
      "z": 17,
      "name": "Rock_Ice_Permafrost"
    },
    {
      "x": -40,
      "y": 31,
      "z": 17,
      "name": "Rock_Ice_Permafrost"
    },
    {
      "x": -40,
      "y": 32,
      "z": 17,
      "name": "Rock_Ice_Permafrost"
    },
    {
      "x": -40,
      "y": 33,
      "z": 17,
      "name": "Rock_Ice_Permafrost"
    },
    {
      "x": -40,
      "y": 34,
      "z": 17,
      "name": "Rock_Ice_Permafrost"
    },
    {
      "x": -40,
      "y": 35,
      "z": 17,
      "name": "Rock_Ice_Permafrost"
    },
    {
      "x": -40,
      "y": 36,
      "z": 17,
      "name": "Soil_Snow"
    },
    {
      "x": -40,
      "y": 28,
      "z": 18,
      "name": "Rock_Ice_Permafrost"
    },
    {
      "x": -40,
      "y": 29,
      "z": 18,
      "name": "Rock_Ice_Permafrost"
    },
    {
      "x": -40,
      "y": 30,
      "z": 18,
      "name": "Rock_Ice_Permafrost"
    },
    {
      "x": -40,
      "y": 31,
      "z": 18,
      "name": "Rock_Ice_Permafrost"
    },
    {
      "x": -40,
      "y": 32,
      "z": 18,
      "name": "Rock_Ice_Permafrost"
    },
    {
      "x": -40,
      "y": 33,
      "z": 18,
      "name": "Rock_Ice_Permafrost"
    },
    {
      "x": -40,
      "y": 34,
      "z": 18,
      "name": "Rock_Ice_Permafrost"
    },
    {
      "x": -40,
      "y": 35,
      "z": 18,
      "name": "Rock_Ice_Permafrost"
    },
    {
      "x": -40,
      "y": 36,
      "z": 18,
      "name": "Rock_Ice_Permafrost"
    },
    {
      "x": -40,
      "y": 37,
      "z": 18,
      "name": "Soil_Snow"
    },
    {
      "x": -40,
      "y": 27,
      "z": 19,
      "name": "Rock_Ice"
    },
    {
      "x": -40,
      "y": 28,
      "z": 19,
      "name": "Rock_Ice_Permafrost"
    },
    {
      "x": -40,
      "y": 29,
      "z": 19,
      "name": "Rock_Ice_Permafrost"
    },
    {
      "x": -40,
      "y": 30,
      "z": 19,
      "name": "Rock_Ice_Permafrost"
    },
    {
      "x": -40,
      "y": 31,
      "z": 19,
      "name": "Rock_Ice_Permafrost"
    },
    {
      "x": -40,
      "y": 32,
      "z": 19,
      "name": "Rock_Ice_Permafrost"
    },
    {
      "x": -40,
      "y": 33,
      "z": 19,
      "name": "Rock_Ice_Permafrost"
    },
    {
      "x": -40,
      "y": 34,
      "z": 19,
      "name": "Rock_Ice_Permafrost"
    },
    {
      "x": -40,
      "y": 35,
      "z": 19,
      "name": "Rock_Ice_Permafrost"
    },
    {
      "x": -40,
      "y": 36,
      "z": 19,
      "name": "Rock_Ice_Permafrost"
    },
    {
      "x": -40,
      "y": 37,
      "z": 19,
      "name": "Soil_Snow"
    },
    {
      "x": -40,
      "y": 26,
      "z": 20,
      "name": "Rock_Ice_Permafrost"
    },
    {
      "x": -40,
      "y": 27,
      "z": 20,
      "name": "Rock_Ice_Permafrost"
    },
    {
      "x": -40,
      "y": 28,
      "z": 20,
      "name": "Rock_Ice_Permafrost"
    },
    {
      "x": -40,
      "y": 29,
      "z": 20,
      "name": "Rock_Ice_Permafrost"
    },
    {
      "x": -40,
      "y": 30,
      "z": 20,
      "name": "Rock_Ice_Permafrost"
    },
    {
      "x": -40,
      "y": 31,
      "z": 20,
      "name": "Rock_Ice_Permafrost"
    },
    {
      "x": -40,
      "y": 32,
      "z": 20,
      "name": "Rock_Ice_Permafrost"
    },
    {
      "x": -40,
      "y": 33,
      "z": 20,
      "name": "Rock_Ice_Permafrost"
    },
    {
      "x": -40,
      "y": 34,
      "z": 20,
      "name": "Rock_Ice_Permafrost"
    },
    {
      "x": -40,
      "y": 35,
      "z": 20,
      "name": "Rock_Ice_Permafrost"
    },
    {
      "x": -40,
      "y": 36,
      "z": 20,
      "name": "Soil_Snow"
    },
    {
      "x": -40,
      "y": 26,
      "z": 21,
      "name": "Rock_Ice"
    },
    {
      "x": -40,
      "y": 27,
      "z": 21,
      "name": "Rock_Ice_Permafrost"
    },
    {
      "x": -40,
      "y": 28,
      "z": 21,
      "name": "Rock_Ice_Permafrost"
    },
    {
      "x": -40,
      "y": 29,
      "z": 21,
      "name": "Rock_Ice_Permafrost"
    },
    {
      "x": -40,
      "y": 30,
      "z": 21,
      "name": "Rock_Ice_Permafrost"
    },
    {
      "x": -40,
      "y": 31,
      "z": 21,
      "name": "Rock_Ice_Permafrost"
    },
    {
      "x": -40,
      "y": 32,
      "z": 21,
      "name": "Rock_Ice_Permafrost"
    },
    {
      "x": -40,
      "y": 33,
      "z": 21,
      "name": "Rock_Ice_Permafrost"
    },
    {
      "x": -40,
      "y": 34,
      "z": 21,
      "name": "Rock_Ice_Permafrost"
    },
    {
      "x": -40,
      "y": 35,
      "z": 21,
      "name": "Rock_Ice_Permafrost"
    },
    {
      "x": -40,
      "y": 36,
      "z": 21,
      "name": "Soil_Snow"
    },
    {
      "x": -40,
      "y": 25,
      "z": 22,
      "name": "Rock_Ice_Permafrost"
    },
    {
      "x": -40,
      "y": 26,
      "z": 22,
      "name": "Rock_Ice"
    },
    {
      "x": -40,
      "y": 27,
      "z": 22,
      "name": "Rock_Ice_Permafrost"
    },
    {
      "x": -40,
      "y": 28,
      "z": 22,
      "name": "Rock_Ice_Permafrost"
    },
    {
      "x": -40,
      "y": 29,
      "z": 22,
      "name": "Rock_Ice_Permafrost"
    },
    {
      "x": -40,
      "y": 30,
      "z": 22,
      "name": "Rock_Ice_Permafrost"
    },
    {
      "x": -40,
      "y": 31,
      "z": 22,
      "name": "Rock_Ice_Permafrost"
    },
    {
      "x": -40,
      "y": 32,
      "z": 22,
      "name": "Rock_Ice_Permafrost"
    },
    {
      "x": -40,
      "y": 33,
      "z": 22,
      "name": "Rock_Ice_Permafrost"
    },
    {
      "x": -40,
      "y": 34,
      "z": 22,
      "name": "Rock_Ice_Permafrost"
    },
    {
      "x": -40,
      "y": 35,
      "z": 22,
      "name": "Rock_Ice_Permafrost"
    },
    {
      "x": -40,
      "y": 36,
      "z": 22,
      "name": "Soil_Snow"
    },
    {
      "x": -40,
      "y": 24,
      "z": 23,
      "name": "Rock_Ice"
    },
    {
      "x": -40,
      "y": 25,
      "z": 23,
      "name": "Rock_Ice_Permafrost"
    },
    {
      "x": -40,
      "y": 26,
      "z": 23,
      "name": "Rock_Ice_Permafrost"
    },
    {
      "x": -40,
      "y": 27,
      "z": 23,
      "name": "Rock_Ice_Permafrost"
    },
    {
      "x": -40,
      "y": 28,
      "z": 23,
      "name": "Rock_Ice_Permafrost"
    },
    {
      "x": -40,
      "y": 29,
      "z": 23,
      "name": "Rock_Ice_Permafrost"
    },
    {
      "x": -40,
      "y": 30,
      "z": 23,
      "name": "Rock_Ice_Permafrost"
    },
    {
      "x": -40,
      "y": 31,
      "z": 23,
      "name": "Rock_Ice_Permafrost"
    },
    {
      "x": -40,
      "y": 32,
      "z": 23,
      "name": "Rock_Ice_Permafrost"
    },
    {
      "x": -40,
      "y": 33,
      "z": 23,
      "name": "Rock_Ice_Permafrost"
    },
    {
      "x": -40,
      "y": 34,
      "z": 23,
      "name": "Rock_Ice_Permafrost"
    },
    {
      "x": -40,
      "y": 35,
      "z": 23,
      "name": "Soil_Snow"
    },
    {
      "x": -40,
      "y": 24,
      "z": 24,
      "name": "Rock_Ice_Permafrost"
    },
    {
      "x": -40,
      "y": 25,
      "z": 24,
      "name": "Rock_Ice_Permafrost"
    },
    {
      "x": -40,
      "y": 26,
      "z": 24,
      "name": "Rock_Ice"
    },
    {
      "x": -40,
      "y": 27,
      "z": 24,
      "name": "Rock_Ice_Permafrost"
    },
    {
      "x": -40,
      "y": 28,
      "z": 24,
      "name": "Rock_Ice_Permafrost"
    },
    {
      "x": -40,
      "y": 29,
      "z": 24,
      "name": "Rock_Ice_Permafrost"
    },
    {
      "x": -40,
      "y": 30,
      "z": 24,
      "name": "Rock_Ice_Permafrost"
    },
    {
      "x": -40,
      "y": 31,
      "z": 24,
      "name": "Rock_Ice_Permafrost"
    },
    {
      "x": -40,
      "y": 32,
      "z": 24,
      "name": "Rock_Ice_Permafrost"
    },
    {
      "x": -40,
      "y": 33,
      "z": 24,
      "name": "Rock_Ice_Permafrost"
    },
    {
      "x": -40,
      "y": 34,
      "z": 24,
      "name": "Rock_Ice"
    },
    {
      "x": -40,
      "y": 35,
      "z": 24,
      "name": "Soil_Snow"
    },
    {
      "x": -40,
      "y": 23,
      "z": 25,
      "name": "Rock_Ice"
    },
    {
      "x": -40,
      "y": 24,
      "z": 25,
      "name": "Rock_Ice"
    },
    {
      "x": -40,
      "y": 25,
      "z": 25,
      "name": "Rock_Ice_Permafrost"
    },
    {
      "x": -40,
      "y": 26,
      "z": 25,
      "name": "Rock_Ice_Permafrost"
    },
    {
      "x": -40,
      "y": 27,
      "z": 25,
      "name": "Rock_Ice_Permafrost"
    },
    {
      "x": -40,
      "y": 28,
      "z": 25,
      "name": "Rock_Ice"
    },
    {
      "x": -40,
      "y": 29,
      "z": 25,
      "name": "Rock_Ice"
    },
    {
      "x": -40,
      "y": 30,
      "z": 25,
      "name": "Rock_Ice_Permafrost"
    },
    {
      "x": -40,
      "y": 31,
      "z": 25,
      "name": "Rock_Ice_Permafrost"
    },
    {
      "x": -40,
      "y": 32,
      "z": 25,
      "name": "Rock_Ice_Permafrost"
    },
    {
      "x": -40,
      "y": 33,
      "z": 25,
      "name": "Rock_Ice_Permafrost"
    },
    {
      "x": -40,
      "y": 34,
      "z": 25,
      "name": "Rock_Ice"
    },
    {
      "x": -40,
      "y": 35,
      "z": 25,
      "name": "Soil_Snow"
    },
    {
      "x": -40,
      "y": 23,
      "z": 26,
      "name": "Rock_Ice_Permafrost"
    },
    {
      "x": -40,
      "y": 24,
      "z": 26,
      "name": "Rock_Ice_Permafrost"
    },
    {
      "x": -40,
      "y": 25,
      "z": 26,
      "name": "Rock_Ice_Permafrost"
    },
    {
      "x": -40,
      "y": 26,
      "z": 26,
      "name": "Rock_Ice_Permafrost"
    },
    {
      "x": -40,
      "y": 27,
      "z": 26,
      "name": "Rock_Ice_Permafrost"
    },
    {
      "x": -40,
      "y": 28,
      "z": 26,
      "name": "Rock_Ice_Permafrost"
    },
    {
      "x": -40,
      "y": 29,
      "z": 26,
      "name": "Rock_Ice_Permafrost"
    },
    {
      "x": -40,
      "y": 30,
      "z": 26,
      "name": "Rock_Ice_Permafrost"
    },
    {
      "x": -40,
      "y": 31,
      "z": 26,
      "name": "Rock_Ice_Permafrost"
    },
    {
      "x": -40,
      "y": 32,
      "z": 26,
      "name": "Rock_Ice_Permafrost"
    },
    {
      "x": -40,
      "y": 33,
      "z": 26,
      "name": "Rock_Ice_Permafrost"
    },
    {
      "x": -40,
      "y": 34,
      "z": 26,
      "name": "Rock_Ice"
    },
    {
      "x": -40,
      "y": 35,
      "z": 26,
      "name": "Soil_Snow"
    },
    {
      "x": -40,
      "y": 23,
      "z": 27,
      "name": "Rock_Ice"
    },
    {
      "x": -40,
      "y": 24,
      "z": 27,
      "name": "Rock_Ice"
    },
    {
      "x": -40,
      "y": 25,
      "z": 27,
      "name": "Rock_Ice_Permafrost"
    },
    {
      "x": -40,
      "y": 26,
      "z": 27,
      "name": "Rock_Ice_Permafrost"
    },
    {
      "x": -40,
      "y": 27,
      "z": 27,
      "name": "Rock_Ice_Permafrost"
    },
    {
      "x": -40,
      "y": 28,
      "z": 27,
      "name": "Rock_Ice_Permafrost"
    },
    {
      "x": -40,
      "y": 29,
      "z": 27,
      "name": "Rock_Ice"
    },
    {
      "x": -40,
      "y": 30,
      "z": 27,
      "name": "Rock_Ice"
    },
    {
      "x": -40,
      "y": 31,
      "z": 27,
      "name": "Rock_Ice_Permafrost"
    },
    {
      "x": -40,
      "y": 32,
      "z": 27,
      "name": "Rock_Ice_Permafrost"
    },
    {
      "x": -40,
      "y": 33,
      "z": 27,
      "name": "Rock_Ice_Permafrost"
    },
    {
      "x": -40,
      "y": 34,
      "z": 27,
      "name": "Rock_Ice"
    },
    {
      "x": -40,
      "y": 35,
      "z": 27,
      "name": "Soil_Snow"
    },
    {
      "x": -40,
      "y": 23,
      "z": 28,
      "name": "Rock_Ice"
    },
    {
      "x": -40,
      "y": 24,
      "z": 28,
      "name": "Rock_Ice"
    },
    {
      "x": -40,
      "y": 25,
      "z": 28,
      "name": "Rock_Ice_Permafrost"
    },
    {
      "x": -40,
      "y": 26,
      "z": 28,
      "name": "Rock_Ice"
    },
    {
      "x": -40,
      "y": 27,
      "z": 28,
      "name": "Rock_Ice_Permafrost"
    },
    {
      "x": -40,
      "y": 28,
      "z": 28,
      "name": "Rock_Ice_Permafrost"
    },
    {
      "x": -40,
      "y": 29,
      "z": 28,
      "name": "Rock_Ice_Permafrost"
    },
    {
      "x": -40,
      "y": 30,
      "z": 28,
      "name": "Rock_Ice_Permafrost"
    },
    {
      "x": -40,
      "y": 31,
      "z": 28,
      "name": "Rock_Ice_Permafrost"
    },
    {
      "x": -40,
      "y": 32,
      "z": 28,
      "name": "Rock_Ice_Permafrost"
    },
    {
      "x": -40,
      "y": 33,
      "z": 28,
      "name": "Rock_Ice_Permafrost"
    },
    {
      "x": -40,
      "y": 34,
      "z": 28,
      "name": "Rock_Ice"
    },
    {
      "x": -40,
      "y": 35,
      "z": 28,
      "name": "Rock_Ice_Permafrost"
    },
    {
      "x": -40,
      "y": 23,
      "z": 29,
      "name": "Rock_Ice"
    },
    {
      "x": -40,
      "y": 24,
      "z": 29,
      "name": "Rock_Ice_Permafrost"
    },
    {
      "x": -40,
      "y": 25,
      "z": 29,
      "name": "Rock_Ice_Permafrost"
    },
    {
      "x": -40,
      "y": 26,
      "z": 29,
      "name": "Rock_Ice"
    },
    {
      "x": -40,
      "y": 27,
      "z": 29,
      "name": "Rock_Ice_Permafrost"
    },
    {
      "x": -40,
      "y": 28,
      "z": 29,
      "name": "Rock_Ice_Permafrost"
    },
    {
      "x": -40,
      "y": 29,
      "z": 29,
      "name": "Rock_Ice_Permafrost"
    },
    {
      "x": -40,
      "y": 30,
      "z": 29,
      "name": "Rock_Ice"
    },
    {
      "x": -40,
      "y": 31,
      "z": 29,
      "name": "Rock_Ice_Permafrost"
    },
    {
      "x": -40,
      "y": 32,
      "z": 29,
      "name": "Rock_Ice_Permafrost"
    },
    {
      "x": -40,
      "y": 33,
      "z": 29,
      "name": "Rock_Ice_Permafrost"
    },
    {
      "x": -40,
      "y": 34,
      "z": 29,
      "name": "Rock_Ice_Permafrost"
    },
    {
      "x": -40,
      "y": 35,
      "z": 29,
      "name": "Rock_Ice_Permafrost"
    },
    {
      "x": -40,
      "y": 24,
      "z": 30,
      "name": "Rock_Ice"
    },
    {
      "x": -40,
      "y": 25,
      "z": 30,
      "name": "Rock_Ice_Permafrost"
    },
    {
      "x": -40,
      "y": 26,
      "z": 30,
      "name": "Rock_Ice_Permafrost"
    },
    {
      "x": -40,
      "y": 27,
      "z": 30,
      "name": "Rock_Ice_Permafrost"
    },
    {
      "x": -40,
      "y": 28,
      "z": 30,
      "name": "Rock_Ice_Permafrost"
    },
    {
      "x": -40,
      "y": 29,
      "z": 30,
      "name": "Rock_Ice_Permafrost"
    },
    {
      "x": -40,
      "y": 30,
      "z": 30,
      "name": "Rock_Ice_Permafrost"
    },
    {
      "x": -40,
      "y": 31,
      "z": 30,
      "name": "Rock_Ice"
    },
    {
      "x": -40,
      "y": 32,
      "z": 30,
      "name": "Rock_Ice"
    },
    {
      "x": -40,
      "y": 33,
      "z": 30,
      "name": "Rock_Ice"
    },
    {
      "x": -40,
      "y": 24,
      "z": 31,
      "name": "Rock_Ice_Permafrost"
    },
    {
      "x": -40,
      "y": 25,
      "z": 31,
      "name": "Rock_Ice"
    },
    {
      "x": -40,
      "y": 26,
      "z": 31,
      "name": "Rock_Ice"
    },
    {
      "x": -40,
      "y": 27,
      "z": 31,
      "name": "Rock_Ice_Permafrost"
    },
    {
      "x": -40,
      "y": 28,
      "z": 31,
      "name": "Rock_Ice_Permafrost"
    },
    {
      "x": -40,
      "y": 29,
      "z": 31,
      "name": "Rock_Ice_Permafrost"
    },
    {
      "x": -40,
      "y": 30,
      "z": 31,
      "name": "Rock_Ice"
    },
    {
      "x": -40,
      "y": 31,
      "z": 31,
      "name": "Rock_Ice"
    },
    {
      "x": -40,
      "y": 32,
      "z": 31,
      "name": "Rock_Ice_Permafrost"
    },
    {
      "x": -40,
      "y": 24,
      "z": 32,
      "name": "Rock_Ice"
    },
    {
      "x": -40,
      "y": 25,
      "z": 32,
      "name": "Rock_Ice"
    },
    {
      "x": -40,
      "y": 26,
      "z": 32,
      "name": "Rock_Ice_Permafrost"
    },
    {
      "x": -40,
      "y": 27,
      "z": 32,
      "name": "Rock_Ice_Permafrost"
    },
    {
      "x": -40,
      "y": 28,
      "z": 32,
      "name": "Rock_Ice_Permafrost"
    },
    {
      "x": -40,
      "y": 29,
      "z": 32,
      "name": "Rock_Ice"
    },
    {
      "x": -40,
      "y": 30,
      "z": 32,
      "name": "Rock_Ice"
    },
    {
      "x": -40,
      "y": 31,
      "z": 32,
      "name": "Rock_Ice"
    },
    {
      "x": -40,
      "y": 24,
      "z": 33,
      "name": "Rock_Ice"
    },
    {
      "x": -40,
      "y": 25,
      "z": 33,
      "name": "Rock_Ice_Permafrost"
    },
    {
      "x": -40,
      "y": 26,
      "z": 33,
      "name": "Rock_Ice_Permafrost"
    },
    {
      "x": -40,
      "y": 27,
      "z": 33,
      "name": "Rock_Ice_Permafrost"
    },
    {
      "x": -40,
      "y": 28,
      "z": 33,
      "name": "Rock_Ice"
    },
    {
      "x": -40,
      "y": 29,
      "z": 33,
      "name": "Soil_Snow"
    },
    {
      "x": -40,
      "y": 24,
      "z": 34,
      "name": "Rock_Ice"
    },
    {
      "x": -40,
      "y": 25,
      "z": 34,
      "name": "Rock_Ice_Permafrost"
    },
    {
      "x": -40,
      "y": 26,
      "z": 34,
      "name": "Rock_Ice_Permafrost"
    },
    {
      "x": -40,
      "y": 27,
      "z": 34,
      "name": "Rock_Ice"
    },
    {
      "x": -40,
      "y": 28,
      "z": 34,
      "name": "Soil_Snow"
    },
    {
      "x": -40,
      "y": 24,
      "z": 35,
      "name": "Rock_Ice"
    },
    {
      "x": -40,
      "y": 25,
      "z": 35,
      "name": "Rock_Ice_Permafrost"
    },
    {
      "x": -40,
      "y": 26,
      "z": 35,
      "name": "Rock_Ice"
    },
    {
      "x": -40,
      "y": 27,
      "z": 35,
      "name": "Soil_Snow"
    },
    {
      "x": -40,
      "y": 24,
      "z": 36,
      "name": "Rock_Ice_Permafrost"
    },
    {
      "x": -40,
      "y": 25,
      "z": 36,
      "name": "Rock_Ice"
    },
    {
      "x": -40,
      "y": 26,
      "z": 36,
      "name": "Soil_Snow"
    },
    {
      "x": -40,
      "y": 23,
      "z": 37,
      "name": "Rock_Ice_Permafrost"
    },
    {
      "x": -40,
      "y": 24,
      "z": 37,
      "name": "Rock_Ice"
    },
    {
      "x": -40,
      "y": 25,
      "z": 37,
      "name": "Soil_Snow"
    },
    {
      "x": -40,
      "y": 23,
      "z": 38,
      "name": "Rock_Ice"
    },
    {
      "x": -40,
      "y": 24,
      "z": 38,
      "name": "Soil_Snow"
    },
    {
      "x": -40,
      "y": 22,
      "z": 39,
      "name": "Rock_Ice"
    },
    {
      "x": -40,
      "y": 23,
      "z": 39,
      "name": "Soil_Snow"
    },
    {
      "x": -40,
      "y": 21,
      "z": 40,
      "name": "Rock_Ice"
    },
    {
      "x": -40,
      "y": 22,
      "z": 40,
      "name": "Soil_Snow"
    },
    {
      "x": -40,
      "y": 21,
      "z": 41,
      "name": "Soil_Snow"
    },
    {
      "x": -39,
      "y": 33,
      "z": 12,
      "name": "Rock_Ice"
    },
    {
      "x": -39,
      "y": 34,
      "z": 12,
      "name": "Soil_Snow"
    },
    {
      "x": -39,
      "y": 31,
      "z": 13,
      "name": "Rock_Ice_Permafrost"
    },
    {
      "x": -39,
      "y": 32,
      "z": 13,
      "name": "Rock_Ice_Permafrost"
    },
    {
      "x": -39,
      "y": 33,
      "z": 13,
      "name": "Rock_Ice_Permafrost"
    },
    {
      "x": -39,
      "y": 34,
      "z": 13,
      "name": "Rock_Ice_Permafrost"
    },
    {
      "x": -39,
      "y": 35,
      "z": 13,
      "name": "Soil_Snow"
    },
    {
      "x": -39,
      "y": 30,
      "z": 14,
      "name": "Rock_Ice_Permafrost"
    },
    {
      "x": -39,
      "y": 31,
      "z": 14,
      "name": "Rock_Ice_Permafrost"
    },
    {
      "x": -39,
      "y": 32,
      "z": 14,
      "name": "Rock_Ice_Permafrost"
    },
    {
      "x": -39,
      "y": 33,
      "z": 14,
      "name": "Rock_Ice_Permafrost"
    },
    {
      "x": -39,
      "y": 34,
      "z": 14,
      "name": "Rock_Ice_Permafrost"
    },
    {
      "x": -39,
      "y": 35,
      "z": 14,
      "name": "Rock_Ice_Permafrost"
    },
    {
      "x": -39,
      "y": 36,
      "z": 14,
      "name": "Soil_Snow"
    },
    {
      "x": -39,
      "y": 29,
      "z": 15,
      "name": "Rock_Ice_Permafrost"
    },
    {
      "x": -39,
      "y": 30,
      "z": 15,
      "name": "Rock_Ice_Permafrost"
    },
    {
      "x": -39,
      "y": 31,
      "z": 15,
      "name": "Rock_Ice"
    },
    {
      "x": -39,
      "y": 32,
      "z": 15,
      "name": "Rock_Ice_Permafrost"
    },
    {
      "x": -39,
      "y": 33,
      "z": 15,
      "name": "Rock_Ice_Permafrost"
    },
    {
      "x": -39,
      "y": 34,
      "z": 15,
      "name": "Rock_Ice_Permafrost"
    },
    {
      "x": -39,
      "y": 35,
      "z": 15,
      "name": "Rock_Ice_Permafrost"
    },
    {
      "x": -39,
      "y": 36,
      "z": 15,
      "name": "Rock_Ice_Permafrost"
    },
    {
      "x": -39,
      "y": 37,
      "z": 15,
      "name": "Soil_Snow"
    },
    {
      "x": -39,
      "y": 28,
      "z": 16,
      "name": "Rock_Ice"
    },
    {
      "x": -39,
      "y": 29,
      "z": 16,
      "name": "Rock_Ice"
    },
    {
      "x": -39,
      "y": 30,
      "z": 16,
      "name": "Rock_Ice_Permafrost"
    },
    {
      "x": -39,
      "y": 31,
      "z": 16,
      "name": "Rock_Ice_Permafrost"
    },
    {
      "x": -39,
      "y": 32,
      "z": 16,
      "name": "Rock_Ice_Permafrost"
    },
    {
      "x": -39,
      "y": 33,
      "z": 16,
      "name": "Rock_Ice_Permafrost"
    },
    {
      "x": -39,
      "y": 34,
      "z": 16,
      "name": "Rock_Ice_Permafrost"
    },
    {
      "x": -39,
      "y": 35,
      "z": 16,
      "name": "Rock_Ice_Permafrost"
    },
    {
      "x": -39,
      "y": 36,
      "z": 16,
      "name": "Rock_Ice_Permafrost"
    },
    {
      "x": -39,
      "y": 37,
      "z": 16,
      "name": "Rock_Ice_Permafrost"
    },
    {
      "x": -39,
      "y": 38,
      "z": 16,
      "name": "Soil_Snow"
    },
    {
      "x": -39,
      "y": 27,
      "z": 17,
      "name": "Rock_Ice"
    },
    {
      "x": -39,
      "y": 28,
      "z": 17,
      "name": "Rock_Ice"
    },
    {
      "x": -39,
      "y": 29,
      "z": 17,
      "name": "Rock_Ice_Permafrost"
    },
    {
      "x": -39,
      "y": 30,
      "z": 17,
      "name": "Rock_Ice_Permafrost"
    },
    {
      "x": -39,
      "y": 31,
      "z": 17,
      "name": "Rock_Ice_Permafrost"
    },
    {
      "x": -39,
      "y": 32,
      "z": 17,
      "name": "Rock_Ice_Permafrost"
    },
    {
      "x": -39,
      "y": 33,
      "z": 17,
      "name": "Rock_Ice_Permafrost"
    },
    {
      "x": -39,
      "y": 34,
      "z": 17,
      "name": "Rock_Ice_Permafrost"
    },
    {
      "x": -39,
      "y": 35,
      "z": 17,
      "name": "Rock_Ice_Permafrost"
    },
    {
      "x": -39,
      "y": 36,
      "z": 17,
      "name": "Rock_Ice_Permafrost"
    },
    {
      "x": -39,
      "y": 37,
      "z": 17,
      "name": "Rock_Ice_Permafrost"
    },
    {
      "x": -39,
      "y": 38,
      "z": 17,
      "name": "Soil_Snow"
    },
    {
      "x": -39,
      "y": 26,
      "z": 18,
      "name": "Rock_Ice"
    },
    {
      "x": -39,
      "y": 27,
      "z": 18,
      "name": "Rock_Ice_Permafrost"
    },
    {
      "x": -39,
      "y": 28,
      "z": 18,
      "name": "Rock_Ice_Permafrost"
    },
    {
      "x": -39,
      "y": 29,
      "z": 18,
      "name": "Rock_Ice"
    },
    {
      "x": -39,
      "y": 30,
      "z": 18,
      "name": "Rock_Ice_Permafrost"
    },
    {
      "x": -39,
      "y": 31,
      "z": 18,
      "name": "Rock_Ice_Permafrost"
    },
    {
      "x": -39,
      "y": 32,
      "z": 18,
      "name": "Rock_Ice_Permafrost"
    },
    {
      "x": -39,
      "y": 33,
      "z": 18,
      "name": "Rock_Ice_Permafrost"
    },
    {
      "x": -39,
      "y": 34,
      "z": 18,
      "name": "Rock_Ice_Permafrost"
    },
    {
      "x": -39,
      "y": 35,
      "z": 18,
      "name": "Rock_Ice_Permafrost"
    },
    {
      "x": -39,
      "y": 36,
      "z": 18,
      "name": "Rock_Ice_Permafrost"
    },
    {
      "x": -39,
      "y": 37,
      "z": 18,
      "name": "Rock_Ice_Permafrost"
    },
    {
      "x": -39,
      "y": 38,
      "z": 18,
      "name": "Soil_Snow"
    },
    {
      "x": -39,
      "y": 26,
      "z": 19,
      "name": "Rock_Ice"
    },
    {
      "x": -39,
      "y": 27,
      "z": 19,
      "name": "Rock_Ice"
    },
    {
      "x": -39,
      "y": 28,
      "z": 19,
      "name": "Rock_Ice_Permafrost"
    },
    {
      "x": -39,
      "y": 29,
      "z": 19,
      "name": "Rock_Ice_Permafrost"
    },
    {
      "x": -39,
      "y": 30,
      "z": 19,
      "name": "Rock_Ice_Permafrost"
    },
    {
      "x": -39,
      "y": 31,
      "z": 19,
      "name": "Rock_Ice_Permafrost"
    },
    {
      "x": -39,
      "y": 32,
      "z": 19,
      "name": "Rock_Ice_Permafrost"
    },
    {
      "x": -39,
      "y": 33,
      "z": 19,
      "name": "Rock_Ice_Permafrost"
    },
    {
      "x": -39,
      "y": 34,
      "z": 19,
      "name": "Rock_Ice_Permafrost"
    },
    {
      "x": -39,
      "y": 35,
      "z": 19,
      "name": "Rock_Ice_Permafrost"
    },
    {
      "x": -39,
      "y": 36,
      "z": 19,
      "name": "Rock_Ice_Permafrost"
    },
    {
      "x": -39,
      "y": 37,
      "z": 19,
      "name": "Rock_Ice_Permafrost"
    },
    {
      "x": -39,
      "y": 38,
      "z": 19,
      "name": "Soil_Snow"
    },
    {
      "x": -39,
      "y": 25,
      "z": 20,
      "name": "Rock_Ice"
    },
    {
      "x": -39,
      "y": 26,
      "z": 20,
      "name": "Rock_Ice_Permafrost"
    },
    {
      "x": -39,
      "y": 27,
      "z": 20,
      "name": "Rock_Ice_Permafrost"
    },
    {
      "x": -39,
      "y": 28,
      "z": 20,
      "name": "Rock_Ice"
    },
    {
      "x": -39,
      "y": 29,
      "z": 20,
      "name": "Rock_Ice_Permafrost"
    },
    {
      "x": -39,
      "y": 30,
      "z": 20,
      "name": "Rock_Ice_Permafrost"
    },
    {
      "x": -39,
      "y": 31,
      "z": 20,
      "name": "Rock_Ice_Permafrost"
    },
    {
      "x": -39,
      "y": 32,
      "z": 20,
      "name": "Rock_Ice_Permafrost"
    },
    {
      "x": -39,
      "y": 33,
      "z": 20,
      "name": "Rock_Ice_Permafrost"
    },
    {
      "x": -39,
      "y": 34,
      "z": 20,
      "name": "Rock_Ice_Permafrost"
    },
    {
      "x": -39,
      "y": 35,
      "z": 20,
      "name": "Rock_Ice_Permafrost"
    },
    {
      "x": -39,
      "y": 36,
      "z": 20,
      "name": "Rock_Ice_Permafrost"
    },
    {
      "x": -39,
      "y": 37,
      "z": 20,
      "name": "Rock_Ice_Permafrost"
    },
    {
      "x": -39,
      "y": 38,
      "z": 20,
      "name": "Soil_Snow"
    },
    {
      "x": -39,
      "y": 25,
      "z": 21,
      "name": "Rock_Ice_Permafrost"
    },
    {
      "x": -39,
      "y": 26,
      "z": 21,
      "name": "Rock_Ice"
    },
    {
      "x": -39,
      "y": 27,
      "z": 21,
      "name": "Rock_Ice_Permafrost"
    },
    {
      "x": -39,
      "y": 28,
      "z": 21,
      "name": "Rock_Ice_Permafrost"
    },
    {
      "x": -39,
      "y": 29,
      "z": 21,
      "name": "Rock_Ice_Permafrost"
    },
    {
      "x": -39,
      "y": 30,
      "z": 21,
      "name": "Rock_Ice_Permafrost"
    },
    {
      "x": -39,
      "y": 31,
      "z": 21,
      "name": "Rock_Ice_Permafrost"
    },
    {
      "x": -39,
      "y": 32,
      "z": 21,
      "name": "Rock_Ice_Permafrost"
    },
    {
      "x": -39,
      "y": 33,
      "z": 21,
      "name": "Rock_Ice_Permafrost"
    },
    {
      "x": -39,
      "y": 34,
      "z": 21,
      "name": "Rock_Ice_Permafrost"
    },
    {
      "x": -39,
      "y": 35,
      "z": 21,
      "name": "Rock_Ice_Permafrost"
    },
    {
      "x": -39,
      "y": 36,
      "z": 21,
      "name": "Rock_Ice_Permafrost"
    },
    {
      "x": -39,
      "y": 37,
      "z": 21,
      "name": "Soil_Snow"
    },
    {
      "x": -39,
      "y": 24,
      "z": 22,
      "name": "Rock_Ice_Permafrost"
    },
    {
      "x": -39,
      "y": 25,
      "z": 22,
      "name": "Rock_Ice_Permafrost"
    },
    {
      "x": -39,
      "y": 26,
      "z": 22,
      "name": "Rock_Ice_Permafrost"
    },
    {
      "x": -39,
      "y": 27,
      "z": 22,
      "name": "Rock_Ice_Permafrost"
    },
    {
      "x": -39,
      "y": 28,
      "z": 22,
      "name": "Rock_Ice_Permafrost"
    },
    {
      "x": -39,
      "y": 29,
      "z": 22,
      "name": "Rock_Ice_Permafrost"
    },
    {
      "x": -39,
      "y": 30,
      "z": 22,
      "name": "Rock_Ice_Permafrost"
    },
    {
      "x": -39,
      "y": 31,
      "z": 22,
      "name": "Rock_Ice_Permafrost"
    },
    {
      "x": -39,
      "y": 32,
      "z": 22,
      "name": "Rock_Ice_Permafrost"
    },
    {
      "x": -39,
      "y": 33,
      "z": 22,
      "name": "Rock_Ice_Permafrost"
    },
    {
      "x": -39,
      "y": 34,
      "z": 22,
      "name": "Rock_Ice_Permafrost"
    },
    {
      "x": -39,
      "y": 35,
      "z": 22,
      "name": "Rock_Ice_Permafrost"
    },
    {
      "x": -39,
      "y": 36,
      "z": 22,
      "name": "Rock_Ice"
    },
    {
      "x": -39,
      "y": 37,
      "z": 22,
      "name": "Soil_Snow"
    },
    {
      "x": -39,
      "y": 24,
      "z": 23,
      "name": "Rock_Ice"
    },
    {
      "x": -39,
      "y": 25,
      "z": 23,
      "name": "Rock_Ice"
    },
    {
      "x": -39,
      "y": 26,
      "z": 23,
      "name": "Rock_Ice_Permafrost"
    },
    {
      "x": -39,
      "y": 27,
      "z": 23,
      "name": "Rock_Ice_Permafrost"
    },
    {
      "x": -39,
      "y": 28,
      "z": 23,
      "name": "Rock_Ice_Permafrost"
    },
    {
      "x": -39,
      "y": 29,
      "z": 23,
      "name": "Rock_Ice_Permafrost"
    },
    {
      "x": -39,
      "y": 30,
      "z": 23,
      "name": "Rock_Ice_Permafrost"
    },
    {
      "x": -39,
      "y": 31,
      "z": 23,
      "name": "Rock_Ice_Permafrost"
    },
    {
      "x": -39,
      "y": 32,
      "z": 23,
      "name": "Rock_Ice_Permafrost"
    },
    {
      "x": -39,
      "y": 33,
      "z": 23,
      "name": "Rock_Ice_Permafrost"
    },
    {
      "x": -39,
      "y": 34,
      "z": 23,
      "name": "Rock_Ice_Permafrost"
    },
    {
      "x": -39,
      "y": 35,
      "z": 23,
      "name": "Rock_Ice_Permafrost"
    },
    {
      "x": -39,
      "y": 36,
      "z": 23,
      "name": "Rock_Ice"
    },
    {
      "x": -39,
      "y": 37,
      "z": 23,
      "name": "Soil_Snow"
    },
    {
      "x": -39,
      "y": 23,
      "z": 24,
      "name": "Rock_Ice"
    },
    {
      "x": -39,
      "y": 24,
      "z": 24,
      "name": "Rock_Ice"
    },
    {
      "x": -39,
      "y": 25,
      "z": 24,
      "name": "Rock_Ice_Permafrost"
    },
    {
      "x": -39,
      "y": 26,
      "z": 24,
      "name": "Rock_Ice_Permafrost"
    },
    {
      "x": -39,
      "y": 27,
      "z": 24,
      "name": "Rock_Ice_Permafrost"
    },
    {
      "x": -39,
      "y": 28,
      "z": 24,
      "name": "Rock_Ice_Permafrost"
    },
    {
      "x": -39,
      "y": 29,
      "z": 24,
      "name": "Rock_Ice_Permafrost"
    },
    {
      "x": -39,
      "y": 30,
      "z": 24,
      "name": "Rock_Ice_Permafrost"
    },
    {
      "x": -39,
      "y": 31,
      "z": 24,
      "name": "Rock_Ice_Permafrost"
    },
    {
      "x": -39,
      "y": 32,
      "z": 24,
      "name": "Rock_Ice_Permafrost"
    },
    {
      "x": -39,
      "y": 33,
      "z": 24,
      "name": "Rock_Ice_Permafrost"
    },
    {
      "x": -39,
      "y": 34,
      "z": 24,
      "name": "Rock_Ice"
    },
    {
      "x": -39,
      "y": 35,
      "z": 24,
      "name": "Rock_Ice_Permafrost"
    },
    {
      "x": -39,
      "y": 36,
      "z": 24,
      "name": "Rock_Ice"
    },
    {
      "x": -39,
      "y": 37,
      "z": 24,
      "name": "Soil_Snow"
    },
    {
      "x": -39,
      "y": 23,
      "z": 25,
      "name": "Rock_Ice_Permafrost"
    },
    {
      "x": -39,
      "y": 24,
      "z": 25,
      "name": "Rock_Ice"
    },
    {
      "x": -39,
      "y": 25,
      "z": 25,
      "name": "Rock_Ice"
    },
    {
      "x": -39,
      "y": 26,
      "z": 25,
      "name": "Rock_Ice"
    },
    {
      "x": -39,
      "y": 27,
      "z": 25,
      "name": "Rock_Ice_Permafrost"
    },
    {
      "x": -39,
      "y": 28,
      "z": 25,
      "name": "Rock_Ice"
    },
    {
      "x": -39,
      "y": 29,
      "z": 25,
      "name": "Rock_Ice_Permafrost"
    },
    {
      "x": -39,
      "y": 30,
      "z": 25,
      "name": "Rock_Ice_Permafrost"
    },
    {
      "x": -39,
      "y": 31,
      "z": 25,
      "name": "Rock_Ice_Permafrost"
    },
    {
      "x": -39,
      "y": 32,
      "z": 25,
      "name": "Rock_Ice_Permafrost"
    },
    {
      "x": -39,
      "y": 33,
      "z": 25,
      "name": "Rock_Ice_Permafrost"
    },
    {
      "x": -39,
      "y": 34,
      "z": 25,
      "name": "Rock_Ice"
    },
    {
      "x": -39,
      "y": 35,
      "z": 25,
      "name": "Rock_Ice"
    },
    {
      "x": -39,
      "y": 36,
      "z": 25,
      "name": "Rock_Ice"
    },
    {
      "x": -39,
      "y": 37,
      "z": 25,
      "name": "Rock_Ice_Permafrost"
    },
    {
      "x": -39,
      "y": 23,
      "z": 26,
      "name": "Rock_Ice_Permafrost"
    },
    {
      "x": -39,
      "y": 24,
      "z": 26,
      "name": "Rock_Ice"
    },
    {
      "x": -39,
      "y": 25,
      "z": 26,
      "name": "Rock_Ice"
    },
    {
      "x": -39,
      "y": 26,
      "z": 26,
      "name": "Rock_Ice"
    },
    {
      "x": -39,
      "y": 27,
      "z": 26,
      "name": "Rock_Ice"
    },
    {
      "x": -39,
      "y": 28,
      "z": 26,
      "name": "Rock_Ice_Permafrost"
    },
    {
      "x": -39,
      "y": 29,
      "z": 26,
      "name": "Rock_Ice_Permafrost"
    },
    {
      "x": -39,
      "y": 30,
      "z": 26,
      "name": "Rock_Ice_Permafrost"
    },
    {
      "x": -39,
      "y": 31,
      "z": 26,
      "name": "Rock_Ice_Permafrost"
    },
    {
      "x": -39,
      "y": 32,
      "z": 26,
      "name": "Rock_Ice_Permafrost"
    },
    {
      "x": -39,
      "y": 33,
      "z": 26,
      "name": "Rock_Ice_Permafrost"
    },
    {
      "x": -39,
      "y": 34,
      "z": 26,
      "name": "Rock_Ice"
    },
    {
      "x": -39,
      "y": 35,
      "z": 26,
      "name": "Rock_Ice"
    },
    {
      "x": -39,
      "y": 36,
      "z": 26,
      "name": "Soil_Snow"
    },
    {
      "x": -39,
      "y": 23,
      "z": 27,
      "name": "Rock_Ice"
    },
    {
      "x": -39,
      "y": 24,
      "z": 27,
      "name": "Rock_Ice"
    },
    {
      "x": -39,
      "y": 25,
      "z": 27,
      "name": "Rock_Ice"
    },
    {
      "x": -39,
      "y": 26,
      "z": 27,
      "name": "Rock_Ice"
    },
    {
      "x": -39,
      "y": 27,
      "z": 27,
      "name": "Rock_Ice"
    },
    {
      "x": -39,
      "y": 28,
      "z": 27,
      "name": "Rock_Ice"
    },
    {
      "x": -39,
      "y": 29,
      "z": 27,
      "name": "Rock_Ice_Permafrost"
    },
    {
      "x": -39,
      "y": 30,
      "z": 27,
      "name": "Rock_Ice_Permafrost"
    },
    {
      "x": -39,
      "y": 31,
      "z": 27,
      "name": "Rock_Ice_Permafrost"
    },
    {
      "x": -39,
      "y": 32,
      "z": 27,
      "name": "Rock_Ice"
    },
    {
      "x": -39,
      "y": 33,
      "z": 27,
      "name": "Rock_Ice_Permafrost"
    },
    {
      "x": -39,
      "y": 34,
      "z": 27,
      "name": "Rock_Ice_Permafrost"
    },
    {
      "x": -39,
      "y": 35,
      "z": 27,
      "name": "Rock_Ice"
    },
    {
      "x": -39,
      "y": 36,
      "z": 27,
      "name": "Rock_Ice_Permafrost"
    },
    {
      "x": -39,
      "y": 23,
      "z": 28,
      "name": "Rock_Ice"
    },
    {
      "x": -39,
      "y": 24,
      "z": 28,
      "name": "Rock_Ice_Permafrost"
    },
    {
      "x": -39,
      "y": 25,
      "z": 28,
      "name": "Rock_Ice_Permafrost"
    },
    {
      "x": -39,
      "y": 26,
      "z": 28,
      "name": "Rock_Ice"
    },
    {
      "x": -39,
      "y": 27,
      "z": 28,
      "name": "Rock_Ice"
    },
    {
      "x": -39,
      "y": 28,
      "z": 28,
      "name": "Rock_Ice"
    },
    {
      "x": -39,
      "y": 29,
      "z": 28,
      "name": "Rock_Ice_Permafrost"
    },
    {
      "x": -39,
      "y": 30,
      "z": 28,
      "name": "Rock_Ice_Permafrost"
    },
    {
      "x": -39,
      "y": 31,
      "z": 28,
      "name": "Rock_Ice_Permafrost"
    },
    {
      "x": -39,
      "y": 32,
      "z": 28,
      "name": "Rock_Ice"
    },
    {
      "x": -39,
      "y": 33,
      "z": 28,
      "name": "Rock_Ice_Permafrost"
    },
    {
      "x": -39,
      "y": 34,
      "z": 28,
      "name": "Rock_Ice_Permafrost"
    },
    {
      "x": -39,
      "y": 35,
      "z": 28,
      "name": "Rock_Ice"
    },
    {
      "x": -39,
      "y": 36,
      "z": 28,
      "name": "Rock_Ice_Permafrost"
    },
    {
      "x": -39,
      "y": 23,
      "z": 29,
      "name": "Rock_Ice"
    },
    {
      "x": -39,
      "y": 24,
      "z": 29,
      "name": "Rock_Ice"
    },
    {
      "x": -39,
      "y": 25,
      "z": 29,
      "name": "Rock_Ice_Permafrost"
    },
    {
      "x": -39,
      "y": 26,
      "z": 29,
      "name": "Rock_Ice"
    },
    {
      "x": -39,
      "y": 27,
      "z": 29,
      "name": "Rock_Ice"
    },
    {
      "x": -39,
      "y": 28,
      "z": 29,
      "name": "Rock_Ice"
    },
    {
      "x": -39,
      "y": 29,
      "z": 29,
      "name": "Rock_Ice_Permafrost"
    },
    {
      "x": -39,
      "y": 30,
      "z": 29,
      "name": "Rock_Ice_Permafrost"
    },
    {
      "x": -39,
      "y": 31,
      "z": 29,
      "name": "Rock_Ice_Permafrost"
    },
    {
      "x": -39,
      "y": 32,
      "z": 29,
      "name": "Rock_Ice_Permafrost"
    },
    {
      "x": -39,
      "y": 33,
      "z": 29,
      "name": "Rock_Ice_Permafrost"
    },
    {
      "x": -39,
      "y": 34,
      "z": 29,
      "name": "Rock_Ice"
    },
    {
      "x": -39,
      "y": 35,
      "z": 29,
      "name": "Rock_Ice_Permafrost"
    },
    {
      "x": -39,
      "y": 36,
      "z": 29,
      "name": "Rock_Ice_Permafrost"
    },
    {
      "x": -39,
      "y": 23,
      "z": 30,
      "name": "Rock_Ice_Permafrost"
    },
    {
      "x": -39,
      "y": 24,
      "z": 30,
      "name": "Rock_Ice"
    },
    {
      "x": -39,
      "y": 25,
      "z": 30,
      "name": "Rock_Ice"
    },
    {
      "x": -39,
      "y": 26,
      "z": 30,
      "name": "Rock_Ice_Permafrost"
    },
    {
      "x": -39,
      "y": 27,
      "z": 30,
      "name": "Rock_Ice"
    },
    {
      "x": -39,
      "y": 28,
      "z": 30,
      "name": "Rock_Ice"
    },
    {
      "x": -39,
      "y": 29,
      "z": 30,
      "name": "Rock_Ice_Permafrost"
    },
    {
      "x": -39,
      "y": 30,
      "z": 30,
      "name": "Rock_Ice_Permafrost"
    },
    {
      "x": -39,
      "y": 31,
      "z": 30,
      "name": "Rock_Ice"
    },
    {
      "x": -39,
      "y": 32,
      "z": 30,
      "name": "Rock_Ice"
    },
    {
      "x": -39,
      "y": 33,
      "z": 30,
      "name": "Rock_Ice"
    },
    {
      "x": -39,
      "y": 34,
      "z": 30,
      "name": "Rock_Ice"
    },
    {
      "x": -39,
      "y": 35,
      "z": 30,
      "name": "Rock_Ice_Permafrost"
    },
    {
      "x": -39,
      "y": 23,
      "z": 31,
      "name": "Rock_Ice"
    },
    {
      "x": -39,
      "y": 24,
      "z": 31,
      "name": "Rock_Ice_Permafrost"
    },
    {
      "x": -39,
      "y": 25,
      "z": 31,
      "name": "Rock_Ice"
    },
    {
      "x": -39,
      "y": 26,
      "z": 31,
      "name": "Rock_Ice"
    },
    {
      "x": -39,
      "y": 27,
      "z": 31,
      "name": "Rock_Ice"
    },
    {
      "x": -39,
      "y": 28,
      "z": 31,
      "name": "Rock_Ice_Permafrost"
    },
    {
      "x": -39,
      "y": 29,
      "z": 31,
      "name": "Rock_Ice_Permafrost"
    },
    {
      "x": -39,
      "y": 30,
      "z": 31,
      "name": "Rock_Ice"
    },
    {
      "x": -39,
      "y": 31,
      "z": 31,
      "name": "Rock_Ice"
    },
    {
      "x": -39,
      "y": 32,
      "z": 31,
      "name": "Rock_Ice"
    },
    {
      "x": -39,
      "y": 33,
      "z": 31,
      "name": "Rock_Ice"
    },
    {
      "x": -39,
      "y": 34,
      "z": 31,
      "name": "Rock_Ice"
    },
    {
      "x": -39,
      "y": 24,
      "z": 32,
      "name": "Rock_Ice_Permafrost"
    },
    {
      "x": -39,
      "y": 25,
      "z": 32,
      "name": "Rock_Ice"
    },
    {
      "x": -39,
      "y": 26,
      "z": 32,
      "name": "Rock_Ice"
    },
    {
      "x": -39,
      "y": 27,
      "z": 32,
      "name": "Rock_Ice"
    },
    {
      "x": -39,
      "y": 28,
      "z": 32,
      "name": "Rock_Ice_Permafrost"
    },
    {
      "x": -39,
      "y": 29,
      "z": 32,
      "name": "Rock_Ice_Permafrost"
    },
    {
      "x": -39,
      "y": 30,
      "z": 32,
      "name": "Rock_Ice"
    },
    {
      "x": -39,
      "y": 31,
      "z": 32,
      "name": "Rock_Ice"
    },
    {
      "x": -39,
      "y": 32,
      "z": 32,
      "name": "Rock_Ice"
    },
    {
      "x": -39,
      "y": 33,
      "z": 32,
      "name": "Rock_Ice"
    },
    {
      "x": -39,
      "y": 24,
      "z": 33,
      "name": "Rock_Ice"
    },
    {
      "x": -39,
      "y": 25,
      "z": 33,
      "name": "Rock_Ice_Permafrost"
    },
    {
      "x": -39,
      "y": 26,
      "z": 33,
      "name": "Rock_Ice"
    },
    {
      "x": -39,
      "y": 27,
      "z": 33,
      "name": "Rock_Ice_Permafrost"
    },
    {
      "x": -39,
      "y": 28,
      "z": 33,
      "name": "Rock_Ice_Permafrost"
    },
    {
      "x": -39,
      "y": 29,
      "z": 33,
      "name": "Rock_Ice"
    },
    {
      "x": -39,
      "y": 30,
      "z": 33,
      "name": "Rock_Ice"
    },
    {
      "x": -39,
      "y": 31,
      "z": 33,
      "name": "Soil_Snow"
    },
    {
      "x": -39,
      "y": 24,
      "z": 34,
      "name": "Rock_Ice"
    },
    {
      "x": -39,
      "y": 25,
      "z": 34,
      "name": "Rock_Ice"
    },
    {
      "x": -39,
      "y": 26,
      "z": 34,
      "name": "Rock_Ice"
    },
    {
      "x": -39,
      "y": 27,
      "z": 34,
      "name": "Rock_Ice_Permafrost"
    },
    {
      "x": -39,
      "y": 28,
      "z": 34,
      "name": "Rock_Ice"
    },
    {
      "x": -39,
      "y": 29,
      "z": 34,
      "name": "Rock_Ice"
    },
    {
      "x": -39,
      "y": 30,
      "z": 34,
      "name": "Soil_Snow"
    },
    {
      "x": -39,
      "y": 23,
      "z": 35,
      "name": "Rock_Ice_Permafrost"
    },
    {
      "x": -39,
      "y": 24,
      "z": 35,
      "name": "Rock_Ice_Permafrost"
    },
    {
      "x": -39,
      "y": 25,
      "z": 35,
      "name": "Rock_Ice_Permafrost"
    },
    {
      "x": -39,
      "y": 26,
      "z": 35,
      "name": "Rock_Ice_Permafrost"
    },
    {
      "x": -39,
      "y": 27,
      "z": 35,
      "name": "Rock_Ice"
    },
    {
      "x": -39,
      "y": 28,
      "z": 35,
      "name": "Rock_Ice"
    },
    {
      "x": -39,
      "y": 29,
      "z": 35,
      "name": "Soil_Snow"
    },
    {
      "x": -39,
      "y": 23,
      "z": 36,
      "name": "Rock_Ice_Permafrost"
    },
    {
      "x": -39,
      "y": 24,
      "z": 36,
      "name": "Rock_Ice_Permafrost"
    },
    {
      "x": -39,
      "y": 25,
      "z": 36,
      "name": "Rock_Ice_Permafrost"
    },
    {
      "x": -39,
      "y": 26,
      "z": 36,
      "name": "Rock_Ice"
    },
    {
      "x": -39,
      "y": 27,
      "z": 36,
      "name": "Rock_Ice"
    },
    {
      "x": -39,
      "y": 28,
      "z": 36,
      "name": "Soil_Snow"
    },
    {
      "x": -39,
      "y": 22,
      "z": 37,
      "name": "Rock_Ice_Permafrost"
    },
    {
      "x": -39,
      "y": 23,
      "z": 37,
      "name": "Rock_Ice_Permafrost"
    },
    {
      "x": -39,
      "y": 24,
      "z": 37,
      "name": "Rock_Ice_Permafrost"
    },
    {
      "x": -39,
      "y": 25,
      "z": 37,
      "name": "Rock_Ice_Permafrost"
    },
    {
      "x": -39,
      "y": 26,
      "z": 37,
      "name": "Rock_Ice"
    },
    {
      "x": -39,
      "y": 27,
      "z": 37,
      "name": "Soil_Snow"
    },
    {
      "x": -39,
      "y": 22,
      "z": 38,
      "name": "Rock_Ice_Permafrost"
    },
    {
      "x": -39,
      "y": 23,
      "z": 38,
      "name": "Rock_Ice_Permafrost"
    },
    {
      "x": -39,
      "y": 24,
      "z": 38,
      "name": "Rock_Ice_Permafrost"
    },
    {
      "x": -39,
      "y": 25,
      "z": 38,
      "name": "Rock_Ice_Permafrost"
    },
    {
      "x": -39,
      "y": 26,
      "z": 38,
      "name": "Rock_Ice"
    },
    {
      "x": -39,
      "y": 27,
      "z": 38,
      "name": "Soil_Snow"
    },
    {
      "x": -39,
      "y": 21,
      "z": 39,
      "name": "Rock_Ice_Permafrost"
    },
    {
      "x": -39,
      "y": 22,
      "z": 39,
      "name": "Rock_Ice_Permafrost"
    },
    {
      "x": -39,
      "y": 23,
      "z": 39,
      "name": "Rock_Ice_Permafrost"
    },
    {
      "x": -39,
      "y": 24,
      "z": 39,
      "name": "Rock_Ice_Permafrost"
    },
    {
      "x": -39,
      "y": 25,
      "z": 39,
      "name": "Rock_Ice"
    },
    {
      "x": -39,
      "y": 26,
      "z": 39,
      "name": "Soil_Snow"
    },
    {
      "x": -39,
      "y": 21,
      "z": 40,
      "name": "Rock_Ice_Permafrost"
    },
    {
      "x": -39,
      "y": 22,
      "z": 40,
      "name": "Rock_Ice_Permafrost"
    },
    {
      "x": -39,
      "y": 23,
      "z": 40,
      "name": "Rock_Ice_Permafrost"
    },
    {
      "x": -39,
      "y": 24,
      "z": 40,
      "name": "Rock_Ice"
    },
    {
      "x": -39,
      "y": 25,
      "z": 40,
      "name": "Soil_Snow"
    },
    {
      "x": -39,
      "y": 21,
      "z": 41,
      "name": "Rock_Ice_Permafrost"
    },
    {
      "x": -39,
      "y": 22,
      "z": 41,
      "name": "Rock_Ice_Permafrost"
    },
    {
      "x": -39,
      "y": 23,
      "z": 41,
      "name": "Rock_Ice"
    },
    {
      "x": -39,
      "y": 24,
      "z": 41,
      "name": "Soil_Snow"
    },
    {
      "x": -38,
      "y": 31,
      "z": 8,
      "name": "Rock_Ice_Permafrost"
    },
    {
      "x": -38,
      "y": 32,
      "z": 8,
      "name": "Rock_Ice_Permafrost"
    },
    {
      "x": -38,
      "y": 33,
      "z": 8,
      "name": "Soil_Snow"
    },
    {
      "x": -38,
      "y": 31,
      "z": 9,
      "name": "Rock_Ice_Permafrost"
    },
    {
      "x": -38,
      "y": 32,
      "z": 9,
      "name": "Rock_Ice_Permafrost"
    },
    {
      "x": -38,
      "y": 33,
      "z": 9,
      "name": "Rock_Ice_Permafrost"
    },
    {
      "x": -38,
      "y": 34,
      "z": 9,
      "name": "Soil_Snow"
    },
    {
      "x": -38,
      "y": 30,
      "z": 10,
      "name": "Rock_Ice_Permafrost"
    },
    {
      "x": -38,
      "y": 31,
      "z": 10,
      "name": "Rock_Ice_Permafrost"
    },
    {
      "x": -38,
      "y": 32,
      "z": 10,
      "name": "Rock_Ice_Permafrost"
    },
    {
      "x": -38,
      "y": 33,
      "z": 10,
      "name": "Rock_Ice_Permafrost"
    },
    {
      "x": -38,
      "y": 34,
      "z": 10,
      "name": "Rock_Ice_Permafrost"
    },
    {
      "x": -38,
      "y": 35,
      "z": 10,
      "name": "Soil_Snow"
    },
    {
      "x": -38,
      "y": 30,
      "z": 11,
      "name": "Rock_Ice_Permafrost"
    },
    {
      "x": -38,
      "y": 31,
      "z": 11,
      "name": "Rock_Ice_Permafrost"
    },
    {
      "x": -38,
      "y": 32,
      "z": 11,
      "name": "Rock_Ice_Permafrost"
    },
    {
      "x": -38,
      "y": 33,
      "z": 11,
      "name": "Rock_Ice_Permafrost"
    },
    {
      "x": -38,
      "y": 34,
      "z": 11,
      "name": "Rock_Ice_Permafrost"
    },
    {
      "x": -38,
      "y": 35,
      "z": 11,
      "name": "Rock_Ice_Permafrost"
    },
    {
      "x": -38,
      "y": 36,
      "z": 11,
      "name": "Soil_Snow"
    },
    {
      "x": -38,
      "y": 29,
      "z": 12,
      "name": "Rock_Ice"
    },
    {
      "x": -38,
      "y": 30,
      "z": 12,
      "name": "Rock_Ice_Permafrost"
    },
    {
      "x": -38,
      "y": 31,
      "z": 12,
      "name": "Rock_Ice_Permafrost"
    },
    {
      "x": -38,
      "y": 32,
      "z": 12,
      "name": "Rock_Ice_Permafrost"
    },
    {
      "x": -38,
      "y": 33,
      "z": 12,
      "name": "Rock_Ice_Permafrost"
    },
    {
      "x": -38,
      "y": 34,
      "z": 12,
      "name": "Rock_Ice_Permafrost"
    },
    {
      "x": -38,
      "y": 35,
      "z": 12,
      "name": "Rock_Ice_Permafrost"
    },
    {
      "x": -38,
      "y": 36,
      "z": 12,
      "name": "Rock_Ice_Permafrost"
    },
    {
      "x": -38,
      "y": 37,
      "z": 12,
      "name": "Soil_Snow"
    },
    {
      "x": -38,
      "y": 29,
      "z": 13,
      "name": "Rock_Ice"
    },
    {
      "x": -38,
      "y": 30,
      "z": 13,
      "name": "Rock_Ice"
    },
    {
      "x": -38,
      "y": 31,
      "z": 13,
      "name": "Rock_Ice_Permafrost"
    },
    {
      "x": -38,
      "y": 32,
      "z": 13,
      "name": "Rock_Ice_Permafrost"
    },
    {
      "x": -38,
      "y": 33,
      "z": 13,
      "name": "Rock_Ice_Permafrost"
    },
    {
      "x": -38,
      "y": 34,
      "z": 13,
      "name": "Rock_Ice_Permafrost"
    },
    {
      "x": -38,
      "y": 35,
      "z": 13,
      "name": "Rock_Ice_Permafrost"
    },
    {
      "x": -38,
      "y": 36,
      "z": 13,
      "name": "Rock_Ice_Permafrost"
    },
    {
      "x": -38,
      "y": 37,
      "z": 13,
      "name": "Rock_Ice"
    },
    {
      "x": -38,
      "y": 38,
      "z": 13,
      "name": "Rock_Ice_Permafrost"
    },
    {
      "x": -38,
      "y": 28,
      "z": 14,
      "name": "Rock_Ice"
    },
    {
      "x": -38,
      "y": 29,
      "z": 14,
      "name": "Rock_Ice"
    },
    {
      "x": -38,
      "y": 30,
      "z": 14,
      "name": "Rock_Ice_Permafrost"
    },
    {
      "x": -38,
      "y": 31,
      "z": 14,
      "name": "Rock_Ice_Permafrost"
    },
    {
      "x": -38,
      "y": 32,
      "z": 14,
      "name": "Rock_Ice_Permafrost"
    },
    {
      "x": -38,
      "y": 33,
      "z": 14,
      "name": "Rock_Ice_Permafrost"
    },
    {
      "x": -38,
      "y": 34,
      "z": 14,
      "name": "Rock_Ice_Permafrost"
    },
    {
      "x": -38,
      "y": 35,
      "z": 14,
      "name": "Rock_Ice_Permafrost"
    },
    {
      "x": -38,
      "y": 36,
      "z": 14,
      "name": "Rock_Ice_Permafrost"
    },
    {
      "x": -38,
      "y": 37,
      "z": 14,
      "name": "Rock_Ice_Permafrost"
    },
    {
      "x": -38,
      "y": 38,
      "z": 14,
      "name": "Rock_Ice_Permafrost"
    },
    {
      "x": -38,
      "y": 39,
      "z": 14,
      "name": "Rock_Ice_Permafrost"
    },
    {
      "x": -38,
      "y": 28,
      "z": 15,
      "name": "Rock_Ice"
    },
    {
      "x": -38,
      "y": 29,
      "z": 15,
      "name": "Rock_Ice"
    },
    {
      "x": -38,
      "y": 30,
      "z": 15,
      "name": "Rock_Ice"
    },
    {
      "x": -38,
      "y": 31,
      "z": 15,
      "name": "Rock_Ice_Permafrost"
    },
    {
      "x": -38,
      "y": 32,
      "z": 15,
      "name": "Rock_Ice_Permafrost"
    },
    {
      "x": -38,
      "y": 33,
      "z": 15,
      "name": "Rock_Ice_Permafrost"
    },
    {
      "x": -38,
      "y": 34,
      "z": 15,
      "name": "Rock_Ice_Permafrost"
    },
    {
      "x": -38,
      "y": 35,
      "z": 15,
      "name": "Rock_Ice_Permafrost"
    },
    {
      "x": -38,
      "y": 36,
      "z": 15,
      "name": "Rock_Ice_Permafrost"
    },
    {
      "x": -38,
      "y": 37,
      "z": 15,
      "name": "Rock_Ice_Permafrost"
    },
    {
      "x": -38,
      "y": 38,
      "z": 15,
      "name": "Rock_Ice_Permafrost"
    },
    {
      "x": -38,
      "y": 39,
      "z": 15,
      "name": "Rock_Ice_Permafrost"
    },
    {
      "x": -38,
      "y": 40,
      "z": 15,
      "name": "Rock_Ice_Permafrost"
    },
    {
      "x": -38,
      "y": 27,
      "z": 16,
      "name": "Rock_Ice"
    },
    {
      "x": -38,
      "y": 28,
      "z": 16,
      "name": "Rock_Ice"
    },
    {
      "x": -38,
      "y": 29,
      "z": 16,
      "name": "Rock_Ice_Permafrost"
    },
    {
      "x": -38,
      "y": 30,
      "z": 16,
      "name": "Rock_Ice_Permafrost"
    },
    {
      "x": -38,
      "y": 31,
      "z": 16,
      "name": "Rock_Ice_Permafrost"
    },
    {
      "x": -38,
      "y": 32,
      "z": 16,
      "name": "Rock_Ice_Permafrost"
    },
    {
      "x": -38,
      "y": 33,
      "z": 16,
      "name": "Rock_Ice_Permafrost"
    },
    {
      "x": -38,
      "y": 34,
      "z": 16,
      "name": "Rock_Ice_Permafrost"
    },
    {
      "x": -38,
      "y": 35,
      "z": 16,
      "name": "Rock_Ice_Permafrost"
    },
    {
      "x": -38,
      "y": 36,
      "z": 16,
      "name": "Rock_Ice_Permafrost"
    },
    {
      "x": -38,
      "y": 37,
      "z": 16,
      "name": "Rock_Ice_Permafrost"
    },
    {
      "x": -38,
      "y": 38,
      "z": 16,
      "name": "Rock_Ice_Permafrost"
    },
    {
      "x": -38,
      "y": 39,
      "z": 16,
      "name": "Rock_Ice_Permafrost"
    },
    {
      "x": -38,
      "y": 40,
      "z": 16,
      "name": "Rock_Ice_Permafrost"
    },
    {
      "x": -38,
      "y": 27,
      "z": 17,
      "name": "Rock_Ice"
    },
    {
      "x": -38,
      "y": 28,
      "z": 17,
      "name": "Rock_Ice_Permafrost"
    },
    {
      "x": -38,
      "y": 29,
      "z": 17,
      "name": "Rock_Ice"
    },
    {
      "x": -38,
      "y": 30,
      "z": 17,
      "name": "Rock_Ice_Permafrost"
    },
    {
      "x": -38,
      "y": 31,
      "z": 17,
      "name": "Rock_Ice_Permafrost"
    },
    {
      "x": -38,
      "y": 32,
      "z": 17,
      "name": "Rock_Ice_Permafrost"
    },
    {
      "x": -38,
      "y": 33,
      "z": 17,
      "name": "Rock_Ice_Permafrost"
    },
    {
      "x": -38,
      "y": 34,
      "z": 17,
      "name": "Rock_Ice_Permafrost"
    },
    {
      "x": -38,
      "y": 35,
      "z": 17,
      "name": "Rock_Ice_Permafrost"
    },
    {
      "x": -38,
      "y": 36,
      "z": 17,
      "name": "Rock_Ice_Permafrost"
    },
    {
      "x": -38,
      "y": 37,
      "z": 17,
      "name": "Rock_Ice_Permafrost"
    },
    {
      "x": -38,
      "y": 38,
      "z": 17,
      "name": "Rock_Ice"
    },
    {
      "x": -38,
      "y": 39,
      "z": 17,
      "name": "Soil_Snow"
    },
    {
      "x": -38,
      "y": 26,
      "z": 18,
      "name": "Rock_Ice_Permafrost"
    },
    {
      "x": -38,
      "y": 27,
      "z": 18,
      "name": "Rock_Ice_Permafrost"
    },
    {
      "x": -38,
      "y": 28,
      "z": 18,
      "name": "Rock_Ice_Permafrost"
    },
    {
      "x": -38,
      "y": 29,
      "z": 18,
      "name": "Rock_Ice_Permafrost"
    },
    {
      "x": -38,
      "y": 30,
      "z": 18,
      "name": "Rock_Ice_Permafrost"
    },
    {
      "x": -38,
      "y": 31,
      "z": 18,
      "name": "Rock_Ice_Permafrost"
    },
    {
      "x": -38,
      "y": 32,
      "z": 18,
      "name": "Rock_Ice_Permafrost"
    },
    {
      "x": -38,
      "y": 33,
      "z": 18,
      "name": "Rock_Ice_Permafrost"
    },
    {
      "x": -38,
      "y": 34,
      "z": 18,
      "name": "Rock_Ice_Permafrost"
    },
    {
      "x": -38,
      "y": 35,
      "z": 18,
      "name": "Rock_Ice_Permafrost"
    },
    {
      "x": -38,
      "y": 36,
      "z": 18,
      "name": "Rock_Ice_Permafrost"
    },
    {
      "x": -38,
      "y": 37,
      "z": 18,
      "name": "Rock_Ice_Permafrost"
    },
    {
      "x": -38,
      "y": 38,
      "z": 18,
      "name": "Rock_Ice"
    },
    {
      "x": -38,
      "y": 39,
      "z": 18,
      "name": "Rock_Ice_Permafrost"
    },
    {
      "x": -38,
      "y": 40,
      "z": 18,
      "name": "Rock_Ice"
    },
    {
      "x": -38,
      "y": 26,
      "z": 19,
      "name": "Rock_Ice"
    },
    {
      "x": -38,
      "y": 27,
      "z": 19,
      "name": "Rock_Ice_Permafrost"
    },
    {
      "x": -38,
      "y": 28,
      "z": 19,
      "name": "Rock_Ice_Permafrost"
    },
    {
      "x": -38,
      "y": 29,
      "z": 19,
      "name": "Rock_Ice_Permafrost"
    },
    {
      "x": -38,
      "y": 30,
      "z": 19,
      "name": "Rock_Ice_Permafrost"
    },
    {
      "x": -38,
      "y": 31,
      "z": 19,
      "name": "Rock_Ice_Permafrost"
    },
    {
      "x": -38,
      "y": 32,
      "z": 19,
      "name": "Rock_Ice_Permafrost"
    },
    {
      "x": -38,
      "y": 33,
      "z": 19,
      "name": "Rock_Ice_Permafrost"
    },
    {
      "x": -38,
      "y": 34,
      "z": 19,
      "name": "Rock_Ice_Permafrost"
    },
    {
      "x": -38,
      "y": 35,
      "z": 19,
      "name": "Rock_Ice_Permafrost"
    },
    {
      "x": -38,
      "y": 36,
      "z": 19,
      "name": "Rock_Ice"
    },
    {
      "x": -38,
      "y": 37,
      "z": 19,
      "name": "Rock_Ice_Permafrost"
    },
    {
      "x": -38,
      "y": 38,
      "z": 19,
      "name": "Rock_Ice"
    },
    {
      "x": -38,
      "y": 39,
      "z": 19,
      "name": "Soil_Snow"
    },
    {
      "x": -38,
      "y": 25,
      "z": 20,
      "name": "Rock_Ice"
    },
    {
      "x": -38,
      "y": 26,
      "z": 20,
      "name": "Rock_Ice"
    },
    {
      "x": -38,
      "y": 27,
      "z": 20,
      "name": "Rock_Ice_Permafrost"
    },
    {
      "x": -38,
      "y": 28,
      "z": 20,
      "name": "Rock_Ice_Permafrost"
    },
    {
      "x": -38,
      "y": 29,
      "z": 20,
      "name": "Rock_Ice_Permafrost"
    },
    {
      "x": -38,
      "y": 30,
      "z": 20,
      "name": "Rock_Ice_Permafrost"
    },
    {
      "x": -38,
      "y": 31,
      "z": 20,
      "name": "Rock_Ice_Permafrost"
    },
    {
      "x": -38,
      "y": 32,
      "z": 20,
      "name": "Rock_Ice_Permafrost"
    },
    {
      "x": -38,
      "y": 33,
      "z": 20,
      "name": "Rock_Ice_Permafrost"
    },
    {
      "x": -38,
      "y": 34,
      "z": 20,
      "name": "Rock_Ice_Permafrost"
    },
    {
      "x": -38,
      "y": 35,
      "z": 20,
      "name": "Rock_Ice"
    },
    {
      "x": -38,
      "y": 36,
      "z": 20,
      "name": "Rock_Ice_Permafrost"
    },
    {
      "x": -38,
      "y": 37,
      "z": 20,
      "name": "Rock_Ice"
    },
    {
      "x": -38,
      "y": 38,
      "z": 20,
      "name": "Rock_Ice"
    },
    {
      "x": -38,
      "y": 39,
      "z": 20,
      "name": "Soil_Snow"
    },
    {
      "x": -38,
      "y": 25,
      "z": 21,
      "name": "Rock_Ice_Permafrost"
    },
    {
      "x": -38,
      "y": 26,
      "z": 21,
      "name": "Rock_Ice"
    },
    {
      "x": -38,
      "y": 27,
      "z": 21,
      "name": "Rock_Ice_Permafrost"
    },
    {
      "x": -38,
      "y": 28,
      "z": 21,
      "name": "Rock_Ice_Permafrost"
    },
    {
      "x": -38,
      "y": 29,
      "z": 21,
      "name": "Rock_Ice"
    },
    {
      "x": -38,
      "y": 30,
      "z": 21,
      "name": "Rock_Ice_Permafrost"
    },
    {
      "x": -38,
      "y": 31,
      "z": 21,
      "name": "Rock_Ice_Permafrost"
    },
    {
      "x": -38,
      "y": 32,
      "z": 21,
      "name": "Rock_Ice_Permafrost"
    },
    {
      "x": -38,
      "y": 33,
      "z": 21,
      "name": "Rock_Ice_Permafrost"
    },
    {
      "x": -38,
      "y": 34,
      "z": 21,
      "name": "Rock_Ice_Permafrost"
    },
    {
      "x": -38,
      "y": 35,
      "z": 21,
      "name": "Rock_Ice_Permafrost"
    },
    {
      "x": -38,
      "y": 36,
      "z": 21,
      "name": "Rock_Ice"
    },
    {
      "x": -38,
      "y": 37,
      "z": 21,
      "name": "Rock_Ice_Permafrost"
    },
    {
      "x": -38,
      "y": 38,
      "z": 21,
      "name": "Rock_Ice"
    },
    {
      "x": -38,
      "y": 39,
      "z": 21,
      "name": "Rock_Ice"
    },
    {
      "x": -38,
      "y": 24,
      "z": 22,
      "name": "Rock_Ice_Permafrost"
    },
    {
      "x": -38,
      "y": 25,
      "z": 22,
      "name": "Rock_Ice_Permafrost"
    },
    {
      "x": -38,
      "y": 26,
      "z": 22,
      "name": "Rock_Ice_Permafrost"
    },
    {
      "x": -38,
      "y": 27,
      "z": 22,
      "name": "Rock_Ice_Permafrost"
    },
    {
      "x": -38,
      "y": 28,
      "z": 22,
      "name": "Rock_Ice_Permafrost"
    },
    {
      "x": -38,
      "y": 29,
      "z": 22,
      "name": "Rock_Ice_Permafrost"
    },
    {
      "x": -38,
      "y": 30,
      "z": 22,
      "name": "Rock_Ice_Permafrost"
    },
    {
      "x": -38,
      "y": 31,
      "z": 22,
      "name": "Rock_Ice_Permafrost"
    },
    {
      "x": -38,
      "y": 32,
      "z": 22,
      "name": "Rock_Ice_Permafrost"
    },
    {
      "x": -38,
      "y": 33,
      "z": 22,
      "name": "Rock_Ice_Permafrost"
    },
    {
      "x": -38,
      "y": 34,
      "z": 22,
      "name": "Rock_Ice_Permafrost"
    },
    {
      "x": -38,
      "y": 35,
      "z": 22,
      "name": "Rock_Ice_Permafrost"
    },
    {
      "x": -38,
      "y": 36,
      "z": 22,
      "name": "Rock_Ice"
    },
    {
      "x": -38,
      "y": 37,
      "z": 22,
      "name": "Rock_Ice_Permafrost"
    },
    {
      "x": -38,
      "y": 38,
      "z": 22,
      "name": "Rock_Ice_Permafrost"
    },
    {
      "x": -38,
      "y": 39,
      "z": 22,
      "name": "Rock_Ice"
    },
    {
      "x": -38,
      "y": 24,
      "z": 23,
      "name": "Rock_Ice"
    },
    {
      "x": -38,
      "y": 25,
      "z": 23,
      "name": "Rock_Ice_Permafrost"
    },
    {
      "x": -38,
      "y": 26,
      "z": 23,
      "name": "Rock_Ice"
    },
    {
      "x": -38,
      "y": 27,
      "z": 23,
      "name": "Rock_Ice_Permafrost"
    },
    {
      "x": -38,
      "y": 28,
      "z": 23,
      "name": "Rock_Ice_Permafrost"
    },
    {
      "x": -38,
      "y": 29,
      "z": 23,
      "name": "Rock_Ice_Permafrost"
    },
    {
      "x": -38,
      "y": 30,
      "z": 23,
      "name": "Rock_Ice_Permafrost"
    },
    {
      "x": -38,
      "y": 31,
      "z": 23,
      "name": "Rock_Ice_Permafrost"
    },
    {
      "x": -38,
      "y": 32,
      "z": 23,
      "name": "Rock_Ice_Permafrost"
    },
    {
      "x": -38,
      "y": 33,
      "z": 23,
      "name": "Rock_Ice_Permafrost"
    },
    {
      "x": -38,
      "y": 34,
      "z": 23,
      "name": "Rock_Ice_Permafrost"
    },
    {
      "x": -38,
      "y": 35,
      "z": 23,
      "name": "Rock_Ice_Permafrost"
    },
    {
      "x": -38,
      "y": 36,
      "z": 23,
      "name": "Rock_Ice"
    },
    {
      "x": -38,
      "y": 37,
      "z": 23,
      "name": "Rock_Ice"
    },
    {
      "x": -38,
      "y": 38,
      "z": 23,
      "name": "Soil_Snow"
    },
    {
      "x": -38,
      "y": 23,
      "z": 24,
      "name": "Rock_Ice"
    },
    {
      "x": -38,
      "y": 24,
      "z": 24,
      "name": "Rock_Ice"
    },
    {
      "x": -38,
      "y": 25,
      "z": 24,
      "name": "Rock_Ice"
    },
    {
      "x": -38,
      "y": 26,
      "z": 24,
      "name": "Rock_Ice"
    },
    {
      "x": -38,
      "y": 27,
      "z": 24,
      "name": "Rock_Ice"
    },
    {
      "x": -38,
      "y": 28,
      "z": 24,
      "name": "Rock_Ice"
    },
    {
      "x": -38,
      "y": 29,
      "z": 24,
      "name": "Rock_Ice_Permafrost"
    },
    {
      "x": -38,
      "y": 30,
      "z": 24,
      "name": "Rock_Ice_Permafrost"
    },
    {
      "x": -38,
      "y": 31,
      "z": 24,
      "name": "Rock_Ice_Permafrost"
    },
    {
      "x": -38,
      "y": 32,
      "z": 24,
      "name": "Rock_Ice_Permafrost"
    },
    {
      "x": -38,
      "y": 33,
      "z": 24,
      "name": "Rock_Ice_Permafrost"
    },
    {
      "x": -38,
      "y": 34,
      "z": 24,
      "name": "Rock_Ice"
    },
    {
      "x": -38,
      "y": 35,
      "z": 24,
      "name": "Rock_Ice_Permafrost"
    },
    {
      "x": -38,
      "y": 36,
      "z": 24,
      "name": "Rock_Ice"
    },
    {
      "x": -38,
      "y": 37,
      "z": 24,
      "name": "Rock_Ice"
    },
    {
      "x": -38,
      "y": 38,
      "z": 24,
      "name": "Rock_Ice_Permafrost"
    },
    {
      "x": -38,
      "y": 23,
      "z": 25,
      "name": "Rock_Ice"
    },
    {
      "x": -38,
      "y": 24,
      "z": 25,
      "name": "Rock_Ice"
    },
    {
      "x": -38,
      "y": 25,
      "z": 25,
      "name": "Rock_Ice"
    },
    {
      "x": -38,
      "y": 26,
      "z": 25,
      "name": "Rock_Ice"
    },
    {
      "x": -38,
      "y": 27,
      "z": 25,
      "name": "Rock_Ice"
    },
    {
      "x": -38,
      "y": 28,
      "z": 25,
      "name": "Rock_Ice"
    },
    {
      "x": -38,
      "y": 29,
      "z": 25,
      "name": "Rock_Ice_Permafrost"
    },
    {
      "x": -38,
      "y": 30,
      "z": 25,
      "name": "Rock_Ice_Permafrost"
    },
    {
      "x": -38,
      "y": 31,
      "z": 25,
      "name": "Rock_Ice"
    },
    {
      "x": -38,
      "y": 32,
      "z": 25,
      "name": "Rock_Ice_Permafrost"
    },
    {
      "x": -38,
      "y": 33,
      "z": 25,
      "name": "Rock_Ice_Permafrost"
    },
    {
      "x": -38,
      "y": 34,
      "z": 25,
      "name": "Rock_Ice_Permafrost"
    },
    {
      "x": -38,
      "y": 35,
      "z": 25,
      "name": "Rock_Ice_Permafrost"
    },
    {
      "x": -38,
      "y": 36,
      "z": 25,
      "name": "Rock_Ice"
    },
    {
      "x": -38,
      "y": 37,
      "z": 25,
      "name": "Rock_Ice"
    },
    {
      "x": -38,
      "y": 38,
      "z": 25,
      "name": "Rock_Ice"
    },
    {
      "x": -38,
      "y": 23,
      "z": 26,
      "name": "Rock_Ice"
    },
    {
      "x": -38,
      "y": 24,
      "z": 26,
      "name": "Rock_Ice_Permafrost"
    },
    {
      "x": -38,
      "y": 25,
      "z": 26,
      "name": "Rock_Ice"
    },
    {
      "x": -38,
      "y": 26,
      "z": 26,
      "name": "Rock_Ice"
    },
    {
      "x": -38,
      "y": 27,
      "z": 26,
      "name": "Rock_Ice_Permafrost"
    },
    {
      "x": -38,
      "y": 28,
      "z": 26,
      "name": "Rock_Ice_Permafrost"
    },
    {
      "x": -38,
      "y": 29,
      "z": 26,
      "name": "Rock_Ice"
    },
    {
      "x": -38,
      "y": 30,
      "z": 26,
      "name": "Rock_Ice"
    },
    {
      "x": -38,
      "y": 31,
      "z": 26,
      "name": "Rock_Ice_Permafrost"
    },
    {
      "x": -38,
      "y": 32,
      "z": 26,
      "name": "Rock_Ice_Permafrost"
    },
    {
      "x": -38,
      "y": 33,
      "z": 26,
      "name": "Rock_Ice"
    },
    {
      "x": -38,
      "y": 34,
      "z": 26,
      "name": "Rock_Ice"
    },
    {
      "x": -38,
      "y": 35,
      "z": 26,
      "name": "Rock_Ice_Permafrost"
    },
    {
      "x": -38,
      "y": 36,
      "z": 26,
      "name": "Rock_Ice_Permafrost"
    },
    {
      "x": -38,
      "y": 37,
      "z": 26,
      "name": "Rock_Ice"
    },
    {
      "x": -38,
      "y": 38,
      "z": 26,
      "name": "Rock_Ice"
    },
    {
      "x": -38,
      "y": 23,
      "z": 27,
      "name": "Rock_Ice"
    },
    {
      "x": -38,
      "y": 24,
      "z": 27,
      "name": "Rock_Ice"
    },
    {
      "x": -38,
      "y": 25,
      "z": 27,
      "name": "Rock_Ice_Permafrost"
    },
    {
      "x": -38,
      "y": 26,
      "z": 27,
      "name": "Rock_Ice"
    },
    {
      "x": -38,
      "y": 27,
      "z": 27,
      "name": "Rock_Ice"
    },
    {
      "x": -38,
      "y": 28,
      "z": 27,
      "name": "Rock_Ice"
    },
    {
      "x": -38,
      "y": 29,
      "z": 27,
      "name": "Rock_Ice"
    },
    {
      "x": -38,
      "y": 30,
      "z": 27,
      "name": "Rock_Ice"
    },
    {
      "x": -38,
      "y": 31,
      "z": 27,
      "name": "Rock_Ice_Permafrost"
    },
    {
      "x": -38,
      "y": 32,
      "z": 27,
      "name": "Rock_Ice_Permafrost"
    },
    {
      "x": -38,
      "y": 33,
      "z": 27,
      "name": "Rock_Ice"
    },
    {
      "x": -38,
      "y": 34,
      "z": 27,
      "name": "Rock_Ice_Permafrost"
    },
    {
      "x": -38,
      "y": 35,
      "z": 27,
      "name": "Rock_Ice"
    },
    {
      "x": -38,
      "y": 36,
      "z": 27,
      "name": "Rock_Ice"
    },
    {
      "x": -38,
      "y": 37,
      "z": 27,
      "name": "Rock_Ice_Permafrost"
    },
    {
      "x": -38,
      "y": 38,
      "z": 27,
      "name": "Rock_Ice"
    },
    {
      "x": -38,
      "y": 23,
      "z": 28,
      "name": "Rock_Ice"
    },
    {
      "x": -38,
      "y": 24,
      "z": 28,
      "name": "Rock_Ice"
    },
    {
      "x": -38,
      "y": 25,
      "z": 28,
      "name": "Rock_Ice"
    },
    {
      "x": -38,
      "y": 26,
      "z": 28,
      "name": "Rock_Ice_Permafrost"
    },
    {
      "x": -38,
      "y": 27,
      "z": 28,
      "name": "Rock_Ice"
    },
    {
      "x": -38,
      "y": 28,
      "z": 28,
      "name": "Rock_Ice"
    },
    {
      "x": -38,
      "y": 29,
      "z": 28,
      "name": "Rock_Ice_Permafrost"
    },
    {
      "x": -38,
      "y": 30,
      "z": 28,
      "name": "Rock_Ice"
    },
    {
      "x": -38,
      "y": 31,
      "z": 28,
      "name": "Rock_Ice_Permafrost"
    },
    {
      "x": -38,
      "y": 32,
      "z": 28,
      "name": "Rock_Ice_Permafrost"
    },
    {
      "x": -38,
      "y": 33,
      "z": 28,
      "name": "Rock_Ice_Permafrost"
    },
    {
      "x": -38,
      "y": 34,
      "z": 28,
      "name": "Rock_Ice"
    },
    {
      "x": -38,
      "y": 35,
      "z": 28,
      "name": "Rock_Ice_Permafrost"
    },
    {
      "x": -38,
      "y": 36,
      "z": 28,
      "name": "Rock_Ice"
    },
    {
      "x": -38,
      "y": 37,
      "z": 28,
      "name": "Rock_Ice"
    },
    {
      "x": -38,
      "y": 38,
      "z": 28,
      "name": "Rock_Ice"
    },
    {
      "x": -38,
      "y": 23,
      "z": 29,
      "name": "Rock_Ice"
    },
    {
      "x": -38,
      "y": 24,
      "z": 29,
      "name": "Rock_Ice"
    },
    {
      "x": -38,
      "y": 25,
      "z": 29,
      "name": "Rock_Ice"
    },
    {
      "x": -38,
      "y": 26,
      "z": 29,
      "name": "Rock_Ice_Permafrost"
    },
    {
      "x": -38,
      "y": 27,
      "z": 29,
      "name": "Rock_Ice"
    },
    {
      "x": -38,
      "y": 28,
      "z": 29,
      "name": "Rock_Ice"
    },
    {
      "x": -38,
      "y": 29,
      "z": 29,
      "name": "Rock_Ice_Permafrost"
    },
    {
      "x": -38,
      "y": 30,
      "z": 29,
      "name": "Rock_Ice"
    },
    {
      "x": -38,
      "y": 31,
      "z": 29,
      "name": "Rock_Ice_Permafrost"
    },
    {
      "x": -38,
      "y": 32,
      "z": 29,
      "name": "Rock_Ice"
    },
    {
      "x": -38,
      "y": 33,
      "z": 29,
      "name": "Rock_Ice"
    },
    {
      "x": -38,
      "y": 34,
      "z": 29,
      "name": "Rock_Ice"
    },
    {
      "x": -38,
      "y": 35,
      "z": 29,
      "name": "Rock_Ice_Permafrost"
    },
    {
      "x": -38,
      "y": 36,
      "z": 29,
      "name": "Rock_Ice"
    },
    {
      "x": -38,
      "y": 37,
      "z": 29,
      "name": "Rock_Ice"
    },
    {
      "x": -38,
      "y": 38,
      "z": 29,
      "name": "Rock_Ice_Permafrost"
    },
    {
      "x": -38,
      "y": 23,
      "z": 30,
      "name": "Rock_Ice"
    },
    {
      "x": -38,
      "y": 24,
      "z": 30,
      "name": "Rock_Ice"
    },
    {
      "x": -38,
      "y": 25,
      "z": 30,
      "name": "Rock_Ice"
    },
    {
      "x": -38,
      "y": 26,
      "z": 30,
      "name": "Rock_Ice"
    },
    {
      "x": -38,
      "y": 27,
      "z": 30,
      "name": "Rock_Ice"
    },
    {
      "x": -38,
      "y": 28,
      "z": 30,
      "name": "Rock_Ice_Permafrost"
    },
    {
      "x": -38,
      "y": 29,
      "z": 30,
      "name": "Rock_Ice"
    },
    {
      "x": -38,
      "y": 30,
      "z": 30,
      "name": "Rock_Ice"
    },
    {
      "x": -38,
      "y": 31,
      "z": 30,
      "name": "Rock_Ice"
    },
    {
      "x": -38,
      "y": 32,
      "z": 30,
      "name": "Rock_Ice_Permafrost"
    },
    {
      "x": -38,
      "y": 33,
      "z": 30,
      "name": "Rock_Ice_Permafrost"
    },
    {
      "x": -38,
      "y": 34,
      "z": 30,
      "name": "Rock_Ice"
    },
    {
      "x": -38,
      "y": 35,
      "z": 30,
      "name": "Rock_Ice"
    },
    {
      "x": -38,
      "y": 36,
      "z": 30,
      "name": "Rock_Ice_Permafrost"
    },
    {
      "x": -38,
      "y": 37,
      "z": 30,
      "name": "Rock_Ice"
    },
    {
      "x": -38,
      "y": 23,
      "z": 31,
      "name": "Rock_Ice"
    },
    {
      "x": -38,
      "y": 24,
      "z": 31,
      "name": "Rock_Ice"
    },
    {
      "x": -38,
      "y": 25,
      "z": 31,
      "name": "Rock_Ice"
    },
    {
      "x": -38,
      "y": 26,
      "z": 31,
      "name": "Rock_Ice"
    },
    {
      "x": -38,
      "y": 27,
      "z": 31,
      "name": "Rock_Ice"
    },
    {
      "x": -38,
      "y": 28,
      "z": 31,
      "name": "Rock_Ice"
    },
    {
      "x": -38,
      "y": 29,
      "z": 31,
      "name": "Rock_Ice"
    },
    {
      "x": -38,
      "y": 30,
      "z": 31,
      "name": "Rock_Ice"
    },
    {
      "x": -38,
      "y": 31,
      "z": 31,
      "name": "Rock_Ice"
    },
    {
      "x": -38,
      "y": 32,
      "z": 31,
      "name": "Rock_Ice"
    },
    {
      "x": -38,
      "y": 33,
      "z": 31,
      "name": "Rock_Ice"
    },
    {
      "x": -38,
      "y": 34,
      "z": 31,
      "name": "Rock_Ice"
    },
    {
      "x": -38,
      "y": 35,
      "z": 31,
      "name": "Rock_Ice"
    },
    {
      "x": -38,
      "y": 36,
      "z": 31,
      "name": "Rock_Ice"
    },
    {
      "x": -38,
      "y": 23,
      "z": 32,
      "name": "Rock_Ice"
    },
    {
      "x": -38,
      "y": 24,
      "z": 32,
      "name": "Rock_Ice"
    },
    {
      "x": -38,
      "y": 25,
      "z": 32,
      "name": "Rock_Ice"
    },
    {
      "x": -38,
      "y": 26,
      "z": 32,
      "name": "Rock_Ice"
    },
    {
      "x": -38,
      "y": 27,
      "z": 32,
      "name": "Rock_Ice"
    },
    {
      "x": -38,
      "y": 28,
      "z": 32,
      "name": "Rock_Ice"
    },
    {
      "x": -38,
      "y": 29,
      "z": 32,
      "name": "Rock_Ice"
    },
    {
      "x": -38,
      "y": 30,
      "z": 32,
      "name": "Rock_Ice_Permafrost"
    },
    {
      "x": -38,
      "y": 31,
      "z": 32,
      "name": "Rock_Ice"
    },
    {
      "x": -38,
      "y": 32,
      "z": 32,
      "name": "Rock_Ice"
    },
    {
      "x": -38,
      "y": 33,
      "z": 32,
      "name": "Rock_Ice"
    },
    {
      "x": -38,
