{
  "version": 8,
  "blockIdVersion": 11,
  "anchorX": 1,
  "anchorY": 17,
  "anchorZ": 3,
  "blocks": [
    {
      "x": -42,
      "y": 39,
      "z": -23,
      "name": "Rock_Ice"
    },
    {
      "x": -42,
      "y": 40,
      "z": -23,
      "name": "Rock_Ice"
    },
    {
      "x": -42,
      "y": 41,
      "z": -23,
      "name": "Rock_Ice"
    },
    {
      "x": -42,
      "y": 39,
      "z": -22,
      "name": "Rock_Ice"
    },
    {
      "x": -42,
      "y": 40,
      "z": -22,
      "name": "Rock_Ice"
    },
    {
      "x": -42,
      "y": 41,
      "z": -22,
      "name": "Rock_Ice"
    },
    {
      "x": -42,
      "y": 42,
      "z": -22,
      "name": "Rock_Ice"
    },
    {
      "x": -42,
      "y": 43,
      "z": -22,
      "name": "Soil_Snow"
    },
    {
      "x": -42,
      "y": 41,
      "z": -21,
      "name": "Rock_Ice"
    },
    {
      "x": -42,
      "y": 42,
      "z": -21,
      "name": "Rock_Ice"
    },
    {
      "x": -42,
      "y": 43,
      "z": -21,
      "name": "Rock_Ice"
    },
    {
      "x": -42,
      "y": 44,
      "z": -21,
      "name": "Rock_Ice"
    },
    {
      "x": -42,
      "y": 45,
      "z": -21,
      "name": "Soil_Snow"
    },
    {
      "x": -42,
      "y": 41,
      "z": 12,
      "name": "Rock_Ice_Permafrost"
    },
    {
      "x": -42,
      "y": 42,
      "z": 12,
      "name": "Soil_Snow"
    },
    {
      "x": -41,
      "y": 40,
      "z": -25,
      "name": "Rock_Ice"
    },
    {
      "x": -41,
      "y": 41,
      "z": -25,
      "name": "Rock_Ice"
    },
    {
      "x": -41,
      "y": 36,
      "z": -24,
      "name": "Rock_Ice"
    },
    {
      "x": -41,
      "y": 37,
      "z": -24,
      "name": "Rock_Ice"
    },
    {
      "x": -41,
      "y": 38,
      "z": -24,
      "name": "Rock_Ice"
    },
    {
      "x": -41,
      "y": 39,
      "z": -24,
      "name": "Rock_Ice"
    },
    {
      "x": -41,
      "y": 40,
      "z": -24,
      "name": "Rock_Ice"
    },
    {
      "x": -41,
      "y": 41,
      "z": -24,
      "name": "Rock_Ice"
    },
    {
      "x": -41,
      "y": 42,
      "z": -24,
      "name": "Rock_Ice"
    },
    {
      "x": -41,
      "y": 43,
      "z": -24,
      "name": "Rock_Ice"
    },
    {
      "x": -41,
      "y": 44,
      "z": -24,
      "name": "Soil_Snow"
    },
    {
      "x": -41,
      "y": 36,
      "z": -23,
      "name": "Rock_Ice"
    },
    {
      "x": -41,
      "y": 37,
      "z": -23,
      "name": "Rock_Ice"
    },
    {
      "x": -41,
      "y": 38,
      "z": -23,
      "name": "Rock_Ice"
    },
    {
      "x": -41,
      "y": 39,
      "z": -23,
      "name": "Rock_Ice"
    },
    {
      "x": -41,
      "y": 40,
      "z": -23,
      "name": "Rock_Ice"
    },
    {
      "x": -41,
      "y": 41,
      "z": -23,
      "name": "Rock_Ice"
    },
    {
      "x": -41,
      "y": 42,
      "z": -23,
      "name": "Rock_Ice"
    },
    {
      "x": -41,
      "y": 43,
      "z": -23,
      "name": "Rock_Ice"
    },
    {
      "x": -41,
      "y": 44,
      "z": -23,
      "name": "Rock_Ice"
    },
    {
      "x": -41,
      "y": 45,
      "z": -23,
      "name": "Soil_Snow"
    },
    {
      "x": -41,
      "y": 37,
      "z": -22,
      "name": "Rock_Ice"
    },
    {
      "x": -41,
      "y": 38,
      "z": -22,
      "name": "Rock_Ice"
    },
    {
      "x": -41,
      "y": 39,
      "z": -22,
      "name": "Rock_Ice"
    },
    {
      "x": -41,
      "y": 40,
      "z": -22,
      "name": "Rock_Ice"
    },
    {
      "x": -41,
      "y": 41,
      "z": -22,
      "name": "Rock_Ice"
    },
    {
      "x": -41,
      "y": 42,
      "z": -22,
      "name": "Rock_Ice"
    },
    {
      "x": -41,
      "y": 43,
      "z": -22,
      "name": "Rock_Ice"
    },
    {
      "x": -41,
      "y": 44,
      "z": -22,
      "name": "Rock_Ice"
    },
    {
      "x": -41,
      "y": 45,
      "z": -22,
      "name": "Rock_Ice"
    },
    {
      "x": -41,
      "y": 46,
      "z": -22,
      "name": "Soil_Snow"
    },
    {
      "x": -41,
      "y": 38,
      "z": -21,
      "name": "Rock_Ice"
    },
    {
      "x": -41,
      "y": 39,
      "z": -21,
      "name": "Rock_Ice"
    },
    {
      "x": -41,
      "y": 40,
      "z": -21,
      "name": "Rock_Ice"
    },
    {
      "x": -41,
      "y": 41,
      "z": -21,
      "name": "Rock_Ice"
    },
    {
      "x": -41,
      "y": 42,
      "z": -21,
      "name": "Rock_Ice"
    },
    {
      "x": -41,
      "y": 43,
      "z": -21,
      "name": "Rock_Ice"
    },
    {
      "x": -41,
      "y": 44,
      "z": -21,
      "name": "Rock_Ice"
    },
    {
      "x": -41,
      "y": 45,
      "z": -21,
      "name": "Rock_Ice"
    },
    {
      "x": -41,
      "y": 46,
      "z": -21,
      "name": "Rock_Ice"
    },
    {
      "x": -41,
      "y": 47,
      "z": -21,
      "name": "Soil_Snow"
    },
    {
      "x": -41,
      "y": 40,
      "z": -20,
      "name": "Rock_Ice"
    },
    {
      "x": -41,
      "y": 41,
      "z": -20,
      "name": "Rock_Ice"
    },
    {
      "x": -41,
      "y": 42,
      "z": -20,
      "name": "Rock_Ice"
    },
    {
      "x": -41,
      "y": 43,
      "z": -20,
      "name": "Rock_Ice"
    },
    {
      "x": -41,
      "y": 44,
      "z": -20,
      "name": "Rock_Ice"
    },
    {
      "x": -41,
      "y": 45,
      "z": -20,
      "name": "Rock_Ice"
    },
    {
      "x": -41,
      "y": 46,
      "z": -20,
      "name": "Rock_Ice"
    },
    {
      "x": -41,
      "y": 47,
      "z": -20,
      "name": "Rock_Ice"
    },
    {
      "x": -41,
      "y": 48,
      "z": -20,
      "name": "Soil_Snow"
    },
    {
      "x": -41,
      "y": 42,
      "z": -19,
      "name": "Rock_Ice"
    },
    {
      "x": -41,
      "y": 43,
      "z": -19,
      "name": "Rock_Ice"
    },
    {
      "x": -41,
      "y": 44,
      "z": -19,
      "name": "Rock_Ice"
    },
    {
      "x": -41,
      "y": 45,
      "z": -19,
      "name": "Rock_Ice"
    },
    {
      "x": -41,
      "y": 46,
      "z": -19,
      "name": "Rock_Ice"
    },
    {
      "x": -41,
      "y": 47,
      "z": -19,
      "name": "Rock_Ice"
    },
    {
      "x": -41,
      "y": 48,
      "z": -19,
      "name": "Rock_Ice"
    },
    {
      "x": -41,
      "y": 43,
      "z": 9,
      "name": "Rock_Ice_Permafrost"
    },
    {
      "x": -41,
      "y": 42,
      "z": 10,
      "name": "Rock_Ice_Permafrost"
    },
    {
      "x": -41,
      "y": 43,
      "z": 10,
      "name": "Rock_Ice_Permafrost"
    },
    {
      "x": -41,
      "y": 44,
      "z": 10,
      "name": "Soil_Snow"
    },
    {
      "x": -41,
      "y": 40,
      "z": 11,
      "name": "Rock_Ice_Permafrost"
    },
    {
      "x": -41,
      "y": 41,
      "z": 11,
      "name": "Rock_Ice_Permafrost"
    },
    {
      "x": -41,
      "y": 42,
      "z": 11,
      "name": "Rock_Ice_Permafrost"
    },
    {
      "x": -41,
      "y": 43,
      "z": 11,
      "name": "Rock_Ice_Permafrost"
    },
    {
      "x": -41,
      "y": 44,
      "z": 11,
      "name": "Rock_Ice"
    },
    {
      "x": -41,
      "y": 45,
      "z": 11,
      "name": "Soil_Snow"
    },
    {
      "x": -41,
      "y": 39,
      "z": 12,
      "name": "Rock_Ice_Permafrost"
    },
    {
      "x": -41,
      "y": 40,
      "z": 12,
      "name": "Rock_Ice_Permafrost"
    },
    {
      "x": -41,
      "y": 41,
      "z": 12,
      "name": "Rock_Ice_Permafrost"
    },
    {
      "x": -41,
      "y": 42,
      "z": 12,
      "name": "Rock_Ice_Permafrost"
    },
    {
      "x": -41,
      "y": 43,
      "z": 12,
      "name": "Rock_Ice_Permafrost"
    },
    {
      "x": -41,
      "y": 44,
      "z": 12,
      "name": "Rock_Ice"
    },
    {
      "x": -41,
      "y": 45,
      "z": 12,
      "name": "Soil_Snow"
    },
    {
      "x": -41,
      "y": 38,
      "z": 13,
      "name": "Rock_Ice_Permafrost"
    },
    {
      "x": -41,
      "y": 39,
      "z": 13,
      "name": "Rock_Ice_Permafrost"
    },
    {
      "x": -41,
      "y": 40,
      "z": 13,
      "name": "Rock_Ice_Permafrost"
    },
    {
      "x": -41,
      "y": 41,
      "z": 13,
      "name": "Rock_Ice_Permafrost"
    },
    {
      "x": -41,
      "y": 42,
      "z": 13,
      "name": "Rock_Ice_Permafrost"
    },
    {
      "x": -41,
      "y": 43,
      "z": 13,
      "name": "Rock_Ice_Permafrost"
    },
    {
      "x": -41,
      "y": 44,
      "z": 13,
      "name": "Rock_Ice"
    },
    {
      "x": -41,
      "y": 45,
      "z": 13,
      "name": "Soil_Snow"
    },
    {
      "x": -41,
      "y": 39,
      "z": 14,
      "name": "Rock_Ice"
    },
    {
      "x": -41,
      "y": 40,
      "z": 14,
      "name": "Rock_Ice"
    },
    {
      "x": -41,
      "y": 41,
      "z": 14,
      "name": "Rock_Ice_Permafrost"
    },
    {
      "x": -41,
      "y": 42,
      "z": 14,
      "name": "Rock_Ice"
    },
    {
      "x": -41,
      "y": 43,
      "z": 14,
      "name": "Soil_Snow"
    },
    {
      "x": -40,
      "y": 38,
      "z": -26,
      "name": "Rock_Ice"
    },
    {
      "x": -40,
      "y": 39,
      "z": -26,
      "name": "Rock_Ice"
    },
    {
      "x": -40,
      "y": 40,
      "z": -26,
      "name": "Rock_Ice"
    },
    {
      "x": -40,
      "y": 41,
      "z": -26,
      "name": "Rock_Ice"
    },
    {
      "x": -40,
      "y": 42,
      "z": -26,
      "name": "Rock_Ice"
    },
    {
      "x": -40,
      "y": 43,
      "z": -26,
      "name": "Soil_Snow"
    },
    {
      "x": -40,
      "y": 36,
      "z": -25,
      "name": "Rock_Ice"
    },
    {
      "x": -40,
      "y": 37,
      "z": -25,
      "name": "Rock_Ice"
    },
    {
      "x": -40,
      "y": 38,
      "z": -25,
      "name": "Rock_Ice"
    },
    {
      "x": -40,
      "y": 39,
      "z": -25,
      "name": "Rock_Ice"
    },
    {
      "x": -40,
      "y": 40,
      "z": -25,
      "name": "Rock_Ice"
    },
    {
      "x": -40,
      "y": 41,
      "z": -25,
      "name": "Rock_Ice"
    },
    {
      "x": -40,
      "y": 42,
      "z": -25,
      "name": "Rock_Ice"
    },
    {
      "x": -40,
      "y": 43,
      "z": -25,
      "name": "Rock_Ice"
    },
    {
      "x": -40,
      "y": 44,
      "z": -25,
      "name": "Rock_Ice"
    },
    {
      "x": -40,
      "y": 45,
      "z": -25,
      "name": "Soil_Snow"
    },
    {
      "x": -40,
      "y": 35,
      "z": -24,
      "name": "Rock_Ice"
    },
    {
      "x": -40,
      "y": 36,
      "z": -24,
      "name": "Rock_Ice"
    },
    {
      "x": -40,
      "y": 37,
      "z": -24,
      "name": "Rock_Ice"
    },
    {
      "x": -40,
      "y": 38,
      "z": -24,
      "name": "Rock_Ice"
    },
    {
      "x": -40,
      "y": 39,
      "z": -24,
      "name": "Rock_Ice"
    },
    {
      "x": -40,
      "y": 40,
      "z": -24,
      "name": "Rock_Ice"
    },
    {
      "x": -40,
      "y": 41,
      "z": -24,
      "name": "Rock_Ice"
    },
    {
      "x": -40,
      "y": 42,
      "z": -24,
      "name": "Rock_Ice"
    },
    {
      "x": -40,
      "y": 43,
      "z": -24,
      "name": "Rock_Ice"
    },
    {
      "x": -40,
      "y": 44,
      "z": -24,
      "name": "Rock_Ice"
    },
    {
      "x": -40,
      "y": 45,
      "z": -24,
      "name": "Rock_Ice"
    },
    {
      "x": -40,
      "y": 46,
      "z": -24,
      "name": "Rock_Ice"
    },
    {
      "x": -40,
      "y": 47,
      "z": -24,
      "name": "Soil_Snow"
    },
    {
      "x": -40,
      "y": 35,
      "z": -23,
      "name": "Rock_Ice"
    },
    {
      "x": -40,
      "y": 36,
      "z": -23,
      "name": "Rock_Ice"
    },
    {
      "x": -40,
      "y": 37,
      "z": -23,
      "name": "Rock_Ice"
    },
    {
      "x": -40,
      "y": 38,
      "z": -23,
      "name": "Rock_Ice"
    },
    {
      "x": -40,
      "y": 39,
      "z": -23,
      "name": "Rock_Ice"
    },
    {
      "x": -40,
      "y": 40,
      "z": -23,
      "name": "Rock_Ice"
    },
    {
      "x": -40,
      "y": 41,
      "z": -23,
      "name": "Rock_Ice"
    },
    {
      "x": -40,
      "y": 42,
      "z": -23,
      "name": "Rock_Ice"
    },
    {
      "x": -40,
      "y": 43,
      "z": -23,
      "name": "Rock_Ice"
    },
    {
      "x": -40,
      "y": 44,
      "z": -23,
      "name": "Rock_Ice"
    },
    {
      "x": -40,
      "y": 45,
      "z": -23,
      "name": "Rock_Ice"
    },
    {
      "x": -40,
      "y": 46,
      "z": -23,
      "name": "Rock_Ice"
    },
    {
      "x": -40,
      "y": 47,
      "z": -23,
      "name": "Rock_Ice"
    },
    {
      "x": -40,
      "y": 48,
      "z": -23,
      "name": "Soil_Snow"
    },
    {
      "x": -40,
      "y": 36,
      "z": -22,
      "name": "Rock_Ice"
    },
    {
      "x": -40,
      "y": 37,
      "z": -22,
      "name": "Rock_Ice"
    },
    {
      "x": -40,
      "y": 38,
      "z": -22,
      "name": "Rock_Ice"
    },
    {
      "x": -40,
      "y": 39,
      "z": -22,
      "name": "Rock_Ice"
    },
    {
      "x": -40,
      "y": 40,
      "z": -22,
      "name": "Rock_Ice"
    },
    {
      "x": -40,
      "y": 41,
      "z": -22,
      "name": "Rock_Ice"
    },
    {
      "x": -40,
      "y": 42,
      "z": -22,
      "name": "Rock_Ice"
    },
    {
      "x": -40,
      "y": 43,
      "z": -22,
      "name": "Rock_Ice"
    },
    {
      "x": -40,
      "y": 44,
      "z": -22,
      "name": "Rock_Ice"
    },
    {
      "x": -40,
      "y": 45,
      "z": -22,
      "name": "Rock_Ice"
    },
    {
      "x": -40,
      "y": 46,
      "z": -22,
      "name": "Rock_Ice"
    },
    {
      "x": -40,
      "y": 47,
      "z": -22,
      "name": "Rock_Ice"
    },
    {
      "x": -40,
      "y": 48,
      "z": -22,
      "name": "Soil_Snow"
    },
    {
      "x": -40,
      "y": 36,
      "z": -21,
      "name": "Rock_Ice"
    },
    {
      "x": -40,
      "y": 37,
      "z": -21,
      "name": "Rock_Ice"
    },
    {
      "x": -40,
      "y": 38,
      "z": -21,
      "name": "Rock_Ice"
    },
    {
      "x": -40,
      "y": 39,
      "z": -21,
      "name": "Rock_Ice"
    },
    {
      "x": -40,
      "y": 40,
      "z": -21,
      "name": "Rock_Ice"
    },
    {
      "x": -40,
      "y": 41,
      "z": -21,
      "name": "Rock_Ice"
    },
    {
      "x": -40,
      "y": 42,
      "z": -21,
      "name": "Rock_Ice"
    },
    {
      "x": -40,
      "y": 43,
      "z": -21,
      "name": "Rock_Ice"
    },
    {
      "x": -40,
      "y": 44,
      "z": -21,
      "name": "Rock_Ice"
    },
    {
      "x": -40,
      "y": 45,
      "z": -21,
      "name": "Rock_Ice"
    },
    {
      "x": -40,
      "y": 46,
      "z": -21,
      "name": "Rock_Ice"
    },
    {
      "x": -40,
      "y": 47,
      "z": -21,
      "name": "Rock_Ice"
    },
    {
      "x": -40,
      "y": 48,
      "z": -21,
      "name": "Rock_Ice"
    },
    {
      "x": -40,
      "y": 49,
      "z": -21,
      "name": "Soil_Snow"
    },
    {
      "x": -40,
      "y": 37,
      "z": -20,
      "name": "Rock_Ice"
    },
    {
      "x": -40,
      "y": 38,
      "z": -20,
      "name": "Rock_Ice"
    },
    {
      "x": -40,
      "y": 39,
      "z": -20,
      "name": "Rock_Ice"
    },
    {
      "x": -40,
      "y": 40,
      "z": -20,
      "name": "Rock_Ice"
    },
    {
      "x": -40,
      "y": 41,
      "z": -20,
      "name": "Rock_Ice"
    },
    {
      "x": -40,
      "y": 42,
      "z": -20,
      "name": "Rock_Ice"
    },
    {
      "x": -40,
      "y": 43,
      "z": -20,
      "name": "Rock_Ice"
    },
    {
      "x": -40,
      "y": 44,
      "z": -20,
      "name": "Rock_Ice"
    },
    {
      "x": -40,
      "y": 45,
      "z": -20,
      "name": "Rock_Ice"
    },
    {
      "x": -40,
      "y": 46,
      "z": -20,
      "name": "Rock_Ice"
    },
    {
      "x": -40,
      "y": 47,
      "z": -20,
      "name": "Rock_Ice"
    },
    {
      "x": -40,
      "y": 48,
      "z": -20,
      "name": "Rock_Ice"
    },
    {
      "x": -40,
      "y": 49,
      "z": -20,
      "name": "Rock_Ice"
    },
    {
      "x": -40,
      "y": 50,
      "z": -20,
      "name": "Soil_Snow"
    },
    {
      "x": -40,
      "y": 38,
      "z": -19,
      "name": "Rock_Ice"
    },
    {
      "x": -40,
      "y": 39,
      "z": -19,
      "name": "Rock_Ice"
    },
    {
      "x": -40,
      "y": 40,
      "z": -19,
      "name": "Rock_Ice"
    },
    {
      "x": -40,
      "y": 41,
      "z": -19,
      "name": "Rock_Ice"
    },
    {
      "x": -40,
      "y": 42,
      "z": -19,
      "name": "Rock_Ice"
    },
    {
      "x": -40,
      "y": 43,
      "z": -19,
      "name": "Rock_Ice"
    },
    {
      "x": -40,
      "y": 44,
      "z": -19,
      "name": "Rock_Ice"
    },
    {
      "x": -40,
      "y": 45,
      "z": -19,
      "name": "Rock_Ice"
    },
    {
      "x": -40,
      "y": 46,
      "z": -19,
      "name": "Rock_Ice"
    },
    {
      "x": -40,
      "y": 47,
      "z": -19,
      "name": "Rock_Ice"
    },
    {
      "x": -40,
      "y": 48,
      "z": -19,
      "name": "Rock_Ice"
    },
    {
      "x": -40,
      "y": 49,
      "z": -19,
      "name": "Rock_Ice"
    },
    {
      "x": -40,
      "y": 50,
      "z": -19,
      "name": "Rock_Ice"
    },
    {
      "x": -40,
      "y": 51,
      "z": -19,
      "name": "Soil_Snow"
    },
    {
      "x": -40,
      "y": 40,
      "z": -18,
      "name": "Rock_Ice"
    },
    {
      "x": -40,
      "y": 41,
      "z": -18,
      "name": "Rock_Ice"
    },
    {
      "x": -40,
      "y": 42,
      "z": -18,
      "name": "Rock_Ice"
    },
    {
      "x": -40,
      "y": 43,
      "z": -18,
      "name": "Rock_Ice"
    },
    {
      "x": -40,
      "y": 44,
      "z": -18,
      "name": "Rock_Ice"
    },
    {
      "x": -40,
      "y": 45,
      "z": -18,
      "name": "Rock_Ice"
    },
    {
      "x": -40,
      "y": 46,
      "z": -18,
      "name": "Rock_Ice"
    },
    {
      "x": -40,
      "y": 47,
      "z": -18,
      "name": "Rock_Ice"
    },
    {
      "x": -40,
      "y": 48,
      "z": -18,
      "name": "Rock_Ice"
    },
    {
      "x": -40,
      "y": 49,
      "z": -18,
      "name": "Rock_Ice"
    },
    {
      "x": -40,
      "y": 50,
      "z": -18,
      "name": "Rock_Ice"
    },
    {
      "x": -40,
      "y": 51,
      "z": -18,
      "name": "Rock_Ice"
    },
    {
      "x": -40,
      "y": 52,
      "z": -18,
      "name": "Soil_Snow"
    },
    {
      "x": -40,
      "y": 42,
      "z": -17,
      "name": "Rock_Ice"
    },
    {
      "x": -40,
      "y": 43,
      "z": -17,
      "name": "Rock_Ice"
    },
    {
      "x": -40,
      "y": 44,
      "z": -17,
      "name": "Rock_Ice"
    },
    {
      "x": -40,
      "y": 45,
      "z": -17,
      "name": "Rock_Ice"
    },
    {
      "x": -40,
      "y": 46,
      "z": -17,
      "name": "Rock_Ice"
    },
    {
      "x": -40,
      "y": 47,
      "z": -17,
      "name": "Rock_Ice"
    },
    {
      "x": -40,
      "y": 48,
      "z": -17,
      "name": "Rock_Ice"
    },
    {
      "x": -40,
      "y": 49,
      "z": -17,
      "name": "Rock_Ice"
    },
    {
      "x": -40,
      "y": 45,
      "z": -16,
      "name": "Rock_Ice"
    },
    {
      "x": -40,
      "y": 46,
      "z": -16,
      "name": "Rock_Ice"
    },
    {
      "x": -40,
      "y": 47,
      "z": -16,
      "name": "Rock_Ice"
    },
    {
      "x": -40,
      "y": 48,
      "z": -16,
      "name": "Rock_Ice"
    },
    {
      "x": -40,
      "y": 46,
      "z": 2,
      "name": "Rock_Ice"
    },
    {
      "x": -40,
      "y": 44,
      "z": 3,
      "name": "Rock_Ice"
    },
    {
      "x": -40,
      "y": 45,
      "z": 3,
      "name": "Rock_Ice"
    },
    {
      "x": -40,
      "y": 46,
      "z": 3,
      "name": "Rock_Ice"
    },
    {
      "x": -40,
      "y": 47,
      "z": 3,
      "name": "Rock_Ice"
    },
    {
      "x": -40,
      "y": 43,
      "z": 4,
      "name": "Rock_Ice"
    },
    {
      "x": -40,
      "y": 44,
      "z": 4,
      "name": "Rock_Ice"
    },
    {
      "x": -40,
      "y": 45,
      "z": 4,
      "name": "Rock_Ice_Permafrost"
    },
    {
      "x": -40,
      "y": 46,
      "z": 4,
      "name": "Rock_Ice"
    },
    {
      "x": -40,
      "y": 47,
      "z": 4,
      "name": "Rock_Ice"
    },
    {
      "x": -40,
      "y": 42,
      "z": 5,
      "name": "Rock_Ice_Permafrost"
    },
    {
      "x": -40,
      "y": 43,
      "z": 5,
      "name": "Rock_Ice_Permafrost"
    },
    {
      "x": -40,
      "y": 44,
      "z": 5,
      "name": "Rock_Ice"
    },
    {
      "x": -40,
      "y": 45,
      "z": 5,
      "name": "Rock_Ice_Permafrost"
    },
    {
      "x": -40,
      "y": 46,
      "z": 5,
      "name": "Rock_Ice"
    },
    {
      "x": -40,
      "y": 47,
      "z": 5,
      "name": "Rock_Ice"
    },
    {
      "x": -40,
      "y": 48,
      "z": 5,
      "name": "Soil_Snow"
    },
    {
      "x": -40,
      "y": 41,
      "z": 6,
      "name": "Rock_Ice_Permafrost"
    },
    {
      "x": -40,
      "y": 42,
      "z": 6,
      "name": "Rock_Ice_Permafrost"
    },
    {
      "x": -40,
      "y": 43,
      "z": 6,
      "name": "Rock_Ice_Permafrost"
    },
    {
      "x": -40,
      "y": 44,
      "z": 6,
      "name": "Rock_Ice"
    },
    {
      "x": -40,
      "y": 45,
      "z": 6,
      "name": "Rock_Ice_Permafrost"
    },
    {
      "x": -40,
      "y": 46,
      "z": 6,
      "name": "Rock_Ice"
    },
    {
      "x": -40,
      "y": 47,
      "z": 6,
      "name": "Rock_Ice"
    },
    {
      "x": -40,
      "y": 48,
      "z": 6,
      "name": "Soil_Snow"
    },
    {
      "x": -40,
      "y": 40,
      "z": 7,
      "name": "Rock_Ice_Permafrost"
    },
    {
      "x": -40,
      "y": 41,
      "z": 7,
      "name": "Rock_Ice_Permafrost"
    },
    {
      "x": -40,
      "y": 42,
      "z": 7,
      "name": "Rock_Ice_Permafrost"
    },
    {
      "x": -40,
      "y": 43,
      "z": 7,
      "name": "Rock_Ice_Permafrost"
    },
    {
      "x": -40,
      "y": 44,
      "z": 7,
      "name": "Rock_Ice_Permafrost"
    },
    {
      "x": -40,
      "y": 45,
      "z": 7,
      "name": "Rock_Ice_Permafrost"
    },
    {
      "x": -40,
      "y": 46,
      "z": 7,
      "name": "Rock_Ice_Permafrost"
    },
    {
      "x": -40,
      "y": 47,
      "z": 7,
      "name": "Rock_Ice"
    },
    {
      "x": -40,
      "y": 48,
      "z": 7,
      "name": "Soil_Snow"
    },
    {
      "x": -40,
      "y": 38,
      "z": 8,
      "name": "Rock_Ice"
    },
    {
      "x": -40,
      "y": 39,
      "z": 8,
      "name": "Rock_Ice_Permafrost"
    },
    {
      "x": -40,
      "y": 40,
      "z": 8,
      "name": "Rock_Ice_Permafrost"
    },
    {
      "x": -40,
      "y": 41,
      "z": 8,
      "name": "Rock_Ice_Permafrost"
    },
    {
      "x": -40,
      "y": 42,
      "z": 8,
      "name": "Rock_Ice_Permafrost"
    },
    {
      "x": -40,
      "y": 43,
      "z": 8,
      "name": "Rock_Ice_Permafrost"
    },
    {
      "x": -40,
      "y": 44,
      "z": 8,
      "name": "Rock_Ice_Permafrost"
    },
    {
      "x": -40,
      "y": 45,
      "z": 8,
      "name": "Rock_Ice_Permafrost"
    },
    {
      "x": -40,
      "y": 46,
      "z": 8,
      "name": "Rock_Ice"
    },
    {
      "x": -40,
      "y": 47,
      "z": 8,
      "name": "Soil_Snow"
    },
    {
      "x": -40,
      "y": 38,
      "z": 9,
      "name": "Rock_Ice"
    },
    {
      "x": -40,
      "y": 39,
      "z": 9,
      "name": "Rock_Ice_Permafrost"
    },
    {
      "x": -40,
      "y": 40,
      "z": 9,
      "name": "Rock_Ice_Permafrost"
    },
    {
      "x": -40,
      "y": 41,
      "z": 9,
      "name": "Rock_Ice_Permafrost"
    },
    {
      "x": -40,
      "y": 42,
      "z": 9,
      "name": "Rock_Ice_Permafrost"
    },
    {
      "x": -40,
      "y": 43,
      "z": 9,
      "name": "Rock_Ice_Permafrost"
    },
    {
      "x": -40,
      "y": 44,
      "z": 9,
      "name": "Rock_Ice_Permafrost"
    },
    {
      "x": -40,
      "y": 45,
      "z": 9,
      "name": "Rock_Ice_Permafrost"
    },
    {
      "x": -40,
      "y": 46,
      "z": 9,
      "name": "Rock_Ice"
    },
    {
      "x": -40,
      "y": 47,
      "z": 9,
      "name": "Soil_Snow"
    },
    {
      "x": -40,
      "y": 37,
      "z": 10,
      "name": "Rock_Ice_Permafrost"
    },
    {
      "x": -40,
      "y": 38,
      "z": 10,
      "name": "Rock_Ice"
    },
    {
      "x": -40,
      "y": 39,
      "z": 10,
      "name": "Rock_Ice_Permafrost"
    },
    {
      "x": -40,
      "y": 40,
      "z": 10,
      "name": "Rock_Ice_Permafrost"
    },
    {
      "x": -40,
      "y": 41,
      "z": 10,
      "name": "Rock_Ice_Permafrost"
    },
    {
      "x": -40,
      "y": 42,
      "z": 10,
      "name": "Rock_Ice_Permafrost"
    },
    {
      "x": -40,
      "y": 43,
      "z": 10,
      "name": "Rock_Ice_Permafrost"
    },
    {
      "x": -40,
      "y": 44,
      "z": 10,
      "name": "Rock_Ice_Permafrost"
    },
    {
      "x": -40,
      "y": 45,
      "z": 10,
      "name": "Rock_Ice_Permafrost"
    },
    {
      "x": -40,
      "y": 46,
      "z": 10,
      "name": "Rock_Ice"
    },
    {
      "x": -40,
      "y": 47,
      "z": 10,
      "name": "Soil_Snow"
    },
    {
      "x": -40,
      "y": 36,
      "z": 11,
      "name": "Rock_Ice"
    },
    {
      "x": -40,
      "y": 37,
      "z": 11,
      "name": "Rock_Ice_Permafrost"
    },
    {
      "x": -40,
      "y": 38,
      "z": 11,
      "name": "Rock_Ice_Permafrost"
    },
    {
      "x": -40,
      "y": 39,
      "z": 11,
      "name": "Rock_Ice_Permafrost"
    },
    {
      "x": -40,
      "y": 40,
      "z": 11,
      "name": "Rock_Ice_Permafrost"
    },
    {
      "x": -40,
      "y": 41,
      "z": 11,
      "name": "Rock_Ice_Permafrost"
    },
    {
      "x": -40,
      "y": 42,
      "z": 11,
      "name": "Rock_Ice_Permafrost"
    },
    {
      "x": -40,
      "y": 43,
      "z": 11,
      "name": "Rock_Ice_Permafrost"
    },
    {
      "x": -40,
      "y": 44,
      "z": 11,
      "name": "Rock_Ice_Permafrost"
    },
    {
      "x": -40,
      "y": 45,
      "z": 11,
      "name": "Rock_Ice_Permafrost"
    },
    {
      "x": -40,
      "y": 46,
      "z": 11,
      "name": "Rock_Ice"
    },
    {
      "x": -40,
      "y": 47,
      "z": 11,
      "name": "Soil_Snow"
    },
    {
      "x": -40,
      "y": 36,
      "z": 12,
      "name": "Rock_Ice_Permafrost"
    },
    {
      "x": -40,
      "y": 37,
      "z": 12,
      "name": "Rock_Ice_Permafrost"
    },
    {
      "x": -40,
      "y": 38,
      "z": 12,
      "name": "Rock_Ice_Permafrost"
    },
    {
      "x": -40,
      "y": 39,
      "z": 12,
      "name": "Rock_Ice_Permafrost"
    },
    {
      "x": -40,
      "y": 40,
      "z": 12,
      "name": "Rock_Ice_Permafrost"
    },
    {
      "x": -40,
      "y": 41,
      "z": 12,
      "name": "Rock_Ice_Permafrost"
    },
    {
      "x": -40,
      "y": 42,
      "z": 12,
      "name": "Rock_Ice_Permafrost"
    },
    {
      "x": -40,
      "y": 43,
      "z": 12,
      "name": "Rock_Ice_Permafrost"
    },
    {
      "x": -40,
      "y": 44,
      "z": 12,
      "name": "Rock_Ice_Permafrost"
    },
    {
      "x": -40,
      "y": 45,
      "z": 12,
      "name": "Rock_Ice_Permafrost"
    },
    {
      "x": -40,
      "y": 46,
      "z": 12,
      "name": "Rock_Ice"
    },
    {
      "x": -40,
      "y": 47,
      "z": 12,
      "name": "Soil_Snow"
    },
    {
      "x": -40,
      "y": 37,
      "z": 13,
      "name": "Rock_Ice_Permafrost"
    },
    {
      "x": -40,
      "y": 38,
      "z": 13,
      "name": "Rock_Ice_Permafrost"
    },
    {
      "x": -40,
      "y": 39,
      "z": 13,
      "name": "Rock_Ice_Permafrost"
    },
    {
      "x": -40,
      "y": 40,
      "z": 13,
      "name": "Rock_Ice_Permafrost"
    },
    {
      "x": -40,
      "y": 41,
      "z": 13,
      "name": "Rock_Ice_Permafrost"
    },
    {
      "x": -40,
      "y": 42,
      "z": 13,
      "name": "Rock_Ice_Permafrost"
    },
    {
      "x": -40,
      "y": 43,
      "z": 13,
      "name": "Rock_Ice_Permafrost"
    },
    {
      "x": -40,
      "y": 44,
      "z": 13,
      "name": "Rock_Ice_Permafrost"
    },
    {
      "x": -40,
      "y": 45,
      "z": 13,
      "name": "Rock_Ice"
    },
    {
      "x": -40,
      "y": 46,
      "z": 13,
      "name": "Soil_Snow"
    },
    {
      "x": -40,
      "y": 37,
      "z": 14,
      "name": "Rock_Ice_Permafrost"
    },
    {
      "x": -40,
      "y": 38,
      "z": 14,
      "name": "Rock_Ice_Permafrost"
    },
    {
      "x": -40,
      "y": 39,
      "z": 14,
      "name": "Rock_Ice_Permafrost"
    },
    {
      "x": -40,
      "y": 40,
      "z": 14,
      "name": "Rock_Ice_Permafrost"
    },
    {
      "x": -40,
      "y": 41,
      "z": 14,
      "name": "Rock_Ice_Permafrost"
    },
    {
      "x": -40,
      "y": 42,
      "z": 14,
      "name": "Rock_Ice_Permafrost"
    },
    {
      "x": -40,
      "y": 43,
      "z": 14,
      "name": "Rock_Ice"
    },
    {
      "x": -40,
      "y": 44,
      "z": 14,
      "name": "Soil_Snow"
    },
    {
      "x": -40,
      "y": 42,
      "z": 15,
      "name": "Rock_Ice_Permafrost"
    },
    {
      "x": -40,
      "y": 43,
      "z": 15,
      "name": "Rock_Ice_Permafrost"
    },
    {
      "x": -40,
      "y": 44,
      "z": 15,
      "name": "Rock_Ice_Permafrost"
    },
    {
      "x": -40,
      "y": 40,
      "z": 16,
      "name": "Rock_Ice"
    },
    {
      "x": -40,
      "y": 41,
      "z": 16,
      "name": "Rock_Ice"
    },
    {
      "x": -40,
      "y": 42,
      "z": 16,
      "name": "Rock_Ice_Permafrost"
    },
    {
      "x": -40,
      "y": 43,
      "z": 16,
      "name": "Rock_Ice_Permafrost"
    },
    {
      "x": -40,
      "y": 44,
      "z": 16,
      "name": "Rock_Ice"
    },
    {
      "x": -40,
      "y": 45,
      "z": 16,
      "name": "Soil_Snow"
    },
    {
      "x": -40,
      "y": 39,
      "z": 17,
      "name": "Rock_Ice"
    },
    {
      "x": -40,
      "y": 40,
      "z": 17,
      "name": "Rock_Ice"
    },
    {
      "x": -40,
      "y": 41,
      "z": 17,
      "name": "Rock_Ice"
    },
    {
      "x": -40,
      "y": 42,
      "z": 17,
      "name": "Rock_Ice_Permafrost"
    },
    {
      "x": -40,
      "y": 43,
      "z": 17,
      "name": "Rock_Ice"
    },
    {
      "x": -40,
      "y": 44,
      "z": 17,
      "name": "Soil_Snow"
    },
    {
      "x": -40,
      "y": 41,
      "z": 18,
      "name": "Rock_Ice"
    },
    {
      "x": -39,
      "y": 37,
      "z": -27,
      "name": "Rock_Ice"
    },
    {
      "x": -39,
      "y": 38,
      "z": -27,
      "name": "Rock_Ice"
    },
    {
      "x": -39,
      "y": 39,
      "z": -27,
      "name": "Rock_Ice"
    },
    {
      "x": -39,
      "y": 40,
      "z": -27,
      "name": "Rock_Ice"
    },
    {
      "x": -39,
      "y": 41,
      "z": -27,
      "name": "Rock_Ice"
    },
    {
      "x": -39,
      "y": 42,
      "z": -27,
      "name": "Rock_Ice"
    },
    {
      "x": -39,
      "y": 43,
      "z": -27,
      "name": "Rock_Ice"
    },
    {
      "x": -39,
      "y": 44,
      "z": -27,
      "name": "Soil_Snow"
    },
    {
      "x": -39,
      "y": 35,
      "z": -26,
      "name": "Rock_Ice"
    },
    {
      "x": -39,
      "y": 36,
      "z": -26,
      "name": "Rock_Ice"
    },
    {
      "x": -39,
      "y": 37,
      "z": -26,
      "name": "Rock_Ice"
    },
    {
      "x": -39,
      "y": 38,
      "z": -26,
      "name": "Rock_Ice"
    },
    {
      "x": -39,
      "y": 39,
      "z": -26,
      "name": "Rock_Ice"
    },
    {
      "x": -39,
      "y": 40,
      "z": -26,
      "name": "Rock_Ice"
    },
    {
      "x": -39,
      "y": 41,
      "z": -26,
      "name": "Rock_Ice"
    },
    {
      "x": -39,
      "y": 42,
      "z": -26,
      "name": "Rock_Ice"
    },
    {
      "x": -39,
      "y": 43,
      "z": -26,
      "name": "Rock_Ice"
    },
    {
      "x": -39,
      "y": 44,
      "z": -26,
      "name": "Rock_Ice"
    },
    {
      "x": -39,
      "y": 45,
      "z": -26,
      "name": "Rock_Ice"
    },
    {
      "x": -39,
      "y": 46,
      "z": -26,
      "name": "Soil_Snow"
    },
    {
      "x": -39,
      "y": 34,
      "z": -25,
      "name": "Rock_Ice"
    },
    {
      "x": -39,
      "y": 35,
      "z": -25,
      "name": "Rock_Ice"
    },
    {
      "x": -39,
      "y": 36,
      "z": -25,
      "name": "Rock_Ice"
    },
    {
      "x": -39,
      "y": 37,
      "z": -25,
      "name": "Rock_Ice"
    },
    {
      "x": -39,
      "y": 38,
      "z": -25,
      "name": "Rock_Ice"
    },
    {
      "x": -39,
      "y": 39,
      "z": -25,
      "name": "Rock_Ice"
    },
    {
      "x": -39,
      "y": 40,
      "z": -25,
      "name": "Rock_Ice"
    },
    {
      "x": -39,
      "y": 41,
      "z": -25,
      "name": "Rock_Ice"
    },
    {
      "x": -39,
      "y": 42,
      "z": -25,
      "name": "Rock_Ice"
    },
    {
      "x": -39,
      "y": 43,
      "z": -25,
      "name": "Rock_Ice"
    },
    {
      "x": -39,
      "y": 44,
      "z": -25,
      "name": "Rock_Ice"
    },
    {
      "x": -39,
      "y": 45,
      "z": -25,
      "name": "Rock_Ice"
    },
    {
      "x": -39,
      "y": 46,
      "z": -25,
      "name": "Rock_Ice"
    },
    {
      "x": -39,
      "y": 47,
      "z": -25,
      "name": "Soil_Snow"
    },
    {
      "x": -39,
      "y": 34,
      "z": -24,
      "name": "Rock_Ice"
    },
    {
      "x": -39,
      "y": 35,
      "z": -24,
      "name": "Rock_Ice"
    },
    {
      "x": -39,
      "y": 36,
      "z": -24,
      "name": "Rock_Ice"
    },
    {
      "x": -39,
      "y": 37,
      "z": -24,
      "name": "Rock_Ice"
    },
    {
      "x": -39,
      "y": 38,
      "z": -24,
      "name": "Rock_Ice"
    },
    {
      "x": -39,
      "y": 39,
      "z": -24,
      "name": "Rock_Ice"
    },
    {
      "x": -39,
      "y": 40,
      "z": -24,
      "name": "Rock_Ice"
    },
    {
      "x": -39,
      "y": 41,
      "z": -24,
      "name": "Rock_Ice"
    },
    {
      "x": -39,
      "y": 42,
      "z": -24,
      "name": "Rock_Ice"
    },
    {
      "x": -39,
      "y": 43,
      "z": -24,
      "name": "Rock_Ice"
    },
    {
      "x": -39,
      "y": 44,
      "z": -24,
      "name": "Rock_Ice"
    },
    {
      "x": -39,
      "y": 45,
      "z": -24,
      "name": "Rock_Ice"
    },
    {
      "x": -39,
      "y": 46,
      "z": -24,
      "name": "Rock_Ice"
    },
    {
      "x": -39,
      "y": 47,
      "z": -24,
      "name": "Rock_Ice"
    },
    {
      "x": -39,
      "y": 48,
      "z": -24,
      "name": "Soil_Snow"
    },
    {
      "x": -39,
      "y": 34,
      "z": -23,
      "name": "Rock_Ice"
    },
    {
      "x": -39,
      "y": 35,
      "z": -23,
      "name": "Rock_Ice"
    },
    {
      "x": -39,
      "y": 36,
      "z": -23,
      "name": "Rock_Ice"
    },
    {
      "x": -39,
      "y": 37,
      "z": -23,
      "name": "Rock_Ice"
    },
    {
      "x": -39,
      "y": 38,
      "z": -23,
      "name": "Rock_Ice"
    },
    {
      "x": -39,
      "y": 39,
      "z": -23,
      "name": "Rock_Ice"
    },
    {
      "x": -39,
      "y": 40,
      "z": -23,
      "name": "Rock_Ice"
    },
    {
      "x": -39,
      "y": 41,
      "z": -23,
      "name": "Rock_Ice"
    },
    {
      "x": -39,
      "y": 42,
      "z": -23,
      "name": "Rock_Ice"
    },
    {
      "x": -39,
      "y": 43,
      "z": -23,
      "name": "Rock_Ice"
    },
    {
      "x": -39,
      "y": 44,
      "z": -23,
      "name": "Rock_Ice"
    },
    {
      "x": -39,
      "y": 45,
      "z": -23,
      "name": "Rock_Ice"
    },
    {
      "x": -39,
      "y": 46,
      "z": -23,
      "name": "Rock_Ice"
    },
    {
      "x": -39,
      "y": 47,
      "z": -23,
      "name": "Rock_Ice"
    },
    {
      "x": -39,
      "y": 48,
      "z": -23,
      "name": "Rock_Ice"
    },
    {
      "x": -39,
      "y": 49,
      "z": -23,
      "name": "Soil_Snow"
    },
    {
      "x": -39,
      "y": 34,
      "z": -22,
      "name": "Rock_Ice"
    },
    {
      "x": -39,
      "y": 35,
      "z": -22,
      "name": "Rock_Ice"
    },
    {
      "x": -39,
      "y": 36,
      "z": -22,
      "name": "Rock_Ice"
    },
    {
      "x": -39,
      "y": 37,
      "z": -22,
      "name": "Rock_Ice"
    },
    {
      "x": -39,
      "y": 38,
      "z": -22,
      "name": "Rock_Ice"
    },
    {
      "x": -39,
      "y": 39,
      "z": -22,
      "name": "Rock_Ice"
    },
    {
      "x": -39,
      "y": 40,
      "z": -22,
      "name": "Rock_Ice"
    },
    {
      "x": -39,
      "y": 41,
      "z": -22,
      "name": "Rock_Ice"
    },
    {
      "x": -39,
      "y": 42,
      "z": -22,
      "name": "Rock_Ice"
    },
    {
      "x": -39,
      "y": 43,
      "z": -22,
      "name": "Rock_Ice"
    },
    {
      "x": -39,
      "y": 44,
      "z": -22,
      "name": "Rock_Ice"
    },
    {
      "x": -39,
      "y": 45,
      "z": -22,
      "name": "Rock_Ice"
    },
    {
      "x": -39,
      "y": 46,
      "z": -22,
      "name": "Rock_Ice"
    },
    {
      "x": -39,
      "y": 47,
      "z": -22,
      "name": "Rock_Ice"
    },
    {
      "x": -39,
      "y": 48,
      "z": -22,
      "name": "Rock_Ice"
    },
    {
      "x": -39,
      "y": 49,
      "z": -22,
      "name": "Rock_Ice"
    },
    {
      "x": -39,
      "y": 50,
      "z": -22,
      "name": "Soil_Snow"
    },
    {
      "x": -39,
      "y": 35,
      "z": -21,
      "name": "Rock_Ice"
    },
    {
      "x": -39,
      "y": 36,
      "z": -21,
      "name": "Rock_Ice"
    },
    {
      "x": -39,
      "y": 37,
      "z": -21,
      "name": "Rock_Ice"
    },
    {
      "x": -39,
      "y": 38,
      "z": -21,
      "name": "Rock_Ice"
    },
    {
      "x": -39,
      "y": 39,
      "z": -21,
      "name": "Rock_Ice"
    },
    {
      "x": -39,
      "y": 40,
      "z": -21,
      "name": "Rock_Ice"
    },
    {
      "x": -39,
      "y": 41,
      "z": -21,
      "name": "Rock_Ice"
    },
    {
      "x": -39,
      "y": 42,
      "z": -21,
      "name": "Rock_Ice"
    },
    {
      "x": -39,
      "y": 43,
      "z": -21,
      "name": "Rock_Ice"
    },
    {
      "x": -39,
      "y": 44,
      "z": -21,
      "name": "Rock_Ice"
    },
    {
      "x": -39,
      "y": 45,
      "z": -21,
      "name": "Rock_Ice"
    },
    {
      "x": -39,
      "y": 46,
      "z": -21,
      "name": "Rock_Ice"
    },
    {
      "x": -39,
      "y": 47,
      "z": -21,
      "name": "Rock_Ice"
    },
    {
      "x": -39,
      "y": 48,
      "z": -21,
      "name": "Rock_Ice"
    },
    {
      "x": -39,
      "y": 49,
      "z": -21,
      "name": "Rock_Ice"
    },
    {
      "x": -39,
      "y": 50,
      "z": -21,
      "name": "Rock_Ice"
    },
    {
      "x": -39,
      "y": 51,
      "z": -21,
      "name": "Soil_Snow"
    },
    {
      "x": -39,
      "y": 36,
      "z": -20,
      "name": "Rock_Ice"
    },
    {
      "x": -39,
      "y": 37,
      "z": -20,
      "name": "Rock_Ice"
    },
    {
      "x": -39,
      "y": 38,
      "z": -20,
      "name": "Rock_Ice"
    },
    {
      "x": -39,
      "y": 39,
      "z": -20,
      "name": "Rock_Ice"
    },
    {
      "x": -39,
      "y": 40,
      "z": -20,
      "name": "Rock_Ice"
    },
    {
      "x": -39,
      "y": 41,
      "z": -20,
      "name": "Rock_Ice"
    },
    {
      "x": -39,
      "y": 42,
      "z": -20,
      "name": "Rock_Ice"
    },
    {
      "x": -39,
      "y": 43,
      "z": -20,
      "name": "Rock_Ice"
    },
    {
      "x": -39,
      "y": 44,
      "z": -20,
      "name": "Rock_Ice"
    },
    {
      "x": -39,
      "y": 45,
      "z": -20,
      "name": "Rock_Ice"
    },
    {
      "x": -39,
      "y": 46,
      "z": -20,
      "name": "Rock_Ice"
    },
    {
      "x": -39,
      "y": 47,
      "z": -20,
      "name": "Rock_Ice"
    },
    {
      "x": -39,
      "y": 48,
      "z": -20,
      "name": "Rock_Ice"
    },
    {
      "x": -39,
      "y": 49,
      "z": -20,
      "name": "Rock_Ice"
    },
    {
      "x": -39,
      "y": 50,
      "z": -20,
      "name": "Rock_Ice"
    },
    {
      "x": -39,
      "y": 51,
      "z": -20,
      "name": "Rock_Ice"
    },
    {
      "x": -39,
      "y": 52,
      "z": -20,
      "name": "Soil_Snow"
    },
    {
      "x": -39,
      "y": 37,
      "z": -19,
      "name": "Rock_Ice"
    },
    {
      "x": -39,
      "y": 38,
      "z": -19,
      "name": "Rock_Ice"
    },
    {
      "x": -39,
      "y": 39,
      "z": -19,
      "name": "Rock_Ice"
    },
    {
      "x": -39,
      "y": 40,
      "z": -19,
      "name": "Rock_Ice"
    },
    {
      "x": -39,
      "y": 41,
      "z": -19,
      "name": "Rock_Ice"
    },
    {
      "x": -39,
      "y": 42,
      "z": -19,
      "name": "Rock_Ice"
    },
    {
      "x": -39,
      "y": 43,
      "z": -19,
      "name": "Rock_Ice"
    },
    {
      "x": -39,
      "y": 44,
      "z": -19,
      "name": "Rock_Ice"
    },
    {
      "x": -39,
      "y": 45,
      "z": -19,
      "name": "Rock_Ice"
    },
    {
      "x": -39,
      "y": 46,
      "z": -19,
      "name": "Rock_Ice"
    },
    {
      "x": -39,
      "y": 47,
      "z": -19,
      "name": "Rock_Ice"
    },
    {
      "x": -39,
      "y": 48,
      "z": -19,
      "name": "Rock_Ice"
    },
    {
      "x": -39,
      "y": 49,
      "z": -19,
      "name": "Rock_Ice"
    },
    {
      "x": -39,
      "y": 50,
      "z": -19,
      "name": "Rock_Ice"
    },
    {
      "x": -39,
      "y": 51,
      "z": -19,
      "name": "Rock_Ice"
    },
    {
      "x": -39,
      "y": 52,
      "z": -19,
      "name": "Rock_Ice"
    },
    {
      "x": -39,
      "y": 53,
      "z": -19,
      "name": "Rock_Ice"
    },
    {
      "x": -39,
      "y": 54,
      "z": -19,
      "name": "Soil_Snow"
    },
    {
      "x": -39,
      "y": 37,
      "z": -18,
      "name": "Rock_Ice"
    },
    {
      "x": -39,
      "y": 38,
      "z": -18,
      "name": "Rock_Ice"
    },
    {
      "x": -39,
      "y": 39,
      "z": -18,
      "name": "Rock_Ice"
    },
    {
      "x": -39,
      "y": 40,
      "z": -18,
      "name": "Rock_Ice"
    },
    {
      "x": -39,
      "y": 41,
      "z": -18,
      "name": "Rock_Ice"
    },
    {
      "x": -39,
      "y": 42,
      "z": -18,
      "name": "Rock_Ice"
    },
    {
      "x": -39,
      "y": 43,
      "z": -18,
      "name": "Rock_Ice"
    },
    {
      "x": -39,
      "y": 44,
      "z": -18,
      "name": "Rock_Ice"
    },
    {
      "x": -39,
      "y": 45,
      "z": -18,
      "name": "Rock_Ice"
    },
    {
      "x": -39,
      "y": 46,
      "z": -18,
      "name": "Rock_Ice"
    },
    {
      "x": -39,
      "y": 47,
      "z": -18,
      "name": "Rock_Ice"
    },
    {
      "x": -39,
      "y": 48,
      "z": -18,
      "name": "Rock_Ice"
    },
    {
      "x": -39,
      "y": 49,
      "z": -18,
      "name": "Rock_Ice"
    },
    {
      "x": -39,
      "y": 50,
      "z": -18,
      "name": "Rock_Ice"
    },
    {
      "x": -39,
      "y": 51,
      "z": -18,
      "name": "Rock_Ice"
    },
    {
      "x": -39,
      "y": 52,
      "z": -18,
      "name": "Rock_Ice"
    },
    {
      "x": -39,
      "y": 53,
      "z": -18,
      "name": "Rock_Ice"
    },
    {
      "x": -39,
      "y": 54,
      "z": -18,
      "name": "Rock_Ice"
    },
    {
      "x": -39,
      "y": 55,
      "z": -18,
      "name": "Soil_Snow"
    },
    {
      "x": -39,
      "y": 39,
      "z": -17,
      "name": "Rock_Ice"
    },
    {
      "x": -39,
      "y": 40,
      "z": -17,
      "name": "Rock_Ice"
    },
    {
      "x": -39,
      "y": 41,
      "z": -17,
      "name": "Rock_Ice"
    },
    {
      "x": -39,
      "y": 42,
      "z": -17,
      "name": "Rock_Ice"
    },
    {
      "x": -39,
      "y": 43,
      "z": -17,
      "name": "Rock_Ice"
    },
    {
      "x": -39,
      "y": 44,
      "z": -17,
      "name": "Rock_Ice"
    },
    {
      "x": -39,
      "y": 45,
      "z": -17,
      "name": "Rock_Ice"
    },
    {
      "x": -39,
      "y": 46,
      "z": -17,
      "name": "Rock_Ice"
    },
    {
      "x": -39,
      "y": 47,
      "z": -17,
      "name": "Rock_Ice"
    },
    {
      "x": -39,
      "y": 48,
      "z": -17,
      "name": "Rock_Ice"
    },
    {
      "x": -39,
      "y": 49,
      "z": -17,
      "name": "Rock_Ice"
    },
    {
      "x": -39,
      "y": 50,
      "z": -17,
      "name": "Rock_Ice"
    },
    {
      "x": -39,
      "y": 51,
      "z": -17,
      "name": "Rock_Ice"
    },
    {
      "x": -39,
      "y": 52,
      "z": -17,
      "name": "Rock_Ice"
    },
    {
      "x": -39,
      "y": 53,
      "z": -17,
      "name": "Rock_Ice"
    },
    {
      "x": -39,
      "y": 54,
      "z": -17,
      "name": "Rock_Ice"
    },
    {
      "x": -39,
      "y": 55,
      "z": -17,
      "name": "Soil_Snow"
    },
    {
      "x": -39,
      "y": 40,
      "z": -16,
      "name": "Rock_Ice"
    },
    {
      "x": -39,
      "y": 41,
      "z": -16,
      "name": "Rock_Ice"
    },
    {
      "x": -39,
      "y": 42,
      "z": -16,
      "name": "Rock_Ice"
    },
    {
      "x": -39,
      "y": 43,
      "z": -16,
      "name": "Rock_Ice"
    },
    {
      "x": -39,
      "y": 44,
      "z": -16,
      "name": "Rock_Ice"
    },
    {
      "x": -39,
      "y": 45,
      "z": -16,
      "name": "Rock_Ice"
    },
    {
      "x": -39,
      "y": 46,
      "z": -16,
      "name": "Rock_Ice"
    },
    {
      "x": -39,
      "y": 47,
      "z": -16,
      "name": "Rock_Ice"
    },
    {
      "x": -39,
      "y": 48,
      "z": -16,
      "name": "Rock_Ice"
    },
    {
      "x": -39,
      "y": 49,
      "z": -16,
      "name": "Rock_Ice"
    },
    {
      "x": -39,
      "y": 50,
      "z": -16,
      "name": "Rock_Ice"
    },
    {
      "x": -39,
      "y": 51,
      "z": -16,
      "name": "Rock_Ice"
    },
    {
      "x": -39,
      "y": 52,
      "z": -16,
      "name": "Rock_Ice"
    },
    {
      "x": -39,
      "y": 53,
      "z": -16,
      "name": "Rock_Ice"
    },
    {
      "x": -39,
      "y": 54,
      "z": -16,
      "name": "Rock_Ice"
    },
    {
      "x": -39,
      "y": 55,
      "z": -16,
      "name": "Soil_Snow"
    },
    {
      "x": -39,
      "y": 42,
      "z": -15,
      "name": "Rock_Ice"
    },
    {
      "x": -39,
      "y": 43,
      "z": -15,
      "name": "Rock_Ice"
    },
    {
      "x": -39,
      "y": 44,
      "z": -15,
      "name": "Rock_Ice"
    },
    {
      "x": -39,
      "y": 45,
      "z": -15,
      "name": "Rock_Ice"
    },
    {
      "x": -39,
      "y": 46,
      "z": -15,
      "name": "Rock_Ice"
    },
    {
      "x": -39,
      "y": 47,
      "z": -15,
      "name": "Rock_Ice"
    },
    {
      "x": -39,
      "y": 48,
      "z": -15,
      "name": "Rock_Ice"
    },
    {
      "x": -39,
      "y": 49,
      "z": -15,
      "name": "Rock_Ice"
    },
    {
      "x": -39,
      "y": 50,
      "z": -15,
      "name": "Rock_Ice"
    },
    {
      "x": -39,
      "y": 51,
      "z": -15,
      "name": "Rock_Ice"
    },
    {
      "x": -39,
      "y": 52,
      "z": -15,
      "name": "Rock_Ice"
    },
    {
      "x": -39,
      "y": 53,
      "z": -15,
      "name": "Rock_Ice"
    },
    {
      "x": -39,
      "y": 54,
      "z": -15,
      "name": "Rock_Ice"
    },
    {
      "x": -39,
      "y": 55,
      "z": -15,
      "name": "Rock_Ice"
    },
    {
      "x": -39,
      "y": 56,
      "z": -15,
      "name": "Soil_Snow"
    },
    {
      "x": -39,
      "y": 44,
      "z": -14,
      "name": "Rock_Ice"
    },
    {
      "x": -39,
      "y": 45,
      "z": -14,
      "name": "Rock_Ice"
    },
    {
      "x": -39,
      "y": 46,
      "z": -14,
      "name": "Rock_Ice"
    },
    {
      "x": -39,
      "y": 47,
      "z": -14,
      "name": "Rock_Ice"
    },
    {
      "x": -39,
      "y": 48,
      "z": -14,
      "name": "Rock_Ice"
    },
    {
      "x": -39,
      "y": 49,
      "z": -14,
      "name": "Rock_Ice"
    },
    {
      "x": -39,
      "y": 50,
      "z": -14,
      "name": "Rock_Ice"
    },
    {
      "x": -39,
      "y": 51,
      "z": -14,
      "name": "Rock_Ice"
    },
    {
      "x": -39,
      "y": 52,
      "z": -14,
      "name": "Rock_Ice"
    },
    {
      "x": -39,
      "y": 53,
      "z": -14,
      "name": "Rock_Ice"
    },
    {
      "x": -39,
      "y": 54,
      "z": -14,
      "name": "Rock_Ice"
    },
    {
      "x": -39,
      "y": 55,
      "z": -14,
      "name": "Rock_Ice"
    },
    {
      "x": -39,
      "y": 56,
      "z": -14,
      "name": "Rock_Ice"
    },
    {
      "x": -39,
      "y": 57,
      "z": -14,
      "name": "Soil_Snow"
    },
    {
      "x": -39,
      "y": 46,
      "z": -13,
      "name": "Rock_Ice_Permafrost"
    },
    {
      "x": -39,
      "y": 47,
      "z": -13,
      "name": "Rock_Ice"
    },
    {
      "x": -39,
      "y": 48,
      "z": -13,
      "name": "Rock_Ice_Permafrost"
    },
    {
      "x": -39,
      "y": 49,
      "z": -13,
      "name": "Rock_Ice"
    },
    {
      "x": -39,
      "y": 50,
      "z": -13,
      "name": "Rock_Ice"
    },
    {
      "x": -39,
      "y": 51,
      "z": -13,
      "name": "Rock_Ice"
    },
    {
      "x": -39,
      "y": 52,
      "z": -13,
      "name": "Rock_Ice"
    },
    {
      "x": -39,
      "y": 53,
      "z": -13,
      "name": "Rock_Ice"
    },
    {
      "x": -39,
      "y": 54,
      "z": -13,
      "name": "Rock_Ice"
    },
    {
      "x": -39,
      "y": 55,
      "z": -13,
      "name": "Rock_Ice"
    },
    {
      "x": -39,
      "y": 56,
      "z": -13,
      "name": "Rock_Ice"
    },
    {
      "x": -39,
      "y": 57,
      "z": -13,
      "name": "Soil_Snow"
    },
    {
      "x": -39,
      "y": 48,
      "z": -12,
      "name": "Rock_Ice_Permafrost"
    },
    {
      "x": -39,
      "y": 49,
      "z": -12,
      "name": "Rock_Ice_Permafrost"
    },
    {
      "x": -39,
      "y": 50,
      "z": -12,
      "name": "Rock_Ice_Permafrost"
    },
    {
      "x": -39,
      "y": 51,
      "z": -12,
      "name": "Rock_Ice_Permafrost"
    },
    {
      "x": -39,
      "y": 52,
      "z": -12,
      "name": "Rock_Ice"
    },
    {
      "x": -39,
      "y": 53,
      "z": -12,
      "name": "Rock_Ice"
    },
    {
      "x": -39,
      "y": 54,
      "z": -12,
      "name": "Rock_Ice"
    },
    {
      "x": -39,
      "y": 55,
      "z": -12,
      "name": "Rock_Ice"
    },
    {
      "x": -39,
      "y": 56,
      "z": -12,
      "name": "Rock_Ice"
    },
    {
      "x": -39,
      "y": 57,
      "z": -12,
      "name": "Soil_Snow"
    },
    {
      "x": -39,
      "y": 48,
      "z": -11,
      "name": "Rock_Ice_Permafrost"
    },
    {
      "x": -39,
      "y": 49,
      "z": -11,
      "name": "Rock_Ice_Permafrost"
    },
    {
      "x": -39,
      "y": 50,
      "z": -11,
      "name": "Rock_Ice_Permafrost"
    },
    {
      "x": -39,
      "y": 51,
      "z": -11,
      "name": "Rock_Ice_Permafrost"
    },
    {
      "x": -39,
      "y": 52,
      "z": -11,
      "name": "Rock_Ice_Permafrost"
    },
    {
      "x": -39,
      "y": 53,
      "z": -11,
      "name": "Rock_Ice"
    },
    {
      "x": -39,
      "y": 54,
      "z": -11,
      "name": "Rock_Ice_Permafrost"
    },
    {
      "x": -39,
      "y": 55,
      "z": -11,
      "name": "Rock_Ice"
    },
    {
      "x": -39,
      "y": 56,
      "z": -11,
      "name": "Rock_Ice"
    },
    {
      "x": -39,
      "y": 57,
      "z": -11,
      "name": "Soil_Snow"
    },
    {
      "x": -39,
      "y": 49,
      "z": -10,
      "name": "Rock_Ice_Permafrost"
    },
    {
      "x": -39,
      "y": 50,
      "z": -10,
      "name": "Rock_Ice_Permafrost"
    },
    {
      "x": -39,
      "y": 51,
      "z": -10,
      "name": "Rock_Ice_Permafrost"
    },
    {
      "x": -39,
      "y": 52,
      "z": -10,
      "name": "Rock_Ice_Permafrost"
    },
    {
      "x": -39,
      "y": 53,
      "z": -10,
      "name": "Rock_Ice_Permafrost"
    },
    {
      "x": -39,
      "y": 54,
      "z": -10,
      "name": "Rock_Ice_Permafrost"
    },
    {
      "x": -39,
      "y": 55,
      "z": -10,
      "name": "Rock_Ice_Permafrost"
    },
    {
      "x": -39,
      "y": 56,
      "z": -10,
      "name": "Rock_Ice"
    },
    {
      "x": -39,
      "y": 57,
      "z": -10,
      "name": "Soil_Snow"
    },
    {
      "x": -39,
      "y": 49,
      "z": -9,
      "name": "Rock_Ice_Permafrost"
    },
    {
      "x": -39,
      "y": 50,
      "z": -9,
      "name": "Rock_Ice_Permafrost"
    },
    {
      "x": -39,
      "y": 51,
      "z": -9,
      "name": "Rock_Ice_Permafrost"
    },
    {
      "x": -39,
      "y": 52,
      "z": -9,
      "name": "Rock_Ice_Permafrost"
    },
    {
      "x": -39,
      "y": 53,
      "z": -9,
      "name": "Rock_Ice_Permafrost"
    },
    {
      "x": -39,
      "y": 54,
      "z": -9,
      "name": "Rock_Ice_Permafrost"
    },
    {
      "x": -39,
      "y": 55,
      "z": -9,
      "name": "Rock_Ice"
    },
    {
      "x": -39,
      "y": 56,
      "z": -9,
      "name": "Soil_Snow"
    },
    {
      "x": -39,
      "y": 49,
      "z": -8,
      "name": "Rock_Ice"
    },
    {
      "x": -39,
      "y": 50,
      "z": -8,
      "name": "Rock_Ice"
    },
    {
      "x": -39,
      "y": 51,
      "z": -8,
      "name": "Rock_Ice"
    },
    {
      "x": -39,
      "y": 52,
      "z": -8,
      "name": "Rock_Ice"
    },
    {
      "x": -39,
      "y": 53,
      "z": -8,
      "name": "Rock_Ice_Permafrost"
    },
    {
      "x": -39,
      "y": 54,
      "z": -8,
      "name": "Rock_Ice_Permafrost"
    },
    {
      "x": -39,
      "y": 55,
      "z": -8,
      "name": "Rock_Ice"
    },
    {
      "x": -39,
      "y": 56,
      "z": -8,
      "name": "Soil_Snow"
    },
    {
      "x": -39,
      "y": 49,
      "z": -7,
      "name": "Rock_Ice"
    },
    {
      "x": -39,
      "y": 50,
      "z": -7,
      "name": "Rock_Ice"
    },
    {
      "x": -39,
      "y": 51,
      "z": -7,
      "name": "Rock_Ice"
    },
    {
      "x": -39,
      "y": 52,
      "z": -7,
      "name": "Rock_Ice"
    },
    {
      "x": -39,
      "y": 53,
      "z": -7,
      "name": "Rock_Ice"
    },
    {
      "x": -39,
      "y": 54,
      "z": -7,
      "name": "Rock_Ice"
    },
    {
      "x": -39,
      "y": 55,
      "z": -7,
      "name": "Soil_Snow"
    },
    {
      "x": -39,
      "y": 48,
      "z": -6,
      "name": "Rock_Ice"
    },
    {
      "x": -39,
      "y": 49,
      "z": -6,
      "name": "Rock_Ice"
    },
    {
      "x": -39,
      "y": 50,
      "z": -6,
      "name": "Rock_Ice"
    },
    {
      "x": -39,
      "y": 51,
      "z": -6,
      "name": "Rock_Ice"
    },
    {
      "x": -39,
      "y": 52,
      "z": -6,
      "name": "Rock_Ice"
    },
    {
      "x": -39,
      "y": 53,
      "z": -6,
      "name": "Rock_Ice"
    },
    {
      "x": -39,
      "y": 54,
      "z": -6,
      "name": "Rock_Ice"
    },
    {
      "x": -39,
      "y": 55,
      "z": -6,
      "name": "Soil_Snow"
    },
    {
      "x": -39,
      "y": 48,
      "z": -5,
      "name": "Rock_Ice"
    },
    {
      "x": -39,
      "y": 49,
      "z": -5,
      "name": "Rock_Ice"
    },
    {
      "x": -39,
      "y": 50,
      "z": -5,
      "name": "Rock_Ice"
    },
    {
      "x": -39,
      "y": 51,
      "z": -5,
      "name": "Rock_Ice"
    },
    {
      "x": -39,
      "y": 52,
      "z": -5,
      "name": "Rock_Ice"
    },
    {
      "x": -39,
      "y": 53,
      "z": -5,
      "name": "Rock_Ice"
    },
    {
      "x": -39,
      "y": 54,
      "z": -5,
      "name": "Soil_Snow"
    },
    {
      "x": -39,
      "y": 47,
      "z": -4,
      "name": "Rock_Ice"
    },
    {
      "x": -39,
      "y": 48,
      "z": -4,
      "name": "Rock_Ice"
    },
    {
      "x": -39,
      "y": 49,
      "z": -4,
      "name": "Rock_Ice"
    },
    {
      "x": -39,
      "y": 50,
      "z": -4,
      "name": "Rock_Ice"
    },
    {
      "x": -39,
      "y": 51,
      "z": -4,
      "name": "Rock_Ice"
    },
    {
      "x": -39,
      "y": 52,
      "z": -4,
      "name": "Rock_Ice"
    },
    {
      "x": -39,
      "y": 53,
      "z": -4,
      "name": "Rock_Ice"
    },
    {
      "x": -39,
      "y": 54,
      "z": -4,
      "name": "Soil_Snow"
    },
    {
      "x": -39,
      "y": 47,
      "z": -3,
      "name": "Rock_Ice"
    },
    {
      "x": -39,
      "y": 48,
      "z": -3,
      "name": "Rock_Ice"
    },
    {
      "x": -39,
      "y": 49,
      "z": -3,
      "name": "Rock_Ice"
    },
    {
      "x": -39,
      "y": 50,
      "z": -3,
      "name": "Rock_Ice"
    },
    {
      "x": -39,
      "y": 51,
      "z": -3,
      "name": "Rock_Ice"
    },
    {
      "x": -39,
      "y": 52,
      "z": -3,
      "name": "Rock_Ice"
    },
    {
      "x": -39,
      "y": 53,
      "z": -3,
      "name": "Soil_Snow"
    },
    {
      "x": -39,
      "y": 46,
      "z": -2,
      "name": "Rock_Ice"
    },
    {
      "x": -39,
      "y": 47,
      "z": -2,
      "name": "Rock_Ice"
    },
    {
      "x": -39,
      "y": 48,
      "z": -2,
      "name": "Rock_Ice"
    },
    {
      "x": -39,
      "y": 49,
      "z": -2,
      "name": "Rock_Ice"
    },
    {
      "x": -39,
      "y": 50,
      "z": -2,
      "name": "Rock_Ice"
    },
    {
      "x": -39,
      "y": 51,
      "z": -2,
      "name": "Rock_Ice"
    },
    {
      "x": -39,
      "y": 52,
      "z": -2,
      "name": "Rock_Ice"
    },
    {
      "x": -39,
      "y": 53,
      "z": -2,
      "name": "Soil_Snow"
    },
    {
      "x": -39,
      "y": 45,
      "z": -1,
      "name": "Rock_Ice"
    },
    {
      "x": -39,
      "y": 46,
      "z": -1,
      "name": "Rock_Ice"
    },
    {
      "x": -39,
      "y": 47,
      "z": -1,
      "name": "Rock_Ice"
    },
    {
      "x": -39,
      "y": 48,
      "z": -1,
      "name": "Rock_Ice"
    },
    {
      "x": -39,
      "y": 49,
      "z": -1,
      "name": "Rock_Ice"
    },
    {
      "x": -39,
      "y": 50,
      "z": -1,
      "name": "Rock_Ice"
    },
    {
      "x": -39,
      "y": 51,
      "z": -1,
      "name": "Rock_Ice"
    },
    {
      "x": -39,
      "y": 52,
      "z": -1,
      "name": "Rock_Ice"
    },
    {
      "x": -39,
      "y": 53,
      "z": -1,
      "name": "Soil_Snow"
    },
    {
      "x": -39,
      "y": 45,
      "z": 0,
      "name": "Rock_Ice"
    },
    {
      "x": -39,
      "y": 46,
      "z": 0,
      "name": "Rock_Ice"
    },
    {
      "x": -39,
      "y": 47,
      "z": 0,
      "name": "Rock_Ice"
    },
    {
      "x": -39,
      "y": 48,
      "z": 0,
      "name": "Rock_Ice"
    },
    {
      "x": -39,
      "y": 49,
      "z": 0,
      "name": "Rock_Ice"
    },
    {
      "x": -39,
      "y": 50,
      "z": 0,
      "name": "Rock_Ice"
    },
    {
      "x": -39,
      "y": 51,
      "z": 0,
      "name": "Rock_Ice"
    },
    {
      "x": -39,
      "y": 52,
      "z": 0,
      "name": "Soil_Snow"
    },
    {
      "x": -39,
      "y": 44,
      "z": 1,
      "name": "Rock_Ice"
    },
    {
      "x": -39,
      "y": 45,
      "z": 1,
      "name": "Rock_Ice"
    },
    {
      "x": -39,
      "y": 46,
      "z": 1,
      "name": "Rock_Ice"
    },
    {
      "x": -39,
      "y": 47,
      "z": 1,
      "name": "Rock_Ice"
    },
    {
      "x": -39,
      "y": 48,
      "z": 1,
      "name": "Rock_Ice"
    },
    {
      "x": -39,
      "y": 49,
      "z": 1,
      "name": "Rock_Ice"
    },
    {
      "x": -39,
      "y": 50,
      "z": 1,
      "name": "Rock_Ice"
    },
    {
      "x": -39,
      "y": 51,
      "z": 1,
      "name": "Rock_Ice"
    },
    {
      "x": -39,
      "y": 52,
      "z": 1,
      "name": "Soil_Snow"
    },
    {
      "x": -39,
      "y": 43,
      "z": 2,
      "name": "Rock_Ice"
    },
    {
      "x": -39,
      "y": 44,
      "z": 2,
      "name": "Rock_Ice"
    },
    {
      "x": -39,
      "y": 45,
      "z": 2,
      "name": "Rock_Ice"
    },
    {
      "x": -39,
      "y": 46,
      "z": 2,
      "name": "Rock_Ice"
    },
    {
      "x": -39,
      "y": 47,
      "z": 2,
      "name": "Rock_Ice"
    },
    {
      "x": -39,
      "y": 48,
      "z": 2,
      "name": "Rock_Ice"
    },
    {
      "x": -39,
      "y": 49,
      "z": 2,
      "name": "Rock_Ice"
    },
    {
      "x": -39,
      "y": 50,
      "z": 2,
      "name": "Rock_Ice"
    },
    {
      "x": -39,
      "y": 51,
      "z": 2,
      "name": "Rock_Ice"
    },
    {
      "x": -39,
      "y": 52,
      "z": 2,
      "name": "Soil_Snow"
    },
    {
      "x": -39,
      "y": 41,
      "z": 3,
      "name": "Rock_Ice"
    },
    {
      "x": -39,
      "y": 42,
      "z": 3,
      "name": "Rock_Ice"
    },
    {
      "x": -39,
      "y": 43,
      "z": 3,
      "name": "Rock_Ice"
    },
    {
      "x": -39,
      "y": 44,
      "z": 3,
      "name": "Rock_Ice"
    },
    {
      "x": -39,
      "y": 45,
      "z": 3,
      "name": "Rock_Ice"
    },
    {
      "x": -39,
      "y": 46,
      "z": 3,
      "name": "Rock_Ice"
    },
    {
      "x": -39,
      "y": 47,
      "z": 3,
      "name": "Rock_Ice"
    },
    {
      "x": -39,
      "y": 48,
      "z": 3,
      "name": "Rock_Ice"
    },
    {
      "x": -39,
      "y": 49,
      "z": 3,
      "name": "Rock_Ice"
    },
    {
      "x": -39,
      "y": 50,
      "z": 3,
      "name": "Rock_Ice"
    },
    {
      "x": -39,
      "y": 51,
      "z": 3,
      "name": "Rock_Ice"
    },
    {
      "x": -39,
      "y": 52,
      "z": 3,
      "name": "Soil_Snow"
    },
    {
      "x": -39,
      "y": 40,
      "z": 4,
      "name": "Rock_Ice_Permafrost"
    },
    {
      "x": -39,
      "y": 41,
      "z": 4,
      "name": "Rock_Ice_Permafrost"
    },
    {
      "x": -39,
      "y": 42,
      "z": 4,
      "name": "Rock_Ice"
    },
    {
      "x": -39,
      "y": 43,
      "z": 4,
      "name": "Rock_Ice"
    },
    {
      "x": -39,
      "y": 44,
      "z": 4,
      "name": "Rock_Ice"
    },
    {
      "x": -39,
      "y": 45,
      "z": 4,
      "name": "Rock_Ice"
    },
    {
      "x": -39,
      "y": 46,
      "z": 4,
      "name": "Rock_Ice"
    },
    {
      "x": -39,
      "y": 47,
      "z": 4,
      "name": "Rock_Ice"
    },
    {
      "x": -39,
      "y": 48,
      "z": 4,
      "name": "Rock_Ice"
    },
    {
      "x": -39,
      "y": 49,
      "z": 4,
      "name": "Rock_Ice"
    },
    {
      "x": -39,
      "y": 50,
      "z": 4,
      "name": "Rock_Ice"
    },
    {
      "x": -39,
      "y": 51,
      "z": 4,
      "name": "Soil_Snow"
    },
    {
      "x": -39,
      "y": 39,
      "z": 5,
      "name": "Rock_Ice_Permafrost"
    },
    {
      "x": -39,
      "y": 40,
      "z": 5,
      "name": "Rock_Ice_Permafrost"
    },
    {
      "x": -39,
      "y": 41,
      "z": 5,
      "name": "Rock_Ice_Permafrost"
    },
    {
      "x": -39,
      "y": 42,
      "z": 5,
      "name": "Rock_Ice"
    },
    {
      "x": -39,
      "y": 43,
      "z": 5,
      "name": "Rock_Ice"
    },
    {
      "x": -39,
      "y": 44,
      "z": 5,
      "name": "Rock_Ice_Permafrost"
    },
    {
      "x": -39,
      "y": 45,
      "z": 5,
      "name": "Rock_Ice"
    },
    {
      "x": -39,
      "y": 46,
      "z": 5,
      "name": "Rock_Ice"
    },
    {
      "x": -39,
      "y": 47,
      "z": 5,
      "name": "Rock_Ice"
    },
    {
      "x": -39,
      "y": 48,
      "z": 5,
      "name": "Rock_Ice"
    },
    {
      "x": -39,
      "y": 49,
      "z": 5,
      "name": "Rock_Ice"
    },
    {
      "x": -39,
      "y": 50,
      "z": 5,
      "name": "Rock_Ice"
    },
    {
      "x": -39,
      "y": 51,
      "z": 5,
      "name": "Soil_Snow"
    },
    {
      "x": -39,
      "y": 38,
      "z": 6,
      "name": "Rock_Ice"
    },
    {
      "x": -39,
      "y": 39,
      "z": 6,
      "name": "Rock_Ice_Permafrost"
    },
    {
      "x": -39,
      "y": 40,
      "z": 6,
      "name": "Rock_Ice_Permafrost"
    },
    {
      "x": -39,
      "y": 41,
      "z": 6,
      "name": "Rock_Ice_Permafrost"
    },
    {
      "x": -39,
      "y": 42,
      "z": 6,
      "name": "Rock_Ice_Permafrost"
    },
    {
      "x": -39,
      "y": 43,
      "z": 6,
      "name": "Rock_Ice_Permafrost"
    },
    {
      "x": -39,
      "y": 44,
      "z": 6,
      "name": "Rock_Ice"
    },
    {
      "x": -39,
      "y": 45,
      "z": 6,
      "name": "Rock_Ice"
    },
    {
      "x": -39,
      "y": 46,
      "z": 6,
      "name": "Rock_Ice"
    },
    {
      "x": -39,
      "y": 47,
      "z": 6,
      "name": "Rock_Ice"
    },
    {
      "x": -39,
      "y": 48,
      "z": 6,
      "name": "Rock_Ice"
    },
    {
      "x": -39,
      "y": 49,
      "z": 6,
      "name": "Rock_Ice"
    },
    {
      "x": -39,
      "y": 50,
      "z": 6,
      "name": "Rock_Ice"
    },
    {
      "x": -39,
      "y": 51,
      "z": 6,
      "name": "Soil_Snow"
    },
    {
      "x": -39,
      "y": 37,
      "z": 7,
      "name": "Rock_Ice"
    },
    {
      "x": -39,
      "y": 38,
      "z": 7,
      "name": "Rock_Ice"
    },
    {
      "x": -39,
      "y": 39,
      "z": 7,
      "name": "Rock_Ice_Permafrost"
    },
    {
      "x": -39,
      "y": 40,
      "z": 7,
      "name": "Rock_Ice_Permafrost"
    },
    {
      "x": -39,
      "y": 41,
      "z": 7,
      "name": "Rock_Ice_Permafrost"
    },
    {
      "x": -39,
      "y": 42,
      "z": 7,
      "name": "Rock_Ice_Permafrost"
    },
    {
      "x": -39,
      "y": 43,
      "z": 7,
      "name": "Rock_Ice_Permafrost"
    },
    {
      "x": -39,
      "y": 44,
      "z": 7,
      "name": "Rock_Ice_Permafrost"
    },
    {
      "x": -39,
      "y": 45,
      "z": 7,
      "name": "Rock_Ice"
    },
    {
      "x": -39,
      "y": 46,
      "z": 7,
      "name": "Rock_Ice_Permafrost"
    },
    {
      "x": -39,
      "y": 47,
      "z": 7,
      "name": "Rock_Ice"
    },
    {
      "x": -39,
      "y": 48,
      "z": 7,
      "name": "Rock_Ice"
    },
    {
      "x": -39,
      "y": 49,
      "z": 7,
      "name": "Rock_Ice"
    },
    {
      "x": -39,
      "y": 50,
      "z": 7,
      "name": "Soil_Snow"
    },
    {
      "x": -39,
      "y": 37,
      "z": 8,
      "name": "Rock_Ice"
    },
    {
      "x": -39,
      "y": 38,
      "z": 8,
      "name": "Rock_Ice"
    },
    {
      "x": -39,
      "y": 39,
      "z": 8,
      "name": "Rock_Ice"
    },
    {
      "x": -39,
      "y": 40,
      "z": 8,
      "name": "Rock_Ice_Permafrost"
    },
    {
      "x": -39,
      "y": 41,
      "z": 8,
      "name": "Rock_Ice_Permafrost"
    },
    {
      "x": -39,
      "y": 42,
      "z": 8,
      "name": "Rock_Ice_Permafrost"
    },
    {
      "x": -39,
      "y": 43,
      "z": 8,
      "name": "Rock_Ice_Permafrost"
    },
    {
      "x": -39,
      "y": 44,
      "z": 8,
      "name": "Rock_Ice_Permafrost"
    },
    {
      "x": -39,
      "y": 45,
      "z": 8,
      "name": "Rock_Ice_Permafrost"
    },
    {
      "x": -39,
      "y": 46,
      "z": 8,
      "name": "Rock_Ice_Permafrost"
    },
    {
      "x": -39,
      "y": 47,
      "z": 8,
      "name": "Rock_Ice_Permafrost"
    },
    {
      "x": -39,
      "y": 48,
      "z": 8,
      "name": "Rock_Ice_Permafrost"
    },
    {
      "x": -39,
      "y": 49,
      "z": 8,
      "name": "Rock_Ice"
    },
    {
      "x": -39,
      "y": 50,
      "z": 8,
      "name": "Soil_Snow"
    },
    {
      "x": -39,
      "y": 36,
      "z": 9,
      "name": "Rock_Ice"
    },
    {
      "x": -39,
      "y": 37,
      "z": 9,
      "name": "Rock_Ice"
    },
    {
      "x": -39,
      "y": 38,
      "z": 9,
      "name": "Rock_Ice"
    },
    {
      "x": -39,
      "y": 39,
      "z": 9,
      "name": "Rock_Ice"
    },
    {
      "x": -39,
      "y": 40,
      "z": 9,
      "name": "Rock_Ice"
    },
    {
      "x": -39,
      "y": 41,
      "z": 9,
      "name": "Rock_Ice_Permafrost"
    },
    {
      "x": -39,
      "y": 42,
      "z": 9,
      "name": "Rock_Ice_Permafrost"
    },
    {
      "x": -39,
      "y": 43,
      "z": 9,
      "name": "Rock_Ice_Permafrost"
    },
    {
      "x": -39,
      "y": 44,
      "z": 9,
      "name": "Rock_Ice_Permafrost"
    },
    {
      "x": -39,
      "y": 45,
      "z": 9,
      "name": "Rock_Ice_Permafrost"
    },
    {
      "x": -39,
      "y": 46,
      "z": 9,
      "name": "Rock_Ice_Permafrost"
    },
    {
      "x": -39,
      "y": 47,
      "z": 9,
      "name": "Rock_Ice_Permafrost"
    },
    {
      "x": -39,
      "y": 48,
      "z": 9,
      "name": "Rock_Ice_Permafrost"
    },
    {
      "x": -39,
      "y": 49,
      "z": 9,
      "name": "Rock_Ice"
    },
    {
      "x": -39,
      "y": 50,
      "z": 9,
      "name": "Soil_Snow"
    },
    {
      "x": -39,
      "y": 36,
      "z": 10,
      "name": "Rock_Ice"
    },
    {
      "x": -39,
      "y": 37,
      "z": 10,
      "name": "Rock_Ice"
    },
    {
      "x": -39,
      "y": 38,
      "z": 10,
      "name": "Rock_Ice"
    },
    {
      "x": -39,
      "y": 39,
      "z": 10,
      "name": "Rock_Ice"
    },
    {
      "x": -39,
      "y": 40,
      "z": 10,
      "name": "Rock_Ice_Permafrost"
    },
    {
      "x": -39,
      "y": 41,
      "z": 10,
      "name": "Rock_Ice_Permafrost"
    },
    {
      "x": -39,
      "y": 42,
      "z": 10,
      "name": "Rock_Ice_Permafrost"
    },
    {
      "x": -39,
      "y": 43,
      "z": 10,
      "name": "Rock_Ice_Permafrost"
    },
    {
      "x": -39,
      "y": 44,
      "z": 10,
      "name": "Rock_Ice_Permafrost"
    },
    {
      "x": -39,
      "y": 45,
      "z": 10,
      "name": "Rock_Ice_Permafrost"
    },
    {
      "x": -39,
      "y": 46,
      "z": 10,
      "name": "Rock_Ice_Permafrost"
    },
    {
      "x": -39,
      "y": 47,
      "z": 10,
      "name": "Rock_Ice_Permafrost"
    },
    {
      "x": -39,
      "y": 48,
      "z": 10,
      "name": "Rock_Ice"
    },
    {
      "x": -39,
      "y": 49,
      "z": 10,
      "name": "Soil_Snow"
    },
    {
      "x": -39,
      "y": 35,
      "z": 11,
      "name": "Rock_Ice"
    },
    {
      "x": -39,
      "y": 36,
      "z": 11,
      "name": "Rock_Ice"
    },
    {
      "x": -39,
      "y": 37,
      "z": 11,
      "name": "Rock_Ice"
    },
    {
      "x": -39,
      "y": 38,
      "z": 11,
      "name": "Rock_Ice"
    },
    {
      "x": -39,
      "y": 39,
      "z": 11,
      "name": "Rock_Ice_Permafrost"
    },
    {
      "x": -39,
      "y": 40,
      "z": 11,
      "name": "Rock_Ice_Permafrost"
    },
    {
      "x": -39,
      "y": 41,
      "z": 11,
      "name": "Rock_Ice_Permafrost"
    },
    {
      "x": -39,
      "y": 42,
      "z": 11,
      "name": "Rock_Ice_Permafrost"
    },
    {
      "x": -39,
      "y": 43,
      "z": 11,
      "name": "Rock_Ice_Permafrost"
    },
    {
      "x": -39,
      "y": 44,
      "z": 11,
      "name": "Rock_Ice_Permafrost"
    },
    {
      "x": -39,
      "y": 45,
      "z": 11,
      "name": "Rock_Ice_Permafrost"
    },
    {
      "x": -39,
      "y": 46,
      "z": 11,
      "name": "Rock_Ice_Permafrost"
    },
    {
      "x": -39,
      "y": 47,
      "z": 11,
      "name": "Rock_Ice_Permafrost"
    },
    {
      "x": -39,
      "y": 48,
      "z": 11,
      "name": "Rock_Ice"
    },
    {
      "x": -39,
      "y": 49,
      "z": 11,
      "name": "Soil_Snow"
    },
    {
      "x": -39,
      "y": 36,
      "z": 12,
      "name": "Rock_Ice"
    },
    {
      "x": -39,
      "y": 37,
      "z": 12,
      "name": "Rock_Ice_Permafrost"
    },
    {
      "x": -39,
      "y": 38,
      "z": 12,
      "name": "Rock_Ice_Permafrost"
    },
    {
      "x": -39,
      "y": 39,
      "z": 12,
      "name": "Rock_Ice_Permafrost"
    },
    {
      "x": -39,
      "y": 40,
      "z": 12,
      "name": "Rock_Ice_Permafrost"
    },
    {
      "x": -39,
      "y": 41,
      "z": 12,
      "name": "Rock_Ice_Permafrost"
    },
    {
      "x": -39,
      "y": 42,
      "z": 12,
      "name": "Rock_Ice_Permafrost"
    },
    {
      "x": -39,
      "y": 43,
      "z": 12,
      "name": "Rock_Ice_Permafrost"
    },
    {
      "x": -39,
      "y": 44,
      "z": 12,
      "name": "Rock_Ice_Permafrost"
    },
    {
      "x": -39,
      "y": 45,
      "z": 12,
      "name": "Rock_Ice_Permafrost"
    },
    {
      "x": -39,
      "y": 46,
      "z": 12,
      "name": "Rock_Ice_Permafrost"
    },
    {
      "x": -39,
      "y": 47,
      "z": 12,
      "name": "Rock_Ice_Permafrost"
    },
    {
      "x": -39,
      "y": 48,
      "z": 12,
      "name": "Rock_Ice"
    },
    {
      "x": -39,
      "y": 49,
      "z": 12,
      "name": "Soil_Snow"
    },
    {
      "x": -39,
      "y": 36,
      "z": 13,
      "name": "Rock_Ice_Permafrost"
    },
    {
      "x": -39,
      "y": 37,
      "z": 13,
      "name": "Rock_Ice_Permafrost"
    },
    {
      "x": -39,
      "y": 38,
      "z": 13,
      "name": "Rock_Ice_Permafrost"
    },
    {
      "x": -39,
      "y": 39,
      "z": 13,
      "name": "Rock_Ice_Permafrost"
    },
    {
      "x": -39,
      "y": 40,
      "z": 13,
      "name": "Rock_Ice_Permafrost"
    },
    {
      "x": -39,
      "y": 41,
      "z": 13,
      "name": "Rock_Ice_Permafrost"
    },
    {
      "x": -39,
      "y": 42,
      "z": 13,
      "name": "Rock_Ice_Permafrost"
    },
    {
      "x": -39,
      "y": 43,
      "z": 13,
      "name": "Rock_Ice_Permafrost"
    },
    {
      "x": -39,
      "y": 44,
      "z": 13,
      "name": "Rock_Ice_Permafrost"
    },
    {
      "x": -39,
      "y": 45,
      "z": 13,
      "name": "Rock_Ice_Permafrost"
    },
    {
      "x": -39,
      "y": 46,
      "z": 13,
      "name": "Rock_Ice"
    },
    {
      "x": -39,
      "y": 47,
      "z": 13,
      "name": "Soil_Snow"
    },
    {
      "x": -39,
      "y": 36,
      "z": 14,
      "name": "Rock_Ice_Permafrost"
    },
    {
      "x": -39,
      "y": 37,
      "z": 14,
      "name": "Rock_Ice_Permafrost"
    },
    {
      "x": -39,
      "y": 38,
      "z": 14,
      "name": "Rock_Ice_Permafrost"
    },
    {
      "x": -39,
      "y": 39,
      "z": 14,
      "name": "Rock_Ice_Permafrost"
    },
    {
      "x": -39,
      "y": 40,
      "z": 14,
      "name": "Rock_Ice_Permafrost"
    },
    {
      "x": -39,
      "y": 41,
      "z": 14,
      "name": "Rock_Ice_Permafrost"
    },
    {
      "x": -39,
      "y": 42,
      "z": 14,
      "name": "Rock_Ice_Permafrost"
    },
    {
      "x": -39,
      "y": 43,
      "z": 14,
      "name": "Rock_Ice_Permafrost"
    },
    {
      "x": -39,
      "y": 44,
      "z": 14,
      "name": "Rock_Ice_Permafrost"
    },
    {
      "x": -39,
      "y": 45,
      "z": 14,
      "name": "Rock_Ice"
    },
    {
      "x": -39,
      "y": 46,
      "z": 14,
      "name": "Soil_Snow"
    },
    {
      "x": -39,
      "y": 39,
      "z": 15,
      "name": "Rock_Ice_Permafrost"
    },
    {
      "x": -39,
      "y": 40,
      "z": 15,
      "name": "Rock_Ice_Permafrost"
    },
    {
      "x": -39,
      "y": 41,
      "z": 15,
      "name": "Rock_Ice_Permafrost"
    },
    {
      "x": -39,
      "y": 42,
      "z": 15,
      "name": "Rock_Ice_Permafrost"
    },
    {
      "x": -39,
      "y": 43,
      "z": 15,
      "name": "Rock_Ice_Permafrost"
    },
    {
      "x": -39,
      "y": 44,
      "z": 15,
      "name": "Rock_Ice_Permafrost"
    },
    {
      "x": -39,
      "y": 45,
      "z": 15,
      "name": "Rock_Ice_Permafrost"
    },
    {
      "x": -39,
      "y": 46,
      "z": 15,
      "name": "Rock_Ice"
    },
    {
      "x": -39,
      "y": 47,
      "z": 15,
      "name": "Soil_Snow"
    },
    {
      "x": -39,
      "y": 39,
      "z": 16,
      "name": "Rock_Ice"
    },
    {
      "x": -39,
      "y": 40,
      "z": 16,
      "name": "Rock_Ice_Permafrost"
    },
    {
      "x": -39,
      "y": 41,
      "z": 16,
      "name": "Rock_Ice_Permafrost"
    },
    {
      "x": -39,
      "y": 42,
      "z": 16,
      "name": "Rock_Ice_Permafrost"
    },
    {
      "x": -39,
      "y": 43,
      "z": 16,
      "name": "Rock_Ice_Permafrost"
    },
    {
      "x": -39,
      "y": 44,
      "z": 16,
      "name": "Rock_Ice_Permafrost"
    },
    {
      "x": -39,
      "y": 45,
      "z": 16,
      "name": "Rock_Ice_Permafrost"
    },
    {
      "x": -39,
      "y": 46,
      "z": 16,
      "name": "Rock_Ice"
    },
    {
      "x": -39,
      "y": 47,
      "z": 16,
      "name": "Soil_Snow"
    },
    {
      "x": -39,
      "y": 38,
      "z": 17,
      "name": "Rock_Ice"
    },
    {
      "x": -39,
      "y": 39,
      "z": 17,
      "name": "Rock_Ice"
    },
    {
      "x": -39,
      "y": 40,
      "z": 17,
      "name": "Rock_Ice"
    },
    {
      "x": -39,
      "y": 41,
      "z": 17,
      "name": "Rock_Ice_Permafrost"
    },
    {
      "x": -39,
      "y": 42,
      "z": 17,
      "name": "Rock_Ice_Permafrost"
    },
    {
      "x": -39,
      "y": 43,
      "z": 17,
      "name": "Rock_Ice_Permafrost"
    },
    {
      "x": -39,
      "y": 44,
      "z": 17,
      "name": "Rock_Ice_Permafrost"
    },
    {
      "x": -39,
      "y": 45,
      "z": 17,
      "name": "Rock_Ice"
    },
    {
      "x": -39,
      "y": 46,
      "z": 17,
      "name": "Soil_Snow"
    },
    {
      "x": -39,
      "y": 39,
      "z": 18,
      "name": "Rock_Ice"
    },
    {
      "x": -39,
      "y": 40,
      "z": 18,
      "name": "Rock_Ice"
    },
    {
      "x": -39,
      "y": 41,
      "z": 18,
      "name": "Rock_Ice_Permafrost"
    },
    {
      "x": -39,
      "y": 42,
      "z": 18,
      "name": "Rock_Ice_Permafrost"
    },
    {
      "x": -39,
      "y": 43,
      "z": 18,
      "name": "Rock_Ice"
    },
    {
      "x": -39,
      "y": 44,
      "z": 18,
      "name": "Soil_Snow"
    },
    {
      "x": -39,
      "y": 41,
      "z": 19,
      "name": "Rock_Ice"
    },
    {
      "x": -39,
      "y": 42,
      "z": 19,
      "name": "Soil_Snow"
    },
    {
      "x": -38,
      "y": 37,
      "z": -28,
      "name": "Rock_Ice"
    },
    {
      "x": -38,
      "y": 38,
      "z": -28,
      "name": "Rock_Ice"
    },
    {
      "x": -38,
      "y": 39,
      "z": -28,
      "name": "Rock_Ice"
    },
    {
      "x": -38,
      "y": 40,
      "z": -28,
      "name": "Rock_Ice"
    },
    {
      "x": -38,
      "y": 41,
      "z": -28,
      "name": "Rock_Ice"
    },
    {
      "x": -38,
      "y": 42,
      "z": -28,
      "name": "Rock_Ice"
    },
    {
      "x": -38,
      "y": 43,
      "z": -28,
      "name": "Rock_Ice"
    },
    {
      "x": -38,
      "y": 44,
      "z": -28,
      "name": "Soil_Snow"
    },
    {
      "x": -38,
      "y": 35,
      "z": -27,
      "name": "Rock_Ice"
    },
    {
      "x": -38,
      "y": 36,
      "z": -27,
      "name": "Rock_Ice"
    },
    {
      "x": -38,
      "y": 37,
      "z": -27,
      "name": "Rock_Ice"
    },
    {
      "x": -38,
      "y": 38,
      "z": -27,
      "name": "Rock_Ice"
    },
    {
      "x": -38,
      "y": 39,
      "z": -27,
      "name": "Rock_Ice"
    },
    {
      "x": -38,
      "y": 40,
      "z": -27,
      "name": "Rock_Ice"
    },
    {
      "x": -38,
      "y": 41,
      "z": -27,
      "name": "Rock_Ice"
    },
    {
      "x": -38,
      "y": 42,
      "z": -27,
      "name": "Rock_Ice"
    },
    {
      "x": -38,
      "y": 43,
      "z": -27,
      "name": "Rock_Ice"
    },
    {
      "x": -38,
      "y": 44,
      "z": -27,
      "name": "Rock_Ice"
    },
    {
      "x": -38,
      "y": 45,
      "z": -27,
      "name": "Rock_Ice"
    },
    {
      "x": -38,
      "y": 46,
      "z": -27,
      "name": "Soil_Snow"
    },
    {
      "x": -38,
      "y": 34,
      "z": -26,
      "name": "Rock_Ice"
    },
    {
      "x": -38,
      "y": 35,
      "z": -26,
      "name": "Rock_Ice"
    },
    {
      "x": -38,
      "y": 36,
      "z": -26,
      "name": "Rock_Ice"
    },
    {
      "x": -38,
      "y": 37,
      "z": -26,
      "name": "Rock_Ice"
    },
    {
      "x": -38,
      "y": 38,
      "z": -26,
      "name": "Rock_Ice"
    },
    {
      "x": -38,
      "y": 39,
      "z": -26,
      "name": "Rock_Ice"
    },
    {
      "x": -38,
      "y": 40,
      "z": -26,
      "name": "Rock_Ice"
    },
    {
      "x": -38,
      "y": 41,
      "z": -26,
      "name": "Rock_Ice"
    },
    {
      "x": -38,
      "y": 42,
      "z": -26,
      "name": "Rock_Ice"
    },
    {
      "x": -38,
      "y": 43,
      "z": -26,
      "name": "Rock_Ice"
    },
    {
      "x": -38,
      "y": 44,
      "z": -26,
      "name": "Rock_Ice"
    },
    {
      "x": -38,
      "y": 45,
      "z": -26,
      "name": "Rock_Ice"
    },
    {
      "x": -38,
      "y": 46,
      "z": -26,
      "name": "Rock_Ice"
    },
    {
      "x": -38,
      "y": 47,
      "z": -26,
      "name": "Rock_Ice"
    },
    {
      "x": -38,
      "y": 48,
      "z": -26,
      "name": "Soil_Snow"
    },
    {
      "x": -38,
      "y": 33,
      "z": -25,
      "name": "Rock_Ice"
    },
    {
      "x": -38,
      "y": 34,
      "z": -25,
      "name": "Rock_Ice"
    },
    {
      "x": -38,
      "y": 35,
      "z": -25,
      "name": "Rock_Ice"
    },
    {
      "x": -38,
      "y": 36,
      "z": -25,
      "name": "Rock_Ice"
    },
    {
      "x": -38,
      "y": 37,
      "z": -25,
      "name": "Rock_Ice"
    },
    {
      "x": -38,
      "y": 38,
      "z": -25,
      "name": "Rock_Ice"
    },
    {
      "x": -38,
      "y": 39,
      "z": -25,
      "name": "Rock_Ice"
    },
    {
      "x": -38,
      "y": 40,
      "z": -25,
      "name": "Rock_Ice"
    },
    {
      "x": -38,
      "y": 41,
      "z": -25,
      "name": "Rock_Ice"
    },
    {
      "x": -38,
      "y": 42,
      "z": -25,
      "name": "Rock_Ice"
    },
    {
      "x": -38,
      "y": 43,
      "z": -25,
      "name": "Rock_Ice"
    },
    {
      "x": -38,
      "y": 44,
      "z": -25,
      "name": "Rock_Ice"
    },
    {
      "x": -38,
      "y": 45,
      "z": -25,
      "name": "Rock_Ice"
    },
    {
      "x": -38,
      "y": 46,
      "z": -25,
      "name": "Rock_Ice"
    },
    {
      "x": -38,
      "y": 47,
      "z": -25,
      "name": "Rock_Ice"
    },
    {
      "x": -38,
      "y": 48,
      "z": -25,
      "name": "Rock_Ice"
    },
    {
      "x": -38,
      "y": 49,
      "z": -25,
      "name": "Soil_Snow"
    },
    {
      "x": -38,
      "y": 33,
      "z": -24,
      "name": "Rock_Ice"
    },
    {
      "x": -38,
      "y": 34,
      "z": -24,
      "name": "Rock_Ice"
    },
    {
      "x": -38,
      "y": 35,
      "z": -24,
      "name": "Rock_Ice"
    },
    {
      "x": -38,
      "y": 36,
      "z": -24,
      "name": "Rock_Ice"
    },
    {
      "x": -38,
      "y": 37,
      "z": -24,
      "name": "Rock_Ice"
    },
    {
      "x": -38,
      "y": 38,
      "z": -24,
      "name": "Rock_Ice"
    },
    {
      "x": -38,
      "y": 39,
      "z": -24,
      "name": "Rock_Ice"
    },
    {
      "x": -38,
      "y": 40,
      "z": -24,
      "name": "Rock_Ice"
    },
    {
      "x": -38,
      "y": 41,
      "z": -24,
      "name": "Rock_Ice"
    },
    {
      "x": -38,
      "y": 42,
      "z": -24,
      "name": "Rock_Ice"
    },
    {
      "x": -38,
      "y": 43,
      "z": -24,
      "name": "Rock_Ice"
    },
    {
      "x": -38,
      "y": 44,
      "z": -24,
      "name": "Rock_Ice"
    },
    {
      "x": -38,
      "y": 45,
      "z": -24,
      "name": "Rock_Ice"
    },
    {
      "x": -38,
      "y": 46,
      "z": -24,
      "name": "Rock_Ice"
    },
    {
      "x": -38,
      "y": 47,
      "z": -24,
      "name": "Rock_Ice"
    },
    {
      "x": -38,
      "y": 48,
      "z": -24,
      "name": "Rock_Ice"
    },
    {
      "x": -38,
      "y": 49,
      "z": -24,
      "name": "Rock_Ice"
    },
    {
      "x": -38,
      "y": 50,
      "z": -24,
      "name": "Soil_Snow"
    },
    {
      "x": -38,
      "y": 33,
      "z": -23,
      "name": "Rock_Ice"
    },
    {
      "x": -38,
      "y": 34,
      "z": -23,
      "name": "Rock_Ice"
    },
    {
      "x": -38,
      "y": 35,
      "z": -23,
      "name": "Rock_Ice"
    },
    {
      "x": -38,
      "y": 36,
      "z": -23,
      "name": "Rock_Ice"
    },
    {
      "x": -38,
      "y": 37,
      "z": -23,
      "name": "Rock_Ice"
    },
    {
      "x": -38,
      "y": 38,
      "z": -23,
      "name": "Rock_Ice"
    },
    {
      "x": -38,
      "y": 39,
      "z": -23,
      "name": "Rock_Ice"
    },
    {
      "x": -38,
      "y": 40,
      "z": -23,
      "name": "Rock_Ice"
    },
    {
      "x": -38,
      "y": 41,
      "z": -23,
      "name": "Rock_Ice"
    },
    {
      "x": -38,
      "y": 42,
      "z": -23,
      "name": "Rock_Ice"
    },
    {
      "x": -38,
      "y": 43,
      "z": -23,
      "name": "Rock_Ice"
    },
    {
      "x": -38,
      "y": 44,
      "z": -23,
      "name": "Rock_Ice"
    },
    {
      "x": -38,
      "y": 45,
      "z": -23,
      "name": "Rock_Ice"
    },
    {
      "x": -38,
      "y": 46,
      "z": -23,
      "name": "Rock_Ice"
    },
    {
      "x": -38,
      "y": 47,
      "z": -23,
      "name": "Rock_Ice"
    },
    {
      "x": -38,
      "y": 48,
      "z": -23,
      "name": "Rock_Ice"
    },
    {
      "x": -38,
      "y": 49,
      "z": -23,
      "name": "Rock_Ice"
    },
    {
      "x": -38,
      "y": 50,
      "z": -23,
      "name": "Rock_Ice"
    },
    {
      "x": -38,
      "y": 51,
      "z": -23,
      "name": "Soil_Snow"
    },
    {
      "x": -38,
      "y": 33,
      "z": -22,
      "name": "Rock_Ice"
    },
    {
      "x": -38,
      "y": 34,
      "z": -22,
      "name": "Rock_Ice"
    },
    {
      "x": -38,
      "y": 35,
      "z": -22,
      "name": "Rock_Ice"
    },
    {
      "x": -38,
      "y": 36,
      "z": -22,
      "name": "Rock_Ice"
    },
    {
      "x": -38,
      "y": 37,
      "z": -22,
      "name": "Rock_Ice"
    },
    {
      "x": -38,
      "y": 38,
      "z": -22,
      "name": "Rock_Ice"
    },
    {
      "x": -38,
      "y": 39,
      "z": -22,
      "name": "Rock_Ice"
    },
    {
      "x": -38,
      "y": 40,
      "z": -22,
      "name": "Rock_Ice"
    },
    {
      "x": -38,
      "y": 41,
      "z": -22,
      "name": "Rock_Ice"
    },
    {
      "x": -38,
      "y": 42,
      "z": -22,
      "name": "Rock_Ice"
    },
    {
      "x": -38,
      "y": 43,
      "z": -22,
      "name": "Rock_Ice"
    },
    {
      "x": -38,
      "y": 44,
      "z": -22,
      "name": "Rock_Ice"
    },
    {
      "x": -38,
      "y": 45,
      "z": -22,
      "name": "Rock_Ice"
    },
    {
      "x": -38,
      "y": 46,
      "z": -22,
      "name": "Rock_Ice"
    },
    {
      "x": -38,
      "y": 47,
      "z": -22,
      "name": "Rock_Ice"
    },
    {
      "x": -38,
      "y": 48,
      "z": -22,
      "name": "Rock_Ice"
    },
    {
      "x": -38,
      "y": 49,
      "z": -22,
      "name": "Rock_Ice"
    },
    {
      "x": -38,
      "y": 50,
      "z": -22,
      "name": "Rock_Ice"
    },
    {
      "x": -38,
      "y": 51,
      "z": -22,
      "name": "Rock_Ice"
    },
    {
      "x": -38,
      "y": 52,
      "z": -22,
      "name": "Rock_Ice"
    },
    {
      "x": -38,
      "y": 53,
      "z": -22,
      "name": "Soil_Snow"
    },
    {
      "x": -38,
      "y": 34,
      "z": -21,
      "name": "Rock_Ice"
    },
    {
      "x": -38,
      "y": 35,
      "z": -21,
      "name": "Rock_Ice"
    },
    {
      "x": -38,
      "y": 36,
      "z": -21,
      "name": "Rock_Ice"
    },
    {
      "x": -38,
      "y": 37,
      "z": -21,
      "name": "Rock_Ice"
    },
    {
      "x": -38,
      "y": 38,
      "z": -21,
      "name": "Rock_Ice"
    },
    {
      "x": -38,
      "y": 39,
      "z": -21,
      "name": "Rock_Ice"
    },
    {
      "x": -38,
      "y": 40,
      "z": -21,
      "name": "Rock_Ice"
    },
    {
      "x": -38,
      "y": 41,
      "z": -21,
      "name": "Rock_Ice"
    },
    {
      "x": -38,
      "y": 42,
      "z": -21,
      "name": "Rock_Ice"
    },
    {
      "x": -38,
      "y": 43,
      "z": -21,
      "name": "Rock_Ice"
    },
    {
      "x": -38,
      "y": 44,
      "z": -21,
      "name": "Rock_Ice"
    },
    {
      "x": -38,
      "y": 45,
      "z": -21,
      "name": "Rock_Ice"
    },
    {
      "x": -38,
      "y": 46,
      "z": -21,
      "name": "Rock_Ice"
    },
    {
      "x": -38,
      "y": 47,
      "z": -21,
      "name": "Rock_Ice"
    },
    {
      "x": -38,
      "y": 48,
      "z": -21,
      "name": "Rock_Ice"
    },
    {
      "x": -38,
      "y": 49,
      "z": -21,
      "name": "Rock_Ice"
    },
    {
      "x": -38,
      "y": 50,
      "z": -21,
      "name": "Rock_Ice"
    },
    {
      "x": -38,
      "y": 51,
      "z": -21,
      "name": "Rock_Ice"
    },
    {
      "x": -38,
      "y": 52,
      "z": -21,
      "name": "Rock_Ice"
    },
    {
      "x": -38,
      "y": 53,
      "z": -21,
      "name": "Rock_Ice"
    },
    {
      "x": -38,
      "y": 54,
      "z": -21,
      "name": "Soil_Snow"
    },
    {
      "x": -38,
      "y": 34,
      "z": -20,
      "name": "Rock_Ice"
    },
    {
      "x": -38,
      "y": 35,
      "z": -20,
      "name": "Rock_Ice"
    },
    {
      "x": -38,
      "y": 36,
      "z": -20,
      "name": "Rock_Ice"
    },
    {
      "x": -38,
      "y": 37,
      "z": -20,
      "name": "Rock_Ice"
    },
    {
      "x": -38,
      "y": 38,
      "z": -20,
      "name": "Rock_Ice"
    },
    {
      "x": -38,
      "y": 39,
      "z": -20,
      "name": "Rock_Ice"
    },
    {
      "x": -38,
      "y": 40,
      "z": -20,
      "name": "Rock_Ice"
    },
    {
      "x": -38,
      "y": 41,
      "z": -20,
      "name": "Rock_Ice"
    },
    {
      "x": -38,
      "y": 42,
      "z": -20,
      "name": "Rock_Ice"
    },
    {
      "x": -38,
      "y": 43,
      "z": -20,
      "name": "Rock_Ice"
    },
    {
      "x": -38,
      "y": 44,
      "z": -20,
      "name": "Rock_Ice"
    },
    {
      "x": -38,
      "y": 45,
      "z": -20,
      "name": "Rock_Ice"
    },
    {
      "x": -38,
      "y": 46,
      "z": -20,
      "name": "Rock_Ice"
    },
    {
      "x": -38,
      "y": 47,
      "z": -20,
      "name": "Rock_Ice"
    },
    {
      "x": -38,
      "y": 48,
      "z": -20,
      "name": "Rock_Ice"
    },
    {
      "x": -38,
      "y": 49,
      "z": -20,
      "name": "Rock_Ice"
    },
    {
      "x": -38,
      "y": 50,
      "z": -20,
      "name": "Rock_Ice"
    },
    {
      "x": -38,
      "y": 51,
      "z": -20,
      "name": "Rock_Ice"
    },
    {
      "x": -38,
      "y": 52,
      "z": -20,
      "name": "Rock_Ice"
    },
    {
      "x": -38,
      "y": 53,
      "z": -20,
      "name": "Rock_Ice"
    },
    {
      "x": -38,
      "y": 54,
      "z": -20,
      "name": "Rock_Ice"
    },
    {
      "x": -38,
      "y": 55,
      "z": -20,
      "name": "Rock_Ice"
    },
    {
      "x": -38,
      "y": 56,
      "z": -20,
      "name": "Rock_Ice"
    },
    {
      "x": -38,
      "y": 57,
      "z": -20,
      "name": "Soil_Snow"
    },
    {
      "x": -38,
      "y": 35,
      "z": -19,
      "name": "Rock_Ice"
    },
    {
      "x": -38,
      "y": 36,
      "z": -19,
      "name": "Rock_Ice"
    },
    {
      "x": -38,
      "y": 37,
      "z": -19,
      "name": "Rock_Ice"
    },
    {
      "x": -38,
      "y": 38,
      "z": -19,
      "name": "Rock_Ice"
    },
    {
      "x": -38,
      "y": 39,
      "z": -19,
      "name": "Rock_Ice"
    },
    {
      "x": -38,
      "y": 40,
      "z": -19,
      "name": "Rock_Ice"
    },
    {
      "x": -38,
      "y": 41,
      "z": -19,
      "name": "Rock_Ice"
    },
    {
      "x": -38,
      "y": 42,
      "z": -19,
      "name": "Rock_Ice"
    },
    {
      "x": -38,
      "y": 43,
      "z": -19,
      "name": "Rock_Ice"
    },
    {
      "x": -38,
      "y": 44,
      "z": -19,
      "name": "Rock_Ice"
    },
    {
      "x": -38,
      "y": 45,
      "z": -19,
      "name": "Rock_Ice"
    },
    {
      "x": -38,
      "y": 46,
      "z": -19,
      "name": "Rock_Ice"
    },
    {
      "x": -38,
      "y": 47,
      "z": -19,
      "name": "Rock_Ice"
    },
    {
      "x": -38,
      "y": 48,
      "z": -19,
      "name": "Rock_Ice"
    },
    {
      "x": -38,
      "y": 49,
      "z": -19,
      "name": "Rock_Ice"
    },
    {
      "x": -38,
      "y": 50,
      "z": -19,
      "name": "Rock_Ice"
    },
    {
      "x": -38,
      "y": 51,
      "z": -19,
      "name": "Rock_Ice"
    },
    {
      "x": -38,
      "y": 52,
      "z": -19,
      "name": "Rock_Ice"
    },
    {
      "x": -38,
      "y": 53,
      "z": -19,
      "name": "Rock_Ice"
    },
    {
      "x": -38,
      "y": 54,
      "z": -19,
      "name": "Rock_Ice"
    },
    {
      "x": -38,
      "y": 55,
      "z": -19,
      "name": "Rock_Ice"
    },
    {
      "x": -38,
      "y": 56,
      "z": -19,
      "name": "Rock_Ice"
    },
    {
      "x": -38,
      "y": 57,
      "z": -19,
      "name": "Soil_Snow"
    },
    {
      "x": -38,
      "y": 36,
      "z": -18,
      "name": "Rock_Ice"
    },
    {
      "x": -38,
      "y": 37,
      "z": -18,
      "name": "Rock_Ice"
    },
    {
      "x": -38,
      "y": 38,
      "z": -18,
      "name": "Rock_Ice"
    },
    {
      "x": -38,
      "y": 39,
      "z": -18,
      "name": "Rock_Ice"
    },
    {
      "x": -38,
      "y": 40,
      "z": -18,
      "name": "Rock_Ice"
    },
    {
      "x": -38,
      "y": 41,
      "z": -18,
      "name": "Rock_Ice"
    },
    {
      "x": -38,
      "y": 42,
      "z": -18,
      "name": "Rock_Ice"
    },
    {
      "x": -38,
      "y": 43,
      "z": -18,
      "name": "Rock_Ice"
    },
    {
      "x": -38,
      "y": 44,
      "z": -18,
      "name": "Rock_Ice"
    },
    {
      "x": -38,
      "y": 45,
      "z": -18,
      "name": "Rock_Ice"
    },
    {
      "x": -38,
      "y": 46,
      "z": -18,
      "name": "Rock_Ice"
    },
    {
      "x": -38,
      "y": 47,
      "z": -18,
      "name": "Rock_Ice"
    },
    {
      "x": -38,
      "y": 48,
      "z": -18,
      "name": "Rock_Ice"
    },
    {
      "x": -38,
      "y": 49,
      "z": -18,
      "name": "Rock_Ice"
    },
    {
      "x": -38,
      "y": 50,
      "z": -18,
      "name": "Rock_Ice"
    },
    {
      "x": -38,
      "y": 51,
      "z": -18,
      "name": "Rock_Ice"
    },
    {
      "x": -38,
      "y": 52,
      "z": -18,
      "name": "Rock_Ice"
    },
    {
      "x": -38,
      "y": 53,
      "z": -18,
      "name": "Rock_Ice"
    },
    {
      "x": -38,
      "y": 54,
      "z": -18,
      "name": "Rock_Ice"
    },
    {
      "x": -38,
      "y": 55,
      "z": -18,
      "name": "Rock_Ice"
    },
    {
      "x": -38,
      "y": 56,
      "z": -18,
      "name": "Rock_Ice"
    },
    {
      "x": -38,
      "y": 57,
      "z": -18,
      "name": "Soil_Snow"
    },
    {
      "x": -38,
      "y": 37,
      "z": -17,
      "name": "Rock_Ice"
    },
    {
      "x": -38,
      "y": 38,
      "z": -17,
      "name": "Rock_Ice"
    },
    {
      "x": -38,
      "y": 39,
      "z": -17,
      "name": "Rock_Ice"
    },
    {
      "x": -38,
      "y": 40,
      "z": -17,
      "name": "Rock_Ice"
    },
    {
      "x": -38,
      "y": 41,
      "z": -17,
      "name": "Rock_Ice"
    },
    {
      "x": -38,
      "y": 42,
      "z": -17,
      "name": "Rock_Ice"
    },
    {
      "x": -38,
      "y": 43,
      "z": -17,
      "name": "Rock_Ice"
    },
    {
      "x": -38,
      "y": 44,
      "z": -17,
      "name": "Rock_Ice"
    },
    {
      "x": -38,
      "y": 45,
      "z": -17,
      "name": "Rock_Ice"
    },
    {
      "x": -38,
      "y": 46,
      "z": -17,
      "name": "Rock_Ice"
    },
    {
      "x": -38,
      "y": 47,
      "z": -17,
      "name": "Rock_Ice"
    },
    {
      "x": -38,
      "y": 48,
      "z": -17,
      "name": "Rock_Ice"
    },
    {
      "x": -38,
      "y": 49,
      "z": -17,
      "name": "Rock_Ice"
    },
    {
      "x": -38,
      "y": 50,
      "z": -17,
      "name": "Rock_Ice"
    },
    {
      "x": -38,
      "y": 51,
      "z": -17,
      "name": "Rock_Ice"
    },
    {
      "x": -38,
      "y": 52,
      "z": -17,
      "name": "Rock_Ice"
    },
    {
      "x": -38,
      "y": 53,
      "z": -17,
      "name": "Rock_Ice"
    },
    {
      "x": -38,
      "y": 54,
      "z": -17,
      "name": "Rock_Ice"
    },
    {
      "x": -38,
      "y": 55,
      "z": -17,
      "name": "Rock_Ice"
    },
    {
      "x": -38,
      "y": 56,
      "z": -17,
      "name": "Rock_Ice"
    },
    {
      "x": -38,
      "y": 57,
      "z": -17,
      "name": "Soil_Snow"
    },
    {
      "x": -38,
      "y": 38,
      "z": -16,
      "name": "Rock_Ice"
    },
    {
      "x": -38,
      "y": 39,
      "z": -16,
      "name": "Rock_Ice"
    },
    {
      "x": -38,
      "y": 40,
      "z": -16,
      "name": "Rock_Ice"
    },
    {
      "x": -38,
      "y": 41,
      "z": -16,
      "name": "Rock_Ice"
    },
    {
      "x": -38,
      "y": 42,
      "z": -16,
      "name": "Rock_Ice"
    },
    {
      "x": -38,
      "y": 43,
      "z": -16,
      "name": "Rock_Ice"
    },
    {
      "x": -38,
      "y": 44,
      "z": -16,
      "name": "Rock_Ice"
    },
    {
      "x": -38,
      "y": 45,
      "z": -16,
      "name": "Rock_Ice"
    },
    {
      "x": -38,
      "y": 46,
      "z": -16,
      "name": "Rock_Ice"
    },
    {
      "x": -38,
      "y": 47,
      "z": -16,
      "name": "Rock_Ice"
    },
    {
      "x": -38,
      "y": 48,
      "z": -16,
      "name": "Rock_Ice"
    },
    {
      "x": -38,
      "y": 49,
      "z": -16,
      "name": "Rock_Ice"
    },
    {
      "x": -38,
      "y": 50,
      "z": -16,
      "name": "Rock_Ice"
    },
    {
      "x": -38,
      "y": 51,
      "z": -16,
      "name": "Rock_Ice"
    },
    {
      "x": -38,
      "y": 52,
      "z": -16,
      "name": "Rock_Ice"
    },
    {
      "x": -38,
      "y": 53,
      "z": -16,
      "name": "Rock_Ice"
    },
    {
      "x": -38,
      "y": 54,
      "z": -16,
      "name": "Rock_Ice"
    },
    {
      "x": -38,
      "y": 55,
      "z": -16,
      "name": "Rock_Ice"
    },
    {
      "x": -38,
      "y": 56,
      "z": -16,
      "name": "Rock_Ice"
    },
    {
      "x": -38,
      "y": 57,
      "z": -16,
      "name": "Soil_Snow"
    },
    {
      "x": -38,
      "y": 39,
      "z": -15,
      "name": "Rock_Ice_Permafrost"
    },
    {
      "x": -38,
      "y": 40,
      "z": -15,
      "name": "Rock_Ice"
    },
    {
      "x": -38,
      "y": 41,
      "z": -15,
      "name": "Rock_Ice"
    },
    {
      "x": -38,
      "y": 42,
      "z": -15,
      "name": "Rock_Ice"
    },
    {
      "x": -38,
      "y": 43,
      "z": -15,
      "name": "Rock_Ice"
    },
    {
      "x": -38,
      "y": 44,
      "z": -15,
      "name": "Rock_Ice"
    },
    {
      "x": -38,
      "y": 45,
      "z": -15,
      "name": "Rock_Ice"
    },
    {
      "x": -38,
      "y": 46,
      "z": -15,
      "name": "Rock_Ice"
    },
    {
      "x": -38,
      "y": 47,
      "z": -15,
      "name": "Rock_Ice"
    },
    {
      "x": -38,
      "y": 48,
      "z": -15,
      "name": "Rock_Ice"
    },
    {
      "x": -38,
      "y": 49,
      "z": -15,
      "name": "Rock_Ice"
    },
    {
      "x": -38,
      "y": 50,
      "z": -15,
      "name": "Rock_Ice"
    },
    {
      "x": -38,
      "y": 51,
      "z": -15,
      "name": "Rock_Ice"
    },
    {
      "x": -38,
      "y": 52,
      "z": -15,
      "name": "Rock_Ice"
    },
    {
      "x": -38,
      "y": 53,
      "z": -15,
      "name": "Rock_Ice"
    },
    {
      "x": -38,
