{
  "version": 8,
  "blockIdVersion": 11,
  "anchorX": 3,
  "anchorY": 30,
  "anchorZ": 7,
  "blocks": [
    {
      "x": -45,
      "y": 61,
      "z": 26,
      "name": "Soil_Snow"
    },
    {
      "x": -45,
      "y": 60,
      "z": 27,
      "name": "Rock_Ice"
    },
    {
      "x": -45,
      "y": 61,
      "z": 27,
      "name": "Soil_Snow"
    },
    {
      "x": -45,
      "y": 59,
      "z": 28,
      "name": "Rock_Ice_Permafrost"
    },
    {
      "x": -45,
      "y": 60,
      "z": 28,
      "name": "Rock_Ice"
    },
    {
      "x": -45,
      "y": 61,
      "z": 28,
      "name": "Soil_Snow"
    },
    {
      "x": -45,
      "y": 58,
      "z": 29,
      "name": "Rock_Ice_Permafrost"
    },
    {
      "x": -45,
      "y": 59,
      "z": 29,
      "name": "Rock_Ice_Permafrost"
    },
    {
      "x": -45,
      "y": 60,
      "z": 29,
      "name": "Rock_Ice"
    },
    {
      "x": -45,
      "y": 61,
      "z": 29,
      "name": "Soil_Snow"
    },
    {
      "x": -45,
      "y": 57,
      "z": 30,
      "name": "Rock_Ice_Permafrost"
    },
    {
      "x": -45,
      "y": 58,
      "z": 30,
      "name": "Rock_Ice_Permafrost"
    },
    {
      "x": -45,
      "y": 59,
      "z": 30,
      "name": "Rock_Ice_Permafrost"
    },
    {
      "x": -45,
      "y": 60,
      "z": 30,
      "name": "Rock_Ice_Permafrost"
    },
    {
      "x": -45,
      "y": 61,
      "z": 30,
      "name": "Rock_Ice"
    },
    {
      "x": -45,
      "y": 62,
      "z": 30,
      "name": "Soil_Snow"
    },
    {
      "x": -45,
      "y": 57,
      "z": 31,
      "name": "Rock_Ice_Permafrost"
    },
    {
      "x": -45,
      "y": 58,
      "z": 31,
      "name": "Rock_Ice_Permafrost"
    },
    {
      "x": -45,
      "y": 59,
      "z": 31,
      "name": "Rock_Ice_Permafrost"
    },
    {
      "x": -45,
      "y": 60,
      "z": 31,
      "name": "Rock_Ice_Permafrost"
    },
    {
      "x": -45,
      "y": 61,
      "z": 31,
      "name": "Rock_Ice"
    },
    {
      "x": -45,
      "y": 62,
      "z": 31,
      "name": "Soil_Snow"
    },
    {
      "x": -45,
      "y": 56,
      "z": 32,
      "name": "Rock_Ice"
    },
    {
      "x": -45,
      "y": 57,
      "z": 32,
      "name": "Rock_Ice_Permafrost"
    },
    {
      "x": -45,
      "y": 58,
      "z": 32,
      "name": "Rock_Ice_Permafrost"
    },
    {
      "x": -45,
      "y": 59,
      "z": 32,
      "name": "Rock_Ice_Permafrost"
    },
    {
      "x": -45,
      "y": 60,
      "z": 32,
      "name": "Rock_Ice"
    },
    {
      "x": -45,
      "y": 61,
      "z": 32,
      "name": "Soil_Snow"
    },
    {
      "x": -45,
      "y": 56,
      "z": 33,
      "name": "Rock_Ice_Permafrost"
    },
    {
      "x": -45,
      "y": 57,
      "z": 33,
      "name": "Rock_Ice"
    },
    {
      "x": -45,
      "y": 58,
      "z": 33,
      "name": "Rock_Ice_Permafrost"
    },
    {
      "x": -45,
      "y": 59,
      "z": 33,
      "name": "Rock_Ice_Permafrost"
    },
    {
      "x": -45,
      "y": 60,
      "z": 33,
      "name": "Rock_Ice"
    },
    {
      "x": -45,
      "y": 61,
      "z": 33,
      "name": "Soil_Snow"
    },
    {
      "x": -45,
      "y": 56,
      "z": 34,
      "name": "Rock_Ice_Permafrost"
    },
    {
      "x": -45,
      "y": 57,
      "z": 34,
      "name": "Rock_Ice_Permafrost"
    },
    {
      "x": -45,
      "y": 58,
      "z": 34,
      "name": "Rock_Ice_Permafrost"
    },
    {
      "x": -45,
      "y": 59,
      "z": 34,
      "name": "Rock_Ice_Permafrost"
    },
    {
      "x": -45,
      "y": 60,
      "z": 34,
      "name": "Rock_Ice_Permafrost"
    },
    {
      "x": -44,
      "y": 62,
      "z": 24,
      "name": "Soil_Snow"
    },
    {
      "x": -44,
      "y": 60,
      "z": 25,
      "name": "Rock_Ice"
    },
    {
      "x": -44,
      "y": 61,
      "z": 25,
      "name": "Rock_Ice"
    },
    {
      "x": -44,
      "y": 62,
      "z": 25,
      "name": "Soil_Snow"
    },
    {
      "x": -44,
      "y": 56,
      "z": 26,
      "name": "Rock_Ice"
    },
    {
      "x": -44,
      "y": 57,
      "z": 26,
      "name": "Rock_Ice"
    },
    {
      "x": -44,
      "y": 58,
      "z": 26,
      "name": "Rock_Ice"
    },
    {
      "x": -44,
      "y": 59,
      "z": 26,
      "name": "Rock_Ice"
    },
    {
      "x": -44,
      "y": 60,
      "z": 26,
      "name": "Rock_Ice"
    },
    {
      "x": -44,
      "y": 61,
      "z": 26,
      "name": "Rock_Ice"
    },
    {
      "x": -44,
      "y": 62,
      "z": 26,
      "name": "Rock_Ice"
    },
    {
      "x": -44,
      "y": 63,
      "z": 26,
      "name": "Soil_Snow"
    },
    {
      "x": -44,
      "y": 55,
      "z": 27,
      "name": "Rock_Ice"
    },
    {
      "x": -44,
      "y": 56,
      "z": 27,
      "name": "Rock_Ice"
    },
    {
      "x": -44,
      "y": 57,
      "z": 27,
      "name": "Rock_Ice"
    },
    {
      "x": -44,
      "y": 58,
      "z": 27,
      "name": "Rock_Ice"
    },
    {
      "x": -44,
      "y": 59,
      "z": 27,
      "name": "Rock_Ice"
    },
    {
      "x": -44,
      "y": 60,
      "z": 27,
      "name": "Rock_Ice_Permafrost"
    },
    {
      "x": -44,
      "y": 61,
      "z": 27,
      "name": "Rock_Ice_Permafrost"
    },
    {
      "x": -44,
      "y": 62,
      "z": 27,
      "name": "Rock_Ice"
    },
    {
      "x": -44,
      "y": 63,
      "z": 27,
      "name": "Soil_Snow"
    },
    {
      "x": -44,
      "y": 54,
      "z": 28,
      "name": "Rock_Ice_Permafrost"
    },
    {
      "x": -44,
      "y": 55,
      "z": 28,
      "name": "Rock_Ice_Permafrost"
    },
    {
      "x": -44,
      "y": 56,
      "z": 28,
      "name": "Rock_Ice_Permafrost"
    },
    {
      "x": -44,
      "y": 57,
      "z": 28,
      "name": "Rock_Ice_Permafrost"
    },
    {
      "x": -44,
      "y": 58,
      "z": 28,
      "name": "Rock_Ice_Permafrost"
    },
    {
      "x": -44,
      "y": 59,
      "z": 28,
      "name": "Rock_Ice_Permafrost"
    },
    {
      "x": -44,
      "y": 60,
      "z": 28,
      "name": "Rock_Ice_Permafrost"
    },
    {
      "x": -44,
      "y": 61,
      "z": 28,
      "name": "Rock_Ice_Permafrost"
    },
    {
      "x": -44,
      "y": 62,
      "z": 28,
      "name": "Rock_Ice"
    },
    {
      "x": -44,
      "y": 63,
      "z": 28,
      "name": "Soil_Snow"
    },
    {
      "x": -44,
      "y": 54,
      "z": 29,
      "name": "Rock_Ice_Permafrost"
    },
    {
      "x": -44,
      "y": 55,
      "z": 29,
      "name": "Rock_Ice_Permafrost"
    },
    {
      "x": -44,
      "y": 56,
      "z": 29,
      "name": "Rock_Ice_Permafrost"
    },
    {
      "x": -44,
      "y": 57,
      "z": 29,
      "name": "Rock_Ice_Permafrost"
    },
    {
      "x": -44,
      "y": 58,
      "z": 29,
      "name": "Rock_Ice_Permafrost"
    },
    {
      "x": -44,
      "y": 59,
      "z": 29,
      "name": "Rock_Ice_Permafrost"
    },
    {
      "x": -44,
      "y": 60,
      "z": 29,
      "name": "Rock_Ice_Permafrost"
    },
    {
      "x": -44,
      "y": 61,
      "z": 29,
      "name": "Rock_Ice_Permafrost"
    },
    {
      "x": -44,
      "y": 62,
      "z": 29,
      "name": "Rock_Ice_Permafrost"
    },
    {
      "x": -44,
      "y": 63,
      "z": 29,
      "name": "Rock_Ice"
    },
    {
      "x": -44,
      "y": 64,
      "z": 29,
      "name": "Soil_Snow"
    },
    {
      "x": -44,
      "y": 54,
      "z": 30,
      "name": "Rock_Ice"
    },
    {
      "x": -44,
      "y": 55,
      "z": 30,
      "name": "Rock_Ice"
    },
    {
      "x": -44,
      "y": 56,
      "z": 30,
      "name": "Rock_Ice_Permafrost"
    },
    {
      "x": -44,
      "y": 57,
      "z": 30,
      "name": "Rock_Ice_Permafrost"
    },
    {
      "x": -44,
      "y": 58,
      "z": 30,
      "name": "Rock_Ice_Permafrost"
    },
    {
      "x": -44,
      "y": 59,
      "z": 30,
      "name": "Rock_Ice_Permafrost"
    },
    {
      "x": -44,
      "y": 60,
      "z": 30,
      "name": "Rock_Ice_Permafrost"
    },
    {
      "x": -44,
      "y": 61,
      "z": 30,
      "name": "Rock_Ice_Permafrost"
    },
    {
      "x": -44,
      "y": 62,
      "z": 30,
      "name": "Rock_Ice"
    },
    {
      "x": -44,
      "y": 63,
      "z": 30,
      "name": "Rock_Ice"
    },
    {
      "x": -44,
      "y": 64,
      "z": 30,
      "name": "Soil_Snow"
    },
    {
      "x": -44,
      "y": 54,
      "z": 31,
      "name": "Rock_Ice"
    },
    {
      "x": -44,
      "y": 55,
      "z": 31,
      "name": "Rock_Ice"
    },
    {
      "x": -44,
      "y": 56,
      "z": 31,
      "name": "Rock_Ice"
    },
    {
      "x": -44,
      "y": 57,
      "z": 31,
      "name": "Rock_Ice_Permafrost"
    },
    {
      "x": -44,
      "y": 58,
      "z": 31,
      "name": "Rock_Ice_Permafrost"
    },
    {
      "x": -44,
      "y": 59,
      "z": 31,
      "name": "Rock_Ice_Permafrost"
    },
    {
      "x": -44,
      "y": 60,
      "z": 31,
      "name": "Rock_Ice_Permafrost"
    },
    {
      "x": -44,
      "y": 61,
      "z": 31,
      "name": "Rock_Ice_Permafrost"
    },
    {
      "x": -44,
      "y": 62,
      "z": 31,
      "name": "Rock_Ice"
    },
    {
      "x": -44,
      "y": 63,
      "z": 31,
      "name": "Rock_Ice"
    },
    {
      "x": -44,
      "y": 64,
      "z": 31,
      "name": "Soil_Snow"
    },
    {
      "x": -44,
      "y": 55,
      "z": 32,
      "name": "Rock_Ice"
    },
    {
      "x": -44,
      "y": 56,
      "z": 32,
      "name": "Rock_Ice"
    },
    {
      "x": -44,
      "y": 57,
      "z": 32,
      "name": "Rock_Ice_Permafrost"
    },
    {
      "x": -44,
      "y": 58,
      "z": 32,
      "name": "Rock_Ice_Permafrost"
    },
    {
      "x": -44,
      "y": 59,
      "z": 32,
      "name": "Rock_Ice_Permafrost"
    },
    {
      "x": -44,
      "y": 60,
      "z": 32,
      "name": "Rock_Ice_Permafrost"
    },
    {
      "x": -44,
      "y": 61,
      "z": 32,
      "name": "Rock_Ice_Permafrost"
    },
    {
      "x": -44,
      "y": 62,
      "z": 32,
      "name": "Rock_Ice"
    },
    {
      "x": -44,
      "y": 63,
      "z": 32,
      "name": "Rock_Ice"
    },
    {
      "x": -44,
      "y": 64,
      "z": 32,
      "name": "Soil_Snow"
    },
    {
      "x": -44,
      "y": 55,
      "z": 33,
      "name": "Rock_Ice"
    },
    {
      "x": -44,
      "y": 56,
      "z": 33,
      "name": "Rock_Ice"
    },
    {
      "x": -44,
      "y": 57,
      "z": 33,
      "name": "Rock_Ice_Permafrost"
    },
    {
      "x": -44,
      "y": 58,
      "z": 33,
      "name": "Rock_Ice_Permafrost"
    },
    {
      "x": -44,
      "y": 59,
      "z": 33,
      "name": "Rock_Ice_Permafrost"
    },
    {
      "x": -44,
      "y": 60,
      "z": 33,
      "name": "Rock_Ice_Permafrost"
    },
    {
      "x": -44,
      "y": 61,
      "z": 33,
      "name": "Rock_Ice_Permafrost"
    },
    {
      "x": -44,
      "y": 62,
      "z": 33,
      "name": "Rock_Ice_Permafrost"
    },
    {
      "x": -44,
      "y": 63,
      "z": 33,
      "name": "Rock_Ice"
    },
    {
      "x": -44,
      "y": 64,
      "z": 33,
      "name": "Soil_Snow"
    },
    {
      "x": -44,
      "y": 55,
      "z": 34,
      "name": "Rock_Ice_Permafrost"
    },
    {
      "x": -44,
      "y": 56,
      "z": 34,
      "name": "Rock_Ice_Permafrost"
    },
    {
      "x": -44,
      "y": 57,
      "z": 34,
      "name": "Rock_Ice_Permafrost"
    },
    {
      "x": -44,
      "y": 58,
      "z": 34,
      "name": "Rock_Ice_Permafrost"
    },
    {
      "x": -44,
      "y": 59,
      "z": 34,
      "name": "Rock_Ice_Permafrost"
    },
    {
      "x": -44,
      "y": 60,
      "z": 34,
      "name": "Rock_Ice_Permafrost"
    },
    {
      "x": -44,
      "y": 61,
      "z": 34,
      "name": "Rock_Ice_Permafrost"
    },
    {
      "x": -44,
      "y": 62,
      "z": 34,
      "name": "Rock_Ice_Permafrost"
    },
    {
      "x": -44,
      "y": 63,
      "z": 34,
      "name": "Rock_Ice"
    },
    {
      "x": -44,
      "y": 64,
      "z": 34,
      "name": "Soil_Snow"
    },
    {
      "x": -44,
      "y": 55,
      "z": 35,
      "name": "Rock_Ice"
    },
    {
      "x": -44,
      "y": 56,
      "z": 35,
      "name": "Rock_Ice"
    },
    {
      "x": -44,
      "y": 57,
      "z": 35,
      "name": "Rock_Ice_Permafrost"
    },
    {
      "x": -44,
      "y": 58,
      "z": 35,
      "name": "Rock_Ice_Permafrost"
    },
    {
      "x": -44,
      "y": 59,
      "z": 35,
      "name": "Rock_Ice"
    },
    {
      "x": -44,
      "y": 60,
      "z": 35,
      "name": "Rock_Ice"
    },
    {
      "x": -44,
      "y": 61,
      "z": 35,
      "name": "Rock_Ice_Permafrost"
    },
    {
      "x": -44,
      "y": 62,
      "z": 35,
      "name": "Rock_Ice"
    },
    {
      "x": -44,
      "y": 63,
      "z": 35,
      "name": "Soil_Snow"
    },
    {
      "x": -44,
      "y": 55,
      "z": 36,
      "name": "Rock_Ice"
    },
    {
      "x": -44,
      "y": 56,
      "z": 36,
      "name": "Rock_Ice"
    },
    {
      "x": -44,
      "y": 57,
      "z": 36,
      "name": "Rock_Ice"
    },
    {
      "x": -44,
      "y": 58,
      "z": 36,
      "name": "Rock_Ice"
    },
    {
      "x": -44,
      "y": 59,
      "z": 36,
      "name": "Rock_Ice"
    },
    {
      "x": -44,
      "y": 60,
      "z": 36,
      "name": "Rock_Ice"
    },
    {
      "x": -44,
      "y": 61,
      "z": 36,
      "name": "Rock_Ice"
    },
    {
      "x": -44,
      "y": 62,
      "z": 36,
      "name": "Soil_Snow"
    },
    {
      "x": -44,
      "y": 56,
      "z": 37,
      "name": "Rock_Ice"
    },
    {
      "x": -44,
      "y": 57,
      "z": 37,
      "name": "Rock_Ice"
    },
    {
      "x": -44,
      "y": 58,
      "z": 37,
      "name": "Rock_Ice"
    },
    {
      "x": -44,
      "y": 59,
      "z": 37,
      "name": "Rock_Ice"
    },
    {
      "x": -44,
      "y": 60,
      "z": 37,
      "name": "Rock_Ice"
    },
    {
      "x": -44,
      "y": 61,
      "z": 37,
      "name": "Soil_Snow"
    },
    {
      "x": -44,
      "y": 57,
      "z": 38,
      "name": "Rock_Ice"
    },
    {
      "x": -44,
      "y": 58,
      "z": 38,
      "name": "Rock_Ice"
    },
    {
      "x": -44,
      "y": 59,
      "z": 38,
      "name": "Rock_Ice"
    },
    {
      "x": -43,
      "y": 54,
      "z": 23,
      "name": "Rock_Ice"
    },
    {
      "x": -43,
      "y": 55,
      "z": 23,
      "name": "Rock_Ice"
    },
    {
      "x": -43,
      "y": 56,
      "z": 23,
      "name": "Rock_Ice"
    },
    {
      "x": -43,
      "y": 57,
      "z": 23,
      "name": "Rock_Ice"
    },
    {
      "x": -43,
      "y": 58,
      "z": 23,
      "name": "Rock_Ice"
    },
    {
      "x": -43,
      "y": 59,
      "z": 23,
      "name": "Rock_Ice"
    },
    {
      "x": -43,
      "y": 61,
      "z": 23,
      "name": "Rock_Ice"
    },
    {
      "x": -43,
      "y": 62,
      "z": 23,
      "name": "Rock_Ice"
    },
    {
      "x": -43,
      "y": 63,
      "z": 23,
      "name": "Soil_Snow"
    },
    {
      "x": -43,
      "y": 54,
      "z": 24,
      "name": "Rock_Ice"
    },
    {
      "x": -43,
      "y": 55,
      "z": 24,
      "name": "Rock_Ice"
    },
    {
      "x": -43,
      "y": 56,
      "z": 24,
      "name": "Rock_Ice"
    },
    {
      "x": -43,
      "y": 57,
      "z": 24,
      "name": "Rock_Ice"
    },
    {
      "x": -43,
      "y": 58,
      "z": 24,
      "name": "Rock_Ice"
    },
    {
      "x": -43,
      "y": 59,
      "z": 24,
      "name": "Rock_Ice"
    },
    {
      "x": -43,
      "y": 60,
      "z": 24,
      "name": "Rock_Ice"
    },
    {
      "x": -43,
      "y": 61,
      "z": 24,
      "name": "Rock_Ice"
    },
    {
      "x": -43,
      "y": 62,
      "z": 24,
      "name": "Rock_Ice"
    },
    {
      "x": -43,
      "y": 63,
      "z": 24,
      "name": "Soil_Snow"
    },
    {
      "x": -43,
      "y": 54,
      "z": 25,
      "name": "Rock_Ice"
    },
    {
      "x": -43,
      "y": 55,
      "z": 25,
      "name": "Rock_Ice"
    },
    {
      "x": -43,
      "y": 56,
      "z": 25,
      "name": "Rock_Ice"
    },
    {
      "x": -43,
      "y": 57,
      "z": 25,
      "name": "Rock_Ice"
    },
    {
      "x": -43,
      "y": 58,
      "z": 25,
      "name": "Rock_Ice"
    },
    {
      "x": -43,
      "y": 59,
      "z": 25,
      "name": "Rock_Ice"
    },
    {
      "x": -43,
      "y": 60,
      "z": 25,
      "name": "Rock_Ice"
    },
    {
      "x": -43,
      "y": 61,
      "z": 25,
      "name": "Rock_Ice"
    },
    {
      "x": -43,
      "y": 62,
      "z": 25,
      "name": "Rock_Ice"
    },
    {
      "x": -43,
      "y": 63,
      "z": 25,
      "name": "Rock_Ice"
    },
    {
      "x": -43,
      "y": 64,
      "z": 25,
      "name": "Soil_Snow"
    },
    {
      "x": -43,
      "y": 54,
      "z": 26,
      "name": "Rock_Ice"
    },
    {
      "x": -43,
      "y": 55,
      "z": 26,
      "name": "Rock_Ice"
    },
    {
      "x": -43,
      "y": 56,
      "z": 26,
      "name": "Rock_Ice"
    },
    {
      "x": -43,
      "y": 57,
      "z": 26,
      "name": "Rock_Ice"
    },
    {
      "x": -43,
      "y": 58,
      "z": 26,
      "name": "Rock_Ice"
    },
    {
      "x": -43,
      "y": 59,
      "z": 26,
      "name": "Rock_Ice"
    },
    {
      "x": -43,
      "y": 60,
      "z": 26,
      "name": "Rock_Ice"
    },
    {
      "x": -43,
      "y": 61,
      "z": 26,
      "name": "Rock_Ice"
    },
    {
      "x": -43,
      "y": 62,
      "z": 26,
      "name": "Rock_Ice_Permafrost"
    },
    {
      "x": -43,
      "y": 63,
      "z": 26,
      "name": "Rock_Ice_Permafrost"
    },
    {
      "x": -43,
      "y": 64,
      "z": 26,
      "name": "Rock_Ice"
    },
    {
      "x": -43,
      "y": 65,
      "z": 26,
      "name": "Soil_Snow"
    },
    {
      "x": -43,
      "y": 54,
      "z": 27,
      "name": "Rock_Ice"
    },
    {
      "x": -43,
      "y": 55,
      "z": 27,
      "name": "Rock_Ice"
    },
    {
      "x": -43,
      "y": 56,
      "z": 27,
      "name": "Rock_Ice"
    },
    {
      "x": -43,
      "y": 57,
      "z": 27,
      "name": "Rock_Ice"
    },
    {
      "x": -43,
      "y": 58,
      "z": 27,
      "name": "Rock_Ice"
    },
    {
      "x": -43,
      "y": 59,
      "z": 27,
      "name": "Rock_Ice"
    },
    {
      "x": -43,
      "y": 60,
      "z": 27,
      "name": "Rock_Ice_Permafrost"
    },
    {
      "x": -43,
      "y": 61,
      "z": 27,
      "name": "Rock_Ice_Permafrost"
    },
    {
      "x": -43,
      "y": 62,
      "z": 27,
      "name": "Rock_Ice_Permafrost"
    },
    {
      "x": -43,
      "y": 63,
      "z": 27,
      "name": "Rock_Ice_Permafrost"
    },
    {
      "x": -43,
      "y": 64,
      "z": 27,
      "name": "Rock_Ice"
    },
    {
      "x": -43,
      "y": 65,
      "z": 27,
      "name": "Soil_Snow"
    },
    {
      "x": -43,
      "y": 54,
      "z": 28,
      "name": "Rock_Ice_Permafrost"
    },
    {
      "x": -43,
      "y": 55,
      "z": 28,
      "name": "Rock_Ice_Permafrost"
    },
    {
      "x": -43,
      "y": 56,
      "z": 28,
      "name": "Rock_Ice_Permafrost"
    },
    {
      "x": -43,
      "y": 57,
      "z": 28,
      "name": "Rock_Ice_Permafrost"
    },
    {
      "x": -43,
      "y": 58,
      "z": 28,
      "name": "Rock_Ice_Permafrost"
    },
    {
      "x": -43,
      "y": 59,
      "z": 28,
      "name": "Rock_Ice_Permafrost"
    },
    {
      "x": -43,
      "y": 60,
      "z": 28,
      "name": "Rock_Ice_Permafrost"
    },
    {
      "x": -43,
      "y": 61,
      "z": 28,
      "name": "Rock_Ice_Permafrost"
    },
    {
      "x": -43,
      "y": 62,
      "z": 28,
      "name": "Rock_Ice_Permafrost"
    },
    {
      "x": -43,
      "y": 63,
      "z": 28,
      "name": "Rock_Ice"
    },
    {
      "x": -43,
      "y": 64,
      "z": 28,
      "name": "Rock_Ice"
    },
    {
      "x": -43,
      "y": 65,
      "z": 28,
      "name": "Rock_Ice"
    },
    {
      "x": -43,
      "y": 66,
      "z": 28,
      "name": "Soil_Snow"
    },
    {
      "x": -43,
      "y": 54,
      "z": 29,
      "name": "Rock_Ice_Permafrost"
    },
    {
      "x": -43,
      "y": 55,
      "z": 29,
      "name": "Rock_Ice_Permafrost"
    },
    {
      "x": -43,
      "y": 56,
      "z": 29,
      "name": "Rock_Ice_Permafrost"
    },
    {
      "x": -43,
      "y": 57,
      "z": 29,
      "name": "Rock_Ice_Permafrost"
    },
    {
      "x": -43,
      "y": 58,
      "z": 29,
      "name": "Rock_Ice_Permafrost"
    },
    {
      "x": -43,
      "y": 59,
      "z": 29,
      "name": "Rock_Ice_Permafrost"
    },
    {
      "x": -43,
      "y": 60,
      "z": 29,
      "name": "Rock_Ice_Permafrost"
    },
    {
      "x": -43,
      "y": 61,
      "z": 29,
      "name": "Rock_Ice"
    },
    {
      "x": -43,
      "y": 62,
      "z": 29,
      "name": "Rock_Ice"
    },
    {
      "x": -43,
      "y": 63,
      "z": 29,
      "name": "Rock_Ice"
    },
    {
      "x": -43,
      "y": 64,
      "z": 29,
      "name": "Rock_Ice"
    },
    {
      "x": -43,
      "y": 65,
      "z": 29,
      "name": "Rock_Ice"
    },
    {
      "x": -43,
      "y": 66,
      "z": 29,
      "name": "Soil_Snow"
    },
    {
      "x": -43,
      "y": 54,
      "z": 30,
      "name": "Rock_Ice"
    },
    {
      "x": -43,
      "y": 55,
      "z": 30,
      "name": "Rock_Ice"
    },
    {
      "x": -43,
      "y": 56,
      "z": 30,
      "name": "Rock_Ice"
    },
    {
      "x": -43,
      "y": 57,
      "z": 30,
      "name": "Rock_Ice_Permafrost"
    },
    {
      "x": -43,
      "y": 58,
      "z": 30,
      "name": "Rock_Ice_Permafrost"
    },
    {
      "x": -43,
      "y": 59,
      "z": 30,
      "name": "Rock_Ice_Permafrost"
    },
    {
      "x": -43,
      "y": 60,
      "z": 30,
      "name": "Rock_Ice_Permafrost"
    },
    {
      "x": -43,
      "y": 61,
      "z": 30,
      "name": "Rock_Ice_Permafrost"
    },
    {
      "x": -43,
      "y": 62,
      "z": 30,
      "name": "Rock_Ice"
    },
    {
      "x": -43,
      "y": 63,
      "z": 30,
      "name": "Rock_Ice"
    },
    {
      "x": -43,
      "y": 64,
      "z": 30,
      "name": "Rock_Ice"
    },
    {
      "x": -43,
      "y": 65,
      "z": 30,
      "name": "Rock_Ice"
    },
    {
      "x": -43,
      "y": 66,
      "z": 30,
      "name": "Soil_Snow"
    },
    {
      "x": -43,
      "y": 54,
      "z": 31,
      "name": "Rock_Ice"
    },
    {
      "x": -43,
      "y": 55,
      "z": 31,
      "name": "Rock_Ice"
    },
    {
      "x": -43,
      "y": 56,
      "z": 31,
      "name": "Rock_Ice"
    },
    {
      "x": -43,
      "y": 57,
      "z": 31,
      "name": "Rock_Ice_Permafrost"
    },
    {
      "x": -43,
      "y": 58,
      "z": 31,
      "name": "Rock_Ice_Permafrost"
    },
    {
      "x": -43,
      "y": 59,
      "z": 31,
      "name": "Rock_Ice_Permafrost"
    },
    {
      "x": -43,
      "y": 60,
      "z": 31,
      "name": "Rock_Ice_Permafrost"
    },
    {
      "x": -43,
      "y": 61,
      "z": 31,
      "name": "Rock_Ice_Permafrost"
    },
    {
      "x": -43,
      "y": 62,
      "z": 31,
      "name": "Rock_Ice_Permafrost"
    },
    {
      "x": -43,
      "y": 63,
      "z": 31,
      "name": "Rock_Ice"
    },
    {
      "x": -43,
      "y": 64,
      "z": 31,
      "name": "Rock_Ice"
    },
    {
      "x": -43,
      "y": 65,
      "z": 31,
      "name": "Rock_Ice"
    },
    {
      "x": -43,
      "y": 66,
      "z": 31,
      "name": "Soil_Snow"
    },
    {
      "x": -43,
      "y": 54,
      "z": 32,
      "name": "Rock_Ice"
    },
    {
      "x": -43,
      "y": 55,
      "z": 32,
      "name": "Rock_Ice"
    },
    {
      "x": -43,
      "y": 56,
      "z": 32,
      "name": "Rock_Ice"
    },
    {
      "x": -43,
      "y": 57,
      "z": 32,
      "name": "Rock_Ice_Permafrost"
    },
    {
      "x": -43,
      "y": 58,
      "z": 32,
      "name": "Rock_Ice_Permafrost"
    },
    {
      "x": -43,
      "y": 59,
      "z": 32,
      "name": "Rock_Ice_Permafrost"
    },
    {
      "x": -43,
      "y": 60,
      "z": 32,
      "name": "Rock_Ice_Permafrost"
    },
    {
      "x": -43,
      "y": 61,
      "z": 32,
      "name": "Rock_Ice_Permafrost"
    },
    {
      "x": -43,
      "y": 62,
      "z": 32,
      "name": "Rock_Ice_Permafrost"
    },
    {
      "x": -43,
      "y": 63,
      "z": 32,
      "name": "Rock_Ice"
    },
    {
      "x": -43,
      "y": 64,
      "z": 32,
      "name": "Rock_Ice"
    },
    {
      "x": -43,
      "y": 65,
      "z": 32,
      "name": "Rock_Ice"
    },
    {
      "x": -43,
      "y": 66,
      "z": 32,
      "name": "Soil_Snow"
    },
    {
      "x": -43,
      "y": 54,
      "z": 33,
      "name": "Rock_Ice"
    },
    {
      "x": -43,
      "y": 55,
      "z": 33,
      "name": "Rock_Ice_Permafrost"
    },
    {
      "x": -43,
      "y": 56,
      "z": 33,
      "name": "Rock_Ice"
    },
    {
      "x": -43,
      "y": 57,
      "z": 33,
      "name": "Rock_Ice_Permafrost"
    },
    {
      "x": -43,
      "y": 58,
      "z": 33,
      "name": "Rock_Ice_Permafrost"
    },
    {
      "x": -43,
      "y": 59,
      "z": 33,
      "name": "Rock_Ice_Permafrost"
    },
    {
      "x": -43,
      "y": 60,
      "z": 33,
      "name": "Rock_Ice_Permafrost"
    },
    {
      "x": -43,
      "y": 61,
      "z": 33,
      "name": "Rock_Ice_Permafrost"
    },
    {
      "x": -43,
      "y": 62,
      "z": 33,
      "name": "Rock_Ice_Permafrost"
    },
    {
      "x": -43,
      "y": 63,
      "z": 33,
      "name": "Rock_Ice"
    },
    {
      "x": -43,
      "y": 64,
      "z": 33,
      "name": "Rock_Ice"
    },
    {
      "x": -43,
      "y": 65,
      "z": 33,
      "name": "Rock_Ice"
    },
    {
      "x": -43,
      "y": 66,
      "z": 33,
      "name": "Soil_Snow"
    },
    {
      "x": -43,
      "y": 54,
      "z": 34,
      "name": "Rock_Ice_Permafrost"
    },
    {
      "x": -43,
      "y": 55,
      "z": 34,
      "name": "Rock_Ice_Permafrost"
    },
    {
      "x": -43,
      "y": 56,
      "z": 34,
      "name": "Rock_Ice_Permafrost"
    },
    {
      "x": -43,
      "y": 57,
      "z": 34,
      "name": "Rock_Ice_Permafrost"
    },
    {
      "x": -43,
      "y": 58,
      "z": 34,
      "name": "Rock_Ice_Permafrost"
    },
    {
      "x": -43,
      "y": 59,
      "z": 34,
      "name": "Rock_Ice_Permafrost"
    },
    {
      "x": -43,
      "y": 60,
      "z": 34,
      "name": "Rock_Ice_Permafrost"
    },
    {
      "x": -43,
      "y": 61,
      "z": 34,
      "name": "Rock_Ice_Permafrost"
    },
    {
      "x": -43,
      "y": 62,
      "z": 34,
      "name": "Rock_Ice_Permafrost"
    },
    {
      "x": -43,
      "y": 63,
      "z": 34,
      "name": "Rock_Ice_Permafrost"
    },
    {
      "x": -43,
      "y": 64,
      "z": 34,
      "name": "Rock_Ice_Permafrost"
    },
    {
      "x": -43,
      "y": 65,
      "z": 34,
      "name": "Rock_Ice"
    },
    {
      "x": -43,
      "y": 66,
      "z": 34,
      "name": "Soil_Snow"
    },
    {
      "x": -43,
      "y": 54,
      "z": 35,
      "name": "Rock_Ice_Permafrost"
    },
    {
      "x": -43,
      "y": 55,
      "z": 35,
      "name": "Rock_Ice_Permafrost"
    },
    {
      "x": -43,
      "y": 56,
      "z": 35,
      "name": "Rock_Ice"
    },
    {
      "x": -43,
      "y": 57,
      "z": 35,
      "name": "Rock_Ice_Permafrost"
    },
    {
      "x": -43,
      "y": 58,
      "z": 35,
      "name": "Rock_Ice"
    },
    {
      "x": -43,
      "y": 59,
      "z": 35,
      "name": "Rock_Ice"
    },
    {
      "x": -43,
      "y": 60,
      "z": 35,
      "name": "Rock_Ice"
    },
    {
      "x": -43,
      "y": 61,
      "z": 35,
      "name": "Rock_Ice_Permafrost"
    },
    {
      "x": -43,
      "y": 62,
      "z": 35,
      "name": "Rock_Ice_Permafrost"
    },
    {
      "x": -43,
      "y": 63,
      "z": 35,
      "name": "Rock_Ice_Permafrost"
    },
    {
      "x": -43,
      "y": 64,
      "z": 35,
      "name": "Rock_Ice"
    },
    {
      "x": -43,
      "y": 65,
      "z": 35,
      "name": "Soil_Snow"
    },
    {
      "x": -43,
      "y": 55,
      "z": 36,
      "name": "Rock_Ice"
    },
    {
      "x": -43,
      "y": 56,
      "z": 36,
      "name": "Rock_Ice"
    },
    {
      "x": -43,
      "y": 57,
      "z": 36,
      "name": "Rock_Ice"
    },
    {
      "x": -43,
      "y": 58,
      "z": 36,
      "name": "Rock_Ice"
    },
    {
      "x": -43,
      "y": 59,
      "z": 36,
      "name": "Rock_Ice"
    },
    {
      "x": -43,
      "y": 60,
      "z": 36,
      "name": "Rock_Ice"
    },
    {
      "x": -43,
      "y": 61,
      "z": 36,
      "name": "Rock_Ice"
    },
    {
      "x": -43,
      "y": 62,
      "z": 36,
      "name": "Rock_Ice"
    },
    {
      "x": -43,
      "y": 63,
      "z": 36,
      "name": "Rock_Ice"
    },
    {
      "x": -43,
      "y": 64,
      "z": 36,
      "name": "Soil_Snow"
    },
    {
      "x": -43,
      "y": 55,
      "z": 37,
      "name": "Rock_Ice"
    },
    {
      "x": -43,
      "y": 56,
      "z": 37,
      "name": "Rock_Ice"
    },
    {
      "x": -43,
      "y": 57,
      "z": 37,
      "name": "Rock_Ice"
    },
    {
      "x": -43,
      "y": 58,
      "z": 37,
      "name": "Rock_Ice"
    },
    {
      "x": -43,
      "y": 59,
      "z": 37,
      "name": "Rock_Ice"
    },
    {
      "x": -43,
      "y": 60,
      "z": 37,
      "name": "Rock_Ice"
    },
    {
      "x": -43,
      "y": 61,
      "z": 37,
      "name": "Rock_Ice"
    },
    {
      "x": -43,
      "y": 62,
      "z": 37,
      "name": "Rock_Ice"
    },
    {
      "x": -43,
      "y": 63,
      "z": 37,
      "name": "Rock_Ice"
    },
    {
      "x": -43,
      "y": 64,
      "z": 37,
      "name": "Soil_Snow"
    },
    {
      "x": -43,
      "y": 55,
      "z": 38,
      "name": "Rock_Ice"
    },
    {
      "x": -43,
      "y": 56,
      "z": 38,
      "name": "Rock_Ice"
    },
    {
      "x": -43,
      "y": 57,
      "z": 38,
      "name": "Rock_Ice"
    },
    {
      "x": -43,
      "y": 58,
      "z": 38,
      "name": "Rock_Ice"
    },
    {
      "x": -43,
      "y": 59,
      "z": 38,
      "name": "Rock_Ice"
    },
    {
      "x": -43,
      "y": 60,
      "z": 38,
      "name": "Rock_Ice"
    },
    {
      "x": -43,
      "y": 61,
      "z": 38,
      "name": "Rock_Ice"
    },
    {
      "x": -43,
      "y": 62,
      "z": 38,
      "name": "Soil_Snow"
    },
    {
      "x": -43,
      "y": 56,
      "z": 39,
      "name": "Rock_Ice"
    },
    {
      "x": -43,
      "y": 57,
      "z": 39,
      "name": "Rock_Ice"
    },
    {
      "x": -43,
      "y": 58,
      "z": 39,
      "name": "Rock_Ice"
    },
    {
      "x": -43,
      "y": 59,
      "z": 39,
      "name": "Rock_Ice"
    },
    {
      "x": -43,
      "y": 60,
      "z": 39,
      "name": "Rock_Ice"
    },
    {
      "x": -43,
      "y": 61,
      "z": 39,
      "name": "Soil_Snow"
    },
    {
      "x": -43,
      "y": 56,
      "z": 40,
      "name": "Rock_Ice"
    },
    {
      "x": -43,
      "y": 57,
      "z": 40,
      "name": "Rock_Ice"
    },
    {
      "x": -43,
      "y": 58,
      "z": 40,
      "name": "Rock_Ice"
    },
    {
      "x": -43,
      "y": 59,
      "z": 40,
      "name": "Soil_Snow"
    },
    {
      "x": -42,
      "y": 56,
      "z": 20,
      "name": "Rock_Ice_Permafrost"
    },
    {
      "x": -42,
      "y": 57,
      "z": 20,
      "name": "Rock_Ice"
    },
    {
      "x": -42,
      "y": 58,
      "z": 20,
      "name": "Soil_Snow"
    },
    {
      "x": -42,
      "y": 55,
      "z": 21,
      "name": "Rock_Ice"
    },
    {
      "x": -42,
      "y": 56,
      "z": 21,
      "name": "Rock_Ice"
    },
    {
      "x": -42,
      "y": 57,
      "z": 21,
      "name": "Rock_Ice"
    },
    {
      "x": -42,
      "y": 58,
      "z": 21,
      "name": "Rock_Ice"
    },
    {
      "x": -42,
      "y": 59,
      "z": 21,
      "name": "Rock_Ice"
    },
    {
      "x": -42,
      "y": 60,
      "z": 21,
      "name": "Rock_Ice"
    },
    {
      "x": -42,
      "y": 61,
      "z": 21,
      "name": "Rock_Ice"
    },
    {
      "x": -42,
      "y": 62,
      "z": 21,
      "name": "Rock_Ice"
    },
    {
      "x": -42,
      "y": 63,
      "z": 21,
      "name": "Soil_Snow"
    },
    {
      "x": -42,
      "y": 54,
      "z": 22,
      "name": "Rock_Ice"
    },
    {
      "x": -42,
      "y": 55,
      "z": 22,
      "name": "Rock_Ice"
    },
    {
      "x": -42,
      "y": 56,
      "z": 22,
      "name": "Rock_Ice"
    },
    {
      "x": -42,
      "y": 57,
      "z": 22,
      "name": "Rock_Ice"
    },
    {
      "x": -42,
      "y": 58,
      "z": 22,
      "name": "Rock_Ice"
    },
    {
      "x": -42,
      "y": 59,
      "z": 22,
      "name": "Rock_Ice"
    },
    {
      "x": -42,
      "y": 60,
      "z": 22,
      "name": "Rock_Ice"
    },
    {
      "x": -42,
      "y": 61,
      "z": 22,
      "name": "Rock_Ice"
    },
    {
      "x": -42,
      "y": 62,
      "z": 22,
      "name": "Rock_Ice"
    },
    {
      "x": -42,
      "y": 63,
      "z": 22,
      "name": "Rock_Ice"
    },
    {
      "x": -42,
      "y": 64,
      "z": 22,
      "name": "Soil_Snow"
    },
    {
      "x": -42,
      "y": 54,
      "z": 23,
      "name": "Rock_Ice"
    },
    {
      "x": -42,
      "y": 55,
      "z": 23,
      "name": "Rock_Ice"
    },
    {
      "x": -42,
      "y": 56,
      "z": 23,
      "name": "Rock_Ice"
    },
    {
      "x": -42,
      "y": 57,
      "z": 23,
      "name": "Rock_Ice"
    },
    {
      "x": -42,
      "y": 58,
      "z": 23,
      "name": "Rock_Ice"
    },
    {
      "x": -42,
      "y": 59,
      "z": 23,
      "name": "Rock_Ice"
    },
    {
      "x": -42,
      "y": 60,
      "z": 23,
      "name": "Rock_Ice"
    },
    {
      "x": -42,
      "y": 61,
      "z": 23,
      "name": "Rock_Ice"
    },
    {
      "x": -42,
      "y": 62,
      "z": 23,
      "name": "Rock_Ice"
    },
    {
      "x": -42,
      "y": 63,
      "z": 23,
      "name": "Rock_Ice"
    },
    {
      "x": -42,
      "y": 64,
      "z": 23,
      "name": "Soil_Snow"
    },
    {
      "x": -42,
      "y": 54,
      "z": 24,
      "name": "Rock_Ice"
    },
    {
      "x": -42,
      "y": 55,
      "z": 24,
      "name": "Rock_Ice"
    },
    {
      "x": -42,
      "y": 56,
      "z": 24,
      "name": "Rock_Ice"
    },
    {
      "x": -42,
      "y": 57,
      "z": 24,
      "name": "Rock_Ice"
    },
    {
      "x": -42,
      "y": 58,
      "z": 24,
      "name": "Rock_Ice"
    },
    {
      "x": -42,
      "y": 59,
      "z": 24,
      "name": "Rock_Ice"
    },
    {
      "x": -42,
      "y": 60,
      "z": 24,
      "name": "Rock_Ice"
    },
    {
      "x": -42,
      "y": 61,
      "z": 24,
      "name": "Rock_Ice"
    },
    {
      "x": -42,
      "y": 62,
      "z": 24,
      "name": "Rock_Ice"
    },
    {
      "x": -42,
      "y": 63,
      "z": 24,
      "name": "Rock_Ice"
    },
    {
      "x": -42,
      "y": 64,
      "z": 24,
      "name": "Rock_Ice"
    },
    {
      "x": -42,
      "y": 65,
      "z": 24,
      "name": "Soil_Snow"
    },
    {
      "x": -42,
      "y": 54,
      "z": 25,
      "name": "Rock_Ice"
    },
    {
      "x": -42,
      "y": 55,
      "z": 25,
      "name": "Rock_Ice"
    },
    {
      "x": -42,
      "y": 56,
      "z": 25,
      "name": "Rock_Ice"
    },
    {
      "x": -42,
      "y": 57,
      "z": 25,
      "name": "Rock_Ice"
    },
    {
      "x": -42,
      "y": 58,
      "z": 25,
      "name": "Rock_Ice"
    },
    {
      "x": -42,
      "y": 59,
      "z": 25,
      "name": "Rock_Ice"
    },
    {
      "x": -42,
      "y": 60,
      "z": 25,
      "name": "Rock_Ice"
    },
    {
      "x": -42,
      "y": 61,
      "z": 25,
      "name": "Rock_Ice"
    },
    {
      "x": -42,
      "y": 62,
      "z": 25,
      "name": "Rock_Ice"
    },
    {
      "x": -42,
      "y": 63,
      "z": 25,
      "name": "Rock_Ice"
    },
    {
      "x": -42,
      "y": 64,
      "z": 25,
      "name": "Rock_Ice_Permafrost"
    },
    {
      "x": -42,
      "y": 65,
      "z": 25,
      "name": "Rock_Ice"
    },
    {
      "x": -42,
      "y": 66,
      "z": 25,
      "name": "Soil_Snow"
    },
    {
      "x": -42,
      "y": 53,
      "z": 26,
      "name": "Rock_Ice"
    },
    {
      "x": -42,
      "y": 54,
      "z": 26,
      "name": "Rock_Ice"
    },
    {
      "x": -42,
      "y": 55,
      "z": 26,
      "name": "Rock_Ice"
    },
    {
      "x": -42,
      "y": 56,
      "z": 26,
      "name": "Rock_Ice"
    },
    {
      "x": -42,
      "y": 57,
      "z": 26,
      "name": "Rock_Ice"
    },
    {
      "x": -42,
      "y": 58,
      "z": 26,
      "name": "Rock_Ice"
    },
    {
      "x": -42,
      "y": 59,
      "z": 26,
      "name": "Rock_Ice"
    },
    {
      "x": -42,
      "y": 60,
      "z": 26,
      "name": "Rock_Ice"
    },
    {
      "x": -42,
      "y": 61,
      "z": 26,
      "name": "Rock_Ice"
    },
    {
      "x": -42,
      "y": 62,
      "z": 26,
      "name": "Rock_Ice"
    },
    {
      "x": -42,
      "y": 63,
      "z": 26,
      "name": "Rock_Ice_Permafrost"
    },
    {
      "x": -42,
      "y": 64,
      "z": 26,
      "name": "Rock_Ice_Permafrost"
    },
    {
      "x": -42,
      "y": 65,
      "z": 26,
      "name": "Rock_Ice_Permafrost"
    },
    {
      "x": -42,
      "y": 66,
      "z": 26,
      "name": "Rock_Ice"
    },
    {
      "x": -42,
      "y": 67,
      "z": 26,
      "name": "Soil_Snow"
    },
    {
      "x": -42,
      "y": 53,
      "z": 27,
      "name": "Rock_Ice_Permafrost"
    },
    {
      "x": -42,
      "y": 54,
      "z": 27,
      "name": "Rock_Ice_Permafrost"
    },
    {
      "x": -42,
      "y": 55,
      "z": 27,
      "name": "Rock_Ice"
    },
    {
      "x": -42,
      "y": 56,
      "z": 27,
      "name": "Rock_Ice"
    },
    {
      "x": -42,
      "y": 57,
      "z": 27,
      "name": "Rock_Ice"
    },
    {
      "x": -42,
      "y": 58,
      "z": 27,
      "name": "Rock_Ice"
    },
    {
      "x": -42,
      "y": 59,
      "z": 27,
      "name": "Rock_Ice"
    },
    {
      "x": -42,
      "y": 60,
      "z": 27,
      "name": "Rock_Ice_Permafrost"
    },
    {
      "x": -42,
      "y": 61,
      "z": 27,
      "name": "Rock_Ice_Permafrost"
    },
    {
      "x": -42,
      "y": 62,
      "z": 27,
      "name": "Rock_Ice_Permafrost"
    },
    {
      "x": -42,
      "y": 63,
      "z": 27,
      "name": "Rock_Ice_Permafrost"
    },
    {
      "x": -42,
      "y": 64,
      "z": 27,
      "name": "Rock_Ice"
    },
    {
      "x": -42,
      "y": 65,
      "z": 27,
      "name": "Rock_Ice"
    },
    {
      "x": -42,
      "y": 66,
      "z": 27,
      "name": "Rock_Ice"
    },
    {
      "x": -42,
      "y": 67,
      "z": 27,
      "name": "Soil_Snow"
    },
    {
      "x": -42,
      "y": 53,
      "z": 28,
      "name": "Rock_Ice_Permafrost"
    },
    {
      "x": -42,
      "y": 54,
      "z": 28,
      "name": "Rock_Ice_Permafrost"
    },
    {
      "x": -42,
      "y": 55,
      "z": 28,
      "name": "Rock_Ice_Permafrost"
    },
    {
      "x": -42,
      "y": 56,
      "z": 28,
      "name": "Rock_Ice_Permafrost"
    },
    {
      "x": -42,
      "y": 57,
      "z": 28,
      "name": "Rock_Ice_Permafrost"
    },
    {
      "x": -42,
      "y": 58,
      "z": 28,
      "name": "Rock_Ice_Permafrost"
    },
    {
      "x": -42,
      "y": 59,
      "z": 28,
      "name": "Rock_Ice_Permafrost"
    },
    {
      "x": -42,
      "y": 60,
      "z": 28,
      "name": "Rock_Ice_Permafrost"
    },
    {
      "x": -42,
      "y": 61,
      "z": 28,
      "name": "Rock_Ice_Permafrost"
    },
    {
      "x": -42,
      "y": 62,
      "z": 28,
      "name": "Rock_Ice_Permafrost"
    },
    {
      "x": -42,
      "y": 63,
      "z": 28,
      "name": "Rock_Ice_Permafrost"
    },
    {
      "x": -42,
      "y": 64,
      "z": 28,
      "name": "Rock_Ice"
    },
    {
      "x": -42,
      "y": 65,
      "z": 28,
      "name": "Rock_Ice"
    },
    {
      "x": -42,
      "y": 66,
      "z": 28,
      "name": "Rock_Ice"
    },
    {
      "x": -42,
      "y": 67,
      "z": 28,
      "name": "Rock_Ice"
    },
    {
      "x": -42,
      "y": 68,
      "z": 28,
      "name": "Soil_Snow"
    },
    {
      "x": -42,
      "y": 53,
      "z": 29,
      "name": "Rock_Ice"
    },
    {
      "x": -42,
      "y": 54,
      "z": 29,
      "name": "Rock_Ice"
    },
    {
      "x": -42,
      "y": 55,
      "z": 29,
      "name": "Rock_Ice_Permafrost"
    },
    {
      "x": -42,
      "y": 56,
      "z": 29,
      "name": "Rock_Ice_Permafrost"
    },
    {
      "x": -42,
      "y": 57,
      "z": 29,
      "name": "Rock_Ice_Permafrost"
    },
    {
      "x": -42,
      "y": 58,
      "z": 29,
      "name": "Rock_Ice_Permafrost"
    },
    {
      "x": -42,
      "y": 59,
      "z": 29,
      "name": "Rock_Ice_Permafrost"
    },
    {
      "x": -42,
      "y": 60,
      "z": 29,
      "name": "Rock_Ice_Permafrost"
    },
    {
      "x": -42,
      "y": 61,
      "z": 29,
      "name": "Rock_Ice_Permafrost"
    },
    {
      "x": -42,
      "y": 62,
      "z": 29,
      "name": "Rock_Ice_Permafrost"
    },
    {
      "x": -42,
      "y": 63,
      "z": 29,
      "name": "Rock_Ice"
    },
    {
      "x": -42,
      "y": 64,
      "z": 29,
      "name": "Rock_Ice"
    },
    {
      "x": -42,
      "y": 65,
      "z": 29,
      "name": "Rock_Ice"
    },
    {
      "x": -42,
      "y": 66,
      "z": 29,
      "name": "Rock_Ice"
    },
    {
      "x": -42,
      "y": 67,
      "z": 29,
      "name": "Rock_Ice"
    },
    {
      "x": -42,
      "y": 68,
      "z": 29,
      "name": "Soil_Snow"
    },
    {
      "x": -42,
      "y": 53,
      "z": 30,
      "name": "Rock_Ice"
    },
    {
      "x": -42,
      "y": 54,
      "z": 30,
      "name": "Rock_Ice"
    },
    {
      "x": -42,
      "y": 55,
      "z": 30,
      "name": "Rock_Ice"
    },
    {
      "x": -42,
      "y": 56,
      "z": 30,
      "name": "Rock_Ice_Permafrost"
    },
    {
      "x": -42,
      "y": 57,
      "z": 30,
      "name": "Rock_Ice_Permafrost"
    },
    {
      "x": -42,
      "y": 58,
      "z": 30,
      "name": "Rock_Ice_Permafrost"
    },
    {
      "x": -42,
      "y": 59,
      "z": 30,
      "name": "Rock_Ice_Permafrost"
    },
    {
      "x": -42,
      "y": 60,
      "z": 30,
      "name": "Rock_Ice_Permafrost"
    },
    {
      "x": -42,
      "y": 61,
      "z": 30,
      "name": "Rock_Ice_Permafrost"
    },
    {
      "x": -42,
      "y": 62,
      "z": 30,
      "name": "Rock_Ice_Permafrost"
    },
    {
      "x": -42,
      "y": 63,
      "z": 30,
      "name": "Rock_Ice"
    },
    {
      "x": -42,
      "y": 64,
      "z": 30,
      "name": "Rock_Ice"
    },
    {
      "x": -42,
      "y": 65,
      "z": 30,
      "name": "Rock_Ice"
    },
    {
      "x": -42,
      "y": 66,
      "z": 30,
      "name": "Rock_Ice"
    },
    {
      "x": -42,
      "y": 67,
      "z": 30,
      "name": "Rock_Ice"
    },
    {
      "x": -42,
      "y": 68,
      "z": 30,
      "name": "Soil_Snow"
    },
    {
      "x": -42,
      "y": 53,
      "z": 31,
      "name": "Rock_Ice"
    },
    {
      "x": -42,
      "y": 54,
      "z": 31,
      "name": "Rock_Ice"
    },
    {
      "x": -42,
      "y": 55,
      "z": 31,
      "name": "Rock_Ice"
    },
    {
      "x": -42,
      "y": 56,
      "z": 31,
      "name": "Rock_Ice"
    },
    {
      "x": -42,
      "y": 57,
      "z": 31,
      "name": "Rock_Ice"
    },
    {
      "x": -42,
      "y": 58,
      "z": 31,
      "name": "Rock_Ice_Permafrost"
    },
    {
      "x": -42,
      "y": 59,
      "z": 31,
      "name": "Rock_Ice_Permafrost"
    },
    {
      "x": -42,
      "y": 60,
      "z": 31,
      "name": "Rock_Ice_Permafrost"
    },
    {
      "x": -42,
      "y": 61,
      "z": 31,
      "name": "Rock_Ice_Permafrost"
    },
    {
      "x": -42,
      "y": 62,
      "z": 31,
      "name": "Rock_Ice"
    },
    {
      "x": -42,
      "y": 63,
      "z": 31,
      "name": "Rock_Ice"
    },
    {
      "x": -42,
      "y": 64,
      "z": 31,
      "name": "Rock_Ice"
    },
    {
      "x": -42,
      "y": 65,
      "z": 31,
      "name": "Rock_Ice"
    },
    {
      "x": -42,
      "y": 66,
      "z": 31,
      "name": "Rock_Ice"
    },
    {
      "x": -42,
      "y": 67,
      "z": 31,
      "name": "Rock_Ice"
    },
    {
      "x": -42,
      "y": 68,
      "z": 31,
      "name": "Soil_Snow"
    },
    {
      "x": -42,
      "y": 53,
      "z": 32,
      "name": "Rock_Ice"
    },
    {
      "x": -42,
      "y": 54,
      "z": 32,
      "name": "Rock_Ice"
    },
    {
      "x": -42,
      "y": 55,
      "z": 32,
      "name": "Rock_Ice"
    },
    {
      "x": -42,
      "y": 56,
      "z": 32,
      "name": "Rock_Ice"
    },
    {
      "x": -42,
      "y": 57,
      "z": 32,
      "name": "Rock_Ice"
    },
    {
      "x": -42,
      "y": 58,
      "z": 32,
      "name": "Rock_Ice_Permafrost"
    },
    {
      "x": -42,
      "y": 59,
      "z": 32,
      "name": "Rock_Ice_Permafrost"
    },
    {
      "x": -42,
      "y": 60,
      "z": 32,
      "name": "Rock_Ice_Permafrost"
    },
    {
      "x": -42,
      "y": 61,
      "z": 32,
      "name": "Rock_Ice_Permafrost"
    },
    {
      "x": -42,
      "y": 62,
      "z": 32,
      "name": "Rock_Ice_Permafrost"
    },
    {
      "x": -42,
      "y": 63,
      "z": 32,
      "name": "Rock_Ice_Permafrost"
    },
    {
      "x": -42,
      "y": 64,
      "z": 32,
      "name": "Rock_Ice"
    },
    {
      "x": -42,
      "y": 65,
      "z": 32,
      "name": "Rock_Ice"
    },
    {
      "x": -42,
      "y": 66,
      "z": 32,
      "name": "Rock_Ice"
    },
    {
      "x": -42,
      "y": 67,
      "z": 32,
      "name": "Rock_Ice"
    },
    {
      "x": -42,
      "y": 68,
      "z": 32,
      "name": "Soil_Snow"
    },
    {
      "x": -42,
      "y": 53,
      "z": 33,
      "name": "Rock_Ice"
    },
    {
      "x": -42,
      "y": 54,
      "z": 33,
      "name": "Rock_Ice"
    },
    {
      "x": -42,
      "y": 55,
      "z": 33,
      "name": "Rock_Ice"
    },
    {
      "x": -42,
      "y": 56,
      "z": 33,
      "name": "Rock_Ice"
    },
    {
      "x": -42,
      "y": 57,
      "z": 33,
      "name": "Rock_Ice_Permafrost"
    },
    {
      "x": -42,
      "y": 58,
      "z": 33,
      "name": "Rock_Ice_Permafrost"
    },
    {
      "x": -42,
      "y": 59,
      "z": 33,
      "name": "Rock_Ice_Permafrost"
    },
    {
      "x": -42,
      "y": 60,
      "z": 33,
      "name": "Rock_Ice_Permafrost"
    },
    {
      "x": -42,
      "y": 61,
      "z": 33,
      "name": "Rock_Ice_Permafrost"
    },
    {
      "x": -42,
      "y": 62,
      "z": 33,
      "name": "Rock_Ice_Permafrost"
    },
    {
      "x": -42,
      "y": 63,
      "z": 33,
      "name": "Rock_Ice_Permafrost"
    },
    {
      "x": -42,
      "y": 64,
      "z": 33,
      "name": "Rock_Ice"
    },
    {
      "x": -42,
      "y": 65,
      "z": 33,
      "name": "Rock_Ice"
    },
    {
      "x": -42,
      "y": 66,
      "z": 33,
      "name": "Rock_Ice"
    },
    {
      "x": -42,
      "y": 67,
      "z": 33,
      "name": "Rock_Ice"
    },
    {
      "x": -42,
      "y": 68,
      "z": 33,
      "name": "Soil_Snow"
    },
    {
      "x": -42,
      "y": 53,
      "z": 34,
      "name": "Rock_Ice_Permafrost"
    },
    {
      "x": -42,
      "y": 54,
      "z": 34,
      "name": "Rock_Ice_Permafrost"
    },
    {
      "x": -42,
      "y": 55,
      "z": 34,
      "name": "Rock_Ice_Permafrost"
    },
    {
      "x": -42,
      "y": 56,
      "z": 34,
      "name": "Rock_Ice_Permafrost"
    },
    {
      "x": -42,
      "y": 57,
      "z": 34,
      "name": "Rock_Ice_Permafrost"
    },
    {
      "x": -42,
      "y": 58,
      "z": 34,
      "name": "Rock_Ice_Permafrost"
    },
    {
      "x": -42,
      "y": 59,
      "z": 34,
      "name": "Rock_Ice_Permafrost"
    },
    {
      "x": -42,
      "y": 60,
      "z": 34,
      "name": "Rock_Ice_Permafrost"
    },
    {
      "x": -42,
      "y": 61,
      "z": 34,
      "name": "Rock_Ice_Permafrost"
    },
    {
      "x": -42,
      "y": 62,
      "z": 34,
      "name": "Rock_Ice_Permafrost"
    },
    {
      "x": -42,
      "y": 63,
      "z": 34,
      "name": "Rock_Ice_Permafrost"
    },
    {
      "x": -42,
      "y": 64,
      "z": 34,
      "name": "Rock_Ice_Permafrost"
    },
    {
      "x": -42,
      "y": 65,
      "z": 34,
      "name": "Rock_Ice_Permafrost"
    },
    {
      "x": -42,
      "y": 66,
      "z": 34,
      "name": "Rock_Ice"
    },
    {
      "x": -42,
      "y": 67,
      "z": 34,
      "name": "Soil_Snow"
    },
    {
      "x": -42,
      "y": 54,
      "z": 35,
      "name": "Rock_Ice_Permafrost"
    },
    {
      "x": -42,
      "y": 55,
      "z": 35,
      "name": "Rock_Ice_Permafrost"
    },
    {
      "x": -42,
      "y": 56,
      "z": 35,
      "name": "Rock_Ice"
    },
    {
      "x": -42,
      "y": 57,
      "z": 35,
      "name": "Rock_Ice"
    },
    {
      "x": -42,
      "y": 58,
      "z": 35,
      "name": "Rock_Ice_Permafrost"
    },
    {
      "x": -42,
      "y": 59,
      "z": 35,
      "name": "Rock_Ice"
    },
    {
      "x": -42,
      "y": 60,
      "z": 35,
      "name": "Rock_Ice"
    },
    {
      "x": -42,
      "y": 61,
      "z": 35,
      "name": "Rock_Ice_Permafrost"
    },
    {
      "x": -42,
      "y": 62,
      "z": 35,
      "name": "Rock_Ice_Permafrost"
    },
    {
      "x": -42,
      "y": 63,
      "z": 35,
      "name": "Rock_Ice_Permafrost"
    },
    {
      "x": -42,
      "y": 64,
      "z": 35,
      "name": "Rock_Ice_Permafrost"
    },
    {
      "x": -42,
      "y": 65,
      "z": 35,
      "name": "Rock_Ice_Permafrost"
    },
    {
      "x": -42,
      "y": 66,
      "z": 35,
      "name": "Rock_Ice"
    },
    {
      "x": -42,
      "y": 67,
      "z": 35,
      "name": "Soil_Snow"
    },
    {
      "x": -42,
      "y": 54,
      "z": 36,
      "name": "Rock_Ice"
    },
    {
      "x": -42,
      "y": 55,
      "z": 36,
      "name": "Rock_Ice"
    },
    {
      "x": -42,
      "y": 56,
      "z": 36,
      "name": "Rock_Ice"
    },
    {
      "x": -42,
      "y": 57,
      "z": 36,
      "name": "Rock_Ice"
    },
    {
      "x": -42,
      "y": 58,
      "z": 36,
      "name": "Rock_Ice"
    },
    {
      "x": -42,
      "y": 59,
      "z": 36,
      "name": "Rock_Ice"
    },
    {
      "x": -42,
      "y": 60,
      "z": 36,
      "name": "Rock_Ice"
    },
    {
      "x": -42,
      "y": 61,
      "z": 36,
      "name": "Rock_Ice"
    },
    {
      "x": -42,
      "y": 62,
      "z": 36,
      "name": "Rock_Ice_Permafrost"
    },
    {
      "x": -42,
      "y": 63,
      "z": 36,
      "name": "Rock_Ice"
    },
    {
      "x": -42,
      "y": 64,
      "z": 36,
      "name": "Rock_Ice"
    },
    {
      "x": -42,
      "y": 65,
      "z": 36,
      "name": "Rock_Ice"
    },
    {
      "x": -42,
      "y": 66,
      "z": 36,
      "name": "Soil_Snow"
    },
    {
      "x": -42,
      "y": 54,
      "z": 37,
      "name": "Rock_Ice"
    },
    {
      "x": -42,
      "y": 55,
      "z": 37,
      "name": "Rock_Ice"
    },
    {
      "x": -42,
      "y": 56,
      "z": 37,
      "name": "Rock_Ice"
    },
    {
      "x": -42,
      "y": 57,
      "z": 37,
      "name": "Rock_Ice"
    },
    {
      "x": -42,
      "y": 58,
      "z": 37,
      "name": "Rock_Ice"
    },
    {
      "x": -42,
      "y": 59,
      "z": 37,
      "name": "Rock_Ice"
    },
    {
      "x": -42,
      "y": 60,
      "z": 37,
      "name": "Rock_Ice"
    },
    {
      "x": -42,
      "y": 61,
      "z": 37,
      "name": "Rock_Ice"
    },
    {
      "x": -42,
      "y": 62,
      "z": 37,
      "name": "Rock_Ice"
    },
    {
      "x": -42,
      "y": 63,
      "z": 37,
      "name": "Rock_Ice_Permafrost"
    },
    {
      "x": -42,
      "y": 64,
      "z": 37,
      "name": "Rock_Ice"
    },
    {
      "x": -42,
      "y": 65,
      "z": 37,
      "name": "Soil_Snow"
    },
    {
      "x": -42,
      "y": 54,
      "z": 38,
      "name": "Rock_Ice"
    },
    {
      "x": -42,
      "y": 55,
      "z": 38,
      "name": "Rock_Ice"
    },
    {
      "x": -42,
      "y": 56,
      "z": 38,
      "name": "Rock_Ice"
    },
    {
      "x": -42,
      "y": 57,
      "z": 38,
      "name": "Rock_Ice"
    },
    {
      "x": -42,
      "y": 58,
      "z": 38,
      "name": "Rock_Ice"
    },
    {
      "x": -42,
      "y": 59,
      "z": 38,
      "name": "Rock_Ice"
    },
    {
      "x": -42,
      "y": 60,
      "z": 38,
      "name": "Rock_Ice"
    },
    {
      "x": -42,
      "y": 61,
      "z": 38,
      "name": "Rock_Ice"
    },
    {
      "x": -42,
      "y": 62,
      "z": 38,
      "name": "Rock_Ice"
    },
    {
      "x": -42,
      "y": 63,
      "z": 38,
      "name": "Rock_Ice"
    },
    {
      "x": -42,
      "y": 64,
      "z": 38,
      "name": "Soil_Snow"
    },
    {
      "x": -42,
      "y": 55,
      "z": 39,
      "name": "Rock_Ice"
    },
    {
      "x": -42,
      "y": 56,
      "z": 39,
      "name": "Rock_Ice"
    },
    {
      "x": -42,
      "y": 57,
      "z": 39,
      "name": "Rock_Ice"
    },
    {
      "x": -42,
      "y": 58,
      "z": 39,
      "name": "Rock_Ice"
    },
    {
      "x": -42,
      "y": 59,
      "z": 39,
      "name": "Rock_Ice"
    },
    {
      "x": -42,
      "y": 60,
      "z": 39,
      "name": "Rock_Ice"
    },
    {
      "x": -42,
      "y": 61,
      "z": 39,
      "name": "Rock_Ice"
    },
    {
      "x": -42,
      "y": 62,
      "z": 39,
      "name": "Rock_Ice"
    },
    {
      "x": -42,
      "y": 63,
      "z": 39,
      "name": "Soil_Snow"
    },
    {
      "x": -42,
      "y": 55,
      "z": 40,
      "name": "Rock_Ice"
    },
    {
      "x": -42,
      "y": 56,
      "z": 40,
      "name": "Rock_Ice"
    },
    {
      "x": -42,
      "y": 57,
      "z": 40,
      "name": "Rock_Ice"
    },
    {
      "x": -42,
      "y": 58,
      "z": 40,
      "name": "Rock_Ice"
    },
    {
      "x": -42,
      "y": 59,
      "z": 40,
      "name": "Rock_Ice"
    },
    {
      "x": -42,
      "y": 60,
      "z": 40,
      "name": "Rock_Ice"
    },
    {
      "x": -42,
      "y": 61,
      "z": 40,
      "name": "Rock_Ice"
    },
    {
      "x": -42,
      "y": 62,
      "z": 40,
      "name": "Soil_Snow"
    },
    {
      "x": -42,
      "y": 56,
      "z": 41,
      "name": "Rock_Ice"
    },
    {
      "x": -42,
      "y": 57,
      "z": 41,
      "name": "Rock_Ice"
    },
    {
      "x": -42,
      "y": 58,
      "z": 41,
      "name": "Rock_Ice"
    },
    {
      "x": -42,
      "y": 59,
      "z": 41,
      "name": "Rock_Ice"
    },
    {
      "x": -42,
      "y": 60,
      "z": 41,
      "name": "Soil_Snow"
    },
    {
      "x": -41,
      "y": 52,
      "z": 19,
      "name": "Rock_Ice_Permafrost"
    },
    {
      "x": -41,
      "y": 53,
      "z": 19,
      "name": "Rock_Ice_Permafrost"
    },
    {
      "x": -41,
      "y": 54,
      "z": 19,
      "name": "Rock_Ice_Permafrost"
    },
    {
      "x": -41,
      "y": 55,
      "z": 19,
      "name": "Rock_Ice_Permafrost"
    },
    {
      "x": -41,
      "y": 56,
      "z": 19,
      "name": "Rock_Ice_Permafrost"
    },
    {
      "x": -41,
      "y": 57,
      "z": 19,
      "name": "Rock_Ice"
    },
    {
      "x": -41,
      "y": 58,
      "z": 19,
      "name": "Rock_Ice_Permafrost"
    },
    {
      "x": -41,
      "y": 53,
      "z": 20,
      "name": "Rock_Ice_Permafrost"
    },
    {
      "x": -41,
      "y": 54,
      "z": 20,
      "name": "Rock_Ice_Permafrost"
    },
    {
      "x": -41,
      "y": 55,
      "z": 20,
      "name": "Rock_Ice_Permafrost"
    },
    {
      "x": -41,
      "y": 56,
      "z": 20,
      "name": "Rock_Ice_Permafrost"
    },
    {
      "x": -41,
      "y": 57,
      "z": 20,
      "name": "Rock_Ice_Permafrost"
    },
    {
      "x": -41,
      "y": 58,
      "z": 20,
      "name": "Rock_Ice"
    },
    {
      "x": -41,
      "y": 59,
      "z": 20,
      "name": "Rock_Ice_Permafrost"
    },
    {
      "x": -41,
      "y": 60,
      "z": 20,
      "name": "Rock_Ice_Permafrost"
    },
    {
      "x": -41,
      "y": 61,
      "z": 20,
      "name": "Rock_Ice_Permafrost"
    },
    {
      "x": -41,
      "y": 62,
      "z": 20,
      "name": "Rock_Ice_Permafrost"
    },
    {
      "x": -41,
      "y": 63,
      "z": 20,
      "name": "Rock_Ice"
    },
    {
      "x": -41,
      "y": 64,
      "z": 20,
      "name": "Soil_Snow"
    },
    {
      "x": -41,
      "y": 54,
      "z": 21,
      "name": "Rock_Ice"
    },
    {
      "x": -41,
      "y": 55,
      "z": 21,
      "name": "Rock_Ice_Permafrost"
    },
    {
      "x": -41,
      "y": 56,
      "z": 21,
      "name": "Rock_Ice"
    },
    {
      "x": -41,
      "y": 57,
      "z": 21,
      "name": "Rock_Ice"
    },
    {
      "x": -41,
      "y": 58,
      "z": 21,
      "name": "Rock_Ice"
    },
    {
      "x": -41,
      "y": 59,
      "z": 21,
      "name": "Rock_Ice"
    },
    {
      "x": -41,
      "y": 60,
      "z": 21,
      "name": "Rock_Ice"
    },
    {
      "x": -41,
      "y": 61,
      "z": 21,
      "name": "Rock_Ice"
    },
    {
      "x": -41,
      "y": 62,
      "z": 21,
      "name": "Rock_Ice"
    },
    {
      "x": -41,
      "y": 63,
      "z": 21,
      "name": "Rock_Ice"
    },
    {
      "x": -41,
      "y": 64,
      "z": 21,
      "name": "Rock_Ice"
    },
    {
      "x": -41,
      "y": 65,
      "z": 21,
      "name": "Soil_Snow"
    },
    {
      "x": -41,
      "y": 54,
      "z": 22,
      "name": "Rock_Ice"
    },
    {
      "x": -41,
      "y": 55,
      "z": 22,
      "name": "Rock_Ice"
    },
    {
      "x": -41,
      "y": 56,
      "z": 22,
      "name": "Rock_Ice"
    },
    {
      "x": -41,
      "y": 57,
      "z": 22,
      "name": "Rock_Ice"
    },
    {
      "x": -41,
      "y": 58,
      "z": 22,
      "name": "Rock_Ice"
    },
    {
      "x": -41,
      "y": 59,
      "z": 22,
      "name": "Rock_Ice"
    },
    {
      "x": -41,
      "y": 60,
      "z": 22,
      "name": "Rock_Ice"
    },
    {
      "x": -41,
      "y": 61,
      "z": 22,
      "name": "Rock_Ice"
    },
    {
      "x": -41,
      "y": 62,
      "z": 22,
      "name": "Rock_Ice"
    },
    {
      "x": -41,
      "y": 63,
      "z": 22,
      "name": "Rock_Ice"
    },
    {
      "x": -41,
      "y": 64,
      "z": 22,
      "name": "Rock_Ice"
    },
    {
      "x": -41,
      "y": 65,
      "z": 22,
      "name": "Soil_Snow"
    },
    {
      "x": -41,
      "y": 54,
      "z": 23,
      "name": "Rock_Ice"
    },
    {
      "x": -41,
      "y": 55,
      "z": 23,
      "name": "Rock_Ice"
    },
    {
      "x": -41,
      "y": 56,
      "z": 23,
      "name": "Rock_Ice"
    },
    {
      "x": -41,
      "y": 57,
      "z": 23,
      "name": "Rock_Ice"
    },
    {
      "x": -41,
      "y": 58,
      "z": 23,
      "name": "Rock_Ice"
    },
    {
      "x": -41,
      "y": 59,
      "z": 23,
      "name": "Rock_Ice"
    },
    {
      "x": -41,
      "y": 60,
      "z": 23,
      "name": "Rock_Ice"
    },
    {
      "x": -41,
      "y": 61,
      "z": 23,
      "name": "Rock_Ice"
    },
    {
      "x": -41,
      "y": 62,
      "z": 23,
      "name": "Rock_Ice"
    },
    {
      "x": -41,
      "y": 63,
      "z": 23,
      "name": "Rock_Ice"
    },
    {
      "x": -41,
      "y": 64,
      "z": 23,
      "name": "Rock_Ice"
    },
    {
      "x": -41,
      "y": 65,
      "z": 23,
      "name": "Rock_Ice"
    },
    {
      "x": -41,
      "y": 66,
      "z": 23,
      "name": "Soil_Snow"
    },
    {
      "x": -41,
      "y": 53,
      "z": 24,
      "name": "Rock_Ice"
    },
    {
      "x": -41,
      "y": 54,
      "z": 24,
      "name": "Rock_Ice"
    },
    {
      "x": -41,
      "y": 55,
      "z": 24,
      "name": "Rock_Ice"
    },
    {
      "x": -41,
      "y": 56,
      "z": 24,
      "name": "Rock_Ice"
    },
    {
      "x": -41,
      "y": 57,
      "z": 24,
      "name": "Rock_Ice"
    },
    {
      "x": -41,
      "y": 58,
      "z": 24,
      "name": "Rock_Ice"
    },
    {
      "x": -41,
      "y": 59,
      "z": 24,
      "name": "Rock_Ice"
    },
    {
      "x": -41,
      "y": 60,
      "z": 24,
      "name": "Rock_Ice"
    },
    {
      "x": -41,
      "y": 61,
      "z": 24,
      "name": "Rock_Ice"
    },
    {
      "x": -41,
      "y": 62,
      "z": 24,
      "name": "Rock_Ice"
    },
    {
      "x": -41,
      "y": 63,
      "z": 24,
      "name": "Rock_Ice"
    },
    {
      "x": -41,
      "y": 64,
      "z": 24,
      "name": "Rock_Ice"
    },
    {
      "x": -41,
      "y": 65,
      "z": 24,
      "name": "Rock_Ice_Permafrost"
    },
    {
      "x": -41,
      "y": 66,
      "z": 24,
      "name": "Rock_Ice"
    },
    {
      "x": -41,
      "y": 67,
      "z": 24,
      "name": "Soil_Snow"
    },
    {
      "x": -41,
      "y": 53,
      "z": 25,
      "name": "Rock_Ice"
    },
    {
      "x": -41,
      "y": 54,
      "z": 25,
      "name": "Rock_Ice"
    },
    {
      "x": -41,
      "y": 55,
      "z": 25,
      "name": "Rock_Ice"
    },
    {
      "x": -41,
      "y": 56,
      "z": 25,
      "name": "Rock_Ice"
    },
    {
      "x": -41,
      "y": 57,
      "z": 25,
      "name": "Rock_Ice"
    },
    {
      "x": -41,
      "y": 58,
      "z": 25,
      "name": "Rock_Ice"
    },
    {
      "x": -41,
      "y": 59,
      "z": 25,
      "name": "Rock_Ice"
    },
    {
      "x": -41,
      "y": 60,
      "z": 25,
      "name": "Rock_Ice"
    },
    {
      "x": -41,
      "y": 61,
      "z": 25,
      "name": "Rock_Ice"
    },
    {
      "x": -41,
      "y": 62,
      "z": 25,
      "name": "Rock_Ice"
    },
    {
      "x": -41,
      "y": 63,
      "z": 25,
      "name": "Rock_Ice_Permafrost"
    },
    {
      "x": -41,
      "y": 64,
      "z": 25,
      "name": "Rock_Ice_Permafrost"
    },
    {
      "x": -41,
      "y": 65,
      "z": 25,
      "name": "Rock_Ice_Permafrost"
    },
    {
      "x": -41,
      "y": 66,
      "z": 25,
      "name": "Rock_Ice_Permafrost"
    },
    {
      "x": -41,
      "y": 67,
      "z": 25,
      "name": "Rock_Ice"
    },
    {
      "x": -41,
      "y": 68,
      "z": 25,
      "name": "Soil_Snow"
    },
    {
      "x": -41,
      "y": 53,
      "z": 26,
      "name": "Rock_Ice"
    },
    {
      "x": -41,
      "y": 54,
      "z": 26,
      "name": "Rock_Ice"
    },
    {
      "x": -41,
      "y": 55,
      "z": 26,
      "name": "Rock_Ice"
    },
    {
      "x": -41,
      "y": 56,
      "z": 26,
      "name": "Rock_Ice"
    },
    {
      "x": -41,
      "y": 57,
      "z": 26,
      "name": "Rock_Ice"
    },
    {
      "x": -41,
      "y": 58,
      "z": 26,
      "name": "Rock_Ice"
    },
    {
      "x": -41,
      "y": 59,
      "z": 26,
      "name": "Rock_Ice"
    },
    {
      "x": -41,
      "y": 60,
      "z": 26,
      "name": "Rock_Ice"
    },
    {
      "x": -41,
      "y": 61,
      "z": 26,
      "name": "Rock_Ice"
    },
    {
      "x": -41,
      "y": 62,
      "z": 26,
      "name": "Rock_Ice_Permafrost"
    },
    {
      "x": -41,
      "y": 63,
      "z": 26,
      "name": "Rock_Ice_Permafrost"
    },
    {
      "x": -41,
      "y": 64,
      "z": 26,
      "name": "Rock_Ice_Permafrost"
    },
    {
      "x": -41,
      "y": 65,
      "z": 26,
      "name": "Rock_Ice"
    },
    {
      "x": -41,
      "y": 66,
      "z": 26,
      "name": "Rock_Ice"
    },
    {
      "x": -41,
      "y": 67,
      "z": 26,
      "name": "Rock_Ice"
    },
    {
      "x": -41,
      "y": 68,
      "z": 26,
      "name": "Rock_Ice"
    },
    {
      "x": -41,
      "y": 69,
      "z": 26,
      "name": "Soil_Snow"
    },
    {
      "x": -41,
      "y": 53,
      "z": 27,
      "name": "Rock_Ice_Permafrost"
    },
    {
      "x": -41,
      "y": 54,
      "z": 27,
      "name": "Rock_Ice_Permafrost"
    },
    {
      "x": -41,
      "y": 55,
      "z": 27,
      "name": "Rock_Ice"
    },
    {
      "x": -41,
      "y": 56,
      "z": 27,
      "name": "Rock_Ice_Permafrost"
    },
    {
      "x": -41,
      "y": 57,
      "z": 27,
      "name": "Rock_Ice_Permafrost"
    },
    {
      "x": -41,
      "y": 58,
      "z": 27,
      "name": "Rock_Ice_Permafrost"
    },
    {
      "x": -41,
      "y": 59,
      "z": 27,
      "name": "Rock_Ice_Permafrost"
    },
    {
      "x": -41,
      "y": 60,
      "z": 27,
      "name": "Rock_Ice_Permafrost"
    },
    {
      "x": -41,
      "y": 61,
      "z": 27,
      "name": "Rock_Ice_Permafrost"
    },
    {
      "x": -41,
      "y": 62,
      "z": 27,
      "name": "Rock_Ice_Permafrost"
    },
    {
      "x": -41,
      "y": 63,
      "z": 27,
      "name": "Rock_Ice_Permafrost"
    },
    {
      "x": -41,
      "y": 64,
      "z": 27,
      "name": "Rock_Ice"
    },
    {
      "x": -41,
      "y": 65,
      "z": 27,
      "name": "Rock_Ice"
    },
    {
      "x": -41,
      "y": 66,
      "z": 27,
      "name": "Rock_Ice"
    },
    {
      "x": -41,
      "y": 67,
      "z": 27,
      "name": "Rock_Ice"
    },
    {
      "x": -41,
      "y": 68,
      "z": 27,
      "name": "Rock_Ice"
    },
    {
      "x": -41,
      "y": 69,
      "z": 27,
      "name": "Soil_Snow"
    },
    {
      "x": -41,
      "y": 53,
      "z": 28,
      "name": "Rock_Ice_Permafrost"
    },
    {
      "x": -41,
      "y": 54,
      "z": 28,
      "name": "Rock_Ice_Permafrost"
    },
    {
      "x": -41,
      "y": 55,
      "z": 28,
      "name": "Rock_Ice_Permafrost"
    },
    {
      "x": -41,
      "y": 56,
      "z": 28,
      "name": "Rock_Ice_Permafrost"
    },
    {
      "x": -41,
      "y": 57,
      "z": 28,
      "name": "Rock_Ice_Permafrost"
    },
    {
      "x": -41,
      "y": 58,
      "z": 28,
      "name": "Rock_Ice_Permafrost"
    },
    {
      "x": -41,
      "y": 59,
      "z": 28,
      "name": "Rock_Ice_Permafrost"
    },
    {
      "x": -41,
      "y": 60,
      "z": 28,
      "name": "Rock_Ice_Permafrost"
    },
    {
      "x": -41,
      "y": 61,
      "z": 28,
      "name": "Rock_Ice_Permafrost"
    },
    {
      "x": -41,
      "y": 62,
      "z": 28,
      "name": "Rock_Ice_Permafrost"
    },
    {
      "x": -41,
      "y": 63,
      "z": 28,
      "name": "Rock_Ice_Permafrost"
    },
    {
      "x": -41,
      "y": 64,
      "z": 28,
      "name": "Rock_Ice"
    },
    {
      "x": -41,
      "y": 65,
      "z": 28,
      "name": "Rock_Ice"
    },
    {
      "x": -41,
      "y": 66,
      "z": 28,
      "name": "Rock_Ice"
    },
    {
      "x": -41,
      "y": 67,
      "z": 28,
      "name": "Rock_Ice"
    },
    {
      "x": -41,
      "y": 68,
      "z": 28,
      "name": "Rock_Ice"
    },
    {
      "x": -41,
      "y": 69,
      "z": 28,
      "name": "Rock_Ice"
    },
    {
      "x": -41,
      "y": 70,
      "z": 28,
      "name": "Soil_Snow"
    },
    {
      "x": -41,
      "y": 53,
      "z": 29,
      "name": "Rock_Ice"
    },
    {
      "x": -41,
      "y": 54,
      "z": 29,
      "name": "Rock_Ice"
    },
    {
      "x": -41,
      "y": 55,
      "z": 29,
      "name": "Rock_Ice"
    },
    {
      "x": -41,
      "y": 56,
      "z": 29,
      "name": "Rock_Ice"
    },
    {
      "x": -41,
      "y": 57,
      "z": 29,
      "name": "Rock_Ice_Permafrost"
    },
    {
      "x": -41,
      "y": 58,
      "z": 29,
      "name": "Rock_Ice_Permafrost"
    },
    {
      "x": -41,
      "y": 59,
      "z": 29,
      "name": "Rock_Ice_Permafrost"
    },
    {
      "x": -41,
      "y": 60,
      "z": 29,
      "name": "Rock_Ice_Permafrost"
    },
    {
      "x": -41,
      "y": 61,
      "z": 29,
      "name": "Rock_Ice_Permafrost"
    },
    {
      "x": -41,
      "y": 62,
      "z": 29,
      "name": "Rock_Ice"
    },
    {
      "x": -41,
      "y": 63,
      "z": 29,
      "name": "Rock_Ice"
    },
    {
      "x": -41,
      "y": 64,
      "z": 29,
      "name": "Rock_Ice"
    },
    {
      "x": -41,
      "y": 65,
      "z": 29,
      "name": "Rock_Ice"
    },
    {
      "x": -41,
      "y": 66,
      "z": 29,
      "name": "Rock_Ice"
    },
    {
      "x": -41,
      "y": 67,
      "z": 29,
      "name": "Rock_Ice"
    },
    {
      "x": -41,
      "y": 68,
      "z": 29,
      "name": "Rock_Ice"
    },
    {
      "x": -41,
      "y": 69,
      "z": 29,
      "name": "Rock_Ice"
    },
    {
      "x": -41,
      "y": 70,
      "z": 29,
      "name": "Soil_Snow"
    },
    {
      "x": -41,
      "y": 53,
      "z": 30,
      "name": "Rock_Ice"
    },
    {
      "x": -41,
      "y": 54,
      "z": 30,
      "name": "Rock_Ice"
    },
    {
      "x": -41,
      "y": 55,
      "z": 30,
      "name": "Rock_Ice"
    },
    {
      "x": -41,
      "y": 56,
      "z": 30,
      "name": "Rock_Ice"
    },
    {
      "x": -41,
      "y": 57,
      "z": 30,
      "name": "Rock_Ice"
    },
    {
      "x": -41,
      "y": 58,
      "z": 30,
      "name": "Rock_Ice_Permafrost"
    },
    {
      "x": -41,
      "y": 59,
      "z": 30,
      "name": "Rock_Ice_Permafrost"
    },
    {
      "x": -41,
      "y": 60,
      "z": 30,
      "name": "Rock_Ice_Permafrost"
    },
    {
      "x": -41,
      "y": 61,
      "z": 30,
      "name": "Rock_Ice_Permafrost"
    },
    {
      "x": -41,
      "y": 62,
      "z": 30,
      "name": "Rock_Ice_Permafrost"
    },
    {
      "x": -41,
      "y": 63,
      "z": 30,
      "name": "Rock_Ice"
    },
    {
      "x": -41,
      "y": 64,
      "z": 30,
      "name": "Rock_Ice"
    },
    {
      "x": -41,
      "y": 65,
      "z": 30,
      "name": "Rock_Ice"
    },
    {
      "x": -41,
      "y": 66,
      "z": 30,
      "name": "Rock_Ice"
    },
    {
      "x": -41,
      "y": 67,
      "z": 30,
      "name": "Rock_Ice"
    },
    {
      "x": -41,
      "y": 68,
      "z": 30,
      "name": "Rock_Ice"
    },
    {
      "x": -41,
      "y": 69,
      "z": 30,
      "name": "Rock_Ice"
    },
    {
      "x": -41,
      "y": 70,
      "z": 30,
      "name": "Soil_Snow"
    },
    {
      "x": -41,
      "y": 52,
      "z": 31,
      "name": "Rock_Ice"
    },
    {
      "x": -41,
      "y": 53,
      "z": 31,
      "name": "Rock_Ice"
    },
    {
      "x": -41,
      "y": 54,
      "z": 31,
      "name": "Rock_Ice"
    },
    {
      "x": -41,
      "y": 55,
      "z": 31,
      "name": "Rock_Ice"
    },
    {
      "x": -41,
      "y": 56,
      "z": 31,
      "name": "Rock_Ice"
    },
    {
      "x": -41,
      "y": 57,
      "z": 31,
      "name": "Rock_Ice_Permafrost"
    },
    {
      "x": -41,
      "y": 58,
      "z": 31,
      "name": "Rock_Ice_Permafrost"
    },
    {
      "x": -41,
      "y": 59,
      "z": 31,
      "name": "Rock_Ice_Permafrost"
    },
    {
      "x": -41,
      "y": 60,
      "z": 31,
      "name": "Rock_Ice_Permafrost"
    },
    {
      "x": -41,
      "y": 61,
      "z": 31,
      "name": "Rock_Ice_Permafrost"
    },
    {
      "x": -41,
      "y": 62,
      "z": 31,
      "name": "Rock_Ice_Permafrost"
    },
    {
      "x": -41,
      "y": 63,
      "z": 31,
      "name": "Rock_Ice_Permafrost"
    },
    {
      "x": -41,
      "y": 64,
      "z": 31,
      "name": "Rock_Ice"
    },
    {
      "x": -41,
      "y": 65,
      "z": 31,
      "name": "Rock_Ice"
    },
    {
      "x": -41,
      "y": 66,
      "z": 31,
      "name": "Rock_Ice"
    },
    {
      "x": -41,
      "y": 67,
      "z": 31,
      "name": "Rock_Ice"
    },
    {
      "x": -41,
      "y": 68,
      "z": 31,
      "name": "Rock_Ice"
    },
    {
      "x": -41,
      "y": 69,
      "z": 31,
      "name": "Rock_Ice"
    },
    {
      "x": -41,
      "y": 70,
      "z": 31,
      "name": "Soil_Snow"
    },
    {
      "x": -41,
      "y": 53,
      "z": 32,
      "name": "Rock_Ice"
    },
    {
      "x": -41,
      "y": 54,
      "z": 32,
      "name": "Rock_Ice"
    },
    {
      "x": -41,
      "y": 55,
      "z": 32,
      "name": "Rock_Ice"
    },
    {
      "x": -41,
      "y": 56,
      "z": 32,
      "name": "Rock_Ice"
    },
    {
      "x": -41,
      "y": 57,
      "z": 32,
      "name": "Rock_Ice"
    },
    {
      "x": -41,
      "y": 58,
      "z": 32,
      "name": "Rock_Ice_Permafrost"
    },
    {
      "x": -41,
      "y": 59,
      "z": 32,
      "name": "Rock_Ice_Permafrost"
    },
    {
      "x": -41,
      "y": 60,
      "z": 32,
      "name": "Rock_Ice_Permafrost"
    },
    {
      "x": -41,
      "y": 61,
      "z": 32,
      "name": "Rock_Ice_Permafrost"
    },
    {
      "x": -41,
      "y": 62,
      "z": 32,
      "name": "Rock_Ice_Permafrost"
    },
    {
      "x": -41,
      "y": 63,
      "z": 32,
      "name": "Rock_Ice_Permafrost"
    },
    {
      "x": -41,
      "y": 64,
      "z": 32,
      "name": "Rock_Ice"
    },
    {
      "x": -41,
      "y": 65,
      "z": 32,
      "name": "Rock_Ice"
    },
    {
      "x": -41,
      "y": 66,
      "z": 32,
      "name": "Rock_Ice"
    },
    {
      "x": -41,
      "y": 67,
      "z": 32,
      "name": "Rock_Ice"
    },
    {
      "x": -41,
      "y": 68,
      "z": 32,
      "name": "Rock_Ice"
    },
    {
      "x": -41,
      "y": 69,
      "z": 32,
      "name": "Rock_Ice"
    },
    {
      "x": -41,
      "y": 70,
      "z": 32,
      "name": "Soil_Snow"
    },
    {
      "x": -41,
      "y": 53,
      "z": 33,
      "name": "Rock_Ice"
    },
    {
      "x": -41,
      "y": 54,
      "z": 33,
      "name": "Rock_Ice"
    },
    {
      "x": -41,
      "y": 55,
      "z": 33,
      "name": "Rock_Ice"
    },
    {
      "x": -41,
      "y": 56,
      "z": 33,
      "name": "Rock_Ice"
    },
    {
      "x": -41,
      "y": 57,
      "z": 33,
      "name": "Rock_Ice"
    },
    {
      "x": -41,
      "y": 58,
      "z": 33,
      "name": "Rock_Ice_Permafrost"
    },
    {
      "x": -41,
      "y": 59,
      "z": 33,
      "name": "Rock_Ice_Permafrost"
    },
    {
      "x": -41,
      "y": 60,
      "z": 33,
      "name": "Rock_Ice_Permafrost"
    },
    {
      "x": -41,
      "y": 61,
      "z": 33,
      "name": "Rock_Ice_Permafrost"
    },
    {
      "x": -41,
      "y": 62,
      "z": 33,
      "name": "Rock_Ice_Permafrost"
    },
    {
      "x": -41,
      "y": 63,
      "z": 33,
      "name": "Rock_Ice_Permafrost"
    },
    {
      "x": -41,
      "y": 64,
      "z": 33,
      "name": "Rock_Ice"
    },
    {
      "x": -41,
      "y": 65,
      "z": 33,
      "name": "Rock_Ice"
    },
    {
      "x": -41,
      "y": 66,
      "z": 33,
      "name": "Rock_Ice"
    },
    {
      "x": -41,
      "y": 67,
      "z": 33,
      "name": "Rock_Ice"
    },
    {
      "x": -41,
      "y": 68,
      "z": 33,
      "name": "Rock_Ice"
    },
    {
      "x": -41,
      "y": 69,
      "z": 33,
      "name": "Soil_Snow"
    },
    {
      "x": -41,
      "y": 53,
      "z": 34,
      "name": "Rock_Ice_Permafrost"
    },
    {
      "x": -41,
      "y": 54,
      "z": 34,
      "name": "Rock_Ice_Permafrost"
    },
    {
      "x": -41,
      "y": 55,
      "z": 34,
      "name": "Rock_Ice_Permafrost"
    },
    {
      "x": -41,
      "y": 56,
      "z": 34,
      "name": "Rock_Ice_Permafrost"
    },
    {
      "x": -41,
      "y": 57,
      "z": 34,
      "name": "Rock_Ice_Permafrost"
    },
    {
      "x": -41,
      "y": 58,
      "z": 34,
      "name": "Rock_Ice_Permafrost"
    },
    {
      "x": -41,
      "y": 59,
      "z": 34,
      "name": "Rock_Ice_Permafrost"
    },
    {
      "x": -41,
      "y": 60,
      "z": 34,
      "name": "Rock_Ice_Permafrost"
    },
    {
      "x": -41,
      "y": 61,
      "z": 34,
      "name": "Rock_Ice_Permafrost"
    },
    {
      "x": -41,
      "y": 62,
      "z": 34,
      "name": "Rock_Ice_Permafrost"
    },
    {
      "x": -41,
      "y": 63,
      "z": 34,
      "name": "Rock_Ice_Permafrost"
    },
    {
      "x": -41,
      "y": 64,
      "z": 34,
      "name": "Rock_Ice_Permafrost"
    },
    {
      "x": -41,
      "y": 65,
      "z": 34,
      "name": "Rock_Ice_Permafrost"
    },
    {
      "x": -41,
      "y": 66,
      "z": 34,
      "name": "Rock_Ice_Permafrost"
    },
    {
      "x": -41,
      "y": 67,
      "z": 34,
      "name": "Rock_Ice_Permafrost"
    },
    {
      "x": -41,
      "y": 68,
      "z": 34,
      "name": "Rock_Ice"
    },
    {
      "x": -41,
      "y": 69,
      "z": 34,
      "name": "Soil_Snow"
    },
    {
      "x": -41,
      "y": 53,
      "z": 35,
      "name": "Rock_Ice"
    },
    {
      "x": -41,
      "y": 54,
      "z": 35,
      "name": "Rock_Ice_Permafrost"
    },
    {
      "x": -41,
      "y": 55,
      "z": 35,
      "name": "Rock_Ice_Permafrost"
    },
    {
      "x": -41,
      "y": 56,
      "z": 35,
      "name": "Rock_Ice_Permafrost"
    },
    {
      "x": -41,
      "y": 57,
      "z": 35,
      "name": "Rock_Ice_Permafrost"
    },
    {
      "x": -41,
      "y": 58,
      "z": 35,
      "name": "Rock_Ice_Permafrost"
    },
    {
      "x": -41,
      "y": 59,
      "z": 35,
      "name": "Rock_Ice_Permafrost"
    },
    {
      "x": -41,
      "y": 60,
      "z": 35,
      "name": "Rock_Ice_Permafrost"
    },
    {
      "x": -41,
      "y": 61,
      "z": 35,
      "name": "Rock_Ice_Permafrost"
    },
    {
      "x": -41,
      "y": 62,
      "z": 35,
      "name": "Rock_Ice_Permafrost"
    },
    {
      "x": -41,
      "y": 63,
      "z": 35,
      "name": "Rock_Ice_Permafrost"
    },
    {
      "x": -41,
      "y": 64,
      "z": 35,
      "name": "Rock_Ice_Permafrost"
    },
    {
      "x": -41,
      "y": 65,
      "z": 35,
      "name": "Rock_Ice_Permafrost"
    },
    {
      "x": -41,
      "y": 66,
      "z": 35,
      "name": "Rock_Ice_Permafrost"
    },
    {
      "x": -41,
      "y": 67,
      "z": 35,
      "name": "Rock_Ice"
    },
    {
      "x": -41,
      "y": 68,
      "z": 35,
      "name": "Soil_Snow"
    },
    {
      "x": -41,
      "y": 53,
      "z": 36,
      "name": "Rock_Ice"
    },
    {
      "x": -41,
      "y": 54,
      "z": 36,
      "name": "Rock_Ice"
    },
    {
      "x": -41,
      "y": 55,
      "z": 36,
      "name": "Rock_Ice"
    },
    {
      "x": -41,
      "y": 56,
      "z": 36,
      "name": "Rock_Ice"
    },
    {
      "x": -41,
      "y": 57,
      "z": 36,
      "name": "Rock_Ice"
    },
    {
      "x": -41,
      "y": 58,
      "z": 36,
      "name": "Rock_Ice"
    },
    {
      "x": -41,
      "y": 59,
      "z": 36,
      "name": "Rock_Ice"
    },
    {
      "x": -41,
      "y": 60,
      "z": 36,
      "name": "Rock_Ice"
    },
    {
      "x": -41,
      "y": 61,
      "z": 36,
      "name": "Rock_Ice"
    },
    {
      "x": -41,
      "y": 62,
      "z": 36,
      "name": "Rock_Ice"
    },
    {
      "x": -41,
      "y": 63,
      "z": 36,
      "name": "Rock_Ice"
    },
    {
      "x": -41,
      "y": 64,
      "z": 36,
      "name": "Rock_Ice_Permafrost"
    },
    {
      "x": -41,
      "y": 65,
      "z": 36,
      "name": "Rock_Ice_Permafrost"
    },
    {
      "x": -41,
      "y": 66,
      "z": 36,
      "name": "Rock_Ice_Permafrost"
    },
    {
      "x": -41,
      "y": 67,
      "z": 36,
      "name": "Rock_Ice"
    },
    {
      "x": -41,
      "y": 68,
      "z": 36,
      "name": "Soil_Snow"
    },
    {
      "x": -41,
      "y": 53,
      "z": 37,
      "name": "Rock_Ice"
    },
    {
      "x": -41,
      "y": 54,
      "z": 37,
      "name": "Rock_Ice"
    },
    {
      "x": -41,
      "y": 55,
      "z": 37,
      "name": "Rock_Ice"
    },
    {
      "x": -41,
      "y": 56,
      "z": 37,
      "name": "Rock_Ice"
    },
    {
      "x": -41,
      "y": 57,
      "z": 37,
      "name": "Rock_Ice"
    },
    {
      "x": -41,
      "y": 58,
      "z": 37,
      "name": "Rock_Ice"
    },
    {
      "x": -41,
      "y": 59,
      "z": 37,
      "name": "Rock_Ice"
    },
    {
      "x": -41,
      "y": 60,
      "z": 37,
      "name": "Rock_Ice"
    },
    {
      "x": -41,
      "y": 61,
      "z": 37,
      "name": "Rock_Ice"
    },
    {
      "x": -41,
      "y": 62,
      "z": 37,
      "name": "Rock_Ice"
    },
    {
      "x": -41,
      "y": 63,
      "z": 37,
      "name": "Rock_Ice"
    },
    {
      "x": -41,
      "y": 64,
      "z": 37,
      "name": "Rock_Ice"
    },
    {
      "x": -41,
      "y": 65,
      "z": 37,
      "name": "Rock_Ice_Permafrost"
    },
    {
      "x": -41,
      "y": 66,
      "z": 37,
      "name": "Rock_Ice"
    },
    {
      "x": -41,
      "y": 67,
      "z": 37,
      "name": "Soil_Snow"
    },
    {
      "x": -41,
      "y": 53,
      "z": 38,
      "name": "Rock_Ice"
    },
    {
      "x": -41,
      "y": 54,
      "z": 38,
      "name": "Rock_Ice"
    },
    {
      "x": -41,
      "y": 55,
      "z": 38,
      "name": "Rock_Ice"
    },
    {
      "x": -41,
      "y": 56,
      "z": 38,
      "name": "Rock_Ice"
    },
    {
      "x": -41,
      "y": 57,
      "z": 38,
      "name": "Rock_Ice"
    },
    {
      "x": -41,
      "y": 58,
      "z": 38,
      "name": "Rock_Ice"
    },
    {
      "x": -41,
      "y": 59,
      "z": 38,
      "name": "Rock_Ice"
    },
    {
      "x": -41,
      "y": 60,
      "z": 38,
      "name": "Rock_Ice"
    },
    {
      "x": -41,
      "y": 61,
      "z": 38,
      "name": "Rock_Ice"
    },
    {
      "x": -41,
      "y": 62,
      "z": 38,
      "name": "Rock_Ice"
    },
    {
      "x": -41,
      "y": 63,
      "z": 38,
      "name": "Rock_Ice"
    },
    {
      "x": -41,
      "y": 64,
      "z": 38,
      "name": "Rock_Ice"
    },
    {
      "x": -41,
      "y": 65,
      "z": 38,
      "name": "Rock_Ice"
    },
    {
      "x": -41,
      "y": 66,
      "z": 38,
      "name": "Soil_Snow"
    },
    {
      "x": -41,
      "y": 54,
      "z": 39,
      "name": "Rock_Ice"
    },
    {
      "x": -41,
      "y": 55,
      "z": 39,
      "name": "Rock_Ice"
    },
    {
      "x": -41,
      "y": 56,
      "z": 39,
      "name": "Rock_Ice"
    },
    {
      "x": -41,
      "y": 57,
      "z": 39,
      "name": "Rock_Ice"
    },
    {
      "x": -41,
      "y": 58,
      "z": 39,
      "name": "Rock_Ice"
    },
    {
      "x": -41,
      "y": 59,
      "z": 39,
      "name": "Rock_Ice"
    },
    {
      "x": -41,
      "y": 60,
      "z": 39,
      "name": "Rock_Ice"
    },
    {
      "x": -41,
      "y": 61,
      "z": 39,
      "name": "Rock_Ice"
    },
    {
      "x": -41,
      "y": 62,
      "z": 39,
      "name": "Rock_Ice"
    },
    {
      "x": -41,
      "y": 63,
      "z": 39,
      "name": "Rock_Ice"
    },
    {
      "x": -41,
      "y": 64,
      "z": 39,
      "name": "Rock_Ice"
    },
    {
      "x": -41,
      "y": 65,
      "z": 39,
      "name": "Soil_Snow"
    },
    {
      "x": -41,
      "y": 54,
      "z": 40,
      "name": "Rock_Ice"
    },
    {
      "x": -41,
      "y": 55,
      "z": 40,
      "name": "Rock_Ice"
    },
    {
      "x": -41,
      "y": 56,
      "z": 40,
      "name": "Rock_Ice"
    },
    {
      "x": -41,
      "y": 57,
      "z": 40,
      "name": "Rock_Ice"
    },
    {
      "x": -41,
      "y": 58,
      "z": 40,
      "name": "Rock_Ice"
    },
    {
      "x": -41,
      "y": 59,
      "z": 40,
      "name": "Rock_Ice"
    },
    {
      "x": -41,
      "y": 60,
      "z": 40,
      "name": "Rock_Ice"
    },
    {
      "x": -41,
      "y": 61,
      "z": 40,
      "name": "Rock_Ice"
    },
    {
      "x": -41,
      "y": 62,
      "z": 40,
      "name": "Rock_Ice"
    },
    {
      "x": -41,
      "y": 63,
      "z": 40,
      "name": "Soil_Snow"
    },
    {
      "x": -41,
      "y": 55,
      "z": 41,
      "name": "Rock_Ice"
    },
    {
      "x": -41,
      "y": 56,
      "z": 41,
      "name": "Rock_Ice"
    },
    {
      "x": -41,
      "y": 57,
      "z": 41,
      "name": "Rock_Ice"
    },
    {
      "x": -41,
      "y": 58,
      "z": 41,
      "name": "Rock_Ice"
    },
    {
      "x": -41,
      "y": 59,
      "z": 41,
      "name": "Rock_Ice"
    },
    {
      "x": -41,
      "y": 60,
      "z": 41,
      "name": "Rock_Ice"
    },
    {
      "x": -41,
      "y": 61,
      "z": 41,
      "name": "Rock_Ice"
    },
    {
      "x": -41,
      "y": 62,
      "z": 41,
      "name": "Soil_Snow"
    },
    {
      "x": -41,
      "y": 56,
      "z": 42,
      "name": "Rock_Ice"
    },
    {
      "x": -41,
      "y": 57,
      "z": 42,
      "name": "Rock_Ice"
    },
    {
      "x": -41,
      "y": 58,
      "z": 42,
      "name": "Rock_Ice"
    },
    {
      "x": -41,
      "y": 59,
      "z": 42,
      "name": "Rock_Ice"
    },
    {
      "x": -41,
      "y": 60,
      "z": 42,
      "name": "Soil_Snow"
    },
    {
      "x": -40,
      "y": 49,
      "z": 18,
      "name": "Rock_Ice"
    },
    {
      "x": -40,
      "y": 50,
      "z": 18,
      "name": "Rock_Ice"
    },
    {
      "x": -40,
      "y": 51,
      "z": 18,
      "name": "Rock_Ice"
    },
    {
      "x": -40,
      "y": 52,
      "z": 18,
      "name": "Rock_Ice"
    },
    {
      "x": -40,
      "y": 53,
      "z": 18,
      "name": "Rock_Ice"
    },
    {
      "x": -40,
      "y": 54,
      "z": 18,
      "name": "Rock_Ice"
    },
    {
      "x": -40,
      "y": 55,
      "z": 18,
      "name": "Rock_Ice"
    },
    {
      "x": -40,
      "y": 56,
      "z": 18,
      "name": "Rock_Ice"
    },
    {
      "x": -40,
      "y": 57,
      "z": 18,
      "name": "Rock_Ice_Permafrost"
    },
    {
      "x": -40,
      "y": 67,
      "z": 18,
      "name": "Soil_Snow"
    },
    {
      "x": -40,
      "y": 51,
      "z": 19,
      "name": "Rock_Ice"
    },
    {
      "x": -40,
      "y": 52,
      "z": 19,
      "name": "Rock_Ice"
    },
    {
      "x": -40,
      "y": 53,
      "z": 19,
      "name": "Rock_Ice"
    },
    {
      "x": -40,
      "y": 54,
      "z": 19,
      "name": "Rock_Ice"
    },
    {
      "x": -40,
      "y": 55,
      "z": 19,
      "name": "Rock_Ice_Permafrost"
    },
    {
      "x": -40,
      "y": 56,
      "z": 19,
      "name": "Rock_Ice_Permafrost"
    },
    {
      "x": -40,
      "y": 57,
      "z": 19,
      "name": "Rock_Ice_Permafrost"
    },
    {
      "x": -40,
      "y": 58,
      "z": 19,
      "name": "Rock_Ice_Permafrost"
    },
    {
      "x": -40,
      "y": 59,
      "z": 19,
      "name": "Rock_Ice_Permafrost"
    },
    {
      "x": -40,
      "y": 60,
      "z": 19,
      "name": "Rock_Ice_Permafrost"
    },
    {
      "x": -40,
      "y": 61,
      "z": 19,
      "name": "Rock_Ice_Permafrost"
    },
    {
      "x": -40,
      "y": 62,
      "z": 19,
      "name": "Rock_Ice_Permafrost"
    },
    {
      "x": -40,
      "y": 63,
      "z": 19,
      "name": "Rock_Ice_Permafrost"
    },
    {
      "x": -40,
      "y": 64,
      "z": 19,
      "name": "Rock_Ice_Permafrost"
    },
    {
      "x": -40,
      "y": 65,
      "z": 19,
      "name": "Rock_Ice_Permafrost"
    },
    {
      "x": -40,
      "y": 66,
      "z": 19,
      "name": "Rock_Ice"
    },
    {
      "x": -40,
      "y": 67,
      "z": 19,
      "name": "Soil_Snow"
    },
    {
      "x": -40,
      "y": 52,
      "z": 20,
      "name": "Rock_Ice_Permafrost"
    },
    {
      "x": -40,
      "y": 53,
      "z": 20,
      "name": "Rock_Ice_Permafrost"
    },
    {
      "x": -40,
      "y": 54,
      "z": 20,
      "name": "Rock_Ice_Permafrost"
    },
    {
      "x": -40,
      "y": 55,
      "z": 20,
      "name": "Rock_Ice_Permafrost"
    },
    {
      "x": -40,
      "y": 56,
      "z": 20,
      "name": "Rock_Ice_Permafrost"
    },
    {
      "x": -40,
      "y": 57,
      "z": 20,
      "name": "Rock_Ice_Permafrost"
    },
    {
      "x": -40,
      "y": 58,
      "z": 20,
      "name": "Rock_Ice_Permafrost"
    },
    {
      "x": -40,
      "y": 59,
      "z": 20,
      "name": "Rock_Ice_Permafrost"
    },
    {
      "x": -40,
      "y": 60,
      "z": 20,
      "name": "Rock_Ice_Permafrost"
    },
    {
      "x": -40,
      "y": 61,
      "z": 20,
      "name": "Rock_Ice_Permafrost"
    },
    {
      "x": -40,
      "y": 62,
      "z": 20,
      "name": "Rock_Ice_Permafrost"
    },
    {
      "x": -40,
      "y": 63,
      "z": 20,
      "name": "Rock_Ice_Permafrost"
    },
    {
      "x": -40,
      "y": 64,
      "z": 20,
      "name": "Rock_Ice_Permafrost"
    },
    {
      "x": -40,
      "y": 65,
      "z": 20,
      "name": "Rock_Ice_Permafrost"
    },
    {
      "x": -40,
      "y": 66,
      "z": 20,
      "name": "Rock_Ice"
    },
    {
      "x": -40,
      "y": 67,
      "z": 20,
      "name": "Soil_Snow"
    },
    {
      "x": -40,
      "y": 53,
      "z": 21,
      "name": "Rock_Ice_Permafrost"
    },
    {
      "x": -40,
      "y": 54,
      "z": 21,
      "name": "Rock_Ice_Permafrost"
    },
    {
      "x": -40,
      "y": 55,
      "z": 21,
      "name": "Rock_Ice_Permafrost"
    },
    {
      "x": -40,
      "y": 56,
      "z": 21,
      "name": "Rock_Ice_Permafrost"
    },
    {
      "x": -40,
      "y": 57,
      "z": 21,
      "name": "Rock_Ice"
    },
    {
      "x": -40,
      "y": 58,
      "z": 21,
      "name": "Rock_Ice"
    },
    {
      "x": -40,
      "y": 59,
      "z": 21,
      "name": "Rock_Ice_Permafrost"
    },
    {
      "x": -40,
      "y": 60,
      "z": 21,
      "name": "Rock_Ice"
    },
    {
      "x": -40,
      "y": 61,
      "z": 21,
      "name": "Rock_Ice"
    },
    {
      "x": -40,
      "y": 62,
      "z": 21,
      "name": "Rock_Ice_Permafrost"
    },
    {
      "x": -40,
      "y": 63,
      "z": 21,
      "name": "Rock_Ice"
    },
    {
      "x": -40,
      "y": 64,
      "z": 21,
      "name": "Rock_Ice"
    },
    {
      "x": -40,
      "y": 65,
      "z": 21,
      "name": "Rock_Ice"
    },
    {
      "x": -40,
      "y": 66,
      "z": 21,
      "name": "Rock_Ice"
    },
    {
      "x": -40,
      "y": 67,
      "z": 21,
      "name": "Soil_Snow"
    },
    {
      "x": -40,
      "y": 53,
      "z": 22,
      "name": "Rock_Ice"
    },
    {
      "x": -40,
      "y": 54,
      "z": 22,
      "name": "Rock_Ice"
    },
    {
      "x": -40,
      "y": 55,
      "z": 22,
      "name": "Rock_Ice"
    },
    {
      "x": -40,
      "y": 56,
      "z": 22,
      "name": "Rock_Ice"
    },
    {
      "x": -40,
      "y": 57,
      "z": 22,
      "name": "Rock_Ice"
    },
    {
      "x": -40,
      "y": 58,
      "z": 22,
      "name": "Rock_Ice"
    },
    {
      "x": -40,
      "y": 59,
      "z": 22,
      "name": "Rock_Ice"
    },
    {
      "x": -40,
      "y": 60,
      "z": 22,
      "name": "Rock_Ice"
    },
    {
      "x": -40,
      "y": 61,
      "z": 22,
      "name": "Rock_Ice"
    },
    {
      "x": -40,
      "y": 62,
      "z": 22,
      "name": "Rock_Ice"
    },
    {
      "x": -40,
      "y": 63,
      "z": 22,
      "name": "Rock_Ice"
    },
    {
      "x": -40,
      "y": 64,
      "z": 22,
      "name": "Rock_Ice"
    },
    {
      "x": -40,
      "y": 65,
      "z": 22,
      "name": "Rock_Ice"
    },
    {
      "x": -40,
      "y": 66,
      "z": 22,
      "name": "Rock_Ice"
    },
    {
      "x": -40,
      "y": 67,
      "z": 22,
      "name": "Rock_Ice"
    },
    {
      "x": -40,
      "y": 68,
      "z": 22,
      "name": "Soil_Snow"
    },
    {
      "x": -40,
      "y": 53,
      "z": 23,
      "name": "Rock_Ice"
    },
    {
      "x": -40,
      "y": 54,
      "z": 23,
      "name": "Rock_Ice"
    },
    {
      "x": -40,
      "y": 55,
      "z": 23,
      "name": "Rock_Ice"
    },
    {
      "x": -40,
      "y": 56,
      "z": 23,
      "name": "Rock_Ice"
    },
    {
      "x": -40,
      "y": 57,
      "z": 23,
      "name": "Rock_Ice"
    },
    {
      "x": -40,
      "y": 58,
      "z": 23,
      "name": "Rock_Ice"
    },
    {
      "x": -40,
      "y": 59,
      "z": 23,
      "name": "Rock_Ice"
    },
    {
      "x": -40,
      "y": 60,
      "z": 23,
      "name": "Rock_Ice"
    },
    {
      "x": -40,
      "y": 61,
      "z": 23,
      "name": "Rock_Ice"
    },
    {
      "x": -40,
      "y": 62,
      "z": 23,
      "name": "Rock_Ice"
    },
    {
      "x": -40,
      "y": 63,
      "z": 23,
      "name": "Rock_Ice"
    },
    {
      "x": -40,
      "y": 64,
      "z": 23,
      "name": "Rock_Ice"
    },
    {
      "x": -40,
      "y": 65,
      "z": 23,
      "name": "Rock_Ice_Permafrost"
    },
    {
      "x": -40,
      "y": 66,
      "z": 23,
      "name": "Rock_Ice_Permafrost"
    },
    {
      "x": -40,
      "y": 67,
      "z": 23,
      "name": "Rock_Ice_Permafrost"
    },
    {
      "x": -40,
      "y": 68,
      "z": 23,
      "name": "Rock_Ice"
    },
    {
      "x": -40,
      "y": 69,
      "z": 23,
      "name": "Soil_Snow"
    },
    {
      "x": -40,
      "y": 53,
      "z": 24,
      "name": "Rock_Ice"
    },
    {
      "x": -40,
      "y": 54,
      "z": 24,
      "name": "Rock_Ice"
    },
    {
      "x": -40,
      "y": 55,
      "z": 24,
      "name": "Rock_Ice"
    },
    {
      "x": -40,
      "y": 56,
      "z": 24,
      "name": "Rock_Ice"
    },
    {
      "x": -40,
      "y": 57,
      "z": 24,
      "name": "Rock_Ice"
    },
    {
      "x": -40,
      "y": 58,
      "z": 24,
      "name": "Rock_Ice"
    },
    {
      "x": -40,
      "y": 59,
      "z": 24,
      "name": "Rock_Ice"
    },
    {
      "x": -40,
      "y": 60,
      "z": 24,
      "name": "Rock_Ice"
    },
    {
      "x": -40,
      "y": 61,
      "z": 24,
      "name": "Rock_Ice"
    },
    {
      "x": -40,
      "y": 62,
      "z": 24,
      "name": "Rock_Ice"
    },
    {
      "x": -40,
      "y": 63,
      "z": 24,
      "name": "Rock_Ice"
    },
    {
      "x": -40,
      "y": 64,
      "z": 24,
      "name": "Rock_Ice_Permafrost"
    },
    {
      "x": -40,
      "y": 65,
      "z": 24,
      "name": "Rock_Ice_Permafrost"
    },
    {
      "x": -40,
      "y": 66,
      "z": 24,
      "name": "Rock_Ice_Permafrost"
    },
    {
      "x": -40,
      "y": 67,
      "z": 24,
      "name": "Rock_Ice_Permafrost"
    },
    {
      "x": -40,
      "y": 68,
      "z": 24,
      "name": "Rock_Ice"
    },
    {
      "x": -40,
      "y": 69,
      "z": 24,
      "name": "Rock_Ice"
    },
    {
      "x": -40,
      "y": 70,
      "z": 24,
      "name": "Soil_Snow"
    },
    {
      "x": -40,
      "y": 53,
      "z": 25,
      "name": "Rock_Ice"
    },
    {
      "x": -40,
      "y": 54,
      "z": 25,
      "name": "Rock_Ice"
    },
    {
      "x": -40,
      "y": 55,
      "z": 25,
      "name": "Rock_Ice"
    },
    {
      "x": -40,
      "y": 56,
      "z": 25,
      "name": "Rock_Ice"
    },
    {
      "x": -40,
      "y": 57,
      "z": 25,
      "name": "Rock_Ice"
    },
    {
      "x": -40,
      "y": 58,
      "z": 25,
      "name": "Rock_Ice"
    },
    {
      "x": -40,
      "y": 59,
      "z": 25,
      "name": "Rock_Ice"
    },
    {
      "x": -40,
      "y": 60,
      "z": 25,
      "name": "Rock_Ice"
    },
    {
      "x": -40,
      "y": 61,
      "z": 25,
      "name": "Rock_Ice"
    },
    {
      "x": -40,
      "y": 62,
      "z": 25,
      "name": "Rock_Ice_Permafrost"
    },
    {
      "x": -40,
      "y": 63,
      "z": 25,
      "name": "Rock_Ice_Permafrost"
    },
    {
      "x": -40,
      "y": 64,
      "z": 25,
      "name": "Rock_Ice_Permafrost"
    },
    {
      "x": -40,
      "y": 65,
      "z": 25,
      "name": "Rock_Ice_Permafrost"
    },
    {
      "x": -40,
      "y": 66,
      "z": 25,
      "name": "Rock_Ice_Permafrost"
    },
    {
      "x": -40,
      "y": 67,
      "z": 25,
      "name": "Rock_Ice"
    },
    {
      "x": -40,
      "y": 68,
      "z": 25,
      "name": "Rock_Ice"
    },
    {
      "x": -40,
      "y": 69,
      "z": 25,
      "name": "Rock_Ice"
    },
    {
      "x": -40,
      "y": 70,
      "z": 25,
      "name": "Rock_Ice"
    },
    {
      "x": -40,
      "y": 71,
      "z": 25,
      "name": "Soil_Snow"
    },
    {
      "x": -40,
      "y": 52,
      "z": 26,
      "name": "Rock_Ice_Permafrost"
    },
    {
      "x": -40,
      "y": 53,
      "z": 26,
      "name": "Rock_Ice_Permafrost"
    },
    {
      "x": -40,
      "y": 54,
      "z": 26,
      "name": "Rock_Ice"
    },
    {
      "x": -40,
      "y": 55,
      "z": 26,
      "name": "Rock_Ice"
    },
    {
      "x": -40,
      "y": 56,
      "z": 26,
      "name": "Rock_Ice"
    },
    {
      "x": -40,
      "y": 57,
      "z": 26,
      "name": "Rock_Ice"
    },
    {
      "x": -40,
      "y": 58,
      "z": 26,
      "name": "Rock_Ice"
    },
    {
      "x": -40,
      "y": 59,
      "z": 26,
      "name": "Rock_Ice"
    },
    {
      "x": -40,
      "y": 60,
      "z": 26,
      "name": "Rock_Ice"
    },
    {
      "x": -40,
      "y": 61,
      "z": 26,
      "name": "Rock_Ice"
    },
    {
      "x": -40,
      "y": 62,
      "z": 26,
      "name": "Rock_Ice_Permafrost"
    },
    {
      "x": -40,
      "y": 63,
      "z": 26,
      "name": "Rock_Ice_Permafrost"
    },
    {
      "x": -40,
      "y": 64,
      "z": 26,
      "name": "Rock_Ice_Permafrost"
    },
    {
      "x": -40,
      "y": 65,
      "z": 26,
      "name": "Rock_Ice"
    },
    {
      "x": -40,
      "y": 66,
      "z": 26,
      "name": "Rock_Ice"
    },
    {
      "x": -40,
      "y": 67,
      "z": 26,
      "name": "Rock_Ice"
    },
    {
      "x": -40,
      "y": 68,
      "z": 26,
      "name": "Rock_Ice"
    },
    {
      "x": -40,
      "y": 69,
      "z": 26,
      "name": "Rock_Ice"
    },
    {
      "x": -40,
      "y": 70,
      "z": 26,
      "name": "Rock_Ice"
    },
    {
      "x": -40,
      "y": 71,
      "z": 26,
      "name": "Soil_Snow"
    },
    {
      "x": -40,
      "y": 52,
      "z": 27,
      "name": "Rock_Ice_Permafrost"
    },
    {
      "x": -40,
      "y": 53,
      "z": 27,
      "name": "Rock_Ice_Permafrost"
    },
    {
      "x": -40,
      "y": 54,
      "z": 27,
      "name": "Rock_Ice_Permafrost"
    },
    {
      "x": -40,
      "y": 55,
      "z": 27,
      "name": "Rock_Ice_Permafrost"
    },
    {
      "x": -40,
      "y": 56,
      "z": 27,
      "name": "Rock_Ice_Permafrost"
    },
    {
      "x": -40,
      "y": 57,
      "z": 27,
      "name": "Rock_Ice_Permafrost"
    },
    {
      "x": -40,
      "y": 58,
      "z": 27,
      "name": "Rock_Ice_Permafrost"
    },
    {
      "x": -40,
      "y": 59,
      "z": 27,
      "name": "Rock_Ice_Permafrost"
    },
    {
      "x": -40,
      "y": 60,
      "z": 27,
      "name": "Rock_Ice_Permafrost"
    },
    {
      "x": -40,
      "y": 61,
      "z": 27,
      "name": "Rock_Ice_Permafrost"
    },
    {
      "x": -40,
      "y": 62,
      "z": 27,
      "name": "Rock_Ice_Permafrost"
    },
    {
      "x": -40,
      "y": 63,
      "z": 27,
      "name": "Rock_Ice_Permafrost"
    },
    {
      "x": -40,
      "y": 64,
      "z": 27,
      "name": "Rock_Ice_Permafrost"
    },
    {
      "x": -40,
      "y": 65,
      "z": 27,
      "name": "Rock_Ice"
    },
    {
      "x": -40,
      "y": 66,
      "z": 27,
      "name": "Rock_Ice"
    },
    {
      "x": -40,
      "y": 67,
      "z": 27,
      "name": "Rock_Ice"
    },
    {
      "x": -40,
      "y": 68,
      "z": 27,
      "name": "Rock_Ice"
    },
    {
      "x": -40,
      "y": 69,
      "z": 27,
      "name": "Rock_Ice"
    },
    {
      "x": -40,
      "y": 70,
      "z": 27,
      "name": "Rock_Ice"
    },
    {
      "x": -40,
      "y": 71,
      "z": 27,
      "name": "Soil_Snow"
    },
    {
      "x": -40,
      "y": 52,
      "z": 28,
      "name": "Rock_Ice"
    },
    {
      "x": -40,
      "y": 53,
      "z": 28,
      "name": "Rock_Ice"
    },
    {
