{
  "version": 8,
  "blockIdVersion": 11,
  "anchorX": 0,
  "anchorY": 0,
  "anchorZ": 0,
  "blocks": [
    {
      "x": -38,
      "y": 21,
      "z": 1,
      "name": "Rail",
      "rotation": 16
    },
    {
      "x": -37,
      "y": 21,
      "z": 0,
      "name": "Rail",
      "rotation": 19
    },
    {
      "x": -37,
      "y": 20,
      "z": 1,
      "name": "Wood_Fir_Trunk_Half",
      "rotation": 8
    },
    {
      "x": -37,
      "y": 21,
      "z": 1,
      "name": "Rock_Shale_Brick_Decorative",
      "support": 15
    },
    {
      "x": -37,
      "y": 22,
      "z": 1,
      "name": "Furniture_Temple_Dark_Statue_Gaia",
      "rotation": 3
    },
    {
      "x": -37,
      "y": 23,
      "z": 1,
      "name": "Furniture_Temple_Dark_Statue_Gaia",
      "filler": 1024,
      "rotation": 3
    },
    {
      "x": -37,
      "y": 24,
      "z": 1,
      "name": "Furniture_Temple_Dark_Statue_Gaia",
      "filler": 2048,
      "rotation": 3
    },
    {
      "x": -37,
      "y": 21,
      "z": 2,
      "name": "Rail",
      "rotation": 17
    },
    {
      "x": -36,
      "y": 20,
      "z": 1,
      "name": "Wood_Fir_Trunk_Full_Locked",
      "support": 15,
      "rotation": 5
    },
    {
      "x": -36,
      "y": 21,
      "z": 1,
      "name": "Wood_Fir_Trunk_Half"
    },
    {
      "x": -35,
      "y": 19,
      "z": 1,
      "name": "Wood_Fir_Trunk_Half",
      "rotation": 8
    },
    {
      "x": -35,
      "y": 20,
      "z": 1,
      "name": "Wood_Fir_Trunk_Full_Locked",
      "support": 15,
      "rotation": 5
    },
    {
      "x": -34,
      "y": 18,
      "z": 1,
      "name": "Wood_Fir_Trunk_Stairs",
      "rotation": 9
    },
    {
      "x": -34,
      "y": 19,
      "z": 1,
      "name": "Wood_Fir_Trunk_Full_Locked",
      "support": 15,
      "rotation": 5
    },
    {
      "x": -34,
      "y": 20,
      "z": 1,
      "name": "Wood_Fir_Trunk_Half"
    },
    {
      "x": -33,
      "y": 17,
      "z": 1,
      "name": "Wood_Fir_Trunk_Stairs",
      "rotation": 9
    },
    {
      "x": -33,
      "y": 18,
      "z": 1,
      "name": "Wood_Fir_Trunk_Full_Locked",
      "support": 15
    },
    {
      "x": -33,
      "y": 19,
      "z": 1,
      "name": "Wood_Fir_Trunk_Full_Locked",
      "support": 15,
      "rotation": 5
    },
    {
      "x": -32,
      "y": 16,
      "z": 1,
      "name": "Wood_Fir_Trunk_Stairs",
      "rotation": 9
    },
    {
      "x": -32,
      "y": 17,
      "z": 1,
      "name": "Wood_Fir_Trunk_Stairs",
      "rotation": 1
    },
    {
      "x": -32,
      "y": 18,
      "z": 1,
      "name": "Wood_Fir_Trunk_Full_Locked",
      "support": 15,
      "rotation": 5
    },
    {
      "x": -32,
      "y": 19,
      "z": 1,
      "name": "Wood_Fir_Trunk_Half"
    },
    {
      "x": -31,
      "y": 15,
      "z": 1,
      "name": "Wood_Fir_Trunk_Stairs",
      "rotation": 9
    },
    {
      "x": -31,
      "y": 16,
      "z": 1,
      "name": "Wood_Fir_Trunk_Stairs",
      "rotation": 1
    },
    {
      "x": -31,
      "y": 17,
      "z": 1,
      "name": "Wood_Fir_Trunk_Half",
      "rotation": 8
    },
    {
      "x": -31,
      "y": 18,
      "z": 1,
      "name": "Wood_Fir_Trunk_Full_Locked",
      "support": 15,
      "rotation": 5
    },
    {
      "x": -30,
      "y": 14,
      "z": 1,
      "name": "Wood_Fir_Trunk_Stairs",
      "rotation": 9
    },
    {
      "x": -30,
      "y": 15,
      "z": 1,
      "name": "Wood_Fir_Trunk_Stairs",
      "rotation": 1
    },
    {
      "x": -30,
      "y": 17,
      "z": 1,
      "name": "Wood_Fir_Trunk_Full_Locked",
      "support": 15
    },
    {
      "x": -30,
      "y": 18,
      "z": 1,
      "name": "Wood_Fir_Trunk_Half"
    },
    {
      "x": -29,
      "y": 13,
      "z": 1,
      "name": "Wood_Fir_Trunk_Stairs",
      "rotation": 9
    },
    {
      "x": -29,
      "y": 14,
      "z": 1,
      "name": "Wood_Fir_Trunk_Stairs",
      "rotation": 1
    },
    {
      "x": -29,
      "y": 16,
      "z": 1,
      "name": "Wood_Fir_Trunk_Half",
      "rotation": 8
    },
    {
      "x": -29,
      "y": 17,
      "z": 1,
      "name": "Wood_Fir_Trunk_Full_Locked",
      "support": 15,
      "rotation": 5
    },
    {
      "x": -29,
      "y": 14,
      "z": 2,
      "name": "Wood_Fir_Trunk_Half",
      "rotation": 4
    },
    {
      "x": -28,
      "y": 12,
      "z": 1,
      "name": "Wood_Fir_Trunk_Stairs",
      "rotation": 9
    },
    {
      "x": -28,
      "y": 13,
      "z": 1,
      "name": "Wood_Fir_Trunk_Stairs",
      "rotation": 1
    },
    {
      "x": -28,
      "y": 16,
      "z": 1,
      "name": "Wood_Fir_Trunk_Full_Locked",
      "support": 15,
      "rotation": 5
    },
    {
      "x": -28,
      "y": 17,
      "z": 1,
      "name": "Wood_Fir_Trunk_Half"
    },
    {
      "x": -28,
      "y": 14,
      "z": 2,
      "name": "Wood_Fir_Trunk_Full_Locked",
      "support": 15,
      "rotation": 4
    },
    {
      "x": -27,
      "y": 11,
      "z": 1,
      "name": "Wood_Fir_Trunk_Stairs",
      "rotation": 9
    },
    {
      "x": -27,
      "y": 12,
      "z": 1,
      "name": "Wood_Fir_Trunk_Stairs",
      "rotation": 1
    },
    {
      "x": -27,
      "y": 15,
      "z": 1,
      "name": "Wood_Fir_Trunk_Half",
      "rotation": 8
    },
    {
      "x": -27,
      "y": 16,
      "z": 1,
      "name": "Wood_Fir_Trunk_Full_Locked",
      "support": 15,
      "rotation": 5
    },
    {
      "x": -27,
      "y": 14,
      "z": 2,
      "name": "Wood_Fir_Trunk_Half",
      "rotation": 6
    },
    {
      "x": -27,
      "y": 14,
      "z": 3,
      "name": "Wood_Fir_Trunk_Half",
      "rotation": 4
    },
    {
      "x": -26,
      "y": 10,
      "z": 1,
      "name": "Wood_Fir_Trunk_Stairs",
      "rotation": 9
    },
    {
      "x": -26,
      "y": 11,
      "z": 1,
      "name": "Wood_Fir_Trunk_Stairs",
      "rotation": 1
    },
    {
      "x": -26,
      "y": 15,
      "z": 1,
      "name": "Wood_Fir_Trunk_Full_Locked",
      "support": 15,
      "rotation": 5
    },
    {
      "x": -26,
      "y": 16,
      "z": 1,
      "name": "Wood_Fir_Trunk_Half"
    },
    {
      "x": -26,
      "y": 14,
      "z": 3,
      "name": "*Wood_Fir_Trunk_Half_State_Definitions_Block",
      "rotation": 6
    },
    {
      "x": -25,
      "y": 9,
      "z": 1,
      "name": "Wood_Fir_Trunk_Stairs",
      "rotation": 9
    },
    {
      "x": -25,
      "y": 10,
      "z": 1,
      "name": "Wood_Fir_Trunk_Stairs",
      "rotation": 1
    },
    {
      "x": -25,
      "y": 15,
      "z": 1,
      "name": "Wood_Fir_Trunk_Full_Locked",
      "support": 15,
      "rotation": 5
    },
    {
      "x": -25,
      "y": 14,
      "z": 3,
      "name": "Wood_Fir_Trunk_Half",
      "rotation": 6
    },
    {
      "x": -25,
      "y": 14,
      "z": 4,
      "name": "Wood_Fir_Trunk_Half",
      "rotation": 4
    },
    {
      "x": -24,
      "y": 11,
      "z": 0,
      "name": "Wood_Fir_Trunk_Full_Locked",
      "support": 15,
      "rotation": 6
    },
    {
      "x": -24,
      "y": 8,
      "z": 1,
      "name": "Wood_Fir_Trunk_Stairs",
      "rotation": 9
    },
    {
      "x": -24,
      "y": 9,
      "z": 1,
      "name": "Wood_Fir_Trunk_Full_Locked",
      "support": 15,
      "rotation": 2
    },
    {
      "x": -24,
      "y": 10,
      "z": 1,
      "name": "Wood_Blackwood_Planks"
    },
    {
      "x": -24,
      "y": 11,
      "z": 1,
      "name": "Wood_Fir_Trunk_Full_Locked",
      "support": 15,
      "rotation": 6
    },
    {
      "x": -24,
      "y": 12,
      "z": 1,
      "name": "Wood_Fir_Trunk_Full_Locked",
      "support": 15
    },
    {
      "x": -24,
      "y": 13,
      "z": 1,
      "name": "Wood_Fir_Trunk_Full_Locked",
      "support": 15
    },
    {
      "x": -24,
      "y": 14,
      "z": 1,
      "name": "Wood_Fir_Trunk_Full_Locked",
      "support": 15
    },
    {
      "x": -24,
      "y": 15,
      "z": 1,
      "name": "Wood_Fir_Trunk_Full_Locked",
      "support": 15
    },
    {
      "x": -24,
      "y": 10,
      "z": 2,
      "name": "Wood_Blackwood_Planks"
    },
    {
      "x": -24,
      "y": 11,
      "z": 2,
      "name": "Wood_Fir_Trunk_Full_Locked",
      "support": 15,
      "rotation": 4
    },
    {
      "x": -24,
      "y": 12,
      "z": 2,
      "name": "Wood_Blackwood_Planks"
    },
    {
      "x": -24,
      "y": 13,
      "z": 2,
      "name": "Wood_Blackwood_Planks"
    },
    {
      "x": -24,
      "y": 14,
      "z": 2,
      "name": "Wood_Fir_Trunk_Full_Locked",
      "support": 15
    },
    {
      "x": -24,
      "y": 15,
      "z": 2,
      "name": "Wood_Fir_Trunk_Full_Locked",
      "support": 15
    },
    {
      "x": -24,
      "y": 14,
      "z": 4,
      "name": "Wood_Fir_Trunk_Full_Locked",
      "support": 15,
      "rotation": 5
    },
    {
      "x": -23,
      "y": 10,
      "z": -2,
      "name": "Wood_Fir_Trunk_Full_Locked",
      "support": 15,
      "rotation": 5
    },
    {
      "x": -23,
      "y": 11,
      "z": -2,
      "name": "Wood_Fir_Trunk_Full_Locked",
      "support": 15,
      "rotation": 6
    },
    {
      "x": -23,
      "y": 11,
      "z": -1,
      "name": "Wood_Fir_Trunk_Full_Locked",
      "support": 15,
      "rotation": 6
    },
    {
      "x": -23,
      "y": 11,
      "z": 0,
      "name": "Wood_Fir_Trunk_Full_Locked",
      "support": 15,
      "rotation": 6
    },
    {
      "x": -23,
      "y": 7,
      "z": 1,
      "name": "Wood_Fir_Trunk_Stairs",
      "rotation": 9
    },
    {
      "x": -23,
      "y": 8,
      "z": 1,
      "name": "Wood_Fir_Trunk_Full_Locked",
      "support": 15,
      "rotation": 2
    },
    {
      "x": -23,
      "y": 11,
      "z": 1,
      "name": "Wood_Fir_Trunk_Full_Locked",
      "support": 15,
      "rotation": 5
    },
    {
      "x": -23,
      "y": 14,
      "z": 1,
      "name": "Wood_Fir_Trunk_Full_Locked",
      "support": 15,
      "rotation": 5
    },
    {
      "x": -23,
      "y": 9,
      "z": 2,
      "name": "Wood_Blackwood_Planks"
    },
    {
      "x": -23,
      "y": 10,
      "z": 2,
      "name": "Wood_Blackwood_Planks"
    },
    {
      "x": -23,
      "y": 11,
      "z": 2,
      "name": "Wood_Fir_Trunk_Full_Locked",
      "support": 15,
      "rotation": 4
    },
    {
      "x": -23,
      "y": 14,
      "z": 2,
      "name": "Wood_Fir_Trunk_Full_Locked",
      "support": 15,
      "rotation": 4
    },
    {
      "x": -23,
      "y": 15,
      "z": 2,
      "name": "Wood_Fir_Trunk_Full_Locked",
      "support": 15
    },
    {
      "x": -23,
      "y": 10,
      "z": 3,
      "name": "Wood_Blackwood_Planks"
    },
    {
      "x": -23,
      "y": 11,
      "z": 3,
      "name": "Wood_Fir_Trunk_Full_Locked",
      "support": 15,
      "rotation": 4
    },
    {
      "x": -23,
      "y": 12,
      "z": 3,
      "name": "Wood_Blackwood_Planks"
    },
    {
      "x": -23,
      "y": 13,
      "z": 3,
      "name": "Wood_Blackwood_Planks"
    },
    {
      "x": -23,
      "y": 14,
      "z": 3,
      "name": "Wood_Fir_Trunk_Full_Locked",
      "support": 15
    },
    {
      "x": -23,
      "y": 15,
      "z": 3,
      "name": "Wood_Blackwood_Fence",
      "rotation": 3
    },
    {
      "x": -23,
      "y": 10,
      "z": 4,
      "name": "Wood_Fir_Trunk_Full_Locked",
      "support": 15,
      "rotation": 5
    },
    {
      "x": -23,
      "y": 11,
      "z": 4,
      "name": "Wood_Fir_Trunk_Full_Locked",
      "support": 15,
      "rotation": 4
    },
    {
      "x": -23,
      "y": 12,
      "z": 4,
      "name": "Wood_Fir_Trunk_Full_Locked",
      "support": 15
    },
    {
      "x": -23,
      "y": 13,
      "z": 4,
      "name": "Wood_Fir_Trunk_Full_Locked",
      "support": 15
    },
    {
      "x": -23,
      "y": 14,
      "z": 4,
      "name": "Wood_Fir_Trunk_Full_Locked",
      "support": 15,
      "rotation": 4
    },
    {
      "x": -23,
      "y": 15,
      "z": 4,
      "name": "*Wood_Blackwood_Fence_State_Definitions_Corner",
      "rotation": 2
    },
    {
      "x": -23,
      "y": 14,
      "z": 5,
      "name": "Wood_Fir_Trunk_Half",
      "rotation": 4
    },
    {
      "x": -22,
      "y": 11,
      "z": -4,
      "name": "Wood_Fir_Trunk_Full_Locked",
      "support": 15,
      "rotation": 5
    },
    {
      "x": -22,
      "y": 11,
      "z": -3,
      "name": "Wood_Fir_Trunk_Full_Locked",
      "support": 15,
      "rotation": 6
    },
    {
      "x": -22,
      "y": 9,
      "z": -2,
      "name": "Wood_Fir_Trunk_Full_Locked",
      "support": 15,
      "rotation": 5
    },
    {
      "x": -22,
      "y": 10,
      "z": -2,
      "name": "Wood_Fir_Trunk_Full_Locked",
      "support": 15,
      "rotation": 5
    },
    {
      "x": -22,
      "y": 6,
      "z": 1,
      "name": "Wood_Fir_Trunk_Stairs",
      "rotation": 9
    },
    {
      "x": -22,
      "y": 7,
      "z": 1,
      "name": "Wood_Fir_Trunk_Full_Locked",
      "support": 15,
      "rotation": 2
    },
    {
      "x": -22,
      "y": 14,
      "z": 1,
      "name": "Wood_Fir_Trunk_Full_Locked",
      "support": 15,
      "rotation": 5
    },
    {
      "x": -22,
      "y": 8,
      "z": 2,
      "name": "Wood_Blackwood_Planks"
    },
    {
      "x": -22,
      "y": 9,
      "z": 2,
      "name": "Wood_Blackwood_Planks"
    },
    {
      "x": -22,
      "y": 14,
      "z": 2,
      "name": "Wood_Deadwood_Planks_Half",
      "rotation": 8
    },
    {
      "x": -22,
      "y": 9,
      "z": 3,
      "name": "Wood_Blackwood_Planks"
    },
    {
      "x": -22,
      "y": 14,
      "z": 3,
      "name": "Wood_Deadwood_Planks_Half",
      "rotation": 8
    },
    {
      "x": -22,
      "y": 9,
      "z": 4,
      "name": "Wood_Fir_Trunk_Full_Locked",
      "support": 15,
      "rotation": 5
    },
    {
      "x": -22,
      "y": 10,
      "z": 4,
      "name": "Wood_Fir_Trunk_Full_Locked",
      "support": 15,
      "rotation": 5
    },
    {
      "x": -22,
      "y": 11,
      "z": 4,
      "name": "Wood_Fir_Trunk_Full_Locked",
      "support": 15,
      "rotation": 5
    },
    {
      "x": -22,
      "y": 14,
      "z": 4,
      "name": "Wood_Fir_Trunk_Full_Locked",
      "support": 15,
      "rotation": 5
    },
    {
      "x": -22,
      "y": 15,
      "z": 4,
      "name": "*Wood_Blackwood_Fence_State_Definitions_Corner"
    },
    {
      "x": -22,
      "y": 10,
      "z": 5,
      "name": "Wood_Blackwood_Planks"
    },
    {
      "x": -22,
      "y": 11,
      "z": 5,
      "name": "Wood_Fir_Trunk_Full_Locked",
      "support": 15,
      "rotation": 4
    },
    {
      "x": -22,
      "y": 12,
      "z": 5,
      "name": "Wood_Blackwood_Planks"
    },
    {
      "x": -22,
      "y": 13,
      "z": 5,
      "name": "Wood_Blackwood_Planks"
    },
    {
      "x": -22,
      "y": 14,
      "z": 5,
      "name": "Wood_Fir_Trunk_Full_Locked",
      "support": 15,
      "rotation": 4
    },
    {
      "x": -22,
      "y": 15,
      "z": 5,
      "name": "Wood_Blackwood_Fence",
      "rotation": 3
    },
    {
      "x": -22,
      "y": 11,
      "z": 6,
      "name": "Wood_Fir_Trunk_Full_Locked",
      "support": 15,
      "rotation": 5
    },
    {
      "x": -22,
      "y": 12,
      "z": 6,
      "name": "Wood_Blackwood_Planks"
    },
    {
      "x": -22,
      "y": 13,
      "z": 6,
      "name": "Wood_Blackwood_Planks"
    },
    {
      "x": -22,
      "y": 14,
      "z": 6,
      "name": "Wood_Fir_Trunk_Full_Locked",
      "support": 15,
      "rotation": 4
    },
    {
      "x": -22,
      "y": 15,
      "z": 6,
      "name": "*Wood_Blackwood_Fence_State_Definitions_Corner",
      "rotation": 2
    },
    {
      "x": -21,
      "y": 11,
      "z": -5,
      "name": "Wood_Fir_Trunk_Full_Locked",
      "support": 15,
      "rotation": 5
    },
    {
      "x": -21,
      "y": 10,
      "z": -4,
      "name": "Wood_Blackwood_Planks"
    },
    {
      "x": -21,
      "y": 11,
      "z": -4,
      "name": "Wood_Fir_Trunk_Full_Locked",
      "support": 15,
      "rotation": 5
    },
    {
      "x": -21,
      "y": 8,
      "z": -2,
      "name": "Wood_Fir_Trunk_Full_Locked",
      "support": 15,
      "rotation": 5
    },
    {
      "x": -21,
      "y": 9,
      "z": -2,
      "name": "Wood_Fir_Trunk_Full_Locked",
      "support": 15,
      "rotation": 5
    },
    {
      "x": -21,
      "y": 5,
      "z": 1,
      "name": "Wood_Fir_Trunk_Stairs",
      "rotation": 9
    },
    {
      "x": -21,
      "y": 6,
      "z": 1,
      "name": "Wood_Fir_Trunk_Full_Locked",
      "support": 15,
      "rotation": 2
    },
    {
      "x": -21,
      "y": 7,
      "z": 1,
      "name": "Wood_Fir_Trunk_Full_Locked",
      "support": 15,
      "rotation": 5
    },
    {
      "x": -21,
      "y": 14,
      "z": 1,
      "name": "Wood_Fir_Trunk_Full_Locked",
      "support": 15,
      "rotation": 5
    },
    {
      "x": -21,
      "y": 7,
      "z": 2,
      "name": "Wood_Blackwood_Planks"
    },
    {
      "x": -21,
      "y": 8,
      "z": 2,
      "name": "Wood_Blackwood_Planks"
    },
    {
      "x": -21,
      "y": 14,
      "z": 2,
      "name": "Wood_Deadwood_Planks_Half",
      "rotation": 8
    },
    {
      "x": -21,
      "y": 8,
      "z": 3,
      "name": "Wood_Blackwood_Planks"
    },
    {
      "x": -21,
      "y": 14,
      "z": 3,
      "name": "Wood_Deadwood_Planks_Half",
      "rotation": 8
    },
    {
      "x": -21,
      "y": 8,
      "z": 4,
      "name": "Wood_Fir_Trunk_Full_Locked",
      "support": 15,
      "rotation": 5
    },
    {
      "x": -21,
      "y": 9,
      "z": 4,
      "name": "Wood_Fir_Trunk_Full_Locked",
      "support": 15,
      "rotation": 5
    },
    {
      "x": -21,
      "y": 11,
      "z": 4,
      "name": "Wood_Fir_Trunk_Full_Locked",
      "support": 15,
      "rotation": 5
    },
    {
      "x": -21,
      "y": 14,
      "z": 4,
      "name": "Wood_Fir_Trunk_Full_Locked",
      "support": 15,
      "rotation": 5
    },
    {
      "x": -21,
      "y": 9,
      "z": 5,
      "name": "Wood_Blackwood_Planks"
    },
    {
      "x": -21,
      "y": 11,
      "z": 5,
      "name": "Wood_Fir_Trunk_Full_Locked",
      "support": 15,
      "rotation": 4
    },
    {
      "x": -21,
      "y": 14,
      "z": 5,
      "name": "Wood_Deadwood_Planks_Half",
      "rotation": 8
    },
    {
      "x": -21,
      "y": 10,
      "z": 6,
      "name": "Wood_Blackwood_Planks"
    },
    {
      "x": -21,
      "y": 11,
      "z": 6,
      "name": "Wood_Fir_Trunk_Full_Locked",
      "support": 15,
      "rotation": 4
    },
    {
      "x": -21,
      "y": 14,
      "z": 6,
      "name": "Wood_Fir_Trunk_Full_Locked",
      "support": 15,
      "rotation": 4
    },
    {
      "x": -21,
      "y": 15,
      "z": 6,
      "name": "*Wood_Blackwood_Fence_State_Definitions_Corner"
    },
    {
      "x": -21,
      "y": 11,
      "z": 7,
      "name": "Wood_Fir_Trunk_Full_Locked",
      "support": 15,
      "rotation": 5
    },
    {
      "x": -21,
      "y": 12,
      "z": 7,
      "name": "Wood_Fir_Trunk_Full_Locked",
      "support": 15
    },
    {
      "x": -21,
      "y": 13,
      "z": 7,
      "name": "Wood_Fir_Trunk_Full_Locked",
      "support": 15
    },
    {
      "x": -21,
      "y": 14,
      "z": 7,
      "name": "Wood_Fir_Trunk_Full_Locked",
      "support": 15
    },
    {
      "x": -21,
      "y": 15,
      "z": 7,
      "name": "*Wood_Blackwood_Fence_State_Definitions_Corner",
      "rotation": 2
    },
    {
      "x": -20,
      "y": 10,
      "z": -5,
      "name": "Wood_Fir_Trunk_Full_Locked",
      "support": 15,
      "rotation": 5
    },
    {
      "x": -20,
      "y": 11,
      "z": -5,
      "name": "Wood_Fir_Trunk_Full_Locked",
      "support": 15,
      "rotation": 5
    },
    {
      "x": -20,
      "y": 7,
      "z": -2,
      "name": "Wood_Fir_Trunk_Full_Locked",
      "support": 15,
      "rotation": 5
    },
    {
      "x": -20,
      "y": 8,
      "z": -2,
      "name": "Wood_Fir_Trunk_Full_Locked",
      "support": 15,
      "rotation": 5
    },
    {
      "x": -20,
      "y": 4,
      "z": 1,
      "name": "Wood_Fir_Trunk_Half",
      "rotation": 8
    },
    {
      "x": -20,
      "y": 5,
      "z": 1,
      "name": "Wood_Fir_Trunk_Full_Locked",
      "support": 15,
      "rotation": 2
    },
    {
      "x": -20,
      "y": 7,
      "z": 1,
      "name": "Wood_Fir_Trunk_Full_Locked",
      "support": 15,
      "rotation": 5
    },
    {
      "x": -20,
      "y": 14,
      "z": 1,
      "name": "Wood_Fir_Trunk_Full_Locked",
      "support": 15,
      "rotation": 5
    },
    {
      "x": -20,
      "y": 6,
      "z": 2,
      "name": "Wood_Blackwood_Planks"
    },
    {
      "x": -20,
      "y": 7,
      "z": 2,
      "name": "Wood_Blackwood_Planks"
    },
    {
      "x": -20,
      "y": 11,
      "z": 2,
      "name": "Wood_Deadwood_Planks_Half",
      "rotation": 8
    },
    {
      "x": -20,
      "y": 14,
      "z": 2,
      "name": "Wood_Deadwood_Planks_Half",
      "rotation": 8
    },
    {
      "x": -20,
      "y": 7,
      "z": 3,
      "name": "Wood_Blackwood_Planks"
    },
    {
      "x": -20,
      "y": 11,
      "z": 3,
      "name": "Wood_Deadwood_Planks_Half",
      "rotation": 8
    },
    {
      "x": -20,
      "y": 14,
      "z": 3,
      "name": "Wood_Deadwood_Planks_Half",
      "rotation": 8
    },
    {
      "x": -20,
      "y": 7,
      "z": 4,
      "name": "Wood_Fir_Trunk_Full_Locked",
      "support": 15,
      "rotation": 5
    },
    {
      "x": -20,
      "y": 11,
      "z": 4,
      "name": "Wood_Fir_Trunk_Full_Locked",
      "support": 15,
      "rotation": 5
    },
    {
      "x": -20,
      "y": 14,
      "z": 4,
      "name": "Wood_Fir_Trunk_Full_Locked",
      "support": 15,
      "rotation": 5
    },
    {
      "x": -20,
      "y": 8,
      "z": 5,
      "name": "Wood_Blackwood_Planks"
    },
    {
      "x": -20,
      "y": 11,
      "z": 5,
      "name": "Wood_Deadwood_Planks_Half",
      "rotation": 8
    },
    {
      "x": -20,
      "y": 14,
      "z": 5,
      "name": "Wood_Deadwood_Planks_Half",
      "rotation": 8
    },
    {
      "x": -20,
      "y": 16,
      "z": 5,
      "name": "Metal_Iron_Pipe_Large",
      "rotation": 7
    },
    {
      "x": -20,
      "y": 9,
      "z": 6,
      "name": "Wood_Blackwood_Planks"
    },
    {
      "x": -20,
      "y": 11,
      "z": 6,
      "name": "Wood_Deadwood_Planks_Half",
      "rotation": 8
    },
    {
      "x": -20,
      "y": 14,
      "z": 6,
      "name": "Wood_Deadwood_Planks_Half",
      "rotation": 8
    },
    {
      "x": -20,
      "y": 10,
      "z": 7,
      "name": "Wood_Fir_Trunk_Full_Locked",
      "support": 15,
      "rotation": 5
    },
    {
      "x": -20,
      "y": 11,
      "z": 7,
      "name": "Wood_Fir_Trunk_Full_Locked",
      "support": 15,
      "rotation": 5
    },
    {
      "x": -20,
      "y": 12,
      "z": 7,
      "name": "Wood_Blackwood_Planks"
    },
    {
      "x": -20,
      "y": 13,
      "z": 7,
      "name": "Wood_Blackwood_Planks"
    },
    {
      "x": -20,
      "y": 14,
      "z": 7,
      "name": "Wood_Fir_Trunk_Full_Locked",
      "support": 15,
      "rotation": 5
    },
    {
      "x": -20,
      "y": 15,
      "z": 7,
      "name": "Wood_Blackwood_Fence"
    },
    {
      "x": -19,
      "y": 11,
      "z": -6,
      "name": "Wood_Fir_Trunk_Full_Locked",
      "support": 15,
      "rotation": 5
    },
    {
      "x": -19,
      "y": 9,
      "z": -5,
      "name": "Wood_Fir_Trunk_Full_Locked",
      "support": 15,
      "rotation": 5
    },
    {
      "x": -19,
      "y": 10,
      "z": -5,
      "name": "Wood_Fir_Trunk_Full_Locked",
      "support": 15,
      "rotation": 5
    },
    {
      "x": -19,
      "y": 11,
      "z": -5,
      "name": "Wood_Fir_Trunk_Full_Locked",
      "support": 15,
      "rotation": 5
    },
    {
      "x": -19,
      "y": 6,
      "z": -2,
      "name": "Wood_Fir_Trunk_Full_Locked",
      "support": 15,
      "rotation": 5
    },
    {
      "x": -19,
      "y": 7,
      "z": -2,
      "name": "Wood_Fir_Trunk_Full_Locked",
      "support": 15,
      "rotation": 5
    },
    {
      "x": -19,
      "y": 4,
      "z": 1,
      "name": "Wood_Fir_Trunk_Full_Locked",
      "support": 15,
      "rotation": 5
    },
    {
      "x": -19,
      "y": 5,
      "z": 1,
      "name": "Wood_Fir_Trunk_Full_Locked",
      "support": 15,
      "rotation": 5
    },
    {
      "x": -19,
      "y": 7,
      "z": 1,
      "name": "Wood_Fir_Trunk_Full_Locked",
      "support": 15,
      "rotation": 5
    },
    {
      "x": -19,
      "y": 14,
      "z": 1,
      "name": "Wood_Fir_Trunk_Full_Locked",
      "support": 15,
      "rotation": 5
    },
    {
      "x": -19,
      "y": 5,
      "z": 2,
      "name": "Wood_Blackwood_Planks"
    },
    {
      "x": -19,
      "y": 6,
      "z": 2,
      "name": "Wood_Blackwood_Planks"
    },
    {
      "x": -19,
      "y": 7,
      "z": 2,
      "name": "Wood_Deadwood_Planks_Half",
      "rotation": 8
    },
    {
      "x": -19,
      "y": 11,
      "z": 2,
      "name": "Wood_Deadwood_Planks_Half",
      "rotation": 8
    },
    {
      "x": -19,
      "y": 14,
      "z": 2,
      "name": "Wood_Deadwood_Planks_Half",
      "rotation": 8
    },
    {
      "x": -19,
      "y": 6,
      "z": 3,
      "name": "Wood_Blackwood_Planks"
    },
    {
      "x": -19,
      "y": 7,
      "z": 3,
      "name": "Wood_Deadwood_Planks_Half",
      "rotation": 8
    },
    {
      "x": -19,
      "y": 11,
      "z": 3,
      "name": "Wood_Deadwood_Planks_Half",
      "rotation": 8
    },
    {
      "x": -19,
      "y": 14,
      "z": 3,
      "name": "Wood_Deadwood_Planks_Half",
      "rotation": 8
    },
    {
      "x": -19,
      "y": 6,
      "z": 4,
      "name": "Wood_Fir_Trunk_Full_Locked",
      "support": 15,
      "rotation": 5
    },
    {
      "x": -19,
      "y": 7,
      "z": 4,
      "name": "Wood_Fir_Trunk_Full_Locked",
      "support": 15,
      "rotation": 5
    },
    {
      "x": -19,
      "y": 11,
      "z": 4,
      "name": "Wood_Fir_Trunk_Full_Locked",
      "support": 15,
      "rotation": 5
    },
    {
      "x": -19,
      "y": 14,
      "z": 4,
      "name": "Wood_Fir_Trunk_Full_Locked",
      "support": 15,
      "rotation": 5
    },
    {
      "x": -19,
      "y": 15,
      "z": 4,
      "name": "Deco_Rope_Diagonal",
      "rotation": 2
    },
    {
      "x": -19,
      "y": 7,
      "z": 5,
      "name": "Wood_Blackwood_Planks"
    },
    {
      "x": -19,
      "y": 11,
      "z": 5,
      "name": "Wood_Deadwood_Planks_Half",
      "rotation": 8
    },
    {
      "x": -19,
      "y": 14,
      "z": 5,
      "name": "Wood_Deadwood_Planks_Half",
      "rotation": 8
    },
    {
      "x": -19,
      "y": 15,
      "z": 5,
      "name": "Bench_Farming",
      "components": {
        "Components": {
          "BenchBlock": {
            "TierLevel": 1,
            "UpgradeItems": []
          },
          "PlacedByInteraction": {
            "WhoPlacedUuid": {
              "$binary": "+u0Lek23TWiDpMOn5L2LqA==",
              "$type": "04"
            }
          }
        }
      },
      "rotation": 2
    },
    {
      "x": -19,
      "y": 16,
      "z": 5,
      "name": "Metal_Iron_Pipe_Large",
      "rotation": 5
    },
    {
      "x": -19,
      "y": 8,
      "z": 6,
      "name": "Wood_Blackwood_Planks"
    },
    {
      "x": -19,
      "y": 11,
      "z": 6,
      "name": "Wood_Deadwood_Planks_Half",
      "rotation": 8
    },
    {
      "x": -19,
      "y": 14,
      "z": 6,
      "name": "Wood_Deadwood_Planks_Half",
      "rotation": 8
    },
    {
      "x": -19,
      "y": 15,
      "z": 6,
      "name": "Deco_Rope_Diagonal"
    },
    {
      "x": -19,
      "y": 9,
      "z": 7,
      "name": "Wood_Fir_Trunk_Full_Locked",
      "support": 15,
      "rotation": 5
    },
    {
      "x": -19,
      "y": 10,
      "z": 7,
      "name": "Wood_Fir_Trunk_Full_Locked",
      "support": 15,
      "rotation": 5
    },
    {
      "x": -19,
      "y": 11,
      "z": 7,
      "name": "Wood_Fir_Trunk_Full_Locked",
      "support": 15,
      "rotation": 5
    },
    {
      "x": -19,
      "y": 12,
      "z": 7,
      "name": "Wood_Blackwood_Planks"
    },
    {
      "x": -19,
      "y": 13,
      "z": 7,
      "name": "Wood_Blackwood_Planks"
    },
    {
      "x": -19,
      "y": 14,
      "z": 7,
      "name": "Wood_Fir_Trunk_Full_Locked",
      "support": 15,
      "rotation": 5
    },
    {
      "x": -19,
      "y": 15,
      "z": 7,
      "name": "*Wood_Blackwood_Fence_State_Definitions_Corner"
    },
    {
      "x": -19,
      "y": 11,
      "z": 8,
      "name": "Wood_Fir_Trunk_Full_Locked",
      "support": 15,
      "rotation": 5
    },
    {
      "x": -19,
      "y": 12,
      "z": 8,
      "name": "Wood_Blackwood_Planks"
    },
    {
      "x": -19,
      "y": 13,
      "z": 8,
      "name": "Wood_Blackwood_Planks"
    },
    {
      "x": -19,
      "y": 14,
      "z": 8,
      "name": "Wood_Fir_Trunk_Full_Locked",
      "support": 15,
      "rotation": 5
    },
    {
      "x": -19,
      "y": 15,
      "z": 8,
      "name": "*Wood_Blackwood_Fence_State_Definitions_Corner",
      "rotation": 2
    },
    {
      "x": -18,
      "y": 11,
      "z": -6,
      "name": "Wood_Fir_Trunk_Full_Locked",
      "support": 15,
      "rotation": 6
    },
    {
      "x": -18,
      "y": 8,
      "z": -5,
      "name": "Wood_Fir_Trunk_Full_Locked",
      "support": 15,
      "rotation": 5
    },
    {
      "x": -18,
      "y": 9,
      "z": -5,
      "name": "Wood_Fir_Trunk_Full_Locked",
      "support": 15,
      "rotation": 5
    },
    {
      "x": -18,
      "y": 6,
      "z": -2,
      "name": "Wood_Fir_Trunk_Full_Locked",
      "support": 15,
      "rotation": 5
    },
    {
      "x": -18,
      "y": 3,
      "z": 1,
      "name": "Wood_Fir_Trunk_Half",
      "rotation": 8
    },
    {
      "x": -18,
      "y": 4,
      "z": 1,
      "name": "Wood_Fir_Trunk_Full_Locked",
      "support": 15,
      "rotation": 2
    },
    {
      "x": -18,
      "y": 7,
      "z": 1,
      "name": "Wood_Fir_Trunk_Full_Locked",
      "support": 15,
      "rotation": 5
    },
    {
      "x": -18,
      "y": 14,
      "z": 1,
      "name": "Wood_Fir_Trunk_Full_Locked",
      "support": 15,
      "rotation": 5
    },
    {
      "x": -18,
      "y": 5,
      "z": 2,
      "name": "Wood_Blackwood_Planks"
    },
    {
      "x": -18,
      "y": 7,
      "z": 2,
      "name": "Wood_Deadwood_Planks_Half",
      "rotation": 8
    },
    {
      "x": -18,
      "y": 11,
      "z": 2,
      "name": "Wood_Deadwood_Planks_Half",
      "rotation": 8
    },
    {
      "x": -18,
      "y": 14,
      "z": 2,
      "name": "Wood_Deadwood_Planks_Half",
      "rotation": 8
    },
    {
      "x": -18,
      "y": 5,
      "z": 3,
      "name": "Wood_Blackwood_Planks"
    },
    {
      "x": -18,
      "y": 6,
      "z": 3,
      "name": "Wood_Blackwood_Planks"
    },
    {
      "x": -18,
      "y": 7,
      "z": 3,
      "name": "Wood_Deadwood_Planks_Half",
      "rotation": 8
    },
    {
      "x": -18,
      "y": 11,
      "z": 3,
      "name": "Wood_Deadwood_Planks_Half",
      "rotation": 8
    },
    {
      "x": -18,
      "y": 14,
      "z": 3,
      "name": "Wood_Deadwood_Planks_Half",
      "rotation": 8
    },
    {
      "x": -18,
      "y": 6,
      "z": 4,
      "name": "Wood_Fir_Trunk_Full_Locked",
      "support": 15,
      "rotation": 5
    },
    {
      "x": -18,
      "y": 7,
      "z": 4,
      "name": "Wood_Fir_Trunk_Full_Locked",
      "support": 15,
      "rotation": 5
    },
    {
      "x": -18,
      "y": 11,
      "z": 4,
      "name": "Wood_Fir_Trunk_Full_Locked",
      "support": 15,
      "rotation": 5
    },
    {
      "x": -18,
      "y": 14,
      "z": 4,
      "name": "Wood_Fir_Trunk_Full_Locked",
      "support": 15,
      "rotation": 5
    },
    {
      "x": -18,
      "y": 15,
      "z": 4,
      "name": "Deco_Rope_Diagonal",
      "rotation": 2
    },
    {
      "x": -18,
      "y": 7,
      "z": 5,
      "name": "Wood_Blackwood_Planks"
    },
    {
      "x": -18,
      "y": 11,
      "z": 5,
      "name": "Wood_Deadwood_Planks_Half",
      "rotation": 8
    },
    {
      "x": -18,
      "y": 14,
      "z": 5,
      "name": "Wood_Deadwood_Planks_Half",
      "rotation": 8
    },
    {
      "x": -18,
      "y": 15,
      "z": 5,
      "name": "Bench_Farming",
      "filler": 1,
      "rotation": 2
    },
    {
      "x": -18,
      "y": 16,
      "z": 5,
      "name": "Metal_Iron_Pipe_Large_Mouthpiece",
      "rotation": 5
    },
    {
      "x": -18,
      "y": 7,
      "z": 6,
      "name": "Wood_Blackwood_Planks"
    },
    {
      "x": -18,
      "y": 11,
      "z": 6,
      "name": "Wood_Deadwood_Planks_Half",
      "rotation": 8
    },
    {
      "x": -18,
      "y": 14,
      "z": 6,
      "name": "Wood_Deadwood_Planks_Half",
      "rotation": 8
    },
    {
      "x": -18,
      "y": 15,
      "z": 6,
      "name": "Deco_Rope_Diagonal"
    },
    {
      "x": -18,
      "y": 8,
      "z": 7,
      "name": "Wood_Fir_Trunk_Full_Locked",
      "support": 15,
      "rotation": 5
    },
    {
      "x": -18,
      "y": 9,
      "z": 7,
      "name": "Wood_Fir_Trunk_Full_Locked",
      "support": 15,
      "rotation": 5
    },
    {
      "x": -18,
      "y": 11,
      "z": 7,
      "name": "Wood_Fir_Trunk_Full_Locked",
      "support": 15,
      "rotation": 5
    },
    {
      "x": -18,
      "y": 14,
      "z": 7,
      "name": "Wood_Fir_Trunk_Full_Locked",
      "support": 15,
      "rotation": 5
    },
    {
      "x": -18,
      "y": 9,
      "z": 8,
      "name": "Wood_Blackwood_Planks"
    },
    {
      "x": -18,
      "y": 10,
      "z": 8,
      "name": "Wood_Blackwood_Planks"
    },
    {
      "x": -18,
      "y": 11,
      "z": 8,
      "name": "Wood_Fir_Trunk_Full_Locked",
      "support": 15,
      "rotation": 4
    },
    {
      "x": -18,
      "y": 12,
      "z": 8,
      "name": "Wood_Blackwood_Planks"
    },
    {
      "x": -18,
      "y": 13,
      "z": 8,
      "name": "Wood_Blackwood_Planks"
    },
    {
      "x": -18,
      "y": 14,
      "z": 8,
      "name": "Wood_Fir_Trunk_Full_Locked",
      "support": 15,
      "rotation": 5
    },
    {
      "x": -18,
      "y": 15,
      "z": 8,
      "name": "Wood_Blackwood_Fence"
    },
    {
      "x": -17,
      "y": 10,
      "z": -7,
      "name": "Wood_Fir_Trunk_Full_Locked",
      "support": 15,
      "rotation": 5
    },
    {
      "x": -17,
      "y": 11,
      "z": -7,
      "name": "Wood_Fir_Trunk_Full_Locked",
      "support": 15,
      "rotation": 5
    },
    {
      "x": -17,
      "y": 11,
      "z": -6,
      "name": "Wood_Fir_Trunk_Full_Locked",
      "support": 15,
      "rotation": 5
    },
    {
      "x": -17,
      "y": 7,
      "z": -5,
      "name": "Wood_Fir_Trunk_Full_Locked",
      "support": 15,
      "rotation": 5
    },
    {
      "x": -17,
      "y": 8,
      "z": -5,
      "name": "Wood_Fir_Trunk_Full_Locked",
      "support": 15,
      "rotation": 5
    },
    {
      "x": -17,
      "y": 5,
      "z": -2,
      "name": "Wood_Fir_Trunk_Full_Locked",
      "support": 15,
      "rotation": 5
    },
    {
      "x": -17,
      "y": 6,
      "z": -2,
      "name": "Wood_Fir_Trunk_Full_Locked",
      "support": 15,
      "rotation": 5
    },
    {
      "x": -17,
      "y": 11,
      "z": -2,
      "name": "Wood_Fir_Trunk_Full_Locked",
      "support": 15,
      "rotation": 4
    },
    {
      "x": -17,
      "y": 11,
      "z": -1,
      "name": "Wood_Fir_Trunk_Full_Locked",
      "support": 15,
      "rotation": 4
    },
    {
      "x": -17,
      "y": 11,
      "z": 0,
      "name": "Wood_Fir_Trunk_Full_Locked",
      "support": 15,
      "rotation": 4
    },
    {
      "x": -17,
      "y": 3,
      "z": 1,
      "name": "Wood_Fir_Trunk_Full_Locked",
      "support": 15,
      "rotation": 5
    },
    {
      "x": -17,
      "y": 4,
      "z": 1,
      "name": "Wood_Fir_Trunk_Full_Locked",
      "support": 15,
      "rotation": 5
    },
    {
      "x": -17,
      "y": 7,
      "z": 1,
      "name": "Wood_Fir_Trunk_Full_Locked",
      "support": 15,
      "rotation": 5
    },
    {
      "x": -17,
      "y": 11,
      "z": 1,
      "name": "Wood_Fir_Trunk_Full_Locked",
      "support": 15,
      "rotation": 4
    },
    {
      "x": -17,
      "y": 14,
      "z": 1,
      "name": "Wood_Fir_Trunk_Full_Locked",
      "support": 15,
      "rotation": 5
    },
    {
      "x": -17,
      "y": 4,
      "z": 2,
      "name": "Wood_Blackwood_Planks"
    },
    {
      "x": -17,
      "y": 7,
      "z": 2,
      "name": "Wood_Deadwood_Planks_Half",
      "rotation": 8
    },
    {
      "x": -17,
      "y": 11,
      "z": 2,
      "name": "Wood_Fir_Trunk_Full_Locked",
      "support": 15,
      "rotation": 4
    },
    {
      "x": -17,
      "y": 14,
      "z": 2,
      "name": "Wood_Deadwood_Planks_Half",
      "rotation": 8
    },
    {
      "x": -17,
      "y": 5,
      "z": 3,
      "name": "Wood_Blackwood_Planks"
    },
    {
      "x": -17,
      "y": 7,
      "z": 3,
      "name": "Wood_Deadwood_Planks_Half",
      "rotation": 8
    },
    {
      "x": -17,
      "y": 11,
      "z": 3,
      "name": "Wood_Fir_Trunk_Full_Locked",
      "support": 15,
      "rotation": 4
    },
    {
      "x": -17,
      "y": 14,
      "z": 3,
      "name": "Wood_Deadwood_Planks_Half",
      "rotation": 8
    },
    {
      "x": -17,
      "y": 5,
      "z": 4,
      "name": "Wood_Fir_Trunk_Full_Locked",
      "support": 15,
      "rotation": 5
    },
    {
      "x": -17,
      "y": 6,
      "z": 4,
      "name": "Wood_Fir_Trunk_Full_Locked",
      "support": 15,
      "rotation": 5
    },
    {
      "x": -17,
      "y": 7,
      "z": 4,
      "name": "Wood_Fir_Trunk_Full_Locked",
      "support": 15,
      "rotation": 5
    },
    {
      "x": -17,
      "y": 11,
      "z": 4,
      "name": "Wood_Fir_Trunk_Full_Locked",
      "support": 15,
      "rotation": 4
    },
    {
      "x": -17,
      "y": 14,
      "z": 4,
      "name": "Wood_Fir_Trunk_Full_Locked",
      "support": 15,
      "rotation": 5
    },
    {
      "x": -17,
      "y": 6,
      "z": 5,
      "name": "Wood_Blackwood_Planks"
    },
    {
      "x": -17,
      "y": 7,
      "z": 5,
      "name": "Wood_Fir_Trunk_Full_Locked",
      "support": 15,
      "rotation": 4
    },
    {
      "x": -17,
      "y": 11,
      "z": 5,
      "name": "Wood_Fir_Trunk_Full_Locked",
      "support": 15,
      "rotation": 4
    },
    {
      "x": -17,
      "y": 14,
      "z": 5,
      "name": "Wood_Deadwood_Planks_Half",
      "rotation": 8
    },
    {
      "x": -17,
      "y": 7,
      "z": 6,
      "name": "Wood_Blackwood_Planks"
    },
    {
      "x": -17,
      "y": 11,
      "z": 6,
      "name": "Wood_Fir_Trunk_Full_Locked",
      "support": 15,
      "rotation": 4
    },
    {
      "x": -17,
      "y": 14,
      "z": 6,
      "name": "Wood_Deadwood_Planks_Half",
      "rotation": 8
    },
    {
      "x": -17,
      "y": 7,
      "z": 7,
      "name": "Wood_Fir_Trunk_Full_Locked",
      "support": 15,
      "rotation": 5
    },
    {
      "x": -17,
      "y": 8,
      "z": 7,
      "name": "Wood_Fir_Trunk_Full_Locked",
      "support": 15,
      "rotation": 5
    },
    {
      "x": -17,
      "y": 11,
      "z": 7,
      "name": "Wood_Fir_Trunk_Full_Locked",
      "support": 15,
      "rotation": 5
    },
    {
      "x": -17,
      "y": 14,
      "z": 7,
      "name": "Wood_Fir_Trunk_Full_Locked",
      "support": 15,
      "rotation": 5
    },
    {
      "x": -17,
      "y": 8,
      "z": 8,
      "name": "Wood_Blackwood_Planks"
    },
    {
      "x": -17,
      "y": 9,
      "z": 8,
      "name": "Wood_Blackwood_Planks"
    },
    {
      "x": -17,
      "y": 10,
      "z": 8,
      "name": "Wood_Blackwood_Planks"
    },
    {
      "x": -17,
      "y": 11,
      "z": 8,
      "name": "Wood_Fir_Trunk_Full_Locked",
      "support": 15,
      "rotation": 5
    },
    {
      "x": -17,
      "y": 12,
      "z": 8,
      "name": "Wood_Fir_Trunk_Full_Locked",
      "support": 15
    },
    {
      "x": -17,
      "y": 13,
      "z": 8,
      "name": "Wood_Fir_Trunk_Full_Locked",
      "support": 15
    },
    {
      "x": -17,
      "y": 14,
      "z": 8,
      "name": "Wood_Fir_Trunk_Full_Locked",
      "support": 15,
      "rotation": 5
    },
    {
      "x": -17,
      "y": 15,
      "z": 8,
      "name": "*Wood_Blackwood_Fence_State_Definitions_Corner"
    },
    {
      "x": -17,
      "y": 10,
      "z": 9,
      "name": "Wood_Fir_Trunk_Full_Locked",
      "support": 15,
      "rotation": 5
    },
    {
      "x": -17,
      "y": 11,
      "z": 9,
      "name": "Wood_Fir_Trunk_Full_Locked",
      "support": 15,
      "rotation": 5
    },
    {
      "x": -17,
      "y": 12,
      "z": 9,
      "name": "Wood_Fir_Trunk_Full_Locked",
      "support": 15
    },
    {
      "x": -17,
      "y": 13,
      "z": 9,
      "name": "Wood_Fir_Trunk_Full_Locked",
      "support": 15
    },
    {
      "x": -17,
      "y": 14,
      "z": 9,
      "name": "Wood_Fir_Trunk_Full_Locked",
      "support": 15
    },
    {
      "x": -17,
      "y": 15,
      "z": 9,
      "name": "*Wood_Blackwood_Fence_State_Definitions_Corner",
      "rotation": 2
    },
    {
      "x": -16,
      "y": 9,
      "z": -7,
      "name": "Wood_Fir_Trunk_Full_Locked",
      "support": 15,
      "rotation": 5
    },
    {
      "x": -16,
      "y": 10,
      "z": -7,
      "name": "Wood_Fir_Trunk_Full_Locked",
      "support": 15,
      "rotation": 5
    },
    {
      "x": -16,
      "y": 11,
      "z": -7,
      "name": "Wood_Fir_Trunk_Full_Locked",
      "support": 15,
      "rotation": 5
    },
    {
      "x": -16,
      "y": 7,
      "z": -5,
      "name": "Wood_Fir_Trunk_Full_Locked",
      "support": 15,
      "rotation": 5
    },
    {
      "x": -16,
      "y": 5,
      "z": -2,
      "name": "Wood_Fir_Trunk_Full_Locked",
      "support": 15,
      "rotation": 5
    },
    {
      "x": -16,
      "y": 2,
      "z": 1,
      "name": "Wood_Fir_Trunk_Half",
      "rotation": 8
    },
    {
      "x": -16,
      "y": 3,
      "z": 1,
      "name": "Wood_Fir_Trunk_Full_Locked",
      "support": 15,
      "rotation": 5
    },
    {
      "x": -16,
      "y": 7,
      "z": 1,
      "name": "Wood_Fir_Trunk_Full_Locked",
      "support": 15,
      "rotation": 5
    },
    {
      "x": -16,
      "y": 14,
      "z": 1,
      "name": "Wood_Fir_Trunk_Full_Locked",
      "support": 15,
      "rotation": 5
    },
    {
      "x": -16,
      "y": 4,
      "z": 2,
      "name": "Wood_Blackwood_Planks"
    },
    {
      "x": -16,
      "y": 7,
      "z": 2,
      "name": "Wood_Deadwood_Planks"
    },
    {
      "x": -16,
      "y": 14,
      "z": 2,
      "name": "Wood_Deadwood_Planks_Half",
      "rotation": 8
    },
    {
      "x": -16,
      "y": 4,
      "z": 3,
      "name": "Wood_Blackwood_Planks"
    },
    {
      "x": -16,
      "y": 7,
      "z": 3,
      "name": "Wood_Deadwood_Planks"
    },
    {
      "x": -16,
      "y": 14,
      "z": 3,
      "name": "Wood_Deadwood_Planks_Half",
      "rotation": 8
    },
    {
      "x": -16,
      "y": 5,
      "z": 4,
      "name": "Wood_Fir_Trunk_Full_Locked",
      "support": 15,
      "rotation": 5
    },
    {
      "x": -16,
      "y": 7,
      "z": 4,
      "name": "Wood_Fir_Trunk_Full_Locked",
      "support": 15,
      "rotation": 5
    },
    {
      "x": -16,
      "y": 14,
      "z": 4,
      "name": "Wood_Fir_Trunk_Full_Locked",
      "support": 15,
      "rotation": 5
    },
    {
      "x": -16,
      "y": 6,
      "z": 5,
      "name": "Wood_Blackwood_Planks"
    },
    {
      "x": -16,
      "y": 7,
      "z": 5,
      "name": "Wood_Deadwood_Planks"
    },
    {
      "x": -16,
      "y": 11,
      "z": 5,
      "name": "Wood_Deadwood_Planks_Half",
      "rotation": 8
    },
    {
      "x": -16,
      "y": 14,
      "z": 5,
      "name": "Wood_Deadwood_Planks_Half",
      "rotation": 8
    },
    {
      "x": -16,
      "y": 6,
      "z": 6,
      "name": "Wood_Blackwood_Planks"
    },
    {
      "x": -16,
      "y": 7,
      "z": 6,
      "name": "Wood_Deadwood_Planks"
    },
    {
      "x": -16,
      "y": 11,
      "z": 6,
      "name": "Wood_Deadwood_Planks_Half",
      "rotation": 8
    },
    {
      "x": -16,
      "y": 14,
      "z": 6,
      "name": "Wood_Deadwood_Planks_Half",
      "rotation": 8
    },
    {
      "x": -16,
      "y": 7,
      "z": 7,
      "name": "Wood_Fir_Trunk_Full_Locked",
      "support": 15,
      "rotation": 5
    },
    {
      "x": -16,
      "y": 11,
      "z": 7,
      "name": "Wood_Fir_Trunk_Full_Locked",
      "support": 15,
      "rotation": 5
    },
    {
      "x": -16,
      "y": 14,
      "z": 7,
      "name": "Wood_Fir_Trunk_Full_Locked",
      "support": 15,
      "rotation": 5
    },
    {
      "x": -16,
      "y": 8,
      "z": 8,
      "name": "Wood_Blackwood_Planks"
    },
    {
      "x": -16,
      "y": 9,
      "z": 8,
      "name": "Wood_Blackwood_Planks"
    },
    {
      "x": -16,
      "y": 11,
      "z": 8,
      "name": "Wood_Deadwood_Planks"
    },
    {
      "x": -16,
      "y": 9,
      "z": 9,
      "name": "Wood_Fir_Trunk_Full_Locked",
      "support": 15,
      "rotation": 5
    },
    {
      "x": -16,
      "y": 10,
      "z": 9,
      "name": "Wood_Fir_Trunk_Full_Locked",
      "support": 15,
      "rotation": 5
    },
    {
      "x": -16,
      "y": 11,
      "z": 9,
      "name": "Wood_Fir_Trunk_Full_Locked",
      "support": 15,
      "rotation": 5
    },
    {
      "x": -16,
      "y": 12,
      "z": 9,
      "name": "Wood_Blackwood_Planks"
    },
    {
      "x": -16,
      "y": 13,
      "z": 9,
      "name": "Wood_Blackwood_Planks"
    },
    {
      "x": -16,
      "y": 14,
      "z": 9,
      "name": "Wood_Fir_Trunk_Full_Locked",
      "support": 15,
      "rotation": 5
    },
    {
      "x": -16,
      "y": 15,
      "z": 9,
      "name": "Wood_Blackwood_Fence"
    },
    {
      "x": -15,
      "y": 8,
      "z": -7,
      "name": "Wood_Fir_Trunk_Full_Locked",
      "support": 15,
      "rotation": 5
    },
    {
      "x": -15,
      "y": 11,
      "z": -7,
      "name": "Wood_Fir_Trunk_Full_Locked",
      "rotation": 5
    },
    {
      "x": -15,
      "y": 6,
      "z": -5,
      "name": "Wood_Fir_Trunk_Full_Locked",
      "support": 15,
      "rotation": 5
    },
    {
      "x": -15,
      "y": 7,
      "z": -5,
      "name": "Wood_Fir_Trunk_Full_Locked",
      "support": 15,
      "rotation": 5
    },
    {
      "x": -15,
      "y": 4,
      "z": -2,
      "name": "Wood_Fir_Trunk_Full_Locked",
      "support": 15,
      "rotation": 5
    },
    {
      "x": -15,
      "y": 5,
      "z": -2,
      "name": "Wood_Fir_Trunk_Full_Locked",
      "support": 15,
      "rotation": 5
    },
    {
      "x": -15,
      "y": 2,
      "z": 1,
      "name": "Wood_Fir_Trunk_Full_Locked",
      "support": 15,
      "rotation": 5
    },
    {
      "x": -15,
      "y": 3,
      "z": 1,
      "name": "Wood_Fir_Trunk_Full_Locked",
      "support": 15,
      "rotation": 2
    },
    {
      "x": -15,
      "y": 7,
      "z": 1,
      "name": "Wood_Fir_Trunk_Full_Locked",
      "support": 15,
      "rotation": 5
    },
    {
      "x": -15,
      "y": 8,
      "z": 1,
      "name": "Wood_Deadwood_Planks_Half"
    },
    {
      "x": -15,
      "y": 14,
      "z": 1,
      "name": "Wood_Fir_Trunk_Full_Locked",
      "support": 15,
      "rotation": 5
    },
    {
      "x": -15,
      "y": 3,
      "z": 2,
      "name": "Wood_Blackwood_Planks"
    },
    {
      "x": -15,
      "y": 7,
      "z": 2,
      "name": "Wood_Deadwood_Planks"
    },
    {
      "x": -15,
      "y": 8,
      "z": 2,
      "name": "Wood_Deadwood_Planks_Half"
    },
    {
      "x": -15,
      "y": 14,
      "z": 2,
      "name": "Wood_Deadwood_Planks_Half",
      "rotation": 8
    },
    {
      "x": -15,
      "y": 4,
      "z": 3,
      "name": "Wood_Blackwood_Planks"
    },
    {
      "x": -15,
      "y": 7,
      "z": 3,
      "name": "Wood_Deadwood_Planks"
    },
    {
      "x": -15,
      "y": 8,
      "z": 3,
      "name": "Wood_Deadwood_Planks_Half"
    },
    {
      "x": -15,
      "y": 14,
      "z": 3,
      "name": "Wood_Deadwood_Planks_Half",
      "rotation": 8
    },
    {
      "x": -15,
      "y": 4,
      "z": 4,
      "name": "Wood_Fir_Trunk_Full_Locked",
      "support": 15,
      "rotation": 5
    },
    {
      "x": -15,
      "y": 5,
      "z": 4,
      "name": "Wood_Fir_Trunk_Full_Locked",
      "support": 15,
      "rotation": 5
    },
    {
      "x": -15,
      "y": 7,
      "z": 4,
      "name": "Wood_Fir_Trunk_Full_Locked",
      "support": 15,
      "rotation": 5
    },
    {
      "x": -15,
      "y": 8,
      "z": 4,
      "name": "Wood_Fir_Trunk_Full_Locked",
      "support": 15,
      "rotation": 5
    },
    {
      "x": -15,
      "y": 14,
      "z": 4,
      "name": "Wood_Fir_Trunk_Full_Locked",
      "support": 15,
      "rotation": 5
    },
    {
      "x": -15,
      "y": 5,
      "z": 5,
      "name": "Wood_Blackwood_Planks"
    },
    {
      "x": -15,
      "y": 7,
      "z": 5,
      "name": "Wood_Deadwood_Planks_Half",
      "rotation": 8
    },
    {
      "x": -15,
      "y": 11,
      "z": 5,
      "name": "Wood_Deadwood_Planks_Half",
      "rotation": 8
    },
    {
      "x": -15,
      "y": 14,
      "z": 5,
      "name": "Wood_Deadwood_Planks_Half",
      "rotation": 8
    },
    {
      "x": -15,
      "y": 6,
      "z": 6,
      "name": "Wood_Blackwood_Planks"
    },
    {
      "x": -15,
      "y": 7,
      "z": 6,
      "name": "Wood_Deadwood_Planks_Half",
      "rotation": 8
    },
    {
      "x": -15,
      "y": 11,
      "z": 6,
      "name": "Wood_Deadwood_Planks_Half",
      "rotation": 8
    },
    {
      "x": -15,
      "y": 14,
      "z": 6,
      "name": "Wood_Deadwood_Planks_Half",
      "rotation": 8
    },
    {
      "x": -15,
      "y": 6,
      "z": 7,
      "name": "Wood_Fir_Trunk_Full_Locked",
      "support": 15,
      "rotation": 5
    },
    {
      "x": -15,
      "y": 7,
      "z": 7,
      "name": "Wood_Fir_Trunk_Full_Locked",
      "support": 15,
      "rotation": 5
    },
    {
      "x": -15,
      "y": 11,
      "z": 7,
      "name": "Wood_Fir_Trunk_Full_Locked",
      "support": 15,
      "rotation": 5
    },
    {
      "x": -15,
      "y": 14,
      "z": 7,
      "name": "Wood_Fir_Trunk_Full_Locked",
      "support": 15,
      "rotation": 5
    },
    {
      "x": -15,
      "y": 7,
      "z": 8,
      "name": "Wood_Blackwood_Planks"
    },
    {
      "x": -15,
      "y": 8,
      "z": 8,
      "name": "Wood_Blackwood_Planks"
    },
    {
      "x": -15,
      "y": 11,
      "z": 8,
      "name": "Wood_Deadwood_Planks"
    },
    {
      "x": -15,
      "y": 8,
      "z": 9,
      "name": "Wood_Fir_Trunk_Full_Locked",
      "support": 15,
      "rotation": 5
    },
    {
      "x": -15,
      "y": 9,
      "z": 9,
      "name": "Wood_Blackwood_Planks"
    },
    {
      "x": -15,
      "y": 10,
      "z": 9,
      "name": "Wood_Blackwood_Planks"
    },
    {
      "x": -15,
      "y": 11,
      "z": 9,
      "name": "Wood_Fir_Trunk_Full_Locked",
      "rotation": 5
    },
    {
      "x": -15,
      "y": 12,
      "z": 9,
      "name": "Wood_Blackwood_Planks"
    },
    {
      "x": -15,
      "y": 13,
      "z": 9,
      "name": "Wood_Blackwood_Planks"
    },
    {
      "x": -15,
      "y": 14,
      "z": 9,
      "name": "Wood_Fir_Trunk_Full_Locked",
      "support": 15,
      "rotation": 5
    },
    {
      "x": -15,
      "y": 15,
      "z": 9,
      "name": "Wood_Blackwood_Fence"
    },
    {
      "x": -14,
      "y": 8,
      "z": -7,
      "name": "Wood_Fir_Trunk_Full_Locked",
      "support": 15,
      "rotation": 5
    },
    {
      "x": -14,
      "y": 11,
      "z": -7,
      "name": "Wood_Fir_Trunk_Full_Locked",
      "rotation": 5
    },
    {
      "x": -14,
      "y": 6,
      "z": -5,
      "name": "Wood_Fir_Trunk_Full_Locked",
      "support": 15,
      "rotation": 5
    },
    {
      "x": -14,
      "y": 4,
      "z": -2,
      "name": "Wood_Fir_Trunk_Full_Locked",
      "support": 15,
      "rotation": 5
    },
    {
      "x": -14,
      "y": 2,
      "z": 1,
      "name": "Wood_Fir_Trunk_Full_Locked",
      "support": 15,
      "rotation": 5
    },
    {
      "x": -14,
      "y": 3,
      "z": 1,
      "name": "Wood_Blackwood_Planks"
    },
    {
      "x": -14,
      "y": 7,
      "z": 1,
      "name": "Wood_Fir_Trunk_Full_Locked",
      "support": 15,
      "rotation": 5
    },
    {
      "x": -14,
      "y": 8,
      "z": 1,
      "name": "Wood_Deadwood_Planks"
    },
    {
      "x": -14,
      "y": 14,
      "z": 1,
      "name": "Wood_Fir_Trunk_Full_Locked",
      "support": 15,
      "rotation": 5
    },
    {
      "x": -14,
      "y": 3,
      "z": 2,
      "name": "Wood_Blackwood_Planks"
    },
    {
      "x": -14,
      "y": 8,
      "z": 2,
      "name": "Wood_Deadwood_Planks"
    },
    {
      "x": -14,
      "y": 14,
      "z": 2,
      "name": "Wood_Deadwood_Planks_Half",
      "rotation": 8
    },
    {
      "x": -14,
      "y": 3,
      "z": 3,
      "name": "Wood_Blackwood_Planks"
    },
    {
      "x": -14,
      "y": 8,
      "z": 3,
      "name": "Wood_Deadwood_Planks"
    },
    {
      "x": -14,
      "y": 14,
      "z": 3,
      "name": "Wood_Deadwood_Planks_Half",
      "rotation": 8
    },
    {
      "x": -14,
      "y": 4,
      "z": 4,
      "name": "Wood_Fir_Trunk_Full_Locked",
      "support": 15,
      "rotation": 5
    },
    {
      "x": -14,
      "y": 7,
      "z": 4,
      "name": "Wood_Fir_Trunk_Full_Locked",
      "support": 15,
      "rotation": 5
    },
    {
      "x": -14,
      "y": 8,
      "z": 4,
      "name": "Wood_Fir_Trunk_Full_Locked",
      "support": 15,
      "rotation": 5
    },
    {
      "x": -14,
      "y": 9,
      "z": 4,
      "name": "Wood_Fir_Trunk_Half"
    },
    {
      "x": -14,
      "y": 14,
      "z": 4,
      "name": "Wood_Fir_Trunk_Full_Locked",
      "support": 15,
      "rotation": 5
    },
    {
      "x": -14,
      "y": 5,
      "z": 5,
      "name": "Wood_Blackwood_Planks"
    },
    {
      "x": -14,
      "y": 7,
      "z": 5,
      "name": "Wood_Deadwood_Planks_Half",
      "rotation": 8
    },
    {
      "x": -14,
      "y": 11,
      "z": 5,
      "name": "Wood_Deadwood_Planks_Half",
      "rotation": 8
    },
    {
      "x": -14,
      "y": 14,
      "z": 5,
      "name": "Wood_Deadwood_Planks_Half",
      "rotation": 8
    },
    {
      "x": -14,
      "y": 5,
      "z": 6,
      "name": "Wood_Blackwood_Planks"
    },
    {
      "x": -14,
      "y": 7,
      "z": 6,
      "name": "Wood_Deadwood_Planks_Half",
      "rotation": 8
    },
    {
      "x": -14,
      "y": 11,
      "z": 6,
      "name": "Wood_Deadwood_Planks_Half",
      "rotation": 8
    },
    {
      "x": -14,
      "y": 14,
      "z": 6,
      "name": "Wood_Deadwood_Planks_Half",
      "rotation": 8
    },
    {
      "x": -14,
      "y": 6,
      "z": 7,
      "name": "Wood_Fir_Trunk_Full_Locked",
      "support": 15,
      "rotation": 5
    },
    {
      "x": -14,
      "y": 7,
      "z": 7,
      "name": "Wood_Fir_Trunk_Full_Locked",
      "support": 15,
      "rotation": 5
    },
    {
      "x": -14,
      "y": 11,
      "z": 7,
      "name": "Wood_Fir_Trunk_Full_Locked",
      "support": 15,
      "rotation": 5
    },
    {
      "x": -14,
      "y": 14,
      "z": 7,
      "name": "Wood_Fir_Trunk_Full_Locked",
      "support": 15,
      "rotation": 5
    },
    {
      "x": -14,
      "y": 7,
      "z": 8,
      "name": "Wood_Blackwood_Planks"
    },
    {
      "x": -14,
      "y": 11,
      "z": 8,
      "name": "Wood_Deadwood_Planks"
    },
    {
      "x": -14,
      "y": 8,
      "z": 9,
      "name": "Wood_Fir_Trunk_Full_Locked",
      "support": 15,
      "rotation": 5
    },
    {
      "x": -14,
      "y": 9,
      "z": 9,
      "name": "Furniture_Temple_Dark_Window"
    },
    {
      "x": -14,
      "y": 10,
      "z": 9,
      "name": "Wood_Blackwood_Planks"
    },
    {
      "x": -14,
      "y": 11,
      "z": 9,
      "name": "Wood_Fir_Trunk_Full_Locked",
      "rotation": 5
    },
    {
      "x": -14,
      "y": 12,
      "z": 9,
      "name": "Wood_Blackwood_Planks"
    },
    {
      "x": -14,
      "y": 13,
      "z": 9,
      "name": "Wood_Blackwood_Planks"
    },
    {
      "x": -14,
      "y": 14,
      "z": 9,
      "name": "Wood_Fir_Trunk_Full_Locked",
      "support": 15,
      "rotation": 5
    },
    {
      "x": -14,
      "y": 15,
      "z": 9,
      "name": "Wood_Blackwood_Fence"
    },
    {
      "x": -13,
      "y": 7,
      "z": -7,
      "name": "Wood_Fir_Trunk_Full_Locked",
      "support": 15,
      "rotation": 5
    },
    {
      "x": -13,
      "y": 8,
      "z": -7,
      "name": "Wood_Fir_Trunk_Full_Locked",
      "support": 15,
      "rotation": 5
    },
    {
      "x": -13,
      "y": 11,
      "z": -7,
      "name": "Wood_Fir_Trunk_Full_Locked",
      "rotation": 5
    },
    {
      "x": -13,
      "y": 5,
      "z": -5,
      "name": "Wood_Fir_Trunk_Full_Locked",
      "support": 15,
      "rotation": 5
    },
    {
      "x": -13,
      "y": 6,
      "z": -5,
      "name": "Wood_Fir_Trunk_Full_Locked",
      "support": 15,
      "rotation": 5
    },
    {
      "x": -13,
      "y": 3,
      "z": -2,
      "name": "Wood_Fir_Trunk_Full_Locked",
      "support": 15,
      "rotation": 5
    },
    {
      "x": -13,
      "y": 4,
      "z": -2,
      "name": "Wood_Fir_Trunk_Full_Locked",
      "support": 15,
      "rotation": 5
    },
    {
      "x": -13,
      "y": 1,
      "z": 1,
      "name": "Wood_Fir_Trunk_Half",
      "rotation": 8
    },
    {
      "x": -13,
      "y": 2,
      "z": 1,
      "name": "Wood_Fir_Trunk_Full_Locked",
      "support": 15,
      "rotation": 5
    },
    {
      "x": -13,
      "y": 7,
      "z": 1,
      "name": "Wood_Fir_Trunk_Full_Locked",
      "support": 15,
      "rotation": 5
    },
    {
      "x": -13,
      "y": 8,
      "z": 1,
      "name": "Wood_Deadwood_Planks"
    },
    {
      "x": -13,
      "y": 9,
      "z": 1,
      "name": "Wood_Deadwood_Planks_Half"
    },
    {
      "x": -13,
      "y": 14,
      "z": 1,
      "name": "Wood_Fir_Trunk_Full_Locked",
      "support": 15,
      "rotation": 5
    },
    {
      "x": -13,
      "y": 8,
      "z": 2,
      "name": "Wood_Deadwood_Planks"
    },
    {
      "x": -13,
      "y": 9,
      "z": 2,
      "name": "Wood_Deadwood_Planks_Half"
    },
    {
      "x": -13,
      "y": 14,
      "z": 2,
      "name": "Wood_Deadwood_Planks_Half",
      "rotation": 8
    },
    {
      "x": -13,
      "y": 8,
      "z": 3,
      "name": "Wood_Deadwood_Planks"
    },
    {
      "x": -13,
      "y": 9,
      "z": 3,
      "name": "Wood_Deadwood_Planks_Half"
    },
    {
      "x": -13,
      "y": 14,
      "z": 3,
      "name": "Wood_Deadwood_Planks_Half",
      "rotation": 8
    },
    {
      "x": -13,
      "y": 3,
      "z": 4,
      "name": "Wood_Fir_Trunk_Full_Locked",
      "support": 15,
      "rotation": 5
    },
    {
      "x": -13,
      "y": 4,
      "z": 4,
      "name": "Wood_Fir_Trunk_Full_Locked",
      "support": 15,
      "rotation": 5
    },
    {
      "x": -13,
      "y": 7,
      "z": 4,
      "name": "Wood_Fir_Trunk_Full_Locked",
      "support": 15,
      "rotation": 5
    },
    {
      "x": -13,
      "y": 8,
      "z": 4,
      "name": "Wood_Fir_Trunk_Full_Locked",
      "support": 15,
      "rotation": 5
    },
    {
      "x": -13,
      "y": 9,
      "z": 4,
      "name": "Wood_Fir_Trunk_Full_Locked",
      "support": 15,
      "rotation": 5
    },
    {
      "x": -13,
      "y": 14,
      "z": 4,
      "name": "Wood_Fir_Trunk_Full_Locked",
      "support": 15,
      "rotation": 5
    },
    {
      "x": -13,
      "y": 4,
      "z": 5,
      "name": "Wood_Blackwood_Planks"
    },
    {
      "x": -13,
      "y": 5,
      "z": 5,
      "name": "Wood_Blackwood_Planks"
    },
    {
      "x": -13,
      "y": 7,
      "z": 5,
      "name": "Wood_Deadwood_Planks_Half",
      "rotation": 8
    },
    {
      "x": -13,
      "y": 11,
      "z": 5,
      "name": "Wood_Deadwood_Planks_Half",
      "rotation": 8
    },
    {
      "x": -13,
      "y": 14,
      "z": 5,
      "name": "Wood_Deadwood_Planks_Half",
      "rotation": 8
    },
    {
      "x": -13,
      "y": 5,
      "z": 6,
      "name": "Wood_Blackwood_Planks"
    },
    {
      "x": -13,
      "y": 7,
      "z": 6,
      "name": "Wood_Deadwood_Planks_Half",
      "rotation": 8
    },
    {
      "x": -13,
      "y": 11,
      "z": 6,
      "name": "Wood_Deadwood_Planks_Half",
      "rotation": 8
    },
    {
      "x": -13,
      "y": 14,
      "z": 6,
      "name": "Wood_Deadwood_Planks_Half",
      "rotation": 8
    },
    {
      "x": -13,
      "y": 5,
      "z": 7,
      "name": "Wood_Fir_Trunk_Full_Locked",
      "support": 15,
      "rotation": 5
    },
    {
      "x": -13,
      "y": 6,
      "z": 7,
      "name": "Wood_Fir_Trunk_Full_Locked",
      "support": 15,
      "rotation": 5
    },
    {
      "x": -13,
      "y": 7,
      "z": 7,
      "name": "Wood_Fir_Trunk_Full_Locked",
      "support": 15,
      "rotation": 5
    },
    {
      "x": -13,
      "y": 11,
      "z": 7,
      "name": "Wood_Fir_Trunk_Full_Locked",
      "support": 15,
      "rotation": 5
    },
    {
      "x": -13,
      "y": 14,
      "z": 7,
      "name": "Wood_Fir_Trunk_Full_Locked",
      "support": 15,
      "rotation": 5
    },
    {
      "x": -13,
      "y": 6,
      "z": 8,
      "name": "Wood_Blackwood_Planks"
    },
    {
      "x": -13,
      "y": 7,
      "z": 8,
      "name": "Wood_Blackwood_Planks"
    },
    {
      "x": -13,
      "y": 11,
      "z": 8,
      "name": "Wood_Deadwood_Planks"
    },
    {
      "x": -13,
      "y": 7,
      "z": 9,
      "name": "Wood_Fir_Trunk_Full_Locked",
      "support": 15,
      "rotation": 5
    },
    {
      "x": -13,
      "y": 8,
      "z": 9,
      "name": "Wood_Fir_Trunk_Full_Locked",
      "support": 15,
      "rotation": 5
    },
    {
      "x": -13,
      "y": 9,
      "z": 9,
      "name": "Wood_Blackwood_Planks"
    },
    {
      "x": -13,
      "y": 10,
      "z": 9,
      "name": "Wood_Blackwood_Planks"
    },
    {
      "x": -13,
      "y": 11,
      "z": 9,
      "name": "Wood_Fir_Trunk_Full_Locked",
      "rotation": 5
    },
    {
      "x": -13,
      "y": 12,
      "z": 9,
      "name": "Wood_Blackwood_Planks"
    },
    {
      "x": -13,
      "y": 13,
      "z": 9,
      "name": "Wood_Blackwood_Planks"
    },
    {
      "x": -13,
      "y": 14,
      "z": 9,
      "name": "Wood_Fir_Trunk_Full_Locked",
      "support": 15,
      "rotation": 5
    },
    {
      "x": -13,
      "y": 15,
      "z": 9,
      "name": "Wood_Blackwood_Fence"
    },
    {
      "x": -12,
      "y": 7,
      "z": -7,
      "name": "Wood_Fir_Trunk_Full_Locked",
      "support": 15,
      "rotation": 5
    },
    {
      "x": -12,
      "y": 11,
      "z": -7,
      "name": "Wood_Fir_Trunk_Full_Locked",
      "rotation": 5
    },
    {
      "x": -12,
      "y": 5,
      "z": -5,
      "name": "Wood_Fir_Trunk_Full_Locked",
      "support": 15,
      "rotation": 5
    },
    {
      "x": -12,
      "y": 3,
      "z": -2,
      "name": "Wood_Fir_Trunk_Full_Locked",
      "support": 15,
      "rotation": 5
    },
    {
      "x": -12,
      "y": 1,
      "z": 1,
      "name": "Wood_Fir_Trunk_Half",
      "rotation": 8
    },
    {
      "x": -12,
      "y": 2,
      "z": 1,
      "name": "Wood_Fir_Trunk_Full_Locked",
      "support": 15,
      "rotation": 5
    },
    {
      "x": -12,
      "y": 7,
      "z": 1,
      "name": "Wood_Fir_Trunk_Full_Locked",
      "support": 15,
      "rotation": 5
    },
    {
      "x": -12,
      "y": 9,
      "z": 1,
      "name": "Wood_Deadwood_Planks"
    },
    {
      "x": -12,
      "y": 14,
      "z": 1,
      "name": "Wood_Fir_Trunk_Full_Locked",
      "support": 15,
      "rotation": 4
    },
    {
      "x": -12,
      "y": 9,
      "z": 2,
      "name": "Wood_Deadwood_Planks"
    },
    {
      "x": -12,
      "y": 14,
      "z": 2,
      "name": "Wood_Fir_Trunk_Full_Locked",
      "support": 15,
      "rotation": 4
    },
    {
      "x": -12,
      "y": 9,
      "z": 3,
      "name": "Wood_Deadwood_Planks"
    },
    {
      "x": -12,
      "y": 14,
      "z": 3,
      "name": "Wood_Fir_Trunk_Full_Locked",
      "support": 15,
      "rotation": 4
    },
    {
      "x": -12,
      "y": 3,
      "z": 4,
      "name": "Wood_Fir_Trunk_Full_Locked",
      "support": 15,
      "rotation": 5
    },
    {
      "x": -12,
      "y": 7,
      "z": 4,
      "name": "Wood_Fir_Trunk_Full_Locked",
      "support": 15,
      "rotation": 5
    },
    {
      "x": -12,
      "y": 8,
      "z": 4,
      "name": "Wood_Fir_Trunk_Full_Locked",
      "support": 15,
      "rotation": 5
    },
    {
      "x": -12,
      "y": 9,
      "z": 4,
      "name": "Wood_Fir_Trunk_Full_Locked",
      "support": 15,
      "rotation": 5
    },
    {
      "x": -12,
      "y": 10,
      "z": 4,
      "name": "Wood_Fir_Trunk_Full_Locked",
      "support": 15
    },
    {
      "x": -12,
      "y": 11,
      "z": 4,
      "name": "Wood_Fir_Trunk_Full_Locked",
      "support": 15
    },
    {
      "x": -12,
      "y": 12,
      "z": 4,
      "name": "Wood_Fir_Trunk_Full_Locked",
      "support": 15
    },
    {
      "x": -12,
      "y": 13,
      "z": 4,
      "name": "Wood_Fir_Trunk_Full_Locked",
      "support": 15
    },
    {
      "x": -12,
      "y": 14,
      "z": 4,
      "name": "Wood_Fir_Trunk_Full_Locked",
      "support": 15,
      "rotation": 4
    },
    {
      "x": -12,
      "y": 4,
      "z": 5,
      "name": "Wood_Blackwood_Planks"
    },
    {
      "x": -12,
      "y": 5,
      "z": 5,
      "name": "Wood_Blackwood_Planks"
    },
    {
      "x": -12,
      "y": 7,
      "z": 5,
      "name": "Wood_Deadwood_Planks_Half",
      "rotation": 8
    },
    {
      "x": -12,
      "y": 11,
      "z": 5,
      "name": "Wood_Fir_Trunk_Full_Locked",
      "support": 15,
      "rotation": 4
    },
    {
      "x": -12,
      "y": 12,
      "z": 5,
      "name": "*Furniture_Human_Ruins_Door_State_Definitions_CloseDoorOut",
      "rotation": 3
    },
    {
      "x": -12,
      "y": 13,
      "z": 5,
      "name": "*Furniture_Human_Ruins_Door_State_Definitions_CloseDoorOut",
      "filler": 1024,
      "rotation": 3
    },
    {
      "x": -12,
      "y": 14,
      "z": 5,
      "name": "Wood_Fir_Trunk_Full_Locked",
      "support": 15,
      "rotation": 4
    },
    {
      "x": -12,
      "y": 4,
      "z": 6,
      "name": "Wood_Blackwood_Planks"
    },
    {
      "x": -12,
      "y": 5,
      "z": 6,
      "name": "Wood_Blackwood_Planks"
    },
    {
      "x": -12,
      "y": 7,
      "z": 6,
      "name": "Wood_Deadwood_Planks_Half",
      "rotation": 8
    },
    {
      "x": -12,
      "y": 11,
      "z": 6,
      "name": "Wood_Fir_Trunk_Full_Locked",
      "support": 15,
      "rotation": 4
    },
    {
      "x": -12,
      "y": 12,
      "z": 6,
      "name": "Wood_Deadwood_Planks_Half",
      "rotation": 5
    },
    {
      "x": -12,
      "y": 13,
      "z": 6,
      "name": "Furniture_Temple_Dark_Window",
      "rotation": 1
    },
    {
      "x": -12,
      "y": 14,
      "z": 6,
      "name": "Wood_Fir_Trunk_Full_Locked",
      "support": 15,
      "rotation": 4
    },
    {
      "x": -12,
      "y": 5,
      "z": 7,
      "name": "Wood_Fir_Trunk_Full_Locked",
      "support": 15,
      "rotation": 5
    },
    {
      "x": -12,
      "y": 7,
      "z": 7,
      "name": "Wood_Fir_Trunk_Full_Locked",
      "support": 15,
      "rotation": 5
    },
    {
      "x": -12,
      "y": 11,
      "z": 7,
      "name": "Wood_Fir_Trunk_Full_Locked",
      "support": 15,
      "rotation": 5
    },
    {
      "x": -12,
      "y": 12,
      "z": 7,
      "name": "Wood_Fir_Trunk_Full_Locked",
      "support": 15
    },
    {
      "x": -12,
      "y": 13,
      "z": 7,
      "name": "Wood_Fir_Trunk_Full_Locked",
      "support": 15
    },
    {
      "x": -12,
      "y": 14,
      "z": 7,
      "name": "Wood_Fir_Trunk_Full_Locked",
      "support": 15
    },
    {
      "x": -12,
      "y": 6,
      "z": 8,
      "name": "Wood_Blackwood_Planks"
    },
    {
      "x": -12,
      "y": 11,
      "z": 8,
      "name": "Wood_Fir_Trunk_Full_Locked",
      "support": 15,
      "rotation": 4
    },
    {
      "x": -12,
      "y": 12,
      "z": 8,
      "name": "Wood_Deadwood_Planks"
    },
    {
      "x": -12,
      "y": 13,
      "z": 8,
      "name": "Wood_Deadwood_Planks"
    },
    {
      "x": -12,
      "y": 14,
      "z": 8,
      "name": "Wood_Fir_Trunk_Full_Locked",
      "support": 15,
      "rotation": 4
    },
    {
      "x": -12,
      "y": 7,
      "z": 9,
      "name": "Wood_Fir_Trunk_Full_Locked",
      "support": 15,
      "rotation": 5
    },
    {
      "x": -12,
      "y": 8,
      "z": 9,
      "name": "Wood_Fir_Trunk_Full_Locked",
      "support": 15
    },
    {
      "x": -12,
      "y": 9,
      "z": 9,
      "name": "Wood_Fir_Trunk_Full_Locked",
      "support": 15
    },
    {
      "x": -12,
      "y": 10,
      "z": 9,
      "name": "Wood_Fir_Trunk_Full_Locked",
      "support": 15
    },
    {
      "x": -12,
      "y": 11,
      "z": 9,
      "name": "Wood_Fir_Trunk_Full_Locked",
      "rotation": 5
    },
    {
      "x": -12,
      "y": 12,
      "z": 9,
      "name": "Wood_Fir_Trunk_Full_Locked",
      "support": 15
    },
    {
      "x": -12,
      "y": 13,
      "z": 9,
      "name": "Wood_Fir_Trunk_Full_Locked",
      "support": 15
    },
    {
      "x": -12,
      "y": 14,
      "z": 9,
      "name": "Wood_Fir_Trunk_Full_Locked",
      "support": 15
    },
    {
      "x": -12,
      "y": 15,
      "z": 9,
      "name": "Wood_Blackwood_Stairs",
      "rotation": 2
    },
    {
      "x": -11,
      "y": 11,
      "z": -8,
      "name": "Wood_Fir_Trunk_Full_Locked",
      "rotation": 5
    },
    {
      "x": -11,
      "y": 6,
      "z": -7,
      "name": "Wood_Fir_Trunk_Full_Locked",
      "support": 15,
      "rotation": 5
    },
    {
      "x": -11,
      "y": 7,
      "z": -7,
      "name": "Wood_Fir_Trunk_Full_Locked",
      "support": 15,
      "rotation": 5
    },
    {
      "x": -11,
      "y": 4,
      "z": -5,
      "name": "Wood_Fir_Trunk_Full_Locked",
      "support": 15,
      "rotation": 5
    },
    {
      "x": -11,
      "y": 5,
      "z": -5,
      "name": "Wood_Fir_Trunk_Full_Locked",
      "support": 15,
      "rotation": 5
    },
    {
      "x": -11,
      "y": 2,
      "z": -2,
      "name": "Wood_Fir_Trunk_Full_Locked",
      "support": 15,
      "rotation": 5
    },
    {
      "x": -11,
      "y": 3,
      "z": -2,
      "name": "Wood_Fir_Trunk_Full_Locked",
      "support": 15,
      "rotation": 5
    },
    {
      "x": -11,
      "y": 1,
      "z": 1,
      "name": "Wood_Fir_Trunk_Full_Locked",
      "support": 15,
      "rotation": 5
    },
    {
      "x": -11,
      "y": 2,
      "z": 1,
      "name": "Wood_Fir_Trunk_Full_Locked",
      "support": 15,
      "rotation": 2
    },
    {
      "x": -11,
      "y": 7,
      "z": 1,
      "name": "Wood_Fir_Trunk_Full_Locked",
      "support": 15,
      "rotation": 5
    },
    {
      "x": -11,
      "y": 9,
      "z": 1,
      "name": "Wood_Deadwood_Planks"
    },
    {
      "x": -11,
      "y": 10,
      "z": 1,
      "name": "Wood_Deadwood_Planks_Half"
    },
    {
      "x": -11,
      "y": 9,
      "z": 2,
      "name": "Wood_Deadwood_Planks"
    },
    {
      "x": -11,
      "y": 10,
      "z": 2,
      "name": "Wood_Deadwood_Planks_Half"
    },
    {
      "x": -11,
      "y": 9,
      "z": 3,
      "name": "Wood_Deadwood_Planks"
    },
    {
      "x": -11,
      "y": 10,
      "z": 3,
      "name": "Wood_Deadwood_Planks_Half"
    },
    {
      "x": -11,
      "y": 2,
      "z": 4,
      "name": "Wood_Fir_Trunk_Full_Locked",
      "support": 15,
      "rotation": 5
    },
    {
      "x": -11,
      "y": 3,
      "z": 4,
      "name": "Wood_Fir_Trunk_Full_Locked",
      "support": 15,
      "rotation": 5
    },
    {
      "x": -11,
      "y": 7,
      "z": 4,
      "name": "Wood_Fir_Trunk_Full_Locked",
      "support": 15,
      "rotation": 5
    },
    {
      "x": -11,
      "y": 9,
      "z": 4,
      "name": "Wood_Fir_Trunk_Full_Locked",
      "support": 15,
      "rotation": 5
    },
    {
      "x": -11,
      "y": 10,
      "z": 4,
      "name": "Wood_Fir_Trunk_Full_Locked",
      "support": 15,
      "rotation": 5
    },
    {
      "x": -11,
      "y": 3,
      "z": 5,
      "name": "Wood_Blackwood_Planks"
    },
    {
      "x": -11,
      "y": 4,
      "z": 5,
      "name": "Wood_Blackwood_Planks"
    },
    {
      "x": -11,
      "y": 7,
      "z": 5,
      "name": "Wood_Deadwood_Planks_Half",
      "rotation": 8
    },
    {
      "x": -11,
      "y": 11,
      "z": 5,
      "name": "Wood_Deadwood_Planks_Half",
      "rotation": 8
    },
    {
      "x": -11,
      "y": 4,
      "z": 6,
      "name": "Wood_Blackwood_Planks"
    },
    {
      "x": -11,
      "y": 7,
      "z": 6,
      "name": "Wood_Deadwood_Planks_Half",
      "rotation": 8
    },
    {
      "x": -11,
      "y": 11,
      "z": 6,
      "name": "Wood_Deadwood_Planks_Half",
      "rotation": 8
    },
    {
      "x": -11,
      "y": 4,
      "z": 7,
      "name": "Wood_Fir_Trunk_Full_Locked",
      "support": 15,
      "rotation": 5
    },
    {
      "x": -11,
      "y": 5,
      "z": 7,
      "name": "Wood_Fir_Trunk_Full_Locked",
      "support": 15,
      "rotation": 5
    },
    {
      "x": -11,
      "y": 7,
      "z": 7,
      "name": "Wood_Fir_Trunk_Full_Locked",
      "support": 15,
      "rotation": 5
    },
    {
      "x": -11,
      "y": 11,
      "z": 7,
      "name": "Wood_Fir_Trunk_Full_Locked",
      "support": 15,
      "rotation": 5
    },
    {
      "x": -11,
      "y": 5,
      "z": 8,
      "name": "Wood_Blackwood_Planks"
    },
    {
      "x": -11,
      "y": 6,
      "z": 8,
      "name": "Wood_Blackwood_Planks"
    },
    {
      "x": -11,
      "y": 11,
      "z": 8,
      "name": "Wood_Deadwood_Planks_Half",
      "rotation": 8
    },
    {
      "x": -11,
      "y": 13,
      "z": 8,
      "name": "Wood_Deadwood_Stairs",
      "rotation": 9
    },
    {
      "x": -11,
      "y": 14,
      "z": 8,
      "name": "Wood_Deadwood_Stairs",
      "rotation": 1
    },
    {
      "x": -11,
      "y": 6,
      "z": 9,
      "name": "Wood_Fir_Trunk_Full_Locked",
      "support": 15,
      "rotation": 5
    },
    {
      "x": -11,
      "y": 7,
      "z": 9,
      "name": "Wood_Fir_Trunk_Full_Locked",
      "support": 15,
      "rotation": 5
    },
    {
      "x": -11,
      "y": 8,
      "z": 9,
      "name": "Wood_Blackwood_Planks"
    },
    {
      "x": -11,
      "y": 9,
      "z": 9,
      "name": "Wood_Blackwood_Planks"
    },
    {
      "x": -11,
      "y": 10,
      "z": 9,
      "name": "Wood_Blackwood_Planks"
    },
    {
      "x": -11,
      "y": 11,
      "z": 9,
      "name": "Wood_Deadwood_Planks_Half",
      "rotation": 8
    },
    {
      "x": -11,
      "y": 8,
      "z": 10,
      "name": "Wood_Blackwood_Planks_Half",
      "rotation": 4
    },
    {
      "x": -11,
      "y": 9,
      "z": 10,
      "name": "Wood_Blackwood_Planks_Half",
      "rotation": 4
    },
    {
      "x": -11,
      "y": 10,
      "z": 10,
      "name": "Wood_Blackwood_Planks"
    },
    {
      "x": -11,
      "y": 11,
      "z": 10,
      "name": "Wood_Fir_Trunk_Full_Locked",
      "rotation": 5
    },
    {
      "x": -11,
      "y": 12,
      "z": 10,
      "name": "Wood_Blackwood_Fence"
    },
    {
      "x": -10,
      "y": 11,
      "z": -8,
      "name": "Wood_Fir_Trunk_Full_Locked",
      "rotation": 5
    },
    {
      "x": -10,
      "y": 6,
      "z": -7,
      "name": "Wood_Fir_Trunk_Full_Locked",
      "support": 15,
      "rotation": 5
    },
    {
      "x": -10,
      "y": 7,
      "z": -7,
      "name": "Wood_Fir_Trunk_Full_Locked",
      "support": 15,
      "rotation": 5
    },
    {
      "x": -10,
      "y": 4,
      "z": -5,
      "name": "Wood_Fir_Trunk_Full_Locked",
      "support": 15,
      "rotation": 5
    },
    {
      "x": -10,
      "y": 2,
      "z": -2,
      "name": "Wood_Fir_Trunk_Full_Locked",
      "support": 15,
      "rotation": 5
    },
    {
      "x": -10,
      "y": 1,
      "z": 1,
      "name": "Wood_Fir_Trunk_Full_Locked",
      "support": 15,
      "rotation": 5
    },
    {
      "x": -10,
      "y": 7,
      "z": 1,
      "name": "Wood_Fir_Trunk_Full_Locked",
      "support": 15,
      "rotation": 5
    },
    {
      "x": -10,
      "y": 10,
      "z": 1,
      "name": "Wood_Deadwood_Planks"
    },
    {
      "x": -10,
      "y": 10,
      "z": 2,
      "name": "Wood_Deadwood_Planks"
    },
    {
      "x": -10,
      "y": 10,
      "z": 3,
      "name": "Wood_Deadwood_Planks"
    },
    {
      "x": -10,
      "y": 2,
      "z": 4,
      "name": "Wood_Fir_Trunk_Full_Locked",
      "support": 15,
      "rotation": 5
    },
    {
      "x": -10,
      "y": 7,
      "z": 4,
      "name": "Wood_Fir_Trunk_Full_Locked",
      "support": 15,
      "rotation": 5
    },
    {
      "x": -10,
      "y": 9,
      "z": 4,
      "name": "Wood_Fir_Trunk_Full_Locked",
      "support": 15,
      "rotation": 5
    },
    {
      "x": -10,
      "y": 10,
      "z": 4,
      "name": "Wood_Fir_Trunk_Full_Locked",
      "support": 15,
      "rotation": 5
    },
    {
      "x": -10,
      "y": 11,
      "z": 4,
      "name": "Wood_Fir_Trunk_Half"
    },
    {
      "x": -10,
      "y": 3,
      "z": 5,
      "name": "Wood_Blackwood_Planks"
    },
    {
      "x": -10,
      "y": 4,
      "z": 5,
      "name": "Wood_Blackwood_Planks"
    },
    {
      "x": -10,
      "y": 7,
      "z": 5,
      "name": "Wood_Deadwood_Planks_Half",
      "rotation": 8
    },
    {
      "x": -10,
      "y": 11,
      "z": 5,
      "name": "Wood_Deadwood_Planks_Half",
      "rotation": 8
    },
    {
      "x": -10,
      "y": 3,
      "z": 6,
      "name": "Wood_Blackwood_Planks"
    },
    {
      "x": -10,
      "y": 7,
      "z": 6,
      "name": "Wood_Deadwood_Planks_Half",
      "rotation": 8
    },
    {
      "x": -10,
      "y": 11,
      "z": 6,
      "name": "Wood_Deadwood_Planks_Half",
      "rotation": 8
    },
    {
      "x": -10,
      "y": 4,
      "z": 7,
      "name": "Wood_Fir_Trunk_Full_Locked",
      "support": 15,
      "rotation": 5
    },
    {
      "x": -10,
      "y": 7,
      "z": 7,
      "name": "Wood_Fir_Trunk_Full_Locked",
      "support": 15,
      "rotation": 5
    },
    {
      "x": -10,
      "y": 11,
      "z": 7,
      "name": "Wood_Fir_Trunk_Full_Locked",
      "support": 15,
      "rotation": 5
    },
    {
      "x": -10,
      "y": 5,
      "z": 8,
      "name": "Wood_Blackwood_Planks"
    },
    {
      "x": -10,
      "y": 11,
      "z": 8,
      "name": "Wood_Deadwood_Planks_Half",
      "rotation": 8
    },
    {
      "x": -10,
      "y": 12,
      "z": 8,
      "name": "Wood_Deadwood_Stairs",
      "rotation": 9
    },
    {
      "x": -10,
      "y": 13,
      "z": 8,
      "name": "Wood_Deadwood_Stairs",
      "rotation": 1
    },
    {
      "x": -10,
      "y": 6,
      "z": 9,
      "name": "Wood_Fir_Trunk_Full_Locked",
      "support": 15,
      "rotation": 5
    },
    {
      "x": -10,
      "y": 7,
      "z": 9,
      "name": "Wood_Fir_Trunk_Full_Locked",
      "support": 15,
      "rotation": 5
    },
    {
      "x": -10,
      "y": 8,
      "z": 9,
      "name": "Wood_Blackwood_Planks"
    },
    {
      "x": -10,
      "y": 10,
      "z": 9,
      "name": "Wood_Blackwood_Planks"
    },
    {
      "x": -10,
      "y": 11,
      "z": 9,
      "name": "Wood_Deadwood_Planks_Half",
      "rotation": 8
    },
    {
      "x": -10,
      "y": 8,
      "z": 10,
      "name": "Wood_Blackwood_Planks_Half",
      "rotation": 4
    },
    {
      "x": -10,
      "y": 9,
      "z": 10,
      "name": "Furniture_Temple_Dark_Window"
    },
    {
      "x": -10,
      "y": 10,
      "z": 10,
      "name": "Wood_Blackwood_Planks"
    },
    {
      "x": -10,
      "y": 11,
      "z": 10,
      "name": "Wood_Fir_Trunk_Full_Locked",
      "rotation": 5
    },
    {
      "x": -10,
      "y": 12,
      "z": 10,
      "name": "Wood_Blackwood_Fence"
    },
    {
      "x": -9,
      "y": 7,
      "z": -8,
      "name": "Wood_Fir_Trunk_Full_Locked",
      "support": 15,
      "rotation": 5
    },
    {
      "x": -9,
      "y": 8,
      "z": -8,
      "name": "Wood_Fir_Trunk_Full_Locked",
      "support": 15,
      "rotation": 2
    },
    {
      "x": -9,
      "y": 9,
      "z": -8,
      "name": "Wood_Fir_Trunk_Full_Locked",
      "support": 15,
      "rotation": 2
    },
    {
      "x": -9,
      "y": 10,
      "z": -8,
      "name": "Wood_Fir_Trunk_Full_Locked",
      "support": 15,
      "rotation": 2
    },
    {
      "x": -9,
      "y": 11,
      "z": -8,
      "name": "Wood_Fir_Trunk_Full_Locked",
      "rotation": 5
    },
    {
      "x": -9,
      "y": 5,
      "z": -7,
      "name": "Wood_Fir_Trunk_Full_Locked",
      "support": 15,
      "rotation": 5
    },
    {
      "x": -9,
      "y": 6,
      "z": -7,
      "name": "Wood_Fir_Trunk_Full_Locked",
      "support": 15,
      "rotation": 5
    },
    {
      "x": -9,
      "y": 7,
      "z": -7,
      "name": "Wood_Fir_Trunk_Full_Locked",
      "support": 15,
      "rotation": 6
    },
    {
      "x": -9,
      "y": 3,
      "z": -5,
      "name": "Wood_Fir_Trunk_Full_Locked",
      "support": 15,
      "rotation": 5
    },
    {
      "x": -9,
      "y": 4,
      "z": -5,
      "name": "Wood_Fir_Trunk_Full_Locked",
      "support": 15,
      "rotation": 5
    },
    {
      "x": -9,
      "y": 2,
      "z": -2,
      "name": "Wood_Fir_Trunk_Full_Locked",
      "support": 15,
      "rotation": 5
    },
    {
      "x": -9,
      "y": 1,
      "z": 1,
      "name": "Wood_Fir_Trunk_Full_Locked",
      "support": 15,
      "rotation": 5
    },
    {
      "x": -9,
      "y": 7,
      "z": 1,
      "name": "Wood_Fir_Trunk_Full_Locked",
      "support": 15,
      "rotation": 5
    },
    {
      "x": -9,
      "y": 10,
      "z": 1,
      "name": "Wood_Deadwood_Planks"
    },
    {
      "x": -9,
      "y": 11,
      "z": 1,
      "name": "Wood_Deadwood_Planks_Half"
    },
    {
      "x": -9,
      "y": 10,
      "z": 2,
      "name": "Wood_Deadwood_Planks"
    },
    {
      "x": -9,
      "y": 11,
      "z": 2,
      "name": "Wood_Deadwood_Planks_Half"
    },
    {
      "x": -9,
      "y": 10,
      "z": 3,
      "name": "Wood_Deadwood_Planks"
    },
    {
      "x": -9,
      "y": 11,
      "z": 3,
      "name": "Wood_Deadwood_Planks_Half"
    },
    {
      "x": -9,
      "y": 2,
      "z": 4,
      "name": "Wood_Fir_Trunk_Full_Locked",
      "support": 15,
      "rotation": 5
    },
    {
      "x": -9,
      "y": 7,
      "z": 4,
      "name": "Wood_Fir_Trunk_Full_Locked",
      "support": 15,
      "rotation": 5
    },
    {
      "x": -9,
      "y": 10,
      "z": 4,
      "name": "Wood_Fir_Trunk_Full_Locked",
      "support": 15,
      "rotation": 5
    },
    {
      "x": -9,
      "y": 11,
      "z": 4,
      "name": "Wood_Fir_Trunk_Full_Locked",
      "support": 15,
      "rotation": 5
    },
    {
      "x": -9,
      "y": 3,
      "z": 5,
      "name": "Wood_Blackwood_Planks"
    },
    {
      "x": -9,
      "y": 7,
      "z": 5,
      "name": "Wood_Deadwood_Planks_Half",
      "rotation": 8
    },
    {
      "x": -9,
      "y": 11,
      "z": 5,
      "name": "Wood_Deadwood_Planks_Half",
      "rotation": 8
    },
    {
      "x": -9,
      "y": 3,
      "z": 6,
      "name": "Wood_Blackwood_Planks"
    },
    {
      "x": -9,
      "y": 7,
      "z": 6,
      "name": "Wood_Deadwood_Planks_Half",
      "rotation": 8
    },
    {
      "x": -9,
      "y": 11,
      "z": 6,
      "name": "Wood_Deadwood_Planks_Half",
      "rotation": 8
    },
    {
      "x": -9,
      "y": 3,
      "z": 7,
      "name": "Wood_Fir_Trunk_Full_Locked",
      "support": 15,
      "rotation": 5
    },
    {
      "x": -9,
      "y": 4,
      "z": 7,
      "name": "Wood_Fir_Trunk_Full_Locked",
      "support": 15,
      "rotation": 5
    },
    {
      "x": -9,
      "y": 7,
      "z": 7,
      "name": "Wood_Fir_Trunk_Full_Locked",
      "support": 15,
      "rotation": 5
    },
    {
      "x": -9,
      "y": 11,
      "z": 7,
      "name": "Wood_Fir_Trunk_Full_Locked",
      "support": 15,
      "rotation": 5
    },
    {
      "x": -9,
      "y": 5,
      "z": 8,
      "name": "Wood_Blackwood_Planks"
    },
    {
      "x": -9,
      "y": 11,
      "z": 8,
      "name": "Wood_Deadwood_Planks_Half",
      "rotation": 8
    },
    {
      "x": -9,
      "y": 12,
      "z": 8,
      "name": "Wood_Deadwood_Stairs",
      "rotation": 1
    },
    {
      "x": -9,
      "y": 5,
      "z": 9,
      "name": "Wood_Fir_Trunk_Full_Locked",
      "support": 15,
      "rotation": 5
    },
    {
      "x": -9,
      "y": 6,
      "z": 9,
      "name": "Wood_Fir_Trunk_Full_Locked",
      "support": 15,
      "rotation": 5
    },
    {
      "x": -9,
      "y": 7,
      "z": 9,
      "name": "Wood_Fir_Trunk_Full_Locked",
      "support": 15,
      "rotation": 4
    },
    {
      "x": -9,
      "y": 11,
      "z": 9,
      "name": "Wood_Deadwood_Planks_Half",
      "rotation": 8
    },
    {
      "x": -9,
      "y": 7,
      "z": 10,
      "name": "Wood_Fir_Trunk_Full_Locked",
      "support": 15,
      "rotation": 5
    },
    {
      "x": -9,
      "y": 8,
      "z": 10,
      "name": "Wood_Blackwood_Planks"
    },
    {
      "x": -9,
      "y": 9,
      "z": 10,
      "name": "Wood_Blackwood_Planks"
    },
    {
      "x": -9,
      "y": 10,
      "z": 10,
      "name": "Wood_Blackwood_Planks"
    },
    {
      "x": -9,
      "y": 11,
      "z": 10,
      "name": "Wood_Fir_Trunk_Full_Locked",
      "rotation": 5
    },
    {
      "x": -9,
      "y": 12,
      "z": 10,
      "name": "Wood_Blackwood_Fence"
    },
    {
      "x": -8,
      "y": 7,
      "z": -8,
      "name": "Wood_Fir_Trunk_Full_Locked",
      "support": 15,
      "rotation": 5
    },
    {
      "x": -8,
      "y": 11,
      "z": -8,
      "name": "Wood_Fir_Trunk_Full_Locked",
      "rotation": 5
    },
    {
      "x": -8,
      "y": 5,
      "z": -7,
      "name": "Wood_Fir_Trunk_Full_Locked",
      "support": 15,
      "rotation": 5
    },
    {
      "x": -8,
      "y": 3,
      "z": -5,
      "name": "Wood_Fir_Trunk_Full_Locked",
      "support": 15,
      "rotation": 5
    },
    {
      "x": -8,
      "y": 1,
      "z": -2,
      "name": "Wood_Fir_Trunk_Full_Locked",
      "support": 15,
      "rotation": 5
    },
    {
      "x": -8,
      "y": 2,
      "z": -2,
      "name": "Wood_Fir_Trunk_Full_Locked",
      "support": 15,
      "rotation": 5
    },
    {
      "x": -8,
      "y": 1,
      "z": 1,
      "name": "Wood_Fir_Trunk_Full_Locked",
      "support": 15,
      "rotation": 5
    },
    {
      "x": -8,
      "y": 7,
      "z": 1,
      "name": "Wood_Fir_Trunk_Full_Locked",
      "support": 15,
      "rotation": 5
    },
    {
      "x": -8,
      "y": 8,
      "z": 1,
      "name": "Wood_Fir_Trunk_Full_Locked",
      "support": 15
    },
    {
      "x": -8,
      "y": 9,
      "z": 1,
      "name": "Wood_Fir_Trunk_Full_Locked",
      "support": 15
    },
    {
      "x": -8,
      "y": 10,
      "z": 1,
      "name": "Wood_Fir_Trunk_Full_Locked",
      "support": 15
    },
    {
      "x": -8,
      "y": 11,
      "z": 1,
      "name": "Wood_Fir_Trunk_Full_Locked",
      "support": 15,
      "rotation": 5
    },
    {
      "x": -8,
      "y": 7,
      "z": 2,
      "name": "Wood_Fir_Trunk_Full_Locked",
      "support": 15,
      "rotation": 4
    },
    {
      "x": -8,
      "y": 11,
      "z": 2,
      "name": "Wood_Fir_Trunk_Full_Locked",
      "support": 15,
      "rotation": 4
    },
    {
      "x": -8,
      "y": 7,
      "z": 3,
      "name": "Wood_Fir_Trunk_Full_Locked",
      "support": 15,
      "rotation": 4
    },
    {
      "x": -8,
      "y": 11,
      "z": 3,
      "name": "Wood_Fir_Trunk_Full_Locked",
      "support": 15,
      "rotation": 4
    },
    {
      "x": -8,
      "y": 1,
      "z": 4,
      "name": "Wood_Fir_Trunk_Full_Locked",
      "support": 15,
      "rotation": 5
    },
    {
      "x": -8,
      "y": 2,
      "z": 4,
      "name": "Wood_Fir_Trunk_Full_Locked",
      "support": 15,
      "rotation": 5
    },
    {
      "x": -8,
      "y": 7,
      "z": 4,
      "name": "Wood_Fir_Trunk_Full_Locked",
      "support": 15,
      "rotation": 5
    },
    {
      "x": -8,
      "y": 8,
      "z": 4,
      "name": "Wood_Fir_Trunk_Full_Locked",
      "support": 15
    },
    {
      "x": -8,
      "y": 9,
      "z": 4,
      "name": "Wood_Fir_Trunk_Full_Locked",
      "support": 15
    },
    {
      "x": -8,
      "y": 10,
      "z": 4,
      "name": "Wood_Fir_Trunk_Full_Locked",
      "support": 15
    },
    {
      "x": -8,
      "y": 11,
      "z": 4,
      "name": "Wood_Fir_Trunk_Full_Locked",
      "support": 15,
      "rotation": 5
    },
    {
      "x": -8,
      "y": 7,
      "z": 5,
      "name": "Wood_Fir_Trunk_Full_Locked",
      "support": 15,
      "rotation": 4
    },
    {
      "x": -8,
      "y": 11,
      "z": 5,
      "name": "Wood_Fir_Trunk_Full_Locked",
      "support": 15,
      "rotation": 4
    },
    {
      "x": -8,
      "y": 7,
      "z": 6,
      "name": "Wood_Fir_Trunk_Full_Locked",
      "support": 15,
      "rotation": 4
    },
    {
      "x": -8,
      "y": 11,
      "z": 6,
      "name": "Wood_Fir_Trunk_Full_Locked",
      "support": 15,
      "rotation": 4
    },
    {
      "x": -8,
      "y": 3,
      "z": 7,
      "name": "Wood_Fir_Trunk_Full_Locked",
      "support": 15,
      "rotation": 5
    },
    {
      "x": -8,
      "y": 7,
      "z": 7,
      "name": "Wood_Fir_Trunk_Full_Locked",
      "support": 15,
      "rotation": 5
    },
    {
      "x": -8,
      "y": 11,
      "z": 7,
      "name": "Wood_Fir_Trunk_Full_Locked",
      "support": 15,
      "rotation": 5
    },
    {
      "x": -8,
      "y": 4,
      "z": 8,
      "name": "Wood_Blackwood_Planks"
    },
    {
      "x": -8,
      "y": 5,
      "z": 8,
      "name": "Wood_Blackwood_Planks"
    },
    {
      "x": -8,
      "y": 7,
      "z": 8,
      "name": "Wood_Fir_Trunk_Full_Locked",
      "support": 15,
      "rotation": 4
    },
    {
      "x": -8,
      "y": 11,
      "z": 8,
      "name": "Wood_Fir_Trunk_Full_Locked",
      "support": 15,
      "rotation": 4
    },
    {
      "x": -8,
      "y": 5,
      "z": 9,
      "name": "Wood_Fir_Trunk_Full_Locked",
      "support": 15,
      "rotation": 5
    },
    {
      "x": -8,
      "y": 7,
      "z": 9,
      "name": "Wood_Fir_Trunk_Full_Locked",
      "support": 15,
      "rotation": 4
    },
    {
      "x": -8,
      "y": 11,
      "z": 9,
      "name": "Wood_Fir_Trunk_Full_Locked",
      "support": 15,
      "rotation": 4
    },
    {
      "x": -8,
      "y": 6,
      "z": 10,
      "name": "Wood_Blackwood_Planks"
    },
    {
      "x": -8,
      "y": 7,
      "z": 10,
      "name": "Wood_Fir_Trunk_Full_Locked",
      "support": 15,
      "rotation": 5
    },
    {
      "x": -8,
      "y": 8,
      "z": 10,
      "name": "Wood_Fir_Trunk_Full_Locked",
      "support": 15
    },
    {
      "x": -8,
      "y": 9,
      "z": 10,
      "name": "Wood_Fir_Trunk_Full_Locked",
      "support": 15
    },
    {
      "x": -8,
      "y": 10,
      "z": 10,
      "name": "Wood_Fir_Trunk_Full_Locked",
      "support": 15
    },
    {
      "x": -8,
      "y": 11,
      "z": 10,
      "name": "Wood_Fir_Trunk_Full_Locked",
      "rotation": 5
    },
    {
      "x": -8,
      "y": 12,
      "z": 10,
      "name": "Wood_Blackwood_Stairs",
      "rotation": 2
    },
    {
      "x": -7,
      "y": 7,
      "z": -8,
      "name": "Wood_Fir_Trunk_Full_Locked",
      "support": 15,
      "rotation": 5
    },
    {
      "x": -7,
      "y": 11,
      "z": -8,
      "name": "Wood_Fir_Trunk_Full_Locked",
      "rotation": 5
    },
    {
      "x": -7,
      "y": 4,
      "z": -7,
      "name": "Wood_Fir_Trunk_Full_Locked",
      "support": 15,
      "rotation": 5
    },
    {
      "x": -7,
      "y": 5,
      "z": -7,
      "name": "Wood_Fir_Trunk_Full_Locked",
      "support": 15,
      "rotation": 5
    },
    {
      "x": -7,
      "y": 3,
      "z": -5,
      "name": "Wood_Fir_Trunk_Full_Locked",
      "support": 15,
      "rotation": 5
    },
    {
      "x": -7,
      "y": 1,
      "z": -2,
      "name": "Wood_Fir_Trunk_Full_Locked",
      "support": 15,
      "rotation": 5
    },
    {
      "x": -7,
      "y": 1,
      "z": 1,
      "name": "Wood_Fir_Trunk_Full_Locked",
      "support": 15,
      "rotation": 5
    },
    {
      "x": -7,
      "y": 7,
      "z": 1,
      "name": "Wood_Fir_Trunk_Full_Locked",
      "support": 15,
      "rotation": 5
    },
    {
      "x": -7,
      "y": 11,
      "z": 1,
      "name": "Wood_Fir_Trunk_Full_Locked",
      "support": 15,
      "rotation": 5
    },
    {
      "x": -7,
      "y": 7,
      "z": 2,
      "name": "Wood_Deadwood_Planks_Half",
      "rotation": 8
    },
    {
      "x": -7,
      "y": 11,
      "z": 2,
      "name": "Wood_Deadwood_Planks_Half",
      "rotation": 8
    },
    {
      "x": -7,
      "y": 7,
      "z": 3,
      "name": "Wood_Deadwood_Planks_Half",
      "rotation": 8
    },
    {
      "x": -7,
      "y": 11,
      "z": 3,
      "name": "Wood_Deadwood_Planks_Half",
      "rotation": 8
    },
    {
      "x": -7,
      "y": 1,
      "z": 4,
      "name": "Wood_Fir_Trunk_Full_Locked",
      "support": 15,
      "rotation": 5
    },
    {
      "x": -7,
      "y": 7,
      "z": 4,
      "name": "Wood_Fir_Trunk_Full_Locked",
      "support": 15,
      "rotation": 5
    },
    {
      "x": -7,
      "y": 11,
      "z": 4,
      "name": "Wood_Fir_Trunk_Full_Locked",
      "support": 15,
      "rotation": 5
    },
    {
      "x": -7,
      "y": 7,
      "z": 5,
      "name": "Wood_Deadwood_Planks_Half",
      "rotation": 8
    },
    {
      "x": -7,
      "y": 11,
      "z": 5,
      "name": "Wood_Deadwood_Planks_Half",
      "rotation": 8
    },
    {
      "x": -7,
      "y": 7,
      "z": 6,
      "name": "Wood_Deadwood_Planks_Half",
      "rotation": 8
    },
    {
      "x": -7,
      "y": 11,
      "z": 6,
      "name": "Wood_Deadwood_Planks_Half",
      "rotation": 8
    },
    {
      "x": -7,
      "y": 3,
      "z": 7,
      "name": "Wood_Fir_Trunk_Full_Locked",
      "support": 15,
      "rotation": 5
    },
    {
      "x": -7,
      "y": 7,
      "z": 7,
      "name": "Wood_Fir_Trunk_Full_Locked",
      "support": 15,
      "rotation": 5
    },
    {
      "x": -7,
      "y": 11,
      "z": 7,
      "name": "Wood_Fir_Trunk_Full_Locked",
      "support": 15,
      "rotation": 5
    },
    {
      "x": -7,
      "y": 4,
      "z": 8,
      "name": "Wood_Blackwood_Planks"
    },
    {
      "x": -7,
      "y": 5,
      "z": 8,
      "name": "Wood_Blackwood_Planks"
    },
    {
      "x": -7,
      "y": 7,
      "z": 8,
      "name": "Wood_Deadwood_Planks_Half",
      "rotation": 8
    },
    {
      "x": -7,
      "y": 11,
      "z": 8,
      "name": "Wood_Deadwood_Planks_Half",
      "rotation": 8
    },
    {
      "x": -7,
      "y": 4,
      "z": 9,
      "name": "Wood_Fir_Trunk_Full_Locked",
      "support": 15,
      "rotation": 5
    },
    {
      "x": -7,
      "y": 5,
      "z": 9,
      "name": "Wood_Fir_Trunk_Full_Locked",
      "support": 15,
      "rotation": 5
    },
    {
      "x": -7,
      "y": 7,
      "z": 9,
      "name": "Wood_Deadwood_Planks_Half",
      "rotation": 8
    },
    {
      "x": -7,
      "y": 11,
      "z": 9,
      "name": "Wood_Deadwood_Planks_Half",
      "rotation": 8
    },
    {
      "x": -7,
      "y": 6,
      "z": 10,
      "name": "Wood_Blackwood_Planks"
    },
    {
      "x": -7,
      "y": 7,
      "z": 10,
      "name": "Wood_Fir_Trunk_Full_Locked",
      "support": 15,
      "rotation": 5
    },
    {
      "x": -7,
      "y": 8,
      "z": 10,
      "name": "Wood_Blackwood_Planks"
    },
    {
      "x": -7,
      "y": 9,
      "z": 10,
      "name": "Wood_Blackwood_Planks_Half",
      "rotation": 5
    },
    {
      "x": -7,
      "y": 10,
      "z": 10,
      "name": "Wood_Blackwood_Planks"
    },
    {
      "x": -7,
      "y": 11,
      "z": 10,
      "name": "Wood_Fir_Trunk_Full_Locked",
      "rotation": 5
    },
    {
      "x": -7,
      "y": 12,
      "z": 10,
      "name": "Wood_Blackwood_Fence"
    },
    {
      "x": -7,
      "y": 10,
      "z": 11,
      "name": "Furniture_Tavern_Platform"
    },
    {
      "x": -7,
      "y": 10,
      "z": 12,
      "name": "Furniture_Tavern_Platform"
    },
    {
      "x": -6,
      "y": 7,
      "z": -8,
      "name": "Wood_Fir_Trunk_Full_Locked",
      "support": 15,
      "rotation": 5
    },
    {
      "x": -6,
      "y": 11,
      "z": -8,
      "name": "Wood_Fir_Trunk_Full_Locked",
      "rotation": 5
    },
    {
      "x": -6,
      "y": 4,
      "z": -7,
      "name": "Wood_Fir_Trunk_Full_Locked",
      "support": 15,
      "rotation": 5
    },
    {
      "x": -6,
      "y": 2,
      "z": -5,
      "name": "Wood_Fir_Trunk_Full_Locked",
      "support": 15,
      "rotation": 5
    },
    {
      "x": -6,
      "y": 3,
      "z": -5,
      "name": "Wood_Fir_Trunk_Full_Locked",
      "support": 15,
      "rotation": 5
    },
    {
      "x": -6,
      "y": 1,
      "z": -2,
      "name": "Wood_Fir_Trunk_Full_Locked",
      "support": 15,
      "rotation": 5
    },
    {
      "x": -6,
      "y": 1,
      "z": 1,
      "name": "Wood_Fir_Trunk_Full_Locked",
      "support": 15,
      "rotation": 5
    },
    {
      "x": -6,
      "y": 7,
      "z": 1,
      "name": "Wood_Fir_Trunk_Full_Locked",
      "support": 15,
      "rotation": 5
    },
    {
      "x": -6,
      "y": 11,
      "z": 1,
      "name": "Wood_Fir_Trunk_Full_Locked",
      "support": 15,
      "rotation": 5
    },
    {
      "x": -6,
      "y": 7,
      "z": 2,
      "name": "Wood_Deadwood_Planks_Half",
      "rotation": 8
    },
    {
      "x": -6,
      "y": 11,
      "z": 2,
      "name": "Wood_Deadwood_Planks_Half",
      "rotation": 8
    },
    {
      "x": -6,
      "y": 7,
      "z": 3,
      "name": "Wood_Deadwood_Planks_Half",
      "rotation": 8
    },
    {
      "x": -6,
      "y": 11,
      "z": 3,
      "name": "Wood_Deadwood_Planks_Half",
      "rotation": 8
    },
    {
      "x": -6,
      "y": 1,
      "z": 4,
      "name": "Wood_Fir_Trunk_Full_Locked",
      "support": 15,
      "rotation": 5
    },
    {
      "x": -6,
      "y": 7,
      "z": 4,
      "name": "Wood_Fir_Trunk_Full_Locked",
      "support": 15,
      "rotation": 5
    },
    {
      "x": -6,
      "y": 11,
      "z": 4,
      "name": "Wood_Fir_Trunk_Full_Locked",
      "support": 15,
      "rotation": 5
    },
    {
      "x": -6,
      "y": 7,
      "z": 5,
      "name": "Wood_Deadwood_Planks_Half",
      "rotation": 8
    },
    {
      "x": -6,
      "y": 11,
      "z": 5,
      "name": "Wood_Deadwood_Planks_Half",
      "rotation": 8
    },
    {
      "x": -6,
      "y": 7,
      "z": 6,
      "name": "Wood_Deadwood_Planks_Half",
      "rotation": 8
    },
    {
      "x": -6,
      "y": 11,
      "z": 6,
      "name": "Wood_Deadwood_Planks_Half",
      "rotation": 8
    },
    {
      "x": -6,
      "y": 2,
      "z": 7,
      "name": "Wood_Fir_Trunk_Full_Locked",
      "support": 15,
      "rotation": 5
