{
  "version": 8,
  "blockIdVersion": 11,
  "anchorX": 0,
  "anchorY": 0,
  "anchorZ": 0,
  "blocks": [
    {
      "x": -34,
      "y": 16,
      "z": 0,
      "name": "Wood_Fir_Trunk_Full_Locked",
      "support": 15,
      "rotation": 5
    },
    {
      "x": -33,
      "y": 15,
      "z": 0,
      "name": "Wood_Fir_Trunk_Full_Locked",
      "support": 15,
      "rotation": 5
    },
    {
      "x": -33,
      "y": 16,
      "z": 0,
      "name": "Wood_Fir_Trunk_Full_Locked",
      "support": 15,
      "rotation": 2
    },
    {
      "x": -32,
      "y": 14,
      "z": 0,
      "name": "Wood_Fir_Trunk_Full_Locked",
      "support": 15,
      "rotation": 5
    },
    {
      "x": -32,
      "y": 15,
      "z": 0,
      "name": "Wood_Fir_Trunk_Full_Locked",
      "support": 15,
      "rotation": 2
    },
    {
      "x": -31,
      "y": 13,
      "z": 0,
      "name": "Wood_Fir_Trunk_Full_Locked",
      "support": 15,
      "rotation": 5
    },
    {
      "x": -31,
      "y": 14,
      "z": 0,
      "name": "Wood_Fir_Trunk_Full_Locked",
      "support": 15,
      "rotation": 2
    },
    {
      "x": -30,
      "y": 12,
      "z": 0,
      "name": "Wood_Fir_Trunk_Full_Locked",
      "support": 15,
      "rotation": 5
    },
    {
      "x": -30,
      "y": 13,
      "z": 0,
      "name": "Wood_Fir_Trunk_Full_Locked",
      "support": 15,
      "rotation": 2
    },
    {
      "x": -29,
      "y": 14,
      "z": -1,
      "name": "Wood_Fir_Trunk_Full_Locked",
      "support": 15,
      "rotation": 6
    },
    {
      "x": -29,
      "y": 11,
      "z": 0,
      "name": "Wood_Fir_Trunk_Full_Locked",
      "support": 15,
      "rotation": 5
    },
    {
      "x": -29,
      "y": 12,
      "z": 0,
      "name": "Wood_Fir_Trunk_Full_Locked",
      "support": 15,
      "rotation": 2
    },
    {
      "x": -29,
      "y": 14,
      "z": 0,
      "name": "Wood_Fir_Trunk_Full_Locked",
      "support": 15,
      "rotation": 6
    },
    {
      "x": -29,
      "y": 14,
      "z": 1,
      "name": "Wood_Fir_Trunk_Full_Locked",
      "support": 15,
      "rotation": 4
    },
    {
      "x": -28,
      "y": 13,
      "z": -3,
      "name": "Wood_Fir_Trunk_Full_Locked",
      "support": 15,
      "rotation": 5
    },
    {
      "x": -28,
      "y": 14,
      "z": -3,
      "name": "Wood_Fir_Trunk_Full_Locked",
      "support": 15,
      "rotation": 6
    },
    {
      "x": -28,
      "y": 14,
      "z": -2,
      "name": "Wood_Fir_Trunk_Full_Locked",
      "support": 15,
      "rotation": 6
    },
    {
      "x": -28,
      "y": 14,
      "z": -1,
      "name": "Wood_Fir_Trunk_Full_Locked",
      "support": 15,
      "rotation": 6
    },
    {
      "x": -28,
      "y": 10,
      "z": 0,
      "name": "Wood_Fir_Trunk_Full_Locked",
      "support": 15,
      "rotation": 5
    },
    {
      "x": -28,
      "y": 11,
      "z": 0,
      "name": "Wood_Fir_Trunk_Full_Locked",
      "support": 15,
      "rotation": 2
    },
    {
      "x": -28,
      "y": 14,
      "z": 0,
      "name": "Wood_Fir_Trunk_Full_Locked",
      "support": 15,
      "rotation": 5
    },
    {
      "x": -28,
      "y": 14,
      "z": 1,
      "name": "Wood_Fir_Trunk_Full_Locked",
      "support": 15,
      "rotation": 4
    },
    {
      "x": -28,
      "y": 14,
      "z": 2,
      "name": "Wood_Fir_Trunk_Full_Locked",
      "support": 15,
      "rotation": 4
    },
    {
      "x": -28,
      "y": 13,
      "z": 3,
      "name": "Wood_Fir_Trunk_Full_Locked",
      "support": 15,
      "rotation": 5
    },
    {
      "x": -28,
      "y": 14,
      "z": 3,
      "name": "Wood_Fir_Trunk_Full_Locked",
      "support": 15,
      "rotation": 4
    },
    {
      "x": -27,
      "y": 14,
      "z": -5,
      "name": "Wood_Fir_Trunk_Full_Locked",
      "support": 15,
      "rotation": 5
    },
    {
      "x": -27,
      "y": 14,
      "z": -4,
      "name": "Wood_Fir_Trunk_Full_Locked",
      "support": 15,
      "rotation": 6
    },
    {
      "x": -27,
      "y": 12,
      "z": -3,
      "name": "Wood_Fir_Trunk_Full_Locked",
      "support": 15,
      "rotation": 5
    },
    {
      "x": -27,
      "y": 13,
      "z": -3,
      "name": "Wood_Fir_Trunk_Full_Locked",
      "support": 15,
      "rotation": 5
    },
    {
      "x": -27,
      "y": 9,
      "z": 0,
      "name": "Wood_Fir_Trunk_Full_Locked",
      "support": 15,
      "rotation": 5
    },
    {
      "x": -27,
      "y": 10,
      "z": 0,
      "name": "Wood_Fir_Trunk_Full_Locked",
      "support": 15,
      "rotation": 2
    },
    {
      "x": -27,
      "y": 14,
      "z": 0,
      "name": "Wood_Fir_Trunk_Full_Locked",
      "support": 15,
      "rotation": 5
    },
    {
      "x": -27,
      "y": 12,
      "z": 3,
      "name": "Wood_Fir_Trunk_Full_Locked",
      "support": 15,
      "rotation": 5
    },
    {
      "x": -27,
      "y": 13,
      "z": 3,
      "name": "Wood_Fir_Trunk_Full_Locked",
      "support": 15,
      "rotation": 5
    },
    {
      "x": -27,
      "y": 14,
      "z": 3,
      "name": "Wood_Fir_Trunk_Full_Locked",
      "support": 15,
      "rotation": 5
    },
    {
      "x": -27,
      "y": 14,
      "z": 4,
      "name": "Wood_Fir_Trunk_Full_Locked",
      "support": 15,
      "rotation": 4
    },
    {
      "x": -27,
      "y": 14,
      "z": 5,
      "name": "Wood_Fir_Trunk_Full_Locked",
      "support": 15,
      "rotation": 5
    },
    {
      "x": -26,
      "y": 14,
      "z": -6,
      "name": "Wood_Fir_Trunk_Full_Locked",
      "support": 15,
      "rotation": 5
    },
    {
      "x": -26,
      "y": 14,
      "z": -5,
      "name": "Wood_Fir_Trunk_Full_Locked",
      "support": 15,
      "rotation": 5
    },
    {
      "x": -26,
      "y": 11,
      "z": -3,
      "name": "Wood_Fir_Trunk_Full_Locked",
      "support": 15,
      "rotation": 5
    },
    {
      "x": -26,
      "y": 12,
      "z": -3,
      "name": "Wood_Fir_Trunk_Full_Locked",
      "support": 15,
      "rotation": 5
    },
    {
      "x": -26,
      "y": 8,
      "z": 0,
      "name": "Wood_Fir_Trunk_Full_Locked",
      "support": 15,
      "rotation": 5
    },
    {
      "x": -26,
      "y": 9,
      "z": 0,
      "name": "Wood_Fir_Trunk_Full_Locked",
      "support": 15,
      "rotation": 2
    },
    {
      "x": -26,
      "y": 14,
      "z": 0,
      "name": "Wood_Fir_Trunk_Full_Locked",
      "support": 15,
      "rotation": 5
    },
    {
      "x": -26,
      "y": 11,
      "z": 3,
      "name": "Wood_Fir_Trunk_Full_Locked",
      "support": 15,
      "rotation": 5
    },
    {
      "x": -26,
      "y": 12,
      "z": 3,
      "name": "Wood_Fir_Trunk_Full_Locked",
      "support": 15,
      "rotation": 5
    },
    {
      "x": -26,
      "y": 14,
      "z": 3,
      "name": "Wood_Fir_Trunk_Full_Locked",
      "support": 15,
      "rotation": 5
    },
    {
      "x": -26,
      "y": 14,
      "z": 5,
      "name": "Wood_Fir_Trunk_Full_Locked",
      "support": 15,
      "rotation": 5
    },
    {
      "x": -26,
      "y": 14,
      "z": 6,
      "name": "Wood_Fir_Trunk_Full_Locked",
      "support": 15,
      "rotation": 5
    },
    {
      "x": -25,
      "y": 13,
      "z": -6,
      "name": "Wood_Fir_Trunk_Full_Locked",
      "support": 15,
      "rotation": 5
    },
    {
      "x": -25,
      "y": 14,
      "z": -6,
      "name": "Wood_Fir_Trunk_Full_Locked",
      "support": 15,
      "rotation": 5
    },
    {
      "x": -25,
      "y": 10,
      "z": -3,
      "name": "Wood_Fir_Trunk_Full_Locked",
      "support": 15,
      "rotation": 5
    },
    {
      "x": -25,
      "y": 11,
      "z": -3,
      "name": "Wood_Fir_Trunk_Full_Locked",
      "support": 15,
      "rotation": 5
    },
    {
      "x": -25,
      "y": 8,
      "z": 0,
      "name": "Wood_Fir_Trunk_Full_Locked",
      "support": 15,
      "rotation": 2
    },
    {
      "x": -25,
      "y": 14,
      "z": 0,
      "name": "Wood_Fir_Trunk_Full_Locked",
      "support": 15,
      "rotation": 5
    },
    {
      "x": -25,
      "y": 10,
      "z": 3,
      "name": "Wood_Fir_Trunk_Full_Locked",
      "support": 15,
      "rotation": 5
    },
    {
      "x": -25,
      "y": 11,
      "z": 3,
      "name": "Wood_Fir_Trunk_Full_Locked",
      "support": 15,
      "rotation": 5
    },
    {
      "x": -25,
      "y": 14,
      "z": 3,
      "name": "Wood_Fir_Trunk_Full_Locked",
      "support": 15,
      "rotation": 5
    },
    {
      "x": -25,
      "y": 13,
      "z": 6,
      "name": "Wood_Fir_Trunk_Full_Locked",
      "support": 15,
      "rotation": 5
    },
    {
      "x": -25,
      "y": 14,
      "z": 6,
      "name": "Wood_Fir_Trunk_Full_Locked",
      "support": 15,
      "rotation": 5
    },
    {
      "x": -24,
      "y": 14,
      "z": -7,
      "name": "Wood_Fir_Trunk_Full_Locked",
      "support": 15,
      "rotation": 5
    },
    {
      "x": -24,
      "y": 12,
      "z": -6,
      "name": "Wood_Fir_Trunk_Full_Locked",
      "support": 15,
      "rotation": 5
    },
    {
      "x": -24,
      "y": 13,
      "z": -6,
      "name": "Wood_Fir_Trunk_Full_Locked",
      "support": 15,
      "rotation": 5
    },
    {
      "x": -24,
      "y": 14,
      "z": -6,
      "name": "Wood_Fir_Trunk_Full_Locked",
      "support": 15,
      "rotation": 5
    },
    {
      "x": -24,
      "y": 9,
      "z": -3,
      "name": "Wood_Fir_Trunk_Full_Locked",
      "support": 15,
      "rotation": 5
    },
    {
      "x": -24,
      "y": 10,
      "z": -3,
      "name": "Wood_Fir_Trunk_Full_Locked",
      "support": 15,
      "rotation": 5
    },
    {
      "x": -24,
      "y": 7,
      "z": 0,
      "name": "Wood_Fir_Trunk_Full_Locked",
      "support": 15,
      "rotation": 5
    },
    {
      "x": -24,
      "y": 8,
      "z": 0,
      "name": "Wood_Fir_Trunk_Full_Locked",
      "support": 15,
      "rotation": 5
    },
    {
      "x": -24,
      "y": 14,
      "z": 0,
      "name": "Wood_Fir_Trunk_Full_Locked",
      "support": 15,
      "rotation": 5
    },
    {
      "x": -24,
      "y": 9,
      "z": 3,
      "name": "Wood_Fir_Trunk_Full_Locked",
      "support": 15,
      "rotation": 5
    },
    {
      "x": -24,
      "y": 10,
      "z": 3,
      "name": "Wood_Fir_Trunk_Full_Locked",
      "support": 15,
      "rotation": 5
    },
    {
      "x": -24,
      "y": 14,
      "z": 3,
      "name": "Wood_Fir_Trunk_Full_Locked",
      "support": 15,
      "rotation": 5
    },
    {
      "x": -24,
      "y": 12,
      "z": 6,
      "name": "Wood_Fir_Trunk_Full_Locked",
      "support": 15,
      "rotation": 5
    },
    {
      "x": -24,
      "y": 13,
      "z": 6,
      "name": "Wood_Fir_Trunk_Full_Locked",
      "support": 15,
      "rotation": 5
    },
    {
      "x": -24,
      "y": 14,
      "z": 6,
      "name": "Wood_Fir_Trunk_Full_Locked",
      "support": 15,
      "rotation": 5
    },
    {
      "x": -24,
      "y": 14,
      "z": 7,
      "name": "Wood_Fir_Trunk_Full_Locked",
      "support": 15,
      "rotation": 5
    },
    {
      "x": -23,
      "y": 14,
      "z": -7,
      "name": "Wood_Fir_Trunk_Full_Locked",
      "support": 15,
      "rotation": 6
    },
    {
      "x": -23,
      "y": 11,
      "z": -6,
      "name": "Wood_Fir_Trunk_Full_Locked",
      "support": 15,
      "rotation": 5
    },
    {
      "x": -23,
      "y": 12,
      "z": -6,
      "name": "Wood_Fir_Trunk_Full_Locked",
      "support": 15,
      "rotation": 5
    },
    {
      "x": -23,
      "y": 9,
      "z": -3,
      "name": "Wood_Fir_Trunk_Full_Locked",
      "support": 15,
      "rotation": 5
    },
    {
      "x": -23,
      "y": 7,
      "z": 0,
      "name": "Wood_Fir_Trunk_Full_Locked",
      "support": 15,
      "rotation": 2
    },
    {
      "x": -23,
      "y": 14,
      "z": 0,
      "name": "Wood_Fir_Trunk_Full_Locked",
      "support": 15,
      "rotation": 5
    },
    {
      "x": -23,
      "y": 9,
      "z": 3,
      "name": "Wood_Fir_Trunk_Full_Locked",
      "support": 15,
      "rotation": 5
    },
    {
      "x": -23,
      "y": 14,
      "z": 3,
      "name": "Wood_Fir_Trunk_Full_Locked",
      "support": 15,
      "rotation": 5
    },
    {
      "x": -23,
      "y": 11,
      "z": 6,
      "name": "Wood_Fir_Trunk_Full_Locked",
      "support": 15,
      "rotation": 5
    },
    {
      "x": -23,
      "y": 12,
      "z": 6,
      "name": "Wood_Fir_Trunk_Full_Locked",
      "support": 15,
      "rotation": 5
    },
    {
      "x": -23,
      "y": 14,
      "z": 6,
      "name": "Wood_Fir_Trunk_Full_Locked",
      "support": 15,
      "rotation": 5
    },
    {
      "x": -23,
      "y": 12,
      "z": 7,
      "name": "Wood_Blackwood_Planks"
    },
    {
      "x": -23,
      "y": 13,
      "z": 7,
      "name": "Wood_Blackwood_Planks"
    },
    {
      "x": -23,
      "y": 14,
      "z": 7,
      "name": "Wood_Fir_Trunk_Full_Locked",
      "support": 15,
      "rotation": 4
    },
    {
      "x": -22,
      "y": 13,
      "z": -8,
      "name": "Wood_Fir_Trunk_Full_Locked",
      "support": 15,
      "rotation": 5
    },
    {
      "x": -22,
      "y": 14,
      "z": -8,
      "name": "Wood_Fir_Trunk_Full_Locked",
      "support": 15,
      "rotation": 5
    },
    {
      "x": -22,
      "y": 14,
      "z": -7,
      "name": "Wood_Fir_Trunk_Full_Locked",
      "support": 15,
      "rotation": 5
    },
    {
      "x": -22,
      "y": 10,
      "z": -6,
      "name": "Wood_Fir_Trunk_Full_Locked",
      "support": 15,
      "rotation": 5
    },
    {
      "x": -22,
      "y": 11,
      "z": -6,
      "name": "Wood_Fir_Trunk_Full_Locked",
      "support": 15,
      "rotation": 5
    },
    {
      "x": -22,
      "y": 8,
      "z": -3,
      "name": "Wood_Fir_Trunk_Full_Locked",
      "support": 15,
      "rotation": 5
    },
    {
      "x": -22,
      "y": 9,
      "z": -3,
      "name": "Wood_Fir_Trunk_Full_Locked",
      "support": 15,
      "rotation": 5
    },
    {
      "x": -22,
      "y": 6,
      "z": 0,
      "name": "Wood_Fir_Trunk_Full_Locked",
      "support": 15,
      "rotation": 5
    },
    {
      "x": -22,
      "y": 7,
      "z": 0,
      "name": "Wood_Fir_Trunk_Full_Locked",
      "support": 15,
      "rotation": 5
    },
    {
      "x": -22,
      "y": 14,
      "z": 0,
      "name": "Wood_Fir_Trunk_Full_Locked",
      "support": 15,
      "rotation": 5
    },
    {
      "x": -22,
      "y": 8,
      "z": 3,
      "name": "Wood_Fir_Trunk_Full_Locked",
      "support": 15,
      "rotation": 5
    },
    {
      "x": -22,
      "y": 9,
      "z": 3,
      "name": "Wood_Fir_Trunk_Full_Locked",
      "support": 15,
      "rotation": 5
    },
    {
      "x": -22,
      "y": 14,
      "z": 3,
      "name": "Wood_Fir_Trunk_Full_Locked",
      "support": 15,
      "rotation": 5
    },
    {
      "x": -22,
      "y": 10,
      "z": 6,
      "name": "Wood_Fir_Trunk_Full_Locked",
      "support": 15,
      "rotation": 5
    },
    {
      "x": -22,
      "y": 11,
      "z": 6,
      "name": "Wood_Fir_Trunk_Full_Locked",
      "support": 15,
      "rotation": 5
    },
    {
      "x": -22,
      "y": 14,
      "z": 6,
      "name": "Wood_Fir_Trunk_Full_Locked",
      "support": 15,
      "rotation": 5
    },
    {
      "x": -22,
      "y": 11,
      "z": 7,
      "name": "Wood_Blackwood_Planks"
    },
    {
      "x": -22,
      "y": 12,
      "z": 7,
      "name": "Wood_Blackwood_Planks"
    },
    {
      "x": -22,
      "y": 13,
      "z": 7,
      "name": "Wood_Blackwood_Planks"
    },
    {
      "x": -22,
      "y": 14,
      "z": 7,
      "name": "Wood_Fir_Trunk_Full_Locked",
      "support": 15,
      "rotation": 5
    },
    {
      "x": -22,
      "y": 13,
      "z": 8,
      "name": "Wood_Fir_Trunk_Full_Locked",
      "support": 15,
      "rotation": 5
    },
    {
      "x": -22,
      "y": 14,
      "z": 8,
      "name": "Wood_Fir_Trunk_Full_Locked",
      "support": 15,
      "rotation": 5
    },
    {
      "x": -21,
      "y": 12,
      "z": -8,
      "name": "Wood_Fir_Trunk_Full_Locked",
      "support": 15,
      "rotation": 5
    },
    {
      "x": -21,
      "y": 13,
      "z": -8,
      "name": "Wood_Fir_Trunk_Full_Locked",
      "support": 15,
      "rotation": 5
    },
    {
      "x": -21,
      "y": 14,
      "z": -8,
      "name": "Wood_Fir_Trunk_Full_Locked",
      "support": 15,
      "rotation": 5
    },
    {
      "x": -21,
      "y": 10,
      "z": -6,
      "name": "Wood_Fir_Trunk_Full_Locked",
      "support": 15,
      "rotation": 5
    },
    {
      "x": -21,
      "y": 8,
      "z": -3,
      "name": "Wood_Fir_Trunk_Full_Locked",
      "support": 15,
      "rotation": 5
    },
    {
      "x": -21,
      "y": 6,
      "z": 0,
      "name": "Wood_Fir_Trunk_Full_Locked",
      "support": 15,
      "rotation": 5
    },
    {
      "x": -21,
      "y": 14,
      "z": 0,
      "name": "Wood_Fir_Trunk_Full_Locked",
      "support": 15,
      "rotation": 5
    },
    {
      "x": -21,
      "y": 8,
      "z": 3,
      "name": "Wood_Fir_Trunk_Full_Locked",
      "support": 15,
      "rotation": 5
    },
    {
      "x": -21,
      "y": 14,
      "z": 3,
      "name": "Wood_Fir_Trunk_Full_Locked",
      "support": 15,
      "rotation": 5
    },
    {
      "x": -21,
      "y": 10,
      "z": 6,
      "name": "Wood_Fir_Trunk_Full_Locked",
      "support": 15,
      "rotation": 5
    },
    {
      "x": -21,
      "y": 14,
      "z": 6,
      "name": "Wood_Fir_Trunk_Full_Locked",
      "support": 15,
      "rotation": 5
    },
    {
      "x": -21,
      "y": 11,
      "z": 7,
      "name": "Wood_Blackwood_Planks"
    },
    {
      "x": -21,
      "y": 12,
      "z": 7,
      "name": "Wood_Blackwood_Planks"
    },
    {
      "x": -21,
      "y": 12,
      "z": 8,
      "name": "Wood_Fir_Trunk_Full_Locked",
      "support": 15,
      "rotation": 5
    },
    {
      "x": -21,
      "y": 13,
      "z": 8,
      "name": "Wood_Fir_Trunk_Full_Locked",
      "support": 15,
      "rotation": 5
    },
    {
      "x": -21,
      "y": 14,
      "z": 8,
      "name": "Wood_Fir_Trunk_Full_Locked",
      "support": 15,
      "rotation": 5
    },
    {
      "x": -20,
      "y": 11,
      "z": -8,
      "name": "Wood_Fir_Trunk_Full_Locked",
      "support": 15,
      "rotation": 5
    },
    {
      "x": -20,
      "y": 14,
      "z": -8,
      "name": "Wood_Fir_Trunk_Full_Locked",
      "rotation": 5
    },
    {
      "x": -20,
      "y": 9,
      "z": -6,
      "name": "Wood_Fir_Trunk_Full_Locked",
      "support": 15,
      "rotation": 5
    },
    {
      "x": -20,
      "y": 10,
      "z": -6,
      "name": "Wood_Fir_Trunk_Full_Locked",
      "support": 15,
      "rotation": 5
    },
    {
      "x": -20,
      "y": 7,
      "z": -3,
      "name": "Wood_Fir_Trunk_Full_Locked",
      "support": 15,
      "rotation": 5
    },
    {
      "x": -20,
      "y": 8,
      "z": -3,
      "name": "Wood_Fir_Trunk_Full_Locked",
      "support": 15,
      "rotation": 5
    },
    {
      "x": -20,
      "y": 5,
      "z": 0,
      "name": "Wood_Fir_Trunk_Full_Locked",
      "support": 15,
      "rotation": 5
    },
    {
      "x": -20,
      "y": 6,
      "z": 0,
      "name": "Wood_Fir_Trunk_Full_Locked",
      "support": 15,
      "rotation": 2
    },
    {
      "x": -20,
      "y": 14,
      "z": 0,
      "name": "Wood_Fir_Trunk_Full_Locked",
      "support": 15,
      "rotation": 5
    },
    {
      "x": -20,
      "y": 7,
      "z": 3,
      "name": "Wood_Fir_Trunk_Full_Locked",
      "support": 15,
      "rotation": 5
    },
    {
      "x": -20,
      "y": 8,
      "z": 3,
      "name": "Wood_Fir_Trunk_Full_Locked",
      "support": 15,
      "rotation": 5
    },
    {
      "x": -20,
      "y": 14,
      "z": 3,
      "name": "Wood_Fir_Trunk_Full_Locked",
      "support": 15,
      "rotation": 5
    },
    {
      "x": -20,
      "y": 9,
      "z": 6,
      "name": "Wood_Fir_Trunk_Full_Locked",
      "support": 15,
      "rotation": 5
    },
    {
      "x": -20,
      "y": 10,
      "z": 6,
      "name": "Wood_Fir_Trunk_Full_Locked",
      "support": 15,
      "rotation": 5
    },
    {
      "x": -20,
      "y": 14,
      "z": 6,
      "name": "Wood_Fir_Trunk_Full_Locked",
      "support": 15,
      "rotation": 5
    },
    {
      "x": -20,
      "y": 10,
      "z": 7,
      "name": "Wood_Blackwood_Planks"
    },
    {
      "x": -20,
      "y": 11,
      "z": 7,
      "name": "Wood_Blackwood_Planks"
    },
    {
      "x": -20,
      "y": 11,
      "z": 8,
      "name": "Wood_Fir_Trunk_Full_Locked",
      "support": 15,
      "rotation": 5
    },
    {
      "x": -20,
      "y": 14,
      "z": 8,
      "name": "Wood_Fir_Trunk_Full_Locked",
      "rotation": 5
    },
    {
      "x": -19,
      "y": 11,
      "z": -8,
      "name": "Wood_Fir_Trunk_Full_Locked",
      "support": 15,
      "rotation": 5
    },
    {
      "x": -19,
      "y": 14,
      "z": -8,
      "name": "Wood_Fir_Trunk_Full_Locked",
      "rotation": 5
    },
    {
      "x": -19,
      "y": 9,
      "z": -6,
      "name": "Wood_Fir_Trunk_Full_Locked",
      "support": 15,
      "rotation": 5
    },
    {
      "x": -19,
      "y": 7,
      "z": -3,
      "name": "Wood_Fir_Trunk_Full_Locked",
      "support": 15,
      "rotation": 5
    },
    {
      "x": -19,
      "y": 5,
      "z": 0,
      "name": "Wood_Fir_Trunk_Full_Locked",
      "support": 15,
      "rotation": 5
    },
    {
      "x": -19,
      "y": 14,
      "z": 0,
      "name": "Wood_Fir_Trunk_Full_Locked",
      "support": 15,
      "rotation": 5
    },
    {
      "x": -19,
      "y": 7,
      "z": 3,
      "name": "Wood_Fir_Trunk_Full_Locked",
      "support": 15,
      "rotation": 5
    },
    {
      "x": -19,
      "y": 14,
      "z": 3,
      "name": "Wood_Fir_Trunk_Full_Locked",
      "support": 15,
      "rotation": 5
    },
    {
      "x": -19,
      "y": 9,
      "z": 6,
      "name": "Wood_Fir_Trunk_Full_Locked",
      "support": 15,
      "rotation": 5
    },
    {
      "x": -19,
      "y": 14,
      "z": 6,
      "name": "Wood_Fir_Trunk_Full_Locked",
      "support": 15,
      "rotation": 5
    },
    {
      "x": -19,
      "y": 10,
      "z": 7,
      "name": "Wood_Blackwood_Planks"
    },
    {
      "x": -19,
      "y": 11,
      "z": 8,
      "name": "Wood_Fir_Trunk_Full_Locked",
      "support": 15,
      "rotation": 5
    },
    {
      "x": -19,
      "y": 14,
      "z": 8,
      "name": "Wood_Fir_Trunk_Full_Locked",
      "rotation": 5
    },
    {
      "x": -18,
      "y": 10,
      "z": -8,
      "name": "Wood_Fir_Trunk_Full_Locked",
      "support": 15,
      "rotation": 5
    },
    {
      "x": -18,
      "y": 11,
      "z": -8,
      "name": "Wood_Fir_Trunk_Full_Locked",
      "support": 15,
      "rotation": 5
    },
    {
      "x": -18,
      "y": 14,
      "z": -8,
      "name": "Wood_Fir_Trunk_Full_Locked",
      "rotation": 5
    },
    {
      "x": -18,
      "y": 8,
      "z": -6,
      "name": "Wood_Fir_Trunk_Full_Locked",
      "support": 15,
      "rotation": 5
    },
    {
      "x": -18,
      "y": 9,
      "z": -6,
      "name": "Wood_Fir_Trunk_Full_Locked",
      "support": 15,
      "rotation": 5
    },
    {
      "x": -18,
      "y": 6,
      "z": -3,
      "name": "Wood_Fir_Trunk_Full_Locked",
      "support": 15,
      "rotation": 5
    },
    {
      "x": -18,
      "y": 7,
      "z": -3,
      "name": "Wood_Fir_Trunk_Full_Locked",
      "support": 15,
      "rotation": 5
    },
    {
      "x": -18,
      "y": 5,
      "z": 0,
      "name": "Wood_Fir_Trunk_Full_Locked",
      "support": 15,
      "rotation": 5
    },
    {
      "x": -18,
      "y": 14,
      "z": 0,
      "name": "Wood_Fir_Trunk_Full_Locked",
      "support": 15,
      "rotation": 5
    },
    {
      "x": -18,
      "y": 6,
      "z": 3,
      "name": "Wood_Fir_Trunk_Full_Locked",
      "support": 15,
      "rotation": 5
    },
    {
      "x": -18,
      "y": 7,
      "z": 3,
      "name": "Wood_Fir_Trunk_Full_Locked",
      "support": 15,
      "rotation": 5
    },
    {
      "x": -18,
      "y": 14,
      "z": 3,
      "name": "Wood_Fir_Trunk_Full_Locked",
      "support": 15,
      "rotation": 5
    },
    {
      "x": -18,
      "y": 8,
      "z": 6,
      "name": "Wood_Fir_Trunk_Full_Locked",
      "support": 15,
      "rotation": 5
    },
    {
      "x": -18,
      "y": 9,
      "z": 6,
      "name": "Wood_Fir_Trunk_Full_Locked",
      "support": 15,
      "rotation": 5
    },
    {
      "x": -18,
      "y": 14,
      "z": 6,
      "name": "Wood_Fir_Trunk_Full_Locked",
      "support": 15,
      "rotation": 5
    },
    {
      "x": -18,
      "y": 9,
      "z": 7,
      "name": "Wood_Blackwood_Planks"
    },
    {
      "x": -18,
      "y": 10,
      "z": 7,
      "name": "Wood_Blackwood_Planks"
    },
    {
      "x": -18,
      "y": 10,
      "z": 8,
      "name": "Wood_Fir_Trunk_Full_Locked",
      "support": 15,
      "rotation": 5
    },
    {
      "x": -18,
      "y": 11,
      "z": 8,
      "name": "Wood_Fir_Trunk_Full_Locked",
      "support": 15,
      "rotation": 5
    },
    {
      "x": -18,
      "y": 14,
      "z": 8,
      "name": "Wood_Fir_Trunk_Full_Locked",
      "rotation": 5
    },
    {
      "x": -17,
      "y": 10,
      "z": -8,
      "name": "Wood_Fir_Trunk_Full_Locked",
      "support": 15,
      "rotation": 5
    },
    {
      "x": -17,
      "y": 14,
      "z": -8,
      "name": "Wood_Fir_Trunk_Full_Locked",
      "rotation": 5
    },
    {
      "x": -17,
      "y": 8,
      "z": -6,
      "name": "Wood_Fir_Trunk_Full_Locked",
      "support": 15,
      "rotation": 5
    },
    {
      "x": -17,
      "y": 6,
      "z": -3,
      "name": "Wood_Fir_Trunk_Full_Locked",
      "support": 15,
      "rotation": 5
    },
    {
      "x": -17,
      "y": 5,
      "z": 0,
      "name": "Wood_Fir_Trunk_Full_Locked",
      "support": 15,
      "rotation": 5
    },
    {
      "x": -17,
      "y": 14,
      "z": 0,
      "name": "Wood_Fir_Trunk_Full_Locked",
      "support": 15,
      "rotation": 5
    },
    {
      "x": -17,
      "y": 6,
      "z": 3,
      "name": "Wood_Fir_Trunk_Full_Locked",
      "support": 15,
      "rotation": 5
    },
    {
      "x": -17,
      "y": 14,
      "z": 3,
      "name": "Wood_Fir_Trunk_Full_Locked",
      "support": 15,
      "rotation": 5
    },
    {
      "x": -17,
      "y": 8,
      "z": 6,
      "name": "Wood_Fir_Trunk_Full_Locked",
      "support": 15,
      "rotation": 5
    },
    {
      "x": -17,
      "y": 14,
      "z": 6,
      "name": "Wood_Fir_Trunk_Full_Locked",
      "support": 15,
      "rotation": 5
    },
    {
      "x": -17,
      "y": 9,
      "z": 7,
      "name": "Wood_Blackwood_Planks"
    },
    {
      "x": -17,
      "y": 10,
      "z": 8,
      "name": "Wood_Fir_Trunk_Full_Locked",
      "support": 15,
      "rotation": 5
    },
    {
      "x": -17,
      "y": 14,
      "z": 8,
      "name": "Wood_Fir_Trunk_Full_Locked",
      "rotation": 5
    },
    {
      "x": -16,
      "y": 14,
      "z": -9,
      "name": "Wood_Fir_Trunk_Full_Locked",
      "rotation": 5
    },
    {
      "x": -16,
      "y": 9,
      "z": -8,
      "name": "Wood_Fir_Trunk_Full_Locked",
      "support": 15,
      "rotation": 5
    },
    {
      "x": -16,
      "y": 10,
      "z": -8,
      "name": "Wood_Fir_Trunk_Full_Locked",
      "support": 15,
      "rotation": 5
    },
    {
      "x": -16,
      "y": 7,
      "z": -6,
      "name": "Wood_Fir_Trunk_Full_Locked",
      "support": 15,
      "rotation": 5
    },
    {
      "x": -16,
      "y": 8,
      "z": -6,
      "name": "Wood_Fir_Trunk_Full_Locked",
      "support": 15,
      "rotation": 5
    },
    {
      "x": -16,
      "y": 5,
      "z": -3,
      "name": "Wood_Fir_Trunk_Full_Locked",
      "support": 15,
      "rotation": 5
    },
    {
      "x": -16,
      "y": 6,
      "z": -3,
      "name": "Wood_Fir_Trunk_Full_Locked",
      "support": 15,
      "rotation": 5
    },
    {
      "x": -16,
      "y": 4,
      "z": 0,
      "name": "Wood_Fir_Trunk_Full_Locked",
      "support": 15,
      "rotation": 5
    },
    {
      "x": -16,
      "y": 5,
      "z": 0,
      "name": "Wood_Fir_Trunk_Full_Locked",
      "support": 15,
      "rotation": 2
    },
    {
      "x": -16,
      "y": 14,
      "z": 0,
      "name": "Wood_Fir_Trunk_Full_Locked",
      "support": 15,
      "rotation": 5
    },
    {
      "x": -16,
      "y": 5,
      "z": 3,
      "name": "Wood_Fir_Trunk_Full_Locked",
      "support": 15,
      "rotation": 5
    },
    {
      "x": -16,
      "y": 6,
      "z": 3,
      "name": "Wood_Fir_Trunk_Full_Locked",
      "support": 15,
      "rotation": 5
    },
    {
      "x": -16,
      "y": 14,
      "z": 3,
      "name": "Wood_Fir_Trunk_Full_Locked",
      "support": 15,
      "rotation": 5
    },
    {
      "x": -16,
      "y": 7,
      "z": 6,
      "name": "Wood_Fir_Trunk_Full_Locked",
      "support": 15,
      "rotation": 5
    },
    {
      "x": -16,
      "y": 8,
      "z": 6,
      "name": "Wood_Fir_Trunk_Full_Locked",
      "support": 15,
      "rotation": 5
    },
    {
      "x": -16,
      "y": 14,
      "z": 6,
      "name": "Wood_Fir_Trunk_Full_Locked",
      "support": 15,
      "rotation": 5
    },
    {
      "x": -16,
      "y": 8,
      "z": 7,
      "name": "Wood_Blackwood_Planks"
    },
    {
      "x": -16,
      "y": 9,
      "z": 7,
      "name": "Wood_Blackwood_Planks"
    },
    {
      "x": -16,
      "y": 9,
      "z": 8,
      "name": "Wood_Fir_Trunk_Full_Locked",
      "support": 15,
      "rotation": 5
    },
    {
      "x": -16,
      "y": 10,
      "z": 8,
      "name": "Wood_Fir_Trunk_Full_Locked",
      "support": 15,
      "rotation": 5
    },
    {
      "x": -16,
      "y": 14,
      "z": 9,
      "name": "Wood_Fir_Trunk_Full_Locked",
      "rotation": 5
    },
    {
      "x": -15,
      "y": 14,
      "z": -9,
      "name": "Wood_Fir_Trunk_Full_Locked",
      "rotation": 5
    },
    {
      "x": -15,
      "y": 9,
      "z": -8,
      "name": "Wood_Fir_Trunk_Full_Locked",
      "support": 15,
      "rotation": 5
    },
    {
      "x": -15,
      "y": 10,
      "z": -8,
      "name": "Wood_Fir_Trunk_Full_Locked",
      "support": 15,
      "rotation": 5
    },
    {
      "x": -15,
      "y": 7,
      "z": -6,
      "name": "Wood_Fir_Trunk_Full_Locked",
      "support": 15,
      "rotation": 5
    },
    {
      "x": -15,
      "y": 5,
      "z": -3,
      "name": "Wood_Fir_Trunk_Full_Locked",
      "support": 15,
      "rotation": 5
    },
    {
      "x": -15,
      "y": 4,
      "z": 0,
      "name": "Wood_Fir_Trunk_Full_Locked",
      "support": 15,
      "rotation": 5
    },
    {
      "x": -15,
      "y": 14,
      "z": 0,
      "name": "Wood_Fir_Trunk_Full_Locked",
      "support": 15,
      "rotation": 5
    },
    {
      "x": -15,
      "y": 5,
      "z": 3,
      "name": "Wood_Fir_Trunk_Full_Locked",
      "support": 15,
      "rotation": 5
    },
    {
      "x": -15,
      "y": 14,
      "z": 3,
      "name": "Wood_Fir_Trunk_Full_Locked",
      "support": 15,
      "rotation": 5
    },
    {
      "x": -15,
      "y": 7,
      "z": 6,
      "name": "Wood_Fir_Trunk_Full_Locked",
      "support": 15,
      "rotation": 5
    },
    {
      "x": -15,
      "y": 14,
      "z": 6,
      "name": "Wood_Fir_Trunk_Full_Locked",
      "support": 15,
      "rotation": 5
    },
    {
      "x": -15,
      "y": 8,
      "z": 7,
      "name": "Wood_Blackwood_Planks"
    },
    {
      "x": -15,
      "y": 9,
      "z": 8,
      "name": "Wood_Fir_Trunk_Full_Locked",
      "support": 15,
      "rotation": 5
    },
    {
      "x": -15,
      "y": 10,
      "z": 8,
      "name": "Wood_Fir_Trunk_Full_Locked",
      "support": 15,
      "rotation": 5
    },
    {
      "x": -15,
      "y": 14,
      "z": 9,
      "name": "Wood_Fir_Trunk_Full_Locked",
      "rotation": 5
    },
    {
      "x": -14,
      "y": 10,
      "z": -9,
      "name": "Wood_Fir_Trunk_Full_Locked",
      "support": 15,
      "rotation": 5
    },
    {
      "x": -14,
      "y": 11,
      "z": -9,
      "name": "Wood_Fir_Trunk_Full_Locked",
      "support": 15,
      "rotation": 2
    },
    {
      "x": -14,
      "y": 12,
      "z": -9,
      "name": "Wood_Fir_Trunk_Full_Locked",
      "support": 15,
      "rotation": 2
    },
    {
      "x": -14,
      "y": 13,
      "z": -9,
      "name": "Wood_Fir_Trunk_Full_Locked",
      "support": 15,
      "rotation": 2
    },
    {
      "x": -14,
      "y": 14,
      "z": -9,
      "name": "Wood_Fir_Trunk_Full_Locked",
      "rotation": 5
    },
    {
      "x": -14,
      "y": 8,
      "z": -8,
      "name": "Wood_Fir_Trunk_Full_Locked",
      "support": 15,
      "rotation": 5
    },
    {
      "x": -14,
      "y": 9,
      "z": -8,
      "name": "Wood_Fir_Trunk_Full_Locked",
      "support": 15,
      "rotation": 5
    },
    {
      "x": -14,
      "y": 10,
      "z": -8,
      "name": "Wood_Fir_Trunk_Full_Locked",
      "support": 15,
      "rotation": 6
    },
    {
      "x": -14,
      "y": 6,
      "z": -6,
      "name": "Wood_Fir_Trunk_Full_Locked",
      "support": 15,
      "rotation": 5
    },
    {
      "x": -14,
      "y": 7,
      "z": -6,
      "name": "Wood_Fir_Trunk_Full_Locked",
      "support": 15,
      "rotation": 5
    },
    {
      "x": -14,
      "y": 5,
      "z": -3,
      "name": "Wood_Fir_Trunk_Full_Locked",
      "support": 15,
      "rotation": 5
    },
    {
      "x": -14,
      "y": 4,
      "z": 0,
      "name": "Wood_Fir_Trunk_Full_Locked",
      "support": 15,
      "rotation": 5
    },
    {
      "x": -14,
      "y": 14,
      "z": 0,
      "name": "Wood_Fir_Trunk_Full_Locked",
      "support": 15,
      "rotation": 5
    },
    {
      "x": -14,
      "y": 5,
      "z": 3,
      "name": "Wood_Fir_Trunk_Full_Locked",
      "support": 15,
      "rotation": 5
    },
    {
      "x": -14,
      "y": 14,
      "z": 3,
      "name": "Wood_Fir_Trunk_Full_Locked",
      "support": 15,
      "rotation": 5
    },
    {
      "x": -14,
      "y": 6,
      "z": 6,
      "name": "Wood_Fir_Trunk_Full_Locked",
      "support": 15,
      "rotation": 5
    },
    {
      "x": -14,
      "y": 7,
      "z": 6,
      "name": "Wood_Fir_Trunk_Full_Locked",
      "support": 15,
      "rotation": 5
    },
    {
      "x": -14,
      "y": 14,
      "z": 6,
      "name": "Wood_Fir_Trunk_Full_Locked",
      "support": 15,
      "rotation": 5
    },
    {
      "x": -14,
      "y": 8,
      "z": 7,
      "name": "Wood_Blackwood_Planks"
    },
    {
      "x": -14,
      "y": 8,
      "z": 8,
      "name": "Wood_Fir_Trunk_Full_Locked",
      "support": 15,
      "rotation": 5
    },
    {
      "x": -14,
      "y": 9,
      "z": 8,
      "name": "Wood_Fir_Trunk_Full_Locked",
      "support": 15,
      "rotation": 5
    },
    {
      "x": -14,
      "y": 10,
      "z": 8,
      "name": "Wood_Fir_Trunk_Full_Locked",
      "support": 15,
      "rotation": 4
    },
    {
      "x": -14,
      "y": 10,
      "z": 9,
      "name": "Wood_Fir_Trunk_Full_Locked",
      "support": 15,
      "rotation": 5
    },
    {
      "x": -14,
      "y": 11,
      "z": 9,
      "name": "Wood_Fir_Trunk_Full_Locked",
      "support": 15
    },
    {
      "x": -14,
      "y": 12,
      "z": 9,
      "name": "Wood_Fir_Trunk_Full_Locked",
      "support": 15
    },
    {
      "x": -14,
      "y": 13,
      "z": 9,
      "name": "Wood_Fir_Trunk_Full_Locked",
      "support": 15
    },
    {
      "x": -14,
      "y": 14,
      "z": 9,
      "name": "Wood_Fir_Trunk_Full_Locked",
      "rotation": 5
    },
    {
      "x": -13,
      "y": 10,
      "z": -9,
      "name": "Wood_Fir_Trunk_Full_Locked",
      "support": 15,
      "rotation": 5
    },
    {
      "x": -13,
      "y": 14,
      "z": -9,
      "name": "Wood_Fir_Trunk_Full_Locked",
      "rotation": 5
    },
    {
      "x": -13,
      "y": 8,
      "z": -8,
      "name": "Wood_Fir_Trunk_Full_Locked",
      "support": 15,
      "rotation": 5
    },
    {
      "x": -13,
      "y": 6,
      "z": -6,
      "name": "Wood_Fir_Trunk_Full_Locked",
      "support": 15,
      "rotation": 5
    },
    {
      "x": -13,
      "y": 4,
      "z": -3,
      "name": "Wood_Fir_Trunk_Full_Locked",
      "support": 15,
      "rotation": 5
    },
    {
      "x": -13,
      "y": 5,
      "z": -3,
      "name": "Wood_Fir_Trunk_Full_Locked",
      "support": 15,
      "rotation": 5
    },
    {
      "x": -13,
      "y": 4,
      "z": 0,
      "name": "Wood_Fir_Trunk_Full_Locked",
      "support": 15,
      "rotation": 5
    },
    {
      "x": -13,
      "y": 14,
      "z": 0,
      "name": "Wood_Fir_Trunk_Full_Locked",
      "support": 15,
      "rotation": 5
    },
    {
      "x": -13,
      "y": 4,
      "z": 3,
      "name": "Wood_Fir_Trunk_Full_Locked",
      "support": 15,
      "rotation": 5
    },
    {
      "x": -13,
      "y": 5,
      "z": 3,
      "name": "Wood_Fir_Trunk_Full_Locked",
      "support": 15,
      "rotation": 5
    },
    {
      "x": -13,
      "y": 14,
      "z": 3,
      "name": "Wood_Fir_Trunk_Full_Locked",
      "support": 15,
      "rotation": 5
    },
    {
      "x": -13,
      "y": 6,
      "z": 6,
      "name": "Wood_Fir_Trunk_Full_Locked",
      "support": 15,
      "rotation": 5
    },
    {
      "x": -13,
      "y": 14,
      "z": 6,
      "name": "Wood_Fir_Trunk_Full_Locked",
      "support": 15,
      "rotation": 5
    },
    {
      "x": -13,
      "y": 7,
      "z": 7,
      "name": "Wood_Blackwood_Planks"
    },
    {
      "x": -13,
      "y": 8,
      "z": 7,
      "name": "Wood_Blackwood_Planks"
    },
    {
      "x": -13,
      "y": 8,
      "z": 8,
      "name": "Wood_Fir_Trunk_Full_Locked",
      "support": 15,
      "rotation": 5
    },
    {
      "x": -13,
      "y": 9,
      "z": 9,
      "name": "Wood_Blackwood_Planks"
    },
    {
      "x": -13,
      "y": 10,
      "z": 9,
      "name": "Wood_Fir_Trunk_Full_Locked",
      "support": 15,
      "rotation": 5
    },
    {
      "x": -13,
      "y": 11,
      "z": 9,
      "name": "Wood_Fir_Trunk_Full_Locked",
      "support": 15
    },
    {
      "x": -13,
      "y": 12,
      "z": 9,
      "name": "Wood_Fir_Trunk_Full_Locked",
      "support": 15
    },
    {
      "x": -13,
      "y": 13,
      "z": 9,
      "name": "Wood_Fir_Trunk_Full_Locked",
      "support": 15
    },
    {
      "x": -13,
      "y": 14,
      "z": 9,
      "name": "Wood_Fir_Trunk_Full_Locked",
      "rotation": 5
    },
    {
      "x": -12,
      "y": 10,
      "z": -9,
      "name": "Wood_Fir_Trunk_Full_Locked",
      "support": 15,
      "rotation": 5
    },
    {
      "x": -12,
      "y": 14,
      "z": -9,
      "name": "Wood_Fir_Trunk_Full_Locked",
      "rotation": 5
    },
    {
      "x": -12,
      "y": 7,
      "z": -8,
      "name": "Wood_Fir_Trunk_Full_Locked",
      "support": 15,
      "rotation": 5
    },
    {
      "x": -12,
      "y": 8,
      "z": -8,
      "name": "Wood_Fir_Trunk_Full_Locked",
      "support": 15,
      "rotation": 5
    },
    {
      "x": -12,
      "y": 6,
      "z": -6,
      "name": "Wood_Fir_Trunk_Full_Locked",
      "support": 15,
      "rotation": 5
    },
    {
      "x": -12,
      "y": 4,
      "z": -3,
      "name": "Wood_Fir_Trunk_Full_Locked",
      "support": 15,
      "rotation": 5
    },
    {
      "x": -12,
      "y": 4,
      "z": 0,
      "name": "Wood_Fir_Trunk_Full_Locked",
      "support": 15,
      "rotation": 5
    },
    {
      "x": -12,
      "y": 14,
      "z": 0,
      "name": "Wood_Fir_Trunk_Full_Locked",
      "support": 15,
      "rotation": 5
    },
    {
      "x": -12,
      "y": 10,
      "z": 1,
      "name": "Wood_Deadwood_Planks"
    },
    {
      "x": -12,
      "y": 10,
      "z": 2,
      "name": "Wood_Deadwood_Planks"
    },
    {
      "x": -12,
      "y": 4,
      "z": 3,
      "name": "Wood_Fir_Trunk_Full_Locked",
      "support": 15,
      "rotation": 5
    },
    {
      "x": -12,
      "y": 10,
      "z": 3,
      "name": "Wood_Deadwood_Planks"
    },
    {
      "x": -12,
      "y": 14,
      "z": 3,
      "name": "Wood_Fir_Trunk_Full_Locked",
      "support": 15,
      "rotation": 5
    },
    {
      "x": -12,
      "y": 10,
      "z": 4,
      "name": "Wood_Deadwood_Planks"
    },
    {
      "x": -12,
      "y": 10,
      "z": 5,
      "name": "Wood_Deadwood_Planks"
    },
    {
      "x": -12,
      "y": 6,
      "z": 6,
      "name": "Wood_Fir_Trunk_Full_Locked",
      "support": 15,
      "rotation": 5
    },
    {
      "x": -12,
      "y": 10,
      "z": 6,
      "name": "Wood_Deadwood_Planks"
    },
    {
      "x": -12,
      "y": 14,
      "z": 6,
      "name": "Wood_Fir_Trunk_Full_Locked",
      "support": 15,
      "rotation": 5
    },
    {
      "x": -12,
      "y": 7,
      "z": 7,
      "name": "Wood_Blackwood_Planks"
    },
    {
      "x": -12,
      "y": 8,
      "z": 7,
      "name": "Wood_Blackwood_Planks"
    },
    {
      "x": -12,
      "y": 10,
      "z": 7,
      "name": "Wood_Deadwood_Planks"
    },
    {
      "x": -12,
      "y": 7,
      "z": 8,
      "name": "Wood_Fir_Trunk_Full_Locked",
      "support": 15,
      "rotation": 5
    },
    {
      "x": -12,
      "y": 8,
      "z": 8,
      "name": "Wood_Fir_Trunk_Full_Locked",
      "support": 15,
      "rotation": 5
    },
    {
      "x": -12,
      "y": 10,
      "z": 8,
      "name": "Wood_Deadwood_Planks"
    },
    {
      "x": -12,
      "y": 9,
      "z": 9,
      "name": "Wood_Blackwood_Planks"
    },
    {
      "x": -12,
      "y": 10,
      "z": 9,
      "name": "Wood_Fir_Trunk_Full_Locked",
      "support": 15,
      "rotation": 5
    },
    {
      "x": -12,
      "y": 11,
      "z": 9,
      "name": "Wood_Blackwood_Stairs",
      "rotation": 1
    },
    {
      "x": -12,
      "y": 13,
      "z": 9,
      "name": "Wood_Blackwood_Stairs",
      "rotation": 11
    },
    {
      "x": -12,
      "y": 14,
      "z": 9,
      "name": "Wood_Fir_Trunk_Full_Locked",
      "rotation": 5
    },
    {
      "x": -12,
      "y": 13,
      "z": 10,
      "name": "Furniture_Tavern_Platform"
    },
    {
      "x": -12,
      "y": 13,
      "z": 11,
      "name": "Furniture_Tavern_Platform"
    },
    {
      "x": -11,
      "y": 10,
      "z": -9,
      "name": "Wood_Fir_Trunk_Full_Locked",
      "support": 15,
      "rotation": 5
    },
    {
      "x": -11,
      "y": 14,
      "z": -9,
      "name": "Wood_Fir_Trunk_Full_Locked",
      "rotation": 5
    },
    {
      "x": -11,
      "y": 7,
      "z": -8,
      "name": "Wood_Fir_Trunk_Full_Locked",
      "support": 15,
      "rotation": 5
    },
    {
      "x": -11,
      "y": 5,
      "z": -6,
      "name": "Wood_Fir_Trunk_Full_Locked",
      "support": 15,
      "rotation": 5
    },
    {
      "x": -11,
      "y": 6,
      "z": -6,
      "name": "Wood_Fir_Trunk_Full_Locked",
      "support": 15,
      "rotation": 5
    },
    {
      "x": -11,
      "y": 4,
      "z": -3,
      "name": "Wood_Fir_Trunk_Full_Locked",
      "support": 15,
      "rotation": 5
    },
    {
      "x": -11,
      "y": 4,
      "z": 0,
      "name": "Wood_Fir_Trunk_Full_Locked",
      "support": 15,
      "rotation": 5
    },
    {
      "x": -11,
      "y": 14,
      "z": 0,
      "name": "Wood_Fir_Trunk_Full_Locked",
      "support": 15,
      "rotation": 5
    },
    {
      "x": -11,
      "y": 10,
      "z": 1,
      "name": "Wood_Deadwood_Planks"
    },
    {
      "x": -11,
      "y": 10,
      "z": 2,
      "name": "Wood_Deadwood_Planks"
    },
    {
      "x": -11,
      "y": 4,
      "z": 3,
      "name": "Wood_Fir_Trunk_Full_Locked",
      "support": 15,
      "rotation": 5
    },
    {
      "x": -11,
      "y": 10,
      "z": 3,
      "name": "Wood_Deadwood_Planks"
    },
    {
      "x": -11,
      "y": 14,
      "z": 3,
      "name": "Wood_Fir_Trunk_Full_Locked",
      "support": 15,
      "rotation": 5
    },
    {
      "x": -11,
      "y": 10,
      "z": 4,
      "name": "Wood_Deadwood_Planks"
    },
    {
      "x": -11,
      "y": 10,
      "z": 5,
      "name": "Wood_Deadwood_Planks"
    },
    {
      "x": -11,
      "y": 5,
      "z": 6,
      "name": "Wood_Fir_Trunk_Full_Locked",
      "support": 15,
      "rotation": 5
    },
    {
      "x": -11,
      "y": 6,
      "z": 6,
      "name": "Wood_Fir_Trunk_Full_Locked",
      "support": 15,
      "rotation": 5
    },
    {
      "x": -11,
      "y": 10,
      "z": 6,
      "name": "Wood_Deadwood_Planks"
    },
    {
      "x": -11,
      "y": 11,
      "z": 6,
      "name": "Bench_Farming",
      "filler": 992,
      "rotation": 3
    },
    {
      "x": -11,
      "y": 12,
      "z": 6,
      "name": "Metal_Iron_Pipe_Large_Mouthpiece",
      "rotation": 6
    },
    {
      "x": -11,
      "y": 14,
      "z": 6,
      "name": "Wood_Fir_Trunk_Full_Locked",
      "support": 15,
      "rotation": 5
    },
    {
      "x": -11,
      "y": 7,
      "z": 7,
      "name": "Wood_Blackwood_Planks"
    },
    {
      "x": -11,
      "y": 10,
      "z": 7,
      "name": "Wood_Deadwood_Planks"
    },
    {
      "x": -11,
      "y": 11,
      "z": 7,
      "name": "Bench_Farming",
      "components": {
        "Components": {
          "BenchBlock": {
            "TierLevel": 1,
            "UpgradeItems": []
          },
          "PlacedByInteraction": {
            "WhoPlacedUuid": {
              "$binary": "+u0Lek23TWiDpMOn5L2LqA==",
              "$type": "04"
            }
          }
        }
      },
      "rotation": 3
    },
    {
      "x": -11,
      "y": 12,
      "z": 7,
      "name": "Metal_Iron_Pipe_Large",
      "rotation": 6
    },
    {
      "x": -11,
      "y": 7,
      "z": 8,
      "name": "Wood_Fir_Trunk_Full_Locked",
      "support": 15,
      "rotation": 5
    },
    {
      "x": -11,
      "y": 10,
      "z": 8,
      "name": "Wood_Deadwood_Planks"
    },
    {
      "x": -11,
      "y": 12,
      "z": 8,
      "name": "Metal_Iron_Pipe_Large",
      "rotation": 4
    },
    {
      "x": -11,
      "y": 8,
      "z": 9,
      "name": "Wood_Blackwood_Planks_Half",
      "rotation": 4
    },
    {
      "x": -11,
      "y": 9,
      "z": 9,
      "name": "Wood_Blackwood_Planks"
    },
    {
      "x": -11,
      "y": 10,
      "z": 9,
      "name": "Wood_Fir_Trunk_Full_Locked",
      "support": 15,
      "rotation": 5
    },
    {
      "x": -11,
      "y": 11,
      "z": 9,
      "name": "Wood_Blackwood_Planks_Half"
    },
    {
      "x": -11,
      "y": 13,
      "z": 9,
      "name": "Wood_Blackwood_Planks_Half",
      "rotation": 8
    },
    {
      "x": -11,
      "y": 14,
      "z": 9,
      "name": "Wood_Fir_Trunk_Full_Locked",
      "rotation": 5
    },
    {
      "x": -11,
      "y": 13,
      "z": 10,
      "name": "Furniture_Tavern_Shelf"
    },
    {
      "x": -11,
      "y": 13,
      "z": 11,
      "name": "Furniture_Tavern_Platform"
    },
    {
      "x": -10,
      "y": 10,
      "z": -9,
      "name": "Wood_Fir_Trunk_Full_Locked",
      "support": 15,
      "rotation": 5
    },
    {
      "x": -10,
      "y": 14,
      "z": -9,
      "name": "Wood_Fir_Trunk_Full_Locked",
      "rotation": 5
    },
    {
      "x": -10,
      "y": 7,
      "z": -8,
      "name": "Wood_Fir_Trunk_Full_Locked",
      "support": 15,
      "rotation": 5
    },
    {
      "x": -10,
      "y": 5,
      "z": -6,
      "name": "Wood_Fir_Trunk_Full_Locked",
      "support": 15,
      "rotation": 5
    },
    {
      "x": -10,
      "y": 4,
      "z": -3,
      "name": "Wood_Fir_Trunk_Full_Locked",
      "support": 15,
      "rotation": 5
    },
    {
      "x": -10,
      "y": 4,
      "z": 0,
      "name": "Wood_Fir_Trunk_Full_Locked",
      "support": 15,
      "rotation": 5
    },
    {
      "x": -10,
      "y": 14,
      "z": 0,
      "name": "Wood_Fir_Trunk_Full_Locked",
      "support": 15,
      "rotation": 5
    },
    {
      "x": -10,
      "y": 10,
      "z": 1,
      "name": "Wood_Deadwood_Planks"
    },
    {
      "x": -10,
      "y": 10,
      "z": 2,
      "name": "Wood_Deadwood_Planks"
    },
    {
      "x": -10,
      "y": 4,
      "z": 3,
      "name": "Wood_Fir_Trunk_Full_Locked",
      "support": 15,
      "rotation": 5
    },
    {
      "x": -10,
      "y": 10,
      "z": 3,
      "name": "Wood_Deadwood_Planks"
    },
    {
      "x": -10,
      "y": 14,
      "z": 3,
      "name": "Wood_Fir_Trunk_Full_Locked",
      "support": 15,
      "rotation": 5
    },
    {
      "x": -10,
      "y": 10,
      "z": 4,
      "name": "Wood_Deadwood_Planks"
    },
    {
      "x": -10,
      "y": 10,
      "z": 5,
      "name": "Wood_Deadwood_Planks"
    },
    {
      "x": -10,
      "y": 5,
      "z": 6,
      "name": "Wood_Fir_Trunk_Full_Locked",
      "support": 15,
      "rotation": 5
    },
    {
      "x": -10,
      "y": 10,
      "z": 6,
      "name": "Wood_Deadwood_Planks"
    },
    {
      "x": -10,
      "y": 14,
      "z": 6,
      "name": "Wood_Fir_Trunk_Full_Locked",
      "support": 15,
      "rotation": 5
    },
    {
      "x": -10,
      "y": 6,
      "z": 7,
      "name": "Wood_Blackwood_Planks"
    },
    {
      "x": -10,
      "y": 10,
      "z": 7,
      "name": "Wood_Deadwood_Planks"
    },
    {
      "x": -10,
      "y": 7,
      "z": 8,
      "name": "Wood_Fir_Trunk_Full_Locked",
      "support": 15,
      "rotation": 5
    },
    {
      "x": -10,
      "y": 10,
      "z": 8,
      "name": "Wood_Deadwood_Planks"
    },
    {
      "x": -10,
      "y": 8,
      "z": 9,
      "name": "Wood_Blackwood_Planks_Half",
      "rotation": 4
    },
    {
      "x": -10,
      "y": 9,
      "z": 9,
      "name": "Wood_Blackwood_Planks"
    },
    {
      "x": -10,
      "y": 10,
      "z": 9,
      "name": "Wood_Fir_Trunk_Full_Locked",
      "support": 15,
      "rotation": 5
    },
    {
      "x": -10,
      "y": 11,
      "z": 9,
      "name": "Wood_Blackwood_Stairs",
      "rotation": 3
    },
    {
      "x": -10,
      "y": 13,
      "z": 9,
      "name": "Wood_Blackwood_Stairs",
      "rotation": 9
    },
    {
      "x": -10,
      "y": 14,
      "z": 9,
      "name": "Wood_Fir_Trunk_Full_Locked",
      "rotation": 5
    },
    {
      "x": -10,
      "y": 13,
      "z": 10,
      "name": "Furniture_Tavern_Platform"
    },
    {
      "x": -10,
      "y": 13,
      "z": 11,
      "name": "Furniture_Tavern_Platform"
    },
    {
      "x": -9,
      "y": 10,
      "z": -9,
      "name": "Wood_Fir_Trunk_Full_Locked",
      "support": 15,
      "rotation": 5
    },
    {
      "x": -9,
      "y": 14,
      "z": -9,
      "name": "Wood_Fir_Trunk_Full_Locked",
      "rotation": 5
    },
    {
      "x": -9,
      "y": 7,
      "z": -8,
      "name": "Wood_Fir_Trunk_Full_Locked",
      "support": 15,
      "rotation": 5
    },
    {
      "x": -9,
      "y": 5,
      "z": -6,
      "name": "Wood_Fir_Trunk_Full_Locked",
      "support": 15,
      "rotation": 5
    },
    {
      "x": -9,
      "y": 4,
      "z": -3,
      "name": "Wood_Fir_Trunk_Full_Locked",
      "support": 15,
      "rotation": 5
    },
    {
      "x": -9,
      "y": 4,
      "z": 0,
      "name": "Wood_Fir_Trunk_Full_Locked",
      "support": 15,
      "rotation": 5
    },
    {
      "x": -9,
      "y": 14,
      "z": 0,
      "name": "Wood_Fir_Trunk_Full_Locked",
      "support": 15,
      "rotation": 5
    },
    {
      "x": -9,
      "y": 10,
      "z": 1,
      "name": "Wood_Deadwood_Planks"
    },
    {
      "x": -9,
      "y": 10,
      "z": 2,
      "name": "Wood_Deadwood_Planks"
    },
    {
      "x": -9,
      "y": 4,
      "z": 3,
      "name": "Wood_Fir_Trunk_Full_Locked",
      "support": 15,
      "rotation": 5
    },
    {
      "x": -9,
      "y": 10,
      "z": 3,
      "name": "Wood_Deadwood_Planks"
    },
    {
      "x": -9,
      "y": 14,
      "z": 3,
      "name": "Wood_Fir_Trunk_Full_Locked",
      "support": 15,
      "rotation": 5
    },
    {
      "x": -9,
      "y": 10,
      "z": 4,
      "name": "Wood_Deadwood_Planks"
    },
    {
      "x": -9,
      "y": 10,
      "z": 5,
      "name": "Wood_Deadwood_Planks"
    },
    {
      "x": -9,
      "y": 5,
      "z": 6,
      "name": "Wood_Fir_Trunk_Full_Locked",
      "support": 15,
      "rotation": 5
    },
    {
      "x": -9,
      "y": 10,
      "z": 6,
      "name": "Wood_Deadwood_Planks"
    },
    {
      "x": -9,
      "y": 14,
      "z": 6,
      "name": "Wood_Fir_Trunk_Full_Locked",
      "support": 15,
      "rotation": 5
    },
    {
      "x": -9,
      "y": 6,
      "z": 7,
      "name": "Wood_Blackwood_Planks"
    },
    {
      "x": -9,
      "y": 10,
      "z": 7,
      "name": "Wood_Deadwood_Planks"
    },
    {
      "x": -9,
      "y": 7,
      "z": 8,
      "name": "Wood_Fir_Trunk_Full_Locked",
      "support": 15,
      "rotation": 5
    },
    {
      "x": -9,
      "y": 10,
      "z": 8,
      "name": "Wood_Deadwood_Planks"
    },
    {
      "x": -9,
      "y": 8,
      "z": 9,
      "name": "Wood_Blackwood_Planks_Half",
      "rotation": 4
    },
    {
      "x": -9,
      "y": 9,
      "z": 9,
      "name": "Wood_Blackwood_Planks"
    },
    {
      "x": -9,
      "y": 10,
      "z": 9,
      "name": "Wood_Fir_Trunk_Full_Locked",
      "support": 15,
      "rotation": 5
    },
    {
      "x": -9,
      "y": 11,
      "z": 9,
      "name": "Wood_Fir_Trunk_Full_Locked",
      "support": 15
    },
    {
      "x": -9,
      "y": 12,
      "z": 9,
      "name": "Wood_Fir_Trunk_Full_Locked",
      "support": 15
    },
    {
      "x": -9,
      "y": 13,
      "z": 9,
      "name": "Wood_Fir_Trunk_Full_Locked",
      "support": 15
    },
    {
      "x": -9,
      "y": 14,
      "z": 9,
      "name": "Wood_Fir_Trunk_Full_Locked",
      "rotation": 5
    },
    {
      "x": -8,
      "y": 10,
      "z": -9,
      "name": "Wood_Fir_Trunk_Full_Locked",
      "support": 15,
      "rotation": 5
    },
    {
      "x": -8,
      "y": 14,
      "z": -9,
      "name": "Wood_Fir_Trunk_Full_Locked",
      "rotation": 5
    },
    {
      "x": -8,
      "y": 7,
      "z": -8,
      "name": "Wood_Fir_Trunk_Full_Locked",
      "support": 15,
      "rotation": 5
    },
    {
      "x": -8,
      "y": 5,
      "z": -6,
      "name": "Wood_Fir_Trunk_Full_Locked",
      "support": 15,
      "rotation": 5
    },
    {
      "x": -8,
      "y": 4,
      "z": -3,
      "name": "Wood_Fir_Trunk_Full_Locked",
      "support": 15,
      "rotation": 5
    },
    {
      "x": -8,
      "y": 4,
      "z": 0,
      "name": "Wood_Fir_Trunk_Full_Locked",
      "support": 15,
      "rotation": 5
    },
    {
      "x": -8,
      "y": 14,
      "z": 0,
      "name": "Wood_Fir_Trunk_Full_Locked",
      "support": 15,
      "rotation": 5
    },
    {
      "x": -8,
      "y": 10,
      "z": 1,
      "name": "Wood_Deadwood_Planks"
    },
    {
      "x": -8,
      "y": 10,
      "z": 2,
      "name": "Wood_Deadwood_Planks"
    },
    {
      "x": -8,
      "y": 4,
      "z": 3,
      "name": "Wood_Fir_Trunk_Full_Locked",
      "support": 15,
      "rotation": 5
    },
    {
      "x": -8,
      "y": 10,
      "z": 3,
      "name": "Wood_Deadwood_Planks"
    },
    {
      "x": -8,
      "y": 14,
      "z": 3,
      "name": "Wood_Fir_Trunk_Full_Locked",
      "support": 15,
      "rotation": 5
    },
    {
      "x": -8,
      "y": 10,
      "z": 4,
      "name": "Wood_Deadwood_Planks"
    },
    {
      "x": -8,
      "y": 10,
      "z": 5,
      "name": "Wood_Deadwood_Planks"
    },
    {
      "x": -8,
      "y": 5,
      "z": 6,
      "name": "Wood_Fir_Trunk_Full_Locked",
      "support": 15,
      "rotation": 5
    },
    {
      "x": -8,
      "y": 10,
      "z": 6,
      "name": "Wood_Deadwood_Planks"
    },
    {
      "x": -8,
      "y": 14,
      "z": 6,
      "name": "Wood_Fir_Trunk_Full_Locked",
      "support": 15,
      "rotation": 5
    },
    {
      "x": -8,
      "y": 6,
      "z": 7,
      "name": "Wood_Blackwood_Planks"
    },
    {
      "x": -8,
      "y": 10,
      "z": 7,
      "name": "Wood_Deadwood_Planks"
    },
    {
      "x": -8,
      "y": 7,
      "z": 8,
      "name": "Wood_Fir_Trunk_Full_Locked",
      "support": 15,
      "rotation": 5
    },
    {
      "x": -8,
      "y": 10,
      "z": 8,
      "name": "Wood_Deadwood_Planks"
    },
    {
      "x": -8,
      "y": 8,
      "z": 9,
      "name": "Wood_Blackwood_Planks_Half",
      "rotation": 4
    },
    {
      "x": -8,
      "y": 9,
      "z": 9,
      "name": "Wood_Blackwood_Planks"
    },
    {
      "x": -8,
      "y": 10,
      "z": 9,
      "name": "Wood_Fir_Trunk_Full_Locked",
      "support": 15,
      "rotation": 5
    },
    {
      "x": -8,
      "y": 11,
      "z": 9,
      "name": "Wood_Blackwood_Stairs",
      "rotation": 1
    },
    {
      "x": -8,
      "y": 13,
      "z": 9,
      "name": "Wood_Blackwood_Stairs",
      "rotation": 11
    },
    {
      "x": -8,
      "y": 14,
      "z": 9,
      "name": "Wood_Fir_Trunk_Full_Locked",
      "rotation": 5
    },
    {
      "x": -8,
      "y": 13,
      "z": 10,
      "name": "Furniture_Tavern_Platform"
    },
    {
      "x": -8,
      "y": 13,
      "z": 11,
      "name": "Furniture_Tavern_Platform"
    },
    {
      "x": -7,
      "y": 10,
      "z": -9,
      "name": "Wood_Fir_Trunk_Full_Locked",
      "support": 15,
      "rotation": 5
    },
    {
      "x": -7,
      "y": 14,
      "z": -9,
      "name": "Wood_Fir_Trunk_Full_Locked",
      "rotation": 5
    },
    {
      "x": -7,
      "y": 7,
      "z": -8,
      "name": "Wood_Fir_Trunk_Full_Locked",
      "support": 15,
      "rotation": 5
    },
    {
      "x": -7,
      "y": 5,
      "z": -6,
      "name": "Wood_Fir_Trunk_Full_Locked",
      "support": 15,
      "rotation": 5
    },
    {
      "x": -7,
      "y": 4,
      "z": -3,
      "name": "Wood_Fir_Trunk_Full_Locked",
      "support": 15,
      "rotation": 5
    },
    {
      "x": -7,
      "y": 4,
      "z": 0,
      "name": "Wood_Fir_Trunk_Full_Locked",
      "support": 15,
      "rotation": 5
    },
    {
      "x": -7,
      "y": 14,
      "z": 0,
      "name": "Wood_Fir_Trunk_Full_Locked",
      "support": 15,
      "rotation": 5
    },
    {
      "x": -7,
      "y": 10,
      "z": 1,
      "name": "Wood_Deadwood_Planks"
    },
    {
      "x": -7,
      "y": 10,
      "z": 2,
      "name": "Wood_Deadwood_Planks"
    },
    {
      "x": -7,
      "y": 4,
      "z": 3,
      "name": "Wood_Fir_Trunk_Full_Locked",
      "support": 15,
      "rotation": 5
    },
    {
      "x": -7,
      "y": 10,
      "z": 3,
      "name": "Wood_Deadwood_Planks"
    },
    {
      "x": -7,
      "y": 14,
      "z": 3,
      "name": "Wood_Fir_Trunk_Full_Locked",
      "support": 15,
      "rotation": 5
    },
    {
      "x": -7,
      "y": 10,
      "z": 4,
      "name": "Wood_Deadwood_Planks"
    },
    {
      "x": -7,
      "y": 10,
      "z": 5,
      "name": "Wood_Deadwood_Planks"
    },
    {
      "x": -7,
      "y": 5,
      "z": 6,
      "name": "Wood_Fir_Trunk_Full_Locked",
      "support": 15,
      "rotation": 5
    },
    {
      "x": -7,
      "y": 10,
      "z": 6,
      "name": "Wood_Deadwood_Planks"
    },
    {
      "x": -7,
      "y": 11,
      "z": 6,
      "name": "Bench_Farming",
      "filler": 992,
      "rotation": 3
    },
    {
      "x": -7,
      "y": 12,
      "z": 6,
      "name": "Metal_Iron_Pipe_Large_Mouthpiece",
      "rotation": 6
    },
    {
      "x": -7,
      "y": 14,
      "z": 6,
      "name": "Wood_Fir_Trunk_Full_Locked",
      "support": 15,
      "rotation": 5
    },
    {
      "x": -7,
      "y": 6,
      "z": 7,
      "name": "Wood_Blackwood_Planks"
    },
    {
      "x": -7,
      "y": 10,
      "z": 7,
      "name": "Wood_Deadwood_Planks"
    },
    {
      "x": -7,
      "y": 11,
      "z": 7,
      "name": "Bench_Farming",
      "components": {
        "Components": {
          "BenchBlock": {
            "TierLevel": 1,
            "UpgradeItems": []
          },
          "PlacedByInteraction": {
            "WhoPlacedUuid": {
              "$binary": "+u0Lek23TWiDpMOn5L2LqA==",
              "$type": "04"
            }
          }
        }
      },
      "rotation": 3
    },
    {
      "x": -7,
      "y": 12,
      "z": 7,
      "name": "Metal_Iron_Pipe_Large",
      "rotation": 6
    },
    {
      "x": -7,
      "y": 7,
      "z": 8,
      "name": "Wood_Fir_Trunk_Full_Locked",
      "support": 15,
      "rotation": 5
    },
    {
      "x": -7,
      "y": 10,
      "z": 8,
      "name": "Wood_Deadwood_Planks"
    },
    {
      "x": -7,
      "y": 12,
      "z": 8,
      "name": "Metal_Iron_Pipe_Large",
      "rotation": 4
    },
    {
      "x": -7,
      "y": 8,
      "z": 9,
      "name": "Wood_Blackwood_Planks_Half",
      "rotation": 4
    },
    {
      "x": -7,
      "y": 9,
      "z": 9,
      "name": "Wood_Blackwood_Planks"
    },
    {
      "x": -7,
      "y": 10,
      "z": 9,
      "name": "Wood_Fir_Trunk_Full_Locked",
      "support": 15,
      "rotation": 5
    },
    {
      "x": -7,
      "y": 11,
      "z": 9,
      "name": "Wood_Blackwood_Planks_Half"
    },
    {
      "x": -7,
      "y": 13,
      "z": 9,
      "name": "Wood_Blackwood_Planks_Half",
      "rotation": 8
    },
    {
      "x": -7,
      "y": 14,
      "z": 9,
      "name": "Wood_Fir_Trunk_Full_Locked",
      "rotation": 5
    },
    {
      "x": -7,
      "y": 13,
      "z": 10,
      "name": "Furniture_Tavern_Shelf"
    },
    {
      "x": -7,
      "y": 13,
      "z": 11,
      "name": "Furniture_Tavern_Platform"
    },
    {
      "x": -6,
      "y": 10,
      "z": -9,
      "name": "Wood_Fir_Trunk_Full_Locked",
      "support": 15,
      "rotation": 5
    },
    {
      "x": -6,
      "y": 14,
      "z": -9,
      "name": "Wood_Fir_Trunk_Full_Locked",
      "rotation": 5
    },
    {
      "x": -6,
      "y": 7,
      "z": -8,
      "name": "Wood_Fir_Trunk_Full_Locked",
      "support": 15,
      "rotation": 5
    },
    {
      "x": -6,
      "y": 5,
      "z": -6,
      "name": "Wood_Fir_Trunk_Full_Locked",
      "support": 15,
      "rotation": 5
    },
    {
      "x": -6,
      "y": 4,
      "z": -3,
      "name": "Wood_Fir_Trunk_Full_Locked",
      "support": 15,
      "rotation": 5
    },
    {
      "x": -6,
      "y": 4,
      "z": 0,
      "name": "Wood_Fir_Trunk_Full_Locked",
      "support": 15,
      "rotation": 5
    },
    {
      "x": -6,
      "y": 14,
      "z": 0,
      "name": "Wood_Fir_Trunk_Full_Locked",
      "support": 15,
      "rotation": 5
    },
    {
      "x": -6,
      "y": 10,
      "z": 1,
      "name": "Wood_Deadwood_Planks"
    },
    {
      "x": -6,
      "y": 10,
      "z": 2,
      "name": "Wood_Deadwood_Planks"
    },
    {
      "x": -6,
      "y": 4,
      "z": 3,
      "name": "Wood_Fir_Trunk_Full_Locked",
      "support": 15,
      "rotation": 5
    },
    {
      "x": -6,
      "y": 10,
      "z": 3,
      "name": "Wood_Deadwood_Planks"
    },
    {
      "x": -6,
      "y": 14,
      "z": 3,
      "name": "Wood_Fir_Trunk_Full_Locked",
      "support": 15,
      "rotation": 5
    },
    {
      "x": -6,
      "y": 10,
      "z": 4,
      "name": "Wood_Deadwood_Planks"
    },
    {
      "x": -6,
      "y": 10,
      "z": 5,
      "name": "Wood_Deadwood_Planks"
    },
    {
      "x": -6,
      "y": 5,
      "z": 6,
      "name": "Wood_Fir_Trunk_Full_Locked",
      "support": 15,
      "rotation": 5
    },
    {
      "x": -6,
      "y": 10,
      "z": 6,
      "name": "Wood_Deadwood_Planks"
    },
    {
      "x": -6,
      "y": 14,
      "z": 6,
      "name": "Wood_Fir_Trunk_Full_Locked",
      "support": 15,
      "rotation": 5
    },
    {
      "x": -6,
      "y": 6,
      "z": 7,
      "name": "Wood_Blackwood_Planks"
    },
    {
      "x": -6,
      "y": 10,
      "z": 7,
      "name": "Wood_Deadwood_Planks"
    },
    {
      "x": -6,
      "y": 7,
      "z": 8,
      "name": "Wood_Fir_Trunk_Full_Locked",
      "support": 15,
      "rotation": 5
    },
    {
      "x": -6,
      "y": 10,
      "z": 8,
      "name": "Wood_Deadwood_Planks"
    },
    {
      "x": -6,
      "y": 8,
      "z": 9,
      "name": "Wood_Blackwood_Planks_Half",
      "rotation": 4
    },
    {
      "x": -6,
      "y": 9,
      "z": 9,
      "name": "Wood_Blackwood_Planks"
    },
    {
      "x": -6,
      "y": 10,
      "z": 9,
      "name": "Wood_Fir_Trunk_Full_Locked",
      "support": 15,
      "rotation": 5
    },
    {
      "x": -6,
      "y": 11,
      "z": 9,
      "name": "Wood_Blackwood_Stairs",
      "rotation": 3
    },
    {
      "x": -6,
      "y": 13,
      "z": 9,
      "name": "Wood_Blackwood_Stairs",
      "rotation": 9
    },
    {
      "x": -6,
      "y": 14,
      "z": 9,
      "name": "Wood_Fir_Trunk_Full_Locked",
      "rotation": 5
    },
    {
      "x": -6,
      "y": 13,
      "z": 10,
      "name": "Furniture_Tavern_Platform"
    },
    {
      "x": -6,
      "y": 13,
      "z": 11,
      "name": "Furniture_Tavern_Platform"
    },
    {
      "x": -5,
      "y": 10,
      "z": -9,
      "name": "Wood_Fir_Trunk_Full_Locked",
      "support": 15,
      "rotation": 5
    },
    {
      "x": -5,
      "y": 14,
      "z": -9,
      "name": "Wood_Fir_Trunk_Full_Locked",
      "rotation": 5
    },
    {
      "x": -5,
      "y": 7,
      "z": -8,
      "name": "Wood_Fir_Trunk_Full_Locked",
      "support": 15,
      "rotation": 5
    },
    {
      "x": -5,
      "y": 5,
      "z": -6,
      "name": "Wood_Fir_Trunk_Full_Locked",
      "support": 15,
      "rotation": 5
    },
    {
      "x": -5,
      "y": 4,
      "z": -3,
      "name": "Wood_Fir_Trunk_Full_Locked",
      "support": 15,
      "rotation": 5
    },
    {
      "x": -5,
      "y": 4,
      "z": 0,
      "name": "Wood_Fir_Trunk_Full_Locked",
      "support": 15,
      "rotation": 5
    },
    {
      "x": -5,
      "y": 14,
      "z": 0,
      "name": "Wood_Fir_Trunk_Full_Locked",
      "support": 15,
      "rotation": 5
    },
    {
      "x": -5,
      "y": 10,
      "z": 1,
      "name": "Wood_Deadwood_Planks"
    },
    {
      "x": -5,
      "y": 10,
      "z": 2,
      "name": "Wood_Deadwood_Planks"
    },
    {
      "x": -5,
      "y": 4,
      "z": 3,
      "name": "Wood_Fir_Trunk_Full_Locked",
      "support": 15,
      "rotation": 5
    },
    {
      "x": -5,
      "y": 10,
      "z": 3,
      "name": "Wood_Deadwood_Planks"
    },
    {
      "x": -5,
      "y": 14,
      "z": 3,
      "name": "Wood_Fir_Trunk_Full_Locked",
      "support": 15,
      "rotation": 5
    },
    {
      "x": -5,
      "y": 10,
      "z": 4,
      "name": "Wood_Deadwood_Planks"
    },
    {
      "x": -5,
      "y": 10,
      "z": 5,
      "name": "Wood_Deadwood_Planks"
    },
    {
      "x": -5,
      "y": 5,
      "z": 6,
      "name": "Wood_Fir_Trunk_Full_Locked",
      "support": 15,
      "rotation": 5
    },
    {
      "x": -5,
      "y": 10,
      "z": 6,
      "name": "Wood_Deadwood_Planks"
    },
    {
      "x": -5,
      "y": 14,
      "z": 6,
      "name": "Wood_Fir_Trunk_Full_Locked",
      "support": 15,
      "rotation": 5
    },
    {
      "x": -5,
      "y": 6,
      "z": 7,
      "name": "Wood_Blackwood_Planks"
    },
    {
      "x": -5,
      "y": 10,
      "z": 7,
      "name": "Wood_Deadwood_Planks"
    },
    {
      "x": -5,
      "y": 7,
      "z": 8,
      "name": "Wood_Fir_Trunk_Full_Locked",
      "support": 15,
      "rotation": 5
    },
    {
      "x": -5,
      "y": 10,
      "z": 8,
      "name": "Wood_Deadwood_Planks"
    },
    {
      "x": -5,
      "y": 8,
      "z": 9,
      "name": "Wood_Blackwood_Planks_Half",
      "rotation": 4
    },
    {
      "x": -5,
      "y": 9,
      "z": 9,
      "name": "Wood_Blackwood_Planks"
    },
    {
      "x": -5,
      "y": 10,
      "z": 9,
      "name": "Wood_Fir_Trunk_Full_Locked",
      "support": 15,
      "rotation": 5
    },
    {
      "x": -5,
      "y": 11,
      "z": 9,
      "name": "Wood_Fir_Trunk_Full_Locked",
      "support": 15
    },
    {
      "x": -5,
      "y": 12,
      "z": 9,
      "name": "Wood_Fir_Trunk_Full_Locked",
      "support": 15
    },
    {
      "x": -5,
      "y": 13,
      "z": 9,
      "name": "Wood_Fir_Trunk_Full_Locked",
      "support": 15
    },
    {
      "x": -5,
      "y": 14,
      "z": 9,
      "name": "Wood_Fir_Trunk_Full_Locked",
      "rotation": 5
    },
    {
      "x": -4,
      "y": 10,
      "z": -9,
      "name": "Wood_Fir_Trunk_Full_Locked",
      "support": 15,
      "rotation": 5
    },
    {
      "x": -4,
      "y": 14,
      "z": -9,
      "name": "Wood_Fir_Trunk_Full_Locked",
      "rotation": 5
    },
    {
      "x": -4,
      "y": 7,
      "z": -8,
      "name": "Wood_Fir_Trunk_Full_Locked",
      "support": 15,
      "rotation": 5
    },
    {
      "x": -4,
      "y": 5,
      "z": -6,
      "name": "Wood_Fir_Trunk_Full_Locked",
      "support": 15,
      "rotation": 5
    },
    {
      "x": -4,
      "y": 4,
      "z": -3,
      "name": "Wood_Fir_Trunk_Full_Locked",
      "support": 15,
      "rotation": 5
    },
    {
      "x": -4,
      "y": 4,
      "z": 0,
      "name": "Wood_Fir_Trunk_Full_Locked",
      "support": 15,
      "rotation": 5
    },
    {
      "x": -4,
      "y": 14,
      "z": 0,
      "name": "Wood_Fir_Trunk_Full_Locked",
      "support": 15,
      "rotation": 5
    },
    {
      "x": -4,
      "y": 10,
      "z": 1,
      "name": "Wood_Deadwood_Planks"
    },
    {
      "x": -4,
      "y": 10,
      "z": 2,
      "name": "Wood_Deadwood_Planks"
    },
    {
      "x": -4,
      "y": 4,
      "z": 3,
      "name": "Wood_Fir_Trunk_Full_Locked",
      "support": 15,
      "rotation": 5
    },
    {
      "x": -4,
      "y": 10,
      "z": 3,
      "name": "Wood_Deadwood_Planks"
    },
    {
      "x": -4,
      "y": 14,
      "z": 3,
      "name": "Wood_Fir_Trunk_Full_Locked",
      "support": 15,
      "rotation": 5
    },
    {
      "x": -4,
      "y": 10,
      "z": 4,
      "name": "Wood_Deadwood_Planks"
    },
    {
      "x": -4,
      "y": 10,
      "z": 5,
      "name": "Wood_Deadwood_Planks"
    },
    {
      "x": -4,
      "y": 5,
      "z": 6,
      "name": "Wood_Fir_Trunk_Full_Locked",
      "support": 15,
      "rotation": 5
    },
    {
      "x": -4,
      "y": 10,
      "z": 6,
      "name": "Wood_Deadwood_Planks"
    },
    {
      "x": -4,
      "y": 14,
      "z": 6,
      "name": "Wood_Fir_Trunk_Full_Locked",
      "support": 15,
      "rotation": 5
    },
    {
      "x": -4,
      "y": 6,
      "z": 7,
      "name": "Wood_Blackwood_Planks"
    },
    {
      "x": -4,
      "y": 10,
      "z": 7,
      "name": "Wood_Deadwood_Planks"
    },
    {
      "x": -4,
      "y": 7,
      "z": 8,
      "name": "Wood_Fir_Trunk_Full_Locked",
      "support": 15,
      "rotation": 5
    },
    {
      "x": -4,
      "y": 10,
      "z": 8,
      "name": "Wood_Deadwood_Planks"
    },
    {
      "x": -4,
      "y": 8,
      "z": 9,
      "name": "Wood_Blackwood_Planks_Half",
      "rotation": 4
    },
    {
      "x": -4,
      "y": 9,
      "z": 9,
      "name": "Wood_Blackwood_Planks"
    },
    {
      "x": -4,
      "y": 10,
      "z": 9,
      "name": "Wood_Fir_Trunk_Full_Locked",
      "support": 15,
      "rotation": 5
    },
    {
      "x": -4,
      "y": 11,
      "z": 9,
      "name": "Wood_Blackwood_Stairs",
      "rotation": 1
    },
    {
      "x": -4,
      "y": 13,
      "z": 9,
      "name": "Wood_Blackwood_Stairs",
      "rotation": 11
    },
    {
      "x": -4,
      "y": 14,
      "z": 9,
      "name": "Wood_Fir_Trunk_Full_Locked",
      "rotation": 5
    },
    {
      "x": -4,
      "y": 13,
      "z": 10,
      "name": "Furniture_Tavern_Platform"
    },
    {
      "x": -4,
      "y": 13,
      "z": 11,
      "name": "Furniture_Tavern_Platform"
    },
    {
      "x": -3,
      "y": 10,
      "z": -9,
      "name": "Wood_Fir_Trunk_Full_Locked",
      "support": 15,
      "rotation": 5
    },
    {
      "x": -3,
      "y": 14,
      "z": -9,
      "name": "Wood_Fir_Trunk_Full_Locked",
      "rotation": 5
    },
    {
      "x": -3,
      "y": 7,
      "z": -8,
      "name": "Wood_Fir_Trunk_Full_Locked",
      "support": 15,
      "rotation": 5
    },
    {
      "x": -3,
      "y": 5,
      "z": -6,
      "name": "Wood_Fir_Trunk_Full_Locked",
      "support": 15,
      "rotation": 5
    },
    {
      "x": -3,
      "y": 4,
      "z": -3,
      "name": "Wood_Fir_Trunk_Full_Locked",
      "support": 15,
      "rotation": 5
    },
    {
      "x": -3,
      "y": 4,
      "z": 0,
      "name": "Wood_Fir_Trunk_Full_Locked",
      "support": 15,
      "rotation": 5
    },
    {
      "x": -3,
      "y": 14,
      "z": 0,
      "name": "Wood_Fir_Trunk_Full_Locked",
      "support": 15,
      "rotation": 5
    },
    {
      "x": -3,
      "y": 10,
      "z": 1,
      "name": "Wood_Deadwood_Planks"
    },
    {
      "x": -3,
      "y": 10,
      "z": 2,
      "name": "Wood_Deadwood_Planks"
    },
    {
      "x": -3,
      "y": 4,
      "z": 3,
      "name": "Wood_Fir_Trunk_Full_Locked",
      "support": 15,
      "rotation": 5
    },
    {
      "x": -3,
      "y": 10,
      "z": 3,
      "name": "Wood_Deadwood_Planks"
    },
    {
      "x": -3,
      "y": 14,
      "z": 3,
      "name": "Wood_Fir_Trunk_Full_Locked",
      "support": 15,
      "rotation": 5
    },
    {
      "x": -3,
      "y": 10,
      "z": 4,
      "name": "Wood_Deadwood_Planks"
    },
    {
      "x": -3,
      "y": 10,
      "z": 5,
      "name": "Wood_Deadwood_Planks"
    },
    {
      "x": -3,
      "y": 5,
      "z": 6,
      "name": "Wood_Fir_Trunk_Full_Locked",
      "support": 15,
      "rotation": 5
    },
    {
      "x": -3,
      "y": 10,
      "z": 6,
      "name": "Wood_Deadwood_Planks"
    },
    {
      "x": -3,
      "y": 11,
      "z": 6,
      "name": "Bench_Farming",
      "filler": 992,
      "rotation": 3
    },
    {
      "x": -3,
      "y": 12,
      "z": 6,
      "name": "Metal_Iron_Pipe_Large_Mouthpiece",
      "rotation": 6
    },
    {
      "x": -3,
      "y": 14,
      "z": 6,
      "name": "Wood_Fir_Trunk_Full_Locked",
      "support": 15,
      "rotation": 5
    },
    {
      "x": -3,
      "y": 6,
      "z": 7,
      "name": "Wood_Blackwood_Planks"
    },
    {
      "x": -3,
      "y": 10,
      "z": 7,
      "name": "Wood_Deadwood_Planks"
    },
    {
      "x": -3,
      "y": 11,
      "z": 7,
      "name": "Bench_Farming",
      "components": {
        "Components": {
          "BenchBlock": {
            "TierLevel": 1,
            "UpgradeItems": []
          },
          "PlacedByInteraction": {
            "WhoPlacedUuid": {
              "$binary": "+u0Lek23TWiDpMOn5L2LqA==",
              "$type": "04"
            }
          }
        }
      },
      "rotation": 3
    },
    {
      "x": -3,
      "y": 12,
      "z": 7,
      "name": "Metal_Iron_Pipe_Large",
      "rotation": 6
    },
    {
      "x": -3,
      "y": 7,
      "z": 8,
      "name": "Wood_Fir_Trunk_Full_Locked",
      "support": 15,
      "rotation": 5
    },
    {
      "x": -3,
      "y": 10,
      "z": 8,
      "name": "Wood_Deadwood_Planks"
    },
    {
      "x": -3,
      "y": 12,
      "z": 8,
      "name": "Metal_Iron_Pipe_Large",
      "rotation": 4
    },
    {
      "x": -3,
      "y": 8,
      "z": 9,
      "name": "Wood_Blackwood_Planks_Half",
      "rotation": 4
    },
    {
      "x": -3,
      "y": 9,
      "z": 9,
      "name": "Wood_Blackwood_Planks"
    },
    {
      "x": -3,
      "y": 10,
      "z": 9,
      "name": "Wood_Fir_Trunk_Full_Locked",
      "support": 15,
      "rotation": 5
    },
    {
      "x": -3,
      "y": 11,
      "z": 9,
      "name": "Wood_Blackwood_Planks_Half"
    },
    {
      "x": -3,
      "y": 13,
      "z": 9,
      "name": "Wood_Blackwood_Planks_Half",
      "rotation": 8
    },
    {
      "x": -3,
      "y": 14,
      "z": 9,
      "name": "Wood_Fir_Trunk_Full_Locked",
      "rotation": 5
    },
    {
      "x": -3,
      "y": 13,
      "z": 10,
      "name": "Furniture_Tavern_Shelf"
    },
    {
      "x": -3,
      "y": 13,
      "z": 11,
      "name": "Furniture_Tavern_Platform"
    },
    {
      "x": -2,
      "y": 10,
      "z": -9,
      "name": "Wood_Fir_Trunk_Full_Locked",
      "support": 15,
      "rotation": 5
    },
    {
      "x": -2,
      "y": 14,
      "z": -9,
      "name": "Wood_Fir_Trunk_Full_Locked",
      "rotation": 5
    },
    {
      "x": -2,
      "y": 7,
      "z": -8,
      "name": "Wood_Fir_Trunk_Full_Locked",
      "support": 15,
      "rotation": 5
    },
    {
      "x": -2,
      "y": 5,
      "z": -6,
      "name": "Wood_Fir_Trunk_Full_Locked",
      "support": 15,
      "rotation": 5
    },
    {
      "x": -2,
      "y": 4,
      "z": -3,
      "name": "Wood_Fir_Trunk_Full_Locked",
      "support": 15,
      "rotation": 5
    },
    {
      "x": -2,
      "y": 4,
      "z": 0,
      "name": "Wood_Fir_Trunk_Full_Locked",
      "support": 15,
      "rotation": 5
    },
    {
      "x": -2,
      "y": 14,
      "z": 0,
      "name": "Wood_Fir_Trunk_Full_Locked",
      "support": 15,
      "rotation": 5
    },
    {
      "x": -2,
      "y": 10,
      "z": 1,
      "name": "Wood_Deadwood_Planks"
    },
    {
      "x": -2,
      "y": 10,
      "z": 2,
      "name": "Wood_Deadwood_Planks"
    },
    {
      "x": -2,
      "y": 4,
      "z": 3,
      "name": "Wood_Fir_Trunk_Full_Locked",
      "support": 15,
      "rotation": 5
    },
    {
      "x": -2,
      "y": 10,
      "z": 3,
      "name": "Wood_Deadwood_Planks"
    },
    {
      "x": -2,
      "y": 14,
      "z": 3,
      "name": "Wood_Fir_Trunk_Full_Locked",
      "support": 15,
      "rotation": 5
    },
    {
      "x": -2,
      "y": 10,
      "z": 4,
      "name": "Wood_Deadwood_Planks"
    },
    {
      "x": -2,
      "y": 10,
      "z": 5,
      "name": "Wood_Deadwood_Planks"
    },
    {
      "x": -2,
      "y": 5,
      "z": 6,
      "name": "Wood_Fir_Trunk_Full_Locked",
      "support": 15,
      "rotation": 5
    },
    {
      "x": -2,
      "y": 10,
      "z": 6,
      "name": "Wood_Deadwood_Planks"
    },
    {
      "x": -2,
      "y": 14,
      "z": 6,
      "name": "Wood_Fir_Trunk_Full_Locked",
      "support": 15,
      "rotation": 5
    },
    {
      "x": -2,
      "y": 6,
      "z": 7,
      "name": "Wood_Blackwood_Planks"
    },
    {
      "x": -2,
      "y": 10,
      "z": 7,
      "name": "Wood_Deadwood_Planks"
    },
    {
      "x": -2,
      "y": 7,
      "z": 8,
      "name": "Wood_Fir_Trunk_Full_Locked",
      "support": 15,
      "rotation": 5
    },
    {
      "x": -2,
      "y": 10,
      "z": 8,
      "name": "Wood_Deadwood_Planks"
    },
    {
      "x": -2,
      "y": 8,
      "z": 9,
      "name": "Wood_Blackwood_Planks_Half",
      "rotation": 4
    },
    {
      "x": -2,
      "y": 9,
      "z": 9,
      "name": "Wood_Blackwood_Planks"
    },
    {
      "x": -2,
      "y": 10,
      "z": 9,
      "name": "Wood_Fir_Trunk_Full_Locked",
      "support": 15,
      "rotation": 5
    },
    {
      "x": -2,
      "y": 11,
      "z": 9,
      "name": "Wood_Blackwood_Stairs",
      "rotation": 3
    },
    {
      "x": -2,
      "y": 13,
      "z": 9,
      "name": "Wood_Blackwood_Stairs",
      "rotation": 9
    },
    {
      "x": -2,
      "y": 14,
      "z": 9,
      "name": "Wood_Fir_Trunk_Full_Locked",
      "rotation": 5
    },
    {
      "x": -2,
      "y": 13,
      "z": 10,
      "name": "Furniture_Tavern_Platform"
    },
    {
      "x": -2,
      "y": 13,
      "z": 11,
      "name": "Furniture_Tavern_Platform"
    },
    {
      "x": -1,
      "y": 10,
      "z": -9,
      "name": "Wood_Fir_Trunk_Full_Locked",
      "support": 15,
      "rotation": 5
    },
    {
      "x": -1,
      "y": 14,
      "z": -9,
      "name": "Wood_Fir_Trunk_Full_Locked",
      "rotation": 5
    },
    {
      "x": -1,
      "y": 7,
      "z": -8,
      "name": "Wood_Fir_Trunk_Full_Locked",
      "support": 15,
      "rotation": 5
    },
    {
      "x": -1,
      "y": 5,
      "z": -6,
      "name": "Wood_Fir_Trunk_Full_Locked",
      "support": 15,
      "rotation": 5
    },
    {
      "x": -1,
      "y": 4,
      "z": -3,
      "name": "Wood_Fir_Trunk_Full_Locked",
      "support": 15,
      "rotation": 5
    },
    {
      "x": -1,
      "y": 4,
      "z": 0,
      "name": "Wood_Fir_Trunk_Full_Locked",
      "support": 15,
      "rotation": 5
    },
    {
      "x": -1,
      "y": 14,
      "z": 0,
      "name": "Wood_Fir_Trunk_Full_Locked",
      "support": 15,
      "rotation": 5
    },
    {
      "x": -1,
      "y": 10,
      "z": 1,
      "name": "Wood_Deadwood_Planks"
    },
    {
      "x": -1,
      "y": 10,
      "z": 2,
      "name": "Wood_Deadwood_Planks"
    },
    {
      "x": -1,
      "y": 4,
      "z": 3,
      "name": "Wood_Fir_Trunk_Full_Locked",
      "support": 15,
      "rotation": 5
    },
    {
      "x": -1,
      "y": 10,
      "z": 3,
      "name": "Wood_Deadwood_Planks"
    },
    {
      "x": -1,
      "y": 14,
      "z": 3,
      "name": "Wood_Fir_Trunk_Full_Locked",
      "support": 15,
      "rotation": 5
    },
    {
      "x": -1,
      "y": 10,
      "z": 4,
      "name": "Wood_Deadwood_Planks"
    },
    {
      "x": -1,
      "y": 10,
      "z": 5,
      "name": "Wood_Deadwood_Planks"
    },
    {
      "x": -1,
      "y": 5,
      "z": 6,
      "name": "Wood_Fir_Trunk_Full_Locked",
      "support": 15,
      "rotation": 5
    },
    {
      "x": -1,
      "y": 10,
      "z": 6,
      "name": "Wood_Deadwood_Planks"
    },
    {
      "x": -1,
      "y": 14,
      "z": 6,
      "name": "Wood_Fir_Trunk_Full_Locked",
      "support": 15,
      "rotation": 5
    },
    {
      "x": -1,
      "y": 6,
      "z": 7,
      "name": "Wood_Blackwood_Planks"
    },
    {
      "x": -1,
      "y": 10,
      "z": 7,
      "name": "Wood_Deadwood_Planks"
    },
    {
      "x": -1,
      "y": 7,
      "z": 8,
      "name": "Wood_Fir_Trunk_Full_Locked",
      "support": 15,
      "rotation": 5
    },
    {
      "x": -1,
      "y": 10,
      "z": 8,
      "name": "Wood_Deadwood_Planks"
    },
    {
      "x": -1,
      "y": 8,
      "z": 9,
      "name": "Wood_Blackwood_Planks_Half",
      "rotation": 4
    },
    {
      "x": -1,
      "y": 9,
      "z": 9,
      "name": "Wood_Blackwood_Planks"
    },
    {
      "x": -1,
      "y": 10,
      "z": 9,
      "name": "Wood_Fir_Trunk_Full_Locked",
      "support": 15,
      "rotation": 5
    },
    {
      "x": -1,
      "y": 11,
      "z": 9,
      "name": "Wood_Fir_Trunk_Full_Locked",
      "support": 15
    },
    {
      "x": -1,
      "y": 12,
      "z": 9,
      "name": "Wood_Fir_Trunk_Full_Locked",
      "support": 15
    },
    {
      "x": -1,
      "y": 13,
      "z": 9,
      "name": "Wood_Fir_Trunk_Full_Locked",
      "support": 15
    },
    {
      "x": -1,
      "y": 14,
      "z": 9,
      "name": "Wood_Fir_Trunk_Full_Locked",
      "rotation": 5
    },
    {
      "x": 0,
      "y": 10,
      "z": -9,
      "name": "Wood_Fir_Trunk_Full_Locked",
      "support": 15,
      "rotation": 5
    },
    {
      "x": 0,
      "y": 14,
      "z": -9,
      "name": "Wood_Fir_Trunk_Full_Locked",
      "rotation": 5
    },
    {
      "x": 0,
      "y": 7,
      "z": -8,
      "name": "Wood_Fir_Trunk_Full_Locked",
      "support": 15,
      "rotation": 5
    },
    {
      "x": 0,
      "y": 5,
      "z": -6,
      "name": "Wood_Fir_Trunk_Full_Locked",
      "support": 15,
      "rotation": 5
    },
    {
      "x": 0,
      "y": 4,
      "z": -3,
      "name": "Wood_Fir_Trunk_Full_Locked",
      "support": 15,
      "rotation": 5
    },
    {
      "x": 0,
      "y": 4,
      "z": 0,
      "name": "Wood_Fir_Trunk_Full_Locked",
      "support": 15,
      "rotation": 5
    },
    {
      "x": 0,
      "y": 14,
      "z": 0,
      "name": "Wood_Fir_Trunk_Full_Locked",
      "support": 15,
      "rotation": 5
    },
    {
      "x": 0,
      "y": 10,
      "z": 1,
      "name": "Wood_Deadwood_Planks"
    },
    {
      "x": 0,
      "y": 10,
      "z": 2,
      "name": "Wood_Deadwood_Planks"
    },
    {
      "x": 0,
      "y": 4,
      "z": 3,
      "name": "Wood_Fir_Trunk_Full_Locked",
      "support": 15,
      "rotation": 5
    },
    {
      "x": 0,
      "y": 10,
      "z": 3,
      "name": "Wood_Deadwood_Planks"
    },
    {
      "x": 0,
      "y": 14,
      "z": 3,
      "name": "Wood_Fir_Trunk_Full_Locked",
      "support": 15,
      "rotation": 5
    },
    {
      "x": 0,
      "y": 10,
      "z": 4,
      "name": "Wood_Deadwood_Planks"
    },
    {
      "x": 0,
      "y": 10,
      "z": 5,
      "name": "Wood_Deadwood_Planks"
    },
    {
      "x": 0,
      "y": 5,
      "z": 6,
      "name": "Wood_Fir_Trunk_Full_Locked",
      "support": 15,
      "rotation": 5
    },
    {
      "x": 0,
      "y": 10,
      "z": 6,
      "name": "Wood_Deadwood_Planks"
    },
    {
      "x": 0,
      "y": 11,
      "z": 6,
      "name": "Deco_Rope_Diagonal",
      "rotation": 3
    },
    {
      "x": 0,
      "y": 14,
      "z": 6,
      "name": "Wood_Fir_Trunk_Full_Locked",
      "support": 15,
      "rotation": 5
    },
    {
      "x": 0,
      "y": 6,
      "z": 7,
      "name": "Wood_Blackwood_Planks"
    },
    {
      "x": 0,
      "y": 10,
      "z": 7,
      "name": "Wood_Deadwood_Planks"
    },
    {
      "x": 0,
      "y": 11,
      "z": 7,
      "name": "Deco_Rope_Diagonal",
      "rotation": 3
    },
    {
      "x": 0,
      "y": 7,
      "z": 8,
      "name": "Wood_Fir_Trunk_Full_Locked",
      "support": 15,
      "rotation": 5
    },
    {
      "x": 0,
      "y": 10,
      "z": 8,
      "name": "Wood_Deadwood_Planks"
    },
    {
      "x": 0,
      "y": 8,
      "z": 9,
      "name": "Wood_Blackwood_Planks_Half",
      "rotation": 4
    },
    {
      "x": 0,
      "y": 9,
      "z": 9,
      "name": "Wood_Blackwood_Planks"
    },
    {
      "x": 0,
      "y": 10,
      "z": 9,
      "name": "Wood_Fir_Trunk_Full_Locked",
      "support": 15,
      "rotation": 5
    },
    {
      "x": 0,
      "y": 11,
      "z": 9,
      "name": "Wood_Blackwood_Stairs",
      "rotation": 1
    },
    {
      "x": 0,
      "y": 13,
      "z": 9,
      "name": "Wood_Blackwood_Stairs",
      "rotation": 11
    },
    {
      "x": 0,
      "y": 14,
      "z": 9,
      "name": "Wood_Fir_Trunk_Full_Locked",
      "rotation": 5
    },
    {
      "x": 0,
      "y": 12,
      "z": 10,
      "name": "Furniture_Tavern_Platform",
      "rotation": 6
    },
    {
      "x": 0,
      "y": 13,
      "z": 10,
      "name": "Furniture_Tavern_Platform",
      "rotation": 6
    },
    {
      "x": 1,
      "y": 10,
      "z": -9,
      "name": "Wood_Fir_Trunk_Full_Locked",
      "support": 15,
      "rotation": 5
    },
    {
      "x": 1,
      "y": 14,
      "z": -9,
      "name": "Wood_Fir_Trunk_Full_Locked",
      "rotation": 5
    },
    {
      "x": 1,
      "y": 7,
      "z": -8,
      "name": "Wood_Fir_Trunk_Full_Locked",
      "support": 15,
      "rotation": 5
    },
    {
      "x": 1,
      "y": 5,
      "z": -6,
      "name": "Wood_Fir_Trunk_Full_Locked",
      "support": 15,
      "rotation": 5
    },
    {
      "x": 1,
      "y": 4,
      "z": -3,
      "name": "Wood_Fir_Trunk_Full_Locked",
      "support": 15,
      "rotation": 5
    },
    {
      "x": 1,
      "y": 4,
      "z": 0,
      "name": "Wood_Fir_Trunk_Full_Locked",
      "support": 15,
      "rotation": 5
    },
    {
      "x": 1,
      "y": 14,
      "z": 0,
      "name": "Wood_Fir_Trunk_Full_Locked",
      "support": 15,
      "rotation": 5
    },
    {
      "x": 1,
      "y": 10,
      "z": 1,
      "name": "Wood_Deadwood_Planks"
    },
    {
      "x": 1,
      "y": 10,
      "z": 2,
      "name": "Wood_Deadwood_Planks"
    },
    {
      "x": 1,
      "y": 4,
      "z": 3,
      "name": "Wood_Fir_Trunk_Full_Locked",
      "support": 15,
      "rotation": 5
    },
    {
      "x": 1,
      "y": 10,
      "z": 3,
      "name": "Wood_Deadwood_Planks"
    },
    {
      "x": 1,
      "y": 14,
      "z": 3,
      "name": "Wood_Fir_Trunk_Full_Locked",
      "support": 15,
      "rotation": 5
    },
    {
      "x": 1,
      "y": 10,
      "z": 4,
      "name": "Wood_Deadwood_Planks"
    },
    {
      "x": 1,
      "y": 10,
      "z": 5,
      "name": "Wood_Deadwood_Planks"
    },
    {
      "x": 1,
      "y": 5,
      "z": 6,
      "name": "Wood_Fir_Trunk_Full_Locked",
      "support": 15,
      "rotation": 5
    },
    {
      "x": 1,
      "y": 10,
      "z": 6,
      "name": "Wood_Deadwood_Planks"
    },
    {
      "x": 1,
      "y": 11,
      "z": 6,
      "name": "Bench_Farming",
      "filler": 992,
      "rotation": 3
    },
    {
      "x": 1,
      "y": 12,
      "z": 6,
      "name": "Metal_Iron_Pipe_Large_Mouthpiece",
      "rotation": 6
    },
    {
      "x": 1,
      "y": 14,
      "z": 6,
      "name": "Wood_Fir_Trunk_Full_Locked",
      "support": 15,
      "rotation": 5
    },
    {
      "x": 1,
      "y": 6,
      "z": 7,
      "name": "Wood_Blackwood_Planks"
    },
    {
      "x": 1,
      "y": 10,
      "z": 7,
      "name": "Wood_Deadwood_Planks"
    },
    {
      "x": 1,
      "y": 11,
      "z": 7,
      "name": "Bench_Farming",
      "components": {
        "Components": {
          "BenchBlock": {
            "TierLevel": 1,
            "UpgradeItems": []
          },
          "PlacedByInteraction": {
            "WhoPlacedUuid": {
              "$binary": "+u0Lek23TWiDpMOn5L2LqA==",
              "$type": "04"
            }
          }
        }
      },
      "rotation": 3
    },
    {
      "x": 1,
      "y": 12,
      "z": 7,
      "name": "Metal_Iron_Pipe_Large",
      "rotation": 6
    },
    {
      "x": 1,
      "y": 7,
      "z": 8,
      "name": "Wood_Fir_Trunk_Full_Locked",
      "support": 15,
      "rotation": 5
    },
    {
      "x": 1,
      "y": 10,
      "z": 8,
      "name": "Wood_Deadwood_Planks"
    },
    {
      "x": 1,
      "y": 12,
      "z": 8,
      "name": "Metal_Iron_Pipe_Large",
      "rotation": 4
    },
    {
      "x": 1,
      "y": 8,
      "z": 9,
      "name": "Wood_Blackwood_Planks_Half",
      "rotation": 4
    },
    {
      "x": 1,
      "y": 9,
      "z": 9,
      "name": "Wood_Blackwood_Planks"
    },
    {
      "x": 1,
      "y": 10,
      "z": 9,
      "name": "Wood_Fir_Trunk_Full_Locked",
      "support": 15,
      "rotation": 5
    },
    {
      "x": 1,
      "y": 11,
      "z": 9,
      "name": "Wood_Blackwood_Planks_Half"
    },
    {
      "x": 1,
      "y": 13,
      "z": 9,
      "name": "Wood_Blackwood_Planks_Half",
      "rotation": 8
    },
    {
      "x": 1,
      "y": 14,
      "z": 9,
      "name": "Wood_Fir_Trunk_Full_Locked",
      "rotation": 5
    },
    {
      "x": 1,
      "y": 11,
      "z": 10,
      "name": "Furniture_Temple_Dark_Ladder"
    },
    {
      "x": 1,
      "y": 12,
      "z": 10,
      "name": "Furniture_Tavern_Platform",
      "rotation": 6
    },
    {
      "x": 1,
      "y": 13,
      "z": 10,
      "name": "Furniture_Tavern_Platform",
      "rotation": 6
    },
    {
      "x": 2,
      "y": 10,
      "z": -9,
      "name": "Wood_Fir_Trunk_Full_Locked",
      "support": 15,
      "rotation": 5
    },
    {
      "x": 2,
      "y": 14,
      "z": -9,
      "name": "Wood_Fir_Trunk_Full_Locked",
      "rotation": 5
    },
    {
      "x": 2,
      "y": 7,
      "z": -8,
      "name": "Wood_Fir_Trunk_Full_Locked",
      "support": 15,
      "rotation": 5
    },
    {
      "x": 2,
      "y": 5,
      "z": -6,
      "name": "Wood_Fir_Trunk_Full_Locked",
      "support": 15,
      "rotation": 5
    },
    {
      "x": 2,
      "y": 4,
      "z": -3,
      "name": "Wood_Fir_Trunk_Full_Locked",
      "support": 15,
      "rotation": 5
    },
    {
      "x": 2,
      "y": 4,
      "z": 0,
      "name": "Wood_Fir_Trunk_Full_Locked",
      "support": 15,
      "rotation": 5
    },
    {
      "x": 2,
      "y": 14,
      "z": 0,
      "name": "Wood_Fir_Trunk_Full_Locked",
      "support": 15,
      "rotation": 5
    },
    {
      "x": 2,
      "y": 10,
      "z": 1,
      "name": "Wood_Deadwood_Planks"
    },
    {
      "x": 2,
      "y": 10,
      "z": 2,
      "name": "Wood_Deadwood_Planks"
    },
    {
      "x": 2,
      "y": 4,
      "z": 3,
      "name": "Wood_Fir_Trunk_Full_Locked",
      "support": 15,
      "rotation": 5
    },
    {
      "x": 2,
      "y": 10,
      "z": 3,
      "name": "Wood_Deadwood_Planks"
    },
    {
      "x": 2,
      "y": 14,
      "z": 3,
      "name": "Wood_Fir_Trunk_Full_Locked",
      "support": 15,
      "rotation": 5
    },
    {
      "x": 2,
      "y": 10,
      "z": 4,
      "name": "Wood_Deadwood_Planks"
    },
    {
      "x": 2,
      "y": 10,
      "z": 5,
      "name": "Wood_Deadwood_Planks"
    },
    {
      "x": 2,
      "y": 5,
      "z": 6,
      "name": "Wood_Fir_Trunk_Full_Locked",
      "support": 15,
      "rotation": 5
    },
    {
      "x": 2,
      "y": 10,
      "z": 6,
      "name": "Wood_Deadwood_Planks"
    },
    {
      "x": 2,
      "y": 11,
      "z": 6,
      "name": "Deco_Rope_Diagonal",
      "rotation": 1
    },
    {
      "x": 2,
      "y": 14,
      "z": 6,
      "name": "Wood_Fir_Trunk_Full_Locked",
      "support": 15,
      "rotation": 5
    },
    {
      "x": 2,
      "y": 6,
      "z": 7,
      "name": "Wood_Blackwood_Planks"
    },
    {
      "x": 2,
      "y": 10,
      "z": 7,
      "name": "Wood_Deadwood_Planks"
    },
    {
      "x": 2,
      "y": 11,
      "z": 7,
      "name": "Deco_Rope_Diagonal",
      "rotation": 1
    },
    {
      "x": 2,
      "y": 7,
      "z": 8,
      "name": "Wood_Fir_Trunk_Full_Locked",
      "support": 15,
      "rotation": 5
    },
    {
      "x": 2,
      "y": 10,
      "z": 8,
      "name": "Wood_Deadwood_Planks"
    },
    {
      "x": 2,
      "y": 8,
      "z": 9,
      "name": "Wood_Blackwood_Planks_Half",
      "rotation": 4
    },
    {
      "x": 2,
      "y": 9,
      "z": 9,
      "name": "Wood_Blackwood_Planks"
    },
    {
      "x": 2,
      "y": 10,
      "z": 9,
      "name": "Wood_Fir_Trunk_Full_Locked",
      "support": 15,
      "rotation": 5
    },
    {
      "x": 2,
      "y": 11,
      "z": 9,
      "name": "Wood_Blackwood_Stairs",
      "rotation": 3
    },
    {
      "x": 2,
      "y": 13,
      "z": 9,
      "name": "Wood_Blackwood_Stairs",
      "rotation": 9
    },
    {
      "x": 2,
      "y": 14,
      "z": 9,
      "name": "Wood_Fir_Trunk_Full_Locked",
      "rotation": 5
    },
    {
      "x": 2,
      "y": 12,
      "z": 10,
      "name": "Furniture_Tavern_Platform",
      "rotation": 6
    },
    {
      "x": 2,
      "y": 13,
      "z": 10,
      "name": "Furniture_Tavern_Platform",
      "rotation": 6
    },
    {
      "x": 3,
      "y": 10,
      "z": -9,
      "name": "Wood_Fir_Trunk_Full_Locked",
      "support": 15,
      "rotation": 5
    },
    {
      "x": 3,
      "y": 14,
      "z": -9,
      "name": "Wood_Fir_Trunk_Full_Locked",
      "rotation": 5
    },
    {
      "x": 3,
      "y": 7,
      "z": -8,
      "name": "Wood_Fir_Trunk_Full_Locked",
      "support": 15,
      "rotation": 5
    },
    {
      "x": 3,
      "y": 5,
      "z": -6,
      "name": "Wood_Fir_Trunk_Full_Locked",
      "support": 15,
      "rotation": 5
    },
    {
      "x": 3,
      "y": 4,
      "z": -3,
      "name": "Wood_Fir_Trunk_Full_Locked",
      "support": 15,
      "rotation": 5
    },
    {
      "x": 3,
      "y": 4,
      "z": 0,
      "name": "Wood_Fir_Trunk_Full_Locked",
      "support": 15,
      "rotation": 5
    },
    {
      "x": 3,
      "y": 14,
      "z": 0,
      "name": "Wood_Fir_Trunk_Full_Locked",
      "support": 15,
      "rotation": 5
    },
    {
      "x": 3,
      "y": 10,
      "z": 1,
      "name": "Wood_Deadwood_Planks"
    },
    {
      "x": 3,
      "y": 10,
      "z": 2,
      "name": "Wood_Deadwood_Planks"
    },
    {
      "x": 3,
      "y": 4,
      "z": 3,
      "name": "Wood_Fir_Trunk_Full_Locked",
      "support": 15,
      "rotation": 5
    },
    {
      "x": 3,
      "y": 10,
      "z": 3,
      "name": "Wood_Deadwood_Planks"
    },
    {
      "x": 3,
      "y": 14,
      "z": 3,
      "name": "Wood_Fir_Trunk_Full_Locked",
      "support": 15,
      "rotation": 5
    },
    {
      "x": 3,
      "y": 10,
      "z": 4,
      "name": "Wood_Deadwood_Planks"
    },
    {
      "x": 3,
      "y": 10,
      "z": 5,
      "name": "Wood_Deadwood_Planks"
    },
    {
      "x": 3,
      "y": 5,
      "z": 6,
      "name": "Wood_Fir_Trunk_Full_Locked",
      "support": 15,
      "rotation": 5
    },
    {
      "x": 3,
      "y": 10,
      "z": 6,
      "name": "Wood_Deadwood_Planks"
    },
    {
      "x": 3,
      "y": 14,
      "z": 6,
      "name": "Wood_Fir_Trunk_Full_Locked",
      "support": 15,
      "rotation": 5
    },
    {
      "x": 3,
      "y": 6,
      "z": 7,
      "name": "Wood_Blackwood_Planks"
    },
    {
      "x": 3,
      "y": 10,
      "z": 7,
      "name": "Wood_Deadwood_Planks"
    },
    {
      "x": 3,
      "y": 7,
      "z": 8,
      "name": "Wood_Fir_Trunk_Full_Locked",
      "support": 15,
      "rotation": 5
    },
    {
      "x": 3,
      "y": 10,
      "z": 8,
      "name": "Wood_Deadwood_Planks"
    },
    {
      "x": 3,
      "y": 8,
      "z": 9,
      "name": "Wood_Blackwood_Planks_Half",
      "rotation": 4
    },
    {
      "x": 3,
      "y": 9,
      "z": 9,
      "name": "Wood_Blackwood_Planks"
    },
    {
      "x": 3,
      "y": 10,
      "z": 9,
      "name": "Wood_Fir_Trunk_Full_Locked",
      "support": 15,
      "rotation": 5
    },
    {
      "x": 3,
      "y": 11,
      "z": 9,
      "name": "Wood_Fir_Trunk_Full_Locked",
      "support": 15
    },
    {
      "x": 3,
      "y": 12,
      "z": 9,
      "name": "Wood_Fir_Trunk_Full_Locked",
      "support": 15
    },
    {
      "x": 3,
      "y": 13,
      "z": 9,
      "name": "Wood_Fir_Trunk_Full_Locked",
      "support": 15
    },
    {
      "x": 3,
      "y": 14,
      "z": 9,
      "name": "Wood_Fir_Trunk_Full_Locked",
      "rotation": 5
    },
    {
      "x": 4,
      "y": 10,
      "z": -9,
      "name": "Wood_Fir_Trunk_Full_Locked",
      "support": 15,
      "rotation": 5
    },
    {
      "x": 4,
      "y": 14,
      "z": -9,
      "name": "Wood_Fir_Trunk_Full_Locked",
      "rotation": 5
    },
    {
      "x": 4,
      "y": 7,
      "z": -8,
      "name": "Wood_Fir_Trunk_Full_Locked",
      "support": 15,
      "rotation": 5
    },
    {
      "x": 4,
      "y": 5,
      "z": -6,
      "name": "Wood_Fir_Trunk_Full_Locked",
      "support": 15,
      "rotation": 5
    },
    {
      "x": 4,
      "y": 4,
      "z": -3,
      "name": "Wood_Fir_Trunk_Full_Locked",
      "support": 15,
      "rotation": 5
    },
    {
      "x": 4,
      "y": 4,
      "z": 0,
      "name": "Wood_Fir_Trunk_Full_Locked",
      "support": 15,
      "rotation": 5
    },
    {
      "x": 4,
      "y": 14,
      "z": 0,
      "name": "Wood_Fir_Trunk_Full_Locked",
      "support": 15,
      "rotation": 5
    },
    {
      "x": 4,
      "y": 10,
      "z": 1,
      "name": "Wood_Deadwood_Planks"
    },
    {
      "x": 4,
      "y": 10,
      "z": 2,
      "name": "Wood_Deadwood_Planks"
    },
    {
      "x": 4,
      "y": 4,
      "z": 3,
      "name": "Wood_Fir_Trunk_Full_Locked",
      "support": 15,
      "rotation": 5
    },
    {
      "x": 4,
      "y": 10,
      "z": 3,
      "name": "Wood_Deadwood_Planks"
    },
    {
      "x": 4,
      "y": 14,
      "z": 3,
      "name": "Wood_Fir_Trunk_Full_Locked",
      "support": 15,
      "rotation": 5
    },
    {
      "x": 4,
      "y": 10,
      "z": 4,
      "name": "Wood_Deadwood_Planks"
    },
    {
      "x": 4,
      "y": 10,
      "z": 5,
      "name": "Wood_Deadwood_Planks"
    },
    {
      "x": 4,
      "y": 5,
      "z": 6,
      "name": "Wood_Fir_Trunk_Full_Locked",
      "support": 15,
      "rotation": 5
    },
    {
      "x": 4,
      "y": 10,
      "z": 6,
      "name": "Wood_Deadwood_Planks"
    },
    {
      "x": 4,
