{
  "version": 8,
  "blockIdVersion": 11,
  "anchorX": 0,
  "anchorY": 0,
  "anchorZ": 0,
  "blocks": [
    {
      "x": -25,
      "y": 25,
      "z": -18,
      "name": "Rock_Ice_Permafrost"
    },
    {
      "x": -25,
      "y": 26,
      "z": -18,
      "name": "Soil_Snow"
    },
    {
      "x": -25,
      "y": 25,
      "z": -17,
      "name": "Rock_Ice_Permafrost"
    },
    {
      "x": -25,
      "y": 26,
      "z": -17,
      "name": "Rock_Ice_Permafrost"
    },
    {
      "x": -25,
      "y": 27,
      "z": -17,
      "name": "Soil_Snow"
    },
    {
      "x": -25,
      "y": 26,
      "z": -16,
      "name": "Rock_Ice_Permafrost"
    },
    {
      "x": -25,
      "y": 27,
      "z": -16,
      "name": "Rock_Ice_Permafrost"
    },
    {
      "x": -25,
      "y": 28,
      "z": -16,
      "name": "Soil_Snow"
    },
    {
      "x": -25,
      "y": 26,
      "z": -15,
      "name": "Rock_Ice_Permafrost"
    },
    {
      "x": -25,
      "y": 27,
      "z": -15,
      "name": "Rock_Ice_Permafrost"
    },
    {
      "x": -25,
      "y": 28,
      "z": -15,
      "name": "Soil_Snow"
    },
    {
      "x": -25,
      "y": 28,
      "z": -14,
      "name": "Soil_Snow"
    },
    {
      "x": -24,
      "y": 24,
      "z": -20,
      "name": "Rock_Ice_Permafrost"
    },
    {
      "x": -24,
      "y": 25,
      "z": -20,
      "name": "Rock_Ice_Permafrost"
    },
    {
      "x": -24,
      "y": 26,
      "z": -20,
      "name": "Rock_Ice_Permafrost"
    },
    {
      "x": -24,
      "y": 27,
      "z": -20,
      "name": "Soil_Snow"
    },
    {
      "x": -24,
      "y": 23,
      "z": -19,
      "name": "Rock_Ice_Permafrost"
    },
    {
      "x": -24,
      "y": 24,
      "z": -19,
      "name": "Rock_Ice_Permafrost"
    },
    {
      "x": -24,
      "y": 25,
      "z": -19,
      "name": "Rock_Ice_Permafrost"
    },
    {
      "x": -24,
      "y": 26,
      "z": -19,
      "name": "Rock_Ice_Permafrost"
    },
    {
      "x": -24,
      "y": 27,
      "z": -19,
      "name": "Rock_Ice_Permafrost"
    },
    {
      "x": -24,
      "y": 28,
      "z": -19,
      "name": "Soil_Snow"
    },
    {
      "x": -24,
      "y": 23,
      "z": -18,
      "name": "Rock_Ice_Permafrost"
    },
    {
      "x": -24,
      "y": 24,
      "z": -18,
      "name": "Rock_Ice_Permafrost"
    },
    {
      "x": -24,
      "y": 25,
      "z": -18,
      "name": "Rock_Ice_Permafrost"
    },
    {
      "x": -24,
      "y": 26,
      "z": -18,
      "name": "Rock_Ice_Permafrost"
    },
    {
      "x": -24,
      "y": 27,
      "z": -18,
      "name": "Rock_Ice_Permafrost"
    },
    {
      "x": -24,
      "y": 28,
      "z": -18,
      "name": "Rock_Ice_Permafrost"
    },
    {
      "x": -24,
      "y": 29,
      "z": -18,
      "name": "Soil_Snow"
    },
    {
      "x": -24,
      "y": 22,
      "z": -17,
      "name": "Rock_Ice_Permafrost"
    },
    {
      "x": -24,
      "y": 23,
      "z": -17,
      "name": "Rock_Ice_Permafrost"
    },
    {
      "x": -24,
      "y": 24,
      "z": -17,
      "name": "Rock_Ice_Permafrost"
    },
    {
      "x": -24,
      "y": 25,
      "z": -17,
      "name": "Rock_Ice_Permafrost"
    },
    {
      "x": -24,
      "y": 26,
      "z": -17,
      "name": "Rock_Ice_Permafrost"
    },
    {
      "x": -24,
      "y": 27,
      "z": -17,
      "name": "Rock_Ice_Permafrost"
    },
    {
      "x": -24,
      "y": 28,
      "z": -17,
      "name": "Rock_Ice_Permafrost"
    },
    {
      "x": -24,
      "y": 29,
      "z": -17,
      "name": "Soil_Snow"
    },
    {
      "x": -24,
      "y": 21,
      "z": -16,
      "name": "Rock_Ice_Permafrost"
    },
    {
      "x": -24,
      "y": 22,
      "z": -16,
      "name": "Rock_Ice_Permafrost"
    },
    {
      "x": -24,
      "y": 23,
      "z": -16,
      "name": "Rock_Ice_Permafrost"
    },
    {
      "x": -24,
      "y": 24,
      "z": -16,
      "name": "Rock_Ice_Permafrost"
    },
    {
      "x": -24,
      "y": 25,
      "z": -16,
      "name": "Rock_Ice_Permafrost"
    },
    {
      "x": -24,
      "y": 26,
      "z": -16,
      "name": "Rock_Ice_Permafrost"
    },
    {
      "x": -24,
      "y": 27,
      "z": -16,
      "name": "Rock_Ice_Permafrost"
    },
    {
      "x": -24,
      "y": 28,
      "z": -16,
      "name": "Rock_Ice_Permafrost"
    },
    {
      "x": -24,
      "y": 29,
      "z": -16,
      "name": "Rock_Ice_Permafrost"
    },
    {
      "x": -24,
      "y": 30,
      "z": -16,
      "name": "Soil_Snow"
    },
    {
      "x": -24,
      "y": 21,
      "z": -15,
      "name": "Rock_Ice_Permafrost"
    },
    {
      "x": -24,
      "y": 22,
      "z": -15,
      "name": "Rock_Ice_Permafrost"
    },
    {
      "x": -24,
      "y": 23,
      "z": -15,
      "name": "Rock_Ice_Permafrost"
    },
    {
      "x": -24,
      "y": 24,
      "z": -15,
      "name": "Rock_Ice_Permafrost"
    },
    {
      "x": -24,
      "y": 25,
      "z": -15,
      "name": "Rock_Ice_Permafrost"
    },
    {
      "x": -24,
      "y": 26,
      "z": -15,
      "name": "Rock_Ice_Permafrost"
    },
    {
      "x": -24,
      "y": 27,
      "z": -15,
      "name": "Rock_Ice"
    },
    {
      "x": -24,
      "y": 28,
      "z": -15,
      "name": "Rock_Ice_Permafrost"
    },
    {
      "x": -24,
      "y": 29,
      "z": -15,
      "name": "Rock_Ice_Permafrost"
    },
    {
      "x": -24,
      "y": 30,
      "z": -15,
      "name": "Soil_Snow"
    },
    {
      "x": -24,
      "y": 19,
      "z": -14,
      "name": "Rock_Ice_Permafrost"
    },
    {
      "x": -24,
      "y": 20,
      "z": -14,
      "name": "Rock_Ice_Permafrost"
    },
    {
      "x": -24,
      "y": 21,
      "z": -14,
      "name": "Rock_Ice_Permafrost"
    },
    {
      "x": -24,
      "y": 22,
      "z": -14,
      "name": "Rock_Ice_Permafrost"
    },
    {
      "x": -24,
      "y": 23,
      "z": -14,
      "name": "Rock_Ice_Permafrost"
    },
    {
      "x": -24,
      "y": 24,
      "z": -14,
      "name": "Rock_Ice_Permafrost"
    },
    {
      "x": -24,
      "y": 25,
      "z": -14,
      "name": "Rock_Ice_Permafrost"
    },
    {
      "x": -24,
      "y": 26,
      "z": -14,
      "name": "Rock_Ice_Permafrost"
    },
    {
      "x": -24,
      "y": 27,
      "z": -14,
      "name": "Rock_Ice_Permafrost"
    },
    {
      "x": -24,
      "y": 28,
      "z": -14,
      "name": "Rock_Ice_Permafrost"
    },
    {
      "x": -24,
      "y": 29,
      "z": -14,
      "name": "Rock_Ice"
    },
    {
      "x": -24,
      "y": 30,
      "z": -14,
      "name": "Soil_Snow"
    },
    {
      "x": -24,
      "y": 15,
      "z": -13,
      "name": "Rock_Ice"
    },
    {
      "x": -24,
      "y": 16,
      "z": -13,
      "name": "Rock_Ice_Permafrost"
    },
    {
      "x": -24,
      "y": 17,
      "z": -13,
      "name": "Rock_Ice_Permafrost"
    },
    {
      "x": -24,
      "y": 18,
      "z": -13,
      "name": "Rock_Ice_Permafrost"
    },
    {
      "x": -24,
      "y": 19,
      "z": -13,
      "name": "Rock_Ice_Permafrost"
    },
    {
      "x": -24,
      "y": 20,
      "z": -13,
      "name": "Rock_Ice_Permafrost"
    },
    {
      "x": -24,
      "y": 21,
      "z": -13,
      "name": "Rock_Ice_Permafrost"
    },
    {
      "x": -24,
      "y": 22,
      "z": -13,
      "name": "Rock_Ice_Permafrost"
    },
    {
      "x": -24,
      "y": 23,
      "z": -13,
      "name": "Rock_Ice_Permafrost"
    },
    {
      "x": -24,
      "y": 24,
      "z": -13,
      "name": "Rock_Ice_Permafrost"
    },
    {
      "x": -24,
      "y": 25,
      "z": -13,
      "name": "Rock_Ice_Permafrost"
    },
    {
      "x": -24,
      "y": 26,
      "z": -13,
      "name": "Rock_Ice_Permafrost"
    },
    {
      "x": -24,
      "y": 27,
      "z": -13,
      "name": "Rock_Ice_Permafrost"
    },
    {
      "x": -24,
      "y": 28,
      "z": -13,
      "name": "Rock_Ice_Permafrost"
    },
    {
      "x": -24,
      "y": 29,
      "z": -13,
      "name": "Rock_Ice_Permafrost"
    },
    {
      "x": -24,
      "y": 30,
      "z": -13,
      "name": "Soil_Snow"
    },
    {
      "x": -24,
      "y": 13,
      "z": -12,
      "name": "Rock_Ice_Permafrost"
    },
    {
      "x": -24,
      "y": 14,
      "z": -12,
      "name": "Rock_Ice_Permafrost"
    },
    {
      "x": -24,
      "y": 15,
      "z": -12,
      "name": "Rock_Ice_Permafrost"
    },
    {
      "x": -24,
      "y": 16,
      "z": -12,
      "name": "Rock_Ice_Permafrost"
    },
    {
      "x": -24,
      "y": 17,
      "z": -12,
      "name": "Rock_Ice_Permafrost"
    },
    {
      "x": -24,
      "y": 18,
      "z": -12,
      "name": "Rock_Ice_Permafrost"
    },
    {
      "x": -24,
      "y": 19,
      "z": -12,
      "name": "Rock_Ice_Permafrost"
    },
    {
      "x": -24,
      "y": 27,
      "z": -12,
      "name": "Rock_Ice_Permafrost"
    },
    {
      "x": -24,
      "y": 28,
      "z": -12,
      "name": "Rock_Ice_Permafrost"
    },
    {
      "x": -24,
      "y": 29,
      "z": -12,
      "name": "Rock_Ice_Permafrost"
    },
    {
      "x": -24,
      "y": 30,
      "z": -12,
      "name": "Soil_Snow"
    },
    {
      "x": -24,
      "y": 12,
      "z": -11,
      "name": "Rock_Ice_Permafrost"
    },
    {
      "x": -24,
      "y": 13,
      "z": -11,
      "name": "Rock_Ice_Permafrost"
    },
    {
      "x": -24,
      "y": 14,
      "z": -11,
      "name": "Rock_Ice_Permafrost"
    },
    {
      "x": -24,
      "y": 15,
      "z": -11,
      "name": "Rock_Ice_Permafrost"
    },
    {
      "x": -24,
      "y": 16,
      "z": -11,
      "name": "Rock_Ice_Permafrost"
    },
    {
      "x": -24,
      "y": 17,
      "z": -11,
      "name": "Rock_Ice_Permafrost"
    },
    {
      "x": -24,
      "y": 18,
      "z": -11,
      "name": "Rock_Ice_Permafrost"
    },
    {
      "x": -24,
      "y": 29,
      "z": -11,
      "name": "Rock_Ice_Permafrost"
    },
    {
      "x": -24,
      "y": 30,
      "z": -11,
      "name": "Soil_Snow"
    },
    {
      "x": -24,
      "y": 11,
      "z": -10,
      "name": "Rock_Ice_Permafrost"
    },
    {
      "x": -24,
      "y": 12,
      "z": -10,
      "name": "Rock_Ice_Permafrost"
    },
    {
      "x": -24,
      "y": 13,
      "z": -10,
      "name": "Rock_Ice"
    },
    {
      "x": -24,
      "y": 14,
      "z": -10,
      "name": "Rock_Ice_Permafrost"
    },
    {
      "x": -24,
      "y": 15,
      "z": -10,
      "name": "Rock_Ice_Permafrost"
    },
    {
      "x": -24,
      "y": 16,
      "z": -10,
      "name": "Rock_Ice_Permafrost"
    },
    {
      "x": -24,
      "y": 17,
      "z": -10,
      "name": "Rock_Ice_Permafrost"
    },
    {
      "x": -24,
      "y": 18,
      "z": -10,
      "name": "Soil_Snow"
    },
    {
      "x": -24,
      "y": 11,
      "z": -9,
      "name": "Rock_Ice_Permafrost"
    },
    {
      "x": -24,
      "y": 12,
      "z": -9,
      "name": "Rock_Ice_Permafrost"
    },
    {
      "x": -24,
      "y": 13,
      "z": -9,
      "name": "Rock_Ice_Permafrost"
    },
    {
      "x": -24,
      "y": 14,
      "z": -9,
      "name": "Rock_Ice_Permafrost"
    },
    {
      "x": -24,
      "y": 15,
      "z": -9,
      "name": "Rock_Ice_Permafrost"
    },
    {
      "x": -24,
      "y": 16,
      "z": -9,
      "name": "Rock_Ice_Permafrost"
    },
    {
      "x": -24,
      "y": 17,
      "z": -9,
      "name": "Soil_Snow"
    },
    {
      "x": -24,
      "y": 11,
      "z": -8,
      "name": "Rock_Ice"
    },
    {
      "x": -24,
      "y": 12,
      "z": -8,
      "name": "Rock_Ice"
    },
    {
      "x": -24,
      "y": 13,
      "z": -8,
      "name": "Rock_Ice"
    },
    {
      "x": -24,
      "y": 14,
      "z": -8,
      "name": "Rock_Ice_Permafrost"
    },
    {
      "x": -24,
      "y": 15,
      "z": -8,
      "name": "Rock_Ice_Permafrost"
    },
    {
      "x": -24,
      "y": 16,
      "z": -8,
      "name": "Soil_Snow"
    },
    {
      "x": -24,
      "y": 12,
      "z": -7,
      "name": "Rock_Ice_Permafrost"
    },
    {
      "x": -24,
      "y": 13,
      "z": -7,
      "name": "Rock_Ice_Permafrost"
    },
    {
      "x": -24,
      "y": 14,
      "z": -7,
      "name": "Rock_Ice_Permafrost"
    },
    {
      "x": -24,
      "y": 15,
      "z": -7,
      "name": "Soil_Snow"
    },
    {
      "x": -23,
      "y": 24,
      "z": -21,
      "name": "Rock_Ice"
    },
    {
      "x": -23,
      "y": 25,
      "z": -21,
      "name": "Rock_Ice"
    },
    {
      "x": -23,
      "y": 26,
      "z": -21,
      "name": "Rock_Ice"
    },
    {
      "x": -23,
      "y": 27,
      "z": -21,
      "name": "Rock_Ice_Permafrost"
    },
    {
      "x": -23,
      "y": 28,
      "z": -21,
      "name": "Soil_Snow"
    },
    {
      "x": -23,
      "y": 22,
      "z": -20,
      "name": "Rock_Ice"
    },
    {
      "x": -23,
      "y": 23,
      "z": -20,
      "name": "Rock_Ice"
    },
    {
      "x": -23,
      "y": 24,
      "z": -20,
      "name": "Rock_Ice"
    },
    {
      "x": -23,
      "y": 25,
      "z": -20,
      "name": "Rock_Ice_Permafrost"
    },
    {
      "x": -23,
      "y": 26,
      "z": -20,
      "name": "Rock_Ice_Permafrost"
    },
    {
      "x": -23,
      "y": 27,
      "z": -20,
      "name": "Rock_Ice"
    },
    {
      "x": -23,
      "y": 28,
      "z": -20,
      "name": "Rock_Ice_Permafrost"
    },
    {
      "x": -23,
      "y": 29,
      "z": -20,
      "name": "Soil_Snow"
    },
    {
      "x": -23,
      "y": 21,
      "z": -19,
      "name": "Rock_Ice_Permafrost"
    },
    {
      "x": -23,
      "y": 22,
      "z": -19,
      "name": "Rock_Ice"
    },
    {
      "x": -23,
      "y": 23,
      "z": -19,
      "name": "Rock_Ice_Permafrost"
    },
    {
      "x": -23,
      "y": 24,
      "z": -19,
      "name": "Rock_Ice_Permafrost"
    },
    {
      "x": -23,
      "y": 25,
      "z": -19,
      "name": "Rock_Ice_Permafrost"
    },
    {
      "x": -23,
      "y": 26,
      "z": -19,
      "name": "Rock_Ice_Permafrost"
    },
    {
      "x": -23,
      "y": 27,
      "z": -19,
      "name": "Rock_Ice_Permafrost"
    },
    {
      "x": -23,
      "y": 28,
      "z": -19,
      "name": "Rock_Ice"
    },
    {
      "x": -23,
      "y": 29,
      "z": -19,
      "name": "Rock_Ice_Permafrost"
    },
    {
      "x": -23,
      "y": 30,
      "z": -19,
      "name": "Soil_Snow"
    },
    {
      "x": -23,
      "y": 20,
      "z": -18,
      "name": "Rock_Ice"
    },
    {
      "x": -23,
      "y": 21,
      "z": -18,
      "name": "Rock_Ice_Permafrost"
    },
    {
      "x": -23,
      "y": 22,
      "z": -18,
      "name": "Rock_Ice_Permafrost"
    },
    {
      "x": -23,
      "y": 23,
      "z": -18,
      "name": "Rock_Ice"
    },
    {
      "x": -23,
      "y": 24,
      "z": -18,
      "name": "Rock_Ice_Permafrost"
    },
    {
      "x": -23,
      "y": 25,
      "z": -18,
      "name": "Rock_Ice_Permafrost"
    },
    {
      "x": -23,
      "y": 26,
      "z": -18,
      "name": "Rock_Ice_Permafrost"
    },
    {
      "x": -23,
      "y": 27,
      "z": -18,
      "name": "Rock_Ice_Permafrost"
    },
    {
      "x": -23,
      "y": 28,
      "z": -18,
      "name": "Rock_Ice"
    },
    {
      "x": -23,
      "y": 29,
      "z": -18,
      "name": "Rock_Ice_Permafrost"
    },
    {
      "x": -23,
      "y": 30,
      "z": -18,
      "name": "Rock_Ice_Permafrost"
    },
    {
      "x": -23,
      "y": 31,
      "z": -18,
      "name": "Soil_Snow"
    },
    {
      "x": -23,
      "y": 18,
      "z": -17,
      "name": "Rock_Ice"
    },
    {
      "x": -23,
      "y": 19,
      "z": -17,
      "name": "Rock_Ice"
    },
    {
      "x": -23,
      "y": 20,
      "z": -17,
      "name": "Rock_Ice_Permafrost"
    },
    {
      "x": -23,
      "y": 21,
      "z": -17,
      "name": "Rock_Ice_Permafrost"
    },
    {
      "x": -23,
      "y": 22,
      "z": -17,
      "name": "Rock_Ice_Permafrost"
    },
    {
      "x": -23,
      "y": 23,
      "z": -17,
      "name": "Rock_Ice_Permafrost"
    },
    {
      "x": -23,
      "y": 24,
      "z": -17,
      "name": "Rock_Ice_Permafrost"
    },
    {
      "x": -23,
      "y": 25,
      "z": -17,
      "name": "Rock_Ice_Permafrost"
    },
    {
      "x": -23,
      "y": 26,
      "z": -17,
      "name": "Rock_Ice_Permafrost"
    },
    {
      "x": -23,
      "y": 27,
      "z": -17,
      "name": "Rock_Ice_Permafrost"
    },
    {
      "x": -23,
      "y": 28,
      "z": -17,
      "name": "Rock_Ice"
    },
    {
      "x": -23,
      "y": 29,
      "z": -17,
      "name": "Rock_Ice"
    },
    {
      "x": -23,
      "y": 30,
      "z": -17,
      "name": "Rock_Ice"
    },
    {
      "x": -23,
      "y": 31,
      "z": -17,
      "name": "Soil_Snow"
    },
    {
      "x": -23,
      "y": 17,
      "z": -16,
      "name": "Rock_Ice"
    },
    {
      "x": -23,
      "y": 18,
      "z": -16,
      "name": "Rock_Ice"
    },
    {
      "x": -23,
      "y": 19,
      "z": -16,
      "name": "Rock_Ice_Permafrost"
    },
    {
      "x": -23,
      "y": 20,
      "z": -16,
      "name": "Rock_Ice_Permafrost"
    },
    {
      "x": -23,
      "y": 21,
      "z": -16,
      "name": "Rock_Ice_Permafrost"
    },
    {
      "x": -23,
      "y": 22,
      "z": -16,
      "name": "Rock_Ice_Permafrost"
    },
    {
      "x": -23,
      "y": 23,
      "z": -16,
      "name": "Rock_Ice_Permafrost"
    },
    {
      "x": -23,
      "y": 24,
      "z": -16,
      "name": "Rock_Ice_Permafrost"
    },
    {
      "x": -23,
      "y": 25,
      "z": -16,
      "name": "Rock_Ice_Permafrost"
    },
    {
      "x": -23,
      "y": 26,
      "z": -16,
      "name": "Rock_Ice_Permafrost"
    },
    {
      "x": -23,
      "y": 27,
      "z": -16,
      "name": "Rock_Ice_Permafrost"
    },
    {
      "x": -23,
      "y": 28,
      "z": -16,
      "name": "Rock_Ice_Permafrost"
    },
    {
      "x": -23,
      "y": 29,
      "z": -16,
      "name": "Rock_Ice"
    },
    {
      "x": -23,
      "y": 30,
      "z": -16,
      "name": "Rock_Ice"
    },
    {
      "x": -23,
      "y": 31,
      "z": -16,
      "name": "Rock_Ice"
    },
    {
      "x": -23,
      "y": 32,
      "z": -16,
      "name": "Soil_Snow"
    },
    {
      "x": -23,
      "y": 15,
      "z": -15,
      "name": "Rock_Ice"
    },
    {
      "x": -23,
      "y": 16,
      "z": -15,
      "name": "Rock_Ice"
    },
    {
      "x": -23,
      "y": 17,
      "z": -15,
      "name": "Rock_Ice"
    },
    {
      "x": -23,
      "y": 18,
      "z": -15,
      "name": "Rock_Ice"
    },
    {
      "x": -23,
      "y": 19,
      "z": -15,
      "name": "Rock_Ice_Permafrost"
    },
    {
      "x": -23,
      "y": 20,
      "z": -15,
      "name": "Rock_Ice_Permafrost"
    },
    {
      "x": -23,
      "y": 21,
      "z": -15,
      "name": "Rock_Ice_Permafrost"
    },
    {
      "x": -23,
      "y": 22,
      "z": -15,
      "name": "Rock_Ice_Permafrost"
    },
    {
      "x": -23,
      "y": 23,
      "z": -15,
      "name": "Rock_Ice_Permafrost"
    },
    {
      "x": -23,
      "y": 24,
      "z": -15,
      "name": "Rock_Ice_Permafrost"
    },
    {
      "x": -23,
      "y": 25,
      "z": -15,
      "name": "Rock_Ice_Permafrost"
    },
    {
      "x": -23,
      "y": 26,
      "z": -15,
      "name": "Rock_Ice_Permafrost"
    },
    {
      "x": -23,
      "y": 27,
      "z": -15,
      "name": "Rock_Ice"
    },
    {
      "x": -23,
      "y": 28,
      "z": -15,
      "name": "Rock_Ice"
    },
    {
      "x": -23,
      "y": 29,
      "z": -15,
      "name": "Rock_Ice"
    },
    {
      "x": -23,
      "y": 30,
      "z": -15,
      "name": "Rock_Ice_Permafrost"
    },
    {
      "x": -23,
      "y": 31,
      "z": -15,
      "name": "Rock_Ice"
    },
    {
      "x": -23,
      "y": 32,
      "z": -15,
      "name": "Soil_Snow"
    },
    {
      "x": -23,
      "y": 13,
      "z": -14,
      "name": "Rock_Ice"
    },
    {
      "x": -23,
      "y": 14,
      "z": -14,
      "name": "Rock_Ice"
    },
    {
      "x": -23,
      "y": 15,
      "z": -14,
      "name": "Rock_Ice"
    },
    {
      "x": -23,
      "y": 16,
      "z": -14,
      "name": "Rock_Ice"
    },
    {
      "x": -23,
      "y": 17,
      "z": -14,
      "name": "Rock_Ice"
    },
    {
      "x": -23,
      "y": 18,
      "z": -14,
      "name": "Rock_Ice_Permafrost"
    },
    {
      "x": -23,
      "y": 19,
      "z": -14,
      "name": "Rock_Ice_Permafrost"
    },
    {
      "x": -23,
      "y": 20,
      "z": -14,
      "name": "Rock_Ice_Permafrost"
    },
    {
      "x": -23,
      "y": 21,
      "z": -14,
      "name": "Rock_Ice_Permafrost"
    },
    {
      "x": -23,
      "y": 22,
      "z": -14,
      "name": "Rock_Ice_Permafrost"
    },
    {
      "x": -23,
      "y": 23,
      "z": -14,
      "name": "Rock_Ice_Permafrost"
    },
    {
      "x": -23,
      "y": 24,
      "z": -14,
      "name": "Rock_Ice_Permafrost"
    },
    {
      "x": -23,
      "y": 25,
      "z": -14,
      "name": "Rock_Ice_Permafrost"
    },
    {
      "x": -23,
      "y": 26,
      "z": -14,
      "name": "Rock_Ice"
    },
    {
      "x": -23,
      "y": 27,
      "z": -14,
      "name": "Rock_Ice_Permafrost"
    },
    {
      "x": -23,
      "y": 28,
      "z": -14,
      "name": "Rock_Ice"
    },
    {
      "x": -23,
      "y": 29,
      "z": -14,
      "name": "Rock_Ice"
    },
    {
      "x": -23,
      "y": 30,
      "z": -14,
      "name": "Rock_Ice_Permafrost"
    },
    {
      "x": -23,
      "y": 31,
      "z": -14,
      "name": "Rock_Ice_Permafrost"
    },
    {
      "x": -23,
      "y": 32,
      "z": -14,
      "name": "Soil_Snow"
    },
    {
      "x": -23,
      "y": 12,
      "z": -13,
      "name": "Rock_Ice"
    },
    {
      "x": -23,
      "y": 13,
      "z": -13,
      "name": "Rock_Ice"
    },
    {
      "x": -23,
      "y": 14,
      "z": -13,
      "name": "Rock_Ice"
    },
    {
      "x": -23,
      "y": 15,
      "z": -13,
      "name": "Rock_Ice_Permafrost"
    },
    {
      "x": -23,
      "y": 16,
      "z": -13,
      "name": "Rock_Ice"
    },
    {
      "x": -23,
      "y": 17,
      "z": -13,
      "name": "Rock_Ice"
    },
    {
      "x": -23,
      "y": 18,
      "z": -13,
      "name": "Rock_Ice_Permafrost"
    },
    {
      "x": -23,
      "y": 19,
      "z": -13,
      "name": "Rock_Ice_Permafrost"
    },
    {
      "x": -23,
      "y": 20,
      "z": -13,
      "name": "Rock_Ice_Permafrost"
    },
    {
      "x": -23,
      "y": 21,
      "z": -13,
      "name": "Rock_Ice_Permafrost"
    },
    {
      "x": -23,
      "y": 22,
      "z": -13,
      "name": "Rock_Ice_Permafrost"
    },
    {
      "x": -23,
      "y": 23,
      "z": -13,
      "name": "Rock_Ice_Permafrost"
    },
    {
      "x": -23,
      "y": 24,
      "z": -13,
      "name": "Rock_Ice_Permafrost"
    },
    {
      "x": -23,
      "y": 25,
      "z": -13,
      "name": "Rock_Ice_Permafrost"
    },
    {
      "x": -23,
      "y": 26,
      "z": -13,
      "name": "Rock_Ice_Permafrost"
    },
    {
      "x": -23,
      "y": 27,
      "z": -13,
      "name": "Rock_Ice_Permafrost"
    },
    {
      "x": -23,
      "y": 28,
      "z": -13,
      "name": "Rock_Ice"
    },
    {
      "x": -23,
      "y": 29,
      "z": -13,
      "name": "Rock_Ice"
    },
    {
      "x": -23,
      "y": 30,
      "z": -13,
      "name": "Rock_Ice"
    },
    {
      "x": -23,
      "y": 31,
      "z": -13,
      "name": "Rock_Ice"
    },
    {
      "x": -23,
      "y": 32,
      "z": -13,
      "name": "Soil_Snow"
    },
    {
      "x": -23,
      "y": 10,
      "z": -12,
      "name": "Rock_Ice"
    },
    {
      "x": -23,
      "y": 11,
      "z": -12,
      "name": "Rock_Ice"
    },
    {
      "x": -23,
      "y": 12,
      "z": -12,
      "name": "Rock_Ice"
    },
    {
      "x": -23,
      "y": 13,
      "z": -12,
      "name": "Rock_Ice"
    },
    {
      "x": -23,
      "y": 14,
      "z": -12,
      "name": "Rock_Ice"
    },
    {
      "x": -23,
      "y": 15,
      "z": -12,
      "name": "Rock_Ice"
    },
    {
      "x": -23,
      "y": 16,
      "z": -12,
      "name": "Rock_Ice_Permafrost"
    },
    {
      "x": -23,
      "y": 17,
      "z": -12,
      "name": "Rock_Ice_Permafrost"
    },
    {
      "x": -23,
      "y": 18,
      "z": -12,
      "name": "Rock_Ice_Permafrost"
    },
    {
      "x": -23,
      "y": 19,
      "z": -12,
      "name": "Rock_Ice_Permafrost"
    },
    {
      "x": -23,
      "y": 20,
      "z": -12,
      "name": "Rock_Ice_Permafrost"
    },
    {
      "x": -23,
      "y": 21,
      "z": -12,
      "name": "Rock_Ice_Permafrost"
    },
    {
      "x": -23,
      "y": 22,
      "z": -12,
      "name": "Rock_Ice_Permafrost"
    },
    {
      "x": -23,
      "y": 23,
      "z": -12,
      "name": "Rock_Ice_Permafrost"
    },
    {
      "x": -23,
      "y": 24,
      "z": -12,
      "name": "Rock_Ice_Permafrost"
    },
    {
      "x": -23,
      "y": 25,
      "z": -12,
      "name": "Rock_Ice_Permafrost"
    },
    {
      "x": -23,
      "y": 26,
      "z": -12,
      "name": "Rock_Ice_Permafrost"
    },
    {
      "x": -23,
      "y": 27,
      "z": -12,
      "name": "Rock_Ice_Permafrost"
    },
    {
      "x": -23,
      "y": 28,
      "z": -12,
      "name": "Rock_Ice_Permafrost"
    },
    {
      "x": -23,
      "y": 29,
      "z": -12,
      "name": "Rock_Ice_Permafrost"
    },
    {
      "x": -23,
      "y": 30,
      "z": -12,
      "name": "Rock_Ice"
    },
    {
      "x": -23,
      "y": 31,
      "z": -12,
      "name": "Rock_Ice"
    },
    {
      "x": -23,
      "y": 32,
      "z": -12,
      "name": "Soil_Snow"
    },
    {
      "x": -23,
      "y": 10,
      "z": -11,
      "name": "Rock_Ice"
    },
    {
      "x": -23,
      "y": 11,
      "z": -11,
      "name": "Rock_Ice"
    },
    {
      "x": -23,
      "y": 12,
      "z": -11,
      "name": "Rock_Ice"
    },
    {
      "x": -23,
      "y": 13,
      "z": -11,
      "name": "Rock_Ice_Permafrost"
    },
    {
      "x": -23,
      "y": 14,
      "z": -11,
      "name": "Rock_Ice_Permafrost"
    },
    {
      "x": -23,
      "y": 15,
      "z": -11,
      "name": "Rock_Ice_Permafrost"
    },
    {
      "x": -23,
      "y": 16,
      "z": -11,
      "name": "Rock_Ice_Permafrost"
    },
    {
      "x": -23,
      "y": 17,
      "z": -11,
      "name": "Rock_Ice_Permafrost"
    },
    {
      "x": -23,
      "y": 18,
      "z": -11,
      "name": "Rock_Ice_Permafrost"
    },
    {
      "x": -23,
      "y": 19,
      "z": -11,
      "name": "Rock_Ice_Permafrost"
    },
    {
      "x": -23,
      "y": 20,
      "z": -11,
      "name": "Rock_Ice_Permafrost"
    },
    {
      "x": -23,
      "y": 21,
      "z": -11,
      "name": "Rock_Ice_Permafrost"
    },
    {
      "x": -23,
      "y": 22,
      "z": -11,
      "name": "Rock_Ice_Permafrost"
    },
    {
      "x": -23,
      "y": 23,
      "z": -11,
      "name": "Rock_Ice_Permafrost"
    },
    {
      "x": -23,
      "y": 24,
      "z": -11,
      "name": "Rock_Ice_Permafrost"
    },
    {
      "x": -23,
      "y": 25,
      "z": -11,
      "name": "Rock_Ice_Permafrost"
    },
    {
      "x": -23,
      "y": 26,
      "z": -11,
      "name": "Rock_Ice_Permafrost"
    },
    {
      "x": -23,
      "y": 27,
      "z": -11,
      "name": "Rock_Ice_Permafrost"
    },
    {
      "x": -23,
      "y": 28,
      "z": -11,
      "name": "Rock_Ice"
    },
    {
      "x": -23,
      "y": 29,
      "z": -11,
      "name": "Rock_Ice"
    },
    {
      "x": -23,
      "y": 30,
      "z": -11,
      "name": "Rock_Ice"
    },
    {
      "x": -23,
      "y": 31,
      "z": -11,
      "name": "Rock_Ice"
    },
    {
      "x": -23,
      "y": 32,
      "z": -11,
      "name": "Rock_Ice"
    },
    {
      "x": -23,
      "y": 10,
      "z": -10,
      "name": "Rock_Ice"
    },
    {
      "x": -23,
      "y": 11,
      "z": -10,
      "name": "Rock_Ice"
    },
    {
      "x": -23,
      "y": 12,
      "z": -10,
      "name": "Rock_Ice_Permafrost"
    },
    {
      "x": -23,
      "y": 13,
      "z": -10,
      "name": "Rock_Ice_Permafrost"
    },
    {
      "x": -23,
      "y": 14,
      "z": -10,
      "name": "Rock_Ice_Permafrost"
    },
    {
      "x": -23,
      "y": 15,
      "z": -10,
      "name": "Rock_Ice_Permafrost"
    },
    {
      "x": -23,
      "y": 16,
      "z": -10,
      "name": "Rock_Ice_Permafrost"
    },
    {
      "x": -23,
      "y": 17,
      "z": -10,
      "name": "Rock_Ice_Permafrost"
    },
    {
      "x": -23,
      "y": 18,
      "z": -10,
      "name": "Rock_Ice_Permafrost"
    },
    {
      "x": -23,
      "y": 19,
      "z": -10,
      "name": "Rock_Ice_Permafrost"
    },
    {
      "x": -23,
      "y": 20,
      "z": -10,
      "name": "Rock_Ice_Permafrost"
    },
    {
      "x": -23,
      "y": 21,
      "z": -10,
      "name": "Rock_Ice_Permafrost"
    },
    {
      "x": -23,
      "y": 22,
      "z": -10,
      "name": "Rock_Ice_Permafrost"
    },
    {
      "x": -23,
      "y": 23,
      "z": -10,
      "name": "Rock_Ice_Permafrost"
    },
    {
      "x": -23,
      "y": 24,
      "z": -10,
      "name": "Rock_Ice_Permafrost"
    },
    {
      "x": -23,
      "y": 25,
      "z": -10,
      "name": "Rock_Ice_Permafrost"
    },
    {
      "x": -23,
      "y": 26,
      "z": -10,
      "name": "Rock_Ice_Permafrost"
    },
    {
      "x": -23,
      "y": 27,
      "z": -10,
      "name": "Rock_Ice_Permafrost"
    },
    {
      "x": -23,
      "y": 28,
      "z": -10,
      "name": "Rock_Ice"
    },
    {
      "x": -23,
      "y": 29,
      "z": -10,
      "name": "Rock_Ice"
    },
    {
      "x": -23,
      "y": 30,
      "z": -10,
      "name": "Rock_Ice"
    },
    {
      "x": -23,
      "y": 31,
      "z": -10,
      "name": "Rock_Ice"
    },
    {
      "x": -23,
      "y": 32,
      "z": -10,
      "name": "Soil_Snow"
    },
    {
      "x": -23,
      "y": 10,
      "z": -9,
      "name": "Rock_Ice_Permafrost"
    },
    {
      "x": -23,
      "y": 11,
      "z": -9,
      "name": "Rock_Ice_Permafrost"
    },
    {
      "x": -23,
      "y": 12,
      "z": -9,
      "name": "Rock_Ice_Permafrost"
    },
    {
      "x": -23,
      "y": 13,
      "z": -9,
      "name": "Rock_Ice_Permafrost"
    },
    {
      "x": -23,
      "y": 14,
      "z": -9,
      "name": "Rock_Ice"
    },
    {
      "x": -23,
      "y": 15,
      "z": -9,
      "name": "Rock_Ice_Permafrost"
    },
    {
      "x": -23,
      "y": 16,
      "z": -9,
      "name": "Rock_Ice_Permafrost"
    },
    {
      "x": -23,
      "y": 17,
      "z": -9,
      "name": "Rock_Ice_Permafrost"
    },
    {
      "x": -23,
      "y": 18,
      "z": -9,
      "name": "Rock_Ice_Permafrost"
    },
    {
      "x": -23,
      "y": 19,
      "z": -9,
      "name": "Rock_Ice_Permafrost"
    },
    {
      "x": -23,
      "y": 20,
      "z": -9,
      "name": "Rock_Ice_Permafrost"
    },
    {
      "x": -23,
      "y": 21,
      "z": -9,
      "name": "Rock_Ice_Permafrost"
    },
    {
      "x": -23,
      "y": 30,
      "z": -9,
      "name": "Rock_Ice_Permafrost"
    },
    {
      "x": -23,
      "y": 31,
      "z": -9,
      "name": "Rock_Ice"
    },
    {
      "x": -23,
      "y": 32,
      "z": -9,
      "name": "Soil_Snow"
    },
    {
      "x": -23,
      "y": 11,
      "z": -8,
      "name": "Rock_Ice"
    },
    {
      "x": -23,
      "y": 12,
      "z": -8,
      "name": "Rock_Ice_Permafrost"
    },
    {
      "x": -23,
      "y": 13,
      "z": -8,
      "name": "Rock_Ice_Permafrost"
    },
    {
      "x": -23,
      "y": 14,
      "z": -8,
      "name": "Rock_Ice_Permafrost"
    },
    {
      "x": -23,
      "y": 15,
      "z": -8,
      "name": "Rock_Ice_Permafrost"
    },
    {
      "x": -23,
      "y": 16,
      "z": -8,
      "name": "Rock_Ice_Permafrost"
    },
    {
      "x": -23,
      "y": 17,
      "z": -8,
      "name": "Rock_Ice_Permafrost"
    },
    {
      "x": -23,
      "y": 18,
      "z": -8,
      "name": "Rock_Ice_Permafrost"
    },
    {
      "x": -23,
      "y": 19,
      "z": -8,
      "name": "Rock_Ice_Permafrost"
    },
    {
      "x": -23,
      "y": 20,
      "z": -8,
      "name": "Soil_Snow"
    },
    {
      "x": -23,
      "y": 11,
      "z": -7,
      "name": "Rock_Ice_Permafrost"
    },
    {
      "x": -23,
      "y": 12,
      "z": -7,
      "name": "Rock_Ice_Permafrost"
    },
    {
      "x": -23,
      "y": 13,
      "z": -7,
      "name": "Rock_Ice_Permafrost"
    },
    {
      "x": -23,
      "y": 14,
      "z": -7,
      "name": "Rock_Ice_Permafrost"
    },
    {
      "x": -23,
      "y": 15,
      "z": -7,
      "name": "Rock_Ice_Permafrost"
    },
    {
      "x": -23,
      "y": 16,
      "z": -7,
      "name": "Rock_Ice_Permafrost"
    },
    {
      "x": -23,
      "y": 17,
      "z": -7,
      "name": "Rock_Ice_Permafrost"
    },
    {
      "x": -23,
      "y": 18,
      "z": -7,
      "name": "Rock_Ice_Permafrost"
    },
    {
      "x": -23,
      "y": 19,
      "z": -7,
      "name": "Rock_Ice_Permafrost"
    },
    {
      "x": -23,
      "y": 12,
      "z": -6,
      "name": "Rock_Ice_Permafrost"
    },
    {
      "x": -23,
      "y": 13,
      "z": -6,
      "name": "Rock_Ice_Permafrost"
    },
    {
      "x": -23,
      "y": 14,
      "z": -6,
      "name": "Rock_Ice_Permafrost"
    },
    {
      "x": -23,
      "y": 15,
      "z": -6,
      "name": "Rock_Ice_Permafrost"
    },
    {
      "x": -23,
      "y": 16,
      "z": -6,
      "name": "Rock_Ice_Permafrost"
    },
    {
      "x": -23,
      "y": 17,
      "z": -6,
      "name": "Soil_Snow"
    },
    {
      "x": -22,
      "y": 24,
      "z": -22,
      "name": "Rock_Ice"
    },
    {
      "x": -22,
      "y": 25,
      "z": -22,
      "name": "Rock_Ice"
    },
    {
      "x": -22,
      "y": 26,
      "z": -22,
      "name": "Rock_Ice"
    },
    {
      "x": -22,
      "y": 27,
      "z": -22,
      "name": "Rock_Ice"
    },
    {
      "x": -22,
      "y": 28,
      "z": -22,
      "name": "Soil_Snow"
    },
    {
      "x": -22,
      "y": 22,
      "z": -21,
      "name": "Rock_Ice"
    },
    {
      "x": -22,
      "y": 23,
      "z": -21,
      "name": "Rock_Ice"
    },
    {
      "x": -22,
      "y": 24,
      "z": -21,
      "name": "Rock_Ice"
    },
    {
      "x": -22,
      "y": 25,
      "z": -21,
      "name": "Rock_Ice_Permafrost"
    },
    {
      "x": -22,
      "y": 26,
      "z": -21,
      "name": "Rock_Ice"
    },
    {
      "x": -22,
      "y": 27,
      "z": -21,
      "name": "Rock_Ice"
    },
    {
      "x": -22,
      "y": 28,
      "z": -21,
      "name": "Rock_Ice"
    },
    {
      "x": -22,
      "y": 29,
      "z": -21,
      "name": "Rock_Ice_Permafrost"
    },
    {
      "x": -22,
      "y": 30,
      "z": -21,
      "name": "Soil_Snow"
    },
    {
      "x": -22,
      "y": 21,
      "z": -20,
      "name": "Rock_Ice"
    },
    {
      "x": -22,
      "y": 22,
      "z": -20,
      "name": "Rock_Ice"
    },
    {
      "x": -22,
      "y": 23,
      "z": -20,
      "name": "Rock_Ice_Permafrost"
    },
    {
      "x": -22,
      "y": 24,
      "z": -20,
      "name": "Rock_Ice"
    },
    {
      "x": -22,
      "y": 25,
      "z": -20,
      "name": "Rock_Ice"
    },
    {
      "x": -22,
      "y": 26,
      "z": -20,
      "name": "Rock_Ice"
    },
    {
      "x": -22,
      "y": 27,
      "z": -20,
      "name": "Rock_Ice_Permafrost"
    },
    {
      "x": -22,
      "y": 28,
      "z": -20,
      "name": "Rock_Ice_Permafrost"
    },
    {
      "x": -22,
      "y": 29,
      "z": -20,
      "name": "Rock_Ice"
    },
    {
      "x": -22,
      "y": 30,
      "z": -20,
      "name": "Rock_Ice"
    },
    {
      "x": -22,
      "y": 31,
      "z": -20,
      "name": "Soil_Snow"
    },
    {
      "x": -22,
      "y": 19,
      "z": -19,
      "name": "Rock_Ice"
    },
    {
      "x": -22,
      "y": 20,
      "z": -19,
      "name": "Rock_Ice"
    },
    {
      "x": -22,
      "y": 21,
      "z": -19,
      "name": "Rock_Ice"
    },
    {
      "x": -22,
      "y": 22,
      "z": -19,
      "name": "Rock_Ice"
    },
    {
      "x": -22,
      "y": 23,
      "z": -19,
      "name": "Rock_Ice"
    },
    {
      "x": -22,
      "y": 24,
      "z": -19,
      "name": "Rock_Ice_Permafrost"
    },
    {
      "x": -22,
      "y": 25,
      "z": -19,
      "name": "Rock_Ice"
    },
    {
      "x": -22,
      "y": 26,
      "z": -19,
      "name": "Rock_Ice"
    },
    {
      "x": -22,
      "y": 27,
      "z": -19,
      "name": "Rock_Ice_Permafrost"
    },
    {
      "x": -22,
      "y": 28,
      "z": -19,
      "name": "Rock_Ice"
    },
    {
      "x": -22,
      "y": 29,
      "z": -19,
      "name": "Rock_Ice"
    },
    {
      "x": -22,
      "y": 30,
      "z": -19,
      "name": "Rock_Ice"
    },
    {
      "x": -22,
      "y": 31,
      "z": -19,
      "name": "Rock_Ice"
    },
    {
      "x": -22,
      "y": 32,
      "z": -19,
      "name": "Soil_Snow"
    },
    {
      "x": -22,
      "y": 18,
      "z": -18,
      "name": "Rock_Ice"
    },
    {
      "x": -22,
      "y": 19,
      "z": -18,
      "name": "Rock_Ice"
    },
    {
      "x": -22,
      "y": 20,
      "z": -18,
      "name": "Rock_Ice"
    },
    {
      "x": -22,
      "y": 21,
      "z": -18,
      "name": "Rock_Ice"
    },
    {
      "x": -22,
      "y": 22,
      "z": -18,
      "name": "Rock_Ice"
    },
    {
      "x": -22,
      "y": 23,
      "z": -18,
      "name": "Rock_Ice"
    },
    {
      "x": -22,
      "y": 24,
      "z": -18,
      "name": "Rock_Ice_Permafrost"
    },
    {
      "x": -22,
      "y": 25,
      "z": -18,
      "name": "Rock_Ice_Permafrost"
    },
    {
      "x": -22,
      "y": 26,
      "z": -18,
      "name": "Rock_Ice_Permafrost"
    },
    {
      "x": -22,
      "y": 27,
      "z": -18,
      "name": "Rock_Ice"
    },
    {
      "x": -22,
      "y": 28,
      "z": -18,
      "name": "Rock_Ice_Permafrost"
    },
    {
      "x": -22,
      "y": 29,
      "z": -18,
      "name": "Rock_Ice"
    },
    {
      "x": -22,
      "y": 30,
      "z": -18,
      "name": "Rock_Ice"
    },
    {
      "x": -22,
      "y": 31,
      "z": -18,
      "name": "Rock_Ice"
    },
    {
      "x": -22,
      "y": 32,
      "z": -18,
      "name": "Rock_Ice"
    },
    {
      "x": -22,
      "y": 33,
      "z": -18,
      "name": "Soil_Snow"
    },
    {
      "x": -22,
      "y": 17,
      "z": -17,
      "name": "Rock_Ice"
    },
    {
      "x": -22,
      "y": 18,
      "z": -17,
      "name": "Rock_Ice"
    },
    {
      "x": -22,
      "y": 19,
      "z": -17,
      "name": "Rock_Ice"
    },
    {
      "x": -22,
      "y": 20,
      "z": -17,
      "name": "Rock_Ice"
    },
    {
      "x": -22,
      "y": 21,
      "z": -17,
      "name": "Rock_Ice"
    },
    {
      "x": -22,
      "y": 22,
      "z": -17,
      "name": "Rock_Ice_Permafrost"
    },
    {
      "x": -22,
      "y": 23,
      "z": -17,
      "name": "Rock_Ice"
    },
    {
      "x": -22,
      "y": 24,
      "z": -17,
      "name": "Rock_Ice"
    },
    {
      "x": -22,
      "y": 25,
      "z": -17,
      "name": "Rock_Ice_Permafrost"
    },
    {
      "x": -22,
      "y": 26,
      "z": -17,
      "name": "Rock_Ice_Permafrost"
    },
    {
      "x": -22,
      "y": 27,
      "z": -17,
      "name": "Rock_Ice"
    },
    {
      "x": -22,
      "y": 28,
      "z": -17,
      "name": "Rock_Ice"
    },
    {
      "x": -22,
      "y": 29,
      "z": -17,
      "name": "Rock_Ice"
    },
    {
      "x": -22,
      "y": 30,
      "z": -17,
      "name": "Rock_Ice"
    },
    {
      "x": -22,
      "y": 31,
      "z": -17,
      "name": "Rock_Ice"
    },
    {
      "x": -22,
      "y": 32,
      "z": -17,
      "name": "Rock_Ice"
    },
    {
      "x": -22,
      "y": 33,
      "z": -17,
      "name": "Soil_Snow"
    },
    {
      "x": -22,
      "y": 15,
      "z": -16,
      "name": "Rock_Ice"
    },
    {
      "x": -22,
      "y": 16,
      "z": -16,
      "name": "Rock_Ice"
    },
    {
      "x": -22,
      "y": 17,
      "z": -16,
      "name": "Rock_Ice"
    },
    {
      "x": -22,
      "y": 18,
      "z": -16,
      "name": "Rock_Ice"
    },
    {
      "x": -22,
      "y": 19,
      "z": -16,
      "name": "Rock_Ice"
    },
    {
      "x": -22,
      "y": 20,
      "z": -16,
      "name": "Rock_Ice_Permafrost"
    },
    {
      "x": -22,
      "y": 21,
      "z": -16,
      "name": "Rock_Ice_Permafrost"
    },
    {
      "x": -22,
      "y": 22,
      "z": -16,
      "name": "Rock_Ice_Permafrost"
    },
    {
      "x": -22,
      "y": 23,
      "z": -16,
      "name": "Rock_Ice_Permafrost"
    },
    {
      "x": -22,
      "y": 24,
      "z": -16,
      "name": "Rock_Ice_Permafrost"
    },
    {
      "x": -22,
      "y": 25,
      "z": -16,
      "name": "Rock_Ice_Permafrost"
    },
    {
      "x": -22,
      "y": 26,
      "z": -16,
      "name": "Rock_Ice_Permafrost"
    },
    {
      "x": -22,
      "y": 27,
      "z": -16,
      "name": "Rock_Ice_Permafrost"
    },
    {
      "x": -22,
      "y": 28,
      "z": -16,
      "name": "Rock_Ice"
    },
    {
      "x": -22,
      "y": 29,
      "z": -16,
      "name": "Rock_Ice"
    },
    {
      "x": -22,
      "y": 30,
      "z": -16,
      "name": "Rock_Ice"
    },
    {
      "x": -22,
      "y": 31,
      "z": -16,
      "name": "Rock_Ice"
    },
    {
      "x": -22,
      "y": 32,
      "z": -16,
      "name": "Rock_Ice"
    },
    {
      "x": -22,
      "y": 33,
      "z": -16,
      "name": "Rock_Ice"
    },
    {
      "x": -22,
      "y": 34,
      "z": -16,
      "name": "Soil_Snow"
    },
    {
      "x": -22,
      "y": 12,
      "z": -15,
      "name": "Rock_Ice"
    },
    {
      "x": -22,
      "y": 13,
      "z": -15,
      "name": "Rock_Ice"
    },
    {
      "x": -22,
      "y": 14,
      "z": -15,
      "name": "Rock_Ice"
    },
    {
      "x": -22,
      "y": 15,
      "z": -15,
      "name": "Rock_Ice"
    },
    {
      "x": -22,
      "y": 16,
      "z": -15,
      "name": "Rock_Ice"
    },
    {
      "x": -22,
      "y": 17,
      "z": -15,
      "name": "Rock_Ice"
    },
    {
      "x": -22,
      "y": 18,
      "z": -15,
      "name": "Rock_Ice"
    },
    {
      "x": -22,
      "y": 19,
      "z": -15,
      "name": "Rock_Ice_Permafrost"
    },
    {
      "x": -22,
      "y": 20,
      "z": -15,
      "name": "Rock_Ice_Permafrost"
    },
    {
      "x": -22,
      "y": 21,
      "z": -15,
      "name": "Rock_Ice_Permafrost"
    },
    {
      "x": -22,
      "y": 22,
      "z": -15,
      "name": "Rock_Ice_Permafrost"
    },
    {
      "x": -22,
      "y": 23,
      "z": -15,
      "name": "Rock_Ice_Permafrost"
    },
    {
      "x": -22,
      "y": 24,
      "z": -15,
      "name": "Rock_Ice_Permafrost"
    },
    {
      "x": -22,
      "y": 25,
      "z": -15,
      "name": "Rock_Ice"
    },
    {
      "x": -22,
      "y": 26,
      "z": -15,
      "name": "Rock_Ice"
    },
    {
      "x": -22,
      "y": 27,
      "z": -15,
      "name": "Rock_Ice"
    },
    {
      "x": -22,
      "y": 28,
      "z": -15,
      "name": "Rock_Ice"
    },
    {
      "x": -22,
      "y": 29,
      "z": -15,
      "name": "Rock_Ice"
    },
    {
      "x": -22,
      "y": 30,
      "z": -15,
      "name": "Rock_Ice"
    },
    {
      "x": -22,
      "y": 31,
      "z": -15,
      "name": "Rock_Ice"
    },
    {
      "x": -22,
      "y": 32,
      "z": -15,
      "name": "Rock_Ice"
    },
    {
      "x": -22,
      "y": 33,
      "z": -15,
      "name": "Rock_Ice"
    },
    {
      "x": -22,
      "y": 34,
      "z": -15,
      "name": "Soil_Snow"
    },
    {
      "x": -22,
      "y": 10,
      "z": -14,
      "name": "Rock_Ice"
    },
    {
      "x": -22,
      "y": 11,
      "z": -14,
      "name": "Rock_Ice"
    },
    {
      "x": -22,
      "y": 12,
      "z": -14,
      "name": "Rock_Ice"
    },
    {
      "x": -22,
      "y": 13,
      "z": -14,
      "name": "Rock_Ice"
    },
    {
      "x": -22,
      "y": 14,
      "z": -14,
      "name": "Rock_Ice"
    },
    {
      "x": -22,
      "y": 15,
      "z": -14,
      "name": "Rock_Ice"
    },
    {
      "x": -22,
      "y": 16,
      "z": -14,
      "name": "Rock_Ice"
    },
    {
      "x": -22,
      "y": 17,
      "z": -14,
      "name": "Rock_Ice"
    },
    {
      "x": -22,
      "y": 18,
      "z": -14,
      "name": "Rock_Ice"
    },
    {
      "x": -22,
      "y": 19,
      "z": -14,
      "name": "Rock_Ice_Permafrost"
    },
    {
      "x": -22,
      "y": 20,
      "z": -14,
      "name": "Rock_Ice_Permafrost"
    },
    {
      "x": -22,
      "y": 21,
      "z": -14,
      "name": "Rock_Ice_Permafrost"
    },
    {
      "x": -22,
      "y": 22,
      "z": -14,
      "name": "Rock_Ice_Permafrost"
    },
    {
      "x": -22,
      "y": 23,
      "z": -14,
      "name": "Rock_Ice"
    },
    {
      "x": -22,
      "y": 24,
      "z": -14,
      "name": "Rock_Ice_Permafrost"
    },
    {
      "x": -22,
      "y": 25,
      "z": -14,
      "name": "Rock_Ice"
    },
    {
      "x": -22,
      "y": 26,
      "z": -14,
      "name": "Rock_Ice"
    },
    {
      "x": -22,
      "y": 27,
      "z": -14,
      "name": "Rock_Ice_Permafrost"
    },
    {
      "x": -22,
      "y": 28,
      "z": -14,
      "name": "Rock_Ice"
    },
    {
      "x": -22,
      "y": 29,
      "z": -14,
      "name": "Rock_Ice"
    },
    {
      "x": -22,
      "y": 30,
      "z": -14,
      "name": "Rock_Ice"
    },
    {
      "x": -22,
      "y": 31,
      "z": -14,
      "name": "Rock_Ice"
    },
    {
      "x": -22,
      "y": 32,
      "z": -14,
      "name": "Rock_Ice"
    },
    {
      "x": -22,
      "y": 33,
      "z": -14,
      "name": "Rock_Ice"
    },
    {
      "x": -22,
      "y": 34,
      "z": -14,
      "name": "Soil_Snow"
    },
    {
      "x": -22,
      "y": 9,
      "z": -13,
      "name": "Rock_Ice"
    },
    {
      "x": -22,
      "y": 10,
      "z": -13,
      "name": "Rock_Ice"
    },
    {
      "x": -22,
      "y": 11,
      "z": -13,
      "name": "Rock_Ice"
    },
    {
      "x": -22,
      "y": 12,
      "z": -13,
      "name": "Rock_Ice"
    },
    {
      "x": -22,
      "y": 13,
      "z": -13,
      "name": "Rock_Ice"
    },
    {
      "x": -22,
      "y": 14,
      "z": -13,
      "name": "Rock_Ice"
    },
    {
      "x": -22,
      "y": 15,
      "z": -13,
      "name": "Rock_Ice"
    },
    {
      "x": -22,
      "y": 16,
      "z": -13,
      "name": "Rock_Ice"
    },
    {
      "x": -22,
      "y": 17,
      "z": -13,
      "name": "Rock_Ice_Permafrost"
    },
    {
      "x": -22,
      "y": 18,
      "z": -13,
      "name": "Rock_Ice_Permafrost"
    },
    {
      "x": -22,
      "y": 19,
      "z": -13,
      "name": "Rock_Ice_Permafrost"
    },
    {
      "x": -22,
      "y": 20,
      "z": -13,
      "name": "Rock_Ice_Permafrost"
    },
    {
      "x": -22,
      "y": 21,
      "z": -13,
      "name": "Rock_Ice_Permafrost"
    },
    {
      "x": -22,
      "y": 22,
      "z": -13,
      "name": "Rock_Ice_Permafrost"
    },
    {
      "x": -22,
      "y": 23,
      "z": -13,
      "name": "Rock_Ice_Permafrost"
    },
    {
      "x": -22,
      "y": 24,
      "z": -13,
      "name": "Rock_Ice_Permafrost"
    },
    {
      "x": -22,
      "y": 25,
      "z": -13,
      "name": "Rock_Ice"
    },
    {
      "x": -22,
      "y": 26,
      "z": -13,
      "name": "Rock_Ice"
    },
    {
      "x": -22,
      "y": 27,
      "z": -13,
      "name": "Rock_Ice"
    },
    {
      "x": -22,
      "y": 28,
      "z": -13,
      "name": "Rock_Ice"
    },
    {
      "x": -22,
      "y": 29,
      "z": -13,
      "name": "Rock_Ice"
    },
    {
      "x": -22,
      "y": 30,
      "z": -13,
      "name": "Rock_Ice"
    },
    {
      "x": -22,
      "y": 31,
      "z": -13,
      "name": "Rock_Ice"
    },
    {
      "x": -22,
      "y": 32,
      "z": -13,
      "name": "Rock_Ice"
    },
    {
      "x": -22,
      "y": 33,
      "z": -13,
      "name": "Rock_Ice"
    },
    {
      "x": -22,
      "y": 34,
      "z": -13,
      "name": "Soil_Snow"
    },
    {
      "x": -22,
      "y": 9,
      "z": -12,
      "name": "Rock_Ice"
    },
    {
      "x": -22,
      "y": 10,
      "z": -12,
      "name": "Rock_Ice"
    },
    {
      "x": -22,
      "y": 11,
      "z": -12,
      "name": "Rock_Ice"
    },
    {
      "x": -22,
      "y": 12,
      "z": -12,
      "name": "Rock_Ice"
    },
    {
      "x": -22,
      "y": 13,
      "z": -12,
      "name": "Rock_Ice"
    },
    {
      "x": -22,
      "y": 14,
      "z": -12,
      "name": "Rock_Ice"
    },
    {
      "x": -22,
      "y": 15,
      "z": -12,
      "name": "Rock_Ice"
    },
    {
      "x": -22,
      "y": 16,
      "z": -12,
      "name": "Rock_Ice_Permafrost"
    },
    {
      "x": -22,
      "y": 17,
      "z": -12,
      "name": "Rock_Ice_Permafrost"
    },
    {
      "x": -22,
      "y": 18,
      "z": -12,
      "name": "Rock_Ice_Permafrost"
    },
    {
      "x": -22,
      "y": 19,
      "z": -12,
      "name": "Rock_Ice_Permafrost"
    },
    {
      "x": -22,
      "y": 20,
      "z": -12,
      "name": "Rock_Ice_Permafrost"
    },
    {
      "x": -22,
      "y": 21,
      "z": -12,
      "name": "Rock_Ice_Permafrost"
    },
    {
      "x": -22,
      "y": 22,
      "z": -12,
      "name": "Rock_Ice"
    },
    {
      "x": -22,
      "y": 23,
      "z": -12,
      "name": "Rock_Ice_Permafrost"
    },
    {
      "x": -22,
      "y": 24,
      "z": -12,
      "name": "Rock_Ice_Permafrost"
    },
    {
      "x": -22,
      "y": 25,
      "z": -12,
      "name": "Rock_Ice"
    },
    {
      "x": -22,
      "y": 26,
      "z": -12,
      "name": "Rock_Ice"
    },
    {
      "x": -22,
      "y": 27,
      "z": -12,
      "name": "Rock_Ice_Permafrost"
    },
    {
      "x": -22,
      "y": 28,
      "z": -12,
      "name": "Rock_Ice"
    },
    {
      "x": -22,
      "y": 29,
      "z": -12,
      "name": "Rock_Ice"
    },
    {
      "x": -22,
      "y": 30,
      "z": -12,
      "name": "Rock_Ice"
    },
    {
      "x": -22,
      "y": 31,
      "z": -12,
      "name": "Rock_Ice"
    },
    {
      "x": -22,
      "y": 32,
      "z": -12,
      "name": "Rock_Ice"
    },
    {
      "x": -22,
      "y": 33,
      "z": -12,
      "name": "Rock_Ice"
    },
    {
      "x": -22,
      "y": 34,
      "z": -12,
      "name": "Soil_Snow"
    },
    {
      "x": -22,
      "y": 9,
      "z": -11,
      "name": "Rock_Ice"
    },
    {
      "x": -22,
      "y": 10,
      "z": -11,
      "name": "Rock_Ice"
    },
    {
      "x": -22,
      "y": 11,
      "z": -11,
      "name": "Rock_Ice"
    },
    {
      "x": -22,
      "y": 12,
      "z": -11,
      "name": "Rock_Ice"
    },
    {
      "x": -22,
      "y": 13,
      "z": -11,
      "name": "Rock_Ice"
    },
    {
      "x": -22,
      "y": 14,
      "z": -11,
      "name": "Rock_Ice"
    },
    {
      "x": -22,
      "y": 15,
      "z": -11,
      "name": "Rock_Ice"
    },
    {
      "x": -22,
      "y": 16,
      "z": -11,
      "name": "Rock_Ice_Permafrost"
    },
    {
      "x": -22,
      "y": 17,
      "z": -11,
      "name": "Rock_Ice_Permafrost"
    },
    {
      "x": -22,
      "y": 18,
      "z": -11,
      "name": "Rock_Ice_Permafrost"
    },
    {
      "x": -22,
      "y": 19,
      "z": -11,
      "name": "Rock_Ice_Permafrost"
    },
    {
      "x": -22,
      "y": 20,
      "z": -11,
      "name": "Rock_Ice_Permafrost"
    },
    {
      "x": -22,
      "y": 21,
      "z": -11,
      "name": "Rock_Ice_Permafrost"
    },
    {
      "x": -22,
      "y": 22,
      "z": -11,
      "name": "Rock_Ice_Permafrost"
    },
    {
      "x": -22,
      "y": 23,
      "z": -11,
      "name": "Rock_Ice_Permafrost"
    },
    {
      "x": -22,
      "y": 24,
      "z": -11,
      "name": "Rock_Ice_Permafrost"
    },
    {
      "x": -22,
      "y": 25,
      "z": -11,
      "name": "Rock_Ice"
    },
    {
      "x": -22,
      "y": 26,
      "z": -11,
      "name": "Rock_Ice"
    },
    {
      "x": -22,
      "y": 27,
      "z": -11,
      "name": "Rock_Ice"
    },
    {
      "x": -22,
      "y": 28,
      "z": -11,
      "name": "Rock_Ice_Permafrost"
    },
    {
      "x": -22,
      "y": 29,
      "z": -11,
      "name": "Rock_Ice"
    },
    {
      "x": -22,
      "y": 30,
      "z": -11,
      "name": "Rock_Ice"
    },
    {
      "x": -22,
      "y": 31,
      "z": -11,
      "name": "Rock_Ice"
    },
    {
      "x": -22,
      "y": 32,
      "z": -11,
      "name": "Rock_Ice"
    },
    {
      "x": -22,
      "y": 33,
      "z": -11,
      "name": "Rock_Ice"
    },
    {
      "x": -22,
      "y": 34,
      "z": -11,
      "name": "Soil_Snow"
    },
    {
      "x": -22,
      "y": 9,
      "z": -10,
      "name": "Rock_Ice"
    },
    {
      "x": -22,
      "y": 10,
      "z": -10,
      "name": "Rock_Ice"
    },
    {
      "x": -22,
      "y": 11,
      "z": -10,
      "name": "Rock_Ice"
    },
    {
      "x": -22,
      "y": 12,
      "z": -10,
      "name": "Rock_Ice"
    },
    {
      "x": -22,
      "y": 13,
      "z": -10,
      "name": "Rock_Ice"
    },
    {
      "x": -22,
      "y": 14,
      "z": -10,
      "name": "Rock_Ice_Permafrost"
    },
    {
      "x": -22,
      "y": 15,
      "z": -10,
      "name": "Rock_Ice_Permafrost"
    },
    {
      "x": -22,
      "y": 16,
      "z": -10,
      "name": "Rock_Ice_Permafrost"
    },
    {
      "x": -22,
      "y": 17,
      "z": -10,
      "name": "Rock_Ice_Permafrost"
    },
    {
      "x": -22,
      "y": 18,
      "z": -10,
      "name": "Rock_Ice_Permafrost"
    },
    {
      "x": -22,
      "y": 19,
      "z": -10,
      "name": "Rock_Ice_Permafrost"
    },
    {
      "x": -22,
      "y": 20,
      "z": -10,
      "name": "Rock_Ice_Permafrost"
    },
    {
      "x": -22,
      "y": 21,
      "z": -10,
      "name": "Rock_Ice_Permafrost"
    },
    {
      "x": -22,
      "y": 22,
      "z": -10,
      "name": "Rock_Ice"
    },
    {
      "x": -22,
      "y": 23,
      "z": -10,
      "name": "Rock_Ice_Permafrost"
    },
    {
      "x": -22,
      "y": 24,
      "z": -10,
      "name": "Rock_Ice_Permafrost"
    },
    {
      "x": -22,
      "y": 25,
      "z": -10,
      "name": "Rock_Ice_Permafrost"
    },
    {
      "x": -22,
      "y": 26,
      "z": -10,
      "name": "Rock_Ice"
    },
    {
      "x": -22,
      "y": 27,
      "z": -10,
      "name": "Rock_Ice"
    },
    {
      "x": -22,
      "y": 28,
      "z": -10,
      "name": "Rock_Ice"
    },
    {
      "x": -22,
      "y": 29,
      "z": -10,
      "name": "Rock_Ice"
    },
    {
      "x": -22,
      "y": 30,
      "z": -10,
      "name": "Rock_Ice"
    },
    {
      "x": -22,
      "y": 31,
      "z": -10,
      "name": "Rock_Ice"
    },
    {
      "x": -22,
      "y": 32,
      "z": -10,
      "name": "Rock_Ice"
    },
    {
      "x": -22,
      "y": 33,
      "z": -10,
      "name": "Soil_Snow"
    },
    {
      "x": -22,
      "y": 9,
      "z": -9,
      "name": "Rock_Ice"
    },
    {
      "x": -22,
      "y": 10,
      "z": -9,
      "name": "Rock_Ice_Permafrost"
    },
    {
      "x": -22,
      "y": 11,
      "z": -9,
      "name": "Rock_Ice"
    },
    {
      "x": -22,
      "y": 12,
      "z": -9,
      "name": "Rock_Ice"
    },
    {
      "x": -22,
      "y": 13,
      "z": -9,
      "name": "Rock_Ice"
    },
    {
      "x": -22,
      "y": 14,
      "z": -9,
      "name": "Rock_Ice_Permafrost"
    },
    {
      "x": -22,
      "y": 15,
      "z": -9,
      "name": "Rock_Ice_Permafrost"
    },
    {
      "x": -22,
      "y": 16,
      "z": -9,
      "name": "Rock_Ice_Permafrost"
    },
    {
      "x": -22,
      "y": 17,
      "z": -9,
      "name": "Rock_Ice_Permafrost"
    },
    {
      "x": -22,
      "y": 18,
      "z": -9,
      "name": "Rock_Ice_Permafrost"
    },
    {
      "x": -22,
      "y": 19,
      "z": -9,
      "name": "Rock_Ice_Permafrost"
    },
    {
      "x": -22,
      "y": 20,
      "z": -9,
      "name": "Rock_Ice_Permafrost"
    },
    {
      "x": -22,
      "y": 21,
      "z": -9,
      "name": "Rock_Ice_Permafrost"
    },
    {
      "x": -22,
      "y": 22,
      "z": -9,
      "name": "Rock_Ice_Permafrost"
    },
    {
      "x": -22,
      "y": 23,
      "z": -9,
      "name": "Rock_Ice_Permafrost"
    },
    {
      "x": -22,
      "y": 24,
      "z": -9,
      "name": "Rock_Ice_Permafrost"
    },
    {
      "x": -22,
      "y": 25,
      "z": -9,
      "name": "Rock_Ice_Permafrost"
    },
    {
      "x": -22,
      "y": 26,
      "z": -9,
      "name": "Rock_Ice"
    },
    {
      "x": -22,
      "y": 27,
      "z": -9,
      "name": "Rock_Ice"
    },
    {
      "x": -22,
      "y": 28,
      "z": -9,
      "name": "Rock_Ice_Permafrost"
    },
    {
      "x": -22,
      "y": 29,
      "z": -9,
      "name": "Rock_Ice"
    },
    {
      "x": -22,
      "y": 30,
      "z": -9,
      "name": "Rock_Ice"
    },
    {
      "x": -22,
      "y": 31,
      "z": -9,
      "name": "Rock_Ice"
    },
    {
      "x": -22,
      "y": 32,
      "z": -9,
      "name": "Rock_Ice"
    },
    {
      "x": -22,
      "y": 33,
      "z": -9,
      "name": "Soil_Snow"
    },
    {
      "x": -22,
      "y": 10,
      "z": -8,
      "name": "Rock_Ice_Permafrost"
    },
    {
      "x": -22,
      "y": 11,
      "z": -8,
      "name": "Rock_Ice_Permafrost"
    },
    {
      "x": -22,
      "y": 12,
      "z": -8,
      "name": "Rock_Ice_Permafrost"
    },
    {
      "x": -22,
      "y": 13,
      "z": -8,
      "name": "Rock_Ice_Permafrost"
    },
    {
      "x": -22,
      "y": 14,
      "z": -8,
      "name": "Rock_Ice_Permafrost"
    },
    {
      "x": -22,
      "y": 15,
      "z": -8,
      "name": "Rock_Ice_Permafrost"
    },
    {
      "x": -22,
      "y": 16,
      "z": -8,
      "name": "Rock_Ice_Permafrost"
    },
    {
      "x": -22,
      "y": 17,
      "z": -8,
      "name": "Rock_Ice_Permafrost"
    },
    {
      "x": -22,
      "y": 18,
      "z": -8,
      "name": "Rock_Ice_Permafrost"
    },
    {
      "x": -22,
      "y": 19,
      "z": -8,
      "name": "Rock_Ice_Permafrost"
    },
    {
      "x": -22,
      "y": 20,
      "z": -8,
      "name": "Rock_Ice_Permafrost"
    },
    {
      "x": -22,
      "y": 21,
      "z": -8,
      "name": "Rock_Ice_Permafrost"
    },
    {
      "x": -22,
      "y": 22,
      "z": -8,
      "name": "Rock_Ice_Permafrost"
    },
    {
      "x": -22,
      "y": 23,
      "z": -8,
      "name": "Rock_Ice_Permafrost"
    },
    {
      "x": -22,
      "y": 24,
      "z": -8,
      "name": "Rock_Ice_Permafrost"
    },
    {
      "x": -22,
      "y": 25,
      "z": -8,
      "name": "Rock_Ice_Permafrost"
    },
    {
      "x": -22,
      "y": 27,
      "z": -8,
      "name": "Rock_Ice_Permafrost"
    },
    {
      "x": -22,
      "y": 28,
      "z": -8,
      "name": "Rock_Ice"
    },
    {
      "x": -22,
      "y": 29,
      "z": -8,
      "name": "Rock_Ice_Permafrost"
    },
    {
      "x": -22,
      "y": 30,
      "z": -8,
      "name": "Rock_Ice"
    },
    {
      "x": -22,
      "y": 31,
      "z": -8,
      "name": "Rock_Ice"
    },
    {
      "x": -22,
      "y": 32,
      "z": -8,
      "name": "Rock_Ice_Permafrost"
    },
    {
      "x": -22,
      "y": 33,
      "z": -8,
      "name": "Soil_Snow"
    },
    {
      "x": -22,
      "y": 10,
      "z": -7,
      "name": "Rock_Ice_Permafrost"
    },
    {
      "x": -22,
      "y": 11,
      "z": -7,
      "name": "Rock_Ice_Permafrost"
    },
    {
      "x": -22,
      "y": 12,
      "z": -7,
      "name": "Rock_Ice"
    },
    {
      "x": -22,
      "y": 13,
      "z": -7,
      "name": "Rock_Ice_Permafrost"
    },
    {
      "x": -22,
      "y": 14,
      "z": -7,
      "name": "Rock_Ice_Permafrost"
    },
    {
      "x": -22,
      "y": 15,
      "z": -7,
      "name": "Rock_Ice_Permafrost"
    },
    {
      "x": -22,
      "y": 16,
      "z": -7,
      "name": "Rock_Ice_Permafrost"
    },
    {
      "x": -22,
      "y": 17,
      "z": -7,
      "name": "Rock_Ice_Permafrost"
    },
    {
      "x": -22,
      "y": 18,
      "z": -7,
      "name": "Rock_Ice_Permafrost"
    },
    {
      "x": -22,
      "y": 19,
      "z": -7,
      "name": "Rock_Ice_Permafrost"
    },
    {
      "x": -22,
      "y": 20,
      "z": -7,
      "name": "Rock_Ice_Permafrost"
    },
    {
      "x": -22,
      "y": 21,
      "z": -7,
      "name": "Rock_Ice_Permafrost"
    },
    {
      "x": -22,
      "y": 22,
      "z": -7,
      "name": "Rock_Ice_Permafrost"
    },
    {
      "x": -22,
      "y": 31,
      "z": -7,
      "name": "Rock_Ice"
    },
    {
      "x": -22,
      "y": 32,
      "z": -7,
      "name": "Soil_Snow"
    },
    {
      "x": -22,
      "y": 11,
      "z": -6,
      "name": "Rock_Ice_Permafrost"
    },
    {
      "x": -22,
      "y": 12,
      "z": -6,
      "name": "Rock_Ice_Permafrost"
    },
    {
      "x": -22,
      "y": 13,
      "z": -6,
      "name": "Rock_Ice_Permafrost"
    },
    {
      "x": -22,
      "y": 14,
      "z": -6,
      "name": "Rock_Ice_Permafrost"
    },
    {
      "x": -22,
      "y": 15,
      "z": -6,
      "name": "Rock_Ice_Permafrost"
    },
    {
      "x": -22,
      "y": 16,
      "z": -6,
      "name": "Rock_Ice_Permafrost"
    },
    {
      "x": -22,
      "y": 17,
      "z": -6,
      "name": "Rock_Ice_Permafrost"
    },
    {
      "x": -22,
      "y": 18,
      "z": -6,
      "name": "Rock_Ice_Permafrost"
    },
    {
      "x": -22,
      "y": 19,
      "z": -6,
      "name": "Rock_Ice_Permafrost"
    },
    {
      "x": -22,
      "y": 20,
      "z": -6,
      "name": "Soil_Snow"
    },
    {
      "x": -22,
      "y": 12,
      "z": -5,
      "name": "Rock_Ice_Permafrost"
    },
    {
      "x": -22,
      "y": 13,
      "z": -5,
      "name": "Rock_Ice_Permafrost"
    },
    {
      "x": -22,
      "y": 14,
      "z": -5,
      "name": "Rock_Ice_Permafrost"
    },
    {
      "x": -22,
      "y": 15,
      "z": -5,
      "name": "Rock_Ice_Permafrost"
    },
    {
      "x": -22,
      "y": 16,
      "z": -5,
      "name": "Rock_Ice_Permafrost"
    },
    {
      "x": -22,
      "y": 17,
      "z": -5,
      "name": "Soil_Snow"
    },
    {
      "x": -21,
      "y": 24,
      "z": -23,
      "name": "Rock_Ice"
    },
    {
      "x": -21,
      "y": 25,
      "z": -23,
      "name": "Rock_Ice"
    },
    {
      "x": -21,
      "y": 26,
      "z": -23,
      "name": "Rock_Ice"
    },
    {
      "x": -21,
      "y": 27,
      "z": -23,
      "name": "Soil_Snow"
    },
    {
      "x": -21,
      "y": 22,
      "z": -22,
      "name": "Rock_Ice"
    },
    {
      "x": -21,
      "y": 23,
      "z": -22,
      "name": "Rock_Ice"
    },
    {
      "x": -21,
      "y": 24,
      "z": -22,
      "name": "Rock_Ice"
    },
    {
      "x": -21,
      "y": 25,
      "z": -22,
      "name": "Rock_Ice"
    },
    {
      "x": -21,
      "y": 26,
      "z": -22,
      "name": "Rock_Ice"
    },
    {
      "x": -21,
      "y": 27,
      "z": -22,
      "name": "Rock_Ice"
    },
    {
      "x": -21,
      "y": 28,
      "z": -22,
      "name": "Rock_Ice"
    },
    {
      "x": -21,
      "y": 29,
      "z": -22,
      "name": "Soil_Snow"
    },
    {
      "x": -21,
      "y": 21,
      "z": -21,
      "name": "Rock_Ice"
    },
    {
      "x": -21,
      "y": 22,
      "z": -21,
      "name": "Rock_Ice"
    },
    {
      "x": -21,
      "y": 23,
      "z": -21,
      "name": "Rock_Ice"
    },
    {
      "x": -21,
      "y": 24,
      "z": -21,
      "name": "Rock_Ice"
    },
    {
      "x": -21,
      "y": 25,
      "z": -21,
      "name": "Rock_Ice"
    },
    {
      "x": -21,
      "y": 26,
      "z": -21,
      "name": "Rock_Ice"
    },
    {
      "x": -21,
      "y": 27,
      "z": -21,
      "name": "Rock_Ice"
    },
    {
      "x": -21,
      "y": 28,
      "z": -21,
      "name": "Rock_Ice"
    },
    {
      "x": -21,
      "y": 29,
      "z": -21,
      "name": "Rock_Ice_Permafrost"
    },
    {
      "x": -21,
      "y": 30,
      "z": -21,
      "name": "Rock_Ice"
    },
    {
      "x": -21,
      "y": 31,
      "z": -21,
      "name": "Soil_Snow"
    },
    {
      "x": -21,
      "y": 19,
      "z": -20,
      "name": "Rock_Ice"
    },
    {
      "x": -21,
      "y": 20,
      "z": -20,
      "name": "Rock_Ice"
    },
    {
      "x": -21,
      "y": 21,
      "z": -20,
      "name": "Rock_Ice"
    },
    {
      "x": -21,
      "y": 22,
      "z": -20,
      "name": "Rock_Ice"
    },
    {
      "x": -21,
      "y": 23,
      "z": -20,
      "name": "Rock_Ice"
    },
    {
      "x": -21,
      "y": 24,
      "z": -20,
      "name": "Rock_Ice"
    },
    {
      "x": -21,
      "y": 25,
      "z": -20,
      "name": "Rock_Ice"
    },
    {
      "x": -21,
      "y": 26,
      "z": -20,
      "name": "Rock_Ice"
    },
    {
      "x": -21,
      "y": 27,
      "z": -20,
      "name": "Rock_Ice_Permafrost"
    },
    {
      "x": -21,
      "y": 28,
      "z": -20,
      "name": "Rock_Ice_Permafrost"
    },
    {
      "x": -21,
      "y": 29,
      "z": -20,
      "name": "Rock_Ice"
    },
    {
      "x": -21,
      "y": 30,
      "z": -20,
      "name": "Rock_Ice"
    },
    {
      "x": -21,
      "y": 31,
      "z": -20,
      "name": "Rock_Ice"
    },
    {
      "x": -21,
      "y": 32,
      "z": -20,
      "name": "Soil_Snow"
    },
    {
      "x": -21,
      "y": 18,
      "z": -19,
      "name": "Rock_Ice"
    },
    {
      "x": -21,
      "y": 19,
      "z": -19,
      "name": "Rock_Ice"
    },
    {
      "x": -21,
      "y": 20,
      "z": -19,
      "name": "Rock_Ice"
    },
    {
      "x": -21,
      "y": 21,
      "z": -19,
      "name": "Rock_Ice"
    },
    {
      "x": -21,
      "y": 22,
      "z": -19,
      "name": "Rock_Ice"
    },
    {
      "x": -21,
      "y": 23,
      "z": -19,
      "name": "Rock_Ice"
    },
    {
      "x": -21,
      "y": 24,
      "z": -19,
      "name": "Rock_Ice"
    },
    {
      "x": -21,
      "y": 25,
      "z": -19,
      "name": "Rock_Ice_Permafrost"
    },
    {
      "x": -21,
      "y": 26,
      "z": -19,
      "name": "Rock_Ice"
    },
    {
      "x": -21,
      "y": 27,
      "z": -19,
      "name": "Rock_Ice"
    },
    {
      "x": -21,
      "y": 28,
      "z": -19,
      "name": "Rock_Ice_Permafrost"
    },
    {
      "x": -21,
      "y": 29,
      "z": -19,
      "name": "Rock_Ice"
    },
    {
      "x": -21,
      "y": 30,
      "z": -19,
      "name": "Rock_Ice"
    },
    {
      "x": -21,
      "y": 31,
      "z": -19,
      "name": "Rock_Ice"
    },
    {
      "x": -21,
      "y": 32,
      "z": -19,
      "name": "Rock_Ice"
    },
    {
      "x": -21,
      "y": 33,
      "z": -19,
      "name": "Rock_Ice"
    },
    {
      "x": -21,
      "y": 16,
      "z": -18,
      "name": "Rock_Ice"
    },
    {
      "x": -21,
      "y": 17,
      "z": -18,
      "name": "Rock_Ice"
    },
    {
      "x": -21,
      "y": 18,
      "z": -18,
      "name": "Rock_Ice"
    },
    {
      "x": -21,
      "y": 19,
      "z": -18,
      "name": "Rock_Ice"
    },
    {
      "x": -21,
      "y": 20,
      "z": -18,
      "name": "Rock_Ice"
    },
    {
      "x": -21,
      "y": 21,
      "z": -18,
      "name": "Rock_Ice"
    },
    {
      "x": -21,
      "y": 22,
      "z": -18,
      "name": "Rock_Ice"
    },
    {
      "x": -21,
      "y": 23,
      "z": -18,
      "name": "Rock_Ice"
    },
    {
      "x": -21,
      "y": 24,
      "z": -18,
      "name": "Rock_Ice"
    },
    {
      "x": -21,
      "y": 25,
      "z": -18,
      "name": "Rock_Ice"
    },
    {
      "x": -21,
      "y": 26,
      "z": -18,
      "name": "Rock_Ice"
    },
    {
      "x": -21,
      "y": 27,
      "z": -18,
      "name": "Rock_Ice"
    },
    {
      "x": -21,
      "y": 28,
      "z": -18,
      "name": "Rock_Ice"
    },
    {
      "x": -21,
      "y": 29,
      "z": -18,
      "name": "Rock_Ice"
    },
    {
      "x": -21,
      "y": 30,
      "z": -18,
      "name": "Rock_Ice"
    },
    {
      "x": -21,
      "y": 31,
      "z": -18,
      "name": "Rock_Ice"
    },
    {
      "x": -21,
      "y": 32,
      "z": -18,
      "name": "Rock_Ice"
    },
    {
      "x": -21,
      "y": 33,
      "z": -18,
      "name": "Rock_Ice"
    },
    {
      "x": -21,
      "y": 34,
      "z": -18,
      "name": "Soil_Snow"
    },
    {
      "x": -21,
      "y": 14,
      "z": -17,
      "name": "Rock_Ice"
    },
    {
      "x": -21,
      "y": 15,
      "z": -17,
      "name": "Rock_Ice"
    },
    {
      "x": -21,
      "y": 16,
      "z": -17,
      "name": "Rock_Ice"
    },
    {
      "x": -21,
      "y": 17,
      "z": -17,
      "name": "Rock_Ice"
    },
    {
      "x": -21,
      "y": 18,
      "z": -17,
      "name": "Rock_Ice"
    },
    {
      "x": -21,
      "y": 19,
      "z": -17,
      "name": "Rock_Ice"
    },
    {
      "x": -21,
      "y": 20,
      "z": -17,
      "name": "Rock_Ice_Permafrost"
    },
    {
      "x": -21,
      "y": 21,
      "z": -17,
      "name": "Rock_Ice"
    },
    {
      "x": -21,
      "y": 22,
      "z": -17,
      "name": "Rock_Ice_Permafrost"
    },
    {
      "x": -21,
      "y": 23,
      "z": -17,
      "name": "Rock_Ice"
    },
    {
      "x": -21,
      "y": 24,
      "z": -17,
      "name": "Rock_Ice"
    },
    {
      "x": -21,
      "y": 25,
      "z": -17,
      "name": "Rock_Ice_Permafrost"
    },
    {
      "x": -21,
      "y": 26,
      "z": -17,
      "name": "Rock_Ice_Permafrost"
    },
    {
      "x": -21,
      "y": 27,
      "z": -17,
      "name": "Rock_Ice"
    },
    {
      "x": -21,
      "y": 28,
      "z": -17,
      "name": "Rock_Ice"
    },
    {
      "x": -21,
      "y": 29,
      "z": -17,
      "name": "Rock_Ice"
    },
    {
      "x": -21,
      "y": 30,
      "z": -17,
      "name": "Rock_Ice"
    },
    {
      "x": -21,
      "y": 31,
      "z": -17,
      "name": "Rock_Ice"
    },
    {
      "x": -21,
      "y": 32,
      "z": -17,
      "name": "Rock_Ice"
    },
    {
      "x": -21,
      "y": 33,
      "z": -17,
      "name": "Rock_Ice"
    },
    {
      "x": -21,
      "y": 34,
      "z": -17,
      "name": "Rock_Ice"
    },
    {
      "x": -21,
      "y": 35,
      "z": -17,
      "name": "Soil_Snow"
    },
    {
      "x": -21,
      "y": 12,
      "z": -16,
      "name": "Rock_Ice"
    },
    {
      "x": -21,
      "y": 13,
      "z": -16,
      "name": "Rock_Ice"
    },
    {
      "x": -21,
      "y": 14,
      "z": -16,
      "name": "Rock_Ice"
    },
    {
      "x": -21,
      "y": 15,
      "z": -16,
      "name": "Rock_Ice"
    },
    {
      "x": -21,
      "y": 16,
      "z": -16,
      "name": "Rock_Ice"
    },
    {
      "x": -21,
      "y": 17,
      "z": -16,
      "name": "Rock_Ice"
    },
    {
      "x": -21,
      "y": 18,
      "z": -16,
      "name": "Rock_Ice"
    },
    {
      "x": -21,
      "y": 19,
      "z": -16,
      "name": "Rock_Ice"
    },
    {
      "x": -21,
      "y": 20,
      "z": -16,
      "name": "Rock_Ice_Permafrost"
    },
    {
      "x": -21,
      "y": 21,
      "z": -16,
      "name": "Rock_Ice_Permafrost"
    },
    {
      "x": -21,
      "y": 22,
      "z": -16,
      "name": "Rock_Ice_Permafrost"
    },
    {
      "x": -21,
      "y": 23,
      "z": -16,
      "name": "Rock_Ice_Permafrost"
    },
    {
      "x": -21,
      "y": 24,
      "z": -16,
      "name": "Rock_Ice_Permafrost"
    },
    {
      "x": -21,
      "y": 25,
      "z": -16,
      "name": "Rock_Ice_Permafrost"
    },
    {
      "x": -21,
      "y": 26,
      "z": -16,
      "name": "Rock_Ice"
    },
    {
      "x": -21,
      "y": 27,
      "z": -16,
      "name": "Rock_Ice"
    },
    {
      "x": -21,
      "y": 28,
      "z": -16,
      "name": "Rock_Ice"
    },
    {
      "x": -21,
      "y": 29,
      "z": -16,
      "name": "Rock_Ice"
    },
    {
      "x": -21,
      "y": 30,
      "z": -16,
      "name": "Rock_Ice"
    },
    {
      "x": -21,
      "y": 31,
      "z": -16,
      "name": "Rock_Ice"
    },
    {
      "x": -21,
      "y": 32,
      "z": -16,
      "name": "Rock_Ice"
    },
    {
      "x": -21,
      "y": 33,
      "z": -16,
      "name": "Rock_Ice"
    },
    {
      "x": -21,
      "y": 34,
      "z": -16,
      "name": "Rock_Ice"
    },
    {
      "x": -21,
      "y": 35,
      "z": -16,
      "name": "Soil_Snow"
    },
    {
      "x": -21,
      "y": 10,
      "z": -15,
      "name": "Rock_Ice"
    },
    {
      "x": -21,
      "y": 11,
      "z": -15,
      "name": "Rock_Ice"
    },
    {
      "x": -21,
      "y": 12,
      "z": -15,
      "name": "Rock_Ice"
    },
    {
      "x": -21,
      "y": 13,
      "z": -15,
      "name": "Rock_Ice"
    },
    {
      "x": -21,
      "y": 14,
      "z": -15,
      "name": "Rock_Ice"
    },
    {
      "x": -21,
      "y": 15,
      "z": -15,
      "name": "Rock_Ice"
    },
    {
      "x": -21,
      "y": 16,
      "z": -15,
      "name": "Rock_Ice"
    },
    {
      "x": -21,
      "y": 17,
      "z": -15,
      "name": "Rock_Ice"
    },
    {
      "x": -21,
      "y": 18,
      "z": -15,
      "name": "Rock_Ice"
    },
    {
      "x": -21,
      "y": 19,
      "z": -15,
      "name": "Rock_Ice_Permafrost"
    },
    {
      "x": -21,
      "y": 20,
      "z": -15,
      "name": "Rock_Ice_Permafrost"
    },
    {
      "x": -21,
      "y": 21,
      "z": -15,
      "name": "Rock_Ice_Permafrost"
    },
    {
      "x": -21,
      "y": 22,
      "z": -15,
      "name": "Rock_Ice_Permafrost"
    },
    {
      "x": -21,
      "y": 23,
      "z": -15,
      "name": "Rock_Ice_Permafrost"
    },
    {
      "x": -21,
      "y": 24,
      "z": -15,
      "name": "Rock_Ice_Permafrost"
    },
    {
      "x": -21,
      "y": 25,
      "z": -15,
      "name": "Rock_Ice"
    },
    {
      "x": -21,
      "y": 26,
      "z": -15,
      "name": "Rock_Ice"
    },
    {
      "x": -21,
      "y": 27,
      "z": -15,
      "name": "Rock_Ice"
    },
    {
      "x": -21,
      "y": 28,
      "z": -15,
      "name": "Rock_Ice"
    },
    {
      "x": -21,
      "y": 29,
      "z": -15,
      "name": "Rock_Ice"
    },
    {
      "x": -21,
      "y": 30,
      "z": -15,
      "name": "Rock_Ice"
    },
    {
      "x": -21,
      "y": 31,
      "z": -15,
      "name": "Rock_Ice"
    },
    {
      "x": -21,
      "y": 32,
      "z": -15,
      "name": "Rock_Ice"
    },
    {
      "x": -21,
      "y": 33,
      "z": -15,
      "name": "Rock_Ice"
    },
    {
      "x": -21,
      "y": 34,
      "z": -15,
      "name": "Rock_Ice"
    },
    {
      "x": -21,
      "y": 35,
      "z": -15,
      "name": "Rock_Ice"
    },
    {
      "x": -21,
      "y": 36,
      "z": -15,
      "name": "Soil_Snow"
    },
    {
      "x": -21,
      "y": 9,
      "z": -14,
      "name": "Rock_Ice"
    },
    {
      "x": -21,
      "y": 10,
      "z": -14,
      "name": "Rock_Ice"
    },
    {
      "x": -21,
      "y": 11,
      "z": -14,
      "name": "Rock_Ice"
    },
    {
      "x": -21,
      "y": 12,
      "z": -14,
      "name": "Rock_Ice"
    },
    {
      "x": -21,
      "y": 13,
      "z": -14,
      "name": "Rock_Ice"
    },
    {
      "x": -21,
      "y": 14,
      "z": -14,
      "name": "Rock_Ice"
    },
    {
      "x": -21,
      "y": 15,
      "z": -14,
      "name": "Rock_Ice"
    },
    {
      "x": -21,
      "y": 16,
      "z": -14,
      "name": "Rock_Ice"
    },
    {
      "x": -21,
      "y": 17,
      "z": -14,
      "name": "Rock_Ice"
    },
    {
      "x": -21,
      "y": 18,
      "z": -14,
      "name": "Rock_Ice_Permafrost"
    },
    {
      "x": -21,
      "y": 19,
      "z": -14,
      "name": "Rock_Ice_Permafrost"
    },
    {
      "x": -21,
      "y": 20,
      "z": -14,
      "name": "Rock_Ice_Permafrost"
    },
    {
      "x": -21,
      "y": 21,
      "z": -14,
      "name": "Rock_Ice_Permafrost"
    },
    {
      "x": -21,
      "y": 22,
      "z": -14,
      "name": "Rock_Ice_Permafrost"
    },
    {
      "x": -21,
      "y": 23,
      "z": -14,
      "name": "Rock_Ice_Permafrost"
    },
    {
      "x": -21,
      "y": 24,
      "z": -14,
      "name": "Rock_Ice_Permafrost"
    },
    {
      "x": -21,
      "y": 25,
      "z": -14,
      "name": "Rock_Ice"
    },
    {
      "x": -21,
      "y": 26,
      "z": -14,
      "name": "Rock_Ice"
    },
    {
      "x": -21,
      "y": 27,
      "z": -14,
      "name": "Rock_Ice"
    },
    {
      "x": -21,
      "y": 28,
      "z": -14,
      "name": "Rock_Ice"
    },
    {
      "x": -21,
      "y": 29,
      "z": -14,
      "name": "Rock_Ice"
    },
    {
      "x": -21,
      "y": 30,
      "z": -14,
      "name": "Rock_Ice"
    },
    {
      "x": -21,
      "y": 31,
      "z": -14,
      "name": "Rock_Ice"
    },
    {
      "x": -21,
      "y": 32,
      "z": -14,
      "name": "Rock_Ice"
    },
    {
      "x": -21,
      "y": 33,
      "z": -14,
      "name": "Rock_Ice"
    },
    {
      "x": -21,
      "y": 34,
      "z": -14,
      "name": "Rock_Ice"
    },
    {
      "x": -21,
      "y": 35,
      "z": -14,
      "name": "Rock_Ice"
    },
    {
      "x": -21,
      "y": 36,
      "z": -14,
      "name": "Soil_Snow"
    },
    {
      "x": -21,
      "y": 8,
      "z": -13,
      "name": "Rock_Ice"
    },
    {
      "x": -21,
      "y": 9,
      "z": -13,
      "name": "Rock_Ice"
    },
    {
      "x": -21,
      "y": 10,
      "z": -13,
      "name": "Rock_Ice"
    },
    {
      "x": -21,
      "y": 11,
      "z": -13,
      "name": "Rock_Ice"
    },
    {
      "x": -21,
      "y": 12,
      "z": -13,
      "name": "Rock_Ice"
    },
    {
      "x": -21,
      "y": 13,
      "z": -13,
      "name": "Rock_Ice"
    },
    {
      "x": -21,
      "y": 14,
      "z": -13,
      "name": "Rock_Ice"
    },
    {
      "x": -21,
      "y": 15,
      "z": -13,
      "name": "Rock_Ice"
    },
    {
      "x": -21,
      "y": 16,
      "z": -13,
      "name": "Rock_Ice"
    },
    {
      "x": -21,
      "y": 17,
      "z": -13,
      "name": "Rock_Ice"
    },
    {
      "x": -21,
      "y": 18,
      "z": -13,
      "name": "Rock_Ice_Permafrost"
    },
    {
      "x": -21,
      "y": 19,
      "z": -13,
      "name": "Rock_Ice_Permafrost"
    },
    {
      "x": -21,
      "y": 20,
      "z": -13,
      "name": "Rock_Ice_Permafrost"
    },
    {
      "x": -21,
      "y": 21,
      "z": -13,
      "name": "Rock_Ice_Permafrost"
    },
    {
      "x": -21,
      "y": 22,
      "z": -13,
      "name": "Rock_Ice_Permafrost"
    },
    {
      "x": -21,
      "y": 23,
      "z": -13,
      "name": "Rock_Ice"
    },
    {
      "x": -21,
      "y": 24,
      "z": -13,
      "name": "Rock_Ice_Permafrost"
    },
    {
      "x": -21,
      "y": 25,
      "z": -13,
      "name": "Rock_Ice_Permafrost"
    },
    {
      "x": -21,
      "y": 26,
      "z": -13,
      "name": "Rock_Ice"
    },
    {
      "x": -21,
      "y": 27,
      "z": -13,
      "name": "Rock_Ice"
    },
    {
      "x": -21,
      "y": 28,
      "z": -13,
      "name": "Rock_Ice"
    },
    {
      "x": -21,
      "y": 29,
      "z": -13,
      "name": "Rock_Ice"
    },
    {
      "x": -21,
      "y": 30,
      "z": -13,
      "name": "Rock_Ice"
    },
    {
      "x": -21,
      "y": 31,
      "z": -13,
      "name": "Rock_Ice"
    },
    {
      "x": -21,
      "y": 32,
      "z": -13,
      "name": "Rock_Ice"
    },
    {
      "x": -21,
      "y": 33,
      "z": -13,
      "name": "Rock_Ice"
    },
    {
      "x": -21,
      "y": 34,
      "z": -13,
      "name": "Rock_Ice"
    },
    {
      "x": -21,
      "y": 35,
      "z": -13,
      "name": "Rock_Ice"
    },
    {
      "x": -21,
      "y": 36,
      "z": -13,
      "name": "Soil_Snow"
    },
    {
      "x": -21,
      "y": 8,
      "z": -12,
      "name": "Rock_Ice"
    },
    {
      "x": -21,
      "y": 9,
      "z": -12,
      "name": "Rock_Ice"
    },
    {
      "x": -21,
      "y": 10,
      "z": -12,
      "name": "Rock_Ice"
    },
    {
      "x": -21,
      "y": 11,
      "z": -12,
      "name": "Rock_Ice"
    },
    {
      "x": -21,
      "y": 12,
      "z": -12,
      "name": "Rock_Ice"
    },
    {
      "x": -21,
      "y": 13,
      "z": -12,
      "name": "Rock_Ice"
    },
    {
      "x": -21,
      "y": 14,
      "z": -12,
      "name": "Rock_Ice"
    },
    {
      "x": -21,
      "y": 15,
      "z": -12,
      "name": "Rock_Ice"
    },
    {
      "x": -21,
      "y": 16,
      "z": -12,
      "name": "Rock_Ice_Permafrost"
    },
    {
      "x": -21,
      "y": 17,
      "z": -12,
      "name": "Rock_Ice_Permafrost"
    },
    {
      "x": -21,
      "y": 18,
      "z": -12,
      "name": "Rock_Ice_Permafrost"
    },
    {
      "x": -21,
      "y": 19,
      "z": -12,
      "name": "Rock_Ice_Permafrost"
    },
    {
      "x": -21,
      "y": 20,
      "z": -12,
      "name": "Rock_Ice_Permafrost"
    },
    {
      "x": -21,
      "y": 21,
      "z": -12,
      "name": "Rock_Ice"
    },
    {
      "x": -21,
      "y": 22,
      "z": -12,
      "name": "Rock_Ice"
    },
    {
      "x": -21,
      "y": 23,
      "z": -12,
      "name": "Rock_Ice"
    },
    {
      "x": -21,
      "y": 24,
      "z": -12,
      "name": "Rock_Ice"
    },
    {
      "x": -21,
      "y": 25,
      "z": -12,
      "name": "Rock_Ice"
    },
    {
      "x": -21,
      "y": 26,
      "z": -12,
      "name": "Rock_Ice"
    },
    {
      "x": -21,
      "y": 27,
      "z": -12,
      "name": "Rock_Ice"
    },
    {
      "x": -21,
      "y": 28,
      "z": -12,
      "name": "Rock_Ice"
    },
    {
      "x": -21,
      "y": 29,
      "z": -12,
      "name": "Rock_Ice"
    },
    {
      "x": -21,
      "y": 30,
      "z": -12,
      "name": "Rock_Ice"
    },
    {
      "x": -21,
      "y": 31,
      "z": -12,
      "name": "Rock_Ice"
    },
    {
      "x": -21,
      "y": 32,
      "z": -12,
      "name": "Rock_Ice"
    },
    {
      "x": -21,
      "y": 33,
      "z": -12,
      "name": "Rock_Ice"
    },
    {
      "x": -21,
      "y": 34,
      "z": -12,
      "name": "Rock_Ice"
    },
    {
      "x": -21,
      "y": 35,
      "z": -12,
      "name": "Rock_Ice"
    },
    {
      "x": -21,
      "y": 36,
      "z": -12,
      "name": "Soil_Snow"
    },
    {
      "x": -21,
      "y": 8,
      "z": -11,
      "name": "Rock_Ice"
    },
    {
      "x": -21,
      "y": 9,
      "z": -11,
      "name": "Rock_Ice"
    },
    {
      "x": -21,
      "y": 10,
      "z": -11,
      "name": "Rock_Ice"
    },
    {
      "x": -21,
      "y": 11,
      "z": -11,
      "name": "Rock_Ice"
    },
    {
      "x": -21,
      "y": 12,
      "z": -11,
      "name": "Rock_Ice"
    },
    {
      "x": -21,
      "y": 13,
      "z": -11,
      "name": "Rock_Ice"
    },
    {
      "x": -21,
      "y": 14,
      "z": -11,
      "name": "Rock_Ice"
    },
    {
      "x": -21,
      "y": 15,
      "z": -11,
      "name": "Rock_Ice"
    },
    {
      "x": -21,
      "y": 16,
      "z": -11,
      "name": "Rock_Ice_Permafrost"
    },
    {
      "x": -21,
      "y": 17,
      "z": -11,
      "name": "Rock_Ice_Permafrost"
    },
    {
      "x": -21,
      "y": 18,
      "z": -11,
      "name": "Rock_Ice_Permafrost"
    },
    {
      "x": -21,
      "y": 19,
      "z": -11,
      "name": "Rock_Ice_Permafrost"
    },
    {
      "x": -21,
      "y": 20,
      "z": -11,
      "name": "Rock_Ice_Permafrost"
    },
    {
      "x": -21,
      "y": 21,
      "z": -11,
      "name": "Rock_Ice_Permafrost"
    },
    {
      "x": -21,
      "y": 22,
      "z": -11,
      "name": "Rock_Ice_Permafrost"
    },
    {
      "x": -21,
      "y": 23,
      "z": -11,
      "name": "Rock_Ice_Permafrost"
    },
    {
      "x": -21,
      "y": 24,
      "z": -11,
      "name": "Rock_Ice"
    },
    {
      "x": -21,
      "y": 25,
      "z": -11,
      "name": "Rock_Ice"
    },
    {
      "x": -21,
      "y": 26,
      "z": -11,
      "name": "Rock_Ice_Permafrost"
    },
    {
      "x": -21,
      "y": 27,
      "z": -11,
      "name": "Rock_Ice"
    },
    {
      "x": -21,
      "y": 28,
      "z": -11,
      "name": "Rock_Ice"
    },
    {
      "x": -21,
      "y": 29,
      "z": -11,
      "name": "Rock_Ice"
    },
    {
      "x": -21,
      "y": 30,
      "z": -11,
      "name": "Rock_Ice"
    },
    {
      "x": -21,
      "y": 31,
      "z": -11,
      "name": "Rock_Ice"
    },
    {
      "x": -21,
      "y": 32,
      "z": -11,
      "name": "Rock_Ice"
    },
    {
      "x": -21,
      "y": 33,
      "z": -11,
      "name": "Rock_Ice"
    },
    {
      "x": -21,
      "y": 34,
      "z": -11,
      "name": "Rock_Ice"
    },
    {
      "x": -21,
      "y": 35,
      "z": -11,
      "name": "Soil_Snow"
    },
    {
      "x": -21,
      "y": 8,
      "z": -10,
      "name": "Rock_Ice"
    },
    {
      "x": -21,
      "y": 9,
      "z": -10,
      "name": "Rock_Ice"
    },
    {
      "x": -21,
      "y": 10,
      "z": -10,
      "name": "Rock_Ice"
    },
    {
      "x": -21,
      "y": 11,
      "z": -10,
      "name": "Rock_Ice"
    },
    {
      "x": -21,
      "y": 12,
      "z": -10,
      "name": "Rock_Ice"
    },
    {
      "x": -21,
      "y": 13,
      "z": -10,
      "name": "Rock_Ice"
    },
    {
      "x": -21,
      "y": 14,
      "z": -10,
      "name": "Rock_Ice"
    },
    {
      "x": -21,
      "y": 15,
      "z": -10,
      "name": "Rock_Ice_Permafrost"
    },
    {
      "x": -21,
      "y": 16,
      "z": -10,
      "name": "Rock_Ice_Permafrost"
    },
    {
      "x": -21,
      "y": 17,
      "z": -10,
      "name": "Rock_Ice_Permafrost"
    },
    {
      "x": -21,
      "y": 18,
      "z": -10,
      "name": "Rock_Ice_Permafrost"
    },
    {
      "x": -21,
      "y": 19,
      "z": -10,
      "name": "Rock_Ice_Permafrost"
    },
    {
      "x": -21,
      "y": 20,
      "z": -10,
      "name": "Rock_Ice"
    },
    {
      "x": -21,
      "y": 21,
      "z": -10,
      "name": "Rock_Ice"
    },
    {
      "x": -21,
      "y": 22,
      "z": -10,
      "name": "Rock_Ice"
    },
    {
      "x": -21,
      "y": 23,
      "z": -10,
      "name": "Rock_Ice"
    },
    {
      "x": -21,
      "y": 24,
      "z": -10,
      "name": "Rock_Ice"
    },
    {
      "x": -21,
      "y": 25,
      "z": -10,
      "name": "Rock_Ice"
    },
    {
      "x": -21,
      "y": 26,
      "z": -10,
      "name": "Rock_Ice_Permafrost"
    },
    {
      "x": -21,
      "y": 27,
      "z": -10,
      "name": "Rock_Ice"
    },
    {
      "x": -21,
      "y": 28,
      "z": -10,
      "name": "Rock_Ice"
    },
    {
      "x": -21,
      "y": 29,
      "z": -10,
      "name": "Rock_Ice"
    },
    {
      "x": -21,
      "y": 30,
      "z": -10,
      "name": "Rock_Ice"
    },
    {
      "x": -21,
      "y": 31,
      "z": -10,
      "name": "Rock_Ice"
    },
    {
      "x": -21,
      "y": 32,
      "z": -10,
      "name": "Rock_Ice"
    },
    {
      "x": -21,
      "y": 33,
      "z": -10,
      "name": "Rock_Ice"
    },
    {
      "x": -21,
      "y": 34,
      "z": -10,
      "name": "Rock_Ice"
    },
    {
      "x": -21,
      "y": 35,
      "z": -10,
      "name": "Soil_Snow"
    },
    {
      "x": -21,
      "y": 9,
      "z": -9,
      "name": "Rock_Ice"
    },
    {
      "x": -21,
      "y": 10,
      "z": -9,
      "name": "Rock_Ice"
    },
    {
      "x": -21,
      "y": 11,
      "z": -9,
      "name": "Rock_Ice"
    },
    {
      "x": -21,
      "y": 12,
      "z": -9,
      "name": "Rock_Ice"
    },
    {
      "x": -21,
      "y": 13,
      "z": -9,
      "name": "Rock_Ice_Permafrost"
    },
    {
      "x": -21,
      "y": 14,
      "z": -9,
      "name": "Rock_Ice_Permafrost"
    },
    {
      "x": -21,
      "y": 15,
      "z": -9,
      "name": "Rock_Ice_Permafrost"
    },
    {
      "x": -21,
      "y": 16,
      "z": -9,
      "name": "Rock_Ice_Permafrost"
    },
    {
      "x": -21,
      "y": 17,
      "z": -9,
      "name": "Rock_Ice_Permafrost"
    },
    {
      "x": -21,
      "y": 18,
      "z": -9,
      "name": "Rock_Ice_Permafrost"
    },
    {
      "x": -21,
      "y": 19,
      "z": -9,
      "name": "Rock_Ice_Permafrost"
    },
    {
      "x": -21,
      "y": 20,
      "z": -9,
      "name": "Rock_Ice_Permafrost"
    },
    {
      "x": -21,
      "y": 21,
      "z": -9,
      "name": "Rock_Ice_Permafrost"
    },
    {
      "x": -21,
      "y": 22,
      "z": -9,
      "name": "Rock_Ice_Permafrost"
    },
    {
      "x": -21,
      "y": 23,
      "z": -9,
      "name": "Rock_Ice"
    },
    {
      "x": -21,
      "y": 24,
      "z": -9,
      "name": "Rock_Ice_Permafrost"
    },
    {
      "x": -21,
      "y": 25,
      "z": -9,
      "name": "Rock_Ice"
    },
    {
      "x": -21,
      "y": 26,
      "z": -9,
      "name": "Rock_Ice_Permafrost"
    },
    {
      "x": -21,
      "y": 27,
      "z": -9,
      "name": "Rock_Ice"
    },
    {
      "x": -21,
      "y": 28,
      "z": -9,
      "name": "Rock_Ice"
    },
    {
      "x": -21,
      "y": 29,
      "z": -9,
      "name": "Rock_Ice"
    },
    {
      "x": -21,
      "y": 30,
      "z": -9,
      "name": "Rock_Ice"
    },
    {
      "x": -21,
      "y": 31,
      "z": -9,
      "name": "Rock_Ice"
    },
    {
      "x": -21,
      "y": 32,
      "z": -9,
      "name": "Rock_Ice"
    },
    {
      "x": -21,
      "y": 33,
      "z": -9,
      "name": "Rock_Ice"
    },
    {
      "x": -21,
      "y": 34,
      "z": -9,
      "name": "Rock_Ice"
    },
    {
      "x": -21,
      "y": 35,
      "z": -9,
      "name": "Soil_Snow"
    },
    {
      "x": -21,
      "y": 9,
      "z": -8,
      "name": "Rock_Ice"
    },
    {
      "x": -21,
      "y": 10,
      "z": -8,
      "name": "Rock_Ice"
    },
    {
      "x": -21,
      "y": 11,
      "z": -8,
      "name": "Rock_Ice"
    },
    {
      "x": -21,
      "y": 12,
      "z": -8,
      "name": "Rock_Ice"
    },
    {
      "x": -21,
      "y": 13,
      "z": -8,
      "name": "Rock_Ice_Permafrost"
    },
    {
      "x": -21,
      "y": 14,
      "z": -8,
      "name": "Rock_Ice_Permafrost"
    },
    {
      "x": -21,
      "y": 15,
      "z": -8,
      "name": "Rock_Ice_Permafrost"
    },
    {
      "x": -21,
      "y": 16,
      "z": -8,
      "name": "Rock_Ice_Permafrost"
    },
    {
      "x": -21,
      "y": 17,
      "z": -8,
      "name": "Rock_Ice_Permafrost"
    },
    {
      "x": -21,
      "y": 18,
      "z": -8,
      "name": "Rock_Ice_Permafrost"
    },
    {
      "x": -21,
      "y": 19,
      "z": -8,
      "name": "Rock_Ice_Permafrost"
    },
    {
      "x": -21,
      "y": 20,
      "z": -8,
      "name": "Rock_Ice_Permafrost"
    },
    {
      "x": -21,
      "y": 21,
      "z": -8,
      "name": "Rock_Ice"
    },
    {
      "x": -21,
      "y": 22,
      "z": -8,
      "name": "Rock_Ice_Permafrost"
    },
    {
      "x": -21,
      "y": 23,
      "z": -8,
      "name": "Rock_Ice_Permafrost"
    },
    {
      "x": -21,
      "y": 24,
      "z": -8,
      "name": "Rock_Ice_Permafrost"
    },
    {
      "x": -21,
      "y": 25,
      "z": -8,
      "name": "Rock_Ice"
    },
    {
      "x": -21,
      "y": 26,
      "z": -8,
      "name": "Rock_Ice"
    },
    {
      "x": -21,
      "y": 27,
      "z": -8,
      "name": "Rock_Ice"
    },
    {
      "x": -21,
      "y": 28,
      "z": -8,
      "name": "Rock_Ice"
    },
    {
      "x": -21,
      "y": 29,
      "z": -8,
      "name": "Rock_Ice"
    },
    {
      "x": -21,
      "y": 30,
      "z": -8,
      "name": "Rock_Ice"
    },
    {
      "x": -21,
      "y": 31,
      "z": -8,
      "name": "Rock_Ice"
    },
    {
      "x": -21,
      "y": 32,
      "z": -8,
      "name": "Rock_Ice_Permafrost"
    },
    {
      "x": -21,
      "y": 33,
      "z": -8,
      "name": "Rock_Ice"
    },
    {
      "x": -21,
      "y": 34,
      "z": -8,
      "name": "Soil_Snow"
    },
    {
      "x": -21,
      "y": 10,
      "z": -7,
      "name": "Rock_Ice"
    },
    {
      "x": -21,
      "y": 11,
      "z": -7,
      "name": "Rock_Ice_Permafrost"
    },
    {
      "x": -21,
      "y": 12,
      "z": -7,
      "name": "Rock_Ice_Permafrost"
    },
    {
      "x": -21,
      "y": 13,
      "z": -7,
      "name": "Rock_Ice_Permafrost"
    },
    {
      "x": -21,
      "y": 14,
      "z": -7,
      "name": "Rock_Ice_Permafrost"
    },
    {
      "x": -21,
      "y": 15,
      "z": -7,
      "name": "Rock_Ice_Permafrost"
    },
    {
      "x": -21,
      "y": 16,
      "z": -7,
      "name": "Rock_Ice_Permafrost"
    },
    {
      "x": -21,
      "y": 17,
      "z": -7,
      "name": "Rock_Ice_Permafrost"
    },
    {
      "x": -21,
      "y": 18,
      "z": -7,
      "name": "Rock_Ice_Permafrost"
    },
    {
      "x": -21,
      "y": 19,
      "z": -7,
      "name": "Rock_Ice_Permafrost"
    },
    {
      "x": -21,
      "y": 20,
      "z": -7,
      "name": "Rock_Ice_Permafrost"
    },
    {
      "x": -21,
      "y": 21,
      "z": -7,
      "name": "Rock_Ice_Permafrost"
    },
    {
      "x": -21,
      "y": 22,
      "z": -7,
      "name": "Rock_Ice_Permafrost"
    },
    {
      "x": -21,
      "y": 23,
      "z": -7,
      "name": "Rock_Ice"
    },
    {
      "x": -21,
      "y": 24,
      "z": -7,
      "name": "Rock_Ice"
    },
    {
      "x": -21,
      "y": 25,
      "z": -7,
      "name": "Rock_Ice"
    },
    {
      "x": -21,
      "y": 26,
      "z": -7,
      "name": "Rock_Ice_Permafrost"
    },
    {
      "x": -21,
      "y": 27,
      "z": -7,
      "name": "Rock_Ice"
    },
    {
      "x": -21,
      "y": 28,
      "z": -7,
      "name": "Rock_Ice"
    },
    {
      "x": -21,
      "y": 29,
      "z": -7,
      "name": "Rock_Ice"
    },
    {
      "x": -21,
      "y": 30,
      "z": -7,
      "name": "Rock_Ice"
    },
    {
      "x": -21,
      "y": 31,
      "z": -7,
      "name": "Rock_Ice"
    },
    {
      "x": -21,
      "y": 32,
      "z": -7,
      "name": "Rock_Ice"
    },
    {
      "x": -21,
      "y": 33,
      "z": -7,
      "name": "Rock_Ice"
    },
    {
      "x": -21,
      "y": 34,
      "z": -7,
      "name": "Soil_Snow"
    },
    {
      "x": -21,
      "y": 10,
      "z": -6,
      "name": "Rock_Ice_Permafrost"
    },
    {
      "x": -21,
      "y": 11,
      "z": -6,
      "name": "Rock_Ice_Permafrost"
    },
    {
      "x": -21,
      "y": 12,
      "z": -6,
      "name": "Rock_Ice_Permafrost"
    },
    {
      "x": -21,
      "y": 13,
      "z": -6,
      "name": "Rock_Ice_Permafrost"
    },
    {
      "x": -21,
      "y": 14,
      "z": -6,
      "name": "Rock_Ice_Permafrost"
    },
    {
      "x": -21,
      "y": 15,
      "z": -6,
      "name": "Rock_Ice_Permafrost"
    },
    {
      "x": -21,
      "y": 16,
      "z": -6,
      "name": "Rock_Ice_Permafrost"
    },
    {
      "x": -21,
      "y": 17,
      "z": -6,
      "name": "Rock_Ice_Permafrost"
    },
    {
      "x": -21,
      "y": 18,
      "z": -6,
      "name": "Rock_Ice_Permafrost"
    },
    {
      "x": -21,
      "y": 19,
      "z": -6,
      "name": "Rock_Ice_Permafrost"
    },
    {
      "x": -21,
      "y": 20,
      "z": -6,
      "name": "Rock_Ice_Permafrost"
    },
    {
      "x": -21,
      "y": 21,
      "z": -6,
      "name": "Rock_Ice"
    },
    {
      "x": -21,
      "y": 22,
      "z": -6,
      "name": "Rock_Ice"
    },
    {
      "x": -21,
      "y": 23,
      "z": -6,
      "name": "Rock_Ice_Permafrost"
    },
    {
      "x": -21,
      "y": 31,
      "z": -6,
      "name": "Rock_Ice"
    },
    {
      "x": -21,
      "y": 32,
      "z": -6,
      "name": "Rock_Ice"
    },
    {
      "x": -21,
      "y": 33,
      "z": -6,
      "name": "Soil_Snow"
    },
    {
      "x": -21,
      "y": 11,
      "z": -5,
      "name": "Rock_Ice_Permafrost"
    },
    {
      "x": -21,
      "y": 12,
      "z": -5,
      "name": "Rock_Ice_Permafrost"
    },
    {
      "x": -21,
      "y": 13,
      "z": -5,
      "name": "Rock_Ice_Permafrost"
    },
    {
      "x": -21,
      "y": 14,
      "z": -5,
      "name": "Rock_Ice_Permafrost"
    },
    {
      "x": -21,
      "y": 15,
      "z": -5,
      "name": "Rock_Ice_Permafrost"
    },
    {
      "x": -21,
      "y": 16,
      "z": -5,
      "name": "Rock_Ice_Permafrost"
    },
    {
      "x": -21,
      "y": 17,
      "z": -5,
      "name": "Rock_Ice_Permafrost"
    },
    {
      "x": -21,
      "y": 18,
      "z": -5,
      "name": "Rock_Ice_Permafrost"
    },
    {
      "x": -21,
      "y": 19,
      "z": -5,
      "name": "Rock_Ice_Permafrost"
    },
    {
      "x": -21,
      "y": 20,
      "z": -5,
      "name": "Soil_Snow"
    },
    {
      "x": -21,
      "y": 14,
      "z": -4,
      "name": "Rock_Ice_Permafrost"
    },
    {
      "x": -21,
      "y": 15,
      "z": -4,
      "name": "Soil_Snow"
    },
    {
      "x": -20,
      "y": 24,
      "z": -24,
      "name": "Rock_Ice"
    },
    {
      "x": -20,
      "y": 25,
      "z": -24,
      "name": "Rock_Ice"
    },
    {
      "x": -20,
      "y": 26,
      "z": -24,
      "name": "Soil_Snow"
    },
    {
      "x": -20,
      "y": 23,
      "z": -23,
      "name": "Rock_Ice"
    },
    {
      "x": -20,
      "y": 24,
      "z": -23,
      "name": "Rock_Ice"
    },
    {
      "x": -20,
      "y": 25,
      "z": -23,
      "name": "Rock_Ice"
    },
    {
      "x": -20,
      "y": 26,
      "z": -23,
      "name": "Rock_Ice"
    },
    {
      "x": -20,
      "y": 27,
      "z": -23,
      "name": "Rock_Ice"
    },
    {
      "x": -20,
      "y": 28,
      "z": -23,
      "name": "Rock_Ice"
    },
    {
      "x": -20,
      "y": 29,
      "z": -23,
      "name": "Soil_Snow"
    },
    {
      "x": -20,
      "y": 21,
      "z": -22,
      "name": "Rock_Ice"
    },
    {
      "x": -20,
      "y": 22,
      "z": -22,
      "name": "Rock_Ice"
    },
    {
      "x": -20,
      "y": 23,
      "z": -22,
      "name": "Rock_Ice"
    },
    {
      "x": -20,
      "y": 24,
      "z": -22,
      "name": "Rock_Ice"
    },
    {
      "x": -20,
      "y": 25,
      "z": -22,
      "name": "Rock_Ice"
    },
    {
      "x": -20,
      "y": 26,
      "z": -22,
      "name": "Rock_Ice"
    },
    {
      "x": -20,
      "y": 27,
      "z": -22,
      "name": "Rock_Ice"
    },
    {
      "x": -20,
      "y": 28,
      "z": -22,
      "name": "Rock_Ice"
    },
    {
      "x": -20,
      "y": 29,
      "z": -22,
      "name": "Rock_Ice"
    },
    {
      "x": -20,
      "y": 30,
      "z": -22,
      "name": "Rock_Ice"
    },
    {
      "x": -20,
      "y": 31,
      "z": -22,
      "name": "Soil_Snow"
    },
    {
      "x": -20,
      "y": 20,
      "z": -21,
      "name": "Rock_Ice"
    },
    {
      "x": -20,
      "y": 21,
      "z": -21,
      "name": "Rock_Ice"
    },
    {
      "x": -20,
      "y": 22,
      "z": -21,
      "name": "Rock_Ice"
    },
    {
      "x": -20,
      "y": 23,
      "z": -21,
      "name": "Rock_Ice"
    },
    {
      "x": -20,
      "y": 24,
      "z": -21,
      "name": "Rock_Ice"
    },
    {
      "x": -20,
      "y": 25,
      "z": -21,
      "name": "Rock_Ice"
    },
    {
      "x": -20,
      "y": 26,
      "z": -21,
      "name": "Rock_Ice"
    },
    {
      "x": -20,
      "y": 27,
      "z": -21,
      "name": "Rock_Ice"
    },
    {
      "x": -20,
      "y": 28,
      "z": -21,
      "name": "Rock_Ice"
    },
    {
      "x": -20,
      "y": 29,
      "z": -21,
      "name": "Rock_Ice"
    },
    {
      "x": -20,
      "y": 30,
      "z": -21,
      "name": "Rock_Ice"
    },
    {
      "x": -20,
      "y": 31,
      "z": -21,
      "name": "Rock_Ice"
    },
    {
      "x": -20,
      "y": 32,
      "z": -21,
      "name": "Soil_Snow"
    },
    {
