{
  "version": 8,
  "blockIdVersion": 11,
  "anchorX": 0,
  "anchorY": 0,
  "anchorZ": 0,
  "blocks": [
    {
      "x": -33,
      "y": 5,
      "z": 10,
      "name": "Rock_Ice_Permafrost"
    },
    {
      "x": -33,
      "y": 6,
      "z": 10,
      "name": "Soil_Snow"
    },
    {
      "x": -33,
      "y": 5,
      "z": 11,
      "name": "Rock_Ice_Permafrost"
    },
    {
      "x": -33,
      "y": 6,
      "z": 11,
      "name": "Soil_Snow"
    },
    {
      "x": -32,
      "y": 5,
      "z": 7,
      "name": "Rock_Ice"
    },
    {
      "x": -32,
      "y": 6,
      "z": 7,
      "name": "Rock_Ice"
    },
    {
      "x": -32,
      "y": 7,
      "z": 7,
      "name": "Rock_Ice_Permafrost"
    },
    {
      "x": -32,
      "y": 8,
      "z": 7,
      "name": "Rock_Ice"
    },
    {
      "x": -32,
      "y": 9,
      "z": 7,
      "name": "Rock_Ice"
    },
    {
      "x": -32,
      "y": 10,
      "z": 7,
      "name": "Rock_Ice_Permafrost"
    },
    {
      "x": -32,
      "y": 11,
      "z": 7,
      "name": "Rock_Ice"
    },
    {
      "x": -32,
      "y": 12,
      "z": 7,
      "name": "Rock_Ice"
    },
    {
      "x": -32,
      "y": 13,
      "z": 7,
      "name": "Rock_Ice"
    },
    {
      "x": -32,
      "y": 5,
      "z": 8,
      "name": "Rock_Ice"
    },
    {
      "x": -32,
      "y": 6,
      "z": 8,
      "name": "Rock_Ice_Permafrost"
    },
    {
      "x": -32,
      "y": 7,
      "z": 8,
      "name": "Rock_Ice_Permafrost"
    },
    {
      "x": -32,
      "y": 8,
      "z": 8,
      "name": "Rock_Ice"
    },
    {
      "x": -32,
      "y": 9,
      "z": 8,
      "name": "Rock_Ice"
    },
    {
      "x": -32,
      "y": 10,
      "z": 8,
      "name": "Rock_Ice"
    },
    {
      "x": -32,
      "y": 11,
      "z": 8,
      "name": "Rock_Ice_Permafrost"
    },
    {
      "x": -32,
      "y": 12,
      "z": 8,
      "name": "Rock_Ice_Permafrost"
    },
    {
      "x": -32,
      "y": 5,
      "z": 9,
      "name": "Rock_Ice_Permafrost"
    },
    {
      "x": -32,
      "y": 6,
      "z": 9,
      "name": "Rock_Ice_Permafrost"
    },
    {
      "x": -32,
      "y": 7,
      "z": 9,
      "name": "Rock_Ice_Permafrost"
    },
    {
      "x": -32,
      "y": 8,
      "z": 9,
      "name": "Rock_Ice_Permafrost"
    },
    {
      "x": -32,
      "y": 9,
      "z": 9,
      "name": "Rock_Ice_Permafrost"
    },
    {
      "x": -32,
      "y": 10,
      "z": 9,
      "name": "Rock_Ice_Permafrost"
    },
    {
      "x": -32,
      "y": 11,
      "z": 9,
      "name": "Rock_Ice_Permafrost"
    },
    {
      "x": -32,
      "y": 12,
      "z": 9,
      "name": "Soil_Snow"
    },
    {
      "x": -32,
      "y": 5,
      "z": 10,
      "name": "Rock_Ice_Permafrost"
    },
    {
      "x": -32,
      "y": 6,
      "z": 10,
      "name": "Rock_Ice_Permafrost"
    },
    {
      "x": -32,
      "y": 7,
      "z": 10,
      "name": "Rock_Ice_Permafrost"
    },
    {
      "x": -32,
      "y": 8,
      "z": 10,
      "name": "Rock_Ice_Permafrost"
    },
    {
      "x": -32,
      "y": 9,
      "z": 10,
      "name": "Rock_Ice_Permafrost"
    },
    {
      "x": -32,
      "y": 10,
      "z": 10,
      "name": "Rock_Ice_Permafrost"
    },
    {
      "x": -32,
      "y": 11,
      "z": 10,
      "name": "Rock_Ice_Permafrost"
    },
    {
      "x": -32,
      "y": 12,
      "z": 10,
      "name": "Rock_Ice"
    },
    {
      "x": -32,
      "y": 5,
      "z": 11,
      "name": "Rock_Ice_Permafrost"
    },
    {
      "x": -32,
      "y": 6,
      "z": 11,
      "name": "Rock_Ice_Permafrost"
    },
    {
      "x": -32,
      "y": 7,
      "z": 11,
      "name": "Rock_Ice_Permafrost"
    },
    {
      "x": -32,
      "y": 8,
      "z": 11,
      "name": "Rock_Ice"
    },
    {
      "x": -32,
      "y": 9,
      "z": 11,
      "name": "Rock_Ice_Permafrost"
    },
    {
      "x": -32,
      "y": 10,
      "z": 11,
      "name": "Rock_Ice"
    },
    {
      "x": -32,
      "y": 11,
      "z": 11,
      "name": "Rock_Ice"
    },
    {
      "x": -32,
      "y": 12,
      "z": 11,
      "name": "Soil_Snow"
    },
    {
      "x": -32,
      "y": 5,
      "z": 12,
      "name": "Rock_Ice_Permafrost"
    },
    {
      "x": -32,
      "y": 6,
      "z": 12,
      "name": "Rock_Ice_Permafrost"
    },
    {
      "x": -32,
      "y": 7,
      "z": 12,
      "name": "Rock_Ice_Permafrost"
    },
    {
      "x": -32,
      "y": 8,
      "z": 12,
      "name": "Rock_Ice_Permafrost"
    },
    {
      "x": -32,
      "y": 9,
      "z": 12,
      "name": "Rock_Ice"
    },
    {
      "x": -32,
      "y": 10,
      "z": 12,
      "name": "Rock_Ice"
    },
    {
      "x": -32,
      "y": 11,
      "z": 12,
      "name": "Rock_Ice"
    },
    {
      "x": -32,
      "y": 5,
      "z": 13,
      "name": "Rock_Ice_Permafrost"
    },
    {
      "x": -32,
      "y": 6,
      "z": 13,
      "name": "Rock_Ice"
    },
    {
      "x": -32,
      "y": 7,
      "z": 13,
      "name": "Rock_Ice"
    },
    {
      "x": -32,
      "y": 8,
      "z": 13,
      "name": "Rock_Ice"
    },
    {
      "x": -32,
      "y": 9,
      "z": 13,
      "name": "Soil_Snow"
    },
    {
      "x": -32,
      "y": 5,
      "z": 14,
      "name": "Rock_Ice_Permafrost"
    },
    {
      "x": -32,
      "y": 6,
      "z": 14,
      "name": "Rock_Ice"
    },
    {
      "x": -32,
      "y": 7,
      "z": 14,
      "name": "Soil_Snow"
    },
    {
      "x": -32,
      "y": 5,
      "z": 15,
      "name": "Soil_Snow"
    },
    {
      "x": -31,
      "y": 16,
      "z": -1,
      "name": "Soil_Snow"
    },
    {
      "x": -31,
      "y": 14,
      "z": 0,
      "name": "Rock_Ice"
    },
    {
      "x": -31,
      "y": 15,
      "z": 0,
      "name": "Rock_Ice"
    },
    {
      "x": -31,
      "y": 16,
      "z": 0,
      "name": "Soil_Snow"
    },
    {
      "x": -31,
      "y": 13,
      "z": 1,
      "name": "Rock_Ice"
    },
    {
      "x": -31,
      "y": 14,
      "z": 1,
      "name": "Rock_Ice"
    },
    {
      "x": -31,
      "y": 15,
      "z": 1,
      "name": "Rock_Ice"
    },
    {
      "x": -31,
      "y": 16,
      "z": 1,
      "name": "Rock_Ice"
    },
    {
      "x": -31,
      "y": 12,
      "z": 2,
      "name": "Rock_Ice"
    },
    {
      "x": -31,
      "y": 13,
      "z": 2,
      "name": "Rock_Ice"
    },
    {
      "x": -31,
      "y": 14,
      "z": 2,
      "name": "Rock_Ice"
    },
    {
      "x": -31,
      "y": 15,
      "z": 2,
      "name": "Rock_Ice"
    },
    {
      "x": -31,
      "y": 11,
      "z": 3,
      "name": "Rock_Ice"
    },
    {
      "x": -31,
      "y": 12,
      "z": 3,
      "name": "Rock_Ice"
    },
    {
      "x": -31,
      "y": 13,
      "z": 3,
      "name": "Rock_Ice"
    },
    {
      "x": -31,
      "y": 14,
      "z": 3,
      "name": "Rock_Ice"
    },
    {
      "x": -31,
      "y": 15,
      "z": 3,
      "name": "Rock_Ice"
    },
    {
      "x": -31,
      "y": 8,
      "z": 4,
      "name": "Rock_Ice"
    },
    {
      "x": -31,
      "y": 9,
      "z": 4,
      "name": "Rock_Ice"
    },
    {
      "x": -31,
      "y": 10,
      "z": 4,
      "name": "Rock_Ice"
    },
    {
      "x": -31,
      "y": 11,
      "z": 4,
      "name": "Rock_Ice"
    },
    {
      "x": -31,
      "y": 12,
      "z": 4,
      "name": "Rock_Ice"
    },
    {
      "x": -31,
      "y": 13,
      "z": 4,
      "name": "Rock_Ice"
    },
    {
      "x": -31,
      "y": 14,
      "z": 4,
      "name": "Rock_Ice"
    },
    {
      "x": -31,
      "y": 15,
      "z": 4,
      "name": "Rock_Ice"
    },
    {
      "x": -31,
      "y": 5,
      "z": 5,
      "name": "Rock_Ice"
    },
    {
      "x": -31,
      "y": 6,
      "z": 5,
      "name": "Rock_Ice"
    },
    {
      "x": -31,
      "y": 7,
      "z": 5,
      "name": "Rock_Ice"
    },
    {
      "x": -31,
      "y": 8,
      "z": 5,
      "name": "Rock_Ice"
    },
    {
      "x": -31,
      "y": 9,
      "z": 5,
      "name": "Rock_Ice"
    },
    {
      "x": -31,
      "y": 10,
      "z": 5,
      "name": "Rock_Ice"
    },
    {
      "x": -31,
      "y": 11,
      "z": 5,
      "name": "Rock_Ice"
    },
    {
      "x": -31,
      "y": 12,
      "z": 5,
      "name": "Rock_Ice"
    },
    {
      "x": -31,
      "y": 13,
      "z": 5,
      "name": "Rock_Ice"
    },
    {
      "x": -31,
      "y": 14,
      "z": 5,
      "name": "Rock_Ice"
    },
    {
      "x": -31,
      "y": 5,
      "z": 6,
      "name": "Rock_Ice"
    },
    {
      "x": -31,
      "y": 6,
      "z": 6,
      "name": "Rock_Ice"
    },
    {
      "x": -31,
      "y": 7,
      "z": 6,
      "name": "Rock_Ice_Permafrost"
    },
    {
      "x": -31,
      "y": 8,
      "z": 6,
      "name": "Rock_Ice"
    },
    {
      "x": -31,
      "y": 9,
      "z": 6,
      "name": "Rock_Ice"
    },
    {
      "x": -31,
      "y": 10,
      "z": 6,
      "name": "Rock_Ice"
    },
    {
      "x": -31,
      "y": 11,
      "z": 6,
      "name": "Rock_Ice"
    },
    {
      "x": -31,
      "y": 12,
      "z": 6,
      "name": "Rock_Ice"
    },
    {
      "x": -31,
      "y": 13,
      "z": 6,
      "name": "Rock_Ice"
    },
    {
      "x": -31,
      "y": 14,
      "z": 6,
      "name": "Rock_Ice"
    },
    {
      "x": -31,
      "y": 5,
      "z": 7,
      "name": "Rock_Ice"
    },
    {
      "x": -31,
      "y": 6,
      "z": 7,
      "name": "Rock_Ice_Permafrost"
    },
    {
      "x": -31,
      "y": 7,
      "z": 7,
      "name": "Rock_Ice"
    },
    {
      "x": -31,
      "y": 8,
      "z": 7,
      "name": "Rock_Ice"
    },
    {
      "x": -31,
      "y": 9,
      "z": 7,
      "name": "Rock_Ice"
    },
    {
      "x": -31,
      "y": 10,
      "z": 7,
      "name": "Rock_Ice"
    },
    {
      "x": -31,
      "y": 11,
      "z": 7,
      "name": "Rock_Ice"
    },
    {
      "x": -31,
      "y": 12,
      "z": 7,
      "name": "Rock_Ice"
    },
    {
      "x": -31,
      "y": 13,
      "z": 7,
      "name": "Rock_Ice"
    },
    {
      "x": -31,
      "y": 14,
      "z": 7,
      "name": "Soil_Snow"
    },
    {
      "x": -31,
      "y": 5,
      "z": 8,
      "name": "Rock_Ice"
    },
    {
      "x": -31,
      "y": 6,
      "z": 8,
      "name": "Rock_Ice"
    },
    {
      "x": -31,
      "y": 7,
      "z": 8,
      "name": "Rock_Ice"
    },
    {
      "x": -31,
      "y": 8,
      "z": 8,
      "name": "Rock_Ice"
    },
    {
      "x": -31,
      "y": 9,
      "z": 8,
      "name": "Rock_Ice"
    },
    {
      "x": -31,
      "y": 10,
      "z": 8,
      "name": "Rock_Ice_Permafrost"
    },
    {
      "x": -31,
      "y": 11,
      "z": 8,
      "name": "Rock_Ice_Permafrost"
    },
    {
      "x": -31,
      "y": 12,
      "z": 8,
      "name": "Rock_Ice"
    },
    {
      "x": -31,
      "y": 13,
      "z": 8,
      "name": "Rock_Ice"
    },
    {
      "x": -31,
      "y": 14,
      "z": 8,
      "name": "Soil_Snow"
    },
    {
      "x": -31,
      "y": 5,
      "z": 9,
      "name": "Rock_Ice_Permafrost"
    },
    {
      "x": -31,
      "y": 6,
      "z": 9,
      "name": "Rock_Ice_Permafrost"
    },
    {
      "x": -31,
      "y": 7,
      "z": 9,
      "name": "Rock_Ice"
    },
    {
      "x": -31,
      "y": 8,
      "z": 9,
      "name": "Rock_Ice"
    },
    {
      "x": -31,
      "y": 9,
      "z": 9,
      "name": "Rock_Ice"
    },
    {
      "x": -31,
      "y": 10,
      "z": 9,
      "name": "Rock_Ice_Permafrost"
    },
    {
      "x": -31,
      "y": 11,
      "z": 9,
      "name": "Rock_Ice_Permafrost"
    },
    {
      "x": -31,
      "y": 12,
      "z": 9,
      "name": "Rock_Ice"
    },
    {
      "x": -31,
      "y": 13,
      "z": 9,
      "name": "Soil_Snow"
    },
    {
      "x": -31,
      "y": 5,
      "z": 10,
      "name": "Rock_Ice_Permafrost"
    },
    {
      "x": -31,
      "y": 6,
      "z": 10,
      "name": "Rock_Ice_Permafrost"
    },
    {
      "x": -31,
      "y": 7,
      "z": 10,
      "name": "Rock_Ice_Permafrost"
    },
    {
      "x": -31,
      "y": 8,
      "z": 10,
      "name": "Rock_Ice_Permafrost"
    },
    {
      "x": -31,
      "y": 9,
      "z": 10,
      "name": "Rock_Ice_Permafrost"
    },
    {
      "x": -31,
      "y": 10,
      "z": 10,
      "name": "Rock_Ice_Permafrost"
    },
    {
      "x": -31,
      "y": 11,
      "z": 10,
      "name": "Rock_Ice_Permafrost"
    },
    {
      "x": -31,
      "y": 12,
      "z": 10,
      "name": "Rock_Ice_Permafrost"
    },
    {
      "x": -31,
      "y": 13,
      "z": 10,
      "name": "Rock_Ice_Permafrost"
    },
    {
      "x": -31,
      "y": 5,
      "z": 11,
      "name": "Rock_Ice_Permafrost"
    },
    {
      "x": -31,
      "y": 6,
      "z": 11,
      "name": "Rock_Ice_Permafrost"
    },
    {
      "x": -31,
      "y": 7,
      "z": 11,
      "name": "Rock_Ice_Permafrost"
    },
    {
      "x": -31,
      "y": 8,
      "z": 11,
      "name": "Rock_Ice_Permafrost"
    },
    {
      "x": -31,
      "y": 9,
      "z": 11,
      "name": "Rock_Ice_Permafrost"
    },
    {
      "x": -31,
      "y": 10,
      "z": 11,
      "name": "Rock_Ice_Permafrost"
    },
    {
      "x": -31,
      "y": 11,
      "z": 11,
      "name": "Rock_Ice_Permafrost"
    },
    {
      "x": -31,
      "y": 12,
      "z": 11,
      "name": "Rock_Ice_Permafrost"
    },
    {
      "x": -31,
      "y": 5,
      "z": 12,
      "name": "Rock_Ice_Permafrost"
    },
    {
      "x": -31,
      "y": 6,
      "z": 12,
      "name": "Rock_Ice_Permafrost"
    },
    {
      "x": -31,
      "y": 7,
      "z": 12,
      "name": "Rock_Ice_Permafrost"
    },
    {
      "x": -31,
      "y": 8,
      "z": 12,
      "name": "Rock_Ice_Permafrost"
    },
    {
      "x": -31,
      "y": 9,
      "z": 12,
      "name": "Rock_Ice"
    },
    {
      "x": -31,
      "y": 10,
      "z": 12,
      "name": "Rock_Ice_Permafrost"
    },
    {
      "x": -31,
      "y": 11,
      "z": 12,
      "name": "Rock_Ice_Permafrost"
    },
    {
      "x": -31,
      "y": 12,
      "z": 12,
      "name": "Soil_Snow"
    },
    {
      "x": -31,
      "y": 5,
      "z": 13,
      "name": "Rock_Ice_Permafrost"
    },
    {
      "x": -31,
      "y": 6,
      "z": 13,
      "name": "Rock_Ice"
    },
    {
      "x": -31,
      "y": 7,
      "z": 13,
      "name": "Rock_Ice"
    },
    {
      "x": -31,
      "y": 8,
      "z": 13,
      "name": "Rock_Ice"
    },
    {
      "x": -31,
      "y": 9,
      "z": 13,
      "name": "Rock_Ice_Permafrost"
    },
    {
      "x": -31,
      "y": 10,
      "z": 13,
      "name": "Rock_Ice_Permafrost"
    },
    {
      "x": -31,
      "y": 11,
      "z": 13,
      "name": "Soil_Snow"
    },
    {
      "x": -31,
      "y": 5,
      "z": 14,
      "name": "Rock_Ice_Permafrost"
    },
    {
      "x": -31,
      "y": 6,
      "z": 14,
      "name": "Rock_Ice"
    },
    {
      "x": -31,
      "y": 7,
      "z": 14,
      "name": "Rock_Ice"
    },
    {
      "x": -31,
      "y": 8,
      "z": 14,
      "name": "Rock_Ice"
    },
    {
      "x": -31,
      "y": 9,
      "z": 14,
      "name": "Rock_Ice"
    },
    {
      "x": -31,
      "y": 10,
      "z": 14,
      "name": "Soil_Snow"
    },
    {
      "x": -31,
      "y": 5,
      "z": 15,
      "name": "Rock_Ice"
    },
    {
      "x": -31,
      "y": 6,
      "z": 15,
      "name": "Rock_Ice_Permafrost"
    },
    {
      "x": -31,
      "y": 7,
      "z": 15,
      "name": "Rock_Ice"
    },
    {
      "x": -31,
      "y": 8,
      "z": 15,
      "name": "Rock_Ice"
    },
    {
      "x": -31,
      "y": 9,
      "z": 15,
      "name": "Soil_Snow"
    },
    {
      "x": -31,
      "y": 5,
      "z": 16,
      "name": "Rock_Ice"
    },
    {
      "x": -31,
      "y": 6,
      "z": 16,
      "name": "Rock_Ice"
    },
    {
      "x": -31,
      "y": 7,
      "z": 16,
      "name": "Rock_Ice_Permafrost"
    },
    {
      "x": -31,
      "y": 8,
      "z": 16,
      "name": "Soil_Snow"
    },
    {
      "x": -31,
      "y": 5,
      "z": 17,
      "name": "Rock_Ice"
    },
    {
      "x": -31,
      "y": 6,
      "z": 17,
      "name": "Soil_Snow"
    },
    {
      "x": -30,
      "y": 16,
      "z": -5,
      "name": "Rock_Ice"
    },
    {
      "x": -30,
      "y": 17,
      "z": -5,
      "name": "Soil_Snow"
    },
    {
      "x": -30,
      "y": 14,
      "z": -4,
      "name": "Rock_Ice"
    },
    {
      "x": -30,
      "y": 15,
      "z": -4,
      "name": "Rock_Ice"
    },
    {
      "x": -30,
      "y": 16,
      "z": -4,
      "name": "Rock_Ice"
    },
    {
      "x": -30,
      "y": 17,
      "z": -4,
      "name": "Soil_Snow"
    },
    {
      "x": -30,
      "y": 14,
      "z": -3,
      "name": "Rock_Ice"
    },
    {
      "x": -30,
      "y": 15,
      "z": -3,
      "name": "Rock_Ice"
    },
    {
      "x": -30,
      "y": 16,
      "z": -3,
      "name": "Rock_Ice"
    },
    {
      "x": -30,
      "y": 17,
      "z": -3,
      "name": "Rock_Ice"
    },
    {
      "x": -30,
      "y": 18,
      "z": -3,
      "name": "Soil_Snow"
    },
    {
      "x": -30,
      "y": 13,
      "z": -2,
      "name": "Rock_Ice"
    },
    {
      "x": -30,
      "y": 14,
      "z": -2,
      "name": "Rock_Ice"
    },
    {
      "x": -30,
      "y": 15,
      "z": -2,
      "name": "Rock_Ice"
    },
    {
      "x": -30,
      "y": 16,
      "z": -2,
      "name": "Rock_Ice"
    },
    {
      "x": -30,
      "y": 17,
      "z": -2,
      "name": "Rock_Ice"
    },
    {
      "x": -30,
      "y": 18,
      "z": -2,
      "name": "Soil_Snow"
    },
    {
      "x": -30,
      "y": 13,
      "z": -1,
      "name": "Rock_Ice"
    },
    {
      "x": -30,
      "y": 14,
      "z": -1,
      "name": "Rock_Ice"
    },
    {
      "x": -30,
      "y": 15,
      "z": -1,
      "name": "Rock_Ice"
    },
    {
      "x": -30,
      "y": 16,
      "z": -1,
      "name": "Rock_Ice"
    },
    {
      "x": -30,
      "y": 17,
      "z": -1,
      "name": "Rock_Ice"
    },
    {
      "x": -30,
      "y": 18,
      "z": -1,
      "name": "Soil_Snow"
    },
    {
      "x": -30,
      "y": 12,
      "z": 0,
      "name": "Rock_Ice"
    },
    {
      "x": -30,
      "y": 13,
      "z": 0,
      "name": "Rock_Ice"
    },
    {
      "x": -30,
      "y": 14,
      "z": 0,
      "name": "Rock_Ice"
    },
    {
      "x": -30,
      "y": 15,
      "z": 0,
      "name": "Rock_Ice"
    },
    {
      "x": -30,
      "y": 16,
      "z": 0,
      "name": "Rock_Ice"
    },
    {
      "x": -30,
      "y": 17,
      "z": 0,
      "name": "Rock_Ice"
    },
    {
      "x": -30,
      "y": 18,
      "z": 0,
      "name": "Rock_Ice"
    },
    {
      "x": -30,
      "y": 10,
      "z": 1,
      "name": "Rock_Ice"
    },
    {
      "x": -30,
      "y": 11,
      "z": 1,
      "name": "Rock_Ice"
    },
    {
      "x": -30,
      "y": 12,
      "z": 1,
      "name": "Rock_Ice"
    },
    {
      "x": -30,
      "y": 13,
      "z": 1,
      "name": "Rock_Ice"
    },
    {
      "x": -30,
      "y": 14,
      "z": 1,
      "name": "Rock_Ice"
    },
    {
      "x": -30,
      "y": 15,
      "z": 1,
      "name": "Rock_Ice"
    },
    {
      "x": -30,
      "y": 16,
      "z": 1,
      "name": "Rock_Ice"
    },
    {
      "x": -30,
      "y": 17,
      "z": 1,
      "name": "Rock_Ice"
    },
    {
      "x": -30,
      "y": 8,
      "z": 2,
      "name": "Rock_Ice"
    },
    {
      "x": -30,
      "y": 9,
      "z": 2,
      "name": "Rock_Ice"
    },
    {
      "x": -30,
      "y": 10,
      "z": 2,
      "name": "Rock_Ice"
    },
    {
      "x": -30,
      "y": 11,
      "z": 2,
      "name": "Rock_Ice"
    },
    {
      "x": -30,
      "y": 12,
      "z": 2,
      "name": "Rock_Ice"
    },
    {
      "x": -30,
      "y": 13,
      "z": 2,
      "name": "Rock_Ice"
    },
    {
      "x": -30,
      "y": 14,
      "z": 2,
      "name": "Rock_Ice"
    },
    {
      "x": -30,
      "y": 15,
      "z": 2,
      "name": "Rock_Ice"
    },
    {
      "x": -30,
      "y": 16,
      "z": 2,
      "name": "Rock_Ice"
    },
    {
      "x": -30,
      "y": 17,
      "z": 2,
      "name": "Rock_Ice"
    },
    {
      "x": -30,
      "y": 6,
      "z": 3,
      "name": "Rock_Ice"
    },
    {
      "x": -30,
      "y": 7,
      "z": 3,
      "name": "Rock_Ice"
    },
    {
      "x": -30,
      "y": 8,
      "z": 3,
      "name": "Rock_Ice"
    },
    {
      "x": -30,
      "y": 9,
      "z": 3,
      "name": "Rock_Ice"
    },
    {
      "x": -30,
      "y": 10,
      "z": 3,
      "name": "Rock_Ice"
    },
    {
      "x": -30,
      "y": 11,
      "z": 3,
      "name": "Rock_Ice"
    },
    {
      "x": -30,
      "y": 12,
      "z": 3,
      "name": "Rock_Ice"
    },
    {
      "x": -30,
      "y": 13,
      "z": 3,
      "name": "Rock_Ice"
    },
    {
      "x": -30,
      "y": 14,
      "z": 3,
      "name": "Rock_Ice"
    },
    {
      "x": -30,
      "y": 15,
      "z": 3,
      "name": "Rock_Ice"
    },
    {
      "x": -30,
      "y": 16,
      "z": 3,
      "name": "Rock_Ice"
    },
    {
      "x": -30,
      "y": 5,
      "z": 4,
      "name": "Rock_Ice"
    },
    {
      "x": -30,
      "y": 6,
      "z": 4,
      "name": "Rock_Ice"
    },
    {
      "x": -30,
      "y": 7,
      "z": 4,
      "name": "Rock_Ice"
    },
    {
      "x": -30,
      "y": 8,
      "z": 4,
      "name": "Rock_Ice"
    },
    {
      "x": -30,
      "y": 9,
      "z": 4,
      "name": "Rock_Ice"
    },
    {
      "x": -30,
      "y": 10,
      "z": 4,
      "name": "Rock_Ice"
    },
    {
      "x": -30,
      "y": 11,
      "z": 4,
      "name": "Rock_Ice"
    },
    {
      "x": -30,
      "y": 12,
      "z": 4,
      "name": "Rock_Ice"
    },
    {
      "x": -30,
      "y": 13,
      "z": 4,
      "name": "Rock_Ice"
    },
    {
      "x": -30,
      "y": 14,
      "z": 4,
      "name": "Rock_Ice"
    },
    {
      "x": -30,
      "y": 15,
      "z": 4,
      "name": "Rock_Ice"
    },
    {
      "x": -30,
      "y": 16,
      "z": 4,
      "name": "Rock_Ice"
    },
    {
      "x": -30,
      "y": 5,
      "z": 5,
      "name": "Rock_Ice"
    },
    {
      "x": -30,
      "y": 6,
      "z": 5,
      "name": "Rock_Ice"
    },
    {
      "x": -30,
      "y": 7,
      "z": 5,
      "name": "Rock_Ice"
    },
    {
      "x": -30,
      "y": 8,
      "z": 5,
      "name": "Rock_Ice"
    },
    {
      "x": -30,
      "y": 9,
      "z": 5,
      "name": "Rock_Ice"
    },
    {
      "x": -30,
      "y": 10,
      "z": 5,
      "name": "Rock_Ice"
    },
    {
      "x": -30,
      "y": 11,
      "z": 5,
      "name": "Rock_Ice"
    },
    {
      "x": -30,
      "y": 12,
      "z": 5,
      "name": "Rock_Ice"
    },
    {
      "x": -30,
      "y": 13,
      "z": 5,
      "name": "Rock_Ice"
    },
    {
      "x": -30,
      "y": 14,
      "z": 5,
      "name": "Rock_Ice"
    },
    {
      "x": -30,
      "y": 15,
      "z": 5,
      "name": "Rock_Ice"
    },
    {
      "x": -30,
      "y": 16,
      "z": 5,
      "name": "Soil_Snow"
    },
    {
      "x": -30,
      "y": 5,
      "z": 6,
      "name": "Rock_Ice"
    },
    {
      "x": -30,
      "y": 6,
      "z": 6,
      "name": "Rock_Ice"
    },
    {
      "x": -30,
      "y": 7,
      "z": 6,
      "name": "Rock_Ice"
    },
    {
      "x": -30,
      "y": 8,
      "z": 6,
      "name": "Rock_Ice"
    },
    {
      "x": -30,
      "y": 9,
      "z": 6,
      "name": "Rock_Ice"
    },
    {
      "x": -30,
      "y": 10,
      "z": 6,
      "name": "Rock_Ice"
    },
    {
      "x": -30,
      "y": 11,
      "z": 6,
      "name": "Rock_Ice"
    },
    {
      "x": -30,
      "y": 12,
      "z": 6,
      "name": "Rock_Ice"
    },
    {
      "x": -30,
      "y": 13,
      "z": 6,
      "name": "Rock_Ice"
    },
    {
      "x": -30,
      "y": 14,
      "z": 6,
      "name": "Rock_Ice"
    },
    {
      "x": -30,
      "y": 15,
      "z": 6,
      "name": "Rock_Ice"
    },
    {
      "x": -30,
      "y": 16,
      "z": 6,
      "name": "Soil_Snow"
    },
    {
      "x": -30,
      "y": 5,
      "z": 7,
      "name": "Rock_Ice"
    },
    {
      "x": -30,
      "y": 6,
      "z": 7,
      "name": "Rock_Ice"
    },
    {
      "x": -30,
      "y": 7,
      "z": 7,
      "name": "Rock_Ice"
    },
    {
      "x": -30,
      "y": 8,
      "z": 7,
      "name": "Rock_Ice"
    },
    {
      "x": -30,
      "y": 9,
      "z": 7,
      "name": "Rock_Ice"
    },
    {
      "x": -30,
      "y": 10,
      "z": 7,
      "name": "Rock_Ice"
    },
    {
      "x": -30,
      "y": 11,
      "z": 7,
      "name": "Rock_Ice"
    },
    {
      "x": -30,
      "y": 12,
      "z": 7,
      "name": "Rock_Ice"
    },
    {
      "x": -30,
      "y": 13,
      "z": 7,
      "name": "Rock_Ice"
    },
    {
      "x": -30,
      "y": 14,
      "z": 7,
      "name": "Rock_Ice"
    },
    {
      "x": -30,
      "y": 15,
      "z": 7,
      "name": "Soil_Snow"
    },
    {
      "x": -30,
      "y": 5,
      "z": 8,
      "name": "Rock_Ice_Permafrost"
    },
    {
      "x": -30,
      "y": 6,
      "z": 8,
      "name": "Rock_Ice"
    },
    {
      "x": -30,
      "y": 7,
      "z": 8,
      "name": "Rock_Ice"
    },
    {
      "x": -30,
      "y": 8,
      "z": 8,
      "name": "Rock_Ice"
    },
    {
      "x": -30,
      "y": 9,
      "z": 8,
      "name": "Rock_Ice"
    },
    {
      "x": -30,
      "y": 10,
      "z": 8,
      "name": "Rock_Ice"
    },
    {
      "x": -30,
      "y": 11,
      "z": 8,
      "name": "Rock_Ice"
    },
    {
      "x": -30,
      "y": 12,
      "z": 8,
      "name": "Rock_Ice"
    },
    {
      "x": -30,
      "y": 13,
      "z": 8,
      "name": "Rock_Ice"
    },
    {
      "x": -30,
      "y": 14,
      "z": 8,
      "name": "Rock_Ice"
    },
    {
      "x": -30,
      "y": 15,
      "z": 8,
      "name": "Soil_Snow"
    },
    {
      "x": -30,
      "y": 5,
      "z": 9,
      "name": "Rock_Ice"
    },
    {
      "x": -30,
      "y": 6,
      "z": 9,
      "name": "Rock_Ice_Permafrost"
    },
    {
      "x": -30,
      "y": 7,
      "z": 9,
      "name": "Rock_Ice"
    },
    {
      "x": -30,
      "y": 8,
      "z": 9,
      "name": "Rock_Ice"
    },
    {
      "x": -30,
      "y": 9,
      "z": 9,
      "name": "Rock_Ice"
    },
    {
      "x": -30,
      "y": 10,
      "z": 9,
      "name": "Rock_Ice"
    },
    {
      "x": -30,
      "y": 11,
      "z": 9,
      "name": "Rock_Ice"
    },
    {
      "x": -30,
      "y": 12,
      "z": 9,
      "name": "Rock_Ice"
    },
    {
      "x": -30,
      "y": 13,
      "z": 9,
      "name": "Rock_Ice_Permafrost"
    },
    {
      "x": -30,
      "y": 14,
      "z": 9,
      "name": "Soil_Snow"
    },
    {
      "x": -30,
      "y": 5,
      "z": 10,
      "name": "Rock_Ice"
    },
    {
      "x": -30,
      "y": 6,
      "z": 10,
      "name": "Rock_Ice"
    },
    {
      "x": -30,
      "y": 7,
      "z": 10,
      "name": "Rock_Ice"
    },
    {
      "x": -30,
      "y": 8,
      "z": 10,
      "name": "Rock_Ice_Permafrost"
    },
    {
      "x": -30,
      "y": 9,
      "z": 10,
      "name": "Rock_Ice"
    },
    {
      "x": -30,
      "y": 10,
      "z": 10,
      "name": "Rock_Ice"
    },
    {
      "x": -30,
      "y": 11,
      "z": 10,
      "name": "Rock_Ice_Permafrost"
    },
    {
      "x": -30,
      "y": 12,
      "z": 10,
      "name": "Rock_Ice"
    },
    {
      "x": -30,
      "y": 13,
      "z": 10,
      "name": "Rock_Ice_Permafrost"
    },
    {
      "x": -30,
      "y": 14,
      "z": 10,
      "name": "Rock_Ice_Permafrost"
    },
    {
      "x": -30,
      "y": 5,
      "z": 11,
      "name": "Rock_Ice_Permafrost"
    },
    {
      "x": -30,
      "y": 6,
      "z": 11,
      "name": "Rock_Ice_Permafrost"
    },
    {
      "x": -30,
      "y": 7,
      "z": 11,
      "name": "Rock_Ice_Permafrost"
    },
    {
      "x": -30,
      "y": 8,
      "z": 11,
      "name": "Rock_Ice_Permafrost"
    },
    {
      "x": -30,
      "y": 9,
      "z": 11,
      "name": "Rock_Ice"
    },
    {
      "x": -30,
      "y": 10,
      "z": 11,
      "name": "Rock_Ice_Permafrost"
    },
    {
      "x": -30,
      "y": 11,
      "z": 11,
      "name": "Rock_Ice_Permafrost"
    },
    {
      "x": -30,
      "y": 12,
      "z": 11,
      "name": "Rock_Ice_Permafrost"
    },
    {
      "x": -30,
      "y": 13,
      "z": 11,
      "name": "Soil_Snow"
    },
    {
      "x": -30,
      "y": 5,
      "z": 12,
      "name": "Rock_Ice"
    },
    {
      "x": -30,
      "y": 6,
      "z": 12,
      "name": "Rock_Ice_Permafrost"
    },
    {
      "x": -30,
      "y": 7,
      "z": 12,
      "name": "Rock_Ice_Permafrost"
    },
    {
      "x": -30,
      "y": 8,
      "z": 12,
      "name": "Rock_Ice"
    },
    {
      "x": -30,
      "y": 9,
      "z": 12,
      "name": "Rock_Ice"
    },
    {
      "x": -30,
      "y": 10,
      "z": 12,
      "name": "Rock_Ice_Permafrost"
    },
    {
      "x": -30,
      "y": 11,
      "z": 12,
      "name": "Rock_Ice"
    },
    {
      "x": -30,
      "y": 12,
      "z": 12,
      "name": "Soil_Snow"
    },
    {
      "x": -30,
      "y": 5,
      "z": 13,
      "name": "Rock_Ice_Permafrost"
    },
    {
      "x": -30,
      "y": 6,
      "z": 13,
      "name": "Rock_Ice_Permafrost"
    },
    {
      "x": -30,
      "y": 7,
      "z": 13,
      "name": "Rock_Ice"
    },
    {
      "x": -30,
      "y": 8,
      "z": 13,
      "name": "Rock_Ice"
    },
    {
      "x": -30,
      "y": 9,
      "z": 13,
      "name": "Rock_Ice"
    },
    {
      "x": -30,
      "y": 10,
      "z": 13,
      "name": "Rock_Ice"
    },
    {
      "x": -30,
      "y": 11,
      "z": 13,
      "name": "Rock_Ice_Permafrost"
    },
    {
      "x": -30,
      "y": 12,
      "z": 13,
      "name": "Soil_Snow"
    },
    {
      "x": -30,
      "y": 5,
      "z": 14,
      "name": "Rock_Ice"
    },
    {
      "x": -30,
      "y": 6,
      "z": 14,
      "name": "Rock_Ice"
    },
    {
      "x": -30,
      "y": 7,
      "z": 14,
      "name": "Rock_Ice"
    },
    {
      "x": -30,
      "y": 8,
      "z": 14,
      "name": "Rock_Ice"
    },
    {
      "x": -30,
      "y": 9,
      "z": 14,
      "name": "Rock_Ice"
    },
    {
      "x": -30,
      "y": 10,
      "z": 14,
      "name": "Rock_Ice"
    },
    {
      "x": -30,
      "y": 11,
      "z": 14,
      "name": "Soil_Snow"
    },
    {
      "x": -30,
      "y": 5,
      "z": 15,
      "name": "Rock_Ice"
    },
    {
      "x": -30,
      "y": 6,
      "z": 15,
      "name": "Rock_Ice"
    },
    {
      "x": -30,
      "y": 7,
      "z": 15,
      "name": "Rock_Ice_Permafrost"
    },
    {
      "x": -30,
      "y": 8,
      "z": 15,
      "name": "Rock_Ice_Permafrost"
    },
    {
      "x": -30,
      "y": 9,
      "z": 15,
      "name": "Rock_Ice_Permafrost"
    },
    {
      "x": -30,
      "y": 10,
      "z": 15,
      "name": "Rock_Ice"
    },
    {
      "x": -30,
      "y": 11,
      "z": 15,
      "name": "Soil_Snow"
    },
    {
      "x": -30,
      "y": 5,
      "z": 16,
      "name": "Rock_Ice"
    },
    {
      "x": -30,
      "y": 6,
      "z": 16,
      "name": "Rock_Ice"
    },
    {
      "x": -30,
      "y": 7,
      "z": 16,
      "name": "Rock_Ice"
    },
    {
      "x": -30,
      "y": 8,
      "z": 16,
      "name": "Rock_Ice"
    },
    {
      "x": -30,
      "y": 9,
      "z": 16,
      "name": "Rock_Ice"
    },
    {
      "x": -30,
      "y": 10,
      "z": 16,
      "name": "Rock_Ice"
    },
    {
      "x": -30,
      "y": 5,
      "z": 17,
      "name": "Rock_Ice_Permafrost"
    },
    {
      "x": -30,
      "y": 6,
      "z": 17,
      "name": "Rock_Ice"
    },
    {
      "x": -30,
      "y": 7,
      "z": 17,
      "name": "Rock_Ice_Permafrost"
    },
    {
      "x": -30,
      "y": 8,
      "z": 17,
      "name": "Soil_Snow"
    },
    {
      "x": -30,
      "y": 5,
      "z": 18,
      "name": "Rock_Ice"
    },
    {
      "x": -30,
      "y": 6,
      "z": 18,
      "name": "Rock_Ice"
    },
    {
      "x": -30,
      "y": 7,
      "z": 18,
      "name": "Rock_Ice"
    },
    {
      "x": -29,
      "y": 15,
      "z": -7,
      "name": "Rock_Ice"
    },
    {
      "x": -29,
      "y": 16,
      "z": -7,
      "name": "Soil_Snow"
    },
    {
      "x": -29,
      "y": 14,
      "z": -6,
      "name": "Rock_Ice"
    },
    {
      "x": -29,
      "y": 15,
      "z": -6,
      "name": "Rock_Ice"
    },
    {
      "x": -29,
      "y": 16,
      "z": -6,
      "name": "Rock_Ice"
    },
    {
      "x": -29,
      "y": 17,
      "z": -6,
      "name": "Soil_Snow"
    },
    {
      "x": -29,
      "y": 14,
      "z": -5,
      "name": "Rock_Ice"
    },
    {
      "x": -29,
      "y": 15,
      "z": -5,
      "name": "Rock_Ice"
    },
    {
      "x": -29,
      "y": 16,
      "z": -5,
      "name": "Rock_Ice"
    },
    {
      "x": -29,
      "y": 17,
      "z": -5,
      "name": "Rock_Ice"
    },
    {
      "x": -29,
      "y": 18,
      "z": -5,
      "name": "Soil_Snow"
    },
    {
      "x": -29,
      "y": 13,
      "z": -4,
      "name": "Rock_Ice"
    },
    {
      "x": -29,
      "y": 14,
      "z": -4,
      "name": "Rock_Ice"
    },
    {
      "x": -29,
      "y": 15,
      "z": -4,
      "name": "Rock_Ice"
    },
    {
      "x": -29,
      "y": 16,
      "z": -4,
      "name": "Rock_Ice"
    },
    {
      "x": -29,
      "y": 17,
      "z": -4,
      "name": "Rock_Ice"
    },
    {
      "x": -29,
      "y": 18,
      "z": -4,
      "name": "Soil_Snow"
    },
    {
      "x": -29,
      "y": 12,
      "z": -3,
      "name": "Rock_Ice"
    },
    {
      "x": -29,
      "y": 13,
      "z": -3,
      "name": "Rock_Ice"
    },
    {
      "x": -29,
      "y": 14,
      "z": -3,
      "name": "Rock_Ice"
    },
    {
      "x": -29,
      "y": 15,
      "z": -3,
      "name": "Rock_Ice"
    },
    {
      "x": -29,
      "y": 16,
      "z": -3,
      "name": "Rock_Ice"
    },
    {
      "x": -29,
      "y": 17,
      "z": -3,
      "name": "Rock_Ice"
    },
    {
      "x": -29,
      "y": 18,
      "z": -3,
      "name": "Rock_Ice"
    },
    {
      "x": -29,
      "y": 19,
      "z": -3,
      "name": "Soil_Snow"
    },
    {
      "x": -29,
      "y": 12,
      "z": -2,
      "name": "Rock_Ice"
    },
    {
      "x": -29,
      "y": 13,
      "z": -2,
      "name": "Rock_Ice"
    },
    {
      "x": -29,
      "y": 14,
      "z": -2,
      "name": "Rock_Ice"
    },
    {
      "x": -29,
      "y": 15,
      "z": -2,
      "name": "Rock_Ice"
    },
    {
      "x": -29,
      "y": 16,
      "z": -2,
      "name": "Rock_Ice"
    },
    {
      "x": -29,
      "y": 17,
      "z": -2,
      "name": "Rock_Ice"
    },
    {
      "x": -29,
      "y": 18,
      "z": -2,
      "name": "Rock_Ice"
    },
    {
      "x": -29,
      "y": 19,
      "z": -2,
      "name": "Soil_Snow"
    },
    {
      "x": -29,
      "y": 10,
      "z": -1,
      "name": "Rock_Ice"
    },
    {
      "x": -29,
      "y": 11,
      "z": -1,
      "name": "Rock_Ice"
    },
    {
      "x": -29,
      "y": 12,
      "z": -1,
      "name": "Rock_Ice"
    },
    {
      "x": -29,
      "y": 13,
      "z": -1,
      "name": "Rock_Ice"
    },
    {
      "x": -29,
      "y": 14,
      "z": -1,
      "name": "Rock_Ice"
    },
    {
      "x": -29,
      "y": 15,
      "z": -1,
      "name": "Rock_Ice"
    },
    {
      "x": -29,
      "y": 16,
      "z": -1,
      "name": "Rock_Ice"
    },
    {
      "x": -29,
      "y": 17,
      "z": -1,
      "name": "Rock_Ice"
    },
    {
      "x": -29,
      "y": 18,
      "z": -1,
      "name": "Rock_Ice"
    },
    {
      "x": -29,
      "y": 19,
      "z": -1,
      "name": "Soil_Snow"
    },
    {
      "x": -29,
      "y": 9,
      "z": 0,
      "name": "Rock_Ice"
    },
    {
      "x": -29,
      "y": 10,
      "z": 0,
      "name": "Rock_Ice"
    },
    {
      "x": -29,
      "y": 11,
      "z": 0,
      "name": "Rock_Ice"
    },
    {
      "x": -29,
      "y": 12,
      "z": 0,
      "name": "Rock_Ice"
    },
    {
      "x": -29,
      "y": 13,
      "z": 0,
      "name": "Rock_Ice"
    },
    {
      "x": -29,
      "y": 14,
      "z": 0,
      "name": "Rock_Ice"
    },
    {
      "x": -29,
      "y": 15,
      "z": 0,
      "name": "Rock_Ice"
    },
    {
      "x": -29,
      "y": 16,
      "z": 0,
      "name": "Rock_Ice"
    },
    {
      "x": -29,
      "y": 17,
      "z": 0,
      "name": "Rock_Ice"
    },
    {
      "x": -29,
      "y": 18,
      "z": 0,
      "name": "Rock_Ice"
    },
    {
      "x": -29,
      "y": 19,
      "z": 0,
      "name": "Rock_Ice"
    },
    {
      "x": -29,
      "y": 7,
      "z": 1,
      "name": "Rock_Ice"
    },
    {
      "x": -29,
      "y": 8,
      "z": 1,
      "name": "Rock_Ice"
    },
    {
      "x": -29,
      "y": 9,
      "z": 1,
      "name": "Rock_Ice"
    },
    {
      "x": -29,
      "y": 10,
      "z": 1,
      "name": "Rock_Ice"
    },
    {
      "x": -29,
      "y": 11,
      "z": 1,
      "name": "Rock_Ice"
    },
    {
      "x": -29,
      "y": 12,
      "z": 1,
      "name": "Rock_Ice"
    },
    {
      "x": -29,
      "y": 13,
      "z": 1,
      "name": "Rock_Ice"
    },
    {
      "x": -29,
      "y": 14,
      "z": 1,
      "name": "Rock_Ice"
    },
    {
      "x": -29,
      "y": 15,
      "z": 1,
      "name": "Rock_Ice"
    },
    {
      "x": -29,
      "y": 16,
      "z": 1,
      "name": "Rock_Ice"
    },
    {
      "x": -29,
      "y": 17,
      "z": 1,
      "name": "Rock_Ice"
    },
    {
      "x": -29,
      "y": 18,
      "z": 1,
      "name": "Rock_Ice"
    },
    {
      "x": -29,
      "y": 19,
      "z": 1,
      "name": "Soil_Snow"
    },
    {
      "x": -29,
      "y": 5,
      "z": 2,
      "name": "Rock_Ice"
    },
    {
      "x": -29,
      "y": 6,
      "z": 2,
      "name": "Rock_Ice"
    },
    {
      "x": -29,
      "y": 7,
      "z": 2,
      "name": "Rock_Ice"
    },
    {
      "x": -29,
      "y": 8,
      "z": 2,
      "name": "Rock_Ice"
    },
    {
      "x": -29,
      "y": 9,
      "z": 2,
      "name": "Rock_Ice"
    },
    {
      "x": -29,
      "y": 10,
      "z": 2,
      "name": "Rock_Ice"
    },
    {
      "x": -29,
      "y": 11,
      "z": 2,
      "name": "Rock_Ice"
    },
    {
      "x": -29,
      "y": 12,
      "z": 2,
      "name": "Rock_Ice"
    },
    {
      "x": -29,
      "y": 13,
      "z": 2,
      "name": "Rock_Ice"
    },
    {
      "x": -29,
      "y": 14,
      "z": 2,
      "name": "Rock_Ice"
    },
    {
      "x": -29,
      "y": 15,
      "z": 2,
      "name": "Rock_Ice"
    },
    {
      "x": -29,
      "y": 16,
      "z": 2,
      "name": "Rock_Ice"
    },
    {
      "x": -29,
      "y": 17,
      "z": 2,
      "name": "Rock_Ice"
    },
    {
      "x": -29,
      "y": 18,
      "z": 2,
      "name": "Soil_Snow"
    },
    {
      "x": -29,
      "y": 5,
      "z": 3,
      "name": "Rock_Ice"
    },
    {
      "x": -29,
      "y": 6,
      "z": 3,
      "name": "Rock_Ice"
    },
    {
      "x": -29,
      "y": 7,
      "z": 3,
      "name": "Rock_Ice"
    },
    {
      "x": -29,
      "y": 8,
      "z": 3,
      "name": "Rock_Ice"
    },
    {
      "x": -29,
      "y": 9,
      "z": 3,
      "name": "Rock_Ice"
    },
    {
      "x": -29,
      "y": 10,
      "z": 3,
      "name": "Rock_Ice"
    },
    {
      "x": -29,
      "y": 11,
      "z": 3,
      "name": "Rock_Ice"
    },
    {
      "x": -29,
      "y": 12,
      "z": 3,
      "name": "Rock_Ice"
    },
    {
      "x": -29,
      "y": 13,
      "z": 3,
      "name": "Rock_Ice"
    },
    {
      "x": -29,
      "y": 14,
      "z": 3,
      "name": "Rock_Ice"
    },
    {
      "x": -29,
      "y": 15,
      "z": 3,
      "name": "Rock_Ice"
    },
    {
      "x": -29,
      "y": 16,
      "z": 3,
      "name": "Rock_Ice"
    },
    {
      "x": -29,
      "y": 17,
      "z": 3,
      "name": "Rock_Ice"
    },
    {
      "x": -29,
      "y": 18,
      "z": 3,
      "name": "Soil_Snow"
    },
    {
      "x": -29,
      "y": 5,
      "z": 4,
      "name": "Rock_Ice"
    },
    {
      "x": -29,
      "y": 6,
      "z": 4,
      "name": "Rock_Ice"
    },
    {
      "x": -29,
      "y": 7,
      "z": 4,
      "name": "Rock_Ice"
    },
    {
      "x": -29,
      "y": 8,
      "z": 4,
      "name": "Rock_Ice"
    },
    {
      "x": -29,
      "y": 9,
      "z": 4,
      "name": "Rock_Ice"
    },
    {
      "x": -29,
      "y": 10,
      "z": 4,
      "name": "Rock_Ice"
    },
    {
      "x": -29,
      "y": 11,
      "z": 4,
      "name": "Rock_Ice"
    },
    {
      "x": -29,
      "y": 12,
      "z": 4,
      "name": "Rock_Ice"
    },
    {
      "x": -29,
      "y": 13,
      "z": 4,
      "name": "Rock_Ice"
    },
    {
      "x": -29,
      "y": 14,
      "z": 4,
      "name": "Rock_Ice"
    },
    {
      "x": -29,
      "y": 15,
      "z": 4,
      "name": "Rock_Ice"
    },
    {
      "x": -29,
      "y": 16,
      "z": 4,
      "name": "Rock_Ice"
    },
    {
      "x": -29,
      "y": 17,
      "z": 4,
      "name": "Soil_Snow"
    },
    {
      "x": -29,
      "y": 5,
      "z": 5,
      "name": "Rock_Ice"
    },
    {
      "x": -29,
      "y": 6,
      "z": 5,
      "name": "Rock_Ice"
    },
    {
      "x": -29,
      "y": 7,
      "z": 5,
      "name": "Rock_Ice"
    },
    {
      "x": -29,
      "y": 8,
      "z": 5,
      "name": "Rock_Ice"
    },
    {
      "x": -29,
      "y": 9,
      "z": 5,
      "name": "Rock_Ice"
    },
    {
      "x": -29,
      "y": 10,
      "z": 5,
      "name": "Rock_Ice"
    },
    {
      "x": -29,
      "y": 11,
      "z": 5,
      "name": "Rock_Ice"
    },
    {
      "x": -29,
      "y": 12,
      "z": 5,
      "name": "Rock_Ice"
    },
    {
      "x": -29,
      "y": 13,
      "z": 5,
      "name": "Rock_Ice"
    },
    {
      "x": -29,
      "y": 14,
      "z": 5,
      "name": "Rock_Ice"
    },
    {
      "x": -29,
      "y": 15,
      "z": 5,
      "name": "Rock_Ice"
    },
    {
      "x": -29,
      "y": 16,
      "z": 5,
      "name": "Rock_Ice"
    },
    {
      "x": -29,
      "y": 17,
      "z": 5,
      "name": "Soil_Snow"
    },
    {
      "x": -29,
      "y": 5,
      "z": 6,
      "name": "Rock_Ice"
    },
    {
      "x": -29,
      "y": 6,
      "z": 6,
      "name": "Rock_Ice"
    },
    {
      "x": -29,
      "y": 7,
      "z": 6,
      "name": "Rock_Ice"
    },
    {
      "x": -29,
      "y": 8,
      "z": 6,
      "name": "Rock_Ice"
    },
    {
      "x": -29,
      "y": 9,
      "z": 6,
      "name": "Rock_Ice"
    },
    {
      "x": -29,
      "y": 10,
      "z": 6,
      "name": "Rock_Ice"
    },
    {
      "x": -29,
      "y": 11,
      "z": 6,
      "name": "Rock_Ice"
    },
    {
      "x": -29,
      "y": 12,
      "z": 6,
      "name": "Rock_Ice"
    },
    {
      "x": -29,
      "y": 13,
      "z": 6,
      "name": "Rock_Ice"
    },
    {
      "x": -29,
      "y": 14,
      "z": 6,
      "name": "Rock_Ice"
    },
    {
      "x": -29,
      "y": 15,
      "z": 6,
      "name": "Rock_Ice"
    },
    {
      "x": -29,
      "y": 16,
      "z": 6,
      "name": "Rock_Ice"
    },
    {
      "x": -29,
      "y": 17,
      "z": 6,
      "name": "Soil_Snow"
    },
    {
      "x": -29,
      "y": 5,
      "z": 7,
      "name": "Rock_Ice"
    },
    {
      "x": -29,
      "y": 6,
      "z": 7,
      "name": "Rock_Ice"
    },
    {
      "x": -29,
      "y": 7,
      "z": 7,
      "name": "Rock_Ice"
    },
    {
      "x": -29,
      "y": 8,
      "z": 7,
      "name": "Rock_Ice"
    },
    {
      "x": -29,
      "y": 9,
      "z": 7,
      "name": "Rock_Ice"
    },
    {
      "x": -29,
      "y": 10,
      "z": 7,
      "name": "Rock_Ice"
    },
    {
      "x": -29,
      "y": 11,
      "z": 7,
      "name": "Rock_Ice"
    },
    {
      "x": -29,
      "y": 12,
      "z": 7,
      "name": "Rock_Ice"
    },
    {
      "x": -29,
      "y": 13,
      "z": 7,
      "name": "Rock_Ice"
    },
    {
      "x": -29,
      "y": 14,
      "z": 7,
      "name": "Rock_Ice"
    },
    {
      "x": -29,
      "y": 15,
      "z": 7,
      "name": "Rock_Ice"
    },
    {
      "x": -29,
      "y": 16,
      "z": 7,
      "name": "Soil_Snow"
    },
    {
      "x": -29,
      "y": 5,
      "z": 8,
      "name": "Rock_Ice"
    },
    {
      "x": -29,
      "y": 6,
      "z": 8,
      "name": "Rock_Ice"
    },
    {
      "x": -29,
      "y": 7,
      "z": 8,
      "name": "Rock_Ice"
    },
    {
      "x": -29,
      "y": 8,
      "z": 8,
      "name": "Rock_Ice"
    },
    {
      "x": -29,
      "y": 9,
      "z": 8,
      "name": "Rock_Ice"
    },
    {
      "x": -29,
      "y": 10,
      "z": 8,
      "name": "Rock_Ice"
    },
    {
      "x": -29,
      "y": 11,
      "z": 8,
      "name": "Rock_Ice"
    },
    {
      "x": -29,
      "y": 12,
      "z": 8,
      "name": "Rock_Ice"
    },
    {
      "x": -29,
      "y": 13,
      "z": 8,
      "name": "Rock_Ice"
    },
    {
      "x": -29,
      "y": 14,
      "z": 8,
      "name": "Rock_Ice"
    },
    {
      "x": -29,
      "y": 15,
      "z": 8,
      "name": "Rock_Ice"
    },
    {
      "x": -29,
      "y": 16,
      "z": 8,
      "name": "Soil_Snow"
    },
    {
      "x": -29,
      "y": 5,
      "z": 9,
      "name": "Rock_Ice"
    },
    {
      "x": -29,
      "y": 6,
      "z": 9,
      "name": "Rock_Ice"
    },
    {
      "x": -29,
      "y": 7,
      "z": 9,
      "name": "Rock_Ice"
    },
    {
      "x": -29,
      "y": 8,
      "z": 9,
      "name": "Rock_Ice"
    },
    {
      "x": -29,
      "y": 9,
      "z": 9,
      "name": "Rock_Ice"
    },
    {
      "x": -29,
      "y": 10,
      "z": 9,
      "name": "Rock_Ice"
    },
    {
      "x": -29,
      "y": 11,
      "z": 9,
      "name": "Rock_Ice"
    },
    {
      "x": -29,
      "y": 12,
      "z": 9,
      "name": "Rock_Ice"
    },
    {
      "x": -29,
      "y": 13,
      "z": 9,
      "name": "Rock_Ice"
    },
    {
      "x": -29,
      "y": 14,
      "z": 9,
      "name": "Rock_Ice"
    },
    {
      "x": -29,
      "y": 15,
      "z": 9,
      "name": "Soil_Snow"
    },
    {
      "x": -29,
      "y": 5,
      "z": 10,
      "name": "Rock_Ice"
    },
    {
      "x": -29,
      "y": 6,
      "z": 10,
      "name": "Rock_Ice"
    },
    {
      "x": -29,
      "y": 7,
      "z": 10,
      "name": "Rock_Ice"
    },
    {
      "x": -29,
      "y": 8,
      "z": 10,
      "name": "Rock_Ice"
    },
    {
      "x": -29,
      "y": 9,
      "z": 10,
      "name": "Rock_Ice"
    },
    {
      "x": -29,
      "y": 10,
      "z": 10,
      "name": "Rock_Ice"
    },
    {
      "x": -29,
      "y": 11,
      "z": 10,
      "name": "Rock_Ice"
    },
    {
      "x": -29,
      "y": 12,
      "z": 10,
      "name": "Rock_Ice"
    },
    {
      "x": -29,
      "y": 13,
      "z": 10,
      "name": "Rock_Ice"
    },
    {
      "x": -29,
      "y": 14,
      "z": 10,
      "name": "Soil_Snow"
    },
    {
      "x": -29,
      "y": 5,
      "z": 11,
      "name": "Rock_Ice"
    },
    {
      "x": -29,
      "y": 6,
      "z": 11,
      "name": "Rock_Ice"
    },
    {
      "x": -29,
      "y": 7,
      "z": 11,
      "name": "Rock_Ice"
    },
    {
      "x": -29,
      "y": 8,
      "z": 11,
      "name": "Rock_Ice"
    },
    {
      "x": -29,
      "y": 9,
      "z": 11,
      "name": "Rock_Ice_Permafrost"
    },
    {
      "x": -29,
      "y": 10,
      "z": 11,
      "name": "Rock_Ice"
    },
    {
      "x": -29,
      "y": 11,
      "z": 11,
      "name": "Rock_Ice"
    },
    {
      "x": -29,
      "y": 12,
      "z": 11,
      "name": "Rock_Ice_Permafrost"
    },
    {
      "x": -29,
      "y": 13,
      "z": 11,
      "name": "Rock_Ice_Permafrost"
    },
    {
      "x": -29,
      "y": 14,
      "z": 11,
      "name": "Soil_Snow"
    },
    {
      "x": -29,
      "y": 5,
      "z": 12,
      "name": "Rock_Ice"
    },
    {
      "x": -29,
      "y": 6,
      "z": 12,
      "name": "Rock_Ice"
    },
    {
      "x": -29,
      "y": 7,
      "z": 12,
      "name": "Rock_Ice_Permafrost"
    },
    {
      "x": -29,
      "y": 8,
      "z": 12,
      "name": "Rock_Ice_Permafrost"
    },
    {
      "x": -29,
      "y": 9,
      "z": 12,
      "name": "Rock_Ice_Permafrost"
    },
    {
      "x": -29,
      "y": 10,
      "z": 12,
      "name": "Rock_Ice_Permafrost"
    },
    {
      "x": -29,
      "y": 11,
      "z": 12,
      "name": "Rock_Ice_Permafrost"
    },
    {
      "x": -29,
      "y": 12,
      "z": 12,
      "name": "Rock_Ice_Permafrost"
    },
    {
      "x": -29,
      "y": 13,
      "z": 12,
      "name": "Soil_Snow"
    },
    {
      "x": -29,
      "y": 5,
      "z": 13,
      "name": "Rock_Ice_Permafrost"
    },
    {
      "x": -29,
      "y": 6,
      "z": 13,
      "name": "Rock_Ice_Permafrost"
    },
    {
      "x": -29,
      "y": 7,
      "z": 13,
      "name": "Rock_Ice_Permafrost"
    },
    {
      "x": -29,
      "y": 8,
      "z": 13,
      "name": "Rock_Ice"
    },
    {
      "x": -29,
      "y": 9,
      "z": 13,
      "name": "Rock_Ice_Permafrost"
    },
    {
      "x": -29,
      "y": 10,
      "z": 13,
      "name": "Rock_Ice"
    },
    {
      "x": -29,
      "y": 11,
      "z": 13,
      "name": "Rock_Ice_Permafrost"
    },
    {
      "x": -29,
      "y": 12,
      "z": 13,
      "name": "Rock_Ice_Permafrost"
    },
    {
      "x": -29,
      "y": 13,
      "z": 13,
      "name": "Soil_Snow"
    },
    {
      "x": -29,
      "y": 5,
      "z": 14,
      "name": "Rock_Ice"
    },
    {
      "x": -29,
      "y": 6,
      "z": 14,
      "name": "Rock_Ice"
    },
    {
      "x": -29,
      "y": 7,
      "z": 14,
      "name": "Rock_Ice_Permafrost"
    },
    {
      "x": -29,
      "y": 8,
      "z": 14,
      "name": "Rock_Ice"
    },
    {
      "x": -29,
      "y": 9,
      "z": 14,
      "name": "Rock_Ice"
    },
    {
      "x": -29,
      "y": 10,
      "z": 14,
      "name": "Rock_Ice"
    },
    {
      "x": -29,
      "y": 11,
      "z": 14,
      "name": "Rock_Ice_Permafrost"
    },
    {
      "x": -29,
      "y": 12,
      "z": 14,
      "name": "Soil_Snow"
    },
    {
      "x": -29,
      "y": 5,
      "z": 15,
      "name": "Rock_Ice"
    },
    {
      "x": -29,
      "y": 6,
      "z": 15,
      "name": "Rock_Ice_Permafrost"
    },
    {
      "x": -29,
      "y": 7,
      "z": 15,
      "name": "Rock_Ice"
    },
    {
      "x": -29,
      "y": 8,
      "z": 15,
      "name": "Rock_Ice_Permafrost"
    },
    {
      "x": -29,
      "y": 9,
      "z": 15,
      "name": "Rock_Ice_Permafrost"
    },
    {
      "x": -29,
      "y": 10,
      "z": 15,
      "name": "Rock_Ice_Permafrost"
    },
    {
      "x": -29,
      "y": 11,
      "z": 15,
      "name": "Soil_Snow"
    },
    {
      "x": -29,
      "y": 5,
      "z": 16,
      "name": "Rock_Ice"
    },
    {
      "x": -29,
      "y": 6,
      "z": 16,
      "name": "Rock_Ice"
    },
    {
      "x": -29,
      "y": 7,
      "z": 16,
      "name": "Rock_Ice"
    },
    {
      "x": -29,
      "y": 8,
      "z": 16,
      "name": "Rock_Ice"
    },
    {
      "x": -29,
      "y": 9,
      "z": 16,
      "name": "Rock_Ice"
    },
    {
      "x": -29,
      "y": 10,
      "z": 16,
      "name": "Rock_Ice_Permafrost"
    },
    {
      "x": -29,
      "y": 11,
      "z": 16,
      "name": "Soil_Snow"
    },
    {
      "x": -29,
      "y": 5,
      "z": 17,
      "name": "Rock_Ice"
    },
    {
      "x": -29,
      "y": 6,
      "z": 17,
      "name": "Rock_Ice"
    },
    {
      "x": -29,
      "y": 7,
      "z": 17,
      "name": "Rock_Ice"
    },
    {
      "x": -29,
      "y": 8,
      "z": 17,
      "name": "Rock_Ice"
    },
    {
      "x": -29,
      "y": 9,
      "z": 17,
      "name": "Rock_Ice"
    },
    {
      "x": -29,
      "y": 10,
      "z": 17,
      "name": "Soil_Snow"
    },
    {
      "x": -29,
      "y": 5,
      "z": 18,
      "name": "Rock_Ice"
    },
    {
      "x": -29,
      "y": 6,
      "z": 18,
      "name": "Rock_Ice"
    },
    {
      "x": -29,
      "y": 7,
      "z": 18,
      "name": "Rock_Ice"
    },
    {
      "x": -29,
      "y": 8,
      "z": 18,
      "name": "Rock_Ice"
    },
    {
      "x": -29,
      "y": 5,
      "z": 19,
      "name": "Rock_Ice"
    },
    {
      "x": -29,
      "y": 6,
      "z": 19,
      "name": "Rock_Ice"
    },
    {
      "x": -29,
      "y": 7,
      "z": 19,
      "name": "Rock_Ice"
    },
    {
      "x": -28,
      "y": 14,
      "z": -8,
      "name": "Rock_Ice"
    },
    {
      "x": -28,
      "y": 15,
      "z": -8,
      "name": "Rock_Ice"
    },
    {
      "x": -28,
      "y": 16,
      "z": -8,
      "name": "Rock_Ice"
    },
    {
      "x": -28,
      "y": 17,
      "z": -8,
      "name": "Soil_Snow"
    },
    {
      "x": -28,
      "y": 14,
      "z": -7,
      "name": "Rock_Ice"
    },
    {
      "x": -28,
      "y": 15,
      "z": -7,
      "name": "Rock_Ice"
    },
    {
      "x": -28,
      "y": 16,
      "z": -7,
      "name": "Rock_Ice"
    },
    {
      "x": -28,
      "y": 17,
      "z": -7,
      "name": "Rock_Ice"
    },
    {
      "x": -28,
      "y": 18,
      "z": -7,
      "name": "Soil_Snow"
    },
    {
      "x": -28,
      "y": 13,
      "z": -6,
      "name": "Rock_Ice"
    },
    {
      "x": -28,
      "y": 14,
      "z": -6,
      "name": "Rock_Ice"
    },
    {
      "x": -28,
      "y": 15,
      "z": -6,
      "name": "Rock_Ice"
    },
    {
      "x": -28,
      "y": 16,
      "z": -6,
      "name": "Rock_Ice"
    },
    {
      "x": -28,
      "y": 17,
      "z": -6,
      "name": "Rock_Ice"
    },
    {
      "x": -28,
      "y": 18,
      "z": -6,
      "name": "Soil_Snow"
    },
    {
      "x": -28,
      "y": 12,
      "z": -5,
      "name": "Rock_Ice"
    },
    {
      "x": -28,
      "y": 13,
      "z": -5,
      "name": "Rock_Ice"
    },
    {
      "x": -28,
      "y": 14,
      "z": -5,
      "name": "Rock_Ice"
    },
    {
      "x": -28,
      "y": 15,
      "z": -5,
      "name": "Rock_Ice"
    },
    {
      "x": -28,
      "y": 16,
      "z": -5,
      "name": "Rock_Ice"
    },
    {
      "x": -28,
      "y": 17,
      "z": -5,
      "name": "Rock_Ice"
    },
    {
      "x": -28,
      "y": 18,
      "z": -5,
      "name": "Rock_Ice"
    },
    {
      "x": -28,
      "y": 19,
      "z": -5,
      "name": "Soil_Snow"
    },
    {
      "x": -28,
      "y": 12,
      "z": -4,
      "name": "Rock_Ice"
    },
    {
      "x": -28,
      "y": 13,
      "z": -4,
      "name": "Rock_Ice"
    },
    {
      "x": -28,
      "y": 14,
      "z": -4,
      "name": "Rock_Ice"
    },
    {
      "x": -28,
      "y": 15,
      "z": -4,
      "name": "Rock_Ice"
    },
    {
      "x": -28,
      "y": 16,
      "z": -4,
      "name": "Rock_Ice"
    },
    {
      "x": -28,
      "y": 17,
      "z": -4,
      "name": "Rock_Ice"
    },
    {
      "x": -28,
      "y": 18,
      "z": -4,
      "name": "Rock_Ice"
    },
    {
      "x": -28,
      "y": 19,
      "z": -4,
      "name": "Soil_Snow"
    },
    {
      "x": -28,
      "y": 11,
      "z": -3,
      "name": "Rock_Ice"
    },
    {
      "x": -28,
      "y": 12,
      "z": -3,
      "name": "Rock_Ice"
    },
    {
      "x": -28,
      "y": 13,
      "z": -3,
      "name": "Rock_Ice"
    },
    {
      "x": -28,
      "y": 14,
      "z": -3,
      "name": "Rock_Ice"
    },
    {
      "x": -28,
      "y": 15,
      "z": -3,
      "name": "Rock_Ice"
    },
    {
      "x": -28,
      "y": 16,
      "z": -3,
      "name": "Rock_Ice"
    },
    {
      "x": -28,
      "y": 17,
      "z": -3,
      "name": "Rock_Ice"
    },
    {
      "x": -28,
      "y": 18,
      "z": -3,
      "name": "Rock_Ice"
    },
    {
      "x": -28,
      "y": 19,
      "z": -3,
      "name": "Soil_Snow"
    },
    {
      "x": -28,
      "y": 9,
      "z": -2,
      "name": "Rock_Ice"
    },
    {
      "x": -28,
      "y": 10,
      "z": -2,
      "name": "Rock_Ice"
    },
    {
      "x": -28,
      "y": 11,
      "z": -2,
      "name": "Rock_Ice"
    },
    {
      "x": -28,
      "y": 12,
      "z": -2,
      "name": "Rock_Ice"
    },
    {
      "x": -28,
      "y": 13,
      "z": -2,
      "name": "Rock_Ice"
    },
    {
      "x": -28,
      "y": 14,
      "z": -2,
      "name": "Rock_Ice"
    },
    {
      "x": -28,
      "y": 15,
      "z": -2,
      "name": "Rock_Ice"
    },
    {
      "x": -28,
      "y": 16,
      "z": -2,
      "name": "Rock_Ice"
    },
    {
      "x": -28,
      "y": 17,
      "z": -2,
      "name": "Rock_Ice"
    },
    {
      "x": -28,
      "y": 18,
      "z": -2,
      "name": "Rock_Ice"
    },
    {
      "x": -28,
      "y": 19,
      "z": -2,
      "name": "Soil_Snow"
    },
    {
      "x": -28,
      "y": 8,
      "z": -1,
      "name": "Rock_Ice"
    },
    {
      "x": -28,
      "y": 9,
      "z": -1,
      "name": "Rock_Ice"
    },
    {
      "x": -28,
      "y": 10,
      "z": -1,
      "name": "Rock_Ice"
    },
    {
      "x": -28,
      "y": 11,
      "z": -1,
      "name": "Rock_Ice"
    },
    {
      "x": -28,
      "y": 12,
      "z": -1,
      "name": "Rock_Ice"
    },
    {
      "x": -28,
      "y": 13,
      "z": -1,
      "name": "Rock_Ice"
    },
    {
      "x": -28,
      "y": 14,
      "z": -1,
      "name": "Rock_Ice"
    },
    {
      "x": -28,
      "y": 15,
      "z": -1,
      "name": "Rock_Ice"
    },
    {
      "x": -28,
      "y": 16,
      "z": -1,
      "name": "Rock_Ice"
    },
    {
      "x": -28,
      "y": 17,
      "z": -1,
      "name": "Rock_Ice"
    },
    {
      "x": -28,
      "y": 18,
      "z": -1,
      "name": "Rock_Ice"
    },
    {
      "x": -28,
      "y": 19,
      "z": -1,
      "name": "Soil_Snow"
    },
    {
      "x": -28,
      "y": 6,
      "z": 0,
      "name": "Rock_Ice"
    },
    {
      "x": -28,
      "y": 7,
      "z": 0,
      "name": "Rock_Ice"
    },
    {
      "x": -28,
      "y": 8,
      "z": 0,
      "name": "Rock_Ice"
    },
    {
      "x": -28,
      "y": 9,
      "z": 0,
      "name": "Rock_Ice"
    },
    {
      "x": -28,
      "y": 10,
      "z": 0,
      "name": "Rock_Ice"
    },
    {
      "x": -28,
      "y": 11,
      "z": 0,
      "name": "Rock_Ice"
    },
    {
      "x": -28,
      "y": 12,
      "z": 0,
      "name": "Rock_Ice"
    },
    {
      "x": -28,
      "y": 13,
      "z": 0,
      "name": "Rock_Ice"
    },
    {
      "x": -28,
      "y": 14,
      "z": 0,
      "name": "Rock_Ice"
    },
    {
      "x": -28,
      "y": 15,
      "z": 0,
      "name": "Rock_Ice"
    },
    {
      "x": -28,
      "y": 16,
      "z": 0,
      "name": "Rock_Ice"
    },
    {
      "x": -28,
      "y": 17,
      "z": 0,
      "name": "Rock_Ice"
    },
    {
      "x": -28,
      "y": 18,
      "z": 0,
      "name": "Rock_Ice"
    },
    {
      "x": -28,
      "y": 19,
      "z": 0,
      "name": "Rock_Ice"
    },
    {
      "x": -28,
      "y": 5,
      "z": 1,
      "name": "Rock_Ice"
    },
    {
      "x": -28,
      "y": 6,
      "z": 1,
      "name": "Rock_Ice"
    },
    {
      "x": -28,
      "y": 7,
      "z": 1,
      "name": "Rock_Ice"
    },
    {
      "x": -28,
      "y": 8,
      "z": 1,
      "name": "Rock_Ice"
    },
    {
      "x": -28,
      "y": 9,
      "z": 1,
      "name": "Rock_Ice"
    },
    {
      "x": -28,
      "y": 10,
      "z": 1,
      "name": "Rock_Ice"
    },
    {
      "x": -28,
      "y": 11,
      "z": 1,
      "name": "Rock_Ice"
    },
    {
      "x": -28,
      "y": 12,
      "z": 1,
      "name": "Rock_Ice"
    },
    {
      "x": -28,
      "y": 13,
      "z": 1,
      "name": "Rock_Ice"
    },
    {
      "x": -28,
      "y": 14,
      "z": 1,
      "name": "Rock_Ice"
    },
    {
      "x": -28,
      "y": 15,
      "z": 1,
      "name": "Rock_Ice"
    },
    {
      "x": -28,
      "y": 16,
      "z": 1,
      "name": "Rock_Ice"
    },
    {
      "x": -28,
      "y": 17,
      "z": 1,
      "name": "Rock_Ice"
    },
    {
      "x": -28,
      "y": 18,
      "z": 1,
      "name": "Rock_Ice"
    },
    {
      "x": -28,
      "y": 19,
      "z": 1,
      "name": "Rock_Ice"
    },
    {
      "x": -28,
      "y": 5,
      "z": 2,
      "name": "Rock_Ice"
    },
    {
      "x": -28,
      "y": 6,
      "z": 2,
      "name": "Rock_Ice"
    },
    {
      "x": -28,
      "y": 7,
      "z": 2,
      "name": "Rock_Ice"
    },
    {
      "x": -28,
      "y": 8,
      "z": 2,
      "name": "Rock_Ice"
    },
    {
      "x": -28,
      "y": 9,
      "z": 2,
      "name": "Rock_Ice"
    },
    {
      "x": -28,
      "y": 10,
      "z": 2,
      "name": "Rock_Ice"
    },
    {
      "x": -28,
      "y": 11,
      "z": 2,
      "name": "Rock_Ice"
    },
    {
      "x": -28,
      "y": 12,
      "z": 2,
      "name": "Rock_Ice"
    },
    {
      "x": -28,
      "y": 13,
      "z": 2,
      "name": "Rock_Ice"
    },
    {
      "x": -28,
      "y": 14,
      "z": 2,
      "name": "Rock_Ice"
    },
    {
      "x": -28,
      "y": 15,
      "z": 2,
      "name": "Rock_Ice"
    },
    {
      "x": -28,
      "y": 16,
      "z": 2,
      "name": "Rock_Ice"
    },
    {
      "x": -28,
      "y": 17,
      "z": 2,
      "name": "Rock_Ice"
    },
    {
      "x": -28,
      "y": 18,
      "z": 2,
      "name": "Rock_Ice"
    },
    {
      "x": -28,
      "y": 19,
      "z": 2,
      "name": "Soil_Snow"
    },
    {
      "x": -28,
      "y": 5,
      "z": 3,
      "name": "Rock_Ice"
    },
    {
      "x": -28,
      "y": 6,
      "z": 3,
      "name": "Rock_Ice"
    },
    {
      "x": -28,
      "y": 7,
      "z": 3,
      "name": "Rock_Ice"
    },
    {
      "x": -28,
      "y": 8,
      "z": 3,
      "name": "Rock_Ice"
    },
    {
      "x": -28,
      "y": 9,
      "z": 3,
      "name": "Rock_Ice"
    },
    {
      "x": -28,
      "y": 10,
      "z": 3,
      "name": "Rock_Ice"
    },
    {
      "x": -28,
      "y": 11,
      "z": 3,
      "name": "Rock_Ice"
    },
    {
      "x": -28,
      "y": 12,
      "z": 3,
      "name": "Rock_Ice"
    },
    {
      "x": -28,
      "y": 13,
      "z": 3,
      "name": "Rock_Ice"
    },
    {
      "x": -28,
      "y": 14,
      "z": 3,
      "name": "Rock_Ice"
    },
    {
      "x": -28,
      "y": 15,
      "z": 3,
      "name": "Rock_Ice"
    },
    {
      "x": -28,
      "y": 16,
      "z": 3,
      "name": "Rock_Ice"
    },
    {
      "x": -28,
      "y": 17,
      "z": 3,
      "name": "Rock_Ice"
    },
    {
      "x": -28,
      "y": 18,
      "z": 3,
      "name": "Soil_Snow"
    },
    {
      "x": -28,
      "y": 5,
      "z": 4,
      "name": "Rock_Ice"
    },
    {
      "x": -28,
      "y": 6,
      "z": 4,
      "name": "Rock_Ice"
    },
    {
      "x": -28,
      "y": 7,
      "z": 4,
      "name": "Rock_Ice"
    },
    {
      "x": -28,
      "y": 8,
      "z": 4,
      "name": "Rock_Ice"
    },
    {
      "x": -28,
      "y": 9,
      "z": 4,
      "name": "Rock_Ice"
    },
    {
      "x": -28,
      "y": 10,
      "z": 4,
      "name": "Rock_Ice"
    },
    {
      "x": -28,
      "y": 11,
      "z": 4,
      "name": "Rock_Ice"
    },
    {
      "x": -28,
      "y": 12,
      "z": 4,
      "name": "Rock_Ice"
    },
    {
      "x": -28,
      "y": 13,
      "z": 4,
      "name": "Rock_Ice"
    },
    {
      "x": -28,
      "y": 14,
      "z": 4,
      "name": "Rock_Ice"
    },
    {
      "x": -28,
      "y": 15,
      "z": 4,
      "name": "Rock_Ice"
    },
    {
      "x": -28,
      "y": 16,
      "z": 4,
      "name": "Rock_Ice"
    },
    {
      "x": -28,
      "y": 17,
      "z": 4,
      "name": "Rock_Ice"
    },
    {
      "x": -28,
      "y": 18,
      "z": 4,
      "name": "Soil_Snow"
    },
    {
      "x": -28,
      "y": 5,
      "z": 5,
      "name": "Rock_Ice"
    },
    {
      "x": -28,
      "y": 6,
      "z": 5,
      "name": "Rock_Ice"
    },
    {
      "x": -28,
      "y": 7,
      "z": 5,
      "name": "Rock_Ice"
    },
    {
      "x": -28,
      "y": 8,
      "z": 5,
      "name": "Rock_Ice"
    },
    {
      "x": -28,
      "y": 9,
      "z": 5,
      "name": "Rock_Ice"
    },
    {
      "x": -28,
      "y": 10,
      "z": 5,
      "name": "Rock_Ice"
    },
    {
      "x": -28,
      "y": 11,
      "z": 5,
      "name": "Rock_Ice"
    },
    {
      "x": -28,
      "y": 12,
      "z": 5,
      "name": "Rock_Ice"
    },
    {
      "x": -28,
      "y": 13,
      "z": 5,
      "name": "Rock_Ice"
    },
    {
      "x": -28,
      "y": 14,
      "z": 5,
      "name": "Rock_Ice"
    },
    {
      "x": -28,
      "y": 15,
      "z": 5,
      "name": "Rock_Ice"
    },
    {
      "x": -28,
      "y": 16,
      "z": 5,
      "name": "Rock_Ice"
    },
    {
      "x": -28,
      "y": 17,
      "z": 5,
      "name": "Rock_Ice"
    },
    {
      "x": -28,
      "y": 18,
      "z": 5,
      "name": "Soil_Snow"
    },
    {
      "x": -28,
      "y": 5,
      "z": 6,
      "name": "Rock_Ice"
    },
    {
      "x": -28,
      "y": 6,
      "z": 6,
      "name": "Rock_Ice"
    },
    {
      "x": -28,
      "y": 7,
      "z": 6,
      "name": "Rock_Ice"
    },
    {
      "x": -28,
      "y": 8,
      "z": 6,
      "name": "Rock_Ice"
    },
    {
      "x": -28,
      "y": 9,
      "z": 6,
      "name": "Rock_Ice"
    },
    {
      "x": -28,
      "y": 10,
      "z": 6,
      "name": "Rock_Ice"
    },
    {
      "x": -28,
      "y": 11,
      "z": 6,
      "name": "Rock_Ice"
    },
    {
      "x": -28,
      "y": 12,
      "z": 6,
      "name": "Rock_Ice"
    },
    {
      "x": -28,
      "y": 13,
      "z": 6,
      "name": "Rock_Ice"
    },
    {
      "x": -28,
      "y": 14,
      "z": 6,
      "name": "Rock_Ice"
    },
    {
      "x": -28,
      "y": 15,
      "z": 6,
      "name": "Rock_Ice"
    },
    {
      "x": -28,
      "y": 16,
      "z": 6,
      "name": "Rock_Ice"
    },
    {
      "x": -28,
      "y": 17,
      "z": 6,
      "name": "Rock_Ice"
    },
    {
      "x": -28,
      "y": 18,
      "z": 6,
      "name": "Soil_Snow"
    },
    {
      "x": -28,
      "y": 5,
      "z": 7,
      "name": "Rock_Ice"
    },
    {
      "x": -28,
      "y": 6,
      "z": 7,
      "name": "Rock_Ice"
    },
    {
      "x": -28,
      "y": 7,
      "z": 7,
      "name": "Rock_Ice"
    },
    {
      "x": -28,
      "y": 8,
      "z": 7,
      "name": "Rock_Ice"
    },
    {
      "x": -28,
      "y": 9,
      "z": 7,
      "name": "Rock_Ice"
    },
    {
      "x": -28,
      "y": 10,
      "z": 7,
      "name": "Rock_Ice"
    },
    {
      "x": -28,
      "y": 11,
      "z": 7,
      "name": "Rock_Ice"
    },
    {
      "x": -28,
      "y": 12,
      "z": 7,
      "name": "Rock_Ice"
    },
    {
      "x": -28,
      "y": 13,
      "z": 7,
      "name": "Rock_Ice"
    },
    {
      "x": -28,
      "y": 14,
      "z": 7,
      "name": "Rock_Ice"
    },
    {
      "x": -28,
      "y": 15,
      "z": 7,
      "name": "Rock_Ice"
    },
    {
      "x": -28,
      "y": 16,
      "z": 7,
      "name": "Rock_Ice"
    },
    {
      "x": -28,
      "y": 17,
      "z": 7,
      "name": "Soil_Snow"
    },
    {
      "x": -28,
      "y": 5,
      "z": 8,
      "name": "Rock_Ice"
    },
    {
      "x": -28,
      "y": 6,
      "z": 8,
      "name": "Rock_Ice"
    },
    {
      "x": -28,
      "y": 7,
      "z": 8,
      "name": "Rock_Ice"
    },
    {
      "x": -28,
      "y": 8,
      "z": 8,
      "name": "Rock_Ice"
    },
    {
      "x": -28,
      "y": 9,
      "z": 8,
      "name": "Rock_Ice"
    },
    {
      "x": -28,
      "y": 10,
      "z": 8,
      "name": "Rock_Ice"
    },
    {
      "x": -28,
      "y": 11,
      "z": 8,
      "name": "Rock_Ice"
    },
    {
      "x": -28,
      "y": 12,
      "z": 8,
      "name": "Rock_Ice"
    },
    {
      "x": -28,
      "y": 13,
      "z": 8,
      "name": "Rock_Ice"
    },
    {
      "x": -28,
      "y": 14,
      "z": 8,
      "name": "Rock_Ice"
    },
    {
      "x": -28,
      "y": 15,
      "z": 8,
      "name": "Rock_Ice"
    },
    {
      "x": -28,
      "y": 16,
      "z": 8,
      "name": "Rock_Ice"
    },
    {
      "x": -28,
      "y": 17,
      "z": 8,
      "name": "Soil_Snow"
    },
    {
      "x": -28,
      "y": 5,
      "z": 9,
      "name": "Rock_Ice"
    },
    {
      "x": -28,
      "y": 6,
      "z": 9,
      "name": "Rock_Ice"
    },
    {
      "x": -28,
      "y": 7,
      "z": 9,
      "name": "Rock_Ice"
    },
    {
      "x": -28,
      "y": 8,
      "z": 9,
      "name": "Rock_Ice"
    },
    {
      "x": -28,
      "y": 9,
      "z": 9,
      "name": "Rock_Ice"
    },
    {
      "x": -28,
      "y": 10,
      "z": 9,
      "name": "Rock_Ice"
    },
    {
      "x": -28,
      "y": 11,
      "z": 9,
      "name": "Rock_Ice"
    },
    {
      "x": -28,
      "y": 12,
      "z": 9,
      "name": "Rock_Ice"
    },
    {
      "x": -28,
      "y": 13,
      "z": 9,
      "name": "Rock_Ice"
    },
    {
      "x": -28,
      "y": 14,
      "z": 9,
      "name": "Rock_Ice"
    },
    {
      "x": -28,
      "y": 15,
      "z": 9,
      "name": "Rock_Ice"
    },
    {
      "x": -28,
      "y": 16,
      "z": 9,
      "name": "Soil_Snow"
    },
    {
      "x": -28,
      "y": 5,
      "z": 10,
      "name": "Rock_Ice"
    },
    {
      "x": -28,
      "y": 6,
      "z": 10,
      "name": "Rock_Ice"
    },
    {
      "x": -28,
      "y": 7,
      "z": 10,
      "name": "Rock_Ice"
    },
    {
      "x": -28,
      "y": 8,
      "z": 10,
      "name": "Rock_Ice"
    },
    {
      "x": -28,
      "y": 9,
      "z": 10,
      "name": "Rock_Ice"
    },
    {
      "x": -28,
      "y": 10,
      "z": 10,
      "name": "Rock_Ice"
    },
    {
      "x": -28,
      "y": 11,
      "z": 10,
      "name": "Rock_Ice"
    },
    {
      "x": -28,
      "y": 12,
      "z": 10,
      "name": "Rock_Ice"
    },
    {
      "x": -28,
      "y": 13,
      "z": 10,
      "name": "Rock_Ice"
    },
    {
      "x": -28,
      "y": 14,
      "z": 10,
      "name": "Rock_Ice"
    },
    {
      "x": -28,
      "y": 15,
      "z": 10,
      "name": "Soil_Snow"
    },
    {
      "x": -28,
      "y": 5,
      "z": 11,
      "name": "Rock_Ice"
    },
    {
      "x": -28,
      "y": 6,
      "z": 11,
      "name": "Rock_Ice"
    },
    {
      "x": -28,
      "y": 7,
      "z": 11,
      "name": "Rock_Ice"
    },
    {
      "x": -28,
      "y": 8,
      "z": 11,
      "name": "Rock_Ice"
    },
    {
      "x": -28,
      "y": 9,
      "z": 11,
      "name": "Rock_Ice"
    },
    {
      "x": -28,
      "y": 10,
      "z": 11,
      "name": "Rock_Ice"
    },
    {
      "x": -28,
      "y": 11,
      "z": 11,
      "name": "Rock_Ice_Permafrost"
    },
    {
      "x": -28,
      "y": 12,
      "z": 11,
      "name": "Rock_Ice"
    },
    {
      "x": -28,
      "y": 13,
      "z": 11,
      "name": "Rock_Ice"
    },
    {
      "x": -28,
      "y": 14,
      "z": 11,
      "name": "Soil_Snow"
    },
    {
      "x": -28,
      "y": 5,
      "z": 12,
      "name": "Rock_Ice"
    },
    {
      "x": -28,
      "y": 6,
      "z": 12,
      "name": "Rock_Ice_Permafrost"
    },
    {
      "x": -28,
      "y": 7,
      "z": 12,
      "name": "Rock_Ice_Permafrost"
    },
    {
      "x": -28,
      "y": 8,
      "z": 12,
      "name": "Rock_Ice"
    },
    {
      "x": -28,
      "y": 9,
      "z": 12,
      "name": "Rock_Ice"
    },
    {
      "x": -28,
      "y": 10,
      "z": 12,
      "name": "Rock_Ice"
    },
    {
      "x": -28,
      "y": 11,
      "z": 12,
      "name": "Rock_Ice_Permafrost"
    },
    {
      "x": -28,
      "y": 12,
      "z": 12,
      "name": "Rock_Ice_Permafrost"
    },
    {
      "x": -28,
      "y": 13,
      "z": 12,
      "name": "Rock_Ice_Permafrost"
    },
    {
      "x": -28,
      "y": 14,
      "z": 12,
      "name": "Soil_Snow"
    },
    {
      "x": -28,
      "y": 5,
      "z": 13,
      "name": "Rock_Ice"
    },
    {
      "x": -28,
      "y": 6,
      "z": 13,
      "name": "Rock_Ice_Permafrost"
    },
    {
      "x": -28,
      "y": 7,
      "z": 13,
      "name": "Rock_Ice_Permafrost"
    },
    {
      "x": -28,
      "y": 8,
      "z": 13,
      "name": "Rock_Ice"
    },
    {
      "x": -28,
      "y": 9,
      "z": 13,
      "name": "Rock_Ice"
    },
    {
      "x": -28,
      "y": 10,
      "z": 13,
      "name": "Rock_Ice_Permafrost"
    },
    {
      "x": -28,
      "y": 11,
      "z": 13,
      "name": "Rock_Ice_Permafrost"
    },
    {
      "x": -28,
      "y": 12,
      "z": 13,
      "name": "Rock_Ice_Permafrost"
    },
    {
      "x": -28,
      "y": 13,
      "z": 13,
      "name": "Soil_Snow"
    },
    {
      "x": -28,
      "y": 5,
      "z": 14,
      "name": "Rock_Ice"
    },
    {
      "x": -28,
      "y": 6,
      "z": 14,
      "name": "Rock_Ice_Permafrost"
    },
    {
      "x": -28,
      "y": 7,
      "z": 14,
      "name": "Rock_Ice"
    },
    {
      "x": -28,
      "y": 8,
      "z": 14,
      "name": "Rock_Ice_Permafrost"
    },
    {
      "x": -28,
      "y": 9,
      "z": 14,
      "name": "Rock_Ice"
    },
    {
      "x": -28,
      "y": 10,
      "z": 14,
      "name": "Rock_Ice_Permafrost"
    },
    {
      "x": -28,
      "y": 11,
      "z": 14,
      "name": "Rock_Ice_Permafrost"
    },
    {
      "x": -28,
      "y": 12,
      "z": 14,
      "name": "Rock_Ice_Permafrost"
    },
    {
      "x": -28,
      "y": 13,
      "z": 14,
      "name": "Soil_Snow"
    },
    {
      "x": -28,
      "y": 5,
      "z": 15,
      "name": "Rock_Ice_Permafrost"
    },
    {
      "x": -28,
      "y": 6,
      "z": 15,
      "name": "Rock_Ice"
    },
    {
      "x": -28,
      "y": 7,
      "z": 15,
      "name": "Rock_Ice"
    },
    {
      "x": -28,
      "y": 8,
      "z": 15,
      "name": "Rock_Ice"
    },
    {
      "x": -28,
      "y": 9,
      "z": 15,
      "name": "Rock_Ice"
    },
    {
      "x": -28,
      "y": 10,
      "z": 15,
      "name": "Rock_Ice_Permafrost"
    },
    {
      "x": -28,
      "y": 11,
      "z": 15,
      "name": "Rock_Ice_Permafrost"
    },
    {
      "x": -28,
      "y": 12,
      "z": 15,
      "name": "Soil_Snow"
    },
    {
      "x": -28,
      "y": 5,
      "z": 16,
      "name": "Rock_Ice"
    },
    {
      "x": -28,
      "y": 6,
      "z": 16,
      "name": "Rock_Ice"
    },
    {
      "x": -28,
      "y": 7,
      "z": 16,
      "name": "Rock_Ice"
    },
    {
      "x": -28,
      "y": 8,
      "z": 16,
      "name": "Rock_Ice"
    },
    {
      "x": -28,
      "y": 9,
      "z": 16,
      "name": "Rock_Ice"
    },
    {
      "x": -28,
      "y": 10,
      "z": 16,
      "name": "Rock_Ice_Permafrost"
    },
    {
      "x": -28,
      "y": 11,
      "z": 16,
      "name": "Soil_Snow"
    },
    {
      "x": -28,
      "y": 5,
      "z": 17,
      "name": "Rock_Ice"
    },
    {
      "x": -28,
      "y": 6,
      "z": 17,
      "name": "Rock_Ice"
    },
    {
      "x": -28,
      "y": 7,
      "z": 17,
      "name": "Rock_Ice"
    },
    {
      "x": -28,
      "y": 8,
      "z": 17,
      "name": "Rock_Ice"
    },
    {
      "x": -28,
      "y": 9,
      "z": 17,
      "name": "Rock_Ice"
    },
    {
      "x": -28,
      "y": 10,
      "z": 17,
      "name": "Rock_Ice_Permafrost"
    },
    {
      "x": -28,
      "y": 11,
      "z": 17,
      "name": "Soil_Snow"
    },
    {
      "x": -28,
      "y": 5,
      "z": 18,
      "name": "Rock_Ice"
    },
    {
      "x": -28,
      "y": 6,
      "z": 18,
      "name": "Rock_Ice"
    },
    {
      "x": -28,
      "y": 7,
      "z": 18,
      "name": "Rock_Ice"
    },
    {
      "x": -28,
      "y": 8,
      "z": 18,
      "name": "Rock_Ice"
    },
    {
      "x": -28,
      "y": 9,
      "z": 18,
      "name": "Rock_Ice"
    },
    {
      "x": -28,
      "y": 10,
      "z": 18,
      "name": "Soil_Snow"
    },
    {
      "x": -28,
      "y": 5,
      "z": 19,
      "name": "Rock_Ice"
    },
    {
      "x": -28,
      "y": 6,
      "z": 19,
      "name": "Rock_Ice"
    },
    {
      "x": -28,
      "y": 7,
      "z": 19,
      "name": "Rock_Ice"
    },
    {
      "x": -28,
      "y": 8,
      "z": 19,
      "name": "Rock_Ice"
    },
    {
      "x": -28,
      "y": 9,
      "z": 19,
      "name": "Soil_Snow"
    },
    {
      "x": -28,
      "y": 5,
      "z": 20,
      "name": "Rock_Ice"
    },
    {
      "x": -28,
      "y": 6,
      "z": 20,
      "name": "Rock_Ice"
    },
    {
      "x": -27,
      "y": 15,
      "z": -10,
      "name": "Soil_Snow"
    },
    {
      "x": -27,
      "y": 14,
      "z": -9,
      "name": "Rock_Ice"
    },
    {
      "x": -27,
      "y": 15,
      "z": -9,
      "name": "Rock_Ice"
    },
    {
      "x": -27,
      "y": 16,
      "z": -9,
      "name": "Rock_Ice"
    },
    {
      "x": -27,
      "y": 17,
      "z": -9,
      "name": "Soil_Snow"
    },
    {
      "x": -27,
      "y": 13,
      "z": -8,
      "name": "Rock_Ice"
    },
    {
      "x": -27,
      "y": 14,
      "z": -8,
      "name": "Rock_Ice"
    },
    {
      "x": -27,
      "y": 15,
      "z": -8,
      "name": "Rock_Ice"
    },
    {
      "x": -27,
      "y": 16,
      "z": -8,
      "name": "Rock_Ice"
    },
    {
      "x": -27,
      "y": 17,
      "z": -8,
      "name": "Rock_Ice"
    },
    {
      "x": -27,
      "y": 18,
      "z": -8,
      "name": "Soil_Snow"
    },
    {
      "x": -27,
      "y": 12,
      "z": -7,
      "name": "Rock_Ice"
    },
    {
      "x": -27,
      "y": 13,
      "z": -7,
      "name": "Rock_Ice"
    },
    {
      "x": -27,
      "y": 14,
      "z": -7,
      "name": "Rock_Ice"
    },
    {
      "x": -27,
      "y": 15,
      "z": -7,
      "name": "Rock_Ice"
    },
    {
      "x": -27,
      "y": 16,
      "z": -7,
      "name": "Rock_Ice"
    },
    {
      "x": -27,
      "y": 17,
      "z": -7,
      "name": "Rock_Ice"
    },
    {
      "x": -27,
      "y": 18,
      "z": -7,
      "name": "Rock_Ice"
    },
    {
      "x": -27,
      "y": 19,
      "z": -7,
      "name": "Soil_Snow"
    },
    {
      "x": -27,
      "y": 12,
      "z": -6,
      "name": "Rock_Ice"
    },
    {
      "x": -27,
      "y": 13,
      "z": -6,
      "name": "Rock_Ice"
    },
    {
      "x": -27,
      "y": 14,
      "z": -6,
      "name": "Rock_Ice"
    },
    {
      "x": -27,
      "y": 15,
      "z": -6,
      "name": "Rock_Ice"
    },
    {
      "x": -27,
      "y": 16,
      "z": -6,
      "name": "Rock_Ice"
    },
    {
      "x": -27,
      "y": 17,
      "z": -6,
      "name": "Rock_Ice"
    },
    {
      "x": -27,
      "y": 18,
      "z": -6,
      "name": "Rock_Ice"
    },
    {
      "x": -27,
      "y": 19,
      "z": -6,
      "name": "Soil_Snow"
    },
    {
      "x": -27,
      "y": 11,
      "z": -5,
      "name": "Rock_Ice"
    },
    {
      "x": -27,
      "y": 12,
      "z": -5,
      "name": "Rock_Ice"
    },
    {
      "x": -27,
      "y": 13,
      "z": -5,
      "name": "Rock_Ice"
    },
    {
      "x": -27,
      "y": 14,
      "z": -5,
      "name": "Rock_Ice"
    },
    {
      "x": -27,
      "y": 15,
      "z": -5,
      "name": "Rock_Ice"
    },
    {
      "x": -27,
      "y": 16,
      "z": -5,
      "name": "Rock_Ice"
    },
    {
      "x": -27,
      "y": 17,
      "z": -5,
      "name": "Rock_Ice"
    },
    {
      "x": -27,
      "y": 18,
      "z": -5,
      "name": "Rock_Ice"
    },
    {
      "x": -27,
      "y": 19,
      "z": -5,
      "name": "Soil_Snow"
    },
    {
      "x": -27,
      "y": 10,
      "z": -4,
      "name": "Rock_Ice"
    },
    {
      "x": -27,
      "y": 11,
      "z": -4,
      "name": "Rock_Ice"
    },
    {
      "x": -27,
      "y": 12,
      "z": -4,
      "name": "Rock_Ice"
    },
    {
      "x": -27,
      "y": 13,
      "z": -4,
      "name": "Rock_Ice"
    },
    {
      "x": -27,
      "y": 14,
      "z": -4,
      "name": "Rock_Ice"
    },
    {
      "x": -27,
      "y": 15,
      "z": -4,
      "name": "Rock_Ice"
    },
    {
      "x": -27,
      "y": 16,
      "z": -4,
      "name": "Rock_Ice"
    },
    {
      "x": -27,
      "y": 17,
      "z": -4,
      "name": "Rock_Ice"
    },
    {
      "x": -27,
      "y": 18,
      "z": -4,
      "name": "Rock_Ice"
    },
    {
      "x": -27,
      "y": 19,
      "z": -4,
      "name": "Soil_Snow"
    },
    {
      "x": -27,
      "y": 9,
      "z": -3,
      "name": "Rock_Ice"
    },
    {
      "x": -27,
      "y": 10,
      "z": -3,
      "name": "Rock_Ice"
    },
    {
      "x": -27,
      "y": 11,
      "z": -3,
      "name": "Rock_Ice"
    },
    {
      "x": -27,
      "y": 12,
      "z": -3,
      "name": "Rock_Ice"
    },
    {
      "x": -27,
      "y": 13,
      "z": -3,
      "name": "Rock_Ice"
    },
    {
      "x": -27,
      "y": 14,
      "z": -3,
      "name": "Rock_Ice"
    },
    {
      "x": -27,
      "y": 15,
      "z": -3,
      "name": "Rock_Ice"
    },
    {
      "x": -27,
      "y": 16,
      "z": -3,
      "name": "Rock_Ice"
    },
    {
      "x": -27,
      "y": 17,
      "z": -3,
      "name": "Rock_Ice"
    },
    {
      "x": -27,
      "y": 18,
      "z": -3,
      "name": "Rock_Ice"
    },
    {
      "x": -27,
      "y": 19,
      "z": -3,
      "name": "Soil_Snow"
    },
    {
      "x": -27,
      "y": 7,
      "z": -2,
      "name": "Rock_Ice"
    },
    {
      "x": -27,
      "y": 8,
      "z": -2,
      "name": "Rock_Ice"
    },
    {
      "x": -27,
      "y": 9,
      "z": -2,
      "name": "Rock_Ice"
    },
    {
      "x": -27,
      "y": 10,
      "z": -2,
      "name": "Rock_Ice"
    },
    {
      "x": -27,
      "y": 11,
      "z": -2,
      "name": "Rock_Ice"
    },
    {
      "x": -27,
      "y": 12,
      "z": -2,
      "name": "Rock_Ice"
    },
    {
      "x": -27,
      "y": 13,
      "z": -2,
      "name": "Rock_Ice"
    },
    {
      "x": -27,
      "y": 14,
      "z": -2,
      "name": "Rock_Ice"
    },
    {
      "x": -27,
      "y": 15,
      "z": -2,
      "name": "Rock_Ice"
    },
    {
      "x": -27,
      "y": 16,
      "z": -2,
      "name": "Rock_Ice"
    },
    {
      "x": -27,
      "y": 17,
      "z": -2,
      "name": "Rock_Ice"
    },
    {
      "x": -27,
      "y": 18,
      "z": -2,
      "name": "Rock_Ice"
    },
    {
      "x": -27,
      "y": 19,
      "z": -2,
      "name": "Soil_Snow"
    },
    {
      "x": -27,
      "y": 6,
      "z": -1,
      "name": "Rock_Ice"
    },
    {
      "x": -27,
      "y": 7,
      "z": -1,
      "name": "Rock_Ice"
    },
    {
      "x": -27,
      "y": 8,
      "z": -1,
      "name": "Rock_Ice"
    },
    {
      "x": -27,
      "y": 9,
      "z": -1,
      "name": "Rock_Ice"
    },
    {
      "x": -27,
      "y": 10,
      "z": -1,
      "name": "Rock_Ice"
    },
    {
      "x": -27,
      "y": 11,
      "z": -1,
      "name": "Rock_Ice"
    },
    {
      "x": -27,
      "y": 12,
      "z": -1,
      "name": "Rock_Ice"
    },
    {
      "x": -27,
      "y": 13,
      "z": -1,
      "name": "Rock_Ice"
    },
    {
      "x": -27,
      "y": 14,
      "z": -1,
      "name": "Rock_Ice"
    },
    {
      "x": -27,
      "y": 15,
      "z": -1,
      "name": "Rock_Ice"
    },
    {
      "x": -27,
      "y": 16,
      "z": -1,
      "name": "Rock_Ice"
    },
    {
      "x": -27,
      "y": 17,
      "z": -1,
      "name": "Rock_Ice"
    },
    {
      "x": -27,
      "y": 18,
      "z": -1,
      "name": "Rock_Ice"
    },
    {
      "x": -27,
      "y": 19,
      "z": -1,
      "name": "Soil_Snow"
    },
    {
      "x": -27,
      "y": 4,
      "z": 0,
      "name": "Rock_Ice"
    },
    {
      "x": -27,
      "y": 5,
      "z": 0,
      "name": "Rock_Ice"
    },
    {
      "x": -27,
      "y": 6,
      "z": 0,
      "name": "Rock_Ice"
    },
    {
      "x": -27,
      "y": 7,
      "z": 0,
      "name": "Rock_Ice"
    },
    {
      "x": -27,
      "y": 8,
      "z": 0,
      "name": "Rock_Ice"
    },
    {
      "x": -27,
      "y": 9,
      "z": 0,
      "name": "Rock_Ice"
    },
    {
      "x": -27,
      "y": 10,
      "z": 0,
      "name": "Rock_Ice"
    },
    {
      "x": -27,
      "y": 11,
      "z": 0,
      "name": "Rock_Ice"
    },
    {
      "x": -27,
      "y": 12,
      "z": 0,
      "name": "Rock_Ice"
    },
    {
      "x": -27,
      "y": 13,
      "z": 0,
      "name": "Rock_Ice"
    },
    {
      "x": -27,
      "y": 14,
      "z": 0,
      "name": "Rock_Ice"
    },
    {
      "x": -27,
      "y": 15,
      "z": 0,
      "name": "Rock_Ice"
    },
    {
      "x": -27,
      "y": 16,
      "z": 0,
      "name": "Rock_Ice"
    },
    {
      "x": -27,
      "y": 17,
      "z": 0,
      "name": "Rock_Ice"
    },
    {
      "x": -27,
      "y": 18,
      "z": 0,
      "name": "Rock_Ice"
    },
    {
      "x": -27,
      "y": 19,
      "z": 0,
      "name": "Soil_Snow"
    },
    {
      "x": -27,
      "y": 4,
      "z": 1,
      "name": "Rock_Ice"
    },
    {
      "x": -27,
      "y": 5,
      "z": 1,
      "name": "Rock_Ice"
    },
    {
      "x": -27,
      "y": 6,
      "z": 1,
      "name": "Rock_Ice"
    },
    {
      "x": -27,
      "y": 7,
      "z": 1,
      "name": "Rock_Ice"
    },
    {
      "x": -27,
      "y": 8,
      "z": 1,
      "name": "Rock_Ice"
    },
    {
      "x": -27,
      "y": 9,
      "z": 1,
      "name": "Rock_Ice"
    },
    {
      "x": -27,
      "y": 10,
      "z": 1,
      "name": "Rock_Ice"
    },
    {
      "x": -27,
      "y": 11,
      "z": 1,
      "name": "Rock_Ice"
    },
    {
      "x": -27,
      "y": 12,
      "z": 1,
      "name": "Rock_Ice"
    },
    {
      "x": -27,
      "y": 13,
      "z": 1,
      "name": "Rock_Ice"
    },
    {
      "x": -27,
      "y": 14,
      "z": 1,
      "name": "Rock_Ice"
    },
    {
      "x": -27,
      "y": 15,
      "z": 1,
      "name": "Rock_Ice"
    },
    {
      "x": -27,
      "y": 16,
      "z": 1,
      "name": "Rock_Ice"
    },
    {
      "x": -27,
      "y": 17,
      "z": 1,
      "name": "Rock_Ice"
    },
    {
      "x": -27,
      "y": 18,
      "z": 1,
      "name": "Rock_Ice"
    },
    {
      "x": -27,
      "y": 19,
      "z": 1,
      "name": "Rock_Ice"
    },
    {
      "x": -27,
      "y": 4,
      "z": 2,
      "name": "Rock_Ice"
    },
    {
      "x": -27,
      "y": 5,
      "z": 2,
      "name": "Rock_Ice"
    },
    {
      "x": -27,
      "y": 6,
      "z": 2,
      "name": "Rock_Ice"
    },
    {
      "x": -27,
      "y": 7,
      "z": 2,
      "name": "Rock_Ice"
    },
    {
      "x": -27,
      "y": 8,
      "z": 2,
      "name": "Rock_Ice"
    },
    {
      "x": -27,
      "y": 9,
      "z": 2,
      "name": "Rock_Ice"
    },
    {
      "x": -27,
      "y": 10,
      "z": 2,
      "name": "Rock_Ice"
    },
    {
      "x": -27,
      "y": 11,
      "z": 2,
      "name": "Rock_Ice"
    },
    {
      "x": -27,
      "y": 12,
      "z": 2,
      "name": "Rock_Ice"
    },
    {
      "x": -27,
      "y": 13,
      "z": 2,
      "name": "Rock_Ice"
    },
    {
      "x": -27,
      "y": 14,
      "z": 2,
      "name": "Rock_Ice"
    },
    {
      "x": -27,
      "y": 15,
      "z": 2,
      "name": "Rock_Ice"
    },
    {
      "x": -27,
      "y": 16,
      "z": 2,
      "name": "Rock_Ice"
    },
    {
      "x": -27,
      "y": 17,
      "z": 2,
      "name": "Rock_Ice"
    },
    {
      "x": -27,
      "y": 18,
      "z": 2,
      "name": "Rock_Ice"
    },
    {
      "x": -27,
      "y": 19,
      "z": 2,
      "name": "Soil_Snow"
    },
    {
      "x": -27,
      "y": 4,
      "z": 3,
      "name": "Rock_Ice"
    },
    {
      "x": -27,
      "y": 5,
      "z": 3,
      "name": "Rock_Ice"
    },
    {
      "x": -27,
      "y": 6,
      "z": 3,
      "name": "Rock_Ice"
    },
    {
      "x": -27,
      "y": 7,
      "z": 3,
      "name": "Rock_Ice"
    },
    {
      "x": -27,
      "y": 8,
      "z": 3,
      "name": "Rock_Ice"
    },
    {
      "x": -27,
      "y": 9,
      "z": 3,
      "name": "Rock_Ice"
    },
    {
      "x": -27,
      "y": 10,
      "z": 3,
      "name": "Rock_Ice"
    },
    {
      "x": -27,
      "y": 11,
      "z": 3,
      "name": "Rock_Ice"
    },
    {
      "x": -27,
      "y": 12,
      "z": 3,
      "name": "Rock_Ice"
    },
    {
      "x": -27,
      "y": 13,
      "z": 3,
      "name": "Rock_Ice"
    },
    {
      "x": -27,
      "y": 14,
      "z": 3,
      "name": "Rock_Ice"
    },
    {
      "x": -27,
      "y": 15,
      "z": 3,
      "name": "Rock_Ice"
    },
    {
      "x": -27,
      "y": 16,
      "z": 3,
      "name": "Rock_Ice"
    },
    {
      "x": -27,
      "y": 17,
      "z": 3,
      "name": "Rock_Ice"
    },
    {
      "x": -27,
      "y": 18,
      "z": 3,
      "name": "Rock_Ice"
    },
    {
      "x": -27,
      "y": 19,
      "z": 3,
      "name": "Soil_Snow"
    },
    {
      "x": -27,
      "y": 5,
      "z": 4,
      "name": "Rock_Ice"
    },
    {
      "x": -27,
      "y": 6,
      "z": 4,
      "name": "Rock_Ice"
    },
    {
      "x": -27,
      "y": 7,
      "z": 4,
      "name": "Rock_Ice"
    },
    {
      "x": -27,
      "y": 8,
      "z": 4,
      "name": "Rock_Ice"
    },
    {
      "x": -27,
      "y": 9,
      "z": 4,
      "name": "Rock_Ice"
    },
    {
      "x": -27,
      "y": 10,
      "z": 4,
      "name": "Rock_Ice"
    },
    {
      "x": -27,
      "y": 11,
      "z": 4,
      "name": "Rock_Ice"
    },
    {
      "x": -27,
      "y": 12,
      "z": 4,
      "name": "Rock_Ice"
    },
    {
      "x": -27,
      "y": 13,
      "z": 4,
      "name": "Rock_Ice"
    },
    {
      "x": -27,
      "y": 14,
      "z": 4,
      "name": "Rock_Ice"
    },
    {
      "x": -27,
      "y": 15,
      "z": 4,
      "name": "Rock_Ice"
    },
    {
      "x": -27,
      "y": 16,
      "z": 4,
      "name": "Rock_Ice"
    },
    {
      "x": -27,
      "y": 17,
      "z": 4,
      "name": "Rock_Ice"
    },
    {
      "x": -27,
      "y": 18,
      "z": 4,
      "name": "Rock_Ice"
    },
    {
      "x": -27,
      "y": 19,
      "z": 4,
      "name": "Soil_Snow"
    },
    {
      "x": -27,
      "y": 5,
      "z": 5,
      "name": "Rock_Ice"
    },
    {
      "x": -27,
      "y": 6,
      "z": 5,
      "name": "Rock_Ice"
    },
    {
      "x": -27,
      "y": 7,
      "z": 5,
      "name": "Rock_Ice"
    },
    {
      "x": -27,
      "y": 8,
      "z": 5,
      "name": "Rock_Ice"
    },
    {
      "x": -27,
      "y": 9,
      "z": 5,
      "name": "Rock_Ice"
    },
    {
      "x": -27,
      "y": 10,
      "z": 5,
      "name": "Rock_Ice"
    },
    {
      "x": -27,
      "y": 11,
      "z": 5,
      "name": "Rock_Ice"
    },
    {
      "x": -27,
      "y": 12,
      "z": 5,
      "name": "Rock_Ice"
    },
    {
      "x": -27,
      "y": 13,
      "z": 5,
      "name": "Rock_Ice"
    },
    {
      "x": -27,
      "y": 14,
      "z": 5,
      "name": "Rock_Ice"
    },
    {
      "x": -27,
      "y": 15,
      "z": 5,
      "name": "Rock_Ice"
    },
    {
      "x": -27,
      "y": 16,
      "z": 5,
      "name": "Rock_Ice"
    },
    {
      "x": -27,
      "y": 17,
      "z": 5,
      "name": "Rock_Ice"
    },
    {
      "x": -27,
      "y": 18,
      "z": 5,
      "name": "Soil_Snow"
    },
    {
      "x": -27,
      "y": 5,
      "z": 6,
      "name": "Rock_Ice"
    },
    {
      "x": -27,
      "y": 6,
      "z": 6,
      "name": "Rock_Ice"
    },
    {
      "x": -27,
      "y": 7,
      "z": 6,
      "name": "Rock_Ice"
    },
    {
      "x": -27,
      "y": 8,
      "z": 6,
      "name": "Rock_Ice"
    },
    {
      "x": -27,
      "y": 9,
      "z": 6,
      "name": "Rock_Ice"
    },
    {
      "x": -27,
      "y": 10,
      "z": 6,
      "name": "Rock_Ice"
    },
    {
      "x": -27,
      "y": 11,
      "z": 6,
      "name": "Rock_Ice"
    },
    {
      "x": -27,
      "y": 12,
      "z": 6,
      "name": "Rock_Ice"
    },
    {
      "x": -27,
      "y": 13,
      "z": 6,
      "name": "Rock_Ice"
    },
    {
      "x": -27,
      "y": 14,
      "z": 6,
      "name": "Rock_Ice"
    },
    {
      "x": -27,
      "y": 15,
      "z": 6,
      "name": "Rock_Ice"
    },
    {
      "x": -27,
      "y": 16,
      "z": 6,
      "name": "Rock_Ice"
    },
    {
      "x": -27,
      "y": 17,
      "z": 6,
      "name": "Rock_Ice"
    },
    {
      "x": -27,
      "y": 18,
      "z": 6,
      "name": "Soil_Snow"
    },
    {
      "x": -27,
      "y": 5,
      "z": 7,
      "name": "Rock_Ice"
    },
    {
      "x": -27,
      "y": 6,
      "z": 7,
      "name": "Rock_Ice"
    },
    {
      "x": -27,
      "y": 7,
      "z": 7,
      "name": "Rock_Ice"
    },
    {
      "x": -27,
      "y": 8,
      "z": 7,
      "name": "Rock_Ice"
    },
    {
      "x": -27,
      "y": 9,
      "z": 7,
      "name": "Rock_Ice"
    },
    {
      "x": -27,
      "y": 10,
      "z": 7,
      "name": "Rock_Ice"
    },
    {
      "x": -27,
      "y": 11,
      "z": 7,
      "name": "Rock_Ice"
    },
    {
      "x": -27,
      "y": 12,
      "z": 7,
      "name": "Rock_Ice"
    },
    {
      "x": -27,
      "y": 13,
      "z": 7,
      "name": "Rock_Ice"
    },
    {
      "x": -27,
      "y": 14,
      "z": 7,
      "name": "Rock_Ice"
    },
    {
      "x": -27,
      "y": 15,
      "z": 7,
      "name": "Rock_Ice"
    },
    {
      "x": -27,
      "y": 16,
      "z": 7,
      "name": "Rock_Ice"
    },
    {
      "x": -27,
      "y": 17,
      "z": 7,
      "name": "Rock_Ice"
    },
    {
      "x": -27,
      "y": 18,
      "z": 7,
      "name": "Soil_Snow"
    },
    {
      "x": -27,
      "y": 5,
      "z": 8,
      "name": "Rock_Ice"
    },
    {
      "x": -27,
      "y": 6,
      "z": 8,
      "name": "Rock_Ice"
    },
    {
      "x": -27,
      "y": 7,
      "z": 8,
      "name": "Rock_Ice"
    },
    {
      "x": -27,
      "y": 8,
      "z": 8,
      "name": "Rock_Ice"
    },
    {
      "x": -27,
      "y": 9,
      "z": 8,
      "name": "Rock_Ice"
    },
    {
      "x": -27,
      "y": 10,
      "z": 8,
      "name": "Rock_Ice"
    },
    {
      "x": -27,
      "y": 11,
      "z": 8,
      "name": "Rock_Ice"
    },
    {
      "x": -27,
      "y": 12,
      "z": 8,
      "name": "Rock_Ice"
    },
    {
      "x": -27,
      "y": 13,
      "z": 8,
      "name": "Rock_Ice"
    },
    {
      "x": -27,
      "y": 14,
      "z": 8,
      "name": "Rock_Ice"
    },
    {
      "x": -27,
      "y": 15,
      "z": 8,
      "name": "Rock_Ice"
    },
    {
      "x": -27,
      "y": 16,
      "z": 8,
      "name": "Rock_Ice"
    },
    {
      "x": -27,
      "y": 17,
      "z": 8,
      "name": "Soil_Snow"
    },
    {
      "x": -27,
      "y": 5,
      "z": 9,
      "name": "Rock_Ice"
    },
    {
      "x": -27,
      "y": 6,
      "z": 9,
      "name": "Rock_Ice"
    },
    {
      "x": -27,
      "y": 7,
      "z": 9,
      "name": "Rock_Ice"
    },
    {
      "x": -27,
      "y": 8,
      "z": 9,
      "name": "Rock_Ice"
    },
    {
      "x": -27,
      "y": 9,
      "z": 9,
      "name": "Rock_Ice"
    },
    {
      "x": -27,
      "y": 10,
      "z": 9,
      "name": "Rock_Ice"
    },
    {
      "x": -27,
      "y": 11,
      "z": 9,
      "name": "Rock_Ice"
    },
    {
      "x": -27,
      "y": 12,
      "z": 9,
      "name": "Rock_Ice"
    },
    {
      "x": -27,
      "y": 13,
      "z": 9,
      "name": "Rock_Ice"
    },
    {
      "x": -27,
      "y": 14,
      "z": 9,
      "name": "Rock_Ice"
    },
    {
      "x": -27,
      "y": 15,
      "z": 9,
      "name": "Rock_Ice"
    },
    {
      "x": -27,
      "y": 16,
      "z": 9,
      "name": "Rock_Ice"
    },
    {
      "x": -27,
      "y": 17,
      "z": 9,
      "name": "Soil_Snow"
    },
    {
      "x": -27,
      "y": 5,
      "z": 10,
      "name": "Rock_Ice"
    },
    {
      "x": -27,
      "y": 6,
      "z": 10,
      "name": "Rock_Ice"
    },
    {
      "x": -27,
      "y": 7,
      "z": 10,
      "name": "Rock_Ice"
    },
    {
      "x": -27,
      "y": 8,
      "z": 10,
      "name": "Rock_Ice"
    },
    {
      "x": -27,
      "y": 9,
      "z": 10,
      "name": "Rock_Ice"
    },
    {
      "x": -27,
      "y": 10,
      "z": 10,
      "name": "Rock_Ice"
    },
    {
      "x": -27,
      "y": 11,
      "z": 10,
      "name": "Rock_Ice"
    },
    {
      "x": -27,
      "y": 12,
      "z": 10,
      "name": "Rock_Ice"
    },
    {
      "x": -27,
      "y": 13,
      "z": 10,
      "name": "Rock_Ice"
    },
    {
      "x": -27,
      "y": 14,
      "z": 10,
      "name": "Rock_Ice"
    },
    {
      "x": -27,
      "y": 15,
      "z": 10,
      "name": "Rock_Ice"
    },
    {
      "x": -27,
      "y": 16,
      "z": 10,
      "name": "Soil_Snow"
    },
    {
      "x": -27,
      "y": 5,
      "z": 11,
      "name": "Rock_Ice"
    },
    {
      "x": -27,
      "y": 6,
      "z": 11,
      "name": "Rock_Ice"
    },
    {
      "x": -27,
      "y": 7,
      "z": 11,
      "name": "Rock_Ice"
    },
    {
      "x": -27,
      "y": 8,
      "z": 11,
      "name": "Rock_Ice"
    },
    {
      "x": -27,
      "y": 9,
      "z": 11,
      "name": "Rock_Ice"
    },
    {
      "x": -27,
      "y": 10,
      "z": 11,
      "name": "Rock_Ice"
    },
    {
      "x": -27,
      "y": 11,
      "z": 11,
      "name": "Rock_Ice"
    },
    {
      "x": -27,
      "y": 12,
      "z": 11,
      "name": "Rock_Ice"
    },
    {
      "x": -27,
      "y": 13,
      "z": 11,
      "name": "Rock_Ice_Permafrost"
    },
    {
      "x": -27,
      "y": 14,
      "z": 11,
      "name": "Rock_Ice_Permafrost"
    },
    {
      "x": -27,
      "y": 15,
      "z": 11,
      "name": "Soil_Snow"
    },
    {
      "x": -27,
      "y": 5,
      "z": 12,
      "name": "Rock_Ice"
    },
    {
      "x": -27,
      "y": 6,
      "z": 12,
      "name": "Rock_Ice"
    },
    {
      "x": -27,
      "y": 7,
      "z": 12,
      "name": "Rock_Ice"
    },
    {
      "x": -27,
      "y": 8,
      "z": 12,
      "name": "Rock_Ice"
    },
    {
      "x": -27,
      "y": 9,
      "z": 12,
      "name": "Rock_Ice"
    },
    {
      "x": -27,
      "y": 10,
      "z": 12,
      "name": "Rock_Ice_Permafrost"
    },
    {
      "x": -27,
      "y": 11,
      "z": 12,
      "name": "Rock_Ice_Permafrost"
    },
    {
      "x": -27,
      "y": 12,
      "z": 12,
      "name": "Rock_Ice_Permafrost"
    },
    {
      "x": -27,
      "y": 13,
      "z": 12,
      "name": "Rock_Ice_Permafrost"
    },
    {
      "x": -27,
      "y": 14,
      "z": 12,
      "name": "Soil_Snow"
    },
    {
      "x": -27,
      "y": 5,
      "z": 13,
      "name": "Rock_Ice"
    },
    {
      "x": -27,
      "y": 6,
      "z": 13,
      "name": "Rock_Ice_Permafrost"
    },
    {
      "x": -27,
      "y": 7,
      "z": 13,
      "name": "Rock_Ice"
    },
    {
      "x": -27,
      "y": 8,
      "z": 13,
      "name": "Rock_Ice"
    },
    {
      "x": -27,
      "y": 9,
      "z": 13,
      "name": "Rock_Ice"
    },
    {
      "x": -27,
      "y": 10,
      "z": 13,
      "name": "Rock_Ice_Permafrost"
    },
    {
      "x": -27,
      "y": 11,
      "z": 13,
      "name": "Rock_Ice_Permafrost"
    },
    {
      "x": -27,
      "y": 12,
      "z": 13,
      "name": "Rock_Ice_Permafrost"
    },
    {
      "x": -27,
      "y": 13,
      "z": 13,
      "name": "Rock_Ice_Permafrost"
    },
    {
      "x": -27,
      "y": 14,
      "z": 13,
      "name": "Soil_Snow"
    },
    {
      "x": -27,
      "y": 5,
      "z": 14,
      "name": "Rock_Ice"
    },
    {
      "x": -27,
      "y": 6,
      "z": 14,
      "name": "Rock_Ice"
    },
    {
      "x": -27,
      "y": 7,
      "z": 14,
      "name": "Rock_Ice_Permafrost"
    },
    {
      "x": -27,
      "y": 8,
      "z": 14,
      "name": "Rock_Ice_Permafrost"
    },
    {
      "x": -27,
      "y": 9,
      "z": 14,
      "name": "Rock_Ice_Permafrost"
    },
    {
      "x": -27,
      "y": 10,
      "z": 14,
      "name": "Rock_Ice"
    },
    {
      "x": -27,
      "y": 11,
      "z": 14,
