{
  "version": 8,
  "blockIdVersion": 11,
  "anchorX": 0,
  "anchorY": 0,
  "anchorZ": 0,
  "blocks": [
    {
      "x": -27,
      "y": 37,
      "z": -4,
      "name": "Rock_Ice"
    },
    {
      "x": -27,
      "y": 38,
      "z": -4,
      "name": "Rock_Ice"
    },
    {
      "x": -27,
      "y": 39,
      "z": -4,
      "name": "Rock_Ice"
    },
    {
      "x": -27,
      "y": 40,
      "z": -4,
      "name": "Soil_Snow"
    },
    {
      "x": -27,
      "y": 36,
      "z": -3,
      "name": "Rock_Ice"
    },
    {
      "x": -27,
      "y": 37,
      "z": -3,
      "name": "Rock_Ice"
    },
    {
      "x": -27,
      "y": 38,
      "z": -3,
      "name": "Rock_Ice"
    },
    {
      "x": -27,
      "y": 39,
      "z": -3,
      "name": "Rock_Ice"
    },
    {
      "x": -27,
      "y": 40,
      "z": -3,
      "name": "Rock_Ice"
    },
    {
      "x": -27,
      "y": 41,
      "z": -3,
      "name": "Rock_Ice"
    },
    {
      "x": -27,
      "y": 42,
      "z": -3,
      "name": "Rock_Ice"
    },
    {
      "x": -27,
      "y": 43,
      "z": -3,
      "name": "Soil_Snow"
    },
    {
      "x": -27,
      "y": 35,
      "z": -2,
      "name": "Rock_Ice"
    },
    {
      "x": -27,
      "y": 36,
      "z": -2,
      "name": "Rock_Ice"
    },
    {
      "x": -27,
      "y": 37,
      "z": -2,
      "name": "Rock_Ice"
    },
    {
      "x": -27,
      "y": 38,
      "z": -2,
      "name": "Rock_Ice"
    },
    {
      "x": -27,
      "y": 39,
      "z": -2,
      "name": "Rock_Ice"
    },
    {
      "x": -27,
      "y": 40,
      "z": -2,
      "name": "Rock_Ice"
    },
    {
      "x": -27,
      "y": 41,
      "z": -2,
      "name": "Rock_Ice"
    },
    {
      "x": -27,
      "y": 42,
      "z": -2,
      "name": "Rock_Ice"
    },
    {
      "x": -27,
      "y": 43,
      "z": -2,
      "name": "Rock_Ice"
    },
    {
      "x": -27,
      "y": 44,
      "z": -2,
      "name": "Soil_Snow"
    },
    {
      "x": -27,
      "y": 35,
      "z": -1,
      "name": "Rock_Ice"
    },
    {
      "x": -27,
      "y": 36,
      "z": -1,
      "name": "Rock_Ice"
    },
    {
      "x": -27,
      "y": 37,
      "z": -1,
      "name": "Rock_Ice"
    },
    {
      "x": -27,
      "y": 38,
      "z": -1,
      "name": "Rock_Ice"
    },
    {
      "x": -27,
      "y": 39,
      "z": -1,
      "name": "Rock_Ice"
    },
    {
      "x": -27,
      "y": 40,
      "z": -1,
      "name": "Rock_Ice"
    },
    {
      "x": -27,
      "y": 41,
      "z": -1,
      "name": "Rock_Ice"
    },
    {
      "x": -27,
      "y": 42,
      "z": -1,
      "name": "Rock_Ice"
    },
    {
      "x": -27,
      "y": 43,
      "z": -1,
      "name": "Rock_Ice"
    },
    {
      "x": -27,
      "y": 44,
      "z": -1,
      "name": "Soil_Snow"
    },
    {
      "x": -27,
      "y": 36,
      "z": 0,
      "name": "Rock_Ice"
    },
    {
      "x": -27,
      "y": 37,
      "z": 0,
      "name": "Rock_Ice"
    },
    {
      "x": -27,
      "y": 38,
      "z": 0,
      "name": "Rock_Ice"
    },
    {
      "x": -27,
      "y": 39,
      "z": 0,
      "name": "Rock_Ice"
    },
    {
      "x": -27,
      "y": 40,
      "z": 0,
      "name": "Rock_Ice"
    },
    {
      "x": -27,
      "y": 41,
      "z": 0,
      "name": "Rock_Ice"
    },
    {
      "x": -27,
      "y": 42,
      "z": 0,
      "name": "Rock_Ice"
    },
    {
      "x": -27,
      "y": 43,
      "z": 0,
      "name": "Rock_Ice"
    },
    {
      "x": -27,
      "y": 44,
      "z": 0,
      "name": "Soil_Snow"
    },
    {
      "x": -27,
      "y": 38,
      "z": 1,
      "name": "Rock_Ice"
    },
    {
      "x": -27,
      "y": 39,
      "z": 1,
      "name": "Rock_Ice"
    },
    {
      "x": -27,
      "y": 40,
      "z": 1,
      "name": "Rock_Ice"
    },
    {
      "x": -27,
      "y": 41,
      "z": 1,
      "name": "Rock_Ice"
    },
    {
      "x": -27,
      "y": 42,
      "z": 1,
      "name": "Rock_Ice"
    },
    {
      "x": -26,
      "y": 35,
      "z": -6,
      "name": "Rock_Ice"
    },
    {
      "x": -26,
      "y": 36,
      "z": -6,
      "name": "Rock_Ice"
    },
    {
      "x": -26,
      "y": 37,
      "z": -6,
      "name": "Rock_Ice"
    },
    {
      "x": -26,
      "y": 38,
      "z": -6,
      "name": "Rock_Ice"
    },
    {
      "x": -26,
      "y": 39,
      "z": -6,
      "name": "Rock_Ice"
    },
    {
      "x": -26,
      "y": 40,
      "z": -6,
      "name": "Rock_Ice"
    },
    {
      "x": -26,
      "y": 41,
      "z": -6,
      "name": "Soil_Snow"
    },
    {
      "x": -26,
      "y": 33,
      "z": -5,
      "name": "Rock_Ice"
    },
    {
      "x": -26,
      "y": 34,
      "z": -5,
      "name": "Rock_Ice"
    },
    {
      "x": -26,
      "y": 35,
      "z": -5,
      "name": "Rock_Ice"
    },
    {
      "x": -26,
      "y": 36,
      "z": -5,
      "name": "Rock_Ice"
    },
    {
      "x": -26,
      "y": 37,
      "z": -5,
      "name": "Rock_Ice"
    },
    {
      "x": -26,
      "y": 38,
      "z": -5,
      "name": "Rock_Ice"
    },
    {
      "x": -26,
      "y": 39,
      "z": -5,
      "name": "Rock_Ice"
    },
    {
      "x": -26,
      "y": 40,
      "z": -5,
      "name": "Rock_Ice"
    },
    {
      "x": -26,
      "y": 41,
      "z": -5,
      "name": "Rock_Ice"
    },
    {
      "x": -26,
      "y": 42,
      "z": -5,
      "name": "Rock_Ice"
    },
    {
      "x": -26,
      "y": 43,
      "z": -5,
      "name": "Rock_Ice"
    },
    {
      "x": -26,
      "y": 44,
      "z": -5,
      "name": "Soil_Snow"
    },
    {
      "x": -26,
      "y": 32,
      "z": -4,
      "name": "Rock_Ice"
    },
    {
      "x": -26,
      "y": 33,
      "z": -4,
      "name": "Rock_Ice"
    },
    {
      "x": -26,
      "y": 34,
      "z": -4,
      "name": "Rock_Ice"
    },
    {
      "x": -26,
      "y": 35,
      "z": -4,
      "name": "Rock_Ice"
    },
    {
      "x": -26,
      "y": 36,
      "z": -4,
      "name": "Rock_Ice"
    },
    {
      "x": -26,
      "y": 37,
      "z": -4,
      "name": "Rock_Ice"
    },
    {
      "x": -26,
      "y": 38,
      "z": -4,
      "name": "Rock_Ice"
    },
    {
      "x": -26,
      "y": 39,
      "z": -4,
      "name": "Rock_Ice"
    },
    {
      "x": -26,
      "y": 40,
      "z": -4,
      "name": "Rock_Ice"
    },
    {
      "x": -26,
      "y": 41,
      "z": -4,
      "name": "Rock_Ice"
    },
    {
      "x": -26,
      "y": 42,
      "z": -4,
      "name": "Rock_Ice"
    },
    {
      "x": -26,
      "y": 43,
      "z": -4,
      "name": "Rock_Ice"
    },
    {
      "x": -26,
      "y": 44,
      "z": -4,
      "name": "Rock_Ice"
    },
    {
      "x": -26,
      "y": 45,
      "z": -4,
      "name": "Soil_Snow"
    },
    {
      "x": -26,
      "y": 32,
      "z": -3,
      "name": "Rock_Ice"
    },
    {
      "x": -26,
      "y": 33,
      "z": -3,
      "name": "Rock_Ice"
    },
    {
      "x": -26,
      "y": 34,
      "z": -3,
      "name": "Rock_Ice"
    },
    {
      "x": -26,
      "y": 35,
      "z": -3,
      "name": "Rock_Ice"
    },
    {
      "x": -26,
      "y": 36,
      "z": -3,
      "name": "Rock_Ice"
    },
    {
      "x": -26,
      "y": 37,
      "z": -3,
      "name": "Rock_Ice"
    },
    {
      "x": -26,
      "y": 38,
      "z": -3,
      "name": "Rock_Ice"
    },
    {
      "x": -26,
      "y": 39,
      "z": -3,
      "name": "Rock_Ice"
    },
    {
      "x": -26,
      "y": 40,
      "z": -3,
      "name": "Rock_Ice"
    },
    {
      "x": -26,
      "y": 41,
      "z": -3,
      "name": "Rock_Ice"
    },
    {
      "x": -26,
      "y": 42,
      "z": -3,
      "name": "Rock_Ice"
    },
    {
      "x": -26,
      "y": 43,
      "z": -3,
      "name": "Rock_Ice"
    },
    {
      "x": -26,
      "y": 44,
      "z": -3,
      "name": "Rock_Ice"
    },
    {
      "x": -26,
      "y": 45,
      "z": -3,
      "name": "Rock_Ice"
    },
    {
      "x": -26,
      "y": 46,
      "z": -3,
      "name": "Rock_Ice"
    },
    {
      "x": -26,
      "y": 47,
      "z": -3,
      "name": "Soil_Snow"
    },
    {
      "x": -26,
      "y": 31,
      "z": -2,
      "name": "Rock_Ice"
    },
    {
      "x": -26,
      "y": 32,
      "z": -2,
      "name": "Rock_Ice"
    },
    {
      "x": -26,
      "y": 33,
      "z": -2,
      "name": "Rock_Ice"
    },
    {
      "x": -26,
      "y": 34,
      "z": -2,
      "name": "Rock_Ice"
    },
    {
      "x": -26,
      "y": 35,
      "z": -2,
      "name": "Rock_Ice"
    },
    {
      "x": -26,
      "y": 36,
      "z": -2,
      "name": "Rock_Ice"
    },
    {
      "x": -26,
      "y": 37,
      "z": -2,
      "name": "Rock_Ice"
    },
    {
      "x": -26,
      "y": 38,
      "z": -2,
      "name": "Rock_Ice"
    },
    {
      "x": -26,
      "y": 39,
      "z": -2,
      "name": "Rock_Ice"
    },
    {
      "x": -26,
      "y": 40,
      "z": -2,
      "name": "Rock_Ice"
    },
    {
      "x": -26,
      "y": 41,
      "z": -2,
      "name": "Rock_Ice"
    },
    {
      "x": -26,
      "y": 42,
      "z": -2,
      "name": "Rock_Ice"
    },
    {
      "x": -26,
      "y": 43,
      "z": -2,
      "name": "Rock_Ice"
    },
    {
      "x": -26,
      "y": 44,
      "z": -2,
      "name": "Rock_Ice"
    },
    {
      "x": -26,
      "y": 45,
      "z": -2,
      "name": "Rock_Ice"
    },
    {
      "x": -26,
      "y": 46,
      "z": -2,
      "name": "Rock_Ice"
    },
    {
      "x": -26,
      "y": 47,
      "z": -2,
      "name": "Rock_Ice"
    },
    {
      "x": -26,
      "y": 48,
      "z": -2,
      "name": "Soil_Snow"
    },
    {
      "x": -26,
      "y": 31,
      "z": -1,
      "name": "Rock_Ice"
    },
    {
      "x": -26,
      "y": 32,
      "z": -1,
      "name": "Rock_Ice"
    },
    {
      "x": -26,
      "y": 33,
      "z": -1,
      "name": "Rock_Ice"
    },
    {
      "x": -26,
      "y": 34,
      "z": -1,
      "name": "Rock_Ice"
    },
    {
      "x": -26,
      "y": 35,
      "z": -1,
      "name": "Rock_Ice"
    },
    {
      "x": -26,
      "y": 36,
      "z": -1,
      "name": "Rock_Ice"
    },
    {
      "x": -26,
      "y": 37,
      "z": -1,
      "name": "Rock_Ice"
    },
    {
      "x": -26,
      "y": 38,
      "z": -1,
      "name": "Rock_Ice"
    },
    {
      "x": -26,
      "y": 39,
      "z": -1,
      "name": "Rock_Ice"
    },
    {
      "x": -26,
      "y": 40,
      "z": -1,
      "name": "Rock_Ice"
    },
    {
      "x": -26,
      "y": 41,
      "z": -1,
      "name": "Rock_Ice"
    },
    {
      "x": -26,
      "y": 42,
      "z": -1,
      "name": "Rock_Ice"
    },
    {
      "x": -26,
      "y": 43,
      "z": -1,
      "name": "Rock_Ice"
    },
    {
      "x": -26,
      "y": 44,
      "z": -1,
      "name": "Rock_Ice"
    },
    {
      "x": -26,
      "y": 45,
      "z": -1,
      "name": "Rock_Ice"
    },
    {
      "x": -26,
      "y": 46,
      "z": -1,
      "name": "Rock_Ice"
    },
    {
      "x": -26,
      "y": 47,
      "z": -1,
      "name": "Rock_Ice"
    },
    {
      "x": -26,
      "y": 48,
      "z": -1,
      "name": "Soil_Snow"
    },
    {
      "x": -26,
      "y": 32,
      "z": 0,
      "name": "Rock_Ice"
    },
    {
      "x": -26,
      "y": 33,
      "z": 0,
      "name": "Rock_Ice"
    },
    {
      "x": -26,
      "y": 34,
      "z": 0,
      "name": "Rock_Ice"
    },
    {
      "x": -26,
      "y": 35,
      "z": 0,
      "name": "Rock_Ice"
    },
    {
      "x": -26,
      "y": 36,
      "z": 0,
      "name": "Rock_Ice"
    },
    {
      "x": -26,
      "y": 37,
      "z": 0,
      "name": "Rock_Ice"
    },
    {
      "x": -26,
      "y": 38,
      "z": 0,
      "name": "Rock_Ice"
    },
    {
      "x": -26,
      "y": 39,
      "z": 0,
      "name": "Rock_Ice"
    },
    {
      "x": -26,
      "y": 40,
      "z": 0,
      "name": "Rock_Ice"
    },
    {
      "x": -26,
      "y": 41,
      "z": 0,
      "name": "Rock_Ice"
    },
    {
      "x": -26,
      "y": 42,
      "z": 0,
      "name": "Rock_Ice"
    },
    {
      "x": -26,
      "y": 43,
      "z": 0,
      "name": "Rock_Ice"
    },
    {
      "x": -26,
      "y": 44,
      "z": 0,
      "name": "Rock_Ice"
    },
    {
      "x": -26,
      "y": 45,
      "z": 0,
      "name": "Rock_Ice"
    },
    {
      "x": -26,
      "y": 46,
      "z": 0,
      "name": "Rock_Ice"
    },
    {
      "x": -26,
      "y": 47,
      "z": 0,
      "name": "Rock_Ice"
    },
    {
      "x": -26,
      "y": 48,
      "z": 0,
      "name": "Soil_Snow"
    },
    {
      "x": -26,
      "y": 33,
      "z": 1,
      "name": "Rock_Ice"
    },
    {
      "x": -26,
      "y": 34,
      "z": 1,
      "name": "Rock_Ice"
    },
    {
      "x": -26,
      "y": 35,
      "z": 1,
      "name": "Rock_Ice"
    },
    {
      "x": -26,
      "y": 36,
      "z": 1,
      "name": "Rock_Ice"
    },
    {
      "x": -26,
      "y": 37,
      "z": 1,
      "name": "Rock_Ice"
    },
    {
      "x": -26,
      "y": 38,
      "z": 1,
      "name": "Rock_Ice"
    },
    {
      "x": -26,
      "y": 39,
      "z": 1,
      "name": "Rock_Ice"
    },
    {
      "x": -26,
      "y": 40,
      "z": 1,
      "name": "Rock_Ice"
    },
    {
      "x": -26,
      "y": 41,
      "z": 1,
      "name": "Rock_Ice"
    },
    {
      "x": -26,
      "y": 42,
      "z": 1,
      "name": "Rock_Ice"
    },
    {
      "x": -26,
      "y": 43,
      "z": 1,
      "name": "Rock_Ice"
    },
    {
      "x": -26,
      "y": 44,
      "z": 1,
      "name": "Rock_Ice"
    },
    {
      "x": -26,
      "y": 45,
      "z": 1,
      "name": "Rock_Ice"
    },
    {
      "x": -26,
      "y": 46,
      "z": 1,
      "name": "Rock_Ice"
    },
    {
      "x": -26,
      "y": 47,
      "z": 1,
      "name": "Rock_Ice"
    },
    {
      "x": -26,
      "y": 48,
      "z": 1,
      "name": "Soil_Snow"
    },
    {
      "x": -26,
      "y": 34,
      "z": 2,
      "name": "Rock_Ice"
    },
    {
      "x": -26,
      "y": 35,
      "z": 2,
      "name": "Rock_Ice"
    },
    {
      "x": -26,
      "y": 36,
      "z": 2,
      "name": "Rock_Ice"
    },
    {
      "x": -26,
      "y": 37,
      "z": 2,
      "name": "Rock_Ice"
    },
    {
      "x": -26,
      "y": 38,
      "z": 2,
      "name": "Rock_Ice"
    },
    {
      "x": -26,
      "y": 39,
      "z": 2,
      "name": "Rock_Ice"
    },
    {
      "x": -26,
      "y": 40,
      "z": 2,
      "name": "Rock_Ice"
    },
    {
      "x": -26,
      "y": 41,
      "z": 2,
      "name": "Rock_Ice"
    },
    {
      "x": -26,
      "y": 42,
      "z": 2,
      "name": "Rock_Ice"
    },
    {
      "x": -26,
      "y": 43,
      "z": 2,
      "name": "Rock_Ice"
    },
    {
      "x": -26,
      "y": 44,
      "z": 2,
      "name": "Rock_Ice"
    },
    {
      "x": -26,
      "y": 45,
      "z": 2,
      "name": "Rock_Ice"
    },
    {
      "x": -26,
      "y": 46,
      "z": 2,
      "name": "Rock_Ice"
    },
    {
      "x": -26,
      "y": 39,
      "z": 3,
      "name": "Rock_Ice"
    },
    {
      "x": -26,
      "y": 40,
      "z": 3,
      "name": "Rock_Ice"
    },
    {
      "x": -26,
      "y": 41,
      "z": 3,
      "name": "Rock_Ice"
    },
    {
      "x": -26,
      "y": 42,
      "z": 3,
      "name": "Soil_Snow"
    },
    {
      "x": -25,
      "y": 36,
      "z": -8,
      "name": "Rock_Ice"
    },
    {
      "x": -25,
      "y": 37,
      "z": -8,
      "name": "Rock_Ice"
    },
    {
      "x": -25,
      "y": 38,
      "z": -8,
      "name": "Soil_Snow"
    },
    {
      "x": -25,
      "y": 33,
      "z": -7,
      "name": "Rock_Ice_Permafrost"
    },
    {
      "x": -25,
      "y": 34,
      "z": -7,
      "name": "Rock_Ice_Permafrost"
    },
    {
      "x": -25,
      "y": 35,
      "z": -7,
      "name": "Rock_Ice"
    },
    {
      "x": -25,
      "y": 36,
      "z": -7,
      "name": "Rock_Ice"
    },
    {
      "x": -25,
      "y": 37,
      "z": -7,
      "name": "Rock_Ice"
    },
    {
      "x": -25,
      "y": 38,
      "z": -7,
      "name": "Rock_Ice"
    },
    {
      "x": -25,
      "y": 39,
      "z": -7,
      "name": "Rock_Ice"
    },
    {
      "x": -25,
      "y": 40,
      "z": -7,
      "name": "Rock_Ice"
    },
    {
      "x": -25,
      "y": 41,
      "z": -7,
      "name": "Rock_Ice"
    },
    {
      "x": -25,
      "y": 42,
      "z": -7,
      "name": "Soil_Snow"
    },
    {
      "x": -25,
      "y": 31,
      "z": -6,
      "name": "Rock_Ice"
    },
    {
      "x": -25,
      "y": 32,
      "z": -6,
      "name": "Rock_Ice"
    },
    {
      "x": -25,
      "y": 33,
      "z": -6,
      "name": "Rock_Ice_Permafrost"
    },
    {
      "x": -25,
      "y": 34,
      "z": -6,
      "name": "Rock_Ice"
    },
    {
      "x": -25,
      "y": 35,
      "z": -6,
      "name": "Rock_Ice"
    },
    {
      "x": -25,
      "y": 36,
      "z": -6,
      "name": "Rock_Ice"
    },
    {
      "x": -25,
      "y": 37,
      "z": -6,
      "name": "Rock_Ice"
    },
    {
      "x": -25,
      "y": 38,
      "z": -6,
      "name": "Rock_Ice"
    },
    {
      "x": -25,
      "y": 39,
      "z": -6,
      "name": "Rock_Ice"
    },
    {
      "x": -25,
      "y": 40,
      "z": -6,
      "name": "Rock_Ice"
    },
    {
      "x": -25,
      "y": 41,
      "z": -6,
      "name": "Rock_Ice"
    },
    {
      "x": -25,
      "y": 42,
      "z": -6,
      "name": "Rock_Ice"
    },
    {
      "x": -25,
      "y": 43,
      "z": -6,
      "name": "Rock_Ice"
    },
    {
      "x": -25,
      "y": 44,
      "z": -6,
      "name": "Soil_Snow"
    },
    {
      "x": -25,
      "y": 30,
      "z": -5,
      "name": "Rock_Ice"
    },
    {
      "x": -25,
      "y": 31,
      "z": -5,
      "name": "Rock_Ice"
    },
    {
      "x": -25,
      "y": 32,
      "z": -5,
      "name": "Rock_Ice_Permafrost"
    },
    {
      "x": -25,
      "y": 33,
      "z": -5,
      "name": "Rock_Ice"
    },
    {
      "x": -25,
      "y": 34,
      "z": -5,
      "name": "Rock_Ice"
    },
    {
      "x": -25,
      "y": 35,
      "z": -5,
      "name": "Rock_Ice"
    },
    {
      "x": -25,
      "y": 36,
      "z": -5,
      "name": "Rock_Ice"
    },
    {
      "x": -25,
      "y": 37,
      "z": -5,
      "name": "Rock_Ice"
    },
    {
      "x": -25,
      "y": 38,
      "z": -5,
      "name": "Rock_Ice"
    },
    {
      "x": -25,
      "y": 39,
      "z": -5,
      "name": "Rock_Ice"
    },
    {
      "x": -25,
      "y": 40,
      "z": -5,
      "name": "Rock_Ice"
    },
    {
      "x": -25,
      "y": 41,
      "z": -5,
      "name": "Rock_Ice"
    },
    {
      "x": -25,
      "y": 42,
      "z": -5,
      "name": "Rock_Ice"
    },
    {
      "x": -25,
      "y": 43,
      "z": -5,
      "name": "Rock_Ice"
    },
    {
      "x": -25,
      "y": 44,
      "z": -5,
      "name": "Rock_Ice"
    },
    {
      "x": -25,
      "y": 45,
      "z": -5,
      "name": "Rock_Ice"
    },
    {
      "x": -25,
      "y": 46,
      "z": -5,
      "name": "Soil_Snow"
    },
    {
      "x": -25,
      "y": 30,
      "z": -4,
      "name": "Rock_Ice"
    },
    {
      "x": -25,
      "y": 31,
      "z": -4,
      "name": "Rock_Ice"
    },
    {
      "x": -25,
      "y": 32,
      "z": -4,
      "name": "Rock_Ice"
    },
    {
      "x": -25,
      "y": 33,
      "z": -4,
      "name": "Rock_Ice"
    },
    {
      "x": -25,
      "y": 34,
      "z": -4,
      "name": "Rock_Ice"
    },
    {
      "x": -25,
      "y": 35,
      "z": -4,
      "name": "Rock_Ice"
    },
    {
      "x": -25,
      "y": 36,
      "z": -4,
      "name": "Rock_Ice"
    },
    {
      "x": -25,
      "y": 37,
      "z": -4,
      "name": "Rock_Ice"
    },
    {
      "x": -25,
      "y": 38,
      "z": -4,
      "name": "Rock_Ice"
    },
    {
      "x": -25,
      "y": 39,
      "z": -4,
      "name": "Rock_Ice"
    },
    {
      "x": -25,
      "y": 40,
      "z": -4,
      "name": "Rock_Ice"
    },
    {
      "x": -25,
      "y": 41,
      "z": -4,
      "name": "Rock_Ice"
    },
    {
      "x": -25,
      "y": 42,
      "z": -4,
      "name": "Rock_Ice"
    },
    {
      "x": -25,
      "y": 43,
      "z": -4,
      "name": "Rock_Ice"
    },
    {
      "x": -25,
      "y": 44,
      "z": -4,
      "name": "Rock_Ice"
    },
    {
      "x": -25,
      "y": 45,
      "z": -4,
      "name": "Rock_Ice"
    },
    {
      "x": -25,
      "y": 46,
      "z": -4,
      "name": "Rock_Ice"
    },
    {
      "x": -25,
      "y": 47,
      "z": -4,
      "name": "Rock_Ice"
    },
    {
      "x": -25,
      "y": 48,
      "z": -4,
      "name": "Soil_Snow"
    },
    {
      "x": -25,
      "y": 29,
      "z": -3,
      "name": "Rock_Ice"
    },
    {
      "x": -25,
      "y": 30,
      "z": -3,
      "name": "Rock_Ice"
    },
    {
      "x": -25,
      "y": 31,
      "z": -3,
      "name": "Rock_Ice"
    },
    {
      "x": -25,
      "y": 32,
      "z": -3,
      "name": "Rock_Ice"
    },
    {
      "x": -25,
      "y": 33,
      "z": -3,
      "name": "Rock_Ice"
    },
    {
      "x": -25,
      "y": 34,
      "z": -3,
      "name": "Rock_Ice"
    },
    {
      "x": -25,
      "y": 35,
      "z": -3,
      "name": "Rock_Ice"
    },
    {
      "x": -25,
      "y": 36,
      "z": -3,
      "name": "Rock_Ice"
    },
    {
      "x": -25,
      "y": 37,
      "z": -3,
      "name": "Rock_Ice"
    },
    {
      "x": -25,
      "y": 38,
      "z": -3,
      "name": "Rock_Ice"
    },
    {
      "x": -25,
      "y": 39,
      "z": -3,
      "name": "Rock_Ice"
    },
    {
      "x": -25,
      "y": 40,
      "z": -3,
      "name": "Rock_Ice"
    },
    {
      "x": -25,
      "y": 41,
      "z": -3,
      "name": "Rock_Ice"
    },
    {
      "x": -25,
      "y": 42,
      "z": -3,
      "name": "Rock_Ice"
    },
    {
      "x": -25,
      "y": 43,
      "z": -3,
      "name": "Rock_Ice"
    },
    {
      "x": -25,
      "y": 44,
      "z": -3,
      "name": "Rock_Ice"
    },
    {
      "x": -25,
      "y": 45,
      "z": -3,
      "name": "Rock_Ice"
    },
    {
      "x": -25,
      "y": 46,
      "z": -3,
      "name": "Rock_Ice"
    },
    {
      "x": -25,
      "y": 47,
      "z": -3,
      "name": "Rock_Ice"
    },
    {
      "x": -25,
      "y": 48,
      "z": -3,
      "name": "Rock_Ice"
    },
    {
      "x": -25,
      "y": 49,
      "z": -3,
      "name": "Soil_Snow"
    },
    {
      "x": -25,
      "y": 29,
      "z": -2,
      "name": "Rock_Ice"
    },
    {
      "x": -25,
      "y": 30,
      "z": -2,
      "name": "Rock_Ice"
    },
    {
      "x": -25,
      "y": 31,
      "z": -2,
      "name": "Rock_Ice"
    },
    {
      "x": -25,
      "y": 32,
      "z": -2,
      "name": "Rock_Ice"
    },
    {
      "x": -25,
      "y": 33,
      "z": -2,
      "name": "Rock_Ice"
    },
    {
      "x": -25,
      "y": 34,
      "z": -2,
      "name": "Rock_Ice"
    },
    {
      "x": -25,
      "y": 35,
      "z": -2,
      "name": "Rock_Ice"
    },
    {
      "x": -25,
      "y": 36,
      "z": -2,
      "name": "Rock_Ice"
    },
    {
      "x": -25,
      "y": 37,
      "z": -2,
      "name": "Rock_Ice"
    },
    {
      "x": -25,
      "y": 38,
      "z": -2,
      "name": "Rock_Ice"
    },
    {
      "x": -25,
      "y": 39,
      "z": -2,
      "name": "Rock_Ice"
    },
    {
      "x": -25,
      "y": 40,
      "z": -2,
      "name": "Rock_Ice"
    },
    {
      "x": -25,
      "y": 41,
      "z": -2,
      "name": "Rock_Ice"
    },
    {
      "x": -25,
      "y": 42,
      "z": -2,
      "name": "Rock_Ice"
    },
    {
      "x": -25,
      "y": 43,
      "z": -2,
      "name": "Rock_Ice"
    },
    {
      "x": -25,
      "y": 44,
      "z": -2,
      "name": "Rock_Ice"
    },
    {
      "x": -25,
      "y": 45,
      "z": -2,
      "name": "Rock_Ice"
    },
    {
      "x": -25,
      "y": 46,
      "z": -2,
      "name": "Rock_Ice"
    },
    {
      "x": -25,
      "y": 47,
      "z": -2,
      "name": "Rock_Ice"
    },
    {
      "x": -25,
      "y": 48,
      "z": -2,
      "name": "Rock_Ice"
    },
    {
      "x": -25,
      "y": 49,
      "z": -2,
      "name": "Rock_Ice"
    },
    {
      "x": -25,
      "y": 50,
      "z": -2,
      "name": "Soil_Snow"
    },
    {
      "x": -25,
      "y": 29,
      "z": -1,
      "name": "Rock_Ice"
    },
    {
      "x": -25,
      "y": 30,
      "z": -1,
      "name": "Rock_Ice"
    },
    {
      "x": -25,
      "y": 31,
      "z": -1,
      "name": "Rock_Ice"
    },
    {
      "x": -25,
      "y": 32,
      "z": -1,
      "name": "Rock_Ice"
    },
    {
      "x": -25,
      "y": 33,
      "z": -1,
      "name": "Rock_Ice"
    },
    {
      "x": -25,
      "y": 34,
      "z": -1,
      "name": "Rock_Ice"
    },
    {
      "x": -25,
      "y": 35,
      "z": -1,
      "name": "Rock_Ice"
    },
    {
      "x": -25,
      "y": 36,
      "z": -1,
      "name": "Rock_Ice"
    },
    {
      "x": -25,
      "y": 37,
      "z": -1,
      "name": "Rock_Ice"
    },
    {
      "x": -25,
      "y": 38,
      "z": -1,
      "name": "Rock_Ice"
    },
    {
      "x": -25,
      "y": 39,
      "z": -1,
      "name": "Rock_Ice"
    },
    {
      "x": -25,
      "y": 40,
      "z": -1,
      "name": "Rock_Ice"
    },
    {
      "x": -25,
      "y": 41,
      "z": -1,
      "name": "Rock_Ice"
    },
    {
      "x": -25,
      "y": 42,
      "z": -1,
      "name": "Rock_Ice"
    },
    {
      "x": -25,
      "y": 43,
      "z": -1,
      "name": "Rock_Ice"
    },
    {
      "x": -25,
      "y": 44,
      "z": -1,
      "name": "Rock_Ice"
    },
    {
      "x": -25,
      "y": 45,
      "z": -1,
      "name": "Rock_Ice"
    },
    {
      "x": -25,
      "y": 46,
      "z": -1,
      "name": "Rock_Ice"
    },
    {
      "x": -25,
      "y": 47,
      "z": -1,
      "name": "Rock_Ice"
    },
    {
      "x": -25,
      "y": 48,
      "z": -1,
      "name": "Rock_Ice"
    },
    {
      "x": -25,
      "y": 49,
      "z": -1,
      "name": "Rock_Ice"
    },
    {
      "x": -25,
      "y": 50,
      "z": -1,
      "name": "Rock_Ice"
    },
    {
      "x": -25,
      "y": 51,
      "z": -1,
      "name": "Soil_Snow"
    },
    {
      "x": -25,
      "y": 29,
      "z": 0,
      "name": "Rock_Ice"
    },
    {
      "x": -25,
      "y": 30,
      "z": 0,
      "name": "Rock_Ice"
    },
    {
      "x": -25,
      "y": 31,
      "z": 0,
      "name": "Rock_Ice"
    },
    {
      "x": -25,
      "y": 32,
      "z": 0,
      "name": "Rock_Ice"
    },
    {
      "x": -25,
      "y": 33,
      "z": 0,
      "name": "Rock_Ice"
    },
    {
      "x": -25,
      "y": 34,
      "z": 0,
      "name": "Rock_Ice"
    },
    {
      "x": -25,
      "y": 35,
      "z": 0,
      "name": "Rock_Ice"
    },
    {
      "x": -25,
      "y": 36,
      "z": 0,
      "name": "Rock_Ice"
    },
    {
      "x": -25,
      "y": 37,
      "z": 0,
      "name": "Rock_Ice"
    },
    {
      "x": -25,
      "y": 38,
      "z": 0,
      "name": "Rock_Ice"
    },
    {
      "x": -25,
      "y": 39,
      "z": 0,
      "name": "Rock_Ice"
    },
    {
      "x": -25,
      "y": 40,
      "z": 0,
      "name": "Rock_Ice"
    },
    {
      "x": -25,
      "y": 41,
      "z": 0,
      "name": "Rock_Ice"
    },
    {
      "x": -25,
      "y": 42,
      "z": 0,
      "name": "Rock_Ice"
    },
    {
      "x": -25,
      "y": 43,
      "z": 0,
      "name": "Rock_Ice"
    },
    {
      "x": -25,
      "y": 44,
      "z": 0,
      "name": "Rock_Ice"
    },
    {
      "x": -25,
      "y": 45,
      "z": 0,
      "name": "Rock_Ice"
    },
    {
      "x": -25,
      "y": 46,
      "z": 0,
      "name": "Rock_Ice"
    },
    {
      "x": -25,
      "y": 47,
      "z": 0,
      "name": "Rock_Ice"
    },
    {
      "x": -25,
      "y": 48,
      "z": 0,
      "name": "Rock_Ice"
    },
    {
      "x": -25,
      "y": 49,
      "z": 0,
      "name": "Rock_Ice"
    },
    {
      "x": -25,
      "y": 50,
      "z": 0,
      "name": "Rock_Ice"
    },
    {
      "x": -25,
      "y": 51,
      "z": 0,
      "name": "Soil_Snow"
    },
    {
      "x": -25,
      "y": 30,
      "z": 1,
      "name": "Rock_Ice"
    },
    {
      "x": -25,
      "y": 31,
      "z": 1,
      "name": "Rock_Ice"
    },
    {
      "x": -25,
      "y": 32,
      "z": 1,
      "name": "Rock_Ice"
    },
    {
      "x": -25,
      "y": 33,
      "z": 1,
      "name": "Rock_Ice"
    },
    {
      "x": -25,
      "y": 34,
      "z": 1,
      "name": "Rock_Ice"
    },
    {
      "x": -25,
      "y": 35,
      "z": 1,
      "name": "Rock_Ice"
    },
    {
      "x": -25,
      "y": 36,
      "z": 1,
      "name": "Rock_Ice"
    },
    {
      "x": -25,
      "y": 37,
      "z": 1,
      "name": "Rock_Ice"
    },
    {
      "x": -25,
      "y": 38,
      "z": 1,
      "name": "Rock_Ice"
    },
    {
      "x": -25,
      "y": 39,
      "z": 1,
      "name": "Rock_Ice"
    },
    {
      "x": -25,
      "y": 40,
      "z": 1,
      "name": "Rock_Ice"
    },
    {
      "x": -25,
      "y": 41,
      "z": 1,
      "name": "Rock_Ice"
    },
    {
      "x": -25,
      "y": 42,
      "z": 1,
      "name": "Rock_Ice"
    },
    {
      "x": -25,
      "y": 43,
      "z": 1,
      "name": "Rock_Ice"
    },
    {
      "x": -25,
      "y": 44,
      "z": 1,
      "name": "Rock_Ice"
    },
    {
      "x": -25,
      "y": 45,
      "z": 1,
      "name": "Rock_Ice"
    },
    {
      "x": -25,
      "y": 46,
      "z": 1,
      "name": "Rock_Ice"
    },
    {
      "x": -25,
      "y": 47,
      "z": 1,
      "name": "Rock_Ice"
    },
    {
      "x": -25,
      "y": 48,
      "z": 1,
      "name": "Rock_Ice"
    },
    {
      "x": -25,
      "y": 49,
      "z": 1,
      "name": "Rock_Ice"
    },
    {
      "x": -25,
      "y": 50,
      "z": 1,
      "name": "Rock_Ice"
    },
    {
      "x": -25,
      "y": 51,
      "z": 1,
      "name": "Soil_Snow"
    },
    {
      "x": -25,
      "y": 31,
      "z": 2,
      "name": "Rock_Ice"
    },
    {
      "x": -25,
      "y": 32,
      "z": 2,
      "name": "Rock_Ice"
    },
    {
      "x": -25,
      "y": 33,
      "z": 2,
      "name": "Rock_Ice"
    },
    {
      "x": -25,
      "y": 34,
      "z": 2,
      "name": "Rock_Ice"
    },
    {
      "x": -25,
      "y": 35,
      "z": 2,
      "name": "Rock_Ice"
    },
    {
      "x": -25,
      "y": 36,
      "z": 2,
      "name": "Rock_Ice"
    },
    {
      "x": -25,
      "y": 37,
      "z": 2,
      "name": "Rock_Ice"
    },
    {
      "x": -25,
      "y": 38,
      "z": 2,
      "name": "Rock_Ice"
    },
    {
      "x": -25,
      "y": 39,
      "z": 2,
      "name": "Rock_Ice"
    },
    {
      "x": -25,
      "y": 40,
      "z": 2,
      "name": "Rock_Ice"
    },
    {
      "x": -25,
      "y": 41,
      "z": 2,
      "name": "Rock_Ice"
    },
    {
      "x": -25,
      "y": 42,
      "z": 2,
      "name": "Rock_Ice"
    },
    {
      "x": -25,
      "y": 43,
      "z": 2,
      "name": "Rock_Ice"
    },
    {
      "x": -25,
      "y": 44,
      "z": 2,
      "name": "Rock_Ice"
    },
    {
      "x": -25,
      "y": 45,
      "z": 2,
      "name": "Rock_Ice"
    },
    {
      "x": -25,
      "y": 46,
      "z": 2,
      "name": "Rock_Ice"
    },
    {
      "x": -25,
      "y": 47,
      "z": 2,
      "name": "Rock_Ice"
    },
    {
      "x": -25,
      "y": 48,
      "z": 2,
      "name": "Rock_Ice"
    },
    {
      "x": -25,
      "y": 49,
      "z": 2,
      "name": "Rock_Ice"
    },
    {
      "x": -25,
      "y": 50,
      "z": 2,
      "name": "Soil_Snow"
    },
    {
      "x": -25,
      "y": 33,
      "z": 3,
      "name": "Rock_Ice"
    },
    {
      "x": -25,
      "y": 34,
      "z": 3,
      "name": "Rock_Ice"
    },
    {
      "x": -25,
      "y": 35,
      "z": 3,
      "name": "Rock_Ice"
    },
    {
      "x": -25,
      "y": 36,
      "z": 3,
      "name": "Rock_Ice"
    },
    {
      "x": -25,
      "y": 37,
      "z": 3,
      "name": "Rock_Ice"
    },
    {
      "x": -25,
      "y": 38,
      "z": 3,
      "name": "Rock_Ice"
    },
    {
      "x": -25,
      "y": 39,
      "z": 3,
      "name": "Rock_Ice"
    },
    {
      "x": -25,
      "y": 40,
      "z": 3,
      "name": "Rock_Ice"
    },
    {
      "x": -25,
      "y": 41,
      "z": 3,
      "name": "Rock_Ice"
    },
    {
      "x": -25,
      "y": 42,
      "z": 3,
      "name": "Rock_Ice"
    },
    {
      "x": -25,
      "y": 43,
      "z": 3,
      "name": "Rock_Ice"
    },
    {
      "x": -25,
      "y": 44,
      "z": 3,
      "name": "Rock_Ice"
    },
    {
      "x": -25,
      "y": 45,
      "z": 3,
      "name": "Rock_Ice"
    },
    {
      "x": -25,
      "y": 46,
      "z": 3,
      "name": "Rock_Ice_Permafrost"
    },
    {
      "x": -25,
      "y": 47,
      "z": 3,
      "name": "Rock_Ice"
    },
    {
      "x": -25,
      "y": 48,
      "z": 3,
      "name": "Rock_Ice"
    },
    {
      "x": -25,
      "y": 49,
      "z": 3,
      "name": "Soil_Snow"
    },
    {
      "x": -25,
      "y": 40,
      "z": 4,
      "name": "Rock_Ice"
    },
    {
      "x": -25,
      "y": 41,
      "z": 4,
      "name": "Rock_Ice"
    },
    {
      "x": -25,
      "y": 42,
      "z": 4,
      "name": "Rock_Ice"
    },
    {
      "x": -25,
      "y": 43,
      "z": 4,
      "name": "Soil_Snow"
    },
    {
      "x": -24,
      "y": 34,
      "z": -9,
      "name": "Rock_Ice"
    },
    {
      "x": -24,
      "y": 35,
      "z": -9,
      "name": "Rock_Ice_Permafrost"
    },
    {
      "x": -24,
      "y": 36,
      "z": -9,
      "name": "Rock_Ice"
    },
    {
      "x": -24,
      "y": 37,
      "z": -9,
      "name": "Rock_Ice"
    },
    {
      "x": -24,
      "y": 38,
      "z": -9,
      "name": "Rock_Ice"
    },
    {
      "x": -24,
      "y": 39,
      "z": -9,
      "name": "Soil_Snow"
    },
    {
      "x": -24,
      "y": 32,
      "z": -8,
      "name": "Rock_Ice"
    },
    {
      "x": -24,
      "y": 33,
      "z": -8,
      "name": "Rock_Ice_Permafrost"
    },
    {
      "x": -24,
      "y": 34,
      "z": -8,
      "name": "Rock_Ice_Permafrost"
    },
    {
      "x": -24,
      "y": 35,
      "z": -8,
      "name": "Rock_Ice"
    },
    {
      "x": -24,
      "y": 36,
      "z": -8,
      "name": "Rock_Ice"
    },
    {
      "x": -24,
      "y": 37,
      "z": -8,
      "name": "Rock_Ice"
    },
    {
      "x": -24,
      "y": 38,
      "z": -8,
      "name": "Rock_Ice"
    },
    {
      "x": -24,
      "y": 39,
      "z": -8,
      "name": "Rock_Ice"
    },
    {
      "x": -24,
      "y": 40,
      "z": -8,
      "name": "Rock_Ice"
    },
    {
      "x": -24,
      "y": 41,
      "z": -8,
      "name": "Rock_Ice"
    },
    {
      "x": -24,
      "y": 42,
      "z": -8,
      "name": "Soil_Snow"
    },
    {
      "x": -24,
      "y": 30,
      "z": -7,
      "name": "Rock_Ice"
    },
    {
      "x": -24,
      "y": 31,
      "z": -7,
      "name": "Rock_Ice"
    },
    {
      "x": -24,
      "y": 32,
      "z": -7,
      "name": "Rock_Ice"
    },
    {
      "x": -24,
      "y": 33,
      "z": -7,
      "name": "Rock_Ice"
    },
    {
      "x": -24,
      "y": 34,
      "z": -7,
      "name": "Rock_Ice"
    },
    {
      "x": -24,
      "y": 35,
      "z": -7,
      "name": "Rock_Ice"
    },
    {
      "x": -24,
      "y": 36,
      "z": -7,
      "name": "Rock_Ice"
    },
    {
      "x": -24,
      "y": 37,
      "z": -7,
      "name": "Rock_Ice"
    },
    {
      "x": -24,
      "y": 38,
      "z": -7,
      "name": "Rock_Ice"
    },
    {
      "x": -24,
      "y": 39,
      "z": -7,
      "name": "Rock_Ice"
    },
    {
      "x": -24,
      "y": 40,
      "z": -7,
      "name": "Rock_Ice"
    },
    {
      "x": -24,
      "y": 41,
      "z": -7,
      "name": "Rock_Ice"
    },
    {
      "x": -24,
      "y": 42,
      "z": -7,
      "name": "Rock_Ice"
    },
    {
      "x": -24,
      "y": 43,
      "z": -7,
      "name": "Rock_Ice"
    },
    {
      "x": -24,
      "y": 44,
      "z": -7,
      "name": "Soil_Snow"
    },
    {
      "x": -24,
      "y": 29,
      "z": -6,
      "name": "Rock_Ice"
    },
    {
      "x": -24,
      "y": 30,
      "z": -6,
      "name": "Rock_Ice"
    },
    {
      "x": -24,
      "y": 31,
      "z": -6,
      "name": "Rock_Ice"
    },
    {
      "x": -24,
      "y": 32,
      "z": -6,
      "name": "Rock_Ice"
    },
    {
      "x": -24,
      "y": 33,
      "z": -6,
      "name": "Rock_Ice_Permafrost"
    },
    {
      "x": -24,
      "y": 34,
      "z": -6,
      "name": "Rock_Ice_Permafrost"
    },
    {
      "x": -24,
      "y": 35,
      "z": -6,
      "name": "Rock_Ice"
    },
    {
      "x": -24,
      "y": 36,
      "z": -6,
      "name": "Rock_Ice"
    },
    {
      "x": -24,
      "y": 37,
      "z": -6,
      "name": "Rock_Ice"
    },
    {
      "x": -24,
      "y": 38,
      "z": -6,
      "name": "Rock_Ice"
    },
    {
      "x": -24,
      "y": 39,
      "z": -6,
      "name": "Rock_Ice"
    },
    {
      "x": -24,
      "y": 40,
      "z": -6,
      "name": "Rock_Ice"
    },
    {
      "x": -24,
      "y": 41,
      "z": -6,
      "name": "Rock_Ice"
    },
    {
      "x": -24,
      "y": 42,
      "z": -6,
      "name": "Rock_Ice"
    },
    {
      "x": -24,
      "y": 43,
      "z": -6,
      "name": "Rock_Ice"
    },
    {
      "x": -24,
      "y": 44,
      "z": -6,
      "name": "Rock_Ice"
    },
    {
      "x": -24,
      "y": 45,
      "z": -6,
      "name": "Rock_Ice"
    },
    {
      "x": -24,
      "y": 46,
      "z": -6,
      "name": "Soil_Snow"
    },
    {
      "x": -24,
      "y": 28,
      "z": -5,
      "name": "Rock_Ice"
    },
    {
      "x": -24,
      "y": 29,
      "z": -5,
      "name": "Rock_Ice"
    },
    {
      "x": -24,
      "y": 30,
      "z": -5,
      "name": "Rock_Ice"
    },
    {
      "x": -24,
      "y": 31,
      "z": -5,
      "name": "Rock_Ice"
    },
    {
      "x": -24,
      "y": 32,
      "z": -5,
      "name": "Rock_Ice"
    },
    {
      "x": -24,
      "y": 33,
      "z": -5,
      "name": "Rock_Ice_Permafrost"
    },
    {
      "x": -24,
      "y": 34,
      "z": -5,
      "name": "Rock_Ice"
    },
    {
      "x": -24,
      "y": 35,
      "z": -5,
      "name": "Rock_Ice"
    },
    {
      "x": -24,
      "y": 36,
      "z": -5,
      "name": "Rock_Ice"
    },
    {
      "x": -24,
      "y": 37,
      "z": -5,
      "name": "Rock_Ice"
    },
    {
      "x": -24,
      "y": 38,
      "z": -5,
      "name": "Rock_Ice"
    },
    {
      "x": -24,
      "y": 39,
      "z": -5,
      "name": "Rock_Ice"
    },
    {
      "x": -24,
      "y": 40,
      "z": -5,
      "name": "Rock_Ice"
    },
    {
      "x": -24,
      "y": 41,
      "z": -5,
      "name": "Rock_Ice"
    },
    {
      "x": -24,
      "y": 42,
      "z": -5,
      "name": "Rock_Ice"
    },
    {
      "x": -24,
      "y": 43,
      "z": -5,
      "name": "Rock_Ice"
    },
    {
      "x": -24,
      "y": 44,
      "z": -5,
      "name": "Rock_Ice"
    },
    {
      "x": -24,
      "y": 45,
      "z": -5,
      "name": "Rock_Ice"
    },
    {
      "x": -24,
      "y": 46,
      "z": -5,
      "name": "Rock_Ice"
    },
    {
      "x": -24,
      "y": 47,
      "z": -5,
      "name": "Soil_Snow"
    },
    {
      "x": -24,
      "y": 28,
      "z": -4,
      "name": "Rock_Ice"
    },
    {
      "x": -24,
      "y": 29,
      "z": -4,
      "name": "Rock_Ice"
    },
    {
      "x": -24,
      "y": 30,
      "z": -4,
      "name": "Rock_Ice"
    },
    {
      "x": -24,
      "y": 31,
      "z": -4,
      "name": "Rock_Ice"
    },
    {
      "x": -24,
      "y": 32,
      "z": -4,
      "name": "Rock_Ice"
    },
    {
      "x": -24,
      "y": 33,
      "z": -4,
      "name": "Rock_Ice"
    },
    {
      "x": -24,
      "y": 34,
      "z": -4,
      "name": "Rock_Ice"
    },
    {
      "x": -24,
      "y": 35,
      "z": -4,
      "name": "Rock_Ice"
    },
    {
      "x": -24,
      "y": 36,
      "z": -4,
      "name": "Rock_Ice"
    },
    {
      "x": -24,
      "y": 37,
      "z": -4,
      "name": "Rock_Ice"
    },
    {
      "x": -24,
      "y": 38,
      "z": -4,
      "name": "Rock_Ice"
    },
    {
      "x": -24,
      "y": 39,
      "z": -4,
      "name": "Rock_Ice"
    },
    {
      "x": -24,
      "y": 40,
      "z": -4,
      "name": "Rock_Ice"
    },
    {
      "x": -24,
      "y": 41,
      "z": -4,
      "name": "Rock_Ice"
    },
    {
      "x": -24,
      "y": 42,
      "z": -4,
      "name": "Rock_Ice"
    },
    {
      "x": -24,
      "y": 43,
      "z": -4,
      "name": "Rock_Ice"
    },
    {
      "x": -24,
      "y": 44,
      "z": -4,
      "name": "Rock_Ice"
    },
    {
      "x": -24,
      "y": 45,
      "z": -4,
      "name": "Rock_Ice"
    },
    {
      "x": -24,
      "y": 46,
      "z": -4,
      "name": "Rock_Ice"
    },
    {
      "x": -24,
      "y": 47,
      "z": -4,
      "name": "Rock_Ice"
    },
    {
      "x": -24,
      "y": 48,
      "z": -4,
      "name": "Rock_Ice"
    },
    {
      "x": -24,
      "y": 49,
      "z": -4,
      "name": "Soil_Snow"
    },
    {
      "x": -24,
      "y": 27,
      "z": -3,
      "name": "Rock_Ice"
    },
    {
      "x": -24,
      "y": 28,
      "z": -3,
      "name": "Rock_Ice"
    },
    {
      "x": -24,
      "y": 29,
      "z": -3,
      "name": "Rock_Ice"
    },
    {
      "x": -24,
      "y": 30,
      "z": -3,
      "name": "Rock_Ice"
    },
    {
      "x": -24,
      "y": 31,
      "z": -3,
      "name": "Rock_Ice"
    },
    {
      "x": -24,
      "y": 32,
      "z": -3,
      "name": "Rock_Ice"
    },
    {
      "x": -24,
      "y": 33,
      "z": -3,
      "name": "Rock_Ice"
    },
    {
      "x": -24,
      "y": 34,
      "z": -3,
      "name": "Rock_Ice"
    },
    {
      "x": -24,
      "y": 35,
      "z": -3,
      "name": "Rock_Ice"
    },
    {
      "x": -24,
      "y": 36,
      "z": -3,
      "name": "Rock_Ice"
    },
    {
      "x": -24,
      "y": 37,
      "z": -3,
      "name": "Rock_Ice"
    },
    {
      "x": -24,
      "y": 38,
      "z": -3,
      "name": "Rock_Ice"
    },
    {
      "x": -24,
      "y": 39,
      "z": -3,
      "name": "Rock_Ice"
    },
    {
      "x": -24,
      "y": 40,
      "z": -3,
      "name": "Rock_Ice"
    },
    {
      "x": -24,
      "y": 41,
      "z": -3,
      "name": "Rock_Ice"
    },
    {
      "x": -24,
      "y": 42,
      "z": -3,
      "name": "Rock_Ice"
    },
    {
      "x": -24,
      "y": 43,
      "z": -3,
      "name": "Rock_Ice"
    },
    {
      "x": -24,
      "y": 44,
      "z": -3,
      "name": "Rock_Ice"
    },
    {
      "x": -24,
      "y": 45,
      "z": -3,
      "name": "Rock_Ice"
    },
    {
      "x": -24,
      "y": 46,
      "z": -3,
      "name": "Rock_Ice"
    },
    {
      "x": -24,
      "y": 47,
      "z": -3,
      "name": "Rock_Ice"
    },
    {
      "x": -24,
      "y": 48,
      "z": -3,
      "name": "Rock_Ice"
    },
    {
      "x": -24,
      "y": 49,
      "z": -3,
      "name": "Rock_Ice"
    },
    {
      "x": -24,
      "y": 50,
      "z": -3,
      "name": "Rock_Ice"
    },
    {
      "x": -24,
      "y": 51,
      "z": -3,
      "name": "Soil_Snow"
    },
    {
      "x": -24,
      "y": 27,
      "z": -2,
      "name": "Rock_Ice"
    },
    {
      "x": -24,
      "y": 28,
      "z": -2,
      "name": "Rock_Ice"
    },
    {
      "x": -24,
      "y": 29,
      "z": -2,
      "name": "Rock_Ice"
    },
    {
      "x": -24,
      "y": 30,
      "z": -2,
      "name": "Rock_Ice"
    },
    {
      "x": -24,
      "y": 31,
      "z": -2,
      "name": "Rock_Ice"
    },
    {
      "x": -24,
      "y": 32,
      "z": -2,
      "name": "Rock_Ice"
    },
    {
      "x": -24,
      "y": 33,
      "z": -2,
      "name": "Rock_Ice"
    },
    {
      "x": -24,
      "y": 34,
      "z": -2,
      "name": "Rock_Ice"
    },
    {
      "x": -24,
      "y": 35,
      "z": -2,
      "name": "Rock_Ice"
    },
    {
      "x": -24,
      "y": 36,
      "z": -2,
      "name": "Rock_Ice"
    },
    {
      "x": -24,
      "y": 37,
      "z": -2,
      "name": "Rock_Ice"
    },
    {
      "x": -24,
      "y": 38,
      "z": -2,
      "name": "Rock_Ice"
    },
    {
      "x": -24,
      "y": 39,
      "z": -2,
      "name": "Rock_Ice"
    },
    {
      "x": -24,
      "y": 40,
      "z": -2,
      "name": "Rock_Ice"
    },
    {
      "x": -24,
      "y": 41,
      "z": -2,
      "name": "Rock_Ice"
    },
    {
      "x": -24,
      "y": 42,
      "z": -2,
      "name": "Rock_Ice"
    },
    {
      "x": -24,
      "y": 43,
      "z": -2,
      "name": "Rock_Ice"
    },
    {
      "x": -24,
      "y": 44,
      "z": -2,
      "name": "Rock_Ice"
    },
    {
      "x": -24,
      "y": 45,
      "z": -2,
      "name": "Rock_Ice"
    },
    {
      "x": -24,
      "y": 46,
      "z": -2,
      "name": "Rock_Ice"
    },
    {
      "x": -24,
      "y": 47,
      "z": -2,
      "name": "Rock_Ice"
    },
    {
      "x": -24,
      "y": 48,
      "z": -2,
      "name": "Rock_Ice"
    },
    {
      "x": -24,
      "y": 49,
      "z": -2,
      "name": "Rock_Ice"
    },
    {
      "x": -24,
      "y": 50,
      "z": -2,
      "name": "Rock_Ice"
    },
    {
      "x": -24,
      "y": 51,
      "z": -2,
      "name": "Rock_Ice"
    },
    {
      "x": -24,
      "y": 52,
      "z": -2,
      "name": "Soil_Snow"
    },
    {
      "x": -24,
      "y": 27,
      "z": -1,
      "name": "Rock_Ice"
    },
    {
      "x": -24,
      "y": 28,
      "z": -1,
      "name": "Rock_Ice"
    },
    {
      "x": -24,
      "y": 29,
      "z": -1,
      "name": "Rock_Ice"
    },
    {
      "x": -24,
      "y": 30,
      "z": -1,
      "name": "Rock_Ice"
    },
    {
      "x": -24,
      "y": 31,
      "z": -1,
      "name": "Rock_Ice"
    },
    {
      "x": -24,
      "y": 32,
      "z": -1,
      "name": "Rock_Ice"
    },
    {
      "x": -24,
      "y": 33,
      "z": -1,
      "name": "Rock_Ice"
    },
    {
      "x": -24,
      "y": 34,
      "z": -1,
      "name": "Rock_Ice"
    },
    {
      "x": -24,
      "y": 35,
      "z": -1,
      "name": "Rock_Ice"
    },
    {
      "x": -24,
      "y": 36,
      "z": -1,
      "name": "Rock_Ice"
    },
    {
      "x": -24,
      "y": 37,
      "z": -1,
      "name": "Rock_Ice"
    },
    {
      "x": -24,
      "y": 38,
      "z": -1,
      "name": "Rock_Ice"
    },
    {
      "x": -24,
      "y": 39,
      "z": -1,
      "name": "Rock_Ice"
    },
    {
      "x": -24,
      "y": 40,
      "z": -1,
      "name": "Rock_Ice"
    },
    {
      "x": -24,
      "y": 41,
      "z": -1,
      "name": "Rock_Ice"
    },
    {
      "x": -24,
      "y": 42,
      "z": -1,
      "name": "Rock_Ice"
    },
    {
      "x": -24,
      "y": 43,
      "z": -1,
      "name": "Rock_Ice"
    },
    {
      "x": -24,
      "y": 44,
      "z": -1,
      "name": "Rock_Ice"
    },
    {
      "x": -24,
      "y": 45,
      "z": -1,
      "name": "Rock_Ice"
    },
    {
      "x": -24,
      "y": 46,
      "z": -1,
      "name": "Rock_Ice"
    },
    {
      "x": -24,
      "y": 47,
      "z": -1,
      "name": "Rock_Ice"
    },
    {
      "x": -24,
      "y": 48,
      "z": -1,
      "name": "Rock_Ice"
    },
    {
      "x": -24,
      "y": 49,
      "z": -1,
      "name": "Rock_Ice"
    },
    {
      "x": -24,
      "y": 50,
      "z": -1,
      "name": "Rock_Ice"
    },
    {
      "x": -24,
      "y": 51,
      "z": -1,
      "name": "Rock_Ice"
    },
    {
      "x": -24,
      "y": 52,
      "z": -1,
      "name": "Rock_Ice"
    },
    {
      "x": -24,
      "y": 53,
      "z": -1,
      "name": "Soil_Snow"
    },
    {
      "x": -24,
      "y": 27,
      "z": 0,
      "name": "Rock_Ice"
    },
    {
      "x": -24,
      "y": 28,
      "z": 0,
      "name": "Rock_Ice"
    },
    {
      "x": -24,
      "y": 29,
      "z": 0,
      "name": "Rock_Ice"
    },
    {
      "x": -24,
      "y": 30,
      "z": 0,
      "name": "Rock_Ice"
    },
    {
      "x": -24,
      "y": 31,
      "z": 0,
      "name": "Rock_Ice"
    },
    {
      "x": -24,
      "y": 32,
      "z": 0,
      "name": "Rock_Ice"
    },
    {
      "x": -24,
      "y": 33,
      "z": 0,
      "name": "Rock_Ice"
    },
    {
      "x": -24,
      "y": 34,
      "z": 0,
      "name": "Rock_Ice"
    },
    {
      "x": -24,
      "y": 35,
      "z": 0,
      "name": "Rock_Ice"
    },
    {
      "x": -24,
      "y": 36,
      "z": 0,
      "name": "Rock_Ice"
    },
    {
      "x": -24,
      "y": 37,
      "z": 0,
      "name": "Rock_Ice"
    },
    {
      "x": -24,
      "y": 38,
      "z": 0,
      "name": "Rock_Ice"
    },
    {
      "x": -24,
      "y": 39,
      "z": 0,
      "name": "Rock_Ice"
    },
    {
      "x": -24,
      "y": 40,
      "z": 0,
      "name": "Rock_Ice"
    },
    {
      "x": -24,
      "y": 41,
      "z": 0,
      "name": "Rock_Ice"
    },
    {
      "x": -24,
      "y": 42,
      "z": 0,
      "name": "Rock_Ice"
    },
    {
      "x": -24,
      "y": 43,
      "z": 0,
      "name": "Rock_Ice"
    },
    {
      "x": -24,
      "y": 44,
      "z": 0,
      "name": "Rock_Ice"
    },
    {
      "x": -24,
      "y": 45,
      "z": 0,
      "name": "Rock_Ice"
    },
    {
      "x": -24,
      "y": 46,
      "z": 0,
      "name": "Rock_Ice"
    },
    {
      "x": -24,
      "y": 47,
      "z": 0,
      "name": "Rock_Ice"
    },
    {
      "x": -24,
      "y": 48,
      "z": 0,
      "name": "Rock_Ice"
    },
    {
      "x": -24,
      "y": 49,
      "z": 0,
      "name": "Rock_Ice"
    },
    {
      "x": -24,
      "y": 50,
      "z": 0,
      "name": "Rock_Ice"
    },
    {
      "x": -24,
      "y": 51,
      "z": 0,
      "name": "Rock_Ice"
    },
    {
      "x": -24,
      "y": 52,
      "z": 0,
      "name": "Rock_Ice"
    },
    {
      "x": -24,
      "y": 53,
      "z": 0,
      "name": "Rock_Ice"
    },
    {
      "x": -24,
      "y": 54,
      "z": 0,
      "name": "Soil_Snow"
    },
    {
      "x": -24,
      "y": 28,
      "z": 1,
      "name": "Rock_Ice"
    },
    {
      "x": -24,
      "y": 29,
      "z": 1,
      "name": "Rock_Ice"
    },
    {
      "x": -24,
      "y": 30,
      "z": 1,
      "name": "Rock_Ice"
    },
    {
      "x": -24,
      "y": 31,
      "z": 1,
      "name": "Rock_Ice"
    },
    {
      "x": -24,
      "y": 32,
      "z": 1,
      "name": "Rock_Ice"
    },
    {
      "x": -24,
      "y": 33,
      "z": 1,
      "name": "Rock_Ice"
    },
    {
      "x": -24,
      "y": 34,
      "z": 1,
      "name": "Rock_Ice"
    },
    {
      "x": -24,
      "y": 35,
      "z": 1,
      "name": "Rock_Ice"
    },
    {
      "x": -24,
      "y": 36,
      "z": 1,
      "name": "Rock_Ice"
    },
    {
      "x": -24,
      "y": 37,
      "z": 1,
      "name": "Rock_Ice"
    },
    {
      "x": -24,
      "y": 38,
      "z": 1,
      "name": "Rock_Ice"
    },
    {
      "x": -24,
      "y": 39,
      "z": 1,
      "name": "Rock_Ice"
    },
    {
      "x": -24,
      "y": 40,
      "z": 1,
      "name": "Rock_Ice"
    },
    {
      "x": -24,
      "y": 41,
      "z": 1,
      "name": "Rock_Ice"
    },
    {
      "x": -24,
      "y": 42,
      "z": 1,
      "name": "Rock_Ice"
    },
    {
      "x": -24,
      "y": 43,
      "z": 1,
      "name": "Rock_Ice"
    },
    {
      "x": -24,
      "y": 44,
      "z": 1,
      "name": "Rock_Ice"
    },
    {
      "x": -24,
      "y": 45,
      "z": 1,
      "name": "Rock_Ice"
    },
    {
      "x": -24,
      "y": 46,
      "z": 1,
      "name": "Rock_Ice"
    },
    {
      "x": -24,
      "y": 47,
      "z": 1,
      "name": "Rock_Ice"
    },
    {
      "x": -24,
      "y": 48,
      "z": 1,
      "name": "Rock_Ice"
    },
    {
      "x": -24,
      "y": 49,
      "z": 1,
      "name": "Rock_Ice"
    },
    {
      "x": -24,
      "y": 50,
      "z": 1,
      "name": "Rock_Ice"
    },
    {
      "x": -24,
      "y": 51,
      "z": 1,
      "name": "Rock_Ice"
    },
    {
      "x": -24,
      "y": 52,
      "z": 1,
      "name": "Rock_Ice"
    },
    {
      "x": -24,
      "y": 53,
      "z": 1,
      "name": "Rock_Ice"
    },
    {
      "x": -24,
      "y": 54,
      "z": 1,
      "name": "Soil_Snow"
    },
    {
      "x": -24,
      "y": 29,
      "z": 2,
      "name": "Rock_Ice"
    },
    {
      "x": -24,
      "y": 30,
      "z": 2,
      "name": "Rock_Ice"
    },
    {
      "x": -24,
      "y": 31,
      "z": 2,
      "name": "Rock_Ice"
    },
    {
      "x": -24,
      "y": 32,
      "z": 2,
      "name": "Rock_Ice"
    },
    {
      "x": -24,
      "y": 33,
      "z": 2,
      "name": "Rock_Ice"
    },
    {
      "x": -24,
      "y": 34,
      "z": 2,
      "name": "Rock_Ice"
    },
    {
      "x": -24,
      "y": 35,
      "z": 2,
      "name": "Rock_Ice"
    },
    {
      "x": -24,
      "y": 36,
      "z": 2,
      "name": "Rock_Ice"
    },
    {
      "x": -24,
      "y": 37,
      "z": 2,
      "name": "Rock_Ice"
    },
    {
      "x": -24,
      "y": 38,
      "z": 2,
      "name": "Rock_Ice"
    },
    {
      "x": -24,
      "y": 39,
      "z": 2,
      "name": "Rock_Ice"
    },
    {
      "x": -24,
      "y": 40,
      "z": 2,
      "name": "Rock_Ice"
    },
    {
      "x": -24,
      "y": 41,
      "z": 2,
      "name": "Rock_Ice"
    },
    {
      "x": -24,
      "y": 42,
      "z": 2,
      "name": "Rock_Ice"
    },
    {
      "x": -24,
      "y": 43,
      "z": 2,
      "name": "Rock_Ice"
    },
    {
      "x": -24,
      "y": 44,
      "z": 2,
      "name": "Rock_Ice"
    },
    {
      "x": -24,
      "y": 45,
      "z": 2,
      "name": "Rock_Ice"
    },
    {
      "x": -24,
      "y": 46,
      "z": 2,
      "name": "Rock_Ice"
    },
    {
      "x": -24,
      "y": 47,
      "z": 2,
      "name": "Rock_Ice"
    },
    {
      "x": -24,
      "y": 48,
      "z": 2,
      "name": "Rock_Ice"
    },
    {
      "x": -24,
      "y": 49,
      "z": 2,
      "name": "Rock_Ice"
    },
    {
      "x": -24,
      "y": 50,
      "z": 2,
      "name": "Rock_Ice"
    },
    {
      "x": -24,
      "y": 51,
      "z": 2,
      "name": "Rock_Ice_Permafrost"
    },
    {
      "x": -24,
      "y": 52,
      "z": 2,
      "name": "Rock_Ice"
    },
    {
      "x": -24,
      "y": 53,
      "z": 2,
      "name": "Soil_Snow"
    },
    {
      "x": -24,
      "y": 30,
      "z": 3,
      "name": "Rock_Ice"
    },
    {
      "x": -24,
      "y": 31,
      "z": 3,
      "name": "Rock_Ice"
    },
    {
      "x": -24,
      "y": 32,
      "z": 3,
      "name": "Rock_Ice"
    },
    {
      "x": -24,
      "y": 33,
      "z": 3,
      "name": "Rock_Ice"
    },
    {
      "x": -24,
      "y": 34,
      "z": 3,
      "name": "Rock_Ice"
    },
    {
      "x": -24,
      "y": 35,
      "z": 3,
      "name": "Rock_Ice"
    },
    {
      "x": -24,
      "y": 36,
      "z": 3,
      "name": "Rock_Ice"
    },
    {
      "x": -24,
      "y": 37,
      "z": 3,
      "name": "Rock_Ice"
    },
    {
      "x": -24,
      "y": 38,
      "z": 3,
      "name": "Rock_Ice"
    },
    {
      "x": -24,
      "y": 39,
      "z": 3,
      "name": "Rock_Ice"
    },
    {
      "x": -24,
      "y": 40,
      "z": 3,
      "name": "Rock_Ice"
    },
    {
      "x": -24,
      "y": 41,
      "z": 3,
      "name": "Rock_Ice"
    },
    {
      "x": -24,
      "y": 42,
      "z": 3,
      "name": "Rock_Ice"
    },
    {
      "x": -24,
      "y": 43,
      "z": 3,
      "name": "Rock_Ice"
    },
    {
      "x": -24,
      "y": 44,
      "z": 3,
      "name": "Rock_Ice"
    },
    {
      "x": -24,
      "y": 45,
      "z": 3,
      "name": "Rock_Ice"
    },
    {
      "x": -24,
      "y": 46,
      "z": 3,
      "name": "Rock_Ice"
    },
    {
      "x": -24,
      "y": 47,
      "z": 3,
      "name": "Rock_Ice_Permafrost"
    },
    {
      "x": -24,
      "y": 48,
      "z": 3,
      "name": "Rock_Ice"
    },
    {
      "x": -24,
      "y": 49,
      "z": 3,
      "name": "Rock_Ice"
    },
    {
      "x": -24,
      "y": 50,
      "z": 3,
      "name": "Rock_Ice_Permafrost"
    },
    {
      "x": -24,
      "y": 51,
      "z": 3,
      "name": "Rock_Ice"
    },
    {
      "x": -24,
      "y": 52,
      "z": 3,
      "name": "Soil_Snow"
    },
    {
      "x": -24,
      "y": 34,
      "z": 4,
      "name": "Rock_Ice"
    },
    {
      "x": -24,
      "y": 35,
      "z": 4,
      "name": "Rock_Ice"
    },
    {
      "x": -24,
      "y": 36,
      "z": 4,
      "name": "Rock_Ice"
    },
    {
      "x": -24,
      "y": 37,
      "z": 4,
      "name": "Rock_Ice"
    },
    {
      "x": -24,
      "y": 38,
      "z": 4,
      "name": "Rock_Ice"
    },
    {
      "x": -24,
      "y": 39,
      "z": 4,
      "name": "Rock_Ice"
    },
    {
      "x": -24,
      "y": 40,
      "z": 4,
      "name": "Rock_Ice"
    },
    {
      "x": -24,
      "y": 41,
      "z": 4,
      "name": "Rock_Ice"
    },
    {
      "x": -24,
      "y": 42,
      "z": 4,
      "name": "Rock_Ice"
    },
    {
      "x": -24,
      "y": 43,
      "z": 4,
      "name": "Rock_Ice"
    },
    {
      "x": -24,
      "y": 44,
      "z": 4,
      "name": "Rock_Ice"
    },
    {
      "x": -24,
      "y": 45,
      "z": 4,
      "name": "Rock_Ice"
    },
    {
      "x": -24,
      "y": 46,
      "z": 4,
      "name": "Rock_Ice"
    },
    {
      "x": -24,
      "y": 47,
      "z": 4,
      "name": "Rock_Ice"
    },
    {
      "x": -24,
      "y": 48,
      "z": 4,
      "name": "Rock_Ice_Permafrost"
    },
    {
      "x": -24,
      "y": 49,
      "z": 4,
      "name": "Rock_Ice"
    },
    {
      "x": -23,
      "y": 33,
      "z": -10,
      "name": "Rock_Ice_Permafrost"
    },
    {
      "x": -23,
      "y": 34,
      "z": -10,
      "name": "Rock_Ice_Permafrost"
    },
    {
      "x": -23,
      "y": 35,
      "z": -10,
      "name": "Rock_Ice_Permafrost"
    },
    {
      "x": -23,
      "y": 36,
      "z": -10,
      "name": "Rock_Ice_Permafrost"
    },
    {
      "x": -23,
      "y": 37,
      "z": -10,
      "name": "Rock_Ice"
    },
    {
      "x": -23,
      "y": 38,
      "z": -10,
      "name": "Soil_Snow"
    },
    {
      "x": -23,
      "y": 31,
      "z": -9,
      "name": "Rock_Ice"
    },
    {
      "x": -23,
      "y": 32,
      "z": -9,
      "name": "Rock_Ice"
    },
    {
      "x": -23,
      "y": 33,
      "z": -9,
      "name": "Rock_Ice_Permafrost"
    },
    {
      "x": -23,
      "y": 34,
      "z": -9,
      "name": "Rock_Ice"
    },
    {
      "x": -23,
      "y": 35,
      "z": -9,
      "name": "Rock_Ice_Permafrost"
    },
    {
      "x": -23,
      "y": 36,
      "z": -9,
      "name": "Rock_Ice"
    },
    {
      "x": -23,
      "y": 37,
      "z": -9,
      "name": "Rock_Ice_Permafrost"
    },
    {
      "x": -23,
      "y": 38,
      "z": -9,
      "name": "Rock_Ice"
    },
    {
      "x": -23,
      "y": 39,
      "z": -9,
      "name": "Rock_Ice"
    },
    {
      "x": -23,
      "y": 40,
      "z": -9,
      "name": "Rock_Ice"
    },
    {
      "x": -23,
      "y": 41,
      "z": -9,
      "name": "Soil_Snow"
    },
    {
      "x": -23,
      "y": 29,
      "z": -8,
      "name": "Rock_Ice"
    },
    {
      "x": -23,
      "y": 30,
      "z": -8,
      "name": "Rock_Ice"
    },
    {
      "x": -23,
      "y": 31,
      "z": -8,
      "name": "Rock_Ice"
    },
    {
      "x": -23,
      "y": 32,
      "z": -8,
      "name": "Rock_Ice"
    },
    {
      "x": -23,
      "y": 33,
      "z": -8,
      "name": "Rock_Ice_Permafrost"
    },
    {
      "x": -23,
      "y": 34,
      "z": -8,
      "name": "Rock_Ice"
    },
    {
      "x": -23,
      "y": 35,
      "z": -8,
      "name": "Rock_Ice"
    },
    {
      "x": -23,
      "y": 36,
      "z": -8,
      "name": "Rock_Ice"
    },
    {
      "x": -23,
      "y": 37,
      "z": -8,
      "name": "Rock_Ice"
    },
    {
      "x": -23,
      "y": 38,
      "z": -8,
      "name": "Rock_Ice"
    },
    {
      "x": -23,
      "y": 39,
      "z": -8,
      "name": "Rock_Ice"
    },
    {
      "x": -23,
      "y": 40,
      "z": -8,
      "name": "Rock_Ice"
    },
    {
      "x": -23,
      "y": 41,
      "z": -8,
      "name": "Rock_Ice"
    },
    {
      "x": -23,
      "y": 42,
      "z": -8,
      "name": "Rock_Ice"
    },
    {
      "x": -23,
      "y": 43,
      "z": -8,
      "name": "Soil_Snow"
    },
    {
      "x": -23,
      "y": 28,
      "z": -7,
      "name": "Rock_Ice"
    },
    {
      "x": -23,
      "y": 29,
      "z": -7,
      "name": "Rock_Ice"
    },
    {
      "x": -23,
      "y": 30,
      "z": -7,
      "name": "Rock_Ice"
    },
    {
      "x": -23,
      "y": 31,
      "z": -7,
      "name": "Rock_Ice"
    },
    {
      "x": -23,
      "y": 32,
      "z": -7,
      "name": "Rock_Ice"
    },
    {
      "x": -23,
      "y": 33,
      "z": -7,
      "name": "Rock_Ice"
    },
    {
      "x": -23,
      "y": 34,
      "z": -7,
      "name": "Rock_Ice"
    },
    {
      "x": -23,
      "y": 35,
      "z": -7,
      "name": "Rock_Ice_Permafrost"
    },
    {
      "x": -23,
      "y": 36,
      "z": -7,
      "name": "Rock_Ice"
    },
    {
      "x": -23,
      "y": 37,
      "z": -7,
      "name": "Rock_Ice"
    },
    {
      "x": -23,
      "y": 38,
      "z": -7,
      "name": "Rock_Ice"
    },
    {
      "x": -23,
      "y": 39,
      "z": -7,
      "name": "Rock_Ice"
    },
    {
      "x": -23,
      "y": 40,
      "z": -7,
      "name": "Rock_Ice"
    },
    {
      "x": -23,
      "y": 41,
      "z": -7,
      "name": "Rock_Ice"
    },
    {
      "x": -23,
      "y": 42,
      "z": -7,
      "name": "Rock_Ice"
    },
    {
      "x": -23,
      "y": 43,
      "z": -7,
      "name": "Rock_Ice"
    },
    {
      "x": -23,
      "y": 44,
      "z": -7,
      "name": "Rock_Ice"
    },
    {
      "x": -23,
      "y": 45,
      "z": -7,
      "name": "Soil_Snow"
    },
    {
      "x": -23,
      "y": 27,
      "z": -6,
      "name": "Rock_Ice"
    },
    {
      "x": -23,
      "y": 28,
      "z": -6,
      "name": "Rock_Ice"
    },
    {
      "x": -23,
      "y": 29,
      "z": -6,
      "name": "Rock_Ice"
    },
    {
      "x": -23,
      "y": 30,
      "z": -6,
      "name": "Rock_Ice"
    },
    {
      "x": -23,
      "y": 31,
      "z": -6,
      "name": "Rock_Ice"
    },
    {
      "x": -23,
      "y": 32,
      "z": -6,
      "name": "Rock_Ice"
    },
    {
      "x": -23,
      "y": 33,
      "z": -6,
      "name": "Rock_Ice"
    },
    {
      "x": -23,
      "y": 34,
      "z": -6,
      "name": "Rock_Ice"
    },
    {
      "x": -23,
      "y": 35,
      "z": -6,
      "name": "Rock_Ice"
    },
    {
      "x": -23,
      "y": 36,
      "z": -6,
      "name": "Rock_Ice"
    },
    {
      "x": -23,
      "y": 37,
      "z": -6,
      "name": "Rock_Ice"
    },
    {
      "x": -23,
      "y": 38,
      "z": -6,
      "name": "Rock_Ice"
    },
    {
      "x": -23,
      "y": 39,
      "z": -6,
      "name": "Rock_Ice"
    },
    {
      "x": -23,
      "y": 40,
      "z": -6,
      "name": "Rock_Ice"
    },
    {
      "x": -23,
      "y": 41,
      "z": -6,
      "name": "Rock_Ice"
    },
    {
      "x": -23,
      "y": 42,
      "z": -6,
      "name": "Rock_Ice"
    },
    {
      "x": -23,
      "y": 43,
      "z": -6,
      "name": "Rock_Ice"
    },
    {
      "x": -23,
      "y": 44,
      "z": -6,
      "name": "Rock_Ice"
    },
    {
      "x": -23,
      "y": 45,
      "z": -6,
      "name": "Rock_Ice"
    },
    {
      "x": -23,
      "y": 46,
      "z": -6,
      "name": "Rock_Ice"
    },
    {
      "x": -23,
      "y": 47,
      "z": -6,
      "name": "Soil_Snow"
    },
    {
      "x": -23,
      "y": 27,
      "z": -5,
      "name": "Rock_Ice"
    },
    {
      "x": -23,
      "y": 28,
      "z": -5,
      "name": "Rock_Ice"
    },
    {
      "x": -23,
      "y": 29,
      "z": -5,
      "name": "Rock_Ice"
    },
    {
      "x": -23,
      "y": 30,
      "z": -5,
      "name": "Rock_Ice"
    },
    {
      "x": -23,
      "y": 31,
      "z": -5,
      "name": "Rock_Ice"
    },
    {
      "x": -23,
      "y": 32,
      "z": -5,
      "name": "Rock_Ice"
    },
    {
      "x": -23,
      "y": 33,
      "z": -5,
      "name": "Rock_Ice"
    },
    {
      "x": -23,
      "y": 34,
      "z": -5,
      "name": "Rock_Ice"
    },
    {
      "x": -23,
      "y": 35,
      "z": -5,
      "name": "Rock_Ice"
    },
    {
      "x": -23,
      "y": 36,
      "z": -5,
      "name": "Rock_Ice"
    },
    {
      "x": -23,
      "y": 37,
      "z": -5,
      "name": "Rock_Ice"
    },
    {
      "x": -23,
      "y": 38,
      "z": -5,
      "name": "Rock_Ice"
    },
    {
      "x": -23,
      "y": 39,
      "z": -5,
      "name": "Rock_Ice"
    },
    {
      "x": -23,
      "y": 40,
      "z": -5,
      "name": "Rock_Ice"
    },
    {
      "x": -23,
      "y": 41,
      "z": -5,
      "name": "Rock_Ice"
    },
    {
      "x": -23,
      "y": 42,
      "z": -5,
      "name": "Rock_Ice"
    },
    {
      "x": -23,
      "y": 43,
      "z": -5,
      "name": "Rock_Ice"
    },
    {
      "x": -23,
      "y": 44,
      "z": -5,
      "name": "Rock_Ice"
    },
    {
      "x": -23,
      "y": 45,
      "z": -5,
      "name": "Rock_Ice"
    },
    {
      "x": -23,
      "y": 46,
      "z": -5,
      "name": "Rock_Ice"
    },
    {
      "x": -23,
      "y": 47,
      "z": -5,
      "name": "Rock_Ice"
    },
    {
      "x": -23,
      "y": 48,
      "z": -5,
      "name": "Soil_Snow"
    },
    {
      "x": -23,
      "y": 26,
      "z": -4,
      "name": "Rock_Ice"
    },
    {
      "x": -23,
      "y": 27,
      "z": -4,
      "name": "Rock_Ice_Permafrost"
    },
    {
      "x": -23,
      "y": 28,
      "z": -4,
      "name": "Rock_Ice"
    },
    {
      "x": -23,
      "y": 29,
      "z": -4,
      "name": "Rock_Ice"
    },
    {
      "x": -23,
      "y": 30,
      "z": -4,
      "name": "Rock_Ice"
    },
    {
      "x": -23,
      "y": 31,
      "z": -4,
      "name": "Rock_Ice"
    },
    {
      "x": -23,
      "y": 32,
      "z": -4,
      "name": "Rock_Ice"
    },
    {
      "x": -23,
      "y": 33,
      "z": -4,
      "name": "Rock_Ice"
    },
    {
      "x": -23,
      "y": 34,
      "z": -4,
      "name": "Rock_Ice"
    },
    {
      "x": -23,
      "y": 35,
      "z": -4,
      "name": "Rock_Ice"
    },
    {
      "x": -23,
      "y": 36,
      "z": -4,
      "name": "Rock_Ice"
    },
    {
      "x": -23,
      "y": 37,
      "z": -4,
      "name": "Rock_Ice"
    },
    {
      "x": -23,
      "y": 38,
      "z": -4,
      "name": "Rock_Ice"
    },
    {
      "x": -23,
      "y": 39,
      "z": -4,
      "name": "Rock_Ice"
    },
    {
      "x": -23,
      "y": 40,
      "z": -4,
      "name": "Rock_Ice"
    },
    {
      "x": -23,
      "y": 41,
      "z": -4,
      "name": "Rock_Ice"
    },
    {
      "x": -23,
      "y": 42,
      "z": -4,
      "name": "Rock_Ice"
    },
    {
      "x": -23,
      "y": 43,
      "z": -4,
      "name": "Rock_Ice"
    },
    {
      "x": -23,
      "y": 44,
      "z": -4,
      "name": "Rock_Ice"
    },
    {
      "x": -23,
      "y": 45,
      "z": -4,
      "name": "Rock_Ice"
    },
    {
      "x": -23,
      "y": 46,
      "z": -4,
      "name": "Rock_Ice"
    },
    {
      "x": -23,
      "y": 47,
      "z": -4,
      "name": "Rock_Ice"
    },
    {
      "x": -23,
      "y": 48,
      "z": -4,
      "name": "Rock_Ice"
    },
    {
      "x": -23,
      "y": 49,
      "z": -4,
      "name": "Rock_Ice"
    },
    {
      "x": -23,
      "y": 50,
      "z": -4,
      "name": "Soil_Snow"
    },
    {
      "x": -23,
      "y": 26,
      "z": -3,
      "name": "Rock_Ice"
    },
    {
      "x": -23,
      "y": 27,
      "z": -3,
      "name": "Rock_Ice"
    },
    {
      "x": -23,
      "y": 28,
      "z": -3,
      "name": "Rock_Ice"
    },
    {
      "x": -23,
      "y": 29,
      "z": -3,
      "name": "Rock_Ice"
    },
    {
      "x": -23,
      "y": 30,
      "z": -3,
      "name": "Rock_Ice"
    },
    {
      "x": -23,
      "y": 31,
      "z": -3,
      "name": "Rock_Ice"
    },
    {
      "x": -23,
      "y": 32,
      "z": -3,
      "name": "Rock_Ice"
    },
    {
      "x": -23,
      "y": 33,
      "z": -3,
      "name": "Rock_Ice"
    },
    {
      "x": -23,
      "y": 34,
      "z": -3,
      "name": "Rock_Ice"
    },
    {
      "x": -23,
      "y": 35,
      "z": -3,
      "name": "Rock_Ice"
    },
    {
      "x": -23,
      "y": 36,
      "z": -3,
      "name": "Rock_Ice"
    },
    {
      "x": -23,
      "y": 37,
      "z": -3,
      "name": "Rock_Ice"
    },
    {
      "x": -23,
      "y": 38,
      "z": -3,
      "name": "Rock_Ice"
    },
    {
      "x": -23,
      "y": 39,
      "z": -3,
      "name": "Rock_Ice"
    },
    {
      "x": -23,
      "y": 40,
      "z": -3,
      "name": "Rock_Ice"
    },
    {
      "x": -23,
      "y": 41,
      "z": -3,
      "name": "Rock_Ice"
    },
    {
      "x": -23,
      "y": 42,
      "z": -3,
      "name": "Rock_Ice"
    },
    {
      "x": -23,
      "y": 43,
      "z": -3,
      "name": "Rock_Ice"
    },
    {
      "x": -23,
      "y": 44,
      "z": -3,
      "name": "Rock_Ice"
    },
    {
      "x": -23,
      "y": 45,
      "z": -3,
      "name": "Rock_Ice"
    },
    {
      "x": -23,
      "y": 46,
      "z": -3,
      "name": "Rock_Ice"
    },
    {
      "x": -23,
      "y": 47,
      "z": -3,
      "name": "Rock_Ice"
    },
    {
      "x": -23,
      "y": 48,
      "z": -3,
      "name": "Rock_Ice"
    },
    {
      "x": -23,
      "y": 49,
      "z": -3,
      "name": "Rock_Ice"
    },
    {
      "x": -23,
      "y": 50,
      "z": -3,
      "name": "Rock_Ice"
    },
    {
      "x": -23,
      "y": 51,
      "z": -3,
      "name": "Rock_Ice"
    },
    {
      "x": -23,
      "y": 52,
      "z": -3,
      "name": "Soil_Snow"
    },
    {
      "x": -23,
      "y": 25,
      "z": -2,
      "name": "Rock_Ice"
    },
    {
      "x": -23,
      "y": 26,
      "z": -2,
      "name": "Rock_Ice"
    },
    {
      "x": -23,
      "y": 27,
      "z": -2,
      "name": "Rock_Ice"
    },
    {
      "x": -23,
      "y": 28,
      "z": -2,
      "name": "Rock_Ice"
    },
    {
      "x": -23,
      "y": 29,
      "z": -2,
      "name": "Rock_Ice"
    },
    {
      "x": -23,
      "y": 30,
      "z": -2,
      "name": "Rock_Ice"
    },
    {
      "x": -23,
      "y": 31,
      "z": -2,
      "name": "Rock_Ice"
    },
    {
      "x": -23,
      "y": 32,
      "z": -2,
      "name": "Rock_Ice"
    },
    {
      "x": -23,
      "y": 33,
      "z": -2,
      "name": "Rock_Ice"
    },
    {
      "x": -23,
      "y": 34,
      "z": -2,
      "name": "Rock_Ice"
    },
    {
      "x": -23,
      "y": 35,
      "z": -2,
      "name": "Rock_Ice"
    },
    {
      "x": -23,
      "y": 36,
      "z": -2,
      "name": "Rock_Ice"
    },
    {
      "x": -23,
      "y": 37,
      "z": -2,
      "name": "Rock_Ice"
    },
    {
      "x": -23,
      "y": 38,
      "z": -2,
      "name": "Rock_Ice"
    },
    {
      "x": -23,
      "y": 39,
      "z": -2,
      "name": "Rock_Ice"
    },
    {
      "x": -23,
      "y": 40,
      "z": -2,
      "name": "Rock_Ice"
    },
    {
      "x": -23,
      "y": 41,
      "z": -2,
      "name": "Rock_Ice"
    },
    {
      "x": -23,
      "y": 42,
      "z": -2,
      "name": "Rock_Ice"
    },
    {
      "x": -23,
      "y": 43,
      "z": -2,
      "name": "Rock_Ice"
    },
    {
      "x": -23,
      "y": 44,
      "z": -2,
      "name": "Rock_Ice"
    },
    {
      "x": -23,
      "y": 45,
      "z": -2,
      "name": "Rock_Ice"
    },
    {
      "x": -23,
      "y": 46,
      "z": -2,
      "name": "Rock_Ice"
    },
    {
      "x": -23,
      "y": 47,
      "z": -2,
      "name": "Rock_Ice"
    },
    {
      "x": -23,
      "y": 48,
      "z": -2,
      "name": "Rock_Ice"
    },
    {
      "x": -23,
      "y": 49,
      "z": -2,
      "name": "Rock_Ice"
    },
    {
      "x": -23,
      "y": 50,
      "z": -2,
      "name": "Rock_Ice"
    },
    {
      "x": -23,
      "y": 51,
      "z": -2,
      "name": "Rock_Ice"
    },
    {
      "x": -23,
      "y": 52,
      "z": -2,
      "name": "Rock_Ice"
    },
    {
      "x": -23,
      "y": 53,
      "z": -2,
      "name": "Soil_Snow"
    },
    {
      "x": -23,
      "y": 25,
      "z": -1,
      "name": "Rock_Ice"
    },
    {
      "x": -23,
      "y": 26,
      "z": -1,
      "name": "Rock_Ice"
    },
    {
      "x": -23,
      "y": 27,
      "z": -1,
      "name": "Rock_Ice"
    },
    {
      "x": -23,
      "y": 28,
      "z": -1,
      "name": "Rock_Ice"
    },
    {
      "x": -23,
      "y": 29,
      "z": -1,
      "name": "Rock_Ice"
    },
    {
      "x": -23,
      "y": 30,
      "z": -1,
      "name": "Rock_Ice"
    },
    {
      "x": -23,
      "y": 31,
      "z": -1,
      "name": "Rock_Ice"
    },
    {
      "x": -23,
      "y": 32,
      "z": -1,
      "name": "Rock_Ice"
    },
    {
      "x": -23,
      "y": 33,
      "z": -1,
      "name": "Rock_Ice"
    },
    {
      "x": -23,
      "y": 34,
      "z": -1,
      "name": "Rock_Ice"
    },
    {
      "x": -23,
      "y": 35,
      "z": -1,
      "name": "Rock_Ice"
    },
    {
      "x": -23,
      "y": 36,
      "z": -1,
      "name": "Rock_Ice"
    },
    {
      "x": -23,
      "y": 37,
      "z": -1,
      "name": "Rock_Ice"
    },
    {
      "x": -23,
      "y": 38,
      "z": -1,
      "name": "Rock_Ice"
    },
    {
      "x": -23,
      "y": 39,
      "z": -1,
      "name": "Rock_Ice"
    },
    {
      "x": -23,
      "y": 40,
      "z": -1,
      "name": "Rock_Ice"
    },
    {
      "x": -23,
      "y": 41,
      "z": -1,
      "name": "Rock_Ice"
    },
    {
      "x": -23,
      "y": 42,
      "z": -1,
      "name": "Rock_Ice"
    },
    {
      "x": -23,
      "y": 43,
      "z": -1,
      "name": "Rock_Ice"
    },
    {
      "x": -23,
      "y": 44,
      "z": -1,
      "name": "Rock_Ice"
    },
    {
      "x": -23,
      "y": 45,
      "z": -1,
      "name": "Rock_Ice"
    },
    {
      "x": -23,
      "y": 46,
      "z": -1,
      "name": "Rock_Ice"
    },
    {
      "x": -23,
      "y": 47,
      "z": -1,
      "name": "Rock_Ice"
    },
    {
      "x": -23,
      "y": 48,
      "z": -1,
      "name": "Rock_Ice"
    },
    {
      "x": -23,
      "y": 49,
      "z": -1,
      "name": "Rock_Ice"
    },
    {
      "x": -23,
      "y": 50,
      "z": -1,
      "name": "Rock_Ice"
    },
    {
      "x": -23,
      "y": 51,
      "z": -1,
      "name": "Rock_Ice"
    },
    {
      "x": -23,
      "y": 52,
      "z": -1,
      "name": "Rock_Ice_Permafrost"
    },
    {
      "x": -23,
      "y": 53,
      "z": -1,
      "name": "Rock_Ice"
    },
    {
      "x": -23,
      "y": 54,
      "z": -1,
      "name": "Rock_Ice"
    },
    {
      "x": -23,
      "y": 55,
      "z": -1,
      "name": "Soil_Snow"
    },
    {
      "x": -23,
      "y": 25,
      "z": 0,
      "name": "Rock_Ice"
    },
    {
      "x": -23,
      "y": 26,
      "z": 0,
      "name": "Rock_Ice"
    },
    {
      "x": -23,
      "y": 27,
      "z": 0,
      "name": "Rock_Ice"
    },
    {
      "x": -23,
      "y": 28,
      "z": 0,
      "name": "Rock_Ice"
    },
    {
      "x": -23,
      "y": 29,
      "z": 0,
      "name": "Rock_Ice"
    },
    {
      "x": -23,
      "y": 30,
      "z": 0,
      "name": "Rock_Ice"
    },
    {
      "x": -23,
      "y": 31,
      "z": 0,
      "name": "Rock_Ice"
    },
    {
      "x": -23,
      "y": 32,
      "z": 0,
      "name": "Rock_Ice"
    },
    {
      "x": -23,
      "y": 33,
      "z": 0,
      "name": "Rock_Ice"
    },
    {
      "x": -23,
      "y": 34,
      "z": 0,
      "name": "Rock_Ice"
    },
    {
      "x": -23,
      "y": 35,
      "z": 0,
      "name": "Rock_Ice"
    },
    {
      "x": -23,
      "y": 36,
      "z": 0,
      "name": "Rock_Ice"
    },
    {
      "x": -23,
      "y": 37,
      "z": 0,
      "name": "Rock_Ice"
    },
    {
      "x": -23,
      "y": 38,
      "z": 0,
      "name": "Rock_Ice"
    },
    {
      "x": -23,
      "y": 39,
      "z": 0,
      "name": "Rock_Ice"
    },
    {
      "x": -23,
      "y": 40,
      "z": 0,
      "name": "Rock_Ice"
    },
    {
      "x": -23,
      "y": 41,
      "z": 0,
      "name": "Rock_Ice"
    },
    {
      "x": -23,
      "y": 42,
      "z": 0,
      "name": "Rock_Ice"
    },
    {
      "x": -23,
      "y": 43,
      "z": 0,
      "name": "Rock_Ice"
    },
    {
      "x": -23,
      "y": 44,
      "z": 0,
      "name": "Rock_Ice"
    },
    {
      "x": -23,
      "y": 45,
      "z": 0,
      "name": "Rock_Ice"
    },
    {
      "x": -23,
      "y": 46,
      "z": 0,
      "name": "Rock_Ice"
    },
    {
      "x": -23,
      "y": 47,
      "z": 0,
      "name": "Rock_Ice"
    },
    {
      "x": -23,
      "y": 48,
      "z": 0,
      "name": "Rock_Ice"
    },
    {
      "x": -23,
      "y": 49,
      "z": 0,
      "name": "Rock_Ice"
    },
    {
      "x": -23,
      "y": 50,
      "z": 0,
      "name": "Rock_Ice"
    },
    {
      "x": -23,
      "y": 51,
      "z": 0,
      "name": "Rock_Ice"
    },
    {
      "x": -23,
      "y": 52,
      "z": 0,
      "name": "Rock_Ice_Permafrost"
    },
    {
      "x": -23,
      "y": 53,
      "z": 0,
      "name": "Rock_Ice"
    },
    {
      "x": -23,
      "y": 54,
      "z": 0,
      "name": "Rock_Ice"
    },
    {
      "x": -23,
      "y": 55,
      "z": 0,
      "name": "Soil_Snow"
    },
    {
      "x": -23,
      "y": 26,
      "z": 1,
      "name": "Rock_Ice"
    },
    {
      "x": -23,
      "y": 27,
      "z": 1,
      "name": "Rock_Ice"
    },
    {
      "x": -23,
      "y": 28,
      "z": 1,
      "name": "Rock_Ice"
    },
    {
      "x": -23,
      "y": 29,
      "z": 1,
      "name": "Rock_Ice"
    },
    {
      "x": -23,
      "y": 30,
      "z": 1,
      "name": "Rock_Ice"
    },
    {
      "x": -23,
      "y": 31,
      "z": 1,
      "name": "Rock_Ice"
    },
    {
      "x": -23,
      "y": 32,
      "z": 1,
      "name": "Rock_Ice"
    },
    {
      "x": -23,
      "y": 33,
      "z": 1,
      "name": "Rock_Ice"
    },
    {
      "x": -23,
      "y": 34,
      "z": 1,
      "name": "Rock_Ice"
    },
    {
      "x": -23,
      "y": 35,
      "z": 1,
      "name": "Rock_Ice"
    },
    {
      "x": -23,
      "y": 36,
      "z": 1,
      "name": "Rock_Ice"
    },
    {
      "x": -23,
      "y": 37,
      "z": 1,
      "name": "Rock_Ice"
    },
    {
      "x": -23,
      "y": 38,
      "z": 1,
      "name": "Rock_Ice"
    },
    {
      "x": -23,
      "y": 39,
      "z": 1,
      "name": "Rock_Ice"
    },
    {
      "x": -23,
      "y": 40,
      "z": 1,
      "name": "Rock_Ice"
    },
    {
      "x": -23,
      "y": 41,
      "z": 1,
      "name": "Rock_Ice"
    },
    {
      "x": -23,
      "y": 42,
      "z": 1,
      "name": "Rock_Ice"
    },
    {
      "x": -23,
      "y": 43,
      "z": 1,
      "name": "Rock_Ice"
    },
    {
      "x": -23,
      "y": 44,
      "z": 1,
      "name": "Rock_Ice"
    },
    {
      "x": -23,
      "y": 45,
      "z": 1,
      "name": "Rock_Ice"
    },
    {
      "x": -23,
      "y": 46,
      "z": 1,
      "name": "Rock_Ice"
    },
    {
      "x": -23,
      "y": 47,
      "z": 1,
      "name": "Rock_Ice"
    },
    {
      "x": -23,
      "y": 48,
      "z": 1,
      "name": "Rock_Ice"
    },
    {
      "x": -23,
      "y": 49,
      "z": 1,
      "name": "Rock_Ice"
    },
    {
      "x": -23,
      "y": 50,
      "z": 1,
      "name": "Rock_Ice"
    },
    {
      "x": -23,
      "y": 51,
      "z": 1,
      "name": "Rock_Ice"
    },
    {
      "x": -23,
      "y": 52,
      "z": 1,
      "name": "Rock_Ice"
    },
    {
      "x": -23,
      "y": 53,
      "z": 1,
      "name": "Rock_Ice"
    },
    {
      "x": -23,
      "y": 54,
      "z": 1,
      "name": "Rock_Ice_Permafrost"
    },
    {
      "x": -23,
      "y": 55,
      "z": 1,
      "name": "Rock_Ice"
    },
    {
      "x": -23,
      "y": 56,
      "z": 1,
      "name": "Soil_Snow"
    },
    {
      "x": -23,
      "y": 26,
      "z": 2,
      "name": "Rock_Ice"
    },
    {
      "x": -23,
      "y": 27,
      "z": 2,
      "name": "Rock_Ice"
    },
    {
      "x": -23,
      "y": 28,
      "z": 2,
      "name": "Rock_Ice"
    },
    {
      "x": -23,
      "y": 29,
      "z": 2,
      "name": "Rock_Ice"
    },
    {
      "x": -23,
      "y": 30,
      "z": 2,
      "name": "Rock_Ice"
    },
    {
      "x": -23,
      "y": 31,
      "z": 2,
      "name": "Rock_Ice"
    },
    {
      "x": -23,
      "y": 32,
      "z": 2,
      "name": "Rock_Ice"
    },
    {
      "x": -23,
      "y": 33,
      "z": 2,
      "name": "Rock_Ice"
    },
    {
      "x": -23,
      "y": 34,
      "z": 2,
      "name": "Rock_Ice"
    },
    {
      "x": -23,
      "y": 35,
      "z": 2,
      "name": "Rock_Ice"
    },
    {
      "x": -23,
      "y": 36,
      "z": 2,
      "name": "Rock_Ice"
    },
    {
      "x": -23,
      "y": 37,
      "z": 2,
      "name": "Rock_Ice"
    },
    {
      "x": -23,
      "y": 38,
      "z": 2,
      "name": "Rock_Ice"
    },
    {
      "x": -23,
      "y": 39,
      "z": 2,
      "name": "Rock_Ice"
    },
    {
      "x": -23,
      "y": 40,
      "z": 2,
      "name": "Rock_Ice"
    },
    {
      "x": -23,
      "y": 41,
      "z": 2,
      "name": "Rock_Ice"
    },
    {
      "x": -23,
      "y": 42,
      "z": 2,
      "name": "Rock_Ice"
    },
    {
      "x": -23,
      "y": 43,
      "z": 2,
      "name": "Rock_Ice"
    },
    {
      "x": -23,
      "y": 44,
      "z": 2,
      "name": "Rock_Ice_Permafrost"
    },
    {
      "x": -23,
      "y": 45,
      "z": 2,
      "name": "Rock_Ice"
    },
    {
      "x": -23,
      "y": 46,
      "z": 2,
      "name": "Rock_Ice"
    },
    {
      "x": -23,
      "y": 47,
      "z": 2,
      "name": "Rock_Ice"
    },
    {
      "x": -23,
      "y": 48,
      "z": 2,
      "name": "Rock_Ice"
    },
    {
      "x": -23,
      "y": 49,
      "z": 2,
      "name": "Rock_Ice"
    },
    {
      "x": -23,
      "y": 50,
      "z": 2,
      "name": "Rock_Ice_Permafrost"
    },
    {
      "x": -23,
      "y": 51,
      "z": 2,
      "name": "Rock_Ice"
    },
    {
      "x": -23,
      "y": 52,
      "z": 2,
      "name": "Rock_Ice_Permafrost"
    },
    {
      "x": -23,
      "y": 53,
      "z": 2,
      "name": "Rock_Ice"
    },
    {
      "x": -23,
      "y": 54,
      "z": 2,
      "name": "Rock_Ice"
    },
    {
      "x": -23,
      "y": 55,
      "z": 2,
      "name": "Soil_Snow"
    },
    {
      "x": -23,
      "y": 28,
      "z": 3,
      "name": "Rock_Ice"
    },
    {
      "x": -23,
      "y": 29,
      "z": 3,
      "name": "Rock_Ice"
    },
    {
      "x": -23,
      "y": 30,
      "z": 3,
      "name": "Rock_Ice"
    },
    {
      "x": -23,
      "y": 31,
      "z": 3,
      "name": "Rock_Ice"
    },
    {
      "x": -23,
      "y": 32,
      "z": 3,
      "name": "Rock_Ice"
    },
    {
      "x": -23,
      "y": 33,
      "z": 3,
      "name": "Rock_Ice"
    },
    {
      "x": -23,
      "y": 34,
      "z": 3,
      "name": "Rock_Ice"
    },
    {
      "x": -23,
      "y": 35,
      "z": 3,
      "name": "Rock_Ice"
    },
    {
      "x": -23,
      "y": 36,
      "z": 3,
      "name": "Rock_Ice"
    },
    {
      "x": -23,
      "y": 37,
      "z": 3,
      "name": "Rock_Ice"
    },
    {
      "x": -23,
      "y": 38,
      "z": 3,
      "name": "Rock_Ice"
    },
    {
      "x": -23,
      "y": 39,
      "z": 3,
      "name": "Rock_Ice"
    },
    {
      "x": -23,
      "y": 40,
      "z": 3,
      "name": "Rock_Ice"
    },
    {
      "x": -23,
      "y": 41,
      "z": 3,
      "name": "Rock_Ice"
    },
    {
      "x": -23,
      "y": 42,
      "z": 3,
      "name": "Rock_Ice"
    },
    {
      "x": -23,
      "y": 43,
      "z": 3,
      "name": "Rock_Ice"
    },
    {
      "x": -23,
      "y": 44,
      "z": 3,
      "name": "Rock_Ice"
    },
    {
      "x": -23,
      "y": 45,
      "z": 3,
      "name": "Rock_Ice"
    },
    {
      "x": -23,
      "y": 46,
      "z": 3,
      "name": "Rock_Ice"
    },
    {
      "x": -23,
      "y": 47,
      "z": 3,
      "name": "Rock_Ice"
    },
    {
      "x": -23,
      "y": 48,
      "z": 3,
      "name": "Rock_Ice"
    },
    {
      "x": -23,
      "y": 49,
      "z": 3,
      "name": "Rock_Ice"
    },
    {
      "x": -23,
      "y": 50,
      "z": 3,
      "name": "Rock_Ice"
    },
    {
      "x": -23,
      "y": 51,
      "z": 3,
      "name": "Rock_Ice"
    },
    {
      "x": -23,
      "y": 52,
      "z": 3,
      "name": "Rock_Ice"
    },
    {
      "x": -23,
      "y": 53,
      "z": 3,
      "name": "Rock_Ice"
    },
    {
      "x": -23,
      "y": 54,
      "z": 3,
      "name": "Rock_Ice"
    },
    {
      "x": -23,
      "y": 55,
      "z": 3,
      "name": "Soil_Snow"
    },
    {
      "x": -23,
      "y": 31,
      "z": 4,
      "name": "Rock_Ice"
    },
    {
      "x": -23,
      "y": 32,
      "z": 4,
      "name": "Rock_Ice"
    },
    {
      "x": -23,
      "y": 33,
      "z": 4,
      "name": "Rock_Ice"
    },
    {
      "x": -23,
      "y": 34,
      "z": 4,
      "name": "Rock_Ice"
    },
    {
      "x": -23,
      "y": 35,
      "z": 4,
      "name": "Rock_Ice"
    },
    {
      "x": -23,
      "y": 36,
      "z": 4,
      "name": "Rock_Ice"
    },
    {
      "x": -23,
      "y": 37,
      "z": 4,
      "name": "Rock_Ice"
    },
    {
      "x": -23,
      "y": 38,
      "z": 4,
      "name": "Rock_Ice"
    },
    {
      "x": -23,
      "y": 39,
      "z": 4,
      "name": "Rock_Ice"
    },
    {
      "x": -23,
      "y": 40,
      "z": 4,
      "name": "Rock_Ice"
    },
    {
      "x": -23,
      "y": 41,
      "z": 4,
      "name": "Rock_Ice"
    },
    {
      "x": -23,
      "y": 42,
      "z": 4,
      "name": "Rock_Ice"
    },
    {
      "x": -23,
      "y": 43,
      "z": 4,
      "name": "Rock_Ice"
    },
    {
      "x": -23,
      "y": 44,
      "z": 4,
      "name": "Rock_Ice"
    },
    {
      "x": -23,
      "y": 45,
      "z": 4,
      "name": "Rock_Ice"
    },
    {
      "x": -23,
      "y": 46,
      "z": 4,
      "name": "Rock_Ice"
    },
    {
      "x": -23,
      "y": 47,
      "z": 4,
      "name": "Rock_Ice"
    },
    {
      "x": -23,
      "y": 48,
      "z": 4,
      "name": "Rock_Ice"
    },
    {
      "x": -23,
      "y": 49,
      "z": 4,
      "name": "Rock_Ice"
    },
    {
      "x": -23,
      "y": 50,
      "z": 4,
      "name": "Rock_Ice_Permafrost"
    },
    {
      "x": -23,
      "y": 51,
      "z": 4,
      "name": "Rock_Ice_Permafrost"
    },
    {
      "x": -23,
      "y": 52,
      "z": 4,
      "name": "Rock_Ice"
    },
    {
      "x": -23,
      "y": 53,
      "z": 4,
      "name": "Soil_Snow"
    },
    {
      "x": -23,
      "y": 40,
      "z": 5,
      "name": "Rock_Ice"
    },
    {
      "x": -23,
      "y": 41,
      "z": 5,
      "name": "Rock_Ice"
    },
    {
      "x": -23,
      "y": 42,
      "z": 5,
      "name": "Rock_Ice"
    },
    {
      "x": -23,
      "y": 43,
      "z": 5,
      "name": "Rock_Ice"
    },
    {
      "x": -23,
      "y": 44,
      "z": 5,
      "name": "Rock_Ice"
    },
    {
      "x": -23,
      "y": 45,
      "z": 5,
      "name": "Rock_Ice"
    },
    {
      "x": -23,
      "y": 46,
      "z": 5,
      "name": "Rock_Ice"
    },
    {
      "x": -23,
      "y": 47,
      "z": 5,
      "name": "Rock_Ice"
    },
    {
      "x": -23,
      "y": 48,
      "z": 5,
      "name": "Soil_Snow"
    },
    {
      "x": -22,
      "y": 33,
      "z": -11,
      "name": "Rock_Ice"
    },
    {
      "x": -22,
      "y": 34,
      "z": -11,
      "name": "Rock_Ice"
    },
    {
      "x": -22,
      "y": 35,
      "z": -11,
      "name": "Rock_Ice"
    },
    {
      "x": -22,
      "y": 36,
      "z": -11,
      "name": "Rock_Ice_Permafrost"
    },
    {
      "x": -22,
      "y": 37,
      "z": -11,
      "name": "Soil_Snow"
    },
    {
      "x": -22,
      "y": 30,
      "z": -10,
      "name": "Rock_Ice"
    },
    {
      "x": -22,
      "y": 31,
      "z": -10,
      "name": "Rock_Ice"
    },
    {
      "x": -22,
      "y": 32,
      "z": -10,
      "name": "Rock_Ice"
    },
    {
      "x": -22,
      "y": 33,
      "z": -10,
      "name": "Rock_Ice"
    },
    {
      "x": -22,
      "y": 34,
      "z": -10,
      "name": "Rock_Ice_Permafrost"
    },
    {
      "x": -22,
      "y": 35,
      "z": -10,
      "name": "Rock_Ice_Permafrost"
    },
    {
      "x": -22,
      "y": 36,
      "z": -10,
      "name": "Rock_Ice_Permafrost"
    },
    {
      "x": -22,
      "y": 37,
      "z": -10,
      "name": "Rock_Ice_Permafrost"
    },
    {
      "x": -22,
      "y": 38,
      "z": -10,
      "name": "Rock_Ice_Permafrost"
    },
    {
      "x": -22,
      "y": 39,
      "z": -10,
      "name": "Rock_Ice"
    },
    {
      "x": -22,
      "y": 40,
      "z": -10,
      "name": "Soil_Snow"
    },
    {
      "x": -22,
      "y": 29,
      "z": -9,
      "name": "Rock_Ice"
    },
    {
      "x": -22,
      "y": 30,
      "z": -9,
      "name": "Rock_Ice"
    },
    {
      "x": -22,
      "y": 31,
      "z": -9,
      "name": "Rock_Ice"
    },
    {
      "x": -22,
      "y": 32,
      "z": -9,
      "name": "Rock_Ice"
    },
    {
      "x": -22,
      "y": 33,
      "z": -9,
      "name": "Rock_Ice"
    },
    {
      "x": -22,
      "y": 34,
      "z": -9,
      "name": "Rock_Ice"
    },
    {
      "x": -22,
      "y": 35,
      "z": -9,
      "name": "Rock_Ice_Permafrost"
    },
    {
      "x": -22,
      "y": 36,
      "z": -9,
      "name": "Rock_Ice_Permafrost"
    },
    {
      "x": -22,
      "y": 37,
      "z": -9,
      "name": "Rock_Ice_Permafrost"
    },
    {
      "x": -22,
      "y": 38,
      "z": -9,
      "name": "Rock_Ice"
    },
    {
      "x": -22,
      "y": 39,
      "z": -9,
      "name": "Rock_Ice"
    },
    {
      "x": -22,
      "y": 40,
      "z": -9,
      "name": "Rock_Ice"
    },
    {
      "x": -22,
      "y": 41,
      "z": -9,
      "name": "Rock_Ice"
    },
    {
      "x": -22,
      "y": 42,
      "z": -9,
      "name": "Soil_Snow"
    },
    {
      "x": -22,
      "y": 27,
      "z": -8,
      "name": "Rock_Ice"
    },
    {
      "x": -22,
      "y": 28,
      "z": -8,
      "name": "Rock_Ice"
    },
    {
      "x": -22,
      "y": 29,
      "z": -8,
      "name": "Rock_Ice"
    },
    {
      "x": -22,
      "y": 30,
      "z": -8,
      "name": "Rock_Ice"
    },
    {
      "x": -22,
      "y": 31,
      "z": -8,
      "name": "Rock_Ice"
    },
    {
      "x": -22,
      "y": 32,
      "z": -8,
      "name": "Rock_Ice"
    },
    {
      "x": -22,
      "y": 33,
      "z": -8,
      "name": "Rock_Ice"
    },
    {
      "x": -22,
      "y": 34,
      "z": -8,
      "name": "Rock_Ice"
    },
    {
      "x": -22,
      "y": 35,
      "z": -8,
      "name": "Rock_Ice"
    },
    {
      "x": -22,
      "y": 36,
      "z": -8,
      "name": "Rock_Ice"
    },
    {
      "x": -22,
      "y": 37,
      "z": -8,
      "name": "Rock_Ice"
    },
    {
      "x": -22,
      "y": 38,
      "z": -8,
      "name": "Rock_Ice"
    },
    {
      "x": -22,
      "y": 39,
      "z": -8,
      "name": "Rock_Ice"
    },
    {
      "x": -22,
      "y": 40,
      "z": -8,
      "name": "Rock_Ice"
    },
    {
      "x": -22,
      "y": 41,
      "z": -8,
      "name": "Rock_Ice"
    },
    {
      "x": -22,
      "y": 42,
      "z": -8,
      "name": "Rock_Ice"
    },
    {
      "x": -22,
      "y": 43,
      "z": -8,
      "name": "Rock_Ice"
    },
    {
      "x": -22,
      "y": 44,
      "z": -8,
      "name": "Soil_Snow"
    },
    {
      "x": -22,
      "y": 26,
      "z": -7,
      "name": "Rock_Ice"
    },
    {
      "x": -22,
      "y": 27,
      "z": -7,
      "name": "Rock_Ice"
    },
    {
      "x": -22,
      "y": 28,
      "z": -7,
      "name": "Rock_Ice_Permafrost"
    },
    {
      "x": -22,
      "y": 29,
      "z": -7,
      "name": "Rock_Ice"
    },
    {
      "x": -22,
      "y": 30,
      "z": -7,
      "name": "Rock_Ice"
    },
    {
      "x": -22,
      "y": 31,
      "z": -7,
      "name": "Rock_Ice"
    },
    {
      "x": -22,
      "y": 32,
      "z": -7,
      "name": "Rock_Ice"
    },
    {
      "x": -22,
      "y": 33,
      "z": -7,
      "name": "Rock_Ice"
    },
    {
      "x": -22,
      "y": 34,
      "z": -7,
      "name": "Rock_Ice_Permafrost"
    },
    {
      "x": -22,
      "y": 35,
      "z": -7,
      "name": "Rock_Ice"
    },
    {
      "x": -22,
      "y": 36,
      "z": -7,
      "name": "Rock_Ice_Permafrost"
    },
    {
      "x": -22,
      "y": 37,
      "z": -7,
      "name": "Rock_Ice"
    },
    {
      "x": -22,
      "y": 38,
      "z": -7,
      "name": "Rock_Ice"
    },
    {
      "x": -22,
      "y": 39,
      "z": -7,
      "name": "Rock_Ice"
    },
    {
      "x": -22,
      "y": 40,
      "z": -7,
      "name": "Rock_Ice"
    },
    {
      "x": -22,
      "y": 41,
      "z": -7,
      "name": "Rock_Ice"
    },
    {
      "x": -22,
      "y": 42,
      "z": -7,
      "name": "Rock_Ice"
    },
    {
      "x": -22,
      "y": 43,
      "z": -7,
      "name": "Rock_Ice"
    },
    {
      "x": -22,
      "y": 44,
      "z": -7,
      "name": "Rock_Ice"
    },
    {
      "x": -22,
      "y": 45,
      "z": -7,
      "name": "Soil_Snow"
    },
    {
      "x": -22,
      "y": 26,
      "z": -6,
      "name": "Rock_Ice"
    },
    {
      "x": -22,
      "y": 27,
      "z": -6,
      "name": "Rock_Ice_Permafrost"
    },
    {
      "x": -22,
      "y": 28,
      "z": -6,
      "name": "Rock_Ice"
    },
    {
      "x": -22,
      "y": 29,
      "z": -6,
      "name": "Rock_Ice"
    },
    {
      "x": -22,
      "y": 30,
      "z": -6,
      "name": "Rock_Ice"
    },
    {
      "x": -22,
      "y": 31,
      "z": -6,
      "name": "Rock_Ice"
    },
    {
      "x": -22,
      "y": 32,
      "z": -6,
      "name": "Rock_Ice"
    },
    {
      "x": -22,
      "y": 33,
      "z": -6,
      "name": "Rock_Ice"
    },
    {
      "x": -22,
      "y": 34,
      "z": -6,
      "name": "Rock_Ice"
    },
    {
      "x": -22,
      "y": 35,
      "z": -6,
      "name": "Rock_Ice"
    },
    {
      "x": -22,
      "y": 36,
      "z": -6,
      "name": "Rock_Ice"
    },
    {
      "x": -22,
      "y": 37,
      "z": -6,
      "name": "Rock_Ice"
    },
    {
      "x": -22,
      "y": 38,
      "z": -6,
      "name": "Rock_Ice"
    },
    {
      "x": -22,
      "y": 39,
      "z": -6,
      "name": "Rock_Ice"
    },
    {
      "x": -22,
      "y": 40,
      "z": -6,
      "name": "Rock_Ice"
    },
    {
      "x": -22,
      "y": 41,
      "z": -6,
      "name": "Rock_Ice"
    },
    {
      "x": -22,
      "y": 42,
      "z": -6,
      "name": "Rock_Ice"
    },
    {
      "x": -22,
      "y": 43,
      "z": -6,
      "name": "Rock_Ice"
    },
    {
      "x": -22,
      "y": 44,
      "z": -6,
      "name": "Rock_Ice"
    },
    {
      "x": -22,
      "y": 45,
      "z": -6,
      "name": "Rock_Ice"
    },
    {
      "x": -22,
      "y": 46,
      "z": -6,
      "name": "Rock_Ice"
    },
    {
      "x": -22,
      "y": 47,
      "z": -6,
      "name": "Soil_Snow"
    },
    {
      "x": -22,
      "y": 25,
      "z": -5,
      "name": "Rock_Ice"
    },
    {
      "x": -22,
      "y": 26,
      "z": -5,
      "name": "Rock_Ice_Permafrost"
    },
    {
      "x": -22,
      "y": 27,
      "z": -5,
      "name": "Rock_Ice_Permafrost"
    },
    {
      "x": -22,
      "y": 28,
      "z": -5,
      "name": "Rock_Ice"
    },
    {
      "x": -22,
      "y": 29,
      "z": -5,
      "name": "Rock_Ice"
    },
    {
      "x": -22,
      "y": 30,
      "z": -5,
      "name": "Rock_Ice"
    },
    {
      "x": -22,
      "y": 31,
      "z": -5,
      "name": "Rock_Ice"
    },
    {
      "x": -22,
      "y": 32,
      "z": -5,
      "name": "Rock_Ice"
    },
    {
      "x": -22,
      "y": 33,
      "z": -5,
      "name": "Rock_Ice"
    },
    {
      "x": -22,
      "y": 34,
      "z": -5,
      "name": "Rock_Ice"
    },
    {
      "x": -22,
      "y": 35,
      "z": -5,
      "name": "Rock_Ice"
    },
    {
      "x": -22,
      "y": 36,
      "z": -5,
      "name": "Rock_Ice"
    },
    {
      "x": -22,
      "y": 37,
      "z": -5,
      "name": "Rock_Ice"
    },
    {
      "x": -22,
      "y": 38,
      "z": -5,
      "name": "Rock_Ice"
    },
    {
      "x": -22,
      "y": 39,
      "z": -5,
      "name": "Rock_Ice"
    },
    {
      "x": -22,
      "y": 40,
      "z": -5,
      "name": "Rock_Ice"
    },
    {
      "x": -22,
      "y": 41,
      "z": -5,
      "name": "Rock_Ice"
    },
    {
      "x": -22,
      "y": 42,
      "z": -5,
      "name": "Rock_Ice"
    },
    {
      "x": -22,
      "y": 43,
      "z": -5,
      "name": "Rock_Ice"
    },
    {
      "x": -22,
      "y": 44,
      "z": -5,
      "name": "Rock_Ice"
    },
    {
      "x": -22,
      "y": 45,
      "z": -5,
      "name": "Rock_Ice"
    },
    {
      "x": -22,
      "y": 46,
      "z": -5,
      "name": "Rock_Ice"
    },
    {
      "x": -22,
      "y": 47,
      "z": -5,
      "name": "Rock_Ice"
    },
    {
      "x": -22,
      "y": 48,
      "z": -5,
      "name": "Rock_Ice"
    },
    {
      "x": -22,
      "y": 49,
      "z": -5,
      "name": "Soil_Snow"
    },
    {
      "x": -22,
      "y": 24,
      "z": -4,
      "name": "Rock_Ice"
    },
    {
      "x": -22,
      "y": 25,
      "z": -4,
      "name": "Rock_Ice"
    },
    {
      "x": -22,
      "y": 26,
      "z": -4,
      "name": "Rock_Ice"
    },
    {
      "x": -22,
      "y": 27,
      "z": -4,
      "name": "Rock_Ice_Permafrost"
    },
    {
      "x": -22,
      "y": 28,
      "z": -4,
      "name": "Rock_Ice_Permafrost"
    },
    {
      "x": -22,
      "y": 29,
      "z": -4,
      "name": "Rock_Ice"
    },
    {
      "x": -22,
      "y": 30,
      "z": -4,
      "name": "Rock_Ice"
    },
    {
      "x": -22,
      "y": 31,
      "z": -4,
      "name": "Rock_Ice"
    },
    {
      "x": -22,
      "y": 32,
      "z": -4,
      "name": "Rock_Ice"
    },
    {
      "x": -22,
      "y": 33,
      "z": -4,
      "name": "Rock_Ice"
    },
    {
      "x": -22,
      "y": 34,
      "z": -4,
      "name": "Rock_Ice"
    },
    {
      "x": -22,
      "y": 35,
      "z": -4,
      "name": "Rock_Ice"
    },
    {
      "x": -22,
      "y": 36,
      "z": -4,
      "name": "Rock_Ice"
    },
    {
      "x": -22,
      "y": 37,
      "z": -4,
      "name": "Rock_Ice"
    },
    {
      "x": -22,
      "y": 38,
      "z": -4,
      "name": "Rock_Ice"
    },
    {
      "x": -22,
      "y": 39,
      "z": -4,
      "name": "Rock_Ice"
    },
    {
      "x": -22,
      "y": 40,
      "z": -4,
      "name": "Rock_Ice"
    },
    {
      "x": -22,
      "y": 41,
      "z": -4,
      "name": "Rock_Ice"
    },
    {
      "x": -22,
      "y": 42,
      "z": -4,
      "name": "Rock_Ice"
    },
    {
      "x": -22,
      "y": 43,
      "z": -4,
      "name": "Rock_Ice"
    },
    {
      "x": -22,
      "y": 44,
      "z": -4,
      "name": "Rock_Ice"
    },
    {
      "x": -22,
      "y": 45,
      "z": -4,
      "name": "Rock_Ice"
    },
    {
      "x": -22,
      "y": 46,
      "z": -4,
      "name": "Rock_Ice"
    },
    {
      "x": -22,
      "y": 47,
      "z": -4,
      "name": "Rock_Ice"
    },
    {
      "x": -22,
      "y": 48,
      "z": -4,
      "name": "Rock_Ice"
    },
    {
      "x": -22,
      "y": 49,
      "z": -4,
      "name": "Rock_Ice"
    },
    {
      "x": -22,
      "y": 50,
      "z": -4,
      "name": "Rock_Ice"
    },
    {
      "x": -22,
      "y": 51,
      "z": -4,
      "name": "Soil_Snow"
    },
    {
      "x": -22,
      "y": 24,
      "z": -3,
      "name": "Rock_Ice"
    },
    {
      "x": -22,
      "y": 25,
      "z": -3,
