{
  "version": 8,
  "blockIdVersion": 11,
  "anchorX": -2,
  "anchorY": 21,
  "anchorZ": 0,
  "blocks": [
    {
      "x": -24,
      "y": 26,
      "z": -11,
      "name": "Rock_Ice_Permafrost"
    },
    {
      "x": -24,
      "y": 27,
      "z": -11,
      "name": "Rock_Ice_Permafrost"
    },
    {
      "x": -24,
      "y": 28,
      "z": -11,
      "name": "Rock_Ice_Permafrost"
    },
    {
      "x": -24,
      "y": 25,
      "z": -10,
      "name": "Rock_Ice_Permafrost"
    },
    {
      "x": -24,
      "y": 26,
      "z": -10,
      "name": "Rock_Ice_Permafrost"
    },
    {
      "x": -24,
      "y": 27,
      "z": -10,
      "name": "Rock_Ice_Permafrost"
    },
    {
      "x": -24,
      "y": 28,
      "z": -10,
      "name": "Rock_Ice_Permafrost"
    },
    {
      "x": -24,
      "y": 29,
      "z": -10,
      "name": "Rock_Ice_Permafrost"
    },
    {
      "x": -24,
      "y": 30,
      "z": -10,
      "name": "Rock_Ice"
    },
    {
      "x": -24,
      "y": 31,
      "z": -10,
      "name": "Soil_Snow"
    },
    {
      "x": -24,
      "y": 23,
      "z": -9,
      "name": "Rock_Ice_Permafrost"
    },
    {
      "x": -24,
      "y": 24,
      "z": -9,
      "name": "Rock_Ice_Permafrost"
    },
    {
      "x": -24,
      "y": 25,
      "z": -9,
      "name": "Rock_Ice_Permafrost"
    },
    {
      "x": -24,
      "y": 26,
      "z": -9,
      "name": "Rock_Ice_Permafrost"
    },
    {
      "x": -24,
      "y": 27,
      "z": -9,
      "name": "Rock_Ice_Permafrost"
    },
    {
      "x": -24,
      "y": 28,
      "z": -9,
      "name": "Rock_Ice_Permafrost"
    },
    {
      "x": -24,
      "y": 29,
      "z": -9,
      "name": "Rock_Ice_Permafrost"
    },
    {
      "x": -24,
      "y": 30,
      "z": -9,
      "name": "Rock_Ice"
    },
    {
      "x": -24,
      "y": 31,
      "z": -9,
      "name": "Soil_Snow"
    },
    {
      "x": -24,
      "y": 24,
      "z": -8,
      "name": "Rock_Ice_Permafrost"
    },
    {
      "x": -24,
      "y": 25,
      "z": -8,
      "name": "Rock_Ice_Permafrost"
    },
    {
      "x": -24,
      "y": 26,
      "z": -8,
      "name": "Rock_Ice_Permafrost"
    },
    {
      "x": -24,
      "y": 27,
      "z": -8,
      "name": "Rock_Ice_Permafrost"
    },
    {
      "x": -24,
      "y": 28,
      "z": -8,
      "name": "Rock_Ice_Permafrost"
    },
    {
      "x": -24,
      "y": 29,
      "z": -8,
      "name": "Rock_Ice_Permafrost"
    },
    {
      "x": -24,
      "y": 30,
      "z": -8,
      "name": "Rock_Ice"
    },
    {
      "x": -24,
      "y": 31,
      "z": -8,
      "name": "Soil_Snow"
    },
    {
      "x": -24,
      "y": 25,
      "z": -7,
      "name": "Rock_Ice"
    },
    {
      "x": -24,
      "y": 26,
      "z": -7,
      "name": "Rock_Ice"
    },
    {
      "x": -24,
      "y": 27,
      "z": -7,
      "name": "Rock_Ice_Permafrost"
    },
    {
      "x": -24,
      "y": 28,
      "z": -7,
      "name": "Rock_Ice"
    },
    {
      "x": -24,
      "y": 29,
      "z": -7,
      "name": "Rock_Ice_Permafrost"
    },
    {
      "x": -24,
      "y": 30,
      "z": -7,
      "name": "Rock_Ice_Permafrost"
    },
    {
      "x": -24,
      "y": 31,
      "z": -7,
      "name": "Rock_Ice_Permafrost"
    },
    {
      "x": -24,
      "y": 32,
      "z": -7,
      "name": "Soil_Snow"
    },
    {
      "x": -24,
      "y": 26,
      "z": -6,
      "name": "Rock_Ice"
    },
    {
      "x": -24,
      "y": 27,
      "z": -6,
      "name": "Rock_Ice"
    },
    {
      "x": -24,
      "y": 28,
      "z": -6,
      "name": "Rock_Ice"
    },
    {
      "x": -24,
      "y": 29,
      "z": -6,
      "name": "Rock_Ice"
    },
    {
      "x": -24,
      "y": 30,
      "z": -6,
      "name": "Rock_Ice"
    },
    {
      "x": -24,
      "y": 31,
      "z": -6,
      "name": "Rock_Ice_Permafrost"
    },
    {
      "x": -24,
      "y": 32,
      "z": -6,
      "name": "Rock_Ice"
    },
    {
      "x": -24,
      "y": 33,
      "z": -6,
      "name": "Soil_Snow"
    },
    {
      "x": -24,
      "y": 28,
      "z": -5,
      "name": "Rock_Ice"
    },
    {
      "x": -24,
      "y": 29,
      "z": -5,
      "name": "Rock_Ice"
    },
    {
      "x": -24,
      "y": 30,
      "z": -5,
      "name": "Rock_Ice"
    },
    {
      "x": -24,
      "y": 31,
      "z": -5,
      "name": "Rock_Ice"
    },
    {
      "x": -24,
      "y": 32,
      "z": -5,
      "name": "Rock_Ice"
    },
    {
      "x": -24,
      "y": 33,
      "z": -5,
      "name": "Rock_Ice_Permafrost"
    },
    {
      "x": -24,
      "y": 34,
      "z": -5,
      "name": "Soil_Snow"
    },
    {
      "x": -24,
      "y": 31,
      "z": -4,
      "name": "Rock_Ice"
    },
    {
      "x": -24,
      "y": 32,
      "z": -4,
      "name": "Rock_Ice"
    },
    {
      "x": -24,
      "y": 33,
      "z": -4,
      "name": "Rock_Ice"
    },
    {
      "x": -24,
      "y": 34,
      "z": -4,
      "name": "Rock_Ice"
    },
    {
      "x": -24,
      "y": 35,
      "z": -4,
      "name": "Rock_Ice_Permafrost"
    },
    {
      "x": -24,
      "y": 36,
      "z": -4,
      "name": "Soil_Snow"
    },
    {
      "x": -24,
      "y": 34,
      "z": -3,
      "name": "Rock_Ice"
    },
    {
      "x": -24,
      "y": 35,
      "z": -3,
      "name": "Rock_Ice"
    },
    {
      "x": -24,
      "y": 36,
      "z": -3,
      "name": "Soil_Snow"
    },
    {
      "x": -24,
      "y": 34,
      "z": -2,
      "name": "Rock_Ice"
    },
    {
      "x": -24,
      "y": 35,
      "z": -2,
      "name": "Rock_Ice"
    },
    {
      "x": -24,
      "y": 36,
      "z": -2,
      "name": "Soil_Snow"
    },
    {
      "x": -24,
      "y": 34,
      "z": 2,
      "name": "Soil_Snow"
    },
    {
      "x": -24,
      "y": 34,
      "z": 3,
      "name": "Soil_Snow"
    },
    {
      "x": -24,
      "y": 22,
      "z": 17,
      "name": "Rock_Ice"
    },
    {
      "x": -24,
      "y": 23,
      "z": 17,
      "name": "Rock_Ice"
    },
    {
      "x": -24,
      "y": 24,
      "z": 17,
      "name": "Rock_Ice"
    },
    {
      "x": -23,
      "y": 25,
      "z": -13,
      "name": "Rock_Ice_Permafrost"
    },
    {
      "x": -23,
      "y": 26,
      "z": -13,
      "name": "Rock_Ice_Permafrost"
    },
    {
      "x": -23,
      "y": 27,
      "z": -13,
      "name": "Rock_Ice_Permafrost"
    },
    {
      "x": -23,
      "y": 28,
      "z": -13,
      "name": "Rock_Ice_Permafrost"
    },
    {
      "x": -23,
      "y": 29,
      "z": -13,
      "name": "Rock_Ice_Permafrost"
    },
    {
      "x": -23,
      "y": 30,
      "z": -13,
      "name": "Rock_Ice"
    },
    {
      "x": -23,
      "y": 31,
      "z": -13,
      "name": "Soil_Snow"
    },
    {
      "x": -23,
      "y": 24,
      "z": -12,
      "name": "Rock_Ice_Permafrost"
    },
    {
      "x": -23,
      "y": 25,
      "z": -12,
      "name": "Rock_Ice_Permafrost"
    },
    {
      "x": -23,
      "y": 26,
      "z": -12,
      "name": "Rock_Ice_Permafrost"
    },
    {
      "x": -23,
      "y": 27,
      "z": -12,
      "name": "Rock_Ice_Permafrost"
    },
    {
      "x": -23,
      "y": 28,
      "z": -12,
      "name": "Rock_Ice_Permafrost"
    },
    {
      "x": -23,
      "y": 29,
      "z": -12,
      "name": "Rock_Ice_Permafrost"
    },
    {
      "x": -23,
      "y": 30,
      "z": -12,
      "name": "Rock_Ice"
    },
    {
      "x": -23,
      "y": 31,
      "z": -12,
      "name": "Rock_Ice"
    },
    {
      "x": -23,
      "y": 32,
      "z": -12,
      "name": "Soil_Snow"
    },
    {
      "x": -23,
      "y": 23,
      "z": -11,
      "name": "Rock_Ice_Permafrost"
    },
    {
      "x": -23,
      "y": 24,
      "z": -11,
      "name": "Rock_Ice_Permafrost"
    },
    {
      "x": -23,
      "y": 25,
      "z": -11,
      "name": "Rock_Ice_Permafrost"
    },
    {
      "x": -23,
      "y": 26,
      "z": -11,
      "name": "Rock_Ice_Permafrost"
    },
    {
      "x": -23,
      "y": 27,
      "z": -11,
      "name": "Rock_Ice_Permafrost"
    },
    {
      "x": -23,
      "y": 28,
      "z": -11,
      "name": "Rock_Ice_Permafrost"
    },
    {
      "x": -23,
      "y": 29,
      "z": -11,
      "name": "Rock_Ice_Permafrost"
    },
    {
      "x": -23,
      "y": 30,
      "z": -11,
      "name": "Rock_Ice"
    },
    {
      "x": -23,
      "y": 31,
      "z": -11,
      "name": "Rock_Ice"
    },
    {
      "x": -23,
      "y": 32,
      "z": -11,
      "name": "Rock_Ice"
    },
    {
      "x": -23,
      "y": 33,
      "z": -11,
      "name": "Soil_Snow"
    },
    {
      "x": -23,
      "y": 19,
      "z": -10,
      "name": "Rock_Ice_Permafrost"
    },
    {
      "x": -23,
      "y": 20,
      "z": -10,
      "name": "Rock_Ice_Permafrost"
    },
    {
      "x": -23,
      "y": 21,
      "z": -10,
      "name": "Rock_Ice_Permafrost"
    },
    {
      "x": -23,
      "y": 22,
      "z": -10,
      "name": "Rock_Ice_Permafrost"
    },
    {
      "x": -23,
      "y": 23,
      "z": -10,
      "name": "Rock_Ice_Permafrost"
    },
    {
      "x": -23,
      "y": 24,
      "z": -10,
      "name": "Rock_Ice_Permafrost"
    },
    {
      "x": -23,
      "y": 25,
      "z": -10,
      "name": "Rock_Ice_Permafrost"
    },
    {
      "x": -23,
      "y": 26,
      "z": -10,
      "name": "Rock_Ice_Permafrost"
    },
    {
      "x": -23,
      "y": 27,
      "z": -10,
      "name": "Rock_Ice_Permafrost"
    },
    {
      "x": -23,
      "y": 28,
      "z": -10,
      "name": "Rock_Ice_Permafrost"
    },
    {
      "x": -23,
      "y": 29,
      "z": -10,
      "name": "Rock_Ice_Permafrost"
    },
    {
      "x": -23,
      "y": 30,
      "z": -10,
      "name": "Rock_Ice_Permafrost"
    },
    {
      "x": -23,
      "y": 31,
      "z": -10,
      "name": "Rock_Ice"
    },
    {
      "x": -23,
      "y": 32,
      "z": -10,
      "name": "Rock_Ice"
    },
    {
      "x": -23,
      "y": 33,
      "z": -10,
      "name": "Soil_Snow"
    },
    {
      "x": -23,
      "y": 20,
      "z": -9,
      "name": "Rock_Ice_Permafrost"
    },
    {
      "x": -23,
      "y": 21,
      "z": -9,
      "name": "Rock_Ice_Permafrost"
    },
    {
      "x": -23,
      "y": 22,
      "z": -9,
      "name": "Rock_Ice_Permafrost"
    },
    {
      "x": -23,
      "y": 23,
      "z": -9,
      "name": "Rock_Ice_Permafrost"
    },
    {
      "x": -23,
      "y": 24,
      "z": -9,
      "name": "Rock_Ice_Permafrost"
    },
    {
      "x": -23,
      "y": 25,
      "z": -9,
      "name": "Rock_Ice_Permafrost"
    },
    {
      "x": -23,
      "y": 26,
      "z": -9,
      "name": "Rock_Ice_Permafrost"
    },
    {
      "x": -23,
      "y": 27,
      "z": -9,
      "name": "Rock_Ice_Permafrost"
    },
    {
      "x": -23,
      "y": 28,
      "z": -9,
      "name": "Rock_Ice_Permafrost"
    },
    {
      "x": -23,
      "y": 29,
      "z": -9,
      "name": "Rock_Ice_Permafrost"
    },
    {
      "x": -23,
      "y": 30,
      "z": -9,
      "name": "Rock_Ice_Permafrost"
    },
    {
      "x": -23,
      "y": 31,
      "z": -9,
      "name": "Rock_Ice_Permafrost"
    },
    {
      "x": -23,
      "y": 32,
      "z": -9,
      "name": "Rock_Ice_Permafrost"
    },
    {
      "x": -23,
      "y": 33,
      "z": -9,
      "name": "Rock_Ice"
    },
    {
      "x": -23,
      "y": 34,
      "z": -9,
      "name": "Soil_Snow"
    },
    {
      "x": -23,
      "y": 21,
      "z": -8,
      "name": "Rock_Ice_Permafrost"
    },
    {
      "x": -23,
      "y": 22,
      "z": -8,
      "name": "Rock_Ice_Permafrost"
    },
    {
      "x": -23,
      "y": 23,
      "z": -8,
      "name": "Rock_Ice"
    },
    {
      "x": -23,
      "y": 24,
      "z": -8,
      "name": "Rock_Ice"
    },
    {
      "x": -23,
      "y": 25,
      "z": -8,
      "name": "Rock_Ice"
    },
    {
      "x": -23,
      "y": 26,
      "z": -8,
      "name": "Rock_Ice_Permafrost"
    },
    {
      "x": -23,
      "y": 27,
      "z": -8,
      "name": "Rock_Ice"
    },
    {
      "x": -23,
      "y": 28,
      "z": -8,
      "name": "Rock_Ice_Permafrost"
    },
    {
      "x": -23,
      "y": 29,
      "z": -8,
      "name": "Rock_Ice_Permafrost"
    },
    {
      "x": -23,
      "y": 30,
      "z": -8,
      "name": "Rock_Ice_Permafrost"
    },
    {
      "x": -23,
      "y": 31,
      "z": -8,
      "name": "Rock_Ice_Permafrost"
    },
    {
      "x": -23,
      "y": 32,
      "z": -8,
      "name": "Rock_Ice_Permafrost"
    },
    {
      "x": -23,
      "y": 33,
      "z": -8,
      "name": "Rock_Ice_Permafrost"
    },
    {
      "x": -23,
      "y": 34,
      "z": -8,
      "name": "Rock_Ice"
    },
    {
      "x": -23,
      "y": 35,
      "z": -8,
      "name": "Soil_Snow"
    },
    {
      "x": -23,
      "y": 22,
      "z": -7,
      "name": "Rock_Ice"
    },
    {
      "x": -23,
      "y": 23,
      "z": -7,
      "name": "Rock_Ice"
    },
    {
      "x": -23,
      "y": 24,
      "z": -7,
      "name": "Rock_Ice"
    },
    {
      "x": -23,
      "y": 25,
      "z": -7,
      "name": "Rock_Ice"
    },
    {
      "x": -23,
      "y": 26,
      "z": -7,
      "name": "Rock_Ice"
    },
    {
      "x": -23,
      "y": 27,
      "z": -7,
      "name": "Rock_Ice"
    },
    {
      "x": -23,
      "y": 28,
      "z": -7,
      "name": "Rock_Ice"
    },
    {
      "x": -23,
      "y": 29,
      "z": -7,
      "name": "Rock_Ice"
    },
    {
      "x": -23,
      "y": 30,
      "z": -7,
      "name": "Rock_Ice_Permafrost"
    },
    {
      "x": -23,
      "y": 31,
      "z": -7,
      "name": "Rock_Ice_Permafrost"
    },
    {
      "x": -23,
      "y": 32,
      "z": -7,
      "name": "Rock_Ice_Permafrost"
    },
    {
      "x": -23,
      "y": 33,
      "z": -7,
      "name": "Rock_Ice_Permafrost"
    },
    {
      "x": -23,
      "y": 34,
      "z": -7,
      "name": "Rock_Ice"
    },
    {
      "x": -23,
      "y": 35,
      "z": -7,
      "name": "Soil_Snow"
    },
    {
      "x": -23,
      "y": 23,
      "z": -6,
      "name": "Rock_Ice"
    },
    {
      "x": -23,
      "y": 24,
      "z": -6,
      "name": "Rock_Ice"
    },
    {
      "x": -23,
      "y": 25,
      "z": -6,
      "name": "Rock_Ice"
    },
    {
      "x": -23,
      "y": 26,
      "z": -6,
      "name": "Rock_Ice"
    },
    {
      "x": -23,
      "y": 27,
      "z": -6,
      "name": "Rock_Ice"
    },
    {
      "x": -23,
      "y": 28,
      "z": -6,
      "name": "Rock_Ice"
    },
    {
      "x": -23,
      "y": 29,
      "z": -6,
      "name": "Rock_Ice"
    },
    {
      "x": -23,
      "y": 30,
      "z": -6,
      "name": "Rock_Ice"
    },
    {
      "x": -23,
      "y": 31,
      "z": -6,
      "name": "Rock_Ice"
    },
    {
      "x": -23,
      "y": 32,
      "z": -6,
      "name": "Rock_Ice"
    },
    {
      "x": -23,
      "y": 33,
      "z": -6,
      "name": "Rock_Ice_Permafrost"
    },
    {
      "x": -23,
      "y": 34,
      "z": -6,
      "name": "Rock_Ice"
    },
    {
      "x": -23,
      "y": 35,
      "z": -6,
      "name": "Soil_Snow"
    },
    {
      "x": -23,
      "y": 24,
      "z": -5,
      "name": "Rock_Ice"
    },
    {
      "x": -23,
      "y": 25,
      "z": -5,
      "name": "Rock_Ice"
    },
    {
      "x": -23,
      "y": 26,
      "z": -5,
      "name": "Rock_Ice"
    },
    {
      "x": -23,
      "y": 27,
      "z": -5,
      "name": "Rock_Ice"
    },
    {
      "x": -23,
      "y": 28,
      "z": -5,
      "name": "Rock_Ice"
    },
    {
      "x": -23,
      "y": 29,
      "z": -5,
      "name": "Rock_Ice"
    },
    {
      "x": -23,
      "y": 30,
      "z": -5,
      "name": "Rock_Ice"
    },
    {
      "x": -23,
      "y": 31,
      "z": -5,
      "name": "Rock_Ice"
    },
    {
      "x": -23,
      "y": 32,
      "z": -5,
      "name": "Rock_Ice"
    },
    {
      "x": -23,
      "y": 33,
      "z": -5,
      "name": "Rock_Ice"
    },
    {
      "x": -23,
      "y": 34,
      "z": -5,
      "name": "Rock_Ice"
    },
    {
      "x": -23,
      "y": 35,
      "z": -5,
      "name": "Rock_Ice_Permafrost"
    },
    {
      "x": -23,
      "y": 36,
      "z": -5,
      "name": "Rock_Ice_Permafrost"
    },
    {
      "x": -23,
      "y": 37,
      "z": -5,
      "name": "Rock_Ice_Permafrost"
    },
    {
      "x": -23,
      "y": 38,
      "z": -5,
      "name": "Rock_Ice"
    },
    {
      "x": -23,
      "y": 39,
      "z": -5,
      "name": "Rock_Ice"
    },
    {
      "x": -23,
      "y": 40,
      "z": -5,
      "name": "Rock_Ice"
    },
    {
      "x": -23,
      "y": 41,
      "z": -5,
      "name": "Rock_Ice"
    },
    {
      "x": -23,
      "y": 42,
      "z": -5,
      "name": "Rock_Ice"
    },
    {
      "x": -23,
      "y": 43,
      "z": -5,
      "name": "Soil_Snow"
    },
    {
      "x": -23,
      "y": 25,
      "z": -4,
      "name": "Rock_Ice"
    },
    {
      "x": -23,
      "y": 26,
      "z": -4,
      "name": "Rock_Ice"
    },
    {
      "x": -23,
      "y": 27,
      "z": -4,
      "name": "Rock_Ice"
    },
    {
      "x": -23,
      "y": 28,
      "z": -4,
      "name": "Rock_Ice"
    },
    {
      "x": -23,
      "y": 29,
      "z": -4,
      "name": "Rock_Ice"
    },
    {
      "x": -23,
      "y": 30,
      "z": -4,
      "name": "Rock_Ice"
    },
    {
      "x": -23,
      "y": 31,
      "z": -4,
      "name": "Rock_Ice"
    },
    {
      "x": -23,
      "y": 32,
      "z": -4,
      "name": "Rock_Ice"
    },
    {
      "x": -23,
      "y": 33,
      "z": -4,
      "name": "Rock_Ice"
    },
    {
      "x": -23,
      "y": 34,
      "z": -4,
      "name": "Rock_Ice"
    },
    {
      "x": -23,
      "y": 35,
      "z": -4,
      "name": "Rock_Ice"
    },
    {
      "x": -23,
      "y": 36,
      "z": -4,
      "name": "Rock_Ice_Permafrost"
    },
    {
      "x": -23,
      "y": 37,
      "z": -4,
      "name": "Rock_Ice_Permafrost"
    },
    {
      "x": -23,
      "y": 38,
      "z": -4,
      "name": "Rock_Ice_Permafrost"
    },
    {
      "x": -23,
      "y": 39,
      "z": -4,
      "name": "Rock_Ice_Permafrost"
    },
    {
      "x": -23,
      "y": 40,
      "z": -4,
      "name": "Rock_Ice"
    },
    {
      "x": -23,
      "y": 41,
      "z": -4,
      "name": "Rock_Ice"
    },
    {
      "x": -23,
      "y": 42,
      "z": -4,
      "name": "Soil_Snow"
    },
    {
      "x": -23,
      "y": 27,
      "z": -3,
      "name": "Rock_Ice"
    },
    {
      "x": -23,
      "y": 28,
      "z": -3,
      "name": "Rock_Ice"
    },
    {
      "x": -23,
      "y": 29,
      "z": -3,
      "name": "Rock_Ice"
    },
    {
      "x": -23,
      "y": 30,
      "z": -3,
      "name": "Rock_Ice"
    },
    {
      "x": -23,
      "y": 31,
      "z": -3,
      "name": "Rock_Ice"
    },
    {
      "x": -23,
      "y": 32,
      "z": -3,
      "name": "Rock_Ice"
    },
    {
      "x": -23,
      "y": 33,
      "z": -3,
      "name": "Rock_Ice"
    },
    {
      "x": -23,
      "y": 34,
      "z": -3,
      "name": "Rock_Ice"
    },
    {
      "x": -23,
      "y": 35,
      "z": -3,
      "name": "Rock_Ice"
    },
    {
      "x": -23,
      "y": 36,
      "z": -3,
      "name": "Rock_Ice"
    },
    {
      "x": -23,
      "y": 37,
      "z": -3,
      "name": "Rock_Ice_Permafrost"
    },
    {
      "x": -23,
      "y": 38,
      "z": -3,
      "name": "Rock_Ice_Permafrost"
    },
    {
      "x": -23,
      "y": 39,
      "z": -3,
      "name": "Rock_Ice_Permafrost"
    },
    {
      "x": -23,
      "y": 40,
      "z": -3,
      "name": "Soil_Snow"
    },
    {
      "x": -23,
      "y": 28,
      "z": -2,
      "name": "Rock_Ice"
    },
    {
      "x": -23,
      "y": 29,
      "z": -2,
      "name": "Rock_Ice"
    },
    {
      "x": -23,
      "y": 30,
      "z": -2,
      "name": "Rock_Ice"
    },
    {
      "x": -23,
      "y": 31,
      "z": -2,
      "name": "Rock_Ice"
    },
    {
      "x": -23,
      "y": 32,
      "z": -2,
      "name": "Rock_Ice"
    },
    {
      "x": -23,
      "y": 33,
      "z": -2,
      "name": "Rock_Ice"
    },
    {
      "x": -23,
      "y": 34,
      "z": -2,
      "name": "Rock_Ice"
    },
    {
      "x": -23,
      "y": 35,
      "z": -2,
      "name": "Rock_Ice"
    },
    {
      "x": -23,
      "y": 36,
      "z": -2,
      "name": "Rock_Ice"
    },
    {
      "x": -23,
      "y": 37,
      "z": -2,
      "name": "Rock_Ice"
    },
    {
      "x": -23,
      "y": 38,
      "z": -2,
      "name": "Rock_Ice"
    },
    {
      "x": -23,
      "y": 39,
      "z": -2,
      "name": "Rock_Ice"
    },
    {
      "x": -23,
      "y": 40,
      "z": -2,
      "name": "Soil_Snow"
    },
    {
      "x": -23,
      "y": 31,
      "z": 1,
      "name": "Rock_Ice"
    },
    {
      "x": -23,
      "y": 32,
      "z": 1,
      "name": "Rock_Ice"
    },
    {
      "x": -23,
      "y": 33,
      "z": 1,
      "name": "Rock_Ice"
    },
    {
      "x": -23,
      "y": 34,
      "z": 1,
      "name": "Rock_Ice"
    },
    {
      "x": -23,
      "y": 35,
      "z": 1,
      "name": "Rock_Ice"
    },
    {
      "x": -23,
      "y": 36,
      "z": 1,
      "name": "Rock_Ice"
    },
    {
      "x": -23,
      "y": 37,
      "z": 1,
      "name": "Soil_Snow"
    },
    {
      "x": -23,
      "y": 30,
      "z": 2,
      "name": "Rock_Ice"
    },
    {
      "x": -23,
      "y": 31,
      "z": 2,
      "name": "Rock_Ice"
    },
    {
      "x": -23,
      "y": 32,
      "z": 2,
      "name": "Rock_Ice"
    },
    {
      "x": -23,
      "y": 33,
      "z": 2,
      "name": "Rock_Ice"
    },
    {
      "x": -23,
      "y": 34,
      "z": 2,
      "name": "Rock_Ice"
    },
    {
      "x": -23,
      "y": 35,
      "z": 2,
      "name": "Rock_Ice"
    },
    {
      "x": -23,
      "y": 36,
      "z": 2,
      "name": "Rock_Ice"
    },
    {
      "x": -23,
      "y": 37,
      "z": 2,
      "name": "Soil_Snow"
    },
    {
      "x": -23,
      "y": 31,
      "z": 3,
      "name": "Rock_Ice"
    },
    {
      "x": -23,
      "y": 32,
      "z": 3,
      "name": "Rock_Ice"
    },
    {
      "x": -23,
      "y": 33,
      "z": 3,
      "name": "Rock_Ice"
    },
    {
      "x": -23,
      "y": 34,
      "z": 3,
      "name": "Rock_Ice"
    },
    {
      "x": -23,
      "y": 35,
      "z": 3,
      "name": "Rock_Ice"
    },
    {
      "x": -23,
      "y": 36,
      "z": 3,
      "name": "Soil_Snow"
    },
    {
      "x": -23,
      "y": 31,
      "z": 4,
      "name": "Rock_Ice"
    },
    {
      "x": -23,
      "y": 32,
      "z": 4,
      "name": "Rock_Ice"
    },
    {
      "x": -23,
      "y": 33,
      "z": 4,
      "name": "Rock_Ice"
    },
    {
      "x": -23,
      "y": 34,
      "z": 4,
      "name": "Rock_Ice"
    },
    {
      "x": -23,
      "y": 35,
      "z": 4,
      "name": "Rock_Ice"
    },
    {
      "x": -23,
      "y": 36,
      "z": 4,
      "name": "Soil_Snow"
    },
    {
      "x": -23,
      "y": 32,
      "z": 5,
      "name": "Rock_Ice"
    },
    {
      "x": -23,
      "y": 33,
      "z": 5,
      "name": "Rock_Ice"
    },
    {
      "x": -23,
      "y": 34,
      "z": 5,
      "name": "Rock_Ice"
    },
    {
      "x": -23,
      "y": 35,
      "z": 5,
      "name": "Soil_Snow"
    },
    {
      "x": -23,
      "y": 32,
      "z": 6,
      "name": "Rock_Ice"
    },
    {
      "x": -23,
      "y": 33,
      "z": 6,
      "name": "Rock_Ice"
    },
    {
      "x": -23,
      "y": 34,
      "z": 6,
      "name": "Rock_Ice_Permafrost"
    },
    {
      "x": -23,
      "y": 35,
      "z": 6,
      "name": "Soil_Snow"
    },
    {
      "x": -23,
      "y": 32,
      "z": 7,
      "name": "Rock_Ice_Permafrost"
    },
    {
      "x": -23,
      "y": 33,
      "z": 7,
      "name": "Rock_Ice"
    },
    {
      "x": -23,
      "y": 34,
      "z": 7,
      "name": "Soil_Snow"
    },
    {
      "x": -23,
      "y": 32,
      "z": 8,
      "name": "Rock_Ice_Permafrost"
    },
    {
      "x": -23,
      "y": 33,
      "z": 8,
      "name": "Rock_Ice"
    },
    {
      "x": -23,
      "y": 34,
      "z": 8,
      "name": "Soil_Snow"
    },
    {
      "x": -23,
      "y": 32,
      "z": 9,
      "name": "Rock_Ice"
    },
    {
      "x": -23,
      "y": 33,
      "z": 9,
      "name": "Soil_Snow"
    },
    {
      "x": -23,
      "y": 32,
      "z": 10,
      "name": "Rock_Ice"
    },
    {
      "x": -23,
      "y": 33,
      "z": 10,
      "name": "Soil_Snow"
    },
    {
      "x": -23,
      "y": 32,
      "z": 11,
      "name": "Soil_Snow"
    },
    {
      "x": -23,
      "y": 32,
      "z": 12,
      "name": "Soil_Snow"
    },
    {
      "x": -23,
      "y": 31,
      "z": 13,
      "name": "Rock_Ice"
    },
    {
      "x": -23,
      "y": 32,
      "z": 13,
      "name": "Soil_Snow"
    },
    {
      "x": -23,
      "y": 30,
      "z": 14,
      "name": "Rock_Ice"
    },
    {
      "x": -23,
      "y": 31,
      "z": 14,
      "name": "Soil_Snow"
    },
    {
      "x": -23,
      "y": 23,
      "z": 15,
      "name": "Rock_Ice"
    },
    {
      "x": -23,
      "y": 24,
      "z": 15,
      "name": "Rock_Ice"
    },
    {
      "x": -23,
      "y": 25,
      "z": 15,
      "name": "Rock_Ice"
    },
    {
      "x": -23,
      "y": 26,
      "z": 15,
      "name": "Rock_Ice"
    },
    {
      "x": -23,
      "y": 27,
      "z": 15,
      "name": "Rock_Ice"
    },
    {
      "x": -23,
      "y": 28,
      "z": 15,
      "name": "Rock_Ice"
    },
    {
      "x": -23,
      "y": 29,
      "z": 15,
      "name": "Rock_Ice"
    },
    {
      "x": -23,
      "y": 30,
      "z": 15,
      "name": "Rock_Ice"
    },
    {
      "x": -23,
      "y": 31,
      "z": 15,
      "name": "Soil_Snow"
    },
    {
      "x": -23,
      "y": 20,
      "z": 16,
      "name": "Rock_Ice_Permafrost"
    },
    {
      "x": -23,
      "y": 21,
      "z": 16,
      "name": "Rock_Ice_Permafrost"
    },
    {
      "x": -23,
      "y": 22,
      "z": 16,
      "name": "Rock_Ice_Permafrost"
    },
    {
      "x": -23,
      "y": 23,
      "z": 16,
      "name": "Rock_Ice_Permafrost"
    },
    {
      "x": -23,
      "y": 24,
      "z": 16,
      "name": "Rock_Ice"
    },
    {
      "x": -23,
      "y": 25,
      "z": 16,
      "name": "Rock_Ice"
    },
    {
      "x": -23,
      "y": 26,
      "z": 16,
      "name": "Rock_Ice"
    },
    {
      "x": -23,
      "y": 27,
      "z": 16,
      "name": "Rock_Ice"
    },
    {
      "x": -23,
      "y": 28,
      "z": 16,
      "name": "Rock_Ice"
    },
    {
      "x": -23,
      "y": 29,
      "z": 16,
      "name": "Rock_Ice"
    },
    {
      "x": -23,
      "y": 30,
      "z": 16,
      "name": "Rock_Ice"
    },
    {
      "x": -23,
      "y": 31,
      "z": 16,
      "name": "Soil_Snow"
    },
    {
      "x": -23,
      "y": 18,
      "z": 17,
      "name": "Rock_Ice_Permafrost"
    },
    {
      "x": -23,
      "y": 19,
      "z": 17,
      "name": "Rock_Ice_Permafrost"
    },
    {
      "x": -23,
      "y": 20,
      "z": 17,
      "name": "Rock_Ice_Permafrost"
    },
    {
      "x": -23,
      "y": 21,
      "z": 17,
      "name": "Rock_Ice_Permafrost"
    },
    {
      "x": -23,
      "y": 22,
      "z": 17,
      "name": "Rock_Ice_Permafrost"
    },
    {
      "x": -23,
      "y": 23,
      "z": 17,
      "name": "Rock_Ice"
    },
    {
      "x": -23,
      "y": 24,
      "z": 17,
      "name": "Rock_Ice"
    },
    {
      "x": -23,
      "y": 25,
      "z": 17,
      "name": "Rock_Ice"
    },
    {
      "x": -23,
      "y": 26,
      "z": 17,
      "name": "Rock_Ice"
    },
    {
      "x": -23,
      "y": 27,
      "z": 17,
      "name": "Rock_Ice"
    },
    {
      "x": -23,
      "y": 28,
      "z": 17,
      "name": "Rock_Ice"
    },
    {
      "x": -23,
      "y": 29,
      "z": 17,
      "name": "Rock_Ice"
    },
    {
      "x": -23,
      "y": 30,
      "z": 17,
      "name": "Rock_Ice"
    },
    {
      "x": -23,
      "y": 31,
      "z": 17,
      "name": "Soil_Snow"
    },
    {
      "x": -23,
      "y": 18,
      "z": 18,
      "name": "Rock_Ice_Permafrost"
    },
    {
      "x": -23,
      "y": 19,
      "z": 18,
      "name": "Rock_Ice_Permafrost"
    },
    {
      "x": -23,
      "y": 20,
      "z": 18,
      "name": "Rock_Ice_Permafrost"
    },
    {
      "x": -23,
      "y": 21,
      "z": 18,
      "name": "Rock_Ice_Permafrost"
    },
    {
      "x": -23,
      "y": 22,
      "z": 18,
      "name": "Rock_Ice_Permafrost"
    },
    {
      "x": -23,
      "y": 23,
      "z": 18,
      "name": "Rock_Ice"
    },
    {
      "x": -23,
      "y": 24,
      "z": 18,
      "name": "Rock_Ice"
    },
    {
      "x": -23,
      "y": 25,
      "z": 18,
      "name": "Rock_Ice"
    },
    {
      "x": -23,
      "y": 26,
      "z": 18,
      "name": "Rock_Ice"
    },
    {
      "x": -23,
      "y": 27,
      "z": 18,
      "name": "Rock_Ice"
    },
    {
      "x": -23,
      "y": 28,
      "z": 18,
      "name": "Rock_Ice"
    },
    {
      "x": -23,
      "y": 29,
      "z": 18,
      "name": "Soil_Snow"
    },
    {
      "x": -23,
      "y": 18,
      "z": 19,
      "name": "Rock_Ice_Permafrost"
    },
    {
      "x": -23,
      "y": 19,
      "z": 19,
      "name": "Rock_Ice_Permafrost"
    },
    {
      "x": -23,
      "y": 20,
      "z": 19,
      "name": "Rock_Ice_Permafrost"
    },
    {
      "x": -23,
      "y": 21,
      "z": 19,
      "name": "Rock_Ice"
    },
    {
      "x": -23,
      "y": 22,
      "z": 19,
      "name": "Rock_Ice"
    },
    {
      "x": -23,
      "y": 23,
      "z": 19,
      "name": "Rock_Ice"
    },
    {
      "x": -23,
      "y": 24,
      "z": 19,
      "name": "Rock_Ice"
    },
    {
      "x": -23,
      "y": 25,
      "z": 19,
      "name": "Rock_Ice"
    },
    {
      "x": -23,
      "y": 26,
      "z": 19,
      "name": "Rock_Ice"
    },
    {
      "x": -23,
      "y": 27,
      "z": 19,
      "name": "Soil_Snow"
    },
    {
      "x": -23,
      "y": 19,
      "z": 20,
      "name": "Rock_Ice_Permafrost"
    },
    {
      "x": -23,
      "y": 20,
      "z": 20,
      "name": "Rock_Ice_Permafrost"
    },
    {
      "x": -23,
      "y": 21,
      "z": 20,
      "name": "Rock_Ice"
    },
    {
      "x": -23,
      "y": 22,
      "z": 20,
      "name": "Rock_Ice"
    },
    {
      "x": -23,
      "y": 23,
      "z": 20,
      "name": "Rock_Ice"
    },
    {
      "x": -23,
      "y": 24,
      "z": 20,
      "name": "Rock_Ice"
    },
    {
      "x": -23,
      "y": 25,
      "z": 20,
      "name": "Rock_Ice"
    },
    {
      "x": -23,
      "y": 26,
      "z": 20,
      "name": "Soil_Snow"
    },
    {
      "x": -23,
      "y": 21,
      "z": 21,
      "name": "Rock_Ice"
    },
    {
      "x": -23,
      "y": 22,
      "z": 21,
      "name": "Rock_Ice"
    },
    {
      "x": -23,
      "y": 23,
      "z": 21,
      "name": "Rock_Ice"
    },
    {
      "x": -23,
      "y": 24,
      "z": 21,
      "name": "Rock_Ice"
    },
    {
      "x": -23,
      "y": 25,
      "z": 21,
      "name": "Rock_Ice"
    },
    {
      "x": -23,
      "y": 26,
      "z": 21,
      "name": "Rock_Ice"
    },
    {
      "x": -23,
      "y": 27,
      "z": 21,
      "name": "Rock_Ice"
    },
    {
      "x": -23,
      "y": 28,
      "z": 21,
      "name": "Rock_Ice"
    },
    {
      "x": -23,
      "y": 23,
      "z": 22,
      "name": "Rock_Ice"
    },
    {
      "x": -23,
      "y": 24,
      "z": 22,
      "name": "Rock_Ice"
    },
    {
      "x": -23,
      "y": 25,
      "z": 22,
      "name": "Rock_Ice"
    },
    {
      "x": -23,
      "y": 26,
      "z": 22,
      "name": "Rock_Ice"
    },
    {
      "x": -23,
      "y": 27,
      "z": 22,
      "name": "Rock_Ice"
    },
    {
      "x": -23,
      "y": 28,
      "z": 22,
      "name": "Rock_Ice"
    },
    {
      "x": -23,
      "y": 29,
      "z": 22,
      "name": "Soil_Snow"
    },
    {
      "x": -23,
      "y": 22,
      "z": 23,
      "name": "Rock_Ice"
    },
    {
      "x": -23,
      "y": 23,
      "z": 23,
      "name": "Rock_Ice"
    },
    {
      "x": -23,
      "y": 24,
      "z": 23,
      "name": "Rock_Ice"
    },
    {
      "x": -23,
      "y": 25,
      "z": 23,
      "name": "Rock_Ice"
    },
    {
      "x": -22,
      "y": 27,
      "z": -15,
      "name": "Rock_Ice_Permafrost"
    },
    {
      "x": -22,
      "y": 28,
      "z": -15,
      "name": "Rock_Ice_Permafrost"
    },
    {
      "x": -22,
      "y": 24,
      "z": -14,
      "name": "Rock_Ice_Permafrost"
    },
    {
      "x": -22,
      "y": 25,
      "z": -14,
      "name": "Rock_Ice_Permafrost"
    },
    {
      "x": -22,
      "y": 26,
      "z": -14,
      "name": "Rock_Ice_Permafrost"
    },
    {
      "x": -22,
      "y": 27,
      "z": -14,
      "name": "Rock_Ice_Permafrost"
    },
    {
      "x": -22,
      "y": 28,
      "z": -14,
      "name": "Rock_Ice_Permafrost"
    },
    {
      "x": -22,
      "y": 29,
      "z": -14,
      "name": "Rock_Ice_Permafrost"
    },
    {
      "x": -22,
      "y": 30,
      "z": -14,
      "name": "Rock_Ice"
    },
    {
      "x": -22,
      "y": 31,
      "z": -14,
      "name": "Soil_Snow"
    },
    {
      "x": -22,
      "y": 23,
      "z": -13,
      "name": "Rock_Ice_Permafrost"
    },
    {
      "x": -22,
      "y": 24,
      "z": -13,
      "name": "Rock_Ice_Permafrost"
    },
    {
      "x": -22,
      "y": 25,
      "z": -13,
      "name": "Rock_Ice_Permafrost"
    },
    {
      "x": -22,
      "y": 26,
      "z": -13,
      "name": "Rock_Ice_Permafrost"
    },
    {
      "x": -22,
      "y": 27,
      "z": -13,
      "name": "Rock_Ice_Permafrost"
    },
    {
      "x": -22,
      "y": 28,
      "z": -13,
      "name": "Rock_Ice_Permafrost"
    },
    {
      "x": -22,
      "y": 29,
      "z": -13,
      "name": "Rock_Ice_Permafrost"
    },
    {
      "x": -22,
      "y": 30,
      "z": -13,
      "name": "Rock_Ice"
    },
    {
      "x": -22,
      "y": 31,
      "z": -13,
      "name": "Rock_Ice"
    },
    {
      "x": -22,
      "y": 32,
      "z": -13,
      "name": "Soil_Snow"
    },
    {
      "x": -22,
      "y": 19,
      "z": -12,
      "name": "Rock_Ice"
    },
    {
      "x": -22,
      "y": 20,
      "z": -12,
      "name": "Rock_Ice"
    },
    {
      "x": -22,
      "y": 21,
      "z": -12,
      "name": "Rock_Ice"
    },
    {
      "x": -22,
      "y": 22,
      "z": -12,
      "name": "Rock_Ice_Permafrost"
    },
    {
      "x": -22,
      "y": 23,
      "z": -12,
      "name": "Rock_Ice_Permafrost"
    },
    {
      "x": -22,
      "y": 24,
      "z": -12,
      "name": "Rock_Ice_Permafrost"
    },
    {
      "x": -22,
      "y": 25,
      "z": -12,
      "name": "Rock_Ice_Permafrost"
    },
    {
      "x": -22,
      "y": 26,
      "z": -12,
      "name": "Rock_Ice_Permafrost"
    },
    {
      "x": -22,
      "y": 27,
      "z": -12,
      "name": "Rock_Ice_Permafrost"
    },
    {
      "x": -22,
      "y": 28,
      "z": -12,
      "name": "Rock_Ice_Permafrost"
    },
    {
      "x": -22,
      "y": 29,
      "z": -12,
      "name": "Rock_Ice"
    },
    {
      "x": -22,
      "y": 30,
      "z": -12,
      "name": "Rock_Ice"
    },
    {
      "x": -22,
      "y": 31,
      "z": -12,
      "name": "Rock_Ice"
    },
    {
      "x": -22,
      "y": 32,
      "z": -12,
      "name": "Rock_Ice"
    },
    {
      "x": -22,
      "y": 33,
      "z": -12,
      "name": "Soil_Snow"
    },
    {
      "x": -22,
      "y": 18,
      "z": -11,
      "name": "Rock_Ice"
    },
    {
      "x": -22,
      "y": 19,
      "z": -11,
      "name": "Rock_Ice_Permafrost"
    },
    {
      "x": -22,
      "y": 20,
      "z": -11,
      "name": "Rock_Ice_Permafrost"
    },
    {
      "x": -22,
      "y": 21,
      "z": -11,
      "name": "Rock_Ice_Permafrost"
    },
    {
      "x": -22,
      "y": 22,
      "z": -11,
      "name": "Rock_Ice_Permafrost"
    },
    {
      "x": -22,
      "y": 23,
      "z": -11,
      "name": "Rock_Ice_Permafrost"
    },
    {
      "x": -22,
      "y": 24,
      "z": -11,
      "name": "Rock_Ice_Permafrost"
    },
    {
      "x": -22,
      "y": 25,
      "z": -11,
      "name": "Rock_Ice_Permafrost"
    },
    {
      "x": -22,
      "y": 26,
      "z": -11,
      "name": "Rock_Ice_Permafrost"
    },
    {
      "x": -22,
      "y": 27,
      "z": -11,
      "name": "Rock_Ice_Permafrost"
    },
    {
      "x": -22,
      "y": 28,
      "z": -11,
      "name": "Rock_Ice_Permafrost"
    },
    {
      "x": -22,
      "y": 29,
      "z": -11,
      "name": "Rock_Ice"
    },
    {
      "x": -22,
      "y": 30,
      "z": -11,
      "name": "Rock_Ice"
    },
    {
      "x": -22,
      "y": 31,
      "z": -11,
      "name": "Rock_Ice"
    },
    {
      "x": -22,
      "y": 32,
      "z": -11,
      "name": "Rock_Ice"
    },
    {
      "x": -22,
      "y": 33,
      "z": -11,
      "name": "Rock_Ice"
    },
    {
      "x": -22,
      "y": 34,
      "z": -11,
      "name": "Soil_Snow"
    },
    {
      "x": -22,
      "y": 17,
      "z": -10,
      "name": "Rock_Ice_Permafrost"
    },
    {
      "x": -22,
      "y": 18,
      "z": -10,
      "name": "Rock_Ice_Permafrost"
    },
    {
      "x": -22,
      "y": 19,
      "z": -10,
      "name": "Rock_Ice_Permafrost"
    },
    {
      "x": -22,
      "y": 20,
      "z": -10,
      "name": "Rock_Ice_Permafrost"
    },
    {
      "x": -22,
      "y": 21,
      "z": -10,
      "name": "Rock_Ice_Permafrost"
    },
    {
      "x": -22,
      "y": 22,
      "z": -10,
      "name": "Rock_Ice_Permafrost"
    },
    {
      "x": -22,
      "y": 23,
      "z": -10,
      "name": "Rock_Ice_Permafrost"
    },
    {
      "x": -22,
      "y": 24,
      "z": -10,
      "name": "Rock_Ice_Permafrost"
    },
    {
      "x": -22,
      "y": 25,
      "z": -10,
      "name": "Rock_Ice_Permafrost"
    },
    {
      "x": -22,
      "y": 26,
      "z": -10,
      "name": "Rock_Ice_Permafrost"
    },
    {
      "x": -22,
      "y": 27,
      "z": -10,
      "name": "Rock_Ice_Permafrost"
    },
    {
      "x": -22,
      "y": 28,
      "z": -10,
      "name": "Rock_Ice_Permafrost"
    },
    {
      "x": -22,
      "y": 29,
      "z": -10,
      "name": "Rock_Ice_Permafrost"
    },
    {
      "x": -22,
      "y": 30,
      "z": -10,
      "name": "Rock_Ice_Permafrost"
    },
    {
      "x": -22,
      "y": 31,
      "z": -10,
      "name": "Rock_Ice_Permafrost"
    },
    {
      "x": -22,
      "y": 32,
      "z": -10,
      "name": "Rock_Ice"
    },
    {
      "x": -22,
      "y": 33,
      "z": -10,
      "name": "Rock_Ice"
    },
    {
      "x": -22,
      "y": 34,
      "z": -10,
      "name": "Rock_Ice"
    },
    {
      "x": -22,
      "y": 35,
      "z": -10,
      "name": "Soil_Snow"
    },
    {
      "x": -22,
      "y": 14,
      "z": -9,
      "name": "Rock_Ice_Permafrost"
    },
    {
      "x": -22,
      "y": 15,
      "z": -9,
      "name": "Rock_Ice_Permafrost"
    },
    {
      "x": -22,
      "y": 16,
      "z": -9,
      "name": "Rock_Ice_Permafrost"
    },
    {
      "x": -22,
      "y": 17,
      "z": -9,
      "name": "Rock_Ice_Permafrost"
    },
    {
      "x": -22,
      "y": 18,
      "z": -9,
      "name": "Rock_Ice_Permafrost"
    },
    {
      "x": -22,
      "y": 19,
      "z": -9,
      "name": "Rock_Ice_Permafrost"
    },
    {
      "x": -22,
      "y": 20,
      "z": -9,
      "name": "Rock_Ice_Permafrost"
    },
    {
      "x": -22,
      "y": 21,
      "z": -9,
      "name": "Rock_Ice_Permafrost"
    },
    {
      "x": -22,
      "y": 22,
      "z": -9,
      "name": "Rock_Ice_Permafrost"
    },
    {
      "x": -22,
      "y": 23,
      "z": -9,
      "name": "Rock_Ice_Permafrost"
    },
    {
      "x": -22,
      "y": 24,
      "z": -9,
      "name": "Rock_Ice"
    },
    {
      "x": -22,
      "y": 25,
      "z": -9,
      "name": "Rock_Ice"
    },
    {
      "x": -22,
      "y": 26,
      "z": -9,
      "name": "Rock_Ice_Permafrost"
    },
    {
      "x": -22,
      "y": 27,
      "z": -9,
      "name": "Rock_Ice"
    },
    {
      "x": -22,
      "y": 28,
      "z": -9,
      "name": "Rock_Ice_Permafrost"
    },
    {
      "x": -22,
      "y": 29,
      "z": -9,
      "name": "Rock_Ice_Permafrost"
    },
    {
      "x": -22,
      "y": 30,
      "z": -9,
      "name": "Rock_Ice_Permafrost"
    },
    {
      "x": -22,
      "y": 31,
      "z": -9,
      "name": "Rock_Ice_Permafrost"
    },
    {
      "x": -22,
      "y": 32,
      "z": -9,
      "name": "Rock_Ice_Permafrost"
    },
    {
      "x": -22,
      "y": 33,
      "z": -9,
      "name": "Rock_Ice_Permafrost"
    },
    {
      "x": -22,
      "y": 34,
      "z": -9,
      "name": "Rock_Ice_Permafrost"
    },
    {
      "x": -22,
      "y": 35,
      "z": -9,
      "name": "Rock_Ice"
    },
    {
      "x": -22,
      "y": 36,
      "z": -9,
      "name": "Soil_Snow"
    },
    {
      "x": -22,
      "y": 17,
      "z": -8,
      "name": "Rock_Ice_Permafrost"
    },
    {
      "x": -22,
      "y": 18,
      "z": -8,
      "name": "Rock_Ice_Permafrost"
    },
    {
      "x": -22,
      "y": 19,
      "z": -8,
      "name": "Rock_Ice_Permafrost"
    },
    {
      "x": -22,
      "y": 20,
      "z": -8,
      "name": "Rock_Ice"
    },
    {
      "x": -22,
      "y": 21,
      "z": -8,
      "name": "Rock_Ice"
    },
    {
      "x": -22,
      "y": 22,
      "z": -8,
      "name": "Rock_Ice"
    },
    {
      "x": -22,
      "y": 23,
      "z": -8,
      "name": "Rock_Ice"
    },
    {
      "x": -22,
      "y": 24,
      "z": -8,
      "name": "Rock_Ice"
    },
    {
      "x": -22,
      "y": 25,
      "z": -8,
      "name": "Rock_Ice"
    },
    {
      "x": -22,
      "y": 26,
      "z": -8,
      "name": "Rock_Ice"
    },
    {
      "x": -22,
      "y": 27,
      "z": -8,
      "name": "Rock_Ice"
    },
    {
      "x": -22,
      "y": 28,
      "z": -8,
      "name": "Rock_Ice_Permafrost"
    },
    {
      "x": -22,
      "y": 29,
      "z": -8,
      "name": "Rock_Ice"
    },
    {
      "x": -22,
      "y": 30,
      "z": -8,
      "name": "Rock_Ice_Permafrost"
    },
    {
      "x": -22,
      "y": 31,
      "z": -8,
      "name": "Rock_Ice_Permafrost"
    },
    {
      "x": -22,
      "y": 32,
      "z": -8,
      "name": "Rock_Ice_Permafrost"
    },
    {
      "x": -22,
      "y": 33,
      "z": -8,
      "name": "Rock_Ice_Permafrost"
    },
    {
      "x": -22,
      "y": 34,
      "z": -8,
      "name": "Rock_Ice_Permafrost"
    },
    {
      "x": -22,
      "y": 35,
      "z": -8,
      "name": "Rock_Ice_Permafrost"
    },
    {
      "x": -22,
      "y": 36,
      "z": -8,
      "name": "Rock_Ice"
    },
    {
      "x": -22,
      "y": 37,
      "z": -8,
      "name": "Soil_Snow"
    },
    {
      "x": -22,
      "y": 19,
      "z": -7,
      "name": "Rock_Ice"
    },
    {
      "x": -22,
      "y": 20,
      "z": -7,
      "name": "Rock_Ice"
    },
    {
      "x": -22,
      "y": 21,
      "z": -7,
      "name": "Rock_Ice"
    },
    {
      "x": -22,
      "y": 22,
      "z": -7,
      "name": "Rock_Ice"
    },
    {
      "x": -22,
      "y": 23,
      "z": -7,
      "name": "Rock_Ice"
    },
    {
      "x": -22,
      "y": 24,
      "z": -7,
      "name": "Rock_Ice"
    },
    {
      "x": -22,
      "y": 25,
      "z": -7,
      "name": "Rock_Ice"
    },
    {
      "x": -22,
      "y": 26,
      "z": -7,
      "name": "Rock_Ice"
    },
    {
      "x": -22,
      "y": 27,
      "z": -7,
      "name": "Rock_Ice"
    },
    {
      "x": -22,
      "y": 28,
      "z": -7,
      "name": "Rock_Ice"
    },
    {
      "x": -22,
      "y": 29,
      "z": -7,
      "name": "Rock_Ice"
    },
    {
      "x": -22,
      "y": 30,
      "z": -7,
      "name": "Rock_Ice"
    },
    {
      "x": -22,
      "y": 31,
      "z": -7,
      "name": "Rock_Ice_Permafrost"
    },
    {
      "x": -22,
      "y": 32,
      "z": -7,
      "name": "Rock_Ice_Permafrost"
    },
    {
      "x": -22,
      "y": 33,
      "z": -7,
      "name": "Rock_Ice_Permafrost"
    },
    {
      "x": -22,
      "y": 34,
      "z": -7,
      "name": "Rock_Ice_Permafrost"
    },
    {
      "x": -22,
      "y": 35,
      "z": -7,
      "name": "Rock_Ice_Permafrost"
    },
    {
      "x": -22,
      "y": 36,
      "z": -7,
      "name": "Rock_Ice_Permafrost"
    },
    {
      "x": -22,
      "y": 37,
      "z": -7,
      "name": "Rock_Ice"
    },
    {
      "x": -22,
      "y": 38,
      "z": -7,
      "name": "Rock_Ice"
    },
    {
      "x": -22,
      "y": 19,
      "z": -6,
      "name": "Rock_Ice"
    },
    {
      "x": -22,
      "y": 20,
      "z": -6,
      "name": "Rock_Ice"
    },
    {
      "x": -22,
      "y": 21,
      "z": -6,
      "name": "Rock_Ice"
    },
    {
      "x": -22,
      "y": 22,
      "z": -6,
      "name": "Rock_Ice"
    },
    {
      "x": -22,
      "y": 23,
      "z": -6,
      "name": "Rock_Ice"
    },
    {
      "x": -22,
      "y": 24,
      "z": -6,
      "name": "Rock_Ice"
    },
    {
      "x": -22,
      "y": 25,
      "z": -6,
      "name": "Rock_Ice"
    },
    {
      "x": -22,
      "y": 26,
      "z": -6,
      "name": "Rock_Ice"
    },
    {
      "x": -22,
      "y": 27,
      "z": -6,
      "name": "Rock_Ice"
    },
    {
      "x": -22,
      "y": 28,
      "z": -6,
      "name": "Rock_Ice"
    },
    {
      "x": -22,
      "y": 29,
      "z": -6,
      "name": "Rock_Ice"
    },
    {
      "x": -22,
      "y": 30,
      "z": -6,
      "name": "Rock_Ice"
    },
    {
      "x": -22,
      "y": 31,
      "z": -6,
      "name": "Rock_Ice"
    },
    {
      "x": -22,
      "y": 32,
      "z": -6,
      "name": "Rock_Ice"
    },
    {
      "x": -22,
      "y": 33,
      "z": -6,
      "name": "Rock_Ice"
    },
    {
      "x": -22,
      "y": 34,
      "z": -6,
      "name": "Rock_Ice_Permafrost"
    },
    {
      "x": -22,
      "y": 35,
      "z": -6,
      "name": "Rock_Ice_Permafrost"
    },
    {
      "x": -22,
      "y": 36,
      "z": -6,
      "name": "Rock_Ice_Permafrost"
    },
    {
      "x": -22,
      "y": 37,
      "z": -6,
      "name": "Rock_Ice_Permafrost"
    },
    {
      "x": -22,
      "y": 38,
      "z": -6,
      "name": "Rock_Ice"
    },
    {
      "x": -22,
      "y": 39,
      "z": -6,
      "name": "Rock_Ice"
    },
    {
      "x": -22,
      "y": 40,
      "z": -6,
      "name": "Rock_Ice"
    },
    {
      "x": -22,
      "y": 41,
      "z": -6,
      "name": "Rock_Ice"
    },
    {
      "x": -22,
      "y": 42,
      "z": -6,
      "name": "Rock_Ice"
    },
    {
      "x": -22,
      "y": 43,
      "z": -6,
      "name": "Rock_Ice"
    },
    {
      "x": -22,
      "y": 44,
      "z": -6,
      "name": "Rock_Ice"
    },
    {
      "x": -22,
      "y": 45,
      "z": -6,
      "name": "Rock_Ice"
    },
    {
      "x": -22,
      "y": 46,
      "z": -6,
      "name": "Soil_Snow"
    },
    {
      "x": -22,
      "y": 20,
      "z": -5,
      "name": "Rock_Ice"
    },
    {
      "x": -22,
      "y": 21,
      "z": -5,
      "name": "Rock_Ice"
    },
    {
      "x": -22,
      "y": 22,
      "z": -5,
      "name": "Rock_Ice"
    },
    {
      "x": -22,
      "y": 23,
      "z": -5,
      "name": "Rock_Ice"
    },
    {
      "x": -22,
      "y": 24,
      "z": -5,
      "name": "Rock_Ice"
    },
    {
      "x": -22,
      "y": 25,
      "z": -5,
      "name": "Rock_Ice"
    },
    {
      "x": -22,
      "y": 26,
      "z": -5,
      "name": "Rock_Ice"
    },
    {
      "x": -22,
      "y": 27,
      "z": -5,
      "name": "Rock_Ice"
    },
    {
      "x": -22,
      "y": 28,
      "z": -5,
      "name": "Rock_Ice"
    },
    {
      "x": -22,
      "y": 29,
      "z": -5,
      "name": "Rock_Ice"
    },
    {
      "x": -22,
      "y": 30,
      "z": -5,
      "name": "Rock_Ice"
    },
    {
      "x": -22,
      "y": 31,
      "z": -5,
      "name": "Rock_Ice"
    },
    {
      "x": -22,
      "y": 32,
      "z": -5,
      "name": "Rock_Ice"
    },
    {
      "x": -22,
      "y": 33,
      "z": -5,
      "name": "Rock_Ice_Permafrost"
    },
    {
      "x": -22,
      "y": 34,
      "z": -5,
      "name": "Rock_Ice"
    },
    {
      "x": -22,
      "y": 35,
      "z": -5,
      "name": "Rock_Ice"
    },
    {
      "x": -22,
      "y": 36,
      "z": -5,
      "name": "Rock_Ice"
    },
    {
      "x": -22,
      "y": 37,
      "z": -5,
      "name": "Rock_Ice_Permafrost"
    },
    {
      "x": -22,
      "y": 38,
      "z": -5,
      "name": "Rock_Ice_Permafrost"
    },
    {
      "x": -22,
      "y": 39,
      "z": -5,
      "name": "Rock_Ice_Permafrost"
    },
    {
      "x": -22,
      "y": 40,
      "z": -5,
      "name": "Rock_Ice"
    },
    {
      "x": -22,
      "y": 41,
      "z": -5,
      "name": "Rock_Ice"
    },
    {
      "x": -22,
      "y": 42,
      "z": -5,
      "name": "Rock_Ice"
    },
    {
      "x": -22,
      "y": 43,
      "z": -5,
      "name": "Rock_Ice"
    },
    {
      "x": -22,
      "y": 44,
      "z": -5,
      "name": "Rock_Ice"
    },
    {
      "x": -22,
      "y": 45,
      "z": -5,
      "name": "Soil_Snow"
    },
    {
      "x": -22,
      "y": 21,
      "z": -4,
      "name": "Rock_Ice"
    },
    {
      "x": -22,
      "y": 22,
      "z": -4,
      "name": "Rock_Ice"
    },
    {
      "x": -22,
      "y": 23,
      "z": -4,
      "name": "Rock_Ice"
    },
    {
      "x": -22,
      "y": 24,
      "z": -4,
      "name": "Rock_Ice"
    },
    {
      "x": -22,
      "y": 25,
      "z": -4,
      "name": "Rock_Ice"
    },
    {
      "x": -22,
      "y": 26,
      "z": -4,
      "name": "Rock_Ice"
    },
    {
      "x": -22,
      "y": 27,
      "z": -4,
      "name": "Rock_Ice"
    },
    {
      "x": -22,
      "y": 28,
      "z": -4,
      "name": "Rock_Ice"
    },
    {
      "x": -22,
      "y": 29,
      "z": -4,
      "name": "Rock_Ice"
    },
    {
      "x": -22,
      "y": 30,
      "z": -4,
      "name": "Rock_Ice"
    },
    {
      "x": -22,
      "y": 31,
      "z": -4,
      "name": "Rock_Ice"
    },
    {
      "x": -22,
      "y": 32,
      "z": -4,
      "name": "Rock_Ice"
    },
    {
      "x": -22,
      "y": 33,
      "z": -4,
      "name": "Rock_Ice"
    },
    {
      "x": -22,
      "y": 34,
      "z": -4,
      "name": "Rock_Ice"
    },
    {
      "x": -22,
      "y": 35,
      "z": -4,
      "name": "Rock_Ice"
    },
    {
      "x": -22,
      "y": 36,
      "z": -4,
      "name": "Rock_Ice_Permafrost"
    },
    {
      "x": -22,
      "y": 37,
      "z": -4,
      "name": "Rock_Ice_Permafrost"
    },
    {
      "x": -22,
      "y": 38,
      "z": -4,
      "name": "Rock_Ice_Permafrost"
    },
    {
      "x": -22,
      "y": 39,
      "z": -4,
      "name": "Rock_Ice_Permafrost"
    },
    {
      "x": -22,
      "y": 40,
      "z": -4,
      "name": "Rock_Ice"
    },
    {
      "x": -22,
      "y": 41,
      "z": -4,
      "name": "Rock_Ice"
    },
    {
      "x": -22,
      "y": 42,
      "z": -4,
      "name": "Rock_Ice"
    },
    {
      "x": -22,
      "y": 43,
      "z": -4,
      "name": "Rock_Ice"
    },
    {
      "x": -22,
      "y": 44,
      "z": -4,
      "name": "Soil_Snow"
    },
    {
      "x": -22,
      "y": 22,
      "z": -3,
      "name": "Rock_Ice"
    },
    {
      "x": -22,
      "y": 23,
      "z": -3,
      "name": "Rock_Ice"
    },
    {
      "x": -22,
      "y": 24,
      "z": -3,
      "name": "Rock_Ice"
    },
    {
      "x": -22,
      "y": 25,
      "z": -3,
      "name": "Rock_Ice"
    },
    {
      "x": -22,
      "y": 26,
      "z": -3,
      "name": "Rock_Ice"
    },
    {
      "x": -22,
      "y": 27,
      "z": -3,
      "name": "Rock_Ice"
    },
    {
      "x": -22,
      "y": 28,
      "z": -3,
      "name": "Rock_Ice"
    },
    {
      "x": -22,
      "y": 29,
      "z": -3,
      "name": "Rock_Ice"
    },
    {
      "x": -22,
      "y": 30,
      "z": -3,
      "name": "Rock_Ice"
    },
    {
      "x": -22,
      "y": 31,
      "z": -3,
      "name": "Rock_Ice"
    },
    {
      "x": -22,
      "y": 32,
      "z": -3,
      "name": "Rock_Ice"
    },
    {
      "x": -22,
      "y": 33,
      "z": -3,
      "name": "Rock_Ice"
    },
    {
      "x": -22,
      "y": 34,
      "z": -3,
      "name": "Rock_Ice"
    },
    {
      "x": -22,
      "y": 35,
      "z": -3,
      "name": "Rock_Ice"
    },
    {
      "x": -22,
      "y": 36,
      "z": -3,
      "name": "Rock_Ice_Permafrost"
    },
    {
      "x": -22,
      "y": 37,
      "z": -3,
      "name": "Rock_Ice_Permafrost"
    },
    {
      "x": -22,
      "y": 38,
      "z": -3,
      "name": "Rock_Ice_Permafrost"
    },
    {
      "x": -22,
      "y": 39,
      "z": -3,
      "name": "Rock_Ice_Permafrost"
    },
    {
      "x": -22,
      "y": 40,
      "z": -3,
      "name": "Rock_Ice_Permafrost"
    },
    {
      "x": -22,
      "y": 41,
      "z": -3,
      "name": "Rock_Ice_Permafrost"
    },
    {
      "x": -22,
      "y": 42,
      "z": -3,
      "name": "Rock_Ice_Permafrost"
    },
    {
      "x": -22,
      "y": 43,
      "z": -3,
      "name": "Soil_Snow"
    },
    {
      "x": -22,
      "y": 25,
      "z": -2,
      "name": "Rock_Ice"
    },
    {
      "x": -22,
      "y": 26,
      "z": -2,
      "name": "Rock_Ice"
    },
    {
      "x": -22,
      "y": 27,
      "z": -2,
      "name": "Rock_Ice"
    },
    {
      "x": -22,
      "y": 28,
      "z": -2,
      "name": "Rock_Ice"
    },
    {
      "x": -22,
      "y": 29,
      "z": -2,
      "name": "Rock_Ice"
    },
    {
      "x": -22,
      "y": 30,
      "z": -2,
      "name": "Rock_Ice"
    },
    {
      "x": -22,
      "y": 31,
      "z": -2,
      "name": "Rock_Ice"
    },
    {
      "x": -22,
      "y": 32,
      "z": -2,
      "name": "Rock_Ice"
    },
    {
      "x": -22,
      "y": 33,
      "z": -2,
      "name": "Rock_Ice"
    },
    {
      "x": -22,
      "y": 34,
      "z": -2,
      "name": "Rock_Ice"
    },
    {
      "x": -22,
      "y": 35,
      "z": -2,
      "name": "Rock_Ice"
    },
    {
      "x": -22,
      "y": 36,
      "z": -2,
      "name": "Rock_Ice_Permafrost"
    },
    {
      "x": -22,
      "y": 37,
      "z": -2,
      "name": "Rock_Ice"
    },
    {
      "x": -22,
      "y": 38,
      "z": -2,
      "name": "Rock_Ice_Permafrost"
    },
    {
      "x": -22,
      "y": 39,
      "z": -2,
      "name": "Rock_Ice_Permafrost"
    },
    {
      "x": -22,
      "y": 40,
      "z": -2,
      "name": "Soil_Snow"
    },
    {
      "x": -22,
      "y": 29,
      "z": 0,
      "name": "Rock_Ice"
    },
    {
      "x": -22,
      "y": 30,
      "z": 0,
      "name": "Rock_Ice"
    },
    {
      "x": -22,
      "y": 31,
      "z": 0,
      "name": "Rock_Ice"
    },
    {
      "x": -22,
      "y": 32,
      "z": 0,
      "name": "Rock_Ice"
    },
    {
      "x": -22,
      "y": 33,
      "z": 0,
      "name": "Rock_Ice"
    },
    {
      "x": -22,
      "y": 34,
      "z": 0,
      "name": "Rock_Ice"
    },
    {
      "x": -22,
      "y": 35,
      "z": 0,
      "name": "Rock_Ice"
    },
    {
      "x": -22,
      "y": 36,
      "z": 0,
      "name": "Rock_Ice"
    },
    {
      "x": -22,
      "y": 37,
      "z": 0,
      "name": "Rock_Ice_Permafrost"
    },
    {
      "x": -22,
      "y": 38,
      "z": 0,
      "name": "Rock_Ice"
    },
    {
      "x": -22,
      "y": 39,
      "z": 0,
      "name": "Rock_Ice_Permafrost"
    },
    {
      "x": -22,
      "y": 40,
      "z": 0,
      "name": "Soil_Snow"
    },
    {
      "x": -22,
      "y": 26,
      "z": 1,
      "name": "Rock_Ice"
    },
    {
      "x": -22,
      "y": 27,
      "z": 1,
      "name": "Rock_Ice"
    },
    {
      "x": -22,
      "y": 28,
      "z": 1,
      "name": "Rock_Ice"
    },
    {
      "x": -22,
      "y": 29,
      "z": 1,
      "name": "Rock_Ice"
    },
    {
      "x": -22,
      "y": 30,
      "z": 1,
      "name": "Rock_Ice"
    },
    {
      "x": -22,
      "y": 31,
      "z": 1,
      "name": "Rock_Ice"
    },
    {
      "x": -22,
      "y": 32,
      "z": 1,
      "name": "Rock_Ice"
    },
    {
      "x": -22,
      "y": 33,
      "z": 1,
      "name": "Rock_Ice"
    },
    {
      "x": -22,
      "y": 34,
      "z": 1,
      "name": "Rock_Ice"
    },
    {
      "x": -22,
      "y": 35,
      "z": 1,
      "name": "Rock_Ice"
    },
    {
      "x": -22,
      "y": 36,
      "z": 1,
      "name": "Rock_Ice"
    },
    {
      "x": -22,
      "y": 37,
      "z": 1,
      "name": "Rock_Ice"
    },
    {
      "x": -22,
      "y": 38,
      "z": 1,
      "name": "Rock_Ice"
    },
    {
      "x": -22,
      "y": 39,
      "z": 1,
      "name": "Rock_Ice"
    },
    {
      "x": -22,
      "y": 40,
      "z": 1,
      "name": "Rock_Ice"
    },
    {
      "x": -22,
      "y": 41,
      "z": 1,
      "name": "Rock_Ice_Permafrost"
    },
    {
      "x": -22,
      "y": 42,
      "z": 1,
      "name": "Soil_Snow"
    },
    {
      "x": -22,
      "y": 27,
      "z": 2,
      "name": "Rock_Ice"
    },
    {
      "x": -22,
      "y": 28,
      "z": 2,
      "name": "Rock_Ice"
    },
    {
      "x": -22,
      "y": 29,
      "z": 2,
      "name": "Rock_Ice"
    },
    {
      "x": -22,
      "y": 30,
      "z": 2,
      "name": "Rock_Ice"
    },
    {
      "x": -22,
      "y": 31,
      "z": 2,
      "name": "Rock_Ice"
    },
    {
      "x": -22,
      "y": 32,
      "z": 2,
      "name": "Rock_Ice"
    },
    {
      "x": -22,
      "y": 33,
      "z": 2,
      "name": "Rock_Ice"
    },
    {
      "x": -22,
      "y": 34,
      "z": 2,
      "name": "Rock_Ice"
    },
    {
      "x": -22,
      "y": 35,
      "z": 2,
      "name": "Rock_Ice"
    },
    {
      "x": -22,
      "y": 36,
      "z": 2,
      "name": "Rock_Ice"
    },
    {
      "x": -22,
      "y": 37,
      "z": 2,
      "name": "Rock_Ice"
    },
    {
      "x": -22,
      "y": 38,
      "z": 2,
      "name": "Rock_Ice_Permafrost"
    },
    {
      "x": -22,
      "y": 39,
      "z": 2,
      "name": "Rock_Ice"
    },
    {
      "x": -22,
      "y": 40,
      "z": 2,
      "name": "Rock_Ice"
    },
    {
      "x": -22,
      "y": 41,
      "z": 2,
      "name": "Rock_Ice"
    },
    {
      "x": -22,
      "y": 42,
      "z": 2,
      "name": "Rock_Ice"
    },
    {
      "x": -22,
      "y": 43,
      "z": 2,
      "name": "Soil_Snow"
    },
    {
      "x": -22,
      "y": 27,
      "z": 3,
      "name": "Rock_Ice"
    },
    {
      "x": -22,
      "y": 28,
      "z": 3,
      "name": "Rock_Ice"
    },
    {
      "x": -22,
      "y": 29,
      "z": 3,
      "name": "Rock_Ice"
    },
    {
      "x": -22,
      "y": 30,
      "z": 3,
      "name": "Rock_Ice"
    },
    {
      "x": -22,
      "y": 31,
      "z": 3,
      "name": "Rock_Ice"
    },
    {
      "x": -22,
      "y": 32,
      "z": 3,
      "name": "Rock_Ice"
    },
    {
      "x": -22,
      "y": 33,
      "z": 3,
      "name": "Rock_Ice"
    },
    {
      "x": -22,
      "y": 34,
      "z": 3,
      "name": "Rock_Ice"
    },
    {
      "x": -22,
      "y": 35,
      "z": 3,
      "name": "Rock_Ice"
    },
    {
      "x": -22,
      "y": 36,
      "z": 3,
      "name": "Rock_Ice"
    },
    {
      "x": -22,
      "y": 37,
      "z": 3,
      "name": "Rock_Ice"
    },
    {
      "x": -22,
      "y": 38,
      "z": 3,
      "name": "Rock_Ice_Permafrost"
    },
    {
      "x": -22,
      "y": 39,
      "z": 3,
      "name": "Rock_Ice_Permafrost"
    },
    {
      "x": -22,
      "y": 40,
      "z": 3,
      "name": "Rock_Ice_Permafrost"
    },
    {
      "x": -22,
      "y": 41,
      "z": 3,
      "name": "Rock_Ice_Permafrost"
    },
    {
      "x": -22,
      "y": 42,
      "z": 3,
      "name": "Rock_Ice_Permafrost"
    },
    {
      "x": -22,
      "y": 43,
      "z": 3,
      "name": "Soil_Snow"
    },
    {
      "x": -22,
      "y": 27,
      "z": 4,
      "name": "Rock_Ice"
    },
    {
      "x": -22,
      "y": 28,
      "z": 4,
      "name": "Rock_Ice"
    },
    {
      "x": -22,
      "y": 29,
      "z": 4,
      "name": "Rock_Ice"
    },
    {
      "x": -22,
      "y": 30,
      "z": 4,
      "name": "Rock_Ice"
    },
    {
      "x": -22,
      "y": 31,
      "z": 4,
      "name": "Rock_Ice"
    },
    {
      "x": -22,
      "y": 32,
      "z": 4,
      "name": "Rock_Ice"
    },
    {
      "x": -22,
      "y": 33,
      "z": 4,
      "name": "Rock_Ice"
    },
    {
      "x": -22,
      "y": 34,
      "z": 4,
      "name": "Rock_Ice"
    },
    {
      "x": -22,
      "y": 35,
      "z": 4,
      "name": "Rock_Ice"
    },
    {
      "x": -22,
      "y": 36,
      "z": 4,
      "name": "Rock_Ice"
    },
    {
      "x": -22,
      "y": 37,
      "z": 4,
      "name": "Rock_Ice_Permafrost"
    },
    {
      "x": -22,
      "y": 38,
      "z": 4,
      "name": "Soil_Snow"
    },
    {
      "x": -22,
      "y": 28,
      "z": 5,
      "name": "Rock_Ice"
    },
    {
      "x": -22,
      "y": 29,
      "z": 5,
      "name": "Rock_Ice"
    },
    {
      "x": -22,
      "y": 30,
      "z": 5,
      "name": "Rock_Ice"
    },
    {
      "x": -22,
      "y": 31,
      "z": 5,
      "name": "Rock_Ice"
    },
    {
      "x": -22,
      "y": 32,
      "z": 5,
      "name": "Rock_Ice"
    },
    {
      "x": -22,
      "y": 33,
      "z": 5,
      "name": "Rock_Ice"
    },
    {
      "x": -22,
      "y": 34,
      "z": 5,
      "name": "Rock_Ice"
    },
    {
      "x": -22,
      "y": 35,
      "z": 5,
      "name": "Rock_Ice_Permafrost"
    },
    {
      "x": -22,
      "y": 36,
      "z": 5,
      "name": "Rock_Ice_Permafrost"
    },
    {
      "x": -22,
      "y": 37,
      "z": 5,
      "name": "Soil_Snow"
    },
    {
      "x": -22,
      "y": 28,
      "z": 6,
      "name": "Rock_Ice"
    },
    {
      "x": -22,
      "y": 29,
      "z": 6,
      "name": "Rock_Ice"
    },
    {
      "x": -22,
      "y": 30,
      "z": 6,
      "name": "Rock_Ice_Permafrost"
    },
    {
      "x": -22,
      "y": 31,
      "z": 6,
      "name": "Rock_Ice_Permafrost"
    },
    {
      "x": -22,
      "y": 32,
      "z": 6,
      "name": "Rock_Ice_Permafrost"
    },
    {
      "x": -22,
      "y": 33,
      "z": 6,
      "name": "Rock_Ice_Permafrost"
    },
    {
      "x": -22,
      "y": 34,
      "z": 6,
      "name": "Rock_Ice_Permafrost"
    },
    {
      "x": -22,
      "y": 35,
      "z": 6,
      "name": "Rock_Ice_Permafrost"
    },
    {
      "x": -22,
      "y": 36,
      "z": 6,
      "name": "Rock_Ice"
    },
    {
      "x": -22,
      "y": 37,
      "z": 6,
      "name": "Soil_Snow"
    },
    {
      "x": -22,
      "y": 28,
      "z": 7,
      "name": "Rock_Ice"
    },
    {
      "x": -22,
      "y": 29,
      "z": 7,
      "name": "Rock_Ice_Permafrost"
    },
    {
      "x": -22,
      "y": 30,
      "z": 7,
      "name": "Rock_Ice_Permafrost"
    },
    {
      "x": -22,
      "y": 31,
      "z": 7,
      "name": "Rock_Ice_Permafrost"
    },
    {
      "x": -22,
      "y": 32,
      "z": 7,
      "name": "Rock_Ice_Permafrost"
    },
    {
      "x": -22,
      "y": 33,
      "z": 7,
      "name": "Rock_Ice_Permafrost"
    },
    {
      "x": -22,
      "y": 34,
      "z": 7,
      "name": "Rock_Ice_Permafrost"
    },
    {
      "x": -22,
      "y": 35,
      "z": 7,
      "name": "Rock_Ice"
    },
    {
      "x": -22,
      "y": 36,
      "z": 7,
      "name": "Soil_Snow"
    },
    {
      "x": -22,
      "y": 28,
      "z": 8,
      "name": "Rock_Ice_Permafrost"
    },
    {
      "x": -22,
      "y": 29,
      "z": 8,
      "name": "Rock_Ice_Permafrost"
    },
    {
      "x": -22,
      "y": 30,
      "z": 8,
      "name": "Rock_Ice_Permafrost"
    },
    {
      "x": -22,
      "y": 31,
      "z": 8,
      "name": "Rock_Ice_Permafrost"
    },
    {
      "x": -22,
      "y": 32,
      "z": 8,
      "name": "Rock_Ice"
    },
    {
      "x": -22,
      "y": 33,
      "z": 8,
      "name": "Rock_Ice"
    },
    {
      "x": -22,
      "y": 34,
      "z": 8,
      "name": "Rock_Ice"
    },
    {
      "x": -22,
      "y": 35,
      "z": 8,
      "name": "Rock_Ice"
    },
    {
      "x": -22,
      "y": 36,
      "z": 8,
      "name": "Soil_Snow"
    },
    {
      "x": -22,
      "y": 28,
      "z": 9,
      "name": "Rock_Ice_Permafrost"
    },
    {
      "x": -22,
      "y": 29,
      "z": 9,
      "name": "Rock_Ice_Permafrost"
    },
    {
      "x": -22,
      "y": 30,
      "z": 9,
      "name": "Rock_Ice_Permafrost"
    },
    {
      "x": -22,
      "y": 31,
      "z": 9,
      "name": "Rock_Ice"
    },
    {
      "x": -22,
      "y": 32,
      "z": 9,
      "name": "Rock_Ice"
    },
    {
      "x": -22,
      "y": 33,
      "z": 9,
      "name": "Rock_Ice"
    },
    {
      "x": -22,
      "y": 34,
      "z": 9,
      "name": "Rock_Ice"
    },
    {
      "x": -22,
      "y": 35,
      "z": 9,
      "name": "Soil_Snow"
    },
    {
      "x": -22,
      "y": 28,
      "z": 10,
      "name": "Rock_Ice_Permafrost"
    },
    {
      "x": -22,
      "y": 29,
      "z": 10,
      "name": "Rock_Ice_Permafrost"
    },
    {
      "x": -22,
      "y": 30,
      "z": 10,
      "name": "Rock_Ice_Permafrost"
    },
    {
      "x": -22,
      "y": 31,
      "z": 10,
      "name": "Rock_Ice"
    },
    {
      "x": -22,
      "y": 32,
      "z": 10,
      "name": "Rock_Ice"
    },
    {
      "x": -22,
      "y": 33,
      "z": 10,
      "name": "Rock_Ice"
    },
    {
      "x": -22,
      "y": 34,
      "z": 10,
      "name": "Rock_Ice"
    },
    {
      "x": -22,
      "y": 35,
      "z": 10,
      "name": "Soil_Snow"
    },
    {
      "x": -22,
      "y": 25,
      "z": 11,
      "name": "Rock_Ice_Permafrost"
    },
    {
      "x": -22,
      "y": 26,
      "z": 11,
      "name": "Rock_Ice_Permafrost"
    },
    {
      "x": -22,
      "y": 27,
      "z": 11,
      "name": "Rock_Ice_Permafrost"
    },
    {
      "x": -22,
      "y": 28,
      "z": 11,
      "name": "Rock_Ice"
    },
    {
      "x": -22,
      "y": 29,
      "z": 11,
      "name": "Rock_Ice_Permafrost"
    },
    {
      "x": -22,
      "y": 30,
      "z": 11,
      "name": "Rock_Ice"
    },
    {
      "x": -22,
      "y": 31,
      "z": 11,
      "name": "Rock_Ice"
    },
    {
      "x": -22,
      "y": 32,
      "z": 11,
      "name": "Rock_Ice"
    },
    {
      "x": -22,
      "y": 33,
      "z": 11,
      "name": "Rock_Ice"
    },
    {
      "x": -22,
      "y": 34,
      "z": 11,
      "name": "Soil_Snow"
    },
    {
      "x": -22,
      "y": 22,
      "z": 12,
      "name": "Rock_Ice_Permafrost"
    },
    {
      "x": -22,
      "y": 23,
      "z": 12,
      "name": "Rock_Ice_Permafrost"
    },
    {
      "x": -22,
      "y": 24,
      "z": 12,
      "name": "Rock_Ice_Permafrost"
    },
    {
      "x": -22,
      "y": 25,
      "z": 12,
      "name": "Rock_Ice_Permafrost"
    },
    {
      "x": -22,
      "y": 26,
      "z": 12,
      "name": "Rock_Ice_Permafrost"
    },
    {
      "x": -22,
      "y": 27,
      "z": 12,
      "name": "Rock_Ice_Permafrost"
    },
    {
      "x": -22,
      "y": 28,
      "z": 12,
      "name": "Rock_Ice_Permafrost"
    },
    {
      "x": -22,
      "y": 29,
      "z": 12,
      "name": "Rock_Ice"
    },
    {
      "x": -22,
      "y": 30,
      "z": 12,
      "name": "Rock_Ice"
    },
    {
      "x": -22,
      "y": 31,
      "z": 12,
      "name": "Rock_Ice"
    },
    {
      "x": -22,
      "y": 32,
      "z": 12,
      "name": "Rock_Ice"
    },
    {
      "x": -22,
      "y": 33,
      "z": 12,
      "name": "Rock_Ice"
    },
    {
      "x": -22,
      "y": 34,
      "z": 12,
      "name": "Soil_Snow"
    },
    {
      "x": -22,
      "y": 20,
      "z": 13,
      "name": "Rock_Ice_Permafrost"
    },
    {
      "x": -22,
      "y": 21,
      "z": 13,
      "name": "Rock_Ice_Permafrost"
    },
    {
      "x": -22,
      "y": 22,
      "z": 13,
      "name": "Rock_Ice_Permafrost"
    },
    {
      "x": -22,
      "y": 23,
      "z": 13,
      "name": "Rock_Ice_Permafrost"
    },
    {
      "x": -22,
      "y": 24,
      "z": 13,
      "name": "Rock_Ice_Permafrost"
    },
    {
      "x": -22,
      "y": 25,
      "z": 13,
      "name": "Rock_Ice_Permafrost"
    },
    {
      "x": -22,
      "y": 26,
      "z": 13,
      "name": "Rock_Ice_Permafrost"
    },
    {
      "x": -22,
      "y": 27,
      "z": 13,
      "name": "Rock_Ice_Permafrost"
    },
    {
      "x": -22,
      "y": 28,
      "z": 13,
      "name": "Rock_Ice_Permafrost"
    },
    {
      "x": -22,
      "y": 29,
      "z": 13,
      "name": "Rock_Ice"
    },
    {
      "x": -22,
      "y": 30,
      "z": 13,
      "name": "Rock_Ice"
    },
    {
      "x": -22,
      "y": 31,
      "z": 13,
      "name": "Rock_Ice"
    },
    {
      "x": -22,
      "y": 32,
      "z": 13,
      "name": "Rock_Ice"
    },
    {
      "x": -22,
      "y": 33,
      "z": 13,
      "name": "Rock_Ice"
    },
    {
      "x": -22,
      "y": 34,
      "z": 13,
      "name": "Soil_Snow"
    },
    {
      "x": -22,
      "y": 19,
      "z": 14,
      "name": "Rock_Ice_Permafrost"
    },
    {
      "x": -22,
      "y": 20,
      "z": 14,
      "name": "Rock_Ice_Permafrost"
    },
    {
      "x": -22,
      "y": 21,
      "z": 14,
      "name": "Rock_Ice_Permafrost"
    },
    {
      "x": -22,
      "y": 22,
      "z": 14,
      "name": "Rock_Ice_Permafrost"
    },
    {
      "x": -22,
      "y": 23,
      "z": 14,
      "name": "Rock_Ice_Permafrost"
    },
    {
      "x": -22,
      "y": 24,
      "z": 14,
      "name": "Rock_Ice_Permafrost"
    },
    {
      "x": -22,
      "y": 25,
      "z": 14,
      "name": "Rock_Ice_Permafrost"
    },
    {
      "x": -22,
      "y": 26,
      "z": 14,
      "name": "Rock_Ice_Permafrost"
    },
    {
      "x": -22,
      "y": 27,
      "z": 14,
      "name": "Rock_Ice_Permafrost"
    },
    {
      "x": -22,
      "y": 28,
      "z": 14,
      "name": "Rock_Ice"
    },
    {
      "x": -22,
      "y": 29,
      "z": 14,
      "name": "Rock_Ice"
    },
    {
      "x": -22,
      "y": 30,
      "z": 14,
      "name": "Rock_Ice"
    },
    {
      "x": -22,
      "y": 31,
      "z": 14,
      "name": "Rock_Ice"
    },
    {
      "x": -22,
      "y": 32,
      "z": 14,
      "name": "Rock_Ice"
    },
    {
      "x": -22,
      "y": 33,
      "z": 14,
      "name": "Soil_Snow"
    },
    {
      "x": -22,
      "y": 17,
      "z": 15,
      "name": "Rock_Ice_Permafrost"
    },
    {
      "x": -22,
      "y": 18,
      "z": 15,
      "name": "Rock_Ice_Permafrost"
    },
    {
      "x": -22,
      "y": 19,
      "z": 15,
      "name": "Rock_Ice_Permafrost"
    },
    {
      "x": -22,
      "y": 20,
      "z": 15,
      "name": "Rock_Ice_Permafrost"
    },
    {
      "x": -22,
      "y": 21,
      "z": 15,
      "name": "Rock_Ice_Permafrost"
    },
    {
      "x": -22,
      "y": 22,
      "z": 15,
      "name": "Rock_Ice_Permafrost"
    },
    {
      "x": -22,
      "y": 23,
      "z": 15,
      "name": "Rock_Ice_Permafrost"
    },
    {
      "x": -22,
      "y": 24,
      "z": 15,
      "name": "Rock_Ice_Permafrost"
    },
    {
      "x": -22,
      "y": 25,
      "z": 15,
      "name": "Rock_Ice_Permafrost"
    },
    {
      "x": -22,
      "y": 26,
      "z": 15,
      "name": "Rock_Ice_Permafrost"
    },
    {
      "x": -22,
      "y": 27,
      "z": 15,
      "name": "Rock_Ice_Permafrost"
    },
    {
      "x": -22,
      "y": 28,
      "z": 15,
      "name": "Rock_Ice"
    },
    {
      "x": -22,
      "y": 29,
      "z": 15,
      "name": "Rock_Ice"
    },
    {
      "x": -22,
      "y": 30,
      "z": 15,
      "name": "Rock_Ice"
    },
    {
      "x": -22,
      "y": 31,
      "z": 15,
      "name": "Rock_Ice"
    },
    {
      "x": -22,
      "y": 32,
      "z": 15,
      "name": "Rock_Ice"
    },
    {
      "x": -22,
      "y": 33,
      "z": 15,
      "name": "Soil_Snow"
    },
    {
      "x": -22,
      "y": 16,
      "z": 16,
      "name": "Rock_Ice_Permafrost"
    },
    {
      "x": -22,
      "y": 17,
      "z": 16,
      "name": "Rock_Ice_Permafrost"
    },
    {
      "x": -22,
      "y": 18,
      "z": 16,
      "name": "Rock_Ice_Permafrost"
    },
    {
      "x": -22,
      "y": 19,
      "z": 16,
      "name": "Rock_Ice_Permafrost"
    },
    {
      "x": -22,
      "y": 20,
      "z": 16,
      "name": "Rock_Ice_Permafrost"
    },
    {
      "x": -22,
      "y": 21,
      "z": 16,
      "name": "Rock_Ice_Permafrost"
    },
    {
      "x": -22,
      "y": 22,
      "z": 16,
      "name": "Rock_Ice_Permafrost"
    },
    {
      "x": -22,
      "y": 23,
      "z": 16,
      "name": "Rock_Ice_Permafrost"
    },
    {
      "x": -22,
      "y": 24,
      "z": 16,
      "name": "Rock_Ice_Permafrost"
    },
    {
      "x": -22,
      "y": 25,
      "z": 16,
      "name": "Rock_Ice_Permafrost"
    },
    {
      "x": -22,
      "y": 26,
      "z": 16,
      "name": "Rock_Ice_Permafrost"
    },
    {
      "x": -22,
      "y": 27,
      "z": 16,
      "name": "Rock_Ice"
    },
    {
      "x": -22,
      "y": 28,
      "z": 16,
      "name": "Rock_Ice"
    },
    {
      "x": -22,
      "y": 29,
      "z": 16,
      "name": "Rock_Ice"
    },
    {
      "x": -22,
      "y": 30,
      "z": 16,
      "name": "Rock_Ice"
    },
    {
      "x": -22,
      "y": 31,
      "z": 16,
      "name": "Rock_Ice"
    },
    {
      "x": -22,
      "y": 32,
      "z": 16,
      "name": "Rock_Ice"
    },
    {
      "x": -22,
      "y": 33,
      "z": 16,
      "name": "Soil_Snow"
    },
    {
      "x": -22,
      "y": 16,
      "z": 17,
      "name": "Rock_Ice_Permafrost"
    },
    {
      "x": -22,
      "y": 17,
      "z": 17,
      "name": "Rock_Ice_Permafrost"
    },
    {
      "x": -22,
      "y": 18,
      "z": 17,
      "name": "Rock_Ice_Permafrost"
    },
    {
      "x": -22,
      "y": 19,
      "z": 17,
      "name": "Rock_Ice_Permafrost"
    },
    {
      "x": -22,
      "y": 20,
      "z": 17,
      "name": "Rock_Ice_Permafrost"
    },
    {
      "x": -22,
      "y": 21,
      "z": 17,
      "name": "Rock_Ice_Permafrost"
    },
    {
      "x": -22,
      "y": 22,
      "z": 17,
      "name": "Rock_Ice_Permafrost"
    },
    {
      "x": -22,
      "y": 23,
      "z": 17,
      "name": "Rock_Ice_Permafrost"
    },
    {
      "x": -22,
      "y": 24,
      "z": 17,
      "name": "Rock_Ice_Permafrost"
    },
    {
      "x": -22,
      "y": 25,
      "z": 17,
      "name": "Rock_Ice_Permafrost"
    },
    {
      "x": -22,
      "y": 26,
      "z": 17,
      "name": "Rock_Ice_Permafrost"
    },
    {
      "x": -22,
      "y": 27,
      "z": 17,
      "name": "Rock_Ice"
    },
    {
      "x": -22,
      "y": 28,
      "z": 17,
      "name": "Rock_Ice"
    },
    {
      "x": -22,
      "y": 29,
      "z": 17,
      "name": "Rock_Ice"
    },
    {
      "x": -22,
      "y": 30,
      "z": 17,
      "name": "Rock_Ice"
    },
    {
      "x": -22,
      "y": 31,
      "z": 17,
      "name": "Rock_Ice"
    },
    {
      "x": -22,
      "y": 32,
      "z": 17,
      "name": "Soil_Snow"
    },
    {
      "x": -22,
      "y": 16,
      "z": 18,
      "name": "Rock_Ice_Permafrost"
    },
    {
      "x": -22,
      "y": 17,
      "z": 18,
      "name": "Rock_Ice_Permafrost"
    },
    {
      "x": -22,
      "y": 18,
      "z": 18,
      "name": "Rock_Ice_Permafrost"
    },
    {
      "x": -22,
      "y": 19,
      "z": 18,
      "name": "Rock_Ice_Permafrost"
    },
    {
      "x": -22,
      "y": 20,
      "z": 18,
      "name": "Rock_Ice_Permafrost"
    },
    {
      "x": -22,
      "y": 21,
      "z": 18,
      "name": "Rock_Ice_Permafrost"
    },
    {
      "x": -22,
      "y": 22,
      "z": 18,
      "name": "Rock_Ice_Permafrost"
    },
    {
      "x": -22,
      "y": 23,
      "z": 18,
      "name": "Rock_Ice_Permafrost"
    },
    {
      "x": -22,
      "y": 24,
      "z": 18,
      "name": "Rock_Ice_Permafrost"
    },
    {
      "x": -22,
      "y": 25,
      "z": 18,
      "name": "Rock_Ice_Permafrost"
    },
    {
      "x": -22,
      "y": 26,
      "z": 18,
      "name": "Rock_Ice"
    },
    {
      "x": -22,
      "y": 27,
      "z": 18,
      "name": "Rock_Ice"
    },
    {
      "x": -22,
      "y": 28,
      "z": 18,
      "name": "Rock_Ice"
    },
    {
      "x": -22,
      "y": 29,
      "z": 18,
      "name": "Rock_Ice"
    },
    {
      "x": -22,
      "y": 30,
      "z": 18,
      "name": "Soil_Snow"
    },
    {
      "x": -22,
      "y": 17,
      "z": 19,
      "name": "Rock_Ice_Permafrost"
    },
    {
      "x": -22,
      "y": 18,
      "z": 19,
      "name": "Rock_Ice_Permafrost"
    },
    {
      "x": -22,
      "y": 19,
      "z": 19,
      "name": "Rock_Ice_Permafrost"
    },
    {
      "x": -22,
      "y": 20,
      "z": 19,
      "name": "Rock_Ice_Permafrost"
    },
    {
      "x": -22,
      "y": 21,
      "z": 19,
      "name": "Rock_Ice_Permafrost"
    },
    {
      "x": -22,
      "y": 22,
      "z": 19,
      "name": "Rock_Ice_Permafrost"
    },
    {
      "x": -22,
      "y": 23,
      "z": 19,
      "name": "Rock_Ice_Permafrost"
    },
    {
      "x": -22,
      "y": 24,
      "z": 19,
      "name": "Rock_Ice_Permafrost"
    },
    {
      "x": -22,
      "y": 25,
      "z": 19,
      "name": "Rock_Ice_Permafrost"
    },
    {
      "x": -22,
      "y": 26,
      "z": 19,
      "name": "Rock_Ice"
    },
    {
      "x": -22,
      "y": 27,
      "z": 19,
      "name": "Rock_Ice"
    },
    {
      "x": -22,
      "y": 28,
      "z": 19,
      "name": "Rock_Ice"
    },
    {
      "x": -22,
      "y": 29,
      "z": 19,
      "name": "Soil_Snow"
    },
    {
      "x": -22,
      "y": 18,
      "z": 20,
      "name": "Rock_Ice_Permafrost"
    },
    {
      "x": -22,
      "y": 19,
      "z": 20,
      "name": "Rock_Ice_Permafrost"
    },
    {
      "x": -22,
      "y": 20,
      "z": 20,
      "name": "Rock_Ice_Permafrost"
    },
    {
      "x": -22,
      "y": 21,
      "z": 20,
      "name": "Rock_Ice_Permafrost"
    },
    {
      "x": -22,
      "y": 22,
      "z": 20,
      "name": "Rock_Ice_Permafrost"
    },
    {
      "x": -22,
      "y": 23,
      "z": 20,
      "name": "Rock_Ice_Permafrost"
    },
    {
      "x": -22,
      "y": 24,
      "z": 20,
      "name": "Rock_Ice_Permafrost"
    },
    {
      "x": -22,
      "y": 25,
      "z": 20,
      "name": "Rock_Ice"
    },
    {
      "x": -22,
      "y": 26,
      "z": 20,
      "name": "Rock_Ice"
    },
    {
      "x": -22,
      "y": 27,
      "z": 20,
      "name": "Rock_Ice"
    },
    {
      "x": -22,
      "y": 28,
      "z": 20,
      "name": "Rock_Ice"
    },
    {
      "x": -22,
      "y": 29,
      "z": 20,
      "name": "Rock_Ice"
    },
    {
      "x": -22,
      "y": 30,
      "z": 20,
      "name": "Soil_Snow"
    },
    {
      "x": -22,
      "y": 20,
      "z": 21,
      "name": "Rock_Ice_Permafrost"
    },
    {
      "x": -22,
      "y": 21,
      "z": 21,
      "name": "Rock_Ice_Permafrost"
    },
    {
      "x": -22,
      "y": 22,
      "z": 21,
      "name": "Rock_Ice_Permafrost"
    },
    {
      "x": -22,
      "y": 23,
      "z": 21,
      "name": "Rock_Ice_Permafrost"
    },
    {
      "x": -22,
      "y": 24,
      "z": 21,
      "name": "Rock_Ice"
    },
    {
      "x": -22,
      "y": 25,
      "z": 21,
      "name": "Rock_Ice"
    },
    {
      "x": -22,
      "y": 26,
      "z": 21,
      "name": "Rock_Ice"
    },
    {
      "x": -22,
      "y": 27,
      "z": 21,
      "name": "Rock_Ice"
    },
    {
      "x": -22,
      "y": 28,
      "z": 21,
      "name": "Rock_Ice"
    },
    {
      "x": -22,
      "y": 29,
      "z": 21,
      "name": "Rock_Ice"
    },
    {
      "x": -22,
      "y": 30,
      "z": 21,
      "name": "Rock_Ice"
    },
    {
      "x": -22,
      "y": 31,
      "z": 21,
      "name": "Soil_Snow"
    },
    {
      "x": -22,
      "y": 20,
      "z": 22,
      "name": "Rock_Ice_Permafrost"
    },
    {
      "x": -22,
      "y": 21,
      "z": 22,
      "name": "Rock_Ice_Permafrost"
    },
    {
      "x": -22,
      "y": 22,
      "z": 22,
      "name": "Rock_Ice_Permafrost"
    },
    {
      "x": -22,
      "y": 23,
      "z": 22,
      "name": "Rock_Ice"
    },
    {
      "x": -22,
      "y": 24,
      "z": 22,
      "name": "Rock_Ice"
    },
    {
      "x": -22,
      "y": 25,
      "z": 22,
      "name": "Rock_Ice"
    },
    {
      "x": -22,
      "y": 26,
      "z": 22,
      "name": "Rock_Ice"
    },
    {
      "x": -22,
      "y": 27,
      "z": 22,
      "name": "Rock_Ice"
    },
    {
      "x": -22,
      "y": 28,
      "z": 22,
      "name": "Rock_Ice"
    },
    {
      "x": -22,
      "y": 29,
      "z": 22,
      "name": "Rock_Ice"
    },
    {
      "x": -22,
      "y": 30,
      "z": 22,
      "name": "Rock_Ice"
    },
    {
      "x": -22,
      "y": 31,
      "z": 22,
      "name": "Soil_Snow"
    },
    {
      "x": -22,
      "y": 19,
      "z": 23,
      "name": "Rock_Ice_Permafrost"
    },
    {
      "x": -22,
      "y": 20,
      "z": 23,
      "name": "Rock_Ice_Permafrost"
    },
    {
      "x": -22,
      "y": 21,
      "z": 23,
      "name": "Rock_Ice_Permafrost"
    },
    {
      "x": -22,
      "y": 22,
      "z": 23,
      "name": "Rock_Ice_Permafrost"
    },
    {
      "x": -22,
      "y": 23,
      "z": 23,
      "name": "Rock_Ice"
    },
    {
      "x": -22,
      "y": 24,
      "z": 23,
      "name": "Rock_Ice"
    },
    {
      "x": -22,
      "y": 25,
      "z": 23,
      "name": "Rock_Ice"
    },
    {
      "x": -22,
      "y": 26,
      "z": 23,
      "name": "Rock_Ice"
    },
    {
      "x": -22,
      "y": 27,
      "z": 23,
      "name": "Rock_Ice"
    },
    {
      "x": -22,
      "y": 28,
      "z": 23,
      "name": "Rock_Ice"
    },
    {
      "x": -22,
      "y": 29,
      "z": 23,
      "name": "Soil_Snow"
    },
    {
      "x": -22,
      "y": 20,
      "z": 24,
      "name": "Rock_Ice_Permafrost"
    },
    {
      "x": -22,
      "y": 21,
      "z": 24,
      "name": "Rock_Ice_Permafrost"
    },
    {
      "x": -22,
      "y": 22,
      "z": 24,
      "name": "Rock_Ice"
    },
    {
      "x": -22,
      "y": 23,
      "z": 24,
      "name": "Rock_Ice"
    },
    {
      "x": -22,
      "y": 24,
      "z": 24,
      "name": "Rock_Ice"
    },
    {
      "x": -22,
      "y": 25,
      "z": 24,
      "name": "Rock_Ice"
    },
    {
      "x": -22,
      "y": 27,
      "z": 24,
      "name": "Rock_Ice"
    },
    {
      "x": -21,
      "y": 20,
      "z": -15,
      "name": "Rock_Ice"
    },
    {
      "x": -21,
      "y": 24,
      "z": -15,
      "name": "Rock_Ice_Permafrost"
    },
    {
      "x": -21,
      "y": 25,
      "z": -15,
      "name": "Rock_Ice_Permafrost"
    },
    {
      "x": -21,
      "y": 26,
      "z": -15,
      "name": "Rock_Ice_Permafrost"
    },
    {
      "x": -21,
      "y": 27,
      "z": -15,
      "name": "Rock_Ice_Permafrost"
    },
    {
      "x": -21,
      "y": 28,
      "z": -15,
      "name": "Rock_Ice_Permafrost"
    },
    {
      "x": -21,
      "y": 29,
      "z": -15,
      "name": "Rock_Ice"
    },
    {
      "x": -21,
      "y": 30,
      "z": -15,
      "name": "Soil_Snow"
    },
    {
      "x": -21,
      "y": 19,
      "z": -14,
      "name": "Rock_Ice"
    },
    {
      "x": -21,
      "y": 20,
      "z": -14,
      "name": "Rock_Ice"
    },
    {
      "x": -21,
      "y": 21,
      "z": -14,
      "name": "Rock_Ice_Permafrost"
    },
    {
      "x": -21,
      "y": 22,
      "z": -14,
      "name": "Rock_Ice"
    },
    {
      "x": -21,
      "y": 23,
      "z": -14,
      "name": "Rock_Ice_Permafrost"
    },
    {
      "x": -21,
      "y": 24,
      "z": -14,
      "name": "Rock_Ice_Permafrost"
    },
    {
      "x": -21,
      "y": 25,
      "z": -14,
      "name": "Rock_Ice_Permafrost"
    },
    {
      "x": -21,
      "y": 26,
      "z": -14,
      "name": "Rock_Ice_Permafrost"
    },
    {
      "x": -21,
      "y": 27,
      "z": -14,
      "name": "Rock_Ice_Permafrost"
    },
    {
      "x": -21,
      "y": 28,
      "z": -14,
      "name": "Rock_Ice_Permafrost"
    },
    {
      "x": -21,
      "y": 29,
      "z": -14,
      "name": "Rock_Ice_Permafrost"
    },
    {
      "x": -21,
      "y": 30,
      "z": -14,
      "name": "Rock_Ice_Permafrost"
    },
    {
      "x": -21,
      "y": 31,
      "z": -14,
      "name": "Rock_Ice"
    },
    {
      "x": -21,
      "y": 32,
      "z": -14,
      "name": "Soil_Snow"
    },
    {
      "x": -21,
      "y": 18,
      "z": -13,
      "name": "Rock_Ice"
    },
    {
      "x": -21,
      "y": 19,
      "z": -13,
      "name": "Rock_Ice"
    },
    {
      "x": -21,
      "y": 20,
      "z": -13,
      "name": "Rock_Ice"
    },
    {
      "x": -21,
      "y": 21,
      "z": -13,
      "name": "Rock_Ice_Permafrost"
    },
    {
      "x": -21,
      "y": 22,
      "z": -13,
      "name": "Rock_Ice_Permafrost"
    },
    {
      "x": -21,
      "y": 23,
      "z": -13,
      "name": "Rock_Ice"
    },
    {
      "x": -21,
      "y": 24,
      "z": -13,
      "name": "Rock_Ice_Permafrost"
    },
    {
      "x": -21,
      "y": 25,
      "z": -13,
      "name": "Rock_Ice_Permafrost"
    },
    {
      "x": -21,
      "y": 26,
      "z": -13,
      "name": "Rock_Ice_Permafrost"
    },
    {
      "x": -21,
      "y": 27,
      "z": -13,
      "name": "Rock_Ice_Permafrost"
    },
    {
      "x": -21,
      "y": 28,
      "z": -13,
      "name": "Rock_Ice_Permafrost"
    },
    {
      "x": -21,
      "y": 29,
      "z": -13,
      "name": "Rock_Ice_Permafrost"
    },
    {
      "x": -21,
      "y": 30,
      "z": -13,
      "name": "Rock_Ice"
    },
    {
      "x": -21,
      "y": 31,
      "z": -13,
      "name": "Rock_Ice"
    },
    {
      "x": -21,
      "y": 32,
      "z": -13,
      "name": "Rock_Ice"
    },
    {
      "x": -21,
      "y": 33,
      "z": -13,
      "name": "Soil_Snow"
    },
    {
      "x": -21,
      "y": 17,
      "z": -12,
      "name": "Rock_Ice"
    },
    {
      "x": -21,
      "y": 18,
      "z": -12,
      "name": "Rock_Ice_Permafrost"
    },
    {
      "x": -21,
      "y": 19,
      "z": -12,
      "name": "Rock_Ice"
    },
    {
      "x": -21,
      "y": 20,
      "z": -12,
      "name": "Rock_Ice_Permafrost"
    },
    {
      "x": -21,
      "y": 21,
      "z": -12,
      "name": "Rock_Ice_Permafrost"
    },
    {
      "x": -21,
      "y": 22,
      "z": -12,
      "name": "Rock_Ice_Permafrost"
    },
    {
      "x": -21,
      "y": 23,
      "z": -12,
      "name": "Rock_Ice_Permafrost"
    },
    {
      "x": -21,
      "y": 24,
      "z": -12,
      "name": "Rock_Ice_Permafrost"
    },
    {
      "x": -21,
      "y": 25,
      "z": -12,
      "name": "Rock_Ice_Permafrost"
    },
    {
      "x": -21,
      "y": 26,
      "z": -12,
      "name": "Rock_Ice_Permafrost"
    },
    {
      "x": -21,
      "y": 27,
      "z": -12,
      "name": "Rock_Ice_Permafrost"
    },
    {
      "x": -21,
      "y": 28,
      "z": -12,
      "name": "Rock_Ice_Permafrost"
    },
    {
      "x": -21,
      "y": 29,
      "z": -12,
      "name": "Rock_Ice_Permafrost"
    },
    {
      "x": -21,
      "y": 30,
      "z": -12,
      "name": "Rock_Ice"
    },
    {
      "x": -21,
      "y": 31,
      "z": -12,
      "name": "Rock_Ice"
    },
    {
      "x": -21,
      "y": 32,
      "z": -12,
      "name": "Rock_Ice"
    },
    {
      "x": -21,
      "y": 33,
      "z": -12,
      "name": "Rock_Ice"
    },
    {
      "x": -21,
      "y": 34,
      "z": -12,
      "name": "Rock_Ice"
    },
    {
      "x": -21,
      "y": 35,
      "z": -12,
      "name": "Soil_Snow"
    },
    {
      "x": -21,
      "y": 16,
      "z": -11,
      "name": "Rock_Ice_Permafrost"
    },
    {
      "x": -21,
      "y": 17,
      "z": -11,
      "name": "Rock_Ice_Permafrost"
    },
    {
      "x": -21,
      "y": 18,
      "z": -11,
      "name": "Rock_Ice_Permafrost"
    },
    {
      "x": -21,
      "y": 19,
      "z": -11,
      "name": "Rock_Ice_Permafrost"
    },
    {
      "x": -21,
      "y": 20,
      "z": -11,
      "name": "Rock_Ice_Permafrost"
    },
    {
      "x": -21,
      "y": 21,
      "z": -11,
      "name": "Rock_Ice_Permafrost"
    },
    {
      "x": -21,
      "y": 22,
      "z": -11,
      "name": "Rock_Ice_Permafrost"
    },
    {
      "x": -21,
      "y": 23,
      "z": -11,
      "name": "Rock_Ice_Permafrost"
    },
    {
      "x": -21,
      "y": 24,
      "z": -11,
      "name": "Rock_Ice_Permafrost"
    },
    {
      "x": -21,
      "y": 25,
      "z": -11,
      "name": "Rock_Ice_Permafrost"
    },
    {
      "x": -21,
      "y": 26,
      "z": -11,
      "name": "Rock_Ice_Permafrost"
    },
    {
      "x": -21,
      "y": 27,
      "z": -11,
      "name": "Rock_Ice_Permafrost"
    },
    {
      "x": -21,
      "y": 28,
      "z": -11,
      "name": "Rock_Ice_Permafrost"
    },
    {
      "x": -21,
      "y": 29,
      "z": -11,
      "name": "Rock_Ice_Permafrost"
    },
    {
      "x": -21,
      "y": 30,
      "z": -11,
      "name": "Rock_Ice_Permafrost"
    },
    {
      "x": -21,
      "y": 31,
      "z": -11,
      "name": "Rock_Ice_Permafrost"
    },
    {
      "x": -21,
      "y": 32,
      "z": -11,
      "name": "Rock_Ice_Permafrost"
    },
    {
      "x": -21,
      "y": 33,
      "z": -11,
      "name": "Rock_Ice"
    },
    {
      "x": -21,
      "y": 34,
      "z": -11,
      "name": "Rock_Ice"
    },
    {
      "x": -21,
      "y": 35,
      "z": -11,
      "name": "Rock_Ice"
    },
    {
      "x": -21,
      "y": 36,
      "z": -11,
      "name": "Soil_Snow"
    },
    {
      "x": -21,
      "y": 14,
      "z": -10,
      "name": "Rock_Ice_Permafrost"
    },
    {
      "x": -21,
      "y": 15,
      "z": -10,
      "name": "Rock_Ice_Permafrost"
    },
    {
      "x": -21,
      "y": 16,
      "z": -10,
      "name": "Rock_Ice_Permafrost"
    },
    {
      "x": -21,
      "y": 17,
      "z": -10,
      "name": "Rock_Ice_Permafrost"
    },
    {
      "x": -21,
      "y": 18,
      "z": -10,
      "name": "Rock_Ice_Permafrost"
    },
    {
      "x": -21,
      "y": 19,
      "z": -10,
      "name": "Rock_Ice_Permafrost"
    },
    {
      "x": -21,
      "y": 20,
      "z": -10,
      "name": "Rock_Ice_Permafrost"
    },
    {
      "x": -21,
      "y": 21,
      "z": -10,
      "name": "Rock_Ice_Permafrost"
    },
    {
      "x": -21,
      "y": 22,
      "z": -10,
      "name": "Rock_Ice_Permafrost"
    },
    {
      "x": -21,
      "y": 23,
      "z": -10,
      "name": "Rock_Ice_Permafrost"
    },
    {
      "x": -21,
      "y": 24,
      "z": -10,
      "name": "Rock_Ice_Permafrost"
    },
    {
      "x": -21,
      "y": 25,
      "z": -10,
      "name": "Rock_Ice_Permafrost"
    },
    {
      "x": -21,
      "y": 26,
      "z": -10,
      "name": "Rock_Ice_Permafrost"
    },
    {
      "x": -21,
      "y": 27,
      "z": -10,
      "name": "Rock_Ice_Permafrost"
    },
    {
      "x": -21,
      "y": 28,
      "z": -10,
      "name": "Rock_Ice_Permafrost"
    },
    {
      "x": -21,
      "y": 29,
      "z": -10,
      "name": "Rock_Ice_Permafrost"
    },
    {
      "x": -21,
      "y": 30,
      "z": -10,
      "name": "Rock_Ice_Permafrost"
    },
    {
      "x": -21,
      "y": 31,
      "z": -10,
      "name": "Rock_Ice_Permafrost"
    },
    {
      "x": -21,
      "y": 32,
      "z": -10,
      "name": "Rock_Ice_Permafrost"
    },
    {
      "x": -21,
      "y": 33,
      "z": -10,
      "name": "Rock_Ice_Permafrost"
    },
    {
      "x": -21,
      "y": 34,
      "z": -10,
      "name": "Rock_Ice"
    },
    {
      "x": -21,
      "y": 35,
      "z": -10,
      "name": "Rock_Ice"
    },
    {
      "x": -21,
      "y": 36,
      "z": -10,
      "name": "Rock_Ice"
    },
    {
      "x": -21,
      "y": 37,
      "z": -10,
      "name": "Soil_Snow"
    },
    {
      "x": -21,
      "y": 13,
      "z": -9,
      "name": "Rock_Ice_Permafrost"
    },
    {
      "x": -21,
      "y": 14,
      "z": -9,
      "name": "Rock_Ice_Permafrost"
    },
    {
      "x": -21,
      "y": 15,
      "z": -9,
      "name": "Rock_Ice_Permafrost"
    },
    {
      "x": -21,
      "y": 16,
      "z": -9,
      "name": "Rock_Ice_Permafrost"
    },
    {
      "x": -21,
      "y": 17,
      "z": -9,
      "name": "Rock_Ice_Permafrost"
    },
    {
      "x": -21,
      "y": 18,
      "z": -9,
      "name": "Rock_Ice_Permafrost"
    },
    {
      "x": -21,
      "y": 19,
      "z": -9,
      "name": "Rock_Ice_Permafrost"
    },
    {
      "x": -21,
      "y": 20,
      "z": -9,
      "name": "Rock_Ice_Permafrost"
    },
    {
      "x": -21,
      "y": 21,
      "z": -9,
      "name": "Rock_Ice"
    },
    {
      "x": -21,
      "y": 22,
      "z": -9,
      "name": "Rock_Ice_Permafrost"
    },
    {
      "x": -21,
      "y": 23,
      "z": -9,
      "name": "Rock_Ice"
    },
    {
      "x": -21,
      "y": 24,
      "z": -9,
      "name": "Rock_Ice"
    },
    {
      "x": -21,
      "y": 25,
      "z": -9,
      "name": "Rock_Ice"
    },
    {
      "x": -21,
      "y": 26,
      "z": -9,
      "name": "Rock_Ice"
    },
    {
      "x": -21,
      "y": 27,
      "z": -9,
      "name": "Rock_Ice_Permafrost"
    },
    {
      "x": -21,
      "y": 28,
      "z": -9,
      "name": "Rock_Ice_Permafrost"
    },
    {
      "x": -21,
      "y": 29,
      "z": -9,
      "name": "Rock_Ice"
    },
    {
      "x": -21,
      "y": 30,
      "z": -9,
      "name": "Rock_Ice_Permafrost"
    },
    {
      "x": -21,
      "y": 31,
      "z": -9,
      "name": "Rock_Ice_Permafrost"
    },
    {
      "x": -21,
      "y": 32,
      "z": -9,
      "name": "Rock_Ice_Permafrost"
    },
    {
      "x": -21,
      "y": 33,
      "z": -9,
      "name": "Rock_Ice_Permafrost"
    },
    {
      "x": -21,
      "y": 34,
      "z": -9,
      "name": "Rock_Ice_Permafrost"
    },
    {
      "x": -21,
      "y": 35,
      "z": -9,
      "name": "Rock_Ice"
    },
    {
      "x": -21,
      "y": 36,
      "z": -9,
      "name": "Rock_Ice"
    },
    {
      "x": -21,
      "y": 37,
      "z": -9,
      "name": "Rock_Ice"
    },
    {
      "x": -21,
      "y": 38,
      "z": -9,
      "name": "Soil_Snow"
    },
    {
      "x": -21,
      "y": 13,
      "z": -8,
      "name": "Rock_Ice_Permafrost"
    },
    {
      "x": -21,
      "y": 14,
      "z": -8,
      "name": "Rock_Ice_Permafrost"
    },
    {
      "x": -21,
      "y": 15,
      "z": -8,
      "name": "Rock_Ice_Permafrost"
    },
    {
      "x": -21,
      "y": 16,
      "z": -8,
      "name": "Rock_Ice_Permafrost"
    },
    {
      "x": -21,
      "y": 17,
      "z": -8,
      "name": "Rock_Ice_Permafrost"
    },
    {
      "x": -21,
      "y": 18,
      "z": -8,
      "name": "Rock_Ice"
    },
    {
      "x": -21,
      "y": 19,
      "z": -8,
      "name": "Rock_Ice"
    },
    {
      "x": -21,
      "y": 20,
      "z": -8,
      "name": "Rock_Ice"
    },
    {
      "x": -21,
      "y": 21,
      "z": -8,
      "name": "Rock_Ice"
    },
    {
      "x": -21,
      "y": 22,
      "z": -8,
      "name": "Rock_Ice"
    },
    {
      "x": -21,
      "y": 23,
      "z": -8,
      "name": "Rock_Ice"
    },
    {
      "x": -21,
      "y": 24,
      "z": -8,
      "name": "Rock_Ice"
    },
    {
      "x": -21,
      "y": 25,
      "z": -8,
      "name": "Rock_Ice"
    },
    {
      "x": -21,
      "y": 26,
      "z": -8,
      "name": "Rock_Ice"
    },
    {
      "x": -21,
      "y": 27,
      "z": -8,
      "name": "Rock_Ice"
    },
    {
      "x": -21,
      "y": 28,
      "z": -8,
      "name": "Rock_Ice"
    },
    {
      "x": -21,
      "y": 29,
      "z": -8,
      "name": "Rock_Ice"
    },
    {
      "x": -21,
      "y": 30,
      "z": -8,
      "name": "Rock_Ice"
    },
    {
      "x": -21,
      "y": 31,
      "z": -8,
      "name": "Rock_Ice_Permafrost"
    },
    {
      "x": -21,
      "y": 32,
      "z": -8,
      "name": "Rock_Ice_Permafrost"
    },
    {
      "x": -21,
      "y": 33,
      "z": -8,
      "name": "Rock_Ice_Permafrost"
    },
    {
      "x": -21,
      "y": 34,
      "z": -8,
      "name": "Rock_Ice_Permafrost"
    },
    {
      "x": -21,
      "y": 35,
      "z": -8,
      "name": "Rock_Ice_Permafrost"
    },
    {
      "x": -21,
      "y": 36,
      "z": -8,
      "name": "Rock_Ice_Permafrost"
    },
    {
      "x": -21,
      "y": 37,
      "z": -8,
      "name": "Rock_Ice"
    },
    {
      "x": -21,
      "y": 38,
      "z": -8,
      "name": "Rock_Ice"
    },
    {
      "x": -21,
      "y": 39,
      "z": -8,
      "name": "Rock_Ice"
    },
    {
      "x": -21,
      "y": 40,
      "z": -8,
      "name": "Rock_Ice"
    },
    {
      "x": -21,
      "y": 41,
      "z": -8,
      "name": "Rock_Ice"
    },
    {
      "x": -21,
      "y": 14,
      "z": -7,
      "name": "Rock_Ice_Permafrost"
    },
    {
      "x": -21,
      "y": 15,
      "z": -7,
      "name": "Rock_Ice"
    },
    {
      "x": -21,
      "y": 16,
      "z": -7,
      "name": "Rock_Ice_Permafrost"
    },
    {
      "x": -21,
      "y": 17,
      "z": -7,
      "name": "Rock_Ice"
    },
    {
      "x": -21,
      "y": 18,
      "z": -7,
      "name": "Rock_Ice"
    },
    {
      "x": -21,
      "y": 19,
      "z": -7,
      "name": "Rock_Ice"
    },
    {
      "x": -21,
      "y": 20,
      "z": -7,
      "name": "Rock_Ice"
    },
    {
      "x": -21,
      "y": 21,
      "z": -7,
      "name": "Rock_Ice"
    },
    {
      "x": -21,
      "y": 22,
      "z": -7,
      "name": "Rock_Ice"
    },
    {
      "x": -21,
      "y": 23,
      "z": -7,
      "name": "Rock_Ice"
    },
    {
      "x": -21,
      "y": 24,
      "z": -7,
      "name": "Rock_Ice"
    },
    {
      "x": -21,
      "y": 25,
      "z": -7,
      "name": "Rock_Ice"
    },
    {
      "x": -21,
      "y": 26,
      "z": -7,
      "name": "Rock_Ice"
    },
    {
      "x": -21,
      "y": 27,
      "z": -7,
      "name": "Rock_Ice"
    },
    {
      "x": -21,
      "y": 28,
      "z": -7,
      "name": "Rock_Ice"
    },
    {
      "x": -21,
      "y": 29,
      "z": -7,
      "name": "Rock_Ice"
    },
    {
      "x": -21,
      "y": 30,
      "z": -7,
      "name": "Rock_Ice"
    },
    {
      "x": -21,
      "y": 31,
      "z": -7,
      "name": "Rock_Ice_Permafrost"
    },
    {
      "x": -21,
      "y": 32,
      "z": -7,
      "name": "Rock_Ice_Permafrost"
    },
    {
      "x": -21,
      "y": 33,
      "z": -7,
      "name": "Rock_Ice_Permafrost"
    },
    {
      "x": -21,
      "y": 34,
      "z": -7,
      "name": "Rock_Ice_Permafrost"
    },
    {
      "x": -21,
      "y": 35,
      "z": -7,
      "name": "Rock_Ice_Permafrost"
    },
    {
      "x": -21,
      "y": 36,
      "z": -7,
      "name": "Rock_Ice_Permafrost"
    },
    {
      "x": -21,
      "y": 37,
      "z": -7,
      "name": "Rock_Ice_Permafrost"
    },
    {
      "x": -21,
      "y": 38,
      "z": -7,
      "name": "Rock_Ice"
    },
    {
      "x": -21,
      "y": 39,
      "z": -7,
      "name": "Rock_Ice"
    },
    {
      "x": -21,
      "y": 40,
      "z": -7,
      "name": "Rock_Ice"
    },
    {
      "x": -21,
      "y": 41,
      "z": -7,
      "name": "Rock_Ice"
    },
    {
      "x": -21,
      "y": 42,
      "z": -7,
      "name": "Rock_Ice"
    },
    {
      "x": -21,
      "y": 43,
      "z": -7,
      "name": "Rock_Ice"
    },
    {
      "x": -21,
      "y": 44,
      "z": -7,
      "name": "Rock_Ice"
    },
    {
      "x": -21,
      "y": 45,
      "z": -7,
      "name": "Rock_Ice"
    },
    {
      "x": -21,
      "y": 46,
      "z": -7,
      "name": "Rock_Ice"
    },
    {
      "x": -21,
      "y": 47,
      "z": -7,
      "name": "Rock_Ice"
    },
    {
      "x": -21,
      "y": 48,
      "z": -7,
      "name": "Rock_Ice"
    },
    {
      "x": -21,
      "y": 49,
      "z": -7,
      "name": "Soil_Snow"
    },
    {
