{
  "version": 8,
  "blockIdVersion": 11,
  "anchorX": -1,
  "anchorY": 22,
  "anchorZ": 4,
  "blocks": [
    {
      "x": -29,
      "y": 26,
      "z": -9,
      "name": "Rock_Ice_Permafrost"
    },
    {
      "x": -29,
      "y": 27,
      "z": -9,
      "name": "Rock_Ice_Permafrost"
    },
    {
      "x": -29,
      "y": 28,
      "z": -9,
      "name": "Rock_Ice_Permafrost"
    },
    {
      "x": -29,
      "y": 29,
      "z": -9,
      "name": "Rock_Ice_Permafrost"
    },
    {
      "x": -29,
      "y": 30,
      "z": -9,
      "name": "Soil_Snow"
    },
    {
      "x": -29,
      "y": 24,
      "z": -8,
      "name": "Rock_Ice_Permafrost"
    },
    {
      "x": -29,
      "y": 25,
      "z": -8,
      "name": "Rock_Ice_Permafrost"
    },
    {
      "x": -29,
      "y": 26,
      "z": -8,
      "name": "Rock_Ice"
    },
    {
      "x": -29,
      "y": 27,
      "z": -8,
      "name": "Rock_Ice"
    },
    {
      "x": -29,
      "y": 28,
      "z": -8,
      "name": "Rock_Ice_Permafrost"
    },
    {
      "x": -29,
      "y": 29,
      "z": -8,
      "name": "Rock_Ice_Permafrost"
    },
    {
      "x": -29,
      "y": 30,
      "z": -8,
      "name": "Soil_Snow"
    },
    {
      "x": -29,
      "y": 23,
      "z": -7,
      "name": "Rock_Ice_Permafrost"
    },
    {
      "x": -29,
      "y": 24,
      "z": -7,
      "name": "Rock_Ice"
    },
    {
      "x": -29,
      "y": 25,
      "z": -7,
      "name": "Rock_Ice"
    },
    {
      "x": -29,
      "y": 26,
      "z": -7,
      "name": "Rock_Ice"
    },
    {
      "x": -29,
      "y": 27,
      "z": -7,
      "name": "Rock_Ice"
    },
    {
      "x": -29,
      "y": 28,
      "z": -7,
      "name": "Rock_Ice"
    },
    {
      "x": -29,
      "y": 29,
      "z": -7,
      "name": "Rock_Ice_Permafrost"
    },
    {
      "x": -29,
      "y": 26,
      "z": -6,
      "name": "Rock_Ice"
    },
    {
      "x": -29,
      "y": 27,
      "z": -6,
      "name": "Rock_Ice"
    },
    {
      "x": -28,
      "y": 28,
      "z": -13,
      "name": "Rock_Ice_Permafrost"
    },
    {
      "x": -28,
      "y": 29,
      "z": -13,
      "name": "Rock_Ice"
    },
    {
      "x": -28,
      "y": 30,
      "z": -13,
      "name": "Rock_Ice"
    },
    {
      "x": -28,
      "y": 31,
      "z": -13,
      "name": "Soil_Snow"
    },
    {
      "x": -28,
      "y": 25,
      "z": -12,
      "name": "Rock_Ice_Permafrost"
    },
    {
      "x": -28,
      "y": 26,
      "z": -12,
      "name": "Rock_Ice_Permafrost"
    },
    {
      "x": -28,
      "y": 27,
      "z": -12,
      "name": "Rock_Ice_Permafrost"
    },
    {
      "x": -28,
      "y": 28,
      "z": -12,
      "name": "Rock_Ice_Permafrost"
    },
    {
      "x": -28,
      "y": 29,
      "z": -12,
      "name": "Rock_Ice"
    },
    {
      "x": -28,
      "y": 30,
      "z": -12,
      "name": "Rock_Ice"
    },
    {
      "x": -28,
      "y": 31,
      "z": -12,
      "name": "Rock_Ice"
    },
    {
      "x": -28,
      "y": 32,
      "z": -12,
      "name": "Soil_Snow"
    },
    {
      "x": -28,
      "y": 23,
      "z": -11,
      "name": "Rock_Ice_Permafrost"
    },
    {
      "x": -28,
      "y": 24,
      "z": -11,
      "name": "Rock_Ice_Permafrost"
    },
    {
      "x": -28,
      "y": 25,
      "z": -11,
      "name": "Rock_Ice"
    },
    {
      "x": -28,
      "y": 26,
      "z": -11,
      "name": "Rock_Ice_Permafrost"
    },
    {
      "x": -28,
      "y": 27,
      "z": -11,
      "name": "Rock_Ice_Permafrost"
    },
    {
      "x": -28,
      "y": 28,
      "z": -11,
      "name": "Rock_Ice_Permafrost"
    },
    {
      "x": -28,
      "y": 29,
      "z": -11,
      "name": "Rock_Ice_Permafrost"
    },
    {
      "x": -28,
      "y": 30,
      "z": -11,
      "name": "Rock_Ice"
    },
    {
      "x": -28,
      "y": 31,
      "z": -11,
      "name": "Rock_Ice"
    },
    {
      "x": -28,
      "y": 32,
      "z": -11,
      "name": "Rock_Ice"
    },
    {
      "x": -28,
      "y": 33,
      "z": -11,
      "name": "Soil_Snow"
    },
    {
      "x": -28,
      "y": 22,
      "z": -10,
      "name": "Rock_Ice"
    },
    {
      "x": -28,
      "y": 23,
      "z": -10,
      "name": "Rock_Ice_Permafrost"
    },
    {
      "x": -28,
      "y": 24,
      "z": -10,
      "name": "Rock_Ice_Permafrost"
    },
    {
      "x": -28,
      "y": 25,
      "z": -10,
      "name": "Rock_Ice_Permafrost"
    },
    {
      "x": -28,
      "y": 26,
      "z": -10,
      "name": "Rock_Ice_Permafrost"
    },
    {
      "x": -28,
      "y": 27,
      "z": -10,
      "name": "Rock_Ice_Permafrost"
    },
    {
      "x": -28,
      "y": 28,
      "z": -10,
      "name": "Rock_Ice_Permafrost"
    },
    {
      "x": -28,
      "y": 29,
      "z": -10,
      "name": "Rock_Ice_Permafrost"
    },
    {
      "x": -28,
      "y": 30,
      "z": -10,
      "name": "Rock_Ice"
    },
    {
      "x": -28,
      "y": 31,
      "z": -10,
      "name": "Rock_Ice"
    },
    {
      "x": -28,
      "y": 32,
      "z": -10,
      "name": "Rock_Ice"
    },
    {
      "x": -28,
      "y": 33,
      "z": -10,
      "name": "Soil_Snow"
    },
    {
      "x": -28,
      "y": 21,
      "z": -9,
      "name": "Rock_Ice_Permafrost"
    },
    {
      "x": -28,
      "y": 22,
      "z": -9,
      "name": "Rock_Ice_Permafrost"
    },
    {
      "x": -28,
      "y": 23,
      "z": -9,
      "name": "Rock_Ice_Permafrost"
    },
    {
      "x": -28,
      "y": 24,
      "z": -9,
      "name": "Rock_Ice_Permafrost"
    },
    {
      "x": -28,
      "y": 25,
      "z": -9,
      "name": "Rock_Ice_Permafrost"
    },
    {
      "x": -28,
      "y": 26,
      "z": -9,
      "name": "Rock_Ice_Permafrost"
    },
    {
      "x": -28,
      "y": 27,
      "z": -9,
      "name": "Rock_Ice_Permafrost"
    },
    {
      "x": -28,
      "y": 28,
      "z": -9,
      "name": "Rock_Ice_Permafrost"
    },
    {
      "x": -28,
      "y": 29,
      "z": -9,
      "name": "Rock_Ice_Permafrost"
    },
    {
      "x": -28,
      "y": 30,
      "z": -9,
      "name": "Rock_Ice_Permafrost"
    },
    {
      "x": -28,
      "y": 31,
      "z": -9,
      "name": "Rock_Ice"
    },
    {
      "x": -28,
      "y": 32,
      "z": -9,
      "name": "Soil_Snow"
    },
    {
      "x": -28,
      "y": 20,
      "z": -8,
      "name": "Rock_Ice_Permafrost"
    },
    {
      "x": -28,
      "y": 21,
      "z": -8,
      "name": "Rock_Ice_Permafrost"
    },
    {
      "x": -28,
      "y": 22,
      "z": -8,
      "name": "Rock_Ice_Permafrost"
    },
    {
      "x": -28,
      "y": 23,
      "z": -8,
      "name": "Rock_Ice_Permafrost"
    },
    {
      "x": -28,
      "y": 24,
      "z": -8,
      "name": "Rock_Ice_Permafrost"
    },
    {
      "x": -28,
      "y": 25,
      "z": -8,
      "name": "Rock_Ice_Permafrost"
    },
    {
      "x": -28,
      "y": 26,
      "z": -8,
      "name": "Rock_Ice_Permafrost"
    },
    {
      "x": -28,
      "y": 27,
      "z": -8,
      "name": "Rock_Ice_Permafrost"
    },
    {
      "x": -28,
      "y": 28,
      "z": -8,
      "name": "Rock_Ice_Permafrost"
    },
    {
      "x": -28,
      "y": 29,
      "z": -8,
      "name": "Rock_Ice_Permafrost"
    },
    {
      "x": -28,
      "y": 30,
      "z": -8,
      "name": "Rock_Ice_Permafrost"
    },
    {
      "x": -28,
      "y": 31,
      "z": -8,
      "name": "Rock_Ice"
    },
    {
      "x": -28,
      "y": 32,
      "z": -8,
      "name": "Soil_Snow"
    },
    {
      "x": -28,
      "y": 20,
      "z": -7,
      "name": "Rock_Ice_Permafrost"
    },
    {
      "x": -28,
      "y": 21,
      "z": -7,
      "name": "Rock_Ice_Permafrost"
    },
    {
      "x": -28,
      "y": 22,
      "z": -7,
      "name": "Rock_Ice_Permafrost"
    },
    {
      "x": -28,
      "y": 23,
      "z": -7,
      "name": "Rock_Ice_Permafrost"
    },
    {
      "x": -28,
      "y": 24,
      "z": -7,
      "name": "Rock_Ice"
    },
    {
      "x": -28,
      "y": 25,
      "z": -7,
      "name": "Rock_Ice"
    },
    {
      "x": -28,
      "y": 26,
      "z": -7,
      "name": "Rock_Ice"
    },
    {
      "x": -28,
      "y": 27,
      "z": -7,
      "name": "Rock_Ice"
    },
    {
      "x": -28,
      "y": 28,
      "z": -7,
      "name": "Rock_Ice_Permafrost"
    },
    {
      "x": -28,
      "y": 29,
      "z": -7,
      "name": "Rock_Ice_Permafrost"
    },
    {
      "x": -28,
      "y": 30,
      "z": -7,
      "name": "Rock_Ice_Permafrost"
    },
    {
      "x": -28,
      "y": 31,
      "z": -7,
      "name": "Rock_Ice"
    },
    {
      "x": -28,
      "y": 32,
      "z": -7,
      "name": "Soil_Snow"
    },
    {
      "x": -28,
      "y": 21,
      "z": -6,
      "name": "Rock_Ice"
    },
    {
      "x": -28,
      "y": 22,
      "z": -6,
      "name": "Rock_Ice"
    },
    {
      "x": -28,
      "y": 23,
      "z": -6,
      "name": "Rock_Ice"
    },
    {
      "x": -28,
      "y": 24,
      "z": -6,
      "name": "Rock_Ice"
    },
    {
      "x": -28,
      "y": 25,
      "z": -6,
      "name": "Rock_Ice"
    },
    {
      "x": -28,
      "y": 26,
      "z": -6,
      "name": "Rock_Ice"
    },
    {
      "x": -28,
      "y": 27,
      "z": -6,
      "name": "Rock_Ice"
    },
    {
      "x": -28,
      "y": 28,
      "z": -6,
      "name": "Rock_Ice"
    },
    {
      "x": -28,
      "y": 29,
      "z": -6,
      "name": "Rock_Ice_Permafrost"
    },
    {
      "x": -28,
      "y": 30,
      "z": -6,
      "name": "Rock_Ice"
    },
    {
      "x": -28,
      "y": 31,
      "z": -6,
      "name": "Soil_Snow"
    },
    {
      "x": -28,
      "y": 22,
      "z": -5,
      "name": "Rock_Ice"
    },
    {
      "x": -28,
      "y": 23,
      "z": -5,
      "name": "Rock_Ice"
    },
    {
      "x": -28,
      "y": 24,
      "z": -5,
      "name": "Rock_Ice"
    },
    {
      "x": -28,
      "y": 25,
      "z": -5,
      "name": "Rock_Ice"
    },
    {
      "x": -28,
      "y": 26,
      "z": -5,
      "name": "Rock_Ice"
    },
    {
      "x": -28,
      "y": 27,
      "z": -5,
      "name": "Rock_Ice"
    },
    {
      "x": -28,
      "y": 28,
      "z": -5,
      "name": "Rock_Ice"
    },
    {
      "x": -28,
      "y": 29,
      "z": -5,
      "name": "Rock_Ice"
    },
    {
      "x": -28,
      "y": 30,
      "z": -5,
      "name": "Soil_Snow"
    },
    {
      "x": -28,
      "y": 23,
      "z": -4,
      "name": "Rock_Ice"
    },
    {
      "x": -28,
      "y": 24,
      "z": -4,
      "name": "Rock_Ice"
    },
    {
      "x": -28,
      "y": 25,
      "z": -4,
      "name": "Rock_Ice"
    },
    {
      "x": -28,
      "y": 26,
      "z": -4,
      "name": "Rock_Ice"
    },
    {
      "x": -28,
      "y": 27,
      "z": -4,
      "name": "Rock_Ice"
    },
    {
      "x": -28,
      "y": 28,
      "z": -4,
      "name": "Rock_Ice"
    },
    {
      "x": -28,
      "y": 29,
      "z": -4,
      "name": "Rock_Ice"
    },
    {
      "x": -28,
      "y": 30,
      "z": -4,
      "name": "Soil_Snow"
    },
    {
      "x": -28,
      "y": 28,
      "z": -3,
      "name": "Rock_Ice_Permafrost"
    },
    {
      "x": -28,
      "y": 27,
      "z": 0,
      "name": "Soil_Snow"
    },
    {
      "x": -27,
      "y": 30,
      "z": -17,
      "name": "Rock_Ice_Permafrost"
    },
    {
      "x": -27,
      "y": 31,
      "z": -17,
      "name": "Rock_Ice"
    },
    {
      "x": -27,
      "y": 28,
      "z": -16,
      "name": "Rock_Ice_Permafrost"
    },
    {
      "x": -27,
      "y": 29,
      "z": -16,
      "name": "Rock_Ice_Permafrost"
    },
    {
      "x": -27,
      "y": 30,
      "z": -16,
      "name": "Rock_Ice_Permafrost"
    },
    {
      "x": -27,
      "y": 31,
      "z": -16,
      "name": "Rock_Ice"
    },
    {
      "x": -27,
      "y": 32,
      "z": -16,
      "name": "Soil_Snow"
    },
    {
      "x": -27,
      "y": 26,
      "z": -15,
      "name": "Rock_Ice_Permafrost"
    },
    {
      "x": -27,
      "y": 27,
      "z": -15,
      "name": "Rock_Ice_Permafrost"
    },
    {
      "x": -27,
      "y": 28,
      "z": -15,
      "name": "Rock_Ice_Permafrost"
    },
    {
      "x": -27,
      "y": 29,
      "z": -15,
      "name": "Rock_Ice_Permafrost"
    },
    {
      "x": -27,
      "y": 30,
      "z": -15,
      "name": "Rock_Ice_Permafrost"
    },
    {
      "x": -27,
      "y": 31,
      "z": -15,
      "name": "Rock_Ice"
    },
    {
      "x": -27,
      "y": 32,
      "z": -15,
      "name": "Rock_Ice"
    },
    {
      "x": -27,
      "y": 33,
      "z": -15,
      "name": "Soil_Snow"
    },
    {
      "x": -27,
      "y": 25,
      "z": -14,
      "name": "Rock_Ice_Permafrost"
    },
    {
      "x": -27,
      "y": 26,
      "z": -14,
      "name": "Rock_Ice_Permafrost"
    },
    {
      "x": -27,
      "y": 27,
      "z": -14,
      "name": "Rock_Ice_Permafrost"
    },
    {
      "x": -27,
      "y": 28,
      "z": -14,
      "name": "Rock_Ice_Permafrost"
    },
    {
      "x": -27,
      "y": 29,
      "z": -14,
      "name": "Rock_Ice"
    },
    {
      "x": -27,
      "y": 30,
      "z": -14,
      "name": "Rock_Ice"
    },
    {
      "x": -27,
      "y": 31,
      "z": -14,
      "name": "Rock_Ice"
    },
    {
      "x": -27,
      "y": 32,
      "z": -14,
      "name": "Rock_Ice"
    },
    {
      "x": -27,
      "y": 33,
      "z": -14,
      "name": "Soil_Snow"
    },
    {
      "x": -27,
      "y": 24,
      "z": -13,
      "name": "Rock_Ice_Permafrost"
    },
    {
      "x": -27,
      "y": 25,
      "z": -13,
      "name": "Rock_Ice_Permafrost"
    },
    {
      "x": -27,
      "y": 26,
      "z": -13,
      "name": "Rock_Ice_Permafrost"
    },
    {
      "x": -27,
      "y": 27,
      "z": -13,
      "name": "Rock_Ice_Permafrost"
    },
    {
      "x": -27,
      "y": 28,
      "z": -13,
      "name": "Rock_Ice_Permafrost"
    },
    {
      "x": -27,
      "y": 29,
      "z": -13,
      "name": "Rock_Ice_Permafrost"
    },
    {
      "x": -27,
      "y": 30,
      "z": -13,
      "name": "Rock_Ice"
    },
    {
      "x": -27,
      "y": 31,
      "z": -13,
      "name": "Rock_Ice"
    },
    {
      "x": -27,
      "y": 32,
      "z": -13,
      "name": "Rock_Ice"
    },
    {
      "x": -27,
      "y": 33,
      "z": -13,
      "name": "Rock_Ice"
    },
    {
      "x": -27,
      "y": 34,
      "z": -13,
      "name": "Soil_Snow"
    },
    {
      "x": -27,
      "y": 22,
      "z": -12,
      "name": "Rock_Ice_Permafrost"
    },
    {
      "x": -27,
      "y": 23,
      "z": -12,
      "name": "Rock_Ice"
    },
    {
      "x": -27,
      "y": 24,
      "z": -12,
      "name": "Rock_Ice"
    },
    {
      "x": -27,
      "y": 25,
      "z": -12,
      "name": "Rock_Ice_Permafrost"
    },
    {
      "x": -27,
      "y": 26,
      "z": -12,
      "name": "Rock_Ice_Permafrost"
    },
    {
      "x": -27,
      "y": 27,
      "z": -12,
      "name": "Rock_Ice_Permafrost"
    },
    {
      "x": -27,
      "y": 28,
      "z": -12,
      "name": "Rock_Ice"
    },
    {
      "x": -27,
      "y": 29,
      "z": -12,
      "name": "Rock_Ice"
    },
    {
      "x": -27,
      "y": 30,
      "z": -12,
      "name": "Rock_Ice_Permafrost"
    },
    {
      "x": -27,
      "y": 31,
      "z": -12,
      "name": "Rock_Ice"
    },
    {
      "x": -27,
      "y": 32,
      "z": -12,
      "name": "Rock_Ice"
    },
    {
      "x": -27,
      "y": 33,
      "z": -12,
      "name": "Rock_Ice"
    },
    {
      "x": -27,
      "y": 34,
      "z": -12,
      "name": "Rock_Ice"
    },
    {
      "x": -27,
      "y": 35,
      "z": -12,
      "name": "Soil_Snow"
    },
    {
      "x": -27,
      "y": 21,
      "z": -11,
      "name": "Rock_Ice_Permafrost"
    },
    {
      "x": -27,
      "y": 22,
      "z": -11,
      "name": "Rock_Ice"
    },
    {
      "x": -27,
      "y": 23,
      "z": -11,
      "name": "Rock_Ice_Permafrost"
    },
    {
      "x": -27,
      "y": 24,
      "z": -11,
      "name": "Rock_Ice_Permafrost"
    },
    {
      "x": -27,
      "y": 25,
      "z": -11,
      "name": "Rock_Ice_Permafrost"
    },
    {
      "x": -27,
      "y": 26,
      "z": -11,
      "name": "Rock_Ice_Permafrost"
    },
    {
      "x": -27,
      "y": 27,
      "z": -11,
      "name": "Rock_Ice_Permafrost"
    },
    {
      "x": -27,
      "y": 28,
      "z": -11,
      "name": "Rock_Ice_Permafrost"
    },
    {
      "x": -27,
      "y": 29,
      "z": -11,
      "name": "Rock_Ice_Permafrost"
    },
    {
      "x": -27,
      "y": 30,
      "z": -11,
      "name": "Rock_Ice_Permafrost"
    },
    {
      "x": -27,
      "y": 31,
      "z": -11,
      "name": "Rock_Ice"
    },
    {
      "x": -27,
      "y": 32,
      "z": -11,
      "name": "Rock_Ice"
    },
    {
      "x": -27,
      "y": 33,
      "z": -11,
      "name": "Rock_Ice"
    },
    {
      "x": -27,
      "y": 34,
      "z": -11,
      "name": "Rock_Ice"
    },
    {
      "x": -27,
      "y": 35,
      "z": -11,
      "name": "Soil_Snow"
    },
    {
      "x": -27,
      "y": 19,
      "z": -10,
      "name": "Rock_Ice"
    },
    {
      "x": -27,
      "y": 20,
      "z": -10,
      "name": "Rock_Ice"
    },
    {
      "x": -27,
      "y": 21,
      "z": -10,
      "name": "Rock_Ice"
    },
    {
      "x": -27,
      "y": 22,
      "z": -10,
      "name": "Rock_Ice"
    },
    {
      "x": -27,
      "y": 23,
      "z": -10,
      "name": "Rock_Ice_Permafrost"
    },
    {
      "x": -27,
      "y": 24,
      "z": -10,
      "name": "Rock_Ice_Permafrost"
    },
    {
      "x": -27,
      "y": 25,
      "z": -10,
      "name": "Rock_Ice_Permafrost"
    },
    {
      "x": -27,
      "y": 26,
      "z": -10,
      "name": "Rock_Ice_Permafrost"
    },
    {
      "x": -27,
      "y": 27,
      "z": -10,
      "name": "Rock_Ice_Permafrost"
    },
    {
      "x": -27,
      "y": 28,
      "z": -10,
      "name": "Rock_Ice_Permafrost"
    },
    {
      "x": -27,
      "y": 29,
      "z": -10,
      "name": "Rock_Ice_Permafrost"
    },
    {
      "x": -27,
      "y": 30,
      "z": -10,
      "name": "Rock_Ice"
    },
    {
      "x": -27,
      "y": 31,
      "z": -10,
      "name": "Rock_Ice_Permafrost"
    },
    {
      "x": -27,
      "y": 32,
      "z": -10,
      "name": "Rock_Ice"
    },
    {
      "x": -27,
      "y": 33,
      "z": -10,
      "name": "Rock_Ice_Permafrost"
    },
    {
      "x": -27,
      "y": 34,
      "z": -10,
      "name": "Rock_Ice"
    },
    {
      "x": -27,
      "y": 35,
      "z": -10,
      "name": "Soil_Snow"
    },
    {
      "x": -27,
      "y": 18,
      "z": -9,
      "name": "Rock_Ice"
    },
    {
      "x": -27,
      "y": 19,
      "z": -9,
      "name": "Rock_Ice"
    },
    {
      "x": -27,
      "y": 20,
      "z": -9,
      "name": "Rock_Ice"
    },
    {
      "x": -27,
      "y": 21,
      "z": -9,
      "name": "Rock_Ice_Permafrost"
    },
    {
      "x": -27,
      "y": 22,
      "z": -9,
      "name": "Rock_Ice_Permafrost"
    },
    {
      "x": -27,
      "y": 23,
      "z": -9,
      "name": "Rock_Ice_Permafrost"
    },
    {
      "x": -27,
      "y": 24,
      "z": -9,
      "name": "Rock_Ice_Permafrost"
    },
    {
      "x": -27,
      "y": 25,
      "z": -9,
      "name": "Rock_Ice_Permafrost"
    },
    {
      "x": -27,
      "y": 26,
      "z": -9,
      "name": "Rock_Ice_Permafrost"
    },
    {
      "x": -27,
      "y": 27,
      "z": -9,
      "name": "Rock_Ice_Permafrost"
    },
    {
      "x": -27,
      "y": 28,
      "z": -9,
      "name": "Rock_Ice_Permafrost"
    },
    {
      "x": -27,
      "y": 29,
      "z": -9,
      "name": "Rock_Ice_Permafrost"
    },
    {
      "x": -27,
      "y": 30,
      "z": -9,
      "name": "Rock_Ice_Permafrost"
    },
    {
      "x": -27,
      "y": 31,
      "z": -9,
      "name": "Rock_Ice_Permafrost"
    },
    {
      "x": -27,
      "y": 32,
      "z": -9,
      "name": "Rock_Ice_Permafrost"
    },
    {
      "x": -27,
      "y": 33,
      "z": -9,
      "name": "Rock_Ice"
    },
    {
      "x": -27,
      "y": 34,
      "z": -9,
      "name": "Soil_Snow"
    },
    {
      "x": -27,
      "y": 17,
      "z": -8,
      "name": "Rock_Ice"
    },
    {
      "x": -27,
      "y": 18,
      "z": -8,
      "name": "Rock_Ice"
    },
    {
      "x": -27,
      "y": 19,
      "z": -8,
      "name": "Rock_Ice_Permafrost"
    },
    {
      "x": -27,
      "y": 20,
      "z": -8,
      "name": "Rock_Ice_Permafrost"
    },
    {
      "x": -27,
      "y": 21,
      "z": -8,
      "name": "Rock_Ice_Permafrost"
    },
    {
      "x": -27,
      "y": 22,
      "z": -8,
      "name": "Rock_Ice_Permafrost"
    },
    {
      "x": -27,
      "y": 23,
      "z": -8,
      "name": "Rock_Ice_Permafrost"
    },
    {
      "x": -27,
      "y": 24,
      "z": -8,
      "name": "Rock_Ice_Permafrost"
    },
    {
      "x": -27,
      "y": 25,
      "z": -8,
      "name": "Rock_Ice_Permafrost"
    },
    {
      "x": -27,
      "y": 26,
      "z": -8,
      "name": "Rock_Ice_Permafrost"
    },
    {
      "x": -27,
      "y": 27,
      "z": -8,
      "name": "Rock_Ice_Permafrost"
    },
    {
      "x": -27,
      "y": 28,
      "z": -8,
      "name": "Rock_Ice_Permafrost"
    },
    {
      "x": -27,
      "y": 29,
      "z": -8,
      "name": "Rock_Ice_Permafrost"
    },
    {
      "x": -27,
      "y": 30,
      "z": -8,
      "name": "Rock_Ice_Permafrost"
    },
    {
      "x": -27,
      "y": 31,
      "z": -8,
      "name": "Rock_Ice_Permafrost"
    },
    {
      "x": -27,
      "y": 32,
      "z": -8,
      "name": "Rock_Ice_Permafrost"
    },
    {
      "x": -27,
      "y": 33,
      "z": -8,
      "name": "Rock_Ice"
    },
    {
      "x": -27,
      "y": 34,
      "z": -8,
      "name": "Soil_Snow"
    },
    {
      "x": -27,
      "y": 16,
      "z": -7,
      "name": "Rock_Ice"
    },
    {
      "x": -27,
      "y": 17,
      "z": -7,
      "name": "Rock_Ice_Permafrost"
    },
    {
      "x": -27,
      "y": 18,
      "z": -7,
      "name": "Rock_Ice_Permafrost"
    },
    {
      "x": -27,
      "y": 19,
      "z": -7,
      "name": "Rock_Ice_Permafrost"
    },
    {
      "x": -27,
      "y": 20,
      "z": -7,
      "name": "Rock_Ice_Permafrost"
    },
    {
      "x": -27,
      "y": 21,
      "z": -7,
      "name": "Rock_Ice_Permafrost"
    },
    {
      "x": -27,
      "y": 22,
      "z": -7,
      "name": "Rock_Ice_Permafrost"
    },
    {
      "x": -27,
      "y": 23,
      "z": -7,
      "name": "Rock_Ice_Permafrost"
    },
    {
      "x": -27,
      "y": 24,
      "z": -7,
      "name": "Rock_Ice_Permafrost"
    },
    {
      "x": -27,
      "y": 25,
      "z": -7,
      "name": "Rock_Ice"
    },
    {
      "x": -27,
      "y": 26,
      "z": -7,
      "name": "Rock_Ice"
    },
    {
      "x": -27,
      "y": 27,
      "z": -7,
      "name": "Rock_Ice_Permafrost"
    },
    {
      "x": -27,
      "y": 28,
      "z": -7,
      "name": "Rock_Ice_Permafrost"
    },
    {
      "x": -27,
      "y": 29,
      "z": -7,
      "name": "Rock_Ice_Permafrost"
    },
    {
      "x": -27,
      "y": 30,
      "z": -7,
      "name": "Rock_Ice_Permafrost"
    },
    {
      "x": -27,
      "y": 31,
      "z": -7,
      "name": "Rock_Ice_Permafrost"
    },
    {
      "x": -27,
      "y": 32,
      "z": -7,
      "name": "Rock_Ice_Permafrost"
    },
    {
      "x": -27,
      "y": 33,
      "z": -7,
      "name": "Rock_Ice"
    },
    {
      "x": -27,
      "y": 34,
      "z": -7,
      "name": "Soil_Snow"
    },
    {
      "x": -27,
      "y": 17,
      "z": -6,
      "name": "Rock_Ice_Permafrost"
    },
    {
      "x": -27,
      "y": 18,
      "z": -6,
      "name": "Rock_Ice_Permafrost"
    },
    {
      "x": -27,
      "y": 19,
      "z": -6,
      "name": "Rock_Ice_Permafrost"
    },
    {
      "x": -27,
      "y": 20,
      "z": -6,
      "name": "Rock_Ice_Permafrost"
    },
    {
      "x": -27,
      "y": 21,
      "z": -6,
      "name": "Rock_Ice_Permafrost"
    },
    {
      "x": -27,
      "y": 22,
      "z": -6,
      "name": "Rock_Ice"
    },
    {
      "x": -27,
      "y": 23,
      "z": -6,
      "name": "Rock_Ice"
    },
    {
      "x": -27,
      "y": 24,
      "z": -6,
      "name": "Rock_Ice"
    },
    {
      "x": -27,
      "y": 25,
      "z": -6,
      "name": "Rock_Ice"
    },
    {
      "x": -27,
      "y": 26,
      "z": -6,
      "name": "Rock_Ice"
    },
    {
      "x": -27,
      "y": 27,
      "z": -6,
      "name": "Rock_Ice_Permafrost"
    },
    {
      "x": -27,
      "y": 28,
      "z": -6,
      "name": "Rock_Ice_Permafrost"
    },
    {
      "x": -27,
      "y": 29,
      "z": -6,
      "name": "Rock_Ice_Permafrost"
    },
    {
      "x": -27,
      "y": 30,
      "z": -6,
      "name": "Rock_Ice_Permafrost"
    },
    {
      "x": -27,
      "y": 31,
      "z": -6,
      "name": "Rock_Ice_Permafrost"
    },
    {
      "x": -27,
      "y": 32,
      "z": -6,
      "name": "Rock_Ice"
    },
    {
      "x": -27,
      "y": 33,
      "z": -6,
      "name": "Soil_Snow"
    },
    {
      "x": -27,
      "y": 17,
      "z": -5,
      "name": "Rock_Ice_Permafrost"
    },
    {
      "x": -27,
      "y": 18,
      "z": -5,
      "name": "Rock_Ice_Permafrost"
    },
    {
      "x": -27,
      "y": 19,
      "z": -5,
      "name": "Rock_Ice_Permafrost"
    },
    {
      "x": -27,
      "y": 20,
      "z": -5,
      "name": "Rock_Ice"
    },
    {
      "x": -27,
      "y": 21,
      "z": -5,
      "name": "Rock_Ice"
    },
    {
      "x": -27,
      "y": 22,
      "z": -5,
      "name": "Rock_Ice"
    },
    {
      "x": -27,
      "y": 23,
      "z": -5,
      "name": "Rock_Ice"
    },
    {
      "x": -27,
      "y": 24,
      "z": -5,
      "name": "Rock_Ice"
    },
    {
      "x": -27,
      "y": 25,
      "z": -5,
      "name": "Rock_Ice"
    },
    {
      "x": -27,
      "y": 26,
      "z": -5,
      "name": "Rock_Ice_Permafrost"
    },
    {
      "x": -27,
      "y": 27,
      "z": -5,
      "name": "Rock_Ice_Permafrost"
    },
    {
      "x": -27,
      "y": 28,
      "z": -5,
      "name": "Rock_Ice_Permafrost"
    },
    {
      "x": -27,
      "y": 29,
      "z": -5,
      "name": "Rock_Ice_Permafrost"
    },
    {
      "x": -27,
      "y": 30,
      "z": -5,
      "name": "Rock_Ice_Permafrost"
    },
    {
      "x": -27,
      "y": 31,
      "z": -5,
      "name": "Rock_Ice"
    },
    {
      "x": -27,
      "y": 32,
      "z": -5,
      "name": "Rock_Ice"
    },
    {
      "x": -27,
      "y": 33,
      "z": -5,
      "name": "Soil_Snow"
    },
    {
      "x": -27,
      "y": 19,
      "z": -4,
      "name": "Rock_Ice"
    },
    {
      "x": -27,
      "y": 20,
      "z": -4,
      "name": "Rock_Ice"
    },
    {
      "x": -27,
      "y": 21,
      "z": -4,
      "name": "Rock_Ice"
    },
    {
      "x": -27,
      "y": 22,
      "z": -4,
      "name": "Rock_Ice"
    },
    {
      "x": -27,
      "y": 23,
      "z": -4,
      "name": "Rock_Ice"
    },
    {
      "x": -27,
      "y": 24,
      "z": -4,
      "name": "Rock_Ice"
    },
    {
      "x": -27,
      "y": 25,
      "z": -4,
      "name": "Rock_Ice"
    },
    {
      "x": -27,
      "y": 26,
      "z": -4,
      "name": "Rock_Ice"
    },
    {
      "x": -27,
      "y": 27,
      "z": -4,
      "name": "Rock_Ice_Permafrost"
    },
    {
      "x": -27,
      "y": 28,
      "z": -4,
      "name": "Rock_Ice_Permafrost"
    },
    {
      "x": -27,
      "y": 29,
      "z": -4,
      "name": "Rock_Ice_Permafrost"
    },
    {
      "x": -27,
      "y": 30,
      "z": -4,
      "name": "Rock_Ice_Permafrost"
    },
    {
      "x": -27,
      "y": 31,
      "z": -4,
      "name": "Rock_Ice_Permafrost"
    },
    {
      "x": -27,
      "y": 32,
      "z": -4,
      "name": "Rock_Ice"
    },
    {
      "x": -27,
      "y": 33,
      "z": -4,
      "name": "Soil_Snow"
    },
    {
      "x": -27,
      "y": 22,
      "z": -3,
      "name": "Rock_Ice"
    },
    {
      "x": -27,
      "y": 23,
      "z": -3,
      "name": "Rock_Ice"
    },
    {
      "x": -27,
      "y": 24,
      "z": -3,
      "name": "Rock_Ice"
    },
    {
      "x": -27,
      "y": 25,
      "z": -3,
      "name": "Rock_Ice"
    },
    {
      "x": -27,
      "y": 26,
      "z": -3,
      "name": "Rock_Ice"
    },
    {
      "x": -27,
      "y": 27,
      "z": -3,
      "name": "Rock_Ice"
    },
    {
      "x": -27,
      "y": 28,
      "z": -3,
      "name": "Rock_Ice_Permafrost"
    },
    {
      "x": -27,
      "y": 29,
      "z": -3,
      "name": "Rock_Ice_Permafrost"
    },
    {
      "x": -27,
      "y": 30,
      "z": -3,
      "name": "Rock_Ice"
    },
    {
      "x": -27,
      "y": 31,
      "z": -3,
      "name": "Soil_Snow"
    },
    {
      "x": -27,
      "y": 23,
      "z": -1,
      "name": "Rock_Ice"
    },
    {
      "x": -27,
      "y": 24,
      "z": -1,
      "name": "Rock_Ice"
    },
    {
      "x": -27,
      "y": 25,
      "z": -1,
      "name": "Rock_Ice"
    },
    {
      "x": -27,
      "y": 26,
      "z": -1,
      "name": "Rock_Ice_Permafrost"
    },
    {
      "x": -27,
      "y": 27,
      "z": -1,
      "name": "Rock_Ice_Permafrost"
    },
    {
      "x": -27,
      "y": 28,
      "z": -1,
      "name": "Rock_Ice"
    },
    {
      "x": -27,
      "y": 29,
      "z": -1,
      "name": "Soil_Snow"
    },
    {
      "x": -27,
      "y": 22,
      "z": 0,
      "name": "Rock_Ice"
    },
    {
      "x": -27,
      "y": 23,
      "z": 0,
      "name": "Rock_Ice"
    },
    {
      "x": -27,
      "y": 24,
      "z": 0,
      "name": "Rock_Ice"
    },
    {
      "x": -27,
      "y": 25,
      "z": 0,
      "name": "Rock_Ice"
    },
    {
      "x": -27,
      "y": 26,
      "z": 0,
      "name": "Rock_Ice_Permafrost"
    },
    {
      "x": -27,
      "y": 27,
      "z": 0,
      "name": "Rock_Ice_Permafrost"
    },
    {
      "x": -27,
      "y": 28,
      "z": 0,
      "name": "Rock_Ice_Permafrost"
    },
    {
      "x": -27,
      "y": 29,
      "z": 0,
      "name": "Rock_Ice"
    },
    {
      "x": -27,
      "y": 30,
      "z": 0,
      "name": "Soil_Snow"
    },
    {
      "x": -27,
      "y": 23,
      "z": 1,
      "name": "Rock_Ice"
    },
    {
      "x": -27,
      "y": 24,
      "z": 1,
      "name": "Rock_Ice_Permafrost"
    },
    {
      "x": -27,
      "y": 25,
      "z": 1,
      "name": "Rock_Ice_Permafrost"
    },
    {
      "x": -27,
      "y": 26,
      "z": 1,
      "name": "Rock_Ice_Permafrost"
    },
    {
      "x": -27,
      "y": 27,
      "z": 1,
      "name": "Rock_Ice_Permafrost"
    },
    {
      "x": -27,
      "y": 28,
      "z": 1,
      "name": "Rock_Ice"
    },
    {
      "x": -27,
      "y": 29,
      "z": 1,
      "name": "Soil_Snow"
    },
    {
      "x": -27,
      "y": 25,
      "z": 2,
      "name": "Rock_Ice"
    },
    {
      "x": -27,
      "y": 26,
      "z": 2,
      "name": "Rock_Ice_Permafrost"
    },
    {
      "x": -26,
      "y": 29,
      "z": -19,
      "name": "Rock_Ice_Permafrost"
    },
    {
      "x": -26,
      "y": 30,
      "z": -19,
      "name": "Rock_Ice_Permafrost"
    },
    {
      "x": -26,
      "y": 31,
      "z": -19,
      "name": "Rock_Ice_Permafrost"
    },
    {
      "x": -26,
      "y": 32,
      "z": -19,
      "name": "Rock_Ice"
    },
    {
      "x": -26,
      "y": 33,
      "z": -19,
      "name": "Soil_Snow"
    },
    {
      "x": -26,
      "y": 28,
      "z": -18,
      "name": "Rock_Ice_Permafrost"
    },
    {
      "x": -26,
      "y": 29,
      "z": -18,
      "name": "Rock_Ice_Permafrost"
    },
    {
      "x": -26,
      "y": 30,
      "z": -18,
      "name": "Rock_Ice"
    },
    {
      "x": -26,
      "y": 31,
      "z": -18,
      "name": "Rock_Ice"
    },
    {
      "x": -26,
      "y": 32,
      "z": -18,
      "name": "Rock_Ice"
    },
    {
      "x": -26,
      "y": 33,
      "z": -18,
      "name": "Soil_Snow"
    },
    {
      "x": -26,
      "y": 26,
      "z": -17,
      "name": "Rock_Ice_Permafrost"
    },
    {
      "x": -26,
      "y": 27,
      "z": -17,
      "name": "Rock_Ice_Permafrost"
    },
    {
      "x": -26,
      "y": 28,
      "z": -17,
      "name": "Rock_Ice_Permafrost"
    },
    {
      "x": -26,
      "y": 29,
      "z": -17,
      "name": "Rock_Ice_Permafrost"
    },
    {
      "x": -26,
      "y": 30,
      "z": -17,
      "name": "Rock_Ice"
    },
    {
      "x": -26,
      "y": 31,
      "z": -17,
      "name": "Rock_Ice"
    },
    {
      "x": -26,
      "y": 32,
      "z": -17,
      "name": "Rock_Ice"
    },
    {
      "x": -26,
      "y": 33,
      "z": -17,
      "name": "Rock_Ice"
    },
    {
      "x": -26,
      "y": 34,
      "z": -17,
      "name": "Soil_Snow"
    },
    {
      "x": -26,
      "y": 25,
      "z": -16,
      "name": "Rock_Ice_Permafrost"
    },
    {
      "x": -26,
      "y": 26,
      "z": -16,
      "name": "Rock_Ice_Permafrost"
    },
    {
      "x": -26,
      "y": 27,
      "z": -16,
      "name": "Rock_Ice_Permafrost"
    },
    {
      "x": -26,
      "y": 28,
      "z": -16,
      "name": "Rock_Ice_Permafrost"
    },
    {
      "x": -26,
      "y": 29,
      "z": -16,
      "name": "Rock_Ice_Permafrost"
    },
    {
      "x": -26,
      "y": 30,
      "z": -16,
      "name": "Rock_Ice"
    },
    {
      "x": -26,
      "y": 31,
      "z": -16,
      "name": "Rock_Ice"
    },
    {
      "x": -26,
      "y": 32,
      "z": -16,
      "name": "Rock_Ice"
    },
    {
      "x": -26,
      "y": 33,
      "z": -16,
      "name": "Rock_Ice"
    },
    {
      "x": -26,
      "y": 34,
      "z": -16,
      "name": "Rock_Ice"
    },
    {
      "x": -26,
      "y": 35,
      "z": -16,
      "name": "Soil_Snow"
    },
    {
      "x": -26,
      "y": 23,
      "z": -15,
      "name": "Rock_Ice_Permafrost"
    },
    {
      "x": -26,
      "y": 24,
      "z": -15,
      "name": "Rock_Ice_Permafrost"
    },
    {
      "x": -26,
      "y": 25,
      "z": -15,
      "name": "Rock_Ice_Permafrost"
    },
    {
      "x": -26,
      "y": 26,
      "z": -15,
      "name": "Rock_Ice_Permafrost"
    },
    {
      "x": -26,
      "y": 27,
      "z": -15,
      "name": "Rock_Ice_Permafrost"
    },
    {
      "x": -26,
      "y": 28,
      "z": -15,
      "name": "Rock_Ice_Permafrost"
    },
    {
      "x": -26,
      "y": 29,
      "z": -15,
      "name": "Rock_Ice_Permafrost"
    },
    {
      "x": -26,
      "y": 30,
      "z": -15,
      "name": "Rock_Ice"
    },
    {
      "x": -26,
      "y": 31,
      "z": -15,
      "name": "Rock_Ice"
    },
    {
      "x": -26,
      "y": 32,
      "z": -15,
      "name": "Rock_Ice"
    },
    {
      "x": -26,
      "y": 33,
      "z": -15,
      "name": "Rock_Ice"
    },
    {
      "x": -26,
      "y": 34,
      "z": -15,
      "name": "Rock_Ice"
    },
    {
      "x": -26,
      "y": 35,
      "z": -15,
      "name": "Rock_Ice"
    },
    {
      "x": -26,
      "y": 36,
      "z": -15,
      "name": "Soil_Snow"
    },
    {
      "x": -26,
      "y": 22,
      "z": -14,
      "name": "Rock_Ice_Permafrost"
    },
    {
      "x": -26,
      "y": 23,
      "z": -14,
      "name": "Rock_Ice_Permafrost"
    },
    {
      "x": -26,
      "y": 24,
      "z": -14,
      "name": "Rock_Ice_Permafrost"
    },
    {
      "x": -26,
      "y": 25,
      "z": -14,
      "name": "Rock_Ice_Permafrost"
    },
    {
      "x": -26,
      "y": 26,
      "z": -14,
      "name": "Rock_Ice_Permafrost"
    },
    {
      "x": -26,
      "y": 27,
      "z": -14,
      "name": "Rock_Ice_Permafrost"
    },
    {
      "x": -26,
      "y": 28,
      "z": -14,
      "name": "Rock_Ice_Permafrost"
    },
    {
      "x": -26,
      "y": 29,
      "z": -14,
      "name": "Rock_Ice_Permafrost"
    },
    {
      "x": -26,
      "y": 30,
      "z": -14,
      "name": "Rock_Ice"
    },
    {
      "x": -26,
      "y": 31,
      "z": -14,
      "name": "Rock_Ice"
    },
    {
      "x": -26,
      "y": 32,
      "z": -14,
      "name": "Rock_Ice"
    },
    {
      "x": -26,
      "y": 33,
      "z": -14,
      "name": "Rock_Ice"
    },
    {
      "x": -26,
      "y": 34,
      "z": -14,
      "name": "Rock_Ice"
    },
    {
      "x": -26,
      "y": 35,
      "z": -14,
      "name": "Rock_Ice"
    },
    {
      "x": -26,
      "y": 36,
      "z": -14,
      "name": "Soil_Snow"
    },
    {
      "x": -26,
      "y": 21,
      "z": -13,
      "name": "Rock_Ice_Permafrost"
    },
    {
      "x": -26,
      "y": 22,
      "z": -13,
      "name": "Rock_Ice_Permafrost"
    },
    {
      "x": -26,
      "y": 23,
      "z": -13,
      "name": "Rock_Ice_Permafrost"
    },
    {
      "x": -26,
      "y": 24,
      "z": -13,
      "name": "Rock_Ice_Permafrost"
    },
    {
      "x": -26,
      "y": 25,
      "z": -13,
      "name": "Rock_Ice_Permafrost"
    },
    {
      "x": -26,
      "y": 26,
      "z": -13,
      "name": "Rock_Ice_Permafrost"
    },
    {
      "x": -26,
      "y": 27,
      "z": -13,
      "name": "Rock_Ice_Permafrost"
    },
    {
      "x": -26,
      "y": 28,
      "z": -13,
      "name": "Rock_Ice_Permafrost"
    },
    {
      "x": -26,
      "y": 29,
      "z": -13,
      "name": "Rock_Ice_Permafrost"
    },
    {
      "x": -26,
      "y": 30,
      "z": -13,
      "name": "Rock_Ice"
    },
    {
      "x": -26,
      "y": 31,
      "z": -13,
      "name": "Rock_Ice"
    },
    {
      "x": -26,
      "y": 32,
      "z": -13,
      "name": "Rock_Ice"
    },
    {
      "x": -26,
      "y": 33,
      "z": -13,
      "name": "Rock_Ice"
    },
    {
      "x": -26,
      "y": 34,
      "z": -13,
      "name": "Rock_Ice"
    },
    {
      "x": -26,
      "y": 35,
      "z": -13,
      "name": "Rock_Ice"
    },
    {
      "x": -26,
      "y": 36,
      "z": -13,
      "name": "Rock_Ice"
    },
    {
      "x": -26,
      "y": 37,
      "z": -13,
      "name": "Soil_Snow"
    },
    {
      "x": -26,
      "y": 20,
      "z": -12,
      "name": "Rock_Ice"
    },
    {
      "x": -26,
      "y": 21,
      "z": -12,
      "name": "Rock_Ice_Permafrost"
    },
    {
      "x": -26,
      "y": 22,
      "z": -12,
      "name": "Rock_Ice_Permafrost"
    },
    {
      "x": -26,
      "y": 23,
      "z": -12,
      "name": "Rock_Ice_Permafrost"
    },
    {
      "x": -26,
      "y": 24,
      "z": -12,
      "name": "Rock_Ice_Permafrost"
    },
    {
      "x": -26,
      "y": 25,
      "z": -12,
      "name": "Rock_Ice_Permafrost"
    },
    {
      "x": -26,
      "y": 26,
      "z": -12,
      "name": "Rock_Ice_Permafrost"
    },
    {
      "x": -26,
      "y": 27,
      "z": -12,
      "name": "Rock_Ice_Permafrost"
    },
    {
      "x": -26,
      "y": 28,
      "z": -12,
      "name": "Rock_Ice_Permafrost"
    },
    {
      "x": -26,
      "y": 29,
      "z": -12,
      "name": "Rock_Ice_Permafrost"
    },
    {
      "x": -26,
      "y": 30,
      "z": -12,
      "name": "Rock_Ice"
    },
    {
      "x": -26,
      "y": 31,
      "z": -12,
      "name": "Rock_Ice"
    },
    {
      "x": -26,
      "y": 32,
      "z": -12,
      "name": "Rock_Ice"
    },
    {
      "x": -26,
      "y": 33,
      "z": -12,
      "name": "Rock_Ice"
    },
    {
      "x": -26,
      "y": 34,
      "z": -12,
      "name": "Rock_Ice_Permafrost"
    },
    {
      "x": -26,
      "y": 35,
      "z": -12,
      "name": "Rock_Ice_Permafrost"
    },
    {
      "x": -26,
      "y": 36,
      "z": -12,
      "name": "Rock_Ice_Permafrost"
    },
    {
      "x": -26,
      "y": 37,
      "z": -12,
      "name": "Rock_Ice"
    },
    {
      "x": -26,
      "y": 38,
      "z": -12,
      "name": "Soil_Snow"
    },
    {
      "x": -26,
      "y": 19,
      "z": -11,
      "name": "Rock_Ice"
    },
    {
      "x": -26,
      "y": 20,
      "z": -11,
      "name": "Rock_Ice"
    },
    {
      "x": -26,
      "y": 21,
      "z": -11,
      "name": "Rock_Ice"
    },
    {
      "x": -26,
      "y": 22,
      "z": -11,
      "name": "Rock_Ice_Permafrost"
    },
    {
      "x": -26,
      "y": 23,
      "z": -11,
      "name": "Rock_Ice"
    },
    {
      "x": -26,
      "y": 24,
      "z": -11,
      "name": "Rock_Ice"
    },
    {
      "x": -26,
      "y": 25,
      "z": -11,
      "name": "Rock_Ice_Permafrost"
    },
    {
      "x": -26,
      "y": 26,
      "z": -11,
      "name": "Rock_Ice_Permafrost"
    },
    {
      "x": -26,
      "y": 27,
      "z": -11,
      "name": "Rock_Ice_Permafrost"
    },
    {
      "x": -26,
      "y": 28,
      "z": -11,
      "name": "Rock_Ice_Permafrost"
    },
    {
      "x": -26,
      "y": 29,
      "z": -11,
      "name": "Rock_Ice_Permafrost"
    },
    {
      "x": -26,
      "y": 30,
      "z": -11,
      "name": "Rock_Ice"
    },
    {
      "x": -26,
      "y": 31,
      "z": -11,
      "name": "Rock_Ice"
    },
    {
      "x": -26,
      "y": 32,
      "z": -11,
      "name": "Rock_Ice"
    },
    {
      "x": -26,
      "y": 33,
      "z": -11,
      "name": "Rock_Ice"
    },
    {
      "x": -26,
      "y": 34,
      "z": -11,
      "name": "Rock_Ice_Permafrost"
    },
    {
      "x": -26,
      "y": 35,
      "z": -11,
      "name": "Rock_Ice_Permafrost"
    },
    {
      "x": -26,
      "y": 36,
      "z": -11,
      "name": "Rock_Ice"
    },
    {
      "x": -26,
      "y": 37,
      "z": -11,
      "name": "Soil_Snow"
    },
    {
      "x": -26,
      "y": 17,
      "z": -10,
      "name": "Rock_Ice"
    },
    {
      "x": -26,
      "y": 18,
      "z": -10,
      "name": "Rock_Ice"
    },
    {
      "x": -26,
      "y": 19,
      "z": -10,
      "name": "Rock_Ice"
    },
    {
      "x": -26,
      "y": 20,
      "z": -10,
      "name": "Rock_Ice"
    },
    {
      "x": -26,
      "y": 21,
      "z": -10,
      "name": "Rock_Ice"
    },
    {
      "x": -26,
      "y": 22,
      "z": -10,
      "name": "Rock_Ice_Permafrost"
    },
    {
      "x": -26,
      "y": 23,
      "z": -10,
      "name": "Rock_Ice_Permafrost"
    },
    {
      "x": -26,
      "y": 24,
      "z": -10,
      "name": "Rock_Ice_Permafrost"
    },
    {
      "x": -26,
      "y": 25,
      "z": -10,
      "name": "Rock_Ice_Permafrost"
    },
    {
      "x": -26,
      "y": 26,
      "z": -10,
      "name": "Rock_Ice_Permafrost"
    },
    {
      "x": -26,
      "y": 27,
      "z": -10,
      "name": "Rock_Ice_Permafrost"
    },
    {
      "x": -26,
      "y": 28,
      "z": -10,
      "name": "Rock_Ice_Permafrost"
    },
    {
      "x": -26,
      "y": 29,
      "z": -10,
      "name": "Rock_Ice_Permafrost"
    },
    {
      "x": -26,
      "y": 30,
      "z": -10,
      "name": "Rock_Ice_Permafrost"
    },
    {
      "x": -26,
      "y": 31,
      "z": -10,
      "name": "Rock_Ice_Permafrost"
    },
    {
      "x": -26,
      "y": 32,
      "z": -10,
      "name": "Rock_Ice_Permafrost"
    },
    {
      "x": -26,
      "y": 33,
      "z": -10,
      "name": "Rock_Ice_Permafrost"
    },
    {
      "x": -26,
      "y": 34,
      "z": -10,
      "name": "Rock_Ice_Permafrost"
    },
    {
      "x": -26,
      "y": 35,
      "z": -10,
      "name": "Rock_Ice_Permafrost"
    },
    {
      "x": -26,
      "y": 36,
      "z": -10,
      "name": "Rock_Ice"
    },
    {
      "x": -26,
      "y": 37,
      "z": -10,
      "name": "Soil_Snow"
    },
    {
      "x": -26,
      "y": 16,
      "z": -9,
      "name": "Rock_Ice"
    },
    {
      "x": -26,
      "y": 17,
      "z": -9,
      "name": "Rock_Ice"
    },
    {
      "x": -26,
      "y": 18,
      "z": -9,
      "name": "Rock_Ice"
    },
    {
      "x": -26,
      "y": 19,
      "z": -9,
      "name": "Rock_Ice"
    },
    {
      "x": -26,
      "y": 20,
      "z": -9,
      "name": "Rock_Ice_Permafrost"
    },
    {
      "x": -26,
      "y": 21,
      "z": -9,
      "name": "Rock_Ice"
    },
    {
      "x": -26,
      "y": 22,
      "z": -9,
      "name": "Rock_Ice_Permafrost"
    },
    {
      "x": -26,
      "y": 23,
      "z": -9,
      "name": "Rock_Ice_Permafrost"
    },
    {
      "x": -26,
      "y": 24,
      "z": -9,
      "name": "Rock_Ice_Permafrost"
    },
    {
      "x": -26,
      "y": 25,
      "z": -9,
      "name": "Rock_Ice_Permafrost"
    },
    {
      "x": -26,
      "y": 26,
      "z": -9,
      "name": "Rock_Ice_Permafrost"
    },
    {
      "x": -26,
      "y": 27,
      "z": -9,
      "name": "Rock_Ice_Permafrost"
    },
    {
      "x": -26,
      "y": 28,
      "z": -9,
      "name": "Rock_Ice_Permafrost"
    },
    {
      "x": -26,
      "y": 29,
      "z": -9,
      "name": "Rock_Ice_Permafrost"
    },
    {
      "x": -26,
      "y": 30,
      "z": -9,
      "name": "Rock_Ice_Permafrost"
    },
    {
      "x": -26,
      "y": 31,
      "z": -9,
      "name": "Rock_Ice_Permafrost"
    },
    {
      "x": -26,
      "y": 32,
      "z": -9,
      "name": "Rock_Ice_Permafrost"
    },
    {
      "x": -26,
      "y": 33,
      "z": -9,
      "name": "Rock_Ice_Permafrost"
    },
    {
      "x": -26,
      "y": 34,
      "z": -9,
      "name": "Rock_Ice_Permafrost"
    },
    {
      "x": -26,
      "y": 35,
      "z": -9,
      "name": "Rock_Ice_Permafrost"
    },
    {
      "x": -26,
      "y": 36,
      "z": -9,
      "name": "Rock_Ice"
    },
    {
      "x": -26,
      "y": 37,
      "z": -9,
      "name": "Soil_Snow"
    },
    {
      "x": -26,
      "y": 15,
      "z": -8,
      "name": "Rock_Ice"
    },
    {
      "x": -26,
      "y": 16,
      "z": -8,
      "name": "Rock_Ice"
    },
    {
      "x": -26,
      "y": 17,
      "z": -8,
      "name": "Rock_Ice"
    },
    {
      "x": -26,
      "y": 18,
      "z": -8,
      "name": "Rock_Ice"
    },
    {
      "x": -26,
      "y": 19,
      "z": -8,
      "name": "Rock_Ice_Permafrost"
    },
    {
      "x": -26,
      "y": 20,
      "z": -8,
      "name": "Rock_Ice_Permafrost"
    },
    {
      "x": -26,
      "y": 21,
      "z": -8,
      "name": "Rock_Ice_Permafrost"
    },
    {
      "x": -26,
      "y": 22,
      "z": -8,
      "name": "Rock_Ice_Permafrost"
    },
    {
      "x": -26,
      "y": 23,
      "z": -8,
      "name": "Rock_Ice_Permafrost"
    },
    {
      "x": -26,
      "y": 24,
      "z": -8,
      "name": "Rock_Ice_Permafrost"
    },
    {
      "x": -26,
      "y": 25,
      "z": -8,
      "name": "Rock_Ice_Permafrost"
    },
    {
      "x": -26,
      "y": 26,
      "z": -8,
      "name": "Rock_Ice_Permafrost"
    },
    {
      "x": -26,
      "y": 27,
      "z": -8,
      "name": "Rock_Ice_Permafrost"
    },
    {
      "x": -26,
      "y": 28,
      "z": -8,
      "name": "Rock_Ice_Permafrost"
    },
    {
      "x": -26,
      "y": 29,
      "z": -8,
      "name": "Rock_Ice_Permafrost"
    },
    {
      "x": -26,
      "y": 30,
      "z": -8,
      "name": "Rock_Ice_Permafrost"
    },
    {
      "x": -26,
      "y": 31,
      "z": -8,
      "name": "Rock_Ice_Permafrost"
    },
    {
      "x": -26,
      "y": 32,
      "z": -8,
      "name": "Rock_Ice_Permafrost"
    },
    {
      "x": -26,
      "y": 33,
      "z": -8,
      "name": "Rock_Ice_Permafrost"
    },
    {
      "x": -26,
      "y": 34,
      "z": -8,
      "name": "Rock_Ice_Permafrost"
    },
    {
      "x": -26,
      "y": 35,
      "z": -8,
      "name": "Rock_Ice"
    },
    {
      "x": -26,
      "y": 36,
      "z": -8,
      "name": "Soil_Snow"
    },
    {
      "x": -26,
      "y": 15,
      "z": -7,
      "name": "Rock_Ice"
    },
    {
      "x": -26,
      "y": 16,
      "z": -7,
      "name": "Rock_Ice"
    },
    {
      "x": -26,
      "y": 17,
      "z": -7,
      "name": "Rock_Ice"
    },
    {
      "x": -26,
      "y": 18,
      "z": -7,
      "name": "Rock_Ice_Permafrost"
    },
    {
      "x": -26,
      "y": 19,
      "z": -7,
      "name": "Rock_Ice_Permafrost"
    },
    {
      "x": -26,
      "y": 20,
      "z": -7,
      "name": "Rock_Ice_Permafrost"
    },
    {
      "x": -26,
      "y": 21,
      "z": -7,
      "name": "Rock_Ice_Permafrost"
    },
    {
      "x": -26,
      "y": 22,
      "z": -7,
      "name": "Rock_Ice_Permafrost"
    },
    {
      "x": -26,
      "y": 23,
      "z": -7,
      "name": "Rock_Ice_Permafrost"
    },
    {
      "x": -26,
      "y": 24,
      "z": -7,
      "name": "Rock_Ice_Permafrost"
    },
    {
      "x": -26,
      "y": 25,
      "z": -7,
      "name": "Rock_Ice_Permafrost"
    },
    {
      "x": -26,
      "y": 26,
      "z": -7,
      "name": "Rock_Ice_Permafrost"
    },
    {
      "x": -26,
      "y": 27,
      "z": -7,
      "name": "Rock_Ice_Permafrost"
    },
    {
      "x": -26,
      "y": 28,
      "z": -7,
      "name": "Rock_Ice_Permafrost"
    },
    {
      "x": -26,
      "y": 29,
      "z": -7,
      "name": "Rock_Ice_Permafrost"
    },
    {
      "x": -26,
      "y": 30,
      "z": -7,
      "name": "Rock_Ice_Permafrost"
    },
    {
      "x": -26,
      "y": 31,
      "z": -7,
      "name": "Rock_Ice_Permafrost"
    },
    {
      "x": -26,
      "y": 32,
      "z": -7,
      "name": "Rock_Ice_Permafrost"
    },
    {
      "x": -26,
      "y": 33,
      "z": -7,
      "name": "Rock_Ice_Permafrost"
    },
    {
      "x": -26,
      "y": 34,
      "z": -7,
      "name": "Rock_Ice"
    },
    {
      "x": -26,
      "y": 35,
      "z": -7,
      "name": "Rock_Ice"
    },
    {
      "x": -26,
      "y": 36,
      "z": -7,
      "name": "Soil_Snow"
    },
    {
      "x": -26,
      "y": 15,
      "z": -6,
      "name": "Rock_Ice"
    },
    {
      "x": -26,
      "y": 16,
      "z": -6,
      "name": "Rock_Ice_Permafrost"
    },
    {
      "x": -26,
      "y": 17,
      "z": -6,
      "name": "Rock_Ice_Permafrost"
    },
    {
      "x": -26,
      "y": 18,
      "z": -6,
      "name": "Rock_Ice_Permafrost"
    },
    {
      "x": -26,
      "y": 19,
      "z": -6,
      "name": "Rock_Ice_Permafrost"
    },
    {
      "x": -26,
      "y": 20,
      "z": -6,
      "name": "Rock_Ice_Permafrost"
    },
    {
      "x": -26,
      "y": 21,
      "z": -6,
      "name": "Rock_Ice_Permafrost"
    },
    {
      "x": -26,
      "y": 22,
      "z": -6,
      "name": "Rock_Ice_Permafrost"
    },
    {
      "x": -26,
      "y": 23,
      "z": -6,
      "name": "Rock_Ice_Permafrost"
    },
    {
      "x": -26,
      "y": 24,
      "z": -6,
      "name": "Rock_Ice"
    },
    {
      "x": -26,
      "y": 25,
      "z": -6,
      "name": "Rock_Ice"
    },
    {
      "x": -26,
      "y": 26,
      "z": -6,
      "name": "Rock_Ice_Permafrost"
    },
    {
      "x": -26,
      "y": 27,
      "z": -6,
      "name": "Rock_Ice_Permafrost"
    },
    {
      "x": -26,
      "y": 28,
      "z": -6,
      "name": "Rock_Ice_Permafrost"
    },
    {
      "x": -26,
      "y": 29,
      "z": -6,
      "name": "Rock_Ice_Permafrost"
    },
    {
      "x": -26,
      "y": 30,
      "z": -6,
      "name": "Rock_Ice_Permafrost"
    },
    {
      "x": -26,
      "y": 31,
      "z": -6,
      "name": "Rock_Ice_Permafrost"
    },
    {
      "x": -26,
      "y": 32,
      "z": -6,
      "name": "Rock_Ice"
    },
    {
      "x": -26,
      "y": 33,
      "z": -6,
      "name": "Rock_Ice"
    },
    {
      "x": -26,
      "y": 34,
      "z": -6,
      "name": "Rock_Ice"
    },
    {
      "x": -26,
      "y": 35,
      "z": -6,
      "name": "Rock_Ice"
    },
    {
      "x": -26,
      "y": 36,
      "z": -6,
      "name": "Soil_Snow"
    },
    {
      "x": -26,
      "y": 15,
      "z": -5,
      "name": "Rock_Ice_Permafrost"
    },
    {
      "x": -26,
      "y": 16,
      "z": -5,
      "name": "Rock_Ice_Permafrost"
    },
    {
      "x": -26,
      "y": 17,
      "z": -5,
      "name": "Rock_Ice_Permafrost"
    },
    {
      "x": -26,
      "y": 18,
      "z": -5,
      "name": "Rock_Ice_Permafrost"
    },
    {
      "x": -26,
      "y": 19,
      "z": -5,
      "name": "Rock_Ice_Permafrost"
    },
    {
      "x": -26,
      "y": 20,
      "z": -5,
      "name": "Rock_Ice_Permafrost"
    },
    {
      "x": -26,
      "y": 21,
      "z": -5,
      "name": "Rock_Ice_Permafrost"
    },
    {
      "x": -26,
      "y": 22,
      "z": -5,
      "name": "Rock_Ice"
    },
    {
      "x": -26,
      "y": 23,
      "z": -5,
      "name": "Rock_Ice"
    },
    {
      "x": -26,
      "y": 24,
      "z": -5,
      "name": "Rock_Ice"
    },
    {
      "x": -26,
      "y": 25,
      "z": -5,
      "name": "Rock_Ice_Permafrost"
    },
    {
      "x": -26,
      "y": 26,
      "z": -5,
      "name": "Rock_Ice_Permafrost"
    },
    {
      "x": -26,
      "y": 27,
      "z": -5,
      "name": "Rock_Ice_Permafrost"
    },
    {
      "x": -26,
      "y": 28,
      "z": -5,
      "name": "Rock_Ice_Permafrost"
    },
    {
      "x": -26,
      "y": 29,
      "z": -5,
      "name": "Rock_Ice_Permafrost"
    },
    {
      "x": -26,
      "y": 30,
      "z": -5,
      "name": "Rock_Ice_Permafrost"
    },
    {
      "x": -26,
      "y": 31,
      "z": -5,
      "name": "Rock_Ice"
    },
    {
      "x": -26,
      "y": 32,
      "z": -5,
      "name": "Rock_Ice"
    },
    {
      "x": -26,
      "y": 33,
      "z": -5,
      "name": "Rock_Ice"
    },
    {
      "x": -26,
      "y": 34,
      "z": -5,
      "name": "Rock_Ice"
    },
    {
      "x": -26,
      "y": 35,
      "z": -5,
      "name": "Rock_Ice"
    },
    {
      "x": -26,
      "y": 36,
      "z": -5,
      "name": "Soil_Snow"
    },
    {
      "x": -26,
      "y": 16,
      "z": -4,
      "name": "Rock_Ice_Permafrost"
    },
    {
      "x": -26,
      "y": 17,
      "z": -4,
      "name": "Rock_Ice_Permafrost"
    },
    {
      "x": -26,
      "y": 18,
      "z": -4,
      "name": "Rock_Ice_Permafrost"
    },
    {
      "x": -26,
      "y": 19,
      "z": -4,
      "name": "Rock_Ice_Permafrost"
    },
    {
      "x": -26,
      "y": 20,
      "z": -4,
      "name": "Rock_Ice"
    },
    {
      "x": -26,
      "y": 21,
      "z": -4,
      "name": "Rock_Ice"
    },
    {
      "x": -26,
      "y": 22,
      "z": -4,
      "name": "Rock_Ice"
    },
    {
      "x": -26,
      "y": 23,
      "z": -4,
      "name": "Rock_Ice"
    },
    {
      "x": -26,
      "y": 24,
      "z": -4,
      "name": "Rock_Ice_Permafrost"
    },
    {
      "x": -26,
      "y": 25,
      "z": -4,
      "name": "Rock_Ice"
    },
    {
      "x": -26,
      "y": 26,
      "z": -4,
      "name": "Rock_Ice_Permafrost"
    },
    {
      "x": -26,
      "y": 27,
      "z": -4,
      "name": "Rock_Ice_Permafrost"
    },
    {
      "x": -26,
      "y": 28,
      "z": -4,
      "name": "Rock_Ice_Permafrost"
    },
    {
      "x": -26,
      "y": 29,
      "z": -4,
      "name": "Rock_Ice_Permafrost"
    },
    {
      "x": -26,
      "y": 30,
      "z": -4,
      "name": "Rock_Ice"
    },
    {
      "x": -26,
      "y": 31,
      "z": -4,
      "name": "Rock_Ice"
    },
    {
      "x": -26,
      "y": 32,
      "z": -4,
      "name": "Rock_Ice"
    },
    {
      "x": -26,
      "y": 33,
      "z": -4,
      "name": "Rock_Ice"
    },
    {
      "x": -26,
      "y": 34,
      "z": -4,
      "name": "Rock_Ice"
    },
    {
      "x": -26,
      "y": 35,
      "z": -4,
      "name": "Rock_Ice"
    },
    {
      "x": -26,
      "y": 36,
      "z": -4,
      "name": "Soil_Snow"
    },
    {
      "x": -26,
      "y": 19,
      "z": -3,
      "name": "Rock_Ice"
    },
    {
      "x": -26,
      "y": 20,
      "z": -3,
      "name": "Rock_Ice"
    },
    {
      "x": -26,
      "y": 21,
      "z": -3,
      "name": "Rock_Ice"
    },
    {
      "x": -26,
      "y": 22,
      "z": -3,
      "name": "Rock_Ice"
    },
    {
      "x": -26,
      "y": 23,
      "z": -3,
      "name": "Rock_Ice"
    },
    {
      "x": -26,
      "y": 24,
      "z": -3,
      "name": "Rock_Ice"
    },
    {
      "x": -26,
      "y": 25,
      "z": -3,
      "name": "Rock_Ice"
    },
    {
      "x": -26,
      "y": 26,
      "z": -3,
      "name": "Rock_Ice_Permafrost"
    },
    {
      "x": -26,
      "y": 27,
      "z": -3,
      "name": "Rock_Ice_Permafrost"
    },
    {
      "x": -26,
      "y": 28,
      "z": -3,
      "name": "Rock_Ice_Permafrost"
    },
    {
      "x": -26,
      "y": 29,
      "z": -3,
      "name": "Rock_Ice_Permafrost"
    },
    {
      "x": -26,
      "y": 30,
      "z": -3,
      "name": "Rock_Ice_Permafrost"
    },
    {
      "x": -26,
      "y": 31,
      "z": -3,
      "name": "Rock_Ice"
    },
    {
      "x": -26,
      "y": 32,
      "z": -3,
      "name": "Rock_Ice"
    },
    {
      "x": -26,
      "y": 33,
      "z": -3,
      "name": "Rock_Ice"
    },
    {
      "x": -26,
      "y": 34,
      "z": -3,
      "name": "Rock_Ice"
    },
    {
      "x": -26,
      "y": 35,
      "z": -3,
      "name": "Rock_Ice"
    },
    {
      "x": -26,
      "y": 36,
      "z": -3,
      "name": "Soil_Snow"
    },
    {
      "x": -26,
      "y": 20,
      "z": -2,
      "name": "Rock_Ice"
    },
    {
      "x": -26,
      "y": 21,
      "z": -2,
      "name": "Rock_Ice"
    },
    {
      "x": -26,
      "y": 22,
      "z": -2,
      "name": "Rock_Ice"
    },
    {
      "x": -26,
      "y": 23,
      "z": -2,
      "name": "Rock_Ice"
    },
    {
      "x": -26,
      "y": 24,
      "z": -2,
      "name": "Rock_Ice_Permafrost"
    },
    {
      "x": -26,
      "y": 25,
      "z": -2,
      "name": "Rock_Ice_Permafrost"
    },
    {
      "x": -26,
      "y": 26,
      "z": -2,
      "name": "Rock_Ice_Permafrost"
    },
    {
      "x": -26,
      "y": 27,
      "z": -2,
      "name": "Rock_Ice_Permafrost"
    },
    {
      "x": -26,
      "y": 28,
      "z": -2,
      "name": "Rock_Ice_Permafrost"
    },
    {
      "x": -26,
      "y": 29,
      "z": -2,
      "name": "Rock_Ice_Permafrost"
    },
    {
      "x": -26,
      "y": 30,
      "z": -2,
      "name": "Rock_Ice"
    },
    {
      "x": -26,
      "y": 31,
      "z": -2,
      "name": "Rock_Ice"
    },
    {
      "x": -26,
      "y": 32,
      "z": -2,
      "name": "Soil_Snow"
    },
    {
      "x": -26,
      "y": 19,
      "z": -1,
      "name": "Rock_Ice"
    },
    {
      "x": -26,
      "y": 20,
      "z": -1,
      "name": "Rock_Ice"
    },
    {
      "x": -26,
      "y": 21,
      "z": -1,
      "name": "Rock_Ice"
    },
    {
      "x": -26,
      "y": 22,
      "z": -1,
      "name": "Rock_Ice"
    },
    {
      "x": -26,
      "y": 23,
      "z": -1,
      "name": "Rock_Ice"
    },
    {
      "x": -26,
      "y": 24,
      "z": -1,
      "name": "Rock_Ice"
    },
    {
      "x": -26,
      "y": 25,
      "z": -1,
      "name": "Rock_Ice_Permafrost"
    },
    {
      "x": -26,
      "y": 26,
      "z": -1,
      "name": "Rock_Ice_Permafrost"
    },
    {
      "x": -26,
      "y": 27,
      "z": -1,
      "name": "Rock_Ice_Permafrost"
    },
    {
      "x": -26,
      "y": 28,
      "z": -1,
      "name": "Rock_Ice_Permafrost"
    },
    {
      "x": -26,
      "y": 29,
      "z": -1,
      "name": "Rock_Ice_Permafrost"
    },
    {
      "x": -26,
      "y": 30,
      "z": -1,
      "name": "Rock_Ice_Permafrost"
    },
    {
      "x": -26,
      "y": 31,
      "z": -1,
      "name": "Rock_Ice"
    },
    {
      "x": -26,
      "y": 32,
      "z": -1,
      "name": "Rock_Ice"
    },
    {
      "x": -26,
      "y": 33,
      "z": -1,
      "name": "Soil_Snow"
    },
    {
      "x": -26,
      "y": 19,
      "z": 0,
      "name": "Rock_Ice"
    },
    {
      "x": -26,
      "y": 20,
      "z": 0,
      "name": "Rock_Ice"
    },
    {
      "x": -26,
      "y": 21,
      "z": 0,
      "name": "Rock_Ice"
    },
    {
      "x": -26,
      "y": 22,
      "z": 0,
      "name": "Rock_Ice"
    },
    {
      "x": -26,
      "y": 23,
      "z": 0,
      "name": "Rock_Ice"
    },
    {
      "x": -26,
      "y": 24,
      "z": 0,
      "name": "Rock_Ice"
    },
    {
      "x": -26,
      "y": 25,
      "z": 0,
      "name": "Rock_Ice_Permafrost"
    },
    {
      "x": -26,
      "y": 26,
      "z": 0,
      "name": "Rock_Ice_Permafrost"
    },
    {
      "x": -26,
      "y": 27,
      "z": 0,
      "name": "Rock_Ice_Permafrost"
    },
    {
      "x": -26,
      "y": 28,
      "z": 0,
      "name": "Rock_Ice_Permafrost"
    },
    {
      "x": -26,
      "y": 29,
      "z": 0,
      "name": "Rock_Ice"
    },
    {
      "x": -26,
      "y": 30,
      "z": 0,
      "name": "Rock_Ice"
    },
    {
      "x": -26,
      "y": 31,
      "z": 0,
      "name": "Rock_Ice"
    },
    {
      "x": -26,
      "y": 32,
      "z": 0,
      "name": "Rock_Ice"
    },
    {
      "x": -26,
      "y": 33,
      "z": 0,
      "name": "Rock_Ice"
    },
    {
      "x": -26,
      "y": 34,
      "z": 0,
      "name": "Soil_Snow"
    },
    {
      "x": -26,
      "y": 20,
      "z": 1,
      "name": "Rock_Ice"
    },
    {
      "x": -26,
      "y": 21,
      "z": 1,
      "name": "Rock_Ice"
    },
    {
      "x": -26,
      "y": 22,
      "z": 1,
      "name": "Rock_Ice"
    },
    {
      "x": -26,
      "y": 23,
      "z": 1,
      "name": "Rock_Ice_Permafrost"
    },
    {
      "x": -26,
      "y": 24,
      "z": 1,
      "name": "Rock_Ice_Permafrost"
    },
    {
      "x": -26,
      "y": 25,
      "z": 1,
      "name": "Rock_Ice_Permafrost"
    },
    {
      "x": -26,
      "y": 26,
      "z": 1,
      "name": "Rock_Ice_Permafrost"
    },
    {
      "x": -26,
      "y": 27,
      "z": 1,
      "name": "Rock_Ice_Permafrost"
    },
    {
      "x": -26,
      "y": 28,
      "z": 1,
      "name": "Rock_Ice_Permafrost"
    },
    {
      "x": -26,
      "y": 29,
      "z": 1,
      "name": "Rock_Ice_Permafrost"
    },
    {
      "x": -26,
      "y": 30,
      "z": 1,
      "name": "Rock_Ice"
    },
    {
      "x": -26,
      "y": 31,
      "z": 1,
      "name": "Rock_Ice"
    },
    {
      "x": -26,
      "y": 32,
      "z": 1,
      "name": "Rock_Ice"
    },
    {
      "x": -26,
      "y": 33,
      "z": 1,
      "name": "Soil_Snow"
    },
    {
      "x": -26,
      "y": 21,
      "z": 2,
      "name": "Rock_Ice"
    },
    {
      "x": -26,
      "y": 22,
      "z": 2,
      "name": "Rock_Ice"
    },
    {
      "x": -26,
      "y": 23,
      "z": 2,
      "name": "Rock_Ice_Permafrost"
    },
    {
      "x": -26,
      "y": 24,
      "z": 2,
      "name": "Rock_Ice"
    },
    {
      "x": -26,
      "y": 25,
      "z": 2,
      "name": "Rock_Ice_Permafrost"
    },
    {
      "x": -26,
      "y": 26,
      "z": 2,
      "name": "Rock_Ice_Permafrost"
    },
    {
      "x": -26,
      "y": 27,
      "z": 2,
      "name": "Rock_Ice_Permafrost"
    },
    {
      "x": -26,
      "y": 28,
      "z": 2,
      "name": "Rock_Ice_Permafrost"
    },
    {
      "x": -26,
      "y": 29,
      "z": 2,
      "name": "Rock_Ice_Permafrost"
    },
    {
      "x": -26,
      "y": 30,
      "z": 2,
      "name": "Rock_Ice"
    },
    {
      "x": -26,
      "y": 31,
      "z": 2,
      "name": "Rock_Ice"
    },
    {
      "x": -26,
      "y": 23,
      "z": 3,
      "name": "Rock_Ice_Permafrost"
    },
    {
      "x": -26,
      "y": 24,
      "z": 3,
      "name": "Rock_Ice_Permafrost"
    },
    {
      "x": -26,
      "y": 25,
      "z": 3,
      "name": "Rock_Ice_Permafrost"
    },
    {
      "x": -26,
      "y": 26,
      "z": 3,
      "name": "Rock_Ice_Permafrost"
    },
    {
      "x": -26,
      "y": 27,
      "z": 3,
      "name": "Rock_Ice_Permafrost"
    },
    {
      "x": -26,
      "y": 28,
      "z": 3,
      "name": "Rock_Ice_Permafrost"
    },
    {
      "x": -25,
      "y": 31,
      "z": -22,
      "name": "Soil_Snow"
    },
    {
      "x": -25,
      "y": 30,
      "z": -21,
      "name": "Rock_Ice_Permafrost"
    },
    {
      "x": -25,
      "y": 31,
      "z": -21,
      "name": "Rock_Ice_Permafrost"
    },
    {
      "x": -25,
      "y": 32,
      "z": -21,
      "name": "Rock_Ice"
    },
    {
      "x": -25,
      "y": 33,
      "z": -21,
      "name": "Soil_Snow"
    },
    {
      "x": -25,
      "y": 28,
      "z": -20,
      "name": "Rock_Ice_Permafrost"
    },
    {
      "x": -25,
      "y": 29,
      "z": -20,
      "name": "Rock_Ice_Permafrost"
    },
    {
      "x": -25,
      "y": 30,
      "z": -20,
      "name": "Rock_Ice_Permafrost"
    },
    {
      "x": -25,
      "y": 31,
      "z": -20,
      "name": "Rock_Ice_Permafrost"
    },
    {
      "x": -25,
      "y": 32,
      "z": -20,
      "name": "Rock_Ice_Permafrost"
    },
    {
      "x": -25,
      "y": 33,
      "z": -20,
      "name": "Rock_Ice"
    },
    {
      "x": -25,
      "y": 34,
      "z": -20,
      "name": "Soil_Snow"
    },
    {
      "x": -25,
      "y": 26,
      "z": -19,
      "name": "Rock_Ice_Permafrost"
    },
    {
      "x": -25,
      "y": 27,
      "z": -19,
      "name": "Rock_Ice_Permafrost"
    },
    {
      "x": -25,
      "y": 28,
      "z": -19,
      "name": "Rock_Ice_Permafrost"
    },
    {
      "x": -25,
      "y": 29,
      "z": -19,
      "name": "Rock_Ice_Permafrost"
    },
    {
      "x": -25,
      "y": 30,
      "z": -19,
      "name": "Rock_Ice_Permafrost"
    },
    {
      "x": -25,
      "y": 31,
      "z": -19,
      "name": "Rock_Ice_Permafrost"
    },
    {
      "x": -25,
      "y": 32,
      "z": -19,
      "name": "Rock_Ice_Permafrost"
    },
    {
      "x": -25,
      "y": 33,
      "z": -19,
      "name": "Rock_Ice"
    },
    {
      "x": -25,
      "y": 34,
      "z": -19,
      "name": "Rock_Ice"
    },
    {
      "x": -25,
      "y": 35,
      "z": -19,
      "name": "Soil_Snow"
    },
    {
      "x": -25,
      "y": 25,
      "z": -18,
      "name": "Rock_Ice_Permafrost"
    },
    {
      "x": -25,
      "y": 26,
      "z": -18,
      "name": "Rock_Ice_Permafrost"
    },
    {
      "x": -25,
      "y": 27,
      "z": -18,
      "name": "Rock_Ice_Permafrost"
    },
    {
      "x": -25,
      "y": 28,
      "z": -18,
      "name": "Rock_Ice_Permafrost"
    },
    {
      "x": -25,
      "y": 29,
      "z": -18,
      "name": "Rock_Ice_Permafrost"
    },
    {
      "x": -25,
      "y": 30,
      "z": -18,
      "name": "Rock_Ice_Permafrost"
    },
    {
      "x": -25,
      "y": 31,
      "z": -18,
      "name": "Rock_Ice_Permafrost"
    },
    {
      "x": -25,
      "y": 32,
      "z": -18,
      "name": "Rock_Ice"
    },
    {
      "x": -25,
      "y": 33,
      "z": -18,
      "name": "Rock_Ice"
    },
    {
      "x": -25,
      "y": 34,
      "z": -18,
      "name": "Rock_Ice"
    },
    {
      "x": -25,
      "y": 35,
      "z": -18,
      "name": "Rock_Ice"
    },
    {
      "x": -25,
      "y": 36,
      "z": -18,
      "name": "Soil_Snow"
    },
    {
      "x": -25,
      "y": 24,
      "z": -17,
      "name": "Rock_Ice_Permafrost"
    },
    {
      "x": -25,
      "y": 25,
      "z": -17,
      "name": "Rock_Ice_Permafrost"
    },
    {
      "x": -25,
      "y": 26,
      "z": -17,
      "name": "Rock_Ice_Permafrost"
    },
    {
      "x": -25,
      "y": 27,
      "z": -17,
      "name": "Rock_Ice_Permafrost"
    },
    {
      "x": -25,
      "y": 28,
      "z": -17,
      "name": "Rock_Ice_Permafrost"
    },
    {
      "x": -25,
      "y": 29,
      "z": -17,
      "name": "Rock_Ice_Permafrost"
    },
    {
      "x": -25,
      "y": 30,
      "z": -17,
      "name": "Rock_Ice_Permafrost"
    },
    {
      "x": -25,
      "y": 31,
      "z": -17,
      "name": "Rock_Ice"
    },
    {
      "x": -25,
      "y": 32,
      "z": -17,
      "name": "Rock_Ice"
    },
    {
      "x": -25,
      "y": 33,
      "z": -17,
      "name": "Rock_Ice"
    },
    {
      "x": -25,
      "y": 34,
      "z": -17,
      "name": "Rock_Ice"
    },
    {
      "x": -25,
      "y": 35,
      "z": -17,
      "name": "Rock_Ice"
    },
    {
      "x": -25,
      "y": 36,
      "z": -17,
      "name": "Rock_Ice"
    },
    {
      "x": -25,
      "y": 37,
      "z": -17,
      "name": "Soil_Snow"
    },
    {
      "x": -25,
      "y": 23,
      "z": -16,
      "name": "Rock_Ice_Permafrost"
    },
    {
      "x": -25,
      "y": 24,
      "z": -16,
      "name": "Rock_Ice_Permafrost"
    },
    {
      "x": -25,
      "y": 25,
      "z": -16,
      "name": "Rock_Ice_Permafrost"
    },
    {
      "x": -25,
      "y": 26,
      "z": -16,
      "name": "Rock_Ice_Permafrost"
    },
    {
      "x": -25,
      "y": 27,
      "z": -16,
      "name": "Rock_Ice_Permafrost"
    },
    {
      "x": -25,
      "y": 28,
      "z": -16,
      "name": "Rock_Ice_Permafrost"
    },
    {
      "x": -25,
      "y": 29,
      "z": -16,
      "name": "Rock_Ice_Permafrost"
    },
    {
      "x": -25,
      "y": 30,
      "z": -16,
      "name": "Rock_Ice"
    },
    {
      "x": -25,
      "y": 31,
      "z": -16,
      "name": "Rock_Ice"
    },
    {
      "x": -25,
      "y": 32,
      "z": -16,
      "name": "Rock_Ice"
    },
    {
      "x": -25,
      "y": 33,
      "z": -16,
      "name": "Rock_Ice"
    },
    {
      "x": -25,
      "y": 34,
      "z": -16,
      "name": "Rock_Ice"
    },
    {
      "x": -25,
      "y": 35,
      "z": -16,
      "name": "Rock_Ice"
    },
    {
      "x": -25,
      "y": 36,
      "z": -16,
      "name": "Rock_Ice"
    },
    {
      "x": -25,
      "y": 37,
      "z": -16,
      "name": "Soil_Snow"
    },
    {
      "x": -25,
      "y": 22,
      "z": -15,
      "name": "Rock_Ice_Permafrost"
    },
    {
      "x": -25,
      "y": 23,
      "z": -15,
      "name": "Rock_Ice_Permafrost"
    },
    {
      "x": -25,
      "y": 24,
      "z": -15,
      "name": "Rock_Ice_Permafrost"
    },
    {
      "x": -25,
      "y": 25,
      "z": -15,
      "name": "Rock_Ice_Permafrost"
    },
    {
      "x": -25,
      "y": 26,
      "z": -15,
      "name": "Rock_Ice_Permafrost"
    },
    {
      "x": -25,
      "y": 27,
      "z": -15,
      "name": "Rock_Ice_Permafrost"
    },
    {
      "x": -25,
      "y": 28,
      "z": -15,
      "name": "Rock_Ice_Permafrost"
    },
    {
      "x": -25,
      "y": 29,
      "z": -15,
      "name": "Rock_Ice_Permafrost"
    },
    {
      "x": -25,
      "y": 30,
      "z": -15,
      "name": "Rock_Ice_Permafrost"
    },
    {
      "x": -25,
      "y": 31,
      "z": -15,
      "name": "Rock_Ice"
    },
    {
      "x": -25,
      "y": 32,
      "z": -15,
      "name": "Rock_Ice"
    },
    {
      "x": -25,
      "y": 33,
      "z": -15,
      "name": "Rock_Ice"
    },
    {
      "x": -25,
      "y": 34,
      "z": -15,
      "name": "Rock_Ice"
    },
    {
      "x": -25,
      "y": 35,
      "z": -15,
      "name": "Rock_Ice"
    },
    {
      "x": -25,
      "y": 36,
      "z": -15,
      "name": "Rock_Ice"
    },
    {
      "x": -25,
      "y": 37,
      "z": -15,
      "name": "Soil_Snow"
    },
    {
      "x": -25,
      "y": 20,
      "z": -14,
      "name": "Rock_Ice_Permafrost"
    },
    {
      "x": -25,
      "y": 21,
      "z": -14,
      "name": "Rock_Ice_Permafrost"
    },
    {
      "x": -25,
      "y": 22,
      "z": -14,
      "name": "Rock_Ice_Permafrost"
    },
    {
      "x": -25,
      "y": 23,
      "z": -14,
      "name": "Rock_Ice_Permafrost"
    },
    {
      "x": -25,
      "y": 24,
      "z": -14,
      "name": "Rock_Ice_Permafrost"
    },
    {
      "x": -25,
      "y": 25,
      "z": -14,
      "name": "Rock_Ice_Permafrost"
    },
    {
      "x": -25,
      "y": 26,
      "z": -14,
      "name": "Rock_Ice_Permafrost"
    },
    {
      "x": -25,
      "y": 27,
      "z": -14,
      "name": "Rock_Ice_Permafrost"
    },
    {
      "x": -25,
      "y": 28,
      "z": -14,
      "name": "Rock_Ice_Permafrost"
    },
    {
      "x": -25,
      "y": 29,
      "z": -14,
      "name": "Rock_Ice"
    },
    {
      "x": -25,
      "y": 30,
      "z": -14,
      "name": "Rock_Ice_Permafrost"
    },
    {
      "x": -25,
      "y": 31,
      "z": -14,
      "name": "Rock_Ice"
    },
    {
      "x": -25,
      "y": 32,
      "z": -14,
      "name": "Rock_Ice"
    },
    {
      "x": -25,
      "y": 33,
      "z": -14,
      "name": "Rock_Ice"
    },
    {
      "x": -25,
      "y": 34,
      "z": -14,
      "name": "Rock_Ice"
    },
    {
      "x": -25,
      "y": 35,
      "z": -14,
      "name": "Rock_Ice"
    },
    {
      "x": -25,
      "y": 36,
      "z": -14,
      "name": "Rock_Ice_Permafrost"
    },
    {
      "x": -25,
      "y": 37,
      "z": -14,
      "name": "Rock_Ice"
    },
    {
      "x": -25,
      "y": 38,
      "z": -14,
      "name": "Soil_Snow"
    },
    {
      "x": -25,
      "y": 19,
      "z": -13,
      "name": "Rock_Ice_Permafrost"
    },
    {
      "x": -25,
      "y": 20,
      "z": -13,
      "name": "Rock_Ice_Permafrost"
    },
    {
      "x": -25,
      "y": 21,
      "z": -13,
      "name": "Rock_Ice_Permafrost"
    },
    {
      "x": -25,
      "y": 22,
      "z": -13,
      "name": "Rock_Ice_Permafrost"
    },
    {
      "x": -25,
      "y": 23,
      "z": -13,
      "name": "Rock_Ice_Permafrost"
    },
    {
      "x": -25,
      "y": 24,
      "z": -13,
      "name": "Rock_Ice_Permafrost"
    },
    {
      "x": -25,
      "y": 25,
      "z": -13,
      "name": "Rock_Ice_Permafrost"
    },
    {
      "x": -25,
      "y": 26,
      "z": -13,
      "name": "Rock_Ice_Permafrost"
    },
    {
      "x": -25,
      "y": 27,
      "z": -13,
      "name": "Rock_Ice_Permafrost"
    },
    {
      "x": -25,
      "y": 28,
      "z": -13,
      "name": "Rock_Ice_Permafrost"
    },
    {
      "x": -25,
      "y": 29,
      "z": -13,
      "name": "Rock_Ice_Permafrost"
    },
    {
      "x": -25,
      "y": 30,
      "z": -13,
      "name": "Rock_Ice_Permafrost"
    },
    {
      "x": -25,
      "y": 31,
      "z": -13,
      "name": "Rock_Ice"
    },
    {
      "x": -25,
      "y": 32,
      "z": -13,
      "name": "Rock_Ice"
    },
    {
      "x": -25,
      "y": 33,
      "z": -13,
      "name": "Rock_Ice_Permafrost"
    },
    {
      "x": -25,
      "y": 34,
      "z": -13,
      "name": "Rock_Ice"
    },
    {
      "x": -25,
      "y": 35,
      "z": -13,
      "name": "Rock_Ice_Permafrost"
    },
    {
      "x": -25,
      "y": 36,
      "z": -13,
      "name": "Rock_Ice_Permafrost"
    },
    {
      "x": -25,
      "y": 37,
      "z": -13,
      "name": "Rock_Ice_Permafrost"
    },
    {
      "x": -25,
      "y": 38,
      "z": -13,
      "name": "Rock_Ice"
    },
    {
      "x": -25,
      "y": 39,
      "z": -13,
      "name": "Soil_Snow"
    },
    {
      "x": -25,
      "y": 18,
      "z": -12,
      "name": "Rock_Ice"
    },
    {
      "x": -25,
      "y": 19,
      "z": -12,
      "name": "Rock_Ice"
    },
    {
      "x": -25,
      "y": 20,
      "z": -12,
      "name": "Rock_Ice"
    },
    {
      "x": -25,
      "y": 21,
      "z": -12,
      "name": "Rock_Ice"
    },
    {
      "x": -25,
      "y": 22,
      "z": -12,
      "name": "Rock_Ice"
    },
    {
      "x": -25,
      "y": 23,
      "z": -12,
      "name": "Rock_Ice_Permafrost"
    },
    {
      "x": -25,
      "y": 24,
      "z": -12,
      "name": "Rock_Ice_Permafrost"
    },
    {
      "x": -25,
      "y": 25,
      "z": -12,
      "name": "Rock_Ice_Permafrost"
    },
    {
      "x": -25,
      "y": 26,
      "z": -12,
      "name": "Rock_Ice_Permafrost"
    },
    {
      "x": -25,
      "y": 27,
      "z": -12,
      "name": "Rock_Ice_Permafrost"
    },
    {
      "x": -25,
      "y": 28,
      "z": -12,
      "name": "Rock_Ice_Permafrost"
    },
    {
      "x": -25,
      "y": 29,
      "z": -12,
      "name": "Rock_Ice_Permafrost"
    },
    {
      "x": -25,
      "y": 30,
      "z": -12,
      "name": "Rock_Ice"
    },
    {
      "x": -25,
      "y": 31,
      "z": -12,
      "name": "Rock_Ice"
    },
    {
      "x": -25,
      "y": 32,
      "z": -12,
      "name": "Rock_Ice_Permafrost"
    },
    {
      "x": -25,
      "y": 33,
      "z": -12,
      "name": "Rock_Ice_Permafrost"
    },
    {
      "x": -25,
      "y": 34,
      "z": -12,
      "name": "Rock_Ice_Permafrost"
    },
    {
      "x": -25,
      "y": 35,
      "z": -12,
      "name": "Rock_Ice_Permafrost"
    },
    {
      "x": -25,
      "y": 36,
      "z": -12,
      "name": "Rock_Ice_Permafrost"
    },
    {
      "x": -25,
      "y": 37,
      "z": -12,
      "name": "Rock_Ice_Permafrost"
    },
    {
      "x": -25,
      "y": 38,
      "z": -12,
      "name": "Rock_Ice_Permafrost"
    },
    {
      "x": -25,
      "y": 39,
      "z": -12,
      "name": "Rock_Ice"
    },
    {
      "x": -25,
      "y": 40,
      "z": -12,
      "name": "Soil_Snow"
    },
    {
      "x": -25,
      "y": 16,
      "z": -11,
      "name": "Rock_Ice"
    },
    {
      "x": -25,
      "y": 17,
      "z": -11,
      "name": "Rock_Ice"
    },
    {
      "x": -25,
      "y": 18,
      "z": -11,
      "name": "Rock_Ice"
    },
    {
      "x": -25,
      "y": 19,
      "z": -11,
      "name": "Rock_Ice"
    },
    {
      "x": -25,
      "y": 20,
      "z": -11,
      "name": "Rock_Ice"
    },
    {
      "x": -25,
      "y": 21,
      "z": -11,
      "name": "Rock_Ice"
    },
    {
      "x": -25,
      "y": 22,
      "z": -11,
      "name": "Rock_Ice"
    },
    {
      "x": -25,
      "y": 23,
      "z": -11,
      "name": "Rock_Ice"
    },
    {
      "x": -25,
      "y": 24,
      "z": -11,
      "name": "Rock_Ice"
    },
    {
      "x": -25,
      "y": 25,
      "z": -11,
      "name": "Rock_Ice_Permafrost"
    },
    {
      "x": -25,
      "y": 26,
      "z": -11,
      "name": "Rock_Ice_Permafrost"
    },
    {
      "x": -25,
      "y": 27,
      "z": -11,
      "name": "Rock_Ice_Permafrost"
    },
    {
      "x": -25,
      "y": 28,
      "z": -11,
      "name": "Rock_Ice_Permafrost"
    },
    {
      "x": -25,
      "y": 29,
      "z": -11,
      "name": "Rock_Ice_Permafrost"
    },
    {
      "x": -25,
      "y": 30,
      "z": -11,
      "name": "Rock_Ice_Permafrost"
    },
    {
      "x": -25,
      "y": 31,
      "z": -11,
      "name": "Rock_Ice_Permafrost"
    },
    {
      "x": -25,
      "y": 32,
      "z": -11,
      "name": "Rock_Ice_Permafrost"
    },
    {
      "x": -25,
      "y": 33,
      "z": -11,
      "name": "Rock_Ice_Permafrost"
    },
    {
      "x": -25,
      "y": 34,
      "z": -11,
      "name": "Rock_Ice_Permafrost"
    },
    {
      "x": -25,
      "y": 35,
      "z": -11,
      "name": "Rock_Ice_Permafrost"
    },
    {
      "x": -25,
      "y": 36,
      "z": -11,
      "name": "Rock_Ice_Permafrost"
    },
    {
      "x": -25,
      "y": 37,
      "z": -11,
      "name": "Rock_Ice_Permafrost"
    },
    {
      "x": -25,
      "y": 38,
      "z": -11,
      "name": "Rock_Ice_Permafrost"
    },
    {
      "x": -25,
      "y": 39,
      "z": -11,
      "name": "Rock_Ice"
    },
    {
      "x": -25,
      "y": 40,
      "z": -11,
      "name": "Soil_Snow"
    },
    {
      "x": -25,
      "y": 15,
      "z": -10,
      "name": "Rock_Ice"
    },
    {
      "x": -25,
      "y": 16,
      "z": -10,
      "name": "Rock_Ice"
    },
    {
      "x": -25,
      "y": 17,
      "z": -10,
      "name": "Rock_Ice"
    },
    {
      "x": -25,
      "y": 18,
      "z": -10,
      "name": "Rock_Ice"
    },
    {
      "x": -25,
      "y": 19,
      "z": -10,
      "name": "Rock_Ice"
    },
    {
      "x": -25,
      "y": 20,
      "z": -10,
      "name": "Rock_Ice"
    },
    {
      "x": -25,
      "y": 21,
      "z": -10,
      "name": "Rock_Ice"
    },
    {
      "x": -25,
      "y": 22,
      "z": -10,
      "name": "Rock_Ice"
    },
    {
      "x": -25,
      "y": 23,
      "z": -10,
      "name": "Rock_Ice_Permafrost"
    },
    {
      "x": -25,
      "y": 24,
      "z": -10,
      "name": "Rock_Ice_Permafrost"
    },
    {
      "x": -25,
      "y": 25,
      "z": -10,
      "name": "Rock_Ice_Permafrost"
    },
    {
      "x": -25,
      "y": 26,
      "z": -10,
      "name": "Rock_Ice_Permafrost"
    },
    {
      "x": -25,
      "y": 27,
      "z": -10,
      "name": "Rock_Ice_Permafrost"
    },
    {
      "x": -25,
      "y": 28,
      "z": -10,
      "name": "Rock_Ice_Permafrost"
    },
    {
      "x": -25,
      "y": 29,
      "z": -10,
      "name": "Rock_Ice_Permafrost"
    },
    {
      "x": -25,
      "y": 30,
      "z": -10,
      "name": "Rock_Ice_Permafrost"
    },
    {
      "x": -25,
      "y": 31,
      "z": -10,
      "name": "Rock_Ice_Permafrost"
    },
    {
      "x": -25,
      "y": 32,
      "z": -10,
      "name": "Rock_Ice_Permafrost"
    },
    {
      "x": -25,
      "y": 33,
      "z": -10,
      "name": "Rock_Ice_Permafrost"
    },
    {
      "x": -25,
      "y": 34,
      "z": -10,
      "name": "Rock_Ice_Permafrost"
    },
    {
      "x": -25,
      "y": 35,
      "z": -10,
      "name": "Rock_Ice_Permafrost"
    },
    {
      "x": -25,
      "y": 36,
      "z": -10,
      "name": "Rock_Ice_Permafrost"
    },
    {
      "x": -25,
      "y": 37,
      "z": -10,
      "name": "Rock_Ice"
    },
    {
      "x": -25,
      "y": 38,
      "z": -10,
      "name": "Rock_Ice"
    },
    {
      "x": -25,
      "y": 39,
      "z": -10,
      "name": "Rock_Ice"
    },
    {
      "x": -25,
      "y": 40,
      "z": -10,
      "name": "Soil_Snow"
    },
    {
      "x": -25,
      "y": 14,
      "z": -9,
      "name": "Rock_Ice"
    },
    {
      "x": -25,
      "y": 15,
      "z": -9,
      "name": "Rock_Ice"
    },
    {
      "x": -25,
      "y": 16,
      "z": -9,
      "name": "Rock_Ice"
    },
    {
      "x": -25,
      "y": 17,
      "z": -9,
      "name": "Rock_Ice"
    },
    {
      "x": -25,
      "y": 18,
      "z": -9,
      "name": "Rock_Ice"
    },
    {
      "x": -25,
      "y": 19,
      "z": -9,
      "name": "Rock_Ice"
    },
    {
      "x": -25,
      "y": 20,
      "z": -9,
      "name": "Rock_Ice"
    },
    {
      "x": -25,
      "y": 21,
      "z": -9,
      "name": "Rock_Ice"
    },
    {
      "x": -25,
      "y": 22,
      "z": -9,
      "name": "Rock_Ice"
    },
    {
      "x": -25,
      "y": 23,
      "z": -9,
      "name": "Rock_Ice_Permafrost"
    },
    {
      "x": -25,
      "y": 24,
      "z": -9,
      "name": "Rock_Ice_Permafrost"
    },
    {
      "x": -25,
      "y": 25,
      "z": -9,
      "name": "Rock_Ice_Permafrost"
    },
    {
      "x": -25,
      "y": 26,
      "z": -9,
      "name": "Rock_Ice_Permafrost"
    },
    {
      "x": -25,
      "y": 27,
      "z": -9,
      "name": "Rock_Ice_Permafrost"
    },
    {
      "x": -25,
      "y": 28,
      "z": -9,
      "name": "Rock_Ice_Permafrost"
    },
    {
      "x": -25,
      "y": 29,
      "z": -9,
      "name": "Rock_Ice_Permafrost"
    },
    {
      "x": -25,
      "y": 30,
      "z": -9,
      "name": "Rock_Ice_Permafrost"
    },
    {
      "x": -25,
      "y": 31,
      "z": -9,
      "name": "Rock_Ice_Permafrost"
    },
    {
      "x": -25,
      "y": 32,
      "z": -9,
      "name": "Rock_Ice_Permafrost"
    },
    {
      "x": -25,
      "y": 33,
      "z": -9,
      "name": "Rock_Ice_Permafrost"
    },
    {
      "x": -25,
      "y": 34,
      "z": -9,
      "name": "Rock_Ice_Permafrost"
    },
    {
      "x": -25,
      "y": 35,
      "z": -9,
      "name": "Rock_Ice"
    },
    {
      "x": -25,
      "y": 36,
      "z": -9,
      "name": "Rock_Ice"
    },
    {
      "x": -25,
      "y": 37,
      "z": -9,
      "name": "Rock_Ice"
    },
    {
      "x": -25,
      "y": 38,
      "z": -9,
      "name": "Rock_Ice"
    },
    {
      "x": -25,
      "y": 39,
      "z": -9,
      "name": "Rock_Ice"
    },
    {
      "x": -25,
      "y": 40,
      "z": -9,
      "name": "Soil_Snow"
    },
    {
      "x": -25,
      "y": 13,
      "z": -8,
      "name": "Rock_Ice"
    },
    {
      "x": -25,
      "y": 14,
      "z": -8,
      "name": "Rock_Ice"
    },
    {
      "x": -25,
      "y": 15,
      "z": -8,
      "name": "Rock_Ice"
    },
    {
      "x": -25,
      "y": 16,
      "z": -8,
      "name": "Rock_Ice"
    },
    {
      "x": -25,
      "y": 17,
      "z": -8,
      "name": "Rock_Ice"
    },
    {
      "x": -25,
      "y": 18,
      "z": -8,
      "name": "Rock_Ice"
    },
    {
      "x": -25,
      "y": 19,
      "z": -8,
      "name": "Rock_Ice"
    },
    {
      "x": -25,
      "y": 20,
      "z": -8,
      "name": "Rock_Ice_Permafrost"
    },
    {
      "x": -25,
      "y": 21,
      "z": -8,
      "name": "Rock_Ice_Permafrost"
    },
    {
      "x": -25,
      "y": 22,
      "z": -8,
      "name": "Rock_Ice_Permafrost"
    },
    {
      "x": -25,
      "y": 23,
      "z": -8,
      "name": "Rock_Ice_Permafrost"
    },
    {
      "x": -25,
      "y": 24,
      "z": -8,
      "name": "Rock_Ice_Permafrost"
    },
    {
      "x": -25,
      "y": 25,
      "z": -8,
      "name": "Rock_Ice_Permafrost"
    },
    {
      "x": -25,
      "y": 26,
      "z": -8,
      "name": "Rock_Ice_Permafrost"
    },
    {
      "x": -25,
      "y": 27,
      "z": -8,
      "name": "Rock_Ice_Permafrost"
    },
    {
      "x": -25,
      "y": 28,
      "z": -8,
      "name": "Rock_Ice_Permafrost"
    },
    {
      "x": -25,
      "y": 29,
      "z": -8,
      "name": "Rock_Ice_Permafrost"
    },
    {
      "x": -25,
      "y": 30,
      "z": -8,
      "name": "Rock_Ice_Permafrost"
    },
    {
      "x": -25,
      "y": 31,
      "z": -8,
      "name": "Rock_Ice_Permafrost"
    },
    {
      "x": -25,
      "y": 32,
      "z": -8,
      "name": "Rock_Ice"
    },
    {
      "x": -25,
      "y": 33,
      "z": -8,
      "name": "Rock_Ice"
    },
    {
      "x": -25,
      "y": 34,
      "z": -8,
      "name": "Rock_Ice"
    },
    {
      "x": -25,
      "y": 35,
      "z": -8,
      "name": "Rock_Ice"
    },
    {
      "x": -25,
      "y": 36,
      "z": -8,
      "name": "Rock_Ice"
    },
    {
      "x": -25,
      "y": 37,
      "z": -8,
      "name": "Rock_Ice"
    },
    {
      "x": -25,
      "y": 38,
      "z": -8,
      "name": "Rock_Ice"
    },
    {
      "x": -25,
      "y": 39,
      "z": -8,
      "name": "Soil_Snow"
    },
    {
      "x": -25,
      "y": 14,
      "z": -7,
      "name": "Rock_Ice"
    },
    {
      "x": -25,
      "y": 15,
      "z": -7,
      "name": "Rock_Ice"
    },
    {
      "x": -25,
      "y": 16,
      "z": -7,
      "name": "Rock_Ice"
    },
    {
      "x": -25,
      "y": 17,
      "z": -7,
      "name": "Rock_Ice_Permafrost"
    },
    {
      "x": -25,
      "y": 18,
      "z": -7,
      "name": "Rock_Ice_Permafrost"
    },
    {
      "x": -25,
      "y": 19,
      "z": -7,
      "name": "Rock_Ice_Permafrost"
    },
    {
      "x": -25,
      "y": 20,
      "z": -7,
      "name": "Rock_Ice_Permafrost"
    },
    {
      "x": -25,
      "y": 21,
      "z": -7,
      "name": "Rock_Ice_Permafrost"
    },
    {
      "x": -25,
      "y": 22,
      "z": -7,
      "name": "Rock_Ice_Permafrost"
    },
    {
      "x": -25,
      "y": 23,
      "z": -7,
      "name": "Rock_Ice_Permafrost"
    },
    {
      "x": -25,
      "y": 24,
      "z": -7,
      "name": "Rock_Ice_Permafrost"
    },
    {
      "x": -25,
      "y": 25,
      "z": -7,
      "name": "Rock_Ice_Permafrost"
    },
    {
      "x": -25,
      "y": 26,
      "z": -7,
      "name": "Rock_Ice_Permafrost"
    },
    {
      "x": -25,
      "y": 27,
      "z": -7,
      "name": "Rock_Ice_Permafrost"
    },
    {
      "x": -25,
      "y": 28,
      "z": -7,
      "name": "Rock_Ice_Permafrost"
    },
    {
      "x": -25,
      "y": 29,
      "z": -7,
      "name": "Rock_Ice_Permafrost"
    },
    {
      "x": -25,
      "y": 30,
      "z": -7,
      "name": "Rock_Ice_Permafrost"
    },
    {
      "x": -25,
      "y": 31,
      "z": -7,
      "name": "Rock_Ice"
    },
    {
      "x": -25,
      "y": 32,
      "z": -7,
      "name": "Rock_Ice_Permafrost"
    },
    {
      "x": -25,
      "y": 33,
      "z": -7,
      "name": "Rock_Ice"
    },
    {
      "x": -25,
      "y": 34,
      "z": -7,
      "name": "Rock_Ice"
    },
    {
      "x": -25,
      "y": 35,
      "z": -7,
      "name": "Rock_Ice"
    },
    {
      "x": -25,
      "y": 36,
      "z": -7,
      "name": "Rock_Ice"
    },
    {
      "x": -25,
      "y": 37,
      "z": -7,
      "name": "Rock_Ice"
    },
    {
      "x": -25,
      "y": 38,
      "z": -7,
      "name": "Rock_Ice"
    },
    {
      "x": -25,
      "y": 39,
      "z": -7,
      "name": "Soil_Snow"
    },
    {
      "x": -25,
      "y": 14,
      "z": -6,
      "name": "Rock_Ice"
    },
    {
      "x": -25,
      "y": 15,
      "z": -6,
      "name": "Rock_Ice"
    },
    {
      "x": -25,
      "y": 16,
      "z": -6,
      "name": "Rock_Ice_Permafrost"
    },
    {
      "x": -25,
      "y": 17,
      "z": -6,
      "name": "Rock_Ice_Permafrost"
    },
    {
      "x": -25,
      "y": 18,
      "z": -6,
      "name": "Rock_Ice_Permafrost"
    },
    {
      "x": -25,
      "y": 19,
      "z": -6,
      "name": "Rock_Ice_Permafrost"
    },
    {
      "x": -25,
      "y": 20,
      "z": -6,
      "name": "Rock_Ice_Permafrost"
    },
    {
      "x": -25,
      "y": 21,
      "z": -6,
      "name": "Rock_Ice_Permafrost"
    },
    {
      "x": -25,
      "y": 22,
      "z": -6,
      "name": "Rock_Ice_Permafrost"
    },
    {
      "x": -25,
      "y": 23,
      "z": -6,
      "name": "Rock_Ice_Permafrost"
    },
    {
      "x": -25,
      "y": 24,
      "z": -6,
      "name": "Rock_Ice_Permafrost"
    },
    {
      "x": -25,
      "y": 25,
      "z": -6,
      "name": "Rock_Ice_Permafrost"
    },
    {
      "x": -25,
      "y": 26,
      "z": -6,
      "name": "Rock_Ice_Permafrost"
    },
    {
      "x": -25,
      "y": 27,
      "z": -6,
      "name": "Rock_Ice_Permafrost"
    },
    {
      "x": -25,
      "y": 28,
      "z": -6,
      "name": "Rock_Ice_Permafrost"
    },
    {
      "x": -25,
      "y": 29,
      "z": -6,
      "name": "Rock_Ice_Permafrost"
    },
    {
      "x": -25,
      "y": 30,
      "z": -6,
      "name": "Rock_Ice"
    },
    {
      "x": -25,
      "y": 31,
      "z": -6,
      "name": "Rock_Ice"
    },
    {
      "x": -25,
      "y": 32,
      "z": -6,
      "name": "Rock_Ice"
    },
    {
      "x": -25,
      "y": 33,
      "z": -6,
      "name": "Rock_Ice"
    },
    {
      "x": -25,
      "y": 34,
      "z": -6,
      "name": "Rock_Ice"
    },
    {
      "x": -25,
      "y": 35,
      "z": -6,
      "name": "Rock_Ice"
    },
    {
      "x": -25,
      "y": 36,
      "z": -6,
      "name": "Rock_Ice"
    },
    {
      "x": -25,
      "y": 37,
      "z": -6,
      "name": "Rock_Ice"
    },
    {
      "x": -25,
      "y": 38,
      "z": -6,
      "name": "Rock_Ice"
    },
    {
      "x": -25,
      "y": 39,
      "z": -6,
      "name": "Rock_Ice"
    },
    {
      "x": -25,
      "y": 40,
      "z": -6,
      "name": "Soil_Snow"
    },
    {
      "x": -25,
      "y": 14,
      "z": -5,
      "name": "Rock_Ice_Permafrost"
    },
    {
      "x": -25,
      "y": 15,
      "z": -5,
      "name": "Rock_Ice_Permafrost"
    },
    {
      "x": -25,
      "y": 16,
      "z": -5,
      "name": "Rock_Ice_Permafrost"
    },
    {
      "x": -25,
      "y": 17,
      "z": -5,
      "name": "Rock_Ice_Permafrost"
    },
    {
      "x": -25,
      "y": 18,
      "z": -5,
      "name": "Rock_Ice_Permafrost"
    },
    {
      "x": -25,
      "y": 19,
      "z": -5,
      "name": "Rock_Ice_Permafrost"
    },
    {
      "x": -25,
      "y": 20,
      "z": -5,
      "name": "Rock_Ice_Permafrost"
    },
    {
      "x": -25,
      "y": 21,
      "z": -5,
      "name": "Rock_Ice"
    },
    {
      "x": -25,
      "y": 22,
      "z": -5,
      "name": "Rock_Ice"
    },
    {
      "x": -25,
      "y": 23,
      "z": -5,
      "name": "Rock_Ice_Permafrost"
    },
    {
      "x": -25,
      "y": 24,
      "z": -5,
      "name": "Rock_Ice_Permafrost"
    },
    {
      "x": -25,
      "y": 25,
      "z": -5,
      "name": "Rock_Ice_Permafrost"
    },
    {
      "x": -25,
      "y": 26,
      "z": -5,
      "name": "Rock_Ice_Permafrost"
    },
    {
      "x": -25,
      "y": 27,
      "z": -5,
      "name": "Rock_Ice_Permafrost"
    },
    {
      "x": -25,
      "y": 28,
      "z": -5,
      "name": "Rock_Ice_Permafrost"
    },
    {
      "x": -25,
      "y": 29,
      "z": -5,
      "name": "Rock_Ice"
    },
    {
      "x": -25,
      "y": 30,
      "z": -5,
      "name": "Rock_Ice"
    },
    {
      "x": -25,
      "y": 31,
      "z": -5,
      "name": "Rock_Ice"
    },
    {
      "x": -25,
      "y": 32,
      "z": -5,
      "name": "Rock_Ice"
    },
    {
      "x": -25,
      "y": 33,
      "z": -5,
      "name": "Rock_Ice"
    },
    {
      "x": -25,
      "y": 34,
      "z": -5,
      "name": "Rock_Ice"
    },
    {
      "x": -25,
      "y": 35,
      "z": -5,
      "name": "Rock_Ice"
    },
    {
      "x": -25,
      "y": 36,
      "z": -5,
      "name": "Rock_Ice"
    },
    {
      "x": -25,
      "y": 37,
      "z": -5,
      "name": "Rock_Ice"
    },
    {
      "x": -25,
      "y": 38,
      "z": -5,
      "name": "Rock_Ice"
    },
    {
      "x": -25,
      "y": 39,
      "z": -5,
      "name": "Rock_Ice"
    },
    {
      "x": -25,
      "y": 40,
      "z": -5,
      "name": "Soil_Snow"
    },
    {
      "x": -25,
      "y": 14,
      "z": -4,
      "name": "Rock_Ice_Permafrost"
    },
    {
      "x": -25,
      "y": 15,
      "z": -4,
      "name": "Rock_Ice_Permafrost"
    },
    {
      "x": -25,
      "y": 16,
      "z": -4,
      "name": "Rock_Ice_Permafrost"
    },
    {
      "x": -25,
      "y": 17,
      "z": -4,
      "name": "Rock_Ice_Permafrost"
    },
    {
      "x": -25,
      "y": 18,
      "z": -4,
      "name": "Rock_Ice_Permafrost"
    },
    {
      "x": -25,
      "y": 19,
      "z": -4,
      "name": "Rock_Ice"
    },
    {
      "x": -25,
      "y": 20,
      "z": -4,
      "name": "Rock_Ice"
    },
    {
      "x": -25,
      "y": 21,
      "z": -4,
      "name": "Rock_Ice"
    },
    {
      "x": -25,
      "y": 22,
      "z": -4,
      "name": "Rock_Ice"
    },
    {
      "x": -25,
      "y": 23,
      "z": -4,
      "name": "Rock_Ice"
    },
    {
      "x": -25,
      "y": 24,
      "z": -4,
      "name": "Rock_Ice"
    },
    {
      "x": -25,
      "y": 25,
      "z": -4,
      "name": "Rock_Ice_Permafrost"
    },
    {
      "x": -25,
      "y": 26,
      "z": -4,
      "name": "Rock_Ice_Permafrost"
    },
    {
      "x": -25,
      "y": 27,
      "z": -4,
      "name": "Rock_Ice_Permafrost"
    },
    {
      "x": -25,
      "y": 28,
      "z": -4,
      "name": "Rock_Ice"
    },
    {
      "x": -25,
      "y": 29,
      "z": -4,
      "name": "Rock_Ice"
    },
    {
      "x": -25,
      "y": 30,
      "z": -4,
      "name": "Rock_Ice"
    },
    {
      "x": -25,
      "y": 31,
      "z": -4,
      "name": "Rock_Ice"
    },
    {
      "x": -25,
      "y": 32,
      "z": -4,
      "name": "Rock_Ice"
    },
    {
      "x": -25,
      "y": 33,
      "z": -4,
      "name": "Rock_Ice"
    },
    {
      "x": -25,
      "y": 34,
      "z": -4,
      "name": "Rock_Ice"
    },
    {
      "x": -25,
      "y": 35,
      "z": -4,
      "name": "Rock_Ice"
    },
    {
      "x": -25,
      "y": 36,
      "z": -4,
      "name": "Rock_Ice"
    },
    {
      "x": -25,
      "y": 37,
      "z": -4,
      "name": "Rock_Ice"
    },
    {
      "x": -25,
      "y": 38,
      "z": -4,
      "name": "Rock_Ice"
    },
    {
      "x": -25,
      "y": 39,
      "z": -4,
      "name": "Rock_Ice"
    },
    {
      "x": -25,
      "y": 40,
      "z": -4,
      "name": "Soil_Snow"
    },
    {
      "x": -25,
      "y": 16,
      "z": -3,
      "name": "Rock_Ice_Permafrost"
    },
    {
      "x": -25,
      "y": 17,
      "z": -3,
      "name": "Rock_Ice_Permafrost"
    },
    {
      "x": -25,
      "y": 18,
      "z": -3,
      "name": "Rock_Ice_Permafrost"
    },
    {
      "x": -25,
      "y": 19,
      "z": -3,
      "name": "Rock_Ice"
    },
    {
      "x": -25,
      "y": 20,
      "z": -3,
      "name": "Rock_Ice"
    },
    {
      "x": -25,
      "y": 21,
      "z": -3,
      "name": "Rock_Ice"
    },
    {
      "x": -25,
      "y": 22,
      "z": -3,
      "name": "Rock_Ice"
    },
    {
      "x": -25,
      "y": 23,
      "z": -3,
      "name": "Rock_Ice"
    },
    {
      "x": -25,
      "y": 24,
      "z": -3,
      "name": "Rock_Ice_Permafrost"
    },
    {
      "x": -25,
      "y": 25,
      "z": -3,
      "name": "Rock_Ice_Permafrost"
    },
    {
      "x": -25,
      "y": 26,
      "z": -3,
      "name": "Rock_Ice_Permafrost"
    },
    {
      "x": -25,
      "y": 27,
      "z": -3,
      "name": "Rock_Ice_Permafrost"
    },
    {
      "x": -25,
      "y": 28,
      "z": -3,
      "name": "Rock_Ice_Permafrost"
    },
    {
      "x": -25,
      "y": 29,
      "z": -3,
      "name": "Rock_Ice"
    },
    {
      "x": -25,
      "y": 30,
      "z": -3,
      "name": "Rock_Ice"
    },
    {
      "x": -25,
      "y": 31,
      "z": -3,
      "name": "Rock_Ice"
    },
    {
      "x": -25,
      "y": 32,
      "z": -3,
      "name": "Rock_Ice"
    },
    {
      "x": -25,
      "y": 33,
      "z": -3,
      "name": "Rock_Ice"
    },
    {
      "x": -25,
      "y": 34,
      "z": -3,
      "name": "Rock_Ice"
    },
    {
      "x": -25,
      "y": 35,
      "z": -3,
      "name": "Rock_Ice"
    },
    {
      "x": -25,
      "y": 36,
      "z": -3,
      "name": "Rock_Ice"
    },
    {
      "x": -25,
      "y": 37,
      "z": -3,
      "name": "Rock_Ice"
    },
    {
      "x": -25,
      "y": 38,
      "z": -3,
      "name": "Rock_Ice"
    },
    {
      "x": -25,
      "y": 39,
      "z": -3,
      "name": "Rock_Ice"
    },
    {
      "x": -25,
      "y": 40,
      "z": -3,
      "name": "Rock_Ice"
    },
    {
      "x": -25,
      "y": 16,
      "z": -2,
      "name": "Rock_Ice_Permafrost"
    },
    {
      "x": -25,
      "y": 17,
      "z": -2,
      "name": "Rock_Ice"
    },
    {
      "x": -25,
      "y": 18,
      "z": -2,
      "name": "Rock_Ice"
    },
    {
      "x": -25,
      "y": 19,
      "z": -2,
      "name": "Rock_Ice"
    },
    {
      "x": -25,
      "y": 20,
      "z": -2,
      "name": "Rock_Ice"
    },
    {
      "x": -25,
      "y": 21,
      "z": -2,
      "name": "Rock_Ice"
    },
    {
      "x": -25,
      "y": 22,
      "z": -2,
      "name": "Rock_Ice"
    },
    {
      "x": -25,
      "y": 23,
      "z": -2,
      "name": "Rock_Ice_Permafrost"
    },
    {
      "x": -25,
      "y": 24,
      "z": -2,
      "name": "Rock_Ice_Permafrost"
    },
    {
      "x": -25,
      "y": 25,
      "z": -2,
      "name": "Rock_Ice_Permafrost"
    },
    {
      "x": -25,
      "y": 26,
      "z": -2,
      "name": "Rock_Ice_Permafrost"
    },
    {
      "x": -25,
      "y": 27,
      "z": -2,
      "name": "Rock_Ice_Permafrost"
    },
    {
      "x": -25,
      "y": 28,
      "z": -2,
      "name": "Rock_Ice_Permafrost"
    },
    {
      "x": -25,
      "y": 29,
      "z": -2,
      "name": "Rock_Ice"
    },
    {
      "x": -25,
      "y": 30,
      "z": -2,
      "name": "Rock_Ice"
    },
    {
      "x": -25,
      "y": 31,
      "z": -2,
      "name": "Rock_Ice"
    },
    {
      "x": -25,
      "y": 32,
      "z": -2,
      "name": "Rock_Ice"
    },
    {
      "x": -25,
      "y": 33,
      "z": -2,
      "name": "Rock_Ice"
    },
    {
      "x": -25,
      "y": 34,
      "z": -2,
      "name": "Rock_Ice"
    },
    {
      "x": -25,
      "y": 35,
      "z": -2,
      "name": "Rock_Ice"
    },
    {
      "x": -25,
      "y": 36,
      "z": -2,
      "name": "Soil_Snow"
    },
    {
      "x": -25,
      "y": 16,
      "z": -1,
      "name": "Rock_Ice"
    },
    {
      "x": -25,
      "y": 17,
      "z": -1,
      "name": "Rock_Ice"
    },
    {
      "x": -25,
      "y": 18,
      "z": -1,
      "name": "Rock_Ice"
    },
    {
      "x": -25,
      "y": 19,
      "z": -1,
      "name": "Rock_Ice"
    },
    {
      "x": -25,
      "y": 20,
      "z": -1,
      "name": "Rock_Ice"
    },
    {
      "x": -25,
      "y": 21,
      "z": -1,
      "name": "Rock_Ice"
