{
  "version": 8,
  "blockIdVersion": 11,
  "anchorX": -2,
  "anchorY": 18,
  "anchorZ": 9,
  "blocks": [
    {
      "x": -26,
      "y": 18,
      "z": -3,
      "name": "Rock_Ice"
    },
    {
      "x": -26,
      "y": 19,
      "z": -3,
      "name": "Soil_Snow"
    },
    {
      "x": -26,
      "y": 18,
      "z": -2,
      "name": "Rock_Ice"
    },
    {
      "x": -26,
      "y": 19,
      "z": -2,
      "name": "Rock_Ice_Permafrost"
    },
    {
      "x": -26,
      "y": 20,
      "z": -2,
      "name": "Rock_Ice_Permafrost"
    },
    {
      "x": -26,
      "y": 21,
      "z": -2,
      "name": "Rock_Ice"
    },
    {
      "x": -26,
      "y": 22,
      "z": -2,
      "name": "Soil_Snow"
    },
    {
      "x": -26,
      "y": 19,
      "z": -1,
      "name": "Rock_Ice_Permafrost"
    },
    {
      "x": -26,
      "y": 20,
      "z": -1,
      "name": "Rock_Ice_Permafrost"
    },
    {
      "x": -26,
      "y": 21,
      "z": -1,
      "name": "Soil_Snow"
    },
    {
      "x": -26,
      "y": 17,
      "z": 3,
      "name": "Soil_Snow"
    },
    {
      "x": -26,
      "y": 17,
      "z": 4,
      "name": "Soil_Snow"
    },
    {
      "x": -26,
      "y": 16,
      "z": 5,
      "name": "Soil_Snow"
    },
    {
      "x": -26,
      "y": 16,
      "z": 6,
      "name": "Soil_Snow"
    },
    {
      "x": -25,
      "y": 16,
      "z": -5,
      "name": "Rock_Ice"
    },
    {
      "x": -25,
      "y": 17,
      "z": -5,
      "name": "Rock_Ice"
    },
    {
      "x": -25,
      "y": 16,
      "z": -4,
      "name": "Rock_Ice"
    },
    {
      "x": -25,
      "y": 17,
      "z": -4,
      "name": "Rock_Ice"
    },
    {
      "x": -25,
      "y": 18,
      "z": -4,
      "name": "Rock_Ice"
    },
    {
      "x": -25,
      "y": 19,
      "z": -4,
      "name": "Rock_Ice"
    },
    {
      "x": -25,
      "y": 20,
      "z": -4,
      "name": "Soil_Snow"
    },
    {
      "x": -25,
      "y": 17,
      "z": -3,
      "name": "Rock_Ice"
    },
    {
      "x": -25,
      "y": 18,
      "z": -3,
      "name": "Rock_Ice"
    },
    {
      "x": -25,
      "y": 19,
      "z": -3,
      "name": "Rock_Ice"
    },
    {
      "x": -25,
      "y": 20,
      "z": -3,
      "name": "Rock_Ice"
    },
    {
      "x": -25,
      "y": 21,
      "z": -3,
      "name": "Rock_Ice_Permafrost"
    },
    {
      "x": -25,
      "y": 22,
      "z": -3,
      "name": "Rock_Ice"
    },
    {
      "x": -25,
      "y": 23,
      "z": -3,
      "name": "Soil_Snow"
    },
    {
      "x": -25,
      "y": 17,
      "z": -2,
      "name": "Rock_Ice"
    },
    {
      "x": -25,
      "y": 18,
      "z": -2,
      "name": "Rock_Ice"
    },
    {
      "x": -25,
      "y": 19,
      "z": -2,
      "name": "Rock_Ice"
    },
    {
      "x": -25,
      "y": 20,
      "z": -2,
      "name": "Rock_Ice"
    },
    {
      "x": -25,
      "y": 21,
      "z": -2,
      "name": "Rock_Ice_Permafrost"
    },
    {
      "x": -25,
      "y": 22,
      "z": -2,
      "name": "Rock_Ice_Permafrost"
    },
    {
      "x": -25,
      "y": 23,
      "z": -2,
      "name": "Rock_Ice_Permafrost"
    },
    {
      "x": -25,
      "y": 24,
      "z": -2,
      "name": "Rock_Ice"
    },
    {
      "x": -25,
      "y": 25,
      "z": -2,
      "name": "Soil_Snow"
    },
    {
      "x": -25,
      "y": 18,
      "z": -1,
      "name": "Rock_Ice"
    },
    {
      "x": -25,
      "y": 19,
      "z": -1,
      "name": "Rock_Ice"
    },
    {
      "x": -25,
      "y": 20,
      "z": -1,
      "name": "Rock_Ice"
    },
    {
      "x": -25,
      "y": 21,
      "z": -1,
      "name": "Rock_Ice_Permafrost"
    },
    {
      "x": -25,
      "y": 22,
      "z": -1,
      "name": "Rock_Ice"
    },
    {
      "x": -25,
      "y": 23,
      "z": -1,
      "name": "Soil_Snow"
    },
    {
      "x": -25,
      "y": 19,
      "z": 0,
      "name": "Rock_Ice"
    },
    {
      "x": -25,
      "y": 20,
      "z": 0,
      "name": "Rock_Ice"
    },
    {
      "x": -25,
      "y": 21,
      "z": 0,
      "name": "Soil_Snow"
    },
    {
      "x": -25,
      "y": 18,
      "z": 1,
      "name": "Rock_Ice"
    },
    {
      "x": -25,
      "y": 19,
      "z": 1,
      "name": "Soil_Snow"
    },
    {
      "x": -25,
      "y": 16,
      "z": 2,
      "name": "Rock_Ice"
    },
    {
      "x": -25,
      "y": 17,
      "z": 2,
      "name": "Rock_Ice"
    },
    {
      "x": -25,
      "y": 18,
      "z": 2,
      "name": "Rock_Ice"
    },
    {
      "x": -25,
      "y": 19,
      "z": 2,
      "name": "Soil_Snow"
    },
    {
      "x": -25,
      "y": 15,
      "z": 3,
      "name": "Rock_Ice"
    },
    {
      "x": -25,
      "y": 16,
      "z": 3,
      "name": "Rock_Ice"
    },
    {
      "x": -25,
      "y": 17,
      "z": 3,
      "name": "Rock_Ice"
    },
    {
      "x": -25,
      "y": 18,
      "z": 3,
      "name": "Rock_Ice"
    },
    {
      "x": -25,
      "y": 19,
      "z": 3,
      "name": "Soil_Snow"
    },
    {
      "x": -25,
      "y": 15,
      "z": 4,
      "name": "Rock_Ice_Permafrost"
    },
    {
      "x": -25,
      "y": 16,
      "z": 4,
      "name": "Rock_Ice_Permafrost"
    },
    {
      "x": -25,
      "y": 17,
      "z": 4,
      "name": "Rock_Ice"
    },
    {
      "x": -25,
      "y": 18,
      "z": 4,
      "name": "Soil_Snow"
    },
    {
      "x": -25,
      "y": 15,
      "z": 5,
      "name": "Rock_Ice_Permafrost"
    },
    {
      "x": -25,
      "y": 16,
      "z": 5,
      "name": "Rock_Ice_Permafrost"
    },
    {
      "x": -25,
      "y": 17,
      "z": 5,
      "name": "Rock_Ice"
    },
    {
      "x": -25,
      "y": 18,
      "z": 5,
      "name": "Soil_Snow"
    },
    {
      "x": -25,
      "y": 14,
      "z": 6,
      "name": "Rock_Ice"
    },
    {
      "x": -25,
      "y": 15,
      "z": 6,
      "name": "Rock_Ice_Permafrost"
    },
    {
      "x": -25,
      "y": 16,
      "z": 6,
      "name": "Rock_Ice"
    },
    {
      "x": -25,
      "y": 17,
      "z": 6,
      "name": "Soil_Snow"
    },
    {
      "x": -25,
      "y": 14,
      "z": 7,
      "name": "Rock_Ice"
    },
    {
      "x": -25,
      "y": 15,
      "z": 7,
      "name": "Rock_Ice"
    },
    {
      "x": -25,
      "y": 16,
      "z": 7,
      "name": "Rock_Ice"
    },
    {
      "x": -25,
      "y": 17,
      "z": 7,
      "name": "Soil_Snow"
    },
    {
      "x": -25,
      "y": 15,
      "z": 8,
      "name": "Rock_Ice"
    },
    {
      "x": -25,
      "y": 16,
      "z": 8,
      "name": "Soil_Snow"
    },
    {
      "x": -25,
      "y": 15,
      "z": 9,
      "name": "Soil_Snow"
    },
    {
      "x": -24,
      "y": 18,
      "z": -12,
      "name": "Soil_Snow"
    },
    {
      "x": -24,
      "y": 15,
      "z": -6,
      "name": "Rock_Ice"
    },
    {
      "x": -24,
      "y": 16,
      "z": -6,
      "name": "Rock_Ice"
    },
    {
      "x": -24,
      "y": 17,
      "z": -6,
      "name": "Rock_Ice"
    },
    {
      "x": -24,
      "y": 15,
      "z": -5,
      "name": "Rock_Ice"
    },
    {
      "x": -24,
      "y": 16,
      "z": -5,
      "name": "Rock_Ice"
    },
    {
      "x": -24,
      "y": 17,
      "z": -5,
      "name": "Rock_Ice"
    },
    {
      "x": -24,
      "y": 18,
      "z": -5,
      "name": "Rock_Ice"
    },
    {
      "x": -24,
      "y": 19,
      "z": -5,
      "name": "Rock_Ice"
    },
    {
      "x": -24,
      "y": 20,
      "z": -5,
      "name": "Rock_Ice"
    },
    {
      "x": -24,
      "y": 21,
      "z": -5,
      "name": "Soil_Snow"
    },
    {
      "x": -24,
      "y": 15,
      "z": -4,
      "name": "Rock_Ice"
    },
    {
      "x": -24,
      "y": 16,
      "z": -4,
      "name": "Rock_Ice"
    },
    {
      "x": -24,
      "y": 17,
      "z": -4,
      "name": "Rock_Ice"
    },
    {
      "x": -24,
      "y": 18,
      "z": -4,
      "name": "Rock_Ice"
    },
    {
      "x": -24,
      "y": 19,
      "z": -4,
      "name": "Rock_Ice"
    },
    {
      "x": -24,
      "y": 20,
      "z": -4,
      "name": "Rock_Ice"
    },
    {
      "x": -24,
      "y": 21,
      "z": -4,
      "name": "Rock_Ice"
    },
    {
      "x": -24,
      "y": 22,
      "z": -4,
      "name": "Rock_Ice"
    },
    {
      "x": -24,
      "y": 23,
      "z": -4,
      "name": "Soil_Snow"
    },
    {
      "x": -24,
      "y": 16,
      "z": -3,
      "name": "Rock_Ice"
    },
    {
      "x": -24,
      "y": 17,
      "z": -3,
      "name": "Rock_Ice"
    },
    {
      "x": -24,
      "y": 18,
      "z": -3,
      "name": "Rock_Ice"
    },
    {
      "x": -24,
      "y": 19,
      "z": -3,
      "name": "Rock_Ice"
    },
    {
      "x": -24,
      "y": 20,
      "z": -3,
      "name": "Rock_Ice"
    },
    {
      "x": -24,
      "y": 21,
      "z": -3,
      "name": "Rock_Ice"
    },
    {
      "x": -24,
      "y": 22,
      "z": -3,
      "name": "Rock_Ice_Permafrost"
    },
    {
      "x": -24,
      "y": 23,
      "z": -3,
      "name": "Rock_Ice_Permafrost"
    },
    {
      "x": -24,
      "y": 24,
      "z": -3,
      "name": "Rock_Ice"
    },
    {
      "x": -24,
      "y": 25,
      "z": -3,
      "name": "Soil_Snow"
    },
    {
      "x": -24,
      "y": 16,
      "z": -2,
      "name": "Rock_Ice"
    },
    {
      "x": -24,
      "y": 17,
      "z": -2,
      "name": "Rock_Ice"
    },
    {
      "x": -24,
      "y": 18,
      "z": -2,
      "name": "Rock_Ice"
    },
    {
      "x": -24,
      "y": 19,
      "z": -2,
      "name": "Rock_Ice"
    },
    {
      "x": -24,
      "y": 20,
      "z": -2,
      "name": "Rock_Ice"
    },
    {
      "x": -24,
      "y": 21,
      "z": -2,
      "name": "Rock_Ice"
    },
    {
      "x": -24,
      "y": 22,
      "z": -2,
      "name": "Rock_Ice"
    },
    {
      "x": -24,
      "y": 23,
      "z": -2,
      "name": "Rock_Ice_Permafrost"
    },
    {
      "x": -24,
      "y": 24,
      "z": -2,
      "name": "Rock_Ice_Permafrost"
    },
    {
      "x": -24,
      "y": 25,
      "z": -2,
      "name": "Rock_Ice"
    },
    {
      "x": -24,
      "y": 26,
      "z": -2,
      "name": "Soil_Snow"
    },
    {
      "x": -24,
      "y": 17,
      "z": -1,
      "name": "Rock_Ice"
    },
    {
      "x": -24,
      "y": 18,
      "z": -1,
      "name": "Rock_Ice"
    },
    {
      "x": -24,
      "y": 19,
      "z": -1,
      "name": "Rock_Ice"
    },
    {
      "x": -24,
      "y": 20,
      "z": -1,
      "name": "Rock_Ice"
    },
    {
      "x": -24,
      "y": 21,
      "z": -1,
      "name": "Rock_Ice"
    },
    {
      "x": -24,
      "y": 22,
      "z": -1,
      "name": "Rock_Ice_Permafrost"
    },
    {
      "x": -24,
      "y": 23,
      "z": -1,
      "name": "Rock_Ice_Permafrost"
    },
    {
      "x": -24,
      "y": 24,
      "z": -1,
      "name": "Rock_Ice"
    },
    {
      "x": -24,
      "y": 25,
      "z": -1,
      "name": "Soil_Snow"
    },
    {
      "x": -24,
      "y": 18,
      "z": 0,
      "name": "Rock_Ice"
    },
    {
      "x": -24,
      "y": 19,
      "z": 0,
      "name": "Rock_Ice"
    },
    {
      "x": -24,
      "y": 20,
      "z": 0,
      "name": "Rock_Ice"
    },
    {
      "x": -24,
      "y": 21,
      "z": 0,
      "name": "Rock_Ice"
    },
    {
      "x": -24,
      "y": 22,
      "z": 0,
      "name": "Rock_Ice"
    },
    {
      "x": -24,
      "y": 23,
      "z": 0,
      "name": "Soil_Snow"
    },
    {
      "x": -24,
      "y": 16,
      "z": 1,
      "name": "Rock_Ice"
    },
    {
      "x": -24,
      "y": 17,
      "z": 1,
      "name": "Rock_Ice"
    },
    {
      "x": -24,
      "y": 18,
      "z": 1,
      "name": "Rock_Ice"
    },
    {
      "x": -24,
      "y": 19,
      "z": 1,
      "name": "Rock_Ice"
    },
    {
      "x": -24,
      "y": 20,
      "z": 1,
      "name": "Rock_Ice"
    },
    {
      "x": -24,
      "y": 21,
      "z": 1,
      "name": "Soil_Snow"
    },
    {
      "x": -24,
      "y": 14,
      "z": 2,
      "name": "Rock_Ice"
    },
    {
      "x": -24,
      "y": 15,
      "z": 2,
      "name": "Rock_Ice"
    },
    {
      "x": -24,
      "y": 16,
      "z": 2,
      "name": "Rock_Ice"
    },
    {
      "x": -24,
      "y": 17,
      "z": 2,
      "name": "Rock_Ice"
    },
    {
      "x": -24,
      "y": 18,
      "z": 2,
      "name": "Rock_Ice"
    },
    {
      "x": -24,
      "y": 19,
      "z": 2,
      "name": "Rock_Ice"
    },
    {
      "x": -24,
      "y": 20,
      "z": 2,
      "name": "Rock_Ice"
    },
    {
      "x": -24,
      "y": 21,
      "z": 2,
      "name": "Soil_Snow"
    },
    {
      "x": -24,
      "y": 14,
      "z": 3,
      "name": "Rock_Ice"
    },
    {
      "x": -24,
      "y": 15,
      "z": 3,
      "name": "Rock_Ice"
    },
    {
      "x": -24,
      "y": 16,
      "z": 3,
      "name": "Rock_Ice"
    },
    {
      "x": -24,
      "y": 17,
      "z": 3,
      "name": "Rock_Ice"
    },
    {
      "x": -24,
      "y": 18,
      "z": 3,
      "name": "Rock_Ice"
    },
    {
      "x": -24,
      "y": 19,
      "z": 3,
      "name": "Rock_Ice"
    },
    {
      "x": -24,
      "y": 20,
      "z": 3,
      "name": "Rock_Ice"
    },
    {
      "x": -24,
      "y": 21,
      "z": 3,
      "name": "Soil_Snow"
    },
    {
      "x": -24,
      "y": 14,
      "z": 4,
      "name": "Rock_Ice"
    },
    {
      "x": -24,
      "y": 15,
      "z": 4,
      "name": "Rock_Ice"
    },
    {
      "x": -24,
      "y": 16,
      "z": 4,
      "name": "Rock_Ice"
    },
    {
      "x": -24,
      "y": 17,
      "z": 4,
      "name": "Rock_Ice"
    },
    {
      "x": -24,
      "y": 18,
      "z": 4,
      "name": "Rock_Ice"
    },
    {
      "x": -24,
      "y": 19,
      "z": 4,
      "name": "Rock_Ice"
    },
    {
      "x": -24,
      "y": 20,
      "z": 4,
      "name": "Soil_Snow"
    },
    {
      "x": -24,
      "y": 13,
      "z": 5,
      "name": "Rock_Ice_Permafrost"
    },
    {
      "x": -24,
      "y": 14,
      "z": 5,
      "name": "Rock_Ice_Permafrost"
    },
    {
      "x": -24,
      "y": 15,
      "z": 5,
      "name": "Rock_Ice_Permafrost"
    },
    {
      "x": -24,
      "y": 16,
      "z": 5,
      "name": "Rock_Ice_Permafrost"
    },
    {
      "x": -24,
      "y": 17,
      "z": 5,
      "name": "Rock_Ice_Permafrost"
    },
    {
      "x": -24,
      "y": 18,
      "z": 5,
      "name": "Rock_Ice_Permafrost"
    },
    {
      "x": -24,
      "y": 19,
      "z": 5,
      "name": "Rock_Ice"
    },
    {
      "x": -24,
      "y": 20,
      "z": 5,
      "name": "Soil_Snow"
    },
    {
      "x": -24,
      "y": 13,
      "z": 6,
      "name": "Rock_Ice_Permafrost"
    },
    {
      "x": -24,
      "y": 14,
      "z": 6,
      "name": "Rock_Ice_Permafrost"
    },
    {
      "x": -24,
      "y": 15,
      "z": 6,
      "name": "Rock_Ice_Permafrost"
    },
    {
      "x": -24,
      "y": 16,
      "z": 6,
      "name": "Rock_Ice_Permafrost"
    },
    {
      "x": -24,
      "y": 17,
      "z": 6,
      "name": "Rock_Ice_Permafrost"
    },
    {
      "x": -24,
      "y": 18,
      "z": 6,
      "name": "Rock_Ice"
    },
    {
      "x": -24,
      "y": 19,
      "z": 6,
      "name": "Soil_Snow"
    },
    {
      "x": -24,
      "y": 13,
      "z": 7,
      "name": "Rock_Ice_Permafrost"
    },
    {
      "x": -24,
      "y": 14,
      "z": 7,
      "name": "Rock_Ice_Permafrost"
    },
    {
      "x": -24,
      "y": 15,
      "z": 7,
      "name": "Rock_Ice"
    },
    {
      "x": -24,
      "y": 16,
      "z": 7,
      "name": "Rock_Ice"
    },
    {
      "x": -24,
      "y": 17,
      "z": 7,
      "name": "Rock_Ice"
    },
    {
      "x": -24,
      "y": 18,
      "z": 7,
      "name": "Soil_Snow"
    },
    {
      "x": -24,
      "y": 13,
      "z": 8,
      "name": "Rock_Ice"
    },
    {
      "x": -24,
      "y": 14,
      "z": 8,
      "name": "Rock_Ice"
    },
    {
      "x": -24,
      "y": 15,
      "z": 8,
      "name": "Rock_Ice"
    },
    {
      "x": -24,
      "y": 16,
      "z": 8,
      "name": "Rock_Ice"
    },
    {
      "x": -24,
      "y": 17,
      "z": 8,
      "name": "Rock_Ice"
    },
    {
      "x": -24,
      "y": 18,
      "z": 8,
      "name": "Soil_Snow"
    },
    {
      "x": -24,
      "y": 13,
      "z": 9,
      "name": "Rock_Ice"
    },
    {
      "x": -24,
      "y": 14,
      "z": 9,
      "name": "Rock_Ice"
    },
    {
      "x": -24,
      "y": 15,
      "z": 9,
      "name": "Rock_Ice"
    },
    {
      "x": -24,
      "y": 16,
      "z": 9,
      "name": "Rock_Ice"
    },
    {
      "x": -24,
      "y": 17,
      "z": 9,
      "name": "Soil_Snow"
    },
    {
      "x": -24,
      "y": 14,
      "z": 10,
      "name": "Rock_Ice"
    },
    {
      "x": -24,
      "y": 15,
      "z": 10,
      "name": "Rock_Ice"
    },
    {
      "x": -24,
      "y": 16,
      "z": 10,
      "name": "Soil_Snow"
    },
    {
      "x": -24,
      "y": 14,
      "z": 11,
      "name": "Soil_Snow"
    },
    {
      "x": -23,
      "y": 25,
      "z": -15,
      "name": "Soil_Snow"
    },
    {
      "x": -23,
      "y": 23,
      "z": -14,
      "name": "Soil_Snow"
    },
    {
      "x": -23,
      "y": 21,
      "z": -13,
      "name": "Rock_Ice"
    },
    {
      "x": -23,
      "y": 22,
      "z": -13,
      "name": "Soil_Snow"
    },
    {
      "x": -23,
      "y": 18,
      "z": -12,
      "name": "Rock_Ice"
    },
    {
      "x": -23,
      "y": 19,
      "z": -12,
      "name": "Rock_Ice"
    },
    {
      "x": -23,
      "y": 20,
      "z": -12,
      "name": "Rock_Ice"
    },
    {
      "x": -23,
      "y": 21,
      "z": -12,
      "name": "Rock_Ice"
    },
    {
      "x": -23,
      "y": 22,
      "z": -12,
      "name": "Soil_Snow"
    },
    {
      "x": -23,
      "y": 17,
      "z": -11,
      "name": "Rock_Ice_Permafrost"
    },
    {
      "x": -23,
      "y": 18,
      "z": -11,
      "name": "Rock_Ice_Permafrost"
    },
    {
      "x": -23,
      "y": 19,
      "z": -11,
      "name": "Rock_Ice"
    },
    {
      "x": -23,
      "y": 20,
      "z": -11,
      "name": "Rock_Ice"
    },
    {
      "x": -23,
      "y": 21,
      "z": -11,
      "name": "Soil_Snow"
    },
    {
      "x": -23,
      "y": 17,
      "z": -10,
      "name": "Rock_Ice_Permafrost"
    },
    {
      "x": -23,
      "y": 18,
      "z": -10,
      "name": "Rock_Ice"
    },
    {
      "x": -23,
      "y": 19,
      "z": -10,
      "name": "Rock_Ice_Permafrost"
    },
    {
      "x": -23,
      "y": 20,
      "z": -10,
      "name": "Rock_Ice"
    },
    {
      "x": -23,
      "y": 21,
      "z": -10,
      "name": "Soil_Snow"
    },
    {
      "x": -23,
      "y": 17,
      "z": -9,
      "name": "Rock_Ice"
    },
    {
      "x": -23,
      "y": 18,
      "z": -9,
      "name": "Rock_Ice"
    },
    {
      "x": -23,
      "y": 19,
      "z": -9,
      "name": "Rock_Ice"
    },
    {
      "x": -23,
      "y": 20,
      "z": -9,
      "name": "Rock_Ice"
    },
    {
      "x": -23,
      "y": 21,
      "z": -9,
      "name": "Soil_Snow"
    },
    {
      "x": -23,
      "y": 18,
      "z": -8,
      "name": "Rock_Ice"
    },
    {
      "x": -23,
      "y": 19,
      "z": -8,
      "name": "Rock_Ice"
    },
    {
      "x": -23,
      "y": 20,
      "z": -8,
      "name": "Rock_Ice"
    },
    {
      "x": -23,
      "y": 21,
      "z": -8,
      "name": "Soil_Snow"
    },
    {
      "x": -23,
      "y": 14,
      "z": -7,
      "name": "Rock_Ice"
    },
    {
      "x": -23,
      "y": 18,
      "z": -7,
      "name": "Rock_Ice"
    },
    {
      "x": -23,
      "y": 19,
      "z": -7,
      "name": "Rock_Ice"
    },
    {
      "x": -23,
      "y": 20,
      "z": -7,
      "name": "Rock_Ice"
    },
    {
      "x": -23,
      "y": 21,
      "z": -7,
      "name": "Rock_Ice"
    },
    {
      "x": -23,
      "y": 22,
      "z": -7,
      "name": "Soil_Snow"
    },
    {
      "x": -23,
      "y": 14,
      "z": -6,
      "name": "Rock_Ice"
    },
    {
      "x": -23,
      "y": 15,
      "z": -6,
      "name": "Rock_Ice"
    },
    {
      "x": -23,
      "y": 16,
      "z": -6,
      "name": "Rock_Ice"
    },
    {
      "x": -23,
      "y": 17,
      "z": -6,
      "name": "Rock_Ice"
    },
    {
      "x": -23,
      "y": 18,
      "z": -6,
      "name": "Rock_Ice"
    },
    {
      "x": -23,
      "y": 19,
      "z": -6,
      "name": "Rock_Ice"
    },
    {
      "x": -23,
      "y": 20,
      "z": -6,
      "name": "Rock_Ice"
    },
    {
      "x": -23,
      "y": 21,
      "z": -6,
      "name": "Rock_Ice"
    },
    {
      "x": -23,
      "y": 22,
      "z": -6,
      "name": "Soil_Snow"
    },
    {
      "x": -23,
      "y": 15,
      "z": -5,
      "name": "Rock_Ice"
    },
    {
      "x": -23,
      "y": 16,
      "z": -5,
      "name": "Rock_Ice"
    },
    {
      "x": -23,
      "y": 17,
      "z": -5,
      "name": "Rock_Ice"
    },
    {
      "x": -23,
      "y": 18,
      "z": -5,
      "name": "Rock_Ice"
    },
    {
      "x": -23,
      "y": 19,
      "z": -5,
      "name": "Rock_Ice"
    },
    {
      "x": -23,
      "y": 20,
      "z": -5,
      "name": "Rock_Ice"
    },
    {
      "x": -23,
      "y": 21,
      "z": -5,
      "name": "Rock_Ice"
    },
    {
      "x": -23,
      "y": 22,
      "z": -5,
      "name": "Rock_Ice"
    },
    {
      "x": -23,
      "y": 23,
      "z": -5,
      "name": "Rock_Ice"
    },
    {
      "x": -23,
      "y": 24,
      "z": -5,
      "name": "Soil_Snow"
    },
    {
      "x": -23,
      "y": 15,
      "z": -4,
      "name": "Rock_Ice"
    },
    {
      "x": -23,
      "y": 16,
      "z": -4,
      "name": "Rock_Ice"
    },
    {
      "x": -23,
      "y": 17,
      "z": -4,
      "name": "Rock_Ice"
    },
    {
      "x": -23,
      "y": 18,
      "z": -4,
      "name": "Rock_Ice"
    },
    {
      "x": -23,
      "y": 19,
      "z": -4,
      "name": "Rock_Ice"
    },
    {
      "x": -23,
      "y": 20,
      "z": -4,
      "name": "Rock_Ice"
    },
    {
      "x": -23,
      "y": 21,
      "z": -4,
      "name": "Rock_Ice"
    },
    {
      "x": -23,
      "y": 22,
      "z": -4,
      "name": "Rock_Ice"
    },
    {
      "x": -23,
      "y": 23,
      "z": -4,
      "name": "Rock_Ice_Permafrost"
    },
    {
      "x": -23,
      "y": 24,
      "z": -4,
      "name": "Rock_Ice_Permafrost"
    },
    {
      "x": -23,
      "y": 25,
      "z": -4,
      "name": "Rock_Ice"
    },
    {
      "x": -23,
      "y": 26,
      "z": -4,
      "name": "Soil_Snow"
    },
    {
      "x": -23,
      "y": 15,
      "z": -3,
      "name": "Rock_Ice"
    },
    {
      "x": -23,
      "y": 16,
      "z": -3,
      "name": "Rock_Ice"
    },
    {
      "x": -23,
      "y": 17,
      "z": -3,
      "name": "Rock_Ice"
    },
    {
      "x": -23,
      "y": 18,
      "z": -3,
      "name": "Rock_Ice"
    },
    {
      "x": -23,
      "y": 19,
      "z": -3,
      "name": "Rock_Ice"
    },
    {
      "x": -23,
      "y": 20,
      "z": -3,
      "name": "Rock_Ice"
    },
    {
      "x": -23,
      "y": 21,
      "z": -3,
      "name": "Rock_Ice"
    },
    {
      "x": -23,
      "y": 22,
      "z": -3,
      "name": "Rock_Ice"
    },
    {
      "x": -23,
      "y": 23,
      "z": -3,
      "name": "Rock_Ice_Permafrost"
    },
    {
      "x": -23,
      "y": 24,
      "z": -3,
      "name": "Rock_Ice_Permafrost"
    },
    {
      "x": -23,
      "y": 25,
      "z": -3,
      "name": "Rock_Ice_Permafrost"
    },
    {
      "x": -23,
      "y": 26,
      "z": -3,
      "name": "Rock_Ice_Permafrost"
    },
    {
      "x": -23,
      "y": 27,
      "z": -3,
      "name": "Rock_Ice"
    },
    {
      "x": -23,
      "y": 28,
      "z": -3,
      "name": "Soil_Snow"
    },
    {
      "x": -23,
      "y": 16,
      "z": -2,
      "name": "Rock_Ice"
    },
    {
      "x": -23,
      "y": 17,
      "z": -2,
      "name": "Rock_Ice"
    },
    {
      "x": -23,
      "y": 18,
      "z": -2,
      "name": "Rock_Ice"
    },
    {
      "x": -23,
      "y": 19,
      "z": -2,
      "name": "Rock_Ice"
    },
    {
      "x": -23,
      "y": 20,
      "z": -2,
      "name": "Rock_Ice"
    },
    {
      "x": -23,
      "y": 21,
      "z": -2,
      "name": "Rock_Ice"
    },
    {
      "x": -23,
      "y": 22,
      "z": -2,
      "name": "Rock_Ice"
    },
    {
      "x": -23,
      "y": 23,
      "z": -2,
      "name": "Rock_Ice_Permafrost"
    },
    {
      "x": -23,
      "y": 24,
      "z": -2,
      "name": "Rock_Ice_Permafrost"
    },
    {
      "x": -23,
      "y": 25,
      "z": -2,
      "name": "Rock_Ice_Permafrost"
    },
    {
      "x": -23,
      "y": 26,
      "z": -2,
      "name": "Rock_Ice_Permafrost"
    },
    {
      "x": -23,
      "y": 27,
      "z": -2,
      "name": "Rock_Ice"
    },
    {
      "x": -23,
      "y": 28,
      "z": -2,
      "name": "Soil_Snow"
    },
    {
      "x": -23,
      "y": 17,
      "z": -1,
      "name": "Rock_Ice"
    },
    {
      "x": -23,
      "y": 18,
      "z": -1,
      "name": "Rock_Ice"
    },
    {
      "x": -23,
      "y": 19,
      "z": -1,
      "name": "Rock_Ice"
    },
    {
      "x": -23,
      "y": 20,
      "z": -1,
      "name": "Rock_Ice"
    },
    {
      "x": -23,
      "y": 21,
      "z": -1,
      "name": "Rock_Ice"
    },
    {
      "x": -23,
      "y": 22,
      "z": -1,
      "name": "Rock_Ice"
    },
    {
      "x": -23,
      "y": 23,
      "z": -1,
      "name": "Rock_Ice_Permafrost"
    },
    {
      "x": -23,
      "y": 24,
      "z": -1,
      "name": "Rock_Ice_Permafrost"
    },
    {
      "x": -23,
      "y": 25,
      "z": -1,
      "name": "Rock_Ice_Permafrost"
    },
    {
      "x": -23,
      "y": 26,
      "z": -1,
      "name": "Rock_Ice"
    },
    {
      "x": -23,
      "y": 27,
      "z": -1,
      "name": "Soil_Snow"
    },
    {
      "x": -23,
      "y": 16,
      "z": 0,
      "name": "Rock_Ice"
    },
    {
      "x": -23,
      "y": 17,
      "z": 0,
      "name": "Rock_Ice"
    },
    {
      "x": -23,
      "y": 18,
      "z": 0,
      "name": "Rock_Ice"
    },
    {
      "x": -23,
      "y": 19,
      "z": 0,
      "name": "Rock_Ice"
    },
    {
      "x": -23,
      "y": 20,
      "z": 0,
      "name": "Rock_Ice"
    },
    {
      "x": -23,
      "y": 21,
      "z": 0,
      "name": "Rock_Ice"
    },
    {
      "x": -23,
      "y": 22,
      "z": 0,
      "name": "Rock_Ice"
    },
    {
      "x": -23,
      "y": 23,
      "z": 0,
      "name": "Rock_Ice_Permafrost"
    },
    {
      "x": -23,
      "y": 24,
      "z": 0,
      "name": "Rock_Ice_Permafrost"
    },
    {
      "x": -23,
      "y": 25,
      "z": 0,
      "name": "Rock_Ice_Permafrost"
    },
    {
      "x": -23,
      "y": 26,
      "z": 0,
      "name": "Rock_Ice"
    },
    {
      "x": -23,
      "y": 27,
      "z": 0,
      "name": "Soil_Snow"
    },
    {
      "x": -23,
      "y": 14,
      "z": 1,
      "name": "Rock_Ice"
    },
    {
      "x": -23,
      "y": 15,
      "z": 1,
      "name": "Rock_Ice"
    },
    {
      "x": -23,
      "y": 16,
      "z": 1,
      "name": "Rock_Ice"
    },
    {
      "x": -23,
      "y": 17,
      "z": 1,
      "name": "Rock_Ice"
    },
    {
      "x": -23,
      "y": 18,
      "z": 1,
      "name": "Rock_Ice"
    },
    {
      "x": -23,
      "y": 19,
      "z": 1,
      "name": "Rock_Ice"
    },
    {
      "x": -23,
      "y": 20,
      "z": 1,
      "name": "Rock_Ice"
    },
    {
      "x": -23,
      "y": 21,
      "z": 1,
      "name": "Rock_Ice"
    },
    {
      "x": -23,
      "y": 22,
      "z": 1,
      "name": "Rock_Ice"
    },
    {
      "x": -23,
      "y": 23,
      "z": 1,
      "name": "Rock_Ice_Permafrost"
    },
    {
      "x": -23,
      "y": 24,
      "z": 1,
      "name": "Rock_Ice_Permafrost"
    },
    {
      "x": -23,
      "y": 25,
      "z": 1,
      "name": "Rock_Ice_Permafrost"
    },
    {
      "x": -23,
      "y": 26,
      "z": 1,
      "name": "Rock_Ice"
    },
    {
      "x": -23,
      "y": 27,
      "z": 1,
      "name": "Soil_Snow"
    },
    {
      "x": -23,
      "y": 13,
      "z": 2,
      "name": "Rock_Ice"
    },
    {
      "x": -23,
      "y": 14,
      "z": 2,
      "name": "Rock_Ice"
    },
    {
      "x": -23,
      "y": 15,
      "z": 2,
      "name": "Rock_Ice"
    },
    {
      "x": -23,
      "y": 16,
      "z": 2,
      "name": "Rock_Ice"
    },
    {
      "x": -23,
      "y": 17,
      "z": 2,
      "name": "Rock_Ice"
    },
    {
      "x": -23,
      "y": 18,
      "z": 2,
      "name": "Rock_Ice"
    },
    {
      "x": -23,
      "y": 19,
      "z": 2,
      "name": "Rock_Ice"
    },
    {
      "x": -23,
      "y": 20,
      "z": 2,
      "name": "Rock_Ice"
    },
    {
      "x": -23,
      "y": 21,
      "z": 2,
      "name": "Rock_Ice"
    },
    {
      "x": -23,
      "y": 22,
      "z": 2,
      "name": "Rock_Ice_Permafrost"
    },
    {
      "x": -23,
      "y": 23,
      "z": 2,
      "name": "Rock_Ice_Permafrost"
    },
    {
      "x": -23,
      "y": 24,
      "z": 2,
      "name": "Rock_Ice_Permafrost"
    },
    {
      "x": -23,
      "y": 25,
      "z": 2,
      "name": "Rock_Ice"
    },
    {
      "x": -23,
      "y": 13,
      "z": 3,
      "name": "Rock_Ice"
    },
    {
      "x": -23,
      "y": 14,
      "z": 3,
      "name": "Rock_Ice"
    },
    {
      "x": -23,
      "y": 15,
      "z": 3,
      "name": "Rock_Ice"
    },
    {
      "x": -23,
      "y": 16,
      "z": 3,
      "name": "Rock_Ice"
    },
    {
      "x": -23,
      "y": 17,
      "z": 3,
      "name": "Rock_Ice"
    },
    {
      "x": -23,
      "y": 18,
      "z": 3,
      "name": "Rock_Ice"
    },
    {
      "x": -23,
      "y": 19,
      "z": 3,
      "name": "Rock_Ice"
    },
    {
      "x": -23,
      "y": 20,
      "z": 3,
      "name": "Rock_Ice"
    },
    {
      "x": -23,
      "y": 21,
      "z": 3,
      "name": "Rock_Ice"
    },
    {
      "x": -23,
      "y": 22,
      "z": 3,
      "name": "Rock_Ice"
    },
    {
      "x": -23,
      "y": 23,
      "z": 3,
      "name": "Soil_Snow"
    },
    {
      "x": -23,
      "y": 12,
      "z": 4,
      "name": "Rock_Ice"
    },
    {
      "x": -23,
      "y": 13,
      "z": 4,
      "name": "Rock_Ice"
    },
    {
      "x": -23,
      "y": 14,
      "z": 4,
      "name": "Rock_Ice"
    },
    {
      "x": -23,
      "y": 15,
      "z": 4,
      "name": "Rock_Ice"
    },
    {
      "x": -23,
      "y": 16,
      "z": 4,
      "name": "Rock_Ice"
    },
    {
      "x": -23,
      "y": 17,
      "z": 4,
      "name": "Rock_Ice"
    },
    {
      "x": -23,
      "y": 18,
      "z": 4,
      "name": "Rock_Ice"
    },
    {
      "x": -23,
      "y": 19,
      "z": 4,
      "name": "Rock_Ice"
    },
    {
      "x": -23,
      "y": 20,
      "z": 4,
      "name": "Rock_Ice"
    },
    {
      "x": -23,
      "y": 21,
      "z": 4,
      "name": "Rock_Ice"
    },
    {
      "x": -23,
      "y": 22,
      "z": 4,
      "name": "Rock_Ice"
    },
    {
      "x": -23,
      "y": 23,
      "z": 4,
      "name": "Soil_Snow"
    },
    {
      "x": -23,
      "y": 12,
      "z": 5,
      "name": "Rock_Ice_Permafrost"
    },
    {
      "x": -23,
      "y": 13,
      "z": 5,
      "name": "Rock_Ice"
    },
    {
      "x": -23,
      "y": 14,
      "z": 5,
      "name": "Rock_Ice"
    },
    {
      "x": -23,
      "y": 15,
      "z": 5,
      "name": "Rock_Ice_Permafrost"
    },
    {
      "x": -23,
      "y": 16,
      "z": 5,
      "name": "Rock_Ice"
    },
    {
      "x": -23,
      "y": 17,
      "z": 5,
      "name": "Rock_Ice"
    },
    {
      "x": -23,
      "y": 18,
      "z": 5,
      "name": "Rock_Ice"
    },
    {
      "x": -23,
      "y": 19,
      "z": 5,
      "name": "Rock_Ice_Permafrost"
    },
    {
      "x": -23,
      "y": 20,
      "z": 5,
      "name": "Rock_Ice_Permafrost"
    },
    {
      "x": -23,
      "y": 21,
      "z": 5,
      "name": "Rock_Ice"
    },
    {
      "x": -23,
      "y": 22,
      "z": 5,
      "name": "Soil_Snow"
    },
    {
      "x": -23,
      "y": 12,
      "z": 6,
      "name": "Rock_Ice_Permafrost"
    },
    {
      "x": -23,
      "y": 13,
      "z": 6,
      "name": "Rock_Ice_Permafrost"
    },
    {
      "x": -23,
      "y": 14,
      "z": 6,
      "name": "Rock_Ice_Permafrost"
    },
    {
      "x": -23,
      "y": 15,
      "z": 6,
      "name": "Rock_Ice_Permafrost"
    },
    {
      "x": -23,
      "y": 16,
      "z": 6,
      "name": "Rock_Ice_Permafrost"
    },
    {
      "x": -23,
      "y": 17,
      "z": 6,
      "name": "Rock_Ice_Permafrost"
    },
    {
      "x": -23,
      "y": 18,
      "z": 6,
      "name": "Rock_Ice_Permafrost"
    },
    {
      "x": -23,
      "y": 19,
      "z": 6,
      "name": "Rock_Ice_Permafrost"
    },
    {
      "x": -23,
      "y": 20,
      "z": 6,
      "name": "Rock_Ice"
    },
    {
      "x": -23,
      "y": 21,
      "z": 6,
      "name": "Soil_Snow"
    },
    {
      "x": -23,
      "y": 12,
      "z": 7,
      "name": "Rock_Ice_Permafrost"
    },
    {
      "x": -23,
      "y": 13,
      "z": 7,
      "name": "Rock_Ice_Permafrost"
    },
    {
      "x": -23,
      "y": 14,
      "z": 7,
      "name": "Rock_Ice_Permafrost"
    },
    {
      "x": -23,
      "y": 15,
      "z": 7,
      "name": "Rock_Ice_Permafrost"
    },
    {
      "x": -23,
      "y": 16,
      "z": 7,
      "name": "Rock_Ice_Permafrost"
    },
    {
      "x": -23,
      "y": 17,
      "z": 7,
      "name": "Rock_Ice_Permafrost"
    },
    {
      "x": -23,
      "y": 18,
      "z": 7,
      "name": "Rock_Ice_Permafrost"
    },
    {
      "x": -23,
      "y": 19,
      "z": 7,
      "name": "Rock_Ice"
    },
    {
      "x": -23,
      "y": 20,
      "z": 7,
      "name": "Soil_Snow"
    },
    {
      "x": -23,
      "y": 12,
      "z": 8,
      "name": "Rock_Ice"
    },
    {
      "x": -23,
      "y": 13,
      "z": 8,
      "name": "Rock_Ice"
    },
    {
      "x": -23,
      "y": 14,
      "z": 8,
      "name": "Rock_Ice"
    },
    {
      "x": -23,
      "y": 15,
      "z": 8,
      "name": "Rock_Ice"
    },
    {
      "x": -23,
      "y": 16,
      "z": 8,
      "name": "Rock_Ice"
    },
    {
      "x": -23,
      "y": 17,
      "z": 8,
      "name": "Rock_Ice"
    },
    {
      "x": -23,
      "y": 18,
      "z": 8,
      "name": "Rock_Ice"
    },
    {
      "x": -23,
      "y": 19,
      "z": 8,
      "name": "Soil_Snow"
    },
    {
      "x": -23,
      "y": 12,
      "z": 9,
      "name": "Rock_Ice"
    },
    {
      "x": -23,
      "y": 13,
      "z": 9,
      "name": "Rock_Ice"
    },
    {
      "x": -23,
      "y": 14,
      "z": 9,
      "name": "Rock_Ice"
    },
    {
      "x": -23,
      "y": 15,
      "z": 9,
      "name": "Rock_Ice"
    },
    {
      "x": -23,
      "y": 16,
      "z": 9,
      "name": "Rock_Ice"
    },
    {
      "x": -23,
      "y": 17,
      "z": 9,
      "name": "Rock_Ice"
    },
    {
      "x": -23,
      "y": 18,
      "z": 9,
      "name": "Rock_Ice"
    },
    {
      "x": -23,
      "y": 19,
      "z": 9,
      "name": "Soil_Snow"
    },
    {
      "x": -23,
      "y": 12,
      "z": 10,
      "name": "Rock_Ice"
    },
    {
      "x": -23,
      "y": 13,
      "z": 10,
      "name": "Rock_Ice"
    },
    {
      "x": -23,
      "y": 14,
      "z": 10,
      "name": "Rock_Ice"
    },
    {
      "x": -23,
      "y": 15,
      "z": 10,
      "name": "Rock_Ice"
    },
    {
      "x": -23,
      "y": 16,
      "z": 10,
      "name": "Rock_Ice"
    },
    {
      "x": -23,
      "y": 17,
      "z": 10,
      "name": "Rock_Ice"
    },
    {
      "x": -23,
      "y": 18,
      "z": 10,
      "name": "Soil_Snow"
    },
    {
      "x": -23,
      "y": 13,
      "z": 11,
      "name": "Rock_Ice"
    },
    {
      "x": -23,
      "y": 14,
      "z": 11,
      "name": "Rock_Ice"
    },
    {
      "x": -23,
      "y": 15,
      "z": 11,
      "name": "Rock_Ice"
    },
    {
      "x": -23,
      "y": 16,
      "z": 11,
      "name": "Rock_Ice"
    },
    {
      "x": -23,
      "y": 17,
      "z": 11,
      "name": "Soil_Snow"
    },
    {
      "x": -23,
      "y": 13,
      "z": 12,
      "name": "Rock_Ice"
    },
    {
      "x": -23,
      "y": 14,
      "z": 12,
      "name": "Rock_Ice"
    },
    {
      "x": -23,
      "y": 15,
      "z": 12,
      "name": "Rock_Ice"
    },
    {
      "x": -23,
      "y": 16,
      "z": 12,
      "name": "Soil_Snow"
    },
    {
      "x": -22,
      "y": 28,
      "z": -16,
      "name": "Soil_Snow"
    },
    {
      "x": -22,
      "y": 25,
      "z": -15,
      "name": "Rock_Ice_Permafrost"
    },
    {
      "x": -22,
      "y": 26,
      "z": -15,
      "name": "Rock_Ice"
    },
    {
      "x": -22,
      "y": 27,
      "z": -15,
      "name": "Soil_Snow"
    },
    {
      "x": -22,
      "y": 23,
      "z": -14,
      "name": "Rock_Ice"
    },
    {
      "x": -22,
      "y": 24,
      "z": -14,
      "name": "Rock_Ice_Permafrost"
    },
    {
      "x": -22,
      "y": 25,
      "z": -14,
      "name": "Rock_Ice"
    },
    {
      "x": -22,
      "y": 26,
      "z": -14,
      "name": "Soil_Snow"
    },
    {
      "x": -22,
      "y": 21,
      "z": -13,
      "name": "Rock_Ice"
    },
    {
      "x": -22,
      "y": 22,
      "z": -13,
      "name": "Rock_Ice"
    },
    {
      "x": -22,
      "y": 23,
      "z": -13,
      "name": "Rock_Ice"
    },
    {
      "x": -22,
      "y": 24,
      "z": -13,
      "name": "Rock_Ice"
    },
    {
      "x": -22,
      "y": 25,
      "z": -13,
      "name": "Soil_Snow"
    },
    {
      "x": -22,
      "y": 19,
      "z": -12,
      "name": "Rock_Ice_Permafrost"
    },
    {
      "x": -22,
      "y": 20,
      "z": -12,
      "name": "Rock_Ice"
    },
    {
      "x": -22,
      "y": 21,
      "z": -12,
      "name": "Rock_Ice"
    },
    {
      "x": -22,
      "y": 22,
      "z": -12,
      "name": "Rock_Ice"
    },
    {
      "x": -22,
      "y": 23,
      "z": -12,
      "name": "Rock_Ice"
    },
    {
      "x": -22,
      "y": 24,
      "z": -12,
      "name": "Soil_Snow"
    },
    {
      "x": -22,
      "y": 17,
      "z": -11,
      "name": "Rock_Ice_Permafrost"
    },
    {
      "x": -22,
      "y": 18,
      "z": -11,
      "name": "Rock_Ice_Permafrost"
    },
    {
      "x": -22,
      "y": 19,
      "z": -11,
      "name": "Rock_Ice_Permafrost"
    },
    {
      "x": -22,
      "y": 20,
      "z": -11,
      "name": "Rock_Ice_Permafrost"
    },
    {
      "x": -22,
      "y": 21,
      "z": -11,
      "name": "Rock_Ice"
    },
    {
      "x": -22,
      "y": 22,
      "z": -11,
      "name": "Rock_Ice"
    },
    {
      "x": -22,
      "y": 23,
      "z": -11,
      "name": "Rock_Ice"
    },
    {
      "x": -22,
      "y": 24,
      "z": -11,
      "name": "Soil_Snow"
    },
    {
      "x": -22,
      "y": 16,
      "z": -10,
      "name": "Rock_Ice"
    },
    {
      "x": -22,
      "y": 17,
      "z": -10,
      "name": "Rock_Ice"
    },
    {
      "x": -22,
      "y": 18,
      "z": -10,
      "name": "Rock_Ice"
    },
    {
      "x": -22,
      "y": 19,
      "z": -10,
      "name": "Rock_Ice"
    },
    {
      "x": -22,
      "y": 20,
      "z": -10,
      "name": "Rock_Ice_Permafrost"
    },
    {
      "x": -22,
      "y": 21,
      "z": -10,
      "name": "Rock_Ice_Permafrost"
    },
    {
      "x": -22,
      "y": 22,
      "z": -10,
      "name": "Rock_Ice_Permafrost"
    },
    {
      "x": -22,
      "y": 23,
      "z": -10,
      "name": "Rock_Ice"
    },
    {
      "x": -22,
      "y": 24,
      "z": -10,
      "name": "Soil_Snow"
    },
    {
      "x": -22,
      "y": 15,
      "z": -9,
      "name": "Rock_Ice"
    },
    {
      "x": -22,
      "y": 16,
      "z": -9,
      "name": "Rock_Ice"
    },
    {
      "x": -22,
      "y": 17,
      "z": -9,
      "name": "Rock_Ice"
    },
    {
      "x": -22,
      "y": 18,
      "z": -9,
      "name": "Rock_Ice"
    },
    {
      "x": -22,
      "y": 19,
      "z": -9,
      "name": "Rock_Ice"
    },
    {
      "x": -22,
      "y": 20,
      "z": -9,
      "name": "Rock_Ice"
    },
    {
      "x": -22,
      "y": 21,
      "z": -9,
      "name": "Rock_Ice"
    },
    {
      "x": -22,
      "y": 22,
      "z": -9,
      "name": "Rock_Ice_Permafrost"
    },
    {
      "x": -22,
      "y": 23,
      "z": -9,
      "name": "Rock_Ice"
    },
    {
      "x": -22,
      "y": 24,
      "z": -9,
      "name": "Soil_Snow"
    },
    {
      "x": -22,
      "y": 14,
      "z": -8,
      "name": "Rock_Ice"
    },
    {
      "x": -22,
      "y": 15,
      "z": -8,
      "name": "Rock_Ice"
    },
    {
      "x": -22,
      "y": 16,
      "z": -8,
      "name": "Rock_Ice"
    },
    {
      "x": -22,
      "y": 17,
      "z": -8,
      "name": "Rock_Ice"
    },
    {
      "x": -22,
      "y": 18,
      "z": -8,
      "name": "Rock_Ice"
    },
    {
      "x": -22,
      "y": 19,
      "z": -8,
      "name": "Rock_Ice"
    },
    {
      "x": -22,
      "y": 20,
      "z": -8,
      "name": "Rock_Ice"
    },
    {
      "x": -22,
      "y": 21,
      "z": -8,
      "name": "Rock_Ice"
    },
    {
      "x": -22,
      "y": 22,
      "z": -8,
      "name": "Rock_Ice_Permafrost"
    },
    {
      "x": -22,
      "y": 23,
      "z": -8,
      "name": "Rock_Ice"
    },
    {
      "x": -22,
      "y": 24,
      "z": -8,
      "name": "Soil_Snow"
    },
    {
      "x": -22,
      "y": 14,
      "z": -7,
      "name": "Rock_Ice"
    },
    {
      "x": -22,
      "y": 15,
      "z": -7,
      "name": "Rock_Ice"
    },
    {
      "x": -22,
      "y": 16,
      "z": -7,
      "name": "Rock_Ice"
    },
    {
      "x": -22,
      "y": 17,
      "z": -7,
      "name": "Rock_Ice"
    },
    {
      "x": -22,
      "y": 18,
      "z": -7,
      "name": "Rock_Ice"
    },
    {
      "x": -22,
      "y": 19,
      "z": -7,
      "name": "Rock_Ice"
    },
    {
      "x": -22,
      "y": 20,
      "z": -7,
      "name": "Rock_Ice"
    },
    {
      "x": -22,
      "y": 21,
      "z": -7,
      "name": "Rock_Ice"
    },
    {
      "x": -22,
      "y": 22,
      "z": -7,
      "name": "Rock_Ice"
    },
    {
      "x": -22,
      "y": 23,
      "z": -7,
      "name": "Rock_Ice"
    },
    {
      "x": -22,
      "y": 24,
      "z": -7,
      "name": "Soil_Snow"
    },
    {
      "x": -22,
      "y": 14,
      "z": -6,
      "name": "Rock_Ice"
    },
    {
      "x": -22,
      "y": 15,
      "z": -6,
      "name": "Rock_Ice"
    },
    {
      "x": -22,
      "y": 16,
      "z": -6,
      "name": "Rock_Ice"
    },
    {
      "x": -22,
      "y": 17,
      "z": -6,
      "name": "Rock_Ice"
    },
    {
      "x": -22,
      "y": 18,
      "z": -6,
      "name": "Rock_Ice"
    },
    {
      "x": -22,
      "y": 19,
      "z": -6,
      "name": "Rock_Ice"
    },
    {
      "x": -22,
      "y": 20,
      "z": -6,
      "name": "Rock_Ice"
    },
    {
      "x": -22,
      "y": 21,
      "z": -6,
      "name": "Rock_Ice"
    },
    {
      "x": -22,
      "y": 22,
      "z": -6,
      "name": "Rock_Ice"
    },
    {
      "x": -22,
      "y": 23,
      "z": -6,
      "name": "Rock_Ice_Permafrost"
    },
    {
      "x": -22,
      "y": 24,
      "z": -6,
      "name": "Rock_Ice"
    },
    {
      "x": -22,
      "y": 25,
      "z": -6,
      "name": "Soil_Snow"
    },
    {
      "x": -22,
      "y": 14,
      "z": -5,
      "name": "Rock_Ice"
    },
    {
      "x": -22,
      "y": 15,
      "z": -5,
      "name": "Rock_Ice"
    },
    {
      "x": -22,
      "y": 16,
      "z": -5,
      "name": "Rock_Ice"
    },
    {
      "x": -22,
      "y": 17,
      "z": -5,
      "name": "Rock_Ice"
    },
    {
      "x": -22,
      "y": 18,
      "z": -5,
      "name": "Rock_Ice"
    },
    {
      "x": -22,
      "y": 19,
      "z": -5,
      "name": "Rock_Ice"
    },
    {
      "x": -22,
      "y": 20,
      "z": -5,
      "name": "Rock_Ice"
    },
    {
      "x": -22,
      "y": 21,
      "z": -5,
      "name": "Rock_Ice"
    },
    {
      "x": -22,
      "y": 22,
      "z": -5,
      "name": "Rock_Ice"
    },
    {
      "x": -22,
      "y": 23,
      "z": -5,
      "name": "Rock_Ice"
    },
    {
      "x": -22,
      "y": 24,
      "z": -5,
      "name": "Rock_Ice_Permafrost"
    },
    {
      "x": -22,
      "y": 25,
      "z": -5,
      "name": "Rock_Ice_Permafrost"
    },
    {
      "x": -22,
      "y": 26,
      "z": -5,
      "name": "Rock_Ice"
    },
    {
      "x": -22,
      "y": 27,
      "z": -5,
      "name": "Soil_Snow"
    },
    {
      "x": -22,
      "y": 14,
      "z": -4,
      "name": "Rock_Ice"
    },
    {
      "x": -22,
      "y": 15,
      "z": -4,
      "name": "Rock_Ice"
    },
    {
      "x": -22,
      "y": 16,
      "z": -4,
      "name": "Rock_Ice"
    },
    {
      "x": -22,
      "y": 17,
      "z": -4,
      "name": "Rock_Ice"
    },
    {
      "x": -22,
      "y": 18,
      "z": -4,
      "name": "Rock_Ice"
    },
    {
      "x": -22,
      "y": 19,
      "z": -4,
      "name": "Rock_Ice"
    },
    {
      "x": -22,
      "y": 20,
      "z": -4,
      "name": "Rock_Ice"
    },
    {
      "x": -22,
      "y": 21,
      "z": -4,
      "name": "Rock_Ice"
    },
    {
      "x": -22,
      "y": 22,
      "z": -4,
      "name": "Rock_Ice"
    },
    {
      "x": -22,
      "y": 23,
      "z": -4,
      "name": "Rock_Ice"
    },
    {
      "x": -22,
      "y": 24,
      "z": -4,
      "name": "Rock_Ice_Permafrost"
    },
    {
      "x": -22,
      "y": 25,
      "z": -4,
      "name": "Rock_Ice"
    },
    {
      "x": -22,
      "y": 26,
      "z": -4,
      "name": "Rock_Ice"
    },
    {
      "x": -22,
      "y": 27,
      "z": -4,
      "name": "Rock_Ice"
    },
    {
      "x": -22,
      "y": 28,
      "z": -4,
      "name": "Rock_Ice"
    },
    {
      "x": -22,
      "y": 29,
      "z": -4,
      "name": "Soil_Snow"
    },
    {
      "x": -22,
      "y": 14,
      "z": -3,
      "name": "Rock_Ice"
    },
    {
      "x": -22,
      "y": 15,
      "z": -3,
      "name": "Rock_Ice"
    },
    {
      "x": -22,
      "y": 16,
      "z": -3,
      "name": "Rock_Ice"
    },
    {
      "x": -22,
      "y": 17,
      "z": -3,
      "name": "Rock_Ice"
    },
    {
      "x": -22,
      "y": 18,
      "z": -3,
      "name": "Rock_Ice"
    },
    {
      "x": -22,
      "y": 19,
      "z": -3,
      "name": "Rock_Ice"
    },
    {
      "x": -22,
      "y": 20,
      "z": -3,
      "name": "Rock_Ice"
    },
    {
      "x": -22,
      "y": 21,
      "z": -3,
      "name": "Rock_Ice"
    },
    {
      "x": -22,
      "y": 22,
      "z": -3,
      "name": "Rock_Ice"
    },
    {
      "x": -22,
      "y": 23,
      "z": -3,
      "name": "Rock_Ice"
    },
    {
      "x": -22,
      "y": 24,
      "z": -3,
      "name": "Rock_Ice_Permafrost"
    },
    {
      "x": -22,
      "y": 25,
      "z": -3,
      "name": "Rock_Ice"
    },
    {
      "x": -22,
      "y": 26,
      "z": -3,
      "name": "Rock_Ice"
    },
    {
      "x": -22,
      "y": 27,
      "z": -3,
      "name": "Rock_Ice_Permafrost"
    },
    {
      "x": -22,
      "y": 28,
      "z": -3,
      "name": "Rock_Ice"
    },
    {
      "x": -22,
      "y": 29,
      "z": -3,
      "name": "Soil_Snow"
    },
    {
      "x": -22,
      "y": 15,
      "z": -2,
      "name": "Rock_Ice"
    },
    {
      "x": -22,
      "y": 16,
      "z": -2,
      "name": "Rock_Ice"
    },
    {
      "x": -22,
      "y": 17,
      "z": -2,
      "name": "Rock_Ice"
    },
    {
      "x": -22,
      "y": 18,
      "z": -2,
      "name": "Rock_Ice"
    },
    {
      "x": -22,
      "y": 19,
      "z": -2,
      "name": "Rock_Ice"
    },
    {
      "x": -22,
      "y": 20,
      "z": -2,
      "name": "Rock_Ice"
    },
    {
      "x": -22,
      "y": 21,
      "z": -2,
      "name": "Rock_Ice"
    },
    {
      "x": -22,
      "y": 22,
      "z": -2,
      "name": "Rock_Ice"
    },
    {
      "x": -22,
      "y": 23,
      "z": -2,
      "name": "Rock_Ice"
    },
    {
      "x": -22,
      "y": 24,
      "z": -2,
      "name": "Rock_Ice_Permafrost"
    },
    {
      "x": -22,
      "y": 25,
      "z": -2,
      "name": "Rock_Ice"
    },
    {
      "x": -22,
      "y": 26,
      "z": -2,
      "name": "Rock_Ice_Permafrost"
    },
    {
      "x": -22,
      "y": 27,
      "z": -2,
      "name": "Rock_Ice_Permafrost"
    },
    {
      "x": -22,
      "y": 28,
      "z": -2,
      "name": "Rock_Ice"
    },
    {
      "x": -22,
      "y": 29,
      "z": -2,
      "name": "Soil_Snow"
    },
    {
      "x": -22,
      "y": 16,
      "z": -1,
      "name": "Rock_Ice"
    },
    {
      "x": -22,
      "y": 17,
      "z": -1,
      "name": "Rock_Ice"
    },
    {
      "x": -22,
      "y": 18,
      "z": -1,
      "name": "Rock_Ice"
    },
    {
      "x": -22,
      "y": 19,
      "z": -1,
      "name": "Rock_Ice"
    },
    {
      "x": -22,
      "y": 20,
      "z": -1,
      "name": "Rock_Ice"
    },
    {
      "x": -22,
      "y": 21,
      "z": -1,
      "name": "Rock_Ice"
    },
    {
      "x": -22,
      "y": 22,
      "z": -1,
      "name": "Rock_Ice"
    },
    {
      "x": -22,
      "y": 23,
      "z": -1,
      "name": "Rock_Ice"
    },
    {
      "x": -22,
      "y": 24,
      "z": -1,
      "name": "Rock_Ice_Permafrost"
    },
    {
      "x": -22,
      "y": 25,
      "z": -1,
      "name": "Rock_Ice"
    },
    {
      "x": -22,
      "y": 26,
      "z": -1,
      "name": "Rock_Ice_Permafrost"
    },
    {
      "x": -22,
      "y": 27,
      "z": -1,
      "name": "Rock_Ice_Permafrost"
    },
    {
      "x": -22,
      "y": 28,
      "z": -1,
      "name": "Rock_Ice_Permafrost"
    },
    {
      "x": -22,
      "y": 29,
      "z": -1,
      "name": "Rock_Ice"
    },
    {
      "x": -22,
      "y": 30,
      "z": -1,
      "name": "Rock_Ice"
    },
    {
      "x": -22,
      "y": 31,
      "z": -1,
      "name": "Soil_Snow"
    },
    {
      "x": -22,
      "y": 14,
      "z": 0,
      "name": "Rock_Ice"
    },
    {
      "x": -22,
      "y": 15,
      "z": 0,
      "name": "Rock_Ice"
    },
    {
      "x": -22,
      "y": 16,
      "z": 0,
      "name": "Rock_Ice"
    },
    {
      "x": -22,
      "y": 17,
      "z": 0,
      "name": "Rock_Ice"
    },
    {
      "x": -22,
      "y": 18,
      "z": 0,
      "name": "Rock_Ice"
    },
    {
      "x": -22,
      "y": 19,
      "z": 0,
      "name": "Rock_Ice"
    },
    {
      "x": -22,
      "y": 20,
      "z": 0,
      "name": "Rock_Ice"
    },
    {
      "x": -22,
      "y": 21,
      "z": 0,
      "name": "Rock_Ice"
    },
    {
      "x": -22,
      "y": 22,
      "z": 0,
      "name": "Rock_Ice"
    },
    {
      "x": -22,
      "y": 23,
      "z": 0,
      "name": "Rock_Ice_Permafrost"
    },
    {
      "x": -22,
      "y": 24,
      "z": 0,
      "name": "Rock_Ice_Permafrost"
    },
    {
      "x": -22,
      "y": 25,
      "z": 0,
      "name": "Rock_Ice_Permafrost"
    },
    {
      "x": -22,
      "y": 26,
      "z": 0,
      "name": "Rock_Ice_Permafrost"
    },
    {
      "x": -22,
      "y": 27,
      "z": 0,
      "name": "Rock_Ice"
    },
    {
      "x": -22,
      "y": 28,
      "z": 0,
      "name": "Rock_Ice"
    },
    {
      "x": -22,
      "y": 29,
      "z": 0,
      "name": "Rock_Ice"
    },
    {
      "x": -22,
      "y": 30,
      "z": 0,
      "name": "Rock_Ice"
    },
    {
      "x": -22,
      "y": 31,
      "z": 0,
      "name": "Soil_Snow"
    },
    {
      "x": -22,
      "y": 12,
      "z": 1,
      "name": "Rock_Ice"
    },
    {
      "x": -22,
      "y": 13,
      "z": 1,
      "name": "Rock_Ice"
    },
    {
      "x": -22,
      "y": 14,
      "z": 1,
      "name": "Rock_Ice"
    },
    {
      "x": -22,
      "y": 15,
      "z": 1,
      "name": "Rock_Ice"
    },
    {
      "x": -22,
      "y": 16,
      "z": 1,
      "name": "Rock_Ice"
    },
    {
      "x": -22,
      "y": 17,
      "z": 1,
      "name": "Rock_Ice"
    },
    {
      "x": -22,
      "y": 18,
      "z": 1,
      "name": "Rock_Ice"
    },
    {
      "x": -22,
      "y": 19,
      "z": 1,
      "name": "Rock_Ice"
    },
    {
      "x": -22,
      "y": 20,
      "z": 1,
      "name": "Rock_Ice"
    },
    {
      "x": -22,
      "y": 21,
      "z": 1,
      "name": "Rock_Ice"
    },
    {
      "x": -22,
      "y": 22,
      "z": 1,
      "name": "Rock_Ice"
    },
    {
      "x": -22,
      "y": 23,
      "z": 1,
      "name": "Rock_Ice_Permafrost"
    },
    {
      "x": -22,
      "y": 24,
      "z": 1,
      "name": "Rock_Ice_Permafrost"
    },
    {
      "x": -22,
      "y": 25,
      "z": 1,
      "name": "Rock_Ice_Permafrost"
    },
    {
      "x": -22,
      "y": 26,
      "z": 1,
      "name": "Rock_Ice_Permafrost"
    },
    {
      "x": -22,
      "y": 27,
      "z": 1,
      "name": "Rock_Ice_Permafrost"
    },
    {
      "x": -22,
      "y": 28,
      "z": 1,
      "name": "Rock_Ice"
    },
    {
      "x": -22,
      "y": 29,
      "z": 1,
      "name": "Rock_Ice"
    },
    {
      "x": -22,
      "y": 30,
      "z": 1,
      "name": "Soil_Snow"
    },
    {
      "x": -22,
      "y": 12,
      "z": 2,
      "name": "Rock_Ice"
    },
    {
      "x": -22,
      "y": 13,
      "z": 2,
      "name": "Rock_Ice"
    },
    {
      "x": -22,
      "y": 14,
      "z": 2,
      "name": "Rock_Ice"
    },
    {
      "x": -22,
      "y": 15,
      "z": 2,
      "name": "Rock_Ice"
    },
    {
      "x": -22,
      "y": 16,
      "z": 2,
      "name": "Rock_Ice"
    },
    {
      "x": -22,
      "y": 17,
      "z": 2,
      "name": "Rock_Ice"
    },
    {
      "x": -22,
      "y": 18,
      "z": 2,
      "name": "Rock_Ice"
    },
    {
      "x": -22,
      "y": 19,
      "z": 2,
      "name": "Rock_Ice"
    },
    {
      "x": -22,
      "y": 20,
      "z": 2,
      "name": "Rock_Ice"
    },
    {
      "x": -22,
      "y": 21,
      "z": 2,
      "name": "Rock_Ice"
    },
    {
      "x": -22,
      "y": 22,
      "z": 2,
      "name": "Rock_Ice"
    },
    {
      "x": -22,
      "y": 23,
      "z": 2,
      "name": "Rock_Ice_Permafrost"
    },
    {
      "x": -22,
      "y": 24,
      "z": 2,
      "name": "Rock_Ice_Permafrost"
    },
    {
      "x": -22,
      "y": 25,
      "z": 2,
      "name": "Rock_Ice_Permafrost"
    },
    {
      "x": -22,
      "y": 26,
      "z": 2,
      "name": "Rock_Ice_Permafrost"
    },
    {
      "x": -22,
      "y": 27,
      "z": 2,
      "name": "Rock_Ice"
    },
    {
      "x": -22,
      "y": 28,
      "z": 2,
      "name": "Rock_Ice"
    },
    {
      "x": -22,
      "y": 29,
      "z": 2,
      "name": "Soil_Snow"
    },
    {
      "x": -22,
      "y": 11,
      "z": 3,
      "name": "Rock_Ice"
    },
    {
      "x": -22,
      "y": 12,
      "z": 3,
      "name": "Rock_Ice"
    },
    {
      "x": -22,
      "y": 13,
      "z": 3,
      "name": "Rock_Ice"
    },
    {
      "x": -22,
      "y": 14,
      "z": 3,
      "name": "Rock_Ice"
    },
    {
      "x": -22,
      "y": 15,
      "z": 3,
      "name": "Rock_Ice"
    },
    {
      "x": -22,
      "y": 16,
      "z": 3,
      "name": "Rock_Ice"
    },
    {
      "x": -22,
      "y": 17,
      "z": 3,
      "name": "Rock_Ice"
    },
    {
      "x": -22,
      "y": 18,
      "z": 3,
      "name": "Rock_Ice"
    },
    {
      "x": -22,
      "y": 19,
      "z": 3,
      "name": "Rock_Ice"
    },
    {
      "x": -22,
      "y": 20,
      "z": 3,
      "name": "Rock_Ice"
    },
    {
      "x": -22,
      "y": 21,
      "z": 3,
      "name": "Rock_Ice"
    },
    {
      "x": -22,
      "y": 22,
      "z": 3,
      "name": "Rock_Ice"
    },
    {
      "x": -22,
      "y": 23,
      "z": 3,
      "name": "Rock_Ice_Permafrost"
    },
    {
      "x": -22,
      "y": 24,
      "z": 3,
      "name": "Rock_Ice_Permafrost"
    },
    {
      "x": -22,
      "y": 25,
      "z": 3,
      "name": "Rock_Ice_Permafrost"
    },
    {
      "x": -22,
      "y": 26,
      "z": 3,
      "name": "Rock_Ice"
    },
    {
      "x": -22,
      "y": 27,
      "z": 3,
      "name": "Soil_Snow"
    },
    {
      "x": -22,
      "y": 11,
      "z": 4,
      "name": "Rock_Ice"
    },
    {
      "x": -22,
      "y": 12,
      "z": 4,
      "name": "Rock_Ice"
    },
    {
      "x": -22,
      "y": 13,
      "z": 4,
      "name": "Rock_Ice"
    },
    {
      "x": -22,
      "y": 14,
      "z": 4,
      "name": "Rock_Ice"
    },
    {
      "x": -22,
      "y": 15,
      "z": 4,
      "name": "Rock_Ice"
    },
    {
      "x": -22,
      "y": 16,
      "z": 4,
      "name": "Rock_Ice"
    },
    {
      "x": -22,
      "y": 17,
      "z": 4,
      "name": "Rock_Ice"
    },
    {
      "x": -22,
      "y": 18,
      "z": 4,
      "name": "Rock_Ice"
    },
    {
      "x": -22,
      "y": 19,
      "z": 4,
      "name": "Rock_Ice"
    },
    {
      "x": -22,
      "y": 20,
      "z": 4,
      "name": "Rock_Ice"
    },
    {
      "x": -22,
      "y": 21,
      "z": 4,
      "name": "Rock_Ice"
    },
    {
      "x": -22,
      "y": 22,
      "z": 4,
      "name": "Rock_Ice"
    },
    {
      "x": -22,
      "y": 23,
      "z": 4,
      "name": "Rock_Ice_Permafrost"
    },
    {
      "x": -22,
      "y": 24,
      "z": 4,
      "name": "Rock_Ice_Permafrost"
    },
    {
      "x": -22,
      "y": 25,
      "z": 4,
      "name": "Rock_Ice"
    },
    {
      "x": -22,
      "y": 26,
      "z": 4,
      "name": "Soil_Snow"
    },
    {
      "x": -22,
      "y": 11,
      "z": 5,
      "name": "Rock_Ice_Permafrost"
    },
    {
      "x": -22,
      "y": 12,
      "z": 5,
      "name": "Rock_Ice_Permafrost"
    },
    {
      "x": -22,
      "y": 13,
      "z": 5,
      "name": "Rock_Ice_Permafrost"
    },
    {
      "x": -22,
      "y": 14,
      "z": 5,
      "name": "Rock_Ice"
    },
    {
      "x": -22,
      "y": 15,
      "z": 5,
      "name": "Rock_Ice"
    },
    {
      "x": -22,
      "y": 16,
      "z": 5,
      "name": "Rock_Ice"
    },
    {
      "x": -22,
      "y": 17,
      "z": 5,
      "name": "Rock_Ice"
    },
    {
      "x": -22,
      "y": 18,
      "z": 5,
      "name": "Rock_Ice"
    },
    {
      "x": -22,
      "y": 19,
      "z": 5,
      "name": "Rock_Ice"
    },
    {
      "x": -22,
      "y": 20,
      "z": 5,
      "name": "Rock_Ice"
    },
    {
      "x": -22,
      "y": 21,
      "z": 5,
      "name": "Rock_Ice_Permafrost"
    },
    {
      "x": -22,
      "y": 22,
      "z": 5,
      "name": "Rock_Ice_Permafrost"
    },
    {
      "x": -22,
      "y": 23,
      "z": 5,
      "name": "Rock_Ice_Permafrost"
    },
    {
      "x": -22,
      "y": 24,
      "z": 5,
      "name": "Rock_Ice_Permafrost"
    },
    {
      "x": -22,
      "y": 25,
      "z": 5,
      "name": "Rock_Ice"
    },
    {
      "x": -22,
      "y": 26,
      "z": 5,
      "name": "Soil_Snow"
    },
    {
      "x": -22,
      "y": 10,
      "z": 6,
      "name": "Rock_Ice_Permafrost"
    },
    {
      "x": -22,
      "y": 11,
      "z": 6,
      "name": "Rock_Ice_Permafrost"
    },
    {
      "x": -22,
      "y": 12,
      "z": 6,
      "name": "Rock_Ice_Permafrost"
    },
    {
      "x": -22,
      "y": 13,
      "z": 6,
      "name": "Rock_Ice_Permafrost"
    },
    {
      "x": -22,
      "y": 14,
      "z": 6,
      "name": "Rock_Ice_Permafrost"
    },
    {
      "x": -22,
      "y": 15,
      "z": 6,
      "name": "Rock_Ice_Permafrost"
    },
    {
      "x": -22,
      "y": 16,
      "z": 6,
      "name": "Rock_Ice_Permafrost"
    },
    {
      "x": -22,
      "y": 17,
      "z": 6,
      "name": "Rock_Ice_Permafrost"
    },
    {
      "x": -22,
      "y": 18,
      "z": 6,
      "name": "Rock_Ice_Permafrost"
    },
    {
      "x": -22,
      "y": 19,
      "z": 6,
      "name": "Rock_Ice_Permafrost"
    },
    {
      "x": -22,
      "y": 20,
      "z": 6,
      "name": "Rock_Ice_Permafrost"
    },
    {
      "x": -22,
      "y": 21,
      "z": 6,
      "name": "Rock_Ice_Permafrost"
    },
    {
      "x": -22,
      "y": 22,
      "z": 6,
      "name": "Rock_Ice_Permafrost"
    },
    {
      "x": -22,
      "y": 23,
      "z": 6,
      "name": "Rock_Ice_Permafrost"
    },
    {
      "x": -22,
      "y": 24,
      "z": 6,
      "name": "Rock_Ice"
    },
    {
      "x": -22,
      "y": 25,
      "z": 6,
      "name": "Soil_Snow"
    },
    {
      "x": -22,
      "y": 10,
      "z": 7,
      "name": "Rock_Ice_Permafrost"
    },
    {
      "x": -22,
      "y": 11,
      "z": 7,
      "name": "Rock_Ice_Permafrost"
    },
    {
      "x": -22,
      "y": 12,
      "z": 7,
      "name": "Rock_Ice_Permafrost"
    },
    {
      "x": -22,
      "y": 13,
      "z": 7,
      "name": "Rock_Ice_Permafrost"
    },
    {
      "x": -22,
      "y": 14,
      "z": 7,
      "name": "Rock_Ice_Permafrost"
    },
    {
      "x": -22,
      "y": 15,
      "z": 7,
      "name": "Rock_Ice_Permafrost"
    },
    {
      "x": -22,
      "y": 16,
      "z": 7,
      "name": "Rock_Ice_Permafrost"
    },
    {
      "x": -22,
      "y": 17,
      "z": 7,
      "name": "Rock_Ice_Permafrost"
    },
    {
      "x": -22,
      "y": 18,
      "z": 7,
      "name": "Rock_Ice_Permafrost"
    },
    {
      "x": -22,
      "y": 19,
      "z": 7,
      "name": "Rock_Ice_Permafrost"
    },
    {
      "x": -22,
      "y": 20,
      "z": 7,
      "name": "Rock_Ice_Permafrost"
    },
    {
      "x": -22,
      "y": 21,
      "z": 7,
      "name": "Rock_Ice_Permafrost"
    },
    {
      "x": -22,
      "y": 22,
      "z": 7,
      "name": "Rock_Ice_Permafrost"
    },
    {
      "x": -22,
      "y": 23,
      "z": 7,
      "name": "Rock_Ice"
    },
    {
      "x": -22,
      "y": 24,
      "z": 7,
      "name": "Soil_Snow"
    },
    {
      "x": -22,
      "y": 10,
      "z": 8,
      "name": "Rock_Ice"
    },
    {
      "x": -22,
      "y": 11,
      "z": 8,
      "name": "Rock_Ice"
    },
    {
      "x": -22,
      "y": 12,
      "z": 8,
      "name": "Rock_Ice"
    },
    {
      "x": -22,
      "y": 13,
      "z": 8,
      "name": "Rock_Ice_Permafrost"
    },
    {
      "x": -22,
      "y": 14,
      "z": 8,
      "name": "Rock_Ice"
    },
    {
      "x": -22,
      "y": 15,
      "z": 8,
      "name": "Rock_Ice"
    },
    {
      "x": -22,
      "y": 16,
      "z": 8,
      "name": "Rock_Ice"
    },
    {
      "x": -22,
      "y": 17,
      "z": 8,
      "name": "Rock_Ice"
    },
    {
      "x": -22,
      "y": 18,
      "z": 8,
      "name": "Rock_Ice_Permafrost"
    },
    {
      "x": -22,
      "y": 19,
      "z": 8,
      "name": "Rock_Ice_Permafrost"
    },
    {
      "x": -22,
      "y": 20,
      "z": 8,
      "name": "Rock_Ice_Permafrost"
    },
    {
      "x": -22,
      "y": 21,
      "z": 8,
      "name": "Rock_Ice_Permafrost"
    },
    {
      "x": -22,
      "y": 22,
      "z": 8,
      "name": "Rock_Ice"
    },
    {
      "x": -22,
      "y": 23,
      "z": 8,
      "name": "Soil_Snow"
    },
    {
      "x": -22,
      "y": 10,
      "z": 9,
      "name": "Rock_Ice"
    },
    {
      "x": -22,
      "y": 11,
      "z": 9,
      "name": "Rock_Ice"
    },
    {
      "x": -22,
      "y": 12,
      "z": 9,
      "name": "Rock_Ice"
    },
    {
      "x": -22,
      "y": 13,
      "z": 9,
      "name": "Rock_Ice"
    },
    {
      "x": -22,
      "y": 14,
      "z": 9,
      "name": "Rock_Ice"
    },
    {
      "x": -22,
      "y": 15,
      "z": 9,
      "name": "Rock_Ice"
    },
    {
      "x": -22,
      "y": 16,
      "z": 9,
      "name": "Rock_Ice"
    },
    {
      "x": -22,
      "y": 17,
      "z": 9,
      "name": "Rock_Ice"
    },
    {
      "x": -22,
      "y": 18,
      "z": 9,
      "name": "Rock_Ice"
    },
    {
      "x": -22,
      "y": 19,
      "z": 9,
      "name": "Rock_Ice"
    },
    {
      "x": -22,
      "y": 20,
      "z": 9,
      "name": "Rock_Ice"
    },
    {
      "x": -22,
      "y": 21,
      "z": 9,
      "name": "Soil_Snow"
    },
    {
      "x": -22,
      "y": 10,
      "z": 10,
      "name": "Rock_Ice"
    },
    {
      "x": -22,
      "y": 11,
      "z": 10,
      "name": "Rock_Ice"
    },
    {
      "x": -22,
      "y": 12,
      "z": 10,
      "name": "Rock_Ice"
    },
    {
      "x": -22,
      "y": 13,
      "z": 10,
      "name": "Rock_Ice"
    },
    {
      "x": -22,
      "y": 14,
      "z": 10,
      "name": "Rock_Ice"
    },
    {
      "x": -22,
      "y": 15,
      "z": 10,
      "name": "Rock_Ice"
    },
    {
      "x": -22,
      "y": 16,
      "z": 10,
      "name": "Rock_Ice"
    },
    {
      "x": -22,
      "y": 17,
      "z": 10,
      "name": "Rock_Ice"
    },
    {
      "x": -22,
      "y": 18,
      "z": 10,
      "name": "Rock_Ice"
    },
    {
      "x": -22,
      "y": 19,
      "z": 10,
      "name": "Rock_Ice"
    },
    {
      "x": -22,
      "y": 20,
      "z": 10,
      "name": "Soil_Snow"
    },
    {
      "x": -22,
      "y": 63,
      "z": 10,
      "name": "Soil_Snow"
    },
    {
      "x": -22,
      "y": 11,
      "z": 11,
      "name": "Rock_Ice"
    },
    {
      "x": -22,
      "y": 12,
      "z": 11,
      "name": "Rock_Ice"
    },
    {
      "x": -22,
      "y": 13,
      "z": 11,
      "name": "Rock_Ice"
    },
    {
      "x": -22,
      "y": 14,
      "z": 11,
      "name": "Rock_Ice"
    },
    {
      "x": -22,
      "y": 15,
      "z": 11,
      "name": "Rock_Ice"
    },
    {
      "x": -22,
      "y": 16,
      "z": 11,
      "name": "Rock_Ice"
    },
    {
      "x": -22,
      "y": 17,
      "z": 11,
      "name": "Rock_Ice"
    },
    {
      "x": -22,
      "y": 18,
      "z": 11,
      "name": "Rock_Ice"
    },
    {
      "x": -22,
      "y": 19,
      "z": 11,
      "name": "Soil_Snow"
    },
    {
      "x": -22,
      "y": 63,
      "z": 11,
      "name": "Soil_Snow"
    },
    {
      "x": -22,
      "y": 11,
      "z": 12,
      "name": "Rock_Ice"
    },
    {
      "x": -22,
      "y": 12,
      "z": 12,
      "name": "Rock_Ice"
    },
    {
      "x": -22,
      "y": 13,
      "z": 12,
      "name": "Rock_Ice"
    },
    {
      "x": -22,
      "y": 14,
      "z": 12,
      "name": "Rock_Ice"
    },
    {
      "x": -22,
      "y": 15,
      "z": 12,
      "name": "Rock_Ice"
    },
    {
      "x": -22,
      "y": 16,
      "z": 12,
      "name": "Rock_Ice"
    },
    {
      "x": -22,
      "y": 17,
      "z": 12,
      "name": "Rock_Ice"
    },
    {
      "x": -22,
      "y": 18,
      "z": 12,
      "name": "Soil_Snow"
    },
    {
      "x": -22,
      "y": 12,
      "z": 13,
      "name": "Rock_Ice"
    },
    {
      "x": -22,
      "y": 13,
      "z": 13,
      "name": "Rock_Ice"
    },
    {
      "x": -22,
      "y": 14,
      "z": 13,
      "name": "Rock_Ice"
    },
    {
      "x": -22,
      "y": 15,
      "z": 13,
      "name": "Rock_Ice"
    },
    {
      "x": -22,
      "y": 16,
      "z": 13,
      "name": "Rock_Ice"
    },
    {
      "x": -22,
      "y": 17,
      "z": 13,
      "name": "Soil_Snow"
    },
    {
      "x": -22,
      "y": 12,
      "z": 14,
      "name": "Rock_Ice"
    },
    {
      "x": -22,
      "y": 13,
      "z": 14,
      "name": "Rock_Ice"
    },
    {
      "x": -22,
      "y": 14,
      "z": 14,
      "name": "Rock_Ice"
    },
    {
      "x": -22,
      "y": 15,
      "z": 14,
      "name": "Rock_Ice"
    },
    {
      "x": -22,
      "y": 16,
      "z": 14,
      "name": "Soil_Snow"
    },
    {
      "x": -22,
      "y": 63,
      "z": 14,
      "name": "Rock_Ice_Permafrost"
    },
    {
      "x": -22,
      "y": 64,
      "z": 14,
      "name": "Soil_Snow"
    },
    {
      "x": -22,
      "y": 15,
      "z": 15,
      "name": "Rock_Ice"
    },
    {
      "x": -22,
      "y": 16,
      "z": 15,
      "name": "Soil_Snow"
    },
    {
      "x": -22,
      "y": 64,
      "z": 15,
      "name": "Rock_Ice_Permafrost"
    },
    {
      "x": -22,
      "y": 65,
      "z": 15,
      "name": "Rock_Ice_Permafrost"
    },
    {
      "x": -22,
      "y": 66,
      "z": 15,
      "name": "Soil_Snow"
    },
    {
      "x": -22,
      "y": 66,
      "z": 16,
      "name": "Rock_Ice_Permafrost"
    },
    {
      "x": -22,
      "y": 67,
      "z": 16,
      "name": "Rock_Ice"
    },
    {
      "x": -22,
      "y": 68,
      "z": 16,
      "name": "Soil_Snow"
    },
    {
      "x": -22,
      "y": 69,
      "z": 17,
      "name": "Soil_Snow"
    },
    {
      "x": -21,
      "y": 31,
      "z": -17,
      "name": "Soil_Snow"
    },
    {
      "x": -21,
      "y": 28,
      "z": -16,
      "name": "Rock_Ice_Permafrost"
    },
    {
      "x": -21,
      "y": 29,
      "z": -16,
      "name": "Rock_Ice"
    },
    {
      "x": -21,
      "y": 30,
      "z": -16,
      "name": "Soil_Snow"
    },
    {
      "x": -21,
      "y": 26,
      "z": -15,
      "name": "Rock_Ice_Permafrost"
    },
    {
      "x": -21,
      "y": 27,
      "z": -15,
      "name": "Rock_Ice"
    },
    {
      "x": -21,
      "y": 28,
      "z": -15,
      "name": "Rock_Ice"
    },
    {
      "x": -21,
      "y": 29,
      "z": -15,
      "name": "Soil_Snow"
    },
    {
      "x": -21,
      "y": 23,
      "z": -14,
      "name": "Rock_Ice"
    },
    {
      "x": -21,
      "y": 24,
      "z": -14,
      "name": "Rock_Ice_Permafrost"
    },
    {
      "x": -21,
      "y": 25,
      "z": -14,
      "name": "Rock_Ice_Permafrost"
    },
    {
      "x": -21,
      "y": 26,
      "z": -14,
      "name": "Rock_Ice"
    },
    {
      "x": -21,
      "y": 27,
      "z": -14,
      "name": "Rock_Ice"
    },
    {
      "x": -21,
      "y": 28,
      "z": -14,
      "name": "Soil_Snow"
    },
    {
      "x": -21,
      "y": 21,
      "z": -13,
      "name": "Rock_Ice"
    },
    {
      "x": -21,
      "y": 22,
      "z": -13,
      "name": "Rock_Ice"
    },
    {
      "x": -21,
      "y": 23,
      "z": -13,
      "name": "Rock_Ice"
    },
    {
      "x": -21,
      "y": 24,
      "z": -13,
      "name": "Rock_Ice"
    },
    {
      "x": -21,
      "y": 25,
      "z": -13,
      "name": "Rock_Ice_Permafrost"
    },
    {
      "x": -21,
      "y": 26,
      "z": -13,
      "name": "Rock_Ice"
    },
    {
      "x": -21,
      "y": 27,
      "z": -13,
      "name": "Soil_Snow"
    },
    {
      "x": -21,
      "y": 19,
      "z": -12,
      "name": "Rock_Ice_Permafrost"
    },
    {
      "x": -21,
      "y": 20,
      "z": -12,
      "name": "Rock_Ice_Permafrost"
    },
    {
      "x": -21,
      "y": 21,
      "z": -12,
      "name": "Rock_Ice_Permafrost"
    },
    {
      "x": -21,
      "y": 22,
      "z": -12,
      "name": "Rock_Ice"
    },
    {
      "x": -21,
      "y": 23,
      "z": -12,
      "name": "Rock_Ice"
    },
    {
      "x": -21,
      "y": 24,
      "z": -12,
      "name": "Rock_Ice"
    },
    {
      "x": -21,
      "y": 25,
      "z": -12,
      "name": "Rock_Ice_Permafrost"
    },
    {
      "x": -21,
      "y": 26,
      "z": -12,
      "name": "Rock_Ice"
    },
    {
      "x": -21,
      "y": 27,
      "z": -12,
      "name": "Soil_Snow"
    },
    {
      "x": -21,
      "y": 17,
      "z": -11,
      "name": "Rock_Ice_Permafrost"
    },
    {
      "x": -21,
      "y": 18,
      "z": -11,
      "name": "Rock_Ice"
    },
    {
      "x": -21,
      "y": 19,
      "z": -11,
      "name": "Rock_Ice"
    },
    {
      "x": -21,
      "y": 20,
      "z": -11,
      "name": "Rock_Ice_Permafrost"
    },
    {
      "x": -21,
      "y": 21,
      "z": -11,
      "name": "Rock_Ice_Permafrost"
    },
    {
      "x": -21,
      "y": 22,
      "z": -11,
      "name": "Rock_Ice_Permafrost"
    },
    {
      "x": -21,
      "y": 23,
      "z": -11,
      "name": "Rock_Ice"
    },
    {
      "x": -21,
      "y": 24,
      "z": -11,
      "name": "Rock_Ice"
    },
    {
      "x": -21,
      "y": 25,
      "z": -11,
      "name": "Rock_Ice"
    },
    {
      "x": -21,
      "y": 26,
      "z": -11,
      "name": "Rock_Ice"
    },
    {
      "x": -21,
      "y": 27,
      "z": -11,
      "name": "Soil_Snow"
    },
    {
      "x": -21,
      "y": 16,
      "z": -10,
      "name": "Rock_Ice"
    },
    {
      "x": -21,
      "y": 17,
      "z": -10,
      "name": "Rock_Ice"
    },
    {
      "x": -21,
      "y": 18,
      "z": -10,
      "name": "Rock_Ice"
    },
    {
      "x": -21,
      "y": 19,
      "z": -10,
      "name": "Rock_Ice"
    },
    {
      "x": -21,
      "y": 20,
      "z": -10,
      "name": "Rock_Ice"
    },
    {
      "x": -21,
      "y": 21,
      "z": -10,
      "name": "Rock_Ice"
    },
    {
      "x": -21,
      "y": 22,
      "z": -10,
      "name": "Rock_Ice_Permafrost"
    },
    {
      "x": -21,
      "y": 23,
      "z": -10,
      "name": "Rock_Ice"
    },
    {
      "x": -21,
      "y": 24,
      "z": -10,
      "name": "Rock_Ice"
    },
    {
      "x": -21,
      "y": 25,
      "z": -10,
      "name": "Rock_Ice"
    },
    {
      "x": -21,
      "y": 26,
      "z": -10,
      "name": "Soil_Snow"
    },
    {
      "x": -21,
      "y": 15,
      "z": -9,
      "name": "Rock_Ice"
    },
    {
      "x": -21,
      "y": 16,
      "z": -9,
      "name": "Rock_Ice"
    },
    {
      "x": -21,
      "y": 17,
      "z": -9,
      "name": "Rock_Ice"
    },
    {
      "x": -21,
      "y": 18,
      "z": -9,
      "name": "Rock_Ice"
    },
    {
      "x": -21,
      "y": 19,
      "z": -9,
      "name": "Rock_Ice"
    },
    {
      "x": -21,
      "y": 20,
      "z": -9,
      "name": "Rock_Ice"
    },
    {
      "x": -21,
      "y": 21,
      "z": -9,
      "name": "Rock_Ice"
    },
    {
      "x": -21,
      "y": 22,
      "z": -9,
      "name": "Rock_Ice"
    },
    {
      "x": -21,
      "y": 23,
      "z": -9,
      "name": "Rock_Ice_Permafrost"
    },
    {
      "x": -21,
      "y": 24,
      "z": -9,
      "name": "Rock_Ice_Permafrost"
    },
    {
      "x": -21,
      "y": 25,
      "z": -9,
      "name": "Rock_Ice"
    },
    {
      "x": -21,
      "y": 26,
      "z": -9,
      "name": "Rock_Ice"
    },
    {
      "x": -21,
      "y": 27,
      "z": -9,
      "name": "Soil_Snow"
    },
    {
      "x": -21,
      "y": 14,
      "z": -8,
      "name": "Rock_Ice"
    },
    {
      "x": -21,
      "y": 15,
      "z": -8,
      "name": "Rock_Ice"
    },
    {
      "x": -21,
      "y": 16,
      "z": -8,
      "name": "Rock_Ice"
    },
    {
      "x": -21,
      "y": 17,
      "z": -8,
      "name": "Rock_Ice"
    },
    {
      "x": -21,
      "y": 18,
      "z": -8,
      "name": "Rock_Ice"
    },
    {
      "x": -21,
      "y": 19,
      "z": -8,
      "name": "Rock_Ice"
    },
    {
      "x": -21,
      "y": 20,
      "z": -8,
      "name": "Rock_Ice"
    },
    {
      "x": -21,
      "y": 21,
      "z": -8,
      "name": "Rock_Ice"
    },
    {
      "x": -21,
      "y": 22,
      "z": -8,
      "name": "Rock_Ice"
    },
    {
      "x": -21,
      "y": 23,
      "z": -8,
      "name": "Rock_Ice_Permafrost"
    },
    {
      "x": -21,
      "y": 24,
      "z": -8,
      "name": "Rock_Ice_Permafrost"
    },
    {
      "x": -21,
      "y": 25,
      "z": -8,
      "name": "Rock_Ice_Permafrost"
    },
    {
      "x": -21,
      "y": 26,
      "z": -8,
      "name": "Rock_Ice"
    },
    {
      "x": -21,
      "y": 27,
      "z": -8,
      "name": "Soil_Snow"
    },
    {
      "x": -21,
      "y": 13,
      "z": -7,
      "name": "Rock_Ice"
    },
    {
      "x": -21,
      "y": 14,
      "z": -7,
      "name": "Rock_Ice"
    },
    {
      "x": -21,
      "y": 15,
      "z": -7,
      "name": "Rock_Ice"
    },
    {
      "x": -21,
      "y": 16,
      "z": -7,
      "name": "Rock_Ice"
    },
    {
      "x": -21,
      "y": 17,
      "z": -7,
      "name": "Rock_Ice"
    },
    {
      "x": -21,
      "y": 18,
      "z": -7,
      "name": "Rock_Ice"
    },
    {
      "x": -21,
      "y": 19,
      "z": -7,
      "name": "Rock_Ice"
    },
    {
      "x": -21,
      "y": 20,
      "z": -7,
      "name": "Rock_Ice"
    },
    {
      "x": -21,
      "y": 21,
      "z": -7,
      "name": "Rock_Ice"
    },
    {
      "x": -21,
      "y": 22,
      "z": -7,
      "name": "Rock_Ice"
    },
    {
      "x": -21,
      "y": 23,
      "z": -7,
      "name": "Rock_Ice"
    },
    {
      "x": -21,
      "y": 24,
      "z": -7,
      "name": "Rock_Ice_Permafrost"
    },
    {
      "x": -21,
      "y": 25,
      "z": -7,
      "name": "Rock_Ice_Permafrost"
    },
    {
      "x": -21,
      "y": 26,
      "z": -7,
      "name": "Rock_Ice"
    },
    {
      "x": -21,
      "y": 27,
      "z": -7,
      "name": "Soil_Snow"
    },
    {
      "x": -21,
      "y": 13,
      "z": -6,
      "name": "Rock_Ice"
    },
    {
      "x": -21,
      "y": 14,
      "z": -6,
      "name": "Rock_Ice"
    },
    {
      "x": -21,
      "y": 15,
      "z": -6,
      "name": "Rock_Ice"
    },
    {
      "x": -21,
      "y": 16,
      "z": -6,
      "name": "Rock_Ice"
    },
    {
      "x": -21,
      "y": 17,
      "z": -6,
      "name": "Rock_Ice"
    },
    {
      "x": -21,
      "y": 18,
      "z": -6,
      "name": "Rock_Ice"
    },
    {
      "x": -21,
      "y": 19,
      "z": -6,
      "name": "Rock_Ice"
    },
    {
      "x": -21,
      "y": 20,
      "z": -6,
      "name": "Rock_Ice"
    },
    {
      "x": -21,
      "y": 21,
      "z": -6,
      "name": "Rock_Ice"
    },
    {
      "x": -21,
      "y": 22,
      "z": -6,
      "name": "Rock_Ice"
    },
    {
      "x": -21,
      "y": 23,
      "z": -6,
      "name": "Rock_Ice"
    },
    {
      "x": -21,
      "y": 24,
      "z": -6,
      "name": "Rock_Ice_Permafrost"
    },
    {
      "x": -21,
      "y": 25,
      "z": -6,
      "name": "Rock_Ice_Permafrost"
    },
    {
      "x": -21,
      "y": 26,
      "z": -6,
      "name": "Rock_Ice"
    },
    {
      "x": -21,
      "y": 27,
      "z": -6,
      "name": "Rock_Ice"
    },
    {
      "x": -21,
      "y": 28,
      "z": -6,
      "name": "Soil_Snow"
    },
    {
      "x": -21,
      "y": 13,
      "z": -5,
      "name": "Rock_Ice"
    },
    {
      "x": -21,
      "y": 14,
      "z": -5,
      "name": "Rock_Ice"
    },
    {
      "x": -21,
      "y": 15,
      "z": -5,
      "name": "Rock_Ice"
    },
    {
      "x": -21,
      "y": 16,
      "z": -5,
      "name": "Rock_Ice"
    },
    {
      "x": -21,
      "y": 17,
      "z": -5,
      "name": "Rock_Ice"
    },
    {
      "x": -21,
      "y": 18,
      "z": -5,
      "name": "Rock_Ice"
    },
    {
      "x": -21,
      "y": 19,
      "z": -5,
      "name": "Rock_Ice"
    },
    {
      "x": -21,
      "y": 20,
      "z": -5,
      "name": "Rock_Ice"
    },
    {
      "x": -21,
      "y": 21,
      "z": -5,
      "name": "Rock_Ice"
    },
    {
      "x": -21,
      "y": 22,
      "z": -5,
      "name": "Rock_Ice"
    },
    {
      "x": -21,
      "y": 23,
      "z": -5,
      "name": "Rock_Ice"
    },
    {
      "x": -21,
      "y": 24,
      "z": -5,
      "name": "Rock_Ice_Permafrost"
    },
    {
      "x": -21,
      "y": 25,
      "z": -5,
      "name": "Rock_Ice_Permafrost"
    },
    {
      "x": -21,
      "y": 26,
      "z": -5,
      "name": "Rock_Ice"
    },
    {
      "x": -21,
      "y": 27,
      "z": -5,
      "name": "Rock_Ice"
    },
    {
      "x": -21,
      "y": 28,
      "z": -5,
      "name": "Rock_Ice"
    },
    {
      "x": -21,
      "y": 29,
      "z": -5,
      "name": "Rock_Ice"
    },
    {
      "x": -21,
      "y": 30,
      "z": -5,
      "name": "Soil_Snow"
    },
    {
      "x": -21,
      "y": 13,
      "z": -4,
      "name": "Rock_Ice"
    },
    {
      "x": -21,
      "y": 14,
      "z": -4,
      "name": "Rock_Ice"
    },
    {
      "x": -21,
      "y": 15,
      "z": -4,
      "name": "Rock_Ice"
    },
    {
      "x": -21,
      "y": 16,
      "z": -4,
      "name": "Rock_Ice"
    },
    {
      "x": -21,
      "y": 17,
      "z": -4,
      "name": "Rock_Ice"
    },
    {
      "x": -21,
      "y": 18,
      "z": -4,
      "name": "Rock_Ice"
    },
    {
      "x": -21,
      "y": 19,
      "z": -4,
      "name": "Rock_Ice"
    },
    {
      "x": -21,
      "y": 20,
      "z": -4,
      "name": "Rock_Ice"
    },
    {
      "x": -21,
      "y": 21,
      "z": -4,
      "name": "Rock_Ice"
    },
    {
      "x": -21,
      "y": 22,
      "z": -4,
      "name": "Rock_Ice"
    },
    {
      "x": -21,
      "y": 23,
      "z": -4,
      "name": "Rock_Ice"
    },
    {
      "x": -21,
      "y": 24,
      "z": -4,
      "name": "Rock_Ice"
    },
    {
      "x": -21,
      "y": 25,
      "z": -4,
      "name": "Rock_Ice_Permafrost"
    },
    {
      "x": -21,
      "y": 26,
      "z": -4,
      "name": "Rock_Ice"
    },
    {
      "x": -21,
      "y": 27,
      "z": -4,
      "name": "Rock_Ice"
    },
    {
      "x": -21,
      "y": 28,
      "z": -4,
      "name": "Rock_Ice"
    },
    {
      "x": -21,
      "y": 29,
      "z": -4,
      "name": "Rock_Ice_Permafrost"
    },
    {
      "x": -21,
      "y": 30,
      "z": -4,
      "name": "Rock_Ice"
    },
    {
      "x": -21,
      "y": 31,
      "z": -4,
      "name": "Soil_Snow"
    },
    {
      "x": -21,
      "y": 13,
      "z": -3,
      "name": "Rock_Ice"
    },
    {
      "x": -21,
      "y": 14,
      "z": -3,
      "name": "Rock_Ice"
    },
    {
      "x": -21,
      "y": 15,
      "z": -3,
      "name": "Rock_Ice"
    },
    {
      "x": -21,
      "y": 16,
      "z": -3,
      "name": "Rock_Ice"
    },
    {
      "x": -21,
      "y": 17,
      "z": -3,
      "name": "Rock_Ice"
    },
    {
      "x": -21,
      "y": 18,
      "z": -3,
      "name": "Rock_Ice"
    },
    {
      "x": -21,
      "y": 19,
      "z": -3,
      "name": "Rock_Ice"
    },
    {
      "x": -21,
      "y": 20,
      "z": -3,
      "name": "Rock_Ice"
    },
    {
      "x": -21,
      "y": 21,
      "z": -3,
      "name": "Rock_Ice"
    },
    {
      "x": -21,
      "y": 22,
      "z": -3,
      "name": "Rock_Ice"
    },
    {
      "x": -21,
      "y": 23,
      "z": -3,
      "name": "Rock_Ice"
    },
    {
      "x": -21,
      "y": 24,
      "z": -3,
      "name": "Rock_Ice"
    },
    {
      "x": -21,
      "y": 25,
      "z": -3,
      "name": "Rock_Ice_Permafrost"
    },
    {
      "x": -21,
      "y": 26,
      "z": -3,
      "name": "Rock_Ice"
    },
    {
      "x": -21,
      "y": 27,
      "z": -3,
      "name": "Rock_Ice"
    },
    {
      "x": -21,
      "y": 28,
      "z": -3,
      "name": "Rock_Ice"
    },
    {
      "x": -21,
      "y": 29,
      "z": -3,
      "name": "Rock_Ice_Permafrost"
    },
    {
      "x": -21,
      "y": 30,
      "z": -3,
      "name": "Rock_Ice"
    },
    {
      "x": -21,
      "y": 31,
      "z": -3,
      "name": "Soil_Snow"
    },
    {
      "x": -21,
      "y": 15,
      "z": -2,
      "name": "Rock_Ice"
    },
    {
      "x": -21,
      "y": 16,
      "z": -2,
      "name": "Rock_Ice"
    },
    {
      "x": -21,
      "y": 17,
      "z": -2,
      "name": "Rock_Ice"
    },
    {
      "x": -21,
      "y": 18,
      "z": -2,
      "name": "Rock_Ice"
    },
    {
      "x": -21,
      "y": 19,
      "z": -2,
      "name": "Rock_Ice"
    },
    {
      "x": -21,
      "y": 20,
      "z": -2,
      "name": "Rock_Ice"
    },
    {
      "x": -21,
      "y": 21,
      "z": -2,
      "name": "Rock_Ice"
    },
    {
      "x": -21,
      "y": 22,
      "z": -2,
      "name": "Rock_Ice"
    },
    {
      "x": -21,
      "y": 23,
      "z": -2,
      "name": "Rock_Ice"
    },
    {
      "x": -21,
      "y": 24,
      "z": -2,
      "name": "Rock_Ice"
    },
    {
      "x": -21,
      "y": 25,
      "z": -2,
      "name": "Rock_Ice_Permafrost"
    },
    {
      "x": -21,
      "y": 26,
      "z": -2,
      "name": "Rock_Ice"
    },
    {
      "x": -21,
      "y": 27,
      "z": -2,
      "name": "Rock_Ice"
    },
    {
      "x": -21,
      "y": 28,
      "z": -2,
      "name": "Rock_Ice_Permafrost"
    },
    {
      "x": -21,
      "y": 29,
      "z": -2,
      "name": "Rock_Ice_Permafrost"
    },
    {
      "x": -21,
      "y": 30,
      "z": -2,
      "name": "Rock_Ice"
    },
    {
      "x": -21,
      "y": 31,
      "z": -2,
      "name": "Soil_Snow"
    },
    {
      "x": -21,
      "y": 15,
      "z": -1,
      "name": "Rock_Ice"
    },
    {
      "x": -21,
      "y": 16,
      "z": -1,
      "name": "Rock_Ice"
    },
    {
      "x": -21,
      "y": 17,
      "z": -1,
      "name": "Rock_Ice"
    },
    {
      "x": -21,
      "y": 18,
      "z": -1,
      "name": "Rock_Ice"
    },
    {
      "x": -21,
      "y": 19,
      "z": -1,
      "name": "Rock_Ice"
    },
    {
      "x": -21,
      "y": 20,
      "z": -1,
      "name": "Rock_Ice"
    },
    {
      "x": -21,
      "y": 21,
      "z": -1,
      "name": "Rock_Ice"
    },
    {
      "x": -21,
      "y": 22,
      "z": -1,
      "name": "Rock_Ice"
    },
    {
      "x": -21,
      "y": 23,
      "z": -1,
      "name": "Rock_Ice"
    },
    {
      "x": -21,
      "y": 24,
      "z": -1,
      "name": "Rock_Ice_Permafrost"
    },
    {
      "x": -21,
      "y": 25,
      "z": -1,
      "name": "Rock_Ice_Permafrost"
    },
    {
      "x": -21,
      "y": 26,
      "z": -1,
      "name": "Rock_Ice"
    },
    {
      "x": -21,
      "y": 27,
      "z": -1,
      "name": "Rock_Ice"
    },
    {
      "x": -21,
      "y": 28,
      "z": -1,
      "name": "Rock_Ice_Permafrost"
    },
    {
      "x": -21,
      "y": 29,
      "z": -1,
      "name": "Rock_Ice_Permafrost"
    },
    {
      "x": -21,
      "y": 30,
      "z": -1,
      "name": "Rock_Ice_Permafrost"
    },
    {
      "x": -21,
      "y": 31,
      "z": -1,
      "name": "Rock_Ice"
    },
    {
      "x": -21,
      "y": 32,
      "z": -1,
      "name": "Rock_Ice"
    },
    {
      "x": -21,
      "y": 33,
      "z": -1,
      "name": "Rock_Ice"
    },
    {
      "x": -21,
      "y": 34,
      "z": -1,
      "name": "Rock_Ice"
    },
    {
      "x": -21,
      "y": 35,
      "z": -1,
      "name": "Rock_Ice_Permafrost"
    },
    {
      "x": -21,
      "y": 36,
      "z": -1,
      "name": "Rock_Ice_Permafrost"
    },
    {
      "x": -21,
      "y": 37,
      "z": -1,
      "name": "Soil_Snow"
    },
    {
      "x": -21,
      "y": 12,
      "z": 0,
      "name": "Rock_Ice"
    },
    {
      "x": -21,
      "y": 13,
      "z": 0,
      "name": "Rock_Ice"
    },
    {
      "x": -21,
      "y": 14,
      "z": 0,
      "name": "Rock_Ice"
    },
    {
      "x": -21,
      "y": 15,
      "z": 0,
      "name": "Rock_Ice"
    },
    {
      "x": -21,
      "y": 16,
      "z": 0,
      "name": "Rock_Ice"
    },
    {
      "x": -21,
      "y": 17,
      "z": 0,
      "name": "Rock_Ice"
    },
    {
      "x": -21,
      "y": 18,
      "z": 0,
      "name": "Rock_Ice"
    },
    {
      "x": -21,
      "y": 19,
      "z": 0,
      "name": "Rock_Ice"
    },
    {
      "x": -21,
      "y": 20,
      "z": 0,
      "name": "Rock_Ice"
    },
    {
      "x": -21,
      "y": 21,
      "z": 0,
      "name": "Rock_Ice"
    },
    {
      "x": -21,
      "y": 22,
      "z": 0,
      "name": "Rock_Ice"
    },
    {
      "x": -21,
      "y": 23,
      "z": 0,
      "name": "Rock_Ice"
    },
    {
      "x": -21,
      "y": 24,
      "z": 0,
      "name": "Rock_Ice_Permafrost"
    },
    {
      "x": -21,
      "y": 25,
      "z": 0,
      "name": "Rock_Ice"
    },
    {
      "x": -21,
      "y": 26,
      "z": 0,
      "name": "Rock_Ice"
    },
    {
      "x": -21,
      "y": 27,
      "z": 0,
      "name": "Rock_Ice_Permafrost"
    },
    {
      "x": -21,
      "y": 28,
      "z": 0,
      "name": "Rock_Ice_Permafrost"
    },
    {
      "x": -21,
      "y": 29,
      "z": 0,
      "name": "Rock_Ice"
    },
    {
      "x": -21,
      "y": 30,
      "z": 0,
      "name": "Rock_Ice"
    },
    {
      "x": -21,
      "y": 31,
      "z": 0,
      "name": "Rock_Ice"
    },
    {
      "x": -21,
      "y": 32,
      "z": 0,
      "name": "Rock_Ice"
    },
    {
      "x": -21,
      "y": 33,
      "z": 0,
      "name": "Rock_Ice"
    },
    {
      "x": -21,
      "y": 34,
      "z": 0,
      "name": "Rock_Ice"
    },
    {
      "x": -21,
      "y": 35,
      "z": 0,
      "name": "Soil_Snow"
    },
    {
      "x": -21,
      "y": 11,
      "z": 1,
      "name": "Rock_Ice"
    },
    {
      "x": -21,
      "y": 12,
      "z": 1,
      "name": "Rock_Ice"
    },
    {
      "x": -21,
      "y": 13,
      "z": 1,
      "name": "Rock_Ice"
    },
    {
      "x": -21,
      "y": 14,
      "z": 1,
      "name": "Rock_Ice"
    },
    {
      "x": -21,
      "y": 15,
      "z": 1,
      "name": "Rock_Ice"
    },
    {
      "x": -21,
      "y": 16,
      "z": 1,
      "name": "Rock_Ice"
    },
    {
      "x": -21,
      "y": 17,
      "z": 1,
      "name": "Rock_Ice"
    },
    {
      "x": -21,
      "y": 18,
      "z": 1,
      "name": "Rock_Ice"
    },
    {
      "x": -21,
      "y": 19,
      "z": 1,
      "name": "Rock_Ice"
    },
    {
      "x": -21,
      "y": 20,
      "z": 1,
      "name": "Rock_Ice"
    },
    {
      "x": -21,
      "y": 21,
      "z": 1,
      "name": "Rock_Ice"
    },
    {
      "x": -21,
      "y": 22,
      "z": 1,
      "name": "Rock_Ice"
    },
    {
      "x": -21,
      "y": 23,
      "z": 1,
      "name": "Rock_Ice"
    },
    {
      "x": -21,
      "y": 24,
      "z": 1,
      "name": "Rock_Ice_Permafrost"
    },
    {
      "x": -21,
      "y": 25,
      "z": 1,
      "name": "Rock_Ice"
    },
    {
      "x": -21,
      "y": 26,
      "z": 1,
      "name": "Rock_Ice_Permafrost"
    },
    {
      "x": -21,
      "y": 27,
      "z": 1,
      "name": "Rock_Ice_Permafrost"
    },
    {
      "x": -21,
      "y": 28,
      "z": 1,
      "name": "Rock_Ice"
    },
    {
      "x": -21,
      "y": 29,
      "z": 1,
      "name": "Rock_Ice"
    },
    {
      "x": -21,
      "y": 30,
      "z": 1,
      "name": "Rock_Ice"
    },
    {
      "x": -21,
      "y": 31,
      "z": 1,
      "name": "Rock_Ice"
    },
    {
      "x": -21,
      "y": 32,
      "z": 1,
      "name": "Rock_Ice"
    },
    {
      "x": -21,
      "y": 33,
      "z": 1,
      "name": "Soil_Snow"
    },
    {
      "x": -21,
      "y": 10,
      "z": 2,
      "name": "Rock_Ice"
    },
    {
      "x": -21,
      "y": 11,
      "z": 2,
      "name": "Rock_Ice"
    },
    {
      "x": -21,
      "y": 12,
      "z": 2,
      "name": "Rock_Ice"
    },
    {
      "x": -21,
      "y": 13,
      "z": 2,
      "name": "Rock_Ice"
    },
    {
      "x": -21,
      "y": 14,
      "z": 2,
      "name": "Rock_Ice"
    },
    {
      "x": -21,
      "y": 15,
      "z": 2,
      "name": "Rock_Ice"
    },
    {
      "x": -21,
      "y": 16,
      "z": 2,
      "name": "Rock_Ice"
    },
    {
      "x": -21,
      "y": 17,
      "z": 2,
      "name": "Rock_Ice"
    },
    {
      "x": -21,
      "y": 18,
      "z": 2,
      "name": "Rock_Ice"
    },
    {
      "x": -21,
      "y": 19,
      "z": 2,
      "name": "Rock_Ice"
    },
    {
      "x": -21,
      "y": 20,
      "z": 2,
      "name": "Rock_Ice"
    },
    {
      "x": -21,
      "y": 21,
      "z": 2,
      "name": "Rock_Ice"
    },
    {
      "x": -21,
      "y": 22,
      "z": 2,
      "name": "Rock_Ice"
    },
    {
      "x": -21,
      "y": 23,
      "z": 2,
      "name": "Rock_Ice"
    },
    {
      "x": -21,
      "y": 24,
      "z": 2,
      "name": "Rock_Ice_Permafrost"
    },
    {
      "x": -21,
      "y": 25,
      "z": 2,
      "name": "Rock_Ice_Permafrost"
    },
    {
      "x": -21,
      "y": 26,
      "z": 2,
      "name": "Rock_Ice_Permafrost"
    },
    {
      "x": -21,
      "y": 27,
      "z": 2,
      "name": "Rock_Ice_Permafrost"
    },
    {
      "x": -21,
      "y": 28,
      "z": 2,
      "name": "Rock_Ice"
    },
    {
      "x": -21,
      "y": 29,
      "z": 2,
      "name": "Rock_Ice"
    },
    {
      "x": -21,
      "y": 30,
      "z": 2,
      "name": "Rock_Ice"
    },
    {
      "x": -21,
      "y": 31,
      "z": 2,
      "name": "Soil_Snow"
    },
    {
      "x": -21,
      "y": 10,
      "z": 3,
      "name": "Rock_Ice"
    },
    {
      "x": -21,
      "y": 11,
      "z": 3,
      "name": "Rock_Ice"
    },
    {
      "x": -21,
      "y": 12,
      "z": 3,
      "name": "Rock_Ice"
    },
    {
      "x": -21,
      "y": 13,
      "z": 3,
      "name": "Rock_Ice"
    },
    {
      "x": -21,
      "y": 14,
      "z": 3,
      "name": "Rock_Ice"
    },
    {
      "x": -21,
      "y": 15,
      "z": 3,
      "name": "Rock_Ice"
    },
    {
      "x": -21,
      "y": 16,
      "z": 3,
      "name": "Rock_Ice"
    },
    {
      "x": -21,
      "y": 17,
      "z": 3,
      "name": "Rock_Ice"
    },
    {
      "x": -21,
      "y": 18,
      "z": 3,
      "name": "Rock_Ice"
    },
    {
      "x": -21,
      "y": 19,
      "z": 3,
      "name": "Rock_Ice"
    },
    {
      "x": -21,
      "y": 20,
      "z": 3,
      "name": "Rock_Ice"
    },
    {
      "x": -21,
      "y": 21,
      "z": 3,
      "name": "Rock_Ice"
    },
    {
      "x": -21,
      "y": 22,
      "z": 3,
      "name": "Rock_Ice"
    },
    {
      "x": -21,
      "y": 23,
      "z": 3,
      "name": "Rock_Ice"
    },
    {
      "x": -21,
      "y": 24,
      "z": 3,
      "name": "Rock_Ice_Permafrost"
    },
    {
      "x": -21,
      "y": 25,
      "z": 3,
      "name": "Rock_Ice_Permafrost"
    },
    {
      "x": -21,
      "y": 26,
      "z": 3,
      "name": "Rock_Ice_Permafrost"
    },
    {
      "x": -21,
      "y": 27,
      "z": 3,
      "name": "Rock_Ice_Permafrost"
    },
    {
      "x": -21,
      "y": 28,
      "z": 3,
      "name": "Rock_Ice"
    },
    {
      "x": -21,
      "y": 29,
      "z": 3,
      "name": "Rock_Ice"
    },
    {
      "x": -21,
      "y": 30,
      "z": 3,
      "name": "Soil_Snow"
    },
    {
      "x": -21,
      "y": 9,
      "z": 4,
      "name": "Rock_Ice"
    },
    {
      "x": -21,
      "y": 10,
      "z": 4,
      "name": "Rock_Ice"
    },
    {
      "x": -21,
      "y": 11,
      "z": 4,
      "name": "Rock_Ice"
    },
    {
      "x": -21,
      "y": 12,
      "z": 4,
      "name": "Rock_Ice"
    },
    {
      "x": -21,
      "y": 13,
      "z": 4,
      "name": "Rock_Ice"
    },
    {
      "x": -21,
      "y": 14,
      "z": 4,
      "name": "Rock_Ice"
    },
    {
      "x": -21,
      "y": 15,
      "z": 4,
      "name": "Rock_Ice"
    },
    {
      "x": -21,
      "y": 16,
      "z": 4,
      "name": "Rock_Ice"
    },
    {
      "x": -21,
      "y": 17,
      "z": 4,
      "name": "Rock_Ice"
    },
    {
      "x": -21,
      "y": 18,
      "z": 4,
      "name": "Rock_Ice"
    },
    {
      "x": -21,
      "y": 19,
      "z": 4,
      "name": "Rock_Ice"
    },
    {
      "x": -21,
      "y": 20,
      "z": 4,
      "name": "Rock_Ice"
    },
    {
      "x": -21,
      "y": 21,
      "z": 4,
      "name": "Rock_Ice"
    },
    {
      "x": -21,
      "y": 22,
      "z": 4,
      "name": "Rock_Ice"
    },
    {
      "x": -21,
      "y": 23,
      "z": 4,
      "name": "Rock_Ice_Permafrost"
    },
    {
      "x": -21,
      "y": 24,
      "z": 4,
      "name": "Rock_Ice_Permafrost"
    },
    {
      "x": -21,
      "y": 25,
      "z": 4,
      "name": "Rock_Ice_Permafrost"
    },
    {
      "x": -21,
      "y": 26,
      "z": 4,
      "name": "Rock_Ice_Permafrost"
    },
    {
      "x": -21,
      "y": 27,
      "z": 4,
      "name": "Rock_Ice"
    },
    {
      "x": -21,
      "y": 28,
      "z": 4,
      "name": "Rock_Ice"
    },
    {
      "x": -21,
      "y": 29,
      "z": 4,
      "name": "Soil_Snow"
    },
    {
      "x": -21,
      "y": 64,
      "z": 4,
      "name": "Soil_Snow"
    },
    {
      "x": -21,
      "y": 8,
      "z": 5,
      "name": "Rock_Ice"
    },
    {
      "x": -21,
      "y": 9,
      "z": 5,
      "name": "Rock_Ice"
    },
    {
      "x": -21,
      "y": 10,
      "z": 5,
      "name": "Rock_Ice_Permafrost"
    },
    {
      "x": -21,
      "y": 11,
      "z": 5,
      "name": "Rock_Ice"
    },
    {
      "x": -21,
      "y": 12,
      "z": 5,
      "name": "Rock_Ice"
    },
    {
      "x": -21,
      "y": 13,
      "z": 5,
      "name": "Rock_Ice"
    },
    {
      "x": -21,
      "y": 14,
      "z": 5,
      "name": "Rock_Ice"
    },
    {
      "x": -21,
      "y": 15,
      "z": 5,
      "name": "Rock_Ice"
    },
    {
      "x": -21,
      "y": 16,
      "z": 5,
      "name": "Rock_Ice"
    },
    {
      "x": -21,
      "y": 17,
      "z": 5,
      "name": "Rock_Ice"
    },
    {
      "x": -21,
      "y": 18,
      "z": 5,
      "name": "Rock_Ice"
    },
    {
      "x": -21,
      "y": 19,
      "z": 5,
      "name": "Rock_Ice"
    },
    {
      "x": -21,
      "y": 20,
      "z": 5,
      "name": "Rock_Ice"
    },
    {
      "x": -21,
      "y": 21,
      "z": 5,
      "name": "Rock_Ice"
    },
    {
      "x": -21,
      "y": 22,
      "z": 5,
      "name": "Rock_Ice"
    },
    {
      "x": -21,
      "y": 23,
      "z": 5,
      "name": "Rock_Ice_Permafrost"
    },
    {
      "x": -21,
      "y": 24,
      "z": 5,
      "name": "Rock_Ice_Permafrost"
    },
    {
      "x": -21,
      "y": 25,
      "z": 5,
      "name": "Rock_Ice_Permafrost"
    },
    {
      "x": -21,
      "y": 26,
      "z": 5,
      "name": "Rock_Ice"
    },
    {
      "x": -21,
      "y": 27,
      "z": 5,
      "name": "Rock_Ice"
    },
    {
      "x": -21,
      "y": 28,
      "z": 5,
      "name": "Soil_Snow"
    },
    {
      "x": -21,
      "y": 63,
      "z": 5,
      "name": "Rock_Ice"
    },
    {
      "x": -21,
      "y": 64,
      "z": 5,
      "name": "Rock_Ice"
    },
    {
      "x": -21,
      "y": 65,
      "z": 5,
      "name": "Soil_Snow"
    },
    {
      "x": -21,
      "y": 8,
      "z": 6,
      "name": "Rock_Ice_Permafrost"
    },
    {
      "x": -21,
      "y": 9,
      "z": 6,
      "name": "Rock_Ice_Permafrost"
    },
    {
      "x": -21,
      "y": 10,
      "z": 6,
      "name": "Rock_Ice_Permafrost"
    },
    {
      "x": -21,
      "y": 11,
      "z": 6,
      "name": "Rock_Ice_Permafrost"
    },
    {
      "x": -21,
      "y": 12,
      "z": 6,
      "name": "Rock_Ice_Permafrost"
    },
    {
      "x": -21,
      "y": 13,
      "z": 6,
      "name": "Rock_Ice_Permafrost"
    },
    {
      "x": -21,
      "y": 14,
      "z": 6,
      "name": "Rock_Ice_Permafrost"
    },
    {
      "x": -21,
      "y": 15,
      "z": 6,
      "name": "Rock_Ice"
    },
    {
      "x": -21,
      "y": 16,
      "z": 6,
      "name": "Rock_Ice"
    },
    {
      "x": -21,
      "y": 17,
      "z": 6,
      "name": "Rock_Ice"
    },
    {
      "x": -21,
      "y": 18,
      "z": 6,
      "name": "Rock_Ice"
    },
    {
      "x": -21,
      "y": 19,
      "z": 6,
      "name": "Rock_Ice_Permafrost"
    },
    {
      "x": -21,
      "y": 20,
      "z": 6,
      "name": "Rock_Ice"
    },
    {
      "x": -21,
      "y": 21,
      "z": 6,
      "name": "Rock_Ice_Permafrost"
    },
    {
      "x": -21,
      "y": 22,
      "z": 6,
      "name": "Rock_Ice_Permafrost"
    },
    {
      "x": -21,
      "y": 23,
      "z": 6,
      "name": "Rock_Ice_Permafrost"
    },
    {
      "x": -21,
      "y": 24,
      "z": 6,
      "name": "Rock_Ice_Permafrost"
    },
    {
      "x": -21,
      "y": 25,
      "z": 6,
      "name": "Rock_Ice_Permafrost"
    },
    {
      "x": -21,
      "y": 26,
      "z": 6,
      "name": "Rock_Ice"
    },
    {
      "x": -21,
      "y": 27,
      "z": 6,
      "name": "Soil_Snow"
    },
    {
      "x": -21,
      "y": 62,
      "z": 6,
      "name": "Rock_Ice"
    },
    {
      "x": -21,
      "y": 63,
      "z": 6,
      "name": "Rock_Ice"
    },
    {
      "x": -21,
      "y": 64,
      "z": 6,
      "name": "Rock_Ice"
    },
    {
      "x": -21,
      "y": 65,
      "z": 6,
      "name": "Soil_Snow"
    },
    {
      "x": -21,
      "y": 7,
      "z": 7,
      "name": "Rock_Ice_Permafrost"
    },
    {
      "x": -21,
      "y": 8,
