{
  "version": 8,
  "blockIdVersion": 11,
  "anchorX": 3,
  "anchorY": 18,
  "anchorZ": 0,
  "blocks": [
    {
      "x": -23,
      "y": 21,
      "z": -11,
      "name": "Rock_Ice_Permafrost"
    },
    {
      "x": -23,
      "y": 22,
      "z": -11,
      "name": "Soil_Snow"
    },
    {
      "x": -23,
      "y": 20,
      "z": -10,
      "name": "Rock_Ice_Permafrost"
    },
    {
      "x": -23,
      "y": 21,
      "z": -10,
      "name": "Rock_Ice_Permafrost"
    },
    {
      "x": -23,
      "y": 22,
      "z": -10,
      "name": "Rock_Ice"
    },
    {
      "x": -23,
      "y": 23,
      "z": -10,
      "name": "Soil_Snow"
    },
    {
      "x": -23,
      "y": 21,
      "z": -9,
      "name": "Rock_Ice"
    },
    {
      "x": -23,
      "y": 22,
      "z": -9,
      "name": "Rock_Ice"
    },
    {
      "x": -23,
      "y": 23,
      "z": -9,
      "name": "Rock_Ice_Permafrost"
    },
    {
      "x": -23,
      "y": 24,
      "z": -9,
      "name": "Rock_Ice"
    },
    {
      "x": -23,
      "y": 25,
      "z": -9,
      "name": "Rock_Ice"
    },
    {
      "x": -23,
      "y": 26,
      "z": -9,
      "name": "Soil_Snow"
    },
    {
      "x": -23,
      "y": 21,
      "z": -8,
      "name": "Rock_Ice"
    },
    {
      "x": -23,
      "y": 22,
      "z": -8,
      "name": "Rock_Ice"
    },
    {
      "x": -23,
      "y": 23,
      "z": -8,
      "name": "Rock_Ice_Permafrost"
    },
    {
      "x": -23,
      "y": 24,
      "z": -8,
      "name": "Rock_Ice"
    },
    {
      "x": -23,
      "y": 25,
      "z": -8,
      "name": "Rock_Ice_Permafrost"
    },
    {
      "x": -23,
      "y": 26,
      "z": -8,
      "name": "Rock_Ice"
    },
    {
      "x": -23,
      "y": 27,
      "z": -8,
      "name": "Rock_Ice"
    },
    {
      "x": -23,
      "y": 28,
      "z": -8,
      "name": "Soil_Snow"
    },
    {
      "x": -23,
      "y": 25,
      "z": -7,
      "name": "Rock_Ice_Permafrost"
    },
    {
      "x": -23,
      "y": 26,
      "z": -7,
      "name": "Rock_Ice_Permafrost"
    },
    {
      "x": -23,
      "y": 27,
      "z": -7,
      "name": "Rock_Ice"
    },
    {
      "x": -23,
      "y": 28,
      "z": -7,
      "name": "Rock_Ice"
    },
    {
      "x": -23,
      "y": 29,
      "z": -7,
      "name": "Soil_Snow"
    },
    {
      "x": -23,
      "y": 27,
      "z": -6,
      "name": "Rock_Ice_Permafrost"
    },
    {
      "x": -23,
      "y": 28,
      "z": -6,
      "name": "Rock_Ice_Permafrost"
    },
    {
      "x": -23,
      "y": 29,
      "z": -6,
      "name": "Soil_Snow"
    },
    {
      "x": -22,
      "y": 18,
      "z": -11,
      "name": "Rock_Ice_Permafrost"
    },
    {
      "x": -22,
      "y": 19,
      "z": -11,
      "name": "Rock_Ice_Permafrost"
    },
    {
      "x": -22,
      "y": 20,
      "z": -11,
      "name": "Rock_Ice_Permafrost"
    },
    {
      "x": -22,
      "y": 21,
      "z": -11,
      "name": "Rock_Ice"
    },
    {
      "x": -22,
      "y": 22,
      "z": -11,
      "name": "Rock_Ice_Permafrost"
    },
    {
      "x": -22,
      "y": 19,
      "z": -10,
      "name": "Rock_Ice"
    },
    {
      "x": -22,
      "y": 20,
      "z": -10,
      "name": "Rock_Ice_Permafrost"
    },
    {
      "x": -22,
      "y": 21,
      "z": -10,
      "name": "Rock_Ice_Permafrost"
    },
    {
      "x": -22,
      "y": 22,
      "z": -10,
      "name": "Rock_Ice_Permafrost"
    },
    {
      "x": -22,
      "y": 23,
      "z": -10,
      "name": "Rock_Ice"
    },
    {
      "x": -22,
      "y": 24,
      "z": -10,
      "name": "Rock_Ice"
    },
    {
      "x": -22,
      "y": 25,
      "z": -10,
      "name": "Rock_Ice_Permafrost"
    },
    {
      "x": -22,
      "y": 26,
      "z": -10,
      "name": "Rock_Ice_Permafrost"
    },
    {
      "x": -22,
      "y": 27,
      "z": -10,
      "name": "Rock_Ice"
    },
    {
      "x": -22,
      "y": 28,
      "z": -10,
      "name": "Soil_Snow"
    },
    {
      "x": -22,
      "y": 19,
      "z": -9,
      "name": "Rock_Ice"
    },
    {
      "x": -22,
      "y": 20,
      "z": -9,
      "name": "Rock_Ice"
    },
    {
      "x": -22,
      "y": 21,
      "z": -9,
      "name": "Rock_Ice_Permafrost"
    },
    {
      "x": -22,
      "y": 22,
      "z": -9,
      "name": "Rock_Ice_Permafrost"
    },
    {
      "x": -22,
      "y": 23,
      "z": -9,
      "name": "Rock_Ice"
    },
    {
      "x": -22,
      "y": 24,
      "z": -9,
      "name": "Rock_Ice"
    },
    {
      "x": -22,
      "y": 25,
      "z": -9,
      "name": "Rock_Ice_Permafrost"
    },
    {
      "x": -22,
      "y": 26,
      "z": -9,
      "name": "Rock_Ice"
    },
    {
      "x": -22,
      "y": 27,
      "z": -9,
      "name": "Rock_Ice_Permafrost"
    },
    {
      "x": -22,
      "y": 28,
      "z": -9,
      "name": "Rock_Ice"
    },
    {
      "x": -22,
      "y": 29,
      "z": -9,
      "name": "Soil_Snow"
    },
    {
      "x": -22,
      "y": 20,
      "z": -8,
      "name": "Rock_Ice"
    },
    {
      "x": -22,
      "y": 21,
      "z": -8,
      "name": "Rock_Ice"
    },
    {
      "x": -22,
      "y": 22,
      "z": -8,
      "name": "Rock_Ice_Permafrost"
    },
    {
      "x": -22,
      "y": 23,
      "z": -8,
      "name": "Rock_Ice_Permafrost"
    },
    {
      "x": -22,
      "y": 24,
      "z": -8,
      "name": "Rock_Ice_Permafrost"
    },
    {
      "x": -22,
      "y": 25,
      "z": -8,
      "name": "Rock_Ice_Permafrost"
    },
    {
      "x": -22,
      "y": 26,
      "z": -8,
      "name": "Rock_Ice"
    },
    {
      "x": -22,
      "y": 27,
      "z": -8,
      "name": "Rock_Ice_Permafrost"
    },
    {
      "x": -22,
      "y": 28,
      "z": -8,
      "name": "Rock_Ice"
    },
    {
      "x": -22,
      "y": 29,
      "z": -8,
      "name": "Soil_Snow"
    },
    {
      "x": -22,
      "y": 22,
      "z": -7,
      "name": "Rock_Ice_Permafrost"
    },
    {
      "x": -22,
      "y": 23,
      "z": -7,
      "name": "Rock_Ice_Permafrost"
    },
    {
      "x": -22,
      "y": 24,
      "z": -7,
      "name": "Rock_Ice_Permafrost"
    },
    {
      "x": -22,
      "y": 25,
      "z": -7,
      "name": "Rock_Ice_Permafrost"
    },
    {
      "x": -22,
      "y": 26,
      "z": -7,
      "name": "Rock_Ice_Permafrost"
    },
    {
      "x": -22,
      "y": 27,
      "z": -7,
      "name": "Rock_Ice_Permafrost"
    },
    {
      "x": -22,
      "y": 28,
      "z": -7,
      "name": "Rock_Ice_Permafrost"
    },
    {
      "x": -22,
      "y": 29,
      "z": -7,
      "name": "Rock_Ice"
    },
    {
      "x": -22,
      "y": 30,
      "z": -7,
      "name": "Soil_Snow"
    },
    {
      "x": -22,
      "y": 22,
      "z": -6,
      "name": "Rock_Ice_Permafrost"
    },
    {
      "x": -22,
      "y": 23,
      "z": -6,
      "name": "Rock_Ice_Permafrost"
    },
    {
      "x": -22,
      "y": 24,
      "z": -6,
      "name": "Rock_Ice_Permafrost"
    },
    {
      "x": -22,
      "y": 25,
      "z": -6,
      "name": "Rock_Ice_Permafrost"
    },
    {
      "x": -22,
      "y": 26,
      "z": -6,
      "name": "Rock_Ice_Permafrost"
    },
    {
      "x": -22,
      "y": 27,
      "z": -6,
      "name": "Rock_Ice_Permafrost"
    },
    {
      "x": -22,
      "y": 28,
      "z": -6,
      "name": "Rock_Ice_Permafrost"
    },
    {
      "x": -22,
      "y": 29,
      "z": -6,
      "name": "Rock_Ice"
    },
    {
      "x": -22,
      "y": 30,
      "z": -6,
      "name": "Soil_Snow"
    },
    {
      "x": -22,
      "y": 24,
      "z": -5,
      "name": "Rock_Ice_Permafrost"
    },
    {
      "x": -22,
      "y": 25,
      "z": -5,
      "name": "Rock_Ice_Permafrost"
    },
    {
      "x": -22,
      "y": 26,
      "z": -5,
      "name": "Rock_Ice_Permafrost"
    },
    {
      "x": -22,
      "y": 27,
      "z": -5,
      "name": "Rock_Ice_Permafrost"
    },
    {
      "x": -22,
      "y": 28,
      "z": -5,
      "name": "Rock_Ice_Permafrost"
    },
    {
      "x": -22,
      "y": 29,
      "z": -5,
      "name": "Soil_Snow"
    },
    {
      "x": -21,
      "y": 16,
      "z": -12,
      "name": "Rock_Ice_Permafrost"
    },
    {
      "x": -21,
      "y": 17,
      "z": -12,
      "name": "Rock_Ice_Permafrost"
    },
    {
      "x": -21,
      "y": 18,
      "z": -12,
      "name": "Rock_Ice_Permafrost"
    },
    {
      "x": -21,
      "y": 19,
      "z": -12,
      "name": "Rock_Ice_Permafrost"
    },
    {
      "x": -21,
      "y": 20,
      "z": -12,
      "name": "Rock_Ice_Permafrost"
    },
    {
      "x": -21,
      "y": 21,
      "z": -12,
      "name": "Rock_Ice"
    },
    {
      "x": -21,
      "y": 22,
      "z": -12,
      "name": "Soil_Snow"
    },
    {
      "x": -21,
      "y": 16,
      "z": -11,
      "name": "Rock_Ice_Permafrost"
    },
    {
      "x": -21,
      "y": 17,
      "z": -11,
      "name": "Rock_Ice_Permafrost"
    },
    {
      "x": -21,
      "y": 18,
      "z": -11,
      "name": "Rock_Ice_Permafrost"
    },
    {
      "x": -21,
      "y": 19,
      "z": -11,
      "name": "Rock_Ice_Permafrost"
    },
    {
      "x": -21,
      "y": 20,
      "z": -11,
      "name": "Rock_Ice_Permafrost"
    },
    {
      "x": -21,
      "y": 21,
      "z": -11,
      "name": "Rock_Ice_Permafrost"
    },
    {
      "x": -21,
      "y": 22,
      "z": -11,
      "name": "Rock_Ice"
    },
    {
      "x": -21,
      "y": 23,
      "z": -11,
      "name": "Rock_Ice"
    },
    {
      "x": -21,
      "y": 24,
      "z": -11,
      "name": "Rock_Ice_Permafrost"
    },
    {
      "x": -21,
      "y": 25,
      "z": -11,
      "name": "Rock_Ice_Permafrost"
    },
    {
      "x": -21,
      "y": 26,
      "z": -11,
      "name": "Rock_Ice_Permafrost"
    },
    {
      "x": -21,
      "y": 27,
      "z": -11,
      "name": "Rock_Ice"
    },
    {
      "x": -21,
      "y": 28,
      "z": -11,
      "name": "Soil_Snow"
    },
    {
      "x": -21,
      "y": 17,
      "z": -10,
      "name": "Rock_Ice"
    },
    {
      "x": -21,
      "y": 18,
      "z": -10,
      "name": "Rock_Ice_Permafrost"
    },
    {
      "x": -21,
      "y": 19,
      "z": -10,
      "name": "Rock_Ice_Permafrost"
    },
    {
      "x": -21,
      "y": 20,
      "z": -10,
      "name": "Rock_Ice_Permafrost"
    },
    {
      "x": -21,
      "y": 21,
      "z": -10,
      "name": "Rock_Ice"
    },
    {
      "x": -21,
      "y": 22,
      "z": -10,
      "name": "Rock_Ice_Permafrost"
    },
    {
      "x": -21,
      "y": 23,
      "z": -10,
      "name": "Rock_Ice"
    },
    {
      "x": -21,
      "y": 24,
      "z": -10,
      "name": "Rock_Ice_Permafrost"
    },
    {
      "x": -21,
      "y": 25,
      "z": -10,
      "name": "Rock_Ice_Permafrost"
    },
    {
      "x": -21,
      "y": 26,
      "z": -10,
      "name": "Rock_Ice"
    },
    {
      "x": -21,
      "y": 27,
      "z": -10,
      "name": "Rock_Ice"
    },
    {
      "x": -21,
      "y": 28,
      "z": -10,
      "name": "Rock_Ice"
    },
    {
      "x": -21,
      "y": 29,
      "z": -10,
      "name": "Soil_Snow"
    },
    {
      "x": -21,
      "y": 17,
      "z": -9,
      "name": "Rock_Ice_Permafrost"
    },
    {
      "x": -21,
      "y": 18,
      "z": -9,
      "name": "Rock_Ice"
    },
    {
      "x": -21,
      "y": 19,
      "z": -9,
      "name": "Rock_Ice"
    },
    {
      "x": -21,
      "y": 20,
      "z": -9,
      "name": "Rock_Ice"
    },
    {
      "x": -21,
      "y": 21,
      "z": -9,
      "name": "Rock_Ice"
    },
    {
      "x": -21,
      "y": 22,
      "z": -9,
      "name": "Rock_Ice_Permafrost"
    },
    {
      "x": -21,
      "y": 23,
      "z": -9,
      "name": "Rock_Ice_Permafrost"
    },
    {
      "x": -21,
      "y": 24,
      "z": -9,
      "name": "Rock_Ice"
    },
    {
      "x": -21,
      "y": 25,
      "z": -9,
      "name": "Rock_Ice_Permafrost"
    },
    {
      "x": -21,
      "y": 26,
      "z": -9,
      "name": "Rock_Ice"
    },
    {
      "x": -21,
      "y": 27,
      "z": -9,
      "name": "Rock_Ice"
    },
    {
      "x": -21,
      "y": 28,
      "z": -9,
      "name": "Rock_Ice"
    },
    {
      "x": -21,
      "y": 29,
      "z": -9,
      "name": "Rock_Ice"
    },
    {
      "x": -21,
      "y": 30,
      "z": -9,
      "name": "Soil_Snow"
    },
    {
      "x": -21,
      "y": 18,
      "z": -8,
      "name": "Rock_Ice"
    },
    {
      "x": -21,
      "y": 19,
      "z": -8,
      "name": "Rock_Ice"
    },
    {
      "x": -21,
      "y": 20,
      "z": -8,
      "name": "Rock_Ice_Permafrost"
    },
    {
      "x": -21,
      "y": 21,
      "z": -8,
      "name": "Rock_Ice"
    },
    {
      "x": -21,
      "y": 22,
      "z": -8,
      "name": "Rock_Ice"
    },
    {
      "x": -21,
      "y": 23,
      "z": -8,
      "name": "Rock_Ice_Permafrost"
    },
    {
      "x": -21,
      "y": 24,
      "z": -8,
      "name": "Rock_Ice_Permafrost"
    },
    {
      "x": -21,
      "y": 25,
      "z": -8,
      "name": "Rock_Ice_Permafrost"
    },
    {
      "x": -21,
      "y": 26,
      "z": -8,
      "name": "Rock_Ice"
    },
    {
      "x": -21,
      "y": 27,
      "z": -8,
      "name": "Rock_Ice_Permafrost"
    },
    {
      "x": -21,
      "y": 28,
      "z": -8,
      "name": "Rock_Ice_Permafrost"
    },
    {
      "x": -21,
      "y": 29,
      "z": -8,
      "name": "Rock_Ice"
    },
    {
      "x": -21,
      "y": 30,
      "z": -8,
      "name": "Soil_Snow"
    },
    {
      "x": -21,
      "y": 18,
      "z": -7,
      "name": "Rock_Ice"
    },
    {
      "x": -21,
      "y": 19,
      "z": -7,
      "name": "Rock_Ice_Permafrost"
    },
    {
      "x": -21,
      "y": 20,
      "z": -7,
      "name": "Rock_Ice_Permafrost"
    },
    {
      "x": -21,
      "y": 21,
      "z": -7,
      "name": "Rock_Ice"
    },
    {
      "x": -21,
      "y": 22,
      "z": -7,
      "name": "Rock_Ice_Permafrost"
    },
    {
      "x": -21,
      "y": 23,
      "z": -7,
      "name": "Rock_Ice_Permafrost"
    },
    {
      "x": -21,
      "y": 24,
      "z": -7,
      "name": "Rock_Ice_Permafrost"
    },
    {
      "x": -21,
      "y": 25,
      "z": -7,
      "name": "Rock_Ice_Permafrost"
    },
    {
      "x": -21,
      "y": 26,
      "z": -7,
      "name": "Rock_Ice_Permafrost"
    },
    {
      "x": -21,
      "y": 27,
      "z": -7,
      "name": "Rock_Ice_Permafrost"
    },
    {
      "x": -21,
      "y": 28,
      "z": -7,
      "name": "Rock_Ice_Permafrost"
    },
    {
      "x": -21,
      "y": 29,
      "z": -7,
      "name": "Rock_Ice_Permafrost"
    },
    {
      "x": -21,
      "y": 30,
      "z": -7,
      "name": "Rock_Ice"
    },
    {
      "x": -21,
      "y": 31,
      "z": -7,
      "name": "Soil_Snow"
    },
    {
      "x": -21,
      "y": 19,
      "z": -6,
      "name": "Rock_Ice_Permafrost"
    },
    {
      "x": -21,
      "y": 20,
      "z": -6,
      "name": "Rock_Ice_Permafrost"
    },
    {
      "x": -21,
      "y": 21,
      "z": -6,
      "name": "Rock_Ice_Permafrost"
    },
    {
      "x": -21,
      "y": 22,
      "z": -6,
      "name": "Rock_Ice_Permafrost"
    },
    {
      "x": -21,
      "y": 23,
      "z": -6,
      "name": "Rock_Ice_Permafrost"
    },
    {
      "x": -21,
      "y": 24,
      "z": -6,
      "name": "Rock_Ice_Permafrost"
    },
    {
      "x": -21,
      "y": 25,
      "z": -6,
      "name": "Rock_Ice_Permafrost"
    },
    {
      "x": -21,
      "y": 26,
      "z": -6,
      "name": "Rock_Ice_Permafrost"
    },
    {
      "x": -21,
      "y": 27,
      "z": -6,
      "name": "Rock_Ice_Permafrost"
    },
    {
      "x": -21,
      "y": 28,
      "z": -6,
      "name": "Rock_Ice_Permafrost"
    },
    {
      "x": -21,
      "y": 29,
      "z": -6,
      "name": "Rock_Ice_Permafrost"
    },
    {
      "x": -21,
      "y": 30,
      "z": -6,
      "name": "Rock_Ice"
    },
    {
      "x": -21,
      "y": 31,
      "z": -6,
      "name": "Soil_Snow"
    },
    {
      "x": -21,
      "y": 22,
      "z": -5,
      "name": "Rock_Ice_Permafrost"
    },
    {
      "x": -21,
      "y": 23,
      "z": -5,
      "name": "Rock_Ice_Permafrost"
    },
    {
      "x": -21,
      "y": 24,
      "z": -5,
      "name": "Rock_Ice_Permafrost"
    },
    {
      "x": -21,
      "y": 25,
      "z": -5,
      "name": "Rock_Ice_Permafrost"
    },
    {
      "x": -21,
      "y": 26,
      "z": -5,
      "name": "Rock_Ice_Permafrost"
    },
    {
      "x": -21,
      "y": 27,
      "z": -5,
      "name": "Rock_Ice_Permafrost"
    },
    {
      "x": -21,
      "y": 28,
      "z": -5,
      "name": "Rock_Ice_Permafrost"
    },
    {
      "x": -21,
      "y": 29,
      "z": -5,
      "name": "Rock_Ice_Permafrost"
    },
    {
      "x": -21,
      "y": 30,
      "z": -5,
      "name": "Rock_Ice"
    },
    {
      "x": -21,
      "y": 31,
      "z": -5,
      "name": "Soil_Snow"
    },
    {
      "x": -21,
      "y": 22,
      "z": -4,
      "name": "Rock_Ice_Permafrost"
    },
    {
      "x": -21,
      "y": 23,
      "z": -4,
      "name": "Rock_Ice_Permafrost"
    },
    {
      "x": -21,
      "y": 24,
      "z": -4,
      "name": "Rock_Ice_Permafrost"
    },
    {
      "x": -21,
      "y": 25,
      "z": -4,
      "name": "Rock_Ice_Permafrost"
    },
    {
      "x": -21,
      "y": 26,
      "z": -4,
      "name": "Rock_Ice_Permafrost"
    },
    {
      "x": -21,
      "y": 27,
      "z": -4,
      "name": "Rock_Ice_Permafrost"
    },
    {
      "x": -21,
      "y": 28,
      "z": -4,
      "name": "Rock_Ice_Permafrost"
    },
    {
      "x": -21,
      "y": 29,
      "z": -4,
      "name": "Soil_Snow"
    },
    {
      "x": -20,
      "y": 17,
      "z": -13,
      "name": "Rock_Ice_Permafrost"
    },
    {
      "x": -20,
      "y": 18,
      "z": -13,
      "name": "Rock_Ice_Permafrost"
    },
    {
      "x": -20,
      "y": 19,
      "z": -13,
      "name": "Rock_Ice_Permafrost"
    },
    {
      "x": -20,
      "y": 20,
      "z": -13,
      "name": "Rock_Ice_Permafrost"
    },
    {
      "x": -20,
      "y": 21,
      "z": -13,
      "name": "Rock_Ice"
    },
    {
      "x": -20,
      "y": 22,
      "z": -13,
      "name": "Soil_Snow"
    },
    {
      "x": -20,
      "y": 15,
      "z": -12,
      "name": "Rock_Ice_Permafrost"
    },
    {
      "x": -20,
      "y": 16,
      "z": -12,
      "name": "Rock_Ice_Permafrost"
    },
    {
      "x": -20,
      "y": 17,
      "z": -12,
      "name": "Rock_Ice_Permafrost"
    },
    {
      "x": -20,
      "y": 18,
      "z": -12,
      "name": "Rock_Ice_Permafrost"
    },
    {
      "x": -20,
      "y": 19,
      "z": -12,
      "name": "Rock_Ice_Permafrost"
    },
    {
      "x": -20,
      "y": 20,
      "z": -12,
      "name": "Rock_Ice_Permafrost"
    },
    {
      "x": -20,
      "y": 21,
      "z": -12,
      "name": "Rock_Ice_Permafrost"
    },
    {
      "x": -20,
      "y": 22,
      "z": -12,
      "name": "Rock_Ice_Permafrost"
    },
    {
      "x": -20,
      "y": 23,
      "z": -12,
      "name": "Rock_Ice_Permafrost"
    },
    {
      "x": -20,
      "y": 26,
      "z": -12,
      "name": "Rock_Ice_Permafrost"
    },
    {
      "x": -20,
      "y": 27,
      "z": -12,
      "name": "Rock_Ice_Permafrost"
    },
    {
      "x": -20,
      "y": 28,
      "z": -12,
      "name": "Soil_Snow"
    },
    {
      "x": -20,
      "y": 15,
      "z": -11,
      "name": "Rock_Ice_Permafrost"
    },
    {
      "x": -20,
      "y": 16,
      "z": -11,
      "name": "Rock_Ice_Permafrost"
    },
    {
      "x": -20,
      "y": 17,
      "z": -11,
      "name": "Rock_Ice_Permafrost"
    },
    {
      "x": -20,
      "y": 18,
      "z": -11,
      "name": "Rock_Ice_Permafrost"
    },
    {
      "x": -20,
      "y": 19,
      "z": -11,
      "name": "Rock_Ice_Permafrost"
    },
    {
      "x": -20,
      "y": 20,
      "z": -11,
      "name": "Rock_Ice_Permafrost"
    },
    {
      "x": -20,
      "y": 21,
      "z": -11,
      "name": "Rock_Ice"
    },
    {
      "x": -20,
      "y": 22,
      "z": -11,
      "name": "Rock_Ice_Permafrost"
    },
    {
      "x": -20,
      "y": 23,
      "z": -11,
      "name": "Rock_Ice_Permafrost"
    },
    {
      "x": -20,
      "y": 24,
      "z": -11,
      "name": "Rock_Ice_Permafrost"
    },
    {
      "x": -20,
      "y": 25,
      "z": -11,
      "name": "Rock_Ice_Permafrost"
    },
    {
      "x": -20,
      "y": 26,
      "z": -11,
      "name": "Rock_Ice_Permafrost"
    },
    {
      "x": -20,
      "y": 27,
      "z": -11,
      "name": "Rock_Ice_Permafrost"
    },
    {
      "x": -20,
      "y": 28,
      "z": -11,
      "name": "Rock_Ice"
    },
    {
      "x": -20,
      "y": 29,
      "z": -11,
      "name": "Soil_Snow"
    },
    {
      "x": -20,
      "y": 16,
      "z": -10,
      "name": "Rock_Ice_Permafrost"
    },
    {
      "x": -20,
      "y": 17,
      "z": -10,
      "name": "Rock_Ice_Permafrost"
    },
    {
      "x": -20,
      "y": 18,
      "z": -10,
      "name": "Rock_Ice"
    },
    {
      "x": -20,
      "y": 19,
      "z": -10,
      "name": "Rock_Ice"
    },
    {
      "x": -20,
      "y": 20,
      "z": -10,
      "name": "Rock_Ice"
    },
    {
      "x": -20,
      "y": 21,
      "z": -10,
      "name": "Rock_Ice"
    },
    {
      "x": -20,
      "y": 22,
      "z": -10,
      "name": "Rock_Ice"
    },
    {
      "x": -20,
      "y": 23,
      "z": -10,
      "name": "Rock_Ice"
    },
    {
      "x": -20,
      "y": 24,
      "z": -10,
      "name": "Rock_Ice"
    },
    {
      "x": -20,
      "y": 25,
      "z": -10,
      "name": "Rock_Ice"
    },
    {
      "x": -20,
      "y": 26,
      "z": -10,
      "name": "Rock_Ice"
    },
    {
      "x": -20,
      "y": 27,
      "z": -10,
      "name": "Rock_Ice_Permafrost"
    },
    {
      "x": -20,
      "y": 28,
      "z": -10,
      "name": "Rock_Ice"
    },
    {
      "x": -20,
      "y": 29,
      "z": -10,
      "name": "Rock_Ice"
    },
    {
      "x": -20,
      "y": 30,
      "z": -10,
      "name": "Soil_Snow"
    },
    {
      "x": -20,
      "y": 16,
      "z": -9,
      "name": "Rock_Ice_Permafrost"
    },
    {
      "x": -20,
      "y": 17,
      "z": -9,
      "name": "Rock_Ice_Permafrost"
    },
    {
      "x": -20,
      "y": 18,
      "z": -9,
      "name": "Rock_Ice"
    },
    {
      "x": -20,
      "y": 19,
      "z": -9,
      "name": "Rock_Ice"
    },
    {
      "x": -20,
      "y": 20,
      "z": -9,
      "name": "Rock_Ice"
    },
    {
      "x": -20,
      "y": 21,
      "z": -9,
      "name": "Rock_Ice"
    },
    {
      "x": -20,
      "y": 22,
      "z": -9,
      "name": "Rock_Ice"
    },
    {
      "x": -20,
      "y": 23,
      "z": -9,
      "name": "Rock_Ice"
    },
    {
      "x": -20,
      "y": 24,
      "z": -9,
      "name": "Rock_Ice"
    },
    {
      "x": -20,
      "y": 25,
      "z": -9,
      "name": "Rock_Ice_Permafrost"
    },
    {
      "x": -20,
      "y": 26,
      "z": -9,
      "name": "Rock_Ice"
    },
    {
      "x": -20,
      "y": 27,
      "z": -9,
      "name": "Rock_Ice"
    },
    {
      "x": -20,
      "y": 28,
      "z": -9,
      "name": "Rock_Ice_Permafrost"
    },
    {
      "x": -20,
      "y": 29,
      "z": -9,
      "name": "Rock_Ice_Permafrost"
    },
    {
      "x": -20,
      "y": 30,
      "z": -9,
      "name": "Rock_Ice"
    },
    {
      "x": -20,
      "y": 31,
      "z": -9,
      "name": "Soil_Snow"
    },
    {
      "x": -20,
      "y": 16,
      "z": -8,
      "name": "Rock_Ice"
    },
    {
      "x": -20,
      "y": 17,
      "z": -8,
      "name": "Rock_Ice"
    },
    {
      "x": -20,
      "y": 18,
      "z": -8,
      "name": "Rock_Ice"
    },
    {
      "x": -20,
      "y": 19,
      "z": -8,
      "name": "Rock_Ice_Permafrost"
    },
    {
      "x": -20,
      "y": 20,
      "z": -8,
      "name": "Rock_Ice_Permafrost"
    },
    {
      "x": -20,
      "y": 21,
      "z": -8,
      "name": "Rock_Ice"
    },
    {
      "x": -20,
      "y": 22,
      "z": -8,
      "name": "Rock_Ice_Permafrost"
    },
    {
      "x": -20,
      "y": 23,
      "z": -8,
      "name": "Rock_Ice_Permafrost"
    },
    {
      "x": -20,
      "y": 24,
      "z": -8,
      "name": "Rock_Ice_Permafrost"
    },
    {
      "x": -20,
      "y": 25,
      "z": -8,
      "name": "Rock_Ice_Permafrost"
    },
    {
      "x": -20,
      "y": 26,
      "z": -8,
      "name": "Rock_Ice_Permafrost"
    },
    {
      "x": -20,
      "y": 27,
      "z": -8,
      "name": "Rock_Ice_Permafrost"
    },
    {
      "x": -20,
      "y": 28,
      "z": -8,
      "name": "Rock_Ice_Permafrost"
    },
    {
      "x": -20,
      "y": 29,
      "z": -8,
      "name": "Rock_Ice_Permafrost"
    },
    {
      "x": -20,
      "y": 30,
      "z": -8,
      "name": "Rock_Ice"
    },
    {
      "x": -20,
      "y": 31,
      "z": -8,
      "name": "Soil_Snow"
    },
    {
      "x": -20,
      "y": 17,
      "z": -7,
      "name": "Rock_Ice"
    },
    {
      "x": -20,
      "y": 18,
      "z": -7,
      "name": "Rock_Ice"
    },
    {
      "x": -20,
      "y": 19,
      "z": -7,
      "name": "Rock_Ice"
    },
    {
      "x": -20,
      "y": 20,
      "z": -7,
      "name": "Rock_Ice_Permafrost"
    },
    {
      "x": -20,
      "y": 21,
      "z": -7,
      "name": "Rock_Ice_Permafrost"
    },
    {
      "x": -20,
      "y": 22,
      "z": -7,
      "name": "Rock_Ice_Permafrost"
    },
    {
      "x": -20,
      "y": 23,
      "z": -7,
      "name": "Rock_Ice_Permafrost"
    },
    {
      "x": -20,
      "y": 24,
      "z": -7,
      "name": "Rock_Ice_Permafrost"
    },
    {
      "x": -20,
      "y": 25,
      "z": -7,
      "name": "Rock_Ice_Permafrost"
    },
    {
      "x": -20,
      "y": 26,
      "z": -7,
      "name": "Rock_Ice_Permafrost"
    },
    {
      "x": -20,
      "y": 27,
      "z": -7,
      "name": "Rock_Ice_Permafrost"
    },
    {
      "x": -20,
      "y": 28,
      "z": -7,
      "name": "Rock_Ice_Permafrost"
    },
    {
      "x": -20,
      "y": 29,
      "z": -7,
      "name": "Rock_Ice_Permafrost"
    },
    {
      "x": -20,
      "y": 30,
      "z": -7,
      "name": "Rock_Ice"
    },
    {
      "x": -20,
      "y": 31,
      "z": -7,
      "name": "Soil_Snow"
    },
    {
      "x": -20,
      "y": 17,
      "z": -6,
      "name": "Rock_Ice_Permafrost"
    },
    {
      "x": -20,
      "y": 18,
      "z": -6,
      "name": "Rock_Ice_Permafrost"
    },
    {
      "x": -20,
      "y": 19,
      "z": -6,
      "name": "Rock_Ice_Permafrost"
    },
    {
      "x": -20,
      "y": 20,
      "z": -6,
      "name": "Rock_Ice_Permafrost"
    },
    {
      "x": -20,
      "y": 21,
      "z": -6,
      "name": "Rock_Ice_Permafrost"
    },
    {
      "x": -20,
      "y": 22,
      "z": -6,
      "name": "Rock_Ice_Permafrost"
    },
    {
      "x": -20,
      "y": 23,
      "z": -6,
      "name": "Rock_Ice_Permafrost"
    },
    {
      "x": -20,
      "y": 24,
      "z": -6,
      "name": "Rock_Ice_Permafrost"
    },
    {
      "x": -20,
      "y": 25,
      "z": -6,
      "name": "Rock_Ice_Permafrost"
    },
    {
      "x": -20,
      "y": 26,
      "z": -6,
      "name": "Rock_Ice_Permafrost"
    },
    {
      "x": -20,
      "y": 27,
      "z": -6,
      "name": "Rock_Ice_Permafrost"
    },
    {
      "x": -20,
      "y": 28,
      "z": -6,
      "name": "Rock_Ice_Permafrost"
    },
    {
      "x": -20,
      "y": 29,
      "z": -6,
      "name": "Rock_Ice_Permafrost"
    },
    {
      "x": -20,
      "y": 30,
      "z": -6,
      "name": "Rock_Ice"
    },
    {
      "x": -20,
      "y": 31,
      "z": -6,
      "name": "Soil_Snow"
    },
    {
      "x": -20,
      "y": 18,
      "z": -5,
      "name": "Rock_Ice_Permafrost"
    },
    {
      "x": -20,
      "y": 19,
      "z": -5,
      "name": "Rock_Ice_Permafrost"
    },
    {
      "x": -20,
      "y": 20,
      "z": -5,
      "name": "Rock_Ice_Permafrost"
    },
    {
      "x": -20,
      "y": 21,
      "z": -5,
      "name": "Rock_Ice_Permafrost"
    },
    {
      "x": -20,
      "y": 22,
      "z": -5,
      "name": "Rock_Ice_Permafrost"
    },
    {
      "x": -20,
      "y": 23,
      "z": -5,
      "name": "Rock_Ice_Permafrost"
    },
    {
      "x": -20,
      "y": 24,
      "z": -5,
      "name": "Rock_Ice_Permafrost"
    },
    {
      "x": -20,
      "y": 25,
      "z": -5,
      "name": "Rock_Ice_Permafrost"
    },
    {
      "x": -20,
      "y": 26,
      "z": -5,
      "name": "Rock_Ice_Permafrost"
    },
    {
      "x": -20,
      "y": 27,
      "z": -5,
      "name": "Rock_Ice_Permafrost"
    },
    {
      "x": -20,
      "y": 28,
      "z": -5,
      "name": "Rock_Ice_Permafrost"
    },
    {
      "x": -20,
      "y": 29,
      "z": -5,
      "name": "Rock_Ice_Permafrost"
    },
    {
      "x": -20,
      "y": 30,
      "z": -5,
      "name": "Rock_Ice"
    },
    {
      "x": -20,
      "y": 31,
      "z": -5,
      "name": "Soil_Snow"
    },
    {
      "x": -20,
      "y": 19,
      "z": -4,
      "name": "Rock_Ice_Permafrost"
    },
    {
      "x": -20,
      "y": 20,
      "z": -4,
      "name": "Rock_Ice_Permafrost"
    },
    {
      "x": -20,
      "y": 21,
      "z": -4,
      "name": "Rock_Ice_Permafrost"
    },
    {
      "x": -20,
      "y": 22,
      "z": -4,
      "name": "Rock_Ice_Permafrost"
    },
    {
      "x": -20,
      "y": 23,
      "z": -4,
      "name": "Rock_Ice_Permafrost"
    },
    {
      "x": -20,
      "y": 24,
      "z": -4,
      "name": "Rock_Ice_Permafrost"
    },
    {
      "x": -20,
      "y": 25,
      "z": -4,
      "name": "Rock_Ice_Permafrost"
    },
    {
      "x": -20,
      "y": 26,
      "z": -4,
      "name": "Rock_Ice_Permafrost"
    },
    {
      "x": -20,
      "y": 27,
      "z": -4,
      "name": "Rock_Ice_Permafrost"
    },
    {
      "x": -20,
      "y": 28,
      "z": -4,
      "name": "Rock_Ice_Permafrost"
    },
    {
      "x": -20,
      "y": 29,
      "z": -4,
      "name": "Rock_Ice"
    },
    {
      "x": -20,
      "y": 30,
      "z": -4,
      "name": "Rock_Ice"
    },
    {
      "x": -20,
      "y": 31,
      "z": -4,
      "name": "Soil_Snow"
    },
    {
      "x": -20,
      "y": 22,
      "z": -3,
      "name": "Rock_Ice_Permafrost"
    },
    {
      "x": -20,
      "y": 23,
      "z": -3,
      "name": "Rock_Ice_Permafrost"
    },
    {
      "x": -20,
      "y": 24,
      "z": -3,
      "name": "Rock_Ice"
    },
    {
      "x": -20,
      "y": 25,
      "z": -3,
      "name": "Rock_Ice_Permafrost"
    },
    {
      "x": -20,
      "y": 21,
      "z": -2,
      "name": "Rock_Ice"
    },
    {
      "x": -20,
      "y": 22,
      "z": -2,
      "name": "Rock_Ice"
    },
    {
      "x": -20,
      "y": 23,
      "z": -2,
      "name": "Rock_Ice"
    },
    {
      "x": -20,
      "y": 24,
      "z": -2,
      "name": "Rock_Ice"
    },
    {
      "x": -20,
      "y": 25,
      "z": -2,
      "name": "Soil_Snow"
    },
    {
      "x": -20,
      "y": 21,
      "z": -1,
      "name": "Rock_Ice"
    },
    {
      "x": -20,
      "y": 22,
      "z": -1,
      "name": "Rock_Ice"
    },
    {
      "x": -20,
      "y": 23,
      "z": -1,
      "name": "Rock_Ice"
    },
    {
      "x": -20,
      "y": 24,
      "z": -1,
      "name": "Rock_Ice"
    },
    {
      "x": -20,
      "y": 25,
      "z": -1,
      "name": "Soil_Snow"
    },
    {
      "x": -20,
      "y": 20,
      "z": 0,
      "name": "Rock_Ice"
    },
    {
      "x": -20,
      "y": 21,
      "z": 0,
      "name": "Rock_Ice"
    },
    {
      "x": -20,
      "y": 22,
      "z": 0,
      "name": "Rock_Ice"
    },
    {
      "x": -20,
      "y": 23,
      "z": 0,
      "name": "Rock_Ice"
    },
    {
      "x": -20,
      "y": 24,
      "z": 0,
      "name": "Rock_Ice"
    },
    {
      "x": -20,
      "y": 25,
      "z": 0,
      "name": "Rock_Ice"
    },
    {
      "x": -20,
      "y": 21,
      "z": 1,
      "name": "Rock_Ice"
    },
    {
      "x": -20,
      "y": 22,
      "z": 1,
      "name": "Rock_Ice"
    },
    {
      "x": -20,
      "y": 23,
      "z": 1,
      "name": "Rock_Ice"
    },
    {
      "x": -20,
      "y": 24,
      "z": 1,
      "name": "Rock_Ice"
    },
    {
      "x": -20,
      "y": 21,
      "z": 2,
      "name": "Rock_Ice"
    },
    {
      "x": -20,
      "y": 22,
      "z": 2,
      "name": "Rock_Ice"
    },
    {
      "x": -20,
      "y": 23,
      "z": 2,
      "name": "Rock_Ice"
    },
    {
      "x": -20,
      "y": 22,
      "z": 3,
      "name": "Rock_Ice"
    },
    {
      "x": -20,
      "y": 21,
      "z": 6,
      "name": "Rock_Ice"
    },
    {
      "x": -20,
      "y": 22,
      "z": 6,
      "name": "Rock_Ice"
    },
    {
      "x": -20,
      "y": 23,
      "z": 6,
      "name": "Rock_Ice"
    },
    {
      "x": -20,
      "y": 20,
      "z": 7,
      "name": "Rock_Ice"
    },
    {
      "x": -20,
      "y": 21,
      "z": 7,
      "name": "Rock_Ice"
    },
    {
      "x": -20,
      "y": 22,
      "z": 7,
      "name": "Rock_Ice"
    },
    {
      "x": -20,
      "y": 23,
      "z": 7,
      "name": "Rock_Ice"
    },
    {
      "x": -20,
      "y": 19,
      "z": 8,
      "name": "Rock_Ice"
    },
    {
      "x": -20,
      "y": 20,
      "z": 8,
      "name": "Rock_Ice"
    },
    {
      "x": -20,
      "y": 21,
      "z": 8,
      "name": "Rock_Ice"
    },
    {
      "x": -20,
      "y": 22,
      "z": 8,
      "name": "Rock_Ice"
    },
    {
      "x": -20,
      "y": 23,
      "z": 8,
      "name": "Rock_Ice"
    },
    {
      "x": -20,
      "y": 24,
      "z": 8,
      "name": "Rock_Ice"
    },
    {
      "x": -20,
      "y": 19,
      "z": 9,
      "name": "Rock_Ice"
    },
    {
      "x": -20,
      "y": 20,
      "z": 9,
      "name": "Rock_Ice"
    },
    {
      "x": -20,
      "y": 21,
      "z": 9,
      "name": "Rock_Ice"
    },
    {
      "x": -20,
      "y": 22,
      "z": 9,
      "name": "Rock_Ice"
    },
    {
      "x": -20,
      "y": 23,
      "z": 9,
      "name": "Rock_Ice"
    },
    {
      "x": -20,
      "y": 24,
      "z": 9,
      "name": "Rock_Ice"
    },
    {
      "x": -20,
      "y": 25,
      "z": 9,
      "name": "Rock_Ice"
    },
    {
      "x": -20,
      "y": 18,
      "z": 10,
      "name": "Rock_Ice"
    },
    {
      "x": -20,
      "y": 19,
      "z": 10,
      "name": "Rock_Ice"
    },
    {
      "x": -20,
      "y": 20,
      "z": 10,
      "name": "Rock_Ice"
    },
    {
      "x": -20,
      "y": 21,
      "z": 10,
      "name": "Rock_Ice"
    },
    {
      "x": -20,
      "y": 22,
      "z": 10,
      "name": "Rock_Ice"
    },
    {
      "x": -20,
      "y": 23,
      "z": 10,
      "name": "Rock_Ice"
    },
    {
      "x": -20,
      "y": 24,
      "z": 10,
      "name": "Rock_Ice"
    },
    {
      "x": -20,
      "y": 25,
      "z": 10,
      "name": "Soil_Snow"
    },
    {
      "x": -20,
      "y": 18,
      "z": 11,
      "name": "Rock_Ice"
    },
    {
      "x": -20,
      "y": 19,
      "z": 11,
      "name": "Rock_Ice"
    },
    {
      "x": -20,
      "y": 20,
      "z": 11,
      "name": "Rock_Ice"
    },
    {
      "x": -20,
      "y": 21,
      "z": 11,
      "name": "Rock_Ice"
    },
    {
      "x": -20,
      "y": 22,
      "z": 11,
      "name": "Rock_Ice"
    },
    {
      "x": -20,
      "y": 23,
      "z": 11,
      "name": "Rock_Ice"
    },
    {
      "x": -20,
      "y": 24,
      "z": 11,
      "name": "Soil_Snow"
    },
    {
      "x": -20,
      "y": 19,
      "z": 12,
      "name": "Rock_Ice"
    },
    {
      "x": -20,
      "y": 20,
      "z": 12,
      "name": "Rock_Ice"
    },
    {
      "x": -20,
      "y": 21,
      "z": 12,
      "name": "Rock_Ice"
    },
    {
      "x": -19,
      "y": 21,
      "z": -14,
      "name": "Rock_Ice_Permafrost"
    },
    {
      "x": -19,
      "y": 22,
      "z": -14,
      "name": "Soil_Snow"
    },
    {
      "x": -19,
      "y": 14,
      "z": -13,
      "name": "Rock_Ice"
    },
    {
      "x": -19,
      "y": 15,
      "z": -13,
      "name": "Rock_Ice"
    },
    {
      "x": -19,
      "y": 16,
      "z": -13,
      "name": "Rock_Ice_Permafrost"
    },
    {
      "x": -19,
      "y": 17,
      "z": -13,
      "name": "Rock_Ice_Permafrost"
    },
    {
      "x": -19,
      "y": 18,
      "z": -13,
      "name": "Rock_Ice_Permafrost"
    },
    {
      "x": -19,
      "y": 19,
      "z": -13,
      "name": "Rock_Ice_Permafrost"
    },
    {
      "x": -19,
      "y": 20,
      "z": -13,
      "name": "Rock_Ice_Permafrost"
    },
    {
      "x": -19,
      "y": 21,
      "z": -13,
      "name": "Rock_Ice_Permafrost"
    },
    {
      "x": -19,
      "y": 22,
      "z": -13,
      "name": "Rock_Ice"
    },
    {
      "x": -19,
      "y": 23,
      "z": -13,
      "name": "Soil_Snow"
    },
    {
      "x": -19,
      "y": 14,
      "z": -12,
      "name": "Rock_Ice_Permafrost"
    },
    {
      "x": -19,
      "y": 15,
      "z": -12,
      "name": "Rock_Ice_Permafrost"
    },
    {
      "x": -19,
      "y": 16,
      "z": -12,
      "name": "Rock_Ice_Permafrost"
    },
    {
      "x": -19,
      "y": 17,
      "z": -12,
      "name": "Rock_Ice_Permafrost"
    },
    {
      "x": -19,
      "y": 18,
      "z": -12,
      "name": "Rock_Ice_Permafrost"
    },
    {
      "x": -19,
      "y": 19,
      "z": -12,
      "name": "Rock_Ice_Permafrost"
    },
    {
      "x": -19,
      "y": 20,
      "z": -12,
      "name": "Rock_Ice_Permafrost"
    },
    {
      "x": -19,
      "y": 21,
      "z": -12,
      "name": "Rock_Ice_Permafrost"
    },
    {
      "x": -19,
      "y": 22,
      "z": -12,
      "name": "Rock_Ice_Permafrost"
    },
    {
      "x": -19,
      "y": 23,
      "z": -12,
      "name": "Rock_Ice_Permafrost"
    },
    {
      "x": -19,
      "y": 24,
      "z": -12,
      "name": "Rock_Ice_Permafrost"
    },
    {
      "x": -19,
      "y": 25,
      "z": -12,
      "name": "Rock_Ice_Permafrost"
    },
    {
      "x": -19,
      "y": 26,
      "z": -12,
      "name": "Rock_Ice_Permafrost"
    },
    {
      "x": -19,
      "y": 27,
      "z": -12,
      "name": "Rock_Ice_Permafrost"
    },
    {
      "x": -19,
      "y": 28,
      "z": -12,
      "name": "Rock_Ice_Permafrost"
    },
    {
      "x": -19,
      "y": 29,
      "z": -12,
      "name": "Rock_Ice"
    },
    {
      "x": -19,
      "y": 30,
      "z": -12,
      "name": "Soil_Snow"
    },
    {
      "x": -19,
      "y": 14,
      "z": -11,
      "name": "Rock_Ice_Permafrost"
    },
    {
      "x": -19,
      "y": 15,
      "z": -11,
      "name": "Rock_Ice_Permafrost"
    },
    {
      "x": -19,
      "y": 16,
      "z": -11,
      "name": "Rock_Ice_Permafrost"
    },
    {
      "x": -19,
      "y": 17,
      "z": -11,
      "name": "Rock_Ice_Permafrost"
    },
    {
      "x": -19,
      "y": 18,
      "z": -11,
      "name": "Rock_Ice_Permafrost"
    },
    {
      "x": -19,
      "y": 19,
      "z": -11,
      "name": "Rock_Ice_Permafrost"
    },
    {
      "x": -19,
      "y": 20,
      "z": -11,
      "name": "Rock_Ice_Permafrost"
    },
    {
      "x": -19,
      "y": 21,
      "z": -11,
      "name": "Rock_Ice"
    },
    {
      "x": -19,
      "y": 22,
      "z": -11,
      "name": "Rock_Ice"
    },
    {
      "x": -19,
      "y": 23,
      "z": -11,
      "name": "Rock_Ice"
    },
    {
      "x": -19,
      "y": 24,
      "z": -11,
      "name": "Rock_Ice"
    },
    {
      "x": -19,
      "y": 25,
      "z": -11,
      "name": "Rock_Ice_Permafrost"
    },
    {
      "x": -19,
      "y": 26,
      "z": -11,
      "name": "Rock_Ice"
    },
    {
      "x": -19,
      "y": 27,
      "z": -11,
      "name": "Rock_Ice"
    },
    {
      "x": -19,
      "y": 28,
      "z": -11,
      "name": "Rock_Ice_Permafrost"
    },
    {
      "x": -19,
      "y": 29,
      "z": -11,
      "name": "Rock_Ice"
    },
    {
      "x": -19,
      "y": 30,
      "z": -11,
      "name": "Rock_Ice"
    },
    {
      "x": -19,
      "y": 31,
      "z": -11,
      "name": "Soil_Snow"
    },
    {
      "x": -19,
      "y": 15,
      "z": -10,
      "name": "Rock_Ice_Permafrost"
    },
    {
      "x": -19,
      "y": 16,
      "z": -10,
      "name": "Rock_Ice"
    },
    {
      "x": -19,
      "y": 17,
      "z": -10,
      "name": "Rock_Ice"
    },
    {
      "x": -19,
      "y": 18,
      "z": -10,
      "name": "Rock_Ice"
    },
    {
      "x": -19,
      "y": 19,
      "z": -10,
      "name": "Rock_Ice"
    },
    {
      "x": -19,
      "y": 20,
      "z": -10,
      "name": "Rock_Ice"
    },
    {
      "x": -19,
      "y": 21,
      "z": -10,
      "name": "Rock_Ice"
    },
    {
      "x": -19,
      "y": 22,
      "z": -10,
      "name": "Rock_Ice"
    },
    {
      "x": -19,
      "y": 23,
      "z": -10,
      "name": "Rock_Ice"
    },
    {
      "x": -19,
      "y": 24,
      "z": -10,
      "name": "Rock_Ice"
    },
    {
      "x": -19,
      "y": 25,
      "z": -10,
      "name": "Rock_Ice"
    },
    {
      "x": -19,
      "y": 26,
      "z": -10,
      "name": "Rock_Ice"
    },
    {
      "x": -19,
      "y": 27,
      "z": -10,
      "name": "Rock_Ice"
    },
    {
      "x": -19,
      "y": 28,
      "z": -10,
      "name": "Rock_Ice_Permafrost"
    },
    {
      "x": -19,
      "y": 29,
      "z": -10,
      "name": "Rock_Ice"
    },
    {
      "x": -19,
      "y": 30,
      "z": -10,
      "name": "Rock_Ice"
    },
    {
      "x": -19,
      "y": 31,
      "z": -10,
      "name": "Rock_Ice"
    },
    {
      "x": -19,
      "y": 32,
      "z": -10,
      "name": "Soil_Snow"
    },
    {
      "x": -19,
      "y": 15,
      "z": -9,
      "name": "Rock_Ice_Permafrost"
    },
    {
      "x": -19,
      "y": 16,
      "z": -9,
      "name": "Rock_Ice"
    },
    {
      "x": -19,
      "y": 17,
      "z": -9,
      "name": "Rock_Ice"
    },
    {
      "x": -19,
      "y": 18,
      "z": -9,
      "name": "Rock_Ice"
    },
    {
      "x": -19,
      "y": 19,
      "z": -9,
      "name": "Rock_Ice"
    },
    {
      "x": -19,
      "y": 20,
      "z": -9,
      "name": "Rock_Ice"
    },
    {
      "x": -19,
      "y": 21,
      "z": -9,
      "name": "Rock_Ice"
    },
    {
      "x": -19,
      "y": 22,
      "z": -9,
      "name": "Rock_Ice"
    },
    {
      "x": -19,
      "y": 23,
      "z": -9,
      "name": "Rock_Ice"
    },
    {
      "x": -19,
      "y": 24,
      "z": -9,
      "name": "Rock_Ice"
    },
    {
      "x": -19,
      "y": 25,
      "z": -9,
      "name": "Rock_Ice_Permafrost"
    },
    {
      "x": -19,
      "y": 26,
      "z": -9,
      "name": "Rock_Ice_Permafrost"
    },
    {
      "x": -19,
      "y": 27,
      "z": -9,
      "name": "Rock_Ice_Permafrost"
    },
    {
      "x": -19,
      "y": 28,
      "z": -9,
      "name": "Rock_Ice_Permafrost"
    },
    {
      "x": -19,
      "y": 29,
      "z": -9,
      "name": "Rock_Ice"
    },
    {
      "x": -19,
      "y": 30,
      "z": -9,
      "name": "Rock_Ice_Permafrost"
    },
    {
      "x": -19,
      "y": 31,
      "z": -9,
      "name": "Rock_Ice"
    },
    {
      "x": -19,
      "y": 32,
      "z": -9,
      "name": "Soil_Snow"
    },
    {
      "x": -19,
      "y": 15,
      "z": -8,
      "name": "Rock_Ice"
    },
    {
      "x": -19,
      "y": 16,
      "z": -8,
      "name": "Rock_Ice"
    },
    {
      "x": -19,
      "y": 17,
      "z": -8,
      "name": "Rock_Ice"
    },
    {
      "x": -19,
      "y": 18,
      "z": -8,
      "name": "Rock_Ice"
    },
    {
      "x": -19,
      "y": 19,
      "z": -8,
      "name": "Rock_Ice"
    },
    {
      "x": -19,
      "y": 20,
      "z": -8,
      "name": "Rock_Ice"
    },
    {
      "x": -19,
      "y": 21,
      "z": -8,
      "name": "Rock_Ice_Permafrost"
    },
    {
      "x": -19,
      "y": 22,
      "z": -8,
      "name": "Rock_Ice_Permafrost"
    },
    {
      "x": -19,
      "y": 23,
      "z": -8,
      "name": "Rock_Ice"
    },
    {
      "x": -19,
      "y": 24,
      "z": -8,
      "name": "Rock_Ice_Permafrost"
    },
    {
      "x": -19,
      "y": 25,
      "z": -8,
      "name": "Rock_Ice_Permafrost"
    },
    {
      "x": -19,
      "y": 26,
      "z": -8,
      "name": "Rock_Ice_Permafrost"
    },
    {
      "x": -19,
      "y": 27,
      "z": -8,
      "name": "Rock_Ice_Permafrost"
    },
    {
      "x": -19,
      "y": 28,
      "z": -8,
      "name": "Rock_Ice_Permafrost"
    },
    {
      "x": -19,
      "y": 29,
      "z": -8,
      "name": "Rock_Ice_Permafrost"
    },
    {
      "x": -19,
      "y": 30,
      "z": -8,
      "name": "Rock_Ice_Permafrost"
    },
    {
      "x": -19,
      "y": 31,
      "z": -8,
      "name": "Rock_Ice"
    },
    {
      "x": -19,
      "y": 32,
      "z": -8,
      "name": "Soil_Snow"
    },
    {
      "x": -19,
      "y": 16,
      "z": -7,
      "name": "Rock_Ice"
    },
    {
      "x": -19,
      "y": 17,
      "z": -7,
      "name": "Rock_Ice"
    },
    {
      "x": -19,
      "y": 18,
      "z": -7,
      "name": "Rock_Ice"
    },
    {
      "x": -19,
      "y": 19,
      "z": -7,
      "name": "Rock_Ice"
    },
    {
      "x": -19,
      "y": 20,
      "z": -7,
      "name": "Rock_Ice_Permafrost"
    },
    {
      "x": -19,
      "y": 21,
      "z": -7,
      "name": "Rock_Ice_Permafrost"
    },
    {
      "x": -19,
      "y": 22,
      "z": -7,
      "name": "Rock_Ice_Permafrost"
    },
    {
      "x": -19,
      "y": 23,
      "z": -7,
      "name": "Rock_Ice_Permafrost"
    },
    {
      "x": -19,
      "y": 24,
      "z": -7,
      "name": "Rock_Ice_Permafrost"
    },
    {
      "x": -19,
      "y": 25,
      "z": -7,
      "name": "Rock_Ice_Permafrost"
    },
    {
      "x": -19,
      "y": 26,
      "z": -7,
      "name": "Rock_Ice_Permafrost"
    },
    {
      "x": -19,
      "y": 27,
      "z": -7,
      "name": "Rock_Ice_Permafrost"
    },
    {
      "x": -19,
      "y": 28,
      "z": -7,
      "name": "Rock_Ice_Permafrost"
    },
    {
      "x": -19,
      "y": 29,
      "z": -7,
      "name": "Rock_Ice_Permafrost"
    },
    {
      "x": -19,
      "y": 30,
      "z": -7,
      "name": "Rock_Ice_Permafrost"
    },
    {
      "x": -19,
      "y": 31,
      "z": -7,
      "name": "Rock_Ice"
    },
    {
      "x": -19,
      "y": 32,
      "z": -7,
      "name": "Soil_Snow"
    },
    {
      "x": -19,
      "y": 16,
      "z": -6,
      "name": "Rock_Ice_Permafrost"
    },
    {
      "x": -19,
      "y": 17,
      "z": -6,
      "name": "Rock_Ice_Permafrost"
    },
    {
      "x": -19,
      "y": 18,
      "z": -6,
      "name": "Rock_Ice_Permafrost"
    },
    {
      "x": -19,
      "y": 19,
      "z": -6,
      "name": "Rock_Ice_Permafrost"
    },
    {
      "x": -19,
      "y": 20,
      "z": -6,
      "name": "Rock_Ice_Permafrost"
    },
    {
      "x": -19,
      "y": 21,
      "z": -6,
      "name": "Rock_Ice_Permafrost"
    },
    {
      "x": -19,
      "y": 22,
      "z": -6,
      "name": "Rock_Ice_Permafrost"
    },
    {
      "x": -19,
      "y": 23,
      "z": -6,
      "name": "Rock_Ice_Permafrost"
    },
    {
      "x": -19,
      "y": 24,
      "z": -6,
      "name": "Rock_Ice_Permafrost"
    },
    {
      "x": -19,
      "y": 25,
      "z": -6,
      "name": "Rock_Ice_Permafrost"
    },
    {
      "x": -19,
      "y": 26,
      "z": -6,
      "name": "Rock_Ice_Permafrost"
    },
    {
      "x": -19,
      "y": 27,
      "z": -6,
      "name": "Rock_Ice_Permafrost"
    },
    {
      "x": -19,
      "y": 28,
      "z": -6,
      "name": "Rock_Ice_Permafrost"
    },
    {
      "x": -19,
      "y": 29,
      "z": -6,
      "name": "Rock_Ice_Permafrost"
    },
    {
      "x": -19,
      "y": 30,
      "z": -6,
      "name": "Rock_Ice_Permafrost"
    },
    {
      "x": -19,
      "y": 31,
      "z": -6,
      "name": "Rock_Ice"
    },
    {
      "x": -19,
      "y": 32,
      "z": -6,
      "name": "Soil_Snow"
    },
    {
      "x": -19,
      "y": 17,
      "z": -5,
      "name": "Rock_Ice_Permafrost"
    },
    {
      "x": -19,
      "y": 18,
      "z": -5,
      "name": "Rock_Ice_Permafrost"
    },
    {
      "x": -19,
      "y": 19,
      "z": -5,
      "name": "Rock_Ice_Permafrost"
    },
    {
      "x": -19,
      "y": 20,
      "z": -5,
      "name": "Rock_Ice_Permafrost"
    },
    {
      "x": -19,
      "y": 21,
      "z": -5,
      "name": "Rock_Ice_Permafrost"
    },
    {
      "x": -19,
      "y": 22,
      "z": -5,
      "name": "Rock_Ice_Permafrost"
    },
    {
      "x": -19,
      "y": 23,
      "z": -5,
      "name": "Rock_Ice_Permafrost"
    },
    {
      "x": -19,
      "y": 24,
      "z": -5,
      "name": "Rock_Ice_Permafrost"
    },
    {
      "x": -19,
      "y": 25,
      "z": -5,
      "name": "Rock_Ice_Permafrost"
    },
    {
      "x": -19,
      "y": 26,
      "z": -5,
      "name": "Rock_Ice_Permafrost"
    },
    {
      "x": -19,
      "y": 27,
      "z": -5,
      "name": "Rock_Ice_Permafrost"
    },
    {
      "x": -19,
      "y": 28,
      "z": -5,
      "name": "Rock_Ice_Permafrost"
    },
    {
      "x": -19,
      "y": 29,
      "z": -5,
      "name": "Rock_Ice_Permafrost"
    },
    {
      "x": -19,
      "y": 30,
      "z": -5,
      "name": "Rock_Ice_Permafrost"
    },
    {
      "x": -19,
      "y": 31,
      "z": -5,
      "name": "Rock_Ice"
    },
    {
      "x": -19,
      "y": 32,
      "z": -5,
      "name": "Soil_Snow"
    },
    {
      "x": -19,
      "y": 17,
      "z": -4,
      "name": "Rock_Ice_Permafrost"
    },
    {
      "x": -19,
      "y": 18,
      "z": -4,
      "name": "Rock_Ice_Permafrost"
    },
    {
      "x": -19,
      "y": 19,
      "z": -4,
      "name": "Rock_Ice_Permafrost"
    },
    {
      "x": -19,
      "y": 20,
      "z": -4,
      "name": "Rock_Ice_Permafrost"
    },
    {
      "x": -19,
      "y": 21,
      "z": -4,
      "name": "Rock_Ice_Permafrost"
    },
    {
      "x": -19,
      "y": 22,
      "z": -4,
      "name": "Rock_Ice_Permafrost"
    },
    {
      "x": -19,
      "y": 23,
      "z": -4,
      "name": "Rock_Ice_Permafrost"
    },
    {
      "x": -19,
      "y": 24,
      "z": -4,
      "name": "Rock_Ice_Permafrost"
    },
    {
      "x": -19,
      "y": 25,
      "z": -4,
      "name": "Rock_Ice_Permafrost"
    },
    {
      "x": -19,
      "y": 26,
      "z": -4,
      "name": "Rock_Ice_Permafrost"
    },
    {
      "x": -19,
      "y": 27,
      "z": -4,
      "name": "Rock_Ice_Permafrost"
    },
    {
      "x": -19,
      "y": 28,
      "z": -4,
      "name": "Rock_Ice_Permafrost"
    },
    {
      "x": -19,
      "y": 29,
      "z": -4,
      "name": "Rock_Ice_Permafrost"
    },
    {
      "x": -19,
      "y": 30,
      "z": -4,
      "name": "Rock_Ice_Permafrost"
    },
    {
      "x": -19,
      "y": 31,
      "z": -4,
      "name": "Rock_Ice"
    },
    {
      "x": -19,
      "y": 32,
      "z": -4,
      "name": "Soil_Snow"
    },
    {
      "x": -19,
      "y": 18,
      "z": -3,
      "name": "Rock_Ice_Permafrost"
    },
    {
      "x": -19,
      "y": 19,
      "z": -3,
      "name": "Rock_Ice_Permafrost"
    },
    {
      "x": -19,
      "y": 20,
      "z": -3,
      "name": "Rock_Ice_Permafrost"
    },
    {
      "x": -19,
      "y": 21,
      "z": -3,
      "name": "Rock_Ice_Permafrost"
    },
    {
      "x": -19,
      "y": 22,
      "z": -3,
      "name": "Rock_Ice_Permafrost"
    },
    {
      "x": -19,
      "y": 23,
      "z": -3,
      "name": "Rock_Ice"
    },
    {
      "x": -19,
      "y": 24,
      "z": -3,
      "name": "Rock_Ice"
    },
    {
      "x": -19,
      "y": 25,
      "z": -3,
      "name": "Rock_Ice_Permafrost"
    },
    {
      "x": -19,
      "y": 26,
      "z": -3,
      "name": "Rock_Ice"
    },
    {
      "x": -19,
      "y": 27,
      "z": -3,
      "name": "Rock_Ice"
    },
    {
      "x": -19,
      "y": 28,
      "z": -3,
      "name": "Rock_Ice"
    },
    {
      "x": -19,
      "y": 29,
      "z": -3,
      "name": "Soil_Snow"
    },
    {
      "x": -19,
      "y": 20,
      "z": -2,
      "name": "Rock_Ice_Permafrost"
    },
    {
      "x": -19,
      "y": 21,
      "z": -2,
      "name": "Rock_Ice_Permafrost"
    },
    {
      "x": -19,
      "y": 22,
      "z": -2,
      "name": "Rock_Ice_Permafrost"
    },
    {
      "x": -19,
      "y": 23,
      "z": -2,
      "name": "Rock_Ice"
    },
    {
      "x": -19,
      "y": 24,
      "z": -2,
      "name": "Rock_Ice"
    },
    {
      "x": -19,
      "y": 25,
      "z": -2,
      "name": "Rock_Ice"
    },
    {
      "x": -19,
      "y": 26,
      "z": -2,
      "name": "Rock_Ice"
    },
    {
      "x": -19,
      "y": 27,
      "z": -2,
      "name": "Rock_Ice"
    },
    {
      "x": -19,
      "y": 28,
      "z": -2,
      "name": "Soil_Snow"
    },
    {
      "x": -19,
      "y": 19,
      "z": -1,
      "name": "Rock_Ice_Permafrost"
    },
    {
      "x": -19,
      "y": 20,
      "z": -1,
      "name": "Rock_Ice_Permafrost"
    },
    {
      "x": -19,
      "y": 21,
      "z": -1,
      "name": "Rock_Ice_Permafrost"
    },
    {
      "x": -19,
      "y": 22,
      "z": -1,
      "name": "Rock_Ice_Permafrost"
    },
    {
      "x": -19,
      "y": 23,
      "z": -1,
      "name": "Rock_Ice"
    },
    {
      "x": -19,
      "y": 24,
      "z": -1,
      "name": "Rock_Ice"
    },
    {
      "x": -19,
      "y": 25,
      "z": -1,
      "name": "Rock_Ice"
    },
    {
      "x": -19,
      "y": 26,
      "z": -1,
      "name": "Rock_Ice"
    },
    {
      "x": -19,
      "y": 27,
      "z": -1,
      "name": "Rock_Ice"
    },
    {
      "x": -19,
      "y": 28,
      "z": -1,
      "name": "Rock_Ice"
    },
    {
      "x": -19,
      "y": 29,
      "z": -1,
      "name": "Soil_Snow"
    },
    {
      "x": -19,
      "y": 19,
      "z": 0,
      "name": "Rock_Ice_Permafrost"
    },
    {
      "x": -19,
      "y": 20,
      "z": 0,
      "name": "Rock_Ice_Permafrost"
    },
    {
      "x": -19,
      "y": 21,
      "z": 0,
      "name": "Rock_Ice_Permafrost"
    },
    {
      "x": -19,
      "y": 22,
      "z": 0,
      "name": "Rock_Ice"
    },
    {
      "x": -19,
      "y": 23,
      "z": 0,
      "name": "Rock_Ice"
    },
    {
      "x": -19,
      "y": 24,
      "z": 0,
      "name": "Rock_Ice"
    },
    {
      "x": -19,
      "y": 25,
      "z": 0,
      "name": "Rock_Ice"
    },
    {
      "x": -19,
      "y": 26,
      "z": 0,
      "name": "Rock_Ice"
    },
    {
      "x": -19,
      "y": 27,
      "z": 0,
      "name": "Rock_Ice"
    },
    {
      "x": -19,
      "y": 28,
      "z": 0,
      "name": "Rock_Ice"
    },
    {
      "x": -19,
      "y": 29,
      "z": 0,
      "name": "Soil_Snow"
    },
    {
      "x": -19,
      "y": 18,
      "z": 1,
      "name": "Rock_Ice_Permafrost"
    },
    {
      "x": -19,
      "y": 19,
      "z": 1,
      "name": "Rock_Ice_Permafrost"
    },
    {
      "x": -19,
      "y": 20,
      "z": 1,
      "name": "Rock_Ice_Permafrost"
    },
    {
      "x": -19,
      "y": 21,
      "z": 1,
      "name": "Rock_Ice"
    },
    {
      "x": -19,
      "y": 22,
      "z": 1,
      "name": "Rock_Ice"
    },
    {
      "x": -19,
      "y": 23,
      "z": 1,
      "name": "Rock_Ice"
    },
    {
      "x": -19,
      "y": 24,
      "z": 1,
      "name": "Rock_Ice"
    },
    {
      "x": -19,
      "y": 25,
      "z": 1,
      "name": "Rock_Ice"
    },
    {
      "x": -19,
      "y": 26,
      "z": 1,
      "name": "Rock_Ice"
    },
    {
      "x": -19,
      "y": 27,
      "z": 1,
      "name": "Rock_Ice"
    },
    {
      "x": -19,
      "y": 28,
      "z": 1,
      "name": "Rock_Ice"
    },
    {
      "x": -19,
      "y": 29,
      "z": 1,
      "name": "Soil_Snow"
    },
    {
      "x": -19,
      "y": 18,
      "z": 2,
      "name": "Rock_Ice_Permafrost"
    },
    {
      "x": -19,
      "y": 19,
      "z": 2,
      "name": "Rock_Ice_Permafrost"
    },
    {
      "x": -19,
      "y": 20,
      "z": 2,
      "name": "Rock_Ice_Permafrost"
    },
    {
      "x": -19,
      "y": 21,
      "z": 2,
      "name": "Rock_Ice"
    },
    {
      "x": -19,
      "y": 22,
      "z": 2,
      "name": "Rock_Ice"
    },
    {
      "x": -19,
      "y": 23,
      "z": 2,
      "name": "Rock_Ice"
    },
    {
      "x": -19,
      "y": 24,
      "z": 2,
      "name": "Rock_Ice"
    },
    {
      "x": -19,
      "y": 25,
      "z": 2,
      "name": "Rock_Ice"
    },
    {
      "x": -19,
      "y": 26,
      "z": 2,
      "name": "Rock_Ice"
    },
    {
      "x": -19,
      "y": 27,
      "z": 2,
      "name": "Rock_Ice"
    },
    {
      "x": -19,
      "y": 28,
      "z": 2,
      "name": "Soil_Snow"
    },
    {
      "x": -19,
      "y": 18,
      "z": 3,
      "name": "Rock_Ice_Permafrost"
    },
    {
      "x": -19,
      "y": 19,
      "z": 3,
      "name": "Rock_Ice_Permafrost"
    },
    {
      "x": -19,
      "y": 20,
      "z": 3,
      "name": "Rock_Ice_Permafrost"
    },
    {
      "x": -19,
      "y": 21,
      "z": 3,
      "name": "Rock_Ice"
    },
    {
      "x": -19,
      "y": 22,
      "z": 3,
      "name": "Rock_Ice"
    },
    {
      "x": -19,
      "y": 23,
      "z": 3,
      "name": "Rock_Ice"
    },
    {
      "x": -19,
      "y": 24,
      "z": 3,
      "name": "Rock_Ice"
    },
    {
      "x": -19,
      "y": 25,
      "z": 3,
      "name": "Rock_Ice"
    },
    {
      "x": -19,
      "y": 26,
      "z": 3,
      "name": "Rock_Ice"
    },
    {
      "x": -19,
      "y": 27,
      "z": 3,
      "name": "Rock_Ice"
    },
    {
      "x": -19,
      "y": 28,
      "z": 3,
      "name": "Soil_Snow"
    },
    {
      "x": -19,
      "y": 18,
      "z": 4,
      "name": "Rock_Ice"
    },
    {
      "x": -19,
      "y": 19,
      "z": 4,
      "name": "Rock_Ice_Permafrost"
    },
    {
      "x": -19,
      "y": 20,
      "z": 4,
      "name": "Rock_Ice"
    },
    {
      "x": -19,
      "y": 21,
      "z": 4,
      "name": "Rock_Ice"
    },
    {
      "x": -19,
      "y": 22,
      "z": 4,
      "name": "Rock_Ice"
    },
    {
      "x": -19,
      "y": 23,
      "z": 4,
      "name": "Rock_Ice"
    },
    {
      "x": -19,
      "y": 24,
      "z": 4,
      "name": "Rock_Ice"
    },
    {
      "x": -19,
      "y": 25,
      "z": 4,
      "name": "Rock_Ice"
    },
    {
      "x": -19,
      "y": 26,
      "z": 4,
      "name": "Rock_Ice"
    },
    {
      "x": -19,
      "y": 27,
      "z": 4,
      "name": "Rock_Ice"
    },
    {
      "x": -19,
      "y": 28,
      "z": 4,
      "name": "Soil_Snow"
    },
    {
      "x": -19,
      "y": 18,
      "z": 5,
      "name": "Rock_Ice_Permafrost"
    },
    {
      "x": -19,
      "y": 19,
      "z": 5,
      "name": "Rock_Ice"
    },
    {
      "x": -19,
      "y": 20,
      "z": 5,
      "name": "Rock_Ice"
    },
    {
      "x": -19,
      "y": 21,
      "z": 5,
      "name": "Rock_Ice"
    },
    {
      "x": -19,
      "y": 22,
      "z": 5,
      "name": "Rock_Ice"
    },
    {
      "x": -19,
      "y": 23,
      "z": 5,
      "name": "Rock_Ice"
    },
    {
      "x": -19,
      "y": 24,
      "z": 5,
      "name": "Rock_Ice"
    },
    {
      "x": -19,
      "y": 25,
      "z": 5,
      "name": "Rock_Ice"
    },
    {
      "x": -19,
      "y": 26,
      "z": 5,
      "name": "Rock_Ice"
    },
    {
      "x": -19,
      "y": 27,
      "z": 5,
      "name": "Rock_Ice"
    },
    {
      "x": -19,
      "y": 28,
      "z": 5,
      "name": "Rock_Ice"
    },
    {
      "x": -19,
      "y": 18,
      "z": 6,
      "name": "Rock_Ice"
    },
    {
      "x": -19,
      "y": 19,
      "z": 6,
      "name": "Rock_Ice"
    },
    {
      "x": -19,
      "y": 20,
      "z": 6,
      "name": "Rock_Ice"
    },
    {
      "x": -19,
      "y": 21,
      "z": 6,
      "name": "Rock_Ice"
    },
    {
      "x": -19,
      "y": 22,
      "z": 6,
      "name": "Rock_Ice"
    },
    {
      "x": -19,
      "y": 23,
      "z": 6,
      "name": "Rock_Ice"
    },
    {
      "x": -19,
      "y": 24,
      "z": 6,
      "name": "Rock_Ice"
    },
    {
      "x": -19,
      "y": 25,
      "z": 6,
      "name": "Rock_Ice"
    },
    {
      "x": -19,
      "y": 26,
      "z": 6,
      "name": "Rock_Ice"
    },
    {
      "x": -19,
      "y": 27,
      "z": 6,
      "name": "Rock_Ice"
    },
    {
      "x": -19,
      "y": 28,
      "z": 6,
      "name": "Soil_Snow"
    },
    {
      "x": -19,
      "y": 18,
      "z": 7,
      "name": "Rock_Ice"
    },
    {
      "x": -19,
      "y": 19,
      "z": 7,
      "name": "Rock_Ice"
    },
    {
      "x": -19,
      "y": 20,
      "z": 7,
      "name": "Rock_Ice"
    },
    {
      "x": -19,
      "y": 21,
      "z": 7,
      "name": "Rock_Ice"
    },
    {
      "x": -19,
      "y": 22,
      "z": 7,
      "name": "Rock_Ice"
    },
    {
      "x": -19,
      "y": 23,
      "z": 7,
      "name": "Rock_Ice"
    },
    {
      "x": -19,
      "y": 24,
      "z": 7,
      "name": "Rock_Ice"
    },
    {
      "x": -19,
      "y": 25,
      "z": 7,
      "name": "Rock_Ice"
    },
    {
      "x": -19,
      "y": 26,
      "z": 7,
      "name": "Rock_Ice"
    },
    {
      "x": -19,
      "y": 27,
      "z": 7,
      "name": "Rock_Ice"
    },
    {
      "x": -19,
      "y": 28,
      "z": 7,
      "name": "Soil_Snow"
    },
    {
      "x": -19,
      "y": 17,
      "z": 8,
      "name": "Rock_Ice"
    },
    {
      "x": -19,
      "y": 18,
      "z": 8,
      "name": "Rock_Ice"
    },
    {
      "x": -19,
      "y": 19,
      "z": 8,
      "name": "Rock_Ice"
    },
    {
      "x": -19,
      "y": 20,
      "z": 8,
      "name": "Rock_Ice"
    },
    {
      "x": -19,
      "y": 21,
      "z": 8,
      "name": "Rock_Ice"
    },
    {
      "x": -19,
      "y": 22,
      "z": 8,
      "name": "Rock_Ice"
    },
    {
      "x": -19,
      "y": 23,
      "z": 8,
      "name": "Rock_Ice"
    },
    {
      "x": -19,
      "y": 24,
      "z": 8,
      "name": "Rock_Ice"
    },
    {
      "x": -19,
      "y": 25,
      "z": 8,
      "name": "Rock_Ice"
    },
    {
      "x": -19,
      "y": 26,
      "z": 8,
      "name": "Rock_Ice"
    },
    {
      "x": -19,
      "y": 27,
      "z": 8,
      "name": "Rock_Ice"
    },
    {
      "x": -19,
      "y": 28,
      "z": 8,
      "name": "Soil_Snow"
    },
    {
      "x": -19,
      "y": 18,
      "z": 9,
      "name": "Rock_Ice"
    },
    {
      "x": -19,
      "y": 19,
      "z": 9,
      "name": "Rock_Ice"
    },
    {
      "x": -19,
      "y": 20,
      "z": 9,
      "name": "Rock_Ice"
    },
    {
      "x": -19,
      "y": 21,
      "z": 9,
      "name": "Rock_Ice"
    },
    {
      "x": -19,
      "y": 22,
      "z": 9,
      "name": "Rock_Ice"
    },
    {
      "x": -19,
      "y": 23,
      "z": 9,
      "name": "Rock_Ice"
    },
    {
      "x": -19,
      "y": 24,
      "z": 9,
      "name": "Rock_Ice"
    },
    {
      "x": -19,
      "y": 25,
      "z": 9,
      "name": "Rock_Ice"
    },
    {
      "x": -19,
      "y": 26,
      "z": 9,
      "name": "Rock_Ice"
    },
    {
      "x": -19,
      "y": 27,
      "z": 9,
      "name": "Rock_Ice"
    },
    {
      "x": -19,
      "y": 28,
      "z": 9,
      "name": "Soil_Snow"
    },
    {
      "x": -19,
      "y": 18,
      "z": 10,
      "name": "Rock_Ice"
    },
    {
      "x": -19,
      "y": 19,
      "z": 10,
      "name": "Rock_Ice"
    },
    {
      "x": -19,
      "y": 20,
      "z": 10,
      "name": "Rock_Ice"
    },
    {
      "x": -19,
      "y": 21,
      "z": 10,
      "name": "Rock_Ice"
    },
    {
      "x": -19,
      "y": 22,
      "z": 10,
      "name": "Rock_Ice"
    },
    {
      "x": -19,
      "y": 23,
      "z": 10,
      "name": "Rock_Ice"
    },
    {
      "x": -19,
      "y": 24,
      "z": 10,
      "name": "Rock_Ice"
    },
    {
      "x": -19,
      "y": 25,
      "z": 10,
      "name": "Rock_Ice"
    },
    {
      "x": -19,
      "y": 26,
      "z": 10,
      "name": "Rock_Ice"
    },
    {
      "x": -19,
      "y": 27,
      "z": 10,
      "name": "Soil_Snow"
    },
    {
      "x": -19,
      "y": 17,
      "z": 11,
      "name": "Rock_Ice"
    },
    {
      "x": -19,
      "y": 18,
      "z": 11,
      "name": "Rock_Ice"
    },
    {
      "x": -19,
      "y": 19,
      "z": 11,
      "name": "Rock_Ice"
    },
    {
      "x": -19,
      "y": 20,
      "z": 11,
      "name": "Rock_Ice"
    },
    {
      "x": -19,
      "y": 21,
      "z": 11,
      "name": "Rock_Ice"
    },
    {
      "x": -19,
      "y": 22,
      "z": 11,
      "name": "Rock_Ice"
    },
    {
      "x": -19,
      "y": 23,
      "z": 11,
      "name": "Rock_Ice"
    },
    {
      "x": -19,
      "y": 24,
      "z": 11,
      "name": "Rock_Ice"
    },
    {
      "x": -19,
      "y": 25,
      "z": 11,
      "name": "Rock_Ice"
    },
    {
      "x": -19,
      "y": 26,
      "z": 11,
      "name": "Rock_Ice"
    },
    {
      "x": -19,
      "y": 27,
      "z": 11,
      "name": "Soil_Snow"
    },
    {
      "x": -19,
      "y": 18,
      "z": 12,
      "name": "Rock_Ice"
    },
    {
      "x": -19,
      "y": 19,
      "z": 12,
      "name": "Rock_Ice"
    },
    {
      "x": -19,
      "y": 20,
      "z": 12,
      "name": "Rock_Ice"
    },
    {
      "x": -19,
      "y": 21,
      "z": 12,
      "name": "Rock_Ice"
    },
    {
      "x": -19,
      "y": 22,
      "z": 12,
      "name": "Rock_Ice"
    },
    {
      "x": -19,
      "y": 23,
      "z": 12,
      "name": "Rock_Ice"
    },
    {
      "x": -19,
      "y": 24,
      "z": 12,
      "name": "Rock_Ice"
    },
    {
      "x": -19,
      "y": 25,
      "z": 12,
      "name": "Rock_Ice"
    },
    {
      "x": -19,
      "y": 26,
      "z": 12,
      "name": "Soil_Snow"
    },
    {
      "x": -19,
      "y": 18,
      "z": 13,
      "name": "Rock_Ice"
    },
    {
      "x": -19,
      "y": 19,
      "z": 13,
      "name": "Rock_Ice"
    },
    {
      "x": -19,
      "y": 20,
      "z": 13,
      "name": "Rock_Ice"
    },
    {
      "x": -19,
      "y": 21,
      "z": 13,
      "name": "Rock_Ice"
    },
    {
      "x": -19,
      "y": 22,
      "z": 13,
      "name": "Rock_Ice"
    },
    {
      "x": -19,
      "y": 23,
      "z": 13,
      "name": "Rock_Ice"
    },
    {
      "x": -19,
      "y": 24,
      "z": 13,
      "name": "Rock_Ice"
    },
    {
      "x": -19,
      "y": 25,
      "z": 13,
      "name": "Soil_Snow"
    },
    {
      "x": -19,
      "y": 19,
      "z": 14,
      "name": "Rock_Ice"
    },
    {
      "x": -19,
      "y": 20,
      "z": 14,
      "name": "Rock_Ice"
    },
    {
      "x": -19,
      "y": 21,
      "z": 14,
      "name": "Rock_Ice"
    },
    {
      "x": -19,
      "y": 22,
      "z": 14,
      "name": "Rock_Ice"
    },
    {
      "x": -19,
      "y": 19,
      "z": 15,
      "name": "Rock_Ice"
    },
    {
      "x": -19,
      "y": 20,
      "z": 15,
      "name": "Soil_Snow"
    },
    {
      "x": -19,
      "y": 19,
      "z": 16,
      "name": "Rock_Ice"
    },
    {
      "x": -19,
      "y": 20,
      "z": 16,
      "name": "Rock_Ice"
    },
    {
      "x": -19,
      "y": 21,
      "z": 16,
      "name": "Rock_Ice"
    },
    {
      "x": -19,
      "y": 22,
      "z": 16,
      "name": "Soil_Snow"
    },
    {
      "x": -19,
      "y": 19,
      "z": 17,
      "name": "Rock_Ice"
    },
    {
      "x": -19,
      "y": 20,
      "z": 17,
      "name": "Rock_Ice"
    },
    {
      "x": -19,
      "y": 21,
      "z": 17,
      "name": "Rock_Ice"
    },
    {
      "x": -19,
      "y": 22,
      "z": 17,
      "name": "Rock_Ice"
    },
    {
      "x": -19,
      "y": 23,
      "z": 17,
      "name": "Soil_Snow"
    },
    {
      "x": -19,
      "y": 20,
      "z": 18,
      "name": "Rock_Ice"
    },
    {
      "x": -19,
      "y": 21,
      "z": 18,
      "name": "Rock_Ice"
    },
    {
      "x": -19,
      "y": 22,
      "z": 18,
      "name": "Rock_Ice"
    },
    {
      "x": -19,
      "y": 23,
      "z": 18,
      "name": "Rock_Ice"
    },
    {
      "x": -18,
      "y": 55,
      "z": -17,
      "name": "Soil_Snow"
    },
    {
      "x": -18,
      "y": 55,
      "z": -16,
      "name": "Rock_Ice"
    },
    {
      "x": -18,
      "y": 56,
      "z": -16,
      "name": "Soil_Snow"
    },
    {
      "x": -18,
      "y": 22,
      "z": -15,
      "name": "Rock_Ice"
    },
    {
      "x": -18,
      "y": 55,
      "z": -15,
      "name": "Rock_Ice"
    },
    {
      "x": -18,
      "y": 56,
      "z": -15,
      "name": "Soil_Snow"
    },
    {
      "x": -18,
      "y": 14,
      "z": -14,
      "name": "Rock_Ice"
    },
    {
      "x": -18,
      "y": 15,
      "z": -14,
      "name": "Rock_Ice"
    },
    {
      "x": -18,
      "y": 16,
      "z": -14,
      "name": "Rock_Ice"
    },
    {
      "x": -18,
      "y": 17,
      "z": -14,
      "name": "Rock_Ice_Permafrost"
    },
    {
      "x": -18,
      "y": 18,
      "z": -14,
      "name": "Rock_Ice"
    },
    {
      "x": -18,
      "y": 19,
      "z": -14,
      "name": "Rock_Ice_Permafrost"
    },
    {
      "x": -18,
      "y": 20,
      "z": -14,
      "name": "Rock_Ice_Permafrost"
    },
    {
      "x": -18,
      "y": 21,
      "z": -14,
      "name": "Rock_Ice_Permafrost"
    },
    {
      "x": -18,
      "y": 22,
      "z": -14,
      "name": "Rock_Ice_Permafrost"
    },
    {
      "x": -18,
      "y": 23,
      "z": -14,
      "name": "Rock_Ice"
    },
    {
      "x": -18,
      "y": 24,
      "z": -14,
      "name": "Soil_Snow"
    },
    {
      "x": -18,
      "y": 55,
      "z": -14,
      "name": "Rock_Ice"
    },
    {
      "x": -18,
      "y": 56,
      "z": -14,
      "name": "Soil_Snow"
    },
    {
      "x": -18,
      "y": 13,
      "z": -13,
      "name": "Rock_Ice"
    },
    {
      "x": -18,
      "y": 14,
      "z": -13,
      "name": "Rock_Ice_Permafrost"
    },
    {
      "x": -18,
      "y": 15,
      "z": -13,
      "name": "Rock_Ice_Permafrost"
    },
    {
      "x": -18,
      "y": 16,
      "z": -13,
      "name": "Rock_Ice_Permafrost"
    },
    {
      "x": -18,
      "y": 17,
      "z": -13,
      "name": "Rock_Ice_Permafrost"
    },
    {
      "x": -18,
      "y": 18,
      "z": -13,
      "name": "Rock_Ice_Permafrost"
    },
    {
      "x": -18,
      "y": 19,
      "z": -13,
      "name": "Rock_Ice_Permafrost"
    },
    {
      "x": -18,
      "y": 20,
      "z": -13,
      "name": "Rock_Ice_Permafrost"
    },
    {
      "x": -18,
      "y": 21,
      "z": -13,
      "name": "Rock_Ice_Permafrost"
    },
    {
      "x": -18,
      "y": 22,
      "z": -13,
      "name": "Rock_Ice_Permafrost"
    },
    {
      "x": -18,
      "y": 23,
      "z": -13,
      "name": "Rock_Ice_Permafrost"
    },
    {
      "x": -18,
      "y": 24,
      "z": -13,
      "name": "Rock_Ice_Permafrost"
    },
    {
      "x": -18,
      "y": 25,
      "z": -13,
      "name": "Rock_Ice_Permafrost"
    },
    {
      "x": -18,
      "y": 27,
      "z": -13,
      "name": "Rock_Ice_Permafrost"
    },
    {
      "x": -18,
      "y": 28,
      "z": -13,
      "name": "Rock_Ice_Permafrost"
    },
    {
      "x": -18,
      "y": 29,
      "z": -13,
      "name": "Rock_Ice_Permafrost"
    },
    {
      "x": -18,
      "y": 30,
      "z": -13,
      "name": "Rock_Ice"
    },
    {
      "x": -18,
      "y": 31,
      "z": -13,
      "name": "Soil_Snow"
    },
    {
      "x": -18,
      "y": 12,
      "z": -12,
      "name": "Rock_Ice_Permafrost"
    },
    {
      "x": -18,
      "y": 13,
      "z": -12,
      "name": "Rock_Ice_Permafrost"
    },
    {
      "x": -18,
      "y": 14,
      "z": -12,
      "name": "Rock_Ice_Permafrost"
    },
    {
      "x": -18,
      "y": 15,
      "z": -12,
      "name": "Rock_Ice_Permafrost"
    },
    {
      "x": -18,
      "y": 16,
      "z": -12,
      "name": "Rock_Ice_Permafrost"
    },
    {
      "x": -18,
      "y": 17,
      "z": -12,
      "name": "Rock_Ice_Permafrost"
    },
    {
      "x": -18,
      "y": 18,
      "z": -12,
      "name": "Rock_Ice_Permafrost"
    },
    {
      "x": -18,
      "y": 19,
      "z": -12,
      "name": "Rock_Ice_Permafrost"
    },
    {
      "x": -18,
      "y": 20,
      "z": -12,
      "name": "Rock_Ice_Permafrost"
    },
    {
      "x": -18,
      "y": 21,
      "z": -12,
      "name": "Rock_Ice_Permafrost"
    },
    {
      "x": -18,
      "y": 22,
      "z": -12,
      "name": "Rock_Ice_Permafrost"
    },
    {
      "x": -18,
      "y": 23,
      "z": -12,
      "name": "Rock_Ice_Permafrost"
    },
    {
      "x": -18,
      "y": 24,
      "z": -12,
      "name": "Rock_Ice_Permafrost"
    },
    {
      "x": -18,
      "y": 25,
      "z": -12,
      "name": "Rock_Ice_Permafrost"
    },
    {
      "x": -18,
      "y": 26,
      "z": -12,
      "name": "Rock_Ice_Permafrost"
    },
    {
      "x": -18,
      "y": 27,
      "z": -12,
      "name": "Rock_Ice"
    },
    {
      "x": -18,
      "y": 28,
      "z": -12,
      "name": "Rock_Ice_Permafrost"
    },
    {
      "x": -18,
      "y": 29,
      "z": -12,
      "name": "Rock_Ice_Permafrost"
    },
    {
      "x": -18,
      "y": 30,
      "z": -12,
      "name": "Rock_Ice_Permafrost"
    },
    {
      "x": -18,
      "y": 31,
      "z": -12,
      "name": "Rock_Ice"
    },
    {
      "x": -18,
      "y": 32,
      "z": -12,
      "name": "Soil_Snow"
    },
    {
      "x": -18,
      "y": 13,
      "z": -11,
      "name": "Rock_Ice_Permafrost"
    },
    {
      "x": -18,
      "y": 14,
      "z": -11,
      "name": "Rock_Ice_Permafrost"
    },
    {
      "x": -18,
      "y": 15,
      "z": -11,
      "name": "Rock_Ice_Permafrost"
    },
    {
      "x": -18,
      "y": 16,
      "z": -11,
      "name": "Rock_Ice_Permafrost"
    },
    {
      "x": -18,
      "y": 17,
      "z": -11,
      "name": "Rock_Ice_Permafrost"
    },
    {
      "x": -18,
      "y": 18,
      "z": -11,
      "name": "Rock_Ice"
    },
    {
      "x": -18,
      "y": 19,
      "z": -11,
      "name": "Rock_Ice_Permafrost"
    },
    {
      "x": -18,
      "y": 20,
      "z": -11,
      "name": "Rock_Ice"
    },
    {
      "x": -18,
      "y": 21,
      "z": -11,
      "name": "Rock_Ice"
    },
    {
      "x": -18,
      "y": 22,
      "z": -11,
      "name": "Rock_Ice_Permafrost"
    },
    {
      "x": -18,
      "y": 23,
      "z": -11,
      "name": "Rock_Ice_Permafrost"
    },
    {
      "x": -18,
      "y": 24,
      "z": -11,
      "name": "Rock_Ice"
    },
    {
      "x": -18,
      "y": 25,
      "z": -11,
      "name": "Rock_Ice"
    },
    {
      "x": -18,
      "y": 26,
      "z": -11,
      "name": "Rock_Ice"
    },
    {
      "x": -18,
      "y": 27,
      "z": -11,
      "name": "Rock_Ice"
    },
    {
      "x": -18,
      "y": 28,
      "z": -11,
      "name": "Rock_Ice"
    },
    {
      "x": -18,
      "y": 29,
      "z": -11,
      "name": "Rock_Ice"
    },
    {
      "x": -18,
      "y": 30,
      "z": -11,
      "name": "Rock_Ice_Permafrost"
    },
    {
      "x": -18,
      "y": 31,
      "z": -11,
      "name": "Rock_Ice"
    },
    {
      "x": -18,
      "y": 32,
      "z": -11,
      "name": "Rock_Ice"
    },
    {
      "x": -18,
      "y": 33,
      "z": -11,
      "name": "Soil_Snow"
    },
    {
      "x": -18,
      "y": 13,
      "z": -10,
      "name": "Rock_Ice_Permafrost"
    },
    {
      "x": -18,
      "y": 14,
      "z": -10,
      "name": "Rock_Ice"
    },
    {
      "x": -18,
      "y": 15,
      "z": -10,
      "name": "Rock_Ice_Permafrost"
    },
    {
      "x": -18,
      "y": 16,
      "z": -10,
      "name": "Rock_Ice"
    },
    {
      "x": -18,
      "y": 17,
      "z": -10,
      "name": "Rock_Ice"
    },
    {
      "x": -18,
      "y": 18,
      "z": -10,
      "name": "Rock_Ice"
    },
    {
      "x": -18,
      "y": 19,
      "z": -10,
      "name": "Rock_Ice"
    },
    {
      "x": -18,
      "y": 20,
      "z": -10,
      "name": "Rock_Ice"
    },
    {
      "x": -18,
      "y": 21,
      "z": -10,
      "name": "Rock_Ice"
    },
    {
      "x": -18,
      "y": 22,
      "z": -10,
      "name": "Rock_Ice"
    },
    {
      "x": -18,
      "y": 23,
      "z": -10,
      "name": "Rock_Ice"
    },
    {
      "x": -18,
      "y": 24,
      "z": -10,
      "name": "Rock_Ice"
    },
    {
      "x": -18,
      "y": 25,
      "z": -10,
      "name": "Rock_Ice_Permafrost"
    },
    {
      "x": -18,
      "y": 26,
      "z": -10,
      "name": "Rock_Ice"
    },
    {
      "x": -18,
      "y": 27,
      "z": -10,
      "name": "Rock_Ice_Permafrost"
    },
    {
      "x": -18,
      "y": 28,
      "z": -10,
      "name": "Rock_Ice"
    },
    {
      "x": -18,
      "y": 29,
      "z": -10,
      "name": "Rock_Ice"
    },
    {
      "x": -18,
      "y": 30,
      "z": -10,
      "name": "Rock_Ice_Permafrost"
    },
    {
      "x": -18,
      "y": 31,
      "z": -10,
      "name": "Rock_Ice_Permafrost"
    },
    {
      "x": -18,
      "y": 32,
      "z": -10,
      "name": "Rock_Ice"
    },
    {
      "x": -18,
      "y": 33,
      "z": -10,
      "name": "Soil_Snow"
    },
    {
      "x": -18,
      "y": 14,
      "z": -9,
      "name": "Rock_Ice"
    },
    {
      "x": -18,
      "y": 15,
      "z": -9,
      "name": "Rock_Ice_Permafrost"
    },
    {
      "x": -18,
      "y": 16,
      "z": -9,
      "name": "Rock_Ice"
    },
    {
      "x": -18,
      "y": 17,
      "z": -9,
      "name": "Rock_Ice"
    },
    {
      "x": -18,
      "y": 18,
      "z": -9,
      "name": "Rock_Ice"
    },
    {
      "x": -18,
      "y": 19,
      "z": -9,
      "name": "Rock_Ice"
    },
    {
      "x": -18,
      "y": 20,
      "z": -9,
      "name": "Rock_Ice"
    },
    {
      "x": -18,
      "y": 21,
      "z": -9,
      "name": "Rock_Ice"
    },
    {
      "x": -18,
      "y": 22,
      "z": -9,
      "name": "Rock_Ice"
    },
    {
      "x": -18,
      "y": 23,
      "z": -9,
      "name": "Rock_Ice"
    },
    {
      "x": -18,
      "y": 24,
      "z": -9,
      "name": "Rock_Ice_Permafrost"
    },
    {
      "x": -18,
      "y": 25,
      "z": -9,
      "name": "Rock_Ice_Permafrost"
    },
    {
      "x": -18,
      "y": 26,
      "z": -9,
      "name": "Rock_Ice_Permafrost"
    },
    {
      "x": -18,
      "y": 27,
      "z": -9,
      "name": "Rock_Ice"
    },
    {
      "x": -18,
      "y": 28,
      "z": -9,
      "name": "Rock_Ice_Permafrost"
    },
    {
      "x": -18,
      "y": 29,
      "z": -9,
      "name": "Rock_Ice_Permafrost"
    },
    {
      "x": -18,
      "y": 30,
      "z": -9,
      "name": "Rock_Ice_Permafrost"
    },
    {
      "x": -18,
      "y": 31,
      "z": -9,
      "name": "Rock_Ice_Permafrost"
    },
    {
      "x": -18,
      "y": 32,
      "z": -9,
      "name": "Rock_Ice"
    },
    {
      "x": -18,
      "y": 33,
      "z": -9,
      "name": "Soil_Snow"
    },
    {
      "x": -18,
      "y": 14,
      "z": -8,
      "name": "Rock_Ice"
    },
    {
      "x": -18,
      "y": 15,
      "z": -8,
      "name": "Rock_Ice"
    },
    {
      "x": -18,
      "y": 16,
      "z": -8,
      "name": "Rock_Ice"
    },
    {
      "x": -18,
      "y": 17,
      "z": -8,
      "name": "Rock_Ice"
    },
    {
      "x": -18,
      "y": 18,
      "z": -8,
      "name": "Rock_Ice"
    },
    {
      "x": -18,
      "y": 19,
      "z": -8,
      "name": "Rock_Ice"
    },
    {
      "x": -18,
      "y": 20,
      "z": -8,
      "name": "Rock_Ice"
    },
    {
      "x": -18,
      "y": 21,
      "z": -8,
      "name": "Rock_Ice_Permafrost"
    },
    {
      "x": -18,
      "y": 22,
      "z": -8,
      "name": "Rock_Ice_Permafrost"
    },
    {
      "x": -18,
      "y": 23,
      "z": -8,
      "name": "Rock_Ice_Permafrost"
    },
    {
      "x": -18,
      "y": 24,
      "z": -8,
      "name": "Rock_Ice_Permafrost"
    },
    {
      "x": -18,
      "y": 25,
      "z": -8,
      "name": "Rock_Ice_Permafrost"
    },
    {
      "x": -18,
      "y": 26,
      "z": -8,
      "name": "Rock_Ice_Permafrost"
    },
    {
      "x": -18,
      "y": 27,
      "z": -8,
      "name": "Rock_Ice_Permafrost"
    },
    {
      "x": -18,
      "y": 28,
      "z": -8,
      "name": "Rock_Ice_Permafrost"
    },
    {
      "x": -18,
      "y": 29,
      "z": -8,
      "name": "Rock_Ice_Permafrost"
    },
    {
      "x": -18,
      "y": 30,
      "z": -8,
      "name": "Rock_Ice_Permafrost"
    },
    {
      "x": -18,
      "y": 31,
      "z": -8,
      "name": "Rock_Ice_Permafrost"
    },
    {
      "x": -18,
      "y": 32,
      "z": -8,
      "name": "Rock_Ice"
    },
    {
      "x": -18,
      "y": 33,
      "z": -8,
      "name": "Soil_Snow"
    },
    {
      "x": -18,
      "y": 15,
      "z": -7,
      "name": "Rock_Ice"
    },
    {
      "x": -18,
      "y": 16,
      "z": -7,
      "name": "Rock_Ice"
    },
    {
      "x": -18,
      "y": 17,
      "z": -7,
      "name": "Rock_Ice"
    },
    {
      "x": -18,
      "y": 18,
      "z": -7,
      "name": "Rock_Ice_Permafrost"
    },
    {
      "x": -18,
      "y": 19,
      "z": -7,
      "name": "Rock_Ice_Permafrost"
    },
    {
      "x": -18,
      "y": 20,
      "z": -7,
      "name": "Rock_Ice"
    },
    {
      "x": -18,
      "y": 21,
      "z": -7,
      "name": "Rock_Ice_Permafrost"
    },
    {
      "x": -18,
      "y": 22,
      "z": -7,
      "name": "Rock_Ice_Permafrost"
    },
    {
      "x": -18,
      "y": 23,
      "z": -7,
      "name": "Rock_Ice_Permafrost"
    },
    {
      "x": -18,
      "y": 24,
      "z": -7,
      "name": "Rock_Ice_Permafrost"
    },
    {
      "x": -18,
      "y": 25,
      "z": -7,
      "name": "Rock_Ice_Permafrost"
    },
    {
      "x": -18,
      "y": 26,
      "z": -7,
      "name": "Rock_Ice_Permafrost"
    },
    {
      "x": -18,
      "y": 27,
      "z": -7,
      "name": "Rock_Ice_Permafrost"
    },
    {
      "x": -18,
      "y": 28,
      "z": -7,
      "name": "Rock_Ice_Permafrost"
    },
    {
      "x": -18,
      "y": 29,
      "z": -7,
      "name": "Rock_Ice_Permafrost"
    },
    {
      "x": -18,
      "y": 30,
      "z": -7,
      "name": "Rock_Ice_Permafrost"
    },
    {
      "x": -18,
      "y": 31,
      "z": -7,
      "name": "Rock_Ice_Permafrost"
    },
    {
      "x": -18,
      "y": 32,
      "z": -7,
      "name": "Rock_Ice"
    },
    {
      "x": -18,
      "y": 33,
      "z": -7,
      "name": "Soil_Snow"
    },
    {
      "x": -18,
      "y": 15,
      "z": -6,
      "name": "Rock_Ice_Permafrost"
    },
    {
      "x": -18,
      "y": 16,
      "z": -6,
      "name": "Rock_Ice_Permafrost"
    },
    {
      "x": -18,
      "y": 17,
      "z": -6,
      "name": "Rock_Ice_Permafrost"
    },
    {
      "x": -18,
      "y": 18,
      "z": -6,
      "name": "Rock_Ice_Permafrost"
    },
    {
      "x": -18,
      "y": 19,
      "z": -6,
      "name": "Rock_Ice_Permafrost"
    },
    {
      "x": -18,
      "y": 20,
      "z": -6,
      "name": "Rock_Ice_Permafrost"
    },
    {
      "x": -18,
      "y": 21,
      "z": -6,
      "name": "Rock_Ice_Permafrost"
    },
    {
      "x": -18,
      "y": 22,
      "z": -6,
      "name": "Rock_Ice_Permafrost"
    },
    {
      "x": -18,
      "y": 23,
      "z": -6,
      "name": "Rock_Ice_Permafrost"
    },
    {
      "x": -18,
      "y": 24,
      "z": -6,
      "name": "Rock_Ice_Permafrost"
    },
    {
      "x": -18,
      "y": 25,
      "z": -6,
      "name": "Rock_Ice_Permafrost"
    },
    {
      "x": -18,
      "y": 26,
      "z": -6,
      "name": "Rock_Ice_Permafrost"
    },
    {
      "x": -18,
      "y": 27,
      "z": -6,
      "name": "Rock_Ice_Permafrost"
    },
    {
      "x": -18,
      "y": 28,
      "z": -6,
      "name": "Rock_Ice_Permafrost"
    },
    {
      "x": -18,
      "y": 29,
      "z": -6,
      "name": "Rock_Ice_Permafrost"
    },
    {
      "x": -18,
      "y": 30,
      "z": -6,
      "name": "Rock_Ice_Permafrost"
    },
    {
      "x": -18,
      "y": 31,
      "z": -6,
      "name": "Rock_Ice_Permafrost"
    },
    {
      "x": -18,
      "y": 32,
      "z": -6,
      "name": "Rock_Ice"
    },
    {
      "x": -18,
      "y": 33,
      "z": -6,
      "name": "Soil_Snow"
    },
    {
      "x": -18,
      "y": 16,
      "z": -5,
      "name": "Rock_Ice_Permafrost"
    },
    {
      "x": -18,
      "y": 17,
      "z": -5,
      "name": "Rock_Ice_Permafrost"
    },
    {
      "x": -18,
      "y": 18,
      "z": -5,
      "name": "Rock_Ice_Permafrost"
    },
    {
      "x": -18,
      "y": 19,
      "z": -5,
      "name": "Rock_Ice_Permafrost"
    },
    {
      "x": -18,
      "y": 20,
      "z": -5,
      "name": "Rock_Ice_Permafrost"
    },
    {
      "x": -18,
      "y": 21,
      "z": -5,
      "name": "Rock_Ice_Permafrost"
    },
    {
      "x": -18,
      "y": 22,
      "z": -5,
      "name": "Rock_Ice_Permafrost"
    },
    {
      "x": -18,
      "y": 23,
      "z": -5,
      "name": "Rock_Ice_Permafrost"
    },
    {
      "x": -18,
      "y": 24,
      "z": -5,
      "name": "Rock_Ice_Permafrost"
    },
    {
      "x": -18,
      "y": 25,
      "z": -5,
      "name": "Rock_Ice_Permafrost"
    },
    {
      "x": -18,
      "y": 26,
      "z": -5,
      "name": "Rock_Ice_Permafrost"
    },
    {
      "x": -18,
      "y": 27,
      "z": -5,
      "name": "Rock_Ice_Permafrost"
    },
    {
      "x": -18,
      "y": 28,
      "z": -5,
      "name": "Rock_Ice_Permafrost"
    },
    {
      "x": -18,
      "y": 29,
      "z": -5,
      "name": "Rock_Ice_Permafrost"
    },
    {
      "x": -18,
      "y": 30,
      "z": -5,
      "name": "Rock_Ice_Permafrost"
    },
    {
      "x": -18,
      "y": 31,
      "z": -5,
      "name": "Rock_Ice_Permafrost"
    },
    {
      "x": -18,
      "y": 32,
      "z": -5,
      "name": "Rock_Ice"
    },
    {
      "x": -18,
      "y": 33,
      "z": -5,
      "name": "Soil_Snow"
    },
    {
      "x": -18,
      "y": 16,
      "z": -4,
      "name": "Rock_Ice_Permafrost"
    },
    {
      "x": -18,
      "y": 17,
      "z": -4,
      "name": "Rock_Ice_Permafrost"
    },
    {
      "x": -18,
      "y": 18,
      "z": -4,
      "name": "Rock_Ice_Permafrost"
    },
    {
      "x": -18,
      "y": 19,
      "z": -4,
      "name": "Rock_Ice_Permafrost"
    },
    {
      "x": -18,
      "y": 20,
      "z": -4,
      "name": "Rock_Ice_Permafrost"
    },
    {
      "x": -18,
      "y": 21,
      "z": -4,
      "name": "Rock_Ice_Permafrost"
    },
    {
      "x": -18,
      "y": 22,
      "z": -4,
      "name": "Rock_Ice_Permafrost"
    },
    {
      "x": -18,
      "y": 23,
      "z": -4,
      "name": "Rock_Ice_Permafrost"
    },
    {
      "x": -18,
      "y": 24,
      "z": -4,
      "name": "Rock_Ice_Permafrost"
    },
    {
      "x": -18,
      "y": 25,
      "z": -4,
      "name": "Rock_Ice"
    },
    {
      "x": -18,
      "y": 26,
      "z": -4,
      "name": "Rock_Ice"
    },
    {
      "x": -18,
      "y": 27,
      "z": -4,
      "name": "Rock_Ice_Permafrost"
    },
    {
      "x": -18,
      "y": 28,
      "z": -4,
      "name": "Rock_Ice"
    },
    {
      "x": -18,
      "y": 29,
      "z": -4,
      "name": "Rock_Ice"
    },
    {
      "x": -18,
      "y": 30,
      "z": -4,
      "name": "Rock_Ice"
    },
    {
      "x": -18,
      "y": 31,
      "z": -4,
      "name": "Rock_Ice"
    },
    {
      "x": -18,
      "y": 32,
      "z": -4,
      "name": "Rock_Ice"
    },
    {
      "x": -18,
      "y": 33,
      "z": -4,
      "name": "Soil_Snow"
    },
    {
      "x": -18,
      "y": 16,
      "z": -3,
      "name": "Rock_Ice_Permafrost"
    },
    {
      "x": -18,
      "y": 17,
      "z": -3,
      "name": "Rock_Ice_Permafrost"
    },
    {
      "x": -18,
      "y": 18,
      "z": -3,
      "name": "Rock_Ice_Permafrost"
    },
    {
      "x": -18,
      "y": 19,
      "z": -3,
      "name": "Rock_Ice_Permafrost"
    },
    {
      "x": -18,
      "y": 20,
      "z": -3,
      "name": "Rock_Ice_Permafrost"
    },
    {
      "x": -18,
      "y": 21,
      "z": -3,
      "name": "Rock_Ice_Permafrost"
    },
    {
      "x": -18,
      "y": 22,
      "z": -3,
      "name": "Rock_Ice_Permafrost"
    },
    {
      "x": -18,
      "y": 23,
      "z": -3,
      "name": "Rock_Ice_Permafrost"
    },
    {
      "x": -18,
      "y": 24,
      "z": -3,
      "name": "Rock_Ice"
    },
    {
      "x": -18,
      "y": 25,
      "z": -3,
      "name": "Rock_Ice"
    },
    {
      "x": -18,
      "y": 26,
      "z": -3,
      "name": "Rock_Ice_Permafrost"
    },
    {
      "x": -18,
      "y": 27,
      "z": -3,
      "name": "Rock_Ice"
    },
    {
      "x": -18,
      "y": 28,
      "z": -3,
      "name": "Rock_Ice"
    },
    {
      "x": -18,
      "y": 29,
      "z": -3,
      "name": "Rock_Ice"
    },
    {
      "x": -18,
      "y": 30,
      "z": -3,
      "name": "Rock_Ice"
    },
    {
      "x": -18,
      "y": 31,
      "z": -3,
      "name": "Soil_Snow"
    },
    {
      "x": -18,
      "y": 17,
      "z": -2,
      "name": "Rock_Ice_Permafrost"
    },
    {
      "x": -18,
      "y": 18,
      "z": -2,
      "name": "Rock_Ice_Permafrost"
    },
    {
      "x": -18,
      "y": 19,
      "z": -2,
      "name": "Rock_Ice_Permafrost"
    },
    {
      "x": -18,
      "y": 20,
      "z": -2,
      "name": "Rock_Ice_Permafrost"
    },
    {
      "x": -18,
      "y": 21,
      "z": -2,
      "name": "Rock_Ice_Permafrost"
    },
    {
      "x": -18,
      "y": 22,
      "z": -2,
      "name": "Rock_Ice_Permafrost"
    },
    {
      "x": -18,
      "y": 23,
      "z": -2,
      "name": "Rock_Ice_Permafrost"
    },
    {
      "x": -18,
      "y": 24,
      "z": -2,
      "name": "Rock_Ice"
    },
    {
      "x": -18,
      "y": 25,
      "z": -2,
      "name": "Rock_Ice"
    },
    {
      "x": -18,
      "y": 26,
      "z": -2,
      "name": "Rock_Ice"
    },
    {
      "x": -18,
      "y": 27,
      "z": -2,
      "name": "Rock_Ice"
    },
    {
      "x": -18,
      "y": 28,
      "z": -2,
      "name": "Rock_Ice"
    },
    {
      "x": -18,
      "y": 29,
      "z": -2,
      "name": "Rock_Ice"
    },
    {
      "x": -18,
      "y": 30,
      "z": -2,
      "name": "Soil_Snow"
    },
    {
      "x": -18,
      "y": 18,
      "z": -1,
      "name": "Rock_Ice_Permafrost"
    },
    {
      "x": -18,
      "y": 19,
      "z": -1,
      "name": "Rock_Ice_Permafrost"
    },
    {
      "x": -18,
      "y": 20,
      "z": -1,
      "name": "Rock_Ice_Permafrost"
    },
    {
      "x": -18,
      "y": 21,
      "z": -1,
      "name": "Rock_Ice_Permafrost"
    },
    {
      "x": -18,
      "y": 22,
      "z": -1,
      "name": "Rock_Ice_Permafrost"
    },
    {
      "x": -18,
      "y": 23,
      "z": -1,
      "name": "Rock_Ice_Permafrost"
    },
    {
      "x": -18,
      "y": 24,
      "z": -1,
      "name": "Rock_Ice"
    },
    {
      "x": -18,
      "y": 25,
      "z": -1,
      "name": "Rock_Ice"
    },
    {
      "x": -18,
      "y": 26,
      "z": -1,
      "name": "Rock_Ice"
    },
    {
      "x": -18,
      "y": 27,
      "z": -1,
      "name": "Rock_Ice"
    },
    {
      "x": -18,
      "y": 28,
      "z": -1,
      "name": "Rock_Ice"
    },
    {
      "x": -18,
      "y": 29,
      "z": -1,
      "name": "Rock_Ice"
    },
    {
      "x": -18,
      "y": 30,
      "z": -1,
      "name": "Rock_Ice"
    },
    {
      "x": -18,
      "y": 31,
      "z": -1,
      "name": "Rock_Ice"
    },
    {
      "x": -18,
      "y": 32,
      "z": -1,
      "name": "Soil_Snow"
    },
    {
      "x": -18,
      "y": 18,
      "z": 0,
      "name": "Rock_Ice_Permafrost"
    },
    {
      "x": -18,
      "y": 19,
      "z": 0,
      "name": "Rock_Ice_Permafrost"
    },
    {
      "x": -18,
      "y": 20,
      "z": 0,
      "name": "Rock_Ice_Permafrost"
    },
    {
      "x": -18,
      "y": 21,
      "z": 0,
      "name": "Rock_Ice_Permafrost"
    },
    {
      "x": -18,
      "y": 22,
      "z": 0,
      "name": "Rock_Ice_Permafrost"
    },
    {
      "x": -18,
      "y": 23,
      "z": 0,
      "name": "Rock_Ice_Permafrost"
    },
    {
      "x": -18,
      "y": 24,
      "z": 0,
      "name": "Rock_Ice"
    },
    {
      "x": -18,
      "y": 25,
      "z": 0,
      "name": "Rock_Ice"
    },
    {
      "x": -18,
      "y": 26,
      "z": 0,
      "name": "Rock_Ice"
    },
    {
      "x": -18,
      "y": 27,
      "z": 0,
      "name": "Rock_Ice"
    },
    {
      "x": -18,
      "y": 28,
      "z": 0,
      "name": "Rock_Ice"
    },
    {
      "x": -18,
      "y": 29,
      "z": 0,
      "name": "Rock_Ice"
    },
    {
      "x": -18,
      "y": 30,
      "z": 0,
      "name": "Rock_Ice"
    },
    {
      "x": -18,
      "y": 31,
      "z": 0,
      "name": "Rock_Ice"
    },
    {
      "x": -18,
      "y": 32,
      "z": 0,
      "name": "Soil_Snow"
    },
    {
      "x": -18,
      "y": 17,
      "z": 1,
      "name": "Rock_Ice_Permafrost"
    },
    {
      "x": -18,
      "y": 18,
      "z": 1,
      "name": "Rock_Ice_Permafrost"
    },
    {
      "x": -18,
      "y": 19,
      "z": 1,
      "name": "Rock_Ice_Permafrost"
    },
    {
      "x": -18,
      "y": 20,
      "z": 1,
      "name": "Rock_Ice_Permafrost"
    },
    {
      "x": -18,
      "y": 21,
      "z": 1,
      "name": "Rock_Ice_Permafrost"
    },
    {
      "x": -18,
      "y": 22,
      "z": 1,
      "name": "Rock_Ice"
    },
    {
      "x": -18,
      "y": 23,
      "z": 1,
      "name": "Rock_Ice"
    },
    {
      "x": -18,
      "y": 24,
      "z": 1,
      "name": "Rock_Ice"
    },
    {
      "x": -18,
      "y": 25,
      "z": 1,
      "name": "Rock_Ice"
    },
    {
      "x": -18,
      "y": 26,
      "z": 1,
      "name": "Rock_Ice"
    },
    {
      "x": -18,
      "y": 27,
      "z": 1,
      "name": "Rock_Ice"
    },
    {
      "x": -18,
      "y": 28,
      "z": 1,
      "name": "Rock_Ice"
    },
    {
      "x": -18,
      "y": 29,
      "z": 1,
      "name": "Rock_Ice"
    },
    {
      "x": -18,
      "y": 30,
      "z": 1,
      "name": "Rock_Ice"
    },
    {
      "x": -18,
      "y": 31,
      "z": 1,
      "name": "Soil_Snow"
    },
    {
      "x": -18,
      "y": 17,
      "z": 2,
      "name": "Rock_Ice_Permafrost"
    },
    {
      "x": -18,
      "y": 18,
      "z": 2,
      "name": "Rock_Ice_Permafrost"
    },
    {
      "x": -18,
      "y": 19,
      "z": 2,
      "name": "Rock_Ice_Permafrost"
    },
    {
      "x": -18,
      "y": 20,
      "z": 2,
      "name": "Rock_Ice_Permafrost"
    },
    {
      "x": -18,
      "y": 21,
      "z": 2,
      "name": "Rock_Ice"
    },
    {
      "x": -18,
      "y": 22,
      "z": 2,
      "name": "Rock_Ice"
    },
    {
      "x": -18,
      "y": 23,
      "z": 2,
      "name": "Rock_Ice"
    },
    {
      "x": -18,
      "y": 24,
      "z": 2,
      "name": "Rock_Ice"
    },
    {
      "x": -18,
      "y": 25,
      "z": 2,
      "name": "Rock_Ice"
    },
    {
      "x": -18,
      "y": 26,
      "z": 2,
      "name": "Rock_Ice"
    },
    {
      "x": -18,
      "y": 27,
      "z": 2,
      "name": "Rock_Ice"
    },
    {
      "x": -18,
      "y": 28,
      "z": 2,
      "name": "Rock_Ice"
    },
    {
      "x": -18,
      "y": 29,
      "z": 2,
      "name": "Rock_Ice"
    },
    {
      "x": -18,
      "y": 30,
      "z": 2,
      "name": "Rock_Ice"
    },
    {
      "x": -18,
      "y": 31,
      "z": 2,
      "name": "Soil_Snow"
    },
    {
      "x": -18,
      "y": 17,
      "z": 3,
      "name": "Rock_Ice_Permafrost"
    },
    {
      "x": -18,
      "y": 18,
      "z": 3,
      "name": "Rock_Ice_Permafrost"
    },
    {
      "x": -18,
      "y": 19,
      "z": 3,
      "name": "Rock_Ice_Permafrost"
    },
    {
      "x": -18,
      "y": 20,
      "z": 3,
      "name": "Rock_Ice"
    },
    {
      "x": -18,
      "y": 21,
      "z": 3,
      "name": "Rock_Ice"
    },
    {
      "x": -18,
      "y": 22,
      "z": 3,
      "name": "Rock_Ice"
    },
    {
      "x": -18,
      "y": 23,
      "z": 3,
      "name": "Rock_Ice"
    },
    {
      "x": -18,
      "y": 24,
      "z": 3,
      "name": "Rock_Ice"
    },
    {
      "x": -18,
      "y": 25,
      "z": 3,
      "name": "Rock_Ice"
    },
    {
      "x": -18,
      "y": 26,
      "z": 3,
      "name": "Rock_Ice"
    },
    {
      "x": -18,
      "y": 27,
      "z": 3,
      "name": "Rock_Ice"
    },
    {
      "x": -18,
      "y": 28,
      "z": 3,
      "name": "Rock_Ice"
    },
    {
      "x": -18,
      "y": 29,
      "z": 3,
      "name": "Rock_Ice"
    },
    {
      "x": -18,
      "y": 30,
      "z": 3,
      "name": "Rock_Ice"
    },
    {
      "x": -18,
      "y": 31,
      "z": 3,
      "name": "Soil_Snow"
    },
    {
      "x": -18,
      "y": 17,
      "z": 4,
      "name": "Rock_Ice_Permafrost"
    },
    {
      "x": -18,
      "y": 18,
      "z": 4,
      "name": "Rock_Ice_Permafrost"
    },
    {
      "x": -18,
      "y": 19,
      "z": 4,
      "name": "Rock_Ice_Permafrost"
    },
    {
      "x": -18,
      "y": 20,
      "z": 4,
      "name": "Rock_Ice_Permafrost"
    },
    {
      "x": -18,
      "y": 21,
      "z": 4,
      "name": "Rock_Ice"
    },
    {
      "x": -18,
      "y": 22,
      "z": 4,
      "name": "Rock_Ice"
    },
    {
      "x": -18,
      "y": 23,
      "z": 4,
      "name": "Rock_Ice"
    },
    {
      "x": -18,
      "y": 24,
      "z": 4,
      "name": "Rock_Ice"
    },
    {
      "x": -18,
      "y": 25,
      "z": 4,
      "name": "Rock_Ice"
    },
    {
      "x": -18,
      "y": 26,
      "z": 4,
      "name": "Rock_Ice"
    },
    {
      "x": -18,
      "y": 27,
      "z": 4,
      "name": "Rock_Ice"
    },
    {
      "x": -18,
      "y": 28,
      "z": 4,
      "name": "Rock_Ice"
    },
    {
      "x": -18,
      "y": 29,
      "z": 4,
      "name": "Rock_Ice"
    },
    {
      "x": -18,
      "y": 30,
      "z": 4,
      "name": "Rock_Ice"
    },
    {
      "x": -18,
      "y": 31,
      "z": 4,
      "name": "Soil_Snow"
    },
    {
      "x": -18,
      "y": 17,
      "z": 5,
      "name": "Rock_Ice_Permafrost"
    },
    {
      "x": -18,
      "y": 18,
      "z": 5,
      "name": "Rock_Ice_Permafrost"
    },
    {
      "x": -18,
      "y": 19,
      "z": 5,
      "name": "Rock_Ice_Permafrost"
    },
    {
      "x": -18,
      "y": 20,
      "z": 5,
      "name": "Rock_Ice"
    },
    {
      "x": -18,
      "y": 21,
      "z": 5,
      "name": "Rock_Ice"
    },
    {
      "x": -18,
      "y": 22,
      "z": 5,
      "name": "Rock_Ice"
    },
    {
      "x": -18,
      "y": 23,
      "z": 5,
      "name": "Rock_Ice"
    },
    {
      "x": -18,
      "y": 24,
      "z": 5,
      "name": "Rock_Ice"
    },
    {
      "x": -18,
      "y": 25,
      "z": 5,
      "name": "Rock_Ice"
    },
    {
      "x": -18,
      "y": 26,
      "z": 5,
      "name": "Rock_Ice"
    },
    {
      "x": -18,
      "y": 27,
      "z": 5,
      "name": "Rock_Ice"
    },
    {
      "x": -18,
      "y": 28,
      "z": 5,
      "name": "Rock_Ice"
    },
    {
      "x": -18,
      "y": 29,
      "z": 5,
      "name": "Rock_Ice"
    },
    {
      "x": -18,
      "y": 30,
      "z": 5,
      "name": "Soil_Snow"
    },
    {
      "x": -18,
      "y": 16,
      "z": 6,
      "name": "Rock_Ice_Permafrost"
    },
    {
      "x": -18,
      "y": 17,
      "z": 6,
      "name": "Rock_Ice_Permafrost"
    },
    {
      "x": -18,
      "y": 18,
      "z": 6,
      "name": "Rock_Ice_Permafrost"
    },
    {
      "x": -18,
      "y": 19,
      "z": 6,
      "name": "Rock_Ice"
    },
    {
      "x": -18,
      "y": 20,
      "z": 6,
      "name": "Rock_Ice"
    },
    {
      "x": -18,
      "y": 21,
      "z": 6,
      "name": "Rock_Ice"
    },
    {
      "x": -18,
      "y": 22,
      "z": 6,
      "name": "Rock_Ice"
    },
    {
      "x": -18,
      "y": 23,
      "z": 6,
      "name": "Rock_Ice"
    },
    {
      "x": -18,
      "y": 24,
      "z": 6,
