{
  "version": 8,
  "blockIdVersion": 11,
  "anchorX": 2,
  "anchorY": 18,
  "anchorZ": 3,
  "blocks": [
    {
      "x": -19,
      "y": 54,
      "z": 8,
      "name": "Rock_Ice"
    },
    {
      "x": -19,
      "y": 55,
      "z": 8,
      "name": "Soil_Snow"
    },
    {
      "x": -19,
      "y": 52,
      "z": 9,
      "name": "Rock_Ice"
    },
    {
      "x": -19,
      "y": 53,
      "z": 9,
      "name": "Rock_Ice"
    },
    {
      "x": -19,
      "y": 54,
      "z": 9,
      "name": "Rock_Ice"
    },
    {
      "x": -19,
      "y": 55,
      "z": 9,
      "name": "Soil_Snow"
    },
    {
      "x": -19,
      "y": 51,
      "z": 10,
      "name": "Rock_Ice"
    },
    {
      "x": -19,
      "y": 52,
      "z": 10,
      "name": "Rock_Ice"
    },
    {
      "x": -19,
      "y": 53,
      "z": 10,
      "name": "Rock_Ice"
    },
    {
      "x": -19,
      "y": 54,
      "z": 10,
      "name": "Rock_Ice"
    },
    {
      "x": -19,
      "y": 55,
      "z": 10,
      "name": "Soil_Snow"
    },
    {
      "x": -19,
      "y": 50,
      "z": 11,
      "name": "Rock_Ice"
    },
    {
      "x": -19,
      "y": 51,
      "z": 11,
      "name": "Rock_Ice"
    },
    {
      "x": -19,
      "y": 52,
      "z": 11,
      "name": "Rock_Ice"
    },
    {
      "x": -19,
      "y": 53,
      "z": 11,
      "name": "Rock_Ice"
    },
    {
      "x": -19,
      "y": 54,
      "z": 11,
      "name": "Rock_Ice"
    },
    {
      "x": -19,
      "y": 55,
      "z": 11,
      "name": "Soil_Snow"
    },
    {
      "x": -19,
      "y": 49,
      "z": 12,
      "name": "Rock_Ice"
    },
    {
      "x": -19,
      "y": 50,
      "z": 12,
      "name": "Rock_Ice"
    },
    {
      "x": -19,
      "y": 51,
      "z": 12,
      "name": "Rock_Ice"
    },
    {
      "x": -19,
      "y": 52,
      "z": 12,
      "name": "Rock_Ice"
    },
    {
      "x": -19,
      "y": 53,
      "z": 12,
      "name": "Rock_Ice"
    },
    {
      "x": -19,
      "y": 54,
      "z": 12,
      "name": "Soil_Snow"
    },
    {
      "x": -19,
      "y": 49,
      "z": 13,
      "name": "Rock_Ice"
    },
    {
      "x": -19,
      "y": 50,
      "z": 13,
      "name": "Rock_Ice"
    },
    {
      "x": -19,
      "y": 51,
      "z": 13,
      "name": "Rock_Ice"
    },
    {
      "x": -19,
      "y": 52,
      "z": 13,
      "name": "Rock_Ice"
    },
    {
      "x": -19,
      "y": 53,
      "z": 13,
      "name": "Soil_Snow"
    },
    {
      "x": -19,
      "y": 48,
      "z": 14,
      "name": "Rock_Ice"
    },
    {
      "x": -19,
      "y": 49,
      "z": 14,
      "name": "Rock_Ice"
    },
    {
      "x": -19,
      "y": 50,
      "z": 14,
      "name": "Rock_Ice"
    },
    {
      "x": -19,
      "y": 51,
      "z": 14,
      "name": "Rock_Ice"
    },
    {
      "x": -19,
      "y": 52,
      "z": 14,
      "name": "Soil_Snow"
    },
    {
      "x": -19,
      "y": 48,
      "z": 15,
      "name": "Rock_Ice"
    },
    {
      "x": -19,
      "y": 49,
      "z": 15,
      "name": "Rock_Ice"
    },
    {
      "x": -19,
      "y": 50,
      "z": 15,
      "name": "Soil_Snow"
    },
    {
      "x": -19,
      "y": 48,
      "z": 16,
      "name": "Soil_Snow"
    },
    {
      "x": -18,
      "y": 49,
      "z": 5,
      "name": "Rock_Ice_Permafrost"
    },
    {
      "x": -18,
      "y": 50,
      "z": 5,
      "name": "Rock_Ice_Permafrost"
    },
    {
      "x": -18,
      "y": 51,
      "z": 5,
      "name": "Rock_Ice_Permafrost"
    },
    {
      "x": -18,
      "y": 52,
      "z": 5,
      "name": "Rock_Ice_Permafrost"
    },
    {
      "x": -18,
      "y": 53,
      "z": 5,
      "name": "Rock_Ice_Permafrost"
    },
    {
      "x": -18,
      "y": 54,
      "z": 5,
      "name": "Rock_Ice_Permafrost"
    },
    {
      "x": -18,
      "y": 55,
      "z": 5,
      "name": "Rock_Ice_Permafrost"
    },
    {
      "x": -18,
      "y": 56,
      "z": 5,
      "name": "Rock_Ice"
    },
    {
      "x": -18,
      "y": 57,
      "z": 5,
      "name": "Soil_Snow"
    },
    {
      "x": -18,
      "y": 46,
      "z": 6,
      "name": "Rock_Ice_Permafrost"
    },
    {
      "x": -18,
      "y": 47,
      "z": 6,
      "name": "Rock_Ice_Permafrost"
    },
    {
      "x": -18,
      "y": 48,
      "z": 6,
      "name": "Rock_Ice_Permafrost"
    },
    {
      "x": -18,
      "y": 49,
      "z": 6,
      "name": "Rock_Ice_Permafrost"
    },
    {
      "x": -18,
      "y": 50,
      "z": 6,
      "name": "Rock_Ice_Permafrost"
    },
    {
      "x": -18,
      "y": 51,
      "z": 6,
      "name": "Rock_Ice_Permafrost"
    },
    {
      "x": -18,
      "y": 52,
      "z": 6,
      "name": "Rock_Ice"
    },
    {
      "x": -18,
      "y": 53,
      "z": 6,
      "name": "Rock_Ice"
    },
    {
      "x": -18,
      "y": 54,
      "z": 6,
      "name": "Rock_Ice"
    },
    {
      "x": -18,
      "y": 55,
      "z": 6,
      "name": "Rock_Ice"
    },
    {
      "x": -18,
      "y": 56,
      "z": 6,
      "name": "Rock_Ice"
    },
    {
      "x": -18,
      "y": 57,
      "z": 6,
      "name": "Rock_Ice"
    },
    {
      "x": -18,
      "y": 44,
      "z": 7,
      "name": "Rock_Ice_Permafrost"
    },
    {
      "x": -18,
      "y": 45,
      "z": 7,
      "name": "Rock_Ice_Permafrost"
    },
    {
      "x": -18,
      "y": 46,
      "z": 7,
      "name": "Rock_Ice_Permafrost"
    },
    {
      "x": -18,
      "y": 47,
      "z": 7,
      "name": "Rock_Ice_Permafrost"
    },
    {
      "x": -18,
      "y": 48,
      "z": 7,
      "name": "Rock_Ice"
    },
    {
      "x": -18,
      "y": 49,
      "z": 7,
      "name": "Rock_Ice"
    },
    {
      "x": -18,
      "y": 50,
      "z": 7,
      "name": "Rock_Ice_Permafrost"
    },
    {
      "x": -18,
      "y": 51,
      "z": 7,
      "name": "Rock_Ice_Permafrost"
    },
    {
      "x": -18,
      "y": 52,
      "z": 7,
      "name": "Rock_Ice"
    },
    {
      "x": -18,
      "y": 53,
      "z": 7,
      "name": "Rock_Ice"
    },
    {
      "x": -18,
      "y": 54,
      "z": 7,
      "name": "Rock_Ice"
    },
    {
      "x": -18,
      "y": 55,
      "z": 7,
      "name": "Rock_Ice"
    },
    {
      "x": -18,
      "y": 56,
      "z": 7,
      "name": "Rock_Ice"
    },
    {
      "x": -18,
      "y": 57,
      "z": 7,
      "name": "Rock_Ice"
    },
    {
      "x": -18,
      "y": 43,
      "z": 8,
      "name": "Rock_Ice_Permafrost"
    },
    {
      "x": -18,
      "y": 44,
      "z": 8,
      "name": "Rock_Ice_Permafrost"
    },
    {
      "x": -18,
      "y": 45,
      "z": 8,
      "name": "Rock_Ice_Permafrost"
    },
    {
      "x": -18,
      "y": 46,
      "z": 8,
      "name": "Rock_Ice_Permafrost"
    },
    {
      "x": -18,
      "y": 47,
      "z": 8,
      "name": "Rock_Ice"
    },
    {
      "x": -18,
      "y": 48,
      "z": 8,
      "name": "Rock_Ice_Permafrost"
    },
    {
      "x": -18,
      "y": 49,
      "z": 8,
      "name": "Rock_Ice_Permafrost"
    },
    {
      "x": -18,
      "y": 50,
      "z": 8,
      "name": "Rock_Ice_Permafrost"
    },
    {
      "x": -18,
      "y": 51,
      "z": 8,
      "name": "Rock_Ice"
    },
    {
      "x": -18,
      "y": 52,
      "z": 8,
      "name": "Rock_Ice"
    },
    {
      "x": -18,
      "y": 53,
      "z": 8,
      "name": "Rock_Ice"
    },
    {
      "x": -18,
      "y": 54,
      "z": 8,
      "name": "Rock_Ice"
    },
    {
      "x": -18,
      "y": 55,
      "z": 8,
      "name": "Rock_Ice"
    },
    {
      "x": -18,
      "y": 56,
      "z": 8,
      "name": "Rock_Ice"
    },
    {
      "x": -18,
      "y": 57,
      "z": 8,
      "name": "Rock_Ice"
    },
    {
      "x": -18,
      "y": 58,
      "z": 8,
      "name": "Rock_Ice"
    },
    {
      "x": -18,
      "y": 42,
      "z": 9,
      "name": "Rock_Ice_Permafrost"
    },
    {
      "x": -18,
      "y": 43,
      "z": 9,
      "name": "Rock_Ice_Permafrost"
    },
    {
      "x": -18,
      "y": 44,
      "z": 9,
      "name": "Rock_Ice"
    },
    {
      "x": -18,
      "y": 45,
      "z": 9,
      "name": "Rock_Ice"
    },
    {
      "x": -18,
      "y": 46,
      "z": 9,
      "name": "Rock_Ice"
    },
    {
      "x": -18,
      "y": 47,
      "z": 9,
      "name": "Rock_Ice_Permafrost"
    },
    {
      "x": -18,
      "y": 48,
      "z": 9,
      "name": "Rock_Ice"
    },
    {
      "x": -18,
      "y": 49,
      "z": 9,
      "name": "Rock_Ice"
    },
    {
      "x": -18,
      "y": 50,
      "z": 9,
      "name": "Rock_Ice"
    },
    {
      "x": -18,
      "y": 51,
      "z": 9,
      "name": "Rock_Ice"
    },
    {
      "x": -18,
      "y": 52,
      "z": 9,
      "name": "Rock_Ice"
    },
    {
      "x": -18,
      "y": 53,
      "z": 9,
      "name": "Rock_Ice"
    },
    {
      "x": -18,
      "y": 54,
      "z": 9,
      "name": "Rock_Ice"
    },
    {
      "x": -18,
      "y": 55,
      "z": 9,
      "name": "Rock_Ice"
    },
    {
      "x": -18,
      "y": 56,
      "z": 9,
      "name": "Rock_Ice"
    },
    {
      "x": -18,
      "y": 57,
      "z": 9,
      "name": "Rock_Ice"
    },
    {
      "x": -18,
      "y": 58,
      "z": 9,
      "name": "Rock_Ice"
    },
    {
      "x": -18,
      "y": 41,
      "z": 10,
      "name": "Rock_Ice_Permafrost"
    },
    {
      "x": -18,
      "y": 42,
      "z": 10,
      "name": "Rock_Ice_Permafrost"
    },
    {
      "x": -18,
      "y": 43,
      "z": 10,
      "name": "Rock_Ice"
    },
    {
      "x": -18,
      "y": 44,
      "z": 10,
      "name": "Rock_Ice"
    },
    {
      "x": -18,
      "y": 45,
      "z": 10,
      "name": "Rock_Ice_Permafrost"
    },
    {
      "x": -18,
      "y": 46,
      "z": 10,
      "name": "Rock_Ice"
    },
    {
      "x": -18,
      "y": 47,
      "z": 10,
      "name": "Rock_Ice"
    },
    {
      "x": -18,
      "y": 48,
      "z": 10,
      "name": "Rock_Ice"
    },
    {
      "x": -18,
      "y": 49,
      "z": 10,
      "name": "Rock_Ice"
    },
    {
      "x": -18,
      "y": 50,
      "z": 10,
      "name": "Rock_Ice"
    },
    {
      "x": -18,
      "y": 51,
      "z": 10,
      "name": "Rock_Ice"
    },
    {
      "x": -18,
      "y": 52,
      "z": 10,
      "name": "Rock_Ice"
    },
    {
      "x": -18,
      "y": 53,
      "z": 10,
      "name": "Rock_Ice"
    },
    {
      "x": -18,
      "y": 54,
      "z": 10,
      "name": "Rock_Ice"
    },
    {
      "x": -18,
      "y": 55,
      "z": 10,
      "name": "Rock_Ice"
    },
    {
      "x": -18,
      "y": 56,
      "z": 10,
      "name": "Rock_Ice"
    },
    {
      "x": -18,
      "y": 57,
      "z": 10,
      "name": "Soil_Snow"
    },
    {
      "x": -18,
      "y": 40,
      "z": 11,
      "name": "Rock_Ice_Permafrost"
    },
    {
      "x": -18,
      "y": 41,
      "z": 11,
      "name": "Rock_Ice_Permafrost"
    },
    {
      "x": -18,
      "y": 42,
      "z": 11,
      "name": "Rock_Ice_Permafrost"
    },
    {
      "x": -18,
      "y": 43,
      "z": 11,
      "name": "Rock_Ice"
    },
    {
      "x": -18,
      "y": 44,
      "z": 11,
      "name": "Rock_Ice"
    },
    {
      "x": -18,
      "y": 45,
      "z": 11,
      "name": "Rock_Ice"
    },
    {
      "x": -18,
      "y": 46,
      "z": 11,
      "name": "Rock_Ice"
    },
    {
      "x": -18,
      "y": 47,
      "z": 11,
      "name": "Rock_Ice"
    },
    {
      "x": -18,
      "y": 48,
      "z": 11,
      "name": "Rock_Ice"
    },
    {
      "x": -18,
      "y": 49,
      "z": 11,
      "name": "Rock_Ice"
    },
    {
      "x": -18,
      "y": 50,
      "z": 11,
      "name": "Rock_Ice"
    },
    {
      "x": -18,
      "y": 51,
      "z": 11,
      "name": "Rock_Ice"
    },
    {
      "x": -18,
      "y": 52,
      "z": 11,
      "name": "Rock_Ice"
    },
    {
      "x": -18,
      "y": 53,
      "z": 11,
      "name": "Rock_Ice"
    },
    {
      "x": -18,
      "y": 54,
      "z": 11,
      "name": "Rock_Ice"
    },
    {
      "x": -18,
      "y": 55,
      "z": 11,
      "name": "Rock_Ice"
    },
    {
      "x": -18,
      "y": 56,
      "z": 11,
      "name": "Rock_Ice"
    },
    {
      "x": -18,
      "y": 57,
      "z": 11,
      "name": "Soil_Snow"
    },
    {
      "x": -18,
      "y": 40,
      "z": 12,
      "name": "Rock_Ice_Permafrost"
    },
    {
      "x": -18,
      "y": 41,
      "z": 12,
      "name": "Rock_Ice_Permafrost"
    },
    {
      "x": -18,
      "y": 42,
      "z": 12,
      "name": "Rock_Ice_Permafrost"
    },
    {
      "x": -18,
      "y": 43,
      "z": 12,
      "name": "Rock_Ice"
    },
    {
      "x": -18,
      "y": 44,
      "z": 12,
      "name": "Rock_Ice"
    },
    {
      "x": -18,
      "y": 45,
      "z": 12,
      "name": "Rock_Ice"
    },
    {
      "x": -18,
      "y": 46,
      "z": 12,
      "name": "Rock_Ice"
    },
    {
      "x": -18,
      "y": 47,
      "z": 12,
      "name": "Rock_Ice"
    },
    {
      "x": -18,
      "y": 48,
      "z": 12,
      "name": "Rock_Ice"
    },
    {
      "x": -18,
      "y": 49,
      "z": 12,
      "name": "Rock_Ice"
    },
    {
      "x": -18,
      "y": 50,
      "z": 12,
      "name": "Rock_Ice"
    },
    {
      "x": -18,
      "y": 51,
      "z": 12,
      "name": "Rock_Ice"
    },
    {
      "x": -18,
      "y": 52,
      "z": 12,
      "name": "Rock_Ice"
    },
    {
      "x": -18,
      "y": 53,
      "z": 12,
      "name": "Rock_Ice"
    },
    {
      "x": -18,
      "y": 54,
      "z": 12,
      "name": "Rock_Ice"
    },
    {
      "x": -18,
      "y": 55,
      "z": 12,
      "name": "Rock_Ice"
    },
    {
      "x": -18,
      "y": 56,
      "z": 12,
      "name": "Rock_Ice"
    },
    {
      "x": -18,
      "y": 57,
      "z": 12,
      "name": "Rock_Ice"
    },
    {
      "x": -18,
      "y": 40,
      "z": 13,
      "name": "Rock_Ice"
    },
    {
      "x": -18,
      "y": 41,
      "z": 13,
      "name": "Rock_Ice_Permafrost"
    },
    {
      "x": -18,
      "y": 42,
      "z": 13,
      "name": "Rock_Ice"
    },
    {
      "x": -18,
      "y": 43,
      "z": 13,
      "name": "Rock_Ice"
    },
    {
      "x": -18,
      "y": 44,
      "z": 13,
      "name": "Rock_Ice"
    },
    {
      "x": -18,
      "y": 45,
      "z": 13,
      "name": "Rock_Ice"
    },
    {
      "x": -18,
      "y": 46,
      "z": 13,
      "name": "Rock_Ice"
    },
    {
      "x": -18,
      "y": 47,
      "z": 13,
      "name": "Rock_Ice"
    },
    {
      "x": -18,
      "y": 48,
      "z": 13,
      "name": "Rock_Ice"
    },
    {
      "x": -18,
      "y": 49,
      "z": 13,
      "name": "Rock_Ice"
    },
    {
      "x": -18,
      "y": 50,
      "z": 13,
      "name": "Rock_Ice"
    },
    {
      "x": -18,
      "y": 51,
      "z": 13,
      "name": "Rock_Ice"
    },
    {
      "x": -18,
      "y": 52,
      "z": 13,
      "name": "Rock_Ice"
    },
    {
      "x": -18,
      "y": 53,
      "z": 13,
      "name": "Rock_Ice"
    },
    {
      "x": -18,
      "y": 54,
      "z": 13,
      "name": "Rock_Ice"
    },
    {
      "x": -18,
      "y": 55,
      "z": 13,
      "name": "Rock_Ice"
    },
    {
      "x": -18,
      "y": 56,
      "z": 13,
      "name": "Soil_Snow"
    },
    {
      "x": -18,
      "y": 41,
      "z": 14,
      "name": "Rock_Ice"
    },
    {
      "x": -18,
      "y": 42,
      "z": 14,
      "name": "Rock_Ice"
    },
    {
      "x": -18,
      "y": 43,
      "z": 14,
      "name": "Rock_Ice"
    },
    {
      "x": -18,
      "y": 44,
      "z": 14,
      "name": "Rock_Ice"
    },
    {
      "x": -18,
      "y": 45,
      "z": 14,
      "name": "Rock_Ice"
    },
    {
      "x": -18,
      "y": 46,
      "z": 14,
      "name": "Rock_Ice"
    },
    {
      "x": -18,
      "y": 47,
      "z": 14,
      "name": "Rock_Ice"
    },
    {
      "x": -18,
      "y": 48,
      "z": 14,
      "name": "Rock_Ice"
    },
    {
      "x": -18,
      "y": 49,
      "z": 14,
      "name": "Rock_Ice"
    },
    {
      "x": -18,
      "y": 50,
      "z": 14,
      "name": "Rock_Ice"
    },
    {
      "x": -18,
      "y": 51,
      "z": 14,
      "name": "Rock_Ice"
    },
    {
      "x": -18,
      "y": 52,
      "z": 14,
      "name": "Rock_Ice"
    },
    {
      "x": -18,
      "y": 53,
      "z": 14,
      "name": "Rock_Ice"
    },
    {
      "x": -18,
      "y": 54,
      "z": 14,
      "name": "Rock_Ice"
    },
    {
      "x": -18,
      "y": 55,
      "z": 14,
      "name": "Soil_Snow"
    },
    {
      "x": -18,
      "y": 42,
      "z": 15,
      "name": "Rock_Ice"
    },
    {
      "x": -18,
      "y": 43,
      "z": 15,
      "name": "Rock_Ice"
    },
    {
      "x": -18,
      "y": 44,
      "z": 15,
      "name": "Rock_Ice"
    },
    {
      "x": -18,
      "y": 45,
      "z": 15,
      "name": "Rock_Ice"
    },
    {
      "x": -18,
      "y": 46,
      "z": 15,
      "name": "Rock_Ice"
    },
    {
      "x": -18,
      "y": 47,
      "z": 15,
      "name": "Rock_Ice"
    },
    {
      "x": -18,
      "y": 48,
      "z": 15,
      "name": "Rock_Ice"
    },
    {
      "x": -18,
      "y": 49,
      "z": 15,
      "name": "Rock_Ice"
    },
    {
      "x": -18,
      "y": 50,
      "z": 15,
      "name": "Rock_Ice"
    },
    {
      "x": -18,
      "y": 51,
      "z": 15,
      "name": "Rock_Ice"
    },
    {
      "x": -18,
      "y": 52,
      "z": 15,
      "name": "Rock_Ice"
    },
    {
      "x": -18,
      "y": 53,
      "z": 15,
      "name": "Rock_Ice"
    },
    {
      "x": -18,
      "y": 54,
      "z": 15,
      "name": "Soil_Snow"
    },
    {
      "x": -18,
      "y": 42,
      "z": 16,
      "name": "Rock_Ice"
    },
    {
      "x": -18,
      "y": 43,
      "z": 16,
      "name": "Rock_Ice"
    },
    {
      "x": -18,
      "y": 44,
      "z": 16,
      "name": "Rock_Ice"
    },
    {
      "x": -18,
      "y": 45,
      "z": 16,
      "name": "Rock_Ice"
    },
    {
      "x": -18,
      "y": 46,
      "z": 16,
      "name": "Rock_Ice"
    },
    {
      "x": -18,
      "y": 47,
      "z": 16,
      "name": "Rock_Ice"
    },
    {
      "x": -18,
      "y": 48,
      "z": 16,
      "name": "Rock_Ice"
    },
    {
      "x": -18,
      "y": 49,
      "z": 16,
      "name": "Rock_Ice"
    },
    {
      "x": -18,
      "y": 50,
      "z": 16,
      "name": "Rock_Ice"
    },
    {
      "x": -18,
      "y": 51,
      "z": 16,
      "name": "Rock_Ice"
    },
    {
      "x": -18,
      "y": 52,
      "z": 16,
      "name": "Rock_Ice"
    },
    {
      "x": -18,
      "y": 53,
      "z": 16,
      "name": "Soil_Snow"
    },
    {
      "x": -18,
      "y": 43,
      "z": 17,
      "name": "Rock_Ice"
    },
    {
      "x": -18,
      "y": 44,
      "z": 17,
      "name": "Rock_Ice"
    },
    {
      "x": -18,
      "y": 45,
      "z": 17,
      "name": "Rock_Ice"
    },
    {
      "x": -18,
      "y": 46,
      "z": 17,
      "name": "Rock_Ice"
    },
    {
      "x": -18,
      "y": 47,
      "z": 17,
      "name": "Rock_Ice"
    },
    {
      "x": -18,
      "y": 48,
      "z": 17,
      "name": "Rock_Ice"
    },
    {
      "x": -18,
      "y": 49,
      "z": 17,
      "name": "Rock_Ice"
    },
    {
      "x": -18,
      "y": 50,
      "z": 17,
      "name": "Rock_Ice"
    },
    {
      "x": -18,
      "y": 51,
      "z": 17,
      "name": "Soil_Snow"
    },
    {
      "x": -18,
      "y": 44,
      "z": 18,
      "name": "Rock_Ice"
    },
    {
      "x": -18,
      "y": 45,
      "z": 18,
      "name": "Rock_Ice"
    },
    {
      "x": -18,
      "y": 46,
      "z": 18,
      "name": "Rock_Ice"
    },
    {
      "x": -18,
      "y": 47,
      "z": 18,
      "name": "Rock_Ice"
    },
    {
      "x": -18,
      "y": 48,
      "z": 18,
      "name": "Rock_Ice"
    },
    {
      "x": -18,
      "y": 49,
      "z": 18,
      "name": "Soil_Snow"
    },
    {
      "x": -18,
      "y": 45,
      "z": 19,
      "name": "Rock_Ice"
    },
    {
      "x": -18,
      "y": 46,
      "z": 19,
      "name": "Rock_Ice"
    },
    {
      "x": -18,
      "y": 47,
      "z": 19,
      "name": "Soil_Snow"
    },
    {
      "x": -17,
      "y": 37,
      "z": 3,
      "name": "Rock_Ice_Permafrost"
    },
    {
      "x": -17,
      "y": 38,
      "z": 3,
      "name": "Rock_Ice_Permafrost"
    },
    {
      "x": -17,
      "y": 39,
      "z": 3,
      "name": "Rock_Ice_Permafrost"
    },
    {
      "x": -17,
      "y": 40,
      "z": 3,
      "name": "Rock_Ice_Permafrost"
    },
    {
      "x": -17,
      "y": 41,
      "z": 3,
      "name": "Rock_Ice_Permafrost"
    },
    {
      "x": -17,
      "y": 42,
      "z": 3,
      "name": "Rock_Ice_Permafrost"
    },
    {
      "x": -17,
      "y": 43,
      "z": 3,
      "name": "Rock_Ice_Permafrost"
    },
    {
      "x": -17,
      "y": 44,
      "z": 3,
      "name": "Rock_Ice_Permafrost"
    },
    {
      "x": -17,
      "y": 45,
      "z": 3,
      "name": "Rock_Ice_Permafrost"
    },
    {
      "x": -17,
      "y": 46,
      "z": 3,
      "name": "Rock_Ice_Permafrost"
    },
    {
      "x": -17,
      "y": 47,
      "z": 3,
      "name": "Rock_Ice_Permafrost"
    },
    {
      "x": -17,
      "y": 48,
      "z": 3,
      "name": "Rock_Ice_Permafrost"
    },
    {
      "x": -17,
      "y": 49,
      "z": 3,
      "name": "Rock_Ice_Permafrost"
    },
    {
      "x": -17,
      "y": 50,
      "z": 3,
      "name": "Rock_Ice_Permafrost"
    },
    {
      "x": -17,
      "y": 55,
      "z": 3,
      "name": "Rock_Ice_Permafrost"
    },
    {
      "x": -17,
      "y": 56,
      "z": 3,
      "name": "Rock_Ice"
    },
    {
      "x": -17,
      "y": 57,
      "z": 3,
      "name": "Soil_Snow"
    },
    {
      "x": -17,
      "y": 34,
      "z": 4,
      "name": "Rock_Ice_Permafrost"
    },
    {
      "x": -17,
      "y": 35,
      "z": 4,
      "name": "Rock_Ice_Permafrost"
    },
    {
      "x": -17,
      "y": 36,
      "z": 4,
      "name": "Rock_Ice_Permafrost"
    },
    {
      "x": -17,
      "y": 37,
      "z": 4,
      "name": "Rock_Ice_Permafrost"
    },
    {
      "x": -17,
      "y": 38,
      "z": 4,
      "name": "Rock_Ice_Permafrost"
    },
    {
      "x": -17,
      "y": 39,
      "z": 4,
      "name": "Rock_Ice_Permafrost"
    },
    {
      "x": -17,
      "y": 40,
      "z": 4,
      "name": "Rock_Ice_Permafrost"
    },
    {
      "x": -17,
      "y": 41,
      "z": 4,
      "name": "Rock_Ice_Permafrost"
    },
    {
      "x": -17,
      "y": 42,
      "z": 4,
      "name": "Rock_Ice_Permafrost"
    },
    {
      "x": -17,
      "y": 43,
      "z": 4,
      "name": "Rock_Ice_Permafrost"
    },
    {
      "x": -17,
      "y": 44,
      "z": 4,
      "name": "Rock_Ice_Permafrost"
    },
    {
      "x": -17,
      "y": 45,
      "z": 4,
      "name": "Rock_Ice_Permafrost"
    },
    {
      "x": -17,
      "y": 46,
      "z": 4,
      "name": "Rock_Ice_Permafrost"
    },
    {
      "x": -17,
      "y": 47,
      "z": 4,
      "name": "Rock_Ice_Permafrost"
    },
    {
      "x": -17,
      "y": 48,
      "z": 4,
      "name": "Rock_Ice_Permafrost"
    },
    {
      "x": -17,
      "y": 49,
      "z": 4,
      "name": "Rock_Ice"
    },
    {
      "x": -17,
      "y": 50,
      "z": 4,
      "name": "Rock_Ice_Permafrost"
    },
    {
      "x": -17,
      "y": 51,
      "z": 4,
      "name": "Rock_Ice_Permafrost"
    },
    {
      "x": -17,
      "y": 52,
      "z": 4,
      "name": "Rock_Ice_Permafrost"
    },
    {
      "x": -17,
      "y": 53,
      "z": 4,
      "name": "Rock_Ice"
    },
    {
      "x": -17,
      "y": 54,
      "z": 4,
      "name": "Rock_Ice_Permafrost"
    },
    {
      "x": -17,
      "y": 55,
      "z": 4,
      "name": "Rock_Ice"
    },
    {
      "x": -17,
      "y": 56,
      "z": 4,
      "name": "Rock_Ice"
    },
    {
      "x": -17,
      "y": 57,
      "z": 4,
      "name": "Rock_Ice"
    },
    {
      "x": -17,
      "y": 58,
      "z": 4,
      "name": "Soil_Snow"
    },
    {
      "x": -17,
      "y": 32,
      "z": 5,
      "name": "Rock_Ice_Permafrost"
    },
    {
      "x": -17,
      "y": 33,
      "z": 5,
      "name": "Rock_Ice_Permafrost"
    },
    {
      "x": -17,
      "y": 34,
      "z": 5,
      "name": "Rock_Ice_Permafrost"
    },
    {
      "x": -17,
      "y": 35,
      "z": 5,
      "name": "Rock_Ice_Permafrost"
    },
    {
      "x": -17,
      "y": 36,
      "z": 5,
      "name": "Rock_Ice_Permafrost"
    },
    {
      "x": -17,
      "y": 37,
      "z": 5,
      "name": "Rock_Ice_Permafrost"
    },
    {
      "x": -17,
      "y": 38,
      "z": 5,
      "name": "Rock_Ice_Permafrost"
    },
    {
      "x": -17,
      "y": 39,
      "z": 5,
      "name": "Rock_Ice_Permafrost"
    },
    {
      "x": -17,
      "y": 40,
      "z": 5,
      "name": "Rock_Ice_Permafrost"
    },
    {
      "x": -17,
      "y": 41,
      "z": 5,
      "name": "Rock_Ice_Permafrost"
    },
    {
      "x": -17,
      "y": 42,
      "z": 5,
      "name": "Rock_Ice_Permafrost"
    },
    {
      "x": -17,
      "y": 43,
      "z": 5,
      "name": "Rock_Ice_Permafrost"
    },
    {
      "x": -17,
      "y": 44,
      "z": 5,
      "name": "Rock_Ice_Permafrost"
    },
    {
      "x": -17,
      "y": 45,
      "z": 5,
      "name": "Rock_Ice_Permafrost"
    },
    {
      "x": -17,
      "y": 46,
      "z": 5,
      "name": "Rock_Ice_Permafrost"
    },
    {
      "x": -17,
      "y": 47,
      "z": 5,
      "name": "Rock_Ice_Permafrost"
    },
    {
      "x": -17,
      "y": 48,
      "z": 5,
      "name": "Rock_Ice_Permafrost"
    },
    {
      "x": -17,
      "y": 49,
      "z": 5,
      "name": "Rock_Ice"
    },
    {
      "x": -17,
      "y": 50,
      "z": 5,
      "name": "Rock_Ice_Permafrost"
    },
    {
      "x": -17,
      "y": 51,
      "z": 5,
      "name": "Rock_Ice_Permafrost"
    },
    {
      "x": -17,
      "y": 52,
      "z": 5,
      "name": "Rock_Ice_Permafrost"
    },
    {
      "x": -17,
      "y": 53,
      "z": 5,
      "name": "Rock_Ice_Permafrost"
    },
    {
      "x": -17,
      "y": 54,
      "z": 5,
      "name": "Rock_Ice_Permafrost"
    },
    {
      "x": -17,
      "y": 55,
      "z": 5,
      "name": "Rock_Ice_Permafrost"
    },
    {
      "x": -17,
      "y": 56,
      "z": 5,
      "name": "Rock_Ice"
    },
    {
      "x": -17,
      "y": 57,
      "z": 5,
      "name": "Rock_Ice"
    },
    {
      "x": -17,
      "y": 58,
      "z": 5,
      "name": "Soil_Snow"
    },
    {
      "x": -17,
      "y": 31,
      "z": 6,
      "name": "Rock_Ice_Permafrost"
    },
    {
      "x": -17,
      "y": 32,
      "z": 6,
      "name": "Rock_Ice_Permafrost"
    },
    {
      "x": -17,
      "y": 33,
      "z": 6,
      "name": "Rock_Ice_Permafrost"
    },
    {
      "x": -17,
      "y": 34,
      "z": 6,
      "name": "Rock_Ice_Permafrost"
    },
    {
      "x": -17,
      "y": 35,
      "z": 6,
      "name": "Rock_Ice_Permafrost"
    },
    {
      "x": -17,
      "y": 36,
      "z": 6,
      "name": "Rock_Ice_Permafrost"
    },
    {
      "x": -17,
      "y": 37,
      "z": 6,
      "name": "Rock_Ice_Permafrost"
    },
    {
      "x": -17,
      "y": 38,
      "z": 6,
      "name": "Rock_Ice_Permafrost"
    },
    {
      "x": -17,
      "y": 39,
      "z": 6,
      "name": "Rock_Ice_Permafrost"
    },
    {
      "x": -17,
      "y": 40,
      "z": 6,
      "name": "Rock_Ice_Permafrost"
    },
    {
      "x": -17,
      "y": 41,
      "z": 6,
      "name": "Rock_Ice_Permafrost"
    },
    {
      "x": -17,
      "y": 42,
      "z": 6,
      "name": "Rock_Ice_Permafrost"
    },
    {
      "x": -17,
      "y": 43,
      "z": 6,
      "name": "Rock_Ice_Permafrost"
    },
    {
      "x": -17,
      "y": 44,
      "z": 6,
      "name": "Rock_Ice_Permafrost"
    },
    {
      "x": -17,
      "y": 45,
      "z": 6,
      "name": "Rock_Ice_Permafrost"
    },
    {
      "x": -17,
      "y": 46,
      "z": 6,
      "name": "Rock_Ice_Permafrost"
    },
    {
      "x": -17,
      "y": 47,
      "z": 6,
      "name": "Rock_Ice_Permafrost"
    },
    {
      "x": -17,
      "y": 48,
      "z": 6,
      "name": "Rock_Ice_Permafrost"
    },
    {
      "x": -17,
      "y": 49,
      "z": 6,
      "name": "Rock_Ice_Permafrost"
    },
    {
      "x": -17,
      "y": 50,
      "z": 6,
      "name": "Rock_Ice_Permafrost"
    },
    {
      "x": -17,
      "y": 51,
      "z": 6,
      "name": "Rock_Ice_Permafrost"
    },
    {
      "x": -17,
      "y": 52,
      "z": 6,
      "name": "Rock_Ice_Permafrost"
    },
    {
      "x": -17,
      "y": 53,
      "z": 6,
      "name": "Rock_Ice"
    },
    {
      "x": -17,
      "y": 54,
      "z": 6,
      "name": "Rock_Ice"
    },
    {
      "x": -17,
      "y": 55,
      "z": 6,
      "name": "Rock_Ice_Permafrost"
    },
    {
      "x": -17,
      "y": 56,
      "z": 6,
      "name": "Rock_Ice_Permafrost"
    },
    {
      "x": -17,
      "y": 57,
      "z": 6,
      "name": "Rock_Ice"
    },
    {
      "x": -17,
      "y": 58,
      "z": 6,
      "name": "Rock_Ice"
    },
    {
      "x": -17,
      "y": 59,
      "z": 6,
      "name": "Rock_Ice"
    },
    {
      "x": -17,
      "y": 30,
      "z": 7,
      "name": "Rock_Ice_Permafrost"
    },
    {
      "x": -17,
      "y": 31,
      "z": 7,
      "name": "Rock_Ice_Permafrost"
    },
    {
      "x": -17,
      "y": 32,
      "z": 7,
      "name": "Rock_Ice_Permafrost"
    },
    {
      "x": -17,
      "y": 33,
      "z": 7,
      "name": "Rock_Ice_Permafrost"
    },
    {
      "x": -17,
      "y": 34,
      "z": 7,
      "name": "Rock_Ice_Permafrost"
    },
    {
      "x": -17,
      "y": 35,
      "z": 7,
      "name": "Rock_Ice_Permafrost"
    },
    {
      "x": -17,
      "y": 36,
      "z": 7,
      "name": "Rock_Ice_Permafrost"
    },
    {
      "x": -17,
      "y": 37,
      "z": 7,
      "name": "Rock_Ice_Permafrost"
    },
    {
      "x": -17,
      "y": 38,
      "z": 7,
      "name": "Rock_Ice_Permafrost"
    },
    {
      "x": -17,
      "y": 39,
      "z": 7,
      "name": "Rock_Ice_Permafrost"
    },
    {
      "x": -17,
      "y": 40,
      "z": 7,
      "name": "Rock_Ice_Permafrost"
    },
    {
      "x": -17,
      "y": 41,
      "z": 7,
      "name": "Rock_Ice_Permafrost"
    },
    {
      "x": -17,
      "y": 42,
      "z": 7,
      "name": "Rock_Ice_Permafrost"
    },
    {
      "x": -17,
      "y": 43,
      "z": 7,
      "name": "Rock_Ice_Permafrost"
    },
    {
      "x": -17,
      "y": 44,
      "z": 7,
      "name": "Rock_Ice_Permafrost"
    },
    {
      "x": -17,
      "y": 45,
      "z": 7,
      "name": "Rock_Ice_Permafrost"
    },
    {
      "x": -17,
      "y": 46,
      "z": 7,
      "name": "Rock_Ice_Permafrost"
    },
    {
      "x": -17,
      "y": 47,
      "z": 7,
      "name": "Rock_Ice_Permafrost"
    },
    {
      "x": -17,
      "y": 48,
      "z": 7,
      "name": "Rock_Ice_Permafrost"
    },
    {
      "x": -17,
      "y": 49,
      "z": 7,
      "name": "Rock_Ice"
    },
    {
      "x": -17,
      "y": 50,
      "z": 7,
      "name": "Rock_Ice_Permafrost"
    },
    {
      "x": -17,
      "y": 51,
      "z": 7,
      "name": "Rock_Ice"
    },
    {
      "x": -17,
      "y": 52,
      "z": 7,
      "name": "Rock_Ice"
    },
    {
      "x": -17,
      "y": 53,
      "z": 7,
      "name": "Rock_Ice"
    },
    {
      "x": -17,
      "y": 54,
      "z": 7,
      "name": "Rock_Ice"
    },
    {
      "x": -17,
      "y": 55,
      "z": 7,
      "name": "Rock_Ice"
    },
    {
      "x": -17,
      "y": 56,
      "z": 7,
      "name": "Rock_Ice"
    },
    {
      "x": -17,
      "y": 57,
      "z": 7,
      "name": "Rock_Ice"
    },
    {
      "x": -17,
      "y": 58,
      "z": 7,
      "name": "Rock_Ice"
    },
    {
      "x": -17,
      "y": 59,
      "z": 7,
      "name": "Rock_Ice"
    },
    {
      "x": -17,
      "y": 30,
      "z": 8,
      "name": "Rock_Ice_Permafrost"
    },
    {
      "x": -17,
      "y": 31,
      "z": 8,
      "name": "Rock_Ice_Permafrost"
    },
    {
      "x": -17,
      "y": 32,
      "z": 8,
      "name": "Rock_Ice_Permafrost"
    },
    {
      "x": -17,
      "y": 33,
      "z": 8,
      "name": "Rock_Ice_Permafrost"
    },
    {
      "x": -17,
      "y": 34,
      "z": 8,
      "name": "Rock_Ice_Permafrost"
    },
    {
      "x": -17,
      "y": 35,
      "z": 8,
      "name": "Rock_Ice_Permafrost"
    },
    {
      "x": -17,
      "y": 36,
      "z": 8,
      "name": "Rock_Ice_Permafrost"
    },
    {
      "x": -17,
      "y": 37,
      "z": 8,
      "name": "Rock_Ice_Permafrost"
    },
    {
      "x": -17,
      "y": 38,
      "z": 8,
      "name": "Rock_Ice_Permafrost"
    },
    {
      "x": -17,
      "y": 39,
      "z": 8,
      "name": "Rock_Ice_Permafrost"
    },
    {
      "x": -17,
      "y": 40,
      "z": 8,
      "name": "Rock_Ice_Permafrost"
    },
    {
      "x": -17,
      "y": 41,
      "z": 8,
      "name": "Rock_Ice_Permafrost"
    },
    {
      "x": -17,
      "y": 42,
      "z": 8,
      "name": "Rock_Ice_Permafrost"
    },
    {
      "x": -17,
      "y": 43,
      "z": 8,
      "name": "Rock_Ice_Permafrost"
    },
    {
      "x": -17,
      "y": 44,
      "z": 8,
      "name": "Rock_Ice_Permafrost"
    },
    {
      "x": -17,
      "y": 45,
      "z": 8,
      "name": "Rock_Ice_Permafrost"
    },
    {
      "x": -17,
      "y": 46,
      "z": 8,
      "name": "Rock_Ice_Permafrost"
    },
    {
      "x": -17,
      "y": 47,
      "z": 8,
      "name": "Rock_Ice_Permafrost"
    },
    {
      "x": -17,
      "y": 48,
      "z": 8,
      "name": "Rock_Ice"
    },
    {
      "x": -17,
      "y": 49,
      "z": 8,
      "name": "Rock_Ice"
    },
    {
      "x": -17,
      "y": 50,
      "z": 8,
      "name": "Rock_Ice"
    },
    {
      "x": -17,
      "y": 51,
      "z": 8,
      "name": "Rock_Ice"
    },
    {
      "x": -17,
      "y": 52,
      "z": 8,
      "name": "Rock_Ice"
    },
    {
      "x": -17,
      "y": 53,
      "z": 8,
      "name": "Rock_Ice"
    },
    {
      "x": -17,
      "y": 54,
      "z": 8,
      "name": "Rock_Ice"
    },
    {
      "x": -17,
      "y": 55,
      "z": 8,
      "name": "Rock_Ice"
    },
    {
      "x": -17,
      "y": 56,
      "z": 8,
      "name": "Rock_Ice"
    },
    {
      "x": -17,
      "y": 57,
      "z": 8,
      "name": "Rock_Ice"
    },
    {
      "x": -17,
      "y": 58,
      "z": 8,
      "name": "Rock_Ice"
    },
    {
      "x": -17,
      "y": 59,
      "z": 8,
      "name": "Rock_Ice"
    },
    {
      "x": -17,
      "y": 30,
      "z": 9,
      "name": "Rock_Ice_Permafrost"
    },
    {
      "x": -17,
      "y": 31,
      "z": 9,
      "name": "Rock_Ice_Permafrost"
    },
    {
      "x": -17,
      "y": 32,
      "z": 9,
      "name": "Rock_Ice_Permafrost"
    },
    {
      "x": -17,
      "y": 33,
      "z": 9,
      "name": "Rock_Ice_Permafrost"
    },
    {
      "x": -17,
      "y": 34,
      "z": 9,
      "name": "Rock_Ice_Permafrost"
    },
    {
      "x": -17,
      "y": 35,
      "z": 9,
      "name": "Rock_Ice_Permafrost"
    },
    {
      "x": -17,
      "y": 36,
      "z": 9,
      "name": "Rock_Ice_Permafrost"
    },
    {
      "x": -17,
      "y": 37,
      "z": 9,
      "name": "Rock_Ice_Permafrost"
    },
    {
      "x": -17,
      "y": 38,
      "z": 9,
      "name": "Rock_Ice_Permafrost"
    },
    {
      "x": -17,
      "y": 39,
      "z": 9,
      "name": "Rock_Ice_Permafrost"
    },
    {
      "x": -17,
      "y": 40,
      "z": 9,
      "name": "Rock_Ice_Permafrost"
    },
    {
      "x": -17,
      "y": 41,
      "z": 9,
      "name": "Rock_Ice_Permafrost"
    },
    {
      "x": -17,
      "y": 42,
      "z": 9,
      "name": "Rock_Ice_Permafrost"
    },
    {
      "x": -17,
      "y": 43,
      "z": 9,
      "name": "Rock_Ice_Permafrost"
    },
    {
      "x": -17,
      "y": 44,
      "z": 9,
      "name": "Rock_Ice_Permafrost"
    },
    {
      "x": -17,
      "y": 45,
      "z": 9,
      "name": "Rock_Ice_Permafrost"
    },
    {
      "x": -17,
      "y": 46,
      "z": 9,
      "name": "Rock_Ice_Permafrost"
    },
    {
      "x": -17,
      "y": 47,
      "z": 9,
      "name": "Rock_Ice"
    },
    {
      "x": -17,
      "y": 48,
      "z": 9,
      "name": "Rock_Ice"
    },
    {
      "x": -17,
      "y": 49,
      "z": 9,
      "name": "Rock_Ice"
    },
    {
      "x": -17,
      "y": 50,
      "z": 9,
      "name": "Rock_Ice"
    },
    {
      "x": -17,
      "y": 51,
      "z": 9,
      "name": "Rock_Ice_Permafrost"
    },
    {
      "x": -17,
      "y": 52,
      "z": 9,
      "name": "Rock_Ice"
    },
    {
      "x": -17,
      "y": 53,
      "z": 9,
      "name": "Rock_Ice"
    },
    {
      "x": -17,
      "y": 54,
      "z": 9,
      "name": "Rock_Ice"
    },
    {
      "x": -17,
      "y": 55,
      "z": 9,
      "name": "Rock_Ice"
    },
    {
      "x": -17,
      "y": 56,
      "z": 9,
      "name": "Rock_Ice"
    },
    {
      "x": -17,
      "y": 57,
      "z": 9,
      "name": "Rock_Ice"
    },
    {
      "x": -17,
      "y": 58,
      "z": 9,
      "name": "Rock_Ice"
    },
    {
      "x": -17,
      "y": 59,
      "z": 9,
      "name": "Rock_Ice"
    },
    {
      "x": -17,
      "y": 30,
      "z": 10,
      "name": "Rock_Ice_Permafrost"
    },
    {
      "x": -17,
      "y": 31,
      "z": 10,
      "name": "Rock_Ice_Permafrost"
    },
    {
      "x": -17,
      "y": 32,
      "z": 10,
      "name": "Rock_Ice_Permafrost"
    },
    {
      "x": -17,
      "y": 33,
      "z": 10,
      "name": "Rock_Ice_Permafrost"
    },
    {
      "x": -17,
      "y": 34,
      "z": 10,
      "name": "Rock_Ice_Permafrost"
    },
    {
      "x": -17,
      "y": 35,
      "z": 10,
      "name": "Rock_Ice_Permafrost"
    },
    {
      "x": -17,
      "y": 36,
      "z": 10,
      "name": "Rock_Ice_Permafrost"
    },
    {
      "x": -17,
      "y": 37,
      "z": 10,
      "name": "Rock_Ice_Permafrost"
    },
    {
      "x": -17,
      "y": 38,
      "z": 10,
      "name": "Rock_Ice_Permafrost"
    },
    {
      "x": -17,
      "y": 39,
      "z": 10,
      "name": "Rock_Ice_Permafrost"
    },
    {
      "x": -17,
      "y": 40,
      "z": 10,
      "name": "Rock_Ice_Permafrost"
    },
    {
      "x": -17,
      "y": 41,
      "z": 10,
      "name": "Rock_Ice_Permafrost"
    },
    {
      "x": -17,
      "y": 42,
      "z": 10,
      "name": "Rock_Ice_Permafrost"
    },
    {
      "x": -17,
      "y": 43,
      "z": 10,
      "name": "Rock_Ice_Permafrost"
    },
    {
      "x": -17,
      "y": 44,
      "z": 10,
      "name": "Rock_Ice_Permafrost"
    },
    {
      "x": -17,
      "y": 45,
      "z": 10,
      "name": "Rock_Ice_Permafrost"
    },
    {
      "x": -17,
      "y": 46,
      "z": 10,
      "name": "Rock_Ice_Permafrost"
    },
    {
      "x": -17,
      "y": 47,
      "z": 10,
      "name": "Rock_Ice"
    },
    {
      "x": -17,
      "y": 48,
      "z": 10,
      "name": "Rock_Ice"
    },
    {
      "x": -17,
      "y": 49,
      "z": 10,
      "name": "Rock_Ice"
    },
    {
      "x": -17,
      "y": 50,
      "z": 10,
      "name": "Rock_Ice"
    },
    {
      "x": -17,
      "y": 51,
      "z": 10,
      "name": "Rock_Ice"
    },
    {
      "x": -17,
      "y": 52,
      "z": 10,
      "name": "Rock_Ice"
    },
    {
      "x": -17,
      "y": 53,
      "z": 10,
      "name": "Rock_Ice"
    },
    {
      "x": -17,
      "y": 54,
      "z": 10,
      "name": "Rock_Ice"
    },
    {
      "x": -17,
      "y": 55,
      "z": 10,
      "name": "Rock_Ice"
    },
    {
      "x": -17,
      "y": 56,
      "z": 10,
      "name": "Rock_Ice"
    },
    {
      "x": -17,
      "y": 57,
      "z": 10,
      "name": "Rock_Ice"
    },
    {
      "x": -17,
      "y": 58,
      "z": 10,
      "name": "Rock_Ice"
    },
    {
      "x": -17,
      "y": 59,
      "z": 10,
      "name": "Rock_Ice"
    },
    {
      "x": -17,
      "y": 30,
      "z": 11,
      "name": "Rock_Ice_Permafrost"
    },
    {
      "x": -17,
      "y": 31,
      "z": 11,
      "name": "Rock_Ice_Permafrost"
    },
    {
      "x": -17,
      "y": 32,
      "z": 11,
      "name": "Rock_Ice_Permafrost"
    },
    {
      "x": -17,
      "y": 33,
      "z": 11,
      "name": "Rock_Ice_Permafrost"
    },
    {
      "x": -17,
      "y": 34,
      "z": 11,
      "name": "Rock_Ice_Permafrost"
    },
    {
      "x": -17,
      "y": 35,
      "z": 11,
      "name": "Rock_Ice_Permafrost"
    },
    {
      "x": -17,
      "y": 36,
      "z": 11,
      "name": "Rock_Ice_Permafrost"
    },
    {
      "x": -17,
      "y": 37,
      "z": 11,
      "name": "Rock_Ice_Permafrost"
    },
    {
      "x": -17,
      "y": 38,
      "z": 11,
      "name": "Rock_Ice_Permafrost"
    },
    {
      "x": -17,
      "y": 39,
      "z": 11,
      "name": "Rock_Ice_Permafrost"
    },
    {
      "x": -17,
      "y": 40,
      "z": 11,
      "name": "Rock_Ice_Permafrost"
    },
    {
      "x": -17,
      "y": 41,
      "z": 11,
      "name": "Rock_Ice_Permafrost"
    },
    {
      "x": -17,
      "y": 42,
      "z": 11,
      "name": "Rock_Ice_Permafrost"
    },
    {
      "x": -17,
      "y": 43,
      "z": 11,
      "name": "Rock_Ice_Permafrost"
    },
    {
      "x": -17,
      "y": 44,
      "z": 11,
      "name": "Rock_Ice_Permafrost"
    },
    {
      "x": -17,
      "y": 45,
      "z": 11,
      "name": "Rock_Ice_Permafrost"
    },
    {
      "x": -17,
      "y": 46,
      "z": 11,
      "name": "Rock_Ice_Permafrost"
    },
    {
      "x": -17,
      "y": 47,
      "z": 11,
      "name": "Rock_Ice"
    },
    {
      "x": -17,
      "y": 48,
      "z": 11,
      "name": "Rock_Ice"
    },
    {
      "x": -17,
      "y": 49,
      "z": 11,
      "name": "Rock_Ice"
    },
    {
      "x": -17,
      "y": 50,
      "z": 11,
      "name": "Rock_Ice"
    },
    {
      "x": -17,
      "y": 51,
      "z": 11,
      "name": "Rock_Ice"
    },
    {
      "x": -17,
      "y": 52,
      "z": 11,
      "name": "Rock_Ice"
    },
    {
      "x": -17,
      "y": 53,
      "z": 11,
      "name": "Rock_Ice"
    },
    {
      "x": -17,
      "y": 54,
      "z": 11,
      "name": "Rock_Ice"
    },
    {
      "x": -17,
      "y": 55,
      "z": 11,
      "name": "Rock_Ice"
    },
    {
      "x": -17,
      "y": 56,
      "z": 11,
      "name": "Rock_Ice"
    },
    {
      "x": -17,
      "y": 57,
      "z": 11,
      "name": "Rock_Ice"
    },
    {
      "x": -17,
      "y": 58,
      "z": 11,
      "name": "Rock_Ice"
    },
    {
      "x": -17,
      "y": 59,
      "z": 11,
      "name": "Soil_Snow"
    },
    {
      "x": -17,
      "y": 31,
      "z": 12,
      "name": "Rock_Ice_Permafrost"
    },
    {
      "x": -17,
      "y": 32,
      "z": 12,
      "name": "Rock_Ice_Permafrost"
    },
    {
      "x": -17,
      "y": 33,
      "z": 12,
      "name": "Rock_Ice_Permafrost"
    },
    {
      "x": -17,
      "y": 34,
      "z": 12,
      "name": "Rock_Ice_Permafrost"
    },
    {
      "x": -17,
      "y": 35,
      "z": 12,
      "name": "Rock_Ice_Permafrost"
    },
    {
      "x": -17,
      "y": 36,
      "z": 12,
      "name": "Rock_Ice_Permafrost"
    },
    {
      "x": -17,
      "y": 37,
      "z": 12,
      "name": "Rock_Ice_Permafrost"
    },
    {
      "x": -17,
      "y": 38,
      "z": 12,
      "name": "Rock_Ice_Permafrost"
    },
    {
      "x": -17,
      "y": 39,
      "z": 12,
      "name": "Rock_Ice_Permafrost"
    },
    {
      "x": -17,
      "y": 40,
      "z": 12,
      "name": "Rock_Ice_Permafrost"
    },
    {
      "x": -17,
      "y": 41,
      "z": 12,
      "name": "Rock_Ice_Permafrost"
    },
    {
      "x": -17,
      "y": 42,
      "z": 12,
      "name": "Rock_Ice_Permafrost"
    },
    {
      "x": -17,
      "y": 43,
      "z": 12,
      "name": "Rock_Ice"
    },
    {
      "x": -17,
      "y": 44,
      "z": 12,
      "name": "Rock_Ice"
    },
    {
      "x": -17,
      "y": 45,
      "z": 12,
      "name": "Rock_Ice"
    },
    {
      "x": -17,
      "y": 46,
      "z": 12,
      "name": "Rock_Ice"
    },
    {
      "x": -17,
      "y": 47,
      "z": 12,
      "name": "Rock_Ice"
    },
    {
      "x": -17,
      "y": 48,
      "z": 12,
      "name": "Rock_Ice"
    },
    {
      "x": -17,
      "y": 49,
      "z": 12,
      "name": "Rock_Ice"
    },
    {
      "x": -17,
      "y": 50,
      "z": 12,
      "name": "Rock_Ice"
    },
    {
      "x": -17,
      "y": 51,
      "z": 12,
      "name": "Rock_Ice"
    },
    {
      "x": -17,
      "y": 52,
      "z": 12,
      "name": "Rock_Ice"
    },
    {
      "x": -17,
      "y": 53,
      "z": 12,
      "name": "Rock_Ice"
    },
    {
      "x": -17,
      "y": 54,
      "z": 12,
      "name": "Rock_Ice"
    },
    {
      "x": -17,
      "y": 55,
      "z": 12,
      "name": "Rock_Ice"
    },
    {
      "x": -17,
      "y": 56,
      "z": 12,
      "name": "Rock_Ice"
    },
    {
      "x": -17,
      "y": 57,
      "z": 12,
      "name": "Rock_Ice"
    },
    {
      "x": -17,
      "y": 58,
      "z": 12,
      "name": "Rock_Ice"
    },
    {
      "x": -17,
      "y": 59,
      "z": 12,
      "name": "Rock_Ice"
    },
    {
      "x": -17,
      "y": 32,
      "z": 13,
      "name": "Rock_Ice_Permafrost"
    },
    {
      "x": -17,
      "y": 33,
      "z": 13,
      "name": "Rock_Ice_Permafrost"
    },
    {
      "x": -17,
      "y": 34,
      "z": 13,
      "name": "Rock_Ice_Permafrost"
    },
    {
      "x": -17,
      "y": 35,
      "z": 13,
      "name": "Rock_Ice_Permafrost"
    },
    {
      "x": -17,
      "y": 36,
      "z": 13,
      "name": "Rock_Ice_Permafrost"
    },
    {
      "x": -17,
      "y": 37,
      "z": 13,
      "name": "Rock_Ice_Permafrost"
    },
    {
      "x": -17,
      "y": 38,
      "z": 13,
      "name": "Rock_Ice_Permafrost"
    },
    {
      "x": -17,
      "y": 39,
      "z": 13,
      "name": "Rock_Ice_Permafrost"
    },
    {
      "x": -17,
      "y": 40,
      "z": 13,
      "name": "Rock_Ice_Permafrost"
    },
    {
      "x": -17,
      "y": 41,
      "z": 13,
      "name": "Rock_Ice_Permafrost"
    },
    {
      "x": -17,
      "y": 42,
      "z": 13,
      "name": "Rock_Ice_Permafrost"
    },
    {
      "x": -17,
      "y": 43,
      "z": 13,
      "name": "Rock_Ice"
    },
    {
      "x": -17,
      "y": 44,
      "z": 13,
      "name": "Rock_Ice"
    },
    {
      "x": -17,
      "y": 45,
      "z": 13,
      "name": "Rock_Ice"
    },
    {
      "x": -17,
      "y": 46,
      "z": 13,
      "name": "Rock_Ice"
    },
    {
      "x": -17,
      "y": 47,
      "z": 13,
      "name": "Rock_Ice"
    },
    {
      "x": -17,
      "y": 48,
      "z": 13,
      "name": "Rock_Ice"
    },
    {
      "x": -17,
      "y": 49,
      "z": 13,
      "name": "Rock_Ice"
    },
    {
      "x": -17,
      "y": 50,
      "z": 13,
      "name": "Rock_Ice"
    },
    {
      "x": -17,
      "y": 51,
      "z": 13,
      "name": "Rock_Ice"
    },
    {
      "x": -17,
      "y": 52,
      "z": 13,
      "name": "Rock_Ice"
    },
    {
      "x": -17,
      "y": 53,
      "z": 13,
      "name": "Rock_Ice"
    },
    {
      "x": -17,
      "y": 54,
      "z": 13,
      "name": "Rock_Ice"
    },
    {
      "x": -17,
      "y": 55,
      "z": 13,
      "name": "Rock_Ice"
    },
    {
      "x": -17,
      "y": 56,
      "z": 13,
      "name": "Rock_Ice"
    },
    {
      "x": -17,
      "y": 57,
      "z": 13,
      "name": "Rock_Ice"
    },
    {
      "x": -17,
      "y": 58,
      "z": 13,
      "name": "Rock_Ice"
    },
    {
      "x": -17,
      "y": 59,
      "z": 13,
      "name": "Rock_Ice"
    },
    {
      "x": -17,
      "y": 33,
      "z": 14,
      "name": "Rock_Ice_Permafrost"
    },
    {
      "x": -17,
      "y": 34,
      "z": 14,
      "name": "Rock_Ice_Permafrost"
    },
    {
      "x": -17,
      "y": 35,
      "z": 14,
      "name": "Rock_Ice_Permafrost"
    },
    {
      "x": -17,
      "y": 36,
      "z": 14,
      "name": "Rock_Ice_Permafrost"
    },
    {
      "x": -17,
      "y": 37,
      "z": 14,
      "name": "Rock_Ice_Permafrost"
    },
    {
      "x": -17,
      "y": 38,
      "z": 14,
      "name": "Rock_Ice"
    },
    {
      "x": -17,
      "y": 39,
      "z": 14,
      "name": "Rock_Ice_Permafrost"
    },
    {
      "x": -17,
      "y": 40,
      "z": 14,
      "name": "Rock_Ice_Permafrost"
    },
    {
      "x": -17,
      "y": 41,
      "z": 14,
      "name": "Rock_Ice_Permafrost"
    },
    {
      "x": -17,
      "y": 42,
      "z": 14,
      "name": "Rock_Ice"
    },
    {
      "x": -17,
      "y": 43,
      "z": 14,
      "name": "Rock_Ice"
    },
    {
      "x": -17,
      "y": 44,
      "z": 14,
      "name": "Rock_Ice"
    },
    {
      "x": -17,
      "y": 45,
      "z": 14,
      "name": "Rock_Ice"
    },
    {
      "x": -17,
      "y": 46,
      "z": 14,
      "name": "Rock_Ice"
    },
    {
      "x": -17,
      "y": 47,
      "z": 14,
      "name": "Rock_Ice"
    },
    {
      "x": -17,
      "y": 48,
      "z": 14,
      "name": "Rock_Ice"
    },
    {
      "x": -17,
      "y": 49,
      "z": 14,
      "name": "Rock_Ice"
    },
    {
      "x": -17,
      "y": 50,
      "z": 14,
      "name": "Rock_Ice"
    },
    {
      "x": -17,
      "y": 51,
      "z": 14,
      "name": "Rock_Ice"
    },
    {
      "x": -17,
      "y": 52,
      "z": 14,
      "name": "Rock_Ice"
    },
    {
      "x": -17,
      "y": 53,
      "z": 14,
      "name": "Rock_Ice"
    },
    {
      "x": -17,
      "y": 54,
      "z": 14,
      "name": "Rock_Ice"
    },
    {
      "x": -17,
      "y": 55,
      "z": 14,
      "name": "Rock_Ice"
    },
    {
      "x": -17,
      "y": 56,
      "z": 14,
      "name": "Rock_Ice"
    },
    {
      "x": -17,
      "y": 57,
      "z": 14,
      "name": "Rock_Ice"
    },
    {
      "x": -17,
      "y": 58,
      "z": 14,
      "name": "Rock_Ice"
    },
    {
      "x": -17,
      "y": 35,
      "z": 15,
      "name": "Rock_Ice_Permafrost"
    },
    {
      "x": -17,
      "y": 36,
      "z": 15,
      "name": "Rock_Ice_Permafrost"
    },
    {
      "x": -17,
      "y": 37,
      "z": 15,
      "name": "Rock_Ice_Permafrost"
    },
    {
      "x": -17,
      "y": 38,
      "z": 15,
      "name": "Rock_Ice_Permafrost"
    },
    {
      "x": -17,
      "y": 39,
      "z": 15,
      "name": "Rock_Ice_Permafrost"
    },
    {
      "x": -17,
      "y": 40,
      "z": 15,
      "name": "Rock_Ice_Permafrost"
    },
    {
      "x": -17,
      "y": 41,
      "z": 15,
      "name": "Rock_Ice_Permafrost"
    },
    {
      "x": -17,
      "y": 42,
      "z": 15,
      "name": "Rock_Ice"
    },
    {
      "x": -17,
      "y": 43,
      "z": 15,
      "name": "Rock_Ice"
    },
    {
      "x": -17,
      "y": 44,
      "z": 15,
      "name": "Rock_Ice"
    },
    {
      "x": -17,
      "y": 45,
      "z": 15,
      "name": "Rock_Ice"
    },
    {
      "x": -17,
      "y": 46,
      "z": 15,
      "name": "Rock_Ice"
    },
    {
      "x": -17,
      "y": 47,
      "z": 15,
      "name": "Rock_Ice"
    },
    {
      "x": -17,
      "y": 48,
      "z": 15,
      "name": "Rock_Ice"
    },
    {
      "x": -17,
      "y": 49,
      "z": 15,
      "name": "Rock_Ice"
    },
    {
      "x": -17,
      "y": 50,
      "z": 15,
      "name": "Rock_Ice"
    },
    {
      "x": -17,
      "y": 51,
      "z": 15,
      "name": "Rock_Ice"
    },
    {
      "x": -17,
      "y": 52,
      "z": 15,
      "name": "Rock_Ice"
    },
    {
      "x": -17,
      "y": 53,
      "z": 15,
      "name": "Rock_Ice"
    },
    {
      "x": -17,
      "y": 54,
      "z": 15,
      "name": "Rock_Ice"
    },
    {
      "x": -17,
      "y": 55,
      "z": 15,
      "name": "Rock_Ice"
    },
    {
      "x": -17,
      "y": 56,
      "z": 15,
      "name": "Rock_Ice"
    },
    {
      "x": -17,
      "y": 57,
      "z": 15,
      "name": "Soil_Snow"
    },
    {
      "x": -17,
      "y": 36,
      "z": 16,
      "name": "Rock_Ice_Permafrost"
    },
    {
      "x": -17,
      "y": 37,
      "z": 16,
      "name": "Rock_Ice_Permafrost"
    },
    {
      "x": -17,
      "y": 38,
      "z": 16,
      "name": "Rock_Ice_Permafrost"
    },
    {
      "x": -17,
      "y": 39,
      "z": 16,
      "name": "Rock_Ice"
    },
    {
      "x": -17,
      "y": 40,
      "z": 16,
      "name": "Rock_Ice"
    },
    {
      "x": -17,
      "y": 41,
      "z": 16,
      "name": "Rock_Ice"
    },
    {
      "x": -17,
      "y": 42,
      "z": 16,
      "name": "Rock_Ice"
    },
    {
      "x": -17,
      "y": 43,
      "z": 16,
      "name": "Rock_Ice"
    },
    {
      "x": -17,
      "y": 44,
      "z": 16,
      "name": "Rock_Ice"
    },
    {
      "x": -17,
      "y": 45,
      "z": 16,
      "name": "Rock_Ice"
    },
    {
      "x": -17,
      "y": 46,
      "z": 16,
      "name": "Rock_Ice"
    },
    {
      "x": -17,
      "y": 47,
      "z": 16,
      "name": "Rock_Ice"
    },
    {
      "x": -17,
      "y": 48,
      "z": 16,
      "name": "Rock_Ice"
    },
    {
      "x": -17,
      "y": 49,
      "z": 16,
      "name": "Rock_Ice"
    },
    {
      "x": -17,
      "y": 50,
      "z": 16,
      "name": "Rock_Ice"
    },
    {
      "x": -17,
      "y": 51,
      "z": 16,
      "name": "Rock_Ice"
    },
    {
      "x": -17,
      "y": 52,
      "z": 16,
      "name": "Rock_Ice"
    },
    {
      "x": -17,
      "y": 53,
      "z": 16,
      "name": "Rock_Ice"
    },
    {
      "x": -17,
      "y": 54,
      "z": 16,
      "name": "Rock_Ice"
    },
    {
      "x": -17,
      "y": 55,
      "z": 16,
      "name": "Rock_Ice"
    },
    {
      "x": -17,
      "y": 56,
      "z": 16,
      "name": "Rock_Ice"
    },
    {
      "x": -17,
      "y": 57,
      "z": 16,
      "name": "Rock_Ice"
    },
    {
      "x": -17,
      "y": 38,
      "z": 17,
      "name": "Rock_Ice_Permafrost"
    },
    {
      "x": -17,
      "y": 39,
      "z": 17,
      "name": "Rock_Ice"
    },
    {
      "x": -17,
      "y": 40,
      "z": 17,
      "name": "Rock_Ice"
    },
    {
      "x": -17,
      "y": 41,
      "z": 17,
      "name": "Rock_Ice"
    },
    {
      "x": -17,
      "y": 42,
      "z": 17,
      "name": "Rock_Ice"
    },
    {
      "x": -17,
      "y": 43,
      "z": 17,
      "name": "Rock_Ice"
    },
    {
      "x": -17,
      "y": 44,
      "z": 17,
      "name": "Rock_Ice"
    },
    {
      "x": -17,
      "y": 45,
      "z": 17,
      "name": "Rock_Ice"
    },
    {
      "x": -17,
      "y": 46,
      "z": 17,
      "name": "Rock_Ice"
    },
    {
      "x": -17,
      "y": 47,
      "z": 17,
      "name": "Rock_Ice"
    },
    {
      "x": -17,
      "y": 48,
      "z": 17,
      "name": "Rock_Ice"
    },
    {
      "x": -17,
      "y": 49,
      "z": 17,
      "name": "Rock_Ice"
    },
    {
      "x": -17,
      "y": 50,
      "z": 17,
      "name": "Rock_Ice"
    },
    {
      "x": -17,
      "y": 51,
      "z": 17,
      "name": "Rock_Ice"
    },
    {
      "x": -17,
      "y": 52,
      "z": 17,
      "name": "Rock_Ice"
    },
    {
      "x": -17,
      "y": 53,
      "z": 17,
      "name": "Rock_Ice"
    },
    {
      "x": -17,
      "y": 54,
      "z": 17,
      "name": "Rock_Ice"
    },
    {
      "x": -17,
      "y": 55,
      "z": 17,
      "name": "Soil_Snow"
    },
    {
      "x": -17,
      "y": 40,
      "z": 18,
      "name": "Rock_Ice"
    },
    {
      "x": -17,
      "y": 41,
      "z": 18,
      "name": "Rock_Ice"
    },
    {
      "x": -17,
      "y": 42,
      "z": 18,
      "name": "Rock_Ice"
    },
    {
      "x": -17,
      "y": 43,
      "z": 18,
      "name": "Rock_Ice"
    },
    {
      "x": -17,
      "y": 44,
      "z": 18,
      "name": "Rock_Ice"
    },
    {
      "x": -17,
      "y": 45,
      "z": 18,
      "name": "Rock_Ice"
    },
    {
      "x": -17,
      "y": 46,
      "z": 18,
      "name": "Rock_Ice"
    },
    {
      "x": -17,
      "y": 47,
      "z": 18,
      "name": "Rock_Ice"
    },
    {
      "x": -17,
      "y": 48,
      "z": 18,
      "name": "Rock_Ice"
    },
    {
      "x": -17,
      "y": 49,
      "z": 18,
      "name": "Rock_Ice"
    },
    {
      "x": -17,
      "y": 50,
      "z": 18,
      "name": "Rock_Ice"
    },
    {
      "x": -17,
      "y": 51,
      "z": 18,
      "name": "Rock_Ice"
    },
    {
      "x": -17,
      "y": 52,
      "z": 18,
      "name": "Rock_Ice"
    },
    {
      "x": -17,
      "y": 53,
      "z": 18,
      "name": "Rock_Ice"
    },
    {
      "x": -17,
      "y": 54,
      "z": 18,
      "name": "Soil_Snow"
    },
    {
      "x": -17,
      "y": 42,
      "z": 19,
      "name": "Rock_Ice"
    },
    {
      "x": -17,
      "y": 43,
      "z": 19,
      "name": "Rock_Ice"
    },
    {
      "x": -17,
      "y": 44,
      "z": 19,
      "name": "Rock_Ice"
    },
    {
      "x": -17,
      "y": 45,
      "z": 19,
      "name": "Rock_Ice"
    },
    {
      "x": -17,
      "y": 46,
      "z": 19,
      "name": "Rock_Ice"
    },
    {
      "x": -17,
      "y": 47,
      "z": 19,
      "name": "Rock_Ice"
    },
    {
      "x": -17,
      "y": 48,
      "z": 19,
      "name": "Rock_Ice"
    },
    {
      "x": -17,
      "y": 49,
      "z": 19,
      "name": "Rock_Ice"
    },
    {
      "x": -17,
      "y": 50,
      "z": 19,
      "name": "Rock_Ice"
    },
    {
      "x": -17,
      "y": 51,
      "z": 19,
      "name": "Rock_Ice"
    },
    {
      "x": -17,
      "y": 52,
      "z": 19,
      "name": "Soil_Snow"
    },
    {
      "x": -17,
      "y": 44,
      "z": 20,
      "name": "Rock_Ice"
    },
    {
      "x": -17,
      "y": 45,
      "z": 20,
      "name": "Rock_Ice"
    },
    {
      "x": -17,
      "y": 46,
      "z": 20,
      "name": "Rock_Ice"
    },
    {
      "x": -17,
      "y": 47,
      "z": 20,
      "name": "Rock_Ice"
    },
    {
      "x": -17,
      "y": 48,
      "z": 20,
      "name": "Rock_Ice"
    },
    {
      "x": -17,
      "y": 49,
      "z": 20,
      "name": "Rock_Ice"
    },
    {
      "x": -17,
      "y": 50,
      "z": 20,
      "name": "Rock_Ice"
    },
    {
      "x": -17,
      "y": 51,
      "z": 20,
      "name": "Soil_Snow"
    },
    {
      "x": -16,
      "y": 27,
      "z": 0,
      "name": "Rock_Ice"
    },
    {
      "x": -16,
      "y": 28,
      "z": 0,
      "name": "Rock_Ice"
    },
    {
      "x": -16,
      "y": 29,
      "z": 0,
      "name": "Rock_Ice"
    },
    {
      "x": -16,
      "y": 30,
      "z": 0,
      "name": "Rock_Ice"
    },
    {
      "x": -16,
      "y": 31,
      "z": 0,
      "name": "Rock_Ice"
    },
    {
      "x": -16,
      "y": 32,
      "z": 0,
      "name": "Rock_Ice"
    },
    {
      "x": -16,
      "y": 33,
      "z": 0,
      "name": "Soil_Snow"
    },
    {
      "x": -16,
      "y": 55,
      "z": 0,
      "name": "Rock_Ice_Permafrost"
    },
    {
      "x": -16,
      "y": 56,
      "z": 0,
      "name": "Soil_Snow"
    },
    {
      "x": -16,
      "y": 24,
      "z": 1,
      "name": "Rock_Ice"
    },
    {
      "x": -16,
      "y": 25,
      "z": 1,
      "name": "Rock_Ice"
    },
    {
      "x": -16,
      "y": 26,
      "z": 1,
      "name": "Rock_Ice"
    },
    {
      "x": -16,
      "y": 27,
      "z": 1,
      "name": "Rock_Ice"
    },
    {
      "x": -16,
      "y": 28,
      "z": 1,
      "name": "Rock_Ice"
    },
    {
      "x": -16,
      "y": 29,
      "z": 1,
      "name": "Rock_Ice"
    },
    {
      "x": -16,
      "y": 30,
      "z": 1,
      "name": "Rock_Ice"
    },
    {
      "x": -16,
      "y": 31,
      "z": 1,
      "name": "Rock_Ice"
    },
    {
      "x": -16,
      "y": 32,
      "z": 1,
      "name": "Rock_Ice"
    },
    {
      "x": -16,
      "y": 33,
      "z": 1,
      "name": "Rock_Ice"
    },
    {
      "x": -16,
      "y": 34,
      "z": 1,
      "name": "Rock_Ice"
    },
    {
      "x": -16,
      "y": 35,
      "z": 1,
      "name": "Rock_Ice"
    },
    {
      "x": -16,
      "y": 36,
      "z": 1,
      "name": "Rock_Ice"
    },
    {
      "x": -16,
      "y": 37,
      "z": 1,
      "name": "Rock_Ice"
    },
    {
      "x": -16,
      "y": 38,
      "z": 1,
      "name": "Rock_Ice_Permafrost"
    },
    {
      "x": -16,
      "y": 39,
      "z": 1,
      "name": "Rock_Ice"
    },
    {
      "x": -16,
      "y": 40,
      "z": 1,
      "name": "Rock_Ice_Permafrost"
    },
    {
      "x": -16,
      "y": 41,
      "z": 1,
      "name": "Rock_Ice_Permafrost"
    },
    {
      "x": -16,
      "y": 42,
      "z": 1,
      "name": "Rock_Ice_Permafrost"
    },
    {
      "x": -16,
      "y": 43,
      "z": 1,
      "name": "Rock_Ice_Permafrost"
    },
    {
      "x": -16,
      "y": 44,
      "z": 1,
      "name": "Rock_Ice_Permafrost"
    },
    {
      "x": -16,
      "y": 53,
      "z": 1,
      "name": "Rock_Ice_Permafrost"
    },
    {
      "x": -16,
      "y": 54,
      "z": 1,
      "name": "Rock_Ice_Permafrost"
    },
    {
      "x": -16,
      "y": 55,
      "z": 1,
      "name": "Rock_Ice_Permafrost"
    },
    {
      "x": -16,
      "y": 56,
      "z": 1,
      "name": "Rock_Ice"
    },
    {
      "x": -16,
      "y": 57,
      "z": 1,
      "name": "Soil_Snow"
    },
    {
      "x": -16,
      "y": 22,
      "z": 2,
      "name": "Rock_Ice"
    },
    {
      "x": -16,
      "y": 23,
      "z": 2,
      "name": "Rock_Ice"
    },
    {
      "x": -16,
      "y": 24,
      "z": 2,
      "name": "Rock_Ice"
    },
    {
      "x": -16,
      "y": 25,
      "z": 2,
      "name": "Rock_Ice"
    },
    {
      "x": -16,
      "y": 26,
      "z": 2,
      "name": "Rock_Ice"
    },
    {
      "x": -16,
      "y": 27,
      "z": 2,
      "name": "Rock_Ice"
    },
    {
      "x": -16,
      "y": 28,
      "z": 2,
      "name": "Rock_Ice"
    },
    {
      "x": -16,
      "y": 29,
      "z": 2,
      "name": "Rock_Ice"
    },
    {
      "x": -16,
      "y": 30,
      "z": 2,
      "name": "Rock_Ice"
    },
    {
      "x": -16,
      "y": 31,
      "z": 2,
      "name": "Rock_Ice"
    },
    {
      "x": -16,
      "y": 32,
      "z": 2,
      "name": "Rock_Ice"
    },
    {
      "x": -16,
      "y": 33,
      "z": 2,
      "name": "Rock_Ice_Permafrost"
    },
    {
      "x": -16,
      "y": 34,
      "z": 2,
      "name": "Rock_Ice"
    },
    {
      "x": -16,
      "y": 35,
      "z": 2,
      "name": "Rock_Ice"
    },
    {
      "x": -16,
      "y": 36,
      "z": 2,
      "name": "Rock_Ice"
    },
    {
      "x": -16,
      "y": 37,
      "z": 2,
      "name": "Rock_Ice_Permafrost"
    },
    {
      "x": -16,
      "y": 38,
      "z": 2,
      "name": "Rock_Ice"
    },
    {
      "x": -16,
      "y": 39,
      "z": 2,
      "name": "Rock_Ice_Permafrost"
    },
    {
      "x": -16,
      "y": 40,
      "z": 2,
      "name": "Rock_Ice_Permafrost"
    },
    {
      "x": -16,
      "y": 41,
      "z": 2,
      "name": "Rock_Ice_Permafrost"
    },
    {
      "x": -16,
      "y": 42,
      "z": 2,
      "name": "Rock_Ice_Permafrost"
    },
    {
      "x": -16,
      "y": 43,
      "z": 2,
      "name": "Rock_Ice_Permafrost"
    },
    {
      "x": -16,
      "y": 44,
      "z": 2,
      "name": "Rock_Ice_Permafrost"
    },
    {
      "x": -16,
      "y": 45,
      "z": 2,
      "name": "Rock_Ice_Permafrost"
    },
    {
      "x": -16,
      "y": 46,
      "z": 2,
      "name": "Rock_Ice_Permafrost"
    },
    {
      "x": -16,
      "y": 47,
      "z": 2,
      "name": "Rock_Ice_Permafrost"
    },
    {
      "x": -16,
      "y": 48,
      "z": 2,
      "name": "Rock_Ice_Permafrost"
    },
    {
      "x": -16,
      "y": 49,
      "z": 2,
      "name": "Rock_Ice_Permafrost"
    },
    {
      "x": -16,
      "y": 50,
      "z": 2,
      "name": "Rock_Ice_Permafrost"
    },
    {
      "x": -16,
      "y": 51,
      "z": 2,
      "name": "Rock_Ice_Permafrost"
    },
    {
      "x": -16,
      "y": 52,
      "z": 2,
      "name": "Rock_Ice_Permafrost"
    },
    {
      "x": -16,
      "y": 53,
      "z": 2,
      "name": "Rock_Ice_Permafrost"
    },
    {
      "x": -16,
      "y": 54,
      "z": 2,
      "name": "Rock_Ice_Permafrost"
    },
    {
      "x": -16,
      "y": 55,
      "z": 2,
      "name": "Rock_Ice_Permafrost"
    },
    {
      "x": -16,
      "y": 56,
      "z": 2,
      "name": "Rock_Ice_Permafrost"
    },
    {
      "x": -16,
      "y": 57,
      "z": 2,
      "name": "Rock_Ice"
    },
    {
      "x": -16,
      "y": 58,
      "z": 2,
      "name": "Soil_Snow"
    },
    {
      "x": -16,
      "y": 21,
      "z": 3,
      "name": "Rock_Ice"
    },
    {
      "x": -16,
      "y": 22,
      "z": 3,
      "name": "Rock_Ice"
    },
    {
      "x": -16,
      "y": 23,
      "z": 3,
      "name": "Rock_Ice"
    },
    {
      "x": -16,
      "y": 24,
      "z": 3,
      "name": "Rock_Ice"
    },
    {
      "x": -16,
      "y": 25,
      "z": 3,
      "name": "Rock_Ice"
    },
    {
      "x": -16,
      "y": 26,
      "z": 3,
      "name": "Rock_Ice"
    },
    {
      "x": -16,
      "y": 27,
      "z": 3,
      "name": "Rock_Ice"
    },
    {
      "x": -16,
      "y": 28,
      "z": 3,
      "name": "Rock_Ice"
    },
    {
      "x": -16,
      "y": 29,
      "z": 3,
      "name": "Rock_Ice"
    },
    {
      "x": -16,
      "y": 30,
      "z": 3,
      "name": "Rock_Ice"
    },
    {
      "x": -16,
      "y": 31,
      "z": 3,
      "name": "Rock_Ice"
    },
    {
      "x": -16,
      "y": 32,
      "z": 3,
      "name": "Rock_Ice"
    },
    {
      "x": -16,
      "y": 33,
      "z": 3,
      "name": "Rock_Ice"
    },
    {
      "x": -16,
      "y": 34,
      "z": 3,
      "name": "Rock_Ice"
    },
    {
      "x": -16,
      "y": 35,
      "z": 3,
      "name": "Rock_Ice_Permafrost"
    },
    {
      "x": -16,
      "y": 36,
      "z": 3,
      "name": "Rock_Ice_Permafrost"
    },
    {
      "x": -16,
      "y": 37,
      "z": 3,
      "name": "Rock_Ice_Permafrost"
    },
    {
      "x": -16,
      "y": 38,
      "z": 3,
      "name": "Rock_Ice_Permafrost"
    },
    {
      "x": -16,
      "y": 39,
      "z": 3,
      "name": "Rock_Ice_Permafrost"
    },
    {
      "x": -16,
      "y": 40,
      "z": 3,
      "name": "Rock_Ice_Permafrost"
    },
    {
      "x": -16,
      "y": 41,
      "z": 3,
      "name": "Rock_Ice_Permafrost"
    },
    {
      "x": -16,
      "y": 42,
      "z": 3,
      "name": "Rock_Ice_Permafrost"
    },
    {
      "x": -16,
      "y": 43,
      "z": 3,
      "name": "Rock_Ice_Permafrost"
    },
    {
      "x": -16,
      "y": 44,
      "z": 3,
      "name": "Rock_Ice_Permafrost"
    },
    {
      "x": -16,
      "y": 45,
      "z": 3,
      "name": "Rock_Ice_Permafrost"
    },
    {
      "x": -16,
      "y": 46,
      "z": 3,
      "name": "Rock_Ice_Permafrost"
    },
    {
      "x": -16,
      "y": 47,
      "z": 3,
      "name": "Rock_Ice_Permafrost"
    },
    {
      "x": -16,
      "y": 48,
      "z": 3,
      "name": "Rock_Ice_Permafrost"
    },
    {
      "x": -16,
      "y": 49,
      "z": 3,
      "name": "Rock_Ice_Permafrost"
    },
    {
      "x": -16,
      "y": 50,
      "z": 3,
      "name": "Rock_Ice_Permafrost"
    },
    {
      "x": -16,
      "y": 51,
      "z": 3,
      "name": "Rock_Ice_Permafrost"
    },
    {
      "x": -16,
      "y": 52,
      "z": 3,
      "name": "Rock_Ice_Permafrost"
    },
    {
      "x": -16,
      "y": 53,
      "z": 3,
      "name": "Rock_Ice_Permafrost"
    },
    {
      "x": -16,
      "y": 54,
      "z": 3,
      "name": "Rock_Ice_Permafrost"
    },
    {
      "x": -16,
      "y": 55,
      "z": 3,
      "name": "Rock_Ice"
    },
    {
      "x": -16,
      "y": 56,
      "z": 3,
      "name": "Rock_Ice_Permafrost"
    },
    {
      "x": -16,
      "y": 57,
      "z": 3,
      "name": "Rock_Ice"
    },
    {
      "x": -16,
      "y": 58,
      "z": 3,
      "name": "Rock_Ice"
    },
    {
      "x": -16,
      "y": 59,
      "z": 3,
      "name": "Soil_Snow"
    },
    {
      "x": -16,
      "y": 20,
      "z": 4,
      "name": "Rock_Ice"
    },
    {
      "x": -16,
      "y": 21,
      "z": 4,
      "name": "Rock_Ice"
    },
    {
      "x": -16,
      "y": 22,
      "z": 4,
      "name": "Rock_Ice"
    },
    {
      "x": -16,
      "y": 23,
      "z": 4,
      "name": "Rock_Ice"
    },
    {
      "x": -16,
      "y": 24,
      "z": 4,
      "name": "Rock_Ice"
    },
    {
      "x": -16,
      "y": 25,
      "z": 4,
      "name": "Rock_Ice"
    },
    {
      "x": -16,
      "y": 26,
      "z": 4,
      "name": "Rock_Ice"
    },
    {
      "x": -16,
      "y": 27,
      "z": 4,
      "name": "Rock_Ice"
    },
    {
      "x": -16,
      "y": 28,
      "z": 4,
      "name": "Rock_Ice"
    },
    {
      "x": -16,
      "y": 29,
      "z": 4,
      "name": "Rock_Ice"
    },
    {
      "x": -16,
      "y": 30,
      "z": 4,
      "name": "Rock_Ice"
    },
    {
      "x": -16,
      "y": 31,
      "z": 4,
      "name": "Rock_Ice"
    },
    {
      "x": -16,
      "y": 32,
      "z": 4,
      "name": "Rock_Ice"
    },
    {
      "x": -16,
      "y": 33,
      "z": 4,
      "name": "Rock_Ice"
    },
    {
      "x": -16,
      "y": 34,
      "z": 4,
      "name": "Rock_Ice_Permafrost"
    },
    {
      "x": -16,
      "y": 35,
      "z": 4,
      "name": "Rock_Ice"
    },
    {
      "x": -16,
      "y": 36,
      "z": 4,
      "name": "Rock_Ice_Permafrost"
    },
    {
      "x": -16,
      "y": 37,
      "z": 4,
      "name": "Rock_Ice_Permafrost"
    },
    {
      "x": -16,
      "y": 38,
      "z": 4,
      "name": "Rock_Ice_Permafrost"
    },
    {
      "x": -16,
      "y": 39,
      "z": 4,
      "name": "Rock_Ice_Permafrost"
    },
    {
      "x": -16,
      "y": 40,
      "z": 4,
      "name": "Rock_Ice_Permafrost"
    },
    {
      "x": -16,
      "y": 41,
      "z": 4,
      "name": "Rock_Ice_Permafrost"
    },
    {
      "x": -16,
      "y": 42,
      "z": 4,
      "name": "Rock_Ice_Permafrost"
    },
    {
      "x": -16,
      "y": 43,
      "z": 4,
      "name": "Rock_Ice_Permafrost"
    },
    {
      "x": -16,
      "y": 44,
      "z": 4,
      "name": "Rock_Ice_Permafrost"
    },
    {
      "x": -16,
      "y": 45,
      "z": 4,
      "name": "Rock_Ice_Permafrost"
    },
    {
      "x": -16,
      "y": 46,
      "z": 4,
      "name": "Rock_Ice_Permafrost"
    },
    {
      "x": -16,
      "y": 47,
      "z": 4,
      "name": "Rock_Ice_Permafrost"
    },
    {
      "x": -16,
      "y": 48,
      "z": 4,
      "name": "Rock_Ice_Permafrost"
    },
    {
      "x": -16,
      "y": 49,
      "z": 4,
      "name": "Rock_Ice_Permafrost"
    },
    {
      "x": -16,
      "y": 50,
      "z": 4,
      "name": "Rock_Ice_Permafrost"
    },
    {
      "x": -16,
      "y": 51,
      "z": 4,
      "name": "Rock_Ice_Permafrost"
    },
    {
      "x": -16,
      "y": 52,
      "z": 4,
      "name": "Rock_Ice_Permafrost"
    },
    {
      "x": -16,
      "y": 53,
      "z": 4,
      "name": "Rock_Ice_Permafrost"
    },
    {
      "x": -16,
      "y": 54,
      "z": 4,
      "name": "Rock_Ice_Permafrost"
    },
    {
      "x": -16,
      "y": 55,
      "z": 4,
      "name": "Rock_Ice_Permafrost"
    },
    {
      "x": -16,
      "y": 56,
      "z": 4,
      "name": "Rock_Ice"
    },
    {
      "x": -16,
      "y": 57,
      "z": 4,
      "name": "Rock_Ice"
    },
    {
      "x": -16,
      "y": 58,
      "z": 4,
      "name": "Rock_Ice"
    },
    {
      "x": -16,
      "y": 59,
      "z": 4,
      "name": "Rock_Ice"
    },
    {
      "x": -16,
      "y": 60,
      "z": 4,
      "name": "Soil_Snow"
    },
    {
      "x": -16,
      "y": 20,
      "z": 5,
      "name": "Rock_Ice"
    },
    {
      "x": -16,
      "y": 21,
      "z": 5,
      "name": "Rock_Ice"
    },
    {
      "x": -16,
      "y": 22,
      "z": 5,
      "name": "Rock_Ice"
    },
    {
      "x": -16,
      "y": 23,
      "z": 5,
      "name": "Rock_Ice"
    },
    {
      "x": -16,
      "y": 24,
      "z": 5,
      "name": "Rock_Ice"
    },
    {
      "x": -16,
      "y": 25,
      "z": 5,
      "name": "Rock_Ice"
    },
    {
      "x": -16,
      "y": 26,
      "z": 5,
      "name": "Rock_Ice"
    },
    {
      "x": -16,
      "y": 27,
      "z": 5,
      "name": "Rock_Ice"
    },
    {
      "x": -16,
      "y": 28,
      "z": 5,
      "name": "Rock_Ice"
    },
    {
      "x": -16,
      "y": 29,
      "z": 5,
      "name": "Rock_Ice"
    },
    {
      "x": -16,
      "y": 30,
      "z": 5,
      "name": "Rock_Ice_Permafrost"
    },
    {
      "x": -16,
      "y": 31,
      "z": 5,
      "name": "Rock_Ice"
    },
    {
      "x": -16,
      "y": 32,
      "z": 5,
      "name": "Rock_Ice_Permafrost"
    },
    {
      "x": -16,
      "y": 33,
      "z": 5,
      "name": "Rock_Ice_Permafrost"
    },
    {
      "x": -16,
      "y": 34,
      "z": 5,
      "name": "Rock_Ice_Permafrost"
    },
    {
      "x": -16,
      "y": 35,
      "z": 5,
      "name": "Rock_Ice_Permafrost"
    },
    {
      "x": -16,
      "y": 36,
      "z": 5,
      "name": "Rock_Ice_Permafrost"
    },
    {
      "x": -16,
      "y": 37,
      "z": 5,
      "name": "Rock_Ice_Permafrost"
    },
    {
      "x": -16,
      "y": 38,
      "z": 5,
      "name": "Rock_Ice_Permafrost"
    },
    {
      "x": -16,
      "y": 39,
      "z": 5,
      "name": "Rock_Ice_Permafrost"
    },
    {
      "x": -16,
      "y": 40,
      "z": 5,
      "name": "Rock_Ice_Permafrost"
    },
    {
      "x": -16,
      "y": 41,
      "z": 5,
      "name": "Rock_Ice_Permafrost"
    },
    {
      "x": -16,
      "y": 42,
      "z": 5,
      "name": "Rock_Ice_Permafrost"
    },
    {
      "x": -16,
      "y": 43,
      "z": 5,
      "name": "Rock_Ice_Permafrost"
    },
    {
      "x": -16,
      "y": 44,
      "z": 5,
      "name": "Rock_Ice_Permafrost"
    },
    {
      "x": -16,
      "y": 45,
      "z": 5,
      "name": "Rock_Ice_Permafrost"
    },
    {
      "x": -16,
      "y": 46,
      "z": 5,
      "name": "Rock_Ice_Permafrost"
    },
    {
      "x": -16,
      "y": 47,
      "z": 5,
      "name": "Rock_Ice_Permafrost"
    },
    {
      "x": -16,
      "y": 48,
      "z": 5,
      "name": "Rock_Ice_Permafrost"
    },
    {
      "x": -16,
      "y": 49,
      "z": 5,
      "name": "Rock_Ice_Permafrost"
    },
    {
      "x": -16,
      "y": 50,
      "z": 5,
      "name": "Rock_Ice_Permafrost"
    },
    {
      "x": -16,
      "y": 51,
      "z": 5,
      "name": "Rock_Ice"
    },
    {
      "x": -16,
      "y": 52,
      "z": 5,
      "name": "Rock_Ice_Permafrost"
    },
    {
      "x": -16,
      "y": 53,
      "z": 5,
      "name": "Rock_Ice_Permafrost"
    },
    {
      "x": -16,
      "y": 54,
      "z": 5,
      "name": "Rock_Ice_Permafrost"
    },
    {
      "x": -16,
      "y": 55,
      "z": 5,
      "name": "Rock_Ice_Permafrost"
    },
    {
      "x": -16,
      "y": 56,
      "z": 5,
      "name": "Rock_Ice"
    },
    {
      "x": -16,
      "y": 57,
      "z": 5,
      "name": "Rock_Ice_Permafrost"
    },
    {
      "x": -16,
      "y": 58,
      "z": 5,
      "name": "Rock_Ice"
    },
    {
      "x": -16,
      "y": 59,
      "z": 5,
      "name": "Rock_Ice"
    },
    {
      "x": -16,
      "y": 60,
      "z": 5,
      "name": "Soil_Snow"
    },
    {
      "x": -16,
      "y": 20,
      "z": 6,
      "name": "Rock_Ice"
    },
    {
      "x": -16,
      "y": 21,
      "z": 6,
      "name": "Rock_Ice"
    },
    {
      "x": -16,
      "y": 22,
      "z": 6,
      "name": "Rock_Ice"
    },
    {
      "x": -16,
      "y": 23,
      "z": 6,
      "name": "Rock_Ice"
    },
    {
      "x": -16,
      "y": 24,
      "z": 6,
      "name": "Rock_Ice"
    },
    {
      "x": -16,
      "y": 25,
      "z": 6,
      "name": "Rock_Ice"
    },
    {
      "x": -16,
      "y": 26,
      "z": 6,
      "name": "Rock_Ice"
    },
    {
      "x": -16,
      "y": 27,
      "z": 6,
      "name": "Rock_Ice"
    },
    {
      "x": -16,
      "y": 28,
      "z": 6,
      "name": "Rock_Ice"
    },
    {
      "x": -16,
      "y": 29,
      "z": 6,
      "name": "Rock_Ice_Permafrost"
    },
    {
      "x": -16,
      "y": 30,
      "z": 6,
      "name": "Rock_Ice"
    },
    {
      "x": -16,
      "y": 31,
      "z": 6,
      "name": "Rock_Ice_Permafrost"
    },
    {
      "x": -16,
      "y": 32,
      "z": 6,
      "name": "Rock_Ice_Permafrost"
    },
    {
      "x": -16,
      "y": 33,
      "z": 6,
      "name": "Rock_Ice_Permafrost"
    },
    {
      "x": -16,
      "y": 34,
      "z": 6,
      "name": "Rock_Ice_Permafrost"
    },
    {
      "x": -16,
      "y": 35,
      "z": 6,
      "name": "Rock_Ice_Permafrost"
    },
    {
      "x": -16,
      "y": 36,
      "z": 6,
      "name": "Rock_Ice_Permafrost"
    },
    {
      "x": -16,
      "y": 37,
      "z": 6,
      "name": "Rock_Ice_Permafrost"
    },
    {
      "x": -16,
      "y": 38,
      "z": 6,
      "name": "Rock_Ice_Permafrost"
    },
    {
      "x": -16,
      "y": 39,
      "z": 6,
      "name": "Rock_Ice_Permafrost"
    },
    {
      "x": -16,
      "y": 40,
      "z": 6,
      "name": "Rock_Ice_Permafrost"
    },
    {
      "x": -16,
      "y": 41,
      "z": 6,
      "name": "Rock_Ice_Permafrost"
    },
    {
      "x": -16,
      "y": 42,
      "z": 6,
      "name": "Rock_Ice_Permafrost"
    },
    {
      "x": -16,
      "y": 43,
      "z": 6,
      "name": "Rock_Ice_Permafrost"
    },
    {
      "x": -16,
      "y": 44,
      "z": 6,
      "name": "Rock_Ice_Permafrost"
    },
    {
      "x": -16,
      "y": 45,
      "z": 6,
      "name": "Rock_Ice_Permafrost"
    },
    {
      "x": -16,
      "y": 46,
      "z": 6,
      "name": "Rock_Ice_Permafrost"
    },
    {
      "x": -16,
      "y": 47,
      "z": 6,
      "name": "Rock_Ice_Permafrost"
    },
    {
      "x": -16,
      "y": 48,
      "z": 6,
      "name": "Rock_Ice_Permafrost"
    },
    {
      "x": -16,
      "y": 49,
      "z": 6,
      "name": "Rock_Ice_Permafrost"
    },
    {
      "x": -16,
      "y": 50,
      "z": 6,
      "name": "Rock_Ice_Permafrost"
    },
    {
      "x": -16,
      "y": 51,
      "z": 6,
      "name": "Rock_Ice_Permafrost"
    },
    {
      "x": -16,
      "y": 52,
      "z": 6,
      "name": "Rock_Ice"
    },
    {
      "x": -16,
      "y": 53,
      "z": 6,
      "name": "Rock_Ice_Permafrost"
    },
    {
      "x": -16,
      "y": 54,
      "z": 6,
      "name": "Rock_Ice_Permafrost"
    },
    {
      "x": -16,
      "y": 55,
      "z": 6,
      "name": "Rock_Ice_Permafrost"
    },
    {
      "x": -16,
      "y": 56,
      "z": 6,
      "name": "Rock_Ice_Permafrost"
    },
    {
      "x": -16,
      "y": 57,
      "z": 6,
      "name": "Rock_Ice"
    },
    {
      "x": -16,
      "y": 58,
      "z": 6,
      "name": "Rock_Ice"
    },
    {
      "x": -16,
      "y": 59,
      "z": 6,
      "name": "Rock_Ice"
    },
    {
      "x": -16,
      "y": 60,
      "z": 6,
      "name": "Soil_Snow"
    },
    {
      "x": -16,
      "y": 20,
      "z": 7,
      "name": "Rock_Ice"
    },
    {
      "x": -16,
      "y": 21,
      "z": 7,
      "name": "Rock_Ice"
    },
    {
      "x": -16,
      "y": 22,
      "z": 7,
      "name": "Rock_Ice"
    },
    {
      "x": -16,
      "y": 23,
      "z": 7,
      "name": "Rock_Ice"
    },
    {
      "x": -16,
      "y": 24,
      "z": 7,
      "name": "Rock_Ice"
    },
    {
      "x": -16,
      "y": 25,
      "z": 7,
      "name": "Rock_Ice"
    },
    {
      "x": -16,
      "y": 26,
      "z": 7,
      "name": "Rock_Ice"
    },
    {
      "x": -16,
      "y": 27,
      "z": 7,
      "name": "Rock_Ice"
    },
    {
      "x": -16,
      "y": 28,
      "z": 7,
      "name": "Rock_Ice_Permafrost"
    },
    {
      "x": -16,
      "y": 29,
      "z": 7,
      "name": "Rock_Ice"
    },
    {
      "x": -16,
      "y": 30,
      "z": 7,
      "name": "Rock_Ice_Permafrost"
    },
    {
      "x": -16,
      "y": 31,
      "z": 7,
      "name": "Rock_Ice"
    },
    {
      "x": -16,
      "y": 32,
      "z": 7,
      "name": "Rock_Ice_Permafrost"
    },
    {
      "x": -16,
      "y": 33,
      "z": 7,
      "name": "Rock_Ice_Permafrost"
    },
    {
      "x": -16,
      "y": 34,
      "z": 7,
      "name": "Rock_Ice_Permafrost"
    },
    {
      "x": -16,
      "y": 35,
      "z": 7,
      "name": "Rock_Ice_Permafrost"
    },
    {
      "x": -16,
      "y": 36,
      "z": 7,
      "name": "Rock_Ice_Permafrost"
    },
    {
      "x": -16,
      "y": 37,
      "z": 7,
      "name": "Rock_Ice_Permafrost"
    },
    {
      "x": -16,
      "y": 38,
      "z": 7,
      "name": "Rock_Ice_Permafrost"
    },
    {
      "x": -16,
      "y": 39,
      "z": 7,
      "name": "Rock_Ice_Permafrost"
    },
    {
      "x": -16,
      "y": 40,
      "z": 7,
      "name": "Rock_Ice_Permafrost"
    },
    {
      "x": -16,
      "y": 41,
      "z": 7,
      "name": "Rock_Ice_Permafrost"
    },
    {
      "x": -16,
      "y": 42,
      "z": 7,
      "name": "Rock_Ice_Permafrost"
    },
    {
      "x": -16,
      "y": 43,
      "z": 7,
      "name": "Rock_Ice_Permafrost"
    },
    {
      "x": -16,
      "y": 44,
      "z": 7,
      "name": "Rock_Ice_Permafrost"
    },
    {
      "x": -16,
      "y": 45,
      "z": 7,
      "name": "Rock_Ice_Permafrost"
    },
    {
      "x": -16,
      "y": 46,
      "z": 7,
      "name": "Rock_Ice_Permafrost"
    },
    {
      "x": -16,
      "y": 47,
      "z": 7,
      "name": "Rock_Ice_Permafrost"
    },
    {
      "x": -16,
      "y": 48,
      "z": 7,
      "name": "Rock_Ice_Permafrost"
    },
    {
      "x": -16,
      "y": 49,
      "z": 7,
      "name": "Rock_Ice_Permafrost"
    },
    {
      "x": -16,
      "y": 50,
      "z": 7,
      "name": "Rock_Ice_Permafrost"
    },
    {
      "x": -16,
      "y": 51,
      "z": 7,
      "name": "Rock_Ice"
    },
    {
      "x": -16,
      "y": 52,
      "z": 7,
      "name": "Rock_Ice_Permafrost"
    },
    {
      "x": -16,
      "y": 53,
      "z": 7,
      "name": "Rock_Ice_Permafrost"
    },
    {
      "x": -16,
      "y": 54,
      "z": 7,
      "name": "Rock_Ice"
    },
    {
      "x": -16,
      "y": 55,
      "z": 7,
      "name": "Rock_Ice_Permafrost"
    },
    {
      "x": -16,
      "y": 56,
      "z": 7,
      "name": "Rock_Ice"
    },
    {
      "x": -16,
      "y": 57,
      "z": 7,
      "name": "Rock_Ice_Permafrost"
    },
    {
      "x": -16,
      "y": 58,
      "z": 7,
      "name": "Rock_Ice"
    },
    {
      "x": -16,
      "y": 59,
      "z": 7,
      "name": "Rock_Ice"
    },
    {
      "x": -16,
      "y": 60,
      "z": 7,
      "name": "Rock_Ice"
    },
    {
      "x": -16,
      "y": 61,
      "z": 7,
      "name": "Rock_Ice"
    },
    {
      "x": -16,
      "y": 20,
      "z": 8,
      "name": "Rock_Ice"
    },
    {
      "x": -16,
      "y": 21,
      "z": 8,
      "name": "Rock_Ice"
    },
    {
      "x": -16,
      "y": 22,
      "z": 8,
      "name": "Rock_Ice"
    },
    {
      "x": -16,
      "y": 23,
      "z": 8,
      "name": "Rock_Ice"
    },
    {
      "x": -16,
      "y": 24,
      "z": 8,
      "name": "Rock_Ice"
    },
    {
      "x": -16,
      "y": 25,
      "z": 8,
      "name": "Rock_Ice"
    },
    {
      "x": -16,
      "y": 26,
      "z": 8,
      "name": "Rock_Ice"
    },
    {
      "x": -16,
      "y": 27,
      "z": 8,
      "name": "Rock_Ice"
    },
    {
      "x": -16,
      "y": 28,
      "z": 8,
      "name": "Rock_Ice_Permafrost"
    },
    {
      "x": -16,
      "y": 29,
      "z": 8,
      "name": "Rock_Ice_Permafrost"
    },
    {
      "x": -16,
      "y": 30,
      "z": 8,
      "name": "Rock_Ice_Permafrost"
    },
    {
      "x": -16,
      "y": 31,
      "z": 8,
      "name": "Rock_Ice_Permafrost"
    },
    {
      "x": -16,
      "y": 32,
      "z": 8,
      "name": "Rock_Ice_Permafrost"
    },
    {
      "x": -16,
      "y": 33,
      "z": 8,
      "name": "Rock_Ice_Permafrost"
    },
    {
      "x": -16,
      "y": 34,
      "z": 8,
      "name": "Rock_Ice_Permafrost"
    },
    {
      "x": -16,
      "y": 35,
      "z": 8,
      "name": "Rock_Ice_Permafrost"
    },
    {
      "x": -16,
      "y": 36,
      "z": 8,
      "name": "Rock_Ice_Permafrost"
    },
    {
      "x": -16,
      "y": 37,
      "z": 8,
      "name": "Rock_Ice_Permafrost"
    },
    {
      "x": -16,
      "y": 38,
      "z": 8,
      "name": "Rock_Ice_Permafrost"
    },
    {
      "x": -16,
      "y": 39,
      "z": 8,
      "name": "Rock_Ice_Permafrost"
    },
    {
      "x": -16,
      "y": 40,
      "z": 8,
      "name": "Rock_Ice_Permafrost"
    },
    {
      "x": -16,
      "y": 41,
      "z": 8,
      "name": "Rock_Ice_Permafrost"
    },
    {
      "x": -16,
      "y": 42,
      "z": 8,
      "name": "Rock_Ice_Permafrost"
    },
    {
      "x": -16,
      "y": 43,
      "z": 8,
      "name": "Rock_Ice_Permafrost"
    },
    {
      "x": -16,
      "y": 44,
      "z": 8,
      "name": "Rock_Ice_Permafrost"
    },
    {
      "x": -16,
      "y": 45,
      "z": 8,
      "name": "Rock_Ice_Permafrost"
    },
    {
      "x": -16,
      "y": 46,
      "z": 8,
      "name": "Rock_Ice_Permafrost"
    },
    {
      "x": -16,
      "y": 47,
      "z": 8,
      "name": "Rock_Ice_Permafrost"
    },
    {
      "x": -16,
      "y": 48,
      "z": 8,
      "name": "Rock_Ice_Permafrost"
    },
    {
      "x": -16,
      "y": 49,
      "z": 8,
      "name": "Rock_Ice_Permafrost"
    },
    {
      "x": -16,
      "y": 50,
      "z": 8,
      "name": "Rock_Ice_Permafrost"
    },
    {
      "x": -16,
      "y": 51,
      "z": 8,
      "name": "Rock_Ice_Permafrost"
    },
    {
      "x": -16,
      "y": 52,
      "z": 8,
      "name": "Rock_Ice_Permafrost"
    },
    {
      "x": -16,
      "y": 53,
      "z": 8,
      "name": "Rock_Ice"
    },
    {
      "x": -16,
      "y": 54,
      "z": 8,
      "name": "Rock_Ice_Permafrost"
    },
    {
      "x": -16,
      "y": 55,
      "z": 8,
      "name": "Rock_Ice_Permafrost"
    },
    {
      "x": -16,
      "y": 56,
      "z": 8,
      "name": "Rock_Ice_Permafrost"
    },
    {
      "x": -16,
      "y": 57,
      "z": 8,
      "name": "Rock_Ice_Permafrost"
    },
    {
      "x": -16,
      "y": 58,
      "z": 8,
      "name": "Rock_Ice"
    },
    {
      "x": -16,
      "y": 59,
      "z": 8,
      "name": "Rock_Ice"
    },
    {
      "x": -16,
      "y": 60,
      "z": 8,
      "name": "Rock_Ice"
    },
    {
      "x": -16,
      "y": 61,
      "z": 8,
      "name": "Rock_Ice"
    },
    {
      "x": -16,
      "y": 21,
      "z": 9,
      "name": "Rock_Ice"
    },
    {
      "x": -16,
      "y": 22,
      "z": 9,
      "name": "Rock_Ice"
    },
    {
      "x": -16,
      "y": 23,
      "z": 9,
      "name": "Rock_Ice"
    },
    {
      "x": -16,
      "y": 24,
      "z": 9,
      "name": "Rock_Ice"
    },
    {
      "x": -16,
      "y": 25,
      "z": 9,
      "name": "Rock_Ice"
    },
    {
      "x": -16,
      "y": 26,
      "z": 9,
      "name": "Rock_Ice_Permafrost"
    },
    {
      "x": -16,
      "y": 27,
      "z": 9,
      "name": "Rock_Ice"
    },
    {
      "x": -16,
      "y": 28,
      "z": 9,
      "name": "Rock_Ice_Permafrost"
    },
    {
      "x": -16,
      "y": 29,
      "z": 9,
      "name": "Rock_Ice_Permafrost"
    },
    {
      "x": -16,
      "y": 30,
      "z": 9,
      "name": "Rock_Ice_Permafrost"
    },
    {
      "x": -16,
      "y": 31,
      "z": 9,
      "name": "Rock_Ice_Permafrost"
    },
    {
      "x": -16,
      "y": 32,
      "z": 9,
      "name": "Rock_Ice_Permafrost"
    },
    {
      "x": -16,
      "y": 33,
      "z": 9,
      "name": "Rock_Ice_Permafrost"
    },
    {
      "x": -16,
      "y": 34,
      "z": 9,
      "name": "Rock_Ice_Permafrost"
    },
    {
      "x": -16,
      "y": 35,
      "z": 9,
      "name": "Rock_Ice_Permafrost"
    },
    {
      "x": -16,
      "y": 36,
      "z": 9,
      "name": "Rock_Ice_Permafrost"
    },
    {
      "x": -16,
      "y": 37,
      "z": 9,
      "name": "Rock_Ice_Permafrost"
    },
    {
      "x": -16,
      "y": 38,
      "z": 9,
      "name": "Rock_Ice_Permafrost"
    },
    {
      "x": -16,
      "y": 39,
      "z": 9,
      "name": "Rock_Ice_Permafrost"
    },
    {
      "x": -16,
      "y": 40,
      "z": 9,
      "name": "Rock_Ice_Permafrost"
    },
    {
      "x": -16,
      "y": 41,
      "z": 9,
      "name": "Rock_Ice_Permafrost"
    },
    {
      "x": -16,
      "y": 42,
      "z": 9,
      "name": "Rock_Ice_Permafrost"
    },
    {
      "x": -16,
      "y": 43,
      "z": 9,
      "name": "Rock_Ice_Permafrost"
    },
    {
      "x": -16,
      "y": 44,
      "z": 9,
      "name": "Rock_Ice_Permafrost"
    },
    {
      "x": -16,
      "y": 45,
      "z": 9,
      "name": "Rock_Ice_Permafrost"
    },
    {
      "x": -16,
      "y": 46,
      "z": 9,
      "name": "Rock_Ice_Permafrost"
    },
    {
      "x": -16,
      "y": 47,
      "z": 9,
      "name": "Rock_Ice_Permafrost"
    },
    {
      "x": -16,
      "y": 48,
      "z": 9,
      "name": "Rock_Ice"
    },
    {
      "x": -16,
      "y": 49,
      "z": 9,
      "name": "Rock_Ice_Permafrost"
    },
    {
      "x": -16,
      "y": 50,
      "z": 9,
      "name": "Rock_Ice"
    },
    {
      "x": -16,
      "y": 51,
      "z": 9,
      "name": "Rock_Ice"
    },
    {
      "x": -16,
      "y": 52,
      "z": 9,
      "name": "Rock_Ice"
    },
    {
      "x": -16,
      "y": 53,
      "z": 9,
      "name": "Rock_Ice"
    },
    {
      "x": -16,
      "y": 54,
      "z": 9,
      "name": "Rock_Ice"
    },
    {
      "x": -16,
      "y": 55,
      "z": 9,
      "name": "Rock_Ice"
    },
    {
      "x": -16,
      "y": 56,
      "z": 9,
      "name": "Rock_Ice"
    },
    {
      "x": -16,
      "y": 57,
      "z": 9,
      "name": "Rock_Ice"
    },
    {
      "x": -16,
      "y": 58,
      "z": 9,
      "name": "Rock_Ice"
    },
    {
      "x": -16,
      "y": 59,
      "z": 9,
      "name": "Rock_Ice"
    },
    {
      "x": -16,
      "y": 60,
      "z": 9,
      "name": "Rock_Ice"
    },
    {
      "x": -16,
      "y": 61,
      "z": 9,
      "name": "Rock_Ice"
    },
    {
      "x": -16,
      "y": 22,
      "z": 10,
      "name": "Rock_Ice"
    },
    {
      "x": -16,
      "y": 23,
      "z": 10,
      "name": "Rock_Ice"
    },
    {
      "x": -16,
      "y": 24,
      "z": 10,
      "name": "Rock_Ice_Permafrost"
    },
    {
      "x": -16,
      "y": 25,
      "z": 10,
      "name": "Rock_Ice"
    },
    {
      "x": -16,
      "y": 26,
      "z": 10,
      "name": "Rock_Ice"
    },
    {
      "x": -16,
      "y": 27,
      "z": 10,
      "name": "Rock_Ice_Permafrost"
    },
    {
      "x": -16,
      "y": 28,
      "z": 10,
      "name": "Rock_Ice_Permafrost"
    },
    {
      "x": -16,
      "y": 29,
      "z": 10,
      "name": "Rock_Ice_Permafrost"
    },
    {
      "x": -16,
      "y": 30,
      "z": 10,
      "name": "Rock_Ice_Permafrost"
    },
    {
      "x": -16,
      "y": 31,
      "z": 10,
      "name": "Rock_Ice_Permafrost"
    },
    {
      "x": -16,
      "y": 32,
      "z": 10,
      "name": "Rock_Ice_Permafrost"
    },
    {
      "x": -16,
      "y": 33,
      "z": 10,
      "name": "Rock_Ice_Permafrost"
    },
    {
      "x": -16,
      "y": 34,
      "z": 10,
      "name": "Rock_Ice_Permafrost"
    },
    {
      "x": -16,
      "y": 35,
      "z": 10,
      "name": "Rock_Ice_Permafrost"
    },
    {
      "x": -16,
      "y": 36,
      "z": 10,
      "name": "Rock_Ice_Permafrost"
    },
    {
      "x": -16,
      "y": 37,
      "z": 10,
      "name": "Rock_Ice_Permafrost"
    },
    {
      "x": -16,
      "y": 38,
      "z": 10,
      "name": "Rock_Ice_Permafrost"
    },
    {
      "x": -16,
      "y": 39,
      "z": 10,
      "name": "Rock_Ice_Permafrost"
    },
    {
      "x": -16,
      "y": 40,
      "z": 10,
      "name": "Rock_Ice_Permafrost"
    },
    {
      "x": -16,
      "y": 41,
      "z": 10,
      "name": "Rock_Ice_Permafrost"
    },
    {
      "x": -16,
      "y": 42,
      "z": 10,
      "name": "Rock_Ice_Permafrost"
    },
    {
      "x": -16,
      "y": 43,
      "z": 10,
      "name": "Rock_Ice_Permafrost"
    },
    {
      "x": -16,
      "y": 44,
      "z": 10,
      "name": "Rock_Ice_Permafrost"
    },
    {
      "x": -16,
      "y": 45,
      "z": 10,
      "name": "Rock_Ice_Permafrost"
    },
    {
      "x": -16,
      "y": 46,
      "z": 10,
      "name": "Rock_Ice_Permafrost"
    },
    {
      "x": -16,
      "y": 47,
      "z": 10,
      "name": "Rock_Ice_Permafrost"
    },
    {
      "x": -16,
      "y": 48,
      "z": 10,
      "name": "Rock_Ice_Permafrost"
    },
    {
      "x": -16,
      "y": 49,
      "z": 10,
      "name": "Rock_Ice"
    },
    {
      "x": -16,
      "y": 50,
      "z": 10,
      "name": "Rock_Ice"
    },
    {
      "x": -16,
      "y": 51,
      "z": 10,
      "name": "Rock_Ice_Permafrost"
    },
    {
      "x": -16,
      "y": 52,
      "z": 10,
      "name": "Rock_Ice"
    },
    {
      "x": -16,
      "y": 53,
      "z": 10,
      "name": "Rock_Ice"
    },
    {
      "x": -16,
      "y": 54,
      "z": 10,
      "name": "Rock_Ice"
    },
    {
      "x": -16,
      "y": 55,
      "z": 10,
      "name": "Rock_Ice"
    },
    {
      "x": -16,
      "y": 56,
      "z": 10,
      "name": "Rock_Ice"
    },
    {
      "x": -16,
      "y": 57,
      "z": 10,
      "name": "Rock_Ice"
    },
    {
      "x": -16,
      "y": 58,
      "z": 10,
      "name": "Rock_Ice"
    },
    {
      "x": -16,
      "y": 59,
      "z": 10,
      "name": "Rock_Ice"
    },
    {
      "x": -16,
      "y": 60,
      "z": 10,
      "name": "Rock_Ice"
    },
    {
      "x": -16,
      "y": 61,
      "z": 10,
      "name": "Soil_Snow"
    },
    {
      "x": -16,
      "y": 23,
      "z": 11,
      "name": "Rock_Ice_Permafrost"
    },
    {
      "x": -16,
      "y": 24,
      "z": 11,
      "name": "Rock_Ice"
    },
    {
      "x": -16,
      "y": 25,
      "z": 11,
      "name": "Rock_Ice_Permafrost"
    },
    {
      "x": -16,
      "y": 26,
      "z": 11,
      "name": "Rock_Ice_Permafrost"
    },
    {
      "x": -16,
      "y": 27,
      "z": 11,
      "name": "Rock_Ice_Permafrost"
    },
    {
      "x": -16,
      "y": 28,
      "z": 11,
      "name": "Rock_Ice_Permafrost"
    },
    {
      "x": -16,
      "y": 29,
      "z": 11,
      "name": "Rock_Ice_Permafrost"
    },
    {
      "x": -16,
      "y": 30,
      "z": 11,
      "name": "Rock_Ice_Permafrost"
    },
    {
      "x": -16,
      "y": 31,
      "z": 11,
      "name": "Rock_Ice_Permafrost"
    },
    {
      "x": -16,
      "y": 32,
      "z": 11,
      "name": "Rock_Ice_Permafrost"
    },
    {
      "x": -16,
      "y": 33,
      "z": 11,
      "name": "Rock_Ice_Permafrost"
    },
    {
      "x": -16,
      "y": 34,
      "z": 11,
      "name": "Rock_Ice_Permafrost"
    },
    {
      "x": -16,
      "y": 35,
      "z": 11,
      "name": "Rock_Ice_Permafrost"
    },
    {
      "x": -16,
      "y": 36,
      "z": 11,
      "name": "Rock_Ice_Permafrost"
    },
    {
      "x": -16,
      "y": 37,
      "z": 11,
      "name": "Rock_Ice_Permafrost"
    },
    {
      "x": -16,
      "y": 38,
      "z": 11,
      "name": "Rock_Ice_Permafrost"
    },
    {
      "x": -16,
      "y": 39,
      "z": 11,
      "name": "Rock_Ice_Permafrost"
    },
    {
      "x": -16,
      "y": 40,
      "z": 11,
      "name": "Rock_Ice_Permafrost"
    },
    {
      "x": -16,
      "y": 41,
      "z": 11,
      "name": "Rock_Ice_Permafrost"
    },
    {
      "x": -16,
      "y": 42,
      "z": 11,
      "name": "Rock_Ice_Permafrost"
    },
    {
      "x": -16,
      "y": 43,
      "z": 11,
      "name": "Rock_Ice_Permafrost"
    },
    {
      "x": -16,
      "y": 44,
      "z": 11,
      "name": "Rock_Ice_Permafrost"
    },
    {
      "x": -16,
      "y": 45,
      "z": 11,
      "name": "Rock_Ice_Permafrost"
    },
    {
      "x": -16,
      "y": 46,
      "z": 11,
      "name": "Rock_Ice_Permafrost"
    },
    {
      "x": -16,
      "y": 47,
      "z": 11,
      "name": "Rock_Ice_Permafrost"
    },
    {
      "x": -16,
      "y": 48,
      "z": 11,
      "name": "Rock_Ice"
    },
    {
      "x": -16,
      "y": 49,
      "z": 11,
      "name": "Rock_Ice"
    },
    {
      "x": -16,
      "y": 50,
      "z": 11,
      "name": "Rock_Ice"
    },
    {
      "x": -16,
      "y": 51,
      "z": 11,
      "name": "Rock_Ice"
    },
    {
      "x": -16,
      "y": 52,
      "z": 11,
      "name": "Rock_Ice"
    },
    {
      "x": -16,
      "y": 53,
      "z": 11,
      "name": "Rock_Ice"
    },
    {
      "x": -16,
      "y": 54,
      "z": 11,
      "name": "Rock_Ice"
    },
    {
      "x": -16,
      "y": 55,
      "z": 11,
      "name": "Rock_Ice"
    },
    {
      "x": -16,
      "y": 56,
      "z": 11,
      "name": "Rock_Ice"
    },
    {
      "x": -16,
      "y": 57,
      "z": 11,
      "name": "Rock_Ice"
    },
    {
      "x": -16,
      "y": 58,
      "z": 11,
      "name": "Rock_Ice"
    },
    {
      "x": -16,
      "y": 59,
      "z": 11,
      "name": "Rock_Ice"
    },
    {
      "x": -16,
      "y": 60,
      "z": 11,
      "name": "Rock_Ice"
    },
    {
      "x": -16,
      "y": 61,
      "z": 11,
      "name": "Soil_Snow"
    },
    {
      "x": -16,
      "y": 24,
      "z": 12,
      "name": "Rock_Ice_Permafrost"
    },
    {
      "x": -16,
      "y": 25,
      "z": 12,
      "name": "Rock_Ice"
    },
    {
      "x": -16,
      "y": 26,
      "z": 12,
      "name": "Rock_Ice_Permafrost"
    },
    {
      "x": -16,
      "y": 27,
      "z": 12,
      "name": "Rock_Ice_Permafrost"
    },
    {
      "x": -16,
      "y": 28,
      "z": 12,
      "name": "Rock_Ice_Permafrost"
    },
    {
      "x": -16,
      "y": 29,
      "z": 12,
      "name": "Rock_Ice_Permafrost"
    },
    {
      "x": -16,
      "y": 30,
      "z": 12,
      "name": "Rock_Ice_Permafrost"
    },
    {
      "x": -16,
      "y": 31,
      "z": 12,
      "name": "Rock_Ice_Permafrost"
    },
    {
      "x": -16,
      "y": 32,
      "z": 12,
      "name": "Rock_Ice_Permafrost"
    },
    {
      "x": -16,
      "y": 33,
      "z": 12,
      "name": "Rock_Ice_Permafrost"
    },
    {
      "x": -16,
      "y": 34,
      "z": 12,
      "name": "Rock_Ice_Permafrost"
    },
    {
      "x": -16,
      "y": 35,
      "z": 12,
      "name": "Rock_Ice_Permafrost"
    },
    {
      "x": -16,
      "y": 36,
      "z": 12,
      "name": "Rock_Ice_Permafrost"
    },
    {
      "x": -16,
      "y": 37,
      "z": 12,
      "name": "Rock_Ice_Permafrost"
    },
    {
      "x": -16,
      "y": 38,
      "z": 12,
      "name": "Rock_Ice_Permafrost"
    },
    {
      "x": -16,
      "y": 39,
      "z": 12,
      "name": "Rock_Ice_Permafrost"
    },
    {
      "x": -16,
      "y": 40,
      "z": 12,
      "name": "Rock_Ice_Permafrost"
    },
    {
      "x": -16,
      "y": 41,
      "z": 12,
      "name": "Rock_Ice_Permafrost"
    },
    {
      "x": -16,
      "y": 42,
      "z": 12,
      "name": "Rock_Ice_Permafrost"
    },
    {
      "x": -16,
      "y": 43,
      "z": 12,
      "name": "Rock_Ice_Permafrost"
    },
    {
      "x": -16,
      "y": 44,
      "z": 12,
      "name": "Rock_Ice_Permafrost"
    },
    {
      "x": -16,
      "y": 45,
      "z": 12,
      "name": "Rock_Ice_Permafrost"
    },
    {
      "x": -16,
      "y": 46,
      "z": 12,
      "name": "Rock_Ice"
    },
    {
      "x": -16,
      "y": 47,
      "z": 12,
      "name": "Rock_Ice"
    },
    {
      "x": -16,
      "y": 48,
      "z": 12,
      "name": "Rock_Ice"
    },
    {
      "x": -16,
      "y": 49,
      "z": 12,
      "name": "Rock_Ice"
    },
    {
      "x": -16,
      "y": 50,
      "z": 12,
      "name": "Rock_Ice"
    },
    {
      "x": -16,
      "y": 51,
      "z": 12,
      "name": "Rock_Ice"
    },
    {
      "x": -16,
      "y": 52,
      "z": 12,
      "name": "Rock_Ice"
    },
    {
