{
  "version": 8,
  "blockIdVersion": 11,
  "anchorX": 3,
  "anchorY": 16,
  "anchorZ": 0,
  "blocks": [
    {
      "x": -27,
      "y": 16,
      "z": -14,
      "name": "Soil_Snow"
    },
    {
      "x": -27,
      "y": 16,
      "z": -13,
      "name": "Rock_Ice"
    },
    {
      "x": -27,
      "y": 17,
      "z": -13,
      "name": "Soil_Snow"
    },
    {
      "x": -27,
      "y": 16,
      "z": -12,
      "name": "Rock_Ice_Permafrost"
    },
    {
      "x": -27,
      "y": 17,
      "z": -12,
      "name": "Rock_Ice"
    },
    {
      "x": -27,
      "y": 18,
      "z": -12,
      "name": "Soil_Snow"
    },
    {
      "x": -27,
      "y": 16,
      "z": -11,
      "name": "Rock_Ice_Permafrost"
    },
    {
      "x": -27,
      "y": 17,
      "z": -11,
      "name": "Rock_Ice"
    },
    {
      "x": -27,
      "y": 18,
      "z": -11,
      "name": "Soil_Snow"
    },
    {
      "x": -27,
      "y": 17,
      "z": -10,
      "name": "Soil_Snow"
    },
    {
      "x": -26,
      "y": 15,
      "z": -16,
      "name": "Rock_Ice"
    },
    {
      "x": -26,
      "y": 16,
      "z": -16,
      "name": "Soil_Snow"
    },
    {
      "x": -26,
      "y": 15,
      "z": -15,
      "name": "Rock_Ice_Permafrost"
    },
    {
      "x": -26,
      "y": 16,
      "z": -15,
      "name": "Rock_Ice"
    },
    {
      "x": -26,
      "y": 17,
      "z": -15,
      "name": "Soil_Snow"
    },
    {
      "x": -26,
      "y": 15,
      "z": -14,
      "name": "Rock_Ice_Permafrost"
    },
    {
      "x": -26,
      "y": 16,
      "z": -14,
      "name": "Rock_Ice_Permafrost"
    },
    {
      "x": -26,
      "y": 17,
      "z": -14,
      "name": "Rock_Ice"
    },
    {
      "x": -26,
      "y": 18,
      "z": -14,
      "name": "Soil_Snow"
    },
    {
      "x": -26,
      "y": 15,
      "z": -13,
      "name": "Rock_Ice_Permafrost"
    },
    {
      "x": -26,
      "y": 16,
      "z": -13,
      "name": "Rock_Ice_Permafrost"
    },
    {
      "x": -26,
      "y": 17,
      "z": -13,
      "name": "Rock_Ice"
    },
    {
      "x": -26,
      "y": 18,
      "z": -13,
      "name": "Soil_Snow"
    },
    {
      "x": -26,
      "y": 15,
      "z": -12,
      "name": "Rock_Ice_Permafrost"
    },
    {
      "x": -26,
      "y": 16,
      "z": -12,
      "name": "Rock_Ice_Permafrost"
    },
    {
      "x": -26,
      "y": 17,
      "z": -12,
      "name": "Rock_Ice_Permafrost"
    },
    {
      "x": -26,
      "y": 18,
      "z": -12,
      "name": "Rock_Ice"
    },
    {
      "x": -26,
      "y": 19,
      "z": -12,
      "name": "Soil_Snow"
    },
    {
      "x": -26,
      "y": 15,
      "z": -11,
      "name": "Rock_Ice_Permafrost"
    },
    {
      "x": -26,
      "y": 16,
      "z": -11,
      "name": "Rock_Ice_Permafrost"
    },
    {
      "x": -26,
      "y": 17,
      "z": -11,
      "name": "Rock_Ice_Permafrost"
    },
    {
      "x": -26,
      "y": 18,
      "z": -11,
      "name": "Rock_Ice"
    },
    {
      "x": -26,
      "y": 19,
      "z": -11,
      "name": "Soil_Snow"
    },
    {
      "x": -26,
      "y": 16,
      "z": -10,
      "name": "Rock_Ice_Permafrost"
    },
    {
      "x": -26,
      "y": 17,
      "z": -10,
      "name": "Rock_Ice_Permafrost"
    },
    {
      "x": -26,
      "y": 18,
      "z": -10,
      "name": "Rock_Ice"
    },
    {
      "x": -26,
      "y": 19,
      "z": -10,
      "name": "Soil_Snow"
    },
    {
      "x": -26,
      "y": 17,
      "z": -9,
      "name": "Rock_Ice_Permafrost"
    },
    {
      "x": -26,
      "y": 18,
      "z": -9,
      "name": "Rock_Ice"
    },
    {
      "x": -26,
      "y": 19,
      "z": -9,
      "name": "Soil_Snow"
    },
    {
      "x": -26,
      "y": 17,
      "z": -8,
      "name": "Rock_Ice"
    },
    {
      "x": -26,
      "y": 18,
      "z": -8,
      "name": "Soil_Snow"
    },
    {
      "x": -25,
      "y": 14,
      "z": -17,
      "name": "Rock_Ice_Permafrost"
    },
    {
      "x": -25,
      "y": 15,
      "z": -17,
      "name": "Rock_Ice"
    },
    {
      "x": -25,
      "y": 16,
      "z": -17,
      "name": "Soil_Snow"
    },
    {
      "x": -25,
      "y": 14,
      "z": -16,
      "name": "Rock_Ice_Permafrost"
    },
    {
      "x": -25,
      "y": 15,
      "z": -16,
      "name": "Rock_Ice_Permafrost"
    },
    {
      "x": -25,
      "y": 16,
      "z": -16,
      "name": "Rock_Ice"
    },
    {
      "x": -25,
      "y": 17,
      "z": -16,
      "name": "Soil_Snow"
    },
    {
      "x": -25,
      "y": 14,
      "z": -15,
      "name": "Rock_Ice_Permafrost"
    },
    {
      "x": -25,
      "y": 15,
      "z": -15,
      "name": "Rock_Ice_Permafrost"
    },
    {
      "x": -25,
      "y": 16,
      "z": -15,
      "name": "Rock_Ice_Permafrost"
    },
    {
      "x": -25,
      "y": 17,
      "z": -15,
      "name": "Rock_Ice"
    },
    {
      "x": -25,
      "y": 18,
      "z": -15,
      "name": "Soil_Snow"
    },
    {
      "x": -25,
      "y": 13,
      "z": -14,
      "name": "Rock_Ice"
    },
    {
      "x": -25,
      "y": 14,
      "z": -14,
      "name": "Rock_Ice_Permafrost"
    },
    {
      "x": -25,
      "y": 15,
      "z": -14,
      "name": "Rock_Ice_Permafrost"
    },
    {
      "x": -25,
      "y": 16,
      "z": -14,
      "name": "Rock_Ice_Permafrost"
    },
    {
      "x": -25,
      "y": 17,
      "z": -14,
      "name": "Rock_Ice_Permafrost"
    },
    {
      "x": -25,
      "y": 18,
      "z": -14,
      "name": "Rock_Ice"
    },
    {
      "x": -25,
      "y": 19,
      "z": -14,
      "name": "Soil_Snow"
    },
    {
      "x": -25,
      "y": 14,
      "z": -13,
      "name": "Rock_Ice"
    },
    {
      "x": -25,
      "y": 15,
      "z": -13,
      "name": "Rock_Ice_Permafrost"
    },
    {
      "x": -25,
      "y": 16,
      "z": -13,
      "name": "Rock_Ice_Permafrost"
    },
    {
      "x": -25,
      "y": 17,
      "z": -13,
      "name": "Rock_Ice_Permafrost"
    },
    {
      "x": -25,
      "y": 18,
      "z": -13,
      "name": "Rock_Ice"
    },
    {
      "x": -25,
      "y": 19,
      "z": -13,
      "name": "Soil_Snow"
    },
    {
      "x": -25,
      "y": 14,
      "z": -12,
      "name": "Rock_Ice_Permafrost"
    },
    {
      "x": -25,
      "y": 15,
      "z": -12,
      "name": "Rock_Ice_Permafrost"
    },
    {
      "x": -25,
      "y": 16,
      "z": -12,
      "name": "Rock_Ice_Permafrost"
    },
    {
      "x": -25,
      "y": 17,
      "z": -12,
      "name": "Rock_Ice_Permafrost"
    },
    {
      "x": -25,
      "y": 18,
      "z": -12,
      "name": "Rock_Ice_Permafrost"
    },
    {
      "x": -25,
      "y": 19,
      "z": -12,
      "name": "Rock_Ice"
    },
    {
      "x": -25,
      "y": 20,
      "z": -12,
      "name": "Soil_Snow"
    },
    {
      "x": -25,
      "y": 14,
      "z": -11,
      "name": "Rock_Ice_Permafrost"
    },
    {
      "x": -25,
      "y": 15,
      "z": -11,
      "name": "Rock_Ice_Permafrost"
    },
    {
      "x": -25,
      "y": 16,
      "z": -11,
      "name": "Rock_Ice_Permafrost"
    },
    {
      "x": -25,
      "y": 17,
      "z": -11,
      "name": "Rock_Ice_Permafrost"
    },
    {
      "x": -25,
      "y": 18,
      "z": -11,
      "name": "Rock_Ice_Permafrost"
    },
    {
      "x": -25,
      "y": 19,
      "z": -11,
      "name": "Rock_Ice"
    },
    {
      "x": -25,
      "y": 20,
      "z": -11,
      "name": "Soil_Snow"
    },
    {
      "x": -25,
      "y": 15,
      "z": -10,
      "name": "Rock_Ice_Permafrost"
    },
    {
      "x": -25,
      "y": 16,
      "z": -10,
      "name": "Rock_Ice_Permafrost"
    },
    {
      "x": -25,
      "y": 17,
      "z": -10,
      "name": "Rock_Ice_Permafrost"
    },
    {
      "x": -25,
      "y": 18,
      "z": -10,
      "name": "Rock_Ice_Permafrost"
    },
    {
      "x": -25,
      "y": 19,
      "z": -10,
      "name": "Rock_Ice"
    },
    {
      "x": -25,
      "y": 20,
      "z": -10,
      "name": "Soil_Snow"
    },
    {
      "x": -25,
      "y": 16,
      "z": -9,
      "name": "Rock_Ice_Permafrost"
    },
    {
      "x": -25,
      "y": 17,
      "z": -9,
      "name": "Rock_Ice_Permafrost"
    },
    {
      "x": -25,
      "y": 18,
      "z": -9,
      "name": "Rock_Ice_Permafrost"
    },
    {
      "x": -25,
      "y": 19,
      "z": -9,
      "name": "Rock_Ice"
    },
    {
      "x": -25,
      "y": 20,
      "z": -9,
      "name": "Rock_Ice"
    },
    {
      "x": -25,
      "y": 21,
      "z": -9,
      "name": "Soil_Snow"
    },
    {
      "x": -25,
      "y": 16,
      "z": -8,
      "name": "Rock_Ice_Permafrost"
    },
    {
      "x": -25,
      "y": 17,
      "z": -8,
      "name": "Rock_Ice_Permafrost"
    },
    {
      "x": -25,
      "y": 18,
      "z": -8,
      "name": "Rock_Ice_Permafrost"
    },
    {
      "x": -25,
      "y": 19,
      "z": -8,
      "name": "Rock_Ice"
    },
    {
      "x": -25,
      "y": 20,
      "z": -8,
      "name": "Soil_Snow"
    },
    {
      "x": -25,
      "y": 17,
      "z": -7,
      "name": "Rock_Ice_Permafrost"
    },
    {
      "x": -25,
      "y": 18,
      "z": -7,
      "name": "Rock_Ice"
    },
    {
      "x": -25,
      "y": 19,
      "z": -7,
      "name": "Soil_Snow"
    },
    {
      "x": -24,
      "y": 14,
      "z": -18,
      "name": "Rock_Ice"
    },
    {
      "x": -24,
      "y": 15,
      "z": -18,
      "name": "Soil_Snow"
    },
    {
      "x": -24,
      "y": 13,
      "z": -17,
      "name": "Rock_Ice_Permafrost"
    },
    {
      "x": -24,
      "y": 14,
      "z": -17,
      "name": "Rock_Ice_Permafrost"
    },
    {
      "x": -24,
      "y": 15,
      "z": -17,
      "name": "Rock_Ice_Permafrost"
    },
    {
      "x": -24,
      "y": 16,
      "z": -17,
      "name": "Rock_Ice"
    },
    {
      "x": -24,
      "y": 17,
      "z": -17,
      "name": "Soil_Snow"
    },
    {
      "x": -24,
      "y": 13,
      "z": -16,
      "name": "Rock_Ice"
    },
    {
      "x": -24,
      "y": 14,
      "z": -16,
      "name": "Rock_Ice_Permafrost"
    },
    {
      "x": -24,
      "y": 15,
      "z": -16,
      "name": "Rock_Ice_Permafrost"
    },
    {
      "x": -24,
      "y": 16,
      "z": -16,
      "name": "Rock_Ice_Permafrost"
    },
    {
      "x": -24,
      "y": 17,
      "z": -16,
      "name": "Rock_Ice"
    },
    {
      "x": -24,
      "y": 18,
      "z": -16,
      "name": "Soil_Snow"
    },
    {
      "x": -24,
      "y": 13,
      "z": -15,
      "name": "Rock_Ice"
    },
    {
      "x": -24,
      "y": 14,
      "z": -15,
      "name": "Rock_Ice_Permafrost"
    },
    {
      "x": -24,
      "y": 15,
      "z": -15,
      "name": "Rock_Ice_Permafrost"
    },
    {
      "x": -24,
      "y": 16,
      "z": -15,
      "name": "Rock_Ice_Permafrost"
    },
    {
      "x": -24,
      "y": 17,
      "z": -15,
      "name": "Rock_Ice_Permafrost"
    },
    {
      "x": -24,
      "y": 18,
      "z": -15,
      "name": "Rock_Ice"
    },
    {
      "x": -24,
      "y": 19,
      "z": -15,
      "name": "Soil_Snow"
    },
    {
      "x": -24,
      "y": 13,
      "z": -14,
      "name": "Rock_Ice_Permafrost"
    },
    {
      "x": -24,
      "y": 14,
      "z": -14,
      "name": "Rock_Ice_Permafrost"
    },
    {
      "x": -24,
      "y": 15,
      "z": -14,
      "name": "Rock_Ice_Permafrost"
    },
    {
      "x": -24,
      "y": 16,
      "z": -14,
      "name": "Rock_Ice_Permafrost"
    },
    {
      "x": -24,
      "y": 17,
      "z": -14,
      "name": "Rock_Ice_Permafrost"
    },
    {
      "x": -24,
      "y": 18,
      "z": -14,
      "name": "Rock_Ice_Permafrost"
    },
    {
      "x": -24,
      "y": 19,
      "z": -14,
      "name": "Rock_Ice"
    },
    {
      "x": -24,
      "y": 20,
      "z": -14,
      "name": "Soil_Snow"
    },
    {
      "x": -24,
      "y": 13,
      "z": -13,
      "name": "Rock_Ice"
    },
    {
      "x": -24,
      "y": 14,
      "z": -13,
      "name": "Rock_Ice_Permafrost"
    },
    {
      "x": -24,
      "y": 15,
      "z": -13,
      "name": "Rock_Ice_Permafrost"
    },
    {
      "x": -24,
      "y": 16,
      "z": -13,
      "name": "Rock_Ice_Permafrost"
    },
    {
      "x": -24,
      "y": 17,
      "z": -13,
      "name": "Rock_Ice_Permafrost"
    },
    {
      "x": -24,
      "y": 18,
      "z": -13,
      "name": "Rock_Ice_Permafrost"
    },
    {
      "x": -24,
      "y": 19,
      "z": -13,
      "name": "Rock_Ice"
    },
    {
      "x": -24,
      "y": 20,
      "z": -13,
      "name": "Soil_Snow"
    },
    {
      "x": -24,
      "y": 13,
      "z": -12,
      "name": "Rock_Ice_Permafrost"
    },
    {
      "x": -24,
      "y": 14,
      "z": -12,
      "name": "Rock_Ice_Permafrost"
    },
    {
      "x": -24,
      "y": 15,
      "z": -12,
      "name": "Rock_Ice_Permafrost"
    },
    {
      "x": -24,
      "y": 16,
      "z": -12,
      "name": "Rock_Ice_Permafrost"
    },
    {
      "x": -24,
      "y": 17,
      "z": -12,
      "name": "Rock_Ice_Permafrost"
    },
    {
      "x": -24,
      "y": 18,
      "z": -12,
      "name": "Rock_Ice_Permafrost"
    },
    {
      "x": -24,
      "y": 19,
      "z": -12,
      "name": "Rock_Ice"
    },
    {
      "x": -24,
      "y": 20,
      "z": -12,
      "name": "Soil_Snow"
    },
    {
      "x": -24,
      "y": 13,
      "z": -11,
      "name": "Rock_Ice"
    },
    {
      "x": -24,
      "y": 14,
      "z": -11,
      "name": "Rock_Ice"
    },
    {
      "x": -24,
      "y": 15,
      "z": -11,
      "name": "Rock_Ice_Permafrost"
    },
    {
      "x": -24,
      "y": 16,
      "z": -11,
      "name": "Rock_Ice_Permafrost"
    },
    {
      "x": -24,
      "y": 17,
      "z": -11,
      "name": "Rock_Ice_Permafrost"
    },
    {
      "x": -24,
      "y": 18,
      "z": -11,
      "name": "Rock_Ice_Permafrost"
    },
    {
      "x": -24,
      "y": 19,
      "z": -11,
      "name": "Rock_Ice_Permafrost"
    },
    {
      "x": -24,
      "y": 20,
      "z": -11,
      "name": "Rock_Ice"
    },
    {
      "x": -24,
      "y": 21,
      "z": -11,
      "name": "Soil_Snow"
    },
    {
      "x": -24,
      "y": 14,
      "z": -10,
      "name": "Rock_Ice_Permafrost"
    },
    {
      "x": -24,
      "y": 15,
      "z": -10,
      "name": "Rock_Ice_Permafrost"
    },
    {
      "x": -24,
      "y": 16,
      "z": -10,
      "name": "Rock_Ice_Permafrost"
    },
    {
      "x": -24,
      "y": 17,
      "z": -10,
      "name": "Rock_Ice_Permafrost"
    },
    {
      "x": -24,
      "y": 18,
      "z": -10,
      "name": "Rock_Ice_Permafrost"
    },
    {
      "x": -24,
      "y": 19,
      "z": -10,
      "name": "Rock_Ice_Permafrost"
    },
    {
      "x": -24,
      "y": 20,
      "z": -10,
      "name": "Rock_Ice"
    },
    {
      "x": -24,
      "y": 21,
      "z": -10,
      "name": "Soil_Snow"
    },
    {
      "x": -24,
      "y": 14,
      "z": -9,
      "name": "Rock_Ice_Permafrost"
    },
    {
      "x": -24,
      "y": 15,
      "z": -9,
      "name": "Rock_Ice_Permafrost"
    },
    {
      "x": -24,
      "y": 16,
      "z": -9,
      "name": "Rock_Ice_Permafrost"
    },
    {
      "x": -24,
      "y": 17,
      "z": -9,
      "name": "Rock_Ice_Permafrost"
    },
    {
      "x": -24,
      "y": 18,
      "z": -9,
      "name": "Rock_Ice_Permafrost"
    },
    {
      "x": -24,
      "y": 19,
      "z": -9,
      "name": "Rock_Ice_Permafrost"
    },
    {
      "x": -24,
      "y": 20,
      "z": -9,
      "name": "Rock_Ice"
    },
    {
      "x": -24,
      "y": 21,
      "z": -9,
      "name": "Soil_Snow"
    },
    {
      "x": -24,
      "y": 15,
      "z": -8,
      "name": "Rock_Ice_Permafrost"
    },
    {
      "x": -24,
      "y": 16,
      "z": -8,
      "name": "Rock_Ice_Permafrost"
    },
    {
      "x": -24,
      "y": 17,
      "z": -8,
      "name": "Rock_Ice_Permafrost"
    },
    {
      "x": -24,
      "y": 18,
      "z": -8,
      "name": "Rock_Ice_Permafrost"
    },
    {
      "x": -24,
      "y": 19,
      "z": -8,
      "name": "Rock_Ice_Permafrost"
    },
    {
      "x": -24,
      "y": 20,
      "z": -8,
      "name": "Rock_Ice"
    },
    {
      "x": -24,
      "y": 21,
      "z": -8,
      "name": "Soil_Snow"
    },
    {
      "x": -24,
      "y": 16,
      "z": -7,
      "name": "Rock_Ice_Permafrost"
    },
    {
      "x": -24,
      "y": 17,
      "z": -7,
      "name": "Rock_Ice_Permafrost"
    },
    {
      "x": -24,
      "y": 18,
      "z": -7,
      "name": "Rock_Ice_Permafrost"
    },
    {
      "x": -24,
      "y": 19,
      "z": -7,
      "name": "Rock_Ice_Permafrost"
    },
    {
      "x": -24,
      "y": 20,
      "z": -7,
      "name": "Rock_Ice"
    },
    {
      "x": -24,
      "y": 21,
      "z": -7,
      "name": "Soil_Snow"
    },
    {
      "x": -24,
      "y": 17,
      "z": -6,
      "name": "Rock_Ice_Permafrost"
    },
    {
      "x": -24,
      "y": 18,
      "z": -6,
      "name": "Rock_Ice_Permafrost"
    },
    {
      "x": -24,
      "y": 19,
      "z": -6,
      "name": "Rock_Ice"
    },
    {
      "x": -24,
      "y": 20,
      "z": -6,
      "name": "Soil_Snow"
    },
    {
      "x": -23,
      "y": 14,
      "z": -19,
      "name": "Rock_Ice"
    },
    {
      "x": -23,
      "y": 15,
      "z": -19,
      "name": "Soil_Snow"
    },
    {
      "x": -23,
      "y": 13,
      "z": -18,
      "name": "Rock_Ice_Permafrost"
    },
    {
      "x": -23,
      "y": 14,
      "z": -18,
      "name": "Rock_Ice_Permafrost"
    },
    {
      "x": -23,
      "y": 15,
      "z": -18,
      "name": "Rock_Ice"
    },
    {
      "x": -23,
      "y": 16,
      "z": -18,
      "name": "Soil_Snow"
    },
    {
      "x": -23,
      "y": 12,
      "z": -17,
      "name": "Rock_Ice"
    },
    {
      "x": -23,
      "y": 13,
      "z": -17,
      "name": "Rock_Ice"
    },
    {
      "x": -23,
      "y": 14,
      "z": -17,
      "name": "Rock_Ice_Permafrost"
    },
    {
      "x": -23,
      "y": 15,
      "z": -17,
      "name": "Rock_Ice_Permafrost"
    },
    {
      "x": -23,
      "y": 16,
      "z": -17,
      "name": "Rock_Ice_Permafrost"
    },
    {
      "x": -23,
      "y": 17,
      "z": -17,
      "name": "Rock_Ice"
    },
    {
      "x": -23,
      "y": 18,
      "z": -17,
      "name": "Soil_Snow"
    },
    {
      "x": -23,
      "y": 12,
      "z": -16,
      "name": "Rock_Ice"
    },
    {
      "x": -23,
      "y": 13,
      "z": -16,
      "name": "Rock_Ice_Permafrost"
    },
    {
      "x": -23,
      "y": 14,
      "z": -16,
      "name": "Rock_Ice_Permafrost"
    },
    {
      "x": -23,
      "y": 15,
      "z": -16,
      "name": "Rock_Ice_Permafrost"
    },
    {
      "x": -23,
      "y": 16,
      "z": -16,
      "name": "Rock_Ice_Permafrost"
    },
    {
      "x": -23,
      "y": 17,
      "z": -16,
      "name": "Rock_Ice_Permafrost"
    },
    {
      "x": -23,
      "y": 18,
      "z": -16,
      "name": "Rock_Ice"
    },
    {
      "x": -23,
      "y": 19,
      "z": -16,
      "name": "Soil_Snow"
    },
    {
      "x": -23,
      "y": 11,
      "z": -15,
      "name": "Rock_Ice"
    },
    {
      "x": -23,
      "y": 12,
      "z": -15,
      "name": "Rock_Ice"
    },
    {
      "x": -23,
      "y": 13,
      "z": -15,
      "name": "Rock_Ice_Permafrost"
    },
    {
      "x": -23,
      "y": 14,
      "z": -15,
      "name": "Rock_Ice_Permafrost"
    },
    {
      "x": -23,
      "y": 15,
      "z": -15,
      "name": "Rock_Ice_Permafrost"
    },
    {
      "x": -23,
      "y": 16,
      "z": -15,
      "name": "Rock_Ice_Permafrost"
    },
    {
      "x": -23,
      "y": 17,
      "z": -15,
      "name": "Rock_Ice_Permafrost"
    },
    {
      "x": -23,
      "y": 18,
      "z": -15,
      "name": "Rock_Ice"
    },
    {
      "x": -23,
      "y": 19,
      "z": -15,
      "name": "Soil_Snow"
    },
    {
      "x": -23,
      "y": 11,
      "z": -14,
      "name": "Rock_Ice"
    },
    {
      "x": -23,
      "y": 12,
      "z": -14,
      "name": "Rock_Ice"
    },
    {
      "x": -23,
      "y": 13,
      "z": -14,
      "name": "Rock_Ice_Permafrost"
    },
    {
      "x": -23,
      "y": 14,
      "z": -14,
      "name": "Rock_Ice_Permafrost"
    },
    {
      "x": -23,
      "y": 15,
      "z": -14,
      "name": "Rock_Ice_Permafrost"
    },
    {
      "x": -23,
      "y": 16,
      "z": -14,
      "name": "Rock_Ice_Permafrost"
    },
    {
      "x": -23,
      "y": 17,
      "z": -14,
      "name": "Rock_Ice_Permafrost"
    },
    {
      "x": -23,
      "y": 18,
      "z": -14,
      "name": "Rock_Ice_Permafrost"
    },
    {
      "x": -23,
      "y": 19,
      "z": -14,
      "name": "Rock_Ice"
    },
    {
      "x": -23,
      "y": 20,
      "z": -14,
      "name": "Soil_Snow"
    },
    {
      "x": -23,
      "y": 12,
      "z": -13,
      "name": "Rock_Ice"
    },
    {
      "x": -23,
      "y": 13,
      "z": -13,
      "name": "Rock_Ice_Permafrost"
    },
    {
      "x": -23,
      "y": 14,
      "z": -13,
      "name": "Rock_Ice"
    },
    {
      "x": -23,
      "y": 15,
      "z": -13,
      "name": "Rock_Ice_Permafrost"
    },
    {
      "x": -23,
      "y": 16,
      "z": -13,
      "name": "Rock_Ice_Permafrost"
    },
    {
      "x": -23,
      "y": 17,
      "z": -13,
      "name": "Rock_Ice_Permafrost"
    },
    {
      "x": -23,
      "y": 18,
      "z": -13,
      "name": "Rock_Ice_Permafrost"
    },
    {
      "x": -23,
      "y": 19,
      "z": -13,
      "name": "Rock_Ice_Permafrost"
    },
    {
      "x": -23,
      "y": 20,
      "z": -13,
      "name": "Rock_Ice"
    },
    {
      "x": -23,
      "y": 21,
      "z": -13,
      "name": "Soil_Snow"
    },
    {
      "x": -23,
      "y": 12,
      "z": -12,
      "name": "Rock_Ice"
    },
    {
      "x": -23,
      "y": 13,
      "z": -12,
      "name": "Rock_Ice"
    },
    {
      "x": -23,
      "y": 14,
      "z": -12,
      "name": "Rock_Ice_Permafrost"
    },
    {
      "x": -23,
      "y": 15,
      "z": -12,
      "name": "Rock_Ice_Permafrost"
    },
    {
      "x": -23,
      "y": 16,
      "z": -12,
      "name": "Rock_Ice_Permafrost"
    },
    {
      "x": -23,
      "y": 17,
      "z": -12,
      "name": "Rock_Ice_Permafrost"
    },
    {
      "x": -23,
      "y": 18,
      "z": -12,
      "name": "Rock_Ice_Permafrost"
    },
    {
      "x": -23,
      "y": 19,
      "z": -12,
      "name": "Rock_Ice_Permafrost"
    },
    {
      "x": -23,
      "y": 20,
      "z": -12,
      "name": "Rock_Ice"
    },
    {
      "x": -23,
      "y": 21,
      "z": -12,
      "name": "Soil_Snow"
    },
    {
      "x": -23,
      "y": 13,
      "z": -11,
      "name": "Rock_Ice"
    },
    {
      "x": -23,
      "y": 14,
      "z": -11,
      "name": "Rock_Ice_Permafrost"
    },
    {
      "x": -23,
      "y": 15,
      "z": -11,
      "name": "Rock_Ice_Permafrost"
    },
    {
      "x": -23,
      "y": 16,
      "z": -11,
      "name": "Rock_Ice_Permafrost"
    },
    {
      "x": -23,
      "y": 17,
      "z": -11,
      "name": "Rock_Ice_Permafrost"
    },
    {
      "x": -23,
      "y": 18,
      "z": -11,
      "name": "Rock_Ice_Permafrost"
    },
    {
      "x": -23,
      "y": 19,
      "z": -11,
      "name": "Rock_Ice_Permafrost"
    },
    {
      "x": -23,
      "y": 20,
      "z": -11,
      "name": "Rock_Ice"
    },
    {
      "x": -23,
      "y": 21,
      "z": -11,
      "name": "Soil_Snow"
    },
    {
      "x": -23,
      "y": 13,
      "z": -10,
      "name": "Rock_Ice"
    },
    {
      "x": -23,
      "y": 14,
      "z": -10,
      "name": "Rock_Ice_Permafrost"
    },
    {
      "x": -23,
      "y": 15,
      "z": -10,
      "name": "Rock_Ice_Permafrost"
    },
    {
      "x": -23,
      "y": 16,
      "z": -10,
      "name": "Rock_Ice_Permafrost"
    },
    {
      "x": -23,
      "y": 17,
      "z": -10,
      "name": "Rock_Ice_Permafrost"
    },
    {
      "x": -23,
      "y": 18,
      "z": -10,
      "name": "Rock_Ice_Permafrost"
    },
    {
      "x": -23,
      "y": 19,
      "z": -10,
      "name": "Rock_Ice_Permafrost"
    },
    {
      "x": -23,
      "y": 20,
      "z": -10,
      "name": "Rock_Ice"
    },
    {
      "x": -23,
      "y": 21,
      "z": -10,
      "name": "Soil_Snow"
    },
    {
      "x": -23,
      "y": 14,
      "z": -9,
      "name": "Rock_Ice_Permafrost"
    },
    {
      "x": -23,
      "y": 15,
      "z": -9,
      "name": "Rock_Ice_Permafrost"
    },
    {
      "x": -23,
      "y": 16,
      "z": -9,
      "name": "Rock_Ice_Permafrost"
    },
    {
      "x": -23,
      "y": 17,
      "z": -9,
      "name": "Rock_Ice_Permafrost"
    },
    {
      "x": -23,
      "y": 18,
      "z": -9,
      "name": "Rock_Ice_Permafrost"
    },
    {
      "x": -23,
      "y": 19,
      "z": -9,
      "name": "Rock_Ice_Permafrost"
    },
    {
      "x": -23,
      "y": 20,
      "z": -9,
      "name": "Rock_Ice"
    },
    {
      "x": -23,
      "y": 21,
      "z": -9,
      "name": "Rock_Ice"
    },
    {
      "x": -23,
      "y": 22,
      "z": -9,
      "name": "Soil_Snow"
    },
    {
      "x": -23,
      "y": 14,
      "z": -8,
      "name": "Rock_Ice_Permafrost"
    },
    {
      "x": -23,
      "y": 15,
      "z": -8,
      "name": "Rock_Ice_Permafrost"
    },
    {
      "x": -23,
      "y": 16,
      "z": -8,
      "name": "Rock_Ice_Permafrost"
    },
    {
      "x": -23,
      "y": 17,
      "z": -8,
      "name": "Rock_Ice_Permafrost"
    },
    {
      "x": -23,
      "y": 18,
      "z": -8,
      "name": "Rock_Ice_Permafrost"
    },
    {
      "x": -23,
      "y": 19,
      "z": -8,
      "name": "Rock_Ice_Permafrost"
    },
    {
      "x": -23,
      "y": 20,
      "z": -8,
      "name": "Rock_Ice_Permafrost"
    },
    {
      "x": -23,
      "y": 21,
      "z": -8,
      "name": "Rock_Ice"
    },
    {
      "x": -23,
      "y": 22,
      "z": -8,
      "name": "Soil_Snow"
    },
    {
      "x": -23,
      "y": 15,
      "z": -7,
      "name": "Rock_Ice_Permafrost"
    },
    {
      "x": -23,
      "y": 16,
      "z": -7,
      "name": "Rock_Ice_Permafrost"
    },
    {
      "x": -23,
      "y": 17,
      "z": -7,
      "name": "Rock_Ice_Permafrost"
    },
    {
      "x": -23,
      "y": 18,
      "z": -7,
      "name": "Rock_Ice_Permafrost"
    },
    {
      "x": -23,
      "y": 19,
      "z": -7,
      "name": "Rock_Ice_Permafrost"
    },
    {
      "x": -23,
      "y": 20,
      "z": -7,
      "name": "Rock_Ice_Permafrost"
    },
    {
      "x": -23,
      "y": 21,
      "z": -7,
      "name": "Rock_Ice"
    },
    {
      "x": -23,
      "y": 22,
      "z": -7,
      "name": "Soil_Snow"
    },
    {
      "x": -23,
      "y": 16,
      "z": -6,
      "name": "Rock_Ice_Permafrost"
    },
    {
      "x": -23,
      "y": 17,
      "z": -6,
      "name": "Rock_Ice_Permafrost"
    },
    {
      "x": -23,
      "y": 18,
      "z": -6,
      "name": "Rock_Ice_Permafrost"
    },
    {
      "x": -23,
      "y": 19,
      "z": -6,
      "name": "Rock_Ice_Permafrost"
    },
    {
      "x": -23,
      "y": 20,
      "z": -6,
      "name": "Rock_Ice_Permafrost"
    },
    {
      "x": -23,
      "y": 21,
      "z": -6,
      "name": "Rock_Ice"
    },
    {
      "x": -23,
      "y": 22,
      "z": -6,
      "name": "Soil_Snow"
    },
    {
      "x": -23,
      "y": 18,
      "z": -5,
      "name": "Rock_Ice_Permafrost"
    },
    {
      "x": -23,
      "y": 19,
      "z": -5,
      "name": "Rock_Ice_Permafrost"
    },
    {
      "x": -23,
      "y": 20,
      "z": -5,
      "name": "Rock_Ice"
    },
    {
      "x": -23,
      "y": 21,
      "z": -5,
      "name": "Soil_Snow"
    },
    {
      "x": -22,
      "y": 13,
      "z": -19,
      "name": "Rock_Ice_Permafrost"
    },
    {
      "x": -22,
      "y": 14,
      "z": -19,
      "name": "Rock_Ice_Permafrost"
    },
    {
      "x": -22,
      "y": 15,
      "z": -19,
      "name": "Rock_Ice"
    },
    {
      "x": -22,
      "y": 16,
      "z": -19,
      "name": "Rock_Ice_Permafrost"
    },
    {
      "x": -22,
      "y": 12,
      "z": -18,
      "name": "Rock_Ice"
    },
    {
      "x": -22,
      "y": 13,
      "z": -18,
      "name": "Rock_Ice"
    },
    {
      "x": -22,
      "y": 14,
      "z": -18,
      "name": "Rock_Ice_Permafrost"
    },
    {
      "x": -22,
      "y": 15,
      "z": -18,
      "name": "Rock_Ice_Permafrost"
    },
    {
      "x": -22,
      "y": 16,
      "z": -18,
      "name": "Rock_Ice"
    },
    {
      "x": -22,
      "y": 17,
      "z": -18,
      "name": "Soil_Snow"
    },
    {
      "x": -22,
      "y": 11,
      "z": -17,
      "name": "Rock_Ice"
    },
    {
      "x": -22,
      "y": 12,
      "z": -17,
      "name": "Rock_Ice"
    },
    {
      "x": -22,
      "y": 13,
      "z": -17,
      "name": "Rock_Ice_Permafrost"
    },
    {
      "x": -22,
      "y": 14,
      "z": -17,
      "name": "Rock_Ice_Permafrost"
    },
    {
      "x": -22,
      "y": 15,
      "z": -17,
      "name": "Rock_Ice_Permafrost"
    },
    {
      "x": -22,
      "y": 16,
      "z": -17,
      "name": "Rock_Ice_Permafrost"
    },
    {
      "x": -22,
      "y": 17,
      "z": -17,
      "name": "Rock_Ice"
    },
    {
      "x": -22,
      "y": 18,
      "z": -17,
      "name": "Soil_Snow"
    },
    {
      "x": -22,
      "y": 11,
      "z": -16,
      "name": "Rock_Ice"
    },
    {
      "x": -22,
      "y": 12,
      "z": -16,
      "name": "Rock_Ice"
    },
    {
      "x": -22,
      "y": 13,
      "z": -16,
      "name": "Rock_Ice"
    },
    {
      "x": -22,
      "y": 14,
      "z": -16,
      "name": "Rock_Ice"
    },
    {
      "x": -22,
      "y": 15,
      "z": -16,
      "name": "Rock_Ice_Permafrost"
    },
    {
      "x": -22,
      "y": 16,
      "z": -16,
      "name": "Rock_Ice_Permafrost"
    },
    {
      "x": -22,
      "y": 17,
      "z": -16,
      "name": "Rock_Ice_Permafrost"
    },
    {
      "x": -22,
      "y": 18,
      "z": -16,
      "name": "Rock_Ice"
    },
    {
      "x": -22,
      "y": 19,
      "z": -16,
      "name": "Soil_Snow"
    },
    {
      "x": -22,
      "y": 10,
      "z": -15,
      "name": "Rock_Ice"
    },
    {
      "x": -22,
      "y": 11,
      "z": -15,
      "name": "Rock_Ice"
    },
    {
      "x": -22,
      "y": 12,
      "z": -15,
      "name": "Rock_Ice"
    },
    {
      "x": -22,
      "y": 13,
      "z": -15,
      "name": "Rock_Ice"
    },
    {
      "x": -22,
      "y": 14,
      "z": -15,
      "name": "Rock_Ice"
    },
    {
      "x": -22,
      "y": 15,
      "z": -15,
      "name": "Rock_Ice_Permafrost"
    },
    {
      "x": -22,
      "y": 16,
      "z": -15,
      "name": "Rock_Ice_Permafrost"
    },
    {
      "x": -22,
      "y": 17,
      "z": -15,
      "name": "Rock_Ice_Permafrost"
    },
    {
      "x": -22,
      "y": 18,
      "z": -15,
      "name": "Rock_Ice_Permafrost"
    },
    {
      "x": -22,
      "y": 19,
      "z": -15,
      "name": "Rock_Ice"
    },
    {
      "x": -22,
      "y": 20,
      "z": -15,
      "name": "Soil_Snow"
    },
    {
      "x": -22,
      "y": 11,
      "z": -14,
      "name": "Rock_Ice"
    },
    {
      "x": -22,
      "y": 12,
      "z": -14,
      "name": "Rock_Ice"
    },
    {
      "x": -22,
      "y": 13,
      "z": -14,
      "name": "Rock_Ice"
    },
    {
      "x": -22,
      "y": 14,
      "z": -14,
      "name": "Rock_Ice"
    },
    {
      "x": -22,
      "y": 15,
      "z": -14,
      "name": "Rock_Ice_Permafrost"
    },
    {
      "x": -22,
      "y": 16,
      "z": -14,
      "name": "Rock_Ice_Permafrost"
    },
    {
      "x": -22,
      "y": 17,
      "z": -14,
      "name": "Rock_Ice_Permafrost"
    },
    {
      "x": -22,
      "y": 18,
      "z": -14,
      "name": "Rock_Ice_Permafrost"
    },
    {
      "x": -22,
      "y": 19,
      "z": -14,
      "name": "Rock_Ice_Permafrost"
    },
    {
      "x": -22,
      "y": 20,
      "z": -14,
      "name": "Rock_Ice"
    },
    {
      "x": -22,
      "y": 21,
      "z": -14,
      "name": "Soil_Snow"
    },
    {
      "x": -22,
      "y": 11,
      "z": -13,
      "name": "Rock_Ice"
    },
    {
      "x": -22,
      "y": 12,
      "z": -13,
      "name": "Rock_Ice"
    },
    {
      "x": -22,
      "y": 13,
      "z": -13,
      "name": "Rock_Ice"
    },
    {
      "x": -22,
      "y": 14,
      "z": -13,
      "name": "Rock_Ice_Permafrost"
    },
    {
      "x": -22,
      "y": 15,
      "z": -13,
      "name": "Rock_Ice_Permafrost"
    },
    {
      "x": -22,
      "y": 16,
      "z": -13,
      "name": "Rock_Ice_Permafrost"
    },
    {
      "x": -22,
      "y": 17,
      "z": -13,
      "name": "Rock_Ice_Permafrost"
    },
    {
      "x": -22,
      "y": 18,
      "z": -13,
      "name": "Rock_Ice_Permafrost"
    },
    {
      "x": -22,
      "y": 19,
      "z": -13,
      "name": "Rock_Ice_Permafrost"
    },
    {
      "x": -22,
      "y": 20,
      "z": -13,
      "name": "Rock_Ice"
    },
    {
      "x": -22,
      "y": 21,
      "z": -13,
      "name": "Soil_Snow"
    },
    {
      "x": -22,
      "y": 11,
      "z": -12,
      "name": "Rock_Ice"
    },
    {
      "x": -22,
      "y": 12,
      "z": -12,
      "name": "Rock_Ice"
    },
    {
      "x": -22,
      "y": 13,
      "z": -12,
      "name": "Rock_Ice"
    },
    {
      "x": -22,
      "y": 14,
      "z": -12,
      "name": "Rock_Ice"
    },
    {
      "x": -22,
      "y": 15,
      "z": -12,
      "name": "Rock_Ice_Permafrost"
    },
    {
      "x": -22,
      "y": 16,
      "z": -12,
      "name": "Rock_Ice_Permafrost"
    },
    {
      "x": -22,
      "y": 17,
      "z": -12,
      "name": "Rock_Ice_Permafrost"
    },
    {
      "x": -22,
      "y": 18,
      "z": -12,
      "name": "Rock_Ice_Permafrost"
    },
    {
      "x": -22,
      "y": 19,
      "z": -12,
      "name": "Rock_Ice_Permafrost"
    },
    {
      "x": -22,
      "y": 20,
      "z": -12,
      "name": "Rock_Ice"
    },
    {
      "x": -22,
      "y": 21,
      "z": -12,
      "name": "Soil_Snow"
    },
    {
      "x": -22,
      "y": 12,
      "z": -11,
      "name": "Rock_Ice"
    },
    {
      "x": -22,
      "y": 13,
      "z": -11,
      "name": "Rock_Ice"
    },
    {
      "x": -22,
      "y": 14,
      "z": -11,
      "name": "Rock_Ice"
    },
    {
      "x": -22,
      "y": 15,
      "z": -11,
      "name": "Rock_Ice_Permafrost"
    },
    {
      "x": -22,
      "y": 16,
      "z": -11,
      "name": "Rock_Ice_Permafrost"
    },
    {
      "x": -22,
      "y": 17,
      "z": -11,
      "name": "Rock_Ice_Permafrost"
    },
    {
      "x": -22,
      "y": 18,
      "z": -11,
      "name": "Rock_Ice_Permafrost"
    },
    {
      "x": -22,
      "y": 19,
      "z": -11,
      "name": "Rock_Ice_Permafrost"
    },
    {
      "x": -22,
      "y": 20,
      "z": -11,
      "name": "Rock_Ice_Permafrost"
    },
    {
      "x": -22,
      "y": 21,
      "z": -11,
      "name": "Rock_Ice"
    },
    {
      "x": -22,
      "y": 22,
      "z": -11,
      "name": "Soil_Snow"
    },
    {
      "x": -22,
      "y": 12,
      "z": -10,
      "name": "Rock_Ice"
    },
    {
      "x": -22,
      "y": 13,
      "z": -10,
      "name": "Rock_Ice"
    },
    {
      "x": -22,
      "y": 14,
      "z": -10,
      "name": "Rock_Ice"
    },
    {
      "x": -22,
      "y": 15,
      "z": -10,
      "name": "Rock_Ice_Permafrost"
    },
    {
      "x": -22,
      "y": 16,
      "z": -10,
      "name": "Rock_Ice_Permafrost"
    },
    {
      "x": -22,
      "y": 17,
      "z": -10,
      "name": "Rock_Ice_Permafrost"
    },
    {
      "x": -22,
      "y": 18,
      "z": -10,
      "name": "Rock_Ice_Permafrost"
    },
    {
      "x": -22,
      "y": 19,
      "z": -10,
      "name": "Rock_Ice_Permafrost"
    },
    {
      "x": -22,
      "y": 20,
      "z": -10,
      "name": "Rock_Ice"
    },
    {
      "x": -22,
      "y": 21,
      "z": -10,
      "name": "Rock_Ice"
    },
    {
      "x": -22,
      "y": 22,
      "z": -10,
      "name": "Soil_Snow"
    },
    {
      "x": -22,
      "y": 13,
      "z": -9,
      "name": "Rock_Ice"
    },
    {
      "x": -22,
      "y": 14,
      "z": -9,
      "name": "Rock_Ice"
    },
    {
      "x": -22,
      "y": 15,
      "z": -9,
      "name": "Rock_Ice_Permafrost"
    },
    {
      "x": -22,
      "y": 16,
      "z": -9,
      "name": "Rock_Ice_Permafrost"
    },
    {
      "x": -22,
      "y": 17,
      "z": -9,
      "name": "Rock_Ice_Permafrost"
    },
    {
      "x": -22,
      "y": 18,
      "z": -9,
      "name": "Rock_Ice_Permafrost"
    },
    {
      "x": -22,
      "y": 19,
      "z": -9,
      "name": "Rock_Ice_Permafrost"
    },
    {
      "x": -22,
      "y": 20,
      "z": -9,
      "name": "Rock_Ice_Permafrost"
    },
    {
      "x": -22,
      "y": 21,
      "z": -9,
      "name": "Rock_Ice"
    },
    {
      "x": -22,
      "y": 22,
      "z": -9,
      "name": "Soil_Snow"
    },
    {
      "x": -22,
      "y": 13,
      "z": -8,
      "name": "Rock_Ice"
    },
    {
      "x": -22,
      "y": 14,
      "z": -8,
      "name": "Rock_Ice_Permafrost"
    },
    {
      "x": -22,
      "y": 15,
      "z": -8,
      "name": "Rock_Ice_Permafrost"
    },
    {
      "x": -22,
      "y": 16,
      "z": -8,
      "name": "Rock_Ice_Permafrost"
    },
    {
      "x": -22,
      "y": 17,
      "z": -8,
      "name": "Rock_Ice_Permafrost"
    },
    {
      "x": -22,
      "y": 18,
      "z": -8,
      "name": "Rock_Ice_Permafrost"
    },
    {
      "x": -22,
      "y": 19,
      "z": -8,
      "name": "Rock_Ice_Permafrost"
    },
    {
      "x": -22,
      "y": 20,
      "z": -8,
      "name": "Rock_Ice_Permafrost"
    },
    {
      "x": -22,
      "y": 21,
      "z": -8,
      "name": "Rock_Ice"
    },
    {
      "x": -22,
      "y": 22,
      "z": -8,
      "name": "Soil_Snow"
    },
    {
      "x": -22,
      "y": 14,
      "z": -7,
      "name": "Rock_Ice"
    },
    {
      "x": -22,
      "y": 15,
      "z": -7,
      "name": "Rock_Ice_Permafrost"
    },
    {
      "x": -22,
      "y": 16,
      "z": -7,
      "name": "Rock_Ice_Permafrost"
    },
    {
      "x": -22,
      "y": 17,
      "z": -7,
      "name": "Rock_Ice_Permafrost"
    },
    {
      "x": -22,
      "y": 18,
      "z": -7,
      "name": "Rock_Ice_Permafrost"
    },
    {
      "x": -22,
      "y": 19,
      "z": -7,
      "name": "Rock_Ice_Permafrost"
    },
    {
      "x": -22,
      "y": 20,
      "z": -7,
      "name": "Rock_Ice_Permafrost"
    },
    {
      "x": -22,
      "y": 21,
      "z": -7,
      "name": "Rock_Ice"
    },
    {
      "x": -22,
      "y": 22,
      "z": -7,
      "name": "Soil_Snow"
    },
    {
      "x": -22,
      "y": 15,
      "z": -6,
      "name": "Rock_Ice_Permafrost"
    },
    {
      "x": -22,
      "y": 16,
      "z": -6,
      "name": "Rock_Ice_Permafrost"
    },
    {
      "x": -22,
      "y": 17,
      "z": -6,
      "name": "Rock_Ice_Permafrost"
    },
    {
      "x": -22,
      "y": 18,
      "z": -6,
      "name": "Rock_Ice_Permafrost"
    },
    {
      "x": -22,
      "y": 19,
      "z": -6,
      "name": "Rock_Ice_Permafrost"
    },
    {
      "x": -22,
      "y": 20,
      "z": -6,
      "name": "Rock_Ice_Permafrost"
    },
    {
      "x": -22,
      "y": 21,
      "z": -6,
      "name": "Rock_Ice"
    },
    {
      "x": -22,
      "y": 22,
      "z": -6,
      "name": "Soil_Snow"
    },
    {
      "x": -22,
      "y": 17,
      "z": -5,
      "name": "Rock_Ice_Permafrost"
    },
    {
      "x": -22,
      "y": 18,
      "z": -5,
      "name": "Rock_Ice_Permafrost"
    },
    {
      "x": -22,
      "y": 19,
      "z": -5,
      "name": "Rock_Ice_Permafrost"
    },
    {
      "x": -22,
      "y": 20,
      "z": -5,
      "name": "Rock_Ice_Permafrost"
    },
    {
      "x": -22,
      "y": 21,
      "z": -5,
      "name": "Rock_Ice"
    },
    {
      "x": -22,
      "y": 22,
      "z": -5,
      "name": "Soil_Snow"
    },
    {
      "x": -22,
      "y": 18,
      "z": -4,
      "name": "Rock_Ice_Permafrost"
    },
    {
      "x": -22,
      "y": 19,
      "z": -4,
      "name": "Rock_Ice_Permafrost"
    },
    {
      "x": -22,
      "y": 20,
      "z": -4,
      "name": "Rock_Ice_Permafrost"
    },
    {
      "x": -22,
      "y": 21,
      "z": -4,
      "name": "Rock_Ice"
    },
    {
      "x": -22,
      "y": 22,
      "z": -4,
      "name": "Soil_Snow"
    },
    {
      "x": -21,
      "y": 14,
      "z": -20,
      "name": "Rock_Ice"
    },
    {
      "x": -21,
      "y": 15,
      "z": -20,
      "name": "Soil_Snow"
    },
    {
      "x": -21,
      "y": 12,
      "z": -19,
      "name": "Rock_Ice_Permafrost"
    },
    {
      "x": -21,
      "y": 13,
      "z": -19,
      "name": "Rock_Ice"
    },
    {
      "x": -21,
      "y": 14,
      "z": -19,
      "name": "Rock_Ice_Permafrost"
    },
    {
      "x": -21,
      "y": 15,
      "z": -19,
      "name": "Rock_Ice"
    },
    {
      "x": -21,
      "y": 16,
      "z": -19,
      "name": "Soil_Snow"
    },
    {
      "x": -21,
      "y": 11,
      "z": -18,
      "name": "Rock_Ice_Permafrost"
    },
    {
      "x": -21,
      "y": 12,
      "z": -18,
      "name": "Rock_Ice"
    },
    {
      "x": -21,
      "y": 13,
      "z": -18,
      "name": "Rock_Ice_Permafrost"
    },
    {
      "x": -21,
      "y": 14,
      "z": -18,
      "name": "Rock_Ice_Permafrost"
    },
    {
      "x": -21,
      "y": 15,
      "z": -18,
      "name": "Rock_Ice_Permafrost"
    },
    {
      "x": -21,
      "y": 16,
      "z": -18,
      "name": "Rock_Ice_Permafrost"
    },
    {
      "x": -21,
      "y": 17,
      "z": -18,
      "name": "Rock_Ice"
    },
    {
      "x": -21,
      "y": 18,
      "z": -18,
      "name": "Soil_Snow"
    },
    {
      "x": -21,
      "y": 10,
      "z": -17,
      "name": "Rock_Ice"
    },
    {
      "x": -21,
      "y": 11,
      "z": -17,
      "name": "Rock_Ice"
    },
    {
      "x": -21,
      "y": 12,
      "z": -17,
      "name": "Rock_Ice"
    },
    {
      "x": -21,
      "y": 13,
      "z": -17,
      "name": "Rock_Ice"
    },
    {
      "x": -21,
      "y": 14,
      "z": -17,
      "name": "Rock_Ice"
    },
    {
      "x": -21,
      "y": 15,
      "z": -17,
      "name": "Rock_Ice_Permafrost"
    },
    {
      "x": -21,
      "y": 16,
      "z": -17,
      "name": "Rock_Ice_Permafrost"
    },
    {
      "x": -21,
      "y": 17,
      "z": -17,
      "name": "Rock_Ice_Permafrost"
    },
    {
      "x": -21,
      "y": 18,
      "z": -17,
      "name": "Rock_Ice"
    },
    {
      "x": -21,
      "y": 19,
      "z": -17,
      "name": "Soil_Snow"
    },
    {
      "x": -21,
      "y": 10,
      "z": -16,
      "name": "Rock_Ice"
    },
    {
      "x": -21,
      "y": 11,
      "z": -16,
      "name": "Rock_Ice"
    },
    {
      "x": -21,
      "y": 12,
      "z": -16,
      "name": "Rock_Ice"
    },
    {
      "x": -21,
      "y": 13,
      "z": -16,
      "name": "Rock_Ice"
    },
    {
      "x": -21,
      "y": 14,
      "z": -16,
      "name": "Rock_Ice"
    },
    {
      "x": -21,
      "y": 15,
      "z": -16,
      "name": "Rock_Ice_Permafrost"
    },
    {
      "x": -21,
      "y": 16,
      "z": -16,
      "name": "Rock_Ice_Permafrost"
    },
    {
      "x": -21,
      "y": 17,
      "z": -16,
      "name": "Rock_Ice_Permafrost"
    },
    {
      "x": -21,
      "y": 18,
      "z": -16,
      "name": "Rock_Ice_Permafrost"
    },
    {
      "x": -21,
      "y": 19,
      "z": -16,
      "name": "Rock_Ice"
    },
    {
      "x": -21,
      "y": 20,
      "z": -16,
      "name": "Soil_Snow"
    },
    {
      "x": -21,
      "y": 10,
      "z": -15,
      "name": "Rock_Ice"
    },
    {
      "x": -21,
      "y": 11,
      "z": -15,
      "name": "Rock_Ice"
    },
    {
      "x": -21,
      "y": 12,
      "z": -15,
      "name": "Rock_Ice"
    },
    {
      "x": -21,
      "y": 13,
      "z": -15,
      "name": "Rock_Ice"
    },
    {
      "x": -21,
      "y": 14,
      "z": -15,
      "name": "Rock_Ice"
    },
    {
      "x": -21,
      "y": 15,
      "z": -15,
      "name": "Rock_Ice"
    },
    {
      "x": -21,
      "y": 16,
      "z": -15,
      "name": "Rock_Ice_Permafrost"
    },
    {
      "x": -21,
      "y": 17,
      "z": -15,
      "name": "Rock_Ice_Permafrost"
    },
    {
      "x": -21,
      "y": 18,
      "z": -15,
      "name": "Rock_Ice_Permafrost"
    },
    {
      "x": -21,
      "y": 19,
      "z": -15,
      "name": "Rock_Ice"
    },
    {
      "x": -21,
      "y": 20,
      "z": -15,
      "name": "Soil_Snow"
    },
    {
      "x": -21,
      "y": 10,
      "z": -14,
      "name": "Rock_Ice"
    },
    {
      "x": -21,
      "y": 11,
      "z": -14,
      "name": "Rock_Ice"
    },
    {
      "x": -21,
      "y": 12,
      "z": -14,
      "name": "Rock_Ice"
    },
    {
      "x": -21,
      "y": 13,
      "z": -14,
      "name": "Rock_Ice"
    },
    {
      "x": -21,
      "y": 14,
      "z": -14,
      "name": "Rock_Ice"
    },
    {
      "x": -21,
      "y": 15,
      "z": -14,
      "name": "Rock_Ice_Permafrost"
    },
    {
      "x": -21,
      "y": 16,
      "z": -14,
      "name": "Rock_Ice_Permafrost"
    },
    {
      "x": -21,
      "y": 17,
      "z": -14,
      "name": "Rock_Ice_Permafrost"
    },
    {
      "x": -21,
      "y": 18,
      "z": -14,
      "name": "Rock_Ice_Permafrost"
    },
    {
      "x": -21,
      "y": 19,
      "z": -14,
      "name": "Rock_Ice_Permafrost"
    },
    {
      "x": -21,
      "y": 20,
      "z": -14,
      "name": "Rock_Ice"
    },
    {
      "x": -21,
      "y": 21,
      "z": -14,
      "name": "Soil_Snow"
    },
    {
      "x": -21,
      "y": 10,
      "z": -13,
      "name": "Rock_Ice"
    },
    {
      "x": -21,
      "y": 11,
      "z": -13,
      "name": "Rock_Ice"
    },
    {
      "x": -21,
      "y": 12,
      "z": -13,
      "name": "Rock_Ice"
    },
    {
      "x": -21,
      "y": 13,
      "z": -13,
      "name": "Rock_Ice"
    },
    {
      "x": -21,
      "y": 14,
      "z": -13,
      "name": "Rock_Ice"
    },
    {
      "x": -21,
      "y": 15,
      "z": -13,
      "name": "Rock_Ice"
    },
    {
      "x": -21,
      "y": 16,
      "z": -13,
      "name": "Rock_Ice_Permafrost"
    },
    {
      "x": -21,
      "y": 17,
      "z": -13,
      "name": "Rock_Ice_Permafrost"
    },
    {
      "x": -21,
      "y": 18,
      "z": -13,
      "name": "Rock_Ice_Permafrost"
    },
    {
      "x": -21,
      "y": 19,
      "z": -13,
      "name": "Rock_Ice_Permafrost"
    },
    {
      "x": -21,
      "y": 20,
      "z": -13,
      "name": "Rock_Ice"
    },
    {
      "x": -21,
      "y": 21,
      "z": -13,
      "name": "Soil_Snow"
    },
    {
      "x": -21,
      "y": 10,
      "z": -12,
      "name": "Rock_Ice"
    },
    {
      "x": -21,
      "y": 11,
      "z": -12,
      "name": "Rock_Ice"
    },
    {
      "x": -21,
      "y": 12,
      "z": -12,
      "name": "Rock_Ice"
    },
    {
      "x": -21,
      "y": 13,
      "z": -12,
      "name": "Rock_Ice"
    },
    {
      "x": -21,
      "y": 14,
      "z": -12,
      "name": "Rock_Ice"
    },
    {
      "x": -21,
      "y": 15,
      "z": -12,
      "name": "Rock_Ice_Permafrost"
    },
    {
      "x": -21,
      "y": 16,
      "z": -12,
      "name": "Rock_Ice_Permafrost"
    },
    {
      "x": -21,
      "y": 17,
      "z": -12,
      "name": "Rock_Ice_Permafrost"
    },
    {
      "x": -21,
      "y": 18,
      "z": -12,
      "name": "Rock_Ice_Permafrost"
    },
    {
      "x": -21,
      "y": 19,
      "z": -12,
      "name": "Rock_Ice_Permafrost"
    },
    {
      "x": -21,
      "y": 20,
      "z": -12,
      "name": "Rock_Ice"
    },
    {
      "x": -21,
      "y": 21,
      "z": -12,
      "name": "Rock_Ice"
    },
    {
      "x": -21,
      "y": 22,
      "z": -12,
      "name": "Soil_Snow"
    },
    {
      "x": -21,
      "y": 11,
      "z": -11,
      "name": "Rock_Ice"
    },
    {
      "x": -21,
      "y": 12,
      "z": -11,
      "name": "Rock_Ice"
    },
    {
      "x": -21,
      "y": 13,
      "z": -11,
      "name": "Rock_Ice"
    },
    {
      "x": -21,
      "y": 14,
      "z": -11,
      "name": "Rock_Ice"
    },
    {
      "x": -21,
      "y": 15,
      "z": -11,
      "name": "Rock_Ice_Permafrost"
    },
    {
      "x": -21,
      "y": 16,
      "z": -11,
      "name": "Rock_Ice_Permafrost"
    },
    {
      "x": -21,
      "y": 17,
      "z": -11,
      "name": "Rock_Ice_Permafrost"
    },
    {
      "x": -21,
      "y": 18,
      "z": -11,
      "name": "Rock_Ice_Permafrost"
    },
    {
      "x": -21,
      "y": 19,
      "z": -11,
      "name": "Rock_Ice_Permafrost"
    },
    {
      "x": -21,
      "y": 20,
      "z": -11,
      "name": "Rock_Ice_Permafrost"
    },
    {
      "x": -21,
      "y": 21,
      "z": -11,
      "name": "Rock_Ice"
    },
    {
      "x": -21,
      "y": 22,
      "z": -11,
      "name": "Soil_Snow"
    },
    {
      "x": -21,
      "y": 11,
      "z": -10,
      "name": "Rock_Ice"
    },
    {
      "x": -21,
      "y": 12,
      "z": -10,
      "name": "Rock_Ice"
    },
    {
      "x": -21,
      "y": 13,
      "z": -10,
      "name": "Rock_Ice"
    },
    {
      "x": -21,
      "y": 14,
      "z": -10,
      "name": "Rock_Ice"
    },
    {
      "x": -21,
      "y": 15,
      "z": -10,
      "name": "Rock_Ice_Permafrost"
    },
    {
      "x": -21,
      "y": 16,
      "z": -10,
      "name": "Rock_Ice_Permafrost"
    },
    {
      "x": -21,
      "y": 17,
      "z": -10,
      "name": "Rock_Ice_Permafrost"
    },
    {
      "x": -21,
      "y": 18,
      "z": -10,
      "name": "Rock_Ice_Permafrost"
    },
    {
      "x": -21,
      "y": 19,
      "z": -10,
      "name": "Rock_Ice_Permafrost"
    },
    {
      "x": -21,
      "y": 20,
      "z": -10,
      "name": "Rock_Ice_Permafrost"
    },
    {
      "x": -21,
      "y": 21,
      "z": -10,
      "name": "Rock_Ice"
    },
    {
      "x": -21,
      "y": 22,
      "z": -10,
      "name": "Soil_Snow"
    },
    {
      "x": -21,
      "y": 12,
      "z": -9,
      "name": "Rock_Ice"
    },
    {
      "x": -21,
      "y": 13,
      "z": -9,
      "name": "Rock_Ice"
    },
    {
      "x": -21,
      "y": 14,
      "z": -9,
      "name": "Rock_Ice"
    },
    {
      "x": -21,
      "y": 15,
      "z": -9,
      "name": "Rock_Ice_Permafrost"
    },
    {
      "x": -21,
      "y": 16,
      "z": -9,
      "name": "Rock_Ice_Permafrost"
    },
    {
      "x": -21,
      "y": 17,
      "z": -9,
      "name": "Rock_Ice_Permafrost"
    },
    {
      "x": -21,
      "y": 18,
      "z": -9,
      "name": "Rock_Ice_Permafrost"
    },
    {
      "x": -21,
      "y": 19,
      "z": -9,
      "name": "Rock_Ice_Permafrost"
    },
    {
      "x": -21,
      "y": 20,
      "z": -9,
      "name": "Rock_Ice_Permafrost"
    },
    {
      "x": -21,
      "y": 21,
      "z": -9,
      "name": "Rock_Ice"
    },
    {
      "x": -21,
      "y": 22,
      "z": -9,
      "name": "Soil_Snow"
    },
    {
      "x": -21,
      "y": 13,
      "z": -8,
      "name": "Rock_Ice"
    },
    {
      "x": -21,
      "y": 14,
      "z": -8,
      "name": "Rock_Ice"
    },
    {
      "x": -21,
      "y": 15,
      "z": -8,
      "name": "Rock_Ice_Permafrost"
    },
    {
      "x": -21,
      "y": 16,
      "z": -8,
      "name": "Rock_Ice_Permafrost"
    },
    {
      "x": -21,
      "y": 17,
      "z": -8,
      "name": "Rock_Ice_Permafrost"
    },
    {
      "x": -21,
      "y": 18,
      "z": -8,
      "name": "Rock_Ice_Permafrost"
    },
    {
      "x": -21,
      "y": 19,
      "z": -8,
      "name": "Rock_Ice_Permafrost"
    },
    {
      "x": -21,
      "y": 20,
      "z": -8,
      "name": "Rock_Ice_Permafrost"
    },
    {
      "x": -21,
      "y": 21,
      "z": -8,
      "name": "Rock_Ice"
    },
    {
      "x": -21,
      "y": 22,
      "z": -8,
      "name": "Soil_Snow"
    },
    {
      "x": -21,
      "y": 13,
      "z": -7,
      "name": "Rock_Ice"
    },
    {
      "x": -21,
      "y": 14,
      "z": -7,
      "name": "Rock_Ice"
    },
    {
      "x": -21,
      "y": 15,
      "z": -7,
      "name": "Rock_Ice_Permafrost"
    },
    {
      "x": -21,
      "y": 16,
      "z": -7,
      "name": "Rock_Ice_Permafrost"
    },
    {
      "x": -21,
      "y": 17,
      "z": -7,
      "name": "Rock_Ice_Permafrost"
    },
    {
      "x": -21,
      "y": 18,
      "z": -7,
      "name": "Rock_Ice_Permafrost"
    },
    {
      "x": -21,
      "y": 19,
      "z": -7,
      "name": "Rock_Ice_Permafrost"
    },
    {
      "x": -21,
      "y": 20,
      "z": -7,
      "name": "Rock_Ice_Permafrost"
    },
    {
      "x": -21,
      "y": 21,
      "z": -7,
      "name": "Rock_Ice_Permafrost"
    },
    {
      "x": -21,
      "y": 22,
      "z": -7,
      "name": "Rock_Ice"
    },
    {
      "x": -21,
      "y": 23,
      "z": -7,
      "name": "Rock_Ice_Permafrost"
    },
    {
      "x": -21,
      "y": 14,
      "z": -6,
      "name": "Rock_Ice"
    },
    {
      "x": -21,
      "y": 15,
      "z": -6,
      "name": "Rock_Ice_Permafrost"
    },
    {
      "x": -21,
      "y": 16,
      "z": -6,
      "name": "Rock_Ice_Permafrost"
    },
    {
      "x": -21,
      "y": 17,
      "z": -6,
      "name": "Rock_Ice_Permafrost"
    },
    {
      "x": -21,
      "y": 18,
      "z": -6,
      "name": "Rock_Ice_Permafrost"
    },
    {
      "x": -21,
      "y": 19,
      "z": -6,
      "name": "Rock_Ice_Permafrost"
    },
    {
      "x": -21,
      "y": 20,
      "z": -6,
      "name": "Rock_Ice_Permafrost"
    },
    {
      "x": -21,
      "y": 21,
      "z": -6,
      "name": "Rock_Ice_Permafrost"
    },
    {
      "x": -21,
      "y": 22,
      "z": -6,
      "name": "Rock_Ice"
    },
    {
      "x": -21,
      "y": 23,
      "z": -6,
      "name": "Soil_Snow"
    },
    {
      "x": -21,
      "y": 15,
      "z": -5,
      "name": "Rock_Ice_Permafrost"
    },
    {
      "x": -21,
      "y": 16,
      "z": -5,
      "name": "Rock_Ice_Permafrost"
    },
    {
      "x": -21,
      "y": 17,
      "z": -5,
      "name": "Rock_Ice_Permafrost"
    },
    {
      "x": -21,
      "y": 18,
      "z": -5,
      "name": "Rock_Ice_Permafrost"
    },
    {
      "x": -21,
      "y": 19,
      "z": -5,
      "name": "Rock_Ice_Permafrost"
    },
    {
      "x": -21,
      "y": 20,
      "z": -5,
      "name": "Rock_Ice_Permafrost"
    },
    {
      "x": -21,
      "y": 21,
      "z": -5,
      "name": "Rock_Ice_Permafrost"
    },
    {
      "x": -21,
      "y": 22,
      "z": -5,
      "name": "Rock_Ice"
    },
    {
      "x": -21,
      "y": 23,
      "z": -5,
      "name": "Soil_Snow"
    },
    {
      "x": -21,
      "y": 17,
      "z": -4,
      "name": "Rock_Ice_Permafrost"
    },
    {
      "x": -21,
      "y": 18,
      "z": -4,
      "name": "Rock_Ice_Permafrost"
    },
    {
      "x": -21,
      "y": 19,
      "z": -4,
      "name": "Rock_Ice_Permafrost"
    },
    {
      "x": -21,
      "y": 20,
      "z": -4,
      "name": "Rock_Ice_Permafrost"
    },
    {
      "x": -21,
      "y": 21,
      "z": -4,
      "name": "Rock_Ice"
    },
    {
      "x": -21,
      "y": 22,
      "z": -4,
      "name": "Rock_Ice"
    },
    {
      "x": -21,
      "y": 23,
      "z": -4,
      "name": "Soil_Snow"
    },
    {
      "x": -21,
      "y": 18,
      "z": -3,
      "name": "Rock_Ice_Permafrost"
    },
    {
      "x": -21,
      "y": 19,
      "z": -3,
      "name": "Rock_Ice_Permafrost"
    },
    {
      "x": -21,
      "y": 20,
      "z": -3,
      "name": "Rock_Ice_Permafrost"
    },
    {
      "x": -21,
      "y": 21,
      "z": -3,
      "name": "Rock_Ice"
    },
    {
      "x": -21,
      "y": 22,
      "z": -3,
      "name": "Soil_Snow"
    },
    {
      "x": -20,
      "y": 13,
      "z": -20,
      "name": "Rock_Ice_Permafrost"
    },
    {
      "x": -20,
      "y": 14,
      "z": -20,
      "name": "Rock_Ice_Permafrost"
    },
    {
      "x": -20,
      "y": 15,
      "z": -20,
      "name": "Rock_Ice"
    },
    {
      "x": -20,
      "y": 16,
      "z": -20,
      "name": "Soil_Snow"
    },
    {
      "x": -20,
      "y": 11,
      "z": -19,
      "name": "Rock_Ice"
    },
    {
      "x": -20,
      "y": 12,
      "z": -19,
      "name": "Rock_Ice_Permafrost"
    },
    {
      "x": -20,
      "y": 13,
      "z": -19,
      "name": "Rock_Ice"
    },
    {
      "x": -20,
      "y": 14,
      "z": -19,
      "name": "Rock_Ice_Permafrost"
    },
    {
      "x": -20,
      "y": 15,
      "z": -19,
      "name": "Rock_Ice_Permafrost"
    },
    {
      "x": -20,
      "y": 16,
      "z": -19,
      "name": "Rock_Ice"
    },
    {
      "x": -20,
      "y": 17,
      "z": -19,
      "name": "Soil_Snow"
    },
    {
      "x": -20,
      "y": 10,
      "z": -18,
      "name": "Rock_Ice_Permafrost"
    },
    {
      "x": -20,
      "y": 11,
      "z": -18,
      "name": "Rock_Ice"
    },
    {
      "x": -20,
      "y": 12,
      "z": -18,
      "name": "Rock_Ice"
    },
    {
      "x": -20,
      "y": 13,
      "z": -18,
      "name": "Rock_Ice"
    },
    {
      "x": -20,
      "y": 14,
      "z": -18,
      "name": "Rock_Ice"
    },
    {
      "x": -20,
      "y": 15,
      "z": -18,
      "name": "Rock_Ice_Permafrost"
    },
    {
      "x": -20,
      "y": 16,
      "z": -18,
      "name": "Rock_Ice_Permafrost"
    },
    {
      "x": -20,
      "y": 17,
      "z": -18,
      "name": "Rock_Ice"
    },
    {
      "x": -20,
      "y": 18,
      "z": -18,
      "name": "Soil_Snow"
    },
    {
      "x": -20,
      "y": 9,
      "z": -17,
      "name": "Rock_Ice"
    },
    {
      "x": -20,
      "y": 10,
      "z": -17,
      "name": "Rock_Ice"
    },
    {
      "x": -20,
      "y": 11,
      "z": -17,
      "name": "Rock_Ice"
    },
    {
      "x": -20,
      "y": 12,
      "z": -17,
      "name": "Rock_Ice"
    },
    {
      "x": -20,
      "y": 13,
      "z": -17,
      "name": "Rock_Ice_Permafrost"
    },
    {
      "x": -20,
      "y": 14,
      "z": -17,
      "name": "Rock_Ice"
    },
    {
      "x": -20,
      "y": 15,
      "z": -17,
      "name": "Rock_Ice"
    },
    {
      "x": -20,
      "y": 16,
      "z": -17,
      "name": "Rock_Ice_Permafrost"
    },
    {
      "x": -20,
      "y": 17,
      "z": -17,
      "name": "Rock_Ice_Permafrost"
    },
    {
      "x": -20,
      "y": 18,
      "z": -17,
      "name": "Rock_Ice"
    },
    {
      "x": -20,
      "y": 19,
      "z": -17,
      "name": "Soil_Snow"
    },
    {
      "x": -20,
      "y": 9,
      "z": -16,
      "name": "Rock_Ice"
    },
    {
      "x": -20,
      "y": 10,
      "z": -16,
      "name": "Rock_Ice"
    },
    {
      "x": -20,
      "y": 11,
      "z": -16,
      "name": "Rock_Ice"
    },
    {
      "x": -20,
      "y": 12,
      "z": -16,
      "name": "Rock_Ice"
    },
    {
      "x": -20,
      "y": 13,
      "z": -16,
      "name": "Rock_Ice"
    },
    {
      "x": -20,
      "y": 14,
      "z": -16,
      "name": "Rock_Ice_Permafrost"
    },
    {
      "x": -20,
      "y": 15,
      "z": -16,
      "name": "Rock_Ice_Permafrost"
    },
    {
      "x": -20,
      "y": 16,
      "z": -16,
      "name": "Rock_Ice_Permafrost"
    },
    {
      "x": -20,
      "y": 17,
      "z": -16,
      "name": "Rock_Ice_Permafrost"
    },
    {
      "x": -20,
      "y": 18,
      "z": -16,
      "name": "Rock_Ice_Permafrost"
    },
    {
      "x": -20,
      "y": 19,
      "z": -16,
      "name": "Rock_Ice"
    },
    {
      "x": -20,
      "y": 20,
      "z": -16,
      "name": "Soil_Snow"
    },
    {
      "x": -20,
      "y": 9,
      "z": -15,
      "name": "Rock_Ice"
    },
    {
      "x": -20,
      "y": 10,
      "z": -15,
      "name": "Rock_Ice"
    },
    {
      "x": -20,
      "y": 11,
      "z": -15,
      "name": "Rock_Ice"
    },
    {
      "x": -20,
      "y": 12,
      "z": -15,
      "name": "Rock_Ice"
    },
    {
      "x": -20,
      "y": 13,
      "z": -15,
      "name": "Rock_Ice"
    },
    {
      "x": -20,
      "y": 14,
      "z": -15,
      "name": "Rock_Ice_Permafrost"
    },
    {
      "x": -20,
      "y": 15,
      "z": -15,
      "name": "Rock_Ice"
    },
    {
      "x": -20,
      "y": 16,
      "z": -15,
      "name": "Rock_Ice_Permafrost"
    },
    {
      "x": -20,
      "y": 17,
      "z": -15,
      "name": "Rock_Ice_Permafrost"
    },
    {
      "x": -20,
      "y": 18,
      "z": -15,
      "name": "Rock_Ice_Permafrost"
    },
    {
      "x": -20,
      "y": 19,
      "z": -15,
      "name": "Rock_Ice_Permafrost"
    },
    {
      "x": -20,
      "y": 20,
      "z": -15,
      "name": "Rock_Ice"
    },
    {
      "x": -20,
      "y": 21,
      "z": -15,
      "name": "Soil_Snow"
    },
    {
      "x": -20,
      "y": 9,
      "z": -14,
      "name": "Rock_Ice"
    },
    {
      "x": -20,
      "y": 10,
      "z": -14,
      "name": "Rock_Ice"
    },
    {
      "x": -20,
      "y": 11,
      "z": -14,
      "name": "Rock_Ice"
    },
    {
      "x": -20,
      "y": 12,
      "z": -14,
      "name": "Rock_Ice"
    },
    {
      "x": -20,
      "y": 13,
      "z": -14,
      "name": "Rock_Ice"
    },
    {
      "x": -20,
      "y": 14,
      "z": -14,
      "name": "Rock_Ice"
    },
    {
      "x": -20,
      "y": 15,
      "z": -14,
      "name": "Rock_Ice_Permafrost"
    },
    {
      "x": -20,
      "y": 16,
      "z": -14,
      "name": "Rock_Ice_Permafrost"
    },
    {
      "x": -20,
      "y": 17,
      "z": -14,
      "name": "Rock_Ice_Permafrost"
    },
    {
      "x": -20,
      "y": 18,
      "z": -14,
      "name": "Rock_Ice_Permafrost"
    },
    {
      "x": -20,
      "y": 19,
      "z": -14,
      "name": "Rock_Ice_Permafrost"
    },
    {
      "x": -20,
      "y": 20,
      "z": -14,
      "name": "Rock_Ice"
    },
    {
      "x": -20,
      "y": 21,
      "z": -14,
      "name": "Soil_Snow"
    },
    {
      "x": -20,
      "y": 9,
      "z": -13,
      "name": "Rock_Ice"
    },
    {
      "x": -20,
      "y": 10,
      "z": -13,
      "name": "Rock_Ice"
    },
    {
      "x": -20,
      "y": 11,
      "z": -13,
      "name": "Rock_Ice"
    },
    {
      "x": -20,
      "y": 12,
      "z": -13,
      "name": "Rock_Ice"
    },
    {
      "x": -20,
      "y": 13,
      "z": -13,
      "name": "Rock_Ice"
    },
    {
      "x": -20,
      "y": 14,
      "z": -13,
      "name": "Rock_Ice"
    },
    {
      "x": -20,
      "y": 15,
      "z": -13,
      "name": "Rock_Ice"
    },
    {
      "x": -20,
      "y": 16,
      "z": -13,
      "name": "Rock_Ice_Permafrost"
    },
    {
      "x": -20,
      "y": 17,
      "z": -13,
      "name": "Rock_Ice_Permafrost"
    },
    {
      "x": -20,
      "y": 18,
      "z": -13,
      "name": "Rock_Ice_Permafrost"
    },
    {
      "x": -20,
      "y": 19,
      "z": -13,
      "name": "Rock_Ice_Permafrost"
    },
    {
      "x": -20,
      "y": 20,
      "z": -13,
      "name": "Rock_Ice_Permafrost"
    },
    {
      "x": -20,
      "y": 21,
      "z": -13,
      "name": "Rock_Ice"
    },
    {
      "x": -20,
      "y": 22,
      "z": -13,
      "name": "Soil_Snow"
    },
    {
      "x": -20,
      "y": 10,
      "z": -12,
      "name": "Rock_Ice"
    },
    {
      "x": -20,
      "y": 11,
      "z": -12,
      "name": "Rock_Ice"
    },
    {
      "x": -20,
      "y": 12,
      "z": -12,
      "name": "Rock_Ice"
    },
    {
      "x": -20,
      "y": 13,
      "z": -12,
      "name": "Rock_Ice"
    },
    {
      "x": -20,
      "y": 14,
      "z": -12,
      "name": "Rock_Ice"
    },
    {
      "x": -20,
      "y": 15,
      "z": -12,
      "name": "Rock_Ice"
    },
    {
      "x": -20,
      "y": 16,
      "z": -12,
      "name": "Rock_Ice_Permafrost"
    },
    {
      "x": -20,
      "y": 17,
      "z": -12,
      "name": "Rock_Ice_Permafrost"
    },
    {
      "x": -20,
      "y": 18,
      "z": -12,
      "name": "Rock_Ice_Permafrost"
    },
    {
      "x": -20,
      "y": 19,
      "z": -12,
      "name": "Rock_Ice_Permafrost"
    },
    {
      "x": -20,
      "y": 20,
      "z": -12,
      "name": "Rock_Ice_Permafrost"
    },
    {
      "x": -20,
      "y": 21,
      "z": -12,
      "name": "Rock_Ice"
    },
    {
      "x": -20,
      "y": 22,
      "z": -12,
      "name": "Soil_Snow"
    },
    {
      "x": -20,
      "y": 10,
      "z": -11,
      "name": "Rock_Ice"
    },
    {
      "x": -20,
      "y": 11,
      "z": -11,
      "name": "Rock_Ice"
    },
    {
      "x": -20,
      "y": 12,
      "z": -11,
      "name": "Rock_Ice"
    },
    {
      "x": -20,
      "y": 13,
      "z": -11,
      "name": "Rock_Ice"
    },
    {
      "x": -20,
      "y": 14,
      "z": -11,
      "name": "Rock_Ice"
    },
    {
      "x": -20,
      "y": 15,
      "z": -11,
      "name": "Rock_Ice"
    },
    {
      "x": -20,
      "y": 16,
      "z": -11,
      "name": "Rock_Ice_Permafrost"
    },
    {
      "x": -20,
      "y": 17,
      "z": -11,
      "name": "Rock_Ice_Permafrost"
    },
    {
      "x": -20,
      "y": 18,
      "z": -11,
      "name": "Rock_Ice_Permafrost"
    },
    {
      "x": -20,
      "y": 19,
      "z": -11,
      "name": "Rock_Ice_Permafrost"
    },
    {
      "x": -20,
      "y": 20,
      "z": -11,
      "name": "Rock_Ice_Permafrost"
    },
    {
      "x": -20,
      "y": 21,
      "z": -11,
      "name": "Rock_Ice"
    },
    {
      "x": -20,
      "y": 22,
      "z": -11,
      "name": "Soil_Snow"
    },
    {
      "x": -20,
      "y": 10,
      "z": -10,
      "name": "Rock_Ice"
    },
    {
      "x": -20,
      "y": 11,
      "z": -10,
      "name": "Rock_Ice"
    },
    {
      "x": -20,
      "y": 12,
      "z": -10,
      "name": "Rock_Ice"
    },
    {
      "x": -20,
      "y": 13,
      "z": -10,
      "name": "Rock_Ice"
    },
    {
      "x": -20,
      "y": 14,
      "z": -10,
      "name": "Rock_Ice"
    },
    {
      "x": -20,
      "y": 15,
      "z": -10,
      "name": "Rock_Ice_Permafrost"
    },
    {
      "x": -20,
      "y": 16,
      "z": -10,
      "name": "Rock_Ice_Permafrost"
    },
    {
      "x": -20,
      "y": 17,
      "z": -10,
      "name": "Rock_Ice_Permafrost"
    },
    {
      "x": -20,
      "y": 18,
      "z": -10,
      "name": "Rock_Ice_Permafrost"
    },
    {
      "x": -20,
      "y": 19,
      "z": -10,
      "name": "Rock_Ice_Permafrost"
    },
    {
      "x": -20,
      "y": 20,
      "z": -10,
      "name": "Rock_Ice_Permafrost"
    },
    {
      "x": -20,
      "y": 21,
      "z": -10,
      "name": "Rock_Ice"
    },
    {
      "x": -20,
      "y": 22,
      "z": -10,
      "name": "Rock_Ice"
    },
    {
      "x": -20,
      "y": 23,
      "z": -10,
      "name": "Soil_Snow"
    },
    {
      "x": -20,
      "y": 11,
      "z": -9,
      "name": "Rock_Ice"
    },
    {
      "x": -20,
      "y": 12,
      "z": -9,
      "name": "Rock_Ice"
    },
    {
      "x": -20,
      "y": 13,
      "z": -9,
      "name": "Rock_Ice"
    },
    {
      "x": -20,
      "y": 14,
      "z": -9,
      "name": "Rock_Ice"
    },
    {
      "x": -20,
      "y": 15,
      "z": -9,
      "name": "Rock_Ice"
    },
    {
      "x": -20,
      "y": 16,
      "z": -9,
      "name": "Rock_Ice_Permafrost"
    },
    {
      "x": -20,
      "y": 17,
      "z": -9,
      "name": "Rock_Ice_Permafrost"
    },
    {
      "x": -20,
      "y": 18,
      "z": -9,
      "name": "Rock_Ice_Permafrost"
    },
    {
      "x": -20,
      "y": 19,
      "z": -9,
      "name": "Rock_Ice_Permafrost"
    },
    {
      "x": -20,
      "y": 20,
      "z": -9,
      "name": "Rock_Ice_Permafrost"
    },
    {
      "x": -20,
      "y": 21,
      "z": -9,
      "name": "Rock_Ice_Permafrost"
    },
    {
      "x": -20,
      "y": 22,
      "z": -9,
      "name": "Rock_Ice"
    },
    {
      "x": -20,
      "y": 23,
      "z": -9,
      "name": "Soil_Snow"
    },
    {
      "x": -20,
      "y": 12,
      "z": -8,
      "name": "Rock_Ice"
    },
    {
      "x": -20,
      "y": 13,
      "z": -8,
      "name": "Rock_Ice"
    },
    {
      "x": -20,
      "y": 14,
      "z": -8,
      "name": "Rock_Ice_Permafrost"
    },
    {
      "x": -20,
      "y": 15,
      "z": -8,
      "name": "Rock_Ice_Permafrost"
    },
    {
      "x": -20,
      "y": 16,
      "z": -8,
      "name": "Rock_Ice_Permafrost"
    },
    {
      "x": -20,
      "y": 17,
      "z": -8,
      "name": "Rock_Ice_Permafrost"
    },
    {
      "x": -20,
      "y": 18,
      "z": -8,
      "name": "Rock_Ice_Permafrost"
    },
    {
      "x": -20,
      "y": 19,
      "z": -8,
      "name": "Rock_Ice_Permafrost"
    },
    {
      "x": -20,
      "y": 20,
      "z": -8,
      "name": "Rock_Ice_Permafrost"
    },
    {
      "x": -20,
      "y": 21,
      "z": -8,
      "name": "Rock_Ice_Permafrost"
    },
    {
      "x": -20,
      "y": 22,
      "z": -8,
      "name": "Rock_Ice"
    },
    {
      "x": -20,
      "y": 23,
      "z": -8,
      "name": "Soil_Snow"
    },
    {
      "x": -20,
      "y": 12,
      "z": -7,
      "name": "Rock_Ice"
    },
    {
      "x": -20,
      "y": 13,
      "z": -7,
      "name": "Rock_Ice_Permafrost"
    },
    {
      "x": -20,
      "y": 14,
      "z": -7,
      "name": "Rock_Ice"
    },
    {
      "x": -20,
      "y": 15,
      "z": -7,
      "name": "Rock_Ice_Permafrost"
    },
    {
      "x": -20,
      "y": 16,
      "z": -7,
      "name": "Rock_Ice_Permafrost"
    },
    {
      "x": -20,
      "y": 17,
      "z": -7,
      "name": "Rock_Ice_Permafrost"
    },
    {
      "x": -20,
      "y": 18,
      "z": -7,
      "name": "Rock_Ice_Permafrost"
    },
    {
      "x": -20,
      "y": 19,
      "z": -7,
      "name": "Rock_Ice_Permafrost"
    },
    {
      "x": -20,
      "y": 20,
      "z": -7,
      "name": "Rock_Ice_Permafrost"
    },
    {
      "x": -20,
      "y": 21,
      "z": -7,
      "name": "Rock_Ice_Permafrost"
    },
    {
      "x": -20,
      "y": 22,
      "z": -7,
      "name": "Rock_Ice"
    },
    {
      "x": -20,
      "y": 23,
      "z": -7,
      "name": "Rock_Ice_Permafrost"
    },
    {
      "x": -20,
      "y": 13,
      "z": -6,
      "name": "Rock_Ice"
    },
    {
      "x": -20,
      "y": 14,
      "z": -6,
      "name": "Rock_Ice_Permafrost"
    },
    {
      "x": -20,
      "y": 15,
      "z": -6,
      "name": "Rock_Ice"
    },
    {
      "x": -20,
      "y": 16,
      "z": -6,
      "name": "Rock_Ice_Permafrost"
    },
    {
      "x": -20,
      "y": 17,
      "z": -6,
      "name": "Rock_Ice_Permafrost"
    },
    {
      "x": -20,
      "y": 18,
      "z": -6,
      "name": "Rock_Ice_Permafrost"
    },
    {
      "x": -20,
      "y": 19,
      "z": -6,
      "name": "Rock_Ice_Permafrost"
    },
    {
      "x": -20,
      "y": 20,
      "z": -6,
      "name": "Rock_Ice_Permafrost"
    },
    {
      "x": -20,
      "y": 21,
      "z": -6,
      "name": "Rock_Ice_Permafrost"
    },
    {
      "x": -20,
      "y": 22,
      "z": -6,
      "name": "Rock_Ice"
    },
    {
      "x": -20,
      "y": 23,
      "z": -6,
      "name": "Soil_Snow"
    },
    {
      "x": -20,
      "y": 14,
      "z": -5,
      "name": "Rock_Ice"
    },
    {
      "x": -20,
      "y": 15,
      "z": -5,
      "name": "Rock_Ice_Permafrost"
    },
    {
      "x": -20,
      "y": 16,
      "z": -5,
      "name": "Rock_Ice"
    },
    {
      "x": -20,
      "y": 17,
      "z": -5,
      "name": "Rock_Ice_Permafrost"
    },
    {
      "x": -20,
      "y": 18,
      "z": -5,
      "name": "Rock_Ice_Permafrost"
    },
    {
      "x": -20,
      "y": 19,
      "z": -5,
      "name": "Rock_Ice_Permafrost"
    },
    {
      "x": -20,
      "y": 20,
      "z": -5,
      "name": "Rock_Ice_Permafrost"
    },
    {
      "x": -20,
      "y": 21,
      "z": -5,
      "name": "Rock_Ice_Permafrost"
    },
    {
      "x": -20,
      "y": 22,
      "z": -5,
      "name": "Rock_Ice"
    },
    {
      "x": -20,
      "y": 23,
      "z": -5,
      "name": "Soil_Snow"
    },
    {
      "x": -20,
      "y": 15,
      "z": -4,
      "name": "Rock_Ice_Permafrost"
    },
    {
      "x": -20,
      "y": 16,
      "z": -4,
      "name": "Rock_Ice_Permafrost"
    },
    {
      "x": -20,
      "y": 17,
      "z": -4,
      "name": "Rock_Ice_Permafrost"
    },
    {
      "x": -20,
      "y": 18,
      "z": -4,
      "name": "Rock_Ice_Permafrost"
    },
    {
      "x": -20,
      "y": 19,
      "z": -4,
      "name": "Rock_Ice_Permafrost"
    },
    {
      "x": -20,
      "y": 20,
      "z": -4,
      "name": "Rock_Ice_Permafrost"
    },
    {
      "x": -20,
      "y": 21,
      "z": -4,
      "name": "Rock_Ice_Permafrost"
    },
    {
      "x": -20,
      "y": 22,
      "z": -4,
      "name": "Rock_Ice"
    },
    {
      "x": -20,
      "y": 23,
      "z": -4,
      "name": "Soil_Snow"
    },
    {
      "x": -20,
      "y": 17,
      "z": -3,
      "name": "Rock_Ice_Permafrost"
    },
    {
      "x": -20,
      "y": 18,
      "z": -3,
      "name": "Rock_Ice_Permafrost"
    },
    {
      "x": -20,
      "y": 19,
      "z": -3,
      "name": "Rock_Ice_Permafrost"
    },
    {
      "x": -20,
      "y": 20,
      "z": -3,
      "name": "Rock_Ice_Permafrost"
    },
    {
      "x": -20,
      "y": 21,
      "z": -3,
      "name": "Rock_Ice_Permafrost"
    },
    {
      "x": -20,
      "y": 22,
      "z": -3,
      "name": "Rock_Ice"
    },
    {
      "x": -20,
      "y": 23,
      "z": -3,
      "name": "Rock_Ice_Permafrost"
    },
    {
      "x": -20,
      "y": 18,
      "z": -2,
      "name": "Rock_Ice_Permafrost"
    },
    {
      "x": -20,
      "y": 19,
      "z": -2,
      "name": "Rock_Ice_Permafrost"
    },
    {
      "x": -20,
      "y": 20,
      "z": -2,
      "name": "Rock_Ice_Permafrost"
    },
    {
      "x": -20,
      "y": 21,
      "z": -2,
      "name": "Rock_Ice"
    },
    {
      "x": -20,
      "y": 22,
      "z": -2,
      "name": "Soil_Snow"
    },
    {
      "x": -19,
      "y": 12,
      "z": -20,
      "name": "Rock_Ice_Permafrost"
    },
    {
      "x": -19,
      "y": 13,
      "z": -20,
      "name": "Rock_Ice"
    },
    {
      "x": -19,
      "y": 14,
      "z": -20,
      "name": "Rock_Ice_Permafrost"
    },
    {
      "x": -19,
      "y": 15,
      "z": -20,
      "name": "Rock_Ice"
    },
    {
      "x": -19,
      "y": 16,
      "z": -20,
      "name": "Soil_Snow"
    },
    {
      "x": -19,
      "y": 11,
      "z": -19,
      "name": "Rock_Ice"
    },
    {
      "x": -19,
      "y": 12,
      "z": -19,
      "name": "Rock_Ice_Permafrost"
    },
    {
      "x": -19,
      "y": 13,
      "z": -19,
      "name": "Rock_Ice_Permafrost"
    },
    {
      "x": -19,
      "y": 14,
      "z": -19,
      "name": "Rock_Ice_Permafrost"
    },
    {
      "x": -19,
      "y": 15,
      "z": -19,
      "name": "Rock_Ice_Permafrost"
    },
    {
      "x": -19,
      "y": 16,
      "z": -19,
      "name": "Rock_Ice"
    },
    {
      "x": -19,
      "y": 17,
      "z": -19,
      "name": "Soil_Snow"
    },
    {
      "x": -19,
      "y": 9,
      "z": -18,
      "name": "Rock_Ice"
    },
    {
      "x": -19,
      "y": 10,
      "z": -18,
      "name": "Rock_Ice"
    },
    {
      "x": -19,
      "y": 11,
      "z": -18,
      "name": "Rock_Ice"
    },
    {
      "x": -19,
      "y": 12,
      "z": -18,
      "name": "Rock_Ice"
    },
    {
      "x": -19,
      "y": 13,
      "z": -18,
      "name": "Rock_Ice"
    },
    {
      "x": -19,
      "y": 14,
      "z": -18,
      "name": "Rock_Ice_Permafrost"
    },
    {
      "x": -19,
      "y": 15,
      "z": -18,
      "name": "Rock_Ice_Permafrost"
    },
    {
      "x": -19,
      "y": 16,
      "z": -18,
      "name": "Rock_Ice"
    },
    {
      "x": -19,
      "y": 17,
      "z": -18,
      "name": "Rock_Ice_Permafrost"
    },
    {
      "x": -19,
      "y": 18,
      "z": -18,
      "name": "Rock_Ice"
    },
    {
      "x": -19,
      "y": 19,
      "z": -18,
      "name": "Soil_Snow"
    },
    {
      "x": -19,
      "y": 9,
      "z": -17,
      "name": "Rock_Ice"
    },
    {
      "x": -19,
      "y": 10,
      "z": -17,
      "name": "Rock_Ice"
    },
    {
      "x": -19,
      "y": 11,
      "z": -17,
      "name": "Rock_Ice"
    },
    {
      "x": -19,
      "y": 12,
      "z": -17,
      "name": "Rock_Ice"
    },
    {
      "x": -19,
      "y": 13,
      "z": -17,
      "name": "Rock_Ice_Permafrost"
    },
    {
      "x": -19,
      "y": 14,
      "z": -17,
      "name": "Rock_Ice"
    },
    {
      "x": -19,
      "y": 15,
      "z": -17,
      "name": "Rock_Ice_Permafrost"
    },
    {
      "x": -19,
      "y": 16,
      "z": -17,
      "name": "Rock_Ice_Permafrost"
    },
    {
      "x": -19,
      "y": 17,
      "z": -17,
      "name": "Rock_Ice_Permafrost"
    },
    {
      "x": -19,
      "y": 18,
      "z": -17,
      "name": "Rock_Ice_Permafrost"
    },
    {
      "x": -19,
      "y": 19,
      "z": -17,
      "name": "Rock_Ice"
    },
    {
      "x": -19,
      "y": 20,
      "z": -17,
      "name": "Soil_Snow"
    },
    {
      "x": -19,
      "y": 8,
      "z": -16,
      "name": "Rock_Ice"
    },
    {
      "x": -19,
      "y": 9,
      "z": -16,
      "name": "Rock_Ice"
    },
    {
      "x": -19,
      "y": 10,
      "z": -16,
      "name": "Rock_Ice"
    },
    {
      "x": -19,
      "y": 11,
      "z": -16,
      "name": "Rock_Ice"
    },
    {
      "x": -19,
      "y": 12,
      "z": -16,
      "name": "Rock_Ice"
    },
    {
      "x": -19,
      "y": 13,
      "z": -16,
      "name": "Rock_Ice"
    },
    {
      "x": -19,
      "y": 14,
      "z": -16,
      "name": "Rock_Ice"
    },
    {
      "x": -19,
      "y": 15,
      "z": -16,
      "name": "Rock_Ice"
    },
    {
      "x": -19,
      "y": 16,
      "z": -16,
      "name": "Rock_Ice_Permafrost"
    },
    {
      "x": -19,
      "y": 17,
      "z": -16,
      "name": "Rock_Ice_Permafrost"
    },
    {
      "x": -19,
      "y": 18,
      "z": -16,
      "name": "Rock_Ice_Permafrost"
    },
    {
      "x": -19,
      "y": 19,
      "z": -16,
      "name": "Rock_Ice"
    },
    {
      "x": -19,
      "y": 20,
      "z": -16,
      "name": "Soil_Snow"
    },
    {
      "x": -19,
      "y": 8,
      "z": -15,
      "name": "Rock_Ice"
    },
    {
      "x": -19,
      "y": 9,
      "z": -15,
      "name": "Rock_Ice"
    },
    {
      "x": -19,
      "y": 10,
      "z": -15,
      "name": "Rock_Ice"
    },
    {
      "x": -19,
      "y": 11,
      "z": -15,
      "name": "Rock_Ice"
    },
    {
      "x": -19,
      "y": 12,
      "z": -15,
      "name": "Rock_Ice"
    },
    {
      "x": -19,
      "y": 13,
      "z": -15,
      "name": "Rock_Ice"
    },
    {
      "x": -19,
      "y": 14,
      "z": -15,
      "name": "Rock_Ice"
    },
    {
      "x": -19,
      "y": 15,
      "z": -15,
      "name": "Rock_Ice_Permafrost"
    },
    {
      "x": -19,
      "y": 16,
      "z": -15,
      "name": "Rock_Ice_Permafrost"
    },
    {
      "x": -19,
      "y": 17,
      "z": -15,
      "name": "Rock_Ice_Permafrost"
    },
    {
      "x": -19,
      "y": 18,
      "z": -15,
      "name": "Rock_Ice_Permafrost"
    },
    {
      "x": -19,
      "y": 19,
      "z": -15,
      "name": "Rock_Ice_Permafrost"
    },
    {
      "x": -19,
      "y": 20,
      "z": -15,
      "name": "Rock_Ice"
    },
    {
      "x": -19,
      "y": 21,
      "z": -15,
      "name": "Soil_Snow"
    },
    {
      "x": -19,
      "y": 8,
      "z": -14,
      "name": "Rock_Ice"
    },
    {
      "x": -19,
      "y": 9,
      "z": -14,
      "name": "Rock_Ice"
    },
    {
      "x": -19,
      "y": 10,
      "z": -14,
      "name": "Rock_Ice"
    },
    {
      "x": -19,
      "y": 11,
      "z": -14,
      "name": "Rock_Ice"
    },
    {
      "x": -19,
      "y": 12,
      "z": -14,
      "name": "Rock_Ice"
    },
    {
      "x": -19,
      "y": 13,
      "z": -14,
      "name": "Rock_Ice"
    },
    {
      "x": -19,
      "y": 14,
      "z": -14,
      "name": "Rock_Ice"
    },
    {
      "x": -19,
      "y": 15,
      "z": -14,
      "name": "Rock_Ice"
    },
    {
      "x": -19,
      "y": 16,
      "z": -14,
      "name": "Rock_Ice"
    },
    {
      "x": -19,
      "y": 17,
      "z": -14,
      "name": "Rock_Ice_Permafrost"
    },
    {
      "x": -19,
      "y": 18,
      "z": -14,
      "name": "Rock_Ice_Permafrost"
    },
    {
      "x": -19,
      "y": 19,
      "z": -14,
      "name": "Rock_Ice_Permafrost"
    },
    {
      "x": -19,
      "y": 20,
      "z": -14,
      "name": "Rock_Ice"
    },
    {
      "x": -19,
      "y": 21,
      "z": -14,
      "name": "Soil_Snow"
    },
    {
      "x": -19,
      "y": 8,
      "z": -13,
      "name": "Rock_Ice"
    },
    {
      "x": -19,
      "y": 9,
      "z": -13,
      "name": "Rock_Ice"
    },
    {
      "x": -19,
      "y": 10,
      "z": -13,
      "name": "Rock_Ice"
    },
    {
      "x": -19,
      "y": 11,
      "z": -13,
      "name": "Rock_Ice"
    },
    {
      "x": -19,
      "y": 12,
      "z": -13,
      "name": "Rock_Ice"
    },
    {
      "x": -19,
      "y": 13,
      "z": -13,
      "name": "Rock_Ice"
    },
    {
      "x": -19,
      "y": 14,
      "z": -13,
      "name": "Rock_Ice"
    },
    {
      "x": -19,
      "y": 15,
      "z": -13,
      "name": "Rock_Ice"
    },
    {
      "x": -19,
      "y": 16,
      "z": -13,
      "name": "Rock_Ice_Permafrost"
    },
    {
      "x": -19,
      "y": 17,
      "z": -13,
      "name": "Rock_Ice_Permafrost"
    },
    {
      "x": -19,
      "y": 18,
      "z": -13,
      "name": "Rock_Ice_Permafrost"
    },
    {
      "x": -19,
      "y": 19,
      "z": -13,
      "name": "Rock_Ice_Permafrost"
    },
    {
      "x": -19,
      "y": 20,
      "z": -13,
      "name": "Rock_Ice_Permafrost"
    },
    {
      "x": -19,
      "y": 21,
      "z": -13,
      "name": "Rock_Ice"
    },
    {
      "x": -19,
      "y": 22,
      "z": -13,
      "name": "Soil_Snow"
    },
    {
      "x": -19,
      "y": 9,
      "z": -12,
      "name": "Rock_Ice"
    },
    {
      "x": -19,
      "y": 10,
      "z": -12,
      "name": "Rock_Ice"
    },
    {
      "x": -19,
      "y": 11,
      "z": -12,
      "name": "Rock_Ice"
    },
    {
      "x": -19,
      "y": 12,
      "z": -12,
      "name": "Rock_Ice"
    },
    {
      "x": -19,
      "y": 13,
      "z": -12,
      "name": "Rock_Ice"
    },
    {
      "x": -19,
      "y": 14,
      "z": -12,
      "name": "Rock_Ice"
    },
    {
      "x": -19,
      "y": 15,
      "z": -12,
      "name": "Rock_Ice_Permafrost"
    },
    {
      "x": -19,
      "y": 16,
      "z": -12,
      "name": "Rock_Ice_Permafrost"
    },
    {
      "x": -19,
      "y": 17,
      "z": -12,
      "name": "Rock_Ice_Permafrost"
    },
    {
      "x": -19,
      "y": 18,
      "z": -12,
      "name": "Rock_Ice_Permafrost"
    },
    {
      "x": -19,
      "y": 19,
      "z": -12,
      "name": "Rock_Ice_Permafrost"
    },
    {
      "x": -19,
      "y": 20,
      "z": -12,
      "name": "Rock_Ice_Permafrost"
    },
    {
      "x": -19,
      "y": 21,
      "z": -12,
      "name": "Rock_Ice"
    },
    {
      "x": -19,
      "y": 22,
      "z": -12,
      "name": "Soil_Snow"
    },
    {
      "x": -19,
      "y": 9,
      "z": -11,
      "name": "Rock_Ice"
    },
    {
      "x": -19,
      "y": 10,
      "z": -11,
      "name": "Rock_Ice"
    },
    {
      "x": -19,
      "y": 11,
      "z": -11,
      "name": "Rock_Ice"
    },
    {
      "x": -19,
      "y": 12,
      "z": -11,
      "name": "Rock_Ice"
    },
    {
      "x": -19,
      "y": 13,
      "z": -11,
      "name": "Rock_Ice"
    },
    {
      "x": -19,
      "y": 14,
      "z": -11,
      "name": "Rock_Ice"
    },
    {
      "x": -19,
      "y": 15,
      "z": -11,
      "name": "Rock_Ice"
    },
    {
      "x": -19,
      "y": 16,
      "z": -11,
      "name": "Rock_Ice_Permafrost"
    },
    {
      "x": -19,
      "y": 17,
      "z": -11,
      "name": "Rock_Ice_Permafrost"
    },
    {
      "x": -19,
      "y": 18,
      "z": -11,
      "name": "Rock_Ice_Permafrost"
    },
    {
      "x": -19,
      "y": 19,
      "z": -11,
      "name": "Rock_Ice_Permafrost"
    },
    {
      "x": -19,
      "y": 20,
      "z": -11,
      "name": "Rock_Ice_Permafrost"
    },
    {
      "x": -19,
      "y": 21,
      "z": -11,
      "name": "Rock_Ice_Permafrost"
    },
    {
      "x": -19,
      "y": 22,
      "z": -11,
      "name": "Rock_Ice"
    },
    {
      "x": -19,
      "y": 23,
      "z": -11,
      "name": "Soil_Snow"
    },
    {
      "x": -19,
      "y": 9,
      "z": -10,
      "name": "Rock_Ice"
    },
    {
      "x": -19,
      "y": 10,
      "z": -10,
      "name": "Rock_Ice"
    },
    {
      "x": -19,
      "y": 11,
      "z": -10,
      "name": "Rock_Ice"
    },
    {
      "x": -19,
      "y": 12,
      "z": -10,
      "name": "Rock_Ice"
    },
    {
      "x": -19,
      "y": 13,
      "z": -10,
      "name": "Rock_Ice"
    },
    {
      "x": -19,
      "y": 14,
      "z": -10,
      "name": "Rock_Ice"
    },
    {
      "x": -19,
      "y": 15,
      "z": -10,
      "name": "Rock_Ice"
    },
    {
      "x": -19,
      "y": 16,
      "z": -10,
      "name": "Rock_Ice_Permafrost"
    },
    {
      "x": -19,
      "y": 17,
      "z": -10,
      "name": "Rock_Ice_Permafrost"
    },
    {
      "x": -19,
      "y": 18,
      "z": -10,
      "name": "Rock_Ice_Permafrost"
    },
    {
      "x": -19,
      "y": 19,
      "z": -10,
      "name": "Rock_Ice_Permafrost"
    },
    {
      "x": -19,
      "y": 20,
      "z": -10,
      "name": "Rock_Ice_Permafrost"
    },
    {
      "x": -19,
      "y": 21,
      "z": -10,
      "name": "Rock_Ice_Permafrost"
    },
    {
      "x": -19,
      "y": 22,
      "z": -10,
      "name": "Rock_Ice"
    },
    {
      "x": -19,
      "y": 23,
      "z": -10,
      "name": "Soil_Snow"
    },
    {
      "x": -19,
      "y": 10,
      "z": -9,
      "name": "Rock_Ice"
    },
    {
      "x": -19,
      "y": 11,
      "z": -9,
      "name": "Rock_Ice"
    },
    {
      "x": -19,
      "y": 12,
      "z": -9,
      "name": "Rock_Ice"
    },
    {
      "x": -19,
      "y": 13,
      "z": -9,
      "name": "Rock_Ice"
    },
    {
      "x": -19,
      "y": 14,
      "z": -9,
      "name": "Rock_Ice_Permafrost"
    },
    {
      "x": -19,
      "y": 15,
      "z": -9,
      "name": "Rock_Ice"
    },
    {
      "x": -19,
      "y": 16,
      "z": -9,
      "name": "Rock_Ice_Permafrost"
    },
    {
      "x": -19,
      "y": 17,
      "z": -9,
      "name": "Rock_Ice_Permafrost"
    },
    {
      "x": -19,
      "y": 18,
      "z": -9,
      "name": "Rock_Ice_Permafrost"
    },
    {
      "x": -19,
      "y": 19,
      "z": -9,
      "name": "Rock_Ice_Permafrost"
    },
    {
      "x": -19,
      "y": 20,
      "z": -9,
      "name": "Rock_Ice_Permafrost"
    },
    {
      "x": -19,
      "y": 21,
      "z": -9,
      "name": "Rock_Ice_Permafrost"
    },
    {
      "x": -19,
      "y": 22,
      "z": -9,
      "name": "Rock_Ice"
    },
    {
      "x": -19,
      "y": 23,
      "z": -9,
      "name": "Soil_Snow"
    },
    {
      "x": -19,
      "y": 11,
      "z": -8,
      "name": "Rock_Ice"
    },
    {
      "x": -19,
      "y": 12,
      "z": -8,
      "name": "Rock_Ice"
    },
    {
      "x": -19,
      "y": 13,
      "z": -8,
      "name": "Rock_Ice"
    },
    {
      "x": -19,
      "y": 14,
      "z": -8,
      "name": "Rock_Ice"
    },
    {
      "x": -19,
      "y": 15,
      "z": -8,
      "name": "Rock_Ice_Permafrost"
    },
    {
      "x": -19,
      "y": 16,
      "z": -8,
      "name": "Rock_Ice_Permafrost"
    },
    {
      "x": -19,
      "y": 17,
      "z": -8,
      "name": "Rock_Ice_Permafrost"
    },
    {
      "x": -19,
      "y": 18,
      "z": -8,
      "name": "Rock_Ice_Permafrost"
    },
    {
      "x": -19,
      "y": 19,
      "z": -8,
      "name": "Rock_Ice_Permafrost"
    },
    {
      "x": -19,
      "y": 20,
      "z": -8,
      "name": "Rock_Ice_Permafrost"
    },
    {
      "x": -19,
      "y": 21,
      "z": -8,
      "name": "Rock_Ice_Permafrost"
    },
    {
      "x": -19,
      "y": 22,
      "z": -8,
      "name": "Rock_Ice"
    },
    {
      "x": -19,
      "y": 23,
      "z": -8,
      "name": "Soil_Snow"
    },
    {
      "x": -19,
      "y": 11,
      "z": -7,
      "name": "Rock_Ice"
    },
    {
      "x": -19,
      "y": 12,
      "z": -7,
      "name": "Rock_Ice"
    },
    {
      "x": -19,
      "y": 13,
      "z": -7,
      "name": "Rock_Ice"
    },
    {
      "x": -19,
      "y": 14,
      "z": -7,
      "name": "Rock_Ice"
    },
    {
      "x": -19,
      "y": 15,
      "z": -7,
      "name": "Rock_Ice"
    },
    {
      "x": -19,
      "y": 16,
      "z": -7,
      "name": "Rock_Ice_Permafrost"
    },
    {
      "x": -19,
      "y": 17,
      "z": -7,
      "name": "Rock_Ice_Permafrost"
    },
    {
      "x": -19,
      "y": 18,
      "z": -7,
      "name": "Rock_Ice_Permafrost"
    },
    {
      "x": -19,
      "y": 19,
      "z": -7,
      "name": "Rock_Ice_Permafrost"
    },
    {
      "x": -19,
      "y": 20,
      "z": -7,
      "name": "Rock_Ice_Permafrost"
    },
    {
      "x": -19,
      "y": 21,
      "z": -7,
      "name": "Rock_Ice_Permafrost"
    },
    {
      "x": -19,
      "y": 22,
      "z": -7,
      "name": "Rock_Ice"
    },
    {
      "x": -19,
      "y": 23,
      "z": -7,
      "name": "Rock_Ice_Permafrost"
    },
    {
      "x": -19,
      "y": 12,
      "z": -6,
      "name": "Rock_Ice"
    },
    {
      "x": -19,
      "y": 13,
      "z": -6,
      "name": "Rock_Ice"
    },
    {
      "x": -19,
      "y": 14,
      "z": -6,
      "name": "Rock_Ice_Permafrost"
    },
    {
      "x": -19,
      "y": 15,
      "z": -6,
      "name": "Rock_Ice"
    },
    {
      "x": -19,
      "y": 16,
      "z": -6,
      "name": "Rock_Ice"
    },
    {
      "x": -19,
      "y": 17,
      "z": -6,
      "name": "Rock_Ice_Permafrost"
    },
    {
      "x": -19,
      "y": 18,
      "z": -6,
      "name": "Rock_Ice_Permafrost"
    },
    {
      "x": -19,
      "y": 19,
      "z": -6,
      "name": "Rock_Ice_Permafrost"
    },
    {
      "x": -19,
      "y": 20,
      "z": -6,
      "name": "Rock_Ice_Permafrost"
    },
    {
      "x": -19,
      "y": 21,
      "z": -6,
      "name": "Rock_Ice_Permafrost"
    },
    {
      "x": -19,
      "y": 22,
      "z": -6,
      "name": "Rock_Ice_Permafrost"
    },
    {
      "x": -19,
      "y": 23,
      "z": -6,
      "name": "Rock_Ice"
    },
    {
      "x": -19,
      "y": 24,
      "z": -6,
      "name": "Soil_Snow"
    },
    {
      "x": -19,
      "y": 13,
      "z": -5,
      "name": "Rock_Ice"
    },
    {
      "x": -19,
      "y": 14,
      "z": -5,
      "name": "Rock_Ice_Permafrost"
    },
    {
      "x": -19,
      "y": 15,
      "z": -5,
      "name": "Rock_Ice"
    },
    {
      "x": -19,
      "y": 16,
      "z": -5,
      "name": "Rock_Ice_Permafrost"
    },
    {
      "x": -19,
      "y": 17,
      "z": -5,
      "name": "Rock_Ice_Permafrost"
    },
    {
      "x": -19,
      "y": 18,
      "z": -5,
      "name": "Rock_Ice_Permafrost"
    },
    {
      "x": -19,
      "y": 19,
      "z": -5,
      "name": "Rock_Ice_Permafrost"
    },
    {
      "x": -19,
      "y": 20,
      "z": -5,
      "name": "Rock_Ice_Permafrost"
    },
    {
      "x": -19,
      "y": 21,
      "z": -5,
      "name": "Rock_Ice_Permafrost"
    },
    {
      "x": -19,
      "y": 22,
      "z": -5,
      "name": "Rock_Ice_Permafrost"
    },
    {
      "x": -19,
      "y": 23,
      "z": -5,
      "name": "Rock_Ice"
    },
    {
      "x": -19,
      "y": 24,
      "z": -5,
      "name": "Soil_Snow"
    },
    {
      "x": -19,
      "y": 14,
      "z": -4,
      "name": "Rock_Ice"
    },
    {
      "x": -19,
      "y": 15,
      "z": -4,
      "name": "Rock_Ice_Permafrost"
    },
    {
      "x": -19,
      "y": 16,
      "z": -4,
      "name": "Rock_Ice_Permafrost"
    },
    {
      "x": -19,
      "y": 17,
      "z": -4,
      "name": "Rock_Ice"
    },
    {
      "x": -19,
      "y": 18,
      "z": -4,
      "name": "Rock_Ice_Permafrost"
    },
    {
      "x": -19,
      "y": 19,
      "z": -4,
      "name": "Rock_Ice_Permafrost"
    },
    {
      "x": -19,
      "y": 20,
      "z": -4,
      "name": "Rock_Ice_Permafrost"
    },
    {
      "x": -19,
      "y": 21,
      "z": -4,
      "name": "Rock_Ice_Permafrost"
    },
    {
      "x": -19,
      "y": 22,
      "z": -4,
      "name": "Rock_Ice_Permafrost"
    },
    {
      "x": -19,
      "y": 23,
      "z": -4,
      "name": "Rock_Ice"
    },
    {
      "x": -19,
      "y": 24,
      "z": -4,
      "name": "Soil_Snow"
    },
    {
      "x": -19,
      "y": 16,
      "z": -3,
      "name": "Rock_Ice_Permafrost"
    },
    {
      "x": -19,
      "y": 17,
      "z": -3,
      "name": "Rock_Ice_Permafrost"
    },
    {
      "x": -19,
      "y": 18,
      "z": -3,
      "name": "Rock_Ice_Permafrost"
    },
    {
      "x": -19,
      "y": 19,
      "z": -3,
      "name": "Rock_Ice_Permafrost"
    },
    {
      "x": -19,
      "y": 20,
      "z": -3,
      "name": "Rock_Ice_Permafrost"
    },
    {
      "x": -19,
      "y": 21,
      "z": -3,
      "name": "Rock_Ice_Permafrost"
    },
    {
      "x": -19,
      "y": 22,
      "z": -3,
      "name": "Rock_Ice_Permafrost"
    },
    {
      "x": -19,
      "y": 23,
      "z": -3,
      "name": "Rock_Ice"
    },
    {
      "x": -19,
      "y": 24,
      "z": -3,
      "name": "Soil_Snow"
    },
    {
      "x": -19,
      "y": 17,
      "z": -2,
      "name": "Rock_Ice_Permafrost"
    },
    {
      "x": -19,
      "y": 18,
      "z": -2,
      "name": "Rock_Ice_Permafrost"
    },
    {
      "x": -19,
      "y": 19,
      "z": -2,
      "name": "Rock_Ice_Permafrost"
    },
    {
      "x": -19,
      "y": 20,
      "z": -2,
      "name": "Rock_Ice_Permafrost"
    },
    {
      "x": -19,
      "y": 21,
      "z": -2,
      "name": "Rock_Ice_Permafrost"
    },
    {
      "x": -19,
      "y": 22,
      "z": -2,
      "name": "Rock_Ice"
    },
    {
      "x": -19,
      "y": 23,
      "z": -2,
      "name": "Soil_Snow"
    },
    {
      "x": -19,
      "y": 18,
      "z": -1,
      "name": "Rock_Ice_Permafrost"
    },
    {
      "x": -19,
      "y": 19,
      "z": -1,
      "name": "Rock_Ice_Permafrost"
    },
    {
      "x": -19,
      "y": 20,
      "z": -1,
      "name": "Rock_Ice_Permafrost"
    },
    {
      "x": -19,
      "y": 21,
      "z": -1,
      "name": "Rock_Ice_Permafrost"
    },
    {
      "x": -19,
      "y": 22,
      "z": -1,
      "name": "Rock_Ice"
    },
    {
      "x": -19,
      "y": 23,
      "z": -1,
      "name": "Soil_Snow"
    },
    {
      "x": -18,
      "y": 12,
      "z": -20,
      "name": "Rock_Ice_Permafrost"
    },
    {
      "x": -18,
      "y": 13,
      "z": -20,
      "name": "Rock_Ice_Permafrost"
    },
    {
      "x": -18,
      "y": 14,
      "z": -20,
      "name": "Rock_Ice_Permafrost"
    },
    {
      "x": -18,
      "y": 15,
      "z": -20,
      "name": "Rock_Ice"
    },
    {
      "x": -18,
      "y": 16,
      "z": -20,
      "name": "Soil_Snow"
    },
    {
      "x": -18,
      "y": 10,
      "z": -19,
      "name": "Rock_Ice_Permafrost"
    },
    {
      "x": -18,
      "y": 11,
      "z": -19,
      "name": "Rock_Ice_Permafrost"
    },
    {
      "x": -18,
      "y": 12,
      "z": -19,
      "name": "Rock_Ice_Permafrost"
    },
    {
      "x": -18,
      "y": 13,
      "z": -19,
      "name": "Rock_Ice"
    },
    {
      "x": -18,
      "y": 14,
      "z": -19,
      "name": "Rock_Ice_Permafrost"
    },
    {
      "x": -18,
      "y": 15,
      "z": -19,
      "name": "Rock_Ice_Permafrost"
    },
    {
      "x": -18,
      "y": 16,
      "z": -19,
      "name": "Rock_Ice_Permafrost"
    },
    {
      "x": -18,
      "y": 17,
      "z": -19,
      "name": "Rock_Ice"
    },
    {
      "x": -18,
      "y": 18,
      "z": -19,
      "name": "Soil_Snow"
    },
    {
      "x": -18,
      "y": 9,
      "z": -18,
      "name": "Rock_Ice"
    },
    {
      "x": -18,
      "y": 10,
      "z": -18,
      "name": "Rock_Ice"
    },
    {
      "x": -18,
      "y": 11,
      "z": -18,
      "name": "Rock_Ice"
    },
    {
      "x": -18,
      "y": 12,
      "z": -18,
      "name": "Rock_Ice"
    },
    {
      "x": -18,
      "y": 13,
      "z": -18,
      "name": "Rock_Ice_Permafrost"
    },
    {
      "x": -18,
      "y": 14,
      "z": -18,
      "name": "Rock_Ice_Permafrost"
    },
    {
      "x": -18,
      "y": 15,
      "z": -18,
      "name": "Rock_Ice_Permafrost"
    },
    {
      "x": -18,
      "y": 16,
      "z": -18,
      "name": "Rock_Ice_Permafrost"
    },
    {
      "x": -18,
      "y": 17,
      "z": -18,
      "name": "Rock_Ice_Permafrost"
    },
    {
      "x": -18,
      "y": 18,
      "z": -18,
      "name": "Rock_Ice"
    },
    {
      "x": -18,
      "y": 19,
      "z": -18,
      "name": "Soil_Snow"
    },
    {
      "x": -18,
      "y": 8,
      "z": -17,
      "name": "Rock_Ice"
    },
    {
      "x": -18,
      "y": 9,
      "z": -17,
      "name": "Rock_Ice_Permafrost"
    },
    {
      "x": -18,
      "y": 10,
      "z": -17,
      "name": "Rock_Ice"
    },
    {
      "x": -18,
      "y": 11,
      "z": -17,
      "name": "Rock_Ice"
    },
    {
      "x": -18,
      "y": 12,
      "z": -17,
      "name": "Rock_Ice_Permafrost"
    },
    {
      "x": -18,
      "y": 13,
      "z": -17,
      "name": "Rock_Ice_Permafrost"
    },
    {
      "x": -18,
      "y": 14,
      "z": -17,
      "name": "Rock_Ice"
    },
    {
      "x": -18,
      "y": 15,
      "z": -17,
      "name": "Rock_Ice"
    },
    {
      "x": -18,
      "y": 16,
      "z": -17,
      "name": "Rock_Ice"
    },
    {
      "x": -18,
      "y": 17,
      "z": -17,
      "name": "Rock_Ice_Permafrost"
    },
    {
      "x": -18,
      "y": 18,
      "z": -17,
      "name": "Rock_Ice_Permafrost"
    },
    {
      "x": -18,
      "y": 19,
      "z": -17,
      "name": "Rock_Ice"
    },
    {
      "x": -18,
      "y": 20,
      "z": -17,
      "name": "Soil_Snow"
    },
    {
      "x": -18,
      "y": 8,
      "z": -16,
      "name": "Rock_Ice"
    },
    {
      "x": -18,
      "y": 9,
      "z": -16,
      "name": "Rock_Ice"
    },
    {
      "x": -18,
      "y": 10,
      "z": -16,
      "name": "Rock_Ice"
    },
    {
      "x": -18,
      "y": 11,
      "z": -16,
      "name": "Rock_Ice"
    },
    {
      "x": -18,
      "y": 12,
      "z": -16,
      "name": "Rock_Ice"
    },
    {
      "x": -18,
      "y": 13,
      "z": -16,
      "name": "Rock_Ice"
    },
    {
      "x": -18,
      "y": 14,
      "z": -16,
      "name": "Rock_Ice"
    },
    {
      "x": -18,
      "y": 15,
      "z": -16,
      "name": "Rock_Ice_Permafrost"
    },
    {
      "x": -18,
      "y": 16,
      "z": -16,
      "name": "Rock_Ice_Permafrost"
    },
    {
      "x": -18,
      "y": 17,
      "z": -16,
      "name": "Rock_Ice_Permafrost"
    },
    {
      "x": -18,
      "y": 18,
      "z": -16,
      "name": "Rock_Ice_Permafrost"
    },
    {
      "x": -18,
      "y": 19,
      "z": -16,
      "name": "Rock_Ice_Permafrost"
    },
    {
      "x": -18,
      "y": 20,
      "z": -16,
      "name": "Rock_Ice"
    },
    {
      "x": -18,
      "y": 21,
      "z": -16,
      "name": "Soil_Snow"
    },
    {
      "x": -18,
      "y": 8,
      "z": -15,
      "name": "Rock_Ice"
    },
    {
      "x": -18,
      "y": 9,
      "z": -15,
      "name": "Rock_Ice"
    },
    {
      "x": -18,
      "y": 10,
      "z": -15,
      "name": "Rock_Ice"
    },
    {
      "x": -18,
      "y": 11,
      "z": -15,
      "name": "Rock_Ice"
    },
    {
      "x": -18,
