{
  "version": 8,
  "blockIdVersion": 11,
  "anchorX": 6,
  "anchorY": 11,
  "anchorZ": -3,
  "blocks": [
    {
      "x": -27,
      "y": 41,
      "z": 14,
      "name": "Rock_Ice"
    },
    {
      "x": -27,
      "y": 42,
      "z": 14,
      "name": "Rock_Ice"
    },
    {
      "x": -27,
      "y": 43,
      "z": 14,
      "name": "Rock_Ice"
    },
    {
      "x": -27,
      "y": 44,
      "z": 14,
      "name": "Soil_Snow"
    },
    {
      "x": -27,
      "y": 40,
      "z": 15,
      "name": "Rock_Ice"
    },
    {
      "x": -27,
      "y": 41,
      "z": 15,
      "name": "Rock_Ice"
    },
    {
      "x": -27,
      "y": 42,
      "z": 15,
      "name": "Rock_Ice"
    },
    {
      "x": -27,
      "y": 43,
      "z": 15,
      "name": "Rock_Ice"
    },
    {
      "x": -27,
      "y": 44,
      "z": 15,
      "name": "Rock_Ice"
    },
    {
      "x": -27,
      "y": 45,
      "z": 15,
      "name": "Rock_Ice"
    },
    {
      "x": -27,
      "y": 46,
      "z": 15,
      "name": "Soil_Snow"
    },
    {
      "x": -26,
      "y": 39,
      "z": 13,
      "name": "Rock_Ice"
    },
    {
      "x": -26,
      "y": 40,
      "z": 13,
      "name": "Rock_Ice"
    },
    {
      "x": -26,
      "y": 41,
      "z": 13,
      "name": "Rock_Ice"
    },
    {
      "x": -26,
      "y": 42,
      "z": 13,
      "name": "Rock_Ice"
    },
    {
      "x": -26,
      "y": 43,
      "z": 13,
      "name": "Rock_Ice"
    },
    {
      "x": -26,
      "y": 44,
      "z": 13,
      "name": "Rock_Ice"
    },
    {
      "x": -26,
      "y": 45,
      "z": 13,
      "name": "Rock_Ice"
    },
    {
      "x": -26,
      "y": 46,
      "z": 13,
      "name": "Soil_Snow"
    },
    {
      "x": -26,
      "y": 37,
      "z": 14,
      "name": "Rock_Ice"
    },
    {
      "x": -26,
      "y": 38,
      "z": 14,
      "name": "Rock_Ice"
    },
    {
      "x": -26,
      "y": 39,
      "z": 14,
      "name": "Rock_Ice"
    },
    {
      "x": -26,
      "y": 40,
      "z": 14,
      "name": "Rock_Ice"
    },
    {
      "x": -26,
      "y": 41,
      "z": 14,
      "name": "Rock_Ice"
    },
    {
      "x": -26,
      "y": 42,
      "z": 14,
      "name": "Rock_Ice"
    },
    {
      "x": -26,
      "y": 43,
      "z": 14,
      "name": "Rock_Ice"
    },
    {
      "x": -26,
      "y": 44,
      "z": 14,
      "name": "Rock_Ice"
    },
    {
      "x": -26,
      "y": 45,
      "z": 14,
      "name": "Rock_Ice"
    },
    {
      "x": -26,
      "y": 46,
      "z": 14,
      "name": "Rock_Ice"
    },
    {
      "x": -26,
      "y": 47,
      "z": 14,
      "name": "Soil_Snow"
    },
    {
      "x": -26,
      "y": 38,
      "z": 15,
      "name": "Rock_Ice"
    },
    {
      "x": -26,
      "y": 39,
      "z": 15,
      "name": "Rock_Ice"
    },
    {
      "x": -26,
      "y": 40,
      "z": 15,
      "name": "Rock_Ice"
    },
    {
      "x": -26,
      "y": 41,
      "z": 15,
      "name": "Rock_Ice"
    },
    {
      "x": -26,
      "y": 42,
      "z": 15,
      "name": "Rock_Ice"
    },
    {
      "x": -26,
      "y": 43,
      "z": 15,
      "name": "Rock_Ice"
    },
    {
      "x": -26,
      "y": 44,
      "z": 15,
      "name": "Rock_Ice"
    },
    {
      "x": -26,
      "y": 45,
      "z": 15,
      "name": "Rock_Ice"
    },
    {
      "x": -26,
      "y": 46,
      "z": 15,
      "name": "Soil_Snow"
    },
    {
      "x": -26,
      "y": 40,
      "z": 16,
      "name": "Rock_Ice"
    },
    {
      "x": -26,
      "y": 41,
      "z": 16,
      "name": "Rock_Ice"
    },
    {
      "x": -26,
      "y": 42,
      "z": 16,
      "name": "Rock_Ice"
    },
    {
      "x": -26,
      "y": 43,
      "z": 16,
      "name": "Rock_Ice"
    },
    {
      "x": -26,
      "y": 44,
      "z": 16,
      "name": "Rock_Ice"
    },
    {
      "x": -26,
      "y": 45,
      "z": 16,
      "name": "Soil_Snow"
    },
    {
      "x": -25,
      "y": 39,
      "z": 12,
      "name": "Rock_Ice"
    },
    {
      "x": -25,
      "y": 40,
      "z": 12,
      "name": "Rock_Ice"
    },
    {
      "x": -25,
      "y": 41,
      "z": 12,
      "name": "Rock_Ice"
    },
    {
      "x": -25,
      "y": 42,
      "z": 12,
      "name": "Rock_Ice"
    },
    {
      "x": -25,
      "y": 43,
      "z": 12,
      "name": "Rock_Ice"
    },
    {
      "x": -25,
      "y": 44,
      "z": 12,
      "name": "Rock_Ice"
    },
    {
      "x": -25,
      "y": 45,
      "z": 12,
      "name": "Rock_Ice"
    },
    {
      "x": -25,
      "y": 46,
      "z": 12,
      "name": "Soil_Snow"
    },
    {
      "x": -25,
      "y": 36,
      "z": 13,
      "name": "Rock_Ice"
    },
    {
      "x": -25,
      "y": 37,
      "z": 13,
      "name": "Rock_Ice"
    },
    {
      "x": -25,
      "y": 38,
      "z": 13,
      "name": "Rock_Ice"
    },
    {
      "x": -25,
      "y": 39,
      "z": 13,
      "name": "Rock_Ice"
    },
    {
      "x": -25,
      "y": 40,
      "z": 13,
      "name": "Rock_Ice"
    },
    {
      "x": -25,
      "y": 41,
      "z": 13,
      "name": "Rock_Ice"
    },
    {
      "x": -25,
      "y": 42,
      "z": 13,
      "name": "Rock_Ice"
    },
    {
      "x": -25,
      "y": 43,
      "z": 13,
      "name": "Rock_Ice"
    },
    {
      "x": -25,
      "y": 44,
      "z": 13,
      "name": "Rock_Ice"
    },
    {
      "x": -25,
      "y": 45,
      "z": 13,
      "name": "Rock_Ice"
    },
    {
      "x": -25,
      "y": 46,
      "z": 13,
      "name": "Rock_Ice"
    },
    {
      "x": -25,
      "y": 47,
      "z": 13,
      "name": "Soil_Snow"
    },
    {
      "x": -25,
      "y": 35,
      "z": 14,
      "name": "Rock_Ice"
    },
    {
      "x": -25,
      "y": 36,
      "z": 14,
      "name": "Rock_Ice"
    },
    {
      "x": -25,
      "y": 37,
      "z": 14,
      "name": "Rock_Ice"
    },
    {
      "x": -25,
      "y": 38,
      "z": 14,
      "name": "Rock_Ice"
    },
    {
      "x": -25,
      "y": 39,
      "z": 14,
      "name": "Rock_Ice"
    },
    {
      "x": -25,
      "y": 40,
      "z": 14,
      "name": "Rock_Ice"
    },
    {
      "x": -25,
      "y": 41,
      "z": 14,
      "name": "Rock_Ice"
    },
    {
      "x": -25,
      "y": 42,
      "z": 14,
      "name": "Rock_Ice"
    },
    {
      "x": -25,
      "y": 43,
      "z": 14,
      "name": "Rock_Ice"
    },
    {
      "x": -25,
      "y": 44,
      "z": 14,
      "name": "Rock_Ice"
    },
    {
      "x": -25,
      "y": 45,
      "z": 14,
      "name": "Rock_Ice"
    },
    {
      "x": -25,
      "y": 46,
      "z": 14,
      "name": "Rock_Ice"
    },
    {
      "x": -25,
      "y": 47,
      "z": 14,
      "name": "Soil_Snow"
    },
    {
      "x": -25,
      "y": 36,
      "z": 15,
      "name": "Rock_Ice"
    },
    {
      "x": -25,
      "y": 37,
      "z": 15,
      "name": "Rock_Ice"
    },
    {
      "x": -25,
      "y": 38,
      "z": 15,
      "name": "Rock_Ice"
    },
    {
      "x": -25,
      "y": 39,
      "z": 15,
      "name": "Rock_Ice"
    },
    {
      "x": -25,
      "y": 40,
      "z": 15,
      "name": "Rock_Ice"
    },
    {
      "x": -25,
      "y": 41,
      "z": 15,
      "name": "Rock_Ice"
    },
    {
      "x": -25,
      "y": 42,
      "z": 15,
      "name": "Rock_Ice"
    },
    {
      "x": -25,
      "y": 43,
      "z": 15,
      "name": "Rock_Ice"
    },
    {
      "x": -25,
      "y": 44,
      "z": 15,
      "name": "Rock_Ice"
    },
    {
      "x": -25,
      "y": 45,
      "z": 15,
      "name": "Rock_Ice"
    },
    {
      "x": -25,
      "y": 46,
      "z": 15,
      "name": "Soil_Snow"
    },
    {
      "x": -25,
      "y": 38,
      "z": 16,
      "name": "Rock_Ice"
    },
    {
      "x": -25,
      "y": 39,
      "z": 16,
      "name": "Rock_Ice"
    },
    {
      "x": -25,
      "y": 40,
      "z": 16,
      "name": "Rock_Ice"
    },
    {
      "x": -25,
      "y": 41,
      "z": 16,
      "name": "Rock_Ice"
    },
    {
      "x": -25,
      "y": 42,
      "z": 16,
      "name": "Rock_Ice"
    },
    {
      "x": -25,
      "y": 43,
      "z": 16,
      "name": "Rock_Ice"
    },
    {
      "x": -25,
      "y": 44,
      "z": 16,
      "name": "Rock_Ice"
    },
    {
      "x": -25,
      "y": 45,
      "z": 16,
      "name": "Soil_Snow"
    },
    {
      "x": -25,
      "y": 41,
      "z": 17,
      "name": "Rock_Ice"
    },
    {
      "x": -25,
      "y": 42,
      "z": 17,
      "name": "Rock_Ice"
    },
    {
      "x": -25,
      "y": 43,
      "z": 17,
      "name": "Soil_Snow"
    },
    {
      "x": -24,
      "y": 35,
      "z": 12,
      "name": "Rock_Ice"
    },
    {
      "x": -24,
      "y": 36,
      "z": 12,
      "name": "Rock_Ice"
    },
    {
      "x": -24,
      "y": 37,
      "z": 12,
      "name": "Rock_Ice"
    },
    {
      "x": -24,
      "y": 38,
      "z": 12,
      "name": "Rock_Ice"
    },
    {
      "x": -24,
      "y": 39,
      "z": 12,
      "name": "Rock_Ice"
    },
    {
      "x": -24,
      "y": 40,
      "z": 12,
      "name": "Rock_Ice"
    },
    {
      "x": -24,
      "y": 41,
      "z": 12,
      "name": "Rock_Ice"
    },
    {
      "x": -24,
      "y": 42,
      "z": 12,
      "name": "Rock_Ice"
    },
    {
      "x": -24,
      "y": 43,
      "z": 12,
      "name": "Rock_Ice"
    },
    {
      "x": -24,
      "y": 44,
      "z": 12,
      "name": "Rock_Ice"
    },
    {
      "x": -24,
      "y": 45,
      "z": 12,
      "name": "Rock_Ice"
    },
    {
      "x": -24,
      "y": 46,
      "z": 12,
      "name": "Rock_Ice"
    },
    {
      "x": -24,
      "y": 47,
      "z": 12,
      "name": "Soil_Snow"
    },
    {
      "x": -24,
      "y": 33,
      "z": 13,
      "name": "Rock_Ice"
    },
    {
      "x": -24,
      "y": 34,
      "z": 13,
      "name": "Rock_Ice"
    },
    {
      "x": -24,
      "y": 35,
      "z": 13,
      "name": "Rock_Ice"
    },
    {
      "x": -24,
      "y": 36,
      "z": 13,
      "name": "Rock_Ice"
    },
    {
      "x": -24,
      "y": 37,
      "z": 13,
      "name": "Rock_Ice"
    },
    {
      "x": -24,
      "y": 38,
      "z": 13,
      "name": "Rock_Ice"
    },
    {
      "x": -24,
      "y": 39,
      "z": 13,
      "name": "Rock_Ice"
    },
    {
      "x": -24,
      "y": 40,
      "z": 13,
      "name": "Rock_Ice"
    },
    {
      "x": -24,
      "y": 41,
      "z": 13,
      "name": "Rock_Ice"
    },
    {
      "x": -24,
      "y": 42,
      "z": 13,
      "name": "Rock_Ice"
    },
    {
      "x": -24,
      "y": 43,
      "z": 13,
      "name": "Rock_Ice"
    },
    {
      "x": -24,
      "y": 44,
      "z": 13,
      "name": "Rock_Ice"
    },
    {
      "x": -24,
      "y": 45,
      "z": 13,
      "name": "Rock_Ice"
    },
    {
      "x": -24,
      "y": 46,
      "z": 13,
      "name": "Rock_Ice"
    },
    {
      "x": -24,
      "y": 47,
      "z": 13,
      "name": "Soil_Snow"
    },
    {
      "x": -24,
      "y": 34,
      "z": 14,
      "name": "Rock_Ice"
    },
    {
      "x": -24,
      "y": 35,
      "z": 14,
      "name": "Rock_Ice"
    },
    {
      "x": -24,
      "y": 36,
      "z": 14,
      "name": "Rock_Ice"
    },
    {
      "x": -24,
      "y": 37,
      "z": 14,
      "name": "Rock_Ice"
    },
    {
      "x": -24,
      "y": 38,
      "z": 14,
      "name": "Rock_Ice"
    },
    {
      "x": -24,
      "y": 39,
      "z": 14,
      "name": "Rock_Ice"
    },
    {
      "x": -24,
      "y": 40,
      "z": 14,
      "name": "Rock_Ice"
    },
    {
      "x": -24,
      "y": 41,
      "z": 14,
      "name": "Rock_Ice"
    },
    {
      "x": -24,
      "y": 42,
      "z": 14,
      "name": "Rock_Ice"
    },
    {
      "x": -24,
      "y": 43,
      "z": 14,
      "name": "Rock_Ice"
    },
    {
      "x": -24,
      "y": 44,
      "z": 14,
      "name": "Rock_Ice"
    },
    {
      "x": -24,
      "y": 45,
      "z": 14,
      "name": "Rock_Ice"
    },
    {
      "x": -24,
      "y": 46,
      "z": 14,
      "name": "Rock_Ice"
    },
    {
      "x": -24,
      "y": 47,
      "z": 14,
      "name": "Soil_Snow"
    },
    {
      "x": -24,
      "y": 35,
      "z": 15,
      "name": "Rock_Ice"
    },
    {
      "x": -24,
      "y": 36,
      "z": 15,
      "name": "Rock_Ice"
    },
    {
      "x": -24,
      "y": 37,
      "z": 15,
      "name": "Rock_Ice"
    },
    {
      "x": -24,
      "y": 38,
      "z": 15,
      "name": "Rock_Ice"
    },
    {
      "x": -24,
      "y": 39,
      "z": 15,
      "name": "Rock_Ice"
    },
    {
      "x": -24,
      "y": 40,
      "z": 15,
      "name": "Rock_Ice"
    },
    {
      "x": -24,
      "y": 41,
      "z": 15,
      "name": "Rock_Ice"
    },
    {
      "x": -24,
      "y": 42,
      "z": 15,
      "name": "Rock_Ice"
    },
    {
      "x": -24,
      "y": 43,
      "z": 15,
      "name": "Rock_Ice"
    },
    {
      "x": -24,
      "y": 44,
      "z": 15,
      "name": "Rock_Ice"
    },
    {
      "x": -24,
      "y": 45,
      "z": 15,
      "name": "Rock_Ice"
    },
    {
      "x": -24,
      "y": 46,
      "z": 15,
      "name": "Soil_Snow"
    },
    {
      "x": -24,
      "y": 37,
      "z": 16,
      "name": "Rock_Ice"
    },
    {
      "x": -24,
      "y": 38,
      "z": 16,
      "name": "Rock_Ice"
    },
    {
      "x": -24,
      "y": 39,
      "z": 16,
      "name": "Rock_Ice"
    },
    {
      "x": -24,
      "y": 40,
      "z": 16,
      "name": "Rock_Ice"
    },
    {
      "x": -24,
      "y": 41,
      "z": 16,
      "name": "Rock_Ice"
    },
    {
      "x": -24,
      "y": 42,
      "z": 16,
      "name": "Rock_Ice"
    },
    {
      "x": -24,
      "y": 43,
      "z": 16,
      "name": "Rock_Ice"
    },
    {
      "x": -24,
      "y": 44,
      "z": 16,
      "name": "Rock_Ice"
    },
    {
      "x": -24,
      "y": 45,
      "z": 16,
      "name": "Soil_Snow"
    },
    {
      "x": -24,
      "y": 39,
      "z": 17,
      "name": "Rock_Ice"
    },
    {
      "x": -24,
      "y": 40,
      "z": 17,
      "name": "Rock_Ice"
    },
    {
      "x": -24,
      "y": 41,
      "z": 17,
      "name": "Rock_Ice"
    },
    {
      "x": -24,
      "y": 42,
      "z": 17,
      "name": "Soil_Snow"
    },
    {
      "x": -23,
      "y": 34,
      "z": 11,
      "name": "Rock_Ice"
    },
    {
      "x": -23,
      "y": 35,
      "z": 11,
      "name": "Rock_Ice"
    },
    {
      "x": -23,
      "y": 36,
      "z": 11,
      "name": "Rock_Ice"
    },
    {
      "x": -23,
      "y": 37,
      "z": 11,
      "name": "Rock_Ice"
    },
    {
      "x": -23,
      "y": 38,
      "z": 11,
      "name": "Rock_Ice"
    },
    {
      "x": -23,
      "y": 39,
      "z": 11,
      "name": "Rock_Ice"
    },
    {
      "x": -23,
      "y": 40,
      "z": 11,
      "name": "Rock_Ice"
    },
    {
      "x": -23,
      "y": 41,
      "z": 11,
      "name": "Rock_Ice"
    },
    {
      "x": -23,
      "y": 42,
      "z": 11,
      "name": "Rock_Ice"
    },
    {
      "x": -23,
      "y": 43,
      "z": 11,
      "name": "Rock_Ice"
    },
    {
      "x": -23,
      "y": 44,
      "z": 11,
      "name": "Rock_Ice"
    },
    {
      "x": -23,
      "y": 45,
      "z": 11,
      "name": "Rock_Ice"
    },
    {
      "x": -23,
      "y": 46,
      "z": 11,
      "name": "Rock_Ice"
    },
    {
      "x": -23,
      "y": 47,
      "z": 11,
      "name": "Soil_Snow"
    },
    {
      "x": -23,
      "y": 32,
      "z": 12,
      "name": "Rock_Ice"
    },
    {
      "x": -23,
      "y": 33,
      "z": 12,
      "name": "Rock_Ice"
    },
    {
      "x": -23,
      "y": 34,
      "z": 12,
      "name": "Rock_Ice"
    },
    {
      "x": -23,
      "y": 35,
      "z": 12,
      "name": "Rock_Ice"
    },
    {
      "x": -23,
      "y": 36,
      "z": 12,
      "name": "Rock_Ice"
    },
    {
      "x": -23,
      "y": 37,
      "z": 12,
      "name": "Rock_Ice"
    },
    {
      "x": -23,
      "y": 38,
      "z": 12,
      "name": "Rock_Ice"
    },
    {
      "x": -23,
      "y": 39,
      "z": 12,
      "name": "Rock_Ice"
    },
    {
      "x": -23,
      "y": 40,
      "z": 12,
      "name": "Rock_Ice"
    },
    {
      "x": -23,
      "y": 41,
      "z": 12,
      "name": "Rock_Ice"
    },
    {
      "x": -23,
      "y": 42,
      "z": 12,
      "name": "Rock_Ice"
    },
    {
      "x": -23,
      "y": 43,
      "z": 12,
      "name": "Rock_Ice"
    },
    {
      "x": -23,
      "y": 44,
      "z": 12,
      "name": "Rock_Ice"
    },
    {
      "x": -23,
      "y": 45,
      "z": 12,
      "name": "Rock_Ice"
    },
    {
      "x": -23,
      "y": 46,
      "z": 12,
      "name": "Rock_Ice"
    },
    {
      "x": -23,
      "y": 47,
      "z": 12,
      "name": "Soil_Snow"
    },
    {
      "x": -23,
      "y": 32,
      "z": 13,
      "name": "Rock_Ice"
    },
    {
      "x": -23,
      "y": 33,
      "z": 13,
      "name": "Rock_Ice"
    },
    {
      "x": -23,
      "y": 34,
      "z": 13,
      "name": "Rock_Ice"
    },
    {
      "x": -23,
      "y": 35,
      "z": 13,
      "name": "Rock_Ice"
    },
    {
      "x": -23,
      "y": 36,
      "z": 13,
      "name": "Rock_Ice"
    },
    {
      "x": -23,
      "y": 37,
      "z": 13,
      "name": "Rock_Ice"
    },
    {
      "x": -23,
      "y": 38,
      "z": 13,
      "name": "Rock_Ice"
    },
    {
      "x": -23,
      "y": 39,
      "z": 13,
      "name": "Rock_Ice"
    },
    {
      "x": -23,
      "y": 40,
      "z": 13,
      "name": "Rock_Ice"
    },
    {
      "x": -23,
      "y": 41,
      "z": 13,
      "name": "Rock_Ice"
    },
    {
      "x": -23,
      "y": 42,
      "z": 13,
      "name": "Rock_Ice"
    },
    {
      "x": -23,
      "y": 43,
      "z": 13,
      "name": "Rock_Ice"
    },
    {
      "x": -23,
      "y": 44,
      "z": 13,
      "name": "Rock_Ice"
    },
    {
      "x": -23,
      "y": 45,
      "z": 13,
      "name": "Rock_Ice"
    },
    {
      "x": -23,
      "y": 46,
      "z": 13,
      "name": "Rock_Ice"
    },
    {
      "x": -23,
      "y": 47,
      "z": 13,
      "name": "Soil_Snow"
    },
    {
      "x": -23,
      "y": 33,
      "z": 14,
      "name": "Rock_Ice"
    },
    {
      "x": -23,
      "y": 34,
      "z": 14,
      "name": "Rock_Ice"
    },
    {
      "x": -23,
      "y": 35,
      "z": 14,
      "name": "Rock_Ice"
    },
    {
      "x": -23,
      "y": 36,
      "z": 14,
      "name": "Rock_Ice"
    },
    {
      "x": -23,
      "y": 37,
      "z": 14,
      "name": "Rock_Ice"
    },
    {
      "x": -23,
      "y": 38,
      "z": 14,
      "name": "Rock_Ice"
    },
    {
      "x": -23,
      "y": 39,
      "z": 14,
      "name": "Rock_Ice"
    },
    {
      "x": -23,
      "y": 40,
      "z": 14,
      "name": "Rock_Ice"
    },
    {
      "x": -23,
      "y": 41,
      "z": 14,
      "name": "Rock_Ice"
    },
    {
      "x": -23,
      "y": 42,
      "z": 14,
      "name": "Rock_Ice"
    },
    {
      "x": -23,
      "y": 43,
      "z": 14,
      "name": "Rock_Ice"
    },
    {
      "x": -23,
      "y": 44,
      "z": 14,
      "name": "Rock_Ice"
    },
    {
      "x": -23,
      "y": 45,
      "z": 14,
      "name": "Rock_Ice"
    },
    {
      "x": -23,
      "y": 46,
      "z": 14,
      "name": "Rock_Ice"
    },
    {
      "x": -23,
      "y": 47,
      "z": 14,
      "name": "Soil_Snow"
    },
    {
      "x": -23,
      "y": 34,
      "z": 15,
      "name": "Rock_Ice"
    },
    {
      "x": -23,
      "y": 35,
      "z": 15,
      "name": "Rock_Ice"
    },
    {
      "x": -23,
      "y": 36,
      "z": 15,
      "name": "Rock_Ice"
    },
    {
      "x": -23,
      "y": 37,
      "z": 15,
      "name": "Rock_Ice"
    },
    {
      "x": -23,
      "y": 38,
      "z": 15,
      "name": "Rock_Ice"
    },
    {
      "x": -23,
      "y": 39,
      "z": 15,
      "name": "Rock_Ice"
    },
    {
      "x": -23,
      "y": 40,
      "z": 15,
      "name": "Rock_Ice"
    },
    {
      "x": -23,
      "y": 41,
      "z": 15,
      "name": "Rock_Ice"
    },
    {
      "x": -23,
      "y": 42,
      "z": 15,
      "name": "Rock_Ice"
    },
    {
      "x": -23,
      "y": 43,
      "z": 15,
      "name": "Rock_Ice"
    },
    {
      "x": -23,
      "y": 44,
      "z": 15,
      "name": "Rock_Ice"
    },
    {
      "x": -23,
      "y": 45,
      "z": 15,
      "name": "Rock_Ice"
    },
    {
      "x": -23,
      "y": 46,
      "z": 15,
      "name": "Soil_Snow"
    },
    {
      "x": -23,
      "y": 36,
      "z": 16,
      "name": "Rock_Ice"
    },
    {
      "x": -23,
      "y": 37,
      "z": 16,
      "name": "Rock_Ice"
    },
    {
      "x": -23,
      "y": 38,
      "z": 16,
      "name": "Rock_Ice"
    },
    {
      "x": -23,
      "y": 39,
      "z": 16,
      "name": "Rock_Ice"
    },
    {
      "x": -23,
      "y": 40,
      "z": 16,
      "name": "Rock_Ice"
    },
    {
      "x": -23,
      "y": 41,
      "z": 16,
      "name": "Rock_Ice"
    },
    {
      "x": -23,
      "y": 42,
      "z": 16,
      "name": "Rock_Ice"
    },
    {
      "x": -23,
      "y": 43,
      "z": 16,
      "name": "Rock_Ice"
    },
    {
      "x": -23,
      "y": 44,
      "z": 16,
      "name": "Rock_Ice"
    },
    {
      "x": -23,
      "y": 45,
      "z": 16,
      "name": "Soil_Snow"
    },
    {
      "x": -23,
      "y": 38,
      "z": 17,
      "name": "Rock_Ice"
    },
    {
      "x": -23,
      "y": 39,
      "z": 17,
      "name": "Rock_Ice"
    },
    {
      "x": -23,
      "y": 40,
      "z": 17,
      "name": "Rock_Ice"
    },
    {
      "x": -23,
      "y": 41,
      "z": 17,
      "name": "Rock_Ice"
    },
    {
      "x": -23,
      "y": 42,
      "z": 17,
      "name": "Soil_Snow"
    },
    {
      "x": -22,
      "y": 34,
      "z": 10,
      "name": "Rock_Ice"
    },
    {
      "x": -22,
      "y": 35,
      "z": 10,
      "name": "Rock_Ice"
    },
    {
      "x": -22,
      "y": 36,
      "z": 10,
      "name": "Rock_Ice"
    },
    {
      "x": -22,
      "y": 37,
      "z": 10,
      "name": "Rock_Ice"
    },
    {
      "x": -22,
      "y": 38,
      "z": 10,
      "name": "Rock_Ice"
    },
    {
      "x": -22,
      "y": 39,
      "z": 10,
      "name": "Rock_Ice"
    },
    {
      "x": -22,
      "y": 40,
      "z": 10,
      "name": "Rock_Ice"
    },
    {
      "x": -22,
      "y": 41,
      "z": 10,
      "name": "Rock_Ice"
    },
    {
      "x": -22,
      "y": 42,
      "z": 10,
      "name": "Rock_Ice"
    },
    {
      "x": -22,
      "y": 43,
      "z": 10,
      "name": "Rock_Ice"
    },
    {
      "x": -22,
      "y": 44,
      "z": 10,
      "name": "Rock_Ice"
    },
    {
      "x": -22,
      "y": 45,
      "z": 10,
      "name": "Rock_Ice"
    },
    {
      "x": -22,
      "y": 46,
      "z": 10,
      "name": "Soil_Snow"
    },
    {
      "x": -22,
      "y": 31,
      "z": 11,
      "name": "Rock_Ice"
    },
    {
      "x": -22,
      "y": 32,
      "z": 11,
      "name": "Rock_Ice"
    },
    {
      "x": -22,
      "y": 33,
      "z": 11,
      "name": "Rock_Ice"
    },
    {
      "x": -22,
      "y": 34,
      "z": 11,
      "name": "Rock_Ice"
    },
    {
      "x": -22,
      "y": 35,
      "z": 11,
      "name": "Rock_Ice"
    },
    {
      "x": -22,
      "y": 36,
      "z": 11,
      "name": "Rock_Ice"
    },
    {
      "x": -22,
      "y": 37,
      "z": 11,
      "name": "Rock_Ice"
    },
    {
      "x": -22,
      "y": 38,
      "z": 11,
      "name": "Rock_Ice"
    },
    {
      "x": -22,
      "y": 39,
      "z": 11,
      "name": "Rock_Ice"
    },
    {
      "x": -22,
      "y": 40,
      "z": 11,
      "name": "Rock_Ice"
    },
    {
      "x": -22,
      "y": 41,
      "z": 11,
      "name": "Rock_Ice"
    },
    {
      "x": -22,
      "y": 42,
      "z": 11,
      "name": "Rock_Ice"
    },
    {
      "x": -22,
      "y": 43,
      "z": 11,
      "name": "Rock_Ice"
    },
    {
      "x": -22,
      "y": 44,
      "z": 11,
      "name": "Rock_Ice"
    },
    {
      "x": -22,
      "y": 45,
      "z": 11,
      "name": "Rock_Ice"
    },
    {
      "x": -22,
      "y": 46,
      "z": 11,
      "name": "Rock_Ice"
    },
    {
      "x": -22,
      "y": 47,
      "z": 11,
      "name": "Soil_Snow"
    },
    {
      "x": -22,
      "y": 30,
      "z": 12,
      "name": "Rock_Ice"
    },
    {
      "x": -22,
      "y": 31,
      "z": 12,
      "name": "Rock_Ice"
    },
    {
      "x": -22,
      "y": 32,
      "z": 12,
      "name": "Rock_Ice"
    },
    {
      "x": -22,
      "y": 33,
      "z": 12,
      "name": "Rock_Ice"
    },
    {
      "x": -22,
      "y": 34,
      "z": 12,
      "name": "Rock_Ice"
    },
    {
      "x": -22,
      "y": 35,
      "z": 12,
      "name": "Rock_Ice"
    },
    {
      "x": -22,
      "y": 36,
      "z": 12,
      "name": "Rock_Ice"
    },
    {
      "x": -22,
      "y": 37,
      "z": 12,
      "name": "Rock_Ice"
    },
    {
      "x": -22,
      "y": 38,
      "z": 12,
      "name": "Rock_Ice"
    },
    {
      "x": -22,
      "y": 39,
      "z": 12,
      "name": "Rock_Ice"
    },
    {
      "x": -22,
      "y": 40,
      "z": 12,
      "name": "Rock_Ice"
    },
    {
      "x": -22,
      "y": 41,
      "z": 12,
      "name": "Rock_Ice"
    },
    {
      "x": -22,
      "y": 42,
      "z": 12,
      "name": "Rock_Ice"
    },
    {
      "x": -22,
      "y": 43,
      "z": 12,
      "name": "Rock_Ice"
    },
    {
      "x": -22,
      "y": 44,
      "z": 12,
      "name": "Rock_Ice"
    },
    {
      "x": -22,
      "y": 45,
      "z": 12,
      "name": "Rock_Ice"
    },
    {
      "x": -22,
      "y": 46,
      "z": 12,
      "name": "Rock_Ice"
    },
    {
      "x": -22,
      "y": 47,
      "z": 12,
      "name": "Soil_Snow"
    },
    {
      "x": -22,
      "y": 30,
      "z": 13,
      "name": "Rock_Ice"
    },
    {
      "x": -22,
      "y": 31,
      "z": 13,
      "name": "Rock_Ice"
    },
    {
      "x": -22,
      "y": 32,
      "z": 13,
      "name": "Rock_Ice"
    },
    {
      "x": -22,
      "y": 33,
      "z": 13,
      "name": "Rock_Ice"
    },
    {
      "x": -22,
      "y": 34,
      "z": 13,
      "name": "Rock_Ice"
    },
    {
      "x": -22,
      "y": 35,
      "z": 13,
      "name": "Rock_Ice"
    },
    {
      "x": -22,
      "y": 36,
      "z": 13,
      "name": "Rock_Ice"
    },
    {
      "x": -22,
      "y": 37,
      "z": 13,
      "name": "Rock_Ice"
    },
    {
      "x": -22,
      "y": 38,
      "z": 13,
      "name": "Rock_Ice"
    },
    {
      "x": -22,
      "y": 39,
      "z": 13,
      "name": "Rock_Ice"
    },
    {
      "x": -22,
      "y": 40,
      "z": 13,
      "name": "Rock_Ice"
    },
    {
      "x": -22,
      "y": 41,
      "z": 13,
      "name": "Rock_Ice"
    },
    {
      "x": -22,
      "y": 42,
      "z": 13,
      "name": "Rock_Ice"
    },
    {
      "x": -22,
      "y": 43,
      "z": 13,
      "name": "Rock_Ice"
    },
    {
      "x": -22,
      "y": 44,
      "z": 13,
      "name": "Rock_Ice"
    },
    {
      "x": -22,
      "y": 45,
      "z": 13,
      "name": "Rock_Ice"
    },
    {
      "x": -22,
      "y": 46,
      "z": 13,
      "name": "Rock_Ice"
    },
    {
      "x": -22,
      "y": 47,
      "z": 13,
      "name": "Soil_Snow"
    },
    {
      "x": -22,
      "y": 32,
      "z": 14,
      "name": "Rock_Ice"
    },
    {
      "x": -22,
      "y": 33,
      "z": 14,
      "name": "Rock_Ice"
    },
    {
      "x": -22,
      "y": 34,
      "z": 14,
      "name": "Rock_Ice"
    },
    {
      "x": -22,
      "y": 35,
      "z": 14,
      "name": "Rock_Ice"
    },
    {
      "x": -22,
      "y": 36,
      "z": 14,
      "name": "Rock_Ice"
    },
    {
      "x": -22,
      "y": 37,
      "z": 14,
      "name": "Rock_Ice"
    },
    {
      "x": -22,
      "y": 38,
      "z": 14,
      "name": "Rock_Ice"
    },
    {
      "x": -22,
      "y": 39,
      "z": 14,
      "name": "Rock_Ice"
    },
    {
      "x": -22,
      "y": 40,
      "z": 14,
      "name": "Rock_Ice"
    },
    {
      "x": -22,
      "y": 41,
      "z": 14,
      "name": "Rock_Ice"
    },
    {
      "x": -22,
      "y": 42,
      "z": 14,
      "name": "Rock_Ice"
    },
    {
      "x": -22,
      "y": 43,
      "z": 14,
      "name": "Rock_Ice"
    },
    {
      "x": -22,
      "y": 44,
      "z": 14,
      "name": "Rock_Ice"
    },
    {
      "x": -22,
      "y": 45,
      "z": 14,
      "name": "Rock_Ice"
    },
    {
      "x": -22,
      "y": 46,
      "z": 14,
      "name": "Rock_Ice"
    },
    {
      "x": -22,
      "y": 47,
      "z": 14,
      "name": "Soil_Snow"
    },
    {
      "x": -22,
      "y": 33,
      "z": 15,
      "name": "Rock_Ice"
    },
    {
      "x": -22,
      "y": 34,
      "z": 15,
      "name": "Rock_Ice"
    },
    {
      "x": -22,
      "y": 35,
      "z": 15,
      "name": "Rock_Ice"
    },
    {
      "x": -22,
      "y": 36,
      "z": 15,
      "name": "Rock_Ice"
    },
    {
      "x": -22,
      "y": 37,
      "z": 15,
      "name": "Rock_Ice"
    },
    {
      "x": -22,
      "y": 38,
      "z": 15,
      "name": "Rock_Ice"
    },
    {
      "x": -22,
      "y": 39,
      "z": 15,
      "name": "Rock_Ice"
    },
    {
      "x": -22,
      "y": 40,
      "z": 15,
      "name": "Rock_Ice"
    },
    {
      "x": -22,
      "y": 41,
      "z": 15,
      "name": "Rock_Ice"
    },
    {
      "x": -22,
      "y": 42,
      "z": 15,
      "name": "Rock_Ice"
    },
    {
      "x": -22,
      "y": 43,
      "z": 15,
      "name": "Rock_Ice"
    },
    {
      "x": -22,
      "y": 44,
      "z": 15,
      "name": "Rock_Ice"
    },
    {
      "x": -22,
      "y": 45,
      "z": 15,
      "name": "Rock_Ice"
    },
    {
      "x": -22,
      "y": 46,
      "z": 15,
      "name": "Soil_Snow"
    },
    {
      "x": -22,
      "y": 35,
      "z": 16,
      "name": "Rock_Ice"
    },
    {
      "x": -22,
      "y": 36,
      "z": 16,
      "name": "Rock_Ice"
    },
    {
      "x": -22,
      "y": 37,
      "z": 16,
      "name": "Rock_Ice"
    },
    {
      "x": -22,
      "y": 38,
      "z": 16,
      "name": "Rock_Ice"
    },
    {
      "x": -22,
      "y": 39,
      "z": 16,
      "name": "Rock_Ice"
    },
    {
      "x": -22,
      "y": 40,
      "z": 16,
      "name": "Rock_Ice"
    },
    {
      "x": -22,
      "y": 41,
      "z": 16,
      "name": "Rock_Ice"
    },
    {
      "x": -22,
      "y": 42,
      "z": 16,
      "name": "Rock_Ice"
    },
    {
      "x": -22,
      "y": 43,
      "z": 16,
      "name": "Rock_Ice"
    },
    {
      "x": -22,
      "y": 44,
      "z": 16,
      "name": "Soil_Snow"
    },
    {
      "x": -22,
      "y": 37,
      "z": 17,
      "name": "Rock_Ice"
    },
    {
      "x": -22,
      "y": 38,
      "z": 17,
      "name": "Rock_Ice"
    },
    {
      "x": -22,
      "y": 39,
      "z": 17,
      "name": "Rock_Ice"
    },
    {
      "x": -22,
      "y": 40,
      "z": 17,
      "name": "Rock_Ice"
    },
    {
      "x": -22,
      "y": 41,
      "z": 17,
      "name": "Rock_Ice"
    },
    {
      "x": -22,
      "y": 42,
      "z": 17,
      "name": "Soil_Snow"
    },
    {
      "x": -21,
      "y": 30,
      "z": 10,
      "name": "Rock_Ice"
    },
    {
      "x": -21,
      "y": 31,
      "z": 10,
      "name": "Rock_Ice"
    },
    {
      "x": -21,
      "y": 32,
      "z": 10,
      "name": "Rock_Ice"
    },
    {
      "x": -21,
      "y": 33,
      "z": 10,
      "name": "Rock_Ice"
    },
    {
      "x": -21,
      "y": 34,
      "z": 10,
      "name": "Rock_Ice"
    },
    {
      "x": -21,
      "y": 35,
      "z": 10,
      "name": "Rock_Ice"
    },
    {
      "x": -21,
      "y": 36,
      "z": 10,
      "name": "Rock_Ice"
    },
    {
      "x": -21,
      "y": 37,
      "z": 10,
      "name": "Rock_Ice"
    },
    {
      "x": -21,
      "y": 38,
      "z": 10,
      "name": "Rock_Ice"
    },
    {
      "x": -21,
      "y": 39,
      "z": 10,
      "name": "Rock_Ice"
    },
    {
      "x": -21,
      "y": 40,
      "z": 10,
      "name": "Rock_Ice"
    },
    {
      "x": -21,
      "y": 41,
      "z": 10,
      "name": "Rock_Ice"
    },
    {
      "x": -21,
      "y": 42,
      "z": 10,
      "name": "Rock_Ice"
    },
    {
      "x": -21,
      "y": 43,
      "z": 10,
      "name": "Rock_Ice"
    },
    {
      "x": -21,
      "y": 44,
      "z": 10,
      "name": "Rock_Ice"
    },
    {
      "x": -21,
      "y": 45,
      "z": 10,
      "name": "Rock_Ice"
    },
    {
      "x": -21,
      "y": 46,
      "z": 10,
      "name": "Soil_Snow"
    },
    {
      "x": -21,
      "y": 29,
      "z": 11,
      "name": "Rock_Ice"
    },
    {
      "x": -21,
      "y": 30,
      "z": 11,
      "name": "Rock_Ice"
    },
    {
      "x": -21,
      "y": 31,
      "z": 11,
      "name": "Rock_Ice"
    },
    {
      "x": -21,
      "y": 32,
      "z": 11,
      "name": "Rock_Ice"
    },
    {
      "x": -21,
      "y": 33,
      "z": 11,
      "name": "Rock_Ice"
    },
    {
      "x": -21,
      "y": 34,
      "z": 11,
      "name": "Rock_Ice"
    },
    {
      "x": -21,
      "y": 35,
      "z": 11,
      "name": "Rock_Ice"
    },
    {
      "x": -21,
      "y": 36,
      "z": 11,
      "name": "Rock_Ice"
    },
    {
      "x": -21,
      "y": 37,
      "z": 11,
      "name": "Rock_Ice"
    },
    {
      "x": -21,
      "y": 38,
      "z": 11,
      "name": "Rock_Ice"
    },
    {
      "x": -21,
      "y": 39,
      "z": 11,
      "name": "Rock_Ice"
    },
    {
      "x": -21,
      "y": 40,
      "z": 11,
      "name": "Rock_Ice"
    },
    {
      "x": -21,
      "y": 41,
      "z": 11,
      "name": "Rock_Ice"
    },
    {
      "x": -21,
      "y": 42,
      "z": 11,
      "name": "Rock_Ice"
    },
    {
      "x": -21,
      "y": 43,
      "z": 11,
      "name": "Rock_Ice"
    },
    {
      "x": -21,
      "y": 44,
      "z": 11,
      "name": "Rock_Ice"
    },
    {
      "x": -21,
      "y": 45,
      "z": 11,
      "name": "Rock_Ice"
    },
    {
      "x": -21,
      "y": 46,
      "z": 11,
      "name": "Rock_Ice"
    },
    {
      "x": -21,
      "y": 47,
      "z": 11,
      "name": "Soil_Snow"
    },
    {
      "x": -21,
      "y": 28,
      "z": 12,
      "name": "Rock_Ice"
    },
    {
      "x": -21,
      "y": 29,
      "z": 12,
      "name": "Rock_Ice"
    },
    {
      "x": -21,
      "y": 30,
      "z": 12,
      "name": "Rock_Ice"
    },
    {
      "x": -21,
      "y": 31,
      "z": 12,
      "name": "Rock_Ice"
    },
    {
      "x": -21,
      "y": 32,
      "z": 12,
      "name": "Rock_Ice"
    },
    {
      "x": -21,
      "y": 33,
      "z": 12,
      "name": "Rock_Ice"
    },
    {
      "x": -21,
      "y": 34,
      "z": 12,
      "name": "Rock_Ice"
    },
    {
      "x": -21,
      "y": 35,
      "z": 12,
      "name": "Rock_Ice"
    },
    {
      "x": -21,
      "y": 36,
      "z": 12,
      "name": "Rock_Ice"
    },
    {
      "x": -21,
      "y": 37,
      "z": 12,
      "name": "Rock_Ice"
    },
    {
      "x": -21,
      "y": 38,
      "z": 12,
      "name": "Rock_Ice"
    },
    {
      "x": -21,
      "y": 39,
      "z": 12,
      "name": "Rock_Ice"
    },
    {
      "x": -21,
      "y": 40,
      "z": 12,
      "name": "Rock_Ice"
    },
    {
      "x": -21,
      "y": 41,
      "z": 12,
      "name": "Rock_Ice"
    },
    {
      "x": -21,
      "y": 42,
      "z": 12,
      "name": "Rock_Ice"
    },
    {
      "x": -21,
      "y": 43,
      "z": 12,
      "name": "Rock_Ice"
    },
    {
      "x": -21,
      "y": 44,
      "z": 12,
      "name": "Rock_Ice"
    },
    {
      "x": -21,
      "y": 45,
      "z": 12,
      "name": "Rock_Ice"
    },
    {
      "x": -21,
      "y": 46,
      "z": 12,
      "name": "Rock_Ice"
    },
    {
      "x": -21,
      "y": 47,
      "z": 12,
      "name": "Soil_Snow"
    },
    {
      "x": -21,
      "y": 29,
      "z": 13,
      "name": "Rock_Ice"
    },
    {
      "x": -21,
      "y": 30,
      "z": 13,
      "name": "Rock_Ice"
    },
    {
      "x": -21,
      "y": 31,
      "z": 13,
      "name": "Rock_Ice"
    },
    {
      "x": -21,
      "y": 32,
      "z": 13,
      "name": "Rock_Ice"
    },
    {
      "x": -21,
      "y": 33,
      "z": 13,
      "name": "Rock_Ice"
    },
    {
      "x": -21,
      "y": 34,
      "z": 13,
      "name": "Rock_Ice"
    },
    {
      "x": -21,
      "y": 35,
      "z": 13,
      "name": "Rock_Ice"
    },
    {
      "x": -21,
      "y": 36,
      "z": 13,
      "name": "Rock_Ice"
    },
    {
      "x": -21,
      "y": 37,
      "z": 13,
      "name": "Rock_Ice"
    },
    {
      "x": -21,
      "y": 38,
      "z": 13,
      "name": "Rock_Ice"
    },
    {
      "x": -21,
      "y": 39,
      "z": 13,
      "name": "Rock_Ice"
    },
    {
      "x": -21,
      "y": 40,
      "z": 13,
      "name": "Rock_Ice"
    },
    {
      "x": -21,
      "y": 41,
      "z": 13,
      "name": "Rock_Ice"
    },
    {
      "x": -21,
      "y": 42,
      "z": 13,
      "name": "Rock_Ice"
    },
    {
      "x": -21,
      "y": 43,
      "z": 13,
      "name": "Rock_Ice"
    },
    {
      "x": -21,
      "y": 44,
      "z": 13,
      "name": "Rock_Ice"
    },
    {
      "x": -21,
      "y": 45,
      "z": 13,
      "name": "Rock_Ice"
    },
    {
      "x": -21,
      "y": 46,
      "z": 13,
      "name": "Rock_Ice"
    },
    {
      "x": -21,
      "y": 47,
      "z": 13,
      "name": "Soil_Snow"
    },
    {
      "x": -21,
      "y": 31,
      "z": 14,
      "name": "Rock_Ice"
    },
    {
      "x": -21,
      "y": 32,
      "z": 14,
      "name": "Rock_Ice"
    },
    {
      "x": -21,
      "y": 33,
      "z": 14,
      "name": "Rock_Ice"
    },
    {
      "x": -21,
      "y": 34,
      "z": 14,
      "name": "Rock_Ice"
    },
    {
      "x": -21,
      "y": 35,
      "z": 14,
      "name": "Rock_Ice"
    },
    {
      "x": -21,
      "y": 36,
      "z": 14,
      "name": "Rock_Ice"
    },
    {
      "x": -21,
      "y": 37,
      "z": 14,
      "name": "Rock_Ice"
    },
    {
      "x": -21,
      "y": 38,
      "z": 14,
      "name": "Rock_Ice"
    },
    {
      "x": -21,
      "y": 39,
      "z": 14,
      "name": "Rock_Ice"
    },
    {
      "x": -21,
      "y": 40,
      "z": 14,
      "name": "Rock_Ice"
    },
    {
      "x": -21,
      "y": 41,
      "z": 14,
      "name": "Rock_Ice"
    },
    {
      "x": -21,
      "y": 42,
      "z": 14,
      "name": "Rock_Ice"
    },
    {
      "x": -21,
      "y": 43,
      "z": 14,
      "name": "Rock_Ice"
    },
    {
      "x": -21,
      "y": 44,
      "z": 14,
      "name": "Rock_Ice"
    },
    {
      "x": -21,
      "y": 45,
      "z": 14,
      "name": "Rock_Ice"
    },
    {
      "x": -21,
      "y": 46,
      "z": 14,
      "name": "Rock_Ice"
    },
    {
      "x": -21,
      "y": 47,
      "z": 14,
      "name": "Soil_Snow"
    },
    {
      "x": -21,
      "y": 33,
      "z": 15,
      "name": "Rock_Ice"
    },
    {
      "x": -21,
      "y": 34,
      "z": 15,
      "name": "Rock_Ice"
    },
    {
      "x": -21,
      "y": 35,
      "z": 15,
      "name": "Rock_Ice"
    },
    {
      "x": -21,
      "y": 36,
      "z": 15,
      "name": "Rock_Ice"
    },
    {
      "x": -21,
      "y": 37,
      "z": 15,
      "name": "Rock_Ice"
    },
    {
      "x": -21,
      "y": 38,
      "z": 15,
      "name": "Rock_Ice"
    },
    {
      "x": -21,
      "y": 39,
      "z": 15,
      "name": "Rock_Ice"
    },
    {
      "x": -21,
      "y": 40,
      "z": 15,
      "name": "Rock_Ice"
    },
    {
      "x": -21,
      "y": 41,
      "z": 15,
      "name": "Rock_Ice"
    },
    {
      "x": -21,
      "y": 42,
      "z": 15,
      "name": "Rock_Ice"
    },
    {
      "x": -21,
      "y": 43,
      "z": 15,
      "name": "Rock_Ice"
    },
    {
      "x": -21,
      "y": 44,
      "z": 15,
      "name": "Rock_Ice"
    },
    {
      "x": -21,
      "y": 45,
      "z": 15,
      "name": "Rock_Ice"
    },
    {
      "x": -21,
      "y": 46,
      "z": 15,
      "name": "Soil_Snow"
    },
    {
      "x": -21,
      "y": 34,
      "z": 16,
      "name": "Rock_Ice"
    },
    {
      "x": -21,
      "y": 35,
      "z": 16,
      "name": "Rock_Ice"
    },
    {
      "x": -21,
      "y": 36,
      "z": 16,
      "name": "Rock_Ice"
    },
    {
      "x": -21,
      "y": 37,
      "z": 16,
      "name": "Rock_Ice"
    },
    {
      "x": -21,
      "y": 38,
      "z": 16,
      "name": "Rock_Ice"
    },
    {
      "x": -21,
      "y": 39,
      "z": 16,
      "name": "Rock_Ice"
    },
    {
      "x": -21,
      "y": 40,
      "z": 16,
      "name": "Rock_Ice"
    },
    {
      "x": -21,
      "y": 41,
      "z": 16,
      "name": "Rock_Ice"
    },
    {
      "x": -21,
      "y": 42,
      "z": 16,
      "name": "Rock_Ice"
    },
    {
      "x": -21,
      "y": 43,
      "z": 16,
      "name": "Rock_Ice"
    },
    {
      "x": -21,
      "y": 44,
      "z": 16,
      "name": "Soil_Snow"
    },
    {
      "x": -21,
      "y": 37,
      "z": 17,
      "name": "Rock_Ice"
    },
    {
      "x": -21,
      "y": 38,
      "z": 17,
      "name": "Rock_Ice"
    },
    {
      "x": -21,
      "y": 39,
      "z": 17,
      "name": "Rock_Ice"
    },
    {
      "x": -21,
      "y": 40,
      "z": 17,
      "name": "Rock_Ice"
    },
    {
      "x": -21,
      "y": 41,
      "z": 17,
      "name": "Soil_Snow"
    },
    {
      "x": -20,
      "y": 30,
      "z": 9,
      "name": "Rock_Ice"
    },
    {
      "x": -20,
      "y": 31,
      "z": 9,
      "name": "Rock_Ice"
    },
    {
      "x": -20,
      "y": 32,
      "z": 9,
      "name": "Rock_Ice"
    },
    {
      "x": -20,
      "y": 33,
      "z": 9,
      "name": "Rock_Ice"
    },
    {
      "x": -20,
      "y": 34,
      "z": 9,
      "name": "Rock_Ice"
    },
    {
      "x": -20,
      "y": 35,
      "z": 9,
      "name": "Rock_Ice"
    },
    {
      "x": -20,
      "y": 36,
      "z": 9,
      "name": "Rock_Ice"
    },
    {
      "x": -20,
      "y": 37,
      "z": 9,
      "name": "Rock_Ice"
    },
    {
      "x": -20,
      "y": 38,
      "z": 9,
      "name": "Rock_Ice"
    },
    {
      "x": -20,
      "y": 39,
      "z": 9,
      "name": "Rock_Ice"
    },
    {
      "x": -20,
      "y": 40,
      "z": 9,
      "name": "Rock_Ice"
    },
    {
      "x": -20,
      "y": 41,
      "z": 9,
      "name": "Rock_Ice"
    },
    {
      "x": -20,
      "y": 42,
      "z": 9,
      "name": "Rock_Ice"
    },
    {
      "x": -20,
      "y": 43,
      "z": 9,
      "name": "Rock_Ice"
    },
    {
      "x": -20,
      "y": 44,
      "z": 9,
      "name": "Rock_Ice"
    },
    {
      "x": -20,
      "y": 45,
      "z": 9,
      "name": "Rock_Ice"
    },
    {
      "x": -20,
      "y": 46,
      "z": 9,
      "name": "Soil_Snow"
    },
    {
      "x": -20,
      "y": 28,
      "z": 10,
      "name": "Rock_Ice"
    },
    {
      "x": -20,
      "y": 29,
      "z": 10,
      "name": "Rock_Ice"
    },
    {
      "x": -20,
      "y": 30,
      "z": 10,
      "name": "Rock_Ice"
    },
    {
      "x": -20,
      "y": 31,
      "z": 10,
      "name": "Rock_Ice"
    },
    {
      "x": -20,
      "y": 32,
      "z": 10,
      "name": "Rock_Ice"
    },
    {
      "x": -20,
      "y": 33,
      "z": 10,
      "name": "Rock_Ice"
    },
    {
      "x": -20,
      "y": 34,
      "z": 10,
      "name": "Rock_Ice"
    },
    {
      "x": -20,
      "y": 35,
      "z": 10,
      "name": "Rock_Ice"
    },
    {
      "x": -20,
      "y": 36,
      "z": 10,
      "name": "Rock_Ice"
    },
    {
      "x": -20,
      "y": 37,
      "z": 10,
      "name": "Rock_Ice"
    },
    {
      "x": -20,
      "y": 38,
      "z": 10,
      "name": "Rock_Ice"
    },
    {
      "x": -20,
      "y": 39,
      "z": 10,
      "name": "Rock_Ice"
    },
    {
      "x": -20,
      "y": 40,
      "z": 10,
      "name": "Rock_Ice"
    },
    {
      "x": -20,
      "y": 41,
      "z": 10,
      "name": "Rock_Ice"
    },
    {
      "x": -20,
      "y": 42,
      "z": 10,
      "name": "Rock_Ice"
    },
    {
      "x": -20,
      "y": 43,
      "z": 10,
      "name": "Rock_Ice"
    },
    {
      "x": -20,
      "y": 44,
      "z": 10,
      "name": "Rock_Ice"
    },
    {
      "x": -20,
      "y": 45,
      "z": 10,
      "name": "Rock_Ice"
    },
    {
      "x": -20,
      "y": 46,
      "z": 10,
      "name": "Rock_Ice"
    },
    {
      "x": -20,
      "y": 47,
      "z": 10,
      "name": "Soil_Snow"
    },
    {
      "x": -20,
      "y": 27,
      "z": 11,
      "name": "Rock_Ice"
    },
    {
      "x": -20,
      "y": 28,
      "z": 11,
      "name": "Rock_Ice"
    },
    {
      "x": -20,
      "y": 29,
      "z": 11,
      "name": "Rock_Ice"
    },
    {
      "x": -20,
      "y": 30,
      "z": 11,
      "name": "Rock_Ice"
    },
    {
      "x": -20,
      "y": 31,
      "z": 11,
      "name": "Rock_Ice"
    },
    {
      "x": -20,
      "y": 32,
      "z": 11,
      "name": "Rock_Ice"
    },
    {
      "x": -20,
      "y": 33,
      "z": 11,
      "name": "Rock_Ice"
    },
    {
      "x": -20,
      "y": 34,
      "z": 11,
      "name": "Rock_Ice"
    },
    {
      "x": -20,
      "y": 35,
      "z": 11,
      "name": "Rock_Ice"
    },
    {
      "x": -20,
      "y": 36,
      "z": 11,
      "name": "Rock_Ice"
    },
    {
      "x": -20,
      "y": 37,
      "z": 11,
      "name": "Rock_Ice"
    },
    {
      "x": -20,
      "y": 38,
      "z": 11,
      "name": "Rock_Ice"
    },
    {
      "x": -20,
      "y": 39,
      "z": 11,
      "name": "Rock_Ice"
    },
    {
      "x": -20,
      "y": 40,
      "z": 11,
      "name": "Rock_Ice"
    },
    {
      "x": -20,
      "y": 41,
      "z": 11,
      "name": "Rock_Ice"
    },
    {
      "x": -20,
      "y": 42,
      "z": 11,
      "name": "Rock_Ice"
    },
    {
      "x": -20,
      "y": 43,
      "z": 11,
      "name": "Rock_Ice"
    },
    {
      "x": -20,
      "y": 44,
      "z": 11,
      "name": "Rock_Ice"
    },
    {
      "x": -20,
      "y": 45,
      "z": 11,
      "name": "Rock_Ice"
    },
    {
      "x": -20,
      "y": 46,
      "z": 11,
      "name": "Rock_Ice"
    },
    {
      "x": -20,
      "y": 47,
      "z": 11,
      "name": "Soil_Snow"
    },
    {
      "x": -20,
      "y": 27,
      "z": 12,
      "name": "Rock_Ice"
    },
    {
      "x": -20,
      "y": 28,
      "z": 12,
      "name": "Rock_Ice"
    },
    {
      "x": -20,
      "y": 29,
      "z": 12,
      "name": "Rock_Ice"
    },
    {
      "x": -20,
      "y": 30,
      "z": 12,
      "name": "Rock_Ice"
    },
    {
      "x": -20,
      "y": 31,
      "z": 12,
      "name": "Rock_Ice"
    },
    {
      "x": -20,
      "y": 32,
      "z": 12,
      "name": "Rock_Ice"
    },
    {
      "x": -20,
      "y": 33,
      "z": 12,
      "name": "Rock_Ice"
    },
    {
      "x": -20,
      "y": 34,
      "z": 12,
      "name": "Rock_Ice"
    },
    {
      "x": -20,
      "y": 35,
      "z": 12,
      "name": "Rock_Ice"
    },
    {
      "x": -20,
      "y": 36,
      "z": 12,
      "name": "Rock_Ice"
    },
    {
      "x": -20,
      "y": 37,
      "z": 12,
      "name": "Rock_Ice"
    },
    {
      "x": -20,
      "y": 38,
      "z": 12,
      "name": "Rock_Ice"
    },
    {
      "x": -20,
      "y": 39,
      "z": 12,
      "name": "Rock_Ice"
    },
    {
      "x": -20,
      "y": 40,
      "z": 12,
      "name": "Rock_Ice"
    },
    {
      "x": -20,
      "y": 41,
      "z": 12,
      "name": "Rock_Ice"
    },
    {
      "x": -20,
      "y": 42,
      "z": 12,
      "name": "Rock_Ice"
    },
    {
      "x": -20,
      "y": 43,
      "z": 12,
      "name": "Rock_Ice"
    },
    {
      "x": -20,
      "y": 44,
      "z": 12,
      "name": "Rock_Ice"
    },
    {
      "x": -20,
      "y": 45,
      "z": 12,
      "name": "Rock_Ice"
    },
    {
      "x": -20,
      "y": 46,
      "z": 12,
      "name": "Rock_Ice"
    },
    {
      "x": -20,
      "y": 47,
      "z": 12,
      "name": "Soil_Snow"
    },
    {
      "x": -20,
      "y": 29,
      "z": 13,
      "name": "Rock_Ice"
    },
    {
      "x": -20,
      "y": 30,
      "z": 13,
      "name": "Rock_Ice"
    },
    {
      "x": -20,
      "y": 31,
      "z": 13,
      "name": "Rock_Ice"
    },
    {
      "x": -20,
      "y": 32,
      "z": 13,
      "name": "Rock_Ice"
    },
    {
      "x": -20,
      "y": 33,
      "z": 13,
      "name": "Rock_Ice"
    },
    {
      "x": -20,
      "y": 34,
      "z": 13,
      "name": "Rock_Ice"
    },
    {
      "x": -20,
      "y": 35,
      "z": 13,
      "name": "Rock_Ice"
    },
    {
      "x": -20,
      "y": 36,
      "z": 13,
      "name": "Rock_Ice"
    },
    {
      "x": -20,
      "y": 37,
      "z": 13,
      "name": "Rock_Ice"
    },
    {
      "x": -20,
      "y": 38,
      "z": 13,
      "name": "Rock_Ice"
    },
    {
      "x": -20,
      "y": 39,
      "z": 13,
      "name": "Rock_Ice"
    },
    {
      "x": -20,
      "y": 40,
      "z": 13,
      "name": "Rock_Ice"
    },
    {
      "x": -20,
      "y": 41,
      "z": 13,
      "name": "Rock_Ice"
    },
    {
      "x": -20,
      "y": 42,
      "z": 13,
      "name": "Rock_Ice"
    },
    {
      "x": -20,
      "y": 43,
      "z": 13,
      "name": "Rock_Ice"
    },
    {
      "x": -20,
      "y": 44,
      "z": 13,
      "name": "Rock_Ice"
    },
    {
      "x": -20,
      "y": 45,
      "z": 13,
      "name": "Rock_Ice"
    },
    {
      "x": -20,
      "y": 46,
      "z": 13,
      "name": "Rock_Ice"
    },
    {
      "x": -20,
      "y": 47,
      "z": 13,
      "name": "Soil_Snow"
    },
    {
      "x": -20,
      "y": 30,
      "z": 14,
      "name": "Rock_Ice"
    },
    {
      "x": -20,
      "y": 31,
      "z": 14,
      "name": "Rock_Ice"
    },
    {
      "x": -20,
      "y": 32,
      "z": 14,
      "name": "Rock_Ice"
    },
    {
      "x": -20,
      "y": 33,
      "z": 14,
      "name": "Rock_Ice"
    },
    {
      "x": -20,
      "y": 34,
      "z": 14,
      "name": "Rock_Ice"
    },
    {
      "x": -20,
      "y": 35,
      "z": 14,
      "name": "Rock_Ice"
    },
    {
      "x": -20,
      "y": 36,
      "z": 14,
      "name": "Rock_Ice"
    },
    {
      "x": -20,
      "y": 37,
      "z": 14,
      "name": "Rock_Ice"
    },
    {
      "x": -20,
      "y": 38,
      "z": 14,
      "name": "Rock_Ice"
    },
    {
      "x": -20,
      "y": 39,
      "z": 14,
      "name": "Rock_Ice"
    },
    {
      "x": -20,
      "y": 40,
      "z": 14,
      "name": "Rock_Ice"
    },
    {
      "x": -20,
      "y": 41,
      "z": 14,
      "name": "Rock_Ice"
    },
    {
      "x": -20,
      "y": 42,
      "z": 14,
      "name": "Rock_Ice"
    },
    {
      "x": -20,
      "y": 43,
      "z": 14,
      "name": "Rock_Ice"
    },
    {
      "x": -20,
      "y": 44,
      "z": 14,
      "name": "Rock_Ice"
    },
    {
      "x": -20,
      "y": 45,
      "z": 14,
      "name": "Rock_Ice"
    },
    {
      "x": -20,
      "y": 46,
      "z": 14,
      "name": "Rock_Ice"
    },
    {
      "x": -20,
      "y": 47,
      "z": 14,
      "name": "Soil_Snow"
    },
    {
      "x": -20,
      "y": 32,
      "z": 15,
      "name": "Rock_Ice"
    },
    {
      "x": -20,
      "y": 33,
      "z": 15,
      "name": "Rock_Ice"
    },
    {
      "x": -20,
      "y": 34,
      "z": 15,
      "name": "Rock_Ice"
    },
    {
      "x": -20,
      "y": 35,
      "z": 15,
      "name": "Rock_Ice"
    },
    {
      "x": -20,
      "y": 36,
      "z": 15,
      "name": "Rock_Ice"
    },
    {
      "x": -20,
      "y": 37,
      "z": 15,
      "name": "Rock_Ice"
    },
    {
      "x": -20,
      "y": 38,
      "z": 15,
      "name": "Rock_Ice"
    },
    {
      "x": -20,
      "y": 39,
      "z": 15,
      "name": "Rock_Ice"
    },
    {
      "x": -20,
      "y": 40,
      "z": 15,
      "name": "Rock_Ice"
    },
    {
      "x": -20,
      "y": 41,
      "z": 15,
      "name": "Rock_Ice"
    },
    {
      "x": -20,
      "y": 42,
      "z": 15,
      "name": "Rock_Ice"
    },
    {
      "x": -20,
      "y": 43,
      "z": 15,
      "name": "Rock_Ice"
    },
    {
      "x": -20,
      "y": 44,
      "z": 15,
      "name": "Rock_Ice"
    },
    {
      "x": -20,
      "y": 45,
      "z": 15,
      "name": "Rock_Ice"
    },
    {
      "x": -20,
      "y": 46,
      "z": 15,
      "name": "Soil_Snow"
    },
    {
      "x": -20,
      "y": 34,
      "z": 16,
      "name": "Rock_Ice"
    },
    {
      "x": -20,
      "y": 35,
      "z": 16,
      "name": "Rock_Ice"
    },
    {
      "x": -20,
      "y": 36,
      "z": 16,
      "name": "Rock_Ice"
    },
    {
      "x": -20,
      "y": 37,
      "z": 16,
      "name": "Rock_Ice"
    },
    {
      "x": -20,
      "y": 38,
      "z": 16,
      "name": "Rock_Ice"
    },
    {
      "x": -20,
      "y": 39,
      "z": 16,
      "name": "Rock_Ice"
    },
    {
      "x": -20,
      "y": 40,
      "z": 16,
      "name": "Rock_Ice"
    },
    {
      "x": -20,
      "y": 41,
      "z": 16,
      "name": "Rock_Ice"
    },
    {
      "x": -20,
      "y": 42,
      "z": 16,
      "name": "Rock_Ice"
    },
    {
      "x": -20,
      "y": 43,
      "z": 16,
      "name": "Rock_Ice"
    },
    {
      "x": -20,
      "y": 44,
      "z": 16,
      "name": "Soil_Snow"
    },
    {
      "x": -20,
      "y": 36,
      "z": 17,
      "name": "Rock_Ice"
    },
    {
      "x": -20,
      "y": 37,
      "z": 17,
      "name": "Rock_Ice"
    },
    {
      "x": -20,
      "y": 38,
      "z": 17,
      "name": "Rock_Ice"
    },
    {
      "x": -20,
      "y": 39,
      "z": 17,
      "name": "Rock_Ice"
    },
    {
      "x": -20,
      "y": 40,
      "z": 17,
      "name": "Soil_Snow"
    },
    {
      "x": -19,
      "y": 31,
      "z": 8,
      "name": "Rock_Ice"
    },
    {
      "x": -19,
      "y": 32,
      "z": 8,
      "name": "Rock_Ice"
    },
    {
      "x": -19,
      "y": 33,
      "z": 8,
      "name": "Rock_Ice"
    },
    {
      "x": -19,
      "y": 34,
      "z": 8,
      "name": "Rock_Ice"
    },
    {
      "x": -19,
      "y": 35,
      "z": 8,
      "name": "Rock_Ice"
    },
    {
      "x": -19,
      "y": 36,
      "z": 8,
      "name": "Rock_Ice"
    },
    {
      "x": -19,
      "y": 37,
      "z": 8,
      "name": "Rock_Ice"
    },
    {
      "x": -19,
      "y": 38,
      "z": 8,
      "name": "Rock_Ice"
    },
    {
      "x": -19,
      "y": 39,
      "z": 8,
      "name": "Rock_Ice"
    },
    {
      "x": -19,
      "y": 40,
      "z": 8,
      "name": "Rock_Ice"
    },
    {
      "x": -19,
      "y": 41,
      "z": 8,
      "name": "Soil_Snow"
    },
    {
      "x": -19,
      "y": 27,
      "z": 9,
      "name": "Rock_Ice"
    },
    {
      "x": -19,
      "y": 28,
      "z": 9,
      "name": "Rock_Ice"
    },
    {
      "x": -19,
      "y": 29,
      "z": 9,
      "name": "Rock_Ice"
    },
    {
      "x": -19,
      "y": 30,
      "z": 9,
      "name": "Rock_Ice"
    },
    {
      "x": -19,
      "y": 31,
      "z": 9,
      "name": "Rock_Ice"
    },
    {
      "x": -19,
      "y": 32,
      "z": 9,
      "name": "Rock_Ice"
    },
    {
      "x": -19,
      "y": 33,
      "z": 9,
      "name": "Rock_Ice"
    },
    {
      "x": -19,
      "y": 34,
      "z": 9,
      "name": "Rock_Ice"
    },
    {
      "x": -19,
      "y": 35,
      "z": 9,
      "name": "Rock_Ice"
    },
    {
      "x": -19,
      "y": 36,
      "z": 9,
      "name": "Rock_Ice"
    },
    {
      "x": -19,
      "y": 37,
      "z": 9,
      "name": "Rock_Ice"
    },
    {
      "x": -19,
      "y": 38,
      "z": 9,
      "name": "Rock_Ice"
    },
    {
      "x": -19,
      "y": 39,
      "z": 9,
      "name": "Rock_Ice"
    },
    {
      "x": -19,
      "y": 40,
      "z": 9,
      "name": "Rock_Ice"
    },
    {
      "x": -19,
      "y": 41,
      "z": 9,
      "name": "Rock_Ice"
    },
    {
      "x": -19,
      "y": 42,
      "z": 9,
      "name": "Rock_Ice"
    },
    {
      "x": -19,
      "y": 43,
      "z": 9,
      "name": "Rock_Ice"
    },
    {
      "x": -19,
      "y": 44,
      "z": 9,
      "name": "Rock_Ice"
    },
    {
      "x": -19,
      "y": 45,
      "z": 9,
      "name": "Rock_Ice"
    },
    {
      "x": -19,
      "y": 46,
      "z": 9,
      "name": "Soil_Snow"
    },
    {
      "x": -19,
      "y": 25,
      "z": 10,
      "name": "Rock_Ice"
    },
    {
      "x": -19,
      "y": 26,
      "z": 10,
      "name": "Rock_Ice"
    },
    {
      "x": -19,
      "y": 27,
      "z": 10,
      "name": "Rock_Ice"
    },
    {
      "x": -19,
      "y": 28,
      "z": 10,
      "name": "Rock_Ice"
    },
    {
      "x": -19,
      "y": 29,
      "z": 10,
      "name": "Rock_Ice"
    },
    {
      "x": -19,
      "y": 30,
      "z": 10,
      "name": "Rock_Ice"
    },
    {
      "x": -19,
      "y": 31,
      "z": 10,
      "name": "Rock_Ice"
    },
    {
      "x": -19,
      "y": 32,
      "z": 10,
      "name": "Rock_Ice"
    },
    {
      "x": -19,
      "y": 33,
      "z": 10,
      "name": "Rock_Ice"
    },
    {
      "x": -19,
      "y": 34,
      "z": 10,
      "name": "Rock_Ice"
    },
    {
      "x": -19,
      "y": 35,
      "z": 10,
      "name": "Rock_Ice"
    },
    {
      "x": -19,
      "y": 36,
      "z": 10,
      "name": "Rock_Ice"
    },
    {
      "x": -19,
      "y": 37,
      "z": 10,
      "name": "Rock_Ice"
    },
    {
      "x": -19,
      "y": 38,
      "z": 10,
      "name": "Rock_Ice"
    },
    {
      "x": -19,
      "y": 39,
      "z": 10,
      "name": "Rock_Ice"
    },
    {
      "x": -19,
      "y": 40,
      "z": 10,
      "name": "Rock_Ice"
    },
    {
      "x": -19,
      "y": 41,
      "z": 10,
      "name": "Rock_Ice"
    },
    {
      "x": -19,
      "y": 42,
      "z": 10,
      "name": "Rock_Ice"
    },
    {
      "x": -19,
      "y": 43,
      "z": 10,
      "name": "Rock_Ice"
    },
    {
      "x": -19,
      "y": 44,
      "z": 10,
      "name": "Rock_Ice"
    },
    {
      "x": -19,
      "y": 45,
      "z": 10,
      "name": "Rock_Ice"
    },
    {
      "x": -19,
      "y": 46,
      "z": 10,
      "name": "Rock_Ice"
    },
    {
      "x": -19,
      "y": 47,
      "z": 10,
      "name": "Soil_Snow"
    },
    {
      "x": -19,
      "y": 25,
      "z": 11,
      "name": "Rock_Ice"
    },
    {
      "x": -19,
      "y": 26,
      "z": 11,
      "name": "Rock_Ice"
    },
    {
      "x": -19,
      "y": 27,
      "z": 11,
      "name": "Rock_Ice"
    },
    {
      "x": -19,
      "y": 28,
      "z": 11,
      "name": "Rock_Ice"
    },
    {
      "x": -19,
      "y": 29,
      "z": 11,
      "name": "Rock_Ice"
    },
    {
      "x": -19,
      "y": 30,
      "z": 11,
      "name": "Rock_Ice"
    },
    {
      "x": -19,
      "y": 31,
      "z": 11,
      "name": "Rock_Ice"
    },
    {
      "x": -19,
      "y": 32,
      "z": 11,
      "name": "Rock_Ice"
    },
    {
      "x": -19,
      "y": 33,
      "z": 11,
      "name": "Rock_Ice"
    },
    {
      "x": -19,
      "y": 34,
      "z": 11,
      "name": "Rock_Ice"
    },
    {
      "x": -19,
      "y": 35,
      "z": 11,
      "name": "Rock_Ice"
    },
    {
      "x": -19,
      "y": 36,
      "z": 11,
      "name": "Rock_Ice"
    },
    {
      "x": -19,
      "y": 37,
      "z": 11,
      "name": "Rock_Ice"
    },
    {
      "x": -19,
      "y": 38,
      "z": 11,
      "name": "Rock_Ice"
    },
    {
      "x": -19,
      "y": 39,
      "z": 11,
      "name": "Rock_Ice"
    },
    {
      "x": -19,
      "y": 40,
      "z": 11,
      "name": "Rock_Ice"
    },
    {
      "x": -19,
      "y": 41,
      "z": 11,
      "name": "Rock_Ice"
    },
    {
      "x": -19,
      "y": 42,
      "z": 11,
      "name": "Rock_Ice"
    },
    {
      "x": -19,
      "y": 43,
      "z": 11,
      "name": "Rock_Ice"
    },
    {
      "x": -19,
      "y": 44,
      "z": 11,
      "name": "Rock_Ice"
    },
    {
      "x": -19,
      "y": 45,
      "z": 11,
      "name": "Rock_Ice"
    },
    {
      "x": -19,
      "y": 46,
      "z": 11,
      "name": "Rock_Ice"
    },
    {
      "x": -19,
      "y": 47,
      "z": 11,
      "name": "Soil_Snow"
    },
    {
      "x": -19,
      "y": 26,
      "z": 12,
      "name": "Rock_Ice"
    },
    {
      "x": -19,
      "y": 27,
      "z": 12,
      "name": "Rock_Ice"
    },
    {
      "x": -19,
      "y": 28,
      "z": 12,
      "name": "Rock_Ice"
    },
    {
      "x": -19,
      "y": 29,
      "z": 12,
      "name": "Rock_Ice"
    },
    {
      "x": -19,
      "y": 30,
      "z": 12,
      "name": "Rock_Ice"
    },
    {
      "x": -19,
      "y": 31,
      "z": 12,
      "name": "Rock_Ice"
    },
    {
      "x": -19,
      "y": 32,
      "z": 12,
      "name": "Rock_Ice"
    },
    {
      "x": -19,
      "y": 33,
      "z": 12,
      "name": "Rock_Ice"
    },
    {
      "x": -19,
      "y": 34,
      "z": 12,
      "name": "Rock_Ice"
    },
    {
      "x": -19,
      "y": 35,
      "z": 12,
      "name": "Rock_Ice"
    },
    {
      "x": -19,
      "y": 36,
      "z": 12,
      "name": "Rock_Ice"
    },
    {
      "x": -19,
      "y": 37,
      "z": 12,
      "name": "Rock_Ice"
    },
    {
      "x": -19,
      "y": 38,
      "z": 12,
      "name": "Rock_Ice"
    },
    {
      "x": -19,
      "y": 39,
      "z": 12,
      "name": "Rock_Ice"
    },
    {
      "x": -19,
      "y": 40,
      "z": 12,
      "name": "Rock_Ice"
    },
    {
      "x": -19,
      "y": 41,
      "z": 12,
      "name": "Rock_Ice"
    },
    {
      "x": -19,
      "y": 42,
      "z": 12,
      "name": "Rock_Ice"
    },
    {
      "x": -19,
      "y": 43,
      "z": 12,
      "name": "Rock_Ice"
    },
    {
      "x": -19,
      "y": 44,
      "z": 12,
      "name": "Rock_Ice"
    },
    {
      "x": -19,
      "y": 45,
      "z": 12,
      "name": "Rock_Ice"
    },
    {
      "x": -19,
      "y": 46,
      "z": 12,
      "name": "Rock_Ice"
    },
    {
      "x": -19,
      "y": 47,
      "z": 12,
      "name": "Soil_Snow"
    },
    {
      "x": -19,
      "y": 28,
      "z": 13,
      "name": "Rock_Ice"
    },
    {
      "x": -19,
      "y": 29,
      "z": 13,
      "name": "Rock_Ice"
    },
    {
      "x": -19,
      "y": 30,
      "z": 13,
      "name": "Rock_Ice"
    },
    {
      "x": -19,
      "y": 31,
      "z": 13,
      "name": "Rock_Ice"
    },
    {
      "x": -19,
      "y": 32,
      "z": 13,
      "name": "Rock_Ice"
    },
    {
      "x": -19,
      "y": 33,
      "z": 13,
      "name": "Rock_Ice"
    },
    {
      "x": -19,
      "y": 34,
      "z": 13,
      "name": "Rock_Ice"
    },
    {
      "x": -19,
      "y": 35,
      "z": 13,
      "name": "Rock_Ice"
    },
    {
      "x": -19,
      "y": 36,
      "z": 13,
      "name": "Rock_Ice"
    },
    {
      "x": -19,
      "y": 37,
      "z": 13,
      "name": "Rock_Ice"
    },
    {
      "x": -19,
      "y": 38,
      "z": 13,
      "name": "Rock_Ice"
    },
    {
      "x": -19,
      "y": 39,
      "z": 13,
      "name": "Rock_Ice"
    },
    {
      "x": -19,
      "y": 40,
      "z": 13,
      "name": "Rock_Ice"
    },
    {
      "x": -19,
      "y": 41,
      "z": 13,
      "name": "Rock_Ice"
    },
    {
      "x": -19,
      "y": 42,
      "z": 13,
      "name": "Rock_Ice"
    },
    {
      "x": -19,
      "y": 43,
      "z": 13,
      "name": "Rock_Ice"
    },
    {
      "x": -19,
      "y": 44,
      "z": 13,
      "name": "Rock_Ice"
    },
    {
      "x": -19,
      "y": 45,
      "z": 13,
      "name": "Rock_Ice"
    },
    {
      "x": -19,
      "y": 46,
      "z": 13,
      "name": "Rock_Ice"
    },
    {
      "x": -19,
      "y": 47,
      "z": 13,
      "name": "Soil_Snow"
    },
    {
      "x": -19,
      "y": 30,
      "z": 14,
      "name": "Rock_Ice"
    },
    {
      "x": -19,
      "y": 31,
      "z": 14,
      "name": "Rock_Ice"
    },
    {
      "x": -19,
      "y": 32,
      "z": 14,
      "name": "Rock_Ice"
    },
    {
      "x": -19,
      "y": 33,
      "z": 14,
      "name": "Rock_Ice"
    },
    {
      "x": -19,
      "y": 34,
      "z": 14,
      "name": "Rock_Ice"
    },
    {
      "x": -19,
      "y": 35,
      "z": 14,
      "name": "Rock_Ice"
    },
    {
      "x": -19,
      "y": 36,
      "z": 14,
      "name": "Rock_Ice"
    },
    {
      "x": -19,
      "y": 37,
      "z": 14,
      "name": "Rock_Ice"
    },
    {
      "x": -19,
      "y": 38,
      "z": 14,
      "name": "Rock_Ice"
    },
    {
      "x": -19,
      "y": 39,
      "z": 14,
      "name": "Rock_Ice"
    },
    {
      "x": -19,
      "y": 40,
      "z": 14,
      "name": "Rock_Ice"
    },
    {
      "x": -19,
      "y": 41,
      "z": 14,
      "name": "Rock_Ice"
    },
    {
      "x": -19,
      "y": 42,
      "z": 14,
      "name": "Rock_Ice"
    },
    {
      "x": -19,
      "y": 43,
      "z": 14,
      "name": "Rock_Ice"
    },
    {
      "x": -19,
      "y": 44,
      "z": 14,
      "name": "Rock_Ice"
    },
    {
      "x": -19,
      "y": 45,
      "z": 14,
      "name": "Rock_Ice"
    },
    {
      "x": -19,
      "y": 46,
      "z": 14,
      "name": "Soil_Snow"
    },
    {
      "x": -19,
      "y": 31,
      "z": 15,
      "name": "Rock_Ice"
    },
    {
      "x": -19,
      "y": 32,
      "z": 15,
      "name": "Rock_Ice"
    },
    {
      "x": -19,
      "y": 33,
      "z": 15,
      "name": "Rock_Ice"
    },
    {
      "x": -19,
      "y": 34,
      "z": 15,
      "name": "Rock_Ice"
    },
    {
      "x": -19,
      "y": 35,
      "z": 15,
      "name": "Rock_Ice"
    },
    {
      "x": -19,
      "y": 36,
      "z": 15,
      "name": "Rock_Ice"
    },
    {
      "x": -19,
      "y": 37,
      "z": 15,
      "name": "Rock_Ice"
    },
    {
      "x": -19,
      "y": 38,
      "z": 15,
      "name": "Rock_Ice"
    },
    {
      "x": -19,
      "y": 39,
      "z": 15,
      "name": "Rock_Ice"
    },
    {
      "x": -19,
      "y": 40,
      "z": 15,
      "name": "Rock_Ice"
    },
    {
      "x": -19,
      "y": 41,
      "z": 15,
      "name": "Rock_Ice"
    },
    {
      "x": -19,
      "y": 42,
      "z": 15,
      "name": "Rock_Ice"
    },
    {
      "x": -19,
      "y": 43,
      "z": 15,
      "name": "Rock_Ice"
    },
    {
      "x": -19,
      "y": 44,
      "z": 15,
      "name": "Rock_Ice"
    },
    {
      "x": -19,
      "y": 45,
      "z": 15,
      "name": "Soil_Snow"
    },
    {
      "x": -19,
      "y": 33,
      "z": 16,
      "name": "Rock_Ice"
    },
    {
      "x": -19,
      "y": 34,
      "z": 16,
      "name": "Rock_Ice"
    },
    {
      "x": -19,
      "y": 35,
      "z": 16,
      "name": "Rock_Ice"
    },
    {
      "x": -19,
      "y": 36,
      "z": 16,
      "name": "Rock_Ice"
    },
    {
      "x": -19,
      "y": 37,
      "z": 16,
      "name": "Rock_Ice"
    },
    {
      "x": -19,
      "y": 38,
      "z": 16,
      "name": "Rock_Ice"
    },
    {
      "x": -19,
      "y": 39,
      "z": 16,
      "name": "Rock_Ice"
    },
    {
      "x": -19,
      "y": 40,
      "z": 16,
      "name": "Rock_Ice"
    },
    {
      "x": -19,
      "y": 41,
      "z": 16,
      "name": "Rock_Ice"
    },
    {
      "x": -19,
      "y": 42,
      "z": 16,
      "name": "Rock_Ice"
    },
    {
      "x": -19,
      "y": 43,
      "z": 16,
      "name": "Soil_Snow"
    },
    {
      "x": -19,
      "y": 36,
      "z": 17,
      "name": "Rock_Ice"
    },
    {
      "x": -19,
      "y": 37,
      "z": 17,
      "name": "Rock_Ice"
    },
    {
      "x": -19,
      "y": 38,
      "z": 17,
      "name": "Rock_Ice"
    },
    {
      "x": -19,
      "y": 39,
      "z": 17,
      "name": "Rock_Ice"
    },
    {
      "x": -19,
      "y": 40,
      "z": 17,
      "name": "Soil_Snow"
    },
    {
      "x": -18,
      "y": 26,
      "z": 8,
      "name": "Rock_Ice"
    },
    {
      "x": -18,
      "y": 27,
      "z": 8,
      "name": "Rock_Ice"
    },
    {
      "x": -18,
      "y": 28,
      "z": 8,
      "name": "Rock_Ice"
    },
    {
      "x": -18,
      "y": 29,
      "z": 8,
      "name": "Rock_Ice"
    },
    {
      "x": -18,
      "y": 30,
      "z": 8,
      "name": "Rock_Ice"
    },
    {
      "x": -18,
      "y": 31,
      "z": 8,
      "name": "Rock_Ice"
    },
    {
      "x": -18,
      "y": 32,
      "z": 8,
      "name": "Rock_Ice"
    },
    {
      "x": -18,
      "y": 33,
      "z": 8,
      "name": "Rock_Ice"
    },
    {
      "x": -18,
      "y": 34,
      "z": 8,
      "name": "Rock_Ice"
    },
    {
      "x": -18,
      "y": 35,
      "z": 8,
      "name": "Rock_Ice"
    },
    {
      "x": -18,
      "y": 36,
      "z": 8,
      "name": "Rock_Ice"
    },
    {
      "x": -18,
      "y": 37,
      "z": 8,
      "name": "Rock_Ice"
    },
    {
      "x": -18,
      "y": 38,
      "z": 8,
      "name": "Rock_Ice"
    },
    {
      "x": -18,
      "y": 39,
      "z": 8,
      "name": "Rock_Ice"
    },
    {
      "x": -18,
      "y": 40,
      "z": 8,
      "name": "Rock_Ice"
    },
    {
      "x": -18,
      "y": 41,
      "z": 8,
      "name": "Rock_Ice"
    },
    {
      "x": -18,
      "y": 42,
      "z": 8,
      "name": "Rock_Ice"
    },
    {
      "x": -18,
      "y": 43,
      "z": 8,
      "name": "Rock_Ice"
    },
    {
      "x": -18,
      "y": 44,
      "z": 8,
      "name": "Rock_Ice"
    },
    {
      "x": -18,
      "y": 45,
      "z": 8,
      "name": "Soil_Snow"
    },
    {
      "x": -18,
      "y": 23,
      "z": 9,
      "name": "Rock_Ice"
    },
    {
      "x": -18,
      "y": 24,
      "z": 9,
      "name": "Rock_Ice"
    },
    {
      "x": -18,
      "y": 25,
      "z": 9,
      "name": "Rock_Ice"
    },
    {
      "x": -18,
      "y": 26,
      "z": 9,
      "name": "Rock_Ice"
    },
    {
      "x": -18,
      "y": 27,
      "z": 9,
      "name": "Rock_Ice"
    },
    {
      "x": -18,
      "y": 28,
      "z": 9,
      "name": "Rock_Ice"
    },
    {
      "x": -18,
      "y": 29,
      "z": 9,
      "name": "Rock_Ice"
    },
    {
      "x": -18,
      "y": 30,
      "z": 9,
      "name": "Rock_Ice"
    },
    {
      "x": -18,
      "y": 31,
      "z": 9,
      "name": "Rock_Ice"
    },
    {
      "x": -18,
      "y": 32,
      "z": 9,
      "name": "Rock_Ice"
    },
    {
      "x": -18,
      "y": 33,
      "z": 9,
      "name": "Rock_Ice"
    },
    {
      "x": -18,
      "y": 34,
      "z": 9,
      "name": "Rock_Ice"
    },
    {
      "x": -18,
      "y": 35,
      "z": 9,
      "name": "Rock_Ice"
    },
    {
      "x": -18,
      "y": 36,
      "z": 9,
      "name": "Rock_Ice"
    },
    {
      "x": -18,
      "y": 37,
      "z": 9,
      "name": "Rock_Ice"
    },
    {
      "x": -18,
      "y": 38,
      "z": 9,
      "name": "Rock_Ice"
    },
    {
      "x": -18,
      "y": 39,
      "z": 9,
      "name": "Rock_Ice"
    },
    {
      "x": -18,
      "y": 40,
      "z": 9,
      "name": "Rock_Ice"
    },
    {
      "x": -18,
      "y": 41,
      "z": 9,
      "name": "Rock_Ice"
    },
    {
      "x": -18,
      "y": 42,
      "z": 9,
      "name": "Rock_Ice"
    },
    {
      "x": -18,
      "y": 43,
      "z": 9,
      "name": "Rock_Ice"
    },
    {
      "x": -18,
      "y": 44,
      "z": 9,
      "name": "Rock_Ice"
    },
    {
      "x": -18,
      "y": 45,
      "z": 9,
      "name": "Rock_Ice"
    },
    {
      "x": -18,
      "y": 46,
      "z": 9,
      "name": "Soil_Snow"
    },
    {
      "x": -18,
      "y": 21,
      "z": 10,
      "name": "Rock_Ice"
    },
    {
      "x": -18,
      "y": 22,
      "z": 10,
      "name": "Rock_Ice"
    },
    {
      "x": -18,
      "y": 23,
      "z": 10,
      "name": "Rock_Ice"
    },
    {
      "x": -18,
      "y": 24,
      "z": 10,
      "name": "Rock_Ice"
    },
    {
      "x": -18,
      "y": 25,
      "z": 10,
      "name": "Rock_Ice"
    },
    {
      "x": -18,
      "y": 26,
      "z": 10,
      "name": "Rock_Ice"
    },
    {
      "x": -18,
      "y": 27,
      "z": 10,
      "name": "Rock_Ice"
    },
    {
      "x": -18,
      "y": 28,
      "z": 10,
      "name": "Rock_Ice"
    },
    {
      "x": -18,
      "y": 29,
      "z": 10,
      "name": "Rock_Ice"
    },
    {
      "x": -18,
      "y": 30,
      "z": 10,
      "name": "Rock_Ice"
    },
    {
      "x": -18,
      "y": 31,
      "z": 10,
      "name": "Rock_Ice"
    },
    {
      "x": -18,
      "y": 32,
      "z": 10,
      "name": "Rock_Ice"
    },
    {
      "x": -18,
      "y": 33,
      "z": 10,
      "name": "Rock_Ice"
    },
    {
      "x": -18,
      "y": 34,
      "z": 10,
      "name": "Rock_Ice"
    },
    {
      "x": -18,
      "y": 35,
      "z": 10,
      "name": "Rock_Ice"
    },
    {
      "x": -18,
      "y": 36,
      "z": 10,
      "name": "Rock_Ice"
    },
    {
      "x": -18,
      "y": 37,
      "z": 10,
      "name": "Rock_Ice"
    },
    {
      "x": -18,
      "y": 38,
      "z": 10,
      "name": "Rock_Ice"
    },
    {
      "x": -18,
      "y": 39,
      "z": 10,
      "name": "Rock_Ice"
    },
    {
      "x": -18,
      "y": 40,
      "z": 10,
      "name": "Rock_Ice"
    },
    {
      "x": -18,
      "y": 41,
      "z": 10,
      "name": "Rock_Ice"
    },
    {
      "x": -18,
      "y": 42,
      "z": 10,
      "name": "Rock_Ice"
    },
    {
      "x": -18,
      "y": 43,
      "z": 10,
      "name": "Rock_Ice"
    },
    {
      "x": -18,
      "y": 44,
      "z": 10,
      "name": "Rock_Ice"
    },
    {
      "x": -18,
      "y": 45,
      "z": 10,
      "name": "Rock_Ice"
    },
    {
      "x": -18,
      "y": 46,
      "z": 10,
      "name": "Rock_Ice"
    },
    {
      "x": -18,
      "y": 47,
      "z": 10,
      "name": "Soil_Snow"
    },
    {
      "x": -18,
      "y": 22,
      "z": 11,
      "name": "Rock_Ice"
    },
    {
      "x": -18,
      "y": 23,
      "z": 11,
      "name": "Rock_Ice"
    },
    {
      "x": -18,
      "y": 24,
      "z": 11,
      "name": "Rock_Ice"
    },
    {
      "x": -18,
      "y": 25,
      "z": 11,
      "name": "Rock_Ice"
    },
    {
      "x": -18,
      "y": 26,
      "z": 11,
      "name": "Rock_Ice"
    },
    {
      "x": -18,
      "y": 27,
      "z": 11,
      "name": "Rock_Ice"
    },
    {
      "x": -18,
      "y": 28,
      "z": 11,
      "name": "Rock_Ice"
    },
    {
      "x": -18,
      "y": 29,
      "z": 11,
      "name": "Rock_Ice"
    },
    {
      "x": -18,
      "y": 30,
      "z": 11,
      "name": "Rock_Ice"
    },
    {
      "x": -18,
      "y": 31,
      "z": 11,
      "name": "Rock_Ice"
    },
    {
      "x": -18,
      "y": 32,
      "z": 11,
      "name": "Rock_Ice"
    },
    {
      "x": -18,
      "y": 33,
      "z": 11,
      "name": "Rock_Ice"
    },
    {
      "x": -18,
      "y": 34,
      "z": 11,
      "name": "Rock_Ice"
    },
    {
      "x": -18,
      "y": 35,
      "z": 11,
      "name": "Rock_Ice"
    },
    {
      "x": -18,
      "y": 36,
      "z": 11,
      "name": "Rock_Ice"
    },
    {
      "x": -18,
      "y": 37,
      "z": 11,
      "name": "Rock_Ice"
    },
    {
      "x": -18,
      "y": 38,
      "z": 11,
      "name": "Rock_Ice"
    },
    {
      "x": -18,
      "y": 39,
      "z": 11,
      "name": "Rock_Ice"
    },
    {
      "x": -18,
      "y": 40,
      "z": 11,
      "name": "Rock_Ice"
    },
    {
      "x": -18,
      "y": 41,
      "z": 11,
      "name": "Rock_Ice"
    },
    {
      "x": -18,
      "y": 42,
      "z": 11,
      "name": "Rock_Ice"
    },
    {
      "x": -18,
      "y": 43,
      "z": 11,
      "name": "Rock_Ice"
    },
    {
      "x": -18,
      "y": 44,
      "z": 11,
      "name": "Rock_Ice"
    },
    {
      "x": -18,
      "y": 45,
      "z": 11,
      "name": "Rock_Ice"
    },
    {
      "x": -18,
      "y": 46,
      "z": 11,
      "name": "Rock_Ice"
    },
    {
      "x": -18,
      "y": 47,
      "z": 11,
      "name": "Soil_Snow"
    },
    {
      "x": -18,
      "y": 24,
      "z": 12,
      "name": "Rock_Ice"
    },
    {
      "x": -18,
      "y": 25,
      "z": 12,
      "name": "Rock_Ice"
    },
    {
      "x": -18,
      "y": 26,
      "z": 12,
      "name": "Rock_Ice"
    },
    {
      "x": -18,
      "y": 27,
      "z": 12,
      "name": "Rock_Ice"
    },
    {
      "x": -18,
      "y": 28,
      "z": 12,
      "name": "Rock_Ice"
    },
    {
      "x": -18,
      "y": 29,
      "z": 12,
      "name": "Rock_Ice"
    },
    {
      "x": -18,
      "y": 30,
      "z": 12,
      "name": "Rock_Ice"
    },
    {
      "x": -18,
      "y": 31,
      "z": 12,
      "name": "Rock_Ice"
    },
    {
      "x": -18,
      "y": 32,
      "z": 12,
      "name": "Rock_Ice"
    },
    {
      "x": -18,
      "y": 33,
      "z": 12,
      "name": "Rock_Ice"
    },
    {
      "x": -18,
      "y": 34,
      "z": 12,
      "name": "Rock_Ice"
    },
    {
      "x": -18,
      "y": 35,
      "z": 12,
      "name": "Rock_Ice"
    },
    {
      "x": -18,
      "y": 36,
      "z": 12,
      "name": "Rock_Ice"
    },
    {
      "x": -18,
      "y": 37,
      "z": 12,
      "name": "Rock_Ice"
    },
    {
      "x": -18,
      "y": 38,
      "z": 12,
      "name": "Rock_Ice"
    },
    {
      "x": -18,
      "y": 39,
      "z": 12,
      "name": "Rock_Ice"
    },
    {
      "x": -18,
      "y": 40,
      "z": 12,
      "name": "Rock_Ice"
    },
    {
      "x": -18,
      "y": 41,
      "z": 12,
      "name": "Rock_Ice"
    },
    {
      "x": -18,
      "y": 42,
      "z": 12,
      "name": "Rock_Ice"
    },
    {
      "x": -18,
      "y": 43,
      "z": 12,
      "name": "Rock_Ice"
    },
    {
      "x": -18,
      "y": 44,
      "z": 12,
      "name": "Rock_Ice"
    },
    {
      "x": -18,
      "y": 45,
      "z": 12,
      "name": "Rock_Ice"
    },
    {
      "x": -18,
      "y": 46,
      "z": 12,
      "name": "Rock_Ice"
    },
    {
      "x": -18,
      "y": 47,
      "z": 12,
      "name": "Soil_Snow"
    },
    {
      "x": -18,
      "y": 27,
      "z": 13,
      "name": "Rock_Ice"
    },
    {
      "x": -18,
      "y": 28,
      "z": 13,
      "name": "Rock_Ice"
    },
    {
      "x": -18,
      "y": 29,
      "z": 13,
      "name": "Rock_Ice"
    },
    {
      "x": -18,
      "y": 30,
      "z": 13,
      "name": "Rock_Ice"
    },
    {
      "x": -18,
      "y": 31,
      "z": 13,
      "name": "Rock_Ice"
    },
    {
      "x": -18,
      "y": 32,
      "z": 13,
      "name": "Rock_Ice"
    },
    {
      "x": -18,
      "y": 33,
      "z": 13,
      "name": "Rock_Ice"
    },
    {
      "x": -18,
      "y": 34,
      "z": 13,
      "name": "Rock_Ice"
    },
    {
      "x": -18,
      "y": 35,
      "z": 13,
      "name": "Rock_Ice"
    },
    {
      "x": -18,
      "y": 36,
      "z": 13,
      "name": "Rock_Ice"
    },
    {
      "x": -18,
      "y": 37,
      "z": 13,
      "name": "Rock_Ice"
    },
    {
      "x": -18,
      "y": 38,
      "z": 13,
      "name": "Rock_Ice"
    },
    {
      "x": -18,
      "y": 39,
      "z": 13,
      "name": "Rock_Ice"
    },
    {
      "x": -18,
      "y": 40,
      "z": 13,
      "name": "Rock_Ice"
    },
    {
      "x": -18,
      "y": 41,
      "z": 13,
      "name": "Rock_Ice"
    },
    {
      "x": -18,
      "y": 42,
      "z": 13,
      "name": "Rock_Ice"
    },
    {
      "x": -18,
      "y": 43,
      "z": 13,
      "name": "Rock_Ice"
    },
    {
      "x": -18,
      "y": 44,
      "z": 13,
      "name": "Rock_Ice"
    },
    {
      "x": -18,
      "y": 45,
      "z": 13,
      "name": "Rock_Ice"
    },
    {
      "x": -18,
      "y": 46,
      "z": 13,
      "name": "Rock_Ice"
    },
    {
      "x": -18,
      "y": 47,
      "z": 13,
      "name": "Soil_Snow"
    },
    {
      "x": -18,
      "y": 29,
      "z": 14,
      "name": "Rock_Ice"
    },
    {
      "x": -18,
      "y": 30,
      "z": 14,
      "name": "Rock_Ice"
    },
    {
      "x": -18,
      "y": 31,
      "z": 14,
      "name": "Rock_Ice"
    },
    {
      "x": -18,
      "y": 32,
      "z": 14,
      "name": "Rock_Ice"
    },
    {
      "x": -18,
      "y": 33,
      "z": 14,
      "name": "Rock_Ice"
    },
    {
      "x": -18,
      "y": 34,
      "z": 14,
      "name": "Rock_Ice"
    },
    {
      "x": -18,
      "y": 35,
      "z": 14,
      "name": "Rock_Ice"
    },
    {
      "x": -18,
      "y": 36,
      "z": 14,
      "name": "Rock_Ice"
    },
    {
      "x": -18,
      "y": 37,
      "z": 14,
      "name": "Rock_Ice"
    },
    {
      "x": -18,
      "y": 38,
      "z": 14,
      "name": "Rock_Ice"
    },
    {
      "x": -18,
      "y": 39,
      "z": 14,
      "name": "Rock_Ice"
    },
    {
      "x": -18,
      "y": 40,
      "z": 14,
      "name": "Rock_Ice"
    },
    {
      "x": -18,
      "y": 41,
      "z": 14,
      "name": "Rock_Ice"
    },
    {
      "x": -18,
      "y": 42,
      "z": 14,
      "name": "Rock_Ice"
    },
    {
      "x": -18,
      "y": 43,
      "z": 14,
      "name": "Rock_Ice"
    },
    {
      "x": -18,
      "y": 44,
      "z": 14,
      "name": "Rock_Ice"
    },
    {
      "x": -18,
      "y": 45,
      "z": 14,
      "name": "Rock_Ice"
    },
    {
      "x": -18,
      "y": 46,
      "z": 14,
      "name": "Soil_Snow"
    },
    {
      "x": -18,
      "y": 31,
      "z": 15,
      "name": "Rock_Ice"
    },
    {
      "x": -18,
      "y": 32,
      "z": 15,
      "name": "Rock_Ice"
    },
    {
      "x": -18,
      "y": 33,
      "z": 15,
      "name": "Rock_Ice"
    },
    {
      "x": -18,
      "y": 34,
      "z": 15,
      "name": "Rock_Ice"
    },
    {
      "x": -18,
      "y": 35,
      "z": 15,
      "name": "Rock_Ice"
    },
    {
      "x": -18,
      "y": 36,
      "z": 15,
      "name": "Rock_Ice"
    },
    {
      "x": -18,
      "y": 37,
      "z": 15,
      "name": "Rock_Ice"
    },
    {
      "x": -18,
      "y": 38,
      "z": 15,
      "name": "Rock_Ice"
    },
    {
      "x": -18,
      "y": 39,
      "z": 15,
      "name": "Rock_Ice"
    },
    {
      "x": -18,
      "y": 40,
      "z": 15,
      "name": "Rock_Ice"
    },
    {
      "x": -18,
      "y": 41,
      "z": 15,
      "name": "Rock_Ice"
    },
    {
      "x": -18,
      "y": 42,
      "z": 15,
      "name": "Rock_Ice"
    },
    {
      "x": -18,
      "y": 43,
      "z": 15,
      "name": "Rock_Ice"
    },
    {
      "x": -18,
      "y": 44,
      "z": 15,
      "name": "Rock_Ice"
    },
    {
      "x": -18,
      "y": 45,
      "z": 15,
      "name": "Soil_Snow"
    },
    {
      "x": -18,
      "y": 33,
      "z": 16,
      "name": "Rock_Ice"
    },
    {
      "x": -18,
      "y": 34,
      "z": 16,
      "name": "Rock_Ice"
    },
    {
      "x": -18,
      "y": 35,
      "z": 16,
      "name": "Rock_Ice"
    },
    {
      "x": -18,
      "y": 36,
      "z": 16,
      "name": "Rock_Ice"
    },
    {
      "x": -18,
      "y": 37,
      "z": 16,
      "name": "Rock_Ice"
    },
    {
      "x": -18,
      "y": 38,
      "z": 16,
      "name": "Rock_Ice"
    },
    {
      "x": -18,
      "y": 39,
      "z": 16,
      "name": "Rock_Ice"
    },
    {
      "x": -18,
      "y": 40,
      "z": 16,
      "name": "Rock_Ice"
    },
    {
      "x": -18,
      "y": 41,
      "z": 16,
      "name": "Rock_Ice"
    },
    {
      "x": -18,
      "y": 42,
      "z": 16,
      "name": "Soil_Snow"
    },
    {
      "x": -18,
      "y": 36,
      "z": 17,
      "name": "Rock_Ice"
    },
    {
      "x": -18,
      "y": 37,
      "z": 17,
      "name": "Rock_Ice"
    },
    {
      "x": -18,
      "y": 38,
      "z": 17,
      "name": "Rock_Ice"
    },
    {
      "x": -18,
      "y": 39,
      "z": 17,
      "name": "Soil_Snow"
    },
    {
      "x": -17,
      "y": 26,
      "z": 7,
      "name": "Rock_Ice"
    },
    {
      "x": -17,
      "y": 27,
      "z": 7,
      "name": "Rock_Ice"
    },
    {
      "x": -17,
      "y": 28,
      "z": 7,
      "name": "Rock_Ice"
    },
    {
      "x": -17,
      "y": 29,
      "z": 7,
      "name": "Rock_Ice"
    },
    {
      "x": -17,
      "y": 30,
      "z": 7,
      "name": "Rock_Ice"
    },
    {
      "x": -17,
      "y": 31,
      "z": 7,
      "name": "Rock_Ice"
    },
    {
      "x": -17,
      "y": 32,
      "z": 7,
      "name": "Rock_Ice"
    },
    {
      "x": -17,
      "y": 33,
      "z": 7,
      "name": "Rock_Ice"
    },
    {
      "x": -17,
      "y": 34,
      "z": 7,
      "name": "Rock_Ice"
    },
    {
      "x": -17,
      "y": 35,
      "z": 7,
      "name": "Rock_Ice"
    },
    {
      "x": -17,
      "y": 36,
      "z": 7,
      "name": "Rock_Ice"
    },
    {
      "x": -17,
      "y": 37,
      "z": 7,
      "name": "Rock_Ice"
    },
    {
      "x": -17,
      "y": 38,
      "z": 7,
      "name": "Rock_Ice"
    },
    {
      "x": -17,
      "y": 39,
      "z": 7,
      "name": "Rock_Ice"
    },
    {
      "x": -17,
      "y": 40,
      "z": 7,
      "name": "Rock_Ice"
    },
    {
      "x": -17,
      "y": 41,
      "z": 7,
      "name": "Rock_Ice"
    },
    {
      "x": -17,
      "y": 42,
      "z": 7,
      "name": "Rock_Ice"
    },
    {
      "x": -17,
      "y": 43,
      "z": 7,
      "name": "Soil_Snow"
    },
    {
      "x": -17,
      "y": 20,
      "z": 8,
      "name": "Rock_Ice"
    },
    {
      "x": -17,
      "y": 21,
      "z": 8,
      "name": "Rock_Ice"
    },
    {
      "x": -17,
      "y": 22,
      "z": 8,
      "name": "Rock_Ice"
    },
    {
      "x": -17,
      "y": 23,
      "z": 8,
      "name": "Rock_Ice"
    },
    {
      "x": -17,
      "y": 24,
      "z": 8,
      "name": "Rock_Ice"
    },
    {
      "x": -17,
      "y": 25,
      "z": 8,
      "name": "Rock_Ice"
    },
    {
      "x": -17,
      "y": 26,
      "z": 8,
      "name": "Rock_Ice"
    },
    {
      "x": -17,
      "y": 27,
      "z": 8,
      "name": "Rock_Ice"
    },
    {
      "x": -17,
      "y": 28,
      "z": 8,
      "name": "Rock_Ice"
    },
    {
      "x": -17,
      "y": 29,
      "z": 8,
      "name": "Rock_Ice"
    },
    {
      "x": -17,
      "y": 30,
      "z": 8,
      "name": "Rock_Ice"
    },
    {
      "x": -17,
      "y": 31,
      "z": 8,
      "name": "Rock_Ice"
    },
    {
      "x": -17,
      "y": 32,
      "z": 8,
      "name": "Rock_Ice"
    },
    {
      "x": -17,
      "y": 33,
      "z": 8,
      "name": "Rock_Ice"
    },
    {
      "x": -17,
      "y": 34,
      "z": 8,
      "name": "Rock_Ice"
    },
    {
      "x": -17,
      "y": 35,
      "z": 8,
      "name": "Rock_Ice"
    },
    {
      "x": -17,
      "y": 36,
      "z": 8,
      "name": "Rock_Ice"
    },
    {
      "x": -17,
      "y": 37,
      "z": 8,
      "name": "Rock_Ice"
    },
    {
      "x": -17,
      "y": 38,
      "z": 8,
      "name": "Rock_Ice"
    },
    {
      "x": -17,
      "y": 39,
      "z": 8,
      "name": "Rock_Ice"
    },
    {
      "x": -17,
      "y": 40,
      "z": 8,
      "name": "Rock_Ice"
    },
    {
      "x": -17,
      "y": 41,
      "z": 8,
      "name": "Rock_Ice"
    },
    {
      "x": -17,
      "y": 42,
      "z": 8,
      "name": "Rock_Ice"
    },
    {
      "x": -17,
      "y": 43,
      "z": 8,
      "name": "Rock_Ice"
    },
    {
      "x": -17,
      "y": 44,
      "z": 8,
      "name": "Rock_Ice"
    },
    {
      "x": -17,
      "y": 45,
      "z": 8,
      "name": "Soil_Snow"
    },
    {
      "x": -17,
      "y": 20,
      "z": 9,
      "name": "Rock_Ice"
    },
    {
      "x": -17,
      "y": 21,
      "z": 9,
      "name": "Rock_Ice"
    },
    {
      "x": -17,
      "y": 22,
      "z": 9,
      "name": "Rock_Ice"
    },
    {
      "x": -17,
      "y": 23,
      "z": 9,
      "name": "Rock_Ice"
    },
    {
      "x": -17,
      "y": 24,
      "z": 9,
      "name": "Rock_Ice"
    },
    {
      "x": -17,
      "y": 25,
      "z": 9,
      "name": "Rock_Ice"
    },
    {
      "x": -17,
      "y": 26,
      "z": 9,
      "name": "Rock_Ice"
    },
    {
      "x": -17,
      "y": 27,
      "z": 9,
      "name": "Rock_Ice"
    },
    {
      "x": -17,
      "y": 28,
      "z": 9,
      "name": "Rock_Ice"
    },
    {
      "x": -17,
      "y": 29,
      "z": 9,
      "name": "Rock_Ice"
    },
    {
      "x": -17,
      "y": 30,
      "z": 9,
      "name": "Rock_Ice"
    },
    {
      "x": -17,
      "y": 31,
      "z": 9,
      "name": "Rock_Ice"
    },
    {
      "x": -17,
      "y": 32,
      "z": 9,
      "name": "Rock_Ice"
    },
    {
      "x": -17,
      "y": 33,
      "z": 9,
      "name": "Rock_Ice"
    },
    {
      "x": -17,
      "y": 34,
      "z": 9,
      "name": "Rock_Ice"
    },
    {
      "x": -17,
      "y": 35,
      "z": 9,
      "name": "Rock_Ice"
    },
    {
      "x": -17,
      "y": 36,
      "z": 9,
      "name": "Rock_Ice"
    },
    {
      "x": -17,
      "y": 37,
      "z": 9,
      "name": "Rock_Ice"
    },
    {
      "x": -17,
      "y": 38,
      "z": 9,
      "name": "Rock_Ice"
    },
    {
      "x": -17,
      "y": 39,
      "z": 9,
      "name": "Rock_Ice"
    },
    {
      "x": -17,
      "y": 40,
      "z": 9,
      "name": "Rock_Ice"
    },
    {
      "x": -17,
      "y": 41,
      "z": 9,
      "name": "Rock_Ice"
    },
    {
      "x": -17,
      "y": 42,
      "z": 9,
      "name": "Rock_Ice"
    },
    {
      "x": -17,
      "y": 43,
      "z": 9,
      "name": "Rock_Ice"
    },
    {
      "x": -17,
      "y": 44,
      "z": 9,
      "name": "Rock_Ice"
    },
    {
      "x": -17,
      "y": 45,
      "z": 9,
      "name": "Rock_Ice"
    },
    {
      "x": -17,
      "y": 46,
      "z": 9,
      "name": "Soil_Snow"
    },
    {
      "x": -17,
      "y": 20,
      "z": 10,
      "name": "Rock_Ice"
    },
    {
      "x": -17,
      "y": 21,
      "z": 10,
      "name": "Rock_Ice"
    },
    {
      "x": -17,
      "y": 22,
      "z": 10,
      "name": "Rock_Ice"
    },
    {
      "x": -17,
      "y": 23,
      "z": 10,
      "name": "Rock_Ice"
    },
    {
      "x": -17,
      "y": 24,
      "z": 10,
      "name": "Rock_Ice"
    },
    {
      "x": -17,
      "y": 25,
      "z": 10,
      "name": "Rock_Ice"
    },
    {
      "x": -17,
      "y": 26,
      "z": 10,
      "name": "Rock_Ice"
    },
    {
      "x": -17,
      "y": 27,
      "z": 10,
      "name": "Rock_Ice"
    },
    {
      "x": -17,
      "y": 28,
      "z": 10,
      "name": "Rock_Ice"
    },
    {
      "x": -17,
      "y": 29,
      "z": 10,
      "name": "Rock_Ice"
    },
    {
      "x": -17,
      "y": 30,
      "z": 10,
      "name": "Rock_Ice"
    },
    {
      "x": -17,
      "y": 31,
      "z": 10,
      "name": "Rock_Ice"
    },
    {
      "x": -17,
      "y": 32,
      "z": 10,
      "name": "Rock_Ice"
    },
    {
      "x": -17,
      "y": 33,
      "z": 10,
      "name": "Rock_Ice"
    },
    {
      "x": -17,
      "y": 34,
      "z": 10,
      "name": "Rock_Ice"
    },
    {
      "x": -17,
      "y": 35,
      "z": 10,
      "name": "Rock_Ice"
    },
    {
      "x": -17,
      "y": 36,
      "z": 10,
      "name": "Rock_Ice"
    },
    {
      "x": -17,
      "y": 37,
      "z": 10,
      "name": "Rock_Ice"
    },
    {
      "x": -17,
      "y": 38,
      "z": 10,
      "name": "Rock_Ice"
    },
    {
      "x": -17,
      "y": 39,
      "z": 10,
      "name": "Rock_Ice"
    },
    {
      "x": -17,
      "y": 40,
      "z": 10,
      "name": "Rock_Ice"
    },
    {
      "x": -17,
      "y": 41,
      "z": 10,
      "name": "Rock_Ice"
    },
    {
      "x": -17,
      "y": 42,
      "z": 10,
      "name": "Rock_Ice"
    },
    {
      "x": -17,
      "y": 43,
      "z": 10,
      "name": "Rock_Ice"
    },
    {
      "x": -17,
      "y": 44,
      "z": 10,
      "name": "Rock_Ice"
    },
    {
      "x": -17,
      "y": 45,
      "z": 10,
      "name": "Rock_Ice"
    },
    {
      "x": -17,
      "y": 46,
      "z": 10,
      "name": "Rock_Ice"
    },
    {
      "x": -17,
      "y": 47,
      "z": 10,
      "name": "Soil_Snow"
    },
    {
      "x": -17,
      "y": 21,
      "z": 11,
      "name": "Rock_Ice"
    },
    {
      "x": -17,
      "y": 22,
      "z": 11,
      "name": "Rock_Ice"
    },
    {
      "x": -17,
      "y": 23,
      "z": 11,
      "name": "Rock_Ice"
    },
    {
      "x": -17,
      "y": 24,
      "z": 11,
      "name": "Rock_Ice"
    },
    {
      "x": -17,
      "y": 25,
      "z": 11,
      "name": "Rock_Ice"
    },
    {
      "x": -17,
      "y": 26,
      "z": 11,
      "name": "Rock_Ice"
    },
    {
      "x": -17,
      "y": 27,
      "z": 11,
      "name": "Rock_Ice"
    },
    {
      "x": -17,
      "y": 28,
      "z": 11,
      "name": "Rock_Ice"
    },
    {
      "x": -17,
      "y": 29,
      "z": 11,
      "name": "Rock_Ice"
    },
    {
      "x": -17,
      "y": 30,
      "z": 11,
      "name": "Rock_Ice"
    },
    {
      "x": -17,
      "y": 31,
      "z": 11,
      "name": "Rock_Ice"
    },
    {
      "x": -17,
      "y": 32,
      "z": 11,
      "name": "Rock_Ice"
    },
    {
      "x": -17,
      "y": 33,
      "z": 11,
      "name": "Rock_Ice"
    },
    {
      "x": -17,
      "y": 34,
      "z": 11,
      "name": "Rock_Ice"
    },
    {
      "x": -17,
      "y": 35,
      "z": 11,
      "name": "Rock_Ice"
    },
    {
      "x": -17,
      "y": 36,
      "z": 11,
      "name": "Rock_Ice"
    },
    {
      "x": -17,
      "y": 37,
      "z": 11,
      "name": "Rock_Ice"
    },
    {
      "x": -17,
      "y": 38,
      "z": 11,
      "name": "Rock_Ice"
    },
    {
      "x": -17,
      "y": 39,
      "z": 11,
      "name": "Rock_Ice"
    },
    {
      "x": -17,
      "y": 40,
      "z": 11,
      "name": "Rock_Ice"
    },
    {
      "x": -17,
      "y": 41,
      "z": 11,
      "name": "Rock_Ice"
    },
    {
      "x": -17,
      "y": 42,
      "z": 11,
      "name": "Rock_Ice"
    },
    {
      "x": -17,
      "y": 43,
      "z": 11,
      "name": "Rock_Ice"
    },
    {
      "x": -17,
      "y": 44,
      "z": 11,
      "name": "Rock_Ice"
    },
    {
      "x": -17,
      "y": 45,
      "z": 11,
      "name": "Rock_Ice"
    },
    {
      "x": -17,
      "y": 46,
      "z": 11,
      "name": "Rock_Ice"
    },
    {
      "x": -17,
      "y": 47,
      "z": 11,
      "name": "Soil_Snow"
    },
    {
      "x": -17,
      "y": 23,
      "z": 12,
      "name": "Rock_Ice"
    },
    {
      "x": -17,
      "y": 24,
      "z": 12,
      "name": "Rock_Ice"
    },
    {
      "x": -17,
      "y": 25,
      "z": 12,
      "name": "Rock_Ice"
    },
    {
      "x": -17,
      "y": 26,
      "z": 12,
      "name": "Rock_Ice"
    },
    {
      "x": -17,
      "y": 27,
      "z": 12,
      "name": "Rock_Ice"
    },
    {
      "x": -17,
      "y": 28,
      "z": 12,
      "name": "Rock_Ice"
    },
    {
      "x": -17,
      "y": 29,
      "z": 12,
      "name": "Rock_Ice"
    },
    {
      "x": -17,
      "y": 30,
      "z": 12,
      "name": "Rock_Ice"
    },
    {
      "x": -17,
      "y": 31,
      "z": 12,
      "name": "Rock_Ice"
    },
    {
      "x": -17,
      "y": 32,
      "z": 12,
      "name": "Rock_Ice"
    },
    {
      "x": -17,
      "y": 33,
      "z": 12,
      "name": "Rock_Ice"
    },
    {
      "x": -17,
      "y": 34,
      "z": 12,
      "name": "Rock_Ice"
    },
    {
      "x": -17,
      "y": 35,
      "z": 12,
      "name": "Rock_Ice"
    },
    {
      "x": -17,
      "y": 36,
      "z": 12,
      "name": "Rock_Ice"
    },
    {
      "x": -17,
      "y": 37,
      "z": 12,
      "name": "Rock_Ice"
    },
    {
      "x": -17,
      "y": 38,
      "z": 12,
      "name": "Rock_Ice"
    },
    {
      "x": -17,
      "y": 39,
      "z": 12,
      "name": "Rock_Ice"
    },
    {
      "x": -17,
      "y": 40,
      "z": 12,
      "name": "Rock_Ice"
    },
    {
      "x": -17,
      "y": 41,
      "z": 12,
      "name": "Rock_Ice"
    },
    {
      "x": -17,
      "y": 42,
      "z": 12,
      "name": "Rock_Ice"
    },
    {
      "x": -17,
      "y": 43,
      "z": 12,
      "name": "Rock_Ice"
    },
    {
      "x": -17,
      "y": 44,
      "z": 12,
      "name": "Rock_Ice"
    },
    {
      "x": -17,
      "y": 45,
      "z": 12,
      "name": "Rock_Ice"
    },
    {
      "x": -17,
      "y": 46,
      "z": 12,
      "name": "Rock_Ice"
    },
    {
      "x": -17,
      "y": 47,
      "z": 12,
      "name": "Soil_Snow"
    },
    {
      "x": -17,
      "y": 27,
      "z": 13,
      "name": "Rock_Ice"
    },
    {
      "x": -17,
      "y": 28,
      "z": 13,
      "name": "Rock_Ice"
    },
    {
      "x": -17,
      "y": 29,
      "z": 13,
      "name": "Rock_Ice"
    },
    {
      "x": -17,
      "y": 30,
      "z": 13,
      "name": "Rock_Ice"
    },
    {
      "x": -17,
      "y": 31,
      "z": 13,
      "name": "Rock_Ice"
    },
    {
      "x": -17,
      "y": 32,
      "z": 13,
      "name": "Rock_Ice"
    },
    {
      "x": -17,
      "y": 33,
      "z": 13,
      "name": "Rock_Ice"
    },
    {
      "x": -17,
      "y": 34,
      "z": 13,
      "name": "Rock_Ice"
    },
    {
      "x": -17,
      "y": 35,
      "z": 13,
      "name": "Rock_Ice"
    },
    {
      "x": -17,
      "y": 36,
      "z": 13,
      "name": "Rock_Ice"
    },
    {
      "x": -17,
      "y": 37,
      "z": 13,
      "name": "Rock_Ice"
    },
    {
      "x": -17,
      "y": 38,
      "z": 13,
      "name": "Rock_Ice"
    },
    {
      "x": -17,
      "y": 39,
      "z": 13,
      "name": "Rock_Ice"
    },
    {
      "x": -17,
      "y": 40,
      "z": 13,
      "name": "Rock_Ice"
    },
    {
      "x": -17,
      "y": 41,
      "z": 13,
      "name": "Rock_Ice"
    },
    {
      "x": -17,
      "y": 42,
      "z": 13,
      "name": "Rock_Ice"
    },
    {
      "x": -17,
      "y": 43,
      "z": 13,
      "name": "Rock_Ice"
    },
    {
      "x": -17,
      "y": 44,
      "z": 13,
      "name": "Rock_Ice"
    },
    {
      "x": -17,
      "y": 45,
      "z": 13,
      "name": "Rock_Ice"
    },
    {
      "x": -17,
      "y": 46,
      "z": 13,
      "name": "Rock_Ice"
    },
    {
      "x": -17,
      "y": 47,
      "z": 13,
      "name": "Soil_Snow"
    },
    {
      "x": -17,
      "y": 29,
      "z": 14,
      "name": "Rock_Ice"
    },
    {
      "x": -17,
      "y": 30,
      "z": 14,
      "name": "Rock_Ice"
    },
    {
      "x": -17,
      "y": 31,
      "z": 14,
      "name": "Rock_Ice"
    },
    {
      "x": -17,
      "y": 32,
      "z": 14,
      "name": "Rock_Ice"
    },
    {
      "x": -17,
      "y": 33,
      "z": 14,
      "name": "Rock_Ice"
    },
    {
      "x": -17,
      "y": 34,
      "z": 14,
      "name": "Rock_Ice"
    },
    {
      "x": -17,
      "y": 35,
      "z": 14,
      "name": "Rock_Ice"
    },
    {
      "x": -17,
      "y": 36,
      "z": 14,
      "name": "Rock_Ice"
    },
    {
      "x": -17,
      "y": 37,
      "z": 14,
      "name": "Rock_Ice"
    },
    {
      "x": -17,
      "y": 38,
      "z": 14,
      "name": "Rock_Ice"
    },
    {
      "x": -17,
      "y": 39,
      "z": 14,
      "name": "Rock_Ice"
    },
    {
      "x": -17,
      "y": 40,
      "z": 14,
      "name": "Rock_Ice"
    },
    {
      "x": -17,
      "y": 41,
      "z": 14,
      "name": "Rock_Ice"
    },
    {
      "x": -17,
      "y": 42,
      "z": 14,
      "name": "Rock_Ice"
    },
    {
      "x": -17,
      "y": 43,
      "z": 14,
      "name": "Rock_Ice"
    },
    {
      "x": -17,
      "y": 44,
      "z": 14,
      "name": "Rock_Ice"
    },
    {
      "x": -17,
      "y": 45,
      "z": 14,
      "name": "Rock_Ice"
    },
    {
      "x": -17,
      "y": 46,
      "z": 14,
      "name": "Soil_Snow"
    },
    {
      "x": -17,
      "y": 31,
      "z": 15,
      "name": "Rock_Ice"
    },
    {
      "x": -17,
      "y": 32,
      "z": 15,
      "name": "Rock_Ice"
    },
    {
      "x": -17,
      "y": 33,
      "z": 15,
      "name": "Rock_Ice"
    },
    {
      "x": -17,
      "y": 34,
      "z": 15,
      "name": "Rock_Ice"
    },
    {
      "x": -17,
      "y": 35,
      "z": 15,
      "name": "Rock_Ice"
    },
    {
      "x": -17,
      "y": 36,
      "z": 15,
      "name": "Rock_Ice"
    },
    {
      "x": -17,
      "y": 37,
      "z": 15,
      "name": "Rock_Ice"
    },
    {
