{
  "version": 8,
  "blockIdVersion": 11,
  "anchorX": -3,
  "anchorY": 22,
  "anchorZ": 1,
  "blocks": [
    {
      "x": -32,
      "y": 61,
      "z": -7,
      "name": "Rock_Ice"
    },
    {
      "x": -32,
      "y": 62,
      "z": -7,
      "name": "Rock_Ice"
    },
    {
      "x": -32,
      "y": 63,
      "z": -7,
      "name": "Rock_Ice"
    },
    {
      "x": -32,
      "y": 64,
      "z": -7,
      "name": "Soil_Snow"
    },
    {
      "x": -32,
      "y": 58,
      "z": -6,
      "name": "Rock_Ice_Permafrost"
    },
    {
      "x": -32,
      "y": 59,
      "z": -6,
      "name": "Rock_Ice"
    },
    {
      "x": -32,
      "y": 60,
      "z": -6,
      "name": "Rock_Ice"
    },
    {
      "x": -32,
      "y": 61,
      "z": -6,
      "name": "Rock_Ice"
    },
    {
      "x": -32,
      "y": 62,
      "z": -6,
      "name": "Rock_Ice"
    },
    {
      "x": -32,
      "y": 63,
      "z": -6,
      "name": "Rock_Ice"
    },
    {
      "x": -31,
      "y": 65,
      "z": -11,
      "name": "Rock_Ice_Permafrost"
    },
    {
      "x": -31,
      "y": 66,
      "z": -11,
      "name": "Rock_Ice"
    },
    {
      "x": -31,
      "y": 67,
      "z": -11,
      "name": "Soil_Snow"
    },
    {
      "x": -31,
      "y": 64,
      "z": -10,
      "name": "Rock_Ice"
    },
    {
      "x": -31,
      "y": 65,
      "z": -10,
      "name": "Rock_Ice"
    },
    {
      "x": -31,
      "y": 66,
      "z": -10,
      "name": "Rock_Ice"
    },
    {
      "x": -31,
      "y": 67,
      "z": -10,
      "name": "Soil_Snow"
    },
    {
      "x": -31,
      "y": 66,
      "z": -9,
      "name": "Rock_Ice"
    },
    {
      "x": -31,
      "y": 67,
      "z": -9,
      "name": "Rock_Ice"
    },
    {
      "x": -31,
      "y": 68,
      "z": -9,
      "name": "Soil_Snow"
    },
    {
      "x": -31,
      "y": 57,
      "z": -7,
      "name": "Rock_Ice_Permafrost"
    },
    {
      "x": -31,
      "y": 58,
      "z": -7,
      "name": "Rock_Ice_Permafrost"
    },
    {
      "x": -31,
      "y": 59,
      "z": -7,
      "name": "Rock_Ice"
    },
    {
      "x": -31,
      "y": 60,
      "z": -7,
      "name": "Rock_Ice"
    },
    {
      "x": -31,
      "y": 61,
      "z": -7,
      "name": "Rock_Ice"
    },
    {
      "x": -31,
      "y": 62,
      "z": -7,
      "name": "Rock_Ice"
    },
    {
      "x": -31,
      "y": 63,
      "z": -7,
      "name": "Rock_Ice"
    },
    {
      "x": -31,
      "y": 64,
      "z": -7,
      "name": "Rock_Ice"
    },
    {
      "x": -31,
      "y": 65,
      "z": -7,
      "name": "Soil_Snow"
    },
    {
      "x": -31,
      "y": 56,
      "z": -6,
      "name": "Rock_Ice_Permafrost"
    },
    {
      "x": -31,
      "y": 57,
      "z": -6,
      "name": "Rock_Ice_Permafrost"
    },
    {
      "x": -31,
      "y": 58,
      "z": -6,
      "name": "Rock_Ice_Permafrost"
    },
    {
      "x": -31,
      "y": 59,
      "z": -6,
      "name": "Rock_Ice"
    },
    {
      "x": -31,
      "y": 60,
      "z": -6,
      "name": "Rock_Ice"
    },
    {
      "x": -31,
      "y": 61,
      "z": -6,
      "name": "Rock_Ice"
    },
    {
      "x": -31,
      "y": 62,
      "z": -6,
      "name": "Rock_Ice"
    },
    {
      "x": -31,
      "y": 63,
      "z": -6,
      "name": "Rock_Ice"
    },
    {
      "x": -31,
      "y": 64,
      "z": -6,
      "name": "Rock_Ice"
    },
    {
      "x": -31,
      "y": 65,
      "z": -6,
      "name": "Soil_Snow"
    },
    {
      "x": -31,
      "y": 57,
      "z": -5,
      "name": "Rock_Ice_Permafrost"
    },
    {
      "x": -31,
      "y": 58,
      "z": -5,
      "name": "Rock_Ice"
    },
    {
      "x": -31,
      "y": 59,
      "z": -5,
      "name": "Rock_Ice"
    },
    {
      "x": -31,
      "y": 60,
      "z": -5,
      "name": "Rock_Ice"
    },
    {
      "x": -31,
      "y": 61,
      "z": -5,
      "name": "Rock_Ice"
    },
    {
      "x": -31,
      "y": 62,
      "z": -5,
      "name": "Rock_Ice"
    },
    {
      "x": -31,
      "y": 63,
      "z": -5,
      "name": "Rock_Ice"
    },
    {
      "x": -31,
      "y": 64,
      "z": -5,
      "name": "Soil_Snow"
    },
    {
      "x": -30,
      "y": 62,
      "z": -13,
      "name": "Rock_Ice_Permafrost"
    },
    {
      "x": -30,
      "y": 63,
      "z": -13,
      "name": "Rock_Ice_Permafrost"
    },
    {
      "x": -30,
      "y": 64,
      "z": -13,
      "name": "Soil_Snow"
    },
    {
      "x": -30,
      "y": 61,
      "z": -12,
      "name": "Rock_Ice"
    },
    {
      "x": -30,
      "y": 62,
      "z": -12,
      "name": "Rock_Ice"
    },
    {
      "x": -30,
      "y": 63,
      "z": -12,
      "name": "Rock_Ice_Permafrost"
    },
    {
      "x": -30,
      "y": 64,
      "z": -12,
      "name": "Rock_Ice_Permafrost"
    },
    {
      "x": -30,
      "y": 65,
      "z": -12,
      "name": "Rock_Ice"
    },
    {
      "x": -30,
      "y": 66,
      "z": -12,
      "name": "Soil_Snow"
    },
    {
      "x": -30,
      "y": 60,
      "z": -11,
      "name": "Rock_Ice"
    },
    {
      "x": -30,
      "y": 61,
      "z": -11,
      "name": "Rock_Ice"
    },
    {
      "x": -30,
      "y": 62,
      "z": -11,
      "name": "Rock_Ice"
    },
    {
      "x": -30,
      "y": 63,
      "z": -11,
      "name": "Rock_Ice"
    },
    {
      "x": -30,
      "y": 64,
      "z": -11,
      "name": "Rock_Ice"
    },
    {
      "x": -30,
      "y": 65,
      "z": -11,
      "name": "Rock_Ice_Permafrost"
    },
    {
      "x": -30,
      "y": 66,
      "z": -11,
      "name": "Rock_Ice"
    },
    {
      "x": -30,
      "y": 67,
      "z": -11,
      "name": "Soil_Snow"
    },
    {
      "x": -30,
      "y": 61,
      "z": -10,
      "name": "Rock_Ice"
    },
    {
      "x": -30,
      "y": 62,
      "z": -10,
      "name": "Rock_Ice"
    },
    {
      "x": -30,
      "y": 63,
      "z": -10,
      "name": "Rock_Ice"
    },
    {
      "x": -30,
      "y": 64,
      "z": -10,
      "name": "Rock_Ice"
    },
    {
      "x": -30,
      "y": 65,
      "z": -10,
      "name": "Rock_Ice"
    },
    {
      "x": -30,
      "y": 66,
      "z": -10,
      "name": "Rock_Ice"
    },
    {
      "x": -30,
      "y": 67,
      "z": -10,
      "name": "Rock_Ice"
    },
    {
      "x": -30,
      "y": 68,
      "z": -10,
      "name": "Soil_Snow"
    },
    {
      "x": -30,
      "y": 62,
      "z": -9,
      "name": "Rock_Ice"
    },
    {
      "x": -30,
      "y": 63,
      "z": -9,
      "name": "Rock_Ice"
    },
    {
      "x": -30,
      "y": 64,
      "z": -9,
      "name": "Rock_Ice"
    },
    {
      "x": -30,
      "y": 65,
      "z": -9,
      "name": "Rock_Ice"
    },
    {
      "x": -30,
      "y": 66,
      "z": -9,
      "name": "Rock_Ice"
    },
    {
      "x": -30,
      "y": 67,
      "z": -9,
      "name": "Rock_Ice"
    },
    {
      "x": -30,
      "y": 68,
      "z": -9,
      "name": "Soil_Snow"
    },
    {
      "x": -30,
      "y": 56,
      "z": -8,
      "name": "Rock_Ice_Permafrost"
    },
    {
      "x": -30,
      "y": 57,
      "z": -8,
      "name": "Rock_Ice_Permafrost"
    },
    {
      "x": -30,
      "y": 58,
      "z": -8,
      "name": "Rock_Ice_Permafrost"
    },
    {
      "x": -30,
      "y": 59,
      "z": -8,
      "name": "Rock_Ice"
    },
    {
      "x": -30,
      "y": 60,
      "z": -8,
      "name": "Rock_Ice"
    },
    {
      "x": -30,
      "y": 61,
      "z": -8,
      "name": "Rock_Ice"
    },
    {
      "x": -30,
      "y": 62,
      "z": -8,
      "name": "Rock_Ice"
    },
    {
      "x": -30,
      "y": 63,
      "z": -8,
      "name": "Rock_Ice"
    },
    {
      "x": -30,
      "y": 64,
      "z": -8,
      "name": "Rock_Ice"
    },
    {
      "x": -30,
      "y": 65,
      "z": -8,
      "name": "Rock_Ice"
    },
    {
      "x": -30,
      "y": 66,
      "z": -8,
      "name": "Rock_Ice"
    },
    {
      "x": -30,
      "y": 67,
      "z": -8,
      "name": "Soil_Snow"
    },
    {
      "x": -30,
      "y": 55,
      "z": -7,
      "name": "Rock_Ice"
    },
    {
      "x": -30,
      "y": 56,
      "z": -7,
      "name": "Rock_Ice_Permafrost"
    },
    {
      "x": -30,
      "y": 57,
      "z": -7,
      "name": "Rock_Ice_Permafrost"
    },
    {
      "x": -30,
      "y": 58,
      "z": -7,
      "name": "Rock_Ice_Permafrost"
    },
    {
      "x": -30,
      "y": 59,
      "z": -7,
      "name": "Rock_Ice"
    },
    {
      "x": -30,
      "y": 60,
      "z": -7,
      "name": "Rock_Ice"
    },
    {
      "x": -30,
      "y": 61,
      "z": -7,
      "name": "Rock_Ice"
    },
    {
      "x": -30,
      "y": 62,
      "z": -7,
      "name": "Rock_Ice"
    },
    {
      "x": -30,
      "y": 63,
      "z": -7,
      "name": "Rock_Ice"
    },
    {
      "x": -30,
      "y": 64,
      "z": -7,
      "name": "Rock_Ice"
    },
    {
      "x": -30,
      "y": 65,
      "z": -7,
      "name": "Rock_Ice"
    },
    {
      "x": -30,
      "y": 66,
      "z": -7,
      "name": "Soil_Snow"
    },
    {
      "x": -30,
      "y": 53,
      "z": -6,
      "name": "Rock_Ice"
    },
    {
      "x": -30,
      "y": 54,
      "z": -6,
      "name": "Rock_Ice"
    },
    {
      "x": -30,
      "y": 55,
      "z": -6,
      "name": "Rock_Ice"
    },
    {
      "x": -30,
      "y": 56,
      "z": -6,
      "name": "Rock_Ice_Permafrost"
    },
    {
      "x": -30,
      "y": 57,
      "z": -6,
      "name": "Rock_Ice_Permafrost"
    },
    {
      "x": -30,
      "y": 58,
      "z": -6,
      "name": "Rock_Ice"
    },
    {
      "x": -30,
      "y": 59,
      "z": -6,
      "name": "Rock_Ice"
    },
    {
      "x": -30,
      "y": 60,
      "z": -6,
      "name": "Rock_Ice"
    },
    {
      "x": -30,
      "y": 61,
      "z": -6,
      "name": "Rock_Ice"
    },
    {
      "x": -30,
      "y": 62,
      "z": -6,
      "name": "Rock_Ice"
    },
    {
      "x": -30,
      "y": 63,
      "z": -6,
      "name": "Rock_Ice"
    },
    {
      "x": -30,
      "y": 64,
      "z": -6,
      "name": "Rock_Ice"
    },
    {
      "x": -30,
      "y": 65,
      "z": -6,
      "name": "Rock_Ice"
    },
    {
      "x": -30,
      "y": 66,
      "z": -6,
      "name": "Soil_Snow"
    },
    {
      "x": -30,
      "y": 53,
      "z": -5,
      "name": "Rock_Ice"
    },
    {
      "x": -30,
      "y": 54,
      "z": -5,
      "name": "Rock_Ice"
    },
    {
      "x": -30,
      "y": 55,
      "z": -5,
      "name": "Rock_Ice"
    },
    {
      "x": -30,
      "y": 56,
      "z": -5,
      "name": "Rock_Ice_Permafrost"
    },
    {
      "x": -30,
      "y": 57,
      "z": -5,
      "name": "Rock_Ice_Permafrost"
    },
    {
      "x": -30,
      "y": 58,
      "z": -5,
      "name": "Rock_Ice"
    },
    {
      "x": -30,
      "y": 59,
      "z": -5,
      "name": "Rock_Ice"
    },
    {
      "x": -30,
      "y": 60,
      "z": -5,
      "name": "Rock_Ice"
    },
    {
      "x": -30,
      "y": 61,
      "z": -5,
      "name": "Rock_Ice"
    },
    {
      "x": -30,
      "y": 62,
      "z": -5,
      "name": "Rock_Ice"
    },
    {
      "x": -30,
      "y": 63,
      "z": -5,
      "name": "Rock_Ice"
    },
    {
      "x": -30,
      "y": 64,
      "z": -5,
      "name": "Rock_Ice"
    },
    {
      "x": -30,
      "y": 65,
      "z": -5,
      "name": "Rock_Ice"
    },
    {
      "x": -30,
      "y": 66,
      "z": -5,
      "name": "Soil_Snow"
    },
    {
      "x": -30,
      "y": 57,
      "z": -4,
      "name": "Rock_Ice_Permafrost"
    },
    {
      "x": -30,
      "y": 58,
      "z": -4,
      "name": "Rock_Ice_Permafrost"
    },
    {
      "x": -30,
      "y": 59,
      "z": -4,
      "name": "Rock_Ice"
    },
    {
      "x": -30,
      "y": 60,
      "z": -4,
      "name": "Rock_Ice"
    },
    {
      "x": -30,
      "y": 61,
      "z": -4,
      "name": "Rock_Ice"
    },
    {
      "x": -30,
      "y": 62,
      "z": -4,
      "name": "Rock_Ice"
    },
    {
      "x": -30,
      "y": 63,
      "z": -4,
      "name": "Rock_Ice"
    },
    {
      "x": -30,
      "y": 64,
      "z": -4,
      "name": "Rock_Ice"
    },
    {
      "x": -29,
      "y": 60,
      "z": -14,
      "name": "Rock_Ice_Permafrost"
    },
    {
      "x": -29,
      "y": 61,
      "z": -14,
      "name": "Rock_Ice"
    },
    {
      "x": -29,
      "y": 62,
      "z": -14,
      "name": "Soil_Snow"
    },
    {
      "x": -29,
      "y": 58,
      "z": -13,
      "name": "Rock_Ice_Permafrost"
    },
    {
      "x": -29,
      "y": 59,
      "z": -13,
      "name": "Rock_Ice_Permafrost"
    },
    {
      "x": -29,
      "y": 60,
      "z": -13,
      "name": "Rock_Ice_Permafrost"
    },
    {
      "x": -29,
      "y": 61,
      "z": -13,
      "name": "Rock_Ice_Permafrost"
    },
    {
      "x": -29,
      "y": 62,
      "z": -13,
      "name": "Rock_Ice_Permafrost"
    },
    {
      "x": -29,
      "y": 63,
      "z": -13,
      "name": "Rock_Ice"
    },
    {
      "x": -29,
      "y": 64,
      "z": -13,
      "name": "Soil_Snow"
    },
    {
      "x": -29,
      "y": 57,
      "z": -12,
      "name": "Rock_Ice_Permafrost"
    },
    {
      "x": -29,
      "y": 58,
      "z": -12,
      "name": "Rock_Ice_Permafrost"
    },
    {
      "x": -29,
      "y": 59,
      "z": -12,
      "name": "Rock_Ice_Permafrost"
    },
    {
      "x": -29,
      "y": 60,
      "z": -12,
      "name": "Rock_Ice_Permafrost"
    },
    {
      "x": -29,
      "y": 61,
      "z": -12,
      "name": "Rock_Ice_Permafrost"
    },
    {
      "x": -29,
      "y": 62,
      "z": -12,
      "name": "Rock_Ice"
    },
    {
      "x": -29,
      "y": 63,
      "z": -12,
      "name": "Rock_Ice_Permafrost"
    },
    {
      "x": -29,
      "y": 64,
      "z": -12,
      "name": "Rock_Ice_Permafrost"
    },
    {
      "x": -29,
      "y": 65,
      "z": -12,
      "name": "Rock_Ice"
    },
    {
      "x": -29,
      "y": 66,
      "z": -12,
      "name": "Soil_Snow"
    },
    {
      "x": -29,
      "y": 57,
      "z": -11,
      "name": "Rock_Ice_Permafrost"
    },
    {
      "x": -29,
      "y": 58,
      "z": -11,
      "name": "Rock_Ice_Permafrost"
    },
    {
      "x": -29,
      "y": 59,
      "z": -11,
      "name": "Rock_Ice_Permafrost"
    },
    {
      "x": -29,
      "y": 60,
      "z": -11,
      "name": "Rock_Ice_Permafrost"
    },
    {
      "x": -29,
      "y": 61,
      "z": -11,
      "name": "Rock_Ice"
    },
    {
      "x": -29,
      "y": 62,
      "z": -11,
      "name": "Rock_Ice"
    },
    {
      "x": -29,
      "y": 63,
      "z": -11,
      "name": "Rock_Ice"
    },
    {
      "x": -29,
      "y": 64,
      "z": -11,
      "name": "Rock_Ice"
    },
    {
      "x": -29,
      "y": 65,
      "z": -11,
      "name": "Rock_Ice_Permafrost"
    },
    {
      "x": -29,
      "y": 66,
      "z": -11,
      "name": "Rock_Ice"
    },
    {
      "x": -29,
      "y": 67,
      "z": -11,
      "name": "Soil_Snow"
    },
    {
      "x": -29,
      "y": 58,
      "z": -10,
      "name": "Rock_Ice_Permafrost"
    },
    {
      "x": -29,
      "y": 59,
      "z": -10,
      "name": "Rock_Ice"
    },
    {
      "x": -29,
      "y": 60,
      "z": -10,
      "name": "Rock_Ice"
    },
    {
      "x": -29,
      "y": 61,
      "z": -10,
      "name": "Rock_Ice"
    },
    {
      "x": -29,
      "y": 62,
      "z": -10,
      "name": "Rock_Ice"
    },
    {
      "x": -29,
      "y": 63,
      "z": -10,
      "name": "Rock_Ice"
    },
    {
      "x": -29,
      "y": 64,
      "z": -10,
      "name": "Rock_Ice"
    },
    {
      "x": -29,
      "y": 65,
      "z": -10,
      "name": "Rock_Ice"
    },
    {
      "x": -29,
      "y": 66,
      "z": -10,
      "name": "Rock_Ice_Permafrost"
    },
    {
      "x": -29,
      "y": 67,
      "z": -10,
      "name": "Rock_Ice"
    },
    {
      "x": -29,
      "y": 68,
      "z": -10,
      "name": "Soil_Snow"
    },
    {
      "x": -29,
      "y": 59,
      "z": -9,
      "name": "Rock_Ice"
    },
    {
      "x": -29,
      "y": 60,
      "z": -9,
      "name": "Rock_Ice"
    },
    {
      "x": -29,
      "y": 61,
      "z": -9,
      "name": "Rock_Ice"
    },
    {
      "x": -29,
      "y": 62,
      "z": -9,
      "name": "Rock_Ice"
    },
    {
      "x": -29,
      "y": 63,
      "z": -9,
      "name": "Rock_Ice"
    },
    {
      "x": -29,
      "y": 64,
      "z": -9,
      "name": "Rock_Ice"
    },
    {
      "x": -29,
      "y": 65,
      "z": -9,
      "name": "Rock_Ice"
    },
    {
      "x": -29,
      "y": 66,
      "z": -9,
      "name": "Rock_Ice"
    },
    {
      "x": -29,
      "y": 67,
      "z": -9,
      "name": "Rock_Ice"
    },
    {
      "x": -29,
      "y": 68,
      "z": -9,
      "name": "Soil_Snow"
    },
    {
      "x": -29,
      "y": 53,
      "z": -8,
      "name": "Rock_Ice"
    },
    {
      "x": -29,
      "y": 54,
      "z": -8,
      "name": "Rock_Ice"
    },
    {
      "x": -29,
      "y": 55,
      "z": -8,
      "name": "Rock_Ice"
    },
    {
      "x": -29,
      "y": 56,
      "z": -8,
      "name": "Rock_Ice_Permafrost"
    },
    {
      "x": -29,
      "y": 57,
      "z": -8,
      "name": "Rock_Ice_Permafrost"
    },
    {
      "x": -29,
      "y": 58,
      "z": -8,
      "name": "Rock_Ice_Permafrost"
    },
    {
      "x": -29,
      "y": 59,
      "z": -8,
      "name": "Rock_Ice"
    },
    {
      "x": -29,
      "y": 60,
      "z": -8,
      "name": "Rock_Ice"
    },
    {
      "x": -29,
      "y": 61,
      "z": -8,
      "name": "Rock_Ice"
    },
    {
      "x": -29,
      "y": 62,
      "z": -8,
      "name": "Rock_Ice"
    },
    {
      "x": -29,
      "y": 63,
      "z": -8,
      "name": "Rock_Ice"
    },
    {
      "x": -29,
      "y": 64,
      "z": -8,
      "name": "Rock_Ice"
    },
    {
      "x": -29,
      "y": 65,
      "z": -8,
      "name": "Rock_Ice"
    },
    {
      "x": -29,
      "y": 66,
      "z": -8,
      "name": "Rock_Ice"
    },
    {
      "x": -29,
      "y": 67,
      "z": -8,
      "name": "Rock_Ice"
    },
    {
      "x": -29,
      "y": 68,
      "z": -8,
      "name": "Soil_Snow"
    },
    {
      "x": -29,
      "y": 52,
      "z": -7,
      "name": "Rock_Ice"
    },
    {
      "x": -29,
      "y": 53,
      "z": -7,
      "name": "Rock_Ice"
    },
    {
      "x": -29,
      "y": 54,
      "z": -7,
      "name": "Rock_Ice"
    },
    {
      "x": -29,
      "y": 55,
      "z": -7,
      "name": "Rock_Ice_Permafrost"
    },
    {
      "x": -29,
      "y": 56,
      "z": -7,
      "name": "Rock_Ice_Permafrost"
    },
    {
      "x": -29,
      "y": 57,
      "z": -7,
      "name": "Rock_Ice_Permafrost"
    },
    {
      "x": -29,
      "y": 58,
      "z": -7,
      "name": "Rock_Ice_Permafrost"
    },
    {
      "x": -29,
      "y": 59,
      "z": -7,
      "name": "Rock_Ice"
    },
    {
      "x": -29,
      "y": 60,
      "z": -7,
      "name": "Rock_Ice"
    },
    {
      "x": -29,
      "y": 61,
      "z": -7,
      "name": "Rock_Ice"
    },
    {
      "x": -29,
      "y": 62,
      "z": -7,
      "name": "Rock_Ice"
    },
    {
      "x": -29,
      "y": 63,
      "z": -7,
      "name": "Rock_Ice"
    },
    {
      "x": -29,
      "y": 64,
      "z": -7,
      "name": "Rock_Ice"
    },
    {
      "x": -29,
      "y": 65,
      "z": -7,
      "name": "Rock_Ice"
    },
    {
      "x": -29,
      "y": 66,
      "z": -7,
      "name": "Rock_Ice"
    },
    {
      "x": -29,
      "y": 67,
      "z": -7,
      "name": "Soil_Snow"
    },
    {
      "x": -29,
      "y": 51,
      "z": -6,
      "name": "Rock_Ice"
    },
    {
      "x": -29,
      "y": 52,
      "z": -6,
      "name": "Rock_Ice"
    },
    {
      "x": -29,
      "y": 53,
      "z": -6,
      "name": "Rock_Ice"
    },
    {
      "x": -29,
      "y": 54,
      "z": -6,
      "name": "Rock_Ice"
    },
    {
      "x": -29,
      "y": 55,
      "z": -6,
      "name": "Rock_Ice_Permafrost"
    },
    {
      "x": -29,
      "y": 56,
      "z": -6,
      "name": "Rock_Ice_Permafrost"
    },
    {
      "x": -29,
      "y": 57,
      "z": -6,
      "name": "Rock_Ice_Permafrost"
    },
    {
      "x": -29,
      "y": 58,
      "z": -6,
      "name": "Rock_Ice_Permafrost"
    },
    {
      "x": -29,
      "y": 59,
      "z": -6,
      "name": "Rock_Ice"
    },
    {
      "x": -29,
      "y": 60,
      "z": -6,
      "name": "Rock_Ice"
    },
    {
      "x": -29,
      "y": 61,
      "z": -6,
      "name": "Rock_Ice"
    },
    {
      "x": -29,
      "y": 62,
      "z": -6,
      "name": "Rock_Ice"
    },
    {
      "x": -29,
      "y": 63,
      "z": -6,
      "name": "Rock_Ice"
    },
    {
      "x": -29,
      "y": 64,
      "z": -6,
      "name": "Rock_Ice"
    },
    {
      "x": -29,
      "y": 65,
      "z": -6,
      "name": "Rock_Ice"
    },
    {
      "x": -29,
      "y": 66,
      "z": -6,
      "name": "Rock_Ice"
    },
    {
      "x": -29,
      "y": 67,
      "z": -6,
      "name": "Rock_Ice"
    },
    {
      "x": -29,
      "y": 68,
      "z": -6,
      "name": "Soil_Snow"
    },
    {
      "x": -29,
      "y": 51,
      "z": -5,
      "name": "Rock_Ice"
    },
    {
      "x": -29,
      "y": 52,
      "z": -5,
      "name": "Rock_Ice"
    },
    {
      "x": -29,
      "y": 53,
      "z": -5,
      "name": "Rock_Ice"
    },
    {
      "x": -29,
      "y": 54,
      "z": -5,
      "name": "Rock_Ice"
    },
    {
      "x": -29,
      "y": 55,
      "z": -5,
      "name": "Rock_Ice"
    },
    {
      "x": -29,
      "y": 56,
      "z": -5,
      "name": "Rock_Ice_Permafrost"
    },
    {
      "x": -29,
      "y": 57,
      "z": -5,
      "name": "Rock_Ice_Permafrost"
    },
    {
      "x": -29,
      "y": 58,
      "z": -5,
      "name": "Rock_Ice"
    },
    {
      "x": -29,
      "y": 59,
      "z": -5,
      "name": "Rock_Ice"
    },
    {
      "x": -29,
      "y": 60,
      "z": -5,
      "name": "Rock_Ice"
    },
    {
      "x": -29,
      "y": 61,
      "z": -5,
      "name": "Rock_Ice"
    },
    {
      "x": -29,
      "y": 62,
      "z": -5,
      "name": "Rock_Ice"
    },
    {
      "x": -29,
      "y": 63,
      "z": -5,
      "name": "Rock_Ice"
    },
    {
      "x": -29,
      "y": 64,
      "z": -5,
      "name": "Rock_Ice"
    },
    {
      "x": -29,
      "y": 65,
      "z": -5,
      "name": "Rock_Ice"
    },
    {
      "x": -29,
      "y": 66,
      "z": -5,
      "name": "Rock_Ice"
    },
    {
      "x": -29,
      "y": 67,
      "z": -5,
      "name": "Rock_Ice"
    },
    {
      "x": -29,
      "y": 68,
      "z": -5,
      "name": "Soil_Snow"
    },
    {
      "x": -29,
      "y": 54,
      "z": -4,
      "name": "Rock_Ice"
    },
    {
      "x": -29,
      "y": 55,
      "z": -4,
      "name": "Rock_Ice_Permafrost"
    },
    {
      "x": -29,
      "y": 56,
      "z": -4,
      "name": "Rock_Ice_Permafrost"
    },
    {
      "x": -29,
      "y": 57,
      "z": -4,
      "name": "Rock_Ice_Permafrost"
    },
    {
      "x": -29,
      "y": 58,
      "z": -4,
      "name": "Rock_Ice"
    },
    {
      "x": -29,
      "y": 59,
      "z": -4,
      "name": "Rock_Ice"
    },
    {
      "x": -29,
      "y": 60,
      "z": -4,
      "name": "Rock_Ice"
    },
    {
      "x": -29,
      "y": 61,
      "z": -4,
      "name": "Rock_Ice"
    },
    {
      "x": -29,
      "y": 62,
      "z": -4,
      "name": "Rock_Ice"
    },
    {
      "x": -29,
      "y": 63,
      "z": -4,
      "name": "Rock_Ice"
    },
    {
      "x": -29,
      "y": 64,
      "z": -4,
      "name": "Rock_Ice"
    },
    {
      "x": -29,
      "y": 65,
      "z": -4,
      "name": "Rock_Ice"
    },
    {
      "x": -29,
      "y": 66,
      "z": -4,
      "name": "Rock_Ice"
    },
    {
      "x": -29,
      "y": 67,
      "z": -4,
      "name": "Soil_Snow"
    },
    {
      "x": -29,
      "y": 57,
      "z": -3,
      "name": "Rock_Ice_Permafrost"
    },
    {
      "x": -29,
      "y": 58,
      "z": -3,
      "name": "Rock_Ice_Permafrost"
    },
    {
      "x": -29,
      "y": 59,
      "z": -3,
      "name": "Rock_Ice"
    },
    {
      "x": -29,
      "y": 60,
      "z": -3,
      "name": "Rock_Ice"
    },
    {
      "x": -29,
      "y": 61,
      "z": -3,
      "name": "Rock_Ice"
    },
    {
      "x": -29,
      "y": 62,
      "z": -3,
      "name": "Rock_Ice"
    },
    {
      "x": -29,
      "y": 63,
      "z": -3,
      "name": "Rock_Ice"
    },
    {
      "x": -29,
      "y": 64,
      "z": -3,
      "name": "Rock_Ice"
    },
    {
      "x": -29,
      "y": 65,
      "z": -3,
      "name": "Soil_Snow"
    },
    {
      "x": -29,
      "y": 59,
      "z": -2,
      "name": "Rock_Ice"
    },
    {
      "x": -29,
      "y": 60,
      "z": -2,
      "name": "Rock_Ice"
    },
    {
      "x": -29,
      "y": 61,
      "z": -2,
      "name": "Rock_Ice"
    },
    {
      "x": -29,
      "y": 62,
      "z": -2,
      "name": "Rock_Ice"
    },
    {
      "x": -29,
      "y": 63,
      "z": -2,
      "name": "Rock_Ice"
    },
    {
      "x": -29,
      "y": 64,
      "z": -2,
      "name": "Rock_Ice"
    },
    {
      "x": -29,
      "y": 65,
      "z": -2,
      "name": "Soil_Snow"
    },
    {
      "x": -29,
      "y": 60,
      "z": -1,
      "name": "Rock_Ice"
    },
    {
      "x": -29,
      "y": 61,
      "z": -1,
      "name": "Rock_Ice"
    },
    {
      "x": -29,
      "y": 62,
      "z": -1,
      "name": "Rock_Ice"
    },
    {
      "x": -29,
      "y": 63,
      "z": -1,
      "name": "Rock_Ice"
    },
    {
      "x": -29,
      "y": 64,
      "z": -1,
      "name": "Soil_Snow"
    },
    {
      "x": -29,
      "y": 58,
      "z": 7,
      "name": "Rock_Ice"
    },
    {
      "x": -29,
      "y": 59,
      "z": 7,
      "name": "Rock_Ice"
    },
    {
      "x": -29,
      "y": 60,
      "z": 7,
      "name": "Rock_Ice"
    },
    {
      "x": -29,
      "y": 61,
      "z": 7,
      "name": "Rock_Ice"
    },
    {
      "x": -29,
      "y": 62,
      "z": 7,
      "name": "Rock_Ice"
    },
    {
      "x": -29,
      "y": 54,
      "z": 8,
      "name": "Rock_Ice"
    },
    {
      "x": -29,
      "y": 55,
      "z": 8,
      "name": "Rock_Ice"
    },
    {
      "x": -29,
      "y": 56,
      "z": 8,
      "name": "Rock_Ice"
    },
    {
      "x": -29,
      "y": 57,
      "z": 8,
      "name": "Rock_Ice"
    },
    {
      "x": -29,
      "y": 58,
      "z": 8,
      "name": "Rock_Ice"
    },
    {
      "x": -29,
      "y": 59,
      "z": 8,
      "name": "Rock_Ice"
    },
    {
      "x": -29,
      "y": 60,
      "z": 8,
      "name": "Rock_Ice"
    },
    {
      "x": -29,
      "y": 61,
      "z": 8,
      "name": "Rock_Ice"
    },
    {
      "x": -29,
      "y": 62,
      "z": 8,
      "name": "Rock_Ice"
    },
    {
      "x": -29,
      "y": 63,
      "z": 8,
      "name": "Soil_Snow"
    },
    {
      "x": -28,
      "y": 57,
      "z": -15,
      "name": "Rock_Ice"
    },
    {
      "x": -28,
      "y": 58,
      "z": -15,
      "name": "Rock_Ice"
    },
    {
      "x": -28,
      "y": 59,
      "z": -15,
      "name": "Soil_Snow"
    },
    {
      "x": -28,
      "y": 56,
      "z": -14,
      "name": "Rock_Ice"
    },
    {
      "x": -28,
      "y": 57,
      "z": -14,
      "name": "Rock_Ice"
    },
    {
      "x": -28,
      "y": 58,
      "z": -14,
      "name": "Rock_Ice"
    },
    {
      "x": -28,
      "y": 59,
      "z": -14,
      "name": "Rock_Ice_Permafrost"
    },
    {
      "x": -28,
      "y": 60,
      "z": -14,
      "name": "Rock_Ice_Permafrost"
    },
    {
      "x": -28,
      "y": 61,
      "z": -14,
      "name": "Rock_Ice"
    },
    {
      "x": -28,
      "y": 62,
      "z": -14,
      "name": "Soil_Snow"
    },
    {
      "x": -28,
      "y": 54,
      "z": -13,
      "name": "Rock_Ice"
    },
    {
      "x": -28,
      "y": 55,
      "z": -13,
      "name": "Rock_Ice"
    },
    {
      "x": -28,
      "y": 56,
      "z": -13,
      "name": "Rock_Ice"
    },
    {
      "x": -28,
      "y": 57,
      "z": -13,
      "name": "Rock_Ice"
    },
    {
      "x": -28,
      "y": 58,
      "z": -13,
      "name": "Rock_Ice"
    },
    {
      "x": -28,
      "y": 59,
      "z": -13,
      "name": "Rock_Ice_Permafrost"
    },
    {
      "x": -28,
      "y": 60,
      "z": -13,
      "name": "Rock_Ice_Permafrost"
    },
    {
      "x": -28,
      "y": 61,
      "z": -13,
      "name": "Rock_Ice_Permafrost"
    },
    {
      "x": -28,
      "y": 62,
      "z": -13,
      "name": "Rock_Ice_Permafrost"
    },
    {
      "x": -28,
      "y": 63,
      "z": -13,
      "name": "Rock_Ice"
    },
    {
      "x": -28,
      "y": 64,
      "z": -13,
      "name": "Soil_Snow"
    },
    {
      "x": -28,
      "y": 54,
      "z": -12,
      "name": "Rock_Ice_Permafrost"
    },
    {
      "x": -28,
      "y": 55,
      "z": -12,
      "name": "Rock_Ice_Permafrost"
    },
    {
      "x": -28,
      "y": 56,
      "z": -12,
      "name": "Rock_Ice_Permafrost"
    },
    {
      "x": -28,
      "y": 57,
      "z": -12,
      "name": "Rock_Ice_Permafrost"
    },
    {
      "x": -28,
      "y": 58,
      "z": -12,
      "name": "Rock_Ice_Permafrost"
    },
    {
      "x": -28,
      "y": 59,
      "z": -12,
      "name": "Rock_Ice_Permafrost"
    },
    {
      "x": -28,
      "y": 60,
      "z": -12,
      "name": "Rock_Ice_Permafrost"
    },
    {
      "x": -28,
      "y": 61,
      "z": -12,
      "name": "Rock_Ice_Permafrost"
    },
    {
      "x": -28,
      "y": 62,
      "z": -12,
      "name": "Rock_Ice"
    },
    {
      "x": -28,
      "y": 63,
      "z": -12,
      "name": "Rock_Ice"
    },
    {
      "x": -28,
      "y": 64,
      "z": -12,
      "name": "Rock_Ice_Permafrost"
    },
    {
      "x": -28,
      "y": 65,
      "z": -12,
      "name": "Rock_Ice"
    },
    {
      "x": -28,
      "y": 66,
      "z": -12,
      "name": "Soil_Snow"
    },
    {
      "x": -28,
      "y": 55,
      "z": -11,
      "name": "Rock_Ice_Permafrost"
    },
    {
      "x": -28,
      "y": 56,
      "z": -11,
      "name": "Rock_Ice_Permafrost"
    },
    {
      "x": -28,
      "y": 57,
      "z": -11,
      "name": "Rock_Ice_Permafrost"
    },
    {
      "x": -28,
      "y": 58,
      "z": -11,
      "name": "Rock_Ice_Permafrost"
    },
    {
      "x": -28,
      "y": 59,
      "z": -11,
      "name": "Rock_Ice_Permafrost"
    },
    {
      "x": -28,
      "y": 60,
      "z": -11,
      "name": "Rock_Ice_Permafrost"
    },
    {
      "x": -28,
      "y": 61,
      "z": -11,
      "name": "Rock_Ice_Permafrost"
    },
    {
      "x": -28,
      "y": 62,
      "z": -11,
      "name": "Rock_Ice"
    },
    {
      "x": -28,
      "y": 63,
      "z": -11,
      "name": "Rock_Ice"
    },
    {
      "x": -28,
      "y": 64,
      "z": -11,
      "name": "Rock_Ice_Permafrost"
    },
    {
      "x": -28,
      "y": 65,
      "z": -11,
      "name": "Rock_Ice_Permafrost"
    },
    {
      "x": -28,
      "y": 66,
      "z": -11,
      "name": "Rock_Ice"
    },
    {
      "x": -28,
      "y": 67,
      "z": -11,
      "name": "Soil_Snow"
    },
    {
      "x": -28,
      "y": 56,
      "z": -10,
      "name": "Rock_Ice_Permafrost"
    },
    {
      "x": -28,
      "y": 57,
      "z": -10,
      "name": "Rock_Ice_Permafrost"
    },
    {
      "x": -28,
      "y": 58,
      "z": -10,
      "name": "Rock_Ice_Permafrost"
    },
    {
      "x": -28,
      "y": 59,
      "z": -10,
      "name": "Rock_Ice_Permafrost"
    },
    {
      "x": -28,
      "y": 60,
      "z": -10,
      "name": "Rock_Ice"
    },
    {
      "x": -28,
      "y": 61,
      "z": -10,
      "name": "Rock_Ice"
    },
    {
      "x": -28,
      "y": 62,
      "z": -10,
      "name": "Rock_Ice"
    },
    {
      "x": -28,
      "y": 63,
      "z": -10,
      "name": "Rock_Ice"
    },
    {
      "x": -28,
      "y": 64,
      "z": -10,
      "name": "Rock_Ice"
    },
    {
      "x": -28,
      "y": 65,
      "z": -10,
      "name": "Rock_Ice"
    },
    {
      "x": -28,
      "y": 66,
      "z": -10,
      "name": "Rock_Ice_Permafrost"
    },
    {
      "x": -28,
      "y": 67,
      "z": -10,
      "name": "Rock_Ice"
    },
    {
      "x": -28,
      "y": 68,
      "z": -10,
      "name": "Soil_Snow"
    },
    {
      "x": -28,
      "y": 52,
      "z": -9,
      "name": "Rock_Ice"
    },
    {
      "x": -28,
      "y": 53,
      "z": -9,
      "name": "Rock_Ice"
    },
    {
      "x": -28,
      "y": 54,
      "z": -9,
      "name": "Rock_Ice"
    },
    {
      "x": -28,
      "y": 55,
      "z": -9,
      "name": "Rock_Ice"
    },
    {
      "x": -28,
      "y": 56,
      "z": -9,
      "name": "Rock_Ice_Permafrost"
    },
    {
      "x": -28,
      "y": 57,
      "z": -9,
      "name": "Rock_Ice_Permafrost"
    },
    {
      "x": -28,
      "y": 58,
      "z": -9,
      "name": "Rock_Ice_Permafrost"
    },
    {
      "x": -28,
      "y": 59,
      "z": -9,
      "name": "Rock_Ice"
    },
    {
      "x": -28,
      "y": 60,
      "z": -9,
      "name": "Rock_Ice"
    },
    {
      "x": -28,
      "y": 61,
      "z": -9,
      "name": "Rock_Ice"
    },
    {
      "x": -28,
      "y": 62,
      "z": -9,
      "name": "Rock_Ice"
    },
    {
      "x": -28,
      "y": 63,
      "z": -9,
      "name": "Rock_Ice"
    },
    {
      "x": -28,
      "y": 64,
      "z": -9,
      "name": "Rock_Ice"
    },
    {
      "x": -28,
      "y": 65,
      "z": -9,
      "name": "Rock_Ice"
    },
    {
      "x": -28,
      "y": 66,
      "z": -9,
      "name": "Rock_Ice"
    },
    {
      "x": -28,
      "y": 67,
      "z": -9,
      "name": "Rock_Ice"
    },
    {
      "x": -28,
      "y": 68,
      "z": -9,
      "name": "Soil_Snow"
    },
    {
      "x": -28,
      "y": 51,
      "z": -8,
      "name": "Rock_Ice"
    },
    {
      "x": -28,
      "y": 52,
      "z": -8,
      "name": "Rock_Ice"
    },
    {
      "x": -28,
      "y": 53,
      "z": -8,
      "name": "Rock_Ice"
    },
    {
      "x": -28,
      "y": 54,
      "z": -8,
      "name": "Rock_Ice"
    },
    {
      "x": -28,
      "y": 55,
      "z": -8,
      "name": "Rock_Ice"
    },
    {
      "x": -28,
      "y": 56,
      "z": -8,
      "name": "Rock_Ice_Permafrost"
    },
    {
      "x": -28,
      "y": 57,
      "z": -8,
      "name": "Rock_Ice_Permafrost"
    },
    {
      "x": -28,
      "y": 58,
      "z": -8,
      "name": "Rock_Ice_Permafrost"
    },
    {
      "x": -28,
      "y": 59,
      "z": -8,
      "name": "Rock_Ice"
    },
    {
      "x": -28,
      "y": 60,
      "z": -8,
      "name": "Rock_Ice"
    },
    {
      "x": -28,
      "y": 61,
      "z": -8,
      "name": "Rock_Ice"
    },
    {
      "x": -28,
      "y": 62,
      "z": -8,
      "name": "Rock_Ice"
    },
    {
      "x": -28,
      "y": 63,
      "z": -8,
      "name": "Rock_Ice"
    },
    {
      "x": -28,
      "y": 64,
      "z": -8,
      "name": "Rock_Ice"
    },
    {
      "x": -28,
      "y": 65,
      "z": -8,
      "name": "Rock_Ice"
    },
    {
      "x": -28,
      "y": 66,
      "z": -8,
      "name": "Rock_Ice"
    },
    {
      "x": -28,
      "y": 67,
      "z": -8,
      "name": "Rock_Ice"
    },
    {
      "x": -28,
      "y": 68,
      "z": -8,
      "name": "Rock_Ice"
    },
    {
      "x": -28,
      "y": 69,
      "z": -8,
      "name": "Soil_Snow"
    },
    {
      "x": -28,
      "y": 50,
      "z": -7,
      "name": "Rock_Ice"
    },
    {
      "x": -28,
      "y": 51,
      "z": -7,
      "name": "Rock_Ice"
    },
    {
      "x": -28,
      "y": 52,
      "z": -7,
      "name": "Rock_Ice"
    },
    {
      "x": -28,
      "y": 53,
      "z": -7,
      "name": "Rock_Ice"
    },
    {
      "x": -28,
      "y": 54,
      "z": -7,
      "name": "Rock_Ice"
    },
    {
      "x": -28,
      "y": 55,
      "z": -7,
      "name": "Rock_Ice"
    },
    {
      "x": -28,
      "y": 56,
      "z": -7,
      "name": "Rock_Ice_Permafrost"
    },
    {
      "x": -28,
      "y": 57,
      "z": -7,
      "name": "Rock_Ice_Permafrost"
    },
    {
      "x": -28,
      "y": 58,
      "z": -7,
      "name": "Rock_Ice"
    },
    {
      "x": -28,
      "y": 59,
      "z": -7,
      "name": "Rock_Ice"
    },
    {
      "x": -28,
      "y": 60,
      "z": -7,
      "name": "Rock_Ice"
    },
    {
      "x": -28,
      "y": 61,
      "z": -7,
      "name": "Rock_Ice"
    },
    {
      "x": -28,
      "y": 62,
      "z": -7,
      "name": "Rock_Ice"
    },
    {
      "x": -28,
      "y": 63,
      "z": -7,
      "name": "Rock_Ice"
    },
    {
      "x": -28,
      "y": 64,
      "z": -7,
      "name": "Rock_Ice"
    },
    {
      "x": -28,
      "y": 65,
      "z": -7,
      "name": "Rock_Ice"
    },
    {
      "x": -28,
      "y": 66,
      "z": -7,
      "name": "Rock_Ice"
    },
    {
      "x": -28,
      "y": 67,
      "z": -7,
      "name": "Rock_Ice"
    },
    {
      "x": -28,
      "y": 68,
      "z": -7,
      "name": "Soil_Snow"
    },
    {
      "x": -28,
      "y": 49,
      "z": -6,
      "name": "Rock_Ice"
    },
    {
      "x": -28,
      "y": 50,
      "z": -6,
      "name": "Rock_Ice"
    },
    {
      "x": -28,
      "y": 51,
      "z": -6,
      "name": "Rock_Ice"
    },
    {
      "x": -28,
      "y": 52,
      "z": -6,
      "name": "Rock_Ice"
    },
    {
      "x": -28,
      "y": 53,
      "z": -6,
      "name": "Rock_Ice"
    },
    {
      "x": -28,
      "y": 54,
      "z": -6,
      "name": "Rock_Ice"
    },
    {
      "x": -28,
      "y": 55,
      "z": -6,
      "name": "Rock_Ice"
    },
    {
      "x": -28,
      "y": 56,
      "z": -6,
      "name": "Rock_Ice_Permafrost"
    },
    {
      "x": -28,
      "y": 57,
      "z": -6,
      "name": "Rock_Ice_Permafrost"
    },
    {
      "x": -28,
      "y": 58,
      "z": -6,
      "name": "Rock_Ice"
    },
    {
      "x": -28,
      "y": 59,
      "z": -6,
      "name": "Rock_Ice"
    },
    {
      "x": -28,
      "y": 60,
      "z": -6,
      "name": "Rock_Ice"
    },
    {
      "x": -28,
      "y": 61,
      "z": -6,
      "name": "Rock_Ice"
    },
    {
      "x": -28,
      "y": 62,
      "z": -6,
      "name": "Rock_Ice"
    },
    {
      "x": -28,
      "y": 63,
      "z": -6,
      "name": "Rock_Ice"
    },
    {
      "x": -28,
      "y": 64,
      "z": -6,
      "name": "Rock_Ice"
    },
    {
      "x": -28,
      "y": 65,
      "z": -6,
      "name": "Rock_Ice"
    },
    {
      "x": -28,
      "y": 66,
      "z": -6,
      "name": "Rock_Ice"
    },
    {
      "x": -28,
      "y": 67,
      "z": -6,
      "name": "Rock_Ice"
    },
    {
      "x": -28,
      "y": 68,
      "z": -6,
      "name": "Soil_Snow"
    },
    {
      "x": -28,
      "y": 48,
      "z": -5,
      "name": "Rock_Ice"
    },
    {
      "x": -28,
      "y": 49,
      "z": -5,
      "name": "Rock_Ice"
    },
    {
      "x": -28,
      "y": 50,
      "z": -5,
      "name": "Rock_Ice"
    },
    {
      "x": -28,
      "y": 51,
      "z": -5,
      "name": "Rock_Ice"
    },
    {
      "x": -28,
      "y": 52,
      "z": -5,
      "name": "Rock_Ice"
    },
    {
      "x": -28,
      "y": 53,
      "z": -5,
      "name": "Rock_Ice"
    },
    {
      "x": -28,
      "y": 54,
      "z": -5,
      "name": "Rock_Ice"
    },
    {
      "x": -28,
      "y": 55,
      "z": -5,
      "name": "Rock_Ice_Permafrost"
    },
    {
      "x": -28,
      "y": 56,
      "z": -5,
      "name": "Rock_Ice_Permafrost"
    },
    {
      "x": -28,
      "y": 57,
      "z": -5,
      "name": "Rock_Ice_Permafrost"
    },
    {
      "x": -28,
      "y": 58,
      "z": -5,
      "name": "Rock_Ice"
    },
    {
      "x": -28,
      "y": 59,
      "z": -5,
      "name": "Rock_Ice"
    },
    {
      "x": -28,
      "y": 60,
      "z": -5,
      "name": "Rock_Ice"
    },
    {
      "x": -28,
      "y": 61,
      "z": -5,
      "name": "Rock_Ice"
    },
    {
      "x": -28,
      "y": 62,
      "z": -5,
      "name": "Rock_Ice"
    },
    {
      "x": -28,
      "y": 63,
      "z": -5,
      "name": "Rock_Ice"
    },
    {
      "x": -28,
      "y": 64,
      "z": -5,
      "name": "Rock_Ice"
    },
    {
      "x": -28,
      "y": 65,
      "z": -5,
      "name": "Rock_Ice"
    },
    {
      "x": -28,
      "y": 66,
      "z": -5,
      "name": "Rock_Ice"
    },
    {
      "x": -28,
      "y": 67,
      "z": -5,
      "name": "Rock_Ice"
    },
    {
      "x": -28,
      "y": 68,
      "z": -5,
      "name": "Rock_Ice"
    },
    {
      "x": -28,
      "y": 69,
      "z": -5,
      "name": "Soil_Snow"
    },
    {
      "x": -28,
      "y": 51,
      "z": -4,
      "name": "Rock_Ice"
    },
    {
      "x": -28,
      "y": 52,
      "z": -4,
      "name": "Rock_Ice"
    },
    {
      "x": -28,
      "y": 53,
      "z": -4,
      "name": "Rock_Ice"
    },
    {
      "x": -28,
      "y": 54,
      "z": -4,
      "name": "Rock_Ice"
    },
    {
      "x": -28,
      "y": 55,
      "z": -4,
      "name": "Rock_Ice_Permafrost"
    },
    {
      "x": -28,
      "y": 56,
      "z": -4,
      "name": "Rock_Ice_Permafrost"
    },
    {
      "x": -28,
      "y": 57,
      "z": -4,
      "name": "Rock_Ice_Permafrost"
    },
    {
      "x": -28,
      "y": 58,
      "z": -4,
      "name": "Rock_Ice_Permafrost"
    },
    {
      "x": -28,
      "y": 59,
      "z": -4,
      "name": "Rock_Ice"
    },
    {
      "x": -28,
      "y": 60,
      "z": -4,
      "name": "Rock_Ice"
    },
    {
      "x": -28,
      "y": 61,
      "z": -4,
      "name": "Rock_Ice"
    },
    {
      "x": -28,
      "y": 62,
      "z": -4,
      "name": "Rock_Ice"
    },
    {
      "x": -28,
      "y": 63,
      "z": -4,
      "name": "Rock_Ice"
    },
    {
      "x": -28,
      "y": 64,
      "z": -4,
      "name": "Rock_Ice"
    },
    {
      "x": -28,
      "y": 65,
      "z": -4,
      "name": "Rock_Ice"
    },
    {
      "x": -28,
      "y": 66,
      "z": -4,
      "name": "Rock_Ice"
    },
    {
      "x": -28,
      "y": 67,
      "z": -4,
      "name": "Rock_Ice"
    },
    {
      "x": -28,
      "y": 68,
      "z": -4,
      "name": "Rock_Ice"
    },
    {
      "x": -28,
      "y": 69,
      "z": -4,
      "name": "Soil_Snow"
    },
    {
      "x": -28,
      "y": 54,
      "z": -3,
      "name": "Rock_Ice"
    },
    {
      "x": -28,
      "y": 55,
      "z": -3,
      "name": "Rock_Ice_Permafrost"
    },
    {
      "x": -28,
      "y": 56,
      "z": -3,
      "name": "Rock_Ice_Permafrost"
    },
    {
      "x": -28,
      "y": 57,
      "z": -3,
      "name": "Rock_Ice_Permafrost"
    },
    {
      "x": -28,
      "y": 58,
      "z": -3,
      "name": "Rock_Ice"
    },
    {
      "x": -28,
      "y": 59,
      "z": -3,
      "name": "Rock_Ice"
    },
    {
      "x": -28,
      "y": 60,
      "z": -3,
      "name": "Rock_Ice"
    },
    {
      "x": -28,
      "y": 61,
      "z": -3,
      "name": "Rock_Ice"
    },
    {
      "x": -28,
      "y": 62,
      "z": -3,
      "name": "Rock_Ice"
    },
    {
      "x": -28,
      "y": 63,
      "z": -3,
      "name": "Rock_Ice"
    },
    {
      "x": -28,
      "y": 64,
      "z": -3,
      "name": "Rock_Ice"
    },
    {
      "x": -28,
      "y": 65,
      "z": -3,
      "name": "Rock_Ice"
    },
    {
      "x": -28,
      "y": 66,
      "z": -3,
      "name": "Rock_Ice"
    },
    {
      "x": -28,
      "y": 67,
      "z": -3,
      "name": "Rock_Ice"
    },
    {
      "x": -28,
      "y": 68,
      "z": -3,
      "name": "Soil_Snow"
    },
    {
      "x": -28,
      "y": 55,
      "z": -2,
      "name": "Rock_Ice_Permafrost"
    },
    {
      "x": -28,
      "y": 56,
      "z": -2,
      "name": "Rock_Ice_Permafrost"
    },
    {
      "x": -28,
      "y": 57,
      "z": -2,
      "name": "Rock_Ice"
    },
    {
      "x": -28,
      "y": 58,
      "z": -2,
      "name": "Rock_Ice_Permafrost"
    },
    {
      "x": -28,
      "y": 59,
      "z": -2,
      "name": "Rock_Ice"
    },
    {
      "x": -28,
      "y": 60,
      "z": -2,
      "name": "Rock_Ice"
    },
    {
      "x": -28,
      "y": 61,
      "z": -2,
      "name": "Rock_Ice"
    },
    {
      "x": -28,
      "y": 62,
      "z": -2,
      "name": "Rock_Ice"
    },
    {
      "x": -28,
      "y": 63,
      "z": -2,
      "name": "Rock_Ice"
    },
    {
      "x": -28,
      "y": 64,
      "z": -2,
      "name": "Rock_Ice"
    },
    {
      "x": -28,
      "y": 65,
      "z": -2,
      "name": "Rock_Ice"
    },
    {
      "x": -28,
      "y": 66,
      "z": -2,
      "name": "Soil_Snow"
    },
    {
      "x": -28,
      "y": 56,
      "z": -1,
      "name": "Rock_Ice_Permafrost"
    },
    {
      "x": -28,
      "y": 57,
      "z": -1,
      "name": "Rock_Ice_Permafrost"
    },
    {
      "x": -28,
      "y": 58,
      "z": -1,
      "name": "Rock_Ice_Permafrost"
    },
    {
      "x": -28,
      "y": 59,
      "z": -1,
      "name": "Rock_Ice"
    },
    {
      "x": -28,
      "y": 60,
      "z": -1,
      "name": "Rock_Ice"
    },
    {
      "x": -28,
      "y": 61,
      "z": -1,
      "name": "Rock_Ice"
    },
    {
      "x": -28,
      "y": 62,
      "z": -1,
      "name": "Rock_Ice"
    },
    {
      "x": -28,
      "y": 63,
      "z": -1,
      "name": "Rock_Ice"
    },
    {
      "x": -28,
      "y": 64,
      "z": -1,
      "name": "Rock_Ice"
    },
    {
      "x": -28,
      "y": 65,
      "z": -1,
      "name": "Rock_Ice"
    },
    {
      "x": -28,
      "y": 66,
      "z": -1,
      "name": "Soil_Snow"
    },
    {
      "x": -28,
      "y": 56,
      "z": 0,
      "name": "Rock_Ice_Permafrost"
    },
    {
      "x": -28,
      "y": 57,
      "z": 0,
      "name": "Rock_Ice_Permafrost"
    },
    {
      "x": -28,
      "y": 58,
      "z": 0,
      "name": "Rock_Ice"
    },
    {
      "x": -28,
      "y": 59,
      "z": 0,
      "name": "Rock_Ice"
    },
    {
      "x": -28,
      "y": 60,
      "z": 0,
      "name": "Rock_Ice"
    },
    {
      "x": -28,
      "y": 61,
      "z": 0,
      "name": "Rock_Ice"
    },
    {
      "x": -28,
      "y": 62,
      "z": 0,
      "name": "Rock_Ice"
    },
    {
      "x": -28,
      "y": 63,
      "z": 0,
      "name": "Rock_Ice"
    },
    {
      "x": -28,
      "y": 64,
      "z": 0,
      "name": "Rock_Ice"
    },
    {
      "x": -28,
      "y": 65,
      "z": 0,
      "name": "Soil_Snow"
    },
    {
      "x": -28,
      "y": 57,
      "z": 1,
      "name": "Rock_Ice_Permafrost"
    },
    {
      "x": -28,
      "y": 58,
      "z": 1,
      "name": "Rock_Ice"
    },
    {
      "x": -28,
      "y": 59,
      "z": 1,
      "name": "Rock_Ice"
    },
    {
      "x": -28,
      "y": 60,
      "z": 1,
      "name": "Rock_Ice"
    },
    {
      "x": -28,
      "y": 61,
      "z": 1,
      "name": "Rock_Ice"
    },
    {
      "x": -28,
      "y": 62,
      "z": 1,
      "name": "Rock_Ice"
    },
    {
      "x": -28,
      "y": 63,
      "z": 1,
      "name": "Rock_Ice"
    },
    {
      "x": -28,
      "y": 64,
      "z": 1,
      "name": "Rock_Ice"
    },
    {
      "x": -28,
      "y": 65,
      "z": 1,
      "name": "Soil_Snow"
    },
    {
      "x": -28,
      "y": 58,
      "z": 2,
      "name": "Rock_Ice_Permafrost"
    },
    {
      "x": -28,
      "y": 59,
      "z": 2,
      "name": "Rock_Ice"
    },
    {
      "x": -28,
      "y": 60,
      "z": 2,
      "name": "Rock_Ice"
    },
    {
      "x": -28,
      "y": 61,
      "z": 2,
      "name": "Rock_Ice"
    },
    {
      "x": -28,
      "y": 62,
      "z": 2,
      "name": "Rock_Ice"
    },
    {
      "x": -28,
      "y": 63,
      "z": 2,
      "name": "Rock_Ice"
    },
    {
      "x": -28,
      "y": 64,
      "z": 2,
      "name": "Rock_Ice"
    },
    {
      "x": -28,
      "y": 65,
      "z": 2,
      "name": "Soil_Snow"
    },
    {
      "x": -28,
      "y": 58,
      "z": 3,
      "name": "Rock_Ice_Permafrost"
    },
    {
      "x": -28,
      "y": 59,
      "z": 3,
      "name": "Rock_Ice_Permafrost"
    },
    {
      "x": -28,
      "y": 60,
      "z": 3,
      "name": "Rock_Ice_Permafrost"
    },
    {
      "x": -28,
      "y": 61,
      "z": 3,
      "name": "Rock_Ice"
    },
    {
      "x": -28,
      "y": 62,
      "z": 3,
      "name": "Rock_Ice"
    },
    {
      "x": -28,
      "y": 63,
      "z": 3,
      "name": "Rock_Ice"
    },
    {
      "x": -28,
      "y": 64,
      "z": 3,
      "name": "Soil_Snow"
    },
    {
      "x": -28,
      "y": 57,
      "z": 4,
      "name": "Rock_Ice"
    },
    {
      "x": -28,
      "y": 58,
      "z": 4,
      "name": "Rock_Ice_Permafrost"
    },
    {
      "x": -28,
      "y": 59,
      "z": 4,
      "name": "Rock_Ice_Permafrost"
    },
    {
      "x": -28,
      "y": 60,
      "z": 4,
      "name": "Rock_Ice_Permafrost"
    },
    {
      "x": -28,
      "y": 61,
      "z": 4,
      "name": "Rock_Ice_Permafrost"
    },
    {
      "x": -28,
      "y": 62,
      "z": 4,
      "name": "Rock_Ice"
    },
    {
      "x": -28,
      "y": 63,
      "z": 4,
      "name": "Rock_Ice"
    },
    {
      "x": -28,
      "y": 64,
      "z": 4,
      "name": "Soil_Snow"
    },
    {
      "x": -28,
      "y": 56,
      "z": 5,
      "name": "Rock_Ice"
    },
    {
      "x": -28,
      "y": 57,
      "z": 5,
      "name": "Rock_Ice"
    },
    {
      "x": -28,
      "y": 58,
      "z": 5,
      "name": "Rock_Ice"
    },
    {
      "x": -28,
      "y": 59,
      "z": 5,
      "name": "Rock_Ice_Permafrost"
    },
    {
      "x": -28,
      "y": 60,
      "z": 5,
      "name": "Rock_Ice_Permafrost"
    },
    {
      "x": -28,
      "y": 61,
      "z": 5,
      "name": "Rock_Ice_Permafrost"
    },
    {
      "x": -28,
      "y": 62,
      "z": 5,
      "name": "Rock_Ice_Permafrost"
    },
    {
      "x": -28,
      "y": 63,
      "z": 5,
      "name": "Rock_Ice_Permafrost"
    },
    {
      "x": -28,
      "y": 64,
      "z": 5,
      "name": "Rock_Ice"
    },
    {
      "x": -28,
      "y": 65,
      "z": 5,
      "name": "Soil_Snow"
    },
    {
      "x": -28,
      "y": 54,
      "z": 6,
      "name": "Rock_Ice"
    },
    {
      "x": -28,
      "y": 55,
      "z": 6,
      "name": "Rock_Ice"
    },
    {
      "x": -28,
      "y": 56,
      "z": 6,
      "name": "Rock_Ice"
    },
    {
      "x": -28,
      "y": 57,
      "z": 6,
      "name": "Rock_Ice"
    },
    {
      "x": -28,
      "y": 58,
      "z": 6,
      "name": "Rock_Ice"
    },
    {
      "x": -28,
      "y": 59,
      "z": 6,
      "name": "Rock_Ice"
    },
    {
      "x": -28,
      "y": 60,
      "z": 6,
      "name": "Rock_Ice_Permafrost"
    },
    {
      "x": -28,
      "y": 61,
      "z": 6,
      "name": "Rock_Ice_Permafrost"
    },
    {
      "x": -28,
      "y": 62,
      "z": 6,
      "name": "Rock_Ice_Permafrost"
    },
    {
      "x": -28,
      "y": 63,
      "z": 6,
      "name": "Rock_Ice_Permafrost"
    },
    {
      "x": -28,
      "y": 64,
      "z": 6,
      "name": "Rock_Ice"
    },
    {
      "x": -28,
      "y": 65,
      "z": 6,
      "name": "Soil_Snow"
    },
    {
      "x": -28,
      "y": 52,
      "z": 7,
      "name": "Rock_Ice"
    },
    {
      "x": -28,
      "y": 53,
      "z": 7,
      "name": "Rock_Ice"
    },
    {
      "x": -28,
      "y": 54,
      "z": 7,
      "name": "Rock_Ice"
    },
    {
      "x": -28,
      "y": 55,
      "z": 7,
      "name": "Rock_Ice"
    },
    {
      "x": -28,
      "y": 56,
      "z": 7,
      "name": "Rock_Ice"
    },
    {
      "x": -28,
      "y": 57,
      "z": 7,
      "name": "Rock_Ice"
    },
    {
      "x": -28,
      "y": 58,
      "z": 7,
      "name": "Rock_Ice"
    },
    {
      "x": -28,
      "y": 59,
      "z": 7,
      "name": "Rock_Ice"
    },
    {
      "x": -28,
      "y": 60,
      "z": 7,
      "name": "Rock_Ice"
    },
    {
      "x": -28,
      "y": 61,
      "z": 7,
      "name": "Rock_Ice_Permafrost"
    },
    {
      "x": -28,
      "y": 62,
      "z": 7,
      "name": "Rock_Ice_Permafrost"
    },
    {
      "x": -28,
      "y": 63,
      "z": 7,
      "name": "Rock_Ice_Permafrost"
    },
    {
      "x": -28,
      "y": 64,
      "z": 7,
      "name": "Rock_Ice_Permafrost"
    },
    {
      "x": -28,
      "y": 65,
      "z": 7,
      "name": "Soil_Snow"
    },
    {
      "x": -28,
      "y": 56,
      "z": 8,
      "name": "Rock_Ice"
    },
    {
      "x": -28,
      "y": 57,
      "z": 8,
      "name": "Rock_Ice"
    },
    {
      "x": -28,
      "y": 58,
      "z": 8,
      "name": "Rock_Ice"
    },
    {
      "x": -28,
      "y": 59,
      "z": 8,
      "name": "Rock_Ice"
    },
    {
      "x": -28,
      "y": 60,
      "z": 8,
      "name": "Rock_Ice"
    },
    {
      "x": -28,
      "y": 61,
      "z": 8,
      "name": "Rock_Ice_Permafrost"
    },
    {
      "x": -28,
      "y": 62,
      "z": 8,
      "name": "Rock_Ice"
    },
    {
      "x": -28,
      "y": 63,
      "z": 8,
      "name": "Soil_Snow"
    },
    {
      "x": -27,
      "y": 54,
      "z": -16,
      "name": "Rock_Ice"
    },
    {
      "x": -27,
      "y": 55,
      "z": -16,
      "name": "Rock_Ice"
    },
    {
      "x": -27,
      "y": 56,
      "z": -16,
      "name": "Rock_Ice"
    },
    {
      "x": -27,
      "y": 57,
      "z": -16,
      "name": "Soil_Snow"
    },
    {
      "x": -27,
      "y": 53,
      "z": -15,
      "name": "Rock_Ice"
    },
    {
      "x": -27,
      "y": 54,
      "z": -15,
      "name": "Rock_Ice"
    },
    {
      "x": -27,
      "y": 55,
      "z": -15,
      "name": "Rock_Ice"
    },
    {
      "x": -27,
      "y": 56,
      "z": -15,
      "name": "Rock_Ice"
    },
    {
      "x": -27,
      "y": 57,
      "z": -15,
      "name": "Rock_Ice"
    },
    {
      "x": -27,
      "y": 58,
      "z": -15,
      "name": "Rock_Ice"
    },
    {
      "x": -27,
      "y": 59,
      "z": -15,
      "name": "Soil_Snow"
    },
    {
      "x": -27,
      "y": 52,
      "z": -14,
      "name": "Rock_Ice"
    },
    {
      "x": -27,
      "y": 53,
      "z": -14,
      "name": "Rock_Ice"
    },
    {
      "x": -27,
      "y": 54,
      "z": -14,
      "name": "Rock_Ice"
    },
    {
      "x": -27,
      "y": 55,
      "z": -14,
      "name": "Rock_Ice"
    },
    {
      "x": -27,
      "y": 56,
      "z": -14,
      "name": "Rock_Ice"
    },
    {
      "x": -27,
      "y": 57,
      "z": -14,
      "name": "Rock_Ice"
    },
    {
      "x": -27,
      "y": 58,
      "z": -14,
      "name": "Rock_Ice"
    },
    {
      "x": -27,
      "y": 59,
      "z": -14,
      "name": "Rock_Ice"
    },
    {
      "x": -27,
      "y": 60,
      "z": -14,
      "name": "Rock_Ice"
    },
    {
      "x": -27,
      "y": 61,
      "z": -14,
      "name": "Soil_Snow"
    },
    {
      "x": -27,
      "y": 51,
      "z": -13,
      "name": "Rock_Ice"
    },
    {
      "x": -27,
      "y": 52,
      "z": -13,
      "name": "Rock_Ice"
    },
    {
      "x": -27,
      "y": 53,
      "z": -13,
      "name": "Rock_Ice"
    },
    {
      "x": -27,
      "y": 54,
      "z": -13,
      "name": "Rock_Ice"
    },
    {
      "x": -27,
      "y": 55,
      "z": -13,
      "name": "Rock_Ice"
    },
    {
      "x": -27,
      "y": 56,
      "z": -13,
      "name": "Rock_Ice"
    },
    {
      "x": -27,
      "y": 57,
      "z": -13,
      "name": "Rock_Ice"
    },
    {
      "x": -27,
      "y": 58,
      "z": -13,
      "name": "Rock_Ice_Permafrost"
    },
    {
      "x": -27,
      "y": 59,
      "z": -13,
      "name": "Rock_Ice"
    },
    {
      "x": -27,
      "y": 60,
      "z": -13,
      "name": "Rock_Ice_Permafrost"
    },
    {
      "x": -27,
      "y": 61,
      "z": -13,
      "name": "Rock_Ice_Permafrost"
    },
    {
      "x": -27,
      "y": 62,
      "z": -13,
      "name": "Rock_Ice_Permafrost"
    },
    {
      "x": -27,
      "y": 63,
      "z": -13,
      "name": "Rock_Ice"
    },
    {
      "x": -27,
      "y": 64,
      "z": -13,
      "name": "Soil_Snow"
    },
    {
      "x": -27,
      "y": 51,
      "z": -12,
      "name": "Rock_Ice_Permafrost"
    },
    {
      "x": -27,
      "y": 52,
      "z": -12,
      "name": "Rock_Ice_Permafrost"
    },
    {
      "x": -27,
      "y": 53,
      "z": -12,
      "name": "Rock_Ice_Permafrost"
    },
    {
      "x": -27,
      "y": 54,
      "z": -12,
      "name": "Rock_Ice"
    },
    {
      "x": -27,
      "y": 55,
      "z": -12,
      "name": "Rock_Ice"
    },
    {
      "x": -27,
      "y": 56,
      "z": -12,
      "name": "Rock_Ice"
    },
    {
      "x": -27,
      "y": 57,
      "z": -12,
      "name": "Rock_Ice_Permafrost"
    },
    {
      "x": -27,
      "y": 58,
      "z": -12,
      "name": "Rock_Ice_Permafrost"
    },
    {
      "x": -27,
      "y": 59,
      "z": -12,
      "name": "Rock_Ice_Permafrost"
    },
    {
      "x": -27,
      "y": 60,
      "z": -12,
      "name": "Rock_Ice_Permafrost"
    },
    {
      "x": -27,
      "y": 61,
      "z": -12,
      "name": "Rock_Ice_Permafrost"
    },
    {
      "x": -27,
      "y": 62,
      "z": -12,
      "name": "Rock_Ice_Permafrost"
    },
    {
      "x": -27,
      "y": 63,
      "z": -12,
      "name": "Rock_Ice_Permafrost"
    },
    {
      "x": -27,
      "y": 64,
      "z": -12,
      "name": "Rock_Ice_Permafrost"
    },
    {
      "x": -27,
      "y": 65,
      "z": -12,
      "name": "Rock_Ice_Permafrost"
    },
    {
      "x": -27,
      "y": 66,
      "z": -12,
      "name": "Rock_Ice"
    },
    {
      "x": -27,
      "y": 67,
      "z": -12,
      "name": "Soil_Snow"
    },
    {
      "x": -27,
      "y": 52,
      "z": -11,
      "name": "Rock_Ice_Permafrost"
    },
    {
      "x": -27,
      "y": 53,
      "z": -11,
      "name": "Rock_Ice_Permafrost"
    },
    {
      "x": -27,
      "y": 54,
      "z": -11,
      "name": "Rock_Ice_Permafrost"
    },
    {
      "x": -27,
      "y": 55,
      "z": -11,
      "name": "Rock_Ice_Permafrost"
    },
    {
      "x": -27,
      "y": 56,
      "z": -11,
      "name": "Rock_Ice_Permafrost"
    },
    {
      "x": -27,
      "y": 57,
      "z": -11,
      "name": "Rock_Ice_Permafrost"
    },
    {
      "x": -27,
      "y": 58,
      "z": -11,
      "name": "Rock_Ice_Permafrost"
    },
    {
      "x": -27,
      "y": 59,
      "z": -11,
      "name": "Rock_Ice_Permafrost"
    },
    {
      "x": -27,
      "y": 60,
      "z": -11,
      "name": "Rock_Ice_Permafrost"
    },
    {
      "x": -27,
      "y": 61,
      "z": -11,
      "name": "Rock_Ice"
    },
    {
      "x": -27,
      "y": 62,
      "z": -11,
      "name": "Rock_Ice"
    },
    {
      "x": -27,
      "y": 63,
      "z": -11,
      "name": "Rock_Ice_Permafrost"
    },
    {
      "x": -27,
      "y": 64,
      "z": -11,
      "name": "Rock_Ice_Permafrost"
    },
    {
      "x": -27,
      "y": 65,
      "z": -11,
      "name": "Rock_Ice_Permafrost"
    },
    {
      "x": -27,
      "y": 66,
      "z": -11,
      "name": "Rock_Ice_Permafrost"
    },
    {
      "x": -27,
      "y": 67,
      "z": -11,
      "name": "Rock_Ice"
    },
    {
      "x": -27,
      "y": 68,
      "z": -11,
      "name": "Soil_Snow"
    },
    {
      "x": -27,
      "y": 52,
      "z": -10,
      "name": "Rock_Ice_Permafrost"
    },
    {
      "x": -27,
      "y": 53,
      "z": -10,
      "name": "Rock_Ice"
    },
    {
      "x": -27,
      "y": 54,
      "z": -10,
      "name": "Rock_Ice_Permafrost"
    },
    {
      "x": -27,
      "y": 55,
      "z": -10,
      "name": "Rock_Ice_Permafrost"
    },
    {
      "x": -27,
      "y": 56,
      "z": -10,
      "name": "Rock_Ice_Permafrost"
    },
    {
      "x": -27,
      "y": 57,
      "z": -10,
      "name": "Rock_Ice_Permafrost"
    },
    {
      "x": -27,
      "y": 58,
      "z": -10,
      "name": "Rock_Ice_Permafrost"
    },
    {
      "x": -27,
      "y": 59,
      "z": -10,
      "name": "Rock_Ice_Permafrost"
    },
    {
      "x": -27,
      "y": 60,
      "z": -10,
      "name": "Rock_Ice_Permafrost"
    },
    {
      "x": -27,
      "y": 61,
      "z": -10,
      "name": "Rock_Ice"
    },
    {
      "x": -27,
      "y": 62,
      "z": -10,
      "name": "Rock_Ice"
    },
    {
      "x": -27,
      "y": 63,
      "z": -10,
      "name": "Rock_Ice"
    },
    {
      "x": -27,
      "y": 64,
      "z": -10,
      "name": "Rock_Ice"
    },
    {
      "x": -27,
      "y": 65,
      "z": -10,
      "name": "Rock_Ice"
    },
    {
      "x": -27,
      "y": 66,
      "z": -10,
      "name": "Rock_Ice"
    },
    {
      "x": -27,
      "y": 67,
      "z": -10,
      "name": "Rock_Ice"
    },
    {
      "x": -27,
      "y": 68,
      "z": -10,
      "name": "Soil_Snow"
    },
    {
      "x": -27,
      "y": 49,
      "z": -9,
      "name": "Rock_Ice"
    },
    {
      "x": -27,
      "y": 50,
      "z": -9,
      "name": "Rock_Ice"
    },
    {
      "x": -27,
      "y": 51,
      "z": -9,
      "name": "Rock_Ice"
    },
    {
      "x": -27,
      "y": 52,
      "z": -9,
      "name": "Rock_Ice"
    },
    {
      "x": -27,
      "y": 53,
      "z": -9,
      "name": "Rock_Ice"
    },
    {
      "x": -27,
      "y": 54,
      "z": -9,
      "name": "Rock_Ice"
    },
    {
      "x": -27,
      "y": 55,
      "z": -9,
      "name": "Rock_Ice_Permafrost"
    },
    {
      "x": -27,
      "y": 56,
      "z": -9,
      "name": "Rock_Ice_Permafrost"
    },
    {
      "x": -27,
      "y": 57,
      "z": -9,
      "name": "Rock_Ice_Permafrost"
    },
    {
      "x": -27,
      "y": 58,
      "z": -9,
      "name": "Rock_Ice_Permafrost"
    },
    {
      "x": -27,
      "y": 59,
      "z": -9,
      "name": "Rock_Ice"
    },
    {
      "x": -27,
      "y": 60,
      "z": -9,
      "name": "Rock_Ice"
    },
    {
      "x": -27,
      "y": 61,
      "z": -9,
      "name": "Rock_Ice"
    },
    {
      "x": -27,
      "y": 62,
      "z": -9,
      "name": "Rock_Ice"
    },
    {
      "x": -27,
      "y": 63,
      "z": -9,
      "name": "Rock_Ice"
    },
    {
      "x": -27,
      "y": 64,
      "z": -9,
      "name": "Rock_Ice"
    },
    {
      "x": -27,
      "y": 65,
      "z": -9,
      "name": "Rock_Ice"
    },
    {
      "x": -27,
      "y": 66,
      "z": -9,
      "name": "Rock_Ice"
    },
    {
      "x": -27,
      "y": 67,
      "z": -9,
      "name": "Rock_Ice_Permafrost"
    },
    {
      "x": -27,
      "y": 68,
      "z": -9,
      "name": "Rock_Ice"
    },
    {
      "x": -27,
      "y": 69,
      "z": -9,
      "name": "Soil_Snow"
    },
    {
      "x": -27,
      "y": 49,
      "z": -8,
      "name": "Rock_Ice"
    },
    {
      "x": -27,
      "y": 50,
      "z": -8,
      "name": "Rock_Ice"
    },
    {
      "x": -27,
      "y": 51,
      "z": -8,
      "name": "Rock_Ice"
    },
    {
      "x": -27,
      "y": 52,
      "z": -8,
      "name": "Rock_Ice"
    },
    {
      "x": -27,
      "y": 53,
      "z": -8,
      "name": "Rock_Ice"
    },
    {
      "x": -27,
      "y": 54,
      "z": -8,
      "name": "Rock_Ice"
    },
    {
      "x": -27,
      "y": 55,
      "z": -8,
      "name": "Rock_Ice_Permafrost"
    },
    {
      "x": -27,
      "y": 56,
      "z": -8,
      "name": "Rock_Ice_Permafrost"
    },
    {
      "x": -27,
      "y": 57,
      "z": -8,
      "name": "Rock_Ice_Permafrost"
    },
    {
      "x": -27,
      "y": 58,
      "z": -8,
      "name": "Rock_Ice"
    },
    {
      "x": -27,
      "y": 59,
      "z": -8,
      "name": "Rock_Ice"
    },
    {
      "x": -27,
      "y": 60,
      "z": -8,
      "name": "Rock_Ice"
    },
    {
      "x": -27,
      "y": 61,
      "z": -8,
      "name": "Rock_Ice"
    },
    {
      "x": -27,
      "y": 62,
      "z": -8,
      "name": "Rock_Ice"
    },
    {
      "x": -27,
      "y": 63,
      "z": -8,
      "name": "Rock_Ice"
    },
    {
      "x": -27,
      "y": 64,
      "z": -8,
      "name": "Rock_Ice"
    },
    {
      "x": -27,
      "y": 65,
      "z": -8,
      "name": "Rock_Ice"
    },
    {
      "x": -27,
      "y": 66,
      "z": -8,
      "name": "Rock_Ice"
    },
    {
      "x": -27,
      "y": 67,
      "z": -8,
      "name": "Rock_Ice"
    },
    {
      "x": -27,
      "y": 68,
      "z": -8,
      "name": "Rock_Ice"
    },
    {
      "x": -27,
      "y": 69,
      "z": -8,
      "name": "Soil_Snow"
    },
    {
      "x": -27,
      "y": 48,
      "z": -7,
      "name": "Rock_Ice"
    },
    {
      "x": -27,
      "y": 49,
      "z": -7,
      "name": "Rock_Ice"
    },
    {
      "x": -27,
      "y": 50,
      "z": -7,
      "name": "Rock_Ice"
    },
    {
      "x": -27,
      "y": 51,
      "z": -7,
      "name": "Rock_Ice"
    },
    {
      "x": -27,
      "y": 52,
      "z": -7,
      "name": "Rock_Ice"
    },
    {
      "x": -27,
      "y": 53,
      "z": -7,
      "name": "Rock_Ice"
    },
    {
      "x": -27,
      "y": 54,
      "z": -7,
      "name": "Rock_Ice"
    },
    {
      "x": -27,
      "y": 55,
      "z": -7,
      "name": "Rock_Ice"
    },
    {
      "x": -27,
      "y": 56,
      "z": -7,
      "name": "Rock_Ice_Permafrost"
    },
    {
      "x": -27,
      "y": 57,
      "z": -7,
      "name": "Rock_Ice_Permafrost"
    },
    {
      "x": -27,
      "y": 58,
      "z": -7,
      "name": "Rock_Ice"
    },
    {
      "x": -27,
      "y": 59,
      "z": -7,
      "name": "Rock_Ice"
    },
    {
      "x": -27,
      "y": 60,
      "z": -7,
      "name": "Rock_Ice"
    },
    {
      "x": -27,
      "y": 61,
      "z": -7,
      "name": "Rock_Ice"
    },
    {
      "x": -27,
      "y": 62,
      "z": -7,
      "name": "Rock_Ice"
    },
    {
      "x": -27,
      "y": 63,
      "z": -7,
      "name": "Rock_Ice"
    },
    {
      "x": -27,
      "y": 64,
      "z": -7,
      "name": "Rock_Ice"
    },
    {
      "x": -27,
      "y": 65,
      "z": -7,
      "name": "Rock_Ice"
    },
    {
      "x": -27,
      "y": 66,
      "z": -7,
      "name": "Rock_Ice"
    },
    {
      "x": -27,
      "y": 67,
      "z": -7,
      "name": "Rock_Ice"
    },
    {
      "x": -27,
      "y": 68,
      "z": -7,
      "name": "Rock_Ice"
    },
    {
      "x": -27,
      "y": 69,
      "z": -7,
      "name": "Soil_Snow"
    },
    {
      "x": -27,
      "y": 47,
      "z": -6,
      "name": "Rock_Ice"
    },
    {
      "x": -27,
      "y": 48,
      "z": -6,
      "name": "Rock_Ice"
    },
    {
      "x": -27,
      "y": 49,
      "z": -6,
      "name": "Rock_Ice"
    },
    {
      "x": -27,
      "y": 50,
      "z": -6,
      "name": "Rock_Ice"
    },
    {
      "x": -27,
      "y": 51,
      "z": -6,
      "name": "Rock_Ice"
    },
    {
      "x": -27,
      "y": 52,
      "z": -6,
      "name": "Rock_Ice"
    },
    {
      "x": -27,
      "y": 53,
      "z": -6,
      "name": "Rock_Ice"
    },
    {
      "x": -27,
      "y": 54,
      "z": -6,
      "name": "Rock_Ice"
    },
    {
      "x": -27,
      "y": 55,
      "z": -6,
      "name": "Rock_Ice_Permafrost"
    },
    {
      "x": -27,
      "y": 56,
      "z": -6,
      "name": "Rock_Ice_Permafrost"
    },
    {
      "x": -27,
      "y": 57,
      "z": -6,
      "name": "Rock_Ice_Permafrost"
    },
    {
      "x": -27,
      "y": 58,
      "z": -6,
      "name": "Rock_Ice"
    },
    {
      "x": -27,
      "y": 59,
      "z": -6,
      "name": "Rock_Ice"
    },
    {
      "x": -27,
      "y": 60,
      "z": -6,
      "name": "Rock_Ice"
    },
    {
      "x": -27,
      "y": 61,
      "z": -6,
      "name": "Rock_Ice"
    },
    {
      "x": -27,
      "y": 62,
      "z": -6,
      "name": "Rock_Ice"
    },
    {
      "x": -27,
      "y": 63,
      "z": -6,
      "name": "Rock_Ice"
    },
    {
      "x": -27,
      "y": 64,
      "z": -6,
      "name": "Rock_Ice"
    },
    {
      "x": -27,
      "y": 65,
      "z": -6,
      "name": "Rock_Ice"
    },
    {
      "x": -27,
      "y": 66,
      "z": -6,
      "name": "Rock_Ice"
    },
    {
      "x": -27,
      "y": 67,
      "z": -6,
      "name": "Rock_Ice"
    },
    {
      "x": -27,
      "y": 68,
      "z": -6,
      "name": "Soil_Snow"
    },
    {
      "x": -27,
      "y": 47,
      "z": -5,
      "name": "Rock_Ice"
    },
    {
      "x": -27,
      "y": 48,
      "z": -5,
      "name": "Rock_Ice"
    },
    {
      "x": -27,
      "y": 49,
      "z": -5,
      "name": "Rock_Ice"
    },
    {
      "x": -27,
      "y": 50,
      "z": -5,
      "name": "Rock_Ice"
    },
    {
      "x": -27,
      "y": 51,
      "z": -5,
      "name": "Rock_Ice"
    },
    {
      "x": -27,
      "y": 52,
      "z": -5,
      "name": "Rock_Ice"
    },
    {
      "x": -27,
      "y": 53,
      "z": -5,
      "name": "Rock_Ice"
    },
    {
      "x": -27,
      "y": 54,
      "z": -5,
      "name": "Rock_Ice"
    },
    {
      "x": -27,
      "y": 55,
      "z": -5,
      "name": "Rock_Ice_Permafrost"
    },
    {
      "x": -27,
      "y": 56,
      "z": -5,
      "name": "Rock_Ice_Permafrost"
    },
    {
      "x": -27,
      "y": 57,
      "z": -5,
      "name": "Rock_Ice_Permafrost"
    },
    {
      "x": -27,
      "y": 58,
      "z": -5,
      "name": "Rock_Ice_Permafrost"
    },
    {
      "x": -27,
      "y": 59,
      "z": -5,
      "name": "Rock_Ice"
    },
    {
      "x": -27,
      "y": 60,
      "z": -5,
      "name": "Rock_Ice"
    },
    {
      "x": -27,
      "y": 61,
      "z": -5,
      "name": "Rock_Ice"
    },
    {
      "x": -27,
      "y": 62,
      "z": -5,
      "name": "Rock_Ice"
    },
    {
      "x": -27,
      "y": 63,
      "z": -5,
      "name": "Rock_Ice"
    },
    {
      "x": -27,
      "y": 64,
      "z": -5,
      "name": "Rock_Ice"
    },
    {
      "x": -27,
      "y": 65,
      "z": -5,
      "name": "Rock_Ice"
    },
    {
      "x": -27,
      "y": 66,
      "z": -5,
      "name": "Rock_Ice"
    },
    {
      "x": -27,
      "y": 67,
      "z": -5,
      "name": "Rock_Ice"
    },
    {
      "x": -27,
      "y": 68,
      "z": -5,
      "name": "Rock_Ice"
    },
    {
      "x": -27,
      "y": 69,
      "z": -5,
      "name": "Soil_Snow"
    },
    {
      "x": -27,
      "y": 49,
      "z": -4,
      "name": "Rock_Ice"
    },
    {
      "x": -27,
      "y": 50,
      "z": -4,
      "name": "Rock_Ice"
    },
    {
      "x": -27,
      "y": 51,
      "z": -4,
      "name": "Rock_Ice"
    },
    {
      "x": -27,
      "y": 52,
      "z": -4,
      "name": "Rock_Ice"
    },
    {
      "x": -27,
      "y": 53,
      "z": -4,
      "name": "Rock_Ice"
    },
    {
      "x": -27,
      "y": 54,
      "z": -4,
      "name": "Rock_Ice"
    },
    {
      "x": -27,
      "y": 55,
      "z": -4,
      "name": "Rock_Ice_Permafrost"
    },
    {
      "x": -27,
      "y": 56,
      "z": -4,
      "name": "Rock_Ice_Permafrost"
    },
    {
      "x": -27,
      "y": 57,
      "z": -4,
      "name": "Rock_Ice_Permafrost"
    },
    {
      "x": -27,
      "y": 58,
      "z": -4,
      "name": "Rock_Ice_Permafrost"
    },
    {
      "x": -27,
      "y": 59,
      "z": -4,
      "name": "Rock_Ice"
    },
    {
      "x": -27,
      "y": 60,
      "z": -4,
      "name": "Rock_Ice"
    },
    {
      "x": -27,
      "y": 61,
      "z": -4,
      "name": "Rock_Ice"
    },
    {
      "x": -27,
      "y": 62,
      "z": -4,
      "name": "Rock_Ice"
    },
    {
      "x": -27,
      "y": 63,
      "z": -4,
      "name": "Rock_Ice"
    },
    {
      "x": -27,
      "y": 64,
      "z": -4,
      "name": "Rock_Ice"
    },
    {
      "x": -27,
      "y": 65,
      "z": -4,
      "name": "Rock_Ice"
    },
    {
      "x": -27,
      "y": 66,
      "z": -4,
      "name": "Rock_Ice"
    },
    {
      "x": -27,
      "y": 67,
      "z": -4,
      "name": "Rock_Ice"
    },
    {
      "x": -27,
      "y": 68,
      "z": -4,
      "name": "Rock_Ice"
    },
    {
      "x": -27,
      "y": 69,
      "z": -4,
      "name": "Soil_Snow"
    },
    {
      "x": -27,
      "y": 51,
      "z": -3,
      "name": "Rock_Ice"
    },
    {
      "x": -27,
      "y": 52,
      "z": -3,
      "name": "Rock_Ice"
    },
    {
      "x": -27,
      "y": 53,
      "z": -3,
      "name": "Rock_Ice"
    },
    {
      "x": -27,
      "y": 54,
      "z": -3,
      "name": "Rock_Ice_Permafrost"
    },
    {
      "x": -27,
      "y": 55,
      "z": -3,
      "name": "Rock_Ice_Permafrost"
    },
    {
      "x": -27,
      "y": 56,
      "z": -3,
      "name": "Rock_Ice_Permafrost"
    },
    {
      "x": -27,
      "y": 57,
      "z": -3,
      "name": "Rock_Ice_Permafrost"
    },
    {
      "x": -27,
      "y": 58,
      "z": -3,
      "name": "Rock_Ice"
    },
    {
      "x": -27,
      "y": 59,
      "z": -3,
      "name": "Rock_Ice"
    },
    {
      "x": -27,
      "y": 60,
      "z": -3,
      "name": "Rock_Ice"
    },
    {
      "x": -27,
      "y": 61,
      "z": -3,
      "name": "Rock_Ice"
    },
    {
      "x": -27,
      "y": 62,
      "z": -3,
      "name": "Rock_Ice"
    },
    {
      "x": -27,
      "y": 63,
      "z": -3,
      "name": "Rock_Ice"
    },
    {
      "x": -27,
      "y": 64,
      "z": -3,
      "name": "Rock_Ice"
    },
    {
      "x": -27,
      "y": 65,
      "z": -3,
      "name": "Rock_Ice"
    },
    {
      "x": -27,
      "y": 66,
      "z": -3,
      "name": "Rock_Ice"
    },
    {
      "x": -27,
      "y": 67,
      "z": -3,
      "name": "Rock_Ice"
    },
    {
      "x": -27,
      "y": 68,
      "z": -3,
      "name": "Soil_Snow"
    },
    {
      "x": -27,
      "y": 52,
      "z": -2,
      "name": "Rock_Ice"
    },
    {
      "x": -27,
      "y": 53,
      "z": -2,
      "name": "Rock_Ice_Permafrost"
    },
    {
      "x": -27,
      "y": 54,
      "z": -2,
      "name": "Rock_Ice_Permafrost"
    },
    {
      "x": -27,
      "y": 55,
      "z": -2,
      "name": "Rock_Ice_Permafrost"
    },
    {
      "x": -27,
      "y": 56,
      "z": -2,
      "name": "Rock_Ice_Permafrost"
    },
    {
      "x": -27,
      "y": 57,
      "z": -2,
      "name": "Rock_Ice_Permafrost"
    },
    {
      "x": -27,
      "y": 58,
      "z": -2,
      "name": "Rock_Ice"
    },
    {
      "x": -27,
      "y": 59,
      "z": -2,
      "name": "Rock_Ice"
    },
    {
      "x": -27,
      "y": 60,
      "z": -2,
      "name": "Rock_Ice"
    },
    {
      "x": -27,
      "y": 61,
      "z": -2,
      "name": "Rock_Ice"
    },
    {
      "x": -27,
      "y": 62,
      "z": -2,
      "name": "Rock_Ice"
    },
    {
      "x": -27,
      "y": 63,
      "z": -2,
      "name": "Rock_Ice"
    },
    {
      "x": -27,
      "y": 64,
      "z": -2,
      "name": "Rock_Ice"
    },
    {
      "x": -27,
      "y": 65,
      "z": -2,
      "name": "Rock_Ice"
    },
    {
      "x": -27,
      "y": 66,
      "z": -2,
      "name": "Rock_Ice"
    },
    {
      "x": -27,
      "y": 67,
      "z": -2,
      "name": "Soil_Snow"
    },
    {
      "x": -27,
      "y": 52,
      "z": -1,
      "name": "Rock_Ice_Permafrost"
    },
    {
      "x": -27,
      "y": 53,
      "z": -1,
      "name": "Rock_Ice_Permafrost"
    },
    {
      "x": -27,
      "y": 54,
      "z": -1,
      "name": "Rock_Ice_Permafrost"
    },
    {
      "x": -27,
      "y": 55,
      "z": -1,
      "name": "Rock_Ice_Permafrost"
    },
    {
      "x": -27,
      "y": 56,
      "z": -1,
      "name": "Rock_Ice_Permafrost"
    },
    {
      "x": -27,
      "y": 57,
      "z": -1,
      "name": "Rock_Ice_Permafrost"
    },
    {
      "x": -27,
      "y": 58,
      "z": -1,
      "name": "Rock_Ice"
    },
    {
      "x": -27,
      "y": 59,
      "z": -1,
      "name": "Rock_Ice"
    },
    {
      "x": -27,
      "y": 60,
      "z": -1,
      "name": "Rock_Ice"
    },
    {
      "x": -27,
      "y": 61,
      "z": -1,
      "name": "Rock_Ice"
    },
    {
      "x": -27,
      "y": 62,
      "z": -1,
      "name": "Rock_Ice"
    },
    {
      "x": -27,
      "y": 63,
      "z": -1,
      "name": "Rock_Ice"
    },
    {
      "x": -27,
      "y": 64,
      "z": -1,
      "name": "Rock_Ice"
    },
    {
      "x": -27,
      "y": 65,
      "z": -1,
      "name": "Rock_Ice"
    },
    {
      "x": -27,
      "y": 66,
      "z": -1,
      "name": "Rock_Ice"
    },
    {
      "x": -27,
      "y": 67,
      "z": -1,
      "name": "Soil_Snow"
    },
    {
      "x": -27,
      "y": 53,
      "z": 0,
      "name": "Rock_Ice_Permafrost"
    },
    {
      "x": -27,
      "y": 54,
      "z": 0,
      "name": "Rock_Ice_Permafrost"
    },
    {
      "x": -27,
      "y": 55,
      "z": 0,
      "name": "Rock_Ice_Permafrost"
    },
    {
      "x": -27,
      "y": 56,
      "z": 0,
      "name": "Rock_Ice_Permafrost"
    },
    {
      "x": -27,
      "y": 57,
      "z": 0,
      "name": "Rock_Ice_Permafrost"
    },
    {
      "x": -27,
      "y": 58,
      "z": 0,
      "name": "Rock_Ice"
    },
    {
      "x": -27,
      "y": 59,
      "z": 0,
      "name": "Rock_Ice"
    },
    {
      "x": -27,
      "y": 60,
      "z": 0,
      "name": "Rock_Ice"
    },
    {
      "x": -27,
      "y": 61,
      "z": 0,
      "name": "Rock_Ice"
    },
    {
      "x": -27,
      "y": 62,
      "z": 0,
      "name": "Rock_Ice"
    },
    {
      "x": -27,
      "y": 63,
      "z": 0,
      "name": "Rock_Ice"
    },
    {
      "x": -27,
      "y": 64,
      "z": 0,
      "name": "Rock_Ice"
    },
    {
      "x": -27,
      "y": 65,
      "z": 0,
      "name": "Rock_Ice"
    },
    {
      "x": -27,
      "y": 66,
      "z": 0,
      "name": "Rock_Ice"
    },
    {
      "x": -27,
      "y": 67,
      "z": 0,
      "name": "Soil_Snow"
    },
    {
      "x": -27,
      "y": 53,
      "z": 1,
      "name": "Rock_Ice_Permafrost"
    },
    {
      "x": -27,
      "y": 54,
      "z": 1,
      "name": "Rock_Ice_Permafrost"
    },
    {
      "x": -27,
      "y": 55,
      "z": 1,
      "name": "Rock_Ice_Permafrost"
    },
    {
      "x": -27,
      "y": 56,
      "z": 1,
      "name": "Rock_Ice_Permafrost"
    },
    {
      "x": -27,
      "y": 57,
      "z": 1,
      "name": "Rock_Ice"
    },
    {
      "x": -27,
      "y": 58,
      "z": 1,
      "name": "Rock_Ice"
    },
    {
      "x": -27,
      "y": 59,
      "z": 1,
      "name": "Rock_Ice"
    },
    {
      "x": -27,
      "y": 60,
      "z": 1,
      "name": "Rock_Ice"
    },
    {
      "x": -27,
      "y": 61,
      "z": 1,
      "name": "Rock_Ice"
    },
    {
      "x": -27,
      "y": 62,
      "z": 1,
      "name": "Rock_Ice"
    },
    {
      "x": -27,
      "y": 63,
      "z": 1,
      "name": "Rock_Ice"
    },
    {
      "x": -27,
      "y": 64,
      "z": 1,
      "name": "Rock_Ice"
    },
    {
      "x": -27,
      "y": 65,
      "z": 1,
      "name": "Rock_Ice"
    },
    {
      "x": -27,
      "y": 66,
      "z": 1,
      "name": "Soil_Snow"
    },
    {
      "x": -27,
      "y": 53,
      "z": 2,
      "name": "Rock_Ice_Permafrost"
    },
    {
      "x": -27,
      "y": 54,
      "z": 2,
      "name": "Rock_Ice_Permafrost"
    },
    {
      "x": -27,
      "y": 55,
      "z": 2,
      "name": "Rock_Ice_Permafrost"
    },
    {
      "x": -27,
      "y": 56,
      "z": 2,
      "name": "Rock_Ice_Permafrost"
    },
    {
      "x": -27,
      "y": 57,
      "z": 2,
      "name": "Rock_Ice_Permafrost"
    },
    {
      "x": -27,
      "y": 58,
      "z": 2,
      "name": "Rock_Ice_Permafrost"
    },
    {
      "x": -27,
      "y": 59,
      "z": 2,
      "name": "Rock_Ice"
    },
    {
      "x": -27,
      "y": 60,
      "z": 2,
      "name": "Rock_Ice"
    },
    {
      "x": -27,
      "y": 61,
      "z": 2,
      "name": "Rock_Ice"
    },
    {
      "x": -27,
      "y": 62,
      "z": 2,
      "name": "Rock_Ice"
    },
    {
      "x": -27,
      "y": 63,
      "z": 2,
      "name": "Rock_Ice"
    },
    {
      "x": -27,
      "y": 64,
      "z": 2,
      "name": "Rock_Ice"
    },
    {
      "x": -27,
      "y": 65,
      "z": 2,
      "name": "Rock_Ice"
    },
    {
      "x": -27,
      "y": 66,
      "z": 2,
      "name": "Soil_Snow"
    },
    {
      "x": -27,
      "y": 53,
      "z": 3,
      "name": "Rock_Ice"
    },
    {
      "x": -27,
      "y": 54,
      "z": 3,
      "name": "Rock_Ice_Permafrost"
    },
    {
      "x": -27,
      "y": 55,
      "z": 3,
      "name": "Rock_Ice_Permafrost"
    },
    {
      "x": -27,
      "y": 56,
      "z": 3,
      "name": "Rock_Ice_Permafrost"
    },
    {
      "x": -27,
      "y": 57,
      "z": 3,
      "name": "Rock_Ice_Permafrost"
    },
    {
      "x": -27,
      "y": 58,
      "z": 3,
      "name": "Rock_Ice_Permafrost"
    },
    {
      "x": -27,
      "y": 59,
      "z": 3,
      "name": "Rock_Ice"
    },
    {
      "x": -27,
      "y": 60,
      "z": 3,
      "name": "Rock_Ice"
    },
    {
      "x": -27,
      "y": 61,
      "z": 3,
      "name": "Rock_Ice"
    },
    {
      "x": -27,
      "y": 62,
      "z": 3,
      "name": "Rock_Ice"
    },
    {
      "x": -27,
      "y": 63,
      "z": 3,
      "name": "Rock_Ice"
    },
    {
      "x": -27,
      "y": 64,
      "z": 3,
      "name": "Rock_Ice"
    },
    {
      "x": -27,
      "y": 65,
      "z": 3,
      "name": "Rock_Ice"
    },
    {
      "x": -27,
      "y": 66,
      "z": 3,
      "name": "Soil_Snow"
    },
    {
      "x": -27,
      "y": 52,
      "z": 4,
      "name": "Rock_Ice"
    },
    {
      "x": -27,
      "y": 53,
      "z": 4,
      "name": "Rock_Ice"
    },
    {
      "x": -27,
      "y": 54,
      "z": 4,
      "name": "Rock_Ice"
    },
    {
      "x": -27,
      "y": 55,
      "z": 4,
      "name": "Rock_Ice"
    },
    {
      "x": -27,
      "y": 56,
      "z": 4,
      "name": "Rock_Ice"
    },
    {
      "x": -27,
      "y": 57,
      "z": 4,
      "name": "Rock_Ice_Permafrost"
    },
    {
      "x": -27,
      "y": 58,
      "z": 4,
      "name": "Rock_Ice_Permafrost"
    },
    {
      "x": -27,
      "y": 59,
      "z": 4,
      "name": "Rock_Ice_Permafrost"
    },
    {
      "x": -27,
      "y": 60,
      "z": 4,
      "name": "Rock_Ice_Permafrost"
    },
    {
      "x": -27,
      "y": 61,
      "z": 4,
      "name": "Rock_Ice_Permafrost"
    },
    {
      "x": -27,
      "y": 62,
      "z": 4,
      "name": "Rock_Ice"
    },
    {
      "x": -27,
      "y": 63,
      "z": 4,
      "name": "Rock_Ice"
    },
    {
      "x": -27,
      "y": 64,
      "z": 4,
      "name": "Rock_Ice"
    },
    {
      "x": -27,
      "y": 65,
      "z": 4,
      "name": "Rock_Ice"
    },
    {
      "x": -27,
      "y": 66,
      "z": 4,
      "name": "Soil_Snow"
    },
    {
      "x": -27,
      "y": 51,
      "z": 5,
      "name": "Rock_Ice"
    },
    {
      "x": -27,
      "y": 52,
      "z": 5,
      "name": "Rock_Ice"
    },
    {
      "x": -27,
      "y": 53,
      "z": 5,
      "name": "Rock_Ice"
    },
    {
      "x": -27,
      "y": 54,
      "z": 5,
      "name": "Rock_Ice"
    },
    {
      "x": -27,
      "y": 55,
      "z": 5,
      "name": "Rock_Ice"
    },
    {
      "x": -27,
      "y": 56,
      "z": 5,
      "name": "Rock_Ice"
    },
    {
      "x": -27,
      "y": 57,
      "z": 5,
      "name": "Rock_Ice"
    },
    {
      "x": -27,
      "y": 58,
      "z": 5,
      "name": "Rock_Ice_Permafrost"
    },
    {
      "x": -27,
      "y": 59,
      "z": 5,
      "name": "Rock_Ice_Permafrost"
    },
    {
      "x": -27,
      "y": 60,
      "z": 5,
      "name": "Rock_Ice_Permafrost"
    },
    {
      "x": -27,
      "y": 61,
      "z": 5,
      "name": "Rock_Ice_Permafrost"
    },
    {
      "x": -27,
      "y": 62,
      "z": 5,
      "name": "Rock_Ice_Permafrost"
    },
    {
      "x": -27,
      "y": 63,
      "z": 5,
      "name": "Rock_Ice"
    },
    {
      "x": -27,
      "y": 64,
      "z": 5,
      "name": "Rock_Ice"
    },
    {
      "x": -27,
      "y": 65,
      "z": 5,
      "name": "Rock_Ice"
    },
    {
      "x": -27,
      "y": 66,
      "z": 5,
      "name": "Soil_Snow"
    },
    {
      "x": -27,
      "y": 50,
      "z": 6,
      "name": "Rock_Ice"
    },
    {
      "x": -27,
      "y": 51,
      "z": 6,
      "name": "Rock_Ice"
    },
    {
      "x": -27,
      "y": 52,
      "z": 6,
      "name": "Rock_Ice"
    },
    {
      "x": -27,
      "y": 53,
      "z": 6,
      "name": "Rock_Ice"
    },
    {
      "x": -27,
      "y": 54,
      "z": 6,
      "name": "Rock_Ice"
    },
    {
      "x": -27,
      "y": 55,
      "z": 6,
      "name": "Rock_Ice"
    },
    {
      "x": -27,
      "y": 56,
      "z": 6,
      "name": "Rock_Ice"
    },
    {
      "x": -27,
      "y": 57,
      "z": 6,
      "name": "Rock_Ice"
    },
    {
      "x": -27,
      "y": 58,
      "z": 6,
      "name": "Rock_Ice"
    },
    {
      "x": -27,
      "y": 59,
      "z": 6,
      "name": "Rock_Ice_Permafrost"
    },
    {
      "x": -27,
      "y": 60,
      "z": 6,
      "name": "Rock_Ice_Permafrost"
    },
    {
      "x": -27,
      "y": 61,
      "z": 6,
      "name": "Rock_Ice_Permafrost"
    },
    {
      "x": -27,
      "y": 62,
      "z": 6,
      "name": "Rock_Ice_Permafrost"
    },
    {
      "x": -27,
      "y": 63,
      "z": 6,
      "name": "Rock_Ice_Permafrost"
    },
    {
      "x": -27,
      "y": 64,
      "z": 6,
      "name": "Rock_Ice"
    },
    {
      "x": -27,
      "y": 65,
      "z": 6,
      "name": "Rock_Ice"
    },
    {
      "x": -27,
      "y": 66,
      "z": 6,
      "name": "Soil_Snow"
    },
    {
      "x": -27,
      "y": 55,
      "z": 7,
      "name": "Rock_Ice"
    },
    {
      "x": -27,
      "y": 56,
      "z": 7,
      "name": "Rock_Ice"
    },
    {
      "x": -27,
      "y": 57,
      "z": 7,
      "name": "Rock_Ice"
    },
    {
      "x": -27,
      "y": 58,
      "z": 7,
      "name": "Rock_Ice"
    },
    {
      "x": -27,
      "y": 59,
      "z": 7,
      "name": "Rock_Ice"
    },
    {
      "x": -27,
      "y": 60,
      "z": 7,
      "name": "Rock_Ice"
    },
    {
      "x": -27,
      "y": 61,
      "z": 7,
      "name": "Rock_Ice_Permafrost"
    },
    {
      "x": -27,
      "y": 62,
      "z": 7,
      "name": "Rock_Ice_Permafrost"
    },
    {
      "x": -27,
      "y": 63,
      "z": 7,
      "name": "Rock_Ice_Permafrost"
    },
    {
      "x": -27,
      "y": 64,
      "z": 7,
      "name": "Rock_Ice"
    },
    {
      "x": -27,
      "y": 65,
      "z": 7,
      "name": "Soil_Snow"
    },
    {
      "x": -27,
      "y": 59,
      "z": 8,
      "name": "Rock_Ice"
    },
    {
      "x": -27,
      "y": 60,
      "z": 8,
      "name": "Rock_Ice"
    },
    {
      "x": -27,
      "y": 61,
      "z": 8,
      "name": "Rock_Ice_Permafrost"
    },
    {
      "x": -27,
      "y": 62,
      "z": 8,
      "name": "Soil_Snow"
    },
    {
      "x": -26,
      "y": 52,
      "z": -17,
      "name": "Rock_Ice"
    },
    {
      "x": -26,
      "y": 53,
      "z": -17,
      "name": "Rock_Ice"
    },
    {
      "x": -26,
      "y": 54,
      "z": -17,
      "name": "Soil_Snow"
    },
    {
      "x": -26,
      "y": 51,
      "z": -16,
      "name": "Rock_Ice"
    },
    {
      "x": -26,
      "y": 52,
      "z": -16,
      "name": "Rock_Ice"
    },
    {
      "x": -26,
      "y": 53,
      "z": -16,
      "name": "Rock_Ice"
    },
    {
      "x": -26,
      "y": 54,
      "z": -16,
      "name": "Rock_Ice"
    },
    {
      "x": -26,
      "y": 55,
      "z": -16,
      "name": "Rock_Ice"
    },
    {
      "x": -26,
      "y": 56,
      "z": -16,
      "name": "Soil_Snow"
    },
    {
      "x": -26,
      "y": 50,
      "z": -15,
      "name": "Rock_Ice"
    },
    {
      "x": -26,
      "y": 51,
      "z": -15,
      "name": "Rock_Ice"
    },
    {
      "x": -26,
      "y": 52,
      "z": -15,
      "name": "Rock_Ice"
    },
    {
      "x": -26,
      "y": 53,
      "z": -15,
      "name": "Rock_Ice"
    },
    {
      "x": -26,
      "y": 54,
      "z": -15,
      "name": "Rock_Ice"
    },
    {
      "x": -26,
      "y": 55,
      "z": -15,
      "name": "Rock_Ice"
    },
    {
      "x": -26,
      "y": 56,
      "z": -15,
      "name": "Rock_Ice"
    },
    {
      "x": -26,
      "y": 57,
      "z": -15,
      "name": "Rock_Ice"
    },
    {
      "x": -26,
      "y": 58,
      "z": -15,
      "name": "Soil_Snow"
    },
    {
      "x": -26,
      "y": 49,
      "z": -14,
      "name": "Rock_Ice"
    },
    {
      "x": -26,
      "y": 50,
      "z": -14,
      "name": "Rock_Ice"
    },
    {
      "x": -26,
      "y": 51,
      "z": -14,
      "name": "Rock_Ice"
    },
    {
      "x": -26,
      "y": 52,
      "z": -14,
      "name": "Rock_Ice"
    },
    {
      "x": -26,
      "y": 53,
      "z": -14,
      "name": "Rock_Ice"
    },
    {
      "x": -26,
      "y": 54,
      "z": -14,
      "name": "Rock_Ice"
    },
    {
      "x": -26,
      "y": 55,
      "z": -14,
      "name": "Rock_Ice"
    },
    {
      "x": -26,
      "y": 56,
      "z": -14,
      "name": "Rock_Ice"
    },
    {
      "x": -26,
      "y": 57,
      "z": -14,
      "name": "Rock_Ice"
    },
    {
      "x": -26,
      "y": 58,
      "z": -14,
      "name": "Rock_Ice"
    },
    {
      "x": -26,
      "y": 59,
      "z": -14,
      "name": "Rock_Ice"
    },
    {
      "x": -26,
      "y": 60,
      "z": -14,
      "name": "Rock_Ice"
    },
    {
      "x": -26,
      "y": 61,
      "z": -14,
      "name": "Soil_Snow"
    },
    {
      "x": -26,
      "y": 48,
      "z": -13,
      "name": "Rock_Ice"
    },
    {
      "x": -26,
      "y": 49,
      "z": -13,
      "name": "Rock_Ice"
    },
    {
      "x": -26,
      "y": 50,
      "z": -13,
      "name": "Rock_Ice"
    },
    {
      "x": -26,
      "y": 51,
      "z": -13,
      "name": "Rock_Ice"
    },
    {
      "x": -26,
      "y": 52,
      "z": -13,
      "name": "Rock_Ice"
    },
    {
      "x": -26,
      "y": 53,
      "z": -13,
      "name": "Rock_Ice"
    },
    {
      "x": -26,
      "y": 54,
      "z": -13,
      "name": "Rock_Ice"
    },
    {
      "x": -26,
      "y": 55,
      "z": -13,
      "name": "Rock_Ice"
    },
    {
      "x": -26,
      "y": 56,
      "z": -13,
      "name": "Rock_Ice"
    },
    {
      "x": -26,
      "y": 57,
      "z": -13,
      "name": "Rock_Ice"
    },
    {
      "x": -26,
      "y": 58,
      "z": -13,
      "name": "Rock_Ice"
    },
    {
      "x": -26,
      "y": 59,
      "z": -13,
      "name": "Rock_Ice_Permafrost"
    },
    {
      "x": -26,
      "y": 60,
      "z": -13,
      "name": "Rock_Ice_Permafrost"
    },
    {
      "x": -26,
      "y": 61,
      "z": -13,
      "name": "Rock_Ice_Permafrost"
    },
    {
      "x": -26,
      "y": 62,
      "z": -13,
      "name": "Rock_Ice_Permafrost"
    },
    {
      "x": -26,
      "y": 63,
      "z": -13,
      "name": "Rock_Ice"
    },
    {
      "x": -26,
      "y": 64,
      "z": -13,
      "name": "Soil_Snow"
    },
    {
      "x": -26,
      "y": 49,
      "z": -12,
      "name": "Rock_Ice"
    },
    {
      "x": -26,
      "y": 50,
      "z": -12,
      "name": "Rock_Ice_Permafrost"
    },
    {
      "x": -26,
      "y": 51,
      "z": -12,
      "name": "Rock_Ice"
    },
    {
      "x": -26,
      "y": 52,
      "z": -12,
      "name": "Rock_Ice"
    },
    {
      "x": -26,
      "y": 53,
      "z": -12,
      "name": "Rock_Ice"
    },
    {
      "x": -26,
      "y": 54,
      "z": -12,
      "name": "Rock_Ice"
    },
    {
      "x": -26,
      "y": 55,
      "z": -12,
      "name": "Rock_Ice"
    },
    {
      "x": -26,
      "y": 56,
      "z": -12,
      "name": "Rock_Ice"
    },
    {
      "x": -26,
      "y": 57,
      "z": -12,
      "name": "Rock_Ice"
    },
    {
      "x": -26,
      "y": 58,
      "z": -12,
      "name": "Rock_Ice"
    },
    {
      "x": -26,
      "y": 59,
      "z": -12,
      "name": "Rock_Ice_Permafrost"
    },
    {
      "x": -26,
      "y": 60,
      "z": -12,
      "name": "Rock_Ice_Permafrost"
    },
    {
      "x": -26,
      "y": 61,
      "z": -12,
      "name": "Rock_Ice_Permafrost"
    },
    {
      "x": -26,
      "y": 62,
      "z": -12,
      "name": "Rock_Ice_Permafrost"
    },
    {
      "x": -26,
      "y": 63,
      "z": -12,
      "name": "Rock_Ice_Permafrost"
    },
    {
      "x": -26,
      "y": 64,
      "z": -12,
      "name": "Rock_Ice_Permafrost"
    },
    {
      "x": -26,
      "y": 65,
      "z": -12,
      "name": "Rock_Ice_Permafrost"
    },
    {
      "x": -26,
      "y": 66,
      "z": -12,
      "name": "Rock_Ice"
    },
    {
      "x": -26,
      "y": 67,
      "z": -12,
      "name": "Soil_Snow"
    },
    {
      "x": -26,
      "y": 50,
      "z": -11,
      "name": "Rock_Ice_Permafrost"
    },
    {
      "x": -26,
      "y": 51,
      "z": -11,
      "name": "Rock_Ice_Permafrost"
    },
    {
      "x": -26,
      "y": 52,
      "z": -11,
      "name": "Rock_Ice_Permafrost"
    },
    {
      "x": -26,
      "y": 53,
      "z": -11,
      "name": "Rock_Ice_Permafrost"
    },
    {
      "x": -26,
      "y": 54,
      "z": -11,
      "name": "Rock_Ice_Permafrost"
    },
    {
      "x": -26,
      "y": 55,
      "z": -11,
      "name": "Rock_Ice_Permafrost"
    },
    {
      "x": -26,
      "y": 56,
      "z": -11,
      "name": "Rock_Ice_Permafrost"
    },
    {
      "x": -26,
      "y": 57,
      "z": -11,
      "name": "Rock_Ice"
    },
    {
      "x": -26,
      "y": 58,
      "z": -11,
      "name": "Rock_Ice_Permafrost"
    },
    {
      "x": -26,
      "y": 59,
      "z": -11,
      "name": "Rock_Ice_Permafrost"
    },
    {
      "x": -26,
      "y": 60,
      "z": -11,
      "name": "Rock_Ice_Permafrost"
    },
    {
      "x": -26,
      "y": 61,
      "z": -11,
      "name": "Rock_Ice_Permafrost"
    },
    {
      "x": -26,
      "y": 62,
      "z": -11,
      "name": "Rock_Ice"
    },
    {
      "x": -26,
      "y": 63,
      "z": -11,
      "name": "Rock_Ice"
    },
    {
      "x": -26,
      "y": 64,
      "z": -11,
      "name": "Rock_Ice_Permafrost"
    },
    {
      "x": -26,
      "y": 65,
      "z": -11,
      "name": "Rock_Ice_Permafrost"
    },
    {
      "x": -26,
      "y": 66,
      "z": -11,
      "name": "Rock_Ice_Permafrost"
    },
    {
      "x": -26,
      "y": 67,
      "z": -11,
      "name": "Rock_Ice"
    },
    {
      "x": -26,
      "y": 68,
      "z": -11,
      "name": "Soil_Snow"
    },
    {
      "x": -26,
      "y": 48,
      "z": -10,
      "name": "Rock_Ice"
    },
    {
      "x": -26,
      "y": 49,
      "z": -10,
      "name": "Rock_Ice"
    },
    {
      "x": -26,
      "y": 50,
      "z": -10,
      "name": "Rock_Ice"
    },
    {
      "x": -26,
      "y": 51,
      "z": -10,
      "name": "Rock_Ice_Permafrost"
    },
    {
      "x": -26,
      "y": 52,
      "z": -10,
      "name": "Rock_Ice_Permafrost"
    },
    {
      "x": -26,
      "y": 53,
      "z": -10,
      "name": "Rock_Ice_Permafrost"
    },
    {
      "x": -26,
      "y": 54,
      "z": -10,
      "name": "Rock_Ice_Permafrost"
    },
    {
      "x": -26,
      "y": 55,
      "z": -10,
      "name": "Rock_Ice_Permafrost"
    },
    {
      "x": -26,
      "y": 56,
      "z": -10,
      "name": "Rock_Ice_Permafrost"
    },
    {
      "x": -26,
      "y": 57,
      "z": -10,
      "name": "Rock_Ice_Permafrost"
    },
    {
      "x": -26,
      "y": 58,
      "z": -10,
      "name": "Rock_Ice_Permafrost"
    },
    {
      "x": -26,
      "y": 59,
      "z": -10,
      "name": "Rock_Ice_Permafrost"
    },
    {
      "x": -26,
      "y": 60,
      "z": -10,
      "name": "Rock_Ice_Permafrost"
    },
    {
      "x": -26,
      "y": 61,
      "z": -10,
      "name": "Rock_Ice"
    },
    {
      "x": -26,
      "y": 62,
      "z": -10,
      "name": "Rock_Ice"
    },
    {
      "x": -26,
      "y": 63,
      "z": -10,
      "name": "Rock_Ice"
    },
    {
      "x": -26,
      "y": 64,
      "z": -10,
      "name": "Rock_Ice"
    },
    {
      "x": -26,
      "y": 65,
      "z": -10,
      "name": "Rock_Ice_Permafrost"
    },
    {
      "x": -26,
      "y": 66,
      "z": -10,
      "name": "Rock_Ice"
    },
    {
      "x": -26,
      "y": 67,
      "z": -10,
      "name": "Rock_Ice_Permafrost"
    },
    {
      "x": -26,
      "y": 68,
      "z": -10,
      "name": "Rock_Ice"
    },
    {
      "x": -26,
      "y": 69,
      "z": -10,
      "name": "Soil_Snow"
    },
    {
      "x": -26,
      "y": 47,
      "z": -9,
      "name": "Rock_Ice"
    },
    {
      "x": -26,
      "y": 48,
      "z": -9,
      "name": "Rock_Ice"
    },
    {
      "x": -26,
      "y": 49,
      "z": -9,
      "name": "Rock_Ice"
    },
    {
      "x": -26,
      "y": 50,
      "z": -9,
      "name": "Rock_Ice"
    },
    {
      "x": -26,
      "y": 51,
      "z": -9,
      "name": "Rock_Ice"
    },
    {
      "x": -26,
      "y": 52,
      "z": -9,
      "name": "Rock_Ice"
    },
    {
      "x": -26,
      "y": 53,
      "z": -9,
      "name": "Rock_Ice"
    },
    {
      "x": -26,
      "y": 54,
      "z": -9,
      "name": "Rock_Ice_Permafrost"
    },
    {
      "x": -26,
      "y": 55,
      "z": -9,
      "name": "Rock_Ice_Permafrost"
    },
    {
      "x": -26,
      "y": 56,
      "z": -9,
      "name": "Rock_Ice_Permafrost"
    },
    {
      "x": -26,
      "y": 57,
      "z": -9,
      "name": "Rock_Ice_Permafrost"
    },
    {
      "x": -26,
      "y": 58,
      "z": -9,
      "name": "Rock_Ice"
    },
    {
      "x": -26,
      "y": 59,
      "z": -9,
      "name": "Rock_Ice"
    },
    {
      "x": -26,
      "y": 60,
      "z": -9,
      "name": "Rock_Ice"
    },
    {
      "x": -26,
      "y": 61,
      "z": -9,
      "name": "Rock_Ice"
    },
    {
      "x": -26,
      "y": 62,
      "z": -9,
      "name": "Rock_Ice"
    },
    {
      "x": -26,
      "y": 63,
      "z": -9,
      "name": "Rock_Ice"
    },
    {
      "x": -26,
      "y": 64,
      "z": -9,
      "name": "Rock_Ice"
    },
    {
      "x": -26,
      "y": 65,
      "z": -9,
      "name": "Rock_Ice"
    },
    {
      "x": -26,
      "y": 66,
      "z": -9,
      "name": "Rock_Ice"
    },
    {
      "x": -26,
      "y": 67,
      "z": -9,
      "name": "Rock_Ice_Permafrost"
    },
    {
      "x": -26,
      "y": 68,
      "z": -9,
      "name": "Rock_Ice"
    },
    {
      "x": -26,
      "y": 69,
      "z": -9,
      "name": "Soil_Snow"
    },
    {
      "x": -26,
      "y": 46,
      "z": -8,
      "name": "Rock_Ice"
    },
    {
      "x": -26,
      "y": 47,
      "z": -8,
      "name": "Rock_Ice"
    },
    {
      "x": -26,
      "y": 48,
      "z": -8,
      "name": "Rock_Ice"
    },
    {
      "x": -26,
      "y": 49,
      "z": -8,
      "name": "Rock_Ice"
    },
    {
      "x": -26,
      "y": 50,
      "z": -8,
      "name": "Rock_Ice"
    },
    {
      "x": -26,
      "y": 51,
      "z": -8,
      "name": "Rock_Ice"
    },
    {
      "x": -26,
      "y": 52,
      "z": -8,
      "name": "Rock_Ice"
    },
    {
      "x": -26,
      "y": 53,
      "z": -8,
      "name": "Rock_Ice"
    },
    {
      "x": -26,
      "y": 54,
      "z": -8,
      "name": "Rock_Ice"
    },
    {
      "x": -26,
      "y": 55,
      "z": -8,
      "name": "Rock_Ice"
    },
    {
      "x": -26,
      "y": 56,
      "z": -8,
      "name": "Rock_Ice_Permafrost"
    },
    {
      "x": -26,
      "y": 57,
      "z": -8,
      "name": "Rock_Ice_Permafrost"
    },
    {
      "x": -26,
      "y": 58,
      "z": -8,
      "name": "Rock_Ice"
    },
    {
      "x": -26,
      "y": 59,
      "z": -8,
      "name": "Rock_Ice"
    },
    {
      "x": -26,
      "y": 60,
      "z": -8,
      "name": "Rock_Ice"
    },
    {
      "x": -26,
      "y": 61,
      "z": -8,
      "name": "Rock_Ice"
    },
    {
      "x": -26,
      "y": 62,
      "z": -8,
      "name": "Rock_Ice"
    },
    {
      "x": -26,
      "y": 63,
      "z": -8,
      "name": "Rock_Ice"
    },
    {
      "x": -26,
      "y": 64,
      "z": -8,
      "name": "Rock_Ice"
    },
    {
      "x": -26,
      "y": 65,
      "z": -8,
      "name": "Rock_Ice"
    },
    {
      "x": -26,
      "y": 66,
      "z": -8,
      "name": "Rock_Ice"
    },
    {
      "x": -26,
      "y": 67,
