{
  "version": 8,
  "blockIdVersion": 11,
  "anchorX": -1,
  "anchorY": 19,
  "anchorZ": 2,
  "blocks": [
    {
      "x": -31,
      "y": 38,
      "z": -10,
      "name": "Rock_Ice"
    },
    {
      "x": -31,
      "y": 39,
      "z": -10,
      "name": "Soil_Snow"
    },
    {
      "x": -31,
      "y": 36,
      "z": -9,
      "name": "Rock_Ice"
    },
    {
      "x": -31,
      "y": 37,
      "z": -9,
      "name": "Rock_Ice"
    },
    {
      "x": -31,
      "y": 38,
      "z": -9,
      "name": "Rock_Ice"
    },
    {
      "x": -31,
      "y": 39,
      "z": -9,
      "name": "Rock_Ice"
    },
    {
      "x": -31,
      "y": 40,
      "z": -9,
      "name": "Soil_Snow"
    },
    {
      "x": -31,
      "y": 36,
      "z": -8,
      "name": "Rock_Ice"
    },
    {
      "x": -31,
      "y": 37,
      "z": -8,
      "name": "Rock_Ice"
    },
    {
      "x": -31,
      "y": 38,
      "z": -8,
      "name": "Rock_Ice"
    },
    {
      "x": -31,
      "y": 39,
      "z": -8,
      "name": "Rock_Ice"
    },
    {
      "x": -31,
      "y": 40,
      "z": -8,
      "name": "Soil_Snow"
    },
    {
      "x": -30,
      "y": 37,
      "z": -10,
      "name": "Rock_Ice"
    },
    {
      "x": -30,
      "y": 38,
      "z": -10,
      "name": "Rock_Ice"
    },
    {
      "x": -30,
      "y": 39,
      "z": -10,
      "name": "Soil_Snow"
    },
    {
      "x": -30,
      "y": 35,
      "z": -9,
      "name": "Rock_Ice"
    },
    {
      "x": -30,
      "y": 36,
      "z": -9,
      "name": "Rock_Ice"
    },
    {
      "x": -30,
      "y": 37,
      "z": -9,
      "name": "Rock_Ice"
    },
    {
      "x": -30,
      "y": 38,
      "z": -9,
      "name": "Rock_Ice"
    },
    {
      "x": -30,
      "y": 39,
      "z": -9,
      "name": "Rock_Ice"
    },
    {
      "x": -30,
      "y": 40,
      "z": -9,
      "name": "Soil_Snow"
    },
    {
      "x": -30,
      "y": 34,
      "z": -8,
      "name": "Rock_Ice"
    },
    {
      "x": -30,
      "y": 35,
      "z": -8,
      "name": "Rock_Ice"
    },
    {
      "x": -30,
      "y": 36,
      "z": -8,
      "name": "Rock_Ice"
    },
    {
      "x": -30,
      "y": 37,
      "z": -8,
      "name": "Rock_Ice"
    },
    {
      "x": -30,
      "y": 38,
      "z": -8,
      "name": "Rock_Ice"
    },
    {
      "x": -30,
      "y": 39,
      "z": -8,
      "name": "Rock_Ice"
    },
    {
      "x": -30,
      "y": 40,
      "z": -8,
      "name": "Rock_Ice_Permafrost"
    },
    {
      "x": -30,
      "y": 41,
      "z": -8,
      "name": "Rock_Ice_Permafrost"
    },
    {
      "x": -30,
      "y": 42,
      "z": -8,
      "name": "Soil_Snow"
    },
    {
      "x": -30,
      "y": 33,
      "z": -7,
      "name": "Rock_Ice_Permafrost"
    },
    {
      "x": -30,
      "y": 34,
      "z": -7,
      "name": "Rock_Ice_Permafrost"
    },
    {
      "x": -30,
      "y": 35,
      "z": -7,
      "name": "Rock_Ice_Permafrost"
    },
    {
      "x": -30,
      "y": 36,
      "z": -7,
      "name": "Rock_Ice_Permafrost"
    },
    {
      "x": -30,
      "y": 37,
      "z": -7,
      "name": "Rock_Ice_Permafrost"
    },
    {
      "x": -30,
      "y": 38,
      "z": -7,
      "name": "Rock_Ice_Permafrost"
    },
    {
      "x": -30,
      "y": 39,
      "z": -7,
      "name": "Rock_Ice_Permafrost"
    },
    {
      "x": -30,
      "y": 40,
      "z": -7,
      "name": "Rock_Ice_Permafrost"
    },
    {
      "x": -30,
      "y": 41,
      "z": -7,
      "name": "Rock_Ice_Permafrost"
    },
    {
      "x": -30,
      "y": 42,
      "z": -7,
      "name": "Soil_Snow"
    },
    {
      "x": -30,
      "y": 35,
      "z": -6,
      "name": "Rock_Ice"
    },
    {
      "x": -30,
      "y": 36,
      "z": -6,
      "name": "Rock_Ice"
    },
    {
      "x": -30,
      "y": 37,
      "z": -6,
      "name": "Rock_Ice"
    },
    {
      "x": -30,
      "y": 38,
      "z": -6,
      "name": "Rock_Ice"
    },
    {
      "x": -30,
      "y": 39,
      "z": -6,
      "name": "Rock_Ice"
    },
    {
      "x": -30,
      "y": 40,
      "z": -6,
      "name": "Soil_Snow"
    },
    {
      "x": -29,
      "y": 39,
      "z": -15,
      "name": "Soil_Snow"
    },
    {
      "x": -29,
      "y": 38,
      "z": -14,
      "name": "Rock_Ice"
    },
    {
      "x": -29,
      "y": 39,
      "z": -14,
      "name": "Soil_Snow"
    },
    {
      "x": -29,
      "y": 38,
      "z": -13,
      "name": "Rock_Ice_Permafrost"
    },
    {
      "x": -29,
      "y": 39,
      "z": -13,
      "name": "Soil_Snow"
    },
    {
      "x": -29,
      "y": 38,
      "z": -12,
      "name": "Soil_Snow"
    },
    {
      "x": -29,
      "y": 37,
      "z": -11,
      "name": "Rock_Ice"
    },
    {
      "x": -29,
      "y": 38,
      "z": -11,
      "name": "Rock_Ice"
    },
    {
      "x": -29,
      "y": 39,
      "z": -11,
      "name": "Soil_Snow"
    },
    {
      "x": -29,
      "y": 36,
      "z": -10,
      "name": "Rock_Ice"
    },
    {
      "x": -29,
      "y": 37,
      "z": -10,
      "name": "Rock_Ice"
    },
    {
      "x": -29,
      "y": 38,
      "z": -10,
      "name": "Rock_Ice"
    },
    {
      "x": -29,
      "y": 39,
      "z": -10,
      "name": "Rock_Ice"
    },
    {
      "x": -29,
      "y": 40,
      "z": -10,
      "name": "Soil_Snow"
    },
    {
      "x": -29,
      "y": 34,
      "z": -9,
      "name": "Rock_Ice_Permafrost"
    },
    {
      "x": -29,
      "y": 35,
      "z": -9,
      "name": "Rock_Ice_Permafrost"
    },
    {
      "x": -29,
      "y": 36,
      "z": -9,
      "name": "Rock_Ice"
    },
    {
      "x": -29,
      "y": 37,
      "z": -9,
      "name": "Rock_Ice_Permafrost"
    },
    {
      "x": -29,
      "y": 38,
      "z": -9,
      "name": "Rock_Ice_Permafrost"
    },
    {
      "x": -29,
      "y": 39,
      "z": -9,
      "name": "Rock_Ice"
    },
    {
      "x": -29,
      "y": 40,
      "z": -9,
      "name": "Soil_Snow"
    },
    {
      "x": -29,
      "y": 33,
      "z": -8,
      "name": "Rock_Ice_Permafrost"
    },
    {
      "x": -29,
      "y": 34,
      "z": -8,
      "name": "Rock_Ice_Permafrost"
    },
    {
      "x": -29,
      "y": 35,
      "z": -8,
      "name": "Rock_Ice_Permafrost"
    },
    {
      "x": -29,
      "y": 36,
      "z": -8,
      "name": "Rock_Ice_Permafrost"
    },
    {
      "x": -29,
      "y": 37,
      "z": -8,
      "name": "Rock_Ice_Permafrost"
    },
    {
      "x": -29,
      "y": 38,
      "z": -8,
      "name": "Rock_Ice_Permafrost"
    },
    {
      "x": -29,
      "y": 39,
      "z": -8,
      "name": "Rock_Ice_Permafrost"
    },
    {
      "x": -29,
      "y": 40,
      "z": -8,
      "name": "Rock_Ice"
    },
    {
      "x": -29,
      "y": 41,
      "z": -8,
      "name": "Soil_Snow"
    },
    {
      "x": -29,
      "y": 31,
      "z": -7,
      "name": "Rock_Ice_Permafrost"
    },
    {
      "x": -29,
      "y": 32,
      "z": -7,
      "name": "Rock_Ice"
    },
    {
      "x": -29,
      "y": 33,
      "z": -7,
      "name": "Rock_Ice"
    },
    {
      "x": -29,
      "y": 34,
      "z": -7,
      "name": "Rock_Ice"
    },
    {
      "x": -29,
      "y": 35,
      "z": -7,
      "name": "Rock_Ice"
    },
    {
      "x": -29,
      "y": 36,
      "z": -7,
      "name": "Rock_Ice"
    },
    {
      "x": -29,
      "y": 37,
      "z": -7,
      "name": "Rock_Ice"
    },
    {
      "x": -29,
      "y": 38,
      "z": -7,
      "name": "Rock_Ice"
    },
    {
      "x": -29,
      "y": 39,
      "z": -7,
      "name": "Rock_Ice"
    },
    {
      "x": -29,
      "y": 40,
      "z": -7,
      "name": "Rock_Ice"
    },
    {
      "x": -29,
      "y": 41,
      "z": -7,
      "name": "Rock_Ice"
    },
    {
      "x": -29,
      "y": 42,
      "z": -7,
      "name": "Soil_Snow"
    },
    {
      "x": -29,
      "y": 30,
      "z": -6,
      "name": "Rock_Ice"
    },
    {
      "x": -29,
      "y": 31,
      "z": -6,
      "name": "Rock_Ice"
    },
    {
      "x": -29,
      "y": 32,
      "z": -6,
      "name": "Rock_Ice"
    },
    {
      "x": -29,
      "y": 33,
      "z": -6,
      "name": "Rock_Ice"
    },
    {
      "x": -29,
      "y": 34,
      "z": -6,
      "name": "Rock_Ice"
    },
    {
      "x": -29,
      "y": 35,
      "z": -6,
      "name": "Rock_Ice"
    },
    {
      "x": -29,
      "y": 36,
      "z": -6,
      "name": "Rock_Ice"
    },
    {
      "x": -29,
      "y": 37,
      "z": -6,
      "name": "Rock_Ice"
    },
    {
      "x": -29,
      "y": 38,
      "z": -6,
      "name": "Rock_Ice"
    },
    {
      "x": -29,
      "y": 39,
      "z": -6,
      "name": "Rock_Ice"
    },
    {
      "x": -29,
      "y": 40,
      "z": -6,
      "name": "Rock_Ice"
    },
    {
      "x": -29,
      "y": 41,
      "z": -6,
      "name": "Rock_Ice"
    },
    {
      "x": -29,
      "y": 42,
      "z": -6,
      "name": "Rock_Ice"
    },
    {
      "x": -29,
      "y": 43,
      "z": -6,
      "name": "Soil_Snow"
    },
    {
      "x": -29,
      "y": 31,
      "z": -5,
      "name": "Rock_Ice"
    },
    {
      "x": -29,
      "y": 32,
      "z": -5,
      "name": "Rock_Ice"
    },
    {
      "x": -29,
      "y": 33,
      "z": -5,
      "name": "Rock_Ice"
    },
    {
      "x": -29,
      "y": 34,
      "z": -5,
      "name": "Rock_Ice"
    },
    {
      "x": -29,
      "y": 35,
      "z": -5,
      "name": "Rock_Ice"
    },
    {
      "x": -29,
      "y": 36,
      "z": -5,
      "name": "Rock_Ice"
    },
    {
      "x": -29,
      "y": 37,
      "z": -5,
      "name": "Rock_Ice"
    },
    {
      "x": -29,
      "y": 38,
      "z": -5,
      "name": "Rock_Ice"
    },
    {
      "x": -29,
      "y": 39,
      "z": -5,
      "name": "Rock_Ice"
    },
    {
      "x": -29,
      "y": 40,
      "z": -5,
      "name": "Rock_Ice"
    },
    {
      "x": -29,
      "y": 41,
      "z": -5,
      "name": "Soil_Snow"
    },
    {
      "x": -29,
      "y": 34,
      "z": -4,
      "name": "Rock_Ice"
    },
    {
      "x": -29,
      "y": 35,
      "z": -4,
      "name": "Rock_Ice"
    },
    {
      "x": -29,
      "y": 36,
      "z": -4,
      "name": "Rock_Ice"
    },
    {
      "x": -29,
      "y": 37,
      "z": -4,
      "name": "Rock_Ice"
    },
    {
      "x": -29,
      "y": 38,
      "z": -4,
      "name": "Rock_Ice"
    },
    {
      "x": -29,
      "y": 39,
      "z": -4,
      "name": "Soil_Snow"
    },
    {
      "x": -28,
      "y": 38,
      "z": -17,
      "name": "Rock_Ice"
    },
    {
      "x": -28,
      "y": 39,
      "z": -17,
      "name": "Soil_Snow"
    },
    {
      "x": -28,
      "y": 38,
      "z": -16,
      "name": "Rock_Ice_Permafrost"
    },
    {
      "x": -28,
      "y": 39,
      "z": -16,
      "name": "Rock_Ice"
    },
    {
      "x": -28,
      "y": 40,
      "z": -16,
      "name": "Soil_Snow"
    },
    {
      "x": -28,
      "y": 37,
      "z": -15,
      "name": "Rock_Ice_Permafrost"
    },
    {
      "x": -28,
      "y": 38,
      "z": -15,
      "name": "Rock_Ice_Permafrost"
    },
    {
      "x": -28,
      "y": 39,
      "z": -15,
      "name": "Rock_Ice"
    },
    {
      "x": -28,
      "y": 40,
      "z": -15,
      "name": "Soil_Snow"
    },
    {
      "x": -28,
      "y": 37,
      "z": -14,
      "name": "Rock_Ice_Permafrost"
    },
    {
      "x": -28,
      "y": 38,
      "z": -14,
      "name": "Rock_Ice"
    },
    {
      "x": -28,
      "y": 39,
      "z": -14,
      "name": "Soil_Snow"
    },
    {
      "x": -28,
      "y": 36,
      "z": -13,
      "name": "Rock_Ice_Permafrost"
    },
    {
      "x": -28,
      "y": 37,
      "z": -13,
      "name": "Rock_Ice_Permafrost"
    },
    {
      "x": -28,
      "y": 38,
      "z": -13,
      "name": "Rock_Ice_Permafrost"
    },
    {
      "x": -28,
      "y": 39,
      "z": -13,
      "name": "Soil_Snow"
    },
    {
      "x": -28,
      "y": 36,
      "z": -12,
      "name": "Rock_Ice_Permafrost"
    },
    {
      "x": -28,
      "y": 37,
      "z": -12,
      "name": "Rock_Ice_Permafrost"
    },
    {
      "x": -28,
      "y": 38,
      "z": -12,
      "name": "Rock_Ice_Permafrost"
    },
    {
      "x": -28,
      "y": 39,
      "z": -12,
      "name": "Soil_Snow"
    },
    {
      "x": -28,
      "y": 35,
      "z": -11,
      "name": "Rock_Ice_Permafrost"
    },
    {
      "x": -28,
      "y": 36,
      "z": -11,
      "name": "Rock_Ice_Permafrost"
    },
    {
      "x": -28,
      "y": 37,
      "z": -11,
      "name": "Rock_Ice_Permafrost"
    },
    {
      "x": -28,
      "y": 38,
      "z": -11,
      "name": "Rock_Ice_Permafrost"
    },
    {
      "x": -28,
      "y": 39,
      "z": -11,
      "name": "Soil_Snow"
    },
    {
      "x": -28,
      "y": 34,
      "z": -10,
      "name": "Rock_Ice_Permafrost"
    },
    {
      "x": -28,
      "y": 35,
      "z": -10,
      "name": "Rock_Ice_Permafrost"
    },
    {
      "x": -28,
      "y": 36,
      "z": -10,
      "name": "Rock_Ice_Permafrost"
    },
    {
      "x": -28,
      "y": 37,
      "z": -10,
      "name": "Rock_Ice_Permafrost"
    },
    {
      "x": -28,
      "y": 38,
      "z": -10,
      "name": "Rock_Ice_Permafrost"
    },
    {
      "x": -28,
      "y": 39,
      "z": -10,
      "name": "Rock_Ice_Permafrost"
    },
    {
      "x": -28,
      "y": 40,
      "z": -10,
      "name": "Soil_Snow"
    },
    {
      "x": -28,
      "y": 33,
      "z": -9,
      "name": "Rock_Ice_Permafrost"
    },
    {
      "x": -28,
      "y": 34,
      "z": -9,
      "name": "Rock_Ice_Permafrost"
    },
    {
      "x": -28,
      "y": 35,
      "z": -9,
      "name": "Rock_Ice_Permafrost"
    },
    {
      "x": -28,
      "y": 36,
      "z": -9,
      "name": "Rock_Ice_Permafrost"
    },
    {
      "x": -28,
      "y": 37,
      "z": -9,
      "name": "Rock_Ice_Permafrost"
    },
    {
      "x": -28,
      "y": 38,
      "z": -9,
      "name": "Rock_Ice"
    },
    {
      "x": -28,
      "y": 39,
      "z": -9,
      "name": "Rock_Ice_Permafrost"
    },
    {
      "x": -28,
      "y": 40,
      "z": -9,
      "name": "Soil_Snow"
    },
    {
      "x": -28,
      "y": 32,
      "z": -8,
      "name": "Rock_Ice"
    },
    {
      "x": -28,
      "y": 33,
      "z": -8,
      "name": "Rock_Ice"
    },
    {
      "x": -28,
      "y": 34,
      "z": -8,
      "name": "Rock_Ice"
    },
    {
      "x": -28,
      "y": 35,
      "z": -8,
      "name": "Rock_Ice"
    },
    {
      "x": -28,
      "y": 36,
      "z": -8,
      "name": "Rock_Ice"
    },
    {
      "x": -28,
      "y": 37,
      "z": -8,
      "name": "Rock_Ice"
    },
    {
      "x": -28,
      "y": 38,
      "z": -8,
      "name": "Rock_Ice"
    },
    {
      "x": -28,
      "y": 39,
      "z": -8,
      "name": "Rock_Ice"
    },
    {
      "x": -28,
      "y": 40,
      "z": -8,
      "name": "Rock_Ice"
    },
    {
      "x": -28,
      "y": 41,
      "z": -8,
      "name": "Soil_Snow"
    },
    {
      "x": -28,
      "y": 30,
      "z": -7,
      "name": "Rock_Ice"
    },
    {
      "x": -28,
      "y": 31,
      "z": -7,
      "name": "Rock_Ice"
    },
    {
      "x": -28,
      "y": 32,
      "z": -7,
      "name": "Rock_Ice"
    },
    {
      "x": -28,
      "y": 33,
      "z": -7,
      "name": "Rock_Ice"
    },
    {
      "x": -28,
      "y": 34,
      "z": -7,
      "name": "Rock_Ice"
    },
    {
      "x": -28,
      "y": 35,
      "z": -7,
      "name": "Rock_Ice"
    },
    {
      "x": -28,
      "y": 36,
      "z": -7,
      "name": "Rock_Ice"
    },
    {
      "x": -28,
      "y": 37,
      "z": -7,
      "name": "Rock_Ice"
    },
    {
      "x": -28,
      "y": 38,
      "z": -7,
      "name": "Rock_Ice"
    },
    {
      "x": -28,
      "y": 39,
      "z": -7,
      "name": "Rock_Ice"
    },
    {
      "x": -28,
      "y": 40,
      "z": -7,
      "name": "Rock_Ice"
    },
    {
      "x": -28,
      "y": 41,
      "z": -7,
      "name": "Rock_Ice"
    },
    {
      "x": -28,
      "y": 42,
      "z": -7,
      "name": "Soil_Snow"
    },
    {
      "x": -28,
      "y": 29,
      "z": -6,
      "name": "Rock_Ice"
    },
    {
      "x": -28,
      "y": 30,
      "z": -6,
      "name": "Rock_Ice"
    },
    {
      "x": -28,
      "y": 31,
      "z": -6,
      "name": "Rock_Ice"
    },
    {
      "x": -28,
      "y": 32,
      "z": -6,
      "name": "Rock_Ice"
    },
    {
      "x": -28,
      "y": 33,
      "z": -6,
      "name": "Rock_Ice"
    },
    {
      "x": -28,
      "y": 34,
      "z": -6,
      "name": "Rock_Ice"
    },
    {
      "x": -28,
      "y": 35,
      "z": -6,
      "name": "Rock_Ice"
    },
    {
      "x": -28,
      "y": 36,
      "z": -6,
      "name": "Rock_Ice"
    },
    {
      "x": -28,
      "y": 37,
      "z": -6,
      "name": "Rock_Ice"
    },
    {
      "x": -28,
      "y": 38,
      "z": -6,
      "name": "Rock_Ice"
    },
    {
      "x": -28,
      "y": 39,
      "z": -6,
      "name": "Rock_Ice"
    },
    {
      "x": -28,
      "y": 40,
      "z": -6,
      "name": "Rock_Ice"
    },
    {
      "x": -28,
      "y": 41,
      "z": -6,
      "name": "Rock_Ice"
    },
    {
      "x": -28,
      "y": 42,
      "z": -6,
      "name": "Rock_Ice"
    },
    {
      "x": -28,
      "y": 43,
      "z": -6,
      "name": "Soil_Snow"
    },
    {
      "x": -28,
      "y": 26,
      "z": -5,
      "name": "Rock_Ice"
    },
    {
      "x": -28,
      "y": 27,
      "z": -5,
      "name": "Rock_Ice"
    },
    {
      "x": -28,
      "y": 28,
      "z": -5,
      "name": "Rock_Ice"
    },
    {
      "x": -28,
      "y": 29,
      "z": -5,
      "name": "Rock_Ice"
    },
    {
      "x": -28,
      "y": 30,
      "z": -5,
      "name": "Rock_Ice"
    },
    {
      "x": -28,
      "y": 31,
      "z": -5,
      "name": "Rock_Ice"
    },
    {
      "x": -28,
      "y": 32,
      "z": -5,
      "name": "Rock_Ice"
    },
    {
      "x": -28,
      "y": 33,
      "z": -5,
      "name": "Rock_Ice"
    },
    {
      "x": -28,
      "y": 34,
      "z": -5,
      "name": "Rock_Ice"
    },
    {
      "x": -28,
      "y": 35,
      "z": -5,
      "name": "Rock_Ice"
    },
    {
      "x": -28,
      "y": 36,
      "z": -5,
      "name": "Rock_Ice"
    },
    {
      "x": -28,
      "y": 37,
      "z": -5,
      "name": "Rock_Ice"
    },
    {
      "x": -28,
      "y": 38,
      "z": -5,
      "name": "Rock_Ice"
    },
    {
      "x": -28,
      "y": 39,
      "z": -5,
      "name": "Rock_Ice"
    },
    {
      "x": -28,
      "y": 40,
      "z": -5,
      "name": "Rock_Ice"
    },
    {
      "x": -28,
      "y": 41,
      "z": -5,
      "name": "Rock_Ice"
    },
    {
      "x": -28,
      "y": 42,
      "z": -5,
      "name": "Rock_Ice"
    },
    {
      "x": -28,
      "y": 43,
      "z": -5,
      "name": "Rock_Ice"
    },
    {
      "x": -28,
      "y": 44,
      "z": -5,
      "name": "Soil_Snow"
    },
    {
      "x": -28,
      "y": 27,
      "z": -4,
      "name": "Rock_Ice"
    },
    {
      "x": -28,
      "y": 28,
      "z": -4,
      "name": "Rock_Ice"
    },
    {
      "x": -28,
      "y": 29,
      "z": -4,
      "name": "Rock_Ice"
    },
    {
      "x": -28,
      "y": 30,
      "z": -4,
      "name": "Rock_Ice"
    },
    {
      "x": -28,
      "y": 31,
      "z": -4,
      "name": "Rock_Ice"
    },
    {
      "x": -28,
      "y": 32,
      "z": -4,
      "name": "Rock_Ice"
    },
    {
      "x": -28,
      "y": 33,
      "z": -4,
      "name": "Rock_Ice"
    },
    {
      "x": -28,
      "y": 34,
      "z": -4,
      "name": "Rock_Ice"
    },
    {
      "x": -28,
      "y": 35,
      "z": -4,
      "name": "Rock_Ice"
    },
    {
      "x": -28,
      "y": 36,
      "z": -4,
      "name": "Rock_Ice"
    },
    {
      "x": -28,
      "y": 37,
      "z": -4,
      "name": "Rock_Ice"
    },
    {
      "x": -28,
      "y": 38,
      "z": -4,
      "name": "Rock_Ice"
    },
    {
      "x": -28,
      "y": 39,
      "z": -4,
      "name": "Rock_Ice"
    },
    {
      "x": -28,
      "y": 40,
      "z": -4,
      "name": "Rock_Ice"
    },
    {
      "x": -28,
      "y": 41,
      "z": -4,
      "name": "Rock_Ice"
    },
    {
      "x": -28,
      "y": 42,
      "z": -4,
      "name": "Rock_Ice"
    },
    {
      "x": -28,
      "y": 43,
      "z": -4,
      "name": "Soil_Snow"
    },
    {
      "x": -28,
      "y": 30,
      "z": -3,
      "name": "Rock_Ice"
    },
    {
      "x": -28,
      "y": 31,
      "z": -3,
      "name": "Rock_Ice"
    },
    {
      "x": -28,
      "y": 32,
      "z": -3,
      "name": "Rock_Ice"
    },
    {
      "x": -28,
      "y": 33,
      "z": -3,
      "name": "Rock_Ice"
    },
    {
      "x": -28,
      "y": 34,
      "z": -3,
      "name": "Rock_Ice"
    },
    {
      "x": -28,
      "y": 35,
      "z": -3,
      "name": "Rock_Ice"
    },
    {
      "x": -28,
      "y": 36,
      "z": -3,
      "name": "Rock_Ice"
    },
    {
      "x": -28,
      "y": 37,
      "z": -3,
      "name": "Rock_Ice"
    },
    {
      "x": -28,
      "y": 38,
      "z": -3,
      "name": "Rock_Ice"
    },
    {
      "x": -28,
      "y": 39,
      "z": -3,
      "name": "Rock_Ice"
    },
    {
      "x": -28,
      "y": 40,
      "z": -3,
      "name": "Rock_Ice"
    },
    {
      "x": -28,
      "y": 41,
      "z": -3,
      "name": "Soil_Snow"
    },
    {
      "x": -28,
      "y": 33,
      "z": -2,
      "name": "Rock_Ice"
    },
    {
      "x": -28,
      "y": 34,
      "z": -2,
      "name": "Rock_Ice"
    },
    {
      "x": -28,
      "y": 35,
      "z": -2,
      "name": "Rock_Ice"
    },
    {
      "x": -28,
      "y": 36,
      "z": -2,
      "name": "Rock_Ice"
    },
    {
      "x": -28,
      "y": 37,
      "z": -2,
      "name": "Rock_Ice"
    },
    {
      "x": -28,
      "y": 38,
      "z": -2,
      "name": "Rock_Ice"
    },
    {
      "x": -28,
      "y": 24,
      "z": 0,
      "name": "Soil_Snow"
    },
    {
      "x": -28,
      "y": 25,
      "z": 1,
      "name": "Soil_Snow"
    },
    {
      "x": -28,
      "y": 25,
      "z": 2,
      "name": "Rock_Ice_Permafrost"
    },
    {
      "x": -28,
      "y": 26,
      "z": 2,
      "name": "Soil_Snow"
    },
    {
      "x": -28,
      "y": 26,
      "z": 3,
      "name": "Rock_Ice_Permafrost"
    },
    {
      "x": -28,
      "y": 27,
      "z": 3,
      "name": "Soil_Snow"
    },
    {
      "x": -28,
      "y": 27,
      "z": 4,
      "name": "Rock_Ice_Permafrost"
    },
    {
      "x": -28,
      "y": 28,
      "z": 4,
      "name": "Soil_Snow"
    },
    {
      "x": -28,
      "y": 28,
      "z": 5,
      "name": "Rock_Ice_Permafrost"
    },
    {
      "x": -28,
      "y": 29,
      "z": 5,
      "name": "Soil_Snow"
    },
    {
      "x": -28,
      "y": 29,
      "z": 6,
      "name": "Rock_Ice"
    },
    {
      "x": -28,
      "y": 30,
      "z": 6,
      "name": "Soil_Snow"
    },
    {
      "x": -27,
      "y": 39,
      "z": -19,
      "name": "Rock_Ice_Permafrost"
    },
    {
      "x": -27,
      "y": 38,
      "z": -18,
      "name": "Rock_Ice_Permafrost"
    },
    {
      "x": -27,
      "y": 39,
      "z": -18,
      "name": "Rock_Ice"
    },
    {
      "x": -27,
      "y": 40,
      "z": -18,
      "name": "Soil_Snow"
    },
    {
      "x": -27,
      "y": 37,
      "z": -17,
      "name": "Rock_Ice"
    },
    {
      "x": -27,
      "y": 38,
      "z": -17,
      "name": "Rock_Ice"
    },
    {
      "x": -27,
      "y": 39,
      "z": -17,
      "name": "Rock_Ice"
    },
    {
      "x": -27,
      "y": 40,
      "z": -17,
      "name": "Soil_Snow"
    },
    {
      "x": -27,
      "y": 36,
      "z": -16,
      "name": "Rock_Ice"
    },
    {
      "x": -27,
      "y": 37,
      "z": -16,
      "name": "Rock_Ice"
    },
    {
      "x": -27,
      "y": 38,
      "z": -16,
      "name": "Rock_Ice"
    },
    {
      "x": -27,
      "y": 39,
      "z": -16,
      "name": "Rock_Ice"
    },
    {
      "x": -27,
      "y": 40,
      "z": -16,
      "name": "Soil_Snow"
    },
    {
      "x": -27,
      "y": 36,
      "z": -15,
      "name": "Rock_Ice"
    },
    {
      "x": -27,
      "y": 37,
      "z": -15,
      "name": "Rock_Ice"
    },
    {
      "x": -27,
      "y": 38,
      "z": -15,
      "name": "Rock_Ice"
    },
    {
      "x": -27,
      "y": 39,
      "z": -15,
      "name": "Rock_Ice"
    },
    {
      "x": -27,
      "y": 40,
      "z": -15,
      "name": "Soil_Snow"
    },
    {
      "x": -27,
      "y": 35,
      "z": -14,
      "name": "Rock_Ice"
    },
    {
      "x": -27,
      "y": 36,
      "z": -14,
      "name": "Rock_Ice"
    },
    {
      "x": -27,
      "y": 37,
      "z": -14,
      "name": "Rock_Ice"
    },
    {
      "x": -27,
      "y": 38,
      "z": -14,
      "name": "Rock_Ice"
    },
    {
      "x": -27,
      "y": 39,
      "z": -14,
      "name": "Rock_Ice"
    },
    {
      "x": -27,
      "y": 40,
      "z": -14,
      "name": "Soil_Snow"
    },
    {
      "x": -27,
      "y": 35,
      "z": -13,
      "name": "Rock_Ice"
    },
    {
      "x": -27,
      "y": 36,
      "z": -13,
      "name": "Rock_Ice"
    },
    {
      "x": -27,
      "y": 37,
      "z": -13,
      "name": "Rock_Ice"
    },
    {
      "x": -27,
      "y": 38,
      "z": -13,
      "name": "Rock_Ice"
    },
    {
      "x": -27,
      "y": 39,
      "z": -13,
      "name": "Soil_Snow"
    },
    {
      "x": -27,
      "y": 35,
      "z": -12,
      "name": "Rock_Ice"
    },
    {
      "x": -27,
      "y": 36,
      "z": -12,
      "name": "Rock_Ice"
    },
    {
      "x": -27,
      "y": 37,
      "z": -12,
      "name": "Rock_Ice_Permafrost"
    },
    {
      "x": -27,
      "y": 38,
      "z": -12,
      "name": "Rock_Ice"
    },
    {
      "x": -27,
      "y": 39,
      "z": -12,
      "name": "Soil_Snow"
    },
    {
      "x": -27,
      "y": 34,
      "z": -11,
      "name": "Rock_Ice_Permafrost"
    },
    {
      "x": -27,
      "y": 35,
      "z": -11,
      "name": "Rock_Ice"
    },
    {
      "x": -27,
      "y": 36,
      "z": -11,
      "name": "Rock_Ice"
    },
    {
      "x": -27,
      "y": 37,
      "z": -11,
      "name": "Rock_Ice_Permafrost"
    },
    {
      "x": -27,
      "y": 38,
      "z": -11,
      "name": "Rock_Ice"
    },
    {
      "x": -27,
      "y": 39,
      "z": -11,
      "name": "Rock_Ice_Permafrost"
    },
    {
      "x": -27,
      "y": 40,
      "z": -11,
      "name": "Soil_Snow"
    },
    {
      "x": -27,
      "y": 33,
      "z": -10,
      "name": "Rock_Ice_Permafrost"
    },
    {
      "x": -27,
      "y": 34,
      "z": -10,
      "name": "Rock_Ice_Permafrost"
    },
    {
      "x": -27,
      "y": 35,
      "z": -10,
      "name": "Rock_Ice_Permafrost"
    },
    {
      "x": -27,
      "y": 36,
      "z": -10,
      "name": "Rock_Ice_Permafrost"
    },
    {
      "x": -27,
      "y": 37,
      "z": -10,
      "name": "Rock_Ice_Permafrost"
    },
    {
      "x": -27,
      "y": 38,
      "z": -10,
      "name": "Rock_Ice_Permafrost"
    },
    {
      "x": -27,
      "y": 39,
      "z": -10,
      "name": "Rock_Ice_Permafrost"
    },
    {
      "x": -27,
      "y": 40,
      "z": -10,
      "name": "Soil_Snow"
    },
    {
      "x": -27,
      "y": 32,
      "z": -9,
      "name": "Rock_Ice"
    },
    {
      "x": -27,
      "y": 33,
      "z": -9,
      "name": "Rock_Ice"
    },
    {
      "x": -27,
      "y": 34,
      "z": -9,
      "name": "Rock_Ice"
    },
    {
      "x": -27,
      "y": 35,
      "z": -9,
      "name": "Rock_Ice"
    },
    {
      "x": -27,
      "y": 36,
      "z": -9,
      "name": "Rock_Ice"
    },
    {
      "x": -27,
      "y": 37,
      "z": -9,
      "name": "Rock_Ice"
    },
    {
      "x": -27,
      "y": 38,
      "z": -9,
      "name": "Rock_Ice"
    },
    {
      "x": -27,
      "y": 39,
      "z": -9,
      "name": "Rock_Ice"
    },
    {
      "x": -27,
      "y": 40,
      "z": -9,
      "name": "Soil_Snow"
    },
    {
      "x": -27,
      "y": 31,
      "z": -8,
      "name": "Rock_Ice"
    },
    {
      "x": -27,
      "y": 32,
      "z": -8,
      "name": "Rock_Ice"
    },
    {
      "x": -27,
      "y": 33,
      "z": -8,
      "name": "Rock_Ice"
    },
    {
      "x": -27,
      "y": 34,
      "z": -8,
      "name": "Rock_Ice"
    },
    {
      "x": -27,
      "y": 35,
      "z": -8,
      "name": "Rock_Ice"
    },
    {
      "x": -27,
      "y": 36,
      "z": -8,
      "name": "Rock_Ice"
    },
    {
      "x": -27,
      "y": 37,
      "z": -8,
      "name": "Rock_Ice"
    },
    {
      "x": -27,
      "y": 38,
      "z": -8,
      "name": "Rock_Ice"
    },
    {
      "x": -27,
      "y": 39,
      "z": -8,
      "name": "Rock_Ice"
    },
    {
      "x": -27,
      "y": 40,
      "z": -8,
      "name": "Soil_Snow"
    },
    {
      "x": -27,
      "y": 30,
      "z": -7,
      "name": "Rock_Ice"
    },
    {
      "x": -27,
      "y": 31,
      "z": -7,
      "name": "Rock_Ice"
    },
    {
      "x": -27,
      "y": 32,
      "z": -7,
      "name": "Rock_Ice"
    },
    {
      "x": -27,
      "y": 33,
      "z": -7,
      "name": "Rock_Ice"
    },
    {
      "x": -27,
      "y": 34,
      "z": -7,
      "name": "Rock_Ice"
    },
    {
      "x": -27,
      "y": 35,
      "z": -7,
      "name": "Rock_Ice"
    },
    {
      "x": -27,
      "y": 36,
      "z": -7,
      "name": "Rock_Ice"
    },
    {
      "x": -27,
      "y": 37,
      "z": -7,
      "name": "Rock_Ice"
    },
    {
      "x": -27,
      "y": 38,
      "z": -7,
      "name": "Rock_Ice"
    },
    {
      "x": -27,
      "y": 39,
      "z": -7,
      "name": "Rock_Ice"
    },
    {
      "x": -27,
      "y": 40,
      "z": -7,
      "name": "Rock_Ice"
    },
    {
      "x": -27,
      "y": 41,
      "z": -7,
      "name": "Soil_Snow"
    },
    {
      "x": -27,
      "y": 28,
      "z": -6,
      "name": "Rock_Ice"
    },
    {
      "x": -27,
      "y": 29,
      "z": -6,
      "name": "Rock_Ice"
    },
    {
      "x": -27,
      "y": 30,
      "z": -6,
      "name": "Rock_Ice"
    },
    {
      "x": -27,
      "y": 31,
      "z": -6,
      "name": "Rock_Ice"
    },
    {
      "x": -27,
      "y": 32,
      "z": -6,
      "name": "Rock_Ice"
    },
    {
      "x": -27,
      "y": 33,
      "z": -6,
      "name": "Rock_Ice"
    },
    {
      "x": -27,
      "y": 34,
      "z": -6,
      "name": "Rock_Ice"
    },
    {
      "x": -27,
      "y": 35,
      "z": -6,
      "name": "Rock_Ice"
    },
    {
      "x": -27,
      "y": 36,
      "z": -6,
      "name": "Rock_Ice"
    },
    {
      "x": -27,
      "y": 37,
      "z": -6,
      "name": "Rock_Ice"
    },
    {
      "x": -27,
      "y": 38,
      "z": -6,
      "name": "Rock_Ice"
    },
    {
      "x": -27,
      "y": 39,
      "z": -6,
      "name": "Rock_Ice"
    },
    {
      "x": -27,
      "y": 40,
      "z": -6,
      "name": "Rock_Ice"
    },
    {
      "x": -27,
      "y": 41,
      "z": -6,
      "name": "Rock_Ice"
    },
    {
      "x": -27,
      "y": 42,
      "z": -6,
      "name": "Soil_Snow"
    },
    {
      "x": -27,
      "y": 26,
      "z": -5,
      "name": "Rock_Ice"
    },
    {
      "x": -27,
      "y": 27,
      "z": -5,
      "name": "Rock_Ice"
    },
    {
      "x": -27,
      "y": 28,
      "z": -5,
      "name": "Rock_Ice"
    },
    {
      "x": -27,
      "y": 29,
      "z": -5,
      "name": "Rock_Ice"
    },
    {
      "x": -27,
      "y": 30,
      "z": -5,
      "name": "Rock_Ice"
    },
    {
      "x": -27,
      "y": 31,
      "z": -5,
      "name": "Rock_Ice"
    },
    {
      "x": -27,
      "y": 32,
      "z": -5,
      "name": "Rock_Ice"
    },
    {
      "x": -27,
      "y": 33,
      "z": -5,
      "name": "Rock_Ice"
    },
    {
      "x": -27,
      "y": 34,
      "z": -5,
      "name": "Rock_Ice"
    },
    {
      "x": -27,
      "y": 35,
      "z": -5,
      "name": "Rock_Ice"
    },
    {
      "x": -27,
      "y": 36,
      "z": -5,
      "name": "Rock_Ice"
    },
    {
      "x": -27,
      "y": 37,
      "z": -5,
      "name": "Rock_Ice"
    },
    {
      "x": -27,
      "y": 38,
      "z": -5,
      "name": "Rock_Ice"
    },
    {
      "x": -27,
      "y": 39,
      "z": -5,
      "name": "Rock_Ice"
    },
    {
      "x": -27,
      "y": 40,
      "z": -5,
      "name": "Rock_Ice"
    },
    {
      "x": -27,
      "y": 41,
      "z": -5,
      "name": "Rock_Ice"
    },
    {
      "x": -27,
      "y": 42,
      "z": -5,
      "name": "Rock_Ice"
    },
    {
      "x": -27,
      "y": 43,
      "z": -5,
      "name": "Rock_Ice"
    },
    {
      "x": -27,
      "y": 44,
      "z": -5,
      "name": "Soil_Snow"
    },
    {
      "x": -27,
      "y": 24,
      "z": -4,
      "name": "Rock_Ice"
    },
    {
      "x": -27,
      "y": 25,
      "z": -4,
      "name": "Rock_Ice"
    },
    {
      "x": -27,
      "y": 26,
      "z": -4,
      "name": "Rock_Ice"
    },
    {
      "x": -27,
      "y": 27,
      "z": -4,
      "name": "Rock_Ice"
    },
    {
      "x": -27,
      "y": 28,
      "z": -4,
      "name": "Rock_Ice"
    },
    {
      "x": -27,
      "y": 29,
      "z": -4,
      "name": "Rock_Ice"
    },
    {
      "x": -27,
      "y": 30,
      "z": -4,
      "name": "Rock_Ice"
    },
    {
      "x": -27,
      "y": 31,
      "z": -4,
      "name": "Rock_Ice"
    },
    {
      "x": -27,
      "y": 32,
      "z": -4,
      "name": "Rock_Ice"
    },
    {
      "x": -27,
      "y": 33,
      "z": -4,
      "name": "Rock_Ice"
    },
    {
      "x": -27,
      "y": 34,
      "z": -4,
      "name": "Rock_Ice"
    },
    {
      "x": -27,
      "y": 35,
      "z": -4,
      "name": "Rock_Ice"
    },
    {
      "x": -27,
      "y": 36,
      "z": -4,
      "name": "Rock_Ice"
    },
    {
      "x": -27,
      "y": 37,
      "z": -4,
      "name": "Rock_Ice"
    },
    {
      "x": -27,
      "y": 38,
      "z": -4,
      "name": "Rock_Ice"
    },
    {
      "x": -27,
      "y": 39,
      "z": -4,
      "name": "Rock_Ice"
    },
    {
      "x": -27,
      "y": 40,
      "z": -4,
      "name": "Rock_Ice"
    },
    {
      "x": -27,
      "y": 41,
      "z": -4,
      "name": "Rock_Ice"
    },
    {
      "x": -27,
      "y": 42,
      "z": -4,
      "name": "Rock_Ice"
    },
    {
      "x": -27,
      "y": 43,
      "z": -4,
      "name": "Rock_Ice"
    },
    {
      "x": -27,
      "y": 44,
      "z": -4,
      "name": "Soil_Snow"
    },
    {
      "x": -27,
      "y": 23,
      "z": -3,
      "name": "Rock_Ice"
    },
    {
      "x": -27,
      "y": 24,
      "z": -3,
      "name": "Rock_Ice"
    },
    {
      "x": -27,
      "y": 25,
      "z": -3,
      "name": "Rock_Ice"
    },
    {
      "x": -27,
      "y": 26,
      "z": -3,
      "name": "Rock_Ice"
    },
    {
      "x": -27,
      "y": 27,
      "z": -3,
      "name": "Rock_Ice"
    },
    {
      "x": -27,
      "y": 28,
      "z": -3,
      "name": "Rock_Ice"
    },
    {
      "x": -27,
      "y": 29,
      "z": -3,
      "name": "Rock_Ice"
    },
    {
      "x": -27,
      "y": 30,
      "z": -3,
      "name": "Rock_Ice"
    },
    {
      "x": -27,
      "y": 31,
      "z": -3,
      "name": "Rock_Ice"
    },
    {
      "x": -27,
      "y": 32,
      "z": -3,
      "name": "Rock_Ice"
    },
    {
      "x": -27,
      "y": 33,
      "z": -3,
      "name": "Rock_Ice"
    },
    {
      "x": -27,
      "y": 34,
      "z": -3,
      "name": "Rock_Ice"
    },
    {
      "x": -27,
      "y": 35,
      "z": -3,
      "name": "Rock_Ice"
    },
    {
      "x": -27,
      "y": 36,
      "z": -3,
      "name": "Rock_Ice"
    },
    {
      "x": -27,
      "y": 37,
      "z": -3,
      "name": "Rock_Ice"
    },
    {
      "x": -27,
      "y": 38,
      "z": -3,
      "name": "Rock_Ice"
    },
    {
      "x": -27,
      "y": 39,
      "z": -3,
      "name": "Rock_Ice"
    },
    {
      "x": -27,
      "y": 40,
      "z": -3,
      "name": "Rock_Ice"
    },
    {
      "x": -27,
      "y": 41,
      "z": -3,
      "name": "Rock_Ice_Permafrost"
    },
    {
      "x": -27,
      "y": 42,
      "z": -3,
      "name": "Rock_Ice_Permafrost"
    },
    {
      "x": -27,
      "y": 43,
      "z": -3,
      "name": "Rock_Ice_Permafrost"
    },
    {
      "x": -27,
      "y": 44,
      "z": -3,
      "name": "Soil_Snow"
    },
    {
      "x": -27,
      "y": 23,
      "z": -2,
      "name": "Rock_Ice"
    },
    {
      "x": -27,
      "y": 24,
      "z": -2,
      "name": "Rock_Ice"
    },
    {
      "x": -27,
      "y": 25,
      "z": -2,
      "name": "Rock_Ice"
    },
    {
      "x": -27,
      "y": 26,
      "z": -2,
      "name": "Rock_Ice"
    },
    {
      "x": -27,
      "y": 27,
      "z": -2,
      "name": "Rock_Ice"
    },
    {
      "x": -27,
      "y": 28,
      "z": -2,
      "name": "Rock_Ice"
    },
    {
      "x": -27,
      "y": 29,
      "z": -2,
      "name": "Rock_Ice"
    },
    {
      "x": -27,
      "y": 30,
      "z": -2,
      "name": "Rock_Ice"
    },
    {
      "x": -27,
      "y": 31,
      "z": -2,
      "name": "Rock_Ice"
    },
    {
      "x": -27,
      "y": 32,
      "z": -2,
      "name": "Rock_Ice"
    },
    {
      "x": -27,
      "y": 33,
      "z": -2,
      "name": "Rock_Ice"
    },
    {
      "x": -27,
      "y": 34,
      "z": -2,
      "name": "Rock_Ice"
    },
    {
      "x": -27,
      "y": 35,
      "z": -2,
      "name": "Rock_Ice"
    },
    {
      "x": -27,
      "y": 36,
      "z": -2,
      "name": "Rock_Ice"
    },
    {
      "x": -27,
      "y": 37,
      "z": -2,
      "name": "Rock_Ice"
    },
    {
      "x": -27,
      "y": 38,
      "z": -2,
      "name": "Rock_Ice_Permafrost"
    },
    {
      "x": -27,
      "y": 39,
      "z": -2,
      "name": "Rock_Ice_Permafrost"
    },
    {
      "x": -27,
      "y": 40,
      "z": -2,
      "name": "Rock_Ice_Permafrost"
    },
    {
      "x": -27,
      "y": 41,
      "z": -2,
      "name": "Rock_Ice_Permafrost"
    },
    {
      "x": -27,
      "y": 42,
      "z": -2,
      "name": "Soil_Snow"
    },
    {
      "x": -27,
      "y": 23,
      "z": -1,
      "name": "Rock_Ice"
    },
    {
      "x": -27,
      "y": 24,
      "z": -1,
      "name": "Rock_Ice"
    },
    {
      "x": -27,
      "y": 25,
      "z": -1,
      "name": "Rock_Ice"
    },
    {
      "x": -27,
      "y": 26,
      "z": -1,
      "name": "Rock_Ice"
    },
    {
      "x": -27,
      "y": 27,
      "z": -1,
      "name": "Rock_Ice"
    },
    {
      "x": -27,
      "y": 28,
      "z": -1,
      "name": "Rock_Ice"
    },
    {
      "x": -27,
      "y": 29,
      "z": -1,
      "name": "Rock_Ice"
    },
    {
      "x": -27,
      "y": 30,
      "z": -1,
      "name": "Rock_Ice_Permafrost"
    },
    {
      "x": -27,
      "y": 31,
      "z": -1,
      "name": "Rock_Ice"
    },
    {
      "x": -27,
      "y": 32,
      "z": -1,
      "name": "Rock_Ice_Permafrost"
    },
    {
      "x": -27,
      "y": 33,
      "z": -1,
      "name": "Rock_Ice_Permafrost"
    },
    {
      "x": -27,
      "y": 34,
      "z": -1,
      "name": "Rock_Ice_Permafrost"
    },
    {
      "x": -27,
      "y": 35,
      "z": -1,
      "name": "Rock_Ice_Permafrost"
    },
    {
      "x": -27,
      "y": 36,
      "z": -1,
      "name": "Rock_Ice_Permafrost"
    },
    {
      "x": -27,
      "y": 37,
      "z": -1,
      "name": "Rock_Ice_Permafrost"
    },
    {
      "x": -27,
      "y": 38,
      "z": -1,
      "name": "Rock_Ice_Permafrost"
    },
    {
      "x": -27,
      "y": 39,
      "z": -1,
      "name": "Rock_Ice_Permafrost"
    },
    {
      "x": -27,
      "y": 40,
      "z": -1,
      "name": "Rock_Ice_Permafrost"
    },
    {
      "x": -27,
      "y": 41,
      "z": -1,
      "name": "Soil_Snow"
    },
    {
      "x": -27,
      "y": 24,
      "z": 0,
      "name": "Rock_Ice_Permafrost"
    },
    {
      "x": -27,
      "y": 25,
      "z": 0,
      "name": "Rock_Ice_Permafrost"
    },
    {
      "x": -27,
      "y": 26,
      "z": 0,
      "name": "Rock_Ice_Permafrost"
    },
    {
      "x": -27,
      "y": 27,
      "z": 0,
      "name": "Rock_Ice_Permafrost"
    },
    {
      "x": -27,
      "y": 28,
      "z": 0,
      "name": "Rock_Ice_Permafrost"
    },
    {
      "x": -27,
      "y": 29,
      "z": 0,
      "name": "Rock_Ice_Permafrost"
    },
    {
      "x": -27,
      "y": 30,
      "z": 0,
      "name": "Rock_Ice_Permafrost"
    },
    {
      "x": -27,
      "y": 31,
      "z": 0,
      "name": "Rock_Ice_Permafrost"
    },
    {
      "x": -27,
      "y": 32,
      "z": 0,
      "name": "Rock_Ice"
    },
    {
      "x": -27,
      "y": 33,
      "z": 0,
      "name": "Rock_Ice"
    },
    {
      "x": -27,
      "y": 34,
      "z": 0,
      "name": "Rock_Ice"
    },
    {
      "x": -27,
      "y": 35,
      "z": 0,
      "name": "Rock_Ice"
    },
    {
      "x": -27,
      "y": 36,
      "z": 0,
      "name": "Rock_Ice"
    },
    {
      "x": -27,
      "y": 37,
      "z": 0,
      "name": "Rock_Ice"
    },
    {
      "x": -27,
      "y": 38,
      "z": 0,
      "name": "Soil_Snow"
    },
    {
      "x": -27,
      "y": 24,
      "z": 1,
      "name": "Rock_Ice_Permafrost"
    },
    {
      "x": -27,
      "y": 25,
      "z": 1,
      "name": "Rock_Ice_Permafrost"
    },
    {
      "x": -27,
      "y": 26,
      "z": 1,
      "name": "Rock_Ice_Permafrost"
    },
    {
      "x": -27,
      "y": 27,
      "z": 1,
      "name": "Rock_Ice_Permafrost"
    },
    {
      "x": -27,
      "y": 28,
      "z": 1,
      "name": "Rock_Ice_Permafrost"
    },
    {
      "x": -27,
      "y": 29,
      "z": 1,
      "name": "Rock_Ice"
    },
    {
      "x": -27,
      "y": 30,
      "z": 1,
      "name": "Rock_Ice"
    },
    {
      "x": -27,
      "y": 31,
      "z": 1,
      "name": "Rock_Ice"
    },
    {
      "x": -27,
      "y": 32,
      "z": 1,
      "name": "Rock_Ice"
    },
    {
      "x": -27,
      "y": 33,
      "z": 1,
      "name": "Rock_Ice"
    },
    {
      "x": -27,
      "y": 34,
      "z": 1,
      "name": "Rock_Ice"
    },
    {
      "x": -27,
      "y": 35,
      "z": 1,
      "name": "Rock_Ice"
    },
    {
      "x": -27,
      "y": 36,
      "z": 1,
      "name": "Rock_Ice"
    },
    {
      "x": -27,
      "y": 25,
      "z": 2,
      "name": "Rock_Ice_Permafrost"
    },
    {
      "x": -27,
      "y": 26,
      "z": 2,
      "name": "Rock_Ice_Permafrost"
    },
    {
      "x": -27,
      "y": 27,
      "z": 2,
      "name": "Rock_Ice_Permafrost"
    },
    {
      "x": -27,
      "y": 28,
      "z": 2,
      "name": "Rock_Ice_Permafrost"
    },
    {
      "x": -27,
      "y": 29,
      "z": 2,
      "name": "Rock_Ice"
    },
    {
      "x": -27,
      "y": 30,
      "z": 2,
      "name": "Rock_Ice"
    },
    {
      "x": -27,
      "y": 31,
      "z": 2,
      "name": "Rock_Ice"
    },
    {
      "x": -27,
      "y": 32,
      "z": 2,
      "name": "Rock_Ice"
    },
    {
      "x": -27,
      "y": 33,
      "z": 2,
      "name": "Rock_Ice"
    },
    {
      "x": -27,
      "y": 34,
      "z": 2,
      "name": "Rock_Ice"
    },
    {
      "x": -27,
      "y": 35,
      "z": 2,
      "name": "Rock_Ice"
    },
    {
      "x": -27,
      "y": 26,
      "z": 3,
      "name": "Rock_Ice_Permafrost"
    },
    {
      "x": -27,
      "y": 27,
      "z": 3,
      "name": "Rock_Ice_Permafrost"
    },
    {
      "x": -27,
      "y": 28,
      "z": 3,
      "name": "Rock_Ice_Permafrost"
    },
    {
      "x": -27,
      "y": 29,
      "z": 3,
      "name": "Rock_Ice"
    },
    {
      "x": -27,
      "y": 30,
      "z": 3,
      "name": "Rock_Ice"
    },
    {
      "x": -27,
      "y": 31,
      "z": 3,
      "name": "Rock_Ice"
    },
    {
      "x": -27,
      "y": 32,
      "z": 3,
      "name": "Rock_Ice"
    },
    {
      "x": -27,
      "y": 33,
      "z": 3,
      "name": "Rock_Ice"
    },
    {
      "x": -27,
      "y": 34,
      "z": 3,
      "name": "Rock_Ice"
    },
    {
      "x": -27,
      "y": 35,
      "z": 3,
      "name": "Rock_Ice"
    },
    {
      "x": -27,
      "y": 27,
      "z": 4,
      "name": "Rock_Ice_Permafrost"
    },
    {
      "x": -27,
      "y": 28,
      "z": 4,
      "name": "Rock_Ice_Permafrost"
    },
    {
      "x": -27,
      "y": 29,
      "z": 4,
      "name": "Rock_Ice"
    },
    {
      "x": -27,
      "y": 30,
      "z": 4,
      "name": "Rock_Ice"
    },
    {
      "x": -27,
      "y": 31,
      "z": 4,
      "name": "Rock_Ice"
    },
    {
      "x": -27,
      "y": 32,
      "z": 4,
      "name": "Rock_Ice"
    },
    {
      "x": -27,
      "y": 33,
      "z": 4,
      "name": "Rock_Ice"
    },
    {
      "x": -27,
      "y": 34,
      "z": 4,
      "name": "Rock_Ice"
    },
    {
      "x": -27,
      "y": 35,
      "z": 4,
      "name": "Rock_Ice"
    },
    {
      "x": -27,
      "y": 28,
      "z": 5,
      "name": "Rock_Ice_Permafrost"
    },
    {
      "x": -27,
      "y": 29,
      "z": 5,
      "name": "Rock_Ice"
    },
    {
      "x": -27,
      "y": 30,
      "z": 5,
      "name": "Rock_Ice"
    },
    {
      "x": -27,
      "y": 31,
      "z": 5,
      "name": "Rock_Ice"
    },
    {
      "x": -27,
      "y": 32,
      "z": 5,
      "name": "Rock_Ice"
    },
    {
      "x": -27,
      "y": 33,
      "z": 5,
      "name": "Rock_Ice"
    },
    {
      "x": -27,
      "y": 34,
      "z": 5,
      "name": "Rock_Ice"
    },
    {
      "x": -27,
      "y": 35,
      "z": 5,
      "name": "Rock_Ice"
    },
    {
      "x": -27,
      "y": 29,
      "z": 6,
      "name": "Rock_Ice"
    },
    {
      "x": -27,
      "y": 30,
      "z": 6,
      "name": "Rock_Ice"
    },
    {
      "x": -27,
      "y": 31,
      "z": 6,
      "name": "Rock_Ice"
    },
    {
      "x": -27,
      "y": 32,
      "z": 6,
      "name": "Rock_Ice"
    },
    {
      "x": -27,
      "y": 33,
      "z": 6,
      "name": "Rock_Ice"
    },
    {
      "x": -27,
      "y": 34,
      "z": 6,
      "name": "Rock_Ice"
    },
    {
      "x": -27,
      "y": 35,
      "z": 6,
      "name": "Rock_Ice"
    },
    {
      "x": -27,
      "y": 31,
      "z": 7,
      "name": "Rock_Ice"
    },
    {
      "x": -27,
      "y": 32,
      "z": 7,
      "name": "Rock_Ice"
    },
    {
      "x": -27,
      "y": 33,
      "z": 7,
      "name": "Rock_Ice"
    },
    {
      "x": -27,
      "y": 34,
      "z": 10,
      "name": "Rock_Ice"
    },
    {
      "x": -27,
      "y": 35,
      "z": 10,
      "name": "Soil_Snow"
    },
    {
      "x": -26,
      "y": 37,
      "z": -20,
      "name": "Rock_Ice"
    },
    {
      "x": -26,
      "y": 38,
      "z": -20,
      "name": "Rock_Ice"
    },
    {
      "x": -26,
      "y": 39,
      "z": -20,
      "name": "Rock_Ice"
    },
    {
      "x": -26,
      "y": 40,
      "z": -20,
      "name": "Rock_Ice"
    },
    {
      "x": -26,
      "y": 41,
      "z": -20,
      "name": "Rock_Ice"
    },
    {
      "x": -26,
      "y": 42,
      "z": -20,
      "name": "Soil_Snow"
    },
    {
      "x": -26,
      "y": 37,
      "z": -19,
      "name": "Rock_Ice"
    },
    {
      "x": -26,
      "y": 38,
      "z": -19,
      "name": "Rock_Ice"
    },
    {
      "x": -26,
      "y": 39,
      "z": -19,
      "name": "Rock_Ice"
    },
    {
      "x": -26,
      "y": 40,
      "z": -19,
      "name": "Rock_Ice"
    },
    {
      "x": -26,
      "y": 41,
      "z": -19,
      "name": "Soil_Snow"
    },
    {
      "x": -26,
      "y": 36,
      "z": -18,
      "name": "Rock_Ice"
    },
    {
      "x": -26,
      "y": 37,
      "z": -18,
      "name": "Rock_Ice"
    },
    {
      "x": -26,
      "y": 38,
      "z": -18,
      "name": "Rock_Ice"
    },
    {
      "x": -26,
      "y": 39,
      "z": -18,
      "name": "Rock_Ice"
    },
    {
      "x": -26,
      "y": 40,
      "z": -18,
      "name": "Rock_Ice"
    },
    {
      "x": -26,
      "y": 41,
      "z": -18,
      "name": "Soil_Snow"
    },
    {
      "x": -26,
      "y": 36,
      "z": -17,
      "name": "Rock_Ice"
    },
    {
      "x": -26,
      "y": 37,
      "z": -17,
      "name": "Rock_Ice"
    },
    {
      "x": -26,
      "y": 38,
      "z": -17,
      "name": "Rock_Ice"
    },
    {
      "x": -26,
      "y": 39,
      "z": -17,
      "name": "Rock_Ice"
    },
    {
      "x": -26,
      "y": 40,
      "z": -17,
      "name": "Rock_Ice"
    },
    {
      "x": -26,
      "y": 41,
      "z": -17,
      "name": "Soil_Snow"
    },
    {
      "x": -26,
      "y": 35,
      "z": -16,
      "name": "Rock_Ice"
    },
    {
      "x": -26,
      "y": 36,
      "z": -16,
      "name": "Rock_Ice"
    },
    {
      "x": -26,
      "y": 37,
      "z": -16,
      "name": "Rock_Ice"
    },
    {
      "x": -26,
      "y": 38,
      "z": -16,
      "name": "Rock_Ice"
    },
    {
      "x": -26,
      "y": 39,
      "z": -16,
      "name": "Rock_Ice"
    },
    {
      "x": -26,
      "y": 40,
      "z": -16,
      "name": "Rock_Ice"
    },
    {
      "x": -26,
      "y": 41,
      "z": -16,
      "name": "Soil_Snow"
    },
    {
      "x": -26,
      "y": 35,
      "z": -15,
      "name": "Rock_Ice"
    },
    {
      "x": -26,
      "y": 36,
      "z": -15,
      "name": "Rock_Ice"
    },
    {
      "x": -26,
      "y": 37,
      "z": -15,
      "name": "Rock_Ice"
    },
    {
      "x": -26,
      "y": 38,
      "z": -15,
      "name": "Rock_Ice"
    },
    {
      "x": -26,
      "y": 39,
      "z": -15,
      "name": "Rock_Ice"
    },
    {
      "x": -26,
      "y": 40,
      "z": -15,
      "name": "Soil_Snow"
    },
    {
      "x": -26,
      "y": 34,
      "z": -14,
      "name": "Rock_Ice"
    },
    {
      "x": -26,
      "y": 35,
      "z": -14,
      "name": "Rock_Ice"
    },
    {
      "x": -26,
      "y": 36,
      "z": -14,
      "name": "Rock_Ice"
    },
    {
      "x": -26,
      "y": 37,
      "z": -14,
      "name": "Rock_Ice"
    },
    {
      "x": -26,
      "y": 38,
      "z": -14,
      "name": "Rock_Ice"
    },
    {
      "x": -26,
      "y": 39,
      "z": -14,
      "name": "Rock_Ice"
    },
    {
      "x": -26,
      "y": 40,
      "z": -14,
      "name": "Soil_Snow"
    },
    {
      "x": -26,
      "y": 34,
      "z": -13,
      "name": "Rock_Ice"
    },
    {
      "x": -26,
      "y": 35,
      "z": -13,
      "name": "Rock_Ice"
    },
    {
      "x": -26,
      "y": 36,
      "z": -13,
      "name": "Rock_Ice"
    },
    {
      "x": -26,
      "y": 37,
      "z": -13,
      "name": "Rock_Ice"
    },
    {
      "x": -26,
      "y": 38,
      "z": -13,
      "name": "Rock_Ice"
    },
    {
      "x": -26,
      "y": 39,
      "z": -13,
      "name": "Rock_Ice"
    },
    {
      "x": -26,
      "y": 40,
      "z": -13,
      "name": "Soil_Snow"
    },
    {
      "x": -26,
      "y": 33,
      "z": -12,
      "name": "Rock_Ice"
    },
    {
      "x": -26,
      "y": 34,
      "z": -12,
      "name": "Rock_Ice"
    },
    {
      "x": -26,
      "y": 35,
      "z": -12,
      "name": "Rock_Ice"
    },
    {
      "x": -26,
      "y": 36,
      "z": -12,
      "name": "Rock_Ice"
    },
    {
      "x": -26,
      "y": 37,
      "z": -12,
      "name": "Rock_Ice"
    },
    {
      "x": -26,
      "y": 38,
      "z": -12,
      "name": "Rock_Ice_Permafrost"
    },
    {
      "x": -26,
      "y": 39,
      "z": -12,
      "name": "Rock_Ice_Permafrost"
    },
    {
      "x": -26,
      "y": 40,
      "z": -12,
      "name": "Soil_Snow"
    },
    {
      "x": -26,
      "y": 33,
      "z": -11,
      "name": "Rock_Ice_Permafrost"
    },
    {
      "x": -26,
      "y": 34,
      "z": -11,
      "name": "Rock_Ice_Permafrost"
    },
    {
      "x": -26,
      "y": 35,
      "z": -11,
      "name": "Rock_Ice_Permafrost"
    },
    {
      "x": -26,
      "y": 36,
      "z": -11,
      "name": "Rock_Ice_Permafrost"
    },
    {
      "x": -26,
      "y": 37,
      "z": -11,
      "name": "Rock_Ice_Permafrost"
    },
    {
      "x": -26,
      "y": 38,
      "z": -11,
      "name": "Rock_Ice"
    },
    {
      "x": -26,
      "y": 39,
      "z": -11,
      "name": "Rock_Ice"
    },
    {
      "x": -26,
      "y": 40,
      "z": -11,
      "name": "Soil_Snow"
    },
    {
      "x": -26,
      "y": 32,
      "z": -10,
      "name": "Rock_Ice_Permafrost"
    },
    {
      "x": -26,
      "y": 33,
      "z": -10,
      "name": "Rock_Ice"
    },
    {
      "x": -26,
      "y": 34,
      "z": -10,
      "name": "Rock_Ice"
    },
    {
      "x": -26,
      "y": 35,
      "z": -10,
      "name": "Rock_Ice"
    },
    {
      "x": -26,
      "y": 36,
      "z": -10,
      "name": "Rock_Ice"
    },
    {
      "x": -26,
      "y": 37,
      "z": -10,
      "name": "Rock_Ice"
    },
    {
      "x": -26,
      "y": 38,
      "z": -10,
      "name": "Rock_Ice"
    },
    {
      "x": -26,
      "y": 39,
      "z": -10,
      "name": "Rock_Ice"
    },
    {
      "x": -26,
      "y": 40,
      "z": -10,
      "name": "Soil_Snow"
    },
    {
      "x": -26,
      "y": 31,
      "z": -9,
      "name": "Rock_Ice"
    },
    {
      "x": -26,
      "y": 32,
      "z": -9,
      "name": "Rock_Ice"
    },
    {
      "x": -26,
      "y": 33,
      "z": -9,
      "name": "Rock_Ice"
    },
    {
      "x": -26,
      "y": 34,
      "z": -9,
      "name": "Rock_Ice"
    },
    {
      "x": -26,
      "y": 35,
      "z": -9,
      "name": "Rock_Ice"
    },
    {
      "x": -26,
      "y": 36,
      "z": -9,
      "name": "Rock_Ice"
    },
    {
      "x": -26,
      "y": 37,
      "z": -9,
      "name": "Rock_Ice"
    },
    {
      "x": -26,
      "y": 38,
      "z": -9,
      "name": "Rock_Ice"
    },
    {
      "x": -26,
      "y": 39,
      "z": -9,
      "name": "Rock_Ice"
    },
    {
      "x": -26,
      "y": 40,
      "z": -9,
      "name": "Soil_Snow"
    },
    {
      "x": -26,
      "y": 30,
      "z": -8,
      "name": "Rock_Ice"
    },
    {
      "x": -26,
      "y": 31,
      "z": -8,
      "name": "Rock_Ice"
    },
    {
      "x": -26,
      "y": 32,
      "z": -8,
      "name": "Rock_Ice"
    },
    {
      "x": -26,
      "y": 33,
      "z": -8,
      "name": "Rock_Ice"
    },
    {
      "x": -26,
      "y": 34,
      "z": -8,
      "name": "Rock_Ice"
    },
    {
      "x": -26,
      "y": 35,
      "z": -8,
      "name": "Rock_Ice"
    },
    {
      "x": -26,
      "y": 36,
      "z": -8,
      "name": "Rock_Ice"
    },
    {
      "x": -26,
      "y": 37,
      "z": -8,
      "name": "Rock_Ice"
    },
    {
      "x": -26,
      "y": 38,
      "z": -8,
      "name": "Rock_Ice"
    },
    {
      "x": -26,
      "y": 39,
      "z": -8,
      "name": "Rock_Ice"
    },
    {
      "x": -26,
      "y": 40,
      "z": -8,
      "name": "Soil_Snow"
    },
    {
      "x": -26,
      "y": 28,
      "z": -7,
      "name": "Rock_Ice"
    },
    {
      "x": -26,
      "y": 29,
      "z": -7,
      "name": "Rock_Ice"
    },
    {
      "x": -26,
      "y": 30,
      "z": -7,
      "name": "Rock_Ice"
    },
    {
      "x": -26,
      "y": 31,
      "z": -7,
      "name": "Rock_Ice"
    },
    {
      "x": -26,
      "y": 32,
      "z": -7,
      "name": "Rock_Ice"
    },
    {
      "x": -26,
      "y": 33,
      "z": -7,
      "name": "Rock_Ice"
    },
    {
      "x": -26,
      "y": 34,
      "z": -7,
      "name": "Rock_Ice"
    },
    {
      "x": -26,
      "y": 35,
      "z": -7,
      "name": "Rock_Ice"
    },
    {
      "x": -26,
      "y": 36,
      "z": -7,
      "name": "Rock_Ice"
    },
    {
      "x": -26,
      "y": 37,
      "z": -7,
      "name": "Rock_Ice"
    },
    {
      "x": -26,
      "y": 38,
      "z": -7,
      "name": "Rock_Ice"
    },
    {
      "x": -26,
      "y": 39,
      "z": -7,
      "name": "Rock_Ice"
    },
    {
      "x": -26,
      "y": 40,
      "z": -7,
      "name": "Rock_Ice"
    },
    {
      "x": -26,
      "y": 41,
      "z": -7,
      "name": "Soil_Snow"
    },
    {
      "x": -26,
      "y": 26,
      "z": -6,
      "name": "Rock_Ice"
    },
    {
      "x": -26,
      "y": 27,
      "z": -6,
      "name": "Rock_Ice"
    },
    {
      "x": -26,
      "y": 28,
      "z": -6,
      "name": "Rock_Ice"
    },
    {
      "x": -26,
      "y": 29,
      "z": -6,
      "name": "Rock_Ice"
    },
    {
      "x": -26,
      "y": 30,
      "z": -6,
      "name": "Rock_Ice"
    },
    {
      "x": -26,
      "y": 31,
      "z": -6,
      "name": "Rock_Ice"
    },
    {
      "x": -26,
      "y": 32,
      "z": -6,
      "name": "Rock_Ice"
    },
    {
      "x": -26,
      "y": 33,
      "z": -6,
      "name": "Rock_Ice"
    },
    {
      "x": -26,
      "y": 34,
      "z": -6,
      "name": "Rock_Ice"
    },
    {
      "x": -26,
      "y": 35,
      "z": -6,
      "name": "Rock_Ice"
    },
    {
      "x": -26,
      "y": 36,
      "z": -6,
      "name": "Rock_Ice"
    },
    {
      "x": -26,
      "y": 37,
      "z": -6,
      "name": "Rock_Ice"
    },
    {
      "x": -26,
      "y": 38,
      "z": -6,
      "name": "Rock_Ice"
    },
    {
      "x": -26,
      "y": 39,
      "z": -6,
      "name": "Rock_Ice"
    },
    {
      "x": -26,
      "y": 40,
      "z": -6,
      "name": "Rock_Ice"
    },
    {
      "x": -26,
      "y": 41,
      "z": -6,
      "name": "Rock_Ice"
    },
    {
      "x": -26,
      "y": 42,
      "z": -6,
      "name": "Soil_Snow"
    },
    {
      "x": -26,
      "y": 25,
      "z": -5,
      "name": "Rock_Ice"
    },
    {
      "x": -26,
      "y": 26,
      "z": -5,
      "name": "Rock_Ice"
    },
    {
      "x": -26,
      "y": 27,
      "z": -5,
      "name": "Rock_Ice"
    },
    {
      "x": -26,
      "y": 28,
      "z": -5,
      "name": "Rock_Ice"
    },
    {
      "x": -26,
      "y": 29,
      "z": -5,
      "name": "Rock_Ice"
    },
    {
      "x": -26,
      "y": 30,
      "z": -5,
      "name": "Rock_Ice"
    },
    {
      "x": -26,
      "y": 31,
      "z": -5,
      "name": "Rock_Ice"
    },
    {
      "x": -26,
      "y": 32,
      "z": -5,
      "name": "Rock_Ice"
    },
    {
      "x": -26,
      "y": 33,
      "z": -5,
      "name": "Rock_Ice"
    },
    {
      "x": -26,
      "y": 34,
      "z": -5,
      "name": "Rock_Ice"
    },
    {
      "x": -26,
      "y": 35,
      "z": -5,
      "name": "Rock_Ice"
    },
    {
      "x": -26,
      "y": 36,
      "z": -5,
      "name": "Rock_Ice"
    },
    {
      "x": -26,
      "y": 37,
      "z": -5,
      "name": "Rock_Ice"
    },
    {
      "x": -26,
      "y": 38,
      "z": -5,
      "name": "Rock_Ice"
    },
    {
      "x": -26,
      "y": 39,
      "z": -5,
      "name": "Rock_Ice"
    },
    {
      "x": -26,
      "y": 40,
      "z": -5,
      "name": "Rock_Ice"
    },
    {
      "x": -26,
      "y": 41,
      "z": -5,
      "name": "Rock_Ice"
    },
    {
      "x": -26,
      "y": 42,
      "z": -5,
      "name": "Rock_Ice"
    },
    {
      "x": -26,
      "y": 43,
      "z": -5,
      "name": "Soil_Snow"
    },
    {
      "x": -26,
      "y": 20,
      "z": -4,
      "name": "Rock_Ice_Permafrost"
    },
    {
      "x": -26,
      "y": 21,
      "z": -4,
      "name": "Rock_Ice"
    },
    {
      "x": -26,
      "y": 22,
      "z": -4,
      "name": "Rock_Ice"
    },
    {
      "x": -26,
      "y": 23,
      "z": -4,
      "name": "Rock_Ice"
    },
    {
      "x": -26,
      "y": 24,
      "z": -4,
      "name": "Rock_Ice"
    },
    {
      "x": -26,
      "y": 25,
      "z": -4,
      "name": "Rock_Ice"
    },
    {
      "x": -26,
      "y": 26,
      "z": -4,
      "name": "Rock_Ice"
    },
    {
      "x": -26,
      "y": 27,
      "z": -4,
      "name": "Rock_Ice"
    },
    {
      "x": -26,
      "y": 28,
      "z": -4,
      "name": "Rock_Ice"
    },
    {
      "x": -26,
      "y": 29,
      "z": -4,
      "name": "Rock_Ice"
    },
    {
      "x": -26,
      "y": 30,
      "z": -4,
      "name": "Rock_Ice"
    },
    {
      "x": -26,
      "y": 31,
      "z": -4,
      "name": "Rock_Ice"
    },
    {
      "x": -26,
      "y": 32,
      "z": -4,
      "name": "Rock_Ice"
    },
    {
      "x": -26,
      "y": 33,
      "z": -4,
      "name": "Rock_Ice"
    },
    {
      "x": -26,
      "y": 34,
      "z": -4,
      "name": "Rock_Ice"
    },
    {
      "x": -26,
      "y": 35,
      "z": -4,
      "name": "Rock_Ice"
    },
    {
      "x": -26,
      "y": 36,
      "z": -4,
      "name": "Rock_Ice"
    },
    {
      "x": -26,
      "y": 37,
      "z": -4,
      "name": "Rock_Ice"
    },
    {
      "x": -26,
      "y": 38,
      "z": -4,
      "name": "Rock_Ice"
    },
    {
      "x": -26,
      "y": 39,
      "z": -4,
      "name": "Rock_Ice"
    },
    {
      "x": -26,
      "y": 40,
      "z": -4,
      "name": "Rock_Ice"
    },
    {
      "x": -26,
      "y": 41,
      "z": -4,
      "name": "Rock_Ice"
    },
    {
      "x": -26,
      "y": 42,
      "z": -4,
      "name": "Rock_Ice_Permafrost"
    },
    {
      "x": -26,
      "y": 43,
      "z": -4,
      "name": "Rock_Ice_Permafrost"
    },
    {
      "x": -26,
      "y": 44,
      "z": -4,
      "name": "Soil_Snow"
    },
    {
      "x": -26,
      "y": 21,
      "z": -3,
      "name": "Rock_Ice_Permafrost"
    },
    {
      "x": -26,
      "y": 22,
      "z": -3,
      "name": "Rock_Ice"
    },
    {
      "x": -26,
      "y": 23,
      "z": -3,
      "name": "Rock_Ice"
    },
    {
      "x": -26,
      "y": 24,
      "z": -3,
      "name": "Rock_Ice"
    },
    {
      "x": -26,
      "y": 25,
      "z": -3,
      "name": "Rock_Ice"
    },
    {
      "x": -26,
      "y": 26,
      "z": -3,
      "name": "Rock_Ice"
    },
    {
      "x": -26,
      "y": 27,
      "z": -3,
      "name": "Rock_Ice"
    },
    {
      "x": -26,
      "y": 28,
      "z": -3,
      "name": "Rock_Ice"
    },
    {
      "x": -26,
      "y": 29,
      "z": -3,
      "name": "Rock_Ice"
    },
    {
      "x": -26,
      "y": 30,
      "z": -3,
      "name": "Rock_Ice"
    },
    {
      "x": -26,
      "y": 31,
      "z": -3,
      "name": "Rock_Ice"
    },
    {
      "x": -26,
      "y": 32,
      "z": -3,
      "name": "Rock_Ice"
    },
    {
      "x": -26,
      "y": 33,
      "z": -3,
      "name": "Rock_Ice"
    },
    {
      "x": -26,
      "y": 34,
      "z": -3,
      "name": "Rock_Ice"
    },
    {
      "x": -26,
      "y": 35,
      "z": -3,
      "name": "Rock_Ice"
    },
    {
      "x": -26,
      "y": 36,
      "z": -3,
      "name": "Rock_Ice"
    },
    {
      "x": -26,
      "y": 37,
      "z": -3,
      "name": "Rock_Ice"
    },
    {
      "x": -26,
      "y": 38,
      "z": -3,
      "name": "Rock_Ice"
    },
    {
      "x": -26,
      "y": 39,
      "z": -3,
      "name": "Rock_Ice_Permafrost"
    },
    {
      "x": -26,
      "y": 40,
      "z": -3,
      "name": "Rock_Ice_Permafrost"
    },
    {
      "x": -26,
      "y": 41,
      "z": -3,
      "name": "Rock_Ice_Permafrost"
    },
    {
      "x": -26,
      "y": 42,
      "z": -3,
      "name": "Rock_Ice_Permafrost"
    },
    {
      "x": -26,
      "y": 43,
      "z": -3,
      "name": "Rock_Ice_Permafrost"
    },
    {
      "x": -26,
      "y": 44,
      "z": -3,
      "name": "Soil_Snow"
    },
    {
      "x": -26,
      "y": 22,
      "z": -2,
      "name": "Rock_Ice"
    },
    {
      "x": -26,
      "y": 23,
      "z": -2,
      "name": "Rock_Ice"
    },
    {
      "x": -26,
      "y": 24,
      "z": -2,
      "name": "Rock_Ice"
    },
    {
      "x": -26,
      "y": 25,
      "z": -2,
      "name": "Rock_Ice"
    },
    {
      "x": -26,
      "y": 26,
      "z": -2,
      "name": "Rock_Ice"
    },
    {
      "x": -26,
      "y": 27,
      "z": -2,
      "name": "Rock_Ice"
    },
    {
      "x": -26,
      "y": 28,
      "z": -2,
      "name": "Rock_Ice"
    },
    {
      "x": -26,
      "y": 29,
      "z": -2,
      "name": "Rock_Ice"
    },
    {
      "x": -26,
      "y": 30,
      "z": -2,
      "name": "Rock_Ice"
    },
    {
      "x": -26,
      "y": 31,
      "z": -2,
      "name": "Rock_Ice"
    },
    {
      "x": -26,
      "y": 32,
      "z": -2,
      "name": "Rock_Ice"
    },
    {
      "x": -26,
      "y": 33,
      "z": -2,
      "name": "Rock_Ice"
    },
    {
      "x": -26,
      "y": 34,
      "z": -2,
      "name": "Rock_Ice_Permafrost"
    },
    {
      "x": -26,
      "y": 35,
      "z": -2,
      "name": "Rock_Ice_Permafrost"
    },
    {
      "x": -26,
      "y": 36,
      "z": -2,
      "name": "Rock_Ice_Permafrost"
    },
    {
      "x": -26,
      "y": 37,
      "z": -2,
      "name": "Rock_Ice_Permafrost"
    },
    {
      "x": -26,
      "y": 38,
      "z": -2,
      "name": "Rock_Ice_Permafrost"
    },
    {
      "x": -26,
      "y": 39,
      "z": -2,
      "name": "Rock_Ice_Permafrost"
    },
    {
      "x": -26,
      "y": 40,
      "z": -2,
      "name": "Rock_Ice_Permafrost"
    },
    {
      "x": -26,
      "y": 41,
      "z": -2,
      "name": "Rock_Ice_Permafrost"
    },
    {
      "x": -26,
      "y": 42,
      "z": -2,
      "name": "Rock_Ice_Permafrost"
    },
    {
      "x": -26,
      "y": 43,
      "z": -2,
      "name": "Rock_Ice_Permafrost"
    },
    {
      "x": -26,
      "y": 44,
      "z": -2,
      "name": "Soil_Snow"
    },
    {
      "x": -26,
      "y": 22,
      "z": -1,
      "name": "Rock_Ice"
    },
    {
      "x": -26,
      "y": 23,
      "z": -1,
      "name": "Rock_Ice"
    },
    {
      "x": -26,
      "y": 24,
      "z": -1,
      "name": "Rock_Ice"
    },
    {
      "x": -26,
      "y": 25,
      "z": -1,
      "name": "Rock_Ice_Permafrost"
    },
    {
      "x": -26,
      "y": 26,
      "z": -1,
      "name": "Rock_Ice"
    },
    {
      "x": -26,
      "y": 27,
      "z": -1,
      "name": "Rock_Ice_Permafrost"
    },
    {
      "x": -26,
      "y": 28,
      "z": -1,
      "name": "Rock_Ice_Permafrost"
    },
    {
      "x": -26,
      "y": 29,
      "z": -1,
      "name": "Rock_Ice_Permafrost"
    },
    {
      "x": -26,
      "y": 30,
      "z": -1,
      "name": "Rock_Ice_Permafrost"
    },
    {
      "x": -26,
      "y": 31,
      "z": -1,
      "name": "Rock_Ice_Permafrost"
    },
    {
      "x": -26,
      "y": 32,
      "z": -1,
      "name": "Rock_Ice_Permafrost"
    },
    {
      "x": -26,
      "y": 33,
      "z": -1,
      "name": "Rock_Ice_Permafrost"
    },
    {
      "x": -26,
      "y": 34,
      "z": -1,
      "name": "Rock_Ice"
    },
    {
      "x": -26,
      "y": 35,
      "z": -1,
      "name": "Rock_Ice"
    },
    {
      "x": -26,
      "y": 36,
      "z": -1,
      "name": "Rock_Ice"
    },
    {
      "x": -26,
      "y": 37,
      "z": -1,
      "name": "Rock_Ice_Permafrost"
    },
    {
      "x": -26,
      "y": 38,
      "z": -1,
      "name": "Rock_Ice"
    },
    {
      "x": -26,
      "y": 39,
      "z": -1,
      "name": "Rock_Ice"
    },
    {
      "x": -26,
      "y": 40,
      "z": -1,
      "name": "Rock_Ice"
    },
    {
      "x": -26,
      "y": 41,
      "z": -1,
      "name": "Rock_Ice"
    },
    {
      "x": -26,
      "y": 42,
      "z": -1,
      "name": "Rock_Ice"
    },
    {
      "x": -26,
      "y": 43,
      "z": -1,
      "name": "Rock_Ice"
    },
    {
      "x": -26,
      "y": 44,
      "z": -1,
      "name": "Soil_Snow"
    },
    {
      "x": -26,
      "y": 23,
      "z": 0,
      "name": "Rock_Ice_Permafrost"
    },
    {
      "x": -26,
      "y": 24,
      "z": 0,
      "name": "Rock_Ice_Permafrost"
    },
    {
      "x": -26,
      "y": 25,
      "z": 0,
      "name": "Rock_Ice_Permafrost"
    },
    {
      "x": -26,
      "y": 26,
      "z": 0,
      "name": "Rock_Ice_Permafrost"
    },
    {
      "x": -26,
      "y": 27,
      "z": 0,
      "name": "Rock_Ice_Permafrost"
    },
    {
      "x": -26,
      "y": 28,
      "z": 0,
      "name": "Rock_Ice_Permafrost"
    },
    {
      "x": -26,
      "y": 29,
      "z": 0,
      "name": "Rock_Ice_Permafrost"
    },
    {
      "x": -26,
      "y": 30,
      "z": 0,
      "name": "Rock_Ice_Permafrost"
    },
    {
      "x": -26,
      "y": 31,
      "z": 0,
      "name": "Rock_Ice"
    },
    {
      "x": -26,
      "y": 32,
      "z": 0,
      "name": "Rock_Ice"
    },
    {
      "x": -26,
      "y": 33,
      "z": 0,
      "name": "Rock_Ice"
    },
    {
      "x": -26,
      "y": 34,
      "z": 0,
      "name": "Rock_Ice"
    },
    {
      "x": -26,
      "y": 35,
      "z": 0,
      "name": "Rock_Ice"
    },
    {
      "x": -26,
      "y": 36,
      "z": 0,
      "name": "Rock_Ice"
    },
    {
      "x": -26,
      "y": 37,
      "z": 0,
      "name": "Rock_Ice"
    },
    {
      "x": -26,
      "y": 38,
      "z": 0,
      "name": "Rock_Ice"
    },
    {
      "x": -26,
      "y": 39,
      "z": 0,
      "name": "Rock_Ice"
    },
    {
      "x": -26,
      "y": 40,
      "z": 0,
      "name": "Rock_Ice"
    },
    {
      "x": -26,
      "y": 41,
      "z": 0,
      "name": "Rock_Ice"
    },
    {
      "x": -26,
      "y": 42,
      "z": 0,
      "name": "Rock_Ice"
    },
    {
      "x": -26,
      "y": 43,
      "z": 0,
      "name": "Soil_Snow"
    },
    {
      "x": -26,
      "y": 23,
      "z": 1,
      "name": "Rock_Ice_Permafrost"
    },
    {
      "x": -26,
      "y": 24,
      "z": 1,
      "name": "Rock_Ice_Permafrost"
    },
    {
      "x": -26,
      "y": 25,
      "z": 1,
      "name": "Rock_Ice_Permafrost"
    },
    {
      "x": -26,
      "y": 26,
      "z": 1,
      "name": "Rock_Ice_Permafrost"
    },
    {
      "x": -26,
      "y": 27,
      "z": 1,
      "name": "Rock_Ice"
    },
    {
      "x": -26,
      "y": 28,
      "z": 1,
      "name": "Rock_Ice"
    },
    {
      "x": -26,
      "y": 29,
      "z": 1,
      "name": "Rock_Ice"
    },
    {
      "x": -26,
      "y": 30,
      "z": 1,
      "name": "Rock_Ice"
    },
    {
      "x": -26,
      "y": 31,
      "z": 1,
      "name": "Rock_Ice"
    },
    {
      "x": -26,
      "y": 32,
      "z": 1,
      "name": "Rock_Ice"
    },
    {
      "x": -26,
      "y": 33,
      "z": 1,
      "name": "Rock_Ice"
    },
    {
      "x": -26,
      "y": 34,
      "z": 1,
      "name": "Rock_Ice"
    },
    {
      "x": -26,
      "y": 35,
      "z": 1,
      "name": "Rock_Ice"
    },
    {
      "x": -26,
      "y": 36,
      "z": 1,
      "name": "Rock_Ice"
    },
    {
      "x": -26,
      "y": 37,
      "z": 1,
      "name": "Rock_Ice"
    },
    {
      "x": -26,
      "y": 38,
      "z": 1,
      "name": "Rock_Ice"
    },
    {
      "x": -26,
      "y": 39,
      "z": 1,
      "name": "Rock_Ice"
    },
    {
      "x": -26,
      "y": 40,
      "z": 1,
      "name": "Rock_Ice"
    },
    {
      "x": -26,
      "y": 41,
      "z": 1,
      "name": "Soil_Snow"
    },
    {
      "x": -26,
      "y": 24,
      "z": 2,
      "name": "Rock_Ice_Permafrost"
    },
    {
      "x": -26,
      "y": 25,
      "z": 2,
      "name": "Rock_Ice_Permafrost"
    },
    {
      "x": -26,
      "y": 26,
      "z": 2,
      "name": "Rock_Ice_Permafrost"
    },
    {
      "x": -26,
      "y": 27,
      "z": 2,
      "name": "Rock_Ice_Permafrost"
    },
    {
      "x": -26,
      "y": 28,
      "z": 2,
      "name": "Rock_Ice"
    },
    {
      "x": -26,
      "y": 29,
      "z": 2,
      "name": "Rock_Ice"
    },
    {
      "x": -26,
      "y": 30,
      "z": 2,
      "name": "Rock_Ice"
    },
    {
      "x": -26,
      "y": 31,
      "z": 2,
      "name": "Rock_Ice"
    },
    {
      "x": -26,
      "y": 32,
      "z": 2,
      "name": "Rock_Ice"
    },
    {
      "x": -26,
      "y": 33,
      "z": 2,
      "name": "Rock_Ice"
    },
    {
      "x": -26,
      "y": 34,
      "z": 2,
      "name": "Rock_Ice"
    },
    {
      "x": -26,
      "y": 35,
      "z": 2,
      "name": "Rock_Ice"
    },
    {
      "x": -26,
      "y": 36,
      "z": 2,
      "name": "Rock_Ice"
    },
    {
      "x": -26,
      "y": 37,
      "z": 2,
      "name": "Rock_Ice"
    },
    {
      "x": -26,
      "y": 38,
      "z": 2,
      "name": "Rock_Ice"
    },
    {
      "x": -26,
      "y": 39,
      "z": 2,
      "name": "Soil_Snow"
    },
    {
      "x": -26,
      "y": 25,
      "z": 3,
      "name": "Rock_Ice_Permafrost"
    },
    {
      "x": -26,
      "y": 26,
      "z": 3,
      "name": "Rock_Ice_Permafrost"
    },
    {
      "x": -26,
      "y": 27,
      "z": 3,
      "name": "Rock_Ice_Permafrost"
    },
    {
      "x": -26,
      "y": 28,
      "z": 3,
      "name": "Rock_Ice"
    },
    {
      "x": -26,
      "y": 29,
      "z": 3,
      "name": "Rock_Ice"
    },
    {
      "x": -26,
      "y": 30,
      "z": 3,
      "name": "Rock_Ice"
    },
    {
      "x": -26,
      "y": 31,
      "z": 3,
      "name": "Rock_Ice"
    },
    {
      "x": -26,
      "y": 32,
      "z": 3,
      "name": "Rock_Ice"
    },
    {
      "x": -26,
      "y": 33,
      "z": 3,
      "name": "Rock_Ice"
    },
    {
      "x": -26,
      "y": 34,
      "z": 3,
      "name": "Rock_Ice"
    },
    {
      "x": -26,
      "y": 35,
      "z": 3,
      "name": "Rock_Ice"
    },
    {
      "x": -26,
      "y": 36,
      "z": 3,
      "name": "Rock_Ice"
    },
    {
      "x": -26,
      "y": 37,
      "z": 3,
      "name": "Rock_Ice"
    },
    {
      "x": -26,
      "y": 38,
      "z": 3,
      "name": "Soil_Snow"
    },
    {
      "x": -26,
      "y": 26,
      "z": 4,
      "name": "Rock_Ice_Permafrost"
    },
    {
      "x": -26,
      "y": 27,
      "z": 4,
      "name": "Rock_Ice"
    },
    {
      "x": -26,
      "y": 28,
      "z": 4,
      "name": "Rock_Ice"
    },
    {
      "x": -26,
      "y": 29,
      "z": 4,
      "name": "Rock_Ice"
    },
    {
      "x": -26,
      "y": 30,
      "z": 4,
      "name": "Rock_Ice"
    },
    {
      "x": -26,
      "y": 31,
      "z": 4,
      "name": "Rock_Ice"
    },
    {
      "x": -26,
      "y": 32,
      "z": 4,
      "name": "Rock_Ice"
    },
    {
      "x": -26,
      "y": 33,
      "z": 4,
      "name": "Rock_Ice"
    },
    {
      "x": -26,
      "y": 34,
      "z": 4,
      "name": "Rock_Ice"
    },
    {
      "x": -26,
      "y": 35,
      "z": 4,
      "name": "Rock_Ice"
    },
    {
      "x": -26,
      "y": 36,
      "z": 4,
      "name": "Rock_Ice"
    },
    {
      "x": -26,
      "y": 37,
      "z": 4,
      "name": "Rock_Ice"
    },
    {
      "x": -26,
      "y": 38,
      "z": 4,
      "name": "Soil_Snow"
    },
    {
      "x": -26,
      "y": 27,
      "z": 5,
      "name": "Rock_Ice_Permafrost"
    },
    {
      "x": -26,
      "y": 28,
      "z": 5,
      "name": "Rock_Ice"
    },
    {
      "x": -26,
      "y": 29,
      "z": 5,
      "name": "Rock_Ice"
    },
    {
      "x": -26,
      "y": 30,
      "z": 5,
      "name": "Rock_Ice"
    },
    {
      "x": -26,
      "y": 31,
      "z": 5,
      "name": "Rock_Ice"
    },
    {
      "x": -26,
      "y": 32,
      "z": 5,
      "name": "Rock_Ice"
    },
    {
      "x": -26,
      "y": 33,
      "z": 5,
      "name": "Rock_Ice"
    },
    {
      "x": -26,
      "y": 34,
      "z": 5,
      "name": "Rock_Ice"
    },
    {
      "x": -26,
      "y": 35,
      "z": 5,
      "name": "Rock_Ice"
    },
    {
      "x": -26,
      "y": 36,
      "z": 5,
      "name": "Rock_Ice"
    },
    {
      "x": -26,
      "y": 37,
      "z": 5,
      "name": "Rock_Ice"
    },
    {
      "x": -26,
      "y": 38,
      "z": 5,
      "name": "Soil_Snow"
    },
    {
      "x": -26,
      "y": 28,
      "z": 6,
      "name": "Rock_Ice_Permafrost"
    },
    {
      "x": -26,
      "y": 29,
      "z": 6,
      "name": "Rock_Ice"
    },
    {
      "x": -26,
      "y": 30,
      "z": 6,
      "name": "Rock_Ice"
    },
    {
      "x": -26,
      "y": 31,
      "z": 6,
      "name": "Rock_Ice"
    },
    {
      "x": -26,
      "y": 32,
      "z": 6,
      "name": "Rock_Ice"
    },
    {
      "x": -26,
      "y": 33,
      "z": 6,
      "name": "Rock_Ice"
    },
    {
      "x": -26,
      "y": 34,
      "z": 6,
      "name": "Rock_Ice"
    },
    {
      "x": -26,
      "y": 35,
      "z": 6,
      "name": "Rock_Ice"
    },
    {
      "x": -26,
      "y": 36,
      "z": 6,
      "name": "Rock_Ice"
    },
    {
      "x": -26,
      "y": 37,
      "z": 6,
      "name": "Rock_Ice"
    },
    {
      "x": -26,
      "y": 38,
      "z": 6,
      "name": "Soil_Snow"
    },
    {
      "x": -26,
      "y": 29,
      "z": 7,
      "name": "Rock_Ice_Permafrost"
    },
    {
      "x": -26,
      "y": 30,
      "z": 7,
      "name": "Rock_Ice"
    },
    {
      "x": -26,
      "y": 31,
      "z": 7,
      "name": "Rock_Ice"
    },
    {
      "x": -26,
      "y": 32,
      "z": 7,
      "name": "Rock_Ice"
    },
    {
      "x": -26,
      "y": 33,
      "z": 7,
      "name": "Rock_Ice"
    },
    {
      "x": -26,
      "y": 34,
      "z": 7,
      "name": "Rock_Ice"
    },
    {
      "x": -26,
      "y": 35,
      "z": 7,
      "name": "Rock_Ice"
    },
    {
      "x": -26,
      "y": 36,
      "z": 7,
      "name": "Rock_Ice"
    },
    {
      "x": -26,
      "y": 37,
      "z": 7,
      "name": "Soil_Snow"
    },
    {
      "x": -26,
      "y": 33,
      "z": 8,
      "name": "Rock_Ice"
    },
    {
      "x": -26,
      "y": 34,
      "z": 8,
      "name": "Rock_Ice_Permafrost"
    },
    {
      "x": -26,
      "y": 35,
      "z": 8,
      "name": "Soil_Snow"
    },
    {
      "x": -26,
      "y": 34,
      "z": 9,
      "name": "Rock_Ice_Permafrost"
    },
    {
      "x": -26,
      "y": 35,
      "z": 9,
      "name": "Rock_Ice_Permafrost"
    },
    {
      "x": -26,
      "y": 36,
      "z": 9,
      "name": "Soil_Snow"
    },
    {
      "x": -26,
      "y": 34,
      "z": 10,
      "name": "Rock_Ice"
    },
    {
      "x": -26,
      "y": 35,
      "z": 10,
      "name": "Rock_Ice"
    },
    {
      "x": -26,
      "y": 36,
      "z": 10,
      "name": "Rock_Ice"
    },
    {
      "x": -26,
      "y": 37,
      "z": 10,
      "name": "Rock_Ice"
    },
    {
      "x": -26,
      "y": 38,
      "z": 10,
      "name": "Soil_Snow"
    },
    {
      "x": -26,
      "y": 35,
      "z": 11,
      "name": "Rock_Ice"
    },
    {
      "x": -26,
      "y": 36,
      "z": 11,
      "name": "Soil_Snow"
    },
    {
      "x": -25,
      "y": 38,
      "z": -21,
      "name": "Rock_Ice"
    },
    {
      "x": -25,
      "y": 39,
      "z": -21,
      "name": "Rock_Ice"
    },
    {
      "x": -25,
      "y": 40,
      "z": -21,
      "name": "Rock_Ice"
    },
    {
      "x": -25,
      "y": 41,
      "z": -21,
      "name": "Rock_Ice"
    },
    {
      "x": -25,
      "y": 42,
      "z": -21,
      "name": "Soil_Snow"
    },
    {
      "x": -25,
      "y": 35,
      "z": -20,
      "name": "Rock_Ice"
    },
    {
      "x": -25,
      "y": 36,
      "z": -20,
      "name": "Rock_Ice"
    },
    {
      "x": -25,
      "y": 37,
      "z": -20,
      "name": "Rock_Ice"
    },
    {
      "x": -25,
      "y": 38,
      "z": -20,
      "name": "Rock_Ice"
    },
    {
      "x": -25,
      "y": 39,
      "z": -20,
      "name": "Rock_Ice"
    },
    {
      "x": -25,
      "y": 40,
      "z": -20,
      "name": "Rock_Ice"
    },
    {
      "x": -25,
      "y": 41,
      "z": -20,
      "name": "Rock_Ice"
    },
    {
      "x": -25,
      "y": 42,
      "z": -20,
      "name": "Rock_Ice"
    },
    {
      "x": -25,
      "y": 43,
      "z": -20,
      "name": "Soil_Snow"
    },
    {
      "x": -25,
      "y": 35,
      "z": -19,
      "name": "Rock_Ice"
    },
    {
      "x": -25,
      "y": 36,
      "z": -19,
      "name": "Rock_Ice"
    },
    {
      "x": -25,
      "y": 37,
      "z": -19,
      "name": "Rock_Ice"
    },
    {
      "x": -25,
      "y": 38,
      "z": -19,
      "name": "Rock_Ice"
    },
    {
      "x": -25,
      "y": 39,
      "z": -19,
      "name": "Rock_Ice"
    },
    {
      "x": -25,
      "y": 40,
      "z": -19,
      "name": "Rock_Ice"
    },
    {
      "x": -25,
      "y": 41,
      "z": -19,
      "name": "Rock_Ice"
    },
    {
      "x": -25,
      "y": 42,
      "z": -19,
      "name": "Soil_Snow"
    },
    {
      "x": -25,
      "y": 35,
      "z": -18,
      "name": "Rock_Ice"
    },
    {
      "x": -25,
      "y": 36,
      "z": -18,
      "name": "Rock_Ice"
    },
    {
      "x": -25,
      "y": 37,
      "z": -18,
      "name": "Rock_Ice"
    },
    {
      "x": -25,
      "y": 38,
      "z": -18,
      "name": "Rock_Ice"
    },
    {
      "x": -25,
      "y": 39,
      "z": -18,
      "name": "Rock_Ice"
    },
    {
      "x": -25,
      "y": 40,
      "z": -18,
      "name": "Rock_Ice"
    },
    {
      "x": -25,
      "y": 41,
      "z": -18,
      "name": "Rock_Ice"
    },
    {
      "x": -25,
      "y": 42,
      "z": -18,
      "name": "Soil_Snow"
    },
    {
      "x": -25,
      "y": 34,
      "z": -17,
      "name": "Rock_Ice"
    },
    {
      "x": -25,
      "y": 35,
      "z": -17,
      "name": "Rock_Ice"
    },
    {
      "x": -25,
      "y": 36,
      "z": -17,
      "name": "Rock_Ice"
    },
    {
      "x": -25,
      "y": 37,
      "z": -17,
      "name": "Rock_Ice"
    },
    {
      "x": -25,
      "y": 38,
      "z": -17,
      "name": "Rock_Ice"
    },
    {
      "x": -25,
      "y": 39,
      "z": -17,
      "name": "Rock_Ice"
    },
    {
      "x": -25,
      "y": 40,
      "z": -17,
      "name": "Rock_Ice"
    },
    {
      "x": -25,
      "y": 41,
      "z": -17,
      "name": "Soil_Snow"
    },
    {
      "x": -25,
      "y": 34,
      "z": -16,
      "name": "Rock_Ice"
    },
    {
      "x": -25,
      "y": 35,
      "z": -16,
      "name": "Rock_Ice"
    },
    {
      "x": -25,
      "y": 36,
      "z": -16,
      "name": "Rock_Ice"
    },
    {
      "x": -25,
      "y": 37,
      "z": -16,
      "name": "Rock_Ice"
    },
    {
      "x": -25,
      "y": 38,
      "z": -16,
      "name": "Rock_Ice"
    },
    {
      "x": -25,
      "y": 39,
      "z": -16,
      "name": "Rock_Ice"
    },
    {
      "x": -25,
      "y": 40,
      "z": -16,
      "name": "Rock_Ice"
    },
    {
      "x": -25,
      "y": 41,
      "z": -16,
      "name": "Soil_Snow"
    },
    {
      "x": -25,
      "y": 33,
      "z": -15,
      "name": "Rock_Ice"
    },
    {
      "x": -25,
      "y": 34,
      "z": -15,
      "name": "Rock_Ice"
    },
    {
      "x": -25,
      "y": 35,
      "z": -15,
      "name": "Rock_Ice"
    },
    {
      "x": -25,
      "y": 36,
      "z": -15,
      "name": "Rock_Ice"
    },
    {
      "x": -25,
      "y": 37,
      "z": -15,
      "name": "Rock_Ice"
    },
    {
      "x": -25,
      "y": 38,
      "z": -15,
      "name": "Rock_Ice"
    },
    {
      "x": -25,
      "y": 39,
      "z": -15,
      "name": "Rock_Ice"
    },
    {
      "x": -25,
      "y": 40,
      "z": -15,
      "name": "Rock_Ice"
    },
    {
      "x": -25,
      "y": 41,
      "z": -15,
      "name": "Soil_Snow"
    },
    {
      "x": -25,
      "y": 33,
      "z": -14,
      "name": "Rock_Ice"
    },
    {
      "x": -25,
      "y": 34,
      "z": -14,
      "name": "Rock_Ice"
    },
    {
      "x": -25,
      "y": 35,
      "z": -14,
      "name": "Rock_Ice"
    },
    {
      "x": -25,
      "y": 36,
      "z": -14,
      "name": "Rock_Ice"
    },
    {
      "x": -25,
      "y": 37,
      "z": -14,
      "name": "Rock_Ice"
    },
    {
      "x": -25,
      "y": 38,
      "z": -14,
      "name": "Rock_Ice"
    },
    {
      "x": -25,
      "y": 39,
      "z": -14,
      "name": "Rock_Ice"
    },
    {
      "x": -25,
      "y": 40,
      "z": -14,
      "name": "Soil_Snow"
    },
    {
      "x": -25,
      "y": 33,
      "z": -13,
      "name": "Rock_Ice"
    },
    {
      "x": -25,
      "y": 34,
      "z": -13,
      "name": "Rock_Ice"
    },
    {
      "x": -25,
      "y": 35,
      "z": -13,
      "name": "Rock_Ice"
    },
    {
      "x": -25,
      "y": 36,
      "z": -13,
      "name": "Rock_Ice"
    },
    {
      "x": -25,
      "y": 37,
      "z": -13,
      "name": "Rock_Ice"
    },
    {
      "x": -25,
      "y": 38,
      "z": -13,
      "name": "Rock_Ice"
    },
    {
      "x": -25,
      "y": 39,
      "z": -13,
      "name": "Rock_Ice_Permafrost"
    },
    {
      "x": -25,
      "y": 40,
      "z": -13,
      "name": "Soil_Snow"
    },
    {
      "x": -25,
      "y": 32,
      "z": -12,
      "name": "Rock_Ice_Permafrost"
    },
    {
      "x": -25,
      "y": 33,
      "z": -12,
      "name": "Rock_Ice_Permafrost"
    },
    {
      "x": -25,
      "y": 34,
      "z": -12,
      "name": "Rock_Ice_Permafrost"
    },
    {
      "x": -25,
      "y": 35,
      "z": -12,
      "name": "Rock_Ice_Permafrost"
    },
    {
      "x": -25,
      "y": 36,
      "z": -12,
      "name": "Rock_Ice_Permafrost"
    },
    {
      "x": -25,
      "y": 37,
      "z": -12,
      "name": "Rock_Ice_Permafrost"
    },
    {
      "x": -25,
      "y": 38,
      "z": -12,
      "name": "Rock_Ice_Permafrost"
    },
    {
      "x": -25,
      "y": 39,
      "z": -12,
      "name": "Rock_Ice"
    },
    {
      "x": -25,
      "y": 40,
      "z": -12,
      "name": "Soil_Snow"
    },
    {
      "x": -25,
      "y": 31,
      "z": -11,
      "name": "Rock_Ice_Permafrost"
    },
    {
      "x": -25,
      "y": 32,
      "z": -11,
      "name": "Rock_Ice"
    },
    {
      "x": -25,
      "y": 33,
      "z": -11,
      "name": "Rock_Ice_Permafrost"
    },
    {
      "x": -25,
      "y": 34,
      "z": -11,
      "name": "Rock_Ice"
    },
    {
      "x": -25,
      "y": 35,
      "z": -11,
      "name": "Rock_Ice"
    },
    {
      "x": -25,
      "y": 36,
      "z": -11,
      "name": "Rock_Ice"
    },
    {
      "x": -25,
      "y": 37,
      "z": -11,
      "name": "Rock_Ice"
    },
    {
      "x": -25,
      "y": 38,
      "z": -11,
      "name": "Rock_Ice"
    },
    {
      "x": -25,
      "y": 39,
      "z": -11,
      "name": "Rock_Ice"
    },
    {
      "x": -25,
      "y": 40,
      "z": -11,
      "name": "Soil_Snow"
    },
    {
      "x": -25,
      "y": 31,
      "z": -10,
      "name": "Rock_Ice"
    },
    {
      "x": -25,
      "y": 32,
      "z": -10,
      "name": "Rock_Ice"
    },
    {
      "x": -25,
      "y": 33,
      "z": -10,
      "name": "Rock_Ice"
    },
    {
      "x": -25,
      "y": 34,
      "z": -10,
      "name": "Rock_Ice"
    },
    {
      "x": -25,
      "y": 35,
      "z": -10,
      "name": "Rock_Ice"
    },
    {
      "x": -25,
      "y": 36,
      "z": -10,
      "name": "Rock_Ice"
    },
    {
      "x": -25,
      "y": 37,
      "z": -10,
      "name": "Rock_Ice"
    },
    {
      "x": -25,
      "y": 38,
      "z": -10,
      "name": "Rock_Ice"
    },
    {
      "x": -25,
      "y": 39,
      "z": -10,
      "name": "Rock_Ice"
    },
    {
      "x": -25,
      "y": 40,
      "z": -10,
      "name": "Soil_Snow"
    },
    {
      "x": -25,
      "y": 30,
      "z": -9,
      "name": "Rock_Ice"
    },
    {
      "x": -25,
      "y": 31,
      "z": -9,
      "name": "Rock_Ice"
    },
    {
      "x": -25,
      "y": 32,
      "z": -9,
      "name": "Rock_Ice"
    },
    {
      "x": -25,
      "y": 33,
      "z": -9,
      "name": "Rock_Ice"
    },
    {
      "x": -25,
      "y": 34,
      "z": -9,
      "name": "Rock_Ice"
    },
    {
      "x": -25,
      "y": 35,
      "z": -9,
      "name": "Rock_Ice"
    },
    {
      "x": -25,
      "y": 36,
      "z": -9,
      "name": "Rock_Ice"
    },
    {
      "x": -25,
      "y": 37,
      "z": -9,
      "name": "Rock_Ice"
    },
    {
      "x": -25,
      "y": 38,
      "z": -9,
      "name": "Rock_Ice"
    },
    {
      "x": -25,
      "y": 39,
      "z": -9,
      "name": "Rock_Ice"
    },
    {
      "x": -25,
      "y": 40,
      "z": -9,
      "name": "Soil_Snow"
    },
    {
      "x": -25,
      "y": 28,
      "z": -8,
      "name": "Rock_Ice"
    },
    {
      "x": -25,
      "y": 29,
      "z": -8,
      "name": "Rock_Ice"
    },
    {
      "x": -25,
      "y": 30,
      "z": -8,
      "name": "Rock_Ice"
    },
    {
      "x": -25,
      "y": 31,
      "z": -8,
      "name": "Rock_Ice"
    },
    {
      "x": -25,
      "y": 32,
      "z": -8,
      "name": "Rock_Ice"
    },
    {
      "x": -25,
      "y": 33,
      "z": -8,
      "name": "Rock_Ice"
    },
    {
      "x": -25,
      "y": 34,
      "z": -8,
      "name": "Rock_Ice"
    },
    {
      "x": -25,
      "y": 35,
      "z": -8,
      "name": "Rock_Ice"
    },
    {
      "x": -25,
      "y": 36,
      "z": -8,
      "name": "Rock_Ice"
    },
    {
      "x": -25,
      "y": 37,
      "z": -8,
      "name": "Rock_Ice"
    },
    {
      "x": -25,
      "y": 38,
      "z": -8,
      "name": "Rock_Ice"
    },
    {
      "x": -25,
      "y": 39,
      "z": -8,
      "name": "Rock_Ice"
    },
    {
      "x": -25,
      "y": 40,
      "z": -8,
      "name": "Soil_Snow"
    },
    {
      "x": -25,
      "y": 27,
      "z": -7,
      "name": "Rock_Ice"
    },
    {
      "x": -25,
      "y": 28,
      "z": -7,
      "name": "Rock_Ice"
    },
    {
      "x": -25,
      "y": 29,
      "z": -7,
      "name": "Rock_Ice"
    },
    {
      "x": -25,
      "y": 30,
      "z": -7,
      "name": "Rock_Ice"
    },
    {
      "x": -25,
      "y": 31,
      "z": -7,
      "name": "Rock_Ice"
    },
    {
      "x": -25,
      "y": 32,
      "z": -7,
      "name": "Rock_Ice"
    },
    {
      "x": -25,
      "y": 33,
      "z": -7,
      "name": "Rock_Ice"
    },
    {
      "x": -25,
      "y": 34,
      "z": -7,
      "name": "Rock_Ice"
    },
    {
      "x": -25,
      "y": 35,
      "z": -7,
      "name": "Rock_Ice"
    },
    {
      "x": -25,
      "y": 36,
      "z": -7,
      "name": "Rock_Ice"
    },
    {
      "x": -25,
      "y": 37,
      "z": -7,
      "name": "Rock_Ice"
    },
    {
      "x": -25,
      "y": 38,
      "z": -7,
      "name": "Rock_Ice"
    },
    {
      "x": -25,
      "y": 39,
      "z": -7,
      "name": "Rock_Ice"
    },
    {
      "x": -25,
      "y": 40,
      "z": -7,
      "name": "Soil_Snow"
    },
    {
      "x": -25,
      "y": 25,
      "z": -6,
      "name": "Rock_Ice"
    },
    {
      "x": -25,
      "y": 26,
      "z": -6,
      "name": "Rock_Ice"
    },
    {
      "x": -25,
      "y": 27,
      "z": -6,
      "name": "Rock_Ice"
    },
    {
      "x": -25,
      "y": 28,
      "z": -6,
      "name": "Rock_Ice"
    },
    {
      "x": -25,
      "y": 29,
      "z": -6,
      "name": "Rock_Ice"
    },
    {
      "x": -25,
      "y": 30,
      "z": -6,
      "name": "Rock_Ice"
    },
    {
      "x": -25,
      "y": 31,
      "z": -6,
      "name": "Rock_Ice"
    },
    {
      "x": -25,
      "y": 32,
      "z": -6,
      "name": "Rock_Ice"
    },
    {
      "x": -25,
      "y": 33,
      "z": -6,
      "name": "Rock_Ice"
    },
    {
      "x": -25,
      "y": 34,
      "z": -6,
      "name": "Rock_Ice"
    },
    {
      "x": -25,
      "y": 35,
      "z": -6,
      "name": "Rock_Ice"
    },
    {
      "x": -25,
      "y": 36,
      "z": -6,
      "name": "Rock_Ice"
    },
    {
      "x": -25,
      "y": 37,
      "z": -6,
      "name": "Rock_Ice"
    },
    {
      "x": -25,
      "y": 38,
      "z": -6,
      "name": "Rock_Ice"
    },
    {
      "x": -25,
      "y": 39,
      "z": -6,
      "name": "Rock_Ice"
    },
    {
      "x": -25,
      "y": 40,
      "z": -6,
      "name": "Rock_Ice"
    },
    {
      "x": -25,
      "y": 41,
      "z": -6,
      "name": "Soil_Snow"
    },
    {
      "x": -25,
      "y": 23,
      "z": -5,
      "name": "Rock_Ice"
    },
    {
      "x": -25,
      "y": 24,
      "z": -5,
      "name": "Rock_Ice"
    },
    {
      "x": -25,
      "y": 25,
      "z": -5,
      "name": "Rock_Ice"
    },
    {
      "x": -25,
      "y": 26,
      "z": -5,
      "name": "Rock_Ice"
    },
    {
      "x": -25,
      "y": 27,
      "z": -5,
      "name": "Rock_Ice"
    },
    {
      "x": -25,
      "y": 28,
      "z": -5,
      "name": "Rock_Ice"
    },
    {
      "x": -25,
      "y": 29,
      "z": -5,
      "name": "Rock_Ice"
    },
    {
      "x": -25,
      "y": 30,
      "z": -5,
      "name": "Rock_Ice"
    },
    {
      "x": -25,
      "y": 31,
      "z": -5,
      "name": "Rock_Ice"
    },
    {
      "x": -25,
      "y": 32,
      "z": -5,
      "name": "Rock_Ice"
    },
    {
      "x": -25,
      "y": 33,
      "z": -5,
      "name": "Rock_Ice"
    },
    {
      "x": -25,
      "y": 34,
      "z": -5,
      "name": "Rock_Ice"
    },
    {
      "x": -25,
      "y": 35,
      "z": -5,
      "name": "Rock_Ice"
    },
    {
      "x": -25,
      "y": 36,
      "z": -5,
      "name": "Rock_Ice"
    },
    {
      "x": -25,
      "y": 37,
      "z": -5,
      "name": "Rock_Ice"
    },
    {
      "x": -25,
      "y": 38,
      "z": -5,
      "name": "Rock_Ice"
    },
    {
      "x": -25,
      "y": 39,
      "z": -5,
      "name": "Rock_Ice"
    },
    {
      "x": -25,
      "y": 40,
      "z": -5,
      "name": "Rock_Ice"
    },
    {
      "x": -25,
      "y": 41,
      "z": -5,
      "name": "Rock_Ice"
    },
    {
      "x": -25,
      "y": 42,
      "z": -5,
      "name": "Soil_Snow"
    },
    {
      "x": -25,
      "y": 18,
      "z": -4,
      "name": "Rock_Ice_Permafrost"
    },
    {
      "x": -25,
      "y": 19,
      "z": -4,
      "name": "Rock_Ice_Permafrost"
    },
    {
      "x": -25,
      "y": 20,
      "z": -4,
      "name": "Rock_Ice_Permafrost"
    },
    {
      "x": -25,
      "y": 21,
      "z": -4,
      "name": "Rock_Ice"
    },
    {
      "x": -25,
      "y": 22,
      "z": -4,
      "name": "Rock_Ice"
    },
    {
      "x": -25,
      "y": 23,
      "z": -4,
      "name": "Rock_Ice"
    },
    {
      "x": -25,
      "y": 24,
      "z": -4,
      "name": "Rock_Ice"
    },
    {
      "x": -25,
      "y": 25,
      "z": -4,
      "name": "Rock_Ice"
    },
    {
      "x": -25,
      "y": 26,
      "z": -4,
      "name": "Rock_Ice"
    },
    {
      "x": -25,
      "y": 27,
      "z": -4,
      "name": "Rock_Ice"
    },
    {
      "x": -25,
      "y": 28,
      "z": -4,
      "name": "Rock_Ice"
    },
    {
      "x": -25,
      "y": 29,
      "z": -4,
      "name": "Rock_Ice"
    },
    {
      "x": -25,
      "y": 30,
      "z": -4,
      "name": "Rock_Ice"
    },
    {
      "x": -25,
      "y": 31,
      "z": -4,
      "name": "Rock_Ice"
    },
    {
      "x": -25,
      "y": 32,
      "z": -4,
      "name": "Rock_Ice"
    },
    {
      "x": -25,
      "y": 33,
      "z": -4,
      "name": "Rock_Ice"
    },
    {
      "x": -25,
      "y": 34,
      "z": -4,
      "name": "Rock_Ice"
    },
    {
      "x": -25,
      "y": 35,
      "z": -4,
      "name": "Rock_Ice"
    },
    {
      "x": -25,
      "y": 36,
      "z": -4,
      "name": "Rock_Ice"
    },
    {
      "x": -25,
      "y": 37,
      "z": -4,
      "name": "Rock_Ice"
    },
    {
      "x": -25,
      "y": 38,
      "z": -4,
      "name": "Rock_Ice"
    },
    {
      "x": -25,
      "y": 39,
      "z": -4,
      "name": "Rock_Ice"
    },
    {
      "x": -25,
      "y": 40,
      "z": -4,
      "name": "Rock_Ice"
    },
    {
      "x": -25,
      "y": 41,
      "z": -4,
      "name": "Rock_Ice_Permafrost"
    },
    {
      "x": -25,
      "y": 42,
      "z": -4,
      "name": "Rock_Ice_Permafrost"
    },
    {
      "x": -25,
      "y": 43,
      "z": -4,
      "name": "Rock_Ice_Permafrost"
    },
    {
      "x": -25,
      "y": 44,
      "z": -4,
      "name": "Soil_Snow"
    },
    {
      "x": -25,
      "y": 19,
      "z": -3,
      "name": "Rock_Ice_Permafrost"
    },
    {
      "x": -25,
      "y": 20,
      "z": -3,
      "name": "Rock_Ice_Permafrost"
    },
    {
      "x": -25,
      "y": 21,
      "z": -3,
      "name": "Rock_Ice"
    },
    {
      "x": -25,
      "y": 22,
      "z": -3,
      "name": "Rock_Ice"
    },
    {
      "x": -25,
      "y": 23,
      "z": -3,
      "name": "Rock_Ice"
    },
    {
      "x": -25,
      "y": 24,
      "z": -3,
      "name": "Rock_Ice"
    },
    {
      "x": -25,
      "y": 25,
      "z": -3,
      "name": "Rock_Ice"
    },
    {
      "x": -25,
      "y": 26,
      "z": -3,
      "name": "Rock_Ice"
    },
    {
      "x": -25,
      "y": 27,
      "z": -3,
      "name": "Rock_Ice"
    },
    {
      "x": -25,
      "y": 28,
      "z": -3,
      "name": "Rock_Ice"
    },
    {
      "x": -25,
      "y": 29,
      "z": -3,
      "name": "Rock_Ice"
    },
    {
      "x": -25,
      "y": 30,
      "z": -3,
      "name": "Rock_Ice"
    },
    {
      "x": -25,
      "y": 31,
      "z": -3,
      "name": "Rock_Ice"
    },
    {
      "x": -25,
      "y": 32,
      "z": -3,
      "name": "Rock_Ice"
    },
    {
      "x": -25,
      "y": 33,
      "z": -3,
      "name": "Rock_Ice"
    },
    {
      "x": -25,
      "y": 34,
      "z": -3,
      "name": "Rock_Ice"
    },
    {
      "x": -25,
      "y": 35,
      "z": -3,
      "name": "Rock_Ice"
    },
    {
      "x": -25,
      "y": 36,
      "z": -3,
      "name": "Rock_Ice_Permafrost"
    },
    {
      "x": -25,
      "y": 37,
      "z": -3,
      "name": "Rock_Ice_Permafrost"
    },
    {
      "x": -25,
      "y": 38,
      "z": -3,
      "name": "Rock_Ice_Permafrost"
    },
    {
      "x": -25,
      "y": 39,
      "z": -3,
      "name": "Rock_Ice_Permafrost"
    },
    {
      "x": -25,
      "y": 40,
      "z": -3,
      "name": "Rock_Ice_Permafrost"
    },
    {
      "x": -25,
      "y": 41,
      "z": -3,
      "name": "Rock_Ice_Permafrost"
    },
    {
      "x": -25,
      "y": 42,
      "z": -3,
      "name": "Rock_Ice_Permafrost"
    },
    {
      "x": -25,
      "y": 43,
      "z": -3,
      "name": "Rock_Ice_Permafrost"
    },
    {
      "x": -25,
      "y": 44,
      "z": -3,
      "name": "Soil_Snow"
    },
    {
      "x": -25,
      "y": 20,
      "z": -2,
      "name": "Rock_Ice"
    },
    {
      "x": -25,
      "y": 21,
      "z": -2,
      "name": "Rock_Ice_Permafrost"
    },
    {
      "x": -25,
      "y": 22,
      "z": -2,
      "name": "Rock_Ice"
    },
    {
      "x": -25,
      "y": 23,
      "z": -2,
      "name": "Rock_Ice"
    },
    {
      "x": -25,
      "y": 24,
      "z": -2,
      "name": "Rock_Ice"
    },
    {
      "x": -25,
      "y": 25,
      "z": -2,
      "name": "Rock_Ice"
    },
    {
      "x": -25,
      "y": 26,
      "z": -2,
      "name": "Rock_Ice"
    },
    {
      "x": -25,
      "y": 27,
      "z": -2,
      "name": "Rock_Ice"
    },
    {
      "x": -25,
      "y": 28,
      "z": -2,
      "name": "Rock_Ice"
    },
    {
      "x": -25,
      "y": 29,
      "z": -2,
      "name": "Rock_Ice"
    },
    {
      "x": -25,
      "y": 30,
      "z": -2,
      "name": "Rock_Ice_Permafrost"
    },
    {
      "x": -25,
      "y": 31,
      "z": -2,
      "name": "Rock_Ice_Permafrost"
    },
    {
      "x": -25,
      "y": 32,
      "z": -2,
      "name": "Rock_Ice_Permafrost"
    },
    {
      "x": -25,
      "y": 33,
      "z": -2,
      "name": "Rock_Ice_Permafrost"
    },
    {
      "x": -25,
      "y": 34,
      "z": -2,
      "name": "Rock_Ice_Permafrost"
    },
    {
      "x": -25,
      "y": 35,
      "z": -2,
      "name": "Rock_Ice_Permafrost"
    },
    {
      "x": -25,
      "y": 36,
      "z": -2,
      "name": "Rock_Ice"
    },
    {
      "x": -25,
      "y": 37,
      "z": -2,
      "name": "Rock_Ice"
    },
    {
      "x": -25,
      "y": 38,
      "z": -2,
      "name": "Rock_Ice"
    },
    {
      "x": -25,
      "y": 39,
      "z": -2,
      "name": "Rock_Ice"
    },
    {
      "x": -25,
      "y": 40,
      "z": -2,
      "name": "Rock_Ice"
    },
    {
      "x": -25,
      "y": 41,
      "z": -2,
      "name": "Rock_Ice"
    },
    {
      "x": -25,
      "y": 42,
      "z": -2,
      "name": "Rock_Ice"
    },
    {
      "x": -25,
      "y": 43,
      "z": -2,
      "name": "Rock_Ice"
    },
    {
      "x": -25,
      "y": 44,
      "z": -2,
      "name": "Rock_Ice"
    },
    {
      "x": -25,
      "y": 45,
      "z": -2,
      "name": "Soil_Snow"
    },
    {
      "x": -25,
      "y": 21,
      "z": -1,
