{
  "version": 8,
  "blockIdVersion": 11,
  "anchorX": 0,
  "anchorY": 19,
  "anchorZ": -2,
  "blocks": [
    {
      "x": -26,
      "y": 45,
      "z": -5,
      "name": "Rock_Ice"
    },
    {
      "x": -26,
      "y": 46,
      "z": -5,
      "name": "Rock_Ice"
    },
    {
      "x": -26,
      "y": 47,
      "z": -5,
      "name": "Rock_Ice"
    },
    {
      "x": -26,
      "y": 48,
      "z": -5,
      "name": "Rock_Ice"
    },
    {
      "x": -26,
      "y": 49,
      "z": -5,
      "name": "Rock_Ice"
    },
    {
      "x": -26,
      "y": 50,
      "z": -5,
      "name": "Soil_Snow"
    },
    {
      "x": -26,
      "y": 45,
      "z": -4,
      "name": "Rock_Ice"
    },
    {
      "x": -26,
      "y": 46,
      "z": -4,
      "name": "Rock_Ice"
    },
    {
      "x": -26,
      "y": 47,
      "z": -4,
      "name": "Rock_Ice"
    },
    {
      "x": -26,
      "y": 48,
      "z": -4,
      "name": "Rock_Ice"
    },
    {
      "x": -26,
      "y": 49,
      "z": -4,
      "name": "Soil_Snow"
    },
    {
      "x": -26,
      "y": 45,
      "z": -3,
      "name": "Rock_Ice"
    },
    {
      "x": -26,
      "y": 46,
      "z": -3,
      "name": "Rock_Ice"
    },
    {
      "x": -26,
      "y": 47,
      "z": -3,
      "name": "Rock_Ice"
    },
    {
      "x": -26,
      "y": 48,
      "z": -3,
      "name": "Rock_Ice"
    },
    {
      "x": -26,
      "y": 49,
      "z": -3,
      "name": "Soil_Snow"
    },
    {
      "x": -26,
      "y": 30,
      "z": -2,
      "name": "Rock_Ice"
    },
    {
      "x": -26,
      "y": 31,
      "z": -2,
      "name": "Rock_Ice"
    },
    {
      "x": -26,
      "y": 32,
      "z": -2,
      "name": "Rock_Ice"
    },
    {
      "x": -26,
      "y": 33,
      "z": -2,
      "name": "Rock_Ice"
    },
    {
      "x": -26,
      "y": 46,
      "z": -2,
      "name": "Rock_Ice"
    },
    {
      "x": -26,
      "y": 47,
      "z": -2,
      "name": "Soil_Snow"
    },
    {
      "x": -26,
      "y": 32,
      "z": 2,
      "name": "Rock_Ice"
    },
    {
      "x": -26,
      "y": 33,
      "z": 2,
      "name": "Rock_Ice"
    },
    {
      "x": -26,
      "y": 34,
      "z": 2,
      "name": "Rock_Ice"
    },
    {
      "x": -26,
      "y": 35,
      "z": 2,
      "name": "Rock_Ice"
    },
    {
      "x": -26,
      "y": 36,
      "z": 2,
      "name": "Rock_Ice"
    },
    {
      "x": -26,
      "y": 37,
      "z": 2,
      "name": "Rock_Ice"
    },
    {
      "x": -26,
      "y": 38,
      "z": 2,
      "name": "Rock_Ice_Permafrost"
    },
    {
      "x": -26,
      "y": 34,
      "z": 3,
      "name": "Rock_Ice"
    },
    {
      "x": -26,
      "y": 35,
      "z": 3,
      "name": "Rock_Ice_Permafrost"
    },
    {
      "x": -26,
      "y": 36,
      "z": 3,
      "name": "Rock_Ice_Permafrost"
    },
    {
      "x": -26,
      "y": 37,
      "z": 3,
      "name": "Rock_Ice_Permafrost"
    },
    {
      "x": -26,
      "y": 38,
      "z": 3,
      "name": "Rock_Ice_Permafrost"
    },
    {
      "x": -26,
      "y": 35,
      "z": 4,
      "name": "Rock_Ice_Permafrost"
    },
    {
      "x": -26,
      "y": 36,
      "z": 4,
      "name": "Rock_Ice_Permafrost"
    },
    {
      "x": -26,
      "y": 37,
      "z": 4,
      "name": "Rock_Ice_Permafrost"
    },
    {
      "x": -26,
      "y": 38,
      "z": 4,
      "name": "Rock_Ice"
    },
    {
      "x": -25,
      "y": 43,
      "z": -10,
      "name": "Rock_Ice"
    },
    {
      "x": -25,
      "y": 44,
      "z": -10,
      "name": "Rock_Ice"
    },
    {
      "x": -25,
      "y": 45,
      "z": -10,
      "name": "Rock_Ice"
    },
    {
      "x": -25,
      "y": 46,
      "z": -10,
      "name": "Soil_Snow"
    },
    {
      "x": -25,
      "y": 42,
      "z": -9,
      "name": "Rock_Ice"
    },
    {
      "x": -25,
      "y": 43,
      "z": -9,
      "name": "Rock_Ice"
    },
    {
      "x": -25,
      "y": 44,
      "z": -9,
      "name": "Rock_Ice"
    },
    {
      "x": -25,
      "y": 45,
      "z": -9,
      "name": "Rock_Ice"
    },
    {
      "x": -25,
      "y": 46,
      "z": -9,
      "name": "Rock_Ice"
    },
    {
      "x": -25,
      "y": 47,
      "z": -9,
      "name": "Soil_Snow"
    },
    {
      "x": -25,
      "y": 41,
      "z": -8,
      "name": "Rock_Ice"
    },
    {
      "x": -25,
      "y": 42,
      "z": -8,
      "name": "Rock_Ice"
    },
    {
      "x": -25,
      "y": 43,
      "z": -8,
      "name": "Rock_Ice"
    },
    {
      "x": -25,
      "y": 44,
      "z": -8,
      "name": "Rock_Ice"
    },
    {
      "x": -25,
      "y": 45,
      "z": -8,
      "name": "Rock_Ice"
    },
    {
      "x": -25,
      "y": 46,
      "z": -8,
      "name": "Rock_Ice"
    },
    {
      "x": -25,
      "y": 47,
      "z": -8,
      "name": "Rock_Ice"
    },
    {
      "x": -25,
      "y": 48,
      "z": -8,
      "name": "Soil_Snow"
    },
    {
      "x": -25,
      "y": 29,
      "z": -7,
      "name": "Rock_Ice"
    },
    {
      "x": -25,
      "y": 30,
      "z": -7,
      "name": "Rock_Ice"
    },
    {
      "x": -25,
      "y": 31,
      "z": -7,
      "name": "Rock_Ice"
    },
    {
      "x": -25,
      "y": 32,
      "z": -7,
      "name": "Rock_Ice"
    },
    {
      "x": -25,
      "y": 33,
      "z": -7,
      "name": "Rock_Ice"
    },
    {
      "x": -25,
      "y": 40,
      "z": -7,
      "name": "Rock_Ice"
    },
    {
      "x": -25,
      "y": 41,
      "z": -7,
      "name": "Rock_Ice"
    },
    {
      "x": -25,
      "y": 42,
      "z": -7,
      "name": "Rock_Ice"
    },
    {
      "x": -25,
      "y": 43,
      "z": -7,
      "name": "Rock_Ice"
    },
    {
      "x": -25,
      "y": 44,
      "z": -7,
      "name": "Rock_Ice"
    },
    {
      "x": -25,
      "y": 45,
      "z": -7,
      "name": "Rock_Ice"
    },
    {
      "x": -25,
      "y": 46,
      "z": -7,
      "name": "Rock_Ice"
    },
    {
      "x": -25,
      "y": 47,
      "z": -7,
      "name": "Rock_Ice"
    },
    {
      "x": -25,
      "y": 48,
      "z": -7,
      "name": "Rock_Ice"
    },
    {
      "x": -25,
      "y": 49,
      "z": -7,
      "name": "Rock_Ice"
    },
    {
      "x": -25,
      "y": 50,
      "z": -7,
      "name": "Soil_Snow"
    },
    {
      "x": -25,
      "y": 27,
      "z": -6,
      "name": "Rock_Ice"
    },
    {
      "x": -25,
      "y": 28,
      "z": -6,
      "name": "Rock_Ice"
    },
    {
      "x": -25,
      "y": 29,
      "z": -6,
      "name": "Rock_Ice"
    },
    {
      "x": -25,
      "y": 30,
      "z": -6,
      "name": "Rock_Ice"
    },
    {
      "x": -25,
      "y": 31,
      "z": -6,
      "name": "Rock_Ice"
    },
    {
      "x": -25,
      "y": 32,
      "z": -6,
      "name": "Rock_Ice"
    },
    {
      "x": -25,
      "y": 33,
      "z": -6,
      "name": "Rock_Ice"
    },
    {
      "x": -25,
      "y": 34,
      "z": -6,
      "name": "Rock_Ice"
    },
    {
      "x": -25,
      "y": 35,
      "z": -6,
      "name": "Rock_Ice"
    },
    {
      "x": -25,
      "y": 40,
      "z": -6,
      "name": "Rock_Ice"
    },
    {
      "x": -25,
      "y": 41,
      "z": -6,
      "name": "Rock_Ice"
    },
    {
      "x": -25,
      "y": 42,
      "z": -6,
      "name": "Rock_Ice"
    },
    {
      "x": -25,
      "y": 43,
      "z": -6,
      "name": "Rock_Ice"
    },
    {
      "x": -25,
      "y": 44,
      "z": -6,
      "name": "Rock_Ice"
    },
    {
      "x": -25,
      "y": 45,
      "z": -6,
      "name": "Rock_Ice"
    },
    {
      "x": -25,
      "y": 46,
      "z": -6,
      "name": "Rock_Ice"
    },
    {
      "x": -25,
      "y": 47,
      "z": -6,
      "name": "Rock_Ice"
    },
    {
      "x": -25,
      "y": 48,
      "z": -6,
      "name": "Rock_Ice"
    },
    {
      "x": -25,
      "y": 49,
      "z": -6,
      "name": "Rock_Ice"
    },
    {
      "x": -25,
      "y": 50,
      "z": -6,
      "name": "Rock_Ice"
    },
    {
      "x": -25,
      "y": 51,
      "z": -6,
      "name": "Soil_Snow"
    },
    {
      "x": -25,
      "y": 19,
      "z": -5,
      "name": "Rock_Ice"
    },
    {
      "x": -25,
      "y": 20,
      "z": -5,
      "name": "Rock_Ice"
    },
    {
      "x": -25,
      "y": 21,
      "z": -5,
      "name": "Rock_Ice"
    },
    {
      "x": -25,
      "y": 22,
      "z": -5,
      "name": "Rock_Ice"
    },
    {
      "x": -25,
      "y": 23,
      "z": -5,
      "name": "Rock_Ice"
    },
    {
      "x": -25,
      "y": 24,
      "z": -5,
      "name": "Rock_Ice"
    },
    {
      "x": -25,
      "y": 25,
      "z": -5,
      "name": "Rock_Ice"
    },
    {
      "x": -25,
      "y": 26,
      "z": -5,
      "name": "Rock_Ice"
    },
    {
      "x": -25,
      "y": 27,
      "z": -5,
      "name": "Rock_Ice"
    },
    {
      "x": -25,
      "y": 28,
      "z": -5,
      "name": "Rock_Ice"
    },
    {
      "x": -25,
      "y": 29,
      "z": -5,
      "name": "Rock_Ice"
    },
    {
      "x": -25,
      "y": 30,
      "z": -5,
      "name": "Rock_Ice"
    },
    {
      "x": -25,
      "y": 31,
      "z": -5,
      "name": "Rock_Ice"
    },
    {
      "x": -25,
      "y": 32,
      "z": -5,
      "name": "Rock_Ice"
    },
    {
      "x": -25,
      "y": 33,
      "z": -5,
      "name": "Rock_Ice"
    },
    {
      "x": -25,
      "y": 34,
      "z": -5,
      "name": "Rock_Ice"
    },
    {
      "x": -25,
      "y": 35,
      "z": -5,
      "name": "Rock_Ice"
    },
    {
      "x": -25,
      "y": 36,
      "z": -5,
      "name": "Rock_Ice"
    },
    {
      "x": -25,
      "y": 37,
      "z": -5,
      "name": "Rock_Ice"
    },
    {
      "x": -25,
      "y": 38,
      "z": -5,
      "name": "Rock_Ice"
    },
    {
      "x": -25,
      "y": 39,
      "z": -5,
      "name": "Rock_Ice"
    },
    {
      "x": -25,
      "y": 40,
      "z": -5,
      "name": "Rock_Ice"
    },
    {
      "x": -25,
      "y": 41,
      "z": -5,
      "name": "Rock_Ice"
    },
    {
      "x": -25,
      "y": 42,
      "z": -5,
      "name": "Rock_Ice"
    },
    {
      "x": -25,
      "y": 43,
      "z": -5,
      "name": "Rock_Ice"
    },
    {
      "x": -25,
      "y": 44,
      "z": -5,
      "name": "Rock_Ice"
    },
    {
      "x": -25,
      "y": 45,
      "z": -5,
      "name": "Rock_Ice"
    },
    {
      "x": -25,
      "y": 46,
      "z": -5,
      "name": "Rock_Ice"
    },
    {
      "x": -25,
      "y": 47,
      "z": -5,
      "name": "Rock_Ice"
    },
    {
      "x": -25,
      "y": 48,
      "z": -5,
      "name": "Rock_Ice"
    },
    {
      "x": -25,
      "y": 49,
      "z": -5,
      "name": "Rock_Ice"
    },
    {
      "x": -25,
      "y": 50,
      "z": -5,
      "name": "Rock_Ice"
    },
    {
      "x": -25,
      "y": 51,
      "z": -5,
      "name": "Rock_Ice"
    },
    {
      "x": -25,
      "y": 52,
      "z": -5,
      "name": "Soil_Snow"
    },
    {
      "x": -25,
      "y": 19,
      "z": -4,
      "name": "Rock_Ice"
    },
    {
      "x": -25,
      "y": 20,
      "z": -4,
      "name": "Rock_Ice"
    },
    {
      "x": -25,
      "y": 21,
      "z": -4,
      "name": "Rock_Ice"
    },
    {
      "x": -25,
      "y": 22,
      "z": -4,
      "name": "Rock_Ice"
    },
    {
      "x": -25,
      "y": 23,
      "z": -4,
      "name": "Rock_Ice"
    },
    {
      "x": -25,
      "y": 24,
      "z": -4,
      "name": "Rock_Ice"
    },
    {
      "x": -25,
      "y": 25,
      "z": -4,
      "name": "Rock_Ice"
    },
    {
      "x": -25,
      "y": 26,
      "z": -4,
      "name": "Rock_Ice"
    },
    {
      "x": -25,
      "y": 27,
      "z": -4,
      "name": "Rock_Ice"
    },
    {
      "x": -25,
      "y": 28,
      "z": -4,
      "name": "Rock_Ice"
    },
    {
      "x": -25,
      "y": 29,
      "z": -4,
      "name": "Rock_Ice"
    },
    {
      "x": -25,
      "y": 30,
      "z": -4,
      "name": "Rock_Ice"
    },
    {
      "x": -25,
      "y": 31,
      "z": -4,
      "name": "Rock_Ice"
    },
    {
      "x": -25,
      "y": 32,
      "z": -4,
      "name": "Rock_Ice"
    },
    {
      "x": -25,
      "y": 33,
      "z": -4,
      "name": "Rock_Ice"
    },
    {
      "x": -25,
      "y": 34,
      "z": -4,
      "name": "Rock_Ice"
    },
    {
      "x": -25,
      "y": 35,
      "z": -4,
      "name": "Rock_Ice"
    },
    {
      "x": -25,
      "y": 36,
      "z": -4,
      "name": "Rock_Ice"
    },
    {
      "x": -25,
      "y": 37,
      "z": -4,
      "name": "Rock_Ice"
    },
    {
      "x": -25,
      "y": 38,
      "z": -4,
      "name": "Rock_Ice"
    },
    {
      "x": -25,
      "y": 39,
      "z": -4,
      "name": "Rock_Ice"
    },
    {
      "x": -25,
      "y": 40,
      "z": -4,
      "name": "Rock_Ice"
    },
    {
      "x": -25,
      "y": 41,
      "z": -4,
      "name": "Rock_Ice"
    },
    {
      "x": -25,
      "y": 42,
      "z": -4,
      "name": "Rock_Ice"
    },
    {
      "x": -25,
      "y": 43,
      "z": -4,
      "name": "Rock_Ice"
    },
    {
      "x": -25,
      "y": 44,
      "z": -4,
      "name": "Rock_Ice"
    },
    {
      "x": -25,
      "y": 45,
      "z": -4,
      "name": "Rock_Ice"
    },
    {
      "x": -25,
      "y": 46,
      "z": -4,
      "name": "Rock_Ice"
    },
    {
      "x": -25,
      "y": 47,
      "z": -4,
      "name": "Rock_Ice"
    },
    {
      "x": -25,
      "y": 48,
      "z": -4,
      "name": "Rock_Ice"
    },
    {
      "x": -25,
      "y": 49,
      "z": -4,
      "name": "Rock_Ice"
    },
    {
      "x": -25,
      "y": 50,
      "z": -4,
      "name": "Rock_Ice"
    },
    {
      "x": -25,
      "y": 51,
      "z": -4,
      "name": "Rock_Ice"
    },
    {
      "x": -25,
      "y": 52,
      "z": -4,
      "name": "Rock_Ice"
    },
    {
      "x": -25,
      "y": 53,
      "z": -4,
      "name": "Soil_Snow"
    },
    {
      "x": -25,
      "y": 20,
      "z": -3,
      "name": "Rock_Ice"
    },
    {
      "x": -25,
      "y": 21,
      "z": -3,
      "name": "Rock_Ice"
    },
    {
      "x": -25,
      "y": 22,
      "z": -3,
      "name": "Rock_Ice"
    },
    {
      "x": -25,
      "y": 23,
      "z": -3,
      "name": "Rock_Ice"
    },
    {
      "x": -25,
      "y": 24,
      "z": -3,
      "name": "Rock_Ice"
    },
    {
      "x": -25,
      "y": 25,
      "z": -3,
      "name": "Rock_Ice"
    },
    {
      "x": -25,
      "y": 26,
      "z": -3,
      "name": "Rock_Ice"
    },
    {
      "x": -25,
      "y": 27,
      "z": -3,
      "name": "Rock_Ice"
    },
    {
      "x": -25,
      "y": 28,
      "z": -3,
      "name": "Rock_Ice"
    },
    {
      "x": -25,
      "y": 29,
      "z": -3,
      "name": "Rock_Ice"
    },
    {
      "x": -25,
      "y": 30,
      "z": -3,
      "name": "Rock_Ice"
    },
    {
      "x": -25,
      "y": 31,
      "z": -3,
      "name": "Rock_Ice"
    },
    {
      "x": -25,
      "y": 32,
      "z": -3,
      "name": "Rock_Ice"
    },
    {
      "x": -25,
      "y": 33,
      "z": -3,
      "name": "Rock_Ice"
    },
    {
      "x": -25,
      "y": 34,
      "z": -3,
      "name": "Rock_Ice"
    },
    {
      "x": -25,
      "y": 35,
      "z": -3,
      "name": "Rock_Ice"
    },
    {
      "x": -25,
      "y": 36,
      "z": -3,
      "name": "Rock_Ice"
    },
    {
      "x": -25,
      "y": 37,
      "z": -3,
      "name": "Rock_Ice"
    },
    {
      "x": -25,
      "y": 38,
      "z": -3,
      "name": "Rock_Ice"
    },
    {
      "x": -25,
      "y": 39,
      "z": -3,
      "name": "Rock_Ice"
    },
    {
      "x": -25,
      "y": 40,
      "z": -3,
      "name": "Rock_Ice"
    },
    {
      "x": -25,
      "y": 41,
      "z": -3,
      "name": "Rock_Ice"
    },
    {
      "x": -25,
      "y": 42,
      "z": -3,
      "name": "Rock_Ice"
    },
    {
      "x": -25,
      "y": 43,
      "z": -3,
      "name": "Rock_Ice"
    },
    {
      "x": -25,
      "y": 44,
      "z": -3,
      "name": "Rock_Ice"
    },
    {
      "x": -25,
      "y": 45,
      "z": -3,
      "name": "Rock_Ice"
    },
    {
      "x": -25,
      "y": 46,
      "z": -3,
      "name": "Rock_Ice"
    },
    {
      "x": -25,
      "y": 47,
      "z": -3,
      "name": "Rock_Ice"
    },
    {
      "x": -25,
      "y": 48,
      "z": -3,
      "name": "Rock_Ice"
    },
    {
      "x": -25,
      "y": 49,
      "z": -3,
      "name": "Rock_Ice"
    },
    {
      "x": -25,
      "y": 50,
      "z": -3,
      "name": "Rock_Ice"
    },
    {
      "x": -25,
      "y": 51,
      "z": -3,
      "name": "Rock_Ice"
    },
    {
      "x": -25,
      "y": 52,
      "z": -3,
      "name": "Rock_Ice_Permafrost"
    },
    {
      "x": -25,
      "y": 21,
      "z": -2,
      "name": "Rock_Ice"
    },
    {
      "x": -25,
      "y": 22,
      "z": -2,
      "name": "Rock_Ice"
    },
    {
      "x": -25,
      "y": 23,
      "z": -2,
      "name": "Rock_Ice"
    },
    {
      "x": -25,
      "y": 24,
      "z": -2,
      "name": "Rock_Ice"
    },
    {
      "x": -25,
      "y": 25,
      "z": -2,
      "name": "Rock_Ice"
    },
    {
      "x": -25,
      "y": 26,
      "z": -2,
      "name": "Rock_Ice"
    },
    {
      "x": -25,
      "y": 27,
      "z": -2,
      "name": "Rock_Ice"
    },
    {
      "x": -25,
      "y": 28,
      "z": -2,
      "name": "Rock_Ice"
    },
    {
      "x": -25,
      "y": 29,
      "z": -2,
      "name": "Rock_Ice"
    },
    {
      "x": -25,
      "y": 30,
      "z": -2,
      "name": "Rock_Ice"
    },
    {
      "x": -25,
      "y": 31,
      "z": -2,
      "name": "Rock_Ice"
    },
    {
      "x": -25,
      "y": 32,
      "z": -2,
      "name": "Rock_Ice"
    },
    {
      "x": -25,
      "y": 33,
      "z": -2,
      "name": "Rock_Ice"
    },
    {
      "x": -25,
      "y": 34,
      "z": -2,
      "name": "Rock_Ice"
    },
    {
      "x": -25,
      "y": 35,
      "z": -2,
      "name": "Rock_Ice"
    },
    {
      "x": -25,
      "y": 36,
      "z": -2,
      "name": "Rock_Ice"
    },
    {
      "x": -25,
      "y": 37,
      "z": -2,
      "name": "Rock_Ice"
    },
    {
      "x": -25,
      "y": 38,
      "z": -2,
      "name": "Rock_Ice"
    },
    {
      "x": -25,
      "y": 39,
      "z": -2,
      "name": "Rock_Ice"
    },
    {
      "x": -25,
      "y": 40,
      "z": -2,
      "name": "Rock_Ice"
    },
    {
      "x": -25,
      "y": 41,
      "z": -2,
      "name": "Rock_Ice"
    },
    {
      "x": -25,
      "y": 42,
      "z": -2,
      "name": "Rock_Ice"
    },
    {
      "x": -25,
      "y": 43,
      "z": -2,
      "name": "Rock_Ice"
    },
    {
      "x": -25,
      "y": 44,
      "z": -2,
      "name": "Rock_Ice"
    },
    {
      "x": -25,
      "y": 45,
      "z": -2,
      "name": "Rock_Ice"
    },
    {
      "x": -25,
      "y": 46,
      "z": -2,
      "name": "Rock_Ice"
    },
    {
      "x": -25,
      "y": 47,
      "z": -2,
      "name": "Rock_Ice"
    },
    {
      "x": -25,
      "y": 48,
      "z": -2,
      "name": "Soil_Snow"
    },
    {
      "x": -25,
      "y": 23,
      "z": -1,
      "name": "Rock_Ice"
    },
    {
      "x": -25,
      "y": 24,
      "z": -1,
      "name": "Rock_Ice"
    },
    {
      "x": -25,
      "y": 25,
      "z": -1,
      "name": "Rock_Ice"
    },
    {
      "x": -25,
      "y": 26,
      "z": -1,
      "name": "Rock_Ice"
    },
    {
      "x": -25,
      "y": 27,
      "z": -1,
      "name": "Rock_Ice"
    },
    {
      "x": -25,
      "y": 28,
      "z": -1,
      "name": "Rock_Ice"
    },
    {
      "x": -25,
      "y": 29,
      "z": -1,
      "name": "Rock_Ice"
    },
    {
      "x": -25,
      "y": 30,
      "z": -1,
      "name": "Rock_Ice"
    },
    {
      "x": -25,
      "y": 31,
      "z": -1,
      "name": "Rock_Ice"
    },
    {
      "x": -25,
      "y": 32,
      "z": -1,
      "name": "Rock_Ice"
    },
    {
      "x": -25,
      "y": 33,
      "z": -1,
      "name": "Rock_Ice"
    },
    {
      "x": -25,
      "y": 34,
      "z": -1,
      "name": "Rock_Ice"
    },
    {
      "x": -25,
      "y": 35,
      "z": -1,
      "name": "Rock_Ice"
    },
    {
      "x": -25,
      "y": 36,
      "z": -1,
      "name": "Rock_Ice"
    },
    {
      "x": -25,
      "y": 37,
      "z": -1,
      "name": "Rock_Ice"
    },
    {
      "x": -25,
      "y": 38,
      "z": -1,
      "name": "Rock_Ice"
    },
    {
      "x": -25,
      "y": 39,
      "z": -1,
      "name": "Rock_Ice"
    },
    {
      "x": -25,
      "y": 40,
      "z": -1,
      "name": "Rock_Ice"
    },
    {
      "x": -25,
      "y": 41,
      "z": -1,
      "name": "Rock_Ice"
    },
    {
      "x": -25,
      "y": 42,
      "z": -1,
      "name": "Rock_Ice"
    },
    {
      "x": -25,
      "y": 43,
      "z": -1,
      "name": "Rock_Ice"
    },
    {
      "x": -25,
      "y": 44,
      "z": -1,
      "name": "Soil_Snow"
    },
    {
      "x": -25,
      "y": 28,
      "z": 0,
      "name": "Rock_Ice"
    },
    {
      "x": -25,
      "y": 29,
      "z": 0,
      "name": "Rock_Ice"
    },
    {
      "x": -25,
      "y": 30,
      "z": 0,
      "name": "Rock_Ice"
    },
    {
      "x": -25,
      "y": 31,
      "z": 0,
      "name": "Rock_Ice"
    },
    {
      "x": -25,
      "y": 32,
      "z": 0,
      "name": "Rock_Ice"
    },
    {
      "x": -25,
      "y": 33,
      "z": 0,
      "name": "Rock_Ice"
    },
    {
      "x": -25,
      "y": 34,
      "z": 0,
      "name": "Rock_Ice"
    },
    {
      "x": -25,
      "y": 35,
      "z": 0,
      "name": "Rock_Ice"
    },
    {
      "x": -25,
      "y": 36,
      "z": 0,
      "name": "Rock_Ice"
    },
    {
      "x": -25,
      "y": 31,
      "z": 1,
      "name": "Rock_Ice"
    },
    {
      "x": -25,
      "y": 32,
      "z": 1,
      "name": "Rock_Ice"
    },
    {
      "x": -25,
      "y": 33,
      "z": 1,
      "name": "Rock_Ice"
    },
    {
      "x": -25,
      "y": 34,
      "z": 1,
      "name": "Rock_Ice"
    },
    {
      "x": -25,
      "y": 35,
      "z": 1,
      "name": "Rock_Ice"
    },
    {
      "x": -25,
      "y": 36,
      "z": 1,
      "name": "Rock_Ice"
    },
    {
      "x": -25,
      "y": 37,
      "z": 1,
      "name": "Rock_Ice"
    },
    {
      "x": -25,
      "y": 38,
      "z": 1,
      "name": "Rock_Ice"
    },
    {
      "x": -25,
      "y": 39,
      "z": 1,
      "name": "Rock_Ice"
    },
    {
      "x": -25,
      "y": 40,
      "z": 1,
      "name": "Rock_Ice"
    },
    {
      "x": -25,
      "y": 41,
      "z": 1,
      "name": "Rock_Ice"
    },
    {
      "x": -25,
      "y": 42,
      "z": 1,
      "name": "Rock_Ice"
    },
    {
      "x": -25,
      "y": 43,
      "z": 1,
      "name": "Soil_Snow"
    },
    {
      "x": -25,
      "y": 29,
      "z": 2,
      "name": "Rock_Ice"
    },
    {
      "x": -25,
      "y": 30,
      "z": 2,
      "name": "Rock_Ice"
    },
    {
      "x": -25,
      "y": 31,
      "z": 2,
      "name": "Rock_Ice"
    },
    {
      "x": -25,
      "y": 32,
      "z": 2,
      "name": "Rock_Ice"
    },
    {
      "x": -25,
      "y": 33,
      "z": 2,
      "name": "Rock_Ice"
    },
    {
      "x": -25,
      "y": 34,
      "z": 2,
      "name": "Rock_Ice"
    },
    {
      "x": -25,
      "y": 35,
      "z": 2,
      "name": "Rock_Ice"
    },
    {
      "x": -25,
      "y": 36,
      "z": 2,
      "name": "Rock_Ice_Permafrost"
    },
    {
      "x": -25,
      "y": 37,
      "z": 2,
      "name": "Rock_Ice"
    },
    {
      "x": -25,
      "y": 38,
      "z": 2,
      "name": "Rock_Ice_Permafrost"
    },
    {
      "x": -25,
      "y": 39,
      "z": 2,
      "name": "Rock_Ice_Permafrost"
    },
    {
      "x": -25,
      "y": 40,
      "z": 2,
      "name": "Rock_Ice_Permafrost"
    },
    {
      "x": -25,
      "y": 41,
      "z": 2,
      "name": "Rock_Ice_Permafrost"
    },
    {
      "x": -25,
      "y": 42,
      "z": 2,
      "name": "Rock_Ice"
    },
    {
      "x": -25,
      "y": 43,
      "z": 2,
      "name": "Soil_Snow"
    },
    {
      "x": -25,
      "y": 29,
      "z": 3,
      "name": "Rock_Ice"
    },
    {
      "x": -25,
      "y": 30,
      "z": 3,
      "name": "Rock_Ice"
    },
    {
      "x": -25,
      "y": 31,
      "z": 3,
      "name": "Rock_Ice"
    },
    {
      "x": -25,
      "y": 32,
      "z": 3,
      "name": "Rock_Ice"
    },
    {
      "x": -25,
      "y": 33,
      "z": 3,
      "name": "Rock_Ice_Permafrost"
    },
    {
      "x": -25,
      "y": 34,
      "z": 3,
      "name": "Rock_Ice"
    },
    {
      "x": -25,
      "y": 35,
      "z": 3,
      "name": "Rock_Ice_Permafrost"
    },
    {
      "x": -25,
      "y": 36,
      "z": 3,
      "name": "Rock_Ice_Permafrost"
    },
    {
      "x": -25,
      "y": 37,
      "z": 3,
      "name": "Rock_Ice_Permafrost"
    },
    {
      "x": -25,
      "y": 38,
      "z": 3,
      "name": "Rock_Ice_Permafrost"
    },
    {
      "x": -25,
      "y": 39,
      "z": 3,
      "name": "Rock_Ice_Permafrost"
    },
    {
      "x": -25,
      "y": 40,
      "z": 3,
      "name": "Rock_Ice_Permafrost"
    },
    {
      "x": -25,
      "y": 41,
      "z": 3,
      "name": "Rock_Ice"
    },
    {
      "x": -25,
      "y": 42,
      "z": 3,
      "name": "Soil_Snow"
    },
    {
      "x": -25,
      "y": 31,
      "z": 4,
      "name": "Rock_Ice_Permafrost"
    },
    {
      "x": -25,
      "y": 32,
      "z": 4,
      "name": "Rock_Ice_Permafrost"
    },
    {
      "x": -25,
      "y": 33,
      "z": 4,
      "name": "Rock_Ice_Permafrost"
    },
    {
      "x": -25,
      "y": 34,
      "z": 4,
      "name": "Rock_Ice_Permafrost"
    },
    {
      "x": -25,
      "y": 35,
      "z": 4,
      "name": "Rock_Ice_Permafrost"
    },
    {
      "x": -25,
      "y": 36,
      "z": 4,
      "name": "Rock_Ice_Permafrost"
    },
    {
      "x": -25,
      "y": 37,
      "z": 4,
      "name": "Rock_Ice_Permafrost"
    },
    {
      "x": -25,
      "y": 38,
      "z": 4,
      "name": "Rock_Ice_Permafrost"
    },
    {
      "x": -25,
      "y": 39,
      "z": 4,
      "name": "Rock_Ice_Permafrost"
    },
    {
      "x": -25,
      "y": 40,
      "z": 4,
      "name": "Rock_Ice"
    },
    {
      "x": -25,
      "y": 41,
      "z": 4,
      "name": "Soil_Snow"
    },
    {
      "x": -25,
      "y": 32,
      "z": 5,
      "name": "Rock_Ice_Permafrost"
    },
    {
      "x": -25,
      "y": 33,
      "z": 5,
      "name": "Rock_Ice_Permafrost"
    },
    {
      "x": -25,
      "y": 34,
      "z": 5,
      "name": "Rock_Ice_Permafrost"
    },
    {
      "x": -25,
      "y": 35,
      "z": 5,
      "name": "Rock_Ice"
    },
    {
      "x": -25,
      "y": 36,
      "z": 5,
      "name": "Rock_Ice_Permafrost"
    },
    {
      "x": -25,
      "y": 37,
      "z": 5,
      "name": "Rock_Ice"
    },
    {
      "x": -25,
      "y": 38,
      "z": 5,
      "name": "Rock_Ice"
    },
    {
      "x": -25,
      "y": 39,
      "z": 5,
      "name": "Rock_Ice"
    },
    {
      "x": -25,
      "y": 40,
      "z": 5,
      "name": "Rock_Ice"
    },
    {
      "x": -25,
      "y": 41,
      "z": 5,
      "name": "Soil_Snow"
    },
    {
      "x": -25,
      "y": 34,
      "z": 6,
      "name": "Rock_Ice"
    },
    {
      "x": -25,
      "y": 35,
      "z": 6,
      "name": "Rock_Ice"
    },
    {
      "x": -25,
      "y": 36,
      "z": 6,
      "name": "Rock_Ice"
    },
    {
      "x": -25,
      "y": 37,
      "z": 6,
      "name": "Rock_Ice"
    },
    {
      "x": -25,
      "y": 38,
      "z": 6,
      "name": "Rock_Ice"
    },
    {
      "x": -25,
      "y": 39,
      "z": 6,
      "name": "Rock_Ice"
    },
    {
      "x": -25,
      "y": 40,
      "z": 6,
      "name": "Soil_Snow"
    },
    {
      "x": -25,
      "y": 36,
      "z": 7,
      "name": "Rock_Ice"
    },
    {
      "x": -25,
      "y": 37,
      "z": 7,
      "name": "Rock_Ice"
    },
    {
      "x": -25,
      "y": 38,
      "z": 7,
      "name": "Soil_Snow"
    },
    {
      "x": -24,
      "y": 41,
      "z": -13,
      "name": "Rock_Ice"
    },
    {
      "x": -24,
      "y": 42,
      "z": -13,
      "name": "Rock_Ice"
    },
    {
      "x": -24,
      "y": 43,
      "z": -13,
      "name": "Rock_Ice"
    },
    {
      "x": -24,
      "y": 44,
      "z": -13,
      "name": "Soil_Snow"
    },
    {
      "x": -24,
      "y": 38,
      "z": -12,
      "name": "Rock_Ice"
    },
    {
      "x": -24,
      "y": 39,
      "z": -12,
      "name": "Rock_Ice"
    },
    {
      "x": -24,
      "y": 40,
      "z": -12,
      "name": "Rock_Ice"
    },
    {
      "x": -24,
      "y": 41,
      "z": -12,
      "name": "Rock_Ice"
    },
    {
      "x": -24,
      "y": 42,
      "z": -12,
      "name": "Rock_Ice"
    },
    {
      "x": -24,
      "y": 43,
      "z": -12,
      "name": "Rock_Ice"
    },
    {
      "x": -24,
      "y": 44,
      "z": -12,
      "name": "Rock_Ice"
    },
    {
      "x": -24,
      "y": 45,
      "z": -12,
      "name": "Soil_Snow"
    },
    {
      "x": -24,
      "y": 30,
      "z": -11,
      "name": "Rock_Ice"
    },
    {
      "x": -24,
      "y": 31,
      "z": -11,
      "name": "Rock_Ice"
    },
    {
      "x": -24,
      "y": 32,
      "z": -11,
      "name": "Rock_Ice"
    },
    {
      "x": -24,
      "y": 33,
      "z": -11,
      "name": "Rock_Ice"
    },
    {
      "x": -24,
      "y": 34,
      "z": -11,
      "name": "Rock_Ice"
    },
    {
      "x": -24,
      "y": 35,
      "z": -11,
      "name": "Rock_Ice"
    },
    {
      "x": -24,
      "y": 36,
      "z": -11,
      "name": "Rock_Ice"
    },
    {
      "x": -24,
      "y": 37,
      "z": -11,
      "name": "Rock_Ice"
    },
    {
      "x": -24,
      "y": 38,
      "z": -11,
      "name": "Rock_Ice"
    },
    {
      "x": -24,
      "y": 39,
      "z": -11,
      "name": "Rock_Ice"
    },
    {
      "x": -24,
      "y": 40,
      "z": -11,
      "name": "Rock_Ice"
    },
    {
      "x": -24,
      "y": 41,
      "z": -11,
      "name": "Rock_Ice"
    },
    {
      "x": -24,
      "y": 42,
      "z": -11,
      "name": "Rock_Ice"
    },
    {
      "x": -24,
      "y": 43,
      "z": -11,
      "name": "Rock_Ice"
    },
    {
      "x": -24,
      "y": 44,
      "z": -11,
      "name": "Rock_Ice"
    },
    {
      "x": -24,
      "y": 45,
      "z": -11,
      "name": "Rock_Ice"
    },
    {
      "x": -24,
      "y": 46,
      "z": -11,
      "name": "Soil_Snow"
    },
    {
      "x": -24,
      "y": 29,
      "z": -10,
      "name": "Rock_Ice"
    },
    {
      "x": -24,
      "y": 30,
      "z": -10,
      "name": "Rock_Ice"
    },
    {
      "x": -24,
      "y": 31,
      "z": -10,
      "name": "Rock_Ice"
    },
    {
      "x": -24,
      "y": 32,
      "z": -10,
      "name": "Rock_Ice"
    },
    {
      "x": -24,
      "y": 33,
      "z": -10,
      "name": "Rock_Ice"
    },
    {
      "x": -24,
      "y": 34,
      "z": -10,
      "name": "Rock_Ice"
    },
    {
      "x": -24,
      "y": 35,
      "z": -10,
      "name": "Rock_Ice"
    },
    {
      "x": -24,
      "y": 36,
      "z": -10,
      "name": "Rock_Ice"
    },
    {
      "x": -24,
      "y": 37,
      "z": -10,
      "name": "Rock_Ice"
    },
    {
      "x": -24,
      "y": 38,
      "z": -10,
      "name": "Rock_Ice"
    },
    {
      "x": -24,
      "y": 39,
      "z": -10,
      "name": "Rock_Ice"
    },
    {
      "x": -24,
      "y": 40,
      "z": -10,
      "name": "Rock_Ice"
    },
    {
      "x": -24,
      "y": 41,
      "z": -10,
      "name": "Rock_Ice"
    },
    {
      "x": -24,
      "y": 42,
      "z": -10,
      "name": "Rock_Ice"
    },
    {
      "x": -24,
      "y": 43,
      "z": -10,
      "name": "Rock_Ice"
    },
    {
      "x": -24,
      "y": 44,
      "z": -10,
      "name": "Rock_Ice"
    },
    {
      "x": -24,
      "y": 45,
      "z": -10,
      "name": "Rock_Ice"
    },
    {
      "x": -24,
      "y": 46,
      "z": -10,
      "name": "Rock_Ice"
    },
    {
      "x": -24,
      "y": 47,
      "z": -10,
      "name": "Soil_Snow"
    },
    {
      "x": -24,
      "y": 27,
      "z": -9,
      "name": "Rock_Ice"
    },
    {
      "x": -24,
      "y": 28,
      "z": -9,
      "name": "Rock_Ice"
    },
    {
      "x": -24,
      "y": 29,
      "z": -9,
      "name": "Rock_Ice"
    },
    {
      "x": -24,
      "y": 30,
      "z": -9,
      "name": "Rock_Ice"
    },
    {
      "x": -24,
      "y": 31,
      "z": -9,
      "name": "Rock_Ice"
    },
    {
      "x": -24,
      "y": 32,
      "z": -9,
      "name": "Rock_Ice"
    },
    {
      "x": -24,
      "y": 33,
      "z": -9,
      "name": "Rock_Ice"
    },
    {
      "x": -24,
      "y": 34,
      "z": -9,
      "name": "Rock_Ice"
    },
    {
      "x": -24,
      "y": 35,
      "z": -9,
      "name": "Rock_Ice"
    },
    {
      "x": -24,
      "y": 36,
      "z": -9,
      "name": "Rock_Ice"
    },
    {
      "x": -24,
      "y": 37,
      "z": -9,
      "name": "Rock_Ice"
    },
    {
      "x": -24,
      "y": 38,
      "z": -9,
      "name": "Rock_Ice"
    },
    {
      "x": -24,
      "y": 39,
      "z": -9,
      "name": "Rock_Ice"
    },
    {
      "x": -24,
      "y": 40,
      "z": -9,
      "name": "Rock_Ice"
    },
    {
      "x": -24,
      "y": 41,
      "z": -9,
      "name": "Rock_Ice"
    },
    {
      "x": -24,
      "y": 42,
      "z": -9,
      "name": "Rock_Ice"
    },
    {
      "x": -24,
      "y": 43,
      "z": -9,
      "name": "Rock_Ice"
    },
    {
      "x": -24,
      "y": 44,
      "z": -9,
      "name": "Rock_Ice"
    },
    {
      "x": -24,
      "y": 45,
      "z": -9,
      "name": "Rock_Ice"
    },
    {
      "x": -24,
      "y": 46,
      "z": -9,
      "name": "Rock_Ice"
    },
    {
      "x": -24,
      "y": 47,
      "z": -9,
      "name": "Rock_Ice"
    },
    {
      "x": -24,
      "y": 48,
      "z": -9,
      "name": "Rock_Ice"
    },
    {
      "x": -24,
      "y": 49,
      "z": -9,
      "name": "Soil_Snow"
    },
    {
      "x": -24,
      "y": 14,
      "z": -8,
      "name": "Rock_Ice_Permafrost"
    },
    {
      "x": -24,
      "y": 15,
      "z": -8,
      "name": "Rock_Ice_Permafrost"
    },
    {
      "x": -24,
      "y": 16,
      "z": -8,
      "name": "Rock_Ice_Permafrost"
    },
    {
      "x": -24,
      "y": 17,
      "z": -8,
      "name": "Rock_Ice_Permafrost"
    },
    {
      "x": -24,
      "y": 18,
      "z": -8,
      "name": "Rock_Ice_Permafrost"
    },
    {
      "x": -24,
      "y": 19,
      "z": -8,
      "name": "Rock_Ice"
    },
    {
      "x": -24,
      "y": 20,
      "z": -8,
      "name": "Rock_Ice"
    },
    {
      "x": -24,
      "y": 21,
      "z": -8,
      "name": "Rock_Ice"
    },
    {
      "x": -24,
      "y": 22,
      "z": -8,
      "name": "Rock_Ice"
    },
    {
      "x": -24,
      "y": 23,
      "z": -8,
      "name": "Rock_Ice"
    },
    {
      "x": -24,
      "y": 24,
      "z": -8,
      "name": "Rock_Ice"
    },
    {
      "x": -24,
      "y": 25,
      "z": -8,
      "name": "Rock_Ice"
    },
    {
      "x": -24,
      "y": 26,
      "z": -8,
      "name": "Rock_Ice"
    },
    {
      "x": -24,
      "y": 27,
      "z": -8,
      "name": "Rock_Ice"
    },
    {
      "x": -24,
      "y": 28,
      "z": -8,
      "name": "Rock_Ice"
    },
    {
      "x": -24,
      "y": 29,
      "z": -8,
      "name": "Rock_Ice"
    },
    {
      "x": -24,
      "y": 30,
      "z": -8,
      "name": "Rock_Ice"
    },
    {
      "x": -24,
      "y": 31,
      "z": -8,
      "name": "Rock_Ice"
    },
    {
      "x": -24,
      "y": 32,
      "z": -8,
      "name": "Rock_Ice"
    },
    {
      "x": -24,
      "y": 33,
      "z": -8,
      "name": "Rock_Ice"
    },
    {
      "x": -24,
      "y": 34,
      "z": -8,
      "name": "Rock_Ice"
    },
    {
      "x": -24,
      "y": 35,
      "z": -8,
      "name": "Rock_Ice"
    },
    {
      "x": -24,
      "y": 36,
      "z": -8,
      "name": "Rock_Ice"
    },
    {
      "x": -24,
      "y": 37,
      "z": -8,
      "name": "Rock_Ice"
    },
    {
      "x": -24,
      "y": 38,
      "z": -8,
      "name": "Rock_Ice"
    },
    {
      "x": -24,
      "y": 39,
      "z": -8,
      "name": "Rock_Ice"
    },
    {
      "x": -24,
      "y": 40,
      "z": -8,
      "name": "Rock_Ice"
    },
    {
      "x": -24,
      "y": 41,
      "z": -8,
      "name": "Rock_Ice"
    },
    {
      "x": -24,
      "y": 42,
      "z": -8,
      "name": "Rock_Ice"
    },
    {
      "x": -24,
      "y": 43,
      "z": -8,
      "name": "Rock_Ice"
    },
    {
      "x": -24,
      "y": 44,
      "z": -8,
      "name": "Rock_Ice"
    },
    {
      "x": -24,
      "y": 45,
      "z": -8,
      "name": "Rock_Ice"
    },
    {
      "x": -24,
      "y": 46,
      "z": -8,
      "name": "Rock_Ice"
    },
    {
      "x": -24,
      "y": 47,
      "z": -8,
      "name": "Rock_Ice"
    },
    {
      "x": -24,
      "y": 48,
      "z": -8,
      "name": "Rock_Ice"
    },
    {
      "x": -24,
      "y": 49,
      "z": -8,
      "name": "Rock_Ice"
    },
    {
      "x": -24,
      "y": 50,
      "z": -8,
      "name": "Soil_Snow"
    },
    {
      "x": -24,
      "y": 14,
      "z": -7,
      "name": "Rock_Ice_Permafrost"
    },
    {
      "x": -24,
      "y": 15,
      "z": -7,
      "name": "Rock_Ice_Permafrost"
    },
    {
      "x": -24,
      "y": 16,
      "z": -7,
      "name": "Rock_Ice_Permafrost"
    },
    {
      "x": -24,
      "y": 17,
      "z": -7,
      "name": "Rock_Ice_Permafrost"
    },
    {
      "x": -24,
      "y": 18,
      "z": -7,
      "name": "Rock_Ice"
    },
    {
      "x": -24,
      "y": 19,
      "z": -7,
      "name": "Rock_Ice"
    },
    {
      "x": -24,
      "y": 20,
      "z": -7,
      "name": "Rock_Ice"
    },
    {
      "x": -24,
      "y": 21,
      "z": -7,
      "name": "Rock_Ice"
    },
    {
      "x": -24,
      "y": 22,
      "z": -7,
      "name": "Rock_Ice"
    },
    {
      "x": -24,
      "y": 23,
      "z": -7,
      "name": "Rock_Ice"
    },
    {
      "x": -24,
      "y": 24,
      "z": -7,
      "name": "Rock_Ice"
    },
    {
      "x": -24,
      "y": 25,
      "z": -7,
      "name": "Rock_Ice"
    },
    {
      "x": -24,
      "y": 26,
      "z": -7,
      "name": "Rock_Ice"
    },
    {
      "x": -24,
      "y": 27,
      "z": -7,
      "name": "Rock_Ice"
    },
    {
      "x": -24,
      "y": 28,
      "z": -7,
      "name": "Rock_Ice"
    },
    {
      "x": -24,
      "y": 29,
      "z": -7,
      "name": "Rock_Ice"
    },
    {
      "x": -24,
      "y": 30,
      "z": -7,
      "name": "Rock_Ice"
    },
    {
      "x": -24,
      "y": 31,
      "z": -7,
      "name": "Rock_Ice"
    },
    {
      "x": -24,
      "y": 32,
      "z": -7,
      "name": "Rock_Ice"
    },
    {
      "x": -24,
      "y": 33,
      "z": -7,
      "name": "Rock_Ice"
    },
    {
      "x": -24,
      "y": 34,
      "z": -7,
      "name": "Rock_Ice"
    },
    {
      "x": -24,
      "y": 35,
      "z": -7,
      "name": "Rock_Ice"
    },
    {
      "x": -24,
      "y": 36,
      "z": -7,
      "name": "Rock_Ice"
    },
    {
      "x": -24,
      "y": 37,
      "z": -7,
      "name": "Rock_Ice"
    },
    {
      "x": -24,
      "y": 38,
      "z": -7,
      "name": "Rock_Ice"
    },
    {
      "x": -24,
      "y": 39,
      "z": -7,
      "name": "Rock_Ice"
    },
    {
      "x": -24,
      "y": 40,
      "z": -7,
      "name": "Rock_Ice"
    },
    {
      "x": -24,
      "y": 41,
      "z": -7,
      "name": "Rock_Ice"
    },
    {
      "x": -24,
      "y": 42,
      "z": -7,
      "name": "Rock_Ice"
    },
    {
      "x": -24,
      "y": 43,
      "z": -7,
      "name": "Rock_Ice"
    },
    {
      "x": -24,
      "y": 44,
      "z": -7,
      "name": "Rock_Ice"
    },
    {
      "x": -24,
      "y": 45,
      "z": -7,
      "name": "Rock_Ice"
    },
    {
      "x": -24,
      "y": 46,
      "z": -7,
      "name": "Rock_Ice"
    },
    {
      "x": -24,
      "y": 47,
      "z": -7,
      "name": "Rock_Ice"
    },
    {
      "x": -24,
      "y": 48,
      "z": -7,
      "name": "Rock_Ice"
    },
    {
      "x": -24,
      "y": 49,
      "z": -7,
      "name": "Rock_Ice"
    },
    {
      "x": -24,
      "y": 50,
      "z": -7,
      "name": "Rock_Ice"
    },
    {
      "x": -24,
      "y": 51,
      "z": -7,
      "name": "Soil_Snow"
    },
    {
      "x": -24,
      "y": 14,
      "z": -6,
      "name": "Rock_Ice_Permafrost"
    },
    {
      "x": -24,
      "y": 15,
      "z": -6,
      "name": "Rock_Ice_Permafrost"
    },
    {
      "x": -24,
      "y": 16,
      "z": -6,
      "name": "Rock_Ice_Permafrost"
    },
    {
      "x": -24,
      "y": 17,
      "z": -6,
      "name": "Rock_Ice_Permafrost"
    },
    {
      "x": -24,
      "y": 18,
      "z": -6,
      "name": "Rock_Ice"
    },
    {
      "x": -24,
      "y": 19,
      "z": -6,
      "name": "Rock_Ice"
    },
    {
      "x": -24,
      "y": 20,
      "z": -6,
      "name": "Rock_Ice"
    },
    {
      "x": -24,
      "y": 21,
      "z": -6,
      "name": "Rock_Ice"
    },
    {
      "x": -24,
      "y": 22,
      "z": -6,
      "name": "Rock_Ice"
    },
    {
      "x": -24,
      "y": 23,
      "z": -6,
      "name": "Rock_Ice"
    },
    {
      "x": -24,
      "y": 24,
      "z": -6,
      "name": "Rock_Ice"
    },
    {
      "x": -24,
      "y": 25,
      "z": -6,
      "name": "Rock_Ice"
    },
    {
      "x": -24,
      "y": 26,
      "z": -6,
      "name": "Rock_Ice"
    },
    {
      "x": -24,
      "y": 27,
      "z": -6,
      "name": "Rock_Ice"
    },
    {
      "x": -24,
      "y": 28,
      "z": -6,
      "name": "Rock_Ice"
    },
    {
      "x": -24,
      "y": 29,
      "z": -6,
      "name": "Rock_Ice"
    },
    {
      "x": -24,
      "y": 30,
      "z": -6,
      "name": "Rock_Ice"
    },
    {
      "x": -24,
      "y": 31,
      "z": -6,
      "name": "Rock_Ice"
    },
    {
      "x": -24,
      "y": 32,
      "z": -6,
      "name": "Rock_Ice"
    },
    {
      "x": -24,
      "y": 33,
      "z": -6,
      "name": "Rock_Ice"
    },
    {
      "x": -24,
      "y": 34,
      "z": -6,
      "name": "Rock_Ice"
    },
    {
      "x": -24,
      "y": 35,
      "z": -6,
      "name": "Rock_Ice"
    },
    {
      "x": -24,
      "y": 36,
      "z": -6,
      "name": "Rock_Ice"
    },
    {
      "x": -24,
      "y": 37,
      "z": -6,
      "name": "Rock_Ice"
    },
    {
      "x": -24,
      "y": 38,
      "z": -6,
      "name": "Rock_Ice"
    },
    {
      "x": -24,
      "y": 39,
      "z": -6,
      "name": "Rock_Ice"
    },
    {
      "x": -24,
      "y": 40,
      "z": -6,
      "name": "Rock_Ice"
    },
    {
      "x": -24,
      "y": 41,
      "z": -6,
      "name": "Rock_Ice"
    },
    {
      "x": -24,
      "y": 42,
      "z": -6,
      "name": "Rock_Ice"
    },
    {
      "x": -24,
      "y": 43,
      "z": -6,
      "name": "Rock_Ice"
    },
    {
      "x": -24,
      "y": 44,
      "z": -6,
      "name": "Rock_Ice"
    },
    {
      "x": -24,
      "y": 45,
      "z": -6,
      "name": "Rock_Ice"
    },
    {
      "x": -24,
      "y": 46,
      "z": -6,
      "name": "Rock_Ice"
    },
    {
      "x": -24,
      "y": 47,
      "z": -6,
      "name": "Rock_Ice"
    },
    {
      "x": -24,
      "y": 48,
      "z": -6,
      "name": "Rock_Ice"
    },
    {
      "x": -24,
      "y": 49,
      "z": -6,
      "name": "Rock_Ice"
    },
    {
      "x": -24,
      "y": 50,
      "z": -6,
      "name": "Rock_Ice"
    },
    {
      "x": -24,
      "y": 51,
      "z": -6,
      "name": "Rock_Ice"
    },
    {
      "x": -24,
      "y": 52,
      "z": -6,
      "name": "Soil_Snow"
    },
    {
      "x": -24,
      "y": 14,
      "z": -5,
      "name": "Rock_Ice_Permafrost"
    },
    {
      "x": -24,
      "y": 15,
      "z": -5,
      "name": "Rock_Ice_Permafrost"
    },
    {
      "x": -24,
      "y": 16,
      "z": -5,
      "name": "Rock_Ice_Permafrost"
    },
    {
      "x": -24,
      "y": 17,
      "z": -5,
      "name": "Rock_Ice"
    },
    {
      "x": -24,
      "y": 18,
      "z": -5,
      "name": "Rock_Ice"
    },
    {
      "x": -24,
      "y": 19,
      "z": -5,
      "name": "Rock_Ice"
    },
    {
      "x": -24,
      "y": 20,
      "z": -5,
      "name": "Rock_Ice"
    },
    {
      "x": -24,
      "y": 21,
      "z": -5,
      "name": "Rock_Ice"
    },
    {
      "x": -24,
      "y": 22,
      "z": -5,
      "name": "Rock_Ice"
    },
    {
      "x": -24,
      "y": 23,
      "z": -5,
      "name": "Rock_Ice"
    },
    {
      "x": -24,
      "y": 24,
      "z": -5,
      "name": "Rock_Ice"
    },
    {
      "x": -24,
      "y": 25,
      "z": -5,
      "name": "Rock_Ice"
    },
    {
      "x": -24,
      "y": 26,
      "z": -5,
      "name": "Rock_Ice"
    },
    {
      "x": -24,
      "y": 27,
      "z": -5,
      "name": "Rock_Ice"
    },
    {
      "x": -24,
      "y": 28,
      "z": -5,
      "name": "Rock_Ice"
    },
    {
      "x": -24,
      "y": 29,
      "z": -5,
      "name": "Rock_Ice"
    },
    {
      "x": -24,
      "y": 30,
      "z": -5,
      "name": "Rock_Ice"
    },
    {
      "x": -24,
      "y": 31,
      "z": -5,
      "name": "Rock_Ice"
    },
    {
      "x": -24,
      "y": 32,
      "z": -5,
      "name": "Rock_Ice"
    },
    {
      "x": -24,
      "y": 33,
      "z": -5,
      "name": "Rock_Ice"
    },
    {
      "x": -24,
      "y": 34,
      "z": -5,
      "name": "Rock_Ice"
    },
    {
      "x": -24,
      "y": 35,
      "z": -5,
      "name": "Rock_Ice"
    },
    {
      "x": -24,
      "y": 36,
      "z": -5,
      "name": "Rock_Ice"
    },
    {
      "x": -24,
      "y": 37,
      "z": -5,
      "name": "Rock_Ice"
    },
    {
      "x": -24,
      "y": 38,
      "z": -5,
      "name": "Rock_Ice"
    },
    {
      "x": -24,
      "y": 39,
      "z": -5,
      "name": "Rock_Ice"
    },
    {
      "x": -24,
      "y": 40,
      "z": -5,
      "name": "Rock_Ice"
    },
    {
      "x": -24,
      "y": 41,
      "z": -5,
      "name": "Rock_Ice"
    },
    {
      "x": -24,
      "y": 42,
      "z": -5,
      "name": "Rock_Ice"
    },
    {
      "x": -24,
      "y": 43,
      "z": -5,
      "name": "Rock_Ice"
    },
    {
      "x": -24,
      "y": 44,
      "z": -5,
      "name": "Rock_Ice"
    },
    {
      "x": -24,
      "y": 45,
      "z": -5,
      "name": "Rock_Ice"
    },
    {
      "x": -24,
      "y": 46,
      "z": -5,
      "name": "Rock_Ice"
    },
    {
      "x": -24,
      "y": 47,
      "z": -5,
      "name": "Rock_Ice"
    },
    {
      "x": -24,
      "y": 48,
      "z": -5,
      "name": "Rock_Ice"
    },
    {
      "x": -24,
      "y": 49,
      "z": -5,
      "name": "Rock_Ice"
    },
    {
      "x": -24,
      "y": 50,
      "z": -5,
      "name": "Rock_Ice"
    },
    {
      "x": -24,
      "y": 51,
      "z": -5,
      "name": "Rock_Ice"
    },
    {
      "x": -24,
      "y": 52,
      "z": -5,
      "name": "Rock_Ice_Permafrost"
    },
    {
      "x": -24,
      "y": 53,
      "z": -5,
      "name": "Rock_Ice"
    },
    {
      "x": -24,
      "y": 54,
      "z": -5,
      "name": "Soil_Snow"
    },
    {
      "x": -24,
      "y": 14,
      "z": -4,
      "name": "Rock_Ice_Permafrost"
    },
    {
      "x": -24,
      "y": 15,
      "z": -4,
      "name": "Rock_Ice_Permafrost"
    },
    {
      "x": -24,
      "y": 16,
      "z": -4,
      "name": "Rock_Ice_Permafrost"
    },
    {
      "x": -24,
      "y": 17,
      "z": -4,
      "name": "Rock_Ice"
    },
    {
      "x": -24,
      "y": 18,
      "z": -4,
      "name": "Rock_Ice"
    },
    {
      "x": -24,
      "y": 19,
      "z": -4,
      "name": "Rock_Ice"
    },
    {
      "x": -24,
      "y": 20,
      "z": -4,
      "name": "Rock_Ice"
    },
    {
      "x": -24,
      "y": 21,
      "z": -4,
      "name": "Rock_Ice"
    },
    {
      "x": -24,
      "y": 22,
      "z": -4,
      "name": "Rock_Ice"
    },
    {
      "x": -24,
      "y": 23,
      "z": -4,
      "name": "Rock_Ice"
    },
    {
      "x": -24,
      "y": 24,
      "z": -4,
      "name": "Rock_Ice"
    },
    {
      "x": -24,
      "y": 25,
      "z": -4,
      "name": "Rock_Ice"
    },
    {
      "x": -24,
      "y": 26,
      "z": -4,
      "name": "Rock_Ice"
    },
    {
      "x": -24,
      "y": 27,
      "z": -4,
      "name": "Rock_Ice"
    },
    {
      "x": -24,
      "y": 28,
      "z": -4,
      "name": "Rock_Ice"
    },
    {
      "x": -24,
      "y": 29,
      "z": -4,
      "name": "Rock_Ice"
    },
    {
      "x": -24,
      "y": 30,
      "z": -4,
      "name": "Rock_Ice"
    },
    {
      "x": -24,
      "y": 31,
      "z": -4,
      "name": "Rock_Ice"
    },
    {
      "x": -24,
      "y": 32,
      "z": -4,
      "name": "Rock_Ice"
    },
    {
      "x": -24,
      "y": 33,
      "z": -4,
      "name": "Rock_Ice"
    },
    {
      "x": -24,
      "y": 34,
      "z": -4,
      "name": "Rock_Ice"
    },
    {
      "x": -24,
      "y": 35,
      "z": -4,
      "name": "Rock_Ice"
    },
    {
      "x": -24,
      "y": 36,
      "z": -4,
      "name": "Rock_Ice"
    },
    {
      "x": -24,
      "y": 37,
      "z": -4,
      "name": "Rock_Ice"
    },
    {
      "x": -24,
      "y": 38,
      "z": -4,
      "name": "Rock_Ice"
    },
    {
      "x": -24,
      "y": 39,
      "z": -4,
      "name": "Rock_Ice"
    },
    {
      "x": -24,
      "y": 40,
      "z": -4,
      "name": "Rock_Ice"
    },
    {
      "x": -24,
      "y": 41,
      "z": -4,
      "name": "Rock_Ice"
    },
    {
      "x": -24,
      "y": 42,
      "z": -4,
      "name": "Rock_Ice"
    },
    {
      "x": -24,
      "y": 43,
      "z": -4,
      "name": "Rock_Ice"
    },
    {
      "x": -24,
      "y": 44,
      "z": -4,
      "name": "Rock_Ice"
    },
    {
      "x": -24,
      "y": 45,
      "z": -4,
      "name": "Rock_Ice"
    },
    {
      "x": -24,
      "y": 46,
      "z": -4,
      "name": "Rock_Ice"
    },
    {
      "x": -24,
      "y": 47,
      "z": -4,
      "name": "Rock_Ice"
    },
    {
      "x": -24,
      "y": 48,
      "z": -4,
      "name": "Rock_Ice"
    },
    {
      "x": -24,
      "y": 49,
      "z": -4,
      "name": "Rock_Ice"
    },
    {
      "x": -24,
      "y": 50,
      "z": -4,
      "name": "Rock_Ice"
    },
    {
      "x": -24,
      "y": 51,
      "z": -4,
      "name": "Rock_Ice"
    },
    {
      "x": -24,
      "y": 52,
      "z": -4,
      "name": "Rock_Ice_Permafrost"
    },
    {
      "x": -24,
      "y": 53,
      "z": -4,
      "name": "Rock_Ice_Permafrost"
    },
    {
      "x": -24,
      "y": 54,
      "z": -4,
      "name": "Rock_Ice"
    },
    {
      "x": -24,
      "y": 55,
      "z": -4,
      "name": "Soil_Snow"
    },
    {
      "x": -24,
      "y": 15,
      "z": -3,
      "name": "Rock_Ice_Permafrost"
    },
    {
      "x": -24,
      "y": 16,
      "z": -3,
      "name": "Rock_Ice_Permafrost"
    },
    {
      "x": -24,
      "y": 17,
      "z": -3,
      "name": "Rock_Ice"
    },
    {
      "x": -24,
      "y": 18,
      "z": -3,
      "name": "Rock_Ice"
    },
    {
      "x": -24,
      "y": 19,
      "z": -3,
      "name": "Rock_Ice"
    },
    {
      "x": -24,
      "y": 20,
      "z": -3,
      "name": "Rock_Ice"
    },
    {
      "x": -24,
      "y": 21,
      "z": -3,
      "name": "Rock_Ice"
    },
    {
      "x": -24,
      "y": 22,
      "z": -3,
      "name": "Rock_Ice"
    },
    {
      "x": -24,
      "y": 23,
      "z": -3,
      "name": "Rock_Ice"
    },
    {
      "x": -24,
      "y": 24,
      "z": -3,
      "name": "Rock_Ice"
    },
    {
      "x": -24,
      "y": 25,
      "z": -3,
      "name": "Rock_Ice"
    },
    {
      "x": -24,
      "y": 26,
      "z": -3,
      "name": "Rock_Ice"
    },
    {
      "x": -24,
      "y": 27,
      "z": -3,
      "name": "Rock_Ice"
    },
    {
      "x": -24,
      "y": 28,
      "z": -3,
      "name": "Rock_Ice"
    },
    {
      "x": -24,
      "y": 29,
      "z": -3,
      "name": "Rock_Ice"
    },
    {
      "x": -24,
      "y": 30,
      "z": -3,
      "name": "Rock_Ice"
    },
    {
      "x": -24,
      "y": 31,
      "z": -3,
      "name": "Rock_Ice"
    },
    {
      "x": -24,
      "y": 32,
      "z": -3,
      "name": "Rock_Ice"
    },
    {
      "x": -24,
      "y": 33,
      "z": -3,
      "name": "Rock_Ice"
    },
    {
      "x": -24,
      "y": 34,
      "z": -3,
      "name": "Rock_Ice"
    },
    {
      "x": -24,
      "y": 35,
      "z": -3,
      "name": "Rock_Ice"
    },
    {
      "x": -24,
      "y": 36,
      "z": -3,
      "name": "Rock_Ice"
    },
    {
      "x": -24,
      "y": 37,
      "z": -3,
      "name": "Rock_Ice"
    },
    {
      "x": -24,
      "y": 38,
      "z": -3,
      "name": "Rock_Ice"
    },
    {
      "x": -24,
      "y": 39,
      "z": -3,
      "name": "Rock_Ice"
    },
    {
      "x": -24,
      "y": 40,
      "z": -3,
      "name": "Rock_Ice"
    },
    {
      "x": -24,
      "y": 41,
      "z": -3,
      "name": "Rock_Ice"
    },
    {
      "x": -24,
      "y": 42,
      "z": -3,
      "name": "Rock_Ice"
    },
    {
      "x": -24,
      "y": 43,
      "z": -3,
      "name": "Rock_Ice"
    },
    {
      "x": -24,
      "y": 44,
      "z": -3,
      "name": "Rock_Ice"
    },
    {
      "x": -24,
      "y": 45,
      "z": -3,
      "name": "Rock_Ice"
    },
    {
      "x": -24,
      "y": 46,
      "z": -3,
      "name": "Rock_Ice"
    },
    {
      "x": -24,
      "y": 47,
      "z": -3,
      "name": "Rock_Ice"
    },
    {
      "x": -24,
      "y": 48,
      "z": -3,
      "name": "Rock_Ice"
    },
    {
      "x": -24,
      "y": 49,
      "z": -3,
      "name": "Rock_Ice"
    },
    {
      "x": -24,
      "y": 50,
      "z": -3,
      "name": "Rock_Ice"
    },
    {
      "x": -24,
      "y": 51,
      "z": -3,
      "name": "Rock_Ice_Permafrost"
    },
    {
      "x": -24,
      "y": 52,
      "z": -3,
      "name": "Rock_Ice_Permafrost"
    },
    {
      "x": -24,
      "y": 53,
      "z": -3,
      "name": "Rock_Ice_Permafrost"
    },
    {
      "x": -24,
      "y": 54,
      "z": -3,
      "name": "Rock_Ice_Permafrost"
    },
    {
      "x": -24,
      "y": 55,
      "z": -3,
      "name": "Rock_Ice_Permafrost"
    },
    {
      "x": -24,
      "y": 56,
      "z": -3,
      "name": "Soil_Snow"
    },
    {
      "x": -24,
      "y": 15,
      "z": -2,
      "name": "Rock_Ice_Permafrost"
    },
    {
      "x": -24,
      "y": 16,
      "z": -2,
      "name": "Rock_Ice"
    },
    {
      "x": -24,
      "y": 17,
      "z": -2,
      "name": "Rock_Ice"
    },
    {
      "x": -24,
      "y": 18,
      "z": -2,
      "name": "Rock_Ice"
    },
    {
      "x": -24,
      "y": 19,
      "z": -2,
      "name": "Rock_Ice"
    },
    {
      "x": -24,
      "y": 20,
      "z": -2,
      "name": "Rock_Ice"
    },
    {
      "x": -24,
      "y": 21,
      "z": -2,
      "name": "Rock_Ice"
    },
    {
      "x": -24,
      "y": 22,
      "z": -2,
      "name": "Rock_Ice"
    },
    {
      "x": -24,
      "y": 23,
      "z": -2,
      "name": "Rock_Ice"
    },
    {
      "x": -24,
      "y": 24,
      "z": -2,
      "name": "Rock_Ice"
    },
    {
      "x": -24,
      "y": 25,
      "z": -2,
      "name": "Rock_Ice"
    },
    {
      "x": -24,
      "y": 26,
      "z": -2,
      "name": "Rock_Ice"
    },
    {
      "x": -24,
      "y": 27,
      "z": -2,
      "name": "Rock_Ice"
    },
    {
      "x": -24,
      "y": 28,
      "z": -2,
      "name": "Rock_Ice"
    },
    {
      "x": -24,
      "y": 29,
      "z": -2,
      "name": "Rock_Ice"
    },
    {
      "x": -24,
      "y": 30,
      "z": -2,
      "name": "Rock_Ice"
    },
    {
      "x": -24,
      "y": 31,
      "z": -2,
      "name": "Rock_Ice"
    },
    {
      "x": -24,
      "y": 32,
      "z": -2,
      "name": "Rock_Ice"
    },
    {
      "x": -24,
      "y": 33,
      "z": -2,
      "name": "Rock_Ice"
    },
    {
      "x": -24,
      "y": 34,
      "z": -2,
      "name": "Rock_Ice"
    },
    {
      "x": -24,
      "y": 35,
      "z": -2,
      "name": "Rock_Ice"
    },
    {
      "x": -24,
      "y": 36,
      "z": -2,
      "name": "Rock_Ice"
    },
    {
      "x": -24,
      "y": 37,
      "z": -2,
      "name": "Rock_Ice"
    },
    {
      "x": -24,
      "y": 38,
      "z": -2,
      "name": "Rock_Ice"
    },
    {
      "x": -24,
      "y": 39,
      "z": -2,
      "name": "Rock_Ice"
    },
    {
      "x": -24,
      "y": 40,
      "z": -2,
      "name": "Rock_Ice"
    },
    {
      "x": -24,
      "y": 41,
      "z": -2,
      "name": "Rock_Ice"
    },
    {
      "x": -24,
      "y": 42,
      "z": -2,
      "name": "Rock_Ice"
    },
    {
      "x": -24,
      "y": 43,
      "z": -2,
      "name": "Rock_Ice"
    },
    {
      "x": -24,
      "y": 44,
      "z": -2,
      "name": "Rock_Ice"
    },
    {
      "x": -24,
      "y": 45,
      "z": -2,
      "name": "Rock_Ice"
    },
    {
      "x": -24,
      "y": 46,
      "z": -2,
      "name": "Rock_Ice"
    },
    {
      "x": -24,
      "y": 47,
      "z": -2,
      "name": "Rock_Ice"
    },
    {
      "x": -24,
      "y": 48,
      "z": -2,
      "name": "Rock_Ice"
    },
    {
      "x": -24,
      "y": 49,
      "z": -2,
      "name": "Rock_Ice_Permafrost"
    },
    {
      "x": -24,
      "y": 50,
      "z": -2,
      "name": "Rock_Ice"
    },
    {
      "x": -24,
      "y": 51,
      "z": -2,
      "name": "Rock_Ice_Permafrost"
    },
    {
      "x": -24,
      "y": 52,
      "z": -2,
      "name": "Rock_Ice_Permafrost"
    },
    {
      "x": -24,
      "y": 53,
      "z": -2,
      "name": "Rock_Ice_Permafrost"
    },
    {
      "x": -24,
      "y": 54,
      "z": -2,
      "name": "Rock_Ice_Permafrost"
    },
    {
      "x": -24,
      "y": 17,
      "z": -1,
      "name": "Rock_Ice"
    },
    {
      "x": -24,
      "y": 18,
      "z": -1,
      "name": "Rock_Ice"
    },
    {
      "x": -24,
      "y": 19,
      "z": -1,
      "name": "Rock_Ice"
    },
    {
      "x": -24,
      "y": 20,
      "z": -1,
      "name": "Rock_Ice"
    },
    {
      "x": -24,
      "y": 21,
      "z": -1,
      "name": "Rock_Ice"
    },
    {
      "x": -24,
      "y": 22,
      "z": -1,
      "name": "Rock_Ice"
    },
    {
      "x": -24,
      "y": 23,
      "z": -1,
      "name": "Rock_Ice"
    },
    {
      "x": -24,
      "y": 24,
      "z": -1,
      "name": "Rock_Ice"
    },
    {
      "x": -24,
      "y": 25,
      "z": -1,
      "name": "Rock_Ice"
    },
    {
      "x": -24,
      "y": 26,
      "z": -1,
      "name": "Rock_Ice"
    },
    {
      "x": -24,
      "y": 27,
      "z": -1,
      "name": "Rock_Ice"
    },
    {
      "x": -24,
      "y": 28,
      "z": -1,
      "name": "Rock_Ice"
    },
    {
      "x": -24,
      "y": 29,
      "z": -1,
      "name": "Rock_Ice"
    },
    {
      "x": -24,
      "y": 30,
      "z": -1,
      "name": "Rock_Ice"
    },
    {
      "x": -24,
      "y": 31,
      "z": -1,
      "name": "Rock_Ice"
    },
    {
      "x": -24,
      "y": 32,
      "z": -1,
      "name": "Rock_Ice"
    },
    {
      "x": -24,
      "y": 33,
      "z": -1,
      "name": "Rock_Ice"
    },
    {
      "x": -24,
      "y": 34,
      "z": -1,
      "name": "Rock_Ice"
    },
    {
      "x": -24,
      "y": 35,
      "z": -1,
      "name": "Rock_Ice"
    },
    {
      "x": -24,
      "y": 36,
      "z": -1,
      "name": "Rock_Ice"
    },
    {
      "x": -24,
      "y": 37,
      "z": -1,
      "name": "Rock_Ice"
    },
    {
      "x": -24,
      "y": 38,
      "z": -1,
      "name": "Rock_Ice"
    },
    {
      "x": -24,
      "y": 39,
      "z": -1,
      "name": "Rock_Ice"
    },
    {
      "x": -24,
      "y": 40,
      "z": -1,
      "name": "Rock_Ice"
    },
    {
      "x": -24,
      "y": 41,
      "z": -1,
      "name": "Rock_Ice"
    },
    {
      "x": -24,
      "y": 42,
      "z": -1,
      "name": "Rock_Ice"
    },
    {
      "x": -24,
      "y": 43,
      "z": -1,
      "name": "Rock_Ice"
    },
    {
      "x": -24,
      "y": 44,
      "z": -1,
      "name": "Rock_Ice"
    },
    {
      "x": -24,
      "y": 45,
      "z": -1,
      "name": "Rock_Ice"
    },
    {
      "x": -24,
      "y": 46,
      "z": -1,
      "name": "Rock_Ice"
    },
    {
      "x": -24,
      "y": 47,
      "z": -1,
      "name": "Soil_Snow"
    },
    {
      "x": -24,
      "y": 20,
      "z": 0,
      "name": "Rock_Ice"
    },
    {
      "x": -24,
      "y": 21,
      "z": 0,
      "name": "Rock_Ice"
    },
    {
      "x": -24,
      "y": 22,
      "z": 0,
      "name": "Rock_Ice"
    },
    {
      "x": -24,
      "y": 23,
      "z": 0,
      "name": "Rock_Ice"
    },
    {
      "x": -24,
      "y": 24,
      "z": 0,
      "name": "Rock_Ice"
    },
    {
      "x": -24,
      "y": 25,
      "z": 0,
      "name": "Rock_Ice"
    },
    {
      "x": -24,
      "y": 26,
      "z": 0,
      "name": "Rock_Ice"
    },
    {
      "x": -24,
      "y": 27,
      "z": 0,
      "name": "Rock_Ice"
    },
    {
      "x": -24,
      "y": 28,
      "z": 0,
      "name": "Rock_Ice"
    },
    {
      "x": -24,
      "y": 29,
      "z": 0,
      "name": "Rock_Ice"
    },
    {
      "x": -24,
      "y": 30,
      "z": 0,
      "name": "Rock_Ice"
    },
    {
      "x": -24,
      "y": 31,
      "z": 0,
      "name": "Rock_Ice"
    },
    {
      "x": -24,
      "y": 32,
      "z": 0,
      "name": "Rock_Ice"
    },
    {
      "x": -24,
      "y": 33,
      "z": 0,
      "name": "Rock_Ice"
    },
    {
      "x": -24,
      "y": 34,
      "z": 0,
      "name": "Rock_Ice"
    },
    {
      "x": -24,
      "y": 35,
      "z": 0,
      "name": "Rock_Ice"
    },
    {
      "x": -24,
      "y": 36,
      "z": 0,
      "name": "Rock_Ice"
    },
    {
      "x": -24,
      "y": 37,
      "z": 0,
      "name": "Rock_Ice"
    },
    {
      "x": -24,
      "y": 38,
      "z": 0,
      "name": "Rock_Ice"
    },
    {
      "x": -24,
      "y": 39,
      "z": 0,
      "name": "Rock_Ice"
    },
    {
      "x": -24,
      "y": 40,
      "z": 0,
      "name": "Rock_Ice"
    },
    {
      "x": -24,
      "y": 41,
      "z": 0,
      "name": "Soil_Snow"
    },
    {
      "x": -24,
      "y": 26,
      "z": 1,
      "name": "Rock_Ice"
    },
    {
      "x": -24,
      "y": 27,
      "z": 1,
      "name": "Rock_Ice"
    },
    {
      "x": -24,
      "y": 28,
      "z": 1,
      "name": "Rock_Ice"
    },
    {
      "x": -24,
      "y": 29,
      "z": 1,
      "name": "Rock_Ice"
    },
    {
      "x": -24,
      "y": 30,
      "z": 1,
      "name": "Rock_Ice"
    },
    {
      "x": -24,
      "y": 31,
      "z": 1,
      "name": "Rock_Ice"
    },
    {
      "x": -24,
      "y": 32,
      "z": 1,
      "name": "Rock_Ice"
    },
    {
      "x": -24,
      "y": 33,
      "z": 1,
      "name": "Rock_Ice"
    },
    {
      "x": -24,
      "y": 34,
      "z": 1,
      "name": "Rock_Ice"
    },
    {
      "x": -24,
      "y": 35,
      "z": 1,
      "name": "Rock_Ice"
    },
    {
      "x": -24,
      "y": 36,
      "z": 1,
      "name": "Rock_Ice"
    },
    {
      "x": -24,
      "y": 37,
      "z": 1,
      "name": "Rock_Ice"
    },
    {
      "x": -24,
      "y": 38,
      "z": 1,
      "name": "Rock_Ice"
    },
    {
      "x": -24,
      "y": 39,
      "z": 1,
      "name": "Rock_Ice"
    },
    {
      "x": -24,
      "y": 40,
      "z": 1,
      "name": "Rock_Ice"
    },
    {
      "x": -24,
      "y": 41,
      "z": 1,
      "name": "Soil_Snow"
    },
    {
      "x": -24,
      "y": 26,
      "z": 2,
      "name": "Rock_Ice"
    },
    {
      "x": -24,
      "y": 27,
      "z": 2,
      "name": "Rock_Ice"
    },
    {
      "x": -24,
      "y": 28,
      "z": 2,
      "name": "Rock_Ice"
    },
    {
      "x": -24,
      "y": 29,
      "z": 2,
      "name": "Rock_Ice"
    },
    {
      "x": -24,
      "y": 30,
      "z": 2,
      "name": "Rock_Ice"
    },
    {
      "x": -24,
      "y": 31,
      "z": 2,
      "name": "Rock_Ice"
    },
    {
      "x": -24,
      "y": 32,
      "z": 2,
      "name": "Rock_Ice"
    },
    {
      "x": -24,
      "y": 33,
      "z": 2,
      "name": "Rock_Ice"
    },
    {
      "x": -24,
      "y": 34,
      "z": 2,
      "name": "Rock_Ice"
    },
    {
      "x": -24,
      "y": 35,
      "z": 2,
      "name": "Rock_Ice"
    },
    {
      "x": -24,
      "y": 36,
      "z": 2,
      "name": "Rock_Ice"
    },
    {
      "x": -24,
      "y": 37,
      "z": 2,
      "name": "Rock_Ice_Permafrost"
    },
    {
      "x": -24,
      "y": 38,
      "z": 2,
      "name": "Rock_Ice_Permafrost"
    },
    {
      "x": -24,
      "y": 39,
      "z": 2,
      "name": "Rock_Ice_Permafrost"
    },
    {
      "x": -24,
      "y": 40,
      "z": 2,
      "name": "Rock_Ice_Permafrost"
    },
    {
      "x": -24,
      "y": 41,
      "z": 2,
      "name": "Rock_Ice_Permafrost"
    },
    {
      "x": -24,
      "y": 42,
      "z": 2,
      "name": "Rock_Ice"
    },
    {
      "x": -24,
      "y": 43,
      "z": 2,
      "name": "Soil_Snow"
    },
    {
      "x": -24,
      "y": 25,
      "z": 3,
      "name": "Rock_Ice"
    },
    {
      "x": -24,
      "y": 26,
      "z": 3,
      "name": "Rock_Ice"
    },
    {
      "x": -24,
      "y": 27,
      "z": 3,
      "name": "Rock_Ice"
    },
    {
      "x": -24,
      "y": 28,
      "z": 3,
      "name": "Rock_Ice"
    },
    {
      "x": -24,
      "y": 29,
      "z": 3,
      "name": "Rock_Ice"
    },
    {
      "x": -24,
      "y": 30,
      "z": 3,
      "name": "Rock_Ice"
    },
    {
      "x": -24,
      "y": 31,
      "z": 3,
      "name": "Rock_Ice"
    },
    {
      "x": -24,
      "y": 32,
      "z": 3,
      "name": "Rock_Ice_Permafrost"
    },
    {
      "x": -24,
      "y": 33,
      "z": 3,
      "name": "Rock_Ice_Permafrost"
    },
    {
      "x": -24,
      "y": 34,
      "z": 3,
      "name": "Rock_Ice_Permafrost"
    },
    {
      "x": -24,
      "y": 35,
      "z": 3,
      "name": "Rock_Ice_Permafrost"
    },
    {
      "x": -24,
      "y": 36,
      "z": 3,
      "name": "Rock_Ice_Permafrost"
    },
    {
      "x": -24,
      "y": 37,
      "z": 3,
      "name": "Rock_Ice_Permafrost"
    },
    {
      "x": -24,
      "y": 38,
      "z": 3,
      "name": "Rock_Ice_Permafrost"
    },
    {
      "x": -24,
      "y": 39,
      "z": 3,
      "name": "Rock_Ice_Permafrost"
    },
    {
      "x": -24,
      "y": 40,
      "z": 3,
      "name": "Rock_Ice_Permafrost"
    },
    {
      "x": -24,
      "y": 41,
      "z": 3,
      "name": "Rock_Ice"
    },
    {
      "x": -24,
      "y": 42,
      "z": 3,
      "name": "Soil_Snow"
    },
    {
      "x": -24,
      "y": 25,
      "z": 4,
      "name": "Rock_Ice_Permafrost"
    },
    {
      "x": -24,
      "y": 26,
      "z": 4,
      "name": "Rock_Ice_Permafrost"
    },
    {
      "x": -24,
      "y": 27,
      "z": 4,
      "name": "Rock_Ice_Permafrost"
    },
    {
      "x": -24,
      "y": 28,
      "z": 4,
      "name": "Rock_Ice_Permafrost"
    },
    {
      "x": -24,
      "y": 29,
      "z": 4,
      "name": "Rock_Ice"
    },
    {
      "x": -24,
      "y": 30,
      "z": 4,
      "name": "Rock_Ice_Permafrost"
    },
    {
      "x": -24,
      "y": 31,
      "z": 4,
      "name": "Rock_Ice_Permafrost"
    },
    {
      "x": -24,
      "y": 32,
      "z": 4,
      "name": "Rock_Ice_Permafrost"
    },
    {
      "x": -24,
      "y": 33,
      "z": 4,
      "name": "Rock_Ice_Permafrost"
    },
    {
      "x": -24,
      "y": 34,
      "z": 4,
      "name": "Rock_Ice_Permafrost"
    },
    {
      "x": -24,
      "y": 35,
      "z": 4,
      "name": "Rock_Ice_Permafrost"
    },
    {
      "x": -24,
      "y": 36,
      "z": 4,
      "name": "Rock_Ice_Permafrost"
    },
    {
      "x": -24,
      "y": 37,
      "z": 4,
      "name": "Rock_Ice_Permafrost"
    },
    {
      "x": -24,
      "y": 38,
      "z": 4,
      "name": "Rock_Ice_Permafrost"
    },
    {
      "x": -24,
      "y": 39,
      "z": 4,
      "name": "Rock_Ice_Permafrost"
    },
    {
      "x": -24,
      "y": 40,
      "z": 4,
      "name": "Rock_Ice"
    },
    {
      "x": -24,
      "y": 41,
      "z": 4,
      "name": "Soil_Snow"
    },
    {
      "x": -24,
      "y": 26,
      "z": 5,
      "name": "Rock_Ice_Permafrost"
    },
    {
      "x": -24,
      "y": 27,
      "z": 5,
      "name": "Rock_Ice_Permafrost"
    },
    {
      "x": -24,
      "y": 28,
      "z": 5,
      "name": "Rock_Ice_Permafrost"
    },
    {
      "x": -24,
      "y": 29,
      "z": 5,
      "name": "Rock_Ice_Permafrost"
    },
    {
      "x": -24,
      "y": 30,
      "z": 5,
      "name": "Rock_Ice_Permafrost"
    },
    {
      "x": -24,
      "y": 31,
      "z": 5,
      "name": "Rock_Ice_Permafrost"
    },
    {
      "x": -24,
      "y": 32,
      "z": 5,
      "name": "Rock_Ice_Permafrost"
    },
    {
      "x": -24,
      "y": 33,
      "z": 5,
      "name": "Rock_Ice_Permafrost"
    },
    {
      "x": -24,
      "y": 34,
      "z": 5,
      "name": "Rock_Ice_Permafrost"
    },
    {
      "x": -24,
      "y": 35,
      "z": 5,
      "name": "Rock_Ice_Permafrost"
    },
    {
      "x": -24,
      "y": 36,
      "z": 5,
      "name": "Rock_Ice"
    },
    {
      "x": -24,
      "y": 37,
      "z": 5,
      "name": "Rock_Ice_Permafrost"
    },
    {
      "x": -24,
      "y": 38,
      "z": 5,
      "name": "Rock_Ice"
    },
    {
      "x": -24,
      "y": 39,
      "z": 5,
      "name": "Rock_Ice"
    },
    {
      "x": -24,
      "y": 40,
      "z": 5,
      "name": "Rock_Ice"
    },
    {
      "x": -24,
      "y": 41,
      "z": 5,
      "name": "Soil_Snow"
    },
    {
      "x": -24,
      "y": 30,
      "z": 6,
      "name": "Rock_Ice_Permafrost"
    },
    {
      "x": -24,
      "y": 31,
      "z": 6,
      "name": "Rock_Ice_Permafrost"
    },
    {
      "x": -24,
      "y": 32,
      "z": 6,
      "name": "Rock_Ice"
    },
    {
      "x": -24,
      "y": 33,
      "z": 6,
      "name": "Rock_Ice"
    },
    {
      "x": -24,
      "y": 34,
      "z": 6,
      "name": "Rock_Ice"
    },
    {
      "x": -24,
      "y": 35,
      "z": 6,
      "name": "Rock_Ice"
    },
    {
      "x": -24,
      "y": 36,
      "z": 6,
      "name": "Rock_Ice"
    },
    {
      "x": -24,
      "y": 37,
      "z": 6,
      "name": "Rock_Ice"
    },
    {
      "x": -24,
      "y": 38,
      "z": 6,
      "name": "Rock_Ice"
    },
    {
      "x": -24,
      "y": 39,
      "z": 6,
      "name": "Rock_Ice"
    },
    {
      "x": -24,
      "y": 40,
      "z": 6,
      "name": "Soil_Snow"
    },
    {
      "x": -24,
      "y": 33,
      "z": 7,
      "name": "Rock_Ice"
    },
    {
      "x": -24,
      "y": 34,
      "z": 7,
      "name": "Rock_Ice"
    },
    {
      "x": -24,
      "y": 35,
      "z": 7,
      "name": "Rock_Ice"
    },
    {
      "x": -24,
      "y": 36,
      "z": 7,
      "name": "Rock_Ice"
    },
    {
      "x": -24,
      "y": 37,
      "z": 7,
      "name": "Rock_Ice"
    },
    {
      "x": -24,
      "y": 38,
      "z": 7,
      "name": "Rock_Ice"
    },
    {
      "x": -24,
      "y": 39,
      "z": 7,
      "name": "Soil_Snow"
    },
    {
      "x": -24,
      "y": 37,
      "z": 8,
      "name": "Rock_Ice"
    },
    {
      "x": -24,
      "y": 38,
      "z": 8,
      "name": "Soil_Snow"
    },
    {
      "x": -23,
      "y": 40,
      "z": -15,
      "name": "Rock_Ice"
    },
    {
      "x": -23,
      "y": 41,
      "z": -15,
      "name": "Rock_Ice"
    },
    {
      "x": -23,
      "y": 42,
      "z": -15,
      "name": "Soil_Snow"
    },
    {
      "x": -23,
      "y": 34,
      "z": -14,
      "name": "Rock_Ice"
    },
    {
      "x": -23,
      "y": 35,
      "z": -14,
      "name": "Rock_Ice"
    },
    {
      "x": -23,
      "y": 36,
      "z": -14,
      "name": "Rock_Ice"
    },
    {
      "x": -23,
      "y": 37,
      "z": -14,
      "name": "Rock_Ice"
    },
    {
      "x": -23,
      "y": 38,
      "z": -14,
      "name": "Rock_Ice"
    },
    {
      "x": -23,
      "y": 39,
      "z": -14,
      "name": "Rock_Ice"
    },
    {
      "x": -23,
      "y": 40,
      "z": -14,
      "name": "Rock_Ice"
    },
    {
      "x": -23,
      "y": 41,
      "z": -14,
      "name": "Rock_Ice"
    },
    {
      "x": -23,
      "y": 42,
      "z": -14,
      "name": "Rock_Ice"
    },
    {
      "x": -23,
      "y": 43,
      "z": -14,
      "name": "Soil_Snow"
    },
    {
      "x": -23,
      "y": 30,
      "z": -13,
      "name": "Rock_Ice"
    },
    {
      "x": -23,
      "y": 31,
      "z": -13,
      "name": "Rock_Ice"
    },
    {
      "x": -23,
      "y": 32,
      "z": -13,
      "name": "Rock_Ice"
    },
    {
      "x": -23,
      "y": 33,
      "z": -13,
      "name": "Rock_Ice"
    },
    {
      "x": -23,
      "y": 34,
      "z": -13,
      "name": "Rock_Ice"
    },
    {
      "x": -23,
      "y": 35,
      "z": -13,
      "name": "Rock_Ice"
    },
    {
      "x": -23,
      "y": 36,
      "z": -13,
      "name": "Rock_Ice"
    },
    {
      "x": -23,
      "y": 37,
      "z": -13,
      "name": "Rock_Ice"
    },
    {
      "x": -23,
      "y": 38,
      "z": -13,
      "name": "Rock_Ice"
    },
    {
      "x": -23,
      "y": 39,
      "z": -13,
      "name": "Rock_Ice"
    },
    {
      "x": -23,
      "y": 40,
      "z": -13,
      "name": "Rock_Ice"
    },
    {
      "x": -23,
      "y": 41,
      "z": -13,
      "name": "Rock_Ice"
    },
    {
      "x": -23,
      "y": 42,
      "z": -13,
      "name": "Rock_Ice"
    },
    {
      "x": -23,
      "y": 43,
      "z": -13,
      "name": "Rock_Ice"
    },
    {
      "x": -23,
      "y": 44,
      "z": -13,
      "name": "Soil_Snow"
    },
    {
      "x": -23,
      "y": 28,
      "z": -12,
      "name": "Rock_Ice"
    },
    {
      "x": -23,
      "y": 29,
      "z": -12,
      "name": "Rock_Ice"
    },
    {
      "x": -23,
      "y": 30,
      "z": -12,
      "name": "Rock_Ice"
    },
    {
      "x": -23,
      "y": 31,
      "z": -12,
      "name": "Rock_Ice"
    },
    {
      "x": -23,
      "y": 32,
      "z": -12,
      "name": "Rock_Ice"
    },
    {
      "x": -23,
      "y": 33,
      "z": -12,
      "name": "Rock_Ice"
    },
    {
      "x": -23,
      "y": 34,
      "z": -12,
      "name": "Rock_Ice"
    },
    {
      "x": -23,
      "y": 35,
      "z": -12,
      "name": "Rock_Ice"
    },
    {
      "x": -23,
      "y": 36,
      "z": -12,
      "name": "Rock_Ice"
    },
    {
      "x": -23,
      "y": 37,
      "z": -12,
      "name": "Rock_Ice"
    },
    {
      "x": -23,
      "y": 38,
      "z": -12,
      "name": "Rock_Ice"
    },
    {
      "x": -23,
      "y": 39,
      "z": -12,
      "name": "Rock_Ice"
    },
    {
      "x": -23,
      "y": 40,
      "z": -12,
      "name": "Rock_Ice"
    },
    {
      "x": -23,
      "y": 41,
      "z": -12,
      "name": "Rock_Ice"
    },
    {
      "x": -23,
      "y": 42,
      "z": -12,
      "name": "Rock_Ice"
    },
    {
      "x": -23,
      "y": 43,
      "z": -12,
      "name": "Rock_Ice"
    },
    {
      "x": -23,
      "y": 44,
      "z": -12,
      "name": "Rock_Ice"
    },
    {
      "x": -23,
      "y": 45,
      "z": -12,
      "name": "Rock_Ice"
    },
    {
      "x": -23,
      "y": 46,
      "z": -12,
      "name": "Soil_Snow"
    },
    {
      "x": -23,
      "y": 26,
      "z": -11,
      "name": "Rock_Ice"
    },
    {
      "x": -23,
      "y": 27,
      "z": -11,
      "name": "Rock_Ice"
    },
    {
      "x": -23,
      "y": 28,
      "z": -11,
      "name": "Rock_Ice"
    },
    {
      "x": -23,
      "y": 29,
      "z": -11,
      "name": "Rock_Ice"
    },
    {
      "x": -23,
      "y": 30,
      "z": -11,
      "name": "Rock_Ice"
    },
    {
      "x": -23,
      "y": 31,
      "z": -11,
      "name": "Rock_Ice"
    },
    {
      "x": -23,
      "y": 32,
      "z": -11,
      "name": "Rock_Ice"
    },
    {
      "x": -23,
      "y": 33,
      "z": -11,
      "name": "Rock_Ice"
    },
    {
      "x": -23,
      "y": 34,
      "z": -11,
      "name": "Rock_Ice"
    },
    {
      "x": -23,
      "y": 35,
      "z": -11,
      "name": "Rock_Ice"
    },
    {
      "x": -23,
      "y": 36,
      "z": -11,
      "name": "Rock_Ice"
    },
    {
      "x": -23,
      "y": 37,
      "z": -11,
      "name": "Rock_Ice"
    },
    {
      "x": -23,
      "y": 38,
      "z": -11,
      "name": "Rock_Ice"
    },
    {
      "x": -23,
      "y": 39,
      "z": -11,
      "name": "Rock_Ice"
    },
    {
      "x": -23,
      "y": 40,
      "z": -11,
      "name": "Rock_Ice"
    },
    {
      "x": -23,
      "y": 41,
      "z": -11,
      "name": "Rock_Ice"
    },
    {
      "x": -23,
      "y": 42,
      "z": -11,
      "name": "Rock_Ice"
    },
    {
      "x": -23,
      "y": 43,
      "z": -11,
      "name": "Rock_Ice"
    },
    {
      "x": -23,
      "y": 44,
      "z": -11,
      "name": "Rock_Ice"
    },
    {
      "x": -23,
      "y": 45,
      "z": -11,
      "name": "Rock_Ice"
    },
    {
      "x": -23,
      "y": 46,
      "z": -11,
      "name": "Rock_Ice"
    },
    {
      "x": -23,
      "y": 47,
      "z": -11,
      "name": "Soil_Snow"
    },
    {
      "x": -23,
      "y": 16,
      "z": -10,
      "name": "Rock_Ice_Permafrost"
    },
    {
      "x": -23,
      "y": 17,
      "z": -10,
      "name": "Rock_Ice_Permafrost"
    },
    {
      "x": -23,
      "y": 18,
      "z": -10,
      "name": "Rock_Ice_Permafrost"
    },
    {
      "x": -23,
      "y": 19,
      "z": -10,
      "name": "Rock_Ice_Permafrost"
    },
    {
      "x": -23,
      "y": 20,
      "z": -10,
      "name": "Rock_Ice_Permafrost"
    },
    {
      "x": -23,
      "y": 21,
      "z": -10,
      "name": "Rock_Ice_Permafrost"
    },
    {
      "x": -23,
      "y": 22,
      "z": -10,
      "name": "Rock_Ice"
    },
    {
      "x": -23,
      "y": 23,
      "z": -10,
      "name": "Rock_Ice"
    },
    {
      "x": -23,
      "y": 24,
      "z": -10,
      "name": "Rock_Ice"
    },
    {
      "x": -23,
      "y": 25,
      "z": -10,
      "name": "Rock_Ice"
    },
    {
      "x": -23,
      "y": 26,
      "z": -10,
      "name": "Rock_Ice"
    },
    {
      "x": -23,
      "y": 27,
      "z": -10,
      "name": "Rock_Ice"
    },
    {
      "x": -23,
      "y": 28,
      "z": -10,
      "name": "Rock_Ice"
    },
    {
      "x": -23,
      "y": 29,
      "z": -10,
      "name": "Rock_Ice"
    },
    {
      "x": -23,
      "y": 30,
      "z": -10,
      "name": "Rock_Ice"
    },
    {
      "x": -23,
      "y": 31,
      "z": -10,
      "name": "Rock_Ice"
    },
    {
      "x": -23,
      "y": 32,
      "z": -10,
      "name": "Rock_Ice"
    },
    {
      "x": -23,
      "y": 33,
      "z": -10,
      "name": "Rock_Ice"
    },
    {
      "x": -23,
      "y": 34,
      "z": -10,
      "name": "Rock_Ice"
    },
    {
      "x": -23,
      "y": 35,
      "z": -10,
      "name": "Rock_Ice"
    },
    {
      "x": -23,
      "y": 36,
      "z": -10,
      "name": "Rock_Ice"
    },
    {
      "x": -23,
      "y": 37,
      "z": -10,
      "name": "Rock_Ice"
    },
    {
      "x": -23,
      "y": 38,
      "z": -10,
      "name": "Rock_Ice"
    },
    {
      "x": -23,
      "y": 39,
      "z": -10,
      "name": "Rock_Ice"
    },
    {
      "x": -23,
      "y": 40,
      "z": -10,
      "name": "Rock_Ice"
    },
    {
      "x": -23,
      "y": 41,
      "z": -10,
      "name": "Rock_Ice"
    },
    {
      "x": -23,
      "y": 42,
      "z": -10,
      "name": "Rock_Ice"
    },
    {
      "x": -23,
      "y": 43,
      "z": -10,
      "name": "Rock_Ice"
    },
    {
      "x": -23,
      "y": 44,
      "z": -10,
      "name": "Rock_Ice"
    },
    {
      "x": -23,
      "y": 45,
      "z": -10,
      "name": "Rock_Ice"
    },
    {
      "x": -23,
      "y": 46,
      "z": -10,
      "name": "Rock_Ice"
    },
    {
      "x": -23,
      "y": 47,
      "z": -10,
      "name": "Rock_Ice"
    },
    {
      "x": -23,
      "y": 48,
      "z": -10,
      "name": "Rock_Ice"
    },
    {
      "x": -23,
      "y": 49,
      "z": -10,
      "name": "Soil_Snow"
    },
    {
      "x": -23,
      "y": 15,
      "z": -9,
      "name": "Rock_Ice_Permafrost"
    },
    {
      "x": -23,
      "y": 16,
      "z": -9,
      "name": "Rock_Ice_Permafrost"
    },
    {
      "x": -23,
      "y": 17,
      "z": -9,
      "name": "Rock_Ice_Permafrost"
    },
    {
      "x": -23,
      "y": 18,
      "z": -9,
      "name": "Rock_Ice_Permafrost"
    },
    {
      "x": -23,
      "y": 19,
      "z": -9,
      "name": "Rock_Ice_Permafrost"
    },
    {
      "x": -23,
      "y": 20,
      "z": -9,
      "name": "Rock_Ice"
    },
    {
      "x": -23,
      "y": 21,
      "z": -9,
      "name": "Rock_Ice"
    },
    {
      "x": -23,
      "y": 22,
      "z": -9,
      "name": "Rock_Ice"
    },
    {
      "x": -23,
      "y": 23,
      "z": -9,
      "name": "Rock_Ice"
    },
    {
      "x": -23,
      "y": 24,
      "z": -9,
      "name": "Rock_Ice"
    },
    {
      "x": -23,
      "y": 25,
      "z": -9,
      "name": "Rock_Ice"
    },
    {
      "x": -23,
      "y": 26,
      "z": -9,
      "name": "Rock_Ice"
    },
    {
      "x": -23,
      "y": 27,
      "z": -9,
      "name": "Rock_Ice"
    },
    {
      "x": -23,
      "y": 28,
      "z": -9,
      "name": "Rock_Ice"
    },
    {
      "x": -23,
      "y": 29,
      "z": -9,
      "name": "Rock_Ice"
    },
    {
      "x": -23,
      "y": 30,
      "z": -9,
      "name": "Rock_Ice"
    },
    {
      "x": -23,
      "y": 31,
      "z": -9,
      "name": "Rock_Ice"
    },
    {
      "x": -23,
      "y": 32,
      "z": -9,
      "name": "Rock_Ice"
    },
    {
      "x": -23,
      "y": 33,
      "z": -9,
      "name": "Rock_Ice"
    },
    {
      "x": -23,
      "y": 34,
      "z": -9,
      "name": "Rock_Ice"
    },
    {
      "x": -23,
      "y": 35,
      "z": -9,
      "name": "Rock_Ice"
    },
    {
      "x": -23,
      "y": 36,
      "z": -9,
      "name": "Rock_Ice"
    },
    {
      "x": -23,
      "y": 37,
      "z": -9,
      "name": "Rock_Ice"
    },
    {
      "x": -23,
      "y": 38,
      "z": -9,
      "name": "Rock_Ice"
    },
    {
      "x": -23,
      "y": 39,
      "z": -9,
      "name": "Rock_Ice"
    },
    {
      "x": -23,
      "y": 40,
      "z": -9,
      "name": "Rock_Ice"
    },
    {
      "x": -23,
      "y": 41,
      "z": -9,
      "name": "Rock_Ice"
    },
    {
      "x": -23,
      "y": 42,
      "z": -9,
      "name": "Rock_Ice"
    },
    {
      "x": -23,
      "y": 43,
      "z": -9,
      "name": "Rock_Ice"
    },
    {
      "x": -23,
      "y": 44,
      "z": -9,
      "name": "Rock_Ice"
    },
    {
      "x": -23,
      "y": 45,
      "z": -9,
      "name": "Rock_Ice"
    },
    {
      "x": -23,
      "y": 46,
      "z": -9,
      "name": "Rock_Ice"
    },
    {
      "x": -23,
      "y": 47,
      "z": -9,
      "name": "Rock_Ice"
    },
    {
      "x": -23,
      "y": 48,
      "z": -9,
      "name": "Rock_Ice"
    },
    {
      "x": -23,
      "y": 49,
      "z": -9,
      "name": "Rock_Ice"
    },
    {
      "x": -23,
      "y": 50,
      "z": -9,
      "name": "Soil_Snow"
    },
    {
      "x": -23,
      "y": 14,
      "z": -8,
      "name": "Rock_Ice_Permafrost"
    },
    {
      "x": -23,
      "y": 15,
      "z": -8,
      "name": "Rock_Ice_Permafrost"
    },
    {
      "x": -23,
      "y": 16,
      "z": -8,
      "name": "Rock_Ice_Permafrost"
    },
    {
      "x": -23,
      "y": 17,
      "z": -8,
      "name": "Rock_Ice_Permafrost"
    },
    {
      "x": -23,
      "y": 18,
      "z": -8,
      "name": "Rock_Ice_Permafrost"
    },
    {
      "x": -23,
      "y": 19,
      "z": -8,
      "name": "Rock_Ice"
    },
    {
      "x": -23,
      "y": 20,
      "z": -8,
      "name": "Rock_Ice"
    },
    {
      "x": -23,
      "y": 21,
      "z": -8,
      "name": "Rock_Ice"
    },
    {
      "x": -23,
      "y": 22,
      "z": -8,
      "name": "Rock_Ice"
    },
    {
      "x": -23,
      "y": 23,
      "z": -8,
      "name": "Rock_Ice"
    },
    {
      "x": -23,
      "y": 24,
      "z": -8,
      "name": "Rock_Ice"
    },
    {
      "x": -23,
      "y": 25,
      "z": -8,
      "name": "Rock_Ice"
    },
    {
      "x": -23,
      "y": 26,
      "z": -8,
      "name": "Rock_Ice"
    },
    {
      "x": -23,
      "y": 27,
      "z": -8,
      "name": "Rock_Ice"
    },
    {
      "x": -23,
      "y": 28,
      "z": -8,
      "name": "Rock_Ice"
    },
    {
      "x": -23,
      "y": 29,
      "z": -8,
      "name": "Rock_Ice"
    },
    {
      "x": -23,
      "y": 30,
      "z": -8,
      "name": "Rock_Ice"
    },
    {
      "x": -23,
      "y": 31,
      "z": -8,
      "name": "Rock_Ice"
    },
    {
      "x": -23,
      "y": 32,
      "z": -8,
      "name": "Rock_Ice"
    },
    {
      "x": -23,
      "y": 33,
      "z": -8,
      "name": "Rock_Ice"
    },
    {
      "x": -23,
      "y": 34,
      "z": -8,
      "name": "Rock_Ice"
    },
    {
      "x": -23,
      "y": 35,
      "z": -8,
      "name": "Rock_Ice"
    },
    {
      "x": -23,
      "y": 36,
      "z": -8,
      "name": "Rock_Ice"
    },
    {
      "x": -23,
      "y": 37,
      "z": -8,
      "name": "Rock_Ice"
    },
    {
      "x": -23,
      "y": 38,
      "z": -8,
      "name": "Rock_Ice"
    },
    {
      "x": -23,
      "y": 39,
      "z": -8,
      "name": "Rock_Ice"
    },
    {
      "x": -23,
      "y": 40,
      "z": -8,
      "name": "Rock_Ice"
    },
    {
      "x": -23,
      "y": 41,
      "z": -8,
      "name": "Rock_Ice"
    },
    {
      "x": -23,
      "y": 42,
      "z": -8,
      "name": "Rock_Ice"
    },
    {
      "x": -23,
      "y": 43,
      "z": -8,
      "name": "Rock_Ice"
    },
    {
      "x": -23,
      "y": 44,
      "z": -8,
      "name": "Rock_Ice"
    },
    {
      "x": -23,
      "y": 45,
      "z": -8,
      "name": "Rock_Ice"
    },
    {
      "x": -23,
      "y": 46,
      "z": -8,
      "name": "Rock_Ice"
    },
    {
      "x": -23,
      "y": 47,
      "z": -8,
      "name": "Rock_Ice"
    },
    {
      "x": -23,
      "y": 48,
      "z": -8,
      "name": "Rock_Ice"
    },
    {
      "x": -23,
      "y": 49,
      "z": -8,
      "name": "Rock_Ice"
    },
    {
      "x": -23,
      "y": 50,
      "z": -8,
      "name": "Rock_Ice"
    },
    {
      "x": -23,
      "y": 51,
      "z": -8,
      "name": "Soil_Snow"
    },
    {
      "x": -23,
      "y": 13,
      "z": -7,
      "name": "Rock_Ice_Permafrost"
    },
    {
      "x": -23,
      "y": 14,
      "z": -7,
      "name": "Rock_Ice_Permafrost"
    },
    {
      "x": -23,
      "y": 15,
      "z": -7,
      "name": "Rock_Ice_Permafrost"
    },
    {
      "x": -23,
      "y": 16,
      "z": -7,
      "name": "Rock_Ice_Permafrost"
    },
    {
      "x": -23,
      "y": 17,
      "z": -7,
      "name": "Rock_Ice_Permafrost"
    },
    {
      "x": -23,
      "y": 18,
      "z": -7,
      "name": "Rock_Ice_Permafrost"
    },
    {
      "x": -23,
      "y": 19,
      "z": -7,
      "name": "Rock_Ice"
    },
    {
      "x": -23,
      "y": 20,
      "z": -7,
      "name": "Rock_Ice"
    },
    {
      "x": -23,
      "y": 21,
      "z": -7,
      "name": "Rock_Ice"
    },
    {
      "x": -23,
      "y": 22,
      "z": -7,
      "name": "Rock_Ice"
    },
    {
      "x": -23,
      "y": 23,
      "z": -7,
      "name": "Rock_Ice"
    },
    {
      "x": -23,
      "y": 24,
      "z": -7,
      "name": "Rock_Ice"
    },
    {
      "x": -23,
      "y": 25,
      "z": -7,
      "name": "Rock_Ice"
    },
    {
      "x": -23,
      "y": 26,
      "z": -7,
      "name": "Rock_Ice"
    },
    {
      "x": -23,
      "y": 27,
      "z": -7,
      "name": "Rock_Ice"
    },
    {
      "x": -23,
      "y": 28,
      "z": -7,
      "name": "Rock_Ice"
    },
    {
      "x": -23,
      "y": 29,
      "z": -7,
      "name": "Rock_Ice"
    },
    {
      "x": -23,
      "y": 30,
      "z": -7,
      "name": "Rock_Ice"
    },
    {
      "x": -23,
      "y": 31,
      "z": -7,
      "name": "Rock_Ice"
    },
    {
      "x": -23,
      "y": 32,
      "z": -7,
      "name": "Rock_Ice"
    },
    {
      "x": -23,
      "y": 33,
      "z": -7,
      "name": "Rock_Ice"
    },
    {
      "x": -23,
      "y": 34,
      "z": -7,
      "name": "Rock_Ice"
    },
    {
      "x": -23,
      "y": 35,
      "z": -7,
      "name": "Rock_Ice"
    },
    {
      "x": -23,
      "y": 36,
      "z": -7,
      "name": "Rock_Ice"
    },
    {
      "x": -23,
      "y": 37,
      "z": -7,
      "name": "Rock_Ice"
    },
    {
      "x": -23,
      "y": 38,
      "z": -7,
      "name": "Rock_Ice"
    },
    {
      "x": -23,
      "y": 39,
      "z": -7,
      "name": "Rock_Ice"
    },
    {
      "x": -23,
      "y": 40,
      "z": -7,
      "name": "Rock_Ice"
    },
    {
      "x": -23,
      "y": 41,
      "z": -7,
      "name": "Rock_Ice"
    },
    {
      "x": -23,
      "y": 42,
      "z": -7,
      "name": "Rock_Ice"
    },
    {
      "x": -23,
      "y": 43,
      "z": -7,
      "name": "Rock_Ice"
    },
    {
      "x": -23,
      "y": 44,
      "z": -7,
      "name": "Rock_Ice"
    },
    {
      "x": -23,
      "y": 45,
      "z": -7,
      "name": "Rock_Ice"
    },
    {
      "x": -23,
      "y": 46,
      "z": -7,
      "name": "Rock_Ice"
    },
    {
      "x": -23,
      "y": 47,
      "z": -7,
      "name": "Rock_Ice"
    },
    {
      "x": -23,
      "y": 48,
      "z": -7,
      "name": "Rock_Ice"
    },
    {
      "x": -23,
      "y": 49,
      "z": -7,
      "name": "Rock_Ice"
    },
    {
      "x": -23,
      "y": 50,
      "z": -7,
      "name": "Rock_Ice"
    },
    {
      "x": -23,
      "y": 51,
      "z": -7,
      "name": "Rock_Ice"
    },
    {
      "x": -23,
      "y": 52,
      "z": -7,
      "name": "Rock_Ice"
    },
    {
      "x": -23,
      "y": 53,
      "z": -7,
      "name": "Soil_Snow"
    },
    {
      "x": -23,
      "y": 13,
      "z": -6,
      "name": "Rock_Ice_Permafrost"
    },
    {
      "x": -23,
      "y": 14,
      "z": -6,
      "name": "Rock_Ice_Permafrost"
    },
    {
      "x": -23,
      "y": 15,
      "z": -6,
      "name": "Rock_Ice_Permafrost"
    },
    {
      "x": -23,
      "y": 16,
      "z": -6,
      "name": "Rock_Ice_Permafrost"
    },
    {
      "x": -23,
      "y": 17,
      "z": -6,
      "name": "Rock_Ice_Permafrost"
    },
    {
      "x": -23,
      "y": 18,
      "z": -6,
      "name": "Rock_Ice"
    },
    {
      "x": -23,
      "y": 19,
      "z": -6,
      "name": "Rock_Ice"
    },
    {
      "x": -23,
      "y": 20,
      "z": -6,
      "name": "Rock_Ice"
    },
    {
      "x": -23,
      "y": 21,
      "z": -6,
      "name": "Rock_Ice"
    },
    {
      "x": -23,
      "y": 22,
      "z": -6,
      "name": "Rock_Ice"
    },
    {
      "x": -23,
      "y": 23,
      "z": -6,
      "name": "Rock_Ice"
    },
    {
      "x": -23,
      "y": 24,
      "z": -6,
      "name": "Rock_Ice"
    },
    {
      "x": -23,
      "y": 25,
      "z": -6,
      "name": "Rock_Ice"
    },
    {
      "x": -23,
      "y": 26,
      "z": -6,
      "name": "Rock_Ice"
    },
    {
      "x": -23,
      "y": 27,
      "z": -6,
      "name": "Rock_Ice"
    },
    {
      "x": -23,
      "y": 28,
      "z": -6,
      "name": "Rock_Ice"
    },
    {
      "x": -23,
      "y": 29,
      "z": -6,
      "name": "Rock_Ice"
    },
    {
      "x": -23,
      "y": 30,
      "z": -6,
      "name": "Rock_Ice"
    },
    {
      "x": -23,
      "y": 31,
      "z": -6,
      "name": "Rock_Ice"
    },
    {
      "x": -23,
      "y": 32,
      "z": -6,
      "name": "Rock_Ice"
    },
    {
      "x": -23,
      "y": 33,
      "z": -6,
      "name": "Rock_Ice"
    },
    {
      "x": -23,
      "y": 34,
      "z": -6,
      "name": "Rock_Ice"
    },
    {
      "x": -23,
      "y": 35,
      "z": -6,
      "name": "Rock_Ice"
    },
    {
      "x": -23,
      "y": 36,
      "z": -6,
      "name": "Rock_Ice"
    },
    {
      "x": -23,
      "y": 37,
      "z": -6,
      "name": "Rock_Ice"
    },
    {
      "x": -23,
      "y": 38,
      "z": -6,
      "name": "Rock_Ice"
    },
    {
      "x": -23,
      "y": 39,
      "z": -6,
      "name": "Rock_Ice"
    },
    {
      "x": -23,
      "y": 40,
      "z": -6,
      "name": "Rock_Ice"
    },
    {
      "x": -23,
      "y": 41,
      "z": -6,
      "name": "Rock_Ice"
    },
    {
      "x": -23,
      "y": 42,
      "z": -6,
      "name": "Rock_Ice"
    },
    {
      "x": -23,
      "y": 43,
      "z": -6,
      "name": "Rock_Ice"
    },
    {
      "x": -23,
      "y": 44,
      "z": -6,
      "name": "Rock_Ice"
    },
    {
      "x": -23,
      "y": 45,
      "z": -6,
      "name": "Rock_Ice"
    },
    {
      "x": -23,
      "y": 46,
      "z": -6,
      "name": "Rock_Ice"
    },
    {
      "x": -23,
      "y": 47,
      "z": -6,
      "name": "Rock_Ice"
    },
    {
      "x": -23,
      "y": 48,
      "z": -6,
      "name": "Rock_Ice"
    },
    {
      "x": -23,
      "y": 49,
      "z": -6,
      "name": "Rock_Ice"
    },
    {
      "x": -23,
      "y": 50,
      "z": -6,
      "name": "Rock_Ice_Permafrost"
    },
    {
      "x": -23,
      "y": 51,
      "z": -6,
      "name": "Rock_Ice_Permafrost"
    },
    {
      "x": -23,
      "y": 52,
      "z": -6,
      "name": "Rock_Ice_Permafrost"
    },
    {
      "x": -23,
      "y": 53,
      "z": -6,
      "name": "Rock_Ice"
    },
    {
      "x": -23,
      "y": 54,
      "z": -6,
      "name": "Soil_Snow"
    },
    {
      "x": -23,
      "y": 14,
      "z": -5,
      "name": "Rock_Ice_Permafrost"
    },
    {
      "x": -23,
      "y": 15,
      "z": -5,
      "name": "Rock_Ice_Permafrost"
    },
    {
      "x": -23,
      "y": 16,
      "z": -5,
      "name": "Rock_Ice_Permafrost"
    },
    {
      "x": -23,
      "y": 17,
      "z": -5,
      "name": "Rock_Ice"
    },
    {
      "x": -23,
      "y": 18,
      "z": -5,
      "name": "Rock_Ice"
    },
    {
      "x": -23,
      "y": 19,
      "z": -5,
      "name": "Rock_Ice"
    },
    {
      "x": -23,
      "y": 20,
      "z": -5,
      "name": "Rock_Ice"
    },
    {
      "x": -23,
      "y": 21,
      "z": -5,
      "name": "Rock_Ice"
    },
    {
      "x": -23,
      "y": 22,
      "z": -5,
      "name": "Rock_Ice"
    },
    {
      "x": -23,
      "y": 23,
      "z": -5,
      "name": "Rock_Ice"
    },
    {
      "x": -23,
      "y": 24,
      "z": -5,
      "name": "Rock_Ice"
    },
    {
      "x": -23,
      "y": 25,
      "z": -5,
      "name": "Rock_Ice"
    },
    {
      "x": -23,
      "y": 26,
      "z": -5,
      "name": "Rock_Ice"
    },
    {
      "x": -23,
      "y": 27,
      "z": -5,
      "name": "Rock_Ice"
    },
    {
      "x": -23,
      "y": 28,
      "z": -5,
      "name": "Rock_Ice"
    },
    {
      "x": -23,
      "y": 29,
      "z": -5,
      "name": "Rock_Ice"
    },
    {
      "x": -23,
      "y": 30,
      "z": -5,
      "name": "Rock_Ice"
    },
    {
      "x": -23,
      "y": 31,
      "z": -5,
      "name": "Rock_Ice"
    },
    {
      "x": -23,
      "y": 32,
      "z": -5,
      "name": "Rock_Ice"
    },
    {
      "x": -23,
      "y": 33,
      "z": -5,
      "name": "Rock_Ice"
    },
    {
      "x": -23,
      "y": 34,
      "z": -5,
      "name": "Rock_Ice"
    },
    {
      "x": -23,
      "y": 35,
      "z": -5,
      "name": "Rock_Ice"
    },
    {
      "x": -23,
      "y": 36,
      "z": -5,
      "name": "Rock_Ice"
    },
    {
      "x": -23,
      "y": 37,
      "z": -5,
      "name": "Rock_Ice"
    },
    {
      "x": -23,
      "y": 38,
      "z": -5,
      "name": "Rock_Ice"
    },
    {
      "x": -23,
      "y": 39,
      "z": -5,
      "name": "Rock_Ice"
    },
    {
      "x": -23,
      "y": 40,
      "z": -5,
      "name": "Rock_Ice"
    },
    {
      "x": -23,
      "y": 41,
      "z": -5,
      "name": "Rock_Ice"
    },
    {
      "x": -23,
      "y": 42,
      "z": -5,
      "name": "Rock_Ice"
    },
    {
      "x": -23,
      "y": 43,
      "z": -5,
      "name": "Rock_Ice"
    },
    {
      "x": -23,
      "y": 44,
      "z": -5,
      "name": "Rock_Ice"
    },
    {
      "x": -23,
      "y": 45,
      "z": -5,
      "name": "Rock_Ice"
    },
    {
      "x": -23,
      "y": 46,
      "z": -5,
      "name": "Rock_Ice"
    },
    {
      "x": -23,
      "y": 47,
      "z": -5,
      "name": "Rock_Ice"
    },
    {
      "x": -23,
      "y": 48,
      "z": -5,
      "name": "Rock_Ice"
    },
    {
      "x": -23,
      "y": 49,
      "z": -5,
      "name": "Rock_Ice"
    },
    {
      "x": -23,
      "y": 50,
      "z": -5,
      "name": "Rock_Ice_Permafrost"
    },
    {
      "x": -23,
      "y": 51,
      "z": -5,
      "name": "Rock_Ice_Permafrost"
    },
    {
      "x": -23,
      "y": 52,
      "z": -5,
      "name": "Rock_Ice_Permafrost"
    },
    {
      "x": -23,
      "y": 53,
      "z": -5,
      "name": "Rock_Ice_Permafrost"
    },
    {
      "x": -23,
      "y": 54,
      "z": -5,
      "name": "Rock_Ice"
    },
    {
      "x": -23,
      "y": 55,
      "z": -5,
      "name": "Soil_Snow"
    },
    {
      "x": -23,
      "y": 14,
      "z": -4,
      "name": "Rock_Ice_Permafrost"
    },
    {
      "x": -23,
      "y": 15,
      "z": -4,
      "name": "Rock_Ice_Permafrost"
    },
    {
      "x": -23,
      "y": 16,
      "z": -4,
      "name": "Rock_Ice_Permafrost"
    },
    {
      "x": -23,
      "y": 17,
      "z": -4,
      "name": "Rock_Ice"
    },
    {
      "x": -23,
      "y": 18,
      "z": -4,
      "name": "Rock_Ice"
    },
    {
      "x": -23,
      "y": 19,
      "z": -4,
      "name": "Rock_Ice"
    },
    {
      "x": -23,
      "y": 20,
      "z": -4,
      "name": "Rock_Ice"
    },
    {
      "x": -23,
      "y": 21,
      "z": -4,
      "name": "Rock_Ice"
    },
    {
      "x": -23,
      "y": 22,
      "z": -4,
      "name": "Rock_Ice"
    },
    {
      "x": -23,
      "y": 23,
      "z": -4,
      "name": "Rock_Ice"
    },
    {
      "x": -23,
      "y": 24,
      "z": -4,
      "name": "Rock_Ice"
    },
    {
      "x": -23,
      "y": 25,
      "z": -4,
      "name": "Rock_Ice"
    },
    {
      "x": -23,
      "y": 26,
      "z": -4,
      "name": "Rock_Ice"
    },
    {
      "x": -23,
      "y": 27,
      "z": -4,
      "name": "Rock_Ice"
    },
    {
      "x": -23,
      "y": 28,
      "z": -4,
      "name": "Rock_Ice"
    },
    {
      "x": -23,
      "y": 29,
      "z": -4,
      "name": "Rock_Ice"
    },
    {
      "x": -23,
      "y": 30,
      "z": -4,
      "name": "Rock_Ice"
    },
    {
      "x": -23,
      "y": 31,
      "z": -4,
      "name": "Rock_Ice"
    },
    {
      "x": -23,
      "y": 32,
      "z": -4,
      "name": "Rock_Ice"
    },
    {
      "x": -23,
      "y": 33,
      "z": -4,
      "name": "Rock_Ice"
    },
    {
      "x": -23,
      "y": 34,
      "z": -4,
      "name": "Rock_Ice"
    },
    {
      "x": -23,
      "y": 35,
      "z": -4,
      "name": "Rock_Ice"
    },
    {
      "x": -23,
      "y": 36,
      "z": -4,
      "name": "Rock_Ice"
    },
    {
      "x": -23,
      "y": 37,
      "z": -4,
      "name": "Rock_Ice"
    },
    {
      "x": -23,
      "y": 38,
      "z": -4,
      "name": "Rock_Ice"
    },
    {
      "x": -23,
      "y": 39,
      "z": -4,
      "name": "Rock_Ice"
    },
    {
      "x": -23,
      "y": 40,
      "z": -4,
      "name": "Rock_Ice"
    },
    {
      "x": -23,
      "y": 41,
      "z": -4,
      "name": "Rock_Ice"
    },
    {
      "x": -23,
      "y": 42,
      "z": -4,
      "name": "Rock_Ice"
    },
    {
      "x": -23,
      "y": 43,
      "z": -4,
      "name": "Rock_Ice"
    },
    {
      "x": -23,
      "y": 44,
      "z": -4,
      "name": "Rock_Ice"
    },
    {
      "x": -23,
      "y": 45,
      "z": -4,
      "name": "Rock_Ice"
    },
    {
      "x": -23,
      "y": 46,
      "z": -4,
