{
  "version": 8,
  "blockIdVersion": 11,
  "anchorX": 1,
  "anchorY": 14,
  "anchorZ": 3,
  "blocks": [
    {
      "x": -24,
      "y": 12,
      "z": -8,
      "name": "Soil_Snow"
    },
    {
      "x": -24,
      "y": 11,
      "z": -7,
      "name": "Rock_Ice"
    },
    {
      "x": -24,
      "y": 12,
      "z": -7,
      "name": "Soil_Snow"
    },
    {
      "x": -24,
      "y": 11,
      "z": -6,
      "name": "Rock_Ice"
    },
    {
      "x": -24,
      "y": 12,
      "z": -6,
      "name": "Rock_Ice"
    },
    {
      "x": -24,
      "y": 7,
      "z": -1,
      "name": "Rock_Ice"
    },
    {
      "x": -24,
      "y": 9,
      "z": -1,
      "name": "Rock_Ice"
    },
    {
      "x": -24,
      "y": 10,
      "z": -1,
      "name": "Rock_Ice"
    },
    {
      "x": -24,
      "y": 11,
      "z": -1,
      "name": "Rock_Ice"
    },
    {
      "x": -24,
      "y": 12,
      "z": -1,
      "name": "Rock_Ice"
    },
    {
      "x": -24,
      "y": 13,
      "z": -1,
      "name": "Rock_Ice"
    },
    {
      "x": -24,
      "y": 14,
      "z": -1,
      "name": "Rock_Ice"
    },
    {
      "x": -24,
      "y": 7,
      "z": 0,
      "name": "Rock_Ice"
    },
    {
      "x": -24,
      "y": 8,
      "z": 0,
      "name": "Rock_Ice"
    },
    {
      "x": -24,
      "y": 9,
      "z": 0,
      "name": "Rock_Ice"
    },
    {
      "x": -24,
      "y": 10,
      "z": 0,
      "name": "Rock_Ice"
    },
    {
      "x": -24,
      "y": 11,
      "z": 0,
      "name": "Rock_Ice"
    },
    {
      "x": -24,
      "y": 12,
      "z": 0,
      "name": "Rock_Ice"
    },
    {
      "x": -24,
      "y": 13,
      "z": 0,
      "name": "Rock_Ice"
    },
    {
      "x": -24,
      "y": 14,
      "z": 0,
      "name": "Soil_Snow"
    },
    {
      "x": -24,
      "y": 6,
      "z": 1,
      "name": "Rock_Ice"
    },
    {
      "x": -24,
      "y": 7,
      "z": 1,
      "name": "Rock_Ice"
    },
    {
      "x": -24,
      "y": 8,
      "z": 1,
      "name": "Rock_Ice"
    },
    {
      "x": -24,
      "y": 9,
      "z": 1,
      "name": "Rock_Ice"
    },
    {
      "x": -24,
      "y": 10,
      "z": 1,
      "name": "Rock_Ice"
    },
    {
      "x": -24,
      "y": 11,
      "z": 1,
      "name": "Rock_Ice"
    },
    {
      "x": -24,
      "y": 12,
      "z": 1,
      "name": "Rock_Ice"
    },
    {
      "x": -24,
      "y": 13,
      "z": 1,
      "name": "Rock_Ice"
    },
    {
      "x": -24,
      "y": 14,
      "z": 1,
      "name": "Soil_Snow"
    },
    {
      "x": -24,
      "y": 5,
      "z": 2,
      "name": "Rock_Ice"
    },
    {
      "x": -24,
      "y": 6,
      "z": 2,
      "name": "Rock_Ice"
    },
    {
      "x": -24,
      "y": 7,
      "z": 2,
      "name": "Rock_Ice"
    },
    {
      "x": -24,
      "y": 8,
      "z": 2,
      "name": "Rock_Ice"
    },
    {
      "x": -24,
      "y": 9,
      "z": 2,
      "name": "Rock_Ice"
    },
    {
      "x": -24,
      "y": 10,
      "z": 2,
      "name": "Rock_Ice"
    },
    {
      "x": -24,
      "y": 11,
      "z": 2,
      "name": "Rock_Ice"
    },
    {
      "x": -24,
      "y": 12,
      "z": 2,
      "name": "Rock_Ice"
    },
    {
      "x": -24,
      "y": 13,
      "z": 2,
      "name": "Rock_Ice"
    },
    {
      "x": -24,
      "y": 14,
      "z": 2,
      "name": "Rock_Ice"
    },
    {
      "x": -24,
      "y": 15,
      "z": 2,
      "name": "Soil_Snow"
    },
    {
      "x": -24,
      "y": 5,
      "z": 3,
      "name": "Rock_Ice"
    },
    {
      "x": -24,
      "y": 6,
      "z": 3,
      "name": "Rock_Ice"
    },
    {
      "x": -24,
      "y": 7,
      "z": 3,
      "name": "Rock_Ice"
    },
    {
      "x": -24,
      "y": 8,
      "z": 3,
      "name": "Rock_Ice"
    },
    {
      "x": -24,
      "y": 9,
      "z": 3,
      "name": "Rock_Ice"
    },
    {
      "x": -24,
      "y": 10,
      "z": 3,
      "name": "Rock_Ice"
    },
    {
      "x": -24,
      "y": 11,
      "z": 3,
      "name": "Rock_Ice"
    },
    {
      "x": -24,
      "y": 12,
      "z": 3,
      "name": "Rock_Ice"
    },
    {
      "x": -24,
      "y": 13,
      "z": 3,
      "name": "Rock_Ice"
    },
    {
      "x": -24,
      "y": 14,
      "z": 3,
      "name": "Soil_Snow"
    },
    {
      "x": -24,
      "y": 4,
      "z": 4,
      "name": "Rock_Ice"
    },
    {
      "x": -24,
      "y": 5,
      "z": 4,
      "name": "Rock_Ice"
    },
    {
      "x": -24,
      "y": 6,
      "z": 4,
      "name": "Rock_Ice"
    },
    {
      "x": -24,
      "y": 7,
      "z": 4,
      "name": "Rock_Ice"
    },
    {
      "x": -24,
      "y": 8,
      "z": 4,
      "name": "Rock_Ice"
    },
    {
      "x": -24,
      "y": 9,
      "z": 4,
      "name": "Rock_Ice"
    },
    {
      "x": -24,
      "y": 10,
      "z": 4,
      "name": "Rock_Ice"
    },
    {
      "x": -24,
      "y": 11,
      "z": 4,
      "name": "Rock_Ice"
    },
    {
      "x": -24,
      "y": 12,
      "z": 4,
      "name": "Rock_Ice"
    },
    {
      "x": -24,
      "y": 13,
      "z": 4,
      "name": "Soil_Snow"
    },
    {
      "x": -24,
      "y": 4,
      "z": 5,
      "name": "Rock_Ice"
    },
    {
      "x": -24,
      "y": 5,
      "z": 5,
      "name": "Rock_Ice"
    },
    {
      "x": -24,
      "y": 6,
      "z": 5,
      "name": "Rock_Ice"
    },
    {
      "x": -24,
      "y": 7,
      "z": 5,
      "name": "Rock_Ice"
    },
    {
      "x": -24,
      "y": 8,
      "z": 5,
      "name": "Rock_Ice"
    },
    {
      "x": -24,
      "y": 9,
      "z": 5,
      "name": "Rock_Ice"
    },
    {
      "x": -24,
      "y": 10,
      "z": 5,
      "name": "Rock_Ice"
    },
    {
      "x": -24,
      "y": 11,
      "z": 5,
      "name": "Rock_Ice"
    },
    {
      "x": -24,
      "y": 12,
      "z": 5,
      "name": "Soil_Snow"
    },
    {
      "x": -24,
      "y": 4,
      "z": 6,
      "name": "Rock_Ice"
    },
    {
      "x": -24,
      "y": 5,
      "z": 6,
      "name": "Rock_Ice"
    },
    {
      "x": -24,
      "y": 6,
      "z": 6,
      "name": "Rock_Ice"
    },
    {
      "x": -24,
      "y": 7,
      "z": 6,
      "name": "Rock_Ice"
    },
    {
      "x": -24,
      "y": 8,
      "z": 6,
      "name": "Rock_Ice"
    },
    {
      "x": -24,
      "y": 9,
      "z": 6,
      "name": "Rock_Ice"
    },
    {
      "x": -24,
      "y": 10,
      "z": 6,
      "name": "Rock_Ice"
    },
    {
      "x": -24,
      "y": 11,
      "z": 6,
      "name": "Soil_Snow"
    },
    {
      "x": -24,
      "y": 5,
      "z": 7,
      "name": "Rock_Ice"
    },
    {
      "x": -24,
      "y": 6,
      "z": 7,
      "name": "Rock_Ice"
    },
    {
      "x": -24,
      "y": 7,
      "z": 7,
      "name": "Rock_Ice"
    },
    {
      "x": -24,
      "y": 8,
      "z": 7,
      "name": "Rock_Ice"
    },
    {
      "x": -24,
      "y": 9,
      "z": 7,
      "name": "Rock_Ice"
    },
    {
      "x": -24,
      "y": 10,
      "z": 7,
      "name": "Rock_Ice"
    },
    {
      "x": -24,
      "y": 11,
      "z": 7,
      "name": "Soil_Snow"
    },
    {
      "x": -24,
      "y": 7,
      "z": 8,
      "name": "Rock_Ice"
    },
    {
      "x": -24,
      "y": 8,
      "z": 8,
      "name": "Rock_Ice"
    },
    {
      "x": -24,
      "y": 9,
      "z": 8,
      "name": "Rock_Ice"
    },
    {
      "x": -24,
      "y": 10,
      "z": 8,
      "name": "Soil_Snow"
    },
    {
      "x": -23,
      "y": 3,
      "z": -12,
      "name": "Rock_Ice_Permafrost"
    },
    {
      "x": -23,
      "y": 4,
      "z": -12,
      "name": "Rock_Ice"
    },
    {
      "x": -23,
      "y": 5,
      "z": -12,
      "name": "Rock_Ice"
    },
    {
      "x": -23,
      "y": 6,
      "z": -12,
      "name": "Rock_Ice_Permafrost"
    },
    {
      "x": -23,
      "y": 7,
      "z": -12,
      "name": "Rock_Ice_Permafrost"
    },
    {
      "x": -23,
      "y": 8,
      "z": -12,
      "name": "Rock_Ice"
    },
    {
      "x": -23,
      "y": 9,
      "z": -12,
      "name": "Soil_Snow"
    },
    {
      "x": -23,
      "y": 1,
      "z": -11,
      "name": "Rock_Ice"
    },
    {
      "x": -23,
      "y": 2,
      "z": -11,
      "name": "Rock_Ice"
    },
    {
      "x": -23,
      "y": 3,
      "z": -11,
      "name": "Rock_Ice"
    },
    {
      "x": -23,
      "y": 4,
      "z": -11,
      "name": "Rock_Ice_Permafrost"
    },
    {
      "x": -23,
      "y": 5,
      "z": -11,
      "name": "Rock_Ice_Permafrost"
    },
    {
      "x": -23,
      "y": 6,
      "z": -11,
      "name": "Rock_Ice_Permafrost"
    },
    {
      "x": -23,
      "y": 7,
      "z": -11,
      "name": "Rock_Ice_Permafrost"
    },
    {
      "x": -23,
      "y": 8,
      "z": -11,
      "name": "Rock_Ice_Permafrost"
    },
    {
      "x": -23,
      "y": 9,
      "z": -11,
      "name": "Rock_Ice_Permafrost"
    },
    {
      "x": -23,
      "y": 10,
      "z": -11,
      "name": "Soil_Snow"
    },
    {
      "x": -23,
      "y": 0,
      "z": -10,
      "name": "Rock_Ice"
    },
    {
      "x": -23,
      "y": 1,
      "z": -10,
      "name": "Rock_Ice"
    },
    {
      "x": -23,
      "y": 2,
      "z": -10,
      "name": "Rock_Ice"
    },
    {
      "x": -23,
      "y": 3,
      "z": -10,
      "name": "Rock_Ice"
    },
    {
      "x": -23,
      "y": 4,
      "z": -10,
      "name": "Rock_Ice_Permafrost"
    },
    {
      "x": -23,
      "y": 5,
      "z": -10,
      "name": "Rock_Ice_Permafrost"
    },
    {
      "x": -23,
      "y": 6,
      "z": -10,
      "name": "Rock_Ice_Permafrost"
    },
    {
      "x": -23,
      "y": 7,
      "z": -10,
      "name": "Rock_Ice_Permafrost"
    },
    {
      "x": -23,
      "y": 8,
      "z": -10,
      "name": "Rock_Ice_Permafrost"
    },
    {
      "x": -23,
      "y": 9,
      "z": -10,
      "name": "Rock_Ice_Permafrost"
    },
    {
      "x": -23,
      "y": 10,
      "z": -10,
      "name": "Rock_Ice"
    },
    {
      "x": -23,
      "y": 11,
      "z": -10,
      "name": "Soil_Snow"
    },
    {
      "x": -23,
      "y": 0,
      "z": -9,
      "name": "Rock_Ice"
    },
    {
      "x": -23,
      "y": 1,
      "z": -9,
      "name": "Rock_Ice"
    },
    {
      "x": -23,
      "y": 2,
      "z": -9,
      "name": "Rock_Ice"
    },
    {
      "x": -23,
      "y": 3,
      "z": -9,
      "name": "Rock_Ice_Permafrost"
    },
    {
      "x": -23,
      "y": 4,
      "z": -9,
      "name": "Rock_Ice_Permafrost"
    },
    {
      "x": -23,
      "y": 5,
      "z": -9,
      "name": "Rock_Ice_Permafrost"
    },
    {
      "x": -23,
      "y": 6,
      "z": -9,
      "name": "Rock_Ice_Permafrost"
    },
    {
      "x": -23,
      "y": 7,
      "z": -9,
      "name": "Rock_Ice_Permafrost"
    },
    {
      "x": -23,
      "y": 8,
      "z": -9,
      "name": "Rock_Ice_Permafrost"
    },
    {
      "x": -23,
      "y": 9,
      "z": -9,
      "name": "Rock_Ice"
    },
    {
      "x": -23,
      "y": 10,
      "z": -9,
      "name": "Rock_Ice_Permafrost"
    },
    {
      "x": -23,
      "y": 11,
      "z": -9,
      "name": "Rock_Ice"
    },
    {
      "x": -23,
      "y": 12,
      "z": -9,
      "name": "Soil_Snow"
    },
    {
      "x": -23,
      "y": 0,
      "z": -8,
      "name": "Rock_Ice"
    },
    {
      "x": -23,
      "y": 1,
      "z": -8,
      "name": "Rock_Ice"
    },
    {
      "x": -23,
      "y": 2,
      "z": -8,
      "name": "Rock_Ice_Permafrost"
    },
    {
      "x": -23,
      "y": 3,
      "z": -8,
      "name": "Rock_Ice_Permafrost"
    },
    {
      "x": -23,
      "y": 4,
      "z": -8,
      "name": "Rock_Ice_Permafrost"
    },
    {
      "x": -23,
      "y": 5,
      "z": -8,
      "name": "Rock_Ice_Permafrost"
    },
    {
      "x": -23,
      "y": 6,
      "z": -8,
      "name": "Rock_Ice_Permafrost"
    },
    {
      "x": -23,
      "y": 7,
      "z": -8,
      "name": "Rock_Ice_Permafrost"
    },
    {
      "x": -23,
      "y": 8,
      "z": -8,
      "name": "Rock_Ice_Permafrost"
    },
    {
      "x": -23,
      "y": 9,
      "z": -8,
      "name": "Rock_Ice"
    },
    {
      "x": -23,
      "y": 10,
      "z": -8,
      "name": "Rock_Ice"
    },
    {
      "x": -23,
      "y": 11,
      "z": -8,
      "name": "Rock_Ice"
    },
    {
      "x": -23,
      "y": 12,
      "z": -8,
      "name": "Rock_Ice"
    },
    {
      "x": -23,
      "y": 13,
      "z": -8,
      "name": "Soil_Snow"
    },
    {
      "x": -23,
      "y": 2,
      "z": -7,
      "name": "Rock_Ice_Permafrost"
    },
    {
      "x": -23,
      "y": 3,
      "z": -7,
      "name": "Rock_Ice_Permafrost"
    },
    {
      "x": -23,
      "y": 4,
      "z": -7,
      "name": "Rock_Ice_Permafrost"
    },
    {
      "x": -23,
      "y": 5,
      "z": -7,
      "name": "Rock_Ice_Permafrost"
    },
    {
      "x": -23,
      "y": 6,
      "z": -7,
      "name": "Rock_Ice_Permafrost"
    },
    {
      "x": -23,
      "y": 7,
      "z": -7,
      "name": "Rock_Ice_Permafrost"
    },
    {
      "x": -23,
      "y": 8,
      "z": -7,
      "name": "Rock_Ice_Permafrost"
    },
    {
      "x": -23,
      "y": 9,
      "z": -7,
      "name": "Rock_Ice"
    },
    {
      "x": -23,
      "y": 10,
      "z": -7,
      "name": "Rock_Ice"
    },
    {
      "x": -23,
      "y": 11,
      "z": -7,
      "name": "Rock_Ice"
    },
    {
      "x": -23,
      "y": 12,
      "z": -7,
      "name": "Rock_Ice"
    },
    {
      "x": -23,
      "y": 13,
      "z": -7,
      "name": "Rock_Ice"
    },
    {
      "x": -23,
      "y": 14,
      "z": -7,
      "name": "Soil_Snow"
    },
    {
      "x": -23,
      "y": 2,
      "z": -6,
      "name": "Rock_Ice_Permafrost"
    },
    {
      "x": -23,
      "y": 3,
      "z": -6,
      "name": "Rock_Ice_Permafrost"
    },
    {
      "x": -23,
      "y": 4,
      "z": -6,
      "name": "Rock_Ice_Permafrost"
    },
    {
      "x": -23,
      "y": 5,
      "z": -6,
      "name": "Rock_Ice_Permafrost"
    },
    {
      "x": -23,
      "y": 6,
      "z": -6,
      "name": "Rock_Ice_Permafrost"
    },
    {
      "x": -23,
      "y": 7,
      "z": -6,
      "name": "Rock_Ice_Permafrost"
    },
    {
      "x": -23,
      "y": 8,
      "z": -6,
      "name": "Rock_Ice_Permafrost"
    },
    {
      "x": -23,
      "y": 9,
      "z": -6,
      "name": "Rock_Ice"
    },
    {
      "x": -23,
      "y": 10,
      "z": -6,
      "name": "Rock_Ice"
    },
    {
      "x": -23,
      "y": 11,
      "z": -6,
      "name": "Rock_Ice"
    },
    {
      "x": -23,
      "y": 12,
      "z": -6,
      "name": "Rock_Ice"
    },
    {
      "x": -23,
      "y": 13,
      "z": -6,
      "name": "Rock_Ice"
    },
    {
      "x": -23,
      "y": 14,
      "z": -6,
      "name": "Soil_Snow"
    },
    {
      "x": -23,
      "y": 3,
      "z": -5,
      "name": "Rock_Ice_Permafrost"
    },
    {
      "x": -23,
      "y": 4,
      "z": -5,
      "name": "Rock_Ice_Permafrost"
    },
    {
      "x": -23,
      "y": 5,
      "z": -5,
      "name": "Rock_Ice_Permafrost"
    },
    {
      "x": -23,
      "y": 6,
      "z": -5,
      "name": "Rock_Ice_Permafrost"
    },
    {
      "x": -23,
      "y": 7,
      "z": -5,
      "name": "Rock_Ice"
    },
    {
      "x": -23,
      "y": 8,
      "z": -5,
      "name": "Rock_Ice"
    },
    {
      "x": -23,
      "y": 9,
      "z": -5,
      "name": "Rock_Ice"
    },
    {
      "x": -23,
      "y": 10,
      "z": -5,
      "name": "Rock_Ice"
    },
    {
      "x": -23,
      "y": 11,
      "z": -5,
      "name": "Rock_Ice"
    },
    {
      "x": -23,
      "y": 12,
      "z": -5,
      "name": "Rock_Ice"
    },
    {
      "x": -23,
      "y": 13,
      "z": -5,
      "name": "Soil_Snow"
    },
    {
      "x": -23,
      "y": 3,
      "z": -4,
      "name": "Rock_Ice_Permafrost"
    },
    {
      "x": -23,
      "y": 4,
      "z": -4,
      "name": "Rock_Ice_Permafrost"
    },
    {
      "x": -23,
      "y": 5,
      "z": -4,
      "name": "Rock_Ice_Permafrost"
    },
    {
      "x": -23,
      "y": 6,
      "z": -4,
      "name": "Rock_Ice"
    },
    {
      "x": -23,
      "y": 7,
      "z": -4,
      "name": "Rock_Ice"
    },
    {
      "x": -23,
      "y": 8,
      "z": -4,
      "name": "Rock_Ice"
    },
    {
      "x": -23,
      "y": 9,
      "z": -4,
      "name": "Rock_Ice"
    },
    {
      "x": -23,
      "y": 10,
      "z": -4,
      "name": "Rock_Ice"
    },
    {
      "x": -23,
      "y": 11,
      "z": -4,
      "name": "Rock_Ice"
    },
    {
      "x": -23,
      "y": 12,
      "z": -4,
      "name": "Rock_Ice"
    },
    {
      "x": -23,
      "y": 13,
      "z": -4,
      "name": "Soil_Snow"
    },
    {
      "x": -23,
      "y": 3,
      "z": -3,
      "name": "Rock_Ice_Permafrost"
    },
    {
      "x": -23,
      "y": 4,
      "z": -3,
      "name": "Rock_Ice_Permafrost"
    },
    {
      "x": -23,
      "y": 5,
      "z": -3,
      "name": "Rock_Ice_Permafrost"
    },
    {
      "x": -23,
      "y": 6,
      "z": -3,
      "name": "Rock_Ice_Permafrost"
    },
    {
      "x": -23,
      "y": 7,
      "z": -3,
      "name": "Rock_Ice"
    },
    {
      "x": -23,
      "y": 8,
      "z": -3,
      "name": "Rock_Ice"
    },
    {
      "x": -23,
      "y": 9,
      "z": -3,
      "name": "Rock_Ice"
    },
    {
      "x": -23,
      "y": 10,
      "z": -3,
      "name": "Rock_Ice"
    },
    {
      "x": -23,
      "y": 11,
      "z": -3,
      "name": "Rock_Ice"
    },
    {
      "x": -23,
      "y": 12,
      "z": -3,
      "name": "Rock_Ice"
    },
    {
      "x": -23,
      "y": 13,
      "z": -3,
      "name": "Rock_Ice"
    },
    {
      "x": -23,
      "y": 14,
      "z": -3,
      "name": "Rock_Ice"
    },
    {
      "x": -23,
      "y": 15,
      "z": -3,
      "name": "Rock_Ice"
    },
    {
      "x": -23,
      "y": 16,
      "z": -3,
      "name": "Rock_Ice"
    },
    {
      "x": -23,
      "y": 17,
      "z": -3,
      "name": "Rock_Ice"
    },
    {
      "x": -23,
      "y": 18,
      "z": -3,
      "name": "Rock_Ice"
    },
    {
      "x": -23,
      "y": 19,
      "z": -3,
      "name": "Soil_Snow"
    },
    {
      "x": -23,
      "y": 4,
      "z": -2,
      "name": "Rock_Ice_Permafrost"
    },
    {
      "x": -23,
      "y": 5,
      "z": -2,
      "name": "Rock_Ice_Permafrost"
    },
    {
      "x": -23,
      "y": 6,
      "z": -2,
      "name": "Rock_Ice"
    },
    {
      "x": -23,
      "y": 7,
      "z": -2,
      "name": "Rock_Ice"
    },
    {
      "x": -23,
      "y": 8,
      "z": -2,
      "name": "Rock_Ice"
    },
    {
      "x": -23,
      "y": 9,
      "z": -2,
      "name": "Rock_Ice"
    },
    {
      "x": -23,
      "y": 10,
      "z": -2,
      "name": "Rock_Ice"
    },
    {
      "x": -23,
      "y": 11,
      "z": -2,
      "name": "Rock_Ice"
    },
    {
      "x": -23,
      "y": 12,
      "z": -2,
      "name": "Rock_Ice"
    },
    {
      "x": -23,
      "y": 13,
      "z": -2,
      "name": "Rock_Ice"
    },
    {
      "x": -23,
      "y": 14,
      "z": -2,
      "name": "Rock_Ice"
    },
    {
      "x": -23,
      "y": 15,
      "z": -2,
      "name": "Rock_Ice"
    },
    {
      "x": -23,
      "y": 16,
      "z": -2,
      "name": "Rock_Ice"
    },
    {
      "x": -23,
      "y": 17,
      "z": -2,
      "name": "Rock_Ice"
    },
    {
      "x": -23,
      "y": 18,
      "z": -2,
      "name": "Rock_Ice"
    },
    {
      "x": -23,
      "y": 19,
      "z": -2,
      "name": "Rock_Ice"
    },
    {
      "x": -23,
      "y": 20,
      "z": -2,
      "name": "Rock_Ice"
    },
    {
      "x": -23,
      "y": 21,
      "z": -2,
      "name": "Soil_Snow"
    },
    {
      "x": -23,
      "y": 4,
      "z": -1,
      "name": "Rock_Ice_Permafrost"
    },
    {
      "x": -23,
      "y": 5,
      "z": -1,
      "name": "Rock_Ice"
    },
    {
      "x": -23,
      "y": 6,
      "z": -1,
      "name": "Rock_Ice"
    },
    {
      "x": -23,
      "y": 7,
      "z": -1,
      "name": "Rock_Ice"
    },
    {
      "x": -23,
      "y": 8,
      "z": -1,
      "name": "Rock_Ice"
    },
    {
      "x": -23,
      "y": 9,
      "z": -1,
      "name": "Rock_Ice"
    },
    {
      "x": -23,
      "y": 10,
      "z": -1,
      "name": "Rock_Ice"
    },
    {
      "x": -23,
      "y": 11,
      "z": -1,
      "name": "Rock_Ice"
    },
    {
      "x": -23,
      "y": 12,
      "z": -1,
      "name": "Rock_Ice"
    },
    {
      "x": -23,
      "y": 13,
      "z": -1,
      "name": "Rock_Ice"
    },
    {
      "x": -23,
      "y": 14,
      "z": -1,
      "name": "Rock_Ice"
    },
    {
      "x": -23,
      "y": 15,
      "z": -1,
      "name": "Rock_Ice"
    },
    {
      "x": -23,
      "y": 16,
      "z": -1,
      "name": "Rock_Ice"
    },
    {
      "x": -23,
      "y": 17,
      "z": -1,
      "name": "Rock_Ice"
    },
    {
      "x": -23,
      "y": 18,
      "z": -1,
      "name": "Rock_Ice"
    },
    {
      "x": -23,
      "y": 19,
      "z": -1,
      "name": "Soil_Snow"
    },
    {
      "x": -23,
      "y": 4,
      "z": 0,
      "name": "Rock_Ice_Permafrost"
    },
    {
      "x": -23,
      "y": 5,
      "z": 0,
      "name": "Rock_Ice_Permafrost"
    },
    {
      "x": -23,
      "y": 6,
      "z": 0,
      "name": "Rock_Ice"
    },
    {
      "x": -23,
      "y": 7,
      "z": 0,
      "name": "Rock_Ice"
    },
    {
      "x": -23,
      "y": 8,
      "z": 0,
      "name": "Rock_Ice"
    },
    {
      "x": -23,
      "y": 9,
      "z": 0,
      "name": "Rock_Ice"
    },
    {
      "x": -23,
      "y": 10,
      "z": 0,
      "name": "Rock_Ice"
    },
    {
      "x": -23,
      "y": 11,
      "z": 0,
      "name": "Rock_Ice"
    },
    {
      "x": -23,
      "y": 12,
      "z": 0,
      "name": "Rock_Ice"
    },
    {
      "x": -23,
      "y": 13,
      "z": 0,
      "name": "Rock_Ice"
    },
    {
      "x": -23,
      "y": 14,
      "z": 0,
      "name": "Rock_Ice"
    },
    {
      "x": -23,
      "y": 15,
      "z": 0,
      "name": "Rock_Ice"
    },
    {
      "x": -23,
      "y": 16,
      "z": 0,
      "name": "Rock_Ice"
    },
    {
      "x": -23,
      "y": 17,
      "z": 0,
      "name": "Rock_Ice"
    },
    {
      "x": -23,
      "y": 18,
      "z": 0,
      "name": "Soil_Snow"
    },
    {
      "x": -23,
      "y": 3,
      "z": 1,
      "name": "Rock_Ice"
    },
    {
      "x": -23,
      "y": 4,
      "z": 1,
      "name": "Rock_Ice_Permafrost"
    },
    {
      "x": -23,
      "y": 5,
      "z": 1,
      "name": "Rock_Ice"
    },
    {
      "x": -23,
      "y": 6,
      "z": 1,
      "name": "Rock_Ice"
    },
    {
      "x": -23,
      "y": 7,
      "z": 1,
      "name": "Rock_Ice"
    },
    {
      "x": -23,
      "y": 8,
      "z": 1,
      "name": "Rock_Ice"
    },
    {
      "x": -23,
      "y": 9,
      "z": 1,
      "name": "Rock_Ice"
    },
    {
      "x": -23,
      "y": 10,
      "z": 1,
      "name": "Rock_Ice"
    },
    {
      "x": -23,
      "y": 11,
      "z": 1,
      "name": "Rock_Ice"
    },
    {
      "x": -23,
      "y": 12,
      "z": 1,
      "name": "Rock_Ice"
    },
    {
      "x": -23,
      "y": 13,
      "z": 1,
      "name": "Rock_Ice"
    },
    {
      "x": -23,
      "y": 14,
      "z": 1,
      "name": "Rock_Ice"
    },
    {
      "x": -23,
      "y": 15,
      "z": 1,
      "name": "Rock_Ice"
    },
    {
      "x": -23,
      "y": 16,
      "z": 1,
      "name": "Rock_Ice"
    },
    {
      "x": -23,
      "y": 17,
      "z": 1,
      "name": "Soil_Snow"
    },
    {
      "x": -23,
      "y": 3,
      "z": 2,
      "name": "Rock_Ice"
    },
    {
      "x": -23,
      "y": 4,
      "z": 2,
      "name": "Rock_Ice"
    },
    {
      "x": -23,
      "y": 5,
      "z": 2,
      "name": "Rock_Ice"
    },
    {
      "x": -23,
      "y": 6,
      "z": 2,
      "name": "Rock_Ice"
    },
    {
      "x": -23,
      "y": 7,
      "z": 2,
      "name": "Rock_Ice"
    },
    {
      "x": -23,
      "y": 8,
      "z": 2,
      "name": "Rock_Ice"
    },
    {
      "x": -23,
      "y": 9,
      "z": 2,
      "name": "Rock_Ice"
    },
    {
      "x": -23,
      "y": 10,
      "z": 2,
      "name": "Rock_Ice"
    },
    {
      "x": -23,
      "y": 11,
      "z": 2,
      "name": "Rock_Ice"
    },
    {
      "x": -23,
      "y": 12,
      "z": 2,
      "name": "Rock_Ice"
    },
    {
      "x": -23,
      "y": 13,
      "z": 2,
      "name": "Rock_Ice"
    },
    {
      "x": -23,
      "y": 14,
      "z": 2,
      "name": "Rock_Ice"
    },
    {
      "x": -23,
      "y": 15,
      "z": 2,
      "name": "Soil_Snow"
    },
    {
      "x": -23,
      "y": 3,
      "z": 3,
      "name": "Rock_Ice_Permafrost"
    },
    {
      "x": -23,
      "y": 4,
      "z": 3,
      "name": "Rock_Ice"
    },
    {
      "x": -23,
      "y": 5,
      "z": 3,
      "name": "Rock_Ice"
    },
    {
      "x": -23,
      "y": 6,
      "z": 3,
      "name": "Rock_Ice"
    },
    {
      "x": -23,
      "y": 7,
      "z": 3,
      "name": "Rock_Ice"
    },
    {
      "x": -23,
      "y": 8,
      "z": 3,
      "name": "Rock_Ice"
    },
    {
      "x": -23,
      "y": 9,
      "z": 3,
      "name": "Rock_Ice"
    },
    {
      "x": -23,
      "y": 10,
      "z": 3,
      "name": "Rock_Ice"
    },
    {
      "x": -23,
      "y": 11,
      "z": 3,
      "name": "Rock_Ice"
    },
    {
      "x": -23,
      "y": 12,
      "z": 3,
      "name": "Rock_Ice"
    },
    {
      "x": -23,
      "y": 13,
      "z": 3,
      "name": "Rock_Ice"
    },
    {
      "x": -23,
      "y": 14,
      "z": 3,
      "name": "Soil_Snow"
    },
    {
      "x": -23,
      "y": 3,
      "z": 4,
      "name": "Rock_Ice_Permafrost"
    },
    {
      "x": -23,
      "y": 4,
      "z": 4,
      "name": "Rock_Ice"
    },
    {
      "x": -23,
      "y": 5,
      "z": 4,
      "name": "Rock_Ice"
    },
    {
      "x": -23,
      "y": 6,
      "z": 4,
      "name": "Rock_Ice"
    },
    {
      "x": -23,
      "y": 7,
      "z": 4,
      "name": "Rock_Ice"
    },
    {
      "x": -23,
      "y": 8,
      "z": 4,
      "name": "Rock_Ice"
    },
    {
      "x": -23,
      "y": 9,
      "z": 4,
      "name": "Rock_Ice"
    },
    {
      "x": -23,
      "y": 10,
      "z": 4,
      "name": "Rock_Ice"
    },
    {
      "x": -23,
      "y": 11,
      "z": 4,
      "name": "Rock_Ice"
    },
    {
      "x": -23,
      "y": 12,
      "z": 4,
      "name": "Rock_Ice"
    },
    {
      "x": -23,
      "y": 13,
      "z": 4,
      "name": "Soil_Snow"
    },
    {
      "x": -23,
      "y": 3,
      "z": 5,
      "name": "Rock_Ice"
    },
    {
      "x": -23,
      "y": 4,
      "z": 5,
      "name": "Rock_Ice"
    },
    {
      "x": -23,
      "y": 5,
      "z": 5,
      "name": "Rock_Ice"
    },
    {
      "x": -23,
      "y": 6,
      "z": 5,
      "name": "Rock_Ice"
    },
    {
      "x": -23,
      "y": 7,
      "z": 5,
      "name": "Rock_Ice"
    },
    {
      "x": -23,
      "y": 8,
      "z": 5,
      "name": "Rock_Ice"
    },
    {
      "x": -23,
      "y": 9,
      "z": 5,
      "name": "Rock_Ice"
    },
    {
      "x": -23,
      "y": 10,
      "z": 5,
      "name": "Rock_Ice"
    },
    {
      "x": -23,
      "y": 11,
      "z": 5,
      "name": "Rock_Ice"
    },
    {
      "x": -23,
      "y": 12,
      "z": 5,
      "name": "Soil_Snow"
    },
    {
      "x": -23,
      "y": 4,
      "z": 6,
      "name": "Rock_Ice"
    },
    {
      "x": -23,
      "y": 5,
      "z": 6,
      "name": "Rock_Ice"
    },
    {
      "x": -23,
      "y": 6,
      "z": 6,
      "name": "Rock_Ice"
    },
    {
      "x": -23,
      "y": 7,
      "z": 6,
      "name": "Rock_Ice"
    },
    {
      "x": -23,
      "y": 8,
      "z": 6,
      "name": "Rock_Ice"
    },
    {
      "x": -23,
      "y": 9,
      "z": 6,
      "name": "Rock_Ice"
    },
    {
      "x": -23,
      "y": 10,
      "z": 6,
      "name": "Rock_Ice"
    },
    {
      "x": -23,
      "y": 11,
      "z": 6,
      "name": "Soil_Snow"
    },
    {
      "x": -23,
      "y": 5,
      "z": 7,
      "name": "Rock_Ice"
    },
    {
      "x": -23,
      "y": 6,
      "z": 7,
      "name": "Rock_Ice"
    },
    {
      "x": -23,
      "y": 7,
      "z": 7,
      "name": "Rock_Ice"
    },
    {
      "x": -23,
      "y": 8,
      "z": 7,
      "name": "Rock_Ice"
    },
    {
      "x": -23,
      "y": 9,
      "z": 7,
      "name": "Rock_Ice"
    },
    {
      "x": -23,
      "y": 10,
      "z": 7,
      "name": "Soil_Snow"
    },
    {
      "x": -23,
      "y": 7,
      "z": 8,
      "name": "Rock_Ice"
    },
    {
      "x": -23,
      "y": 8,
      "z": 8,
      "name": "Rock_Ice"
    },
    {
      "x": -23,
      "y": 9,
      "z": 8,
      "name": "Soil_Snow"
    },
    {
      "x": -22,
      "y": 8,
      "z": -14,
      "name": "Rock_Ice"
    },
    {
      "x": -22,
      "y": 9,
      "z": -14,
      "name": "Soil_Snow"
    },
    {
      "x": -22,
      "y": 5,
      "z": -13,
      "name": "Rock_Ice_Permafrost"
    },
    {
      "x": -22,
      "y": 6,
      "z": -13,
      "name": "Rock_Ice_Permafrost"
    },
    {
      "x": -22,
      "y": 7,
      "z": -13,
      "name": "Rock_Ice_Permafrost"
    },
    {
      "x": -22,
      "y": 8,
      "z": -13,
      "name": "Rock_Ice_Permafrost"
    },
    {
      "x": -22,
      "y": 9,
      "z": -13,
      "name": "Rock_Ice"
    },
    {
      "x": -22,
      "y": 10,
      "z": -13,
      "name": "Soil_Snow"
    },
    {
      "x": -22,
      "y": 2,
      "z": -12,
      "name": "Rock_Ice"
    },
    {
      "x": -22,
      "y": 3,
      "z": -12,
      "name": "Rock_Ice_Permafrost"
    },
    {
      "x": -22,
      "y": 4,
      "z": -12,
      "name": "Rock_Ice_Permafrost"
    },
    {
      "x": -22,
      "y": 5,
      "z": -12,
      "name": "Rock_Ice_Permafrost"
    },
    {
      "x": -22,
      "y": 6,
      "z": -12,
      "name": "Rock_Ice_Permafrost"
    },
    {
      "x": -22,
      "y": 7,
      "z": -12,
      "name": "Rock_Ice_Permafrost"
    },
    {
      "x": -22,
      "y": 8,
      "z": -12,
      "name": "Rock_Ice_Permafrost"
    },
    {
      "x": -22,
      "y": 9,
      "z": -12,
      "name": "Rock_Ice_Permafrost"
    },
    {
      "x": -22,
      "y": 10,
      "z": -12,
      "name": "Rock_Ice"
    },
    {
      "x": -22,
      "y": 11,
      "z": -12,
      "name": "Soil_Snow"
    },
    {
      "x": -22,
      "y": 1,
      "z": -11,
      "name": "Rock_Ice"
    },
    {
      "x": -22,
      "y": 2,
      "z": -11,
      "name": "Rock_Ice"
    },
    {
      "x": -22,
      "y": 3,
      "z": -11,
      "name": "Rock_Ice_Permafrost"
    },
    {
      "x": -22,
      "y": 4,
      "z": -11,
      "name": "Rock_Ice_Permafrost"
    },
    {
      "x": -22,
      "y": 5,
      "z": -11,
      "name": "Rock_Ice_Permafrost"
    },
    {
      "x": -22,
      "y": 6,
      "z": -11,
      "name": "Rock_Ice_Permafrost"
    },
    {
      "x": -22,
      "y": 7,
      "z": -11,
      "name": "Rock_Ice_Permafrost"
    },
    {
      "x": -22,
      "y": 8,
      "z": -11,
      "name": "Rock_Ice_Permafrost"
    },
    {
      "x": -22,
      "y": 9,
      "z": -11,
      "name": "Rock_Ice_Permafrost"
    },
    {
      "x": -22,
      "y": 10,
      "z": -11,
      "name": "Rock_Ice_Permafrost"
    },
    {
      "x": -22,
      "y": 11,
      "z": -11,
      "name": "Rock_Ice"
    },
    {
      "x": -22,
      "y": 12,
      "z": -11,
      "name": "Soil_Snow"
    },
    {
      "x": -22,
      "y": 0,
      "z": -10,
      "name": "Rock_Ice"
    },
    {
      "x": -22,
      "y": 1,
      "z": -10,
      "name": "Rock_Ice"
    },
    {
      "x": -22,
      "y": 2,
      "z": -10,
      "name": "Rock_Ice"
    },
    {
      "x": -22,
      "y": 3,
      "z": -10,
      "name": "Rock_Ice_Permafrost"
    },
    {
      "x": -22,
      "y": 4,
      "z": -10,
      "name": "Rock_Ice_Permafrost"
    },
    {
      "x": -22,
      "y": 5,
      "z": -10,
      "name": "Rock_Ice_Permafrost"
    },
    {
      "x": -22,
      "y": 6,
      "z": -10,
      "name": "Rock_Ice_Permafrost"
    },
    {
      "x": -22,
      "y": 7,
      "z": -10,
      "name": "Rock_Ice_Permafrost"
    },
    {
      "x": -22,
      "y": 8,
      "z": -10,
      "name": "Rock_Ice_Permafrost"
    },
    {
      "x": -22,
      "y": 9,
      "z": -10,
      "name": "Rock_Ice_Permafrost"
    },
    {
      "x": -22,
      "y": 10,
      "z": -10,
      "name": "Rock_Ice_Permafrost"
    },
    {
      "x": -22,
      "y": 11,
      "z": -10,
      "name": "Rock_Ice_Permafrost"
    },
    {
      "x": -22,
      "y": 12,
      "z": -10,
      "name": "Rock_Ice"
    },
    {
      "x": -22,
      "y": 13,
      "z": -10,
      "name": "Soil_Snow"
    },
    {
      "x": -22,
      "y": 0,
      "z": -9,
      "name": "Rock_Ice"
    },
    {
      "x": -22,
      "y": 1,
      "z": -9,
      "name": "Rock_Ice_Permafrost"
    },
    {
      "x": -22,
      "y": 2,
      "z": -9,
      "name": "Rock_Ice_Permafrost"
    },
    {
      "x": -22,
      "y": 3,
      "z": -9,
      "name": "Rock_Ice_Permafrost"
    },
    {
      "x": -22,
      "y": 4,
      "z": -9,
      "name": "Rock_Ice_Permafrost"
    },
    {
      "x": -22,
      "y": 5,
      "z": -9,
      "name": "Rock_Ice_Permafrost"
    },
    {
      "x": -22,
      "y": 6,
      "z": -9,
      "name": "Rock_Ice_Permafrost"
    },
    {
      "x": -22,
      "y": 7,
      "z": -9,
      "name": "Rock_Ice_Permafrost"
    },
    {
      "x": -22,
      "y": 8,
      "z": -9,
      "name": "Rock_Ice_Permafrost"
    },
    {
      "x": -22,
      "y": 9,
      "z": -9,
      "name": "Rock_Ice_Permafrost"
    },
    {
      "x": -22,
      "y": 10,
      "z": -9,
      "name": "Rock_Ice_Permafrost"
    },
    {
      "x": -22,
      "y": 11,
      "z": -9,
      "name": "Rock_Ice_Permafrost"
    },
    {
      "x": -22,
      "y": 12,
      "z": -9,
      "name": "Rock_Ice_Permafrost"
    },
    {
      "x": -22,
      "y": 13,
      "z": -9,
      "name": "Rock_Ice"
    },
    {
      "x": -22,
      "y": 14,
      "z": -9,
      "name": "Soil_Snow"
    },
    {
      "x": -22,
      "y": 0,
      "z": -8,
      "name": "Rock_Ice"
    },
    {
      "x": -22,
      "y": 1,
      "z": -8,
      "name": "Rock_Ice"
    },
    {
      "x": -22,
      "y": 2,
      "z": -8,
      "name": "Rock_Ice_Permafrost"
    },
    {
      "x": -22,
      "y": 3,
      "z": -8,
      "name": "Rock_Ice_Permafrost"
    },
    {
      "x": -22,
      "y": 4,
      "z": -8,
      "name": "Rock_Ice_Permafrost"
    },
    {
      "x": -22,
      "y": 5,
      "z": -8,
      "name": "Rock_Ice_Permafrost"
    },
    {
      "x": -22,
      "y": 6,
      "z": -8,
      "name": "Rock_Ice_Permafrost"
    },
    {
      "x": -22,
      "y": 7,
      "z": -8,
      "name": "Rock_Ice_Permafrost"
    },
    {
      "x": -22,
      "y": 8,
      "z": -8,
      "name": "Rock_Ice_Permafrost"
    },
    {
      "x": -22,
      "y": 9,
      "z": -8,
      "name": "Rock_Ice"
    },
    {
      "x": -22,
      "y": 10,
      "z": -8,
      "name": "Rock_Ice_Permafrost"
    },
    {
      "x": -22,
      "y": 11,
      "z": -8,
      "name": "Rock_Ice"
    },
    {
      "x": -22,
      "y": 12,
      "z": -8,
      "name": "Rock_Ice"
    },
    {
      "x": -22,
      "y": 13,
      "z": -8,
      "name": "Rock_Ice"
    },
    {
      "x": -22,
      "y": 14,
      "z": -8,
      "name": "Rock_Ice"
    },
    {
      "x": -22,
      "y": 15,
      "z": -8,
      "name": "Soil_Snow"
    },
    {
      "x": -22,
      "y": 0,
      "z": -7,
      "name": "Rock_Ice_Permafrost"
    },
    {
      "x": -22,
      "y": 1,
      "z": -7,
      "name": "Rock_Ice_Permafrost"
    },
    {
      "x": -22,
      "y": 2,
      "z": -7,
      "name": "Rock_Ice_Permafrost"
    },
    {
      "x": -22,
      "y": 3,
      "z": -7,
      "name": "Rock_Ice_Permafrost"
    },
    {
      "x": -22,
      "y": 4,
      "z": -7,
      "name": "Rock_Ice_Permafrost"
    },
    {
      "x": -22,
      "y": 5,
      "z": -7,
      "name": "Rock_Ice_Permafrost"
    },
    {
      "x": -22,
      "y": 6,
      "z": -7,
      "name": "Rock_Ice_Permafrost"
    },
    {
      "x": -22,
      "y": 7,
      "z": -7,
      "name": "Rock_Ice_Permafrost"
    },
    {
      "x": -22,
      "y": 8,
      "z": -7,
      "name": "Rock_Ice_Permafrost"
    },
    {
      "x": -22,
      "y": 9,
      "z": -7,
      "name": "Rock_Ice_Permafrost"
    },
    {
      "x": -22,
      "y": 10,
      "z": -7,
      "name": "Rock_Ice_Permafrost"
    },
    {
      "x": -22,
      "y": 11,
      "z": -7,
      "name": "Rock_Ice"
    },
    {
      "x": -22,
      "y": 12,
      "z": -7,
      "name": "Rock_Ice"
    },
    {
      "x": -22,
      "y": 13,
      "z": -7,
      "name": "Rock_Ice"
    },
    {
      "x": -22,
      "y": 14,
      "z": -7,
      "name": "Rock_Ice"
    },
    {
      "x": -22,
      "y": 15,
      "z": -7,
      "name": "Rock_Ice"
    },
    {
      "x": -22,
      "y": 16,
      "z": -7,
      "name": "Soil_Snow"
    },
    {
      "x": -22,
      "y": 0,
      "z": -6,
      "name": "Rock_Ice_Permafrost"
    },
    {
      "x": -22,
      "y": 1,
      "z": -6,
      "name": "Rock_Ice_Permafrost"
    },
    {
      "x": -22,
      "y": 2,
      "z": -6,
      "name": "Rock_Ice_Permafrost"
    },
    {
      "x": -22,
      "y": 3,
      "z": -6,
      "name": "Rock_Ice_Permafrost"
    },
    {
      "x": -22,
      "y": 4,
      "z": -6,
      "name": "Rock_Ice_Permafrost"
    },
    {
      "x": -22,
      "y": 5,
      "z": -6,
      "name": "Rock_Ice_Permafrost"
    },
    {
      "x": -22,
      "y": 6,
      "z": -6,
      "name": "Rock_Ice_Permafrost"
    },
    {
      "x": -22,
      "y": 7,
      "z": -6,
      "name": "Rock_Ice_Permafrost"
    },
    {
      "x": -22,
      "y": 8,
      "z": -6,
      "name": "Rock_Ice_Permafrost"
    },
    {
      "x": -22,
      "y": 9,
      "z": -6,
      "name": "Rock_Ice"
    },
    {
      "x": -22,
      "y": 10,
      "z": -6,
      "name": "Rock_Ice_Permafrost"
    },
    {
      "x": -22,
      "y": 11,
      "z": -6,
      "name": "Rock_Ice"
    },
    {
      "x": -22,
      "y": 12,
      "z": -6,
      "name": "Rock_Ice"
    },
    {
      "x": -22,
      "y": 13,
      "z": -6,
      "name": "Rock_Ice"
    },
    {
      "x": -22,
      "y": 14,
      "z": -6,
      "name": "Rock_Ice"
    },
    {
      "x": -22,
      "y": 15,
      "z": -6,
      "name": "Rock_Ice"
    },
    {
      "x": -22,
      "y": 16,
      "z": -6,
      "name": "Soil_Snow"
    },
    {
      "x": -22,
      "y": 0,
      "z": -5,
      "name": "Rock_Ice_Permafrost"
    },
    {
      "x": -22,
      "y": 1,
      "z": -5,
      "name": "Rock_Ice_Permafrost"
    },
    {
      "x": -22,
      "y": 2,
      "z": -5,
      "name": "Rock_Ice_Permafrost"
    },
    {
      "x": -22,
      "y": 3,
      "z": -5,
      "name": "Rock_Ice_Permafrost"
    },
    {
      "x": -22,
      "y": 4,
      "z": -5,
      "name": "Rock_Ice_Permafrost"
    },
    {
      "x": -22,
      "y": 5,
      "z": -5,
      "name": "Rock_Ice_Permafrost"
    },
    {
      "x": -22,
      "y": 6,
      "z": -5,
      "name": "Rock_Ice_Permafrost"
    },
    {
      "x": -22,
      "y": 7,
      "z": -5,
      "name": "Rock_Ice_Permafrost"
    },
    {
      "x": -22,
      "y": 8,
      "z": -5,
      "name": "Rock_Ice"
    },
    {
      "x": -22,
      "y": 9,
      "z": -5,
      "name": "Rock_Ice"
    },
    {
      "x": -22,
      "y": 10,
      "z": -5,
      "name": "Rock_Ice"
    },
    {
      "x": -22,
      "y": 11,
      "z": -5,
      "name": "Rock_Ice"
    },
    {
      "x": -22,
      "y": 12,
      "z": -5,
      "name": "Rock_Ice"
    },
    {
      "x": -22,
      "y": 13,
      "z": -5,
      "name": "Rock_Ice"
    },
    {
      "x": -22,
      "y": 14,
      "z": -5,
      "name": "Rock_Ice"
    },
    {
      "x": -22,
      "y": 15,
      "z": -5,
      "name": "Rock_Ice"
    },
    {
      "x": -22,
      "y": 16,
      "z": -5,
      "name": "Soil_Snow"
    },
    {
      "x": -22,
      "y": 0,
      "z": -4,
      "name": "Rock_Ice_Permafrost"
    },
    {
      "x": -22,
      "y": 1,
      "z": -4,
      "name": "Rock_Ice_Permafrost"
    },
    {
      "x": -22,
      "y": 2,
      "z": -4,
      "name": "Rock_Ice_Permafrost"
    },
    {
      "x": -22,
      "y": 3,
      "z": -4,
      "name": "Rock_Ice_Permafrost"
    },
    {
      "x": -22,
      "y": 4,
      "z": -4,
      "name": "Rock_Ice_Permafrost"
    },
    {
      "x": -22,
      "y": 5,
      "z": -4,
      "name": "Rock_Ice_Permafrost"
    },
    {
      "x": -22,
      "y": 6,
      "z": -4,
      "name": "Rock_Ice_Permafrost"
    },
    {
      "x": -22,
      "y": 7,
      "z": -4,
      "name": "Rock_Ice_Permafrost"
    },
    {
      "x": -22,
      "y": 8,
      "z": -4,
      "name": "Rock_Ice"
    },
    {
      "x": -22,
      "y": 9,
      "z": -4,
      "name": "Rock_Ice"
    },
    {
      "x": -22,
      "y": 10,
      "z": -4,
      "name": "Rock_Ice"
    },
    {
      "x": -22,
      "y": 11,
      "z": -4,
      "name": "Rock_Ice"
    },
    {
      "x": -22,
      "y": 12,
      "z": -4,
      "name": "Rock_Ice"
    },
    {
      "x": -22,
      "y": 13,
      "z": -4,
      "name": "Rock_Ice"
    },
    {
      "x": -22,
      "y": 14,
      "z": -4,
      "name": "Rock_Ice"
    },
    {
      "x": -22,
      "y": 15,
      "z": -4,
      "name": "Rock_Ice"
    },
    {
      "x": -22,
      "y": 16,
      "z": -4,
      "name": "Rock_Ice"
    },
    {
      "x": -22,
      "y": 17,
      "z": -4,
      "name": "Rock_Ice"
    },
    {
      "x": -22,
      "y": 18,
      "z": -4,
      "name": "Rock_Ice"
    },
    {
      "x": -22,
      "y": 19,
      "z": -4,
      "name": "Rock_Ice"
    },
    {
      "x": -22,
      "y": 20,
      "z": -4,
      "name": "Soil_Snow"
    },
    {
      "x": -22,
      "y": 0,
      "z": -3,
      "name": "Rock_Ice_Permafrost"
    },
    {
      "x": -22,
      "y": 1,
      "z": -3,
      "name": "Rock_Ice_Permafrost"
    },
    {
      "x": -22,
      "y": 2,
      "z": -3,
      "name": "Rock_Ice_Permafrost"
    },
    {
      "x": -22,
      "y": 3,
      "z": -3,
      "name": "Rock_Ice_Permafrost"
    },
    {
      "x": -22,
      "y": 4,
      "z": -3,
      "name": "Rock_Ice_Permafrost"
    },
    {
      "x": -22,
      "y": 5,
      "z": -3,
      "name": "Rock_Ice_Permafrost"
    },
    {
      "x": -22,
      "y": 6,
      "z": -3,
      "name": "Rock_Ice"
    },
    {
      "x": -22,
      "y": 7,
      "z": -3,
      "name": "Rock_Ice"
    },
    {
      "x": -22,
      "y": 8,
      "z": -3,
      "name": "Rock_Ice"
    },
    {
      "x": -22,
      "y": 9,
      "z": -3,
      "name": "Rock_Ice"
    },
    {
      "x": -22,
      "y": 10,
      "z": -3,
      "name": "Rock_Ice"
    },
    {
      "x": -22,
      "y": 11,
      "z": -3,
      "name": "Rock_Ice"
    },
    {
      "x": -22,
      "y": 12,
      "z": -3,
      "name": "Rock_Ice"
    },
    {
      "x": -22,
      "y": 13,
      "z": -3,
      "name": "Rock_Ice"
    },
    {
      "x": -22,
      "y": 14,
      "z": -3,
      "name": "Rock_Ice"
    },
    {
      "x": -22,
      "y": 15,
      "z": -3,
      "name": "Rock_Ice"
    },
    {
      "x": -22,
      "y": 16,
      "z": -3,
      "name": "Rock_Ice"
    },
    {
      "x": -22,
      "y": 17,
      "z": -3,
      "name": "Rock_Ice"
    },
    {
      "x": -22,
      "y": 18,
      "z": -3,
      "name": "Rock_Ice"
    },
    {
      "x": -22,
      "y": 19,
      "z": -3,
      "name": "Rock_Ice"
    },
    {
      "x": -22,
      "y": 20,
      "z": -3,
      "name": "Rock_Ice"
    },
    {
      "x": -22,
      "y": 21,
      "z": -3,
      "name": "Rock_Ice"
    },
    {
      "x": -22,
      "y": 22,
      "z": -3,
      "name": "Soil_Snow"
    },
    {
      "x": -22,
      "y": 0,
      "z": -2,
      "name": "Rock_Ice_Permafrost"
    },
    {
      "x": -22,
      "y": 1,
      "z": -2,
      "name": "Rock_Ice_Permafrost"
    },
    {
      "x": -22,
      "y": 2,
      "z": -2,
      "name": "Rock_Ice_Permafrost"
    },
    {
      "x": -22,
      "y": 3,
      "z": -2,
      "name": "Rock_Ice_Permafrost"
    },
    {
      "x": -22,
      "y": 4,
      "z": -2,
      "name": "Rock_Ice_Permafrost"
    },
    {
      "x": -22,
      "y": 5,
      "z": -2,
      "name": "Rock_Ice_Permafrost"
    },
    {
      "x": -22,
      "y": 6,
      "z": -2,
      "name": "Rock_Ice_Permafrost"
    },
    {
      "x": -22,
      "y": 7,
      "z": -2,
      "name": "Rock_Ice"
    },
    {
      "x": -22,
      "y": 8,
      "z": -2,
      "name": "Rock_Ice"
    },
    {
      "x": -22,
      "y": 9,
      "z": -2,
      "name": "Rock_Ice"
    },
    {
      "x": -22,
      "y": 10,
      "z": -2,
      "name": "Rock_Ice"
    },
    {
      "x": -22,
      "y": 11,
      "z": -2,
      "name": "Rock_Ice"
    },
    {
      "x": -22,
      "y": 12,
      "z": -2,
      "name": "Rock_Ice"
    },
    {
      "x": -22,
      "y": 13,
      "z": -2,
      "name": "Rock_Ice"
    },
    {
      "x": -22,
      "y": 14,
      "z": -2,
      "name": "Rock_Ice"
    },
    {
      "x": -22,
      "y": 15,
      "z": -2,
      "name": "Rock_Ice"
    },
    {
      "x": -22,
      "y": 16,
      "z": -2,
      "name": "Rock_Ice"
    },
    {
      "x": -22,
      "y": 17,
      "z": -2,
      "name": "Rock_Ice"
    },
    {
      "x": -22,
      "y": 18,
      "z": -2,
      "name": "Rock_Ice"
    },
    {
      "x": -22,
      "y": 19,
      "z": -2,
      "name": "Rock_Ice"
    },
    {
      "x": -22,
      "y": 20,
      "z": -2,
      "name": "Rock_Ice"
    },
    {
      "x": -22,
      "y": 21,
      "z": -2,
      "name": "Rock_Ice"
    },
    {
      "x": -22,
      "y": 22,
      "z": -2,
      "name": "Rock_Ice"
    },
    {
      "x": -22,
      "y": 23,
      "z": -2,
      "name": "Rock_Ice"
    },
    {
      "x": -22,
      "y": 24,
      "z": -2,
      "name": "Soil_Snow"
    },
    {
      "x": -22,
      "y": 0,
      "z": -1,
      "name": "Rock_Ice_Permafrost"
    },
    {
      "x": -22,
      "y": 1,
      "z": -1,
      "name": "Rock_Ice_Permafrost"
    },
    {
      "x": -22,
      "y": 2,
      "z": -1,
      "name": "Rock_Ice_Permafrost"
    },
    {
      "x": -22,
      "y": 3,
      "z": -1,
      "name": "Rock_Ice_Permafrost"
    },
    {
      "x": -22,
      "y": 4,
      "z": -1,
      "name": "Rock_Ice_Permafrost"
    },
    {
      "x": -22,
      "y": 5,
      "z": -1,
      "name": "Rock_Ice"
    },
    {
      "x": -22,
      "y": 6,
      "z": -1,
      "name": "Rock_Ice_Permafrost"
    },
    {
      "x": -22,
      "y": 7,
      "z": -1,
      "name": "Rock_Ice"
    },
    {
      "x": -22,
      "y": 8,
      "z": -1,
      "name": "Rock_Ice"
    },
    {
      "x": -22,
      "y": 9,
      "z": -1,
      "name": "Rock_Ice"
    },
    {
      "x": -22,
      "y": 10,
      "z": -1,
      "name": "Rock_Ice"
    },
    {
      "x": -22,
      "y": 11,
      "z": -1,
      "name": "Rock_Ice"
    },
    {
      "x": -22,
      "y": 12,
      "z": -1,
      "name": "Rock_Ice"
    },
    {
      "x": -22,
      "y": 13,
      "z": -1,
      "name": "Rock_Ice"
    },
    {
      "x": -22,
      "y": 14,
      "z": -1,
      "name": "Rock_Ice"
    },
    {
      "x": -22,
      "y": 15,
      "z": -1,
      "name": "Rock_Ice"
    },
    {
      "x": -22,
      "y": 16,
      "z": -1,
      "name": "Rock_Ice"
    },
    {
      "x": -22,
      "y": 17,
      "z": -1,
      "name": "Rock_Ice"
    },
    {
      "x": -22,
      "y": 18,
      "z": -1,
      "name": "Rock_Ice"
    },
    {
      "x": -22,
      "y": 19,
      "z": -1,
      "name": "Rock_Ice"
    },
    {
      "x": -22,
      "y": 20,
      "z": -1,
      "name": "Rock_Ice"
    },
    {
      "x": -22,
      "y": 21,
      "z": -1,
      "name": "Rock_Ice"
    },
    {
      "x": -22,
      "y": 22,
      "z": -1,
      "name": "Rock_Ice"
    },
    {
      "x": -22,
      "y": 23,
      "z": -1,
      "name": "Rock_Ice"
    },
    {
      "x": -22,
      "y": 24,
      "z": -1,
      "name": "Rock_Ice"
    },
    {
      "x": -22,
      "y": 3,
      "z": 0,
      "name": "Rock_Ice_Permafrost"
    },
    {
      "x": -22,
      "y": 4,
      "z": 0,
      "name": "Rock_Ice_Permafrost"
    },
    {
      "x": -22,
      "y": 5,
      "z": 0,
      "name": "Rock_Ice"
    },
    {
      "x": -22,
      "y": 6,
      "z": 0,
      "name": "Rock_Ice"
    },
    {
      "x": -22,
      "y": 7,
      "z": 0,
      "name": "Rock_Ice"
    },
    {
      "x": -22,
      "y": 8,
      "z": 0,
      "name": "Rock_Ice"
    },
    {
      "x": -22,
      "y": 9,
      "z": 0,
      "name": "Rock_Ice"
    },
    {
      "x": -22,
      "y": 10,
      "z": 0,
      "name": "Rock_Ice"
    },
    {
      "x": -22,
      "y": 11,
      "z": 0,
      "name": "Rock_Ice"
    },
    {
      "x": -22,
      "y": 12,
      "z": 0,
      "name": "Rock_Ice"
    },
    {
      "x": -22,
      "y": 13,
      "z": 0,
      "name": "Rock_Ice"
    },
    {
      "x": -22,
      "y": 14,
      "z": 0,
      "name": "Rock_Ice"
    },
    {
      "x": -22,
      "y": 15,
      "z": 0,
      "name": "Rock_Ice"
    },
    {
      "x": -22,
      "y": 16,
      "z": 0,
      "name": "Rock_Ice"
    },
    {
      "x": -22,
      "y": 17,
      "z": 0,
      "name": "Rock_Ice"
    },
    {
      "x": -22,
      "y": 18,
      "z": 0,
      "name": "Rock_Ice"
    },
    {
      "x": -22,
      "y": 19,
      "z": 0,
      "name": "Soil_Snow"
    },
    {
      "x": -22,
      "y": 3,
      "z": 1,
      "name": "Rock_Ice_Permafrost"
    },
    {
      "x": -22,
      "y": 4,
      "z": 1,
      "name": "Rock_Ice_Permafrost"
    },
    {
      "x": -22,
      "y": 5,
      "z": 1,
      "name": "Rock_Ice_Permafrost"
    },
    {
      "x": -22,
      "y": 6,
      "z": 1,
      "name": "Rock_Ice"
    },
    {
      "x": -22,
      "y": 7,
      "z": 1,
      "name": "Rock_Ice"
    },
    {
      "x": -22,
      "y": 8,
      "z": 1,
      "name": "Rock_Ice"
    },
    {
      "x": -22,
      "y": 9,
      "z": 1,
      "name": "Rock_Ice"
    },
    {
      "x": -22,
      "y": 10,
      "z": 1,
      "name": "Rock_Ice"
    },
    {
      "x": -22,
      "y": 11,
      "z": 1,
      "name": "Rock_Ice"
    },
    {
      "x": -22,
      "y": 12,
      "z": 1,
      "name": "Rock_Ice"
    },
    {
      "x": -22,
      "y": 13,
      "z": 1,
      "name": "Rock_Ice"
    },
    {
      "x": -22,
      "y": 14,
      "z": 1,
      "name": "Rock_Ice"
    },
    {
      "x": -22,
      "y": 15,
      "z": 1,
      "name": "Rock_Ice"
    },
    {
      "x": -22,
      "y": 16,
      "z": 1,
      "name": "Rock_Ice"
    },
    {
      "x": -22,
      "y": 17,
      "z": 1,
      "name": "Rock_Ice"
    },
    {
      "x": -22,
      "y": 18,
      "z": 1,
      "name": "Soil_Snow"
    },
    {
      "x": -22,
      "y": 3,
      "z": 2,
      "name": "Rock_Ice_Permafrost"
    },
    {
      "x": -22,
      "y": 4,
      "z": 2,
      "name": "Rock_Ice"
    },
    {
      "x": -22,
      "y": 5,
      "z": 2,
      "name": "Rock_Ice"
    },
    {
      "x": -22,
      "y": 6,
      "z": 2,
      "name": "Rock_Ice"
    },
    {
      "x": -22,
      "y": 7,
      "z": 2,
      "name": "Rock_Ice"
    },
    {
      "x": -22,
      "y": 8,
      "z": 2,
      "name": "Rock_Ice"
    },
    {
      "x": -22,
      "y": 9,
      "z": 2,
      "name": "Rock_Ice"
    },
    {
      "x": -22,
      "y": 10,
      "z": 2,
      "name": "Rock_Ice"
    },
    {
      "x": -22,
      "y": 11,
      "z": 2,
      "name": "Rock_Ice"
    },
    {
      "x": -22,
      "y": 12,
      "z": 2,
      "name": "Rock_Ice"
    },
    {
      "x": -22,
      "y": 13,
      "z": 2,
      "name": "Rock_Ice"
    },
    {
      "x": -22,
      "y": 14,
      "z": 2,
      "name": "Rock_Ice"
    },
    {
      "x": -22,
      "y": 15,
      "z": 2,
      "name": "Rock_Ice"
    },
    {
      "x": -22,
      "y": 16,
      "z": 2,
      "name": "Soil_Snow"
    },
    {
      "x": -22,
      "y": 3,
      "z": 3,
      "name": "Rock_Ice_Permafrost"
    },
    {
      "x": -22,
      "y": 4,
      "z": 3,
      "name": "Rock_Ice_Permafrost"
    },
    {
      "x": -22,
      "y": 5,
      "z": 3,
      "name": "Rock_Ice"
    },
    {
      "x": -22,
      "y": 6,
      "z": 3,
      "name": "Rock_Ice"
    },
    {
      "x": -22,
      "y": 7,
      "z": 3,
      "name": "Rock_Ice"
    },
    {
      "x": -22,
      "y": 8,
      "z": 3,
      "name": "Rock_Ice"
    },
    {
      "x": -22,
      "y": 9,
      "z": 3,
      "name": "Rock_Ice"
    },
    {
      "x": -22,
      "y": 10,
      "z": 3,
      "name": "Rock_Ice"
    },
    {
      "x": -22,
      "y": 11,
      "z": 3,
      "name": "Rock_Ice"
    },
    {
      "x": -22,
      "y": 12,
      "z": 3,
      "name": "Rock_Ice"
    },
    {
      "x": -22,
      "y": 13,
      "z": 3,
      "name": "Rock_Ice"
    },
    {
      "x": -22,
      "y": 14,
      "z": 3,
      "name": "Soil_Snow"
    },
    {
      "x": -22,
      "y": 3,
      "z": 4,
      "name": "Rock_Ice_Permafrost"
    },
    {
      "x": -22,
      "y": 4,
      "z": 4,
      "name": "Rock_Ice_Permafrost"
    },
    {
      "x": -22,
      "y": 5,
      "z": 4,
      "name": "Rock_Ice"
    },
    {
      "x": -22,
      "y": 6,
      "z": 4,
      "name": "Rock_Ice"
    },
    {
      "x": -22,
      "y": 7,
      "z": 4,
      "name": "Rock_Ice"
    },
    {
      "x": -22,
      "y": 8,
      "z": 4,
      "name": "Rock_Ice"
    },
    {
      "x": -22,
      "y": 9,
      "z": 4,
      "name": "Rock_Ice"
    },
    {
      "x": -22,
      "y": 10,
      "z": 4,
      "name": "Rock_Ice"
    },
    {
      "x": -22,
      "y": 11,
      "z": 4,
      "name": "Rock_Ice"
    },
    {
      "x": -22,
      "y": 12,
      "z": 4,
      "name": "Rock_Ice"
    },
    {
      "x": -22,
      "y": 13,
      "z": 4,
      "name": "Soil_Snow"
    },
    {
      "x": -22,
      "y": 3,
      "z": 5,
      "name": "Rock_Ice_Permafrost"
    },
    {
      "x": -22,
      "y": 4,
      "z": 5,
      "name": "Rock_Ice"
    },
    {
      "x": -22,
      "y": 5,
      "z": 5,
      "name": "Rock_Ice"
    },
    {
      "x": -22,
      "y": 6,
      "z": 5,
      "name": "Rock_Ice"
    },
    {
      "x": -22,
      "y": 7,
      "z": 5,
      "name": "Rock_Ice"
    },
    {
      "x": -22,
      "y": 8,
      "z": 5,
      "name": "Rock_Ice"
    },
    {
      "x": -22,
      "y": 9,
      "z": 5,
      "name": "Rock_Ice"
    },
    {
      "x": -22,
      "y": 10,
      "z": 5,
      "name": "Rock_Ice"
    },
    {
      "x": -22,
      "y": 11,
      "z": 5,
      "name": "Rock_Ice"
    },
    {
      "x": -22,
      "y": 12,
      "z": 5,
      "name": "Soil_Snow"
    },
    {
      "x": -22,
      "y": 3,
      "z": 6,
      "name": "Rock_Ice"
    },
    {
      "x": -22,
      "y": 4,
      "z": 6,
      "name": "Rock_Ice"
    },
    {
      "x": -22,
      "y": 5,
      "z": 6,
      "name": "Rock_Ice"
    },
    {
      "x": -22,
      "y": 6,
      "z": 6,
      "name": "Rock_Ice"
    },
    {
      "x": -22,
      "y": 7,
      "z": 6,
      "name": "Rock_Ice"
    },
    {
      "x": -22,
      "y": 8,
      "z": 6,
      "name": "Rock_Ice"
    },
    {
      "x": -22,
      "y": 9,
      "z": 6,
      "name": "Rock_Ice"
    },
    {
      "x": -22,
      "y": 10,
      "z": 6,
      "name": "Rock_Ice"
    },
    {
      "x": -22,
      "y": 11,
      "z": 6,
      "name": "Soil_Snow"
    },
    {
      "x": -22,
      "y": 4,
      "z": 7,
      "name": "Rock_Ice"
    },
    {
      "x": -22,
      "y": 5,
      "z": 7,
      "name": "Rock_Ice"
    },
    {
      "x": -22,
      "y": 6,
      "z": 7,
      "name": "Rock_Ice"
    },
    {
      "x": -22,
      "y": 7,
      "z": 7,
      "name": "Rock_Ice"
    },
    {
      "x": -22,
      "y": 8,
      "z": 7,
      "name": "Rock_Ice"
    },
    {
      "x": -22,
      "y": 9,
      "z": 7,
      "name": "Rock_Ice"
    },
    {
      "x": -22,
      "y": 10,
      "z": 7,
      "name": "Soil_Snow"
    },
    {
      "x": -22,
      "y": 6,
      "z": 8,
      "name": "Rock_Ice"
    },
    {
      "x": -22,
      "y": 7,
      "z": 8,
      "name": "Rock_Ice"
    },
    {
      "x": -22,
      "y": 8,
      "z": 8,
      "name": "Rock_Ice"
    },
    {
      "x": -22,
      "y": 9,
      "z": 8,
      "name": "Rock_Ice"
    },
    {
      "x": -22,
      "y": 10,
      "z": 8,
      "name": "Soil_Snow"
    },
    {
      "x": -22,
      "y": 8,
      "z": 9,
      "name": "Rock_Ice"
    },
    {
      "x": -22,
      "y": 9,
      "z": 9,
      "name": "Soil_Snow"
    },
    {
      "x": -21,
      "y": 9,
      "z": -16,
      "name": "Rock_Ice"
    },
    {
      "x": -21,
      "y": 10,
      "z": -16,
      "name": "Soil_Snow"
    },
    {
      "x": -21,
      "y": 8,
      "z": -15,
      "name": "Rock_Ice_Permafrost"
    },
    {
      "x": -21,
      "y": 9,
      "z": -15,
      "name": "Rock_Ice_Permafrost"
    },
    {
      "x": -21,
      "y": 10,
      "z": -15,
      "name": "Rock_Ice"
    },
    {
      "x": -21,
      "y": 11,
      "z": -15,
      "name": "Soil_Snow"
    },
    {
      "x": -21,
      "y": 6,
      "z": -14,
      "name": "Rock_Ice_Permafrost"
    },
    {
      "x": -21,
      "y": 7,
      "z": -14,
      "name": "Rock_Ice"
    },
    {
      "x": -21,
      "y": 8,
      "z": -14,
      "name": "Rock_Ice_Permafrost"
    },
    {
      "x": -21,
      "y": 9,
      "z": -14,
      "name": "Rock_Ice_Permafrost"
    },
    {
      "x": -21,
      "y": 10,
      "z": -14,
      "name": "Rock_Ice_Permafrost"
    },
    {
      "x": -21,
      "y": 11,
      "z": -14,
      "name": "Rock_Ice"
    },
    {
      "x": -21,
      "y": 12,
      "z": -14,
      "name": "Soil_Snow"
    },
    {
      "x": -21,
      "y": 3,
      "z": -13,
      "name": "Rock_Ice"
    },
    {
      "x": -21,
      "y": 4,
      "z": -13,
      "name": "Rock_Ice_Permafrost"
    },
    {
      "x": -21,
      "y": 5,
      "z": -13,
      "name": "Rock_Ice_Permafrost"
    },
    {
      "x": -21,
      "y": 6,
      "z": -13,
      "name": "Rock_Ice_Permafrost"
    },
    {
      "x": -21,
      "y": 7,
      "z": -13,
      "name": "Rock_Ice_Permafrost"
    },
    {
      "x": -21,
      "y": 8,
      "z": -13,
      "name": "Rock_Ice_Permafrost"
    },
    {
      "x": -21,
      "y": 9,
      "z": -13,
      "name": "Rock_Ice_Permafrost"
    },
    {
      "x": -21,
      "y": 10,
      "z": -13,
      "name": "Rock_Ice_Permafrost"
    },
    {
      "x": -21,
      "y": 11,
      "z": -13,
      "name": "Rock_Ice_Permafrost"
    },
    {
      "x": -21,
      "y": 12,
      "z": -13,
      "name": "Rock_Ice"
    },
    {
      "x": -21,
      "y": 13,
      "z": -13,
      "name": "Soil_Snow"
    },
    {
      "x": -21,
      "y": 2,
      "z": -12,
      "name": "Rock_Ice"
    },
    {
      "x": -21,
      "y": 3,
      "z": -12,
      "name": "Rock_Ice"
    },
    {
      "x": -21,
      "y": 4,
      "z": -12,
      "name": "Rock_Ice_Permafrost"
    },
    {
      "x": -21,
      "y": 5,
      "z": -12,
      "name": "Rock_Ice_Permafrost"
    },
    {
      "x": -21,
      "y": 6,
      "z": -12,
      "name": "Rock_Ice_Permafrost"
    },
    {
      "x": -21,
      "y": 7,
      "z": -12,
      "name": "Rock_Ice_Permafrost"
    },
    {
      "x": -21,
      "y": 8,
      "z": -12,
      "name": "Rock_Ice_Permafrost"
    },
    {
      "x": -21,
      "y": 9,
      "z": -12,
      "name": "Rock_Ice_Permafrost"
    },
    {
      "x": -21,
      "y": 10,
      "z": -12,
      "name": "Rock_Ice_Permafrost"
    },
    {
      "x": -21,
      "y": 11,
      "z": -12,
      "name": "Rock_Ice_Permafrost"
    },
    {
      "x": -21,
      "y": 12,
      "z": -12,
      "name": "Rock_Ice"
    },
    {
      "x": -21,
      "y": 13,
      "z": -12,
      "name": "Soil_Snow"
    },
    {
      "x": -21,
      "y": 0,
      "z": -11,
      "name": "Rock_Ice"
    },
    {
      "x": -21,
      "y": 1,
      "z": -11,
      "name": "Rock_Ice"
    },
    {
      "x": -21,
      "y": 2,
      "z": -11,
      "name": "Rock_Ice"
    },
    {
      "x": -21,
      "y": 3,
      "z": -11,
      "name": "Rock_Ice_Permafrost"
    },
    {
      "x": -21,
      "y": 4,
      "z": -11,
      "name": "Rock_Ice_Permafrost"
    },
    {
      "x": -21,
      "y": 5,
      "z": -11,
      "name": "Rock_Ice_Permafrost"
    },
    {
      "x": -21,
      "y": 6,
      "z": -11,
      "name": "Rock_Ice_Permafrost"
    },
    {
      "x": -21,
      "y": 7,
      "z": -11,
      "name": "Rock_Ice_Permafrost"
    },
    {
      "x": -21,
      "y": 8,
      "z": -11,
      "name": "Rock_Ice_Permafrost"
    },
    {
      "x": -21,
      "y": 9,
      "z": -11,
      "name": "Rock_Ice_Permafrost"
    },
    {
      "x": -21,
      "y": 10,
      "z": -11,
      "name": "Rock_Ice_Permafrost"
    },
    {
      "x": -21,
      "y": 11,
      "z": -11,
      "name": "Rock_Ice_Permafrost"
    },
    {
      "x": -21,
      "y": 12,
      "z": -11,
      "name": "Rock_Ice_Permafrost"
    },
    {
      "x": -21,
      "y": 13,
      "z": -11,
      "name": "Rock_Ice"
    },
    {
      "x": -21,
      "y": 14,
      "z": -11,
      "name": "Soil_Snow"
    },
    {
      "x": -21,
      "y": 0,
      "z": -10,
      "name": "Rock_Ice"
    },
    {
      "x": -21,
      "y": 1,
      "z": -10,
      "name": "Rock_Ice"
    },
    {
      "x": -21,
      "y": 2,
      "z": -10,
      "name": "Rock_Ice"
    },
    {
      "x": -21,
      "y": 3,
      "z": -10,
      "name": "Rock_Ice"
    },
    {
      "x": -21,
      "y": 4,
      "z": -10,
      "name": "Rock_Ice_Permafrost"
    },
    {
      "x": -21,
      "y": 5,
      "z": -10,
      "name": "Rock_Ice_Permafrost"
    },
    {
      "x": -21,
      "y": 6,
      "z": -10,
      "name": "Rock_Ice_Permafrost"
    },
    {
      "x": -21,
      "y": 7,
      "z": -10,
      "name": "Rock_Ice_Permafrost"
    },
    {
      "x": -21,
      "y": 8,
      "z": -10,
      "name": "Rock_Ice_Permafrost"
    },
    {
      "x": -21,
      "y": 9,
      "z": -10,
      "name": "Rock_Ice_Permafrost"
    },
    {
      "x": -21,
      "y": 10,
      "z": -10,
      "name": "Rock_Ice_Permafrost"
    },
    {
      "x": -21,
      "y": 11,
      "z": -10,
      "name": "Rock_Ice_Permafrost"
    },
    {
      "x": -21,
      "y": 12,
      "z": -10,
      "name": "Rock_Ice_Permafrost"
    },
    {
      "x": -21,
      "y": 13,
      "z": -10,
      "name": "Rock_Ice_Permafrost"
    },
    {
      "x": -21,
      "y": 14,
      "z": -10,
      "name": "Rock_Ice"
    },
    {
      "x": -21,
      "y": 15,
      "z": -10,
      "name": "Soil_Snow"
    },
    {
      "x": -21,
      "y": 0,
      "z": -9,
      "name": "Rock_Ice"
    },
    {
      "x": -21,
      "y": 1,
      "z": -9,
      "name": "Rock_Ice"
    },
    {
      "x": -21,
      "y": 2,
      "z": -9,
      "name": "Rock_Ice_Permafrost"
    },
    {
      "x": -21,
      "y": 3,
      "z": -9,
      "name": "Rock_Ice_Permafrost"
    },
    {
      "x": -21,
      "y": 4,
      "z": -9,
      "name": "Rock_Ice_Permafrost"
    },
    {
      "x": -21,
      "y": 5,
      "z": -9,
      "name": "Rock_Ice_Permafrost"
    },
    {
      "x": -21,
      "y": 6,
      "z": -9,
      "name": "Rock_Ice_Permafrost"
    },
    {
      "x": -21,
      "y": 7,
      "z": -9,
      "name": "Rock_Ice_Permafrost"
    },
    {
      "x": -21,
      "y": 8,
      "z": -9,
      "name": "Rock_Ice_Permafrost"
    },
    {
      "x": -21,
      "y": 9,
      "z": -9,
      "name": "Rock_Ice_Permafrost"
    },
    {
      "x": -21,
      "y": 10,
      "z": -9,
      "name": "Rock_Ice_Permafrost"
    },
    {
      "x": -21,
      "y": 11,
      "z": -9,
      "name": "Rock_Ice"
    },
    {
      "x": -21,
      "y": 12,
      "z": -9,
      "name": "Rock_Ice_Permafrost"
    },
    {
      "x": -21,
      "y": 13,
      "z": -9,
      "name": "Rock_Ice_Permafrost"
    },
    {
      "x": -21,
      "y": 14,
      "z": -9,
      "name": "Rock_Ice_Permafrost"
    },
    {
      "x": -21,
      "y": 15,
      "z": -9,
      "name": "Rock_Ice"
    },
    {
      "x": -21,
      "y": 16,
      "z": -9,
      "name": "Soil_Snow"
    },
    {
      "x": -21,
      "y": 0,
      "z": -8,
      "name": "Rock_Ice"
    },
    {
      "x": -21,
      "y": 1,
      "z": -8,
      "name": "Rock_Ice_Permafrost"
    },
    {
      "x": -21,
      "y": 2,
      "z": -8,
      "name": "Rock_Ice_Permafrost"
    },
    {
      "x": -21,
      "y": 3,
      "z": -8,
      "name": "Rock_Ice_Permafrost"
    },
    {
      "x": -21,
      "y": 4,
      "z": -8,
      "name": "Rock_Ice_Permafrost"
    },
    {
      "x": -21,
      "y": 5,
      "z": -8,
      "name": "Rock_Ice_Permafrost"
    },
    {
      "x": -21,
      "y": 6,
      "z": -8,
      "name": "Rock_Ice_Permafrost"
    },
    {
      "x": -21,
      "y": 7,
      "z": -8,
      "name": "Rock_Ice_Permafrost"
    },
    {
      "x": -21,
      "y": 8,
      "z": -8,
      "name": "Rock_Ice_Permafrost"
    },
    {
      "x": -21,
      "y": 9,
      "z": -8,
      "name": "Rock_Ice_Permafrost"
    },
    {
      "x": -21,
      "y": 10,
      "z": -8,
      "name": "Rock_Ice_Permafrost"
    },
    {
      "x": -21,
      "y": 11,
      "z": -8,
      "name": "Rock_Ice_Permafrost"
    },
    {
      "x": -21,
      "y": 12,
      "z": -8,
      "name": "Rock_Ice_Permafrost"
    },
    {
      "x": -21,
      "y": 13,
      "z": -8,
      "name": "Rock_Ice_Permafrost"
    },
    {
      "x": -21,
      "y": 14,
      "z": -8,
      "name": "Rock_Ice_Permafrost"
    },
    {
      "x": -21,
      "y": 15,
      "z": -8,
      "name": "Rock_Ice_Permafrost"
    },
    {
      "x": -21,
      "y": 16,
      "z": -8,
      "name": "Rock_Ice"
    },
    {
      "x": -21,
      "y": 17,
      "z": -8,
      "name": "Soil_Snow"
    },
    {
      "x": -21,
      "y": 0,
      "z": -7,
      "name": "Rock_Ice"
    },
    {
      "x": -21,
      "y": 1,
      "z": -7,
      "name": "Rock_Ice"
    },
    {
      "x": -21,
      "y": 2,
      "z": -7,
      "name": "Rock_Ice_Permafrost"
    },
    {
      "x": -21,
      "y": 3,
      "z": -7,
      "name": "Rock_Ice_Permafrost"
    },
    {
      "x": -21,
      "y": 4,
      "z": -7,
      "name": "Rock_Ice_Permafrost"
    },
    {
      "x": -21,
      "y": 5,
      "z": -7,
      "name": "Rock_Ice_Permafrost"
    },
    {
      "x": -21,
      "y": 6,
      "z": -7,
      "name": "Rock_Ice_Permafrost"
    },
    {
      "x": -21,
      "y": 7,
      "z": -7,
      "name": "Rock_Ice_Permafrost"
    },
    {
      "x": -21,
      "y": 8,
      "z": -7,
      "name": "Rock_Ice_Permafrost"
    },
    {
      "x": -21,
      "y": 9,
      "z": -7,
      "name": "Rock_Ice_Permafrost"
    },
    {
      "x": -21,
      "y": 10,
      "z": -7,
      "name": "Rock_Ice_Permafrost"
    },
    {
      "x": -21,
      "y": 11,
      "z": -7,
      "name": "Rock_Ice_Permafrost"
    },
    {
      "x": -21,
      "y": 12,
      "z": -7,
      "name": "Rock_Ice_Permafrost"
    },
    {
      "x": -21,
      "y": 13,
      "z": -7,
      "name": "Rock_Ice"
    },
    {
      "x": -21,
      "y": 14,
      "z": -7,
      "name": "Rock_Ice_Permafrost"
    },
    {
      "x": -21,
      "y": 15,
      "z": -7,
      "name": "Rock_Ice_Permafrost"
    },
    {
      "x": -21,
      "y": 16,
      "z": -7,
      "name": "Rock_Ice"
    },
    {
      "x": -21,
      "y": 17,
      "z": -7,
      "name": "Rock_Ice"
    },
    {
      "x": -21,
      "y": 18,
      "z": -7,
      "name": "Rock_Ice"
    },
    {
      "x": -21,
      "y": 19,
      "z": -7,
      "name": "Soil_Snow"
    },
    {
      "x": -21,
      "y": 0,
      "z": -6,
      "name": "Rock_Ice"
    },
    {
      "x": -21,
      "y": 1,
      "z": -6,
      "name": "Rock_Ice_Permafrost"
    },
    {
      "x": -21,
      "y": 2,
      "z": -6,
      "name": "Rock_Ice_Permafrost"
    },
    {
      "x": -21,
      "y": 3,
      "z": -6,
      "name": "Rock_Ice_Permafrost"
    },
    {
      "x": -21,
      "y": 4,
      "z": -6,
      "name": "Rock_Ice_Permafrost"
    },
    {
      "x": -21,
      "y": 5,
      "z": -6,
      "name": "Rock_Ice_Permafrost"
    },
    {
      "x": -21,
      "y": 6,
      "z": -6,
      "name": "Rock_Ice_Permafrost"
    },
    {
      "x": -21,
      "y": 7,
      "z": -6,
      "name": "Rock_Ice_Permafrost"
    },
    {
      "x": -21,
      "y": 8,
      "z": -6,
      "name": "Rock_Ice"
    },
    {
      "x": -21,
      "y": 9,
      "z": -6,
      "name": "Rock_Ice_Permafrost"
    },
    {
      "x": -21,
      "y": 10,
      "z": -6,
      "name": "Rock_Ice"
    },
    {
      "x": -21,
      "y": 11,
      "z": -6,
      "name": "Rock_Ice_Permafrost"
    },
    {
      "x": -21,
      "y": 12,
      "z": -6,
      "name": "Rock_Ice_Permafrost"
    },
    {
      "x": -21,
      "y": 13,
      "z": -6,
      "name": "Rock_Ice"
    },
    {
      "x": -21,
      "y": 14,
      "z": -6,
      "name": "Rock_Ice"
    },
    {
      "x": -21,
      "y": 15,
      "z": -6,
      "name": "Rock_Ice"
    },
    {
      "x": -21,
      "y": 16,
      "z": -6,
      "name": "Rock_Ice_Permafrost"
    },
    {
      "x": -21,
      "y": 17,
      "z": -6,
      "name": "Rock_Ice"
    },
    {
      "x": -21,
      "y": 18,
      "z": -6,
      "name": "Rock_Ice_Permafrost"
    },
    {
      "x": -21,
      "y": 19,
      "z": -6,
      "name": "Soil_Snow"
    },
    {
      "x": -21,
      "y": 0,
      "z": -5,
      "name": "Rock_Ice_Permafrost"
    },
    {
      "x": -21,
      "y": 1,
      "z": -5,
      "name": "Rock_Ice_Permafrost"
    },
    {
      "x": -21,
      "y": 2,
      "z": -5,
      "name": "Rock_Ice_Permafrost"
    },
    {
      "x": -21,
      "y": 3,
      "z": -5,
      "name": "Rock_Ice_Permafrost"
    },
    {
      "x": -21,
      "y": 4,
      "z": -5,
      "name": "Rock_Ice_Permafrost"
    },
    {
      "x": -21,
      "y": 5,
      "z": -5,
      "name": "Rock_Ice_Permafrost"
    },
    {
      "x": -21,
      "y": 6,
      "z": -5,
      "name": "Rock_Ice_Permafrost"
    },
    {
      "x": -21,
      "y": 7,
      "z": -5,
      "name": "Rock_Ice"
    },
    {
      "x": -21,
      "y": 8,
      "z": -5,
      "name": "Rock_Ice_Permafrost"
    },
    {
      "x": -21,
      "y": 9,
      "z": -5,
      "name": "Rock_Ice"
    },
    {
      "x": -21,
      "y": 10,
      "z": -5,
      "name": "Rock_Ice"
    },
    {
      "x": -21,
      "y": 11,
      "z": -5,
      "name": "Rock_Ice"
    },
    {
      "x": -21,
      "y": 12,
      "z": -5,
      "name": "Rock_Ice"
    },
    {
      "x": -21,
      "y": 13,
      "z": -5,
      "name": "Rock_Ice"
    },
    {
      "x": -21,
      "y": 14,
      "z": -5,
      "name": "Rock_Ice"
    },
    {
      "x": -21,
      "y": 15,
      "z": -5,
      "name": "Rock_Ice"
    },
    {
      "x": -21,
      "y": 16,
      "z": -5,
      "name": "Rock_Ice"
    },
    {
      "x": -21,
      "y": 17,
      "z": -5,
      "name": "Rock_Ice"
    },
    {
      "x": -21,
      "y": 18,
      "z": -5,
      "name": "Rock_Ice"
    },
    {
      "x": -21,
      "y": 19,
      "z": -5,
      "name": "Rock_Ice"
    },
    {
      "x": -21,
      "y": 20,
      "z": -5,
      "name": "Rock_Ice_Permafrost"
    },
    {
      "x": -21,
      "y": 21,
      "z": -5,
      "name": "Rock_Ice_Permafrost"
    },
    {
      "x": -21,
      "y": 0,
      "z": -4,
      "name": "Rock_Ice_Permafrost"
    },
    {
      "x": -21,
      "y": 1,
      "z": -4,
      "name": "Rock_Ice_Permafrost"
    },
    {
      "x": -21,
      "y": 2,
      "z": -4,
      "name": "Rock_Ice_Permafrost"
    },
    {
      "x": -21,
      "y": 3,
      "z": -4,
      "name": "Rock_Ice_Permafrost"
    },
    {
      "x": -21,
      "y": 4,
      "z": -4,
      "name": "Rock_Ice_Permafrost"
    },
    {
      "x": -21,
      "y": 5,
      "z": -4,
      "name": "Rock_Ice_Permafrost"
    },
    {
      "x": -21,
      "y": 6,
      "z": -4,
      "name": "Rock_Ice_Permafrost"
    },
    {
      "x": -21,
      "y": 7,
      "z": -4,
      "name": "Rock_Ice_Permafrost"
    },
    {
      "x": -21,
      "y": 8,
      "z": -4,
      "name": "Rock_Ice"
    },
    {
      "x": -21,
      "y": 9,
      "z": -4,
      "name": "Rock_Ice"
    },
    {
      "x": -21,
      "y": 10,
      "z": -4,
      "name": "Rock_Ice"
    },
    {
      "x": -21,
      "y": 11,
      "z": -4,
      "name": "Rock_Ice"
    },
    {
      "x": -21,
      "y": 12,
      "z": -4,
      "name": "Rock_Ice"
    },
    {
      "x": -21,
      "y": 13,
      "z": -4,
      "name": "Rock_Ice"
    },
    {
      "x": -21,
      "y": 14,
      "z": -4,
      "name": "Rock_Ice"
    },
    {
      "x": -21,
      "y": 15,
      "z": -4,
      "name": "Rock_Ice"
    },
    {
      "x": -21,
      "y": 16,
      "z": -4,
      "name": "Rock_Ice"
    },
    {
      "x": -21,
      "y": 17,
      "z": -4,
      "name": "Rock_Ice"
    },
    {
      "x": -21,
      "y": 18,
      "z": -4,
      "name": "Rock_Ice"
    },
    {
      "x": -21,
      "y": 19,
      "z": -4,
      "name": "Rock_Ice"
    },
    {
      "x": -21,
      "y": 20,
      "z": -4,
      "name": "Rock_Ice"
    },
    {
      "x": -21,
      "y": 21,
      "z": -4,
      "name": "Rock_Ice"
    },
    {
      "x": -21,
      "y": 22,
      "z": -4,
      "name": "Rock_Ice"
    },
    {
      "x": -21,
      "y": 23,
      "z": -4,
      "name": "Soil_Snow"
    },
    {
      "x": -21,
      "y": 0,
      "z": -3,
      "name": "Rock_Ice_Permafrost"
    },
    {
      "x": -21,
      "y": 1,
      "z": -3,
      "name": "Rock_Ice_Permafrost"
    },
    {
      "x": -21,
      "y": 2,
      "z": -3,
      "name": "Rock_Ice_Permafrost"
    },
    {
      "x": -21,
      "y": 3,
      "z": -3,
      "name": "Rock_Ice_Permafrost"
    },
    {
      "x": -21,
      "y": 4,
      "z": -3,
      "name": "Rock_Ice_Permafrost"
    },
    {
      "x": -21,
      "y": 5,
      "z": -3,
      "name": "Rock_Ice_Permafrost"
    },
    {
      "x": -21,
      "y": 6,
      "z": -3,
      "name": "Rock_Ice_Permafrost"
    },
    {
      "x": -21,
      "y": 7,
      "z": -3,
      "name": "Rock_Ice_Permafrost"
    },
    {
      "x": -21,
      "y": 8,
      "z": -3,
      "name": "Rock_Ice"
    },
    {
      "x": -21,
      "y": 9,
      "z": -3,
      "name": "Rock_Ice"
    },
    {
      "x": -21,
      "y": 10,
      "z": -3,
      "name": "Rock_Ice"
    },
    {
      "x": -21,
      "y": 11,
      "z": -3,
      "name": "Rock_Ice"
    },
    {
      "x": -21,
      "y": 12,
      "z": -3,
      "name": "Rock_Ice"
    },
    {
      "x": -21,
      "y": 13,
      "z": -3,
      "name": "Rock_Ice"
    },
    {
      "x": -21,
      "y": 14,
      "z": -3,
      "name": "Rock_Ice"
    },
    {
      "x": -21,
      "y": 15,
      "z": -3,
      "name": "Rock_Ice"
    },
    {
      "x": -21,
      "y": 16,
      "z": -3,
      "name": "Rock_Ice"
    },
    {
      "x": -21,
      "y": 17,
      "z": -3,
      "name": "Rock_Ice"
    },
    {
      "x": -21,
      "y": 18,
      "z": -3,
      "name": "Rock_Ice"
    },
    {
      "x": -21,
      "y": 19,
      "z": -3,
      "name": "Rock_Ice"
    },
    {
      "x": -21,
      "y": 20,
      "z": -3,
      "name": "Rock_Ice"
    },
    {
      "x": -21,
      "y": 21,
      "z": -3,
      "name": "Rock_Ice"
    },
    {
      "x": -21,
      "y": 22,
      "z": -3,
      "name": "Rock_Ice_Permafrost"
    },
    {
      "x": -21,
      "y": 23,
      "z": -3,
      "name": "Rock_Ice"
    },
    {
      "x": -21,
      "y": 24,
      "z": -3,
      "name": "Rock_Ice"
    },
    {
      "x": -21,
      "y": 25,
      "z": -3,
      "name": "Soil_Snow"
    },
    {
      "x": -21,
      "y": 0,
      "z": -2,
      "name": "Rock_Ice_Permafrost"
    },
    {
      "x": -21,
      "y": 1,
      "z": -2,
      "name": "Rock_Ice_Permafrost"
    },
    {
      "x": -21,
      "y": 2,
      "z": -2,
      "name": "Rock_Ice_Permafrost"
    },
    {
      "x": -21,
      "y": 3,
      "z": -2,
      "name": "Rock_Ice_Permafrost"
    },
    {
      "x": -21,
      "y": 4,
      "z": -2,
      "name": "Rock_Ice_Permafrost"
    },
    {
      "x": -21,
      "y": 5,
      "z": -2,
      "name": "Rock_Ice_Permafrost"
    },
    {
      "x": -21,
      "y": 6,
      "z": -2,
      "name": "Rock_Ice_Permafrost"
    },
    {
      "x": -21,
      "y": 7,
      "z": -2,
      "name": "Rock_Ice"
    },
    {
      "x": -21,
      "y": 8,
      "z": -2,
      "name": "Rock_Ice"
    },
    {
      "x": -21,
      "y": 9,
      "z": -2,
      "name": "Rock_Ice"
    },
    {
      "x": -21,
      "y": 10,
      "z": -2,
      "name": "Rock_Ice"
    },
    {
      "x": -21,
      "y": 11,
      "z": -2,
      "name": "Rock_Ice"
    },
    {
      "x": -21,
      "y": 12,
      "z": -2,
      "name": "Rock_Ice"
    },
    {
      "x": -21,
      "y": 13,
      "z": -2,
      "name": "Rock_Ice"
    },
    {
      "x": -21,
      "y": 14,
      "z": -2,
      "name": "Rock_Ice"
    },
    {
      "x": -21,
      "y": 15,
      "z": -2,
      "name": "Rock_Ice"
    },
    {
      "x": -21,
      "y": 16,
      "z": -2,
      "name": "Rock_Ice"
    },
    {
      "x": -21,
      "y": 17,
      "z": -2,
      "name": "Rock_Ice"
    },
    {
      "x": -21,
      "y": 18,
      "z": -2,
      "name": "Rock_Ice"
    },
    {
      "x": -21,
      "y": 19,
      "z": -2,
      "name": "Rock_Ice"
    },
    {
      "x": -21,
      "y": 20,
      "z": -2,
      "name": "Rock_Ice"
    },
    {
      "x": -21,
      "y": 21,
      "z": -2,
      "name": "Rock_Ice"
    },
    {
      "x": -21,
      "y": 22,
      "z": -2,
      "name": "Rock_Ice"
    },
    {
      "x": -21,
      "y": 23,
      "z": -2,
      "name": "Rock_Ice"
    },
    {
      "x": -21,
      "y": 24,
      "z": -2,
      "name": "Rock_Ice"
    },
    {
      "x": -21,
      "y": 25,
      "z": -2,
      "name": "Rock_Ice"
    },
    {
      "x": -21,
      "y": 26,
      "z": -2,
      "name": "Rock_Ice_Permafrost"
    },
    {
      "x": -21,
      "y": 27,
      "z": -2,
      "name": "Soil_Snow"
    },
    {
      "x": -21,
      "y": 0,
      "z": -1,
      "name": "Rock_Ice_Permafrost"
    },
    {
      "x": -21,
      "y": 1,
      "z": -1,
      "name": "Rock_Ice_Permafrost"
    },
    {
      "x": -21,
      "y": 2,
      "z": -1,
      "name": "Rock_Ice_Permafrost"
    },
    {
      "x": -21,
      "y": 3,
      "z": -1,
      "name": "Rock_Ice_Permafrost"
    },
    {
      "x": -21,
      "y": 4,
      "z": -1,
      "name": "Rock_Ice_Permafrost"
    },
    {
      "x": -21,
      "y": 5,
      "z": -1,
      "name": "Rock_Ice"
    },
    {
      "x": -21,
      "y": 6,
      "z": -1,
      "name": "Rock_Ice_Permafrost"
    },
    {
      "x": -21,
      "y": 7,
      "z": -1,
      "name": "Rock_Ice_Permafrost"
    },
    {
      "x": -21,
      "y": 8,
      "z": -1,
      "name": "Rock_Ice"
    },
    {
      "x": -21,
      "y": 9,
      "z": -1,
      "name": "Rock_Ice"
    },
    {
      "x": -21,
      "y": 10,
      "z": -1,
      "name": "Rock_Ice"
    },
    {
      "x": -21,
      "y": 11,
      "z": -1,
      "name": "Rock_Ice"
    },
    {
      "x": -21,
      "y": 12,
      "z": -1,
      "name": "Rock_Ice"
    },
    {
      "x": -21,
      "y": 13,
      "z": -1,
      "name": "Rock_Ice"
    },
    {
      "x": -21,
      "y": 14,
      "z": -1,
      "name": "Rock_Ice"
    },
    {
      "x": -21,
      "y": 15,
      "z": -1,
      "name": "Rock_Ice"
    },
    {
      "x": -21,
      "y": 16,
      "z": -1,
      "name": "Rock_Ice"
    },
    {
      "x": -21,
      "y": 17,
      "z": -1,
      "name": "Rock_Ice"
    },
    {
      "x": -21,
      "y": 18,
      "z": -1,
      "name": "Rock_Ice"
    },
    {
      "x": -21,
      "y": 19,
      "z": -1,
      "name": "Rock_Ice"
    },
    {
      "x": -21,
      "y": 20,
      "z": -1,
      "name": "Rock_Ice"
    },
    {
      "x": -21,
      "y": 21,
      "z": -1,
      "name": "Rock_Ice"
    },
    {
      "x": -21,
      "y": 22,
      "z": -1,
      "name": "Rock_Ice"
    },
    {
      "x": -21,
      "y": 23,
      "z": -1,
      "name": "Rock_Ice"
    },
    {
      "x": -21,
      "y": 24,
      "z": -1,
      "name": "Rock_Ice"
    },
    {
      "x": -21,
      "y": 25,
      "z": -1,
      "name": "Rock_Ice"
    },
    {
      "x": -21,
      "y": 26,
      "z": -1,
      "name": "Rock_Ice"
    },
    {
      "x": -21,
      "y": 27,
      "z": -1,
      "name": "Rock_Ice_Permafrost"
    },
    {
      "x": -21,
      "y": 28,
      "z": -1,
      "name": "Soil_Snow"
    },
    {
      "x": -21,
      "y": 0,
      "z": 0,
      "name": "Rock_Ice_Permafrost"
    },
    {
      "x": -21,
      "y": 1,
      "z": 0,
      "name": "Rock_Ice_Permafrost"
    },
    {
      "x": -21,
      "y": 2,
      "z": 0,
      "name": "Rock_Ice_Permafrost"
    },
    {
      "x": -21,
      "y": 3,
      "z": 0,
      "name": "Rock_Ice_Permafrost"
    },
    {
      "x": -21,
      "y": 4,
      "z": 0,
      "name": "Rock_Ice"
    },
    {
      "x": -21,
      "y": 5,
      "z": 0,
      "name": "Rock_Ice_Permafrost"
    },
    {
      "x": -21,
      "y": 6,
      "z": 0,
      "name": "Rock_Ice_Permafrost"
    },
    {
      "x": -21,
      "y": 7,
      "z": 0,
      "name": "Rock_Ice"
    },
    {
      "x": -21,
      "y": 8,
      "z": 0,
      "name": "Rock_Ice"
    },
    {
      "x": -21,
      "y": 9,
      "z": 0,
      "name": "Rock_Ice"
    },
    {
      "x": -21,
      "y": 10,
      "z": 0,
      "name": "Rock_Ice"
    },
    {
      "x": -21,
      "y": 11,
      "z": 0,
      "name": "Rock_Ice"
    },
    {
      "x": -21,
      "y": 12,
      "z": 0,
      "name": "Rock_Ice"
    },
    {
      "x": -21,
      "y": 13,
      "z": 0,
      "name": "Rock_Ice"
    },
    {
      "x": -21,
      "y": 14,
      "z": 0,
      "name": "Rock_Ice"
    },
    {
      "x": -21,
      "y": 15,
      "z": 0,
      "name": "Rock_Ice"
    },
    {
      "x": -21,
      "y": 16,
      "z": 0,
      "name": "Rock_Ice"
    },
    {
      "x": -21,
      "y": 17,
      "z": 0,
      "name": "Rock_Ice"
    },
    {
      "x": -21,
      "y": 18,
      "z": 0,
      "name": "Rock_Ice"
    },
    {
      "x": -21,
      "y": 19,
      "z": 0,
      "name": "Rock_Ice"
    },
    {
      "x": -21,
      "y": 20,
      "z": 0,
      "name": "Rock_Ice"
    },
    {
      "x": -21,
      "y": 21,
      "z": 0,
      "name": "Rock_Ice"
    },
    {
      "x": -21,
      "y": 22,
      "z": 0,
      "name": "Rock_Ice"
    },
    {
      "x": -21,
      "y": 23,
      "z": 0,
      "name": "Rock_Ice"
    },
    {
      "x": -21,
      "y": 24,
      "z": 0,
      "name": "Rock_Ice"
    },
    {
      "x": -21,
      "y": 25,
      "z": 0,
      "name": "Soil_Snow"
    },
    {
      "x": -21,
      "y": 2,
      "z": 1,
      "name": "Rock_Ice_Permafrost"
    },
    {
      "x": -21,
      "y": 3,
      "z": 1,
      "name": "Rock_Ice_Permafrost"
    },
    {
      "x": -21,
      "y": 4,
      "z": 1,
      "name": "Rock_Ice_Permafrost"
    },
    {
      "x": -21,
      "y": 5,
      "z": 1,
      "name": "Rock_Ice"
    },
    {
      "x": -21,
      "y": 6,
      "z": 1,
      "name": "Rock_Ice_Permafrost"
    },
    {
      "x": -21,
      "y": 7,
      "z": 1,
      "name": "Rock_Ice"
    },
    {
      "x": -21,
      "y": 8,
      "z": 1,
      "name": "Rock_Ice"
    },
    {
      "x": -21,
      "y": 9,
      "z": 1,
      "name": "Rock_Ice"
    },
    {
      "x": -21,
      "y": 10,
      "z": 1,
      "name": "Rock_Ice"
    },
    {
      "x": -21,
      "y": 11,
      "z": 1,
      "name": "Rock_Ice"
    },
    {
      "x": -21,
      "y": 12,
      "z": 1,
      "name": "Rock_Ice"
    },
    {
      "x": -21,
      "y": 13,
      "z": 1,
      "name": "Rock_Ice"
    },
    {
      "x": -21,
      "y": 14,
      "z": 1,
      "name": "Rock_Ice"
    },
    {
      "x": -21,
      "y": 15,
      "z": 1,
      "name": "Rock_Ice"
    },
    {
      "x": -21,
      "y": 16,
      "z": 1,
      "name": "Rock_Ice"
    },
    {
      "x": -21,
      "y": 17,
      "z": 1,
      "name": "Rock_Ice"
    },
    {
      "x": -21,
      "y": 18,
      "z": 1,
      "name": "Rock_Ice"
    },
    {
      "x": -21,
      "y": 19,
      "z": 1,
      "name": "Rock_Ice"
    },
    {
      "x": -21,
      "y": 20,
      "z": 1,
      "name": "Soil_Snow"
    },
    {
      "x": -21,
      "y": 2,
      "z": 2,
      "name": "Rock_Ice_Permafrost"
    },
    {
      "x": -21,
      "y": 3,
      "z": 2,
      "name": "Rock_Ice_Permafrost"
    },
    {
      "x": -21,
      "y": 4,
      "z": 2,
      "name": "Rock_Ice_Permafrost"
    },
    {
      "x": -21,
      "y": 5,
      "z": 2,
      "name": "Rock_Ice_Permafrost"
    },
    {
      "x": -21,
      "y": 6,
      "z": 2,
      "name": "Rock_Ice"
    },
    {
      "x": -21,
      "y": 7,
      "z": 2,
      "name": "Rock_Ice"
    },
    {
      "x": -21,
      "y": 8,
      "z": 2,
      "name": "Rock_Ice"
    },
    {
      "x": -21,
      "y": 9,
      "z": 2,
      "name": "Rock_Ice"
    },
    {
      "x": -21,
      "y": 10,
      "z": 2,
      "name": "Rock_Ice"
    },
    {
      "x": -21,
      "y": 11,
      "z": 2,
      "name": "Rock_Ice"
    },
    {
      "x": -21,
      "y": 12,
      "z": 2,
      "name": "Rock_Ice"
    },
    {
      "x": -21,
      "y": 13,
      "z": 2,
      "name": "Rock_Ice"
    },
    {
      "x": -21,
      "y": 14,
      "z": 2,
      "name": "Rock_Ice"
    },
    {
      "x": -21,
      "y": 15,
      "z": 2,
      "name": "Rock_Ice"
    },
    {
      "x": -21,
      "y": 16,
      "z": 2,
      "name": "Rock_Ice"
    },
    {
      "x": -21,
      "y": 17,
      "z": 2,
      "name": "Rock_Ice"
    },
    {
      "x": -21,
      "y": 18,
      "z": 2,
      "name": "Soil_Snow"
    },
    {
      "x": -21,
      "y": 2,
      "z": 3,
      "name": "Rock_Ice_Permafrost"
    },
    {
      "x": -21,
      "y": 3,
      "z": 3,
      "name": "Rock_Ice_Permafrost"
    },
    {
      "x": -21,
      "y": 4,
      "z": 3,
      "name": "Rock_Ice"
    },
    {
      "x": -21,
      "y": 5,
      "z": 3,
      "name": "Rock_Ice_Permafrost"
    },
    {
      "x": -21,
      "y": 6,
      "z": 3,
      "name": "Rock_Ice"
    },
    {
      "x": -21,
      "y": 7,
      "z": 3,
      "name": "Rock_Ice"
    },
    {
      "x": -21,
      "y": 8,
      "z": 3,
      "name": "Rock_Ice"
    },
    {
      "x": -21,
      "y": 9,
      "z": 3,
      "name": "Rock_Ice"
    },
    {
      "x": -21,
      "y": 10,
      "z": 3,
      "name": "Rock_Ice"
    },
    {
      "x": -21,
      "y": 11,
      "z": 3,
      "name": "Rock_Ice"
    },
    {
      "x": -21,
      "y": 12,
      "z": 3,
      "name": "Rock_Ice"
    },
    {
      "x": -21,
      "y": 13,
      "z": 3,
      "name": "Rock_Ice"
    },
    {
      "x": -21,
      "y": 14,
      "z": 3,
      "name": "Rock_Ice"
    },
    {
      "x": -21,
      "y": 15,
      "z": 3,
      "name": "Rock_Ice"
    },
    {
      "x": -21,
      "y": 16,
      "z": 3,
      "name": "Soil_Snow"
    },
    {
      "x": -21,
      "y": 2,
      "z": 4,
      "name": "Rock_Ice_Permafrost"
    },
    {
      "x": -21,
      "y": 3,
      "z": 4,
      "name": "Rock_Ice"
    },
    {
      "x": -21,
      "y": 4,
      "z": 4,
      "name": "Rock_Ice"
    },
    {
      "x": -21,
      "y": 5,
      "z": 4,
      "name": "Rock_Ice"
    },
    {
      "x": -21,
      "y": 6,
      "z": 4,
      "name": "Rock_Ice"
    },
    {
      "x": -21,
      "y": 7,
      "z": 4,
      "name": "Rock_Ice"
    },
    {
      "x": -21,
      "y": 8,
      "z": 4,
      "name": "Rock_Ice"
    },
    {
      "x": -21,
      "y": 9,
      "z": 4,
      "name": "Rock_Ice"
    },
    {
      "x": -21,
      "y": 10,
      "z": 4,
      "name": "Rock_Ice"
    },
    {
      "x": -21,
      "y": 11,
      "z": 4,
      "name": "Rock_Ice"
    },
    {
      "x": -21,
      "y": 12,
      "z": 4,
      "name": "Rock_Ice"
    },
    {
      "x": -21,
      "y": 13,
      "z": 4,
      "name": "Rock_Ice"
    },
    {
      "x": -21,
      "y": 14,
      "z": 4,
      "name": "Soil_Snow"
    },
    {
      "x": -21,
      "y": 2,
      "z": 5,
      "name": "Rock_Ice_Permafrost"
    },
    {
      "x": -21,
      "y": 3,
      "z": 5,
      "name": "Rock_Ice_Permafrost"
    },
    {
      "x": -21,
      "y": 4,
      "z": 5,
      "name": "Rock_Ice"
    },
    {
      "x": -21,
      "y": 5,
      "z": 5,
      "name": "Rock_Ice"
    },
    {
      "x": -21,
      "y": 6,
      "z": 5,
      "name": "Rock_Ice"
    },
    {
      "x": -21,
      "y": 7,
      "z": 5,
      "name": "Rock_Ice"
    },
    {
      "x": -21,
      "y": 8,
      "z": 5,
      "name": "Rock_Ice"
    },
    {
      "x": -21,
      "y": 9,
      "z": 5,
      "name": "Rock_Ice"
    },
    {
      "x": -21,
      "y": 10,
      "z": 5,
      "name": "Rock_Ice"
    },
    {
      "x": -21,
      "y": 11,
      "z": 5,
      "name": "Rock_Ice"
    },
    {
      "x": -21,
      "y": 12,
      "z": 5,
      "name": "Rock_Ice"
    },
    {
      "x": -21,
      "y": 13,
      "z": 5,
      "name": "Soil_Snow"
    },
    {
      "x": -21,
      "y": 2,
      "z": 6,
      "name": "Rock_Ice"
    },
    {
      "x": -21,
      "y": 3,
      "z": 6,
      "name": "Rock_Ice_Permafrost"
    },
    {
      "x": -21,
      "y": 4,
      "z": 6,
      "name": "Rock_Ice"
    },
    {
      "x": -21,
      "y": 5,
      "z": 6,
      "name": "Rock_Ice"
    },
    {
      "x": -21,
      "y": 6,
      "z": 6,
      "name": "Rock_Ice"
    },
    {
      "x": -21,
      "y": 7,
      "z": 6,
      "name": "Rock_Ice"
    },
    {
      "x": -21,
      "y": 8,
      "z": 6,
      "name": "Rock_Ice"
    },
    {
      "x": -21,
      "y": 9,
      "z": 6,
      "name": "Rock_Ice"
    },
    {
      "x": -21,
      "y": 10,
      "z": 6,
      "name": "Rock_Ice"
    },
    {
      "x": -21,
      "y": 11,
      "z": 6,
      "name": "Rock_Ice"
    },
    {
      "x": -21,
      "y": 12,
      "z": 6,
      "name": "Soil_Snow"
    },
    {
      "x": -21,
      "y": 3,
      "z": 7,
      "name": "Rock_Ice"
    },
    {
      "x": -21,
      "y": 4,
      "z": 7,
      "name": "Rock_Ice_Permafrost"
    },
    {
      "x": -21,
      "y": 5,
      "z": 7,
      "name": "Rock_Ice"
    },
    {
      "x": -21,
      "y": 6,
      "z": 7,
      "name": "Rock_Ice"
    },
    {
      "x": -21,
      "y": 7,
      "z": 7,
      "name": "Rock_Ice"
    },
    {
      "x": -21,
      "y": 8,
      "z": 7,
      "name": "Rock_Ice"
    },
    {
      "x": -21,
      "y": 9,
      "z": 7,
      "name": "Rock_Ice"
    },
    {
      "x": -21,
      "y": 10,
      "z": 7,
      "name": "Rock_Ice"
    },
    {
      "x": -21,
      "y": 11,
      "z": 7,
      "name": "Soil_Snow"
    },
    {
      "x": -21,
      "y": 4,
      "z": 8,
      "name": "Rock_Ice"
    },
    {
      "x": -21,
      "y": 5,
      "z": 8,
      "name": "Rock_Ice"
    },
    {
      "x": -21,
      "y": 6,
      "z": 8,
      "name": "Rock_Ice"
    },
    {
      "x": -21,
      "y": 7,
      "z": 8,
      "name": "Rock_Ice"
    },
    {
      "x": -21,
      "y": 8,
      "z": 8,
      "name": "Rock_Ice"
    },
    {
      "x": -21,
      "y": 9,
      "z": 8,
      "name": "Rock_Ice"
    },
    {
      "x": -21,
      "y": 10,
      "z": 8,
      "name": "Rock_Ice"
    },
    {
      "x": -21,
      "y": 11,
      "z": 8,
      "name": "Soil_Snow"
    },
    {
      "x": -21,
      "y": 5,
      "z": 9,
      "name": "Rock_Ice"
    },
    {
      "x": -21,
      "y": 6,
      "z": 9,
      "name": "Rock_Ice"
    },
    {
      "x": -21,
      "y": 7,
      "z": 9,
      "name": "Rock_Ice"
    },
    {
      "x": -21,
      "y": 8,
      "z": 9,
      "name": "Rock_Ice"
    },
    {
      "x": -21,
      "y": 9,
      "z": 9,
      "name": "Rock_Ice"
    },
    {
      "x": -21,
      "y": 10,
      "z": 9,
      "name": "Rock_Ice"
    },
    {
      "x": -21,
      "y": 11,
      "z": 9,
      "name": "Soil_Snow"
    },
    {
      "x": -21,
      "y": 7,
      "z": 10,
      "name": "Rock_Ice"
    },
    {
      "x": -21,
      "y": 8,
      "z": 10,
      "name": "Rock_Ice"
    },
    {
      "x": -21,
      "y": 9,
      "z": 10,
      "name": "Rock_Ice"
    },
    {
      "x": -21,
      "y": 10,
      "z": 10,
      "name": "Rock_Ice"
    },
    {
      "x": -21,
      "y": 11,
      "z": 10,
      "name": "Soil_Snow"
    },
    {
      "x": -21,
      "y": 8,
      "z": 11,
      "name": "Rock_Ice"
    },
    {
      "x": -21,
      "y": 9,
      "z": 11,
      "name": "Rock_Ice"
    },
    {
      "x": -21,
      "y": 10,
      "z": 11,
      "name": "Soil_Snow"
    },
    {
      "x": -21,
      "y": 9,
      "z": 12,
      "name": "Rock_Ice"
    },
    {
      "x": -21,
      "y": 10,
      "z": 12,
      "name": "Soil_Snow"
    },
    {
      "x": -20,
      "y": 5,
      "z": -18,
      "name": "Rock_Ice"
    },
    {
      "x": -20,
      "y": 6,
      "z": -18,
      "name": "Rock_Ice"
    },
    {
      "x": -20,
      "y": 7,
      "z": -18,
      "name": "Rock_Ice"
    },
    {
      "x": -20,
      "y": 8,
      "z": -18,
      "name": "Rock_Ice"
    },
    {
      "x": -20,
      "y": 9,
      "z": -18,
      "name": "Rock_Ice"
    },
    {
      "x": -20,
      "y": 10,
      "z": -18,
      "name": "Rock_Ice_Permafrost"
    },
    {
      "x": -20,
      "y": 5,
      "z": -17,
      "name": "Rock_Ice"
    },
    {
      "x": -20,
      "y": 6,
      "z": -17,
      "name": "Rock_Ice"
    },
    {
      "x": -20,
      "y": 7,
      "z": -17,
      "name": "Rock_Ice"
    },
    {
      "x": -20,
      "y": 8,
      "z": -17,
      "name": "Rock_Ice_Permafrost"
    },
    {
      "x": -20,
      "y": 9,
      "z": -17,
      "name": "Rock_Ice_Permafrost"
    },
    {
      "x": -20,
      "y": 10,
      "z": -17,
      "name": "Rock_Ice_Permafrost"
    },
    {
      "x": -20,
      "y": 11,
      "z": -17,
      "name": "Rock_Ice"
    },
    {
      "x": -20,
      "y": 12,
      "z": -17,
      "name": "Soil_Snow"
    },
    {
      "x": -20,
      "y": 5,
      "z": -16,
      "name": "Rock_Ice"
    },
    {
      "x": -20,
      "y": 6,
      "z": -16,
      "name": "Rock_Ice"
    },
    {
      "x": -20,
      "y": 7,
      "z": -16,
      "name": "Rock_Ice_Permafrost"
    },
    {
      "x": -20,
      "y": 8,
      "z": -16,
      "name": "Rock_Ice_Permafrost"
    },
    {
      "x": -20,
      "y": 9,
      "z": -16,
      "name": "Rock_Ice_Permafrost"
    },
    {
      "x": -20,
      "y": 10,
      "z": -16,
      "name": "Rock_Ice_Permafrost"
    },
    {
      "x": -20,
      "y": 11,
      "z": -16,
      "name": "Rock_Ice_Permafrost"
    },
    {
      "x": -20,
      "y": 12,
      "z": -16,
      "name": "Rock_Ice"
    },
    {
      "x": -20,
      "y": 13,
      "z": -16,
      "name": "Soil_Snow"
    },
    {
      "x": -20,
      "y": 5,
      "z": -15,
      "name": "Rock_Ice_Permafrost"
    },
    {
      "x": -20,
      "y": 6,
      "z": -15,
      "name": "Rock_Ice_Permafrost"
    },
    {
      "x": -20,
      "y": 7,
      "z": -15,
      "name": "Rock_Ice_Permafrost"
    },
    {
      "x": -20,
      "y": 8,
      "z": -15,
      "name": "Rock_Ice_Permafrost"
    },
    {
      "x": -20,
      "y": 9,
      "z": -15,
      "name": "Rock_Ice_Permafrost"
    },
    {
      "x": -20,
      "y": 10,
      "z": -15,
      "name": "Rock_Ice_Permafrost"
    },
    {
      "x": -20,
      "y": 11,
      "z": -15,
      "name": "Rock_Ice_Permafrost"
    },
    {
      "x": -20,
      "y": 12,
      "z": -15,
      "name": "Rock_Ice_Permafrost"
    },
    {
      "x": -20,
      "y": 13,
      "z": -15,
      "name": "Rock_Ice"
    },
    {
      "x": -20,
      "y": 14,
      "z": -15,
      "name": "Soil_Snow"
    },
    {
      "x": -20,
      "y": 4,
      "z": -14,
      "name": "Rock_Ice"
    },
    {
      "x": -20,
      "y": 5,
      "z": -14,
      "name": "Rock_Ice_Permafrost"
    },
    {
      "x": -20,
      "y": 6,
      "z": -14,
      "name": "Rock_Ice"
    },
    {
      "x": -20,
      "y": 7,
      "z": -14,
      "name": "Rock_Ice_Permafrost"
    },
    {
      "x": -20,
      "y": 8,
      "z": -14,
      "name": "Rock_Ice_Permafrost"
    },
    {
      "x": -20,
      "y": 9,
      "z": -14,
      "name": "Rock_Ice_Permafrost"
    },
    {
      "x": -20,
      "y": 10,
      "z": -14,
      "name": "Rock_Ice_Permafrost"
    },
    {
      "x": -20,
      "y": 11,
      "z": -14,
      "name": "Rock_Ice_Permafrost"
    },
    {
      "x": -20,
      "y": 12,
      "z": -14,
      "name": "Rock_Ice_Permafrost"
    },
    {
      "x": -20,
      "y": 13,
      "z": -14,
      "name": "Rock_Ice"
    },
    {
      "x": -20,
      "y": 14,
      "z": -14,
      "name": "Soil_Snow"
    },
    {
      "x": -20,
      "y": 2,
      "z": -13,
      "name": "Rock_Ice"
    },
    {
      "x": -20,
      "y": 3,
      "z": -13,
      "name": "Rock_Ice_Permafrost"
    },
    {
      "x": -20,
      "y": 4,
      "z": -13,
      "name": "Rock_Ice_Permafrost"
    },
    {
      "x": -20,
      "y": 5,
      "z": -13,
      "name": "Rock_Ice_Permafrost"
    },
    {
      "x": -20,
      "y": 6,
      "z": -13,
      "name": "Rock_Ice_Permafrost"
    },
    {
      "x": -20,
      "y": 7,
      "z": -13,
      "name": "Rock_Ice_Permafrost"
    },
    {
      "x": -20,
      "y": 8,
      "z": -13,
      "name": "Rock_Ice_Permafrost"
    },
    {
      "x": -20,
      "y": 9,
      "z": -13,
      "name": "Rock_Ice_Permafrost"
    },
    {
      "x": -20,
      "y": 10,
      "z": -13,
      "name": "Rock_Ice_Permafrost"
    },
    {
      "x": -20,
      "y": 11,
      "z": -13,
      "name": "Rock_Ice_Permafrost"
    },
    {
      "x": -20,
      "y": 12,
      "z": -13,
      "name": "Rock_Ice_Permafrost"
    },
    {
      "x": -20,
      "y": 13,
      "z": -13,
      "name": "Rock_Ice_Permafrost"
    },
    {
      "x": -20,
      "y": 14,
      "z": -13,
      "name": "Rock_Ice"
    },
    {
      "x": -20,
      "y": 15,
      "z": -13,
      "name": "Soil_Snow"
    },
    {
      "x": -20,
      "y": 1,
      "z": -12,
      "name": "Rock_Ice"
    },
    {
      "x": -20,
      "y": 2,
      "z": -12,
      "name": "Rock_Ice"
    },
    {
      "x": -20,
      "y": 3,
      "z": -12,
      "name": "Rock_Ice"
    },
    {
      "x": -20,
      "y": 4,
      "z": -12,
      "name": "Rock_Ice_Permafrost"
    },
    {
      "x": -20,
      "y": 5,
      "z": -12,
      "name": "Rock_Ice_Permafrost"
    },
    {
      "x": -20,
      "y": 6,
      "z": -12,
      "name": "Rock_Ice_Permafrost"
    },
    {
      "x": -20,
      "y": 7,
      "z": -12,
      "name": "Rock_Ice_Permafrost"
    },
    {
      "x": -20,
      "y": 8,
      "z": -12,
      "name": "Rock_Ice_Permafrost"
    },
    {
      "x": -20,
      "y": 9,
      "z": -12,
      "name": "Rock_Ice_Permafrost"
    },
    {
      "x": -20,
      "y": 10,
      "z": -12,
      "name": "Rock_Ice_Permafrost"
    },
    {
      "x": -20,
      "y": 11,
      "z": -12,
      "name": "Rock_Ice_Permafrost"
    },
    {
      "x": -20,
      "y": 12,
      "z": -12,
      "name": "Rock_Ice_Permafrost"
    },
    {
      "x": -20,
      "y": 13,
      "z": -12,
      "name": "Rock_Ice_Permafrost"
    },
    {
