{
  "version": 8,
  "blockIdVersion": 11,
  "anchorX": -1,
  "anchorY": 12,
  "anchorZ": 2,
  "blocks": [
    {
      "x": -24,
      "y": 6,
      "z": 5,
      "name": "Soil_Snow"
    },
    {
      "x": -24,
      "y": 6,
      "z": 6,
      "name": "Rock_Ice"
    },
    {
      "x": -24,
      "y": 7,
      "z": 6,
      "name": "Rock_Ice"
    },
    {
      "x": -24,
      "y": 8,
      "z": 6,
      "name": "Rock_Ice"
    },
    {
      "x": -24,
      "y": 9,
      "z": 6,
      "name": "Rock_Ice"
    },
    {
      "x": -24,
      "y": 6,
      "z": 7,
      "name": "Rock_Ice"
    },
    {
      "x": -24,
      "y": 7,
      "z": 7,
      "name": "Rock_Ice"
    },
    {
      "x": -24,
      "y": 8,
      "z": 7,
      "name": "Rock_Ice"
    },
    {
      "x": -24,
      "y": 9,
      "z": 7,
      "name": "Rock_Ice"
    },
    {
      "x": -24,
      "y": 10,
      "z": 7,
      "name": "Soil_Snow"
    },
    {
      "x": -24,
      "y": 6,
      "z": 8,
      "name": "Rock_Ice"
    },
    {
      "x": -24,
      "y": 7,
      "z": 8,
      "name": "Rock_Ice"
    },
    {
      "x": -24,
      "y": 8,
      "z": 8,
      "name": "Rock_Ice"
    },
    {
      "x": -24,
      "y": 9,
      "z": 8,
      "name": "Rock_Ice"
    },
    {
      "x": -24,
      "y": 10,
      "z": 8,
      "name": "Soil_Snow"
    },
    {
      "x": -24,
      "y": 7,
      "z": 9,
      "name": "Rock_Ice"
    },
    {
      "x": -24,
      "y": 8,
      "z": 9,
      "name": "Rock_Ice"
    },
    {
      "x": -24,
      "y": 9,
      "z": 9,
      "name": "Rock_Ice"
    },
    {
      "x": -24,
      "y": 10,
      "z": 9,
      "name": "Soil_Snow"
    },
    {
      "x": -23,
      "y": 3,
      "z": 4,
      "name": "Rock_Ice"
    },
    {
      "x": -23,
      "y": 4,
      "z": 4,
      "name": "Rock_Ice"
    },
    {
      "x": -23,
      "y": 5,
      "z": 4,
      "name": "Rock_Ice"
    },
    {
      "x": -23,
      "y": 6,
      "z": 4,
      "name": "Rock_Ice"
    },
    {
      "x": -23,
      "y": 7,
      "z": 4,
      "name": "Rock_Ice"
    },
    {
      "x": -23,
      "y": 8,
      "z": 4,
      "name": "Rock_Ice"
    },
    {
      "x": -23,
      "y": 9,
      "z": 4,
      "name": "Rock_Ice"
    },
    {
      "x": -23,
      "y": 3,
      "z": 5,
      "name": "Rock_Ice"
    },
    {
      "x": -23,
      "y": 4,
      "z": 5,
      "name": "Rock_Ice"
    },
    {
      "x": -23,
      "y": 5,
      "z": 5,
      "name": "Rock_Ice"
    },
    {
      "x": -23,
      "y": 6,
      "z": 5,
      "name": "Rock_Ice"
    },
    {
      "x": -23,
      "y": 7,
      "z": 5,
      "name": "Rock_Ice"
    },
    {
      "x": -23,
      "y": 8,
      "z": 5,
      "name": "Rock_Ice"
    },
    {
      "x": -23,
      "y": 9,
      "z": 5,
      "name": "Rock_Ice"
    },
    {
      "x": -23,
      "y": 10,
      "z": 5,
      "name": "Rock_Ice"
    },
    {
      "x": -23,
      "y": 3,
      "z": 6,
      "name": "Rock_Ice"
    },
    {
      "x": -23,
      "y": 4,
      "z": 6,
      "name": "Rock_Ice"
    },
    {
      "x": -23,
      "y": 5,
      "z": 6,
      "name": "Rock_Ice"
    },
    {
      "x": -23,
      "y": 6,
      "z": 6,
      "name": "Rock_Ice"
    },
    {
      "x": -23,
      "y": 7,
      "z": 6,
      "name": "Rock_Ice"
    },
    {
      "x": -23,
      "y": 8,
      "z": 6,
      "name": "Rock_Ice"
    },
    {
      "x": -23,
      "y": 9,
      "z": 6,
      "name": "Rock_Ice"
    },
    {
      "x": -23,
      "y": 10,
      "z": 6,
      "name": "Rock_Ice"
    },
    {
      "x": -23,
      "y": 11,
      "z": 6,
      "name": "Soil_Snow"
    },
    {
      "x": -23,
      "y": 3,
      "z": 7,
      "name": "Rock_Ice"
    },
    {
      "x": -23,
      "y": 4,
      "z": 7,
      "name": "Rock_Ice"
    },
    {
      "x": -23,
      "y": 5,
      "z": 7,
      "name": "Rock_Ice"
    },
    {
      "x": -23,
      "y": 6,
      "z": 7,
      "name": "Rock_Ice"
    },
    {
      "x": -23,
      "y": 7,
      "z": 7,
      "name": "Rock_Ice"
    },
    {
      "x": -23,
      "y": 8,
      "z": 7,
      "name": "Rock_Ice"
    },
    {
      "x": -23,
      "y": 9,
      "z": 7,
      "name": "Rock_Ice"
    },
    {
      "x": -23,
      "y": 10,
      "z": 7,
      "name": "Rock_Ice"
    },
    {
      "x": -23,
      "y": 11,
      "z": 7,
      "name": "Rock_Ice"
    },
    {
      "x": -23,
      "y": 12,
      "z": 7,
      "name": "Soil_Snow"
    },
    {
      "x": -23,
      "y": 4,
      "z": 8,
      "name": "Rock_Ice"
    },
    {
      "x": -23,
      "y": 5,
      "z": 8,
      "name": "Rock_Ice"
    },
    {
      "x": -23,
      "y": 6,
      "z": 8,
      "name": "Rock_Ice"
    },
    {
      "x": -23,
      "y": 7,
      "z": 8,
      "name": "Rock_Ice"
    },
    {
      "x": -23,
      "y": 8,
      "z": 8,
      "name": "Rock_Ice"
    },
    {
      "x": -23,
      "y": 9,
      "z": 8,
      "name": "Rock_Ice"
    },
    {
      "x": -23,
      "y": 10,
      "z": 8,
      "name": "Rock_Ice"
    },
    {
      "x": -23,
      "y": 11,
      "z": 8,
      "name": "Rock_Ice"
    },
    {
      "x": -23,
      "y": 12,
      "z": 8,
      "name": "Soil_Snow"
    },
    {
      "x": -23,
      "y": 6,
      "z": 9,
      "name": "Rock_Ice"
    },
    {
      "x": -23,
      "y": 7,
      "z": 9,
      "name": "Rock_Ice"
    },
    {
      "x": -23,
      "y": 8,
      "z": 9,
      "name": "Rock_Ice"
    },
    {
      "x": -23,
      "y": 9,
      "z": 9,
      "name": "Rock_Ice"
    },
    {
      "x": -23,
      "y": 10,
      "z": 9,
      "name": "Rock_Ice"
    },
    {
      "x": -23,
      "y": 11,
      "z": 9,
      "name": "Soil_Snow"
    },
    {
      "x": -23,
      "y": 7,
      "z": 10,
      "name": "Rock_Ice"
    },
    {
      "x": -23,
      "y": 8,
      "z": 10,
      "name": "Rock_Ice"
    },
    {
      "x": -23,
      "y": 9,
      "z": 10,
      "name": "Soil_Snow"
    },
    {
      "x": -22,
      "y": 3,
      "z": 3,
      "name": "Rock_Ice"
    },
    {
      "x": -22,
      "y": 4,
      "z": 3,
      "name": "Rock_Ice"
    },
    {
      "x": -22,
      "y": 5,
      "z": 3,
      "name": "Rock_Ice"
    },
    {
      "x": -22,
      "y": 6,
      "z": 3,
      "name": "Rock_Ice"
    },
    {
      "x": -22,
      "y": 7,
      "z": 3,
      "name": "Rock_Ice"
    },
    {
      "x": -22,
      "y": 8,
      "z": 3,
      "name": "Rock_Ice"
    },
    {
      "x": -22,
      "y": 9,
      "z": 3,
      "name": "Rock_Ice"
    },
    {
      "x": -22,
      "y": 3,
      "z": 4,
      "name": "Rock_Ice"
    },
    {
      "x": -22,
      "y": 4,
      "z": 4,
      "name": "Rock_Ice"
    },
    {
      "x": -22,
      "y": 5,
      "z": 4,
      "name": "Rock_Ice"
    },
    {
      "x": -22,
      "y": 6,
      "z": 4,
      "name": "Rock_Ice"
    },
    {
      "x": -22,
      "y": 7,
      "z": 4,
      "name": "Rock_Ice"
    },
    {
      "x": -22,
      "y": 8,
      "z": 4,
      "name": "Rock_Ice"
    },
    {
      "x": -22,
      "y": 9,
      "z": 4,
      "name": "Rock_Ice"
    },
    {
      "x": -22,
      "y": 10,
      "z": 4,
      "name": "Rock_Ice"
    },
    {
      "x": -22,
      "y": 11,
      "z": 4,
      "name": "Soil_Snow"
    },
    {
      "x": -22,
      "y": 3,
      "z": 5,
      "name": "Rock_Ice"
    },
    {
      "x": -22,
      "y": 4,
      "z": 5,
      "name": "Rock_Ice"
    },
    {
      "x": -22,
      "y": 5,
      "z": 5,
      "name": "Rock_Ice"
    },
    {
      "x": -22,
      "y": 6,
      "z": 5,
      "name": "Rock_Ice"
    },
    {
      "x": -22,
      "y": 7,
      "z": 5,
      "name": "Rock_Ice"
    },
    {
      "x": -22,
      "y": 8,
      "z": 5,
      "name": "Rock_Ice"
    },
    {
      "x": -22,
      "y": 9,
      "z": 5,
      "name": "Rock_Ice"
    },
    {
      "x": -22,
      "y": 10,
      "z": 5,
      "name": "Rock_Ice"
    },
    {
      "x": -22,
      "y": 11,
      "z": 5,
      "name": "Rock_Ice"
    },
    {
      "x": -22,
      "y": 12,
      "z": 5,
      "name": "Rock_Ice"
    },
    {
      "x": -22,
      "y": 13,
      "z": 5,
      "name": "Soil_Snow"
    },
    {
      "x": -22,
      "y": 2,
      "z": 6,
      "name": "Rock_Ice"
    },
    {
      "x": -22,
      "y": 3,
      "z": 6,
      "name": "Rock_Ice"
    },
    {
      "x": -22,
      "y": 4,
      "z": 6,
      "name": "Rock_Ice"
    },
    {
      "x": -22,
      "y": 5,
      "z": 6,
      "name": "Rock_Ice"
    },
    {
      "x": -22,
      "y": 6,
      "z": 6,
      "name": "Rock_Ice"
    },
    {
      "x": -22,
      "y": 7,
      "z": 6,
      "name": "Rock_Ice"
    },
    {
      "x": -22,
      "y": 8,
      "z": 6,
      "name": "Rock_Ice"
    },
    {
      "x": -22,
      "y": 9,
      "z": 6,
      "name": "Rock_Ice"
    },
    {
      "x": -22,
      "y": 10,
      "z": 6,
      "name": "Rock_Ice"
    },
    {
      "x": -22,
      "y": 11,
      "z": 6,
      "name": "Rock_Ice"
    },
    {
      "x": -22,
      "y": 12,
      "z": 6,
      "name": "Rock_Ice"
    },
    {
      "x": -22,
      "y": 13,
      "z": 6,
      "name": "Rock_Ice"
    },
    {
      "x": -22,
      "y": 14,
      "z": 6,
      "name": "Rock_Ice"
    },
    {
      "x": -22,
      "y": 15,
      "z": 6,
      "name": "Rock_Ice"
    },
    {
      "x": -22,
      "y": 16,
      "z": 6,
      "name": "Soil_Snow"
    },
    {
      "x": -22,
      "y": 2,
      "z": 7,
      "name": "Rock_Ice"
    },
    {
      "x": -22,
      "y": 3,
      "z": 7,
      "name": "Rock_Ice"
    },
    {
      "x": -22,
      "y": 4,
      "z": 7,
      "name": "Rock_Ice"
    },
    {
      "x": -22,
      "y": 5,
      "z": 7,
      "name": "Rock_Ice"
    },
    {
      "x": -22,
      "y": 6,
      "z": 7,
      "name": "Rock_Ice"
    },
    {
      "x": -22,
      "y": 7,
      "z": 7,
      "name": "Rock_Ice"
    },
    {
      "x": -22,
      "y": 8,
      "z": 7,
      "name": "Rock_Ice"
    },
    {
      "x": -22,
      "y": 9,
      "z": 7,
      "name": "Rock_Ice"
    },
    {
      "x": -22,
      "y": 10,
      "z": 7,
      "name": "Rock_Ice"
    },
    {
      "x": -22,
      "y": 11,
      "z": 7,
      "name": "Rock_Ice"
    },
    {
      "x": -22,
      "y": 12,
      "z": 7,
      "name": "Rock_Ice"
    },
    {
      "x": -22,
      "y": 13,
      "z": 7,
      "name": "Rock_Ice"
    },
    {
      "x": -22,
      "y": 14,
      "z": 7,
      "name": "Rock_Ice"
    },
    {
      "x": -22,
      "y": 15,
      "z": 7,
      "name": "Soil_Snow"
    },
    {
      "x": -22,
      "y": 2,
      "z": 8,
      "name": "Rock_Ice"
    },
    {
      "x": -22,
      "y": 3,
      "z": 8,
      "name": "Rock_Ice"
    },
    {
      "x": -22,
      "y": 4,
      "z": 8,
      "name": "Rock_Ice"
    },
    {
      "x": -22,
      "y": 5,
      "z": 8,
      "name": "Rock_Ice"
    },
    {
      "x": -22,
      "y": 6,
      "z": 8,
      "name": "Rock_Ice"
    },
    {
      "x": -22,
      "y": 7,
      "z": 8,
      "name": "Rock_Ice"
    },
    {
      "x": -22,
      "y": 8,
      "z": 8,
      "name": "Rock_Ice"
    },
    {
      "x": -22,
      "y": 9,
      "z": 8,
      "name": "Rock_Ice"
    },
    {
      "x": -22,
      "y": 10,
      "z": 8,
      "name": "Rock_Ice"
    },
    {
      "x": -22,
      "y": 11,
      "z": 8,
      "name": "Rock_Ice"
    },
    {
      "x": -22,
      "y": 12,
      "z": 8,
      "name": "Rock_Ice"
    },
    {
      "x": -22,
      "y": 13,
      "z": 8,
      "name": "Rock_Ice"
    },
    {
      "x": -22,
      "y": 14,
      "z": 8,
      "name": "Soil_Snow"
    },
    {
      "x": -22,
      "y": 4,
      "z": 9,
      "name": "Rock_Ice"
    },
    {
      "x": -22,
      "y": 5,
      "z": 9,
      "name": "Rock_Ice"
    },
    {
      "x": -22,
      "y": 6,
      "z": 9,
      "name": "Rock_Ice"
    },
    {
      "x": -22,
      "y": 7,
      "z": 9,
      "name": "Rock_Ice"
    },
    {
      "x": -22,
      "y": 8,
      "z": 9,
      "name": "Rock_Ice"
    },
    {
      "x": -22,
      "y": 9,
      "z": 9,
      "name": "Rock_Ice"
    },
    {
      "x": -22,
      "y": 10,
      "z": 9,
      "name": "Rock_Ice"
    },
    {
      "x": -22,
      "y": 11,
      "z": 9,
      "name": "Rock_Ice"
    },
    {
      "x": -22,
      "y": 12,
      "z": 9,
      "name": "Soil_Snow"
    },
    {
      "x": -22,
      "y": 6,
      "z": 10,
      "name": "Rock_Ice"
    },
    {
      "x": -22,
      "y": 7,
      "z": 10,
      "name": "Rock_Ice"
    },
    {
      "x": -22,
      "y": 8,
      "z": 10,
      "name": "Rock_Ice"
    },
    {
      "x": -22,
      "y": 9,
      "z": 10,
      "name": "Rock_Ice"
    },
    {
      "x": -22,
      "y": 10,
      "z": 10,
      "name": "Soil_Snow"
    },
    {
      "x": -21,
      "y": 4,
      "z": 1,
      "name": "Soil_Snow"
    },
    {
      "x": -21,
      "y": 3,
      "z": 2,
      "name": "Rock_Ice"
    },
    {
      "x": -21,
      "y": 4,
      "z": 2,
      "name": "Rock_Ice"
    },
    {
      "x": -21,
      "y": 5,
      "z": 2,
      "name": "Rock_Ice"
    },
    {
      "x": -21,
      "y": 6,
      "z": 2,
      "name": "Rock_Ice"
    },
    {
      "x": -21,
      "y": 7,
      "z": 2,
      "name": "Rock_Ice"
    },
    {
      "x": -21,
      "y": 8,
      "z": 2,
      "name": "Rock_Ice"
    },
    {
      "x": -21,
      "y": 9,
      "z": 2,
      "name": "Rock_Ice"
    },
    {
      "x": -21,
      "y": 10,
      "z": 2,
      "name": "Soil_Snow"
    },
    {
      "x": -21,
      "y": 3,
      "z": 3,
      "name": "Rock_Ice"
    },
    {
      "x": -21,
      "y": 4,
      "z": 3,
      "name": "Rock_Ice"
    },
    {
      "x": -21,
      "y": 5,
      "z": 3,
      "name": "Rock_Ice"
    },
    {
      "x": -21,
      "y": 6,
      "z": 3,
      "name": "Rock_Ice"
    },
    {
      "x": -21,
      "y": 7,
      "z": 3,
      "name": "Rock_Ice"
    },
    {
      "x": -21,
      "y": 8,
      "z": 3,
      "name": "Rock_Ice"
    },
    {
      "x": -21,
      "y": 9,
      "z": 3,
      "name": "Rock_Ice"
    },
    {
      "x": -21,
      "y": 10,
      "z": 3,
      "name": "Rock_Ice"
    },
    {
      "x": -21,
      "y": 11,
      "z": 3,
      "name": "Soil_Snow"
    },
    {
      "x": -21,
      "y": 3,
      "z": 4,
      "name": "Rock_Ice"
    },
    {
      "x": -21,
      "y": 4,
      "z": 4,
      "name": "Rock_Ice"
    },
    {
      "x": -21,
      "y": 5,
      "z": 4,
      "name": "Rock_Ice"
    },
    {
      "x": -21,
      "y": 6,
      "z": 4,
      "name": "Rock_Ice"
    },
    {
      "x": -21,
      "y": 7,
      "z": 4,
      "name": "Rock_Ice"
    },
    {
      "x": -21,
      "y": 8,
      "z": 4,
      "name": "Rock_Ice"
    },
    {
      "x": -21,
      "y": 9,
      "z": 4,
      "name": "Rock_Ice"
    },
    {
      "x": -21,
      "y": 10,
      "z": 4,
      "name": "Rock_Ice"
    },
    {
      "x": -21,
      "y": 11,
      "z": 4,
      "name": "Rock_Ice"
    },
    {
      "x": -21,
      "y": 12,
      "z": 4,
      "name": "Rock_Ice"
    },
    {
      "x": -21,
      "y": 13,
      "z": 4,
      "name": "Rock_Ice"
    },
    {
      "x": -21,
      "y": 14,
      "z": 4,
      "name": "Soil_Snow"
    },
    {
      "x": -21,
      "y": 2,
      "z": 5,
      "name": "Rock_Ice"
    },
    {
      "x": -21,
      "y": 3,
      "z": 5,
      "name": "Rock_Ice"
    },
    {
      "x": -21,
      "y": 4,
      "z": 5,
      "name": "Rock_Ice"
    },
    {
      "x": -21,
      "y": 5,
      "z": 5,
      "name": "Rock_Ice"
    },
    {
      "x": -21,
      "y": 6,
      "z": 5,
      "name": "Rock_Ice"
    },
    {
      "x": -21,
      "y": 7,
      "z": 5,
      "name": "Rock_Ice"
    },
    {
      "x": -21,
      "y": 8,
      "z": 5,
      "name": "Rock_Ice"
    },
    {
      "x": -21,
      "y": 9,
      "z": 5,
      "name": "Rock_Ice"
    },
    {
      "x": -21,
      "y": 10,
      "z": 5,
      "name": "Rock_Ice"
    },
    {
      "x": -21,
      "y": 11,
      "z": 5,
      "name": "Rock_Ice"
    },
    {
      "x": -21,
      "y": 12,
      "z": 5,
      "name": "Rock_Ice"
    },
    {
      "x": -21,
      "y": 13,
      "z": 5,
      "name": "Rock_Ice"
    },
    {
      "x": -21,
      "y": 14,
      "z": 5,
      "name": "Rock_Ice"
    },
    {
      "x": -21,
      "y": 15,
      "z": 5,
      "name": "Rock_Ice"
    },
    {
      "x": -21,
      "y": 16,
      "z": 5,
      "name": "Rock_Ice"
    },
    {
      "x": -21,
      "y": 17,
      "z": 5,
      "name": "Soil_Snow"
    },
    {
      "x": -21,
      "y": 2,
      "z": 6,
      "name": "Rock_Ice"
    },
    {
      "x": -21,
      "y": 3,
      "z": 6,
      "name": "Rock_Ice"
    },
    {
      "x": -21,
      "y": 4,
      "z": 6,
      "name": "Rock_Ice"
    },
    {
      "x": -21,
      "y": 5,
      "z": 6,
      "name": "Rock_Ice"
    },
    {
      "x": -21,
      "y": 6,
      "z": 6,
      "name": "Rock_Ice"
    },
    {
      "x": -21,
      "y": 7,
      "z": 6,
      "name": "Rock_Ice"
    },
    {
      "x": -21,
      "y": 8,
      "z": 6,
      "name": "Rock_Ice"
    },
    {
      "x": -21,
      "y": 9,
      "z": 6,
      "name": "Rock_Ice"
    },
    {
      "x": -21,
      "y": 10,
      "z": 6,
      "name": "Rock_Ice"
    },
    {
      "x": -21,
      "y": 11,
      "z": 6,
      "name": "Rock_Ice"
    },
    {
      "x": -21,
      "y": 12,
      "z": 6,
      "name": "Rock_Ice"
    },
    {
      "x": -21,
      "y": 13,
      "z": 6,
      "name": "Rock_Ice"
    },
    {
      "x": -21,
      "y": 14,
      "z": 6,
      "name": "Rock_Ice"
    },
    {
      "x": -21,
      "y": 15,
      "z": 6,
      "name": "Rock_Ice"
    },
    {
      "x": -21,
      "y": 16,
      "z": 6,
      "name": "Rock_Ice"
    },
    {
      "x": -21,
      "y": 17,
      "z": 6,
      "name": "Soil_Snow"
    },
    {
      "x": -21,
      "y": 2,
      "z": 7,
      "name": "Rock_Ice"
    },
    {
      "x": -21,
      "y": 3,
      "z": 7,
      "name": "Rock_Ice"
    },
    {
      "x": -21,
      "y": 4,
      "z": 7,
      "name": "Rock_Ice"
    },
    {
      "x": -21,
      "y": 5,
      "z": 7,
      "name": "Rock_Ice"
    },
    {
      "x": -21,
      "y": 6,
      "z": 7,
      "name": "Rock_Ice"
    },
    {
      "x": -21,
      "y": 7,
      "z": 7,
      "name": "Rock_Ice"
    },
    {
      "x": -21,
      "y": 8,
      "z": 7,
      "name": "Rock_Ice"
    },
    {
      "x": -21,
      "y": 9,
      "z": 7,
      "name": "Rock_Ice"
    },
    {
      "x": -21,
      "y": 10,
      "z": 7,
      "name": "Rock_Ice"
    },
    {
      "x": -21,
      "y": 11,
      "z": 7,
      "name": "Rock_Ice"
    },
    {
      "x": -21,
      "y": 12,
      "z": 7,
      "name": "Rock_Ice"
    },
    {
      "x": -21,
      "y": 13,
      "z": 7,
      "name": "Rock_Ice"
    },
    {
      "x": -21,
      "y": 14,
      "z": 7,
      "name": "Rock_Ice"
    },
    {
      "x": -21,
      "y": 15,
      "z": 7,
      "name": "Rock_Ice"
    },
    {
      "x": -21,
      "y": 16,
      "z": 7,
      "name": "Soil_Snow"
    },
    {
      "x": -21,
      "y": 2,
      "z": 8,
      "name": "Rock_Ice"
    },
    {
      "x": -21,
      "y": 3,
      "z": 8,
      "name": "Rock_Ice"
    },
    {
      "x": -21,
      "y": 4,
      "z": 8,
      "name": "Rock_Ice"
    },
    {
      "x": -21,
      "y": 5,
      "z": 8,
      "name": "Rock_Ice"
    },
    {
      "x": -21,
      "y": 6,
      "z": 8,
      "name": "Rock_Ice"
    },
    {
      "x": -21,
      "y": 7,
      "z": 8,
      "name": "Rock_Ice"
    },
    {
      "x": -21,
      "y": 8,
      "z": 8,
      "name": "Rock_Ice"
    },
    {
      "x": -21,
      "y": 9,
      "z": 8,
      "name": "Rock_Ice"
    },
    {
      "x": -21,
      "y": 10,
      "z": 8,
      "name": "Rock_Ice"
    },
    {
      "x": -21,
      "y": 11,
      "z": 8,
      "name": "Rock_Ice"
    },
    {
      "x": -21,
      "y": 12,
      "z": 8,
      "name": "Rock_Ice"
    },
    {
      "x": -21,
      "y": 13,
      "z": 8,
      "name": "Rock_Ice"
    },
    {
      "x": -21,
      "y": 14,
      "z": 8,
      "name": "Rock_Ice"
    },
    {
      "x": -21,
      "y": 15,
      "z": 8,
      "name": "Rock_Ice"
    },
    {
      "x": -21,
      "y": 16,
      "z": 8,
      "name": "Soil_Snow"
    },
    {
      "x": -21,
      "y": 2,
      "z": 9,
      "name": "Rock_Ice"
    },
    {
      "x": -21,
      "y": 3,
      "z": 9,
      "name": "Rock_Ice"
    },
    {
      "x": -21,
      "y": 4,
      "z": 9,
      "name": "Rock_Ice"
    },
    {
      "x": -21,
      "y": 5,
      "z": 9,
      "name": "Rock_Ice"
    },
    {
      "x": -21,
      "y": 6,
      "z": 9,
      "name": "Rock_Ice"
    },
    {
      "x": -21,
      "y": 7,
      "z": 9,
      "name": "Rock_Ice"
    },
    {
      "x": -21,
      "y": 8,
      "z": 9,
      "name": "Rock_Ice"
    },
    {
      "x": -21,
      "y": 9,
      "z": 9,
      "name": "Rock_Ice"
    },
    {
      "x": -21,
      "y": 10,
      "z": 9,
      "name": "Rock_Ice"
    },
    {
      "x": -21,
      "y": 11,
      "z": 9,
      "name": "Rock_Ice"
    },
    {
      "x": -21,
      "y": 12,
      "z": 9,
      "name": "Rock_Ice"
    },
    {
      "x": -21,
      "y": 13,
      "z": 9,
      "name": "Rock_Ice"
    },
    {
      "x": -21,
      "y": 14,
      "z": 9,
      "name": "Soil_Snow"
    },
    {
      "x": -21,
      "y": 5,
      "z": 10,
      "name": "Rock_Ice"
    },
    {
      "x": -21,
      "y": 6,
      "z": 10,
      "name": "Rock_Ice"
    },
    {
      "x": -21,
      "y": 7,
      "z": 10,
      "name": "Rock_Ice"
    },
    {
      "x": -21,
      "y": 8,
      "z": 10,
      "name": "Rock_Ice"
    },
    {
      "x": -21,
      "y": 9,
      "z": 10,
      "name": "Rock_Ice"
    },
    {
      "x": -21,
      "y": 10,
      "z": 10,
      "name": "Rock_Ice"
    },
    {
      "x": -21,
      "y": 11,
      "z": 10,
      "name": "Rock_Ice"
    },
    {
      "x": -21,
      "y": 12,
      "z": 10,
      "name": "Soil_Snow"
    },
    {
      "x": -21,
      "y": 8,
      "z": 11,
      "name": "Rock_Ice"
    },
    {
      "x": -21,
      "y": 9,
      "z": 11,
      "name": "Soil_Snow"
    },
    {
      "x": -20,
      "y": 3,
      "z": 1,
      "name": "Rock_Ice"
    },
    {
      "x": -20,
      "y": 4,
      "z": 1,
      "name": "Rock_Ice"
    },
    {
      "x": -20,
      "y": 5,
      "z": 1,
      "name": "Rock_Ice"
    },
    {
      "x": -20,
      "y": 6,
      "z": 1,
      "name": "Rock_Ice"
    },
    {
      "x": -20,
      "y": 7,
      "z": 1,
      "name": "Rock_Ice"
    },
    {
      "x": -20,
      "y": 8,
      "z": 1,
      "name": "Rock_Ice"
    },
    {
      "x": -20,
      "y": 9,
      "z": 1,
      "name": "Rock_Ice"
    },
    {
      "x": -20,
      "y": 10,
      "z": 1,
      "name": "Soil_Snow"
    },
    {
      "x": -20,
      "y": 3,
      "z": 2,
      "name": "Rock_Ice"
    },
    {
      "x": -20,
      "y": 4,
      "z": 2,
      "name": "Rock_Ice"
    },
    {
      "x": -20,
      "y": 5,
      "z": 2,
      "name": "Rock_Ice"
    },
    {
      "x": -20,
      "y": 6,
      "z": 2,
      "name": "Rock_Ice"
    },
    {
      "x": -20,
      "y": 7,
      "z": 2,
      "name": "Rock_Ice"
    },
    {
      "x": -20,
      "y": 8,
      "z": 2,
      "name": "Rock_Ice"
    },
    {
      "x": -20,
      "y": 9,
      "z": 2,
      "name": "Rock_Ice"
    },
    {
      "x": -20,
      "y": 10,
      "z": 2,
      "name": "Rock_Ice"
    },
    {
      "x": -20,
      "y": 11,
      "z": 2,
      "name": "Rock_Ice"
    },
    {
      "x": -20,
      "y": 12,
      "z": 2,
      "name": "Soil_Snow"
    },
    {
      "x": -20,
      "y": 2,
      "z": 3,
      "name": "Rock_Ice"
    },
    {
      "x": -20,
      "y": 3,
      "z": 3,
      "name": "Rock_Ice"
    },
    {
      "x": -20,
      "y": 4,
      "z": 3,
      "name": "Rock_Ice"
    },
    {
      "x": -20,
      "y": 5,
      "z": 3,
      "name": "Rock_Ice"
    },
    {
      "x": -20,
      "y": 6,
      "z": 3,
      "name": "Rock_Ice"
    },
    {
      "x": -20,
      "y": 7,
      "z": 3,
      "name": "Rock_Ice"
    },
    {
      "x": -20,
      "y": 8,
      "z": 3,
      "name": "Rock_Ice"
    },
    {
      "x": -20,
      "y": 9,
      "z": 3,
      "name": "Rock_Ice"
    },
    {
      "x": -20,
      "y": 10,
      "z": 3,
      "name": "Rock_Ice"
    },
    {
      "x": -20,
      "y": 11,
      "z": 3,
      "name": "Rock_Ice"
    },
    {
      "x": -20,
      "y": 12,
      "z": 3,
      "name": "Rock_Ice"
    },
    {
      "x": -20,
      "y": 13,
      "z": 3,
      "name": "Rock_Ice"
    },
    {
      "x": -20,
      "y": 14,
      "z": 3,
      "name": "Rock_Ice"
    },
    {
      "x": -20,
      "y": 15,
      "z": 3,
      "name": "Rock_Ice"
    },
    {
      "x": -20,
      "y": 16,
      "z": 3,
      "name": "Soil_Snow"
    },
    {
      "x": -20,
      "y": 2,
      "z": 4,
      "name": "Rock_Ice"
    },
    {
      "x": -20,
      "y": 3,
      "z": 4,
      "name": "Rock_Ice"
    },
    {
      "x": -20,
      "y": 4,
      "z": 4,
      "name": "Rock_Ice"
    },
    {
      "x": -20,
      "y": 5,
      "z": 4,
      "name": "Rock_Ice"
    },
    {
      "x": -20,
      "y": 6,
      "z": 4,
      "name": "Rock_Ice"
    },
    {
      "x": -20,
      "y": 7,
      "z": 4,
      "name": "Rock_Ice"
    },
    {
      "x": -20,
      "y": 8,
      "z": 4,
      "name": "Rock_Ice"
    },
    {
      "x": -20,
      "y": 9,
      "z": 4,
      "name": "Rock_Ice"
    },
    {
      "x": -20,
      "y": 10,
      "z": 4,
      "name": "Rock_Ice"
    },
    {
      "x": -20,
      "y": 11,
      "z": 4,
      "name": "Rock_Ice"
    },
    {
      "x": -20,
      "y": 12,
      "z": 4,
      "name": "Rock_Ice"
    },
    {
      "x": -20,
      "y": 13,
      "z": 4,
      "name": "Rock_Ice"
    },
    {
      "x": -20,
      "y": 14,
      "z": 4,
      "name": "Rock_Ice"
    },
    {
      "x": -20,
      "y": 15,
      "z": 4,
      "name": "Rock_Ice"
    },
    {
      "x": -20,
      "y": 16,
      "z": 4,
      "name": "Rock_Ice"
    },
    {
      "x": -20,
      "y": 17,
      "z": 4,
      "name": "Rock_Ice"
    },
    {
      "x": -20,
      "y": 18,
      "z": 4,
      "name": "Rock_Ice"
    },
    {
      "x": -20,
      "y": 19,
      "z": 4,
      "name": "Soil_Snow"
    },
    {
      "x": -20,
      "y": 2,
      "z": 5,
      "name": "Rock_Ice"
    },
    {
      "x": -20,
      "y": 3,
      "z": 5,
      "name": "Rock_Ice"
    },
    {
      "x": -20,
      "y": 4,
      "z": 5,
      "name": "Rock_Ice"
    },
    {
      "x": -20,
      "y": 5,
      "z": 5,
      "name": "Rock_Ice"
    },
    {
      "x": -20,
      "y": 6,
      "z": 5,
      "name": "Rock_Ice"
    },
    {
      "x": -20,
      "y": 7,
      "z": 5,
      "name": "Rock_Ice"
    },
    {
      "x": -20,
      "y": 8,
      "z": 5,
      "name": "Rock_Ice"
    },
    {
      "x": -20,
      "y": 9,
      "z": 5,
      "name": "Rock_Ice"
    },
    {
      "x": -20,
      "y": 10,
      "z": 5,
      "name": "Rock_Ice"
    },
    {
      "x": -20,
      "y": 11,
      "z": 5,
      "name": "Rock_Ice"
    },
    {
      "x": -20,
      "y": 12,
      "z": 5,
      "name": "Rock_Ice"
    },
    {
      "x": -20,
      "y": 13,
      "z": 5,
      "name": "Rock_Ice"
    },
    {
      "x": -20,
      "y": 14,
      "z": 5,
      "name": "Rock_Ice"
    },
    {
      "x": -20,
      "y": 15,
      "z": 5,
      "name": "Rock_Ice"
    },
    {
      "x": -20,
      "y": 16,
      "z": 5,
      "name": "Rock_Ice"
    },
    {
      "x": -20,
      "y": 17,
      "z": 5,
      "name": "Rock_Ice"
    },
    {
      "x": -20,
      "y": 18,
      "z": 5,
      "name": "Rock_Ice"
    },
    {
      "x": -20,
      "y": 19,
      "z": 5,
      "name": "Soil_Snow"
    },
    {
      "x": -20,
      "y": 2,
      "z": 6,
      "name": "Rock_Ice"
    },
    {
      "x": -20,
      "y": 3,
      "z": 6,
      "name": "Rock_Ice"
    },
    {
      "x": -20,
      "y": 4,
      "z": 6,
      "name": "Rock_Ice"
    },
    {
      "x": -20,
      "y": 5,
      "z": 6,
      "name": "Rock_Ice"
    },
    {
      "x": -20,
      "y": 6,
      "z": 6,
      "name": "Rock_Ice"
    },
    {
      "x": -20,
      "y": 7,
      "z": 6,
      "name": "Rock_Ice"
    },
    {
      "x": -20,
      "y": 8,
      "z": 6,
      "name": "Rock_Ice"
    },
    {
      "x": -20,
      "y": 9,
      "z": 6,
      "name": "Rock_Ice"
    },
    {
      "x": -20,
      "y": 10,
      "z": 6,
      "name": "Rock_Ice"
    },
    {
      "x": -20,
      "y": 11,
      "z": 6,
      "name": "Rock_Ice"
    },
    {
      "x": -20,
      "y": 12,
      "z": 6,
      "name": "Rock_Ice"
    },
    {
      "x": -20,
      "y": 13,
      "z": 6,
      "name": "Rock_Ice"
    },
    {
      "x": -20,
      "y": 14,
      "z": 6,
      "name": "Rock_Ice"
    },
    {
      "x": -20,
      "y": 15,
      "z": 6,
      "name": "Rock_Ice"
    },
    {
      "x": -20,
      "y": 16,
      "z": 6,
      "name": "Rock_Ice"
    },
    {
      "x": -20,
      "y": 17,
      "z": 6,
      "name": "Rock_Ice"
    },
    {
      "x": -20,
      "y": 18,
      "z": 6,
      "name": "Rock_Ice"
    },
    {
      "x": -20,
      "y": 19,
      "z": 6,
      "name": "Soil_Snow"
    },
    {
      "x": -20,
      "y": 1,
      "z": 7,
      "name": "Rock_Ice"
    },
    {
      "x": -20,
      "y": 2,
      "z": 7,
      "name": "Rock_Ice"
    },
    {
      "x": -20,
      "y": 3,
      "z": 7,
      "name": "Rock_Ice"
    },
    {
      "x": -20,
      "y": 4,
      "z": 7,
      "name": "Rock_Ice"
    },
    {
      "x": -20,
      "y": 5,
      "z": 7,
      "name": "Rock_Ice"
    },
    {
      "x": -20,
      "y": 6,
      "z": 7,
      "name": "Rock_Ice"
    },
    {
      "x": -20,
      "y": 7,
      "z": 7,
      "name": "Rock_Ice"
    },
    {
      "x": -20,
      "y": 8,
      "z": 7,
      "name": "Rock_Ice"
    },
    {
      "x": -20,
      "y": 9,
      "z": 7,
      "name": "Rock_Ice"
    },
    {
      "x": -20,
      "y": 10,
      "z": 7,
      "name": "Rock_Ice"
    },
    {
      "x": -20,
      "y": 11,
      "z": 7,
      "name": "Rock_Ice"
    },
    {
      "x": -20,
      "y": 12,
      "z": 7,
      "name": "Rock_Ice"
    },
    {
      "x": -20,
      "y": 13,
      "z": 7,
      "name": "Rock_Ice"
    },
    {
      "x": -20,
      "y": 14,
      "z": 7,
      "name": "Rock_Ice"
    },
    {
      "x": -20,
      "y": 15,
      "z": 7,
      "name": "Rock_Ice"
    },
    {
      "x": -20,
      "y": 16,
      "z": 7,
      "name": "Rock_Ice"
    },
    {
      "x": -20,
      "y": 17,
      "z": 7,
      "name": "Rock_Ice"
    },
    {
      "x": -20,
      "y": 18,
      "z": 7,
      "name": "Soil_Snow"
    },
    {
      "x": -20,
      "y": 1,
      "z": 8,
      "name": "Rock_Ice"
    },
    {
      "x": -20,
      "y": 2,
      "z": 8,
      "name": "Rock_Ice"
    },
    {
      "x": -20,
      "y": 3,
      "z": 8,
      "name": "Rock_Ice"
    },
    {
      "x": -20,
      "y": 4,
      "z": 8,
      "name": "Rock_Ice"
    },
    {
      "x": -20,
      "y": 5,
      "z": 8,
      "name": "Rock_Ice"
    },
    {
      "x": -20,
      "y": 6,
      "z": 8,
      "name": "Rock_Ice"
    },
    {
      "x": -20,
      "y": 7,
      "z": 8,
      "name": "Rock_Ice"
    },
    {
      "x": -20,
      "y": 8,
      "z": 8,
      "name": "Rock_Ice"
    },
    {
      "x": -20,
      "y": 9,
      "z": 8,
      "name": "Rock_Ice"
    },
    {
      "x": -20,
      "y": 10,
      "z": 8,
      "name": "Rock_Ice"
    },
    {
      "x": -20,
      "y": 11,
      "z": 8,
      "name": "Rock_Ice"
    },
    {
      "x": -20,
      "y": 12,
      "z": 8,
      "name": "Rock_Ice"
    },
    {
      "x": -20,
      "y": 13,
      "z": 8,
      "name": "Rock_Ice"
    },
    {
      "x": -20,
      "y": 14,
      "z": 8,
      "name": "Rock_Ice"
    },
    {
      "x": -20,
      "y": 15,
      "z": 8,
      "name": "Rock_Ice"
    },
    {
      "x": -20,
      "y": 16,
      "z": 8,
      "name": "Rock_Ice"
    },
    {
      "x": -20,
      "y": 17,
      "z": 8,
      "name": "Soil_Snow"
    },
    {
      "x": -20,
      "y": 1,
      "z": 9,
      "name": "Rock_Ice"
    },
    {
      "x": -20,
      "y": 2,
      "z": 9,
      "name": "Rock_Ice"
    },
    {
      "x": -20,
      "y": 3,
      "z": 9,
      "name": "Rock_Ice"
    },
    {
      "x": -20,
      "y": 4,
      "z": 9,
      "name": "Rock_Ice"
    },
    {
      "x": -20,
      "y": 5,
      "z": 9,
      "name": "Rock_Ice"
    },
    {
      "x": -20,
      "y": 6,
      "z": 9,
      "name": "Rock_Ice"
    },
    {
      "x": -20,
      "y": 7,
      "z": 9,
      "name": "Rock_Ice"
    },
    {
      "x": -20,
      "y": 8,
      "z": 9,
      "name": "Rock_Ice"
    },
    {
      "x": -20,
      "y": 9,
      "z": 9,
      "name": "Rock_Ice"
    },
    {
      "x": -20,
      "y": 10,
      "z": 9,
      "name": "Rock_Ice"
    },
    {
      "x": -20,
      "y": 11,
      "z": 9,
      "name": "Rock_Ice"
    },
    {
      "x": -20,
      "y": 12,
      "z": 9,
      "name": "Rock_Ice"
    },
    {
      "x": -20,
      "y": 13,
      "z": 9,
      "name": "Rock_Ice"
    },
    {
      "x": -20,
      "y": 14,
      "z": 9,
      "name": "Rock_Ice"
    },
    {
      "x": -20,
      "y": 15,
      "z": 9,
      "name": "Soil_Snow"
    },
    {
      "x": -20,
      "y": 3,
      "z": 10,
      "name": "Rock_Ice"
    },
    {
      "x": -20,
      "y": 4,
      "z": 10,
      "name": "Rock_Ice"
    },
    {
      "x": -20,
      "y": 5,
      "z": 10,
      "name": "Rock_Ice"
    },
    {
      "x": -20,
      "y": 6,
      "z": 10,
      "name": "Rock_Ice"
    },
    {
      "x": -20,
      "y": 7,
      "z": 10,
      "name": "Rock_Ice"
    },
    {
      "x": -20,
      "y": 8,
      "z": 10,
      "name": "Rock_Ice"
    },
    {
      "x": -20,
      "y": 9,
      "z": 10,
      "name": "Rock_Ice"
    },
    {
      "x": -20,
      "y": 10,
      "z": 10,
      "name": "Rock_Ice"
    },
    {
      "x": -20,
      "y": 11,
      "z": 10,
      "name": "Rock_Ice"
    },
    {
      "x": -20,
      "y": 12,
      "z": 10,
      "name": "Rock_Ice"
    },
    {
      "x": -20,
      "y": 13,
      "z": 10,
      "name": "Rock_Ice"
    },
    {
      "x": -20,
      "y": 14,
      "z": 10,
      "name": "Soil_Snow"
    },
    {
      "x": -20,
      "y": 7,
      "z": 11,
      "name": "Rock_Ice"
    },
    {
      "x": -20,
      "y": 8,
      "z": 11,
      "name": "Rock_Ice"
    },
    {
      "x": -20,
      "y": 9,
      "z": 11,
      "name": "Rock_Ice"
    },
    {
      "x": -20,
      "y": 10,
      "z": 11,
      "name": "Soil_Snow"
    },
    {
      "x": -19,
      "y": 3,
      "z": 0,
      "name": "Rock_Ice"
    },
    {
      "x": -19,
      "y": 4,
      "z": 0,
      "name": "Rock_Ice"
    },
    {
      "x": -19,
      "y": 5,
      "z": 0,
      "name": "Rock_Ice"
    },
    {
      "x": -19,
      "y": 6,
      "z": 0,
      "name": "Rock_Ice"
    },
    {
      "x": -19,
      "y": 7,
      "z": 0,
      "name": "Rock_Ice"
    },
    {
      "x": -19,
      "y": 8,
      "z": 0,
      "name": "Rock_Ice"
    },
    {
      "x": -19,
      "y": 9,
      "z": 0,
      "name": "Rock_Ice"
    },
    {
      "x": -19,
      "y": 10,
      "z": 0,
      "name": "Soil_Snow"
    },
    {
      "x": -19,
      "y": 3,
      "z": 1,
      "name": "Rock_Ice"
    },
    {
      "x": -19,
      "y": 4,
      "z": 1,
      "name": "Rock_Ice"
    },
    {
      "x": -19,
      "y": 5,
      "z": 1,
      "name": "Rock_Ice"
    },
    {
      "x": -19,
      "y": 6,
      "z": 1,
      "name": "Rock_Ice"
    },
    {
      "x": -19,
      "y": 7,
      "z": 1,
      "name": "Rock_Ice"
    },
    {
      "x": -19,
      "y": 8,
      "z": 1,
      "name": "Rock_Ice"
    },
    {
      "x": -19,
      "y": 9,
      "z": 1,
      "name": "Rock_Ice"
    },
    {
      "x": -19,
      "y": 10,
      "z": 1,
      "name": "Rock_Ice"
    },
    {
      "x": -19,
      "y": 11,
      "z": 1,
      "name": "Rock_Ice"
    },
    {
      "x": -19,
      "y": 12,
      "z": 1,
      "name": "Soil_Snow"
    },
    {
      "x": -19,
      "y": 2,
      "z": 2,
      "name": "Rock_Ice"
    },
    {
      "x": -19,
      "y": 3,
      "z": 2,
      "name": "Rock_Ice"
    },
    {
      "x": -19,
      "y": 4,
      "z": 2,
      "name": "Rock_Ice"
    },
    {
      "x": -19,
      "y": 5,
      "z": 2,
      "name": "Rock_Ice"
    },
    {
      "x": -19,
      "y": 6,
      "z": 2,
      "name": "Rock_Ice"
    },
    {
      "x": -19,
      "y": 7,
      "z": 2,
      "name": "Rock_Ice"
    },
    {
      "x": -19,
      "y": 8,
      "z": 2,
      "name": "Rock_Ice"
    },
    {
      "x": -19,
      "y": 9,
      "z": 2,
      "name": "Rock_Ice"
    },
    {
      "x": -19,
      "y": 10,
      "z": 2,
      "name": "Rock_Ice"
    },
    {
      "x": -19,
      "y": 11,
      "z": 2,
      "name": "Rock_Ice"
    },
    {
      "x": -19,
      "y": 12,
      "z": 2,
      "name": "Rock_Ice"
    },
    {
      "x": -19,
      "y": 13,
      "z": 2,
      "name": "Rock_Ice"
    },
    {
      "x": -19,
      "y": 14,
      "z": 2,
      "name": "Rock_Ice"
    },
    {
      "x": -19,
      "y": 15,
      "z": 2,
      "name": "Rock_Ice"
    },
    {
      "x": -19,
      "y": 16,
      "z": 2,
      "name": "Rock_Ice"
    },
    {
      "x": -19,
      "y": 17,
      "z": 2,
      "name": "Rock_Ice"
    },
    {
      "x": -19,
      "y": 24,
      "z": 2,
      "name": "Rock_Ice"
    },
    {
      "x": -19,
      "y": 25,
      "z": 2,
      "name": "Soil_Snow"
    },
    {
      "x": -19,
      "y": 2,
      "z": 3,
      "name": "Rock_Ice"
    },
    {
      "x": -19,
      "y": 3,
      "z": 3,
      "name": "Rock_Ice"
    },
    {
      "x": -19,
      "y": 4,
      "z": 3,
      "name": "Rock_Ice"
    },
    {
      "x": -19,
      "y": 5,
      "z": 3,
      "name": "Rock_Ice"
    },
    {
      "x": -19,
      "y": 6,
      "z": 3,
      "name": "Rock_Ice"
    },
    {
      "x": -19,
      "y": 7,
      "z": 3,
      "name": "Rock_Ice"
    },
    {
      "x": -19,
      "y": 8,
      "z": 3,
      "name": "Rock_Ice"
    },
    {
      "x": -19,
      "y": 9,
      "z": 3,
      "name": "Rock_Ice"
    },
    {
      "x": -19,
      "y": 10,
      "z": 3,
      "name": "Rock_Ice"
    },
    {
      "x": -19,
      "y": 11,
      "z": 3,
      "name": "Rock_Ice"
    },
    {
      "x": -19,
      "y": 12,
      "z": 3,
      "name": "Rock_Ice"
    },
    {
      "x": -19,
      "y": 13,
      "z": 3,
      "name": "Rock_Ice"
    },
    {
      "x": -19,
      "y": 14,
      "z": 3,
      "name": "Rock_Ice"
    },
    {
      "x": -19,
      "y": 15,
      "z": 3,
      "name": "Rock_Ice"
    },
    {
      "x": -19,
      "y": 16,
      "z": 3,
      "name": "Rock_Ice"
    },
    {
      "x": -19,
      "y": 17,
      "z": 3,
      "name": "Rock_Ice"
    },
    {
      "x": -19,
      "y": 18,
      "z": 3,
      "name": "Rock_Ice"
    },
    {
      "x": -19,
      "y": 19,
      "z": 3,
      "name": "Rock_Ice"
    },
    {
      "x": -19,
      "y": 20,
      "z": 3,
      "name": "Rock_Ice"
    },
    {
      "x": -19,
      "y": 21,
      "z": 3,
      "name": "Rock_Ice"
    },
    {
      "x": -19,
      "y": 22,
      "z": 3,
      "name": "Rock_Ice"
    },
    {
      "x": -19,
      "y": 23,
      "z": 3,
      "name": "Rock_Ice"
    },
    {
      "x": -19,
      "y": 24,
      "z": 3,
      "name": "Rock_Ice"
    },
    {
      "x": -19,
      "y": 25,
      "z": 3,
      "name": "Soil_Snow"
    },
    {
      "x": -19,
      "y": 2,
      "z": 4,
      "name": "Rock_Ice"
    },
    {
      "x": -19,
      "y": 3,
      "z": 4,
      "name": "Rock_Ice"
    },
    {
      "x": -19,
      "y": 4,
      "z": 4,
      "name": "Rock_Ice"
    },
    {
      "x": -19,
      "y": 5,
      "z": 4,
      "name": "Rock_Ice"
    },
    {
      "x": -19,
      "y": 6,
      "z": 4,
      "name": "Rock_Ice"
    },
    {
      "x": -19,
      "y": 7,
      "z": 4,
      "name": "Rock_Ice"
    },
    {
      "x": -19,
      "y": 8,
      "z": 4,
      "name": "Rock_Ice"
    },
    {
      "x": -19,
      "y": 9,
      "z": 4,
      "name": "Rock_Ice"
    },
    {
      "x": -19,
      "y": 10,
      "z": 4,
      "name": "Rock_Ice"
    },
    {
      "x": -19,
      "y": 11,
      "z": 4,
      "name": "Rock_Ice"
    },
    {
      "x": -19,
      "y": 12,
      "z": 4,
      "name": "Rock_Ice"
    },
    {
      "x": -19,
      "y": 13,
      "z": 4,
      "name": "Rock_Ice"
    },
    {
      "x": -19,
      "y": 14,
      "z": 4,
      "name": "Rock_Ice"
    },
    {
      "x": -19,
      "y": 15,
      "z": 4,
      "name": "Rock_Ice"
    },
    {
      "x": -19,
      "y": 16,
      "z": 4,
      "name": "Rock_Ice"
    },
    {
      "x": -19,
      "y": 17,
      "z": 4,
      "name": "Rock_Ice"
    },
    {
      "x": -19,
      "y": 18,
      "z": 4,
      "name": "Rock_Ice"
    },
    {
      "x": -19,
      "y": 19,
      "z": 4,
      "name": "Rock_Ice"
    },
    {
      "x": -19,
      "y": 20,
      "z": 4,
      "name": "Rock_Ice"
    },
    {
      "x": -19,
      "y": 21,
      "z": 4,
      "name": "Rock_Ice"
    },
    {
      "x": -19,
      "y": 22,
      "z": 4,
      "name": "Rock_Ice"
    },
    {
      "x": -19,
      "y": 23,
      "z": 4,
      "name": "Rock_Ice"
    },
    {
      "x": -19,
      "y": 24,
      "z": 4,
      "name": "Rock_Ice"
    },
    {
      "x": -19,
      "y": 2,
      "z": 5,
      "name": "Rock_Ice"
    },
    {
      "x": -19,
      "y": 3,
      "z": 5,
      "name": "Rock_Ice"
    },
    {
      "x": -19,
      "y": 4,
      "z": 5,
      "name": "Rock_Ice"
    },
    {
      "x": -19,
      "y": 5,
      "z": 5,
      "name": "Rock_Ice"
    },
    {
      "x": -19,
      "y": 6,
      "z": 5,
      "name": "Rock_Ice"
    },
    {
      "x": -19,
      "y": 7,
      "z": 5,
      "name": "Rock_Ice"
    },
    {
      "x": -19,
      "y": 8,
      "z": 5,
      "name": "Rock_Ice"
    },
    {
      "x": -19,
      "y": 9,
      "z": 5,
      "name": "Rock_Ice"
    },
    {
      "x": -19,
      "y": 10,
      "z": 5,
      "name": "Rock_Ice"
    },
    {
      "x": -19,
      "y": 11,
      "z": 5,
      "name": "Rock_Ice"
    },
    {
      "x": -19,
      "y": 12,
      "z": 5,
      "name": "Rock_Ice"
    },
    {
      "x": -19,
      "y": 13,
      "z": 5,
      "name": "Rock_Ice"
    },
    {
      "x": -19,
      "y": 14,
      "z": 5,
      "name": "Rock_Ice"
    },
    {
      "x": -19,
      "y": 15,
      "z": 5,
      "name": "Rock_Ice"
    },
    {
      "x": -19,
      "y": 16,
      "z": 5,
      "name": "Rock_Ice"
    },
    {
      "x": -19,
      "y": 17,
      "z": 5,
      "name": "Rock_Ice"
    },
    {
      "x": -19,
      "y": 18,
      "z": 5,
      "name": "Rock_Ice"
    },
    {
      "x": -19,
      "y": 19,
      "z": 5,
      "name": "Rock_Ice"
    },
    {
      "x": -19,
      "y": 20,
      "z": 5,
      "name": "Rock_Ice"
    },
    {
      "x": -19,
      "y": 21,
      "z": 5,
      "name": "Rock_Ice"
    },
    {
      "x": -19,
      "y": 22,
      "z": 5,
      "name": "Rock_Ice"
    },
    {
      "x": -19,
      "y": 23,
      "z": 5,
      "name": "Rock_Ice"
    },
    {
      "x": -19,
      "y": 24,
      "z": 5,
      "name": "Rock_Ice"
    },
    {
      "x": -19,
      "y": 1,
      "z": 6,
      "name": "Rock_Ice"
    },
    {
      "x": -19,
      "y": 2,
      "z": 6,
      "name": "Rock_Ice"
    },
    {
      "x": -19,
      "y": 3,
      "z": 6,
      "name": "Rock_Ice"
    },
    {
      "x": -19,
      "y": 4,
      "z": 6,
      "name": "Rock_Ice"
    },
    {
      "x": -19,
      "y": 5,
      "z": 6,
      "name": "Rock_Ice"
    },
    {
      "x": -19,
      "y": 6,
      "z": 6,
      "name": "Rock_Ice"
    },
    {
      "x": -19,
      "y": 7,
      "z": 6,
      "name": "Rock_Ice"
    },
    {
      "x": -19,
      "y": 8,
      "z": 6,
      "name": "Rock_Ice"
    },
    {
      "x": -19,
      "y": 9,
      "z": 6,
      "name": "Rock_Ice"
    },
    {
      "x": -19,
      "y": 10,
      "z": 6,
      "name": "Rock_Ice"
    },
    {
      "x": -19,
      "y": 11,
      "z": 6,
      "name": "Rock_Ice"
    },
    {
      "x": -19,
      "y": 12,
      "z": 6,
      "name": "Rock_Ice"
    },
    {
      "x": -19,
      "y": 13,
      "z": 6,
      "name": "Rock_Ice"
    },
    {
      "x": -19,
      "y": 14,
      "z": 6,
      "name": "Rock_Ice"
    },
    {
      "x": -19,
      "y": 15,
      "z": 6,
      "name": "Rock_Ice"
    },
    {
      "x": -19,
      "y": 16,
      "z": 6,
      "name": "Rock_Ice"
    },
    {
      "x": -19,
      "y": 17,
      "z": 6,
      "name": "Rock_Ice"
    },
    {
      "x": -19,
      "y": 18,
      "z": 6,
      "name": "Rock_Ice"
    },
    {
      "x": -19,
      "y": 19,
      "z": 6,
      "name": "Rock_Ice"
    },
    {
      "x": -19,
      "y": 20,
      "z": 6,
      "name": "Rock_Ice"
    },
    {
      "x": -19,
      "y": 21,
      "z": 6,
      "name": "Rock_Ice"
    },
    {
      "x": -19,
      "y": 22,
      "z": 6,
      "name": "Rock_Ice"
    },
    {
      "x": -19,
      "y": 23,
      "z": 6,
      "name": "Soil_Snow"
    },
    {
      "x": -19,
      "y": 1,
      "z": 7,
      "name": "Rock_Ice"
    },
    {
      "x": -19,
      "y": 2,
      "z": 7,
      "name": "Rock_Ice"
    },
    {
      "x": -19,
      "y": 3,
      "z": 7,
      "name": "Rock_Ice"
    },
    {
      "x": -19,
      "y": 4,
      "z": 7,
      "name": "Rock_Ice"
    },
    {
      "x": -19,
      "y": 5,
      "z": 7,
      "name": "Rock_Ice"
    },
    {
      "x": -19,
      "y": 6,
      "z": 7,
      "name": "Rock_Ice"
    },
    {
      "x": -19,
      "y": 7,
      "z": 7,
      "name": "Rock_Ice"
    },
    {
      "x": -19,
      "y": 8,
      "z": 7,
      "name": "Rock_Ice"
    },
    {
      "x": -19,
      "y": 9,
      "z": 7,
      "name": "Rock_Ice"
    },
    {
      "x": -19,
      "y": 10,
      "z": 7,
      "name": "Rock_Ice"
    },
    {
      "x": -19,
      "y": 11,
      "z": 7,
      "name": "Rock_Ice"
    },
    {
      "x": -19,
      "y": 12,
      "z": 7,
      "name": "Rock_Ice"
    },
    {
      "x": -19,
      "y": 13,
      "z": 7,
      "name": "Rock_Ice"
    },
    {
      "x": -19,
      "y": 14,
      "z": 7,
      "name": "Rock_Ice"
    },
    {
      "x": -19,
      "y": 15,
      "z": 7,
      "name": "Rock_Ice"
    },
    {
      "x": -19,
      "y": 16,
      "z": 7,
      "name": "Rock_Ice"
    },
    {
      "x": -19,
      "y": 17,
      "z": 7,
      "name": "Rock_Ice"
    },
    {
      "x": -19,
      "y": 18,
      "z": 7,
      "name": "Rock_Ice"
    },
    {
      "x": -19,
      "y": 19,
      "z": 7,
      "name": "Rock_Ice"
    },
    {
      "x": -19,
      "y": 20,
      "z": 7,
      "name": "Soil_Snow"
    },
    {
      "x": -19,
      "y": 1,
      "z": 8,
      "name": "Rock_Ice"
    },
    {
      "x": -19,
      "y": 2,
      "z": 8,
      "name": "Rock_Ice"
    },
    {
      "x": -19,
      "y": 3,
      "z": 8,
      "name": "Rock_Ice"
    },
    {
      "x": -19,
      "y": 4,
      "z": 8,
      "name": "Rock_Ice"
    },
    {
      "x": -19,
      "y": 5,
      "z": 8,
      "name": "Rock_Ice"
    },
    {
      "x": -19,
      "y": 6,
      "z": 8,
      "name": "Rock_Ice"
    },
    {
      "x": -19,
      "y": 7,
      "z": 8,
      "name": "Rock_Ice"
    },
    {
      "x": -19,
      "y": 8,
      "z": 8,
      "name": "Rock_Ice"
    },
    {
      "x": -19,
      "y": 9,
      "z": 8,
      "name": "Rock_Ice"
    },
    {
      "x": -19,
      "y": 10,
      "z": 8,
      "name": "Rock_Ice"
    },
    {
      "x": -19,
      "y": 11,
      "z": 8,
      "name": "Rock_Ice"
    },
    {
      "x": -19,
      "y": 12,
      "z": 8,
      "name": "Rock_Ice"
    },
    {
      "x": -19,
      "y": 13,
      "z": 8,
      "name": "Rock_Ice"
    },
    {
      "x": -19,
      "y": 14,
      "z": 8,
      "name": "Rock_Ice"
    },
    {
      "x": -19,
      "y": 15,
      "z": 8,
      "name": "Rock_Ice"
    },
    {
      "x": -19,
      "y": 16,
      "z": 8,
      "name": "Rock_Ice"
    },
    {
      "x": -19,
      "y": 17,
      "z": 8,
      "name": "Rock_Ice"
    },
    {
      "x": -19,
      "y": 18,
      "z": 8,
      "name": "Soil_Snow"
    },
    {
      "x": -19,
      "y": 1,
      "z": 9,
      "name": "Rock_Ice"
    },
    {
      "x": -19,
      "y": 2,
      "z": 9,
      "name": "Rock_Ice"
    },
    {
      "x": -19,
      "y": 3,
      "z": 9,
      "name": "Rock_Ice"
    },
    {
      "x": -19,
      "y": 4,
      "z": 9,
      "name": "Rock_Ice"
    },
    {
      "x": -19,
      "y": 5,
      "z": 9,
      "name": "Rock_Ice"
    },
    {
      "x": -19,
      "y": 6,
      "z": 9,
      "name": "Rock_Ice"
    },
    {
      "x": -19,
      "y": 7,
      "z": 9,
      "name": "Rock_Ice"
    },
    {
      "x": -19,
      "y": 8,
      "z": 9,
      "name": "Rock_Ice"
    },
    {
      "x": -19,
      "y": 9,
      "z": 9,
      "name": "Rock_Ice"
    },
    {
      "x": -19,
      "y": 10,
      "z": 9,
      "name": "Rock_Ice"
    },
    {
      "x": -19,
      "y": 11,
      "z": 9,
      "name": "Rock_Ice"
    },
    {
      "x": -19,
      "y": 12,
      "z": 9,
      "name": "Rock_Ice"
    },
    {
      "x": -19,
      "y": 13,
      "z": 9,
      "name": "Rock_Ice"
    },
    {
      "x": -19,
      "y": 14,
      "z": 9,
      "name": "Rock_Ice"
    },
    {
      "x": -19,
      "y": 15,
      "z": 9,
      "name": "Rock_Ice"
    },
    {
      "x": -19,
      "y": 16,
      "z": 9,
      "name": "Soil_Snow"
    },
    {
      "x": -19,
      "y": 2,
      "z": 10,
      "name": "Rock_Ice"
    },
    {
      "x": -19,
      "y": 3,
      "z": 10,
      "name": "Rock_Ice"
    },
    {
      "x": -19,
      "y": 4,
      "z": 10,
      "name": "Rock_Ice"
    },
    {
      "x": -19,
      "y": 5,
      "z": 10,
      "name": "Rock_Ice"
    },
    {
      "x": -19,
      "y": 6,
      "z": 10,
      "name": "Rock_Ice"
    },
    {
      "x": -19,
      "y": 7,
      "z": 10,
      "name": "Rock_Ice"
    },
    {
      "x": -19,
      "y": 8,
      "z": 10,
      "name": "Rock_Ice"
    },
    {
      "x": -19,
      "y": 9,
      "z": 10,
      "name": "Rock_Ice"
    },
    {
      "x": -19,
      "y": 10,
      "z": 10,
      "name": "Rock_Ice"
    },
    {
      "x": -19,
      "y": 11,
      "z": 10,
      "name": "Rock_Ice"
    },
    {
      "x": -19,
      "y": 12,
      "z": 10,
      "name": "Rock_Ice"
    },
    {
      "x": -19,
      "y": 13,
      "z": 10,
      "name": "Rock_Ice"
    },
    {
      "x": -19,
      "y": 14,
      "z": 10,
      "name": "Rock_Ice"
    },
    {
      "x": -19,
      "y": 15,
      "z": 10,
      "name": "Soil_Snow"
    },
    {
      "x": -19,
      "y": 6,
      "z": 11,
      "name": "Rock_Ice"
    },
    {
      "x": -19,
      "y": 7,
      "z": 11,
      "name": "Rock_Ice"
    },
    {
      "x": -19,
      "y": 8,
      "z": 11,
      "name": "Rock_Ice"
    },
    {
      "x": -19,
      "y": 9,
      "z": 11,
      "name": "Rock_Ice"
    },
    {
      "x": -19,
      "y": 10,
      "z": 11,
      "name": "Rock_Ice"
    },
    {
      "x": -19,
      "y": 11,
      "z": 11,
      "name": "Rock_Ice"
    },
    {
      "x": -19,
      "y": 12,
      "z": 11,
      "name": "Soil_Snow"
    },
    {
      "x": -19,
      "y": 9,
      "z": 12,
      "name": "Soil_Snow"
    },
    {
      "x": -18,
      "y": 3,
      "z": -1,
      "name": "Rock_Ice"
    },
    {
      "x": -18,
      "y": 4,
      "z": -1,
      "name": "Rock_Ice"
    },
    {
      "x": -18,
      "y": 5,
      "z": -1,
      "name": "Rock_Ice"
    },
    {
      "x": -18,
      "y": 6,
      "z": -1,
      "name": "Rock_Ice"
    },
    {
      "x": -18,
      "y": 7,
      "z": -1,
      "name": "Rock_Ice"
    },
    {
      "x": -18,
      "y": 8,
      "z": -1,
      "name": "Rock_Ice"
    },
    {
      "x": -18,
      "y": 9,
      "z": -1,
      "name": "Rock_Ice"
    },
    {
      "x": -18,
      "y": 10,
      "z": -1,
      "name": "Soil_Snow"
    },
    {
      "x": -18,
      "y": 3,
      "z": 0,
      "name": "Rock_Ice"
    },
    {
      "x": -18,
      "y": 4,
      "z": 0,
      "name": "Rock_Ice"
    },
    {
      "x": -18,
      "y": 5,
      "z": 0,
      "name": "Rock_Ice"
    },
    {
      "x": -18,
      "y": 6,
      "z": 0,
      "name": "Rock_Ice"
    },
    {
      "x": -18,
      "y": 7,
      "z": 0,
      "name": "Rock_Ice"
    },
    {
      "x": -18,
      "y": 8,
      "z": 0,
      "name": "Rock_Ice"
    },
    {
      "x": -18,
      "y": 9,
      "z": 0,
      "name": "Rock_Ice"
    },
    {
      "x": -18,
      "y": 10,
      "z": 0,
      "name": "Rock_Ice"
    },
    {
      "x": -18,
      "y": 11,
      "z": 0,
      "name": "Rock_Ice"
    },
    {
      "x": -18,
      "y": 12,
      "z": 0,
      "name": "Rock_Ice"
    },
    {
      "x": -18,
      "y": 25,
      "z": 0,
      "name": "Soil_Snow"
    },
    {
      "x": -18,
      "y": 2,
      "z": 1,
      "name": "Rock_Ice"
    },
    {
      "x": -18,
      "y": 3,
      "z": 1,
      "name": "Rock_Ice"
    },
    {
      "x": -18,
      "y": 4,
      "z": 1,
      "name": "Rock_Ice"
    },
    {
      "x": -18,
      "y": 5,
      "z": 1,
      "name": "Rock_Ice"
    },
    {
      "x": -18,
      "y": 6,
      "z": 1,
      "name": "Rock_Ice"
    },
    {
      "x": -18,
      "y": 7,
      "z": 1,
      "name": "Rock_Ice"
    },
    {
      "x": -18,
      "y": 8,
      "z": 1,
      "name": "Rock_Ice"
    },
    {
      "x": -18,
      "y": 9,
      "z": 1,
      "name": "Rock_Ice"
    },
    {
      "x": -18,
      "y": 10,
      "z": 1,
      "name": "Rock_Ice"
    },
    {
      "x": -18,
      "y": 11,
      "z": 1,
      "name": "Rock_Ice"
    },
    {
      "x": -18,
      "y": 12,
      "z": 1,
      "name": "Rock_Ice"
    },
    {
      "x": -18,
      "y": 13,
      "z": 1,
      "name": "Rock_Ice"
    },
    {
      "x": -18,
      "y": 14,
      "z": 1,
      "name": "Rock_Ice"
    },
    {
      "x": -18,
      "y": 15,
      "z": 1,
      "name": "Rock_Ice"
    },
    {
      "x": -18,
      "y": 16,
      "z": 1,
      "name": "Rock_Ice"
    },
    {
      "x": -18,
      "y": 17,
      "z": 1,
      "name": "Rock_Ice"
    },
    {
      "x": -18,
      "y": 18,
      "z": 1,
      "name": "Rock_Ice"
    },
    {
      "x": -18,
      "y": 19,
      "z": 1,
      "name": "Rock_Ice"
    },
    {
      "x": -18,
      "y": 20,
      "z": 1,
      "name": "Rock_Ice"
    },
    {
      "x": -18,
      "y": 21,
      "z": 1,
      "name": "Rock_Ice"
    },
    {
      "x": -18,
      "y": 22,
      "z": 1,
      "name": "Rock_Ice"
    },
    {
      "x": -18,
      "y": 23,
      "z": 1,
      "name": "Rock_Ice"
    },
    {
      "x": -18,
      "y": 24,
      "z": 1,
      "name": "Rock_Ice"
    },
    {
      "x": -18,
      "y": 25,
      "z": 1,
      "name": "Soil_Snow"
    },
    {
      "x": -18,
      "y": 2,
      "z": 2,
      "name": "Rock_Ice"
    },
    {
      "x": -18,
      "y": 3,
      "z": 2,
      "name": "Rock_Ice"
    },
    {
      "x": -18,
      "y": 4,
      "z": 2,
      "name": "Rock_Ice"
    },
    {
      "x": -18,
      "y": 5,
      "z": 2,
      "name": "Rock_Ice"
    },
    {
      "x": -18,
      "y": 6,
      "z": 2,
      "name": "Rock_Ice"
    },
    {
      "x": -18,
      "y": 7,
      "z": 2,
      "name": "Rock_Ice"
    },
    {
      "x": -18,
      "y": 8,
      "z": 2,
      "name": "Rock_Ice"
    },
    {
      "x": -18,
      "y": 9,
      "z": 2,
      "name": "Rock_Ice"
    },
    {
      "x": -18,
      "y": 10,
      "z": 2,
      "name": "Rock_Ice"
    },
    {
      "x": -18,
      "y": 11,
      "z": 2,
      "name": "Rock_Ice"
    },
    {
      "x": -18,
      "y": 12,
      "z": 2,
      "name": "Rock_Ice"
    },
    {
      "x": -18,
      "y": 13,
      "z": 2,
      "name": "Rock_Ice"
    },
    {
      "x": -18,
      "y": 14,
      "z": 2,
      "name": "Rock_Ice"
    },
    {
      "x": -18,
      "y": 15,
      "z": 2,
      "name": "Rock_Ice"
    },
    {
      "x": -18,
      "y": 16,
      "z": 2,
      "name": "Rock_Ice"
    },
    {
      "x": -18,
      "y": 17,
      "z": 2,
      "name": "Rock_Ice"
    },
    {
      "x": -18,
      "y": 18,
      "z": 2,
      "name": "Rock_Ice"
    },
    {
      "x": -18,
      "y": 19,
      "z": 2,
      "name": "Rock_Ice"
    },
    {
      "x": -18,
      "y": 20,
      "z": 2,
      "name": "Rock_Ice"
    },
    {
      "x": -18,
      "y": 21,
      "z": 2,
      "name": "Rock_Ice"
    },
    {
      "x": -18,
      "y": 22,
      "z": 2,
      "name": "Rock_Ice"
    },
    {
      "x": -18,
      "y": 23,
      "z": 2,
      "name": "Rock_Ice"
    },
    {
      "x": -18,
      "y": 24,
      "z": 2,
      "name": "Rock_Ice"
    },
    {
      "x": -18,
      "y": 25,
      "z": 2,
      "name": "Soil_Snow"
    },
    {
      "x": -18,
      "y": 2,
      "z": 3,
      "name": "Rock_Ice"
    },
    {
      "x": -18,
      "y": 3,
      "z": 3,
      "name": "Rock_Ice"
    },
    {
      "x": -18,
      "y": 4,
      "z": 3,
      "name": "Rock_Ice"
    },
    {
      "x": -18,
      "y": 5,
      "z": 3,
      "name": "Rock_Ice"
    },
    {
      "x": -18,
      "y": 6,
      "z": 3,
      "name": "Rock_Ice"
    },
    {
      "x": -18,
      "y": 7,
      "z": 3,
      "name": "Rock_Ice"
    },
    {
      "x": -18,
      "y": 8,
      "z": 3,
      "name": "Rock_Ice"
    },
    {
      "x": -18,
      "y": 9,
      "z": 3,
      "name": "Rock_Ice"
    },
    {
      "x": -18,
      "y": 10,
      "z": 3,
      "name": "Rock_Ice"
    },
    {
      "x": -18,
      "y": 11,
      "z": 3,
      "name": "Rock_Ice"
    },
    {
      "x": -18,
      "y": 12,
      "z": 3,
      "name": "Rock_Ice"
    },
    {
      "x": -18,
      "y": 13,
      "z": 3,
      "name": "Rock_Ice"
    },
    {
      "x": -18,
      "y": 14,
      "z": 3,
      "name": "Rock_Ice"
    },
    {
      "x": -18,
      "y": 15,
      "z": 3,
      "name": "Rock_Ice"
    },
    {
      "x": -18,
      "y": 16,
      "z": 3,
      "name": "Rock_Ice"
    },
    {
      "x": -18,
      "y": 17,
      "z": 3,
      "name": "Rock_Ice"
    },
    {
      "x": -18,
      "y": 18,
      "z": 3,
      "name": "Rock_Ice"
    },
    {
      "x": -18,
      "y": 19,
      "z": 3,
      "name": "Rock_Ice"
    },
    {
      "x": -18,
      "y": 20,
      "z": 3,
      "name": "Rock_Ice"
    },
    {
      "x": -18,
      "y": 21,
      "z": 3,
      "name": "Rock_Ice"
    },
    {
      "x": -18,
      "y": 22,
      "z": 3,
      "name": "Rock_Ice"
    },
    {
      "x": -18,
      "y": 23,
      "z": 3,
      "name": "Rock_Ice"
    },
    {
      "x": -18,
      "y": 24,
      "z": 3,
      "name": "Rock_Ice"
    },
    {
      "x": -18,
      "y": 25,
      "z": 3,
      "name": "Rock_Ice"
    },
    {
      "x": -18,
      "y": 1,
      "z": 4,
      "name": "Rock_Ice"
    },
    {
      "x": -18,
      "y": 2,
      "z": 4,
      "name": "Rock_Ice"
    },
    {
      "x": -18,
      "y": 3,
      "z": 4,
      "name": "Rock_Ice"
    },
    {
      "x": -18,
      "y": 4,
      "z": 4,
      "name": "Rock_Ice"
    },
    {
      "x": -18,
      "y": 5,
      "z": 4,
      "name": "Rock_Ice"
    },
    {
      "x": -18,
      "y": 6,
      "z": 4,
      "name": "Rock_Ice"
    },
    {
      "x": -18,
      "y": 7,
      "z": 4,
      "name": "Rock_Ice"
    },
    {
      "x": -18,
      "y": 8,
      "z": 4,
      "name": "Rock_Ice"
    },
    {
      "x": -18,
      "y": 9,
      "z": 4,
      "name": "Rock_Ice"
    },
    {
      "x": -18,
      "y": 10,
      "z": 4,
      "name": "Rock_Ice"
    },
    {
      "x": -18,
      "y": 11,
      "z": 4,
      "name": "Rock_Ice"
    },
    {
      "x": -18,
      "y": 12,
      "z": 4,
      "name": "Rock_Ice"
    },
    {
      "x": -18,
      "y": 13,
      "z": 4,
      "name": "Rock_Ice"
    },
    {
      "x": -18,
      "y": 14,
      "z": 4,
      "name": "Rock_Ice"
    },
    {
      "x": -18,
      "y": 15,
      "z": 4,
      "name": "Rock_Ice"
    },
    {
      "x": -18,
      "y": 16,
      "z": 4,
      "name": "Rock_Ice"
    },
    {
      "x": -18,
      "y": 17,
      "z": 4,
      "name": "Rock_Ice"
    },
    {
      "x": -18,
      "y": 18,
      "z": 4,
      "name": "Rock_Ice"
    },
    {
      "x": -18,
      "y": 19,
      "z": 4,
      "name": "Rock_Ice"
    },
    {
      "x": -18,
      "y": 20,
      "z": 4,
      "name": "Rock_Ice"
    },
    {
      "x": -18,
      "y": 21,
      "z": 4,
      "name": "Rock_Ice"
    },
    {
      "x": -18,
      "y": 22,
      "z": 4,
      "name": "Rock_Ice"
    },
    {
      "x": -18,
      "y": 23,
      "z": 4,
      "name": "Rock_Ice"
    },
    {
      "x": -18,
      "y": 24,
      "z": 4,
      "name": "Rock_Ice"
    },
    {
      "x": -18,
      "y": 25,
      "z": 4,
      "name": "Rock_Ice"
    },
    {
      "x": -18,
      "y": 1,
      "z": 5,
      "name": "Rock_Ice"
    },
    {
      "x": -18,
      "y": 2,
      "z": 5,
      "name": "Rock_Ice"
    },
    {
      "x": -18,
      "y": 3,
      "z": 5,
      "name": "Rock_Ice"
    },
    {
      "x": -18,
      "y": 4,
      "z": 5,
      "name": "Rock_Ice"
    },
    {
      "x": -18,
      "y": 5,
      "z": 5,
      "name": "Rock_Ice"
    },
    {
      "x": -18,
      "y": 6,
      "z": 5,
      "name": "Rock_Ice"
    },
    {
      "x": -18,
      "y": 7,
      "z": 5,
      "name": "Rock_Ice"
    },
    {
      "x": -18,
      "y": 8,
      "z": 5,
      "name": "Rock_Ice"
    },
    {
      "x": -18,
      "y": 9,
      "z": 5,
      "name": "Rock_Ice"
    },
    {
      "x": -18,
      "y": 10,
      "z": 5,
      "name": "Rock_Ice"
    },
    {
      "x": -18,
      "y": 11,
      "z": 5,
      "name": "Rock_Ice"
    },
    {
      "x": -18,
      "y": 12,
      "z": 5,
      "name": "Rock_Ice"
    },
    {
      "x": -18,
      "y": 13,
      "z": 5,
      "name": "Rock_Ice"
    },
    {
      "x": -18,
      "y": 14,
      "z": 5,
      "name": "Rock_Ice"
    },
    {
      "x": -18,
      "y": 15,
      "z": 5,
      "name": "Rock_Ice"
    },
    {
      "x": -18,
      "y": 16,
      "z": 5,
      "name": "Rock_Ice"
    },
    {
      "x": -18,
      "y": 17,
      "z": 5,
      "name": "Rock_Ice"
    },
    {
      "x": -18,
      "y": 18,
      "z": 5,
      "name": "Rock_Ice"
    },
    {
      "x": -18,
      "y": 19,
      "z": 5,
      "name": "Rock_Ice"
    },
    {
      "x": -18,
      "y": 20,
      "z": 5,
      "name": "Rock_Ice"
    },
    {
      "x": -18,
      "y": 21,
      "z": 5,
      "name": "Rock_Ice"
    },
    {
      "x": -18,
      "y": 22,
      "z": 5,
      "name": "Rock_Ice"
    },
    {
      "x": -18,
      "y": 23,
      "z": 5,
      "name": "Rock_Ice"
    },
    {
      "x": -18,
      "y": 24,
      "z": 5,
      "name": "Rock_Ice"
    },
    {
      "x": -18,
      "y": 1,
      "z": 6,
      "name": "Rock_Ice"
    },
    {
      "x": -18,
      "y": 2,
      "z": 6,
      "name": "Rock_Ice"
    },
    {
      "x": -18,
      "y": 3,
      "z": 6,
      "name": "Rock_Ice"
    },
    {
      "x": -18,
      "y": 4,
      "z": 6,
      "name": "Rock_Ice"
    },
    {
      "x": -18,
      "y": 5,
      "z": 6,
      "name": "Rock_Ice"
    },
    {
      "x": -18,
      "y": 6,
      "z": 6,
      "name": "Rock_Ice"
    },
    {
      "x": -18,
      "y": 7,
      "z": 6,
      "name": "Rock_Ice"
    },
    {
      "x": -18,
      "y": 8,
      "z": 6,
      "name": "Rock_Ice"
    },
    {
      "x": -18,
      "y": 9,
      "z": 6,
      "name": "Rock_Ice"
    },
    {
      "x": -18,
      "y": 10,
      "z": 6,
      "name": "Rock_Ice"
    },
    {
      "x": -18,
      "y": 11,
      "z": 6,
      "name": "Rock_Ice"
    },
    {
      "x": -18,
      "y": 12,
      "z": 6,
      "name": "Rock_Ice"
    },
    {
      "x": -18,
      "y": 13,
      "z": 6,
      "name": "Rock_Ice"
    },
    {
      "x": -18,
      "y": 14,
      "z": 6,
      "name": "Rock_Ice"
    },
    {
      "x": -18,
      "y": 15,
      "z": 6,
      "name": "Rock_Ice"
    },
    {
      "x": -18,
      "y": 16,
      "z": 6,
      "name": "Rock_Ice"
    },
    {
      "x": -18,
      "y": 17,
      "z": 6,
      "name": "Rock_Ice"
    },
    {
      "x": -18,
      "y": 18,
      "z": 6,
      "name": "Rock_Ice"
    },
    {
      "x": -18,
      "y": 19,
      "z": 6,
      "name": "Rock_Ice"
    },
    {
      "x": -18,
      "y": 20,
      "z": 6,
      "name": "Rock_Ice"
    },
    {
      "x": -18,
      "y": 21,
      "z": 6,
      "name": "Rock_Ice"
    },
    {
      "x": -18,
      "y": 22,
      "z": 6,
      "name": "Rock_Ice"
    },
    {
      "x": -18,
      "y": 23,
      "z": 6,
      "name": "Rock_Ice"
    },
    {
      "x": -18,
      "y": 24,
      "z": 6,
      "name": "Rock_Ice"
    },
    {
      "x": -18,
      "y": 1,
      "z": 7,
      "name": "Rock_Ice"
    },
    {
      "x": -18,
      "y": 2,
      "z": 7,
      "name": "Rock_Ice"
    },
    {
      "x": -18,
      "y": 3,
      "z": 7,
      "name": "Rock_Ice"
    },
    {
      "x": -18,
      "y": 4,
      "z": 7,
      "name": "Rock_Ice"
    },
    {
      "x": -18,
      "y": 5,
      "z": 7,
      "name": "Rock_Ice"
    },
    {
      "x": -18,
      "y": 6,
      "z": 7,
      "name": "Rock_Ice"
    },
    {
      "x": -18,
      "y": 7,
      "z": 7,
      "name": "Rock_Ice"
    },
    {
      "x": -18,
      "y": 8,
      "z": 7,
      "name": "Rock_Ice"
    },
    {
      "x": -18,
      "y": 9,
      "z": 7,
      "name": "Rock_Ice"
    },
    {
      "x": -18,
      "y": 10,
      "z": 7,
      "name": "Rock_Ice"
    },
    {
      "x": -18,
      "y": 11,
      "z": 7,
      "name": "Rock_Ice"
    },
    {
      "x": -18,
      "y": 12,
      "z": 7,
      "name": "Rock_Ice"
    },
    {
      "x": -18,
      "y": 13,
      "z": 7,
      "name": "Rock_Ice"
    },
    {
      "x": -18,
      "y": 14,
      "z": 7,
      "name": "Rock_Ice"
    },
    {
      "x": -18,
      "y": 15,
      "z": 7,
      "name": "Rock_Ice"
    },
    {
      "x": -18,
      "y": 16,
      "z": 7,
      "name": "Rock_Ice"
    },
    {
      "x": -18,
      "y": 17,
      "z": 7,
      "name": "Rock_Ice"
    },
    {
      "x": -18,
      "y": 18,
      "z": 7,
      "name": "Rock_Ice"
    },
    {
      "x": -18,
      "y": 19,
      "z": 7,
      "name": "Rock_Ice"
    },
    {
      "x": -18,
      "y": 20,
      "z": 7,
      "name": "Rock_Ice"
    },
    {
      "x": -18,
      "y": 21,
      "z": 7,
      "name": "Rock_Ice"
    },
    {
      "x": -18,
      "y": 22,
      "z": 7,
      "name": "Rock_Ice"
    },
    {
      "x": -18,
      "y": 23,
      "z": 7,
      "name": "Rock_Ice"
    },
    {
      "x": -18,
      "y": 1,
      "z": 8,
      "name": "Rock_Ice"
    },
    {
      "x": -18,
      "y": 2,
      "z": 8,
      "name": "Rock_Ice"
    },
    {
      "x": -18,
      "y": 3,
      "z": 8,
      "name": "Rock_Ice"
    },
    {
      "x": -18,
      "y": 4,
      "z": 8,
      "name": "Rock_Ice"
    },
    {
      "x": -18,
      "y": 5,
      "z": 8,
      "name": "Rock_Ice"
    },
    {
      "x": -18,
      "y": 6,
      "z": 8,
      "name": "Rock_Ice"
    },
    {
      "x": -18,
      "y": 7,
      "z": 8,
      "name": "Rock_Ice"
    },
    {
      "x": -18,
      "y": 8,
      "z": 8,
      "name": "Rock_Ice"
    },
    {
      "x": -18,
      "y": 9,
      "z": 8,
      "name": "Rock_Ice"
    },
    {
      "x": -18,
      "y": 10,
      "z": 8,
      "name": "Rock_Ice"
    },
    {
      "x": -18,
      "y": 11,
      "z": 8,
      "name": "Rock_Ice"
    },
    {
      "x": -18,
      "y": 12,
      "z": 8,
      "name": "Rock_Ice"
    },
    {
      "x": -18,
      "y": 13,
      "z": 8,
      "name": "Rock_Ice"
    },
    {
      "x": -18,
      "y": 14,
      "z": 8,
      "name": "Rock_Ice"
    },
    {
      "x": -18,
      "y": 15,
      "z": 8,
      "name": "Rock_Ice"
    },
    {
      "x": -18,
      "y": 16,
      "z": 8,
      "name": "Rock_Ice"
    },
    {
      "x": -18,
      "y": 17,
      "z": 8,
      "name": "Rock_Ice"
    },
    {
      "x": -18,
      "y": 18,
      "z": 8,
      "name": "Rock_Ice"
    },
    {
      "x": -18,
      "y": 19,
      "z": 8,
      "name": "Rock_Ice"
    },
    {
      "x": -18,
      "y": 20,
      "z": 8,
      "name": "Rock_Ice"
    },
    {
      "x": -18,
      "y": 21,
      "z": 8,
      "name": "Soil_Snow"
    },
    {
      "x": -18,
      "y": 1,
      "z": 9,
      "name": "Rock_Ice"
    },
    {
      "x": -18,
      "y": 2,
      "z": 9,
      "name": "Rock_Ice"
    },
    {
      "x": -18,
      "y": 3,
      "z": 9,
      "name": "Rock_Ice"
    },
    {
      "x": -18,
      "y": 4,
      "z": 9,
      "name": "Rock_Ice"
    },
    {
      "x": -18,
      "y": 5,
      "z": 9,
      "name": "Rock_Ice"
    },
    {
      "x": -18,
      "y": 6,
      "z": 9,
      "name": "Rock_Ice"
    },
    {
      "x": -18,
      "y": 7,
      "z": 9,
      "name": "Rock_Ice"
    },
    {
      "x": -18,
      "y": 8,
      "z": 9,
      "name": "Rock_Ice"
    },
    {
      "x": -18,
      "y": 9,
      "z": 9,
      "name": "Rock_Ice"
    },
    {
      "x": -18,
      "y": 10,
      "z": 9,
      "name": "Rock_Ice"
    },
    {
      "x": -18,
      "y": 11,
      "z": 9,
      "name": "Rock_Ice"
    },
    {
      "x": -18,
      "y": 12,
      "z": 9,
      "name": "Rock_Ice"
    },
    {
      "x": -18,
      "y": 13,
      "z": 9,
      "name": "Rock_Ice"
    },
    {
      "x": -18,
      "y": 14,
      "z": 9,
      "name": "Rock_Ice"
    },
    {
      "x": -18,
      "y": 15,
      "z": 9,
      "name": "Rock_Ice"
    },
    {
      "x": -18,
      "y": 16,
      "z": 9,
      "name": "Rock_Ice"
    },
    {
      "x": -18,
      "y": 17,
      "z": 9,
      "name": "Rock_Ice"
    },
    {
      "x": -18,
      "y": 18,
      "z": 9,
      "name": "Soil_Snow"
    },
    {
      "x": -18,
      "y": 1,
      "z": 10,
      "name": "Rock_Ice"
    },
    {
      "x": -18,
      "y": 2,
      "z": 10,
      "name": "Rock_Ice"
    },
    {
      "x": -18,
      "y": 3,
      "z": 10,
      "name": "Rock_Ice"
    },
    {
      "x": -18,
      "y": 4,
      "z": 10,
      "name": "Rock_Ice"
    },
    {
      "x": -18,
      "y": 5,
      "z": 10,
      "name": "Rock_Ice"
    },
    {
      "x": -18,
      "y": 6,
      "z": 10,
      "name": "Rock_Ice"
    },
    {
      "x": -18,
      "y": 7,
      "z": 10,
      "name": "Rock_Ice"
    },
    {
      "x": -18,
      "y": 8,
      "z": 10,
      "name": "Rock_Ice"
    },
    {
      "x": -18,
      "y": 9,
      "z": 10,
      "name": "Rock_Ice"
    },
    {
      "x": -18,
      "y": 10,
      "z": 10,
      "name": "Rock_Ice"
    },
    {
      "x": -18,
      "y": 11,
      "z": 10,
      "name": "Rock_Ice"
    },
    {
      "x": -18,
      "y": 12,
      "z": 10,
      "name": "Rock_Ice"
    },
    {
      "x": -18,
      "y": 13,
      "z": 10,
      "name": "Rock_Ice"
    },
    {
      "x": -18,
      "y": 14,
      "z": 10,
      "name": "Rock_Ice"
    },
    {
      "x": -18,
      "y": 15,
      "z": 10,
      "name": "Rock_Ice"
    },
    {
      "x": -18,
      "y": 16,
      "z": 10,
      "name": "Soil_Snow"
    },
    {
      "x": -18,
      "y": 4,
      "z": 11,
      "name": "Rock_Ice"
    },
    {
      "x": -18,
      "y": 5,
      "z": 11,
      "name": "Rock_Ice"
    },
    {
      "x": -18,
      "y": 6,
      "z": 11,
      "name": "Rock_Ice"
    },
    {
      "x": -18,
      "y": 7,
      "z": 11,
      "name": "Rock_Ice"
    },
    {
      "x": -18,
      "y": 8,
      "z": 11,
      "name": "Rock_Ice"
    },
    {
      "x": -18,
      "y": 9,
      "z": 11,
      "name": "Rock_Ice"
    },
    {
      "x": -18,
      "y": 10,
      "z": 11,
      "name": "Rock_Ice"
    },
    {
      "x": -18,
      "y": 11,
      "z": 11,
      "name": "Rock_Ice"
    },
    {
      "x": -18,
      "y": 12,
      "z": 11,
      "name": "Rock_Ice"
    },
    {
      "x": -18,
      "y": 13,
      "z": 11,
      "name": "Rock_Ice"
    },
    {
      "x": -18,
      "y": 14,
      "z": 11,
      "name": "Soil_Snow"
    },
    {
      "x": -18,
      "y": 8,
      "z": 12,
      "name": "Rock_Ice"
    },
    {
      "x": -18,
      "y": 9,
      "z": 12,
      "name": "Rock_Ice"
    },
    {
      "x": -18,
      "y": 10,
      "z": 12,
      "name": "Rock_Ice"
    },
    {
      "x": -18,
      "y": 11,
      "z": 12,
      "name": "Soil_Snow"
    },
    {
      "x": -17,
      "y": 3,
      "z": -2,
      "name": "Rock_Ice"
    },
    {
      "x": -17,
      "y": 4,
      "z": -2,
      "name": "Rock_Ice"
    },
    {
      "x": -17,
      "y": 5,
      "z": -2,
      "name": "Rock_Ice"
    },
    {
      "x": -17,
      "y": 6,
      "z": -2,
      "name": "Rock_Ice"
    },
    {
      "x": -17,
      "y": 7,
      "z": -2,
      "name": "Rock_Ice"
    },
    {
      "x": -17,
      "y": 8,
      "z": -2,
      "name": "Rock_Ice"
    },
    {
      "x": -17,
      "y": 9,
      "z": -2,
      "name": "Soil_Snow"
    },
    {
      "x": -17,
      "y": 3,
      "z": -1,
      "name": "Rock_Ice"
    },
    {
      "x": -17,
      "y": 4,
      "z": -1,
      "name": "Rock_Ice"
    },
    {
      "x": -17,
      "y": 5,
      "z": -1,
      "name": "Rock_Ice"
    },
    {
      "x": -17,
      "y": 6,
      "z": -1,
      "name": "Rock_Ice"
    },
    {
      "x": -17,
      "y": 7,
      "z": -1,
      "name": "Rock_Ice"
    },
    {
      "x": -17,
      "y": 8,
      "z": -1,
      "name": "Rock_Ice"
    },
    {
      "x": -17,
      "y": 9,
      "z": -1,
      "name": "Rock_Ice"
    },
    {
      "x": -17,
      "y": 10,
      "z": -1,
      "name": "Rock_Ice"
    },
    {
      "x": -17,
      "y": 11,
      "z": -1,
      "name": "Rock_Ice"
    },
    {
      "x": -17,
      "y": 12,
      "z": -1,
      "name": "Rock_Ice"
    },
    {
      "x": -17,
      "y": 25,
      "z": -1,
      "name": "Rock_Ice"
    },
    {
      "x": -17,
      "y": 26,
      "z": -1,
      "name": "Soil_Snow"
    },
    {
      "x": -17,
      "y": 2,
      "z": 0,
      "name": "Rock_Ice"
    },
    {
      "x": -17,
      "y": 3,
      "z": 0,
      "name": "Rock_Ice"
    },
    {
      "x": -17,
      "y": 4,
      "z": 0,
      "name": "Rock_Ice"
    },
    {
      "x": -17,
      "y": 5,
      "z": 0,
      "name": "Rock_Ice"
    },
    {
      "x": -17,
      "y": 6,
      "z": 0,
      "name": "Rock_Ice"
    },
    {
      "x": -17,
      "y": 7,
      "z": 0,
      "name": "Rock_Ice"
    },
    {
      "x": -17,
      "y": 8,
      "z": 0,
      "name": "Rock_Ice"
    },
    {
      "x": -17,
      "y": 9,
      "z": 0,
      "name": "Rock_Ice"
    },
    {
      "x": -17,
      "y": 10,
      "z": 0,
      "name": "Rock_Ice"
    },
    {
      "x": -17,
      "y": 11,
      "z": 0,
      "name": "Rock_Ice"
    },
    {
      "x": -17,
      "y": 12,
      "z": 0,
      "name": "Rock_Ice"
    },
    {
      "x": -17,
      "y": 13,
      "z": 0,
      "name": "Rock_Ice"
    },
    {
      "x": -17,
      "y": 14,
      "z": 0,
      "name": "Rock_Ice"
    },
    {
      "x": -17,
      "y": 15,
      "z": 0,
      "name": "Rock_Ice"
    },
    {
      "x": -17,
      "y": 16,
      "z": 0,
      "name": "Rock_Ice"
    },
    {
      "x": -17,
      "y": 17,
      "z": 0,
      "name": "Rock_Ice"
    },
    {
      "x": -17,
      "y": 18,
      "z": 0,
      "name": "Rock_Ice"
    },
    {
      "x": -17,
      "y": 19,
      "z": 0,
      "name": "Rock_Ice"
    },
    {
      "x": -17,
      "y": 20,
      "z": 0,
      "name": "Rock_Ice"
    },
    {
      "x": -17,
      "y": 21,
      "z": 0,
      "name": "Rock_Ice"
    },
    {
      "x": -17,
      "y": 22,
      "z": 0,
      "name": "Rock_Ice"
    },
    {
      "x": -17,
      "y": 23,
      "z": 0,
      "name": "Rock_Ice"
    },
    {
      "x": -17,
      "y": 24,
      "z": 0,
      "name": "Rock_Ice"
    },
    {
      "x": -17,
      "y": 25,
      "z": 0,
      "name": "Rock_Ice"
    },
    {
      "x": -17,
      "y": 26,
      "z": 0,
      "name": "Soil_Snow"
    },
    {
      "x": -17,
      "y": 2,
      "z": 1,
      "name": "Rock_Ice"
    },
    {
      "x": -17,
      "y": 3,
      "z": 1,
      "name": "Rock_Ice"
    },
    {
      "x": -17,
      "y": 4,
      "z": 1,
      "name": "Rock_Ice"
    },
    {
      "x": -17,
      "y": 5,
      "z": 1,
      "name": "Rock_Ice"
    },
    {
      "x": -17,
      "y": 6,
      "z": 1,
      "name": "Rock_Ice"
    },
    {
      "x": -17,
      "y": 7,
      "z": 1,
      "name": "Rock_Ice"
    },
    {
      "x": -17,
      "y": 8,
      "z": 1,
      "name": "Rock_Ice"
    },
    {
      "x": -17,
      "y": 9,
      "z": 1,
      "name": "Rock_Ice"
    },
    {
      "x": -17,
      "y": 10,
      "z": 1,
      "name": "Rock_Ice"
    },
    {
      "x": -17,
      "y": 11,
      "z": 1,
      "name": "Rock_Ice"
    },
    {
      "x": -17,
      "y": 12,
      "z": 1,
      "name": "Rock_Ice"
    },
    {
      "x": -17,
      "y": 13,
      "z": 1,
      "name": "Rock_Ice"
    },
    {
      "x": -17,
      "y": 14,
      "z": 1,
      "name": "Rock_Ice"
    },
    {
      "x": -17,
      "y": 15,
      "z": 1,
      "name": "Rock_Ice"
    },
    {
      "x": -17,
      "y": 16,
      "z": 1,
      "name": "Rock_Ice"
    },
    {
      "x": -17,
      "y": 17,
      "z": 1,
      "name": "Rock_Ice"
    },
    {
      "x": -17,
      "y": 18,
      "z": 1,
      "name": "Rock_Ice"
    },
    {
      "x": -17,
      "y": 19,
      "z": 1,
      "name": "Rock_Ice"
    },
    {
      "x": -17,
      "y": 20,
      "z": 1,
      "name": "Rock_Ice"
    },
    {
      "x": -17,
      "y": 21,
      "z": 1,
      "name": "Rock_Ice"
    },
    {
      "x": -17,
      "y": 22,
      "z": 1,
      "name": "Rock_Ice"
    },
    {
      "x": -17,
      "y": 23,
      "z": 1,
      "name": "Rock_Ice"
    },
    {
      "x": -17,
      "y": 24,
      "z": 1,
      "name": "Rock_Ice"
    },
    {
      "x": -17,
      "y": 25,
      "z": 1,
      "name": "Rock_Ice"
    },
    {
      "x": -17,
      "y": 26,
      "z": 1,
      "name": "Soil_Snow"
    },
    {
      "x": -17,
      "y": 2,
      "z": 2,
      "name": "Rock_Ice"
    },
    {
      "x": -17,
      "y": 3,
      "z": 2,
      "name": "Rock_Ice"
    },
    {
      "x": -17,
      "y": 4,
      "z": 2,
      "name": "Rock_Ice"
    },
    {
      "x": -17,
      "y": 5,
      "z": 2,
      "name": "Rock_Ice"
    },
    {
      "x": -17,
      "y": 6,
      "z": 2,
      "name": "Rock_Ice"
    },
    {
      "x": -17,
      "y": 7,
      "z": 2,
      "name": "Rock_Ice"
    },
    {
      "x": -17,
      "y": 8,
      "z": 2,
      "name": "Rock_Ice"
    },
    {
      "x": -17,
      "y": 9,
      "z": 2,
      "name": "Rock_Ice"
    },
    {
      "x": -17,
      "y": 10,
      "z": 2,
      "name": "Rock_Ice"
    },
    {
      "x": -17,
      "y": 11,
      "z": 2,
      "name": "Rock_Ice"
    },
    {
      "x": -17,
      "y": 12,
      "z": 2,
      "name": "Rock_Ice"
    },
    {
      "x": -17,
      "y": 13,
      "z": 2,
      "name": "Rock_Ice"
    },
    {
      "x": -17,
      "y": 14,
      "z": 2,
      "name": "Rock_Ice"
    },
    {
      "x": -17,
      "y": 15,
      "z": 2,
      "name": "Rock_Ice"
    },
    {
      "x": -17,
      "y": 16,
      "z": 2,
      "name": "Rock_Ice"
    },
    {
      "x": -17,
      "y": 17,
      "z": 2,
      "name": "Rock_Ice"
    },
    {
      "x": -17,
      "y": 18,
      "z": 2,
      "name": "Rock_Ice"
    },
    {
      "x": -17,
      "y": 19,
      "z": 2,
      "name": "Rock_Ice"
    },
    {
      "x": -17,
      "y": 20,
      "z": 2,
      "name": "Rock_Ice"
    },
    {
      "x": -17,
      "y": 21,
      "z": 2,
      "name": "Rock_Ice"
    },
    {
      "x": -17,
      "y": 22,
      "z": 2,
      "name": "Rock_Ice"
    },
    {
      "x": -17,
      "y": 23,
      "z": 2,
      "name": "Rock_Ice"
    },
    {
      "x": -17,
      "y": 24,
      "z": 2,
      "name": "Rock_Ice"
    },
    {
      "x": -17,
      "y": 25,
      "z": 2,
      "name": "Rock_Ice"
    },
    {
      "x": -17,
      "y": 1,
      "z": 3,
      "name": "Rock_Ice"
    },
    {
      "x": -17,
      "y": 2,
      "z": 3,
      "name": "Rock_Ice"
    },
    {
      "x": -17,
      "y": 3,
      "z": 3,
      "name": "Rock_Ice"
    },
    {
      "x": -17,
      "y": 4,
      "z": 3,
      "name": "Rock_Ice"
    },
    {
      "x": -17,
      "y": 5,
      "z": 3,
      "name": "Rock_Ice"
    },
    {
      "x": -17,
      "y": 6,
      "z": 3,
      "name": "Rock_Ice"
    },
    {
      "x": -17,
      "y": 7,
      "z": 3,
      "name": "Rock_Ice"
    },
    {
      "x": -17,
      "y": 8,
      "z": 3,
      "name": "Rock_Ice"
    },
    {
      "x": -17,
      "y": 9,
      "z": 3,
      "name": "Rock_Ice"
    },
    {
      "x": -17,
      "y": 10,
      "z": 3,
      "name": "Rock_Ice"
    },
    {
      "x": -17,
      "y": 11,
      "z": 3,
      "name": "Rock_Ice"
    },
    {
      "x": -17,
      "y": 12,
      "z": 3,
      "name": "Rock_Ice"
    },
    {
      "x": -17,
      "y": 13,
      "z": 3,
      "name": "Rock_Ice"
    },
    {
      "x": -17,
      "y": 14,
      "z": 3,
      "name": "Rock_Ice"
    },
    {
      "x": -17,
      "y": 15,
      "z": 3,
      "name": "Rock_Ice"
    },
    {
      "x": -17,
      "y": 16,
      "z": 3,
      "name": "Rock_Ice"
    },
    {
      "x": -17,
      "y": 17,
      "z": 3,
      "name": "Rock_Ice"
    },
    {
      "x": -17,
      "y": 18,
      "z": 3,
      "name": "Rock_Ice"
    },
    {
      "x": -17,
      "y": 19,
      "z": 3,
      "name": "Rock_Ice"
    },
    {
      "x": -17,
      "y": 20,
      "z": 3,
      "name": "Rock_Ice"
    },
    {
      "x": -17,
      "y": 21,
      "z": 3,
      "name": "Rock_Ice"
    },
    {
      "x": -17,
      "y": 22,
      "z": 3,
      "name": "Rock_Ice"
    },
    {
      "x": -17,
      "y": 23,
      "z": 3,
      "name": "Rock_Ice"
    },
    {
      "x": -17,
      "y": 24,
      "z": 3,
      "name": "Rock_Ice"
    },
    {
      "x": -17,
      "y": 25,
      "z": 3,
      "name": "Rock_Ice"
    },
    {
      "x": -17,
      "y": 1,
      "z": 4,
      "name": "Rock_Ice"
    },
    {
      "x": -17,
      "y": 2,
      "z": 4,
      "name": "Rock_Ice"
    },
    {
      "x": -17,
      "y": 3,
      "z": 4,
      "name": "Rock_Ice"
    },
    {
      "x": -17,
      "y": 4,
      "z": 4,
      "name": "Rock_Ice"
    },
    {
      "x": -17,
      "y": 5,
      "z": 4,
      "name": "Rock_Ice"
    },
    {
      "x": -17,
      "y": 6,
      "z": 4,
      "name": "Rock_Ice"
    },
    {
      "x": -17,
      "y": 7,
      "z": 4,
      "name": "Rock_Ice"
    },
    {
      "x": -17,
      "y": 8,
      "z": 4,
      "name": "Rock_Ice"
    },
    {
      "x": -17,
      "y": 9,
      "z": 4,
      "name": "Rock_Ice"
    },
    {
      "x": -17,
      "y": 10,
      "z": 4,
      "name": "Rock_Ice"
    },
    {
      "x": -17,
      "y": 11,
      "z": 4,
      "name": "Rock_Ice"
    },
    {
      "x": -17,
      "y": 12,
      "z": 4,
      "name": "Rock_Ice"
    },
    {
      "x": -17,
      "y": 13,
      "z": 4,
      "name": "Rock_Ice"
    },
    {
      "x": -17,
      "y": 14,
      "z": 4,
      "name": "Rock_Ice"
    },
    {
      "x": -17,
      "y": 15,
      "z": 4,
      "name": "Rock_Ice"
    },
    {
      "x": -17,
      "y": 16,
      "z": 4,
      "name": "Rock_Ice"
    },
    {
      "x": -17,
      "y": 17,
      "z": 4,
      "name": "Rock_Ice"
    },
    {
      "x": -17,
      "y": 18,
      "z": 4,
      "name": "Rock_Ice"
    },
    {
      "x": -17,
      "y": 19,
      "z": 4,
      "name": "Rock_Ice"
    },
    {
      "x": -17,
      "y": 20,
      "z": 4,
      "name": "Rock_Ice"
    },
    {
      "x": -17,
      "y": 21,
      "z": 4,
      "name": "Rock_Ice"
    },
    {
      "x": -17,
      "y": 22,
      "z": 4,
      "name": "Rock_Ice"
    },
    {
      "x": -17,
      "y": 23,
      "z": 4,
      "name": "Rock_Ice"
    },
    {
      "x": -17,
      "y": 24,
      "z": 4,
      "name": "Rock_Ice"
    },
    {
      "x": -17,
      "y": 25,
      "z": 4,
      "name": "Rock_Ice"
    },
    {
      "x": -17,
      "y": 1,
      "z": 5,
      "name": "Rock_Ice"
    },
    {
      "x": -17,
      "y": 2,
      "z": 5,
      "name": "Rock_Ice"
    },
    {
      "x": -17,
      "y": 3,
      "z": 5,
      "name": "Rock_Ice"
    },
    {
      "x": -17,
      "y": 4,
      "z": 5,
      "name": "Rock_Ice"
    },
    {
      "x": -17,
      "y": 5,
      "z": 5,
      "name": "Rock_Ice"
    },
    {
      "x": -17,
      "y": 6,
      "z": 5,
      "name": "Rock_Ice"
    },
    {
      "x": -17,
      "y": 7,
      "z": 5,
      "name": "Rock_Ice"
    },
    {
      "x": -17,
      "y": 8,
      "z": 5,
      "name": "Rock_Ice"
    },
    {
      "x": -17,
      "y": 9,
      "z": 5,
      "name": "Rock_Ice"
    },
    {
      "x": -17,
      "y": 10,
      "z": 5,
      "name": "Rock_Ice"
    },
    {
      "x": -17,
      "y": 11,
      "z": 5,
      "name": "Rock_Ice"
    },
    {
      "x": -17,
      "y": 12,
      "z": 5,
      "name": "Rock_Ice"
    },
    {
      "x": -17,
      "y": 13,
      "z": 5,
      "name": "Rock_Ice"
    },
    {
      "x": -17,
      "y": 14,
      "z": 5,
      "name": "Rock_Ice"
    },
    {
      "x": -17,
      "y": 15,
      "z": 5,
      "name": "Rock_Ice"
    },
    {
      "x": -17,
      "y": 16,
      "z": 5,
      "name": "Rock_Ice"
    },
    {
      "x": -17,
      "y": 17,
      "z": 5,
      "name": "Rock_Ice"
    },
    {
      "x": -17,
      "y": 18,
      "z": 5,
      "name": "Rock_Ice"
    },
    {
      "x": -17,
      "y": 19,
      "z": 5,
      "name": "Rock_Ice"
    },
    {
      "x": -17,
      "y": 20,
      "z": 5,
      "name": "Rock_Ice"
    },
    {
      "x": -17,
      "y": 21,
      "z": 5,
      "name": "Rock_Ice"
    },
    {
      "x": -17,
      "y": 22,
      "z": 5,
      "name": "Rock_Ice"
    },
    {
      "x": -17,
      "y": 23,
      "z": 5,
      "name": "Rock_Ice"
    },
    {
      "x": -17,
      "y": 24,
      "z": 5,
      "name": "Rock_Ice"
    },
    {
      "x": -17,
      "y": 25,
      "z": 5,
      "name": "Rock_Ice"
    },
    {
      "x": -17,
      "y": 1,
      "z": 6,
      "name": "Rock_Ice"
    },
    {
      "x": -17,
      "y": 2,
      "z": 6,
      "name": "Rock_Ice"
    },
    {
      "x": -17,
      "y": 3,
      "z": 6,
      "name": "Rock_Ice"
    },
    {
      "x": -17,
      "y": 4,
      "z": 6,
      "name": "Rock_Ice"
    },
    {
      "x": -17,
      "y": 5,
      "z": 6,
      "name": "Rock_Ice"
    },
    {
      "x": -17,
      "y": 6,
      "z": 6,
      "name": "Rock_Ice"
    },
    {
      "x": -17,
      "y": 7,
      "z": 6,
      "name": "Rock_Ice"
    },
    {
      "x": -17,
      "y": 8,
      "z": 6,
      "name": "Rock_Ice"
    },
    {
      "x": -17,
      "y": 9,
      "z": 6,
      "name": "Rock_Ice"
    },
    {
      "x": -17,
      "y": 10,
      "z": 6,
      "name": "Rock_Ice"
    },
    {
      "x": -17,
      "y": 11,
      "z": 6,
      "name": "Rock_Ice"
    },
    {
      "x": -17,
      "y": 12,
      "z": 6,
      "name": "Rock_Ice"
    },
    {
      "x": -17,
      "y": 13,
      "z": 6,
      "name": "Rock_Ice"
    },
    {
      "x": -17,
      "y": 14,
      "z": 6,
      "name": "Rock_Ice"
    },
    {
      "x": -17,
      "y": 15,
      "z": 6,
      "name": "Rock_Ice"
    },
    {
      "x": -17,
      "y": 16,
      "z": 6,
      "name": "Rock_Ice"
    },
    {
      "x": -17,
      "y": 17,
      "z": 6,
      "name": "Rock_Ice"
    },
    {
      "x": -17,
      "y": 18,
      "z": 6,
      "name": "Rock_Ice"
    },
    {
      "x": -17,
      "y": 19,
      "z": 6,
      "name": "Rock_Ice"
    },
    {
      "x": -17,
      "y": 20,
      "z": 6,
      "name": "Rock_Ice"
    },
    {
      "x": -17,
      "y": 21,
      "z": 6,
      "name": "Rock_Ice"
    },
    {
      "x": -17,
      "y": 22,
      "z": 6,
      "name": "Rock_Ice"
    },
    {
      "x": -17,
      "y": 23,
      "z": 6,
      "name": "Rock_Ice"
    },
    {
      "x": -17,
      "y": 24,
      "z": 6,
      "name": "Rock_Ice"
    },
    {
      "x": -17,
      "y": 1,
      "z": 7,
      "name": "Rock_Ice"
    },
    {
      "x": -17,
      "y": 2,
      "z": 7,
      "name": "Rock_Ice"
    },
    {
      "x": -17,
      "y": 3,
      "z": 7,
      "name": "Rock_Ice"
    },
    {
      "x": -17,
      "y": 4,
      "z": 7,
      "name": "Rock_Ice"
    },
    {
      "x": -17,
      "y": 5,
      "z": 7,
      "name": "Rock_Ice"
    },
    {
      "x": -17,
      "y": 6,
      "z": 7,
      "name": "Rock_Ice"
    },
    {
      "x": -17,
      "y": 7,
      "z": 7,
      "name": "Rock_Ice"
    },
    {
      "x": -17,
      "y": 8,
      "z": 7,
      "name": "Rock_Ice"
    },
    {
      "x": -17,
      "y": 9,
      "z": 7,
      "name": "Rock_Ice"
    },
    {
      "x": -17,
      "y": 10,
      "z": 7,
      "name": "Rock_Ice"
    },
    {
      "x": -17,
      "y": 11,
      "z": 7,
      "name": "Rock_Ice"
    },
    {
      "x": -17,
      "y": 12,
      "z": 7,
      "name": "Rock_Ice"
    },
    {
      "x": -17,
      "y": 13,
      "z": 7,
      "name": "Rock_Ice"
    },
    {
      "x": -17,
      "y": 14,
      "z": 7,
      "name": "Rock_Ice"
    },
    {
      "x": -17,
      "y": 15,
      "z": 7,
      "name": "Rock_Ice"
    },
    {
      "x": -17,
      "y": 16,
      "z": 7,
      "name": "Rock_Ice"
    },
    {
      "x": -17,
      "y": 17,
      "z": 7,
      "name": "Rock_Ice"
    },
    {
      "x": -17,
      "y": 18,
      "z": 7,
      "name": "Rock_Ice"
    },
    {
      "x": -17,
      "y": 19,
      "z": 7,
      "name": "Rock_Ice"
    },
    {
      "x": -17,
      "y": 20,
      "z": 7,
      "name": "Rock_Ice"
    },
    {
      "x": -17,
      "y": 21,
      "z": 7,
      "name": "Rock_Ice"
    },
    {
      "x": -17,
      "y": 22,
      "z": 7,
      "name": "Rock_Ice"
    },
    {
      "x": -17,
      "y": 23,
      "z": 7,
      "name": "Rock_Ice"
    },
    {
      "x": -17,
      "y": 1,
      "z": 8,
      "name": "Rock_Ice"
    },
    {
      "x": -17,
      "y": 2,
      "z": 8,
      "name": "Rock_Ice"
    },
    {
      "x": -17,
      "y": 3,
      "z": 8,
      "name": "Rock_Ice"
    },
    {
      "x": -17,
      "y": 4,
      "z": 8,
      "name": "Rock_Ice"
    },
    {
      "x": -17,
      "y": 5,
      "z": 8,
      "name": "Rock_Ice"
    },
    {
      "x": -17,
      "y": 6,
      "z": 8,
      "name": "Rock_Ice"
    },
    {
      "x": -17,
      "y": 7,
      "z": 8,
      "name": "Rock_Ice"
    },
    {
      "x": -17,
      "y": 8,
      "z": 8,
      "name": "Rock_Ice"
    },
    {
      "x": -17,
      "y": 9,
      "z": 8,
      "name": "Rock_Ice"
    },
    {
      "x": -17,
      "y": 10,
      "z": 8,
      "name": "Rock_Ice"
    },
    {
      "x": -17,
      "y": 11,
      "z": 8,
      "name": "Rock_Ice"
    },
    {
      "x": -17,
      "y": 12,
      "z": 8,
      "name": "Rock_Ice"
    },
    {
      "x": -17,
      "y": 13,
      "z": 8,
      "name": "Rock_Ice"
    },
    {
      "x": -17,
      "y": 14,
      "z": 8,
      "name": "Rock_Ice"
    },
    {
      "x": -17,
      "y": 15,
      "z": 8,
      "name": "Rock_Ice"
    },
    {
      "x": -17,
      "y": 16,
      "z": 8,
      "name": "Rock_Ice"
    },
    {
      "x": -17,
      "y": 17,
      "z": 8,
      "name": "Rock_Ice"
    },
    {
      "x": -17,
      "y": 18,
      "z": 8,
      "name": "Rock_Ice"
    },
    {
      "x": -17,
      "y": 19,
      "z": 8,
      "name": "Rock_Ice"
    },
    {
      "x": -17,
      "y": 20,
      "z": 8,
      "name": "Rock_Ice"
    },
    {
      "x": -17,
      "y": 21,
      "z": 8,
      "name": "Rock_Ice"
    },
    {
      "x": -17,
      "y": 22,
      "z": 8,
      "name": "Rock_Ice"
    },
    {
      "x": -17,
      "y": 1,
      "z": 9,
      "name": "Rock_Ice"
    },
    {
      "x": -17,
      "y": 2,
      "z": 9,
      "name": "Rock_Ice"
    },
    {
      "x": -17,
      "y": 3,
      "z": 9,
      "name": "Rock_Ice"
    },
    {
      "x": -17,
      "y": 4,
      "z": 9,
      "name": "Rock_Ice"
    },
    {
      "x": -17,
      "y": 5,
      "z": 9,
      "name": "Rock_Ice"
    },
    {
      "x": -17,
      "y": 6,
      "z": 9,
      "name": "Rock_Ice"
    },
    {
      "x": -17,
      "y": 7,
      "z": 9,
      "name": "Rock_Ice"
    },
    {
      "x": -17,
      "y": 8,
      "z": 9,
      "name": "Rock_Ice"
    },
    {
      "x": -17,
      "y": 9,
      "z": 9,
      "name": "Rock_Ice"
    },
    {
      "x": -17,
      "y": 10,
      "z": 9,
      "name": "Rock_Ice"
    },
    {
      "x": -17,
      "y": 11,
      "z": 9,
      "name": "Rock_Ice"
    },
    {
      "x": -17,
      "y": 12,
      "z": 9,
      "name": "Rock_Ice"
    },
    {
      "x": -17,
      "y": 13,
      "z": 9,
      "name": "Rock_Ice"
    },
    {
      "x": -17,
      "y": 14,
      "z": 9,
      "name": "Rock_Ice"
    },
    {
      "x": -17,
      "y": 15,
      "z": 9,
      "name": "Rock_Ice"
    },
    {
      "x": -17,
      "y": 16,
      "z": 9,
      "name": "Rock_Ice"
    },
    {
      "x": -17,
      "y": 17,
      "z": 9,
      "name": "Rock_Ice"
    },
    {
      "x": -17,
      "y": 18,
      "z": 9,
      "name": "Rock_Ice"
    },
    {
      "x": -17,
      "y": 19,
      "z": 9,
      "name": "Rock_Ice"
    },
    {
      "x": -17,
      "y": 20,
      "z": 9,
      "name": "Soil_Snow"
    },
    {
      "x": -17,
      "y": 1,
      "z": 10,
      "name": "Rock_Ice"
    },
    {
      "x": -17,
      "y": 2,
      "z": 10,
      "name": "Rock_Ice"
    },
    {
      "x": -17,
      "y": 3,
      "z": 10,
      "name": "Rock_Ice"
    },
    {
      "x": -17,
      "y": 4,
      "z": 10,
      "name": "Rock_Ice"
    },
    {
      "x": -17,
      "y": 5,
      "z": 10,
      "name": "Rock_Ice"
    },
    {
      "x": -17,
      "y": 6,
      "z": 10,
      "name": "Rock_Ice"
    },
    {
      "x": -17,
      "y": 7,
      "z": 10,
      "name": "Rock_Ice"
    },
    {
      "x": -17,
      "y": 8,
      "z": 10,
      "name": "Rock_Ice"
    },
    {
      "x": -17,
      "y": 9,
      "z": 10,
      "name": "Rock_Ice"
    },
    {
      "x": -17,
      "y": 10,
      "z": 10,
      "name": "Rock_Ice"
    },
    {
      "x": -17,
      "y": 11,
      "z": 10,
      "name": "Rock_Ice"
    },
    {
      "x": -17,
      "y": 12,
      "z": 10,
      "name": "Rock_Ice"
    },
    {
      "x": -17,
      "y": 13,
      "z": 10,
      "name": "Rock_Ice"
    },
    {
      "x": -17,
      "y": 14,
      "z": 10,
      "name": "Rock_Ice"
    },
    {
      "x": -17,
      "y": 15,
      "z": 10,
      "name": "Rock_Ice"
    },
    {
      "x": -17,
      "y": 16,
      "z": 10,
      "name": "Rock_Ice"
    },
    {
      "x": -17,
      "y": 17,
      "z": 10,
      "name": "Soil_Snow"
    },
    {
      "x": -17,
      "y": 3,
      "z": 11,
      "name": "Rock_Ice"
    },
    {
      "x": -17,
      "y": 4,
      "z": 11,
      "name": "Rock_Ice"
    },
    {
      "x": -17,
      "y": 5,
      "z": 11,
      "name": "Rock_Ice"
    },
    {
      "x": -17,
      "y": 6,
      "z": 11,
      "name": "Rock_Ice"
    },
    {
      "x": -17,
      "y": 7,
      "z": 11,
      "name": "Rock_Ice"
    },
    {
      "x": -17,
      "y": 8,
      "z": 11,
      "name": "Rock_Ice"
    },
    {
      "x": -17,
      "y": 9,
      "z": 11,
      "name": "Rock_Ice"
    },
    {
      "x": -17,
      "y": 10,
      "z": 11,
      "name": "Rock_Ice"
    },
    {
      "x": -17,
      "y": 11,
      "z": 11,
      "name": "Rock_Ice"
    },
    {
      "x": -17,
      "y": 12,
      "z": 11,
      "name": "Rock_Ice"
    },
    {
      "x": -17,
      "y": 13,
      "z": 11,
      "name": "Rock_Ice"
    },
    {
      "x": -17,
      "y": 14,
      "z": 11,
      "name": "Rock_Ice"
    },
    {
      "x": -17,
      "y": 15,
      "z": 11,
      "name": "Soil_Snow"
    },
    {
      "x": -17,
      "y": 6,
      "z": 12,
      "name": "Rock_Ice"
    },
    {
      "x": -17,
      "y": 7,
      "z": 12,
      "name": "Rock_Ice"
    },
    {
      "x": -17,
      "y": 8,
      "z": 12,
      "name": "Rock_Ice"
    },
    {
      "x": -17,
      "y": 9,
      "z": 12,
      "name": "Rock_Ice"
    },
    {
      "x": -17,
      "y": 10,
      "z": 12,
      "name": "Rock_Ice"
    },
    {
      "x": -17,
      "y": 11,
      "z": 12,
      "name": "Rock_Ice"
    },
    {
      "x": -17,
      "y": 12,
      "z": 12,
      "name": "Rock_Ice"
    },
    {
      "x": -17,
      "y": 13,
      "z": 12,
      "name": "Soil_Snow"
    },
    {
      "x": -16,
      "y": 26,
      "z": -3,
      "name": "Soil_Snow"
    },
    {
      "x": -16,
      "y": 3,
      "z": -2,
      "name": "Rock_Ice"
    },
    {
      "x": -16,
      "y": 4,
      "z": -2,
      "name": "Rock_Ice"
    },
    {
      "x": -16,
      "y": 5,
      "z": -2,
      "name": "Rock_Ice"
    },
    {
      "x": -16,
      "y": 6,
      "z": -2,
      "name": "Rock_Ice"
    },
    {
      "x": -16,
      "y": 7,
      "z": -2,
      "name": "Rock_Ice"
    },
    {
      "x": -16,
      "y": 8,
      "z": -2,
      "name": "Rock_Ice"
    },
    {
      "x": -16,
      "y": 9,
      "z": -2,
      "name": "Rock_Ice"
    },
    {
      "x": -16,
      "y": 10,
      "z": -2,
      "name": "Rock_Ice"
    },
    {
      "x": -16,
      "y": 11,
      "z": -2,
      "name": "Rock_Ice"
    },
    {
      "x": -16,
      "y": 12,
      "z": -2,
      "name": "Rock_Ice"
    },
    {
      "x": -16,
      "y": 24,
      "z": -2,
      "name": "Rock_Ice"
    },
    {
      "x": -16,
      "y": 25,
      "z": -2,
      "name": "Rock_Ice"
    },
    {
      "x": -16,
      "y": 26,
      "z": -2,
      "name": "Soil_Snow"
    },
    {
      "x": -16,
      "y": 2,
      "z": -1,
      "name": "Rock_Ice"
    },
    {
      "x": -16,
      "y": 3,
      "z": -1,
      "name": "Rock_Ice"
    },
    {
      "x": -16,
      "y": 4,
      "z": -1,
      "name": "Rock_Ice"
    },
    {
      "x": -16,
      "y": 5,
      "z": -1,
      "name": "Rock_Ice"
    },
    {
      "x": -16,
      "y": 6,
      "z": -1,
      "name": "Rock_Ice"
    },
    {
      "x": -16,
      "y": 7,
      "z": -1,
      "name": "Rock_Ice"
    },
    {
      "x": -16,
      "y": 8,
      "z": -1,
      "name": "Rock_Ice"
    },
    {
      "x": -16,
      "y": 9,
      "z": -1,
      "name": "Rock_Ice"
    },
    {
      "x": -16,
      "y": 10,
      "z": -1,
      "name": "Rock_Ice"
    },
    {
      "x": -16,
      "y": 11,
      "z": -1,
      "name": "Rock_Ice"
    },
    {
      "x": -16,
      "y": 12,
      "z": -1,
      "name": "Rock_Ice"
    },
    {
      "x": -16,
      "y": 13,
      "z": -1,
      "name": "Rock_Ice"
    },
    {
      "x": -16,
      "y": 14,
      "z": -1,
      "name": "Rock_Ice"
    },
    {
      "x": -16,
      "y": 15,
      "z": -1,
      "name": "Rock_Ice"
    },
    {
      "x": -16,
      "y": 16,
      "z": -1,
