{
  "version": 8,
  "blockIdVersion": 11,
  "anchorX": -1,
  "anchorY": 19,
  "anchorZ": 1,
  "blocks": [
    {
      "x": -16,
      "y": 28,
      "z": -2,
      "name": "Soil_Snow"
    },
    {
      "x": -16,
      "y": 27,
      "z": -1,
      "name": "Rock_Ice"
    },
    {
      "x": -16,
      "y": 28,
      "z": -1,
      "name": "Rock_Ice"
    },
    {
      "x": -16,
      "y": 29,
      "z": -1,
      "name": "Rock_Ice"
    },
    {
      "x": -16,
      "y": 28,
      "z": 0,
      "name": "Rock_Ice"
    },
    {
      "x": -16,
      "y": 29,
      "z": 0,
      "name": "Rock_Ice"
    },
    {
      "x": -16,
      "y": 28,
      "z": 1,
      "name": "Rock_Ice"
    },
    {
      "x": -16,
      "y": 29,
      "z": 1,
      "name": "Rock_Ice"
    },
    {
      "x": -15,
      "y": 27,
      "z": -4,
      "name": "Soil_Snow"
    },
    {
      "x": -15,
      "y": 27,
      "z": -3,
      "name": "Rock_Ice"
    },
    {
      "x": -15,
      "y": 28,
      "z": -3,
      "name": "Rock_Ice"
    },
    {
      "x": -15,
      "y": 29,
      "z": -3,
      "name": "Soil_Snow"
    },
    {
      "x": -15,
      "y": 26,
      "z": -2,
      "name": "Rock_Ice"
    },
    {
      "x": -15,
      "y": 27,
      "z": -2,
      "name": "Rock_Ice"
    },
    {
      "x": -15,
      "y": 28,
      "z": -2,
      "name": "Rock_Ice"
    },
    {
      "x": -15,
      "y": 29,
      "z": -2,
      "name": "Rock_Ice"
    },
    {
      "x": -15,
      "y": 30,
      "z": -2,
      "name": "Rock_Ice"
    },
    {
      "x": -15,
      "y": 26,
      "z": -1,
      "name": "Rock_Ice"
    },
    {
      "x": -15,
      "y": 27,
      "z": -1,
      "name": "Rock_Ice"
    },
    {
      "x": -15,
      "y": 28,
      "z": -1,
      "name": "Rock_Ice"
    },
    {
      "x": -15,
      "y": 29,
      "z": -1,
      "name": "Rock_Ice"
    },
    {
      "x": -15,
      "y": 30,
      "z": -1,
      "name": "Rock_Ice"
    },
    {
      "x": -15,
      "y": 31,
      "z": -1,
      "name": "Rock_Ice"
    },
    {
      "x": -15,
      "y": 25,
      "z": 0,
      "name": "Rock_Ice"
    },
    {
      "x": -15,
      "y": 26,
      "z": 0,
      "name": "Rock_Ice"
    },
    {
      "x": -15,
      "y": 27,
      "z": 0,
      "name": "Rock_Ice"
    },
    {
      "x": -15,
      "y": 28,
      "z": 0,
      "name": "Rock_Ice"
    },
    {
      "x": -15,
      "y": 29,
      "z": 0,
      "name": "Rock_Ice"
    },
    {
      "x": -15,
      "y": 30,
      "z": 0,
      "name": "Rock_Ice"
    },
    {
      "x": -15,
      "y": 31,
      "z": 0,
      "name": "Rock_Ice"
    },
    {
      "x": -15,
      "y": 32,
      "z": 0,
      "name": "Soil_Snow"
    },
    {
      "x": -15,
      "y": 25,
      "z": 1,
      "name": "Rock_Ice"
    },
    {
      "x": -15,
      "y": 26,
      "z": 1,
      "name": "Rock_Ice"
    },
    {
      "x": -15,
      "y": 27,
      "z": 1,
      "name": "Rock_Ice"
    },
    {
      "x": -15,
      "y": 28,
      "z": 1,
      "name": "Rock_Ice"
    },
    {
      "x": -15,
      "y": 29,
      "z": 1,
      "name": "Rock_Ice"
    },
    {
      "x": -15,
      "y": 30,
      "z": 1,
      "name": "Rock_Ice"
    },
    {
      "x": -15,
      "y": 31,
      "z": 1,
      "name": "Rock_Ice"
    },
    {
      "x": -15,
      "y": 26,
      "z": 2,
      "name": "Rock_Ice"
    },
    {
      "x": -15,
      "y": 27,
      "z": 2,
      "name": "Rock_Ice"
    },
    {
      "x": -15,
      "y": 28,
      "z": 2,
      "name": "Rock_Ice"
    },
    {
      "x": -15,
      "y": 29,
      "z": 2,
      "name": "Rock_Ice"
    },
    {
      "x": -15,
      "y": 30,
      "z": 2,
      "name": "Rock_Ice"
    },
    {
      "x": -15,
      "y": 31,
      "z": 2,
      "name": "Rock_Ice"
    },
    {
      "x": -15,
      "y": 28,
      "z": 3,
      "name": "Rock_Ice"
    },
    {
      "x": -15,
      "y": 29,
      "z": 3,
      "name": "Rock_Ice"
    },
    {
      "x": -14,
      "y": 26,
      "z": -6,
      "name": "Rock_Ice"
    },
    {
      "x": -14,
      "y": 27,
      "z": -6,
      "name": "Soil_Snow"
    },
    {
      "x": -14,
      "y": 26,
      "z": -5,
      "name": "Rock_Ice"
    },
    {
      "x": -14,
      "y": 27,
      "z": -5,
      "name": "Rock_Ice"
    },
    {
      "x": -14,
      "y": 28,
      "z": -5,
      "name": "Soil_Snow"
    },
    {
      "x": -14,
      "y": 25,
      "z": -4,
      "name": "Rock_Ice"
    },
    {
      "x": -14,
      "y": 26,
      "z": -4,
      "name": "Rock_Ice"
    },
    {
      "x": -14,
      "y": 27,
      "z": -4,
      "name": "Rock_Ice"
    },
    {
      "x": -14,
      "y": 28,
      "z": -4,
      "name": "Rock_Ice"
    },
    {
      "x": -14,
      "y": 29,
      "z": -4,
      "name": "Soil_Snow"
    },
    {
      "x": -14,
      "y": 24,
      "z": -3,
      "name": "Rock_Ice"
    },
    {
      "x": -14,
      "y": 25,
      "z": -3,
      "name": "Rock_Ice"
    },
    {
      "x": -14,
      "y": 26,
      "z": -3,
      "name": "Rock_Ice"
    },
    {
      "x": -14,
      "y": 27,
      "z": -3,
      "name": "Rock_Ice"
    },
    {
      "x": -14,
      "y": 28,
      "z": -3,
      "name": "Rock_Ice"
    },
    {
      "x": -14,
      "y": 29,
      "z": -3,
      "name": "Rock_Ice"
    },
    {
      "x": -14,
      "y": 30,
      "z": -3,
      "name": "Soil_Snow"
    },
    {
      "x": -14,
      "y": 24,
      "z": -2,
      "name": "Rock_Ice"
    },
    {
      "x": -14,
      "y": 25,
      "z": -2,
      "name": "Rock_Ice"
    },
    {
      "x": -14,
      "y": 26,
      "z": -2,
      "name": "Rock_Ice"
    },
    {
      "x": -14,
      "y": 27,
      "z": -2,
      "name": "Rock_Ice"
    },
    {
      "x": -14,
      "y": 28,
      "z": -2,
      "name": "Rock_Ice"
    },
    {
      "x": -14,
      "y": 29,
      "z": -2,
      "name": "Rock_Ice"
    },
    {
      "x": -14,
      "y": 30,
      "z": -2,
      "name": "Rock_Ice"
    },
    {
      "x": -14,
      "y": 31,
      "z": -2,
      "name": "Rock_Ice"
    },
    {
      "x": -14,
      "y": 32,
      "z": -2,
      "name": "Rock_Ice"
    },
    {
      "x": -14,
      "y": 23,
      "z": -1,
      "name": "Rock_Ice"
    },
    {
      "x": -14,
      "y": 24,
      "z": -1,
      "name": "Rock_Ice"
    },
    {
      "x": -14,
      "y": 25,
      "z": -1,
      "name": "Rock_Ice"
    },
    {
      "x": -14,
      "y": 26,
      "z": -1,
      "name": "Rock_Ice"
    },
    {
      "x": -14,
      "y": 27,
      "z": -1,
      "name": "Rock_Ice"
    },
    {
      "x": -14,
      "y": 28,
      "z": -1,
      "name": "Rock_Ice"
    },
    {
      "x": -14,
      "y": 29,
      "z": -1,
      "name": "Rock_Ice"
    },
    {
      "x": -14,
      "y": 30,
      "z": -1,
      "name": "Rock_Ice"
    },
    {
      "x": -14,
      "y": 31,
      "z": -1,
      "name": "Rock_Ice"
    },
    {
      "x": -14,
      "y": 32,
      "z": -1,
      "name": "Rock_Ice"
    },
    {
      "x": -14,
      "y": 33,
      "z": -1,
      "name": "Rock_Ice"
    },
    {
      "x": -14,
      "y": 23,
      "z": 0,
      "name": "Rock_Ice"
    },
    {
      "x": -14,
      "y": 24,
      "z": 0,
      "name": "Rock_Ice"
    },
    {
      "x": -14,
      "y": 25,
      "z": 0,
      "name": "Rock_Ice"
    },
    {
      "x": -14,
      "y": 26,
      "z": 0,
      "name": "Rock_Ice"
    },
    {
      "x": -14,
      "y": 27,
      "z": 0,
      "name": "Rock_Ice"
    },
    {
      "x": -14,
      "y": 28,
      "z": 0,
      "name": "Rock_Ice"
    },
    {
      "x": -14,
      "y": 29,
      "z": 0,
      "name": "Rock_Ice"
    },
    {
      "x": -14,
      "y": 30,
      "z": 0,
      "name": "Rock_Ice"
    },
    {
      "x": -14,
      "y": 31,
      "z": 0,
      "name": "Rock_Ice"
    },
    {
      "x": -14,
      "y": 32,
      "z": 0,
      "name": "Rock_Ice"
    },
    {
      "x": -14,
      "y": 33,
      "z": 0,
      "name": "Soil_Snow"
    },
    {
      "x": -14,
      "y": 23,
      "z": 1,
      "name": "Rock_Ice"
    },
    {
      "x": -14,
      "y": 24,
      "z": 1,
      "name": "Rock_Ice"
    },
    {
      "x": -14,
      "y": 25,
      "z": 1,
      "name": "Rock_Ice"
    },
    {
      "x": -14,
      "y": 26,
      "z": 1,
      "name": "Rock_Ice"
    },
    {
      "x": -14,
      "y": 27,
      "z": 1,
      "name": "Rock_Ice"
    },
    {
      "x": -14,
      "y": 28,
      "z": 1,
      "name": "Rock_Ice"
    },
    {
      "x": -14,
      "y": 29,
      "z": 1,
      "name": "Rock_Ice"
    },
    {
      "x": -14,
      "y": 30,
      "z": 1,
      "name": "Rock_Ice"
    },
    {
      "x": -14,
      "y": 31,
      "z": 1,
      "name": "Rock_Ice"
    },
    {
      "x": -14,
      "y": 32,
      "z": 1,
      "name": "Rock_Ice"
    },
    {
      "x": -14,
      "y": 33,
      "z": 1,
      "name": "Soil_Snow"
    },
    {
      "x": -14,
      "y": 23,
      "z": 2,
      "name": "Rock_Ice"
    },
    {
      "x": -14,
      "y": 24,
      "z": 2,
      "name": "Rock_Ice"
    },
    {
      "x": -14,
      "y": 25,
      "z": 2,
      "name": "Rock_Ice"
    },
    {
      "x": -14,
      "y": 26,
      "z": 2,
      "name": "Rock_Ice"
    },
    {
      "x": -14,
      "y": 27,
      "z": 2,
      "name": "Rock_Ice"
    },
    {
      "x": -14,
      "y": 28,
      "z": 2,
      "name": "Rock_Ice"
    },
    {
      "x": -14,
      "y": 29,
      "z": 2,
      "name": "Rock_Ice"
    },
    {
      "x": -14,
      "y": 30,
      "z": 2,
      "name": "Rock_Ice"
    },
    {
      "x": -14,
      "y": 31,
      "z": 2,
      "name": "Rock_Ice"
    },
    {
      "x": -14,
      "y": 32,
      "z": 2,
      "name": "Rock_Ice"
    },
    {
      "x": -14,
      "y": 24,
      "z": 3,
      "name": "Rock_Ice"
    },
    {
      "x": -14,
      "y": 25,
      "z": 3,
      "name": "Rock_Ice"
    },
    {
      "x": -14,
      "y": 26,
      "z": 3,
      "name": "Rock_Ice"
    },
    {
      "x": -14,
      "y": 27,
      "z": 3,
      "name": "Rock_Ice"
    },
    {
      "x": -14,
      "y": 28,
      "z": 3,
      "name": "Rock_Ice"
    },
    {
      "x": -14,
      "y": 29,
      "z": 3,
      "name": "Rock_Ice"
    },
    {
      "x": -14,
      "y": 30,
      "z": 3,
      "name": "Rock_Ice"
    },
    {
      "x": -14,
      "y": 31,
      "z": 3,
      "name": "Rock_Ice"
    },
    {
      "x": -14,
      "y": 26,
      "z": 4,
      "name": "Rock_Ice"
    },
    {
      "x": -14,
      "y": 27,
      "z": 4,
      "name": "Rock_Ice"
    },
    {
      "x": -14,
      "y": 28,
      "z": 4,
      "name": "Rock_Ice"
    },
    {
      "x": -14,
      "y": 29,
      "z": 4,
      "name": "Rock_Ice"
    },
    {
      "x": -14,
      "y": 30,
      "z": 4,
      "name": "Rock_Ice"
    },
    {
      "x": -13,
      "y": 25,
      "z": -10,
      "name": "Rock_Ice"
    },
    {
      "x": -13,
      "y": 26,
      "z": -10,
      "name": "Soil_Snow"
    },
    {
      "x": -13,
      "y": 25,
      "z": -9,
      "name": "Rock_Ice_Permafrost"
    },
    {
      "x": -13,
      "y": 26,
      "z": -9,
      "name": "Rock_Ice"
    },
    {
      "x": -13,
      "y": 27,
      "z": -9,
      "name": "Soil_Snow"
    },
    {
      "x": -13,
      "y": 24,
      "z": -8,
      "name": "Rock_Ice"
    },
    {
      "x": -13,
      "y": 25,
      "z": -8,
      "name": "Rock_Ice"
    },
    {
      "x": -13,
      "y": 26,
      "z": -8,
      "name": "Rock_Ice"
    },
    {
      "x": -13,
      "y": 27,
      "z": -8,
      "name": "Rock_Ice"
    },
    {
      "x": -13,
      "y": 23,
      "z": -7,
      "name": "Rock_Ice"
    },
    {
      "x": -13,
      "y": 24,
      "z": -7,
      "name": "Rock_Ice"
    },
    {
      "x": -13,
      "y": 25,
      "z": -7,
      "name": "Rock_Ice_Permafrost"
    },
    {
      "x": -13,
      "y": 26,
      "z": -7,
      "name": "Rock_Ice"
    },
    {
      "x": -13,
      "y": 27,
      "z": -7,
      "name": "Rock_Ice"
    },
    {
      "x": -13,
      "y": 28,
      "z": -7,
      "name": "Rock_Ice"
    },
    {
      "x": -13,
      "y": 23,
      "z": -6,
      "name": "Rock_Ice"
    },
    {
      "x": -13,
      "y": 24,
      "z": -6,
      "name": "Rock_Ice"
    },
    {
      "x": -13,
      "y": 25,
      "z": -6,
      "name": "Rock_Ice"
    },
    {
      "x": -13,
      "y": 26,
      "z": -6,
      "name": "Rock_Ice"
    },
    {
      "x": -13,
      "y": 27,
      "z": -6,
      "name": "Rock_Ice"
    },
    {
      "x": -13,
      "y": 28,
      "z": -6,
      "name": "Rock_Ice"
    },
    {
      "x": -13,
      "y": 29,
      "z": -6,
      "name": "Soil_Snow"
    },
    {
      "x": -13,
      "y": 22,
      "z": -5,
      "name": "Rock_Ice"
    },
    {
      "x": -13,
      "y": 23,
      "z": -5,
      "name": "Rock_Ice"
    },
    {
      "x": -13,
      "y": 24,
      "z": -5,
      "name": "Rock_Ice"
    },
    {
      "x": -13,
      "y": 25,
      "z": -5,
      "name": "Rock_Ice"
    },
    {
      "x": -13,
      "y": 26,
      "z": -5,
      "name": "Rock_Ice"
    },
    {
      "x": -13,
      "y": 27,
      "z": -5,
      "name": "Rock_Ice"
    },
    {
      "x": -13,
      "y": 28,
      "z": -5,
      "name": "Rock_Ice"
    },
    {
      "x": -13,
      "y": 29,
      "z": -5,
      "name": "Rock_Ice"
    },
    {
      "x": -13,
      "y": 30,
      "z": -5,
      "name": "Soil_Snow"
    },
    {
      "x": -13,
      "y": 22,
      "z": -4,
      "name": "Rock_Ice"
    },
    {
      "x": -13,
      "y": 23,
      "z": -4,
      "name": "Rock_Ice"
    },
    {
      "x": -13,
      "y": 24,
      "z": -4,
      "name": "Rock_Ice"
    },
    {
      "x": -13,
      "y": 25,
      "z": -4,
      "name": "Rock_Ice"
    },
    {
      "x": -13,
      "y": 26,
      "z": -4,
      "name": "Rock_Ice"
    },
    {
      "x": -13,
      "y": 27,
      "z": -4,
      "name": "Rock_Ice"
    },
    {
      "x": -13,
      "y": 28,
      "z": -4,
      "name": "Rock_Ice"
    },
    {
      "x": -13,
      "y": 29,
      "z": -4,
      "name": "Rock_Ice"
    },
    {
      "x": -13,
      "y": 30,
      "z": -4,
      "name": "Rock_Ice"
    },
    {
      "x": -13,
      "y": 31,
      "z": -4,
      "name": "Soil_Snow"
    },
    {
      "x": -13,
      "y": 22,
      "z": -3,
      "name": "Rock_Ice"
    },
    {
      "x": -13,
      "y": 23,
      "z": -3,
      "name": "Rock_Ice"
    },
    {
      "x": -13,
      "y": 24,
      "z": -3,
      "name": "Rock_Ice"
    },
    {
      "x": -13,
      "y": 25,
      "z": -3,
      "name": "Rock_Ice"
    },
    {
      "x": -13,
      "y": 26,
      "z": -3,
      "name": "Rock_Ice"
    },
    {
      "x": -13,
      "y": 27,
      "z": -3,
      "name": "Rock_Ice"
    },
    {
      "x": -13,
      "y": 28,
      "z": -3,
      "name": "Rock_Ice"
    },
    {
      "x": -13,
      "y": 29,
      "z": -3,
      "name": "Rock_Ice"
    },
    {
      "x": -13,
      "y": 30,
      "z": -3,
      "name": "Rock_Ice"
    },
    {
      "x": -13,
      "y": 31,
      "z": -3,
      "name": "Rock_Ice_Permafrost"
    },
    {
      "x": -13,
      "y": 32,
      "z": -3,
      "name": "Rock_Ice_Permafrost"
    },
    {
      "x": -13,
      "y": 21,
      "z": -2,
      "name": "Rock_Ice"
    },
    {
      "x": -13,
      "y": 22,
      "z": -2,
      "name": "Rock_Ice"
    },
    {
      "x": -13,
      "y": 23,
      "z": -2,
      "name": "Rock_Ice"
    },
    {
      "x": -13,
      "y": 24,
      "z": -2,
      "name": "Rock_Ice"
    },
    {
      "x": -13,
      "y": 25,
      "z": -2,
      "name": "Rock_Ice"
    },
    {
      "x": -13,
      "y": 26,
      "z": -2,
      "name": "Rock_Ice"
    },
    {
      "x": -13,
      "y": 27,
      "z": -2,
      "name": "Rock_Ice"
    },
    {
      "x": -13,
      "y": 28,
      "z": -2,
      "name": "Rock_Ice"
    },
    {
      "x": -13,
      "y": 29,
      "z": -2,
      "name": "Rock_Ice"
    },
    {
      "x": -13,
      "y": 30,
      "z": -2,
      "name": "Rock_Ice"
    },
    {
      "x": -13,
      "y": 31,
      "z": -2,
      "name": "Rock_Ice"
    },
    {
      "x": -13,
      "y": 32,
      "z": -2,
      "name": "Rock_Ice"
    },
    {
      "x": -13,
      "y": 33,
      "z": -2,
      "name": "Rock_Ice"
    },
    {
      "x": -13,
      "y": 21,
      "z": -1,
      "name": "Rock_Ice"
    },
    {
      "x": -13,
      "y": 22,
      "z": -1,
      "name": "Rock_Ice"
    },
    {
      "x": -13,
      "y": 23,
      "z": -1,
      "name": "Rock_Ice"
    },
    {
      "x": -13,
      "y": 24,
      "z": -1,
      "name": "Rock_Ice"
    },
    {
      "x": -13,
      "y": 25,
      "z": -1,
      "name": "Rock_Ice"
    },
    {
      "x": -13,
      "y": 26,
      "z": -1,
      "name": "Rock_Ice"
    },
    {
      "x": -13,
      "y": 27,
      "z": -1,
      "name": "Rock_Ice"
    },
    {
      "x": -13,
      "y": 28,
      "z": -1,
      "name": "Rock_Ice"
    },
    {
      "x": -13,
      "y": 29,
      "z": -1,
      "name": "Rock_Ice"
    },
    {
      "x": -13,
      "y": 30,
      "z": -1,
      "name": "Rock_Ice"
    },
    {
      "x": -13,
      "y": 31,
      "z": -1,
      "name": "Rock_Ice"
    },
    {
      "x": -13,
      "y": 32,
      "z": -1,
      "name": "Rock_Ice"
    },
    {
      "x": -13,
      "y": 33,
      "z": -1,
      "name": "Rock_Ice"
    },
    {
      "x": -13,
      "y": 34,
      "z": -1,
      "name": "Rock_Ice"
    },
    {
      "x": -13,
      "y": 20,
      "z": 0,
      "name": "Rock_Ice"
    },
    {
      "x": -13,
      "y": 21,
      "z": 0,
      "name": "Rock_Ice"
    },
    {
      "x": -13,
      "y": 22,
      "z": 0,
      "name": "Rock_Ice"
    },
    {
      "x": -13,
      "y": 23,
      "z": 0,
      "name": "Rock_Ice"
    },
    {
      "x": -13,
      "y": 24,
      "z": 0,
      "name": "Rock_Ice"
    },
    {
      "x": -13,
      "y": 25,
      "z": 0,
      "name": "Rock_Ice"
    },
    {
      "x": -13,
      "y": 26,
      "z": 0,
      "name": "Rock_Ice"
    },
    {
      "x": -13,
      "y": 27,
      "z": 0,
      "name": "Rock_Ice"
    },
    {
      "x": -13,
      "y": 28,
      "z": 0,
      "name": "Rock_Ice"
    },
    {
      "x": -13,
      "y": 29,
      "z": 0,
      "name": "Rock_Ice"
    },
    {
      "x": -13,
      "y": 30,
      "z": 0,
      "name": "Rock_Ice"
    },
    {
      "x": -13,
      "y": 31,
      "z": 0,
      "name": "Rock_Ice"
    },
    {
      "x": -13,
      "y": 32,
      "z": 0,
      "name": "Rock_Ice"
    },
    {
      "x": -13,
      "y": 33,
      "z": 0,
      "name": "Rock_Ice"
    },
    {
      "x": -13,
      "y": 34,
      "z": 0,
      "name": "Soil_Snow"
    },
    {
      "x": -13,
      "y": 20,
      "z": 1,
      "name": "Rock_Ice"
    },
    {
      "x": -13,
      "y": 21,
      "z": 1,
      "name": "Rock_Ice"
    },
    {
      "x": -13,
      "y": 22,
      "z": 1,
      "name": "Rock_Ice"
    },
    {
      "x": -13,
      "y": 23,
      "z": 1,
      "name": "Rock_Ice"
    },
    {
      "x": -13,
      "y": 24,
      "z": 1,
      "name": "Rock_Ice"
    },
    {
      "x": -13,
      "y": 25,
      "z": 1,
      "name": "Rock_Ice"
    },
    {
      "x": -13,
      "y": 26,
      "z": 1,
      "name": "Rock_Ice"
    },
    {
      "x": -13,
      "y": 27,
      "z": 1,
      "name": "Rock_Ice"
    },
    {
      "x": -13,
      "y": 28,
      "z": 1,
      "name": "Rock_Ice"
    },
    {
      "x": -13,
      "y": 29,
      "z": 1,
      "name": "Rock_Ice"
    },
    {
      "x": -13,
      "y": 30,
      "z": 1,
      "name": "Rock_Ice"
    },
    {
      "x": -13,
      "y": 31,
      "z": 1,
      "name": "Rock_Ice"
    },
    {
      "x": -13,
      "y": 32,
      "z": 1,
      "name": "Rock_Ice"
    },
    {
      "x": -13,
      "y": 33,
      "z": 1,
      "name": "Rock_Ice"
    },
    {
      "x": -13,
      "y": 34,
      "z": 1,
      "name": "Soil_Snow"
    },
    {
      "x": -13,
      "y": 20,
      "z": 2,
      "name": "Rock_Ice"
    },
    {
      "x": -13,
      "y": 21,
      "z": 2,
      "name": "Rock_Ice"
    },
    {
      "x": -13,
      "y": 22,
      "z": 2,
      "name": "Rock_Ice"
    },
    {
      "x": -13,
      "y": 23,
      "z": 2,
      "name": "Rock_Ice"
    },
    {
      "x": -13,
      "y": 24,
      "z": 2,
      "name": "Rock_Ice"
    },
    {
      "x": -13,
      "y": 25,
      "z": 2,
      "name": "Rock_Ice"
    },
    {
      "x": -13,
      "y": 26,
      "z": 2,
      "name": "Rock_Ice"
    },
    {
      "x": -13,
      "y": 27,
      "z": 2,
      "name": "Rock_Ice"
    },
    {
      "x": -13,
      "y": 28,
      "z": 2,
      "name": "Rock_Ice"
    },
    {
      "x": -13,
      "y": 29,
      "z": 2,
      "name": "Rock_Ice"
    },
    {
      "x": -13,
      "y": 30,
      "z": 2,
      "name": "Rock_Ice"
    },
    {
      "x": -13,
      "y": 31,
      "z": 2,
      "name": "Rock_Ice"
    },
    {
      "x": -13,
      "y": 32,
      "z": 2,
      "name": "Rock_Ice"
    },
    {
      "x": -13,
      "y": 33,
      "z": 2,
      "name": "Rock_Ice"
    },
    {
      "x": -13,
      "y": 34,
      "z": 2,
      "name": "Soil_Snow"
    },
    {
      "x": -13,
      "y": 20,
      "z": 3,
      "name": "Rock_Ice"
    },
    {
      "x": -13,
      "y": 21,
      "z": 3,
      "name": "Rock_Ice"
    },
    {
      "x": -13,
      "y": 22,
      "z": 3,
      "name": "Rock_Ice"
    },
    {
      "x": -13,
      "y": 23,
      "z": 3,
      "name": "Rock_Ice"
    },
    {
      "x": -13,
      "y": 24,
      "z": 3,
      "name": "Rock_Ice"
    },
    {
      "x": -13,
      "y": 25,
      "z": 3,
      "name": "Rock_Ice"
    },
    {
      "x": -13,
      "y": 26,
      "z": 3,
      "name": "Rock_Ice"
    },
    {
      "x": -13,
      "y": 27,
      "z": 3,
      "name": "Rock_Ice"
    },
    {
      "x": -13,
      "y": 28,
      "z": 3,
      "name": "Rock_Ice"
    },
    {
      "x": -13,
      "y": 29,
      "z": 3,
      "name": "Rock_Ice"
    },
    {
      "x": -13,
      "y": 30,
      "z": 3,
      "name": "Rock_Ice"
    },
    {
      "x": -13,
      "y": 31,
      "z": 3,
      "name": "Rock_Ice"
    },
    {
      "x": -13,
      "y": 32,
      "z": 3,
      "name": "Rock_Ice"
    },
    {
      "x": -13,
      "y": 33,
      "z": 3,
      "name": "Rock_Ice"
    },
    {
      "x": -13,
      "y": 22,
      "z": 4,
      "name": "Rock_Ice"
    },
    {
      "x": -13,
      "y": 23,
      "z": 4,
      "name": "Rock_Ice"
    },
    {
      "x": -13,
      "y": 24,
      "z": 4,
      "name": "Rock_Ice"
    },
    {
      "x": -13,
      "y": 25,
      "z": 4,
      "name": "Rock_Ice"
    },
    {
      "x": -13,
      "y": 26,
      "z": 4,
      "name": "Rock_Ice"
    },
    {
      "x": -13,
      "y": 27,
      "z": 4,
      "name": "Rock_Ice"
    },
    {
      "x": -13,
      "y": 28,
      "z": 4,
      "name": "Rock_Ice"
    },
    {
      "x": -13,
      "y": 29,
      "z": 4,
      "name": "Rock_Ice"
    },
    {
      "x": -13,
      "y": 30,
      "z": 4,
      "name": "Rock_Ice"
    },
    {
      "x": -13,
      "y": 31,
      "z": 4,
      "name": "Rock_Ice"
    },
    {
      "x": -13,
      "y": 32,
      "z": 4,
      "name": "Rock_Ice"
    },
    {
      "x": -13,
      "y": 27,
      "z": 5,
      "name": "Rock_Ice"
    },
    {
      "x": -13,
      "y": 28,
      "z": 5,
      "name": "Rock_Ice_Permafrost"
    },
    {
      "x": -13,
      "y": 29,
      "z": 5,
      "name": "Rock_Ice"
    },
    {
      "x": -13,
      "y": 30,
      "z": 5,
      "name": "Rock_Ice_Permafrost"
    },
    {
      "x": -13,
      "y": 31,
      "z": 5,
      "name": "Rock_Ice_Permafrost"
    },
    {
      "x": -12,
      "y": 25,
      "z": -14,
      "name": "Soil_Snow"
    },
    {
      "x": -12,
      "y": 24,
      "z": -13,
      "name": "Rock_Ice"
    },
    {
      "x": -12,
      "y": 25,
      "z": -13,
      "name": "Rock_Ice"
    },
    {
      "x": -12,
      "y": 24,
      "z": -12,
      "name": "Rock_Ice"
    },
    {
      "x": -12,
      "y": 25,
      "z": -12,
      "name": "Rock_Ice"
    },
    {
      "x": -12,
      "y": 26,
      "z": -12,
      "name": "Rock_Ice"
    },
    {
      "x": -12,
      "y": 23,
      "z": -11,
      "name": "Rock_Ice"
    },
    {
      "x": -12,
      "y": 24,
      "z": -11,
      "name": "Rock_Ice"
    },
    {
      "x": -12,
      "y": 25,
      "z": -11,
      "name": "Rock_Ice_Permafrost"
    },
    {
      "x": -12,
      "y": 26,
      "z": -11,
      "name": "Rock_Ice"
    },
    {
      "x": -12,
      "y": 27,
      "z": -11,
      "name": "Soil_Snow"
    },
    {
      "x": -12,
      "y": 22,
      "z": -10,
      "name": "Rock_Ice_Permafrost"
    },
    {
      "x": -12,
      "y": 23,
      "z": -10,
      "name": "Rock_Ice_Permafrost"
    },
    {
      "x": -12,
      "y": 24,
      "z": -10,
      "name": "Rock_Ice_Permafrost"
    },
    {
      "x": -12,
      "y": 25,
      "z": -10,
      "name": "Rock_Ice_Permafrost"
    },
    {
      "x": -12,
      "y": 26,
      "z": -10,
      "name": "Rock_Ice_Permafrost"
    },
    {
      "x": -12,
      "y": 27,
      "z": -10,
      "name": "Soil_Snow"
    },
    {
      "x": -12,
      "y": 22,
      "z": -9,
      "name": "Rock_Ice"
    },
    {
      "x": -12,
      "y": 23,
      "z": -9,
      "name": "Rock_Ice_Permafrost"
    },
    {
      "x": -12,
      "y": 24,
      "z": -9,
      "name": "Rock_Ice"
    },
    {
      "x": -12,
      "y": 25,
      "z": -9,
      "name": "Rock_Ice_Permafrost"
    },
    {
      "x": -12,
      "y": 26,
      "z": -9,
      "name": "Rock_Ice"
    },
    {
      "x": -12,
      "y": 27,
      "z": -9,
      "name": "Rock_Ice"
    },
    {
      "x": -12,
      "y": 28,
      "z": -9,
      "name": "Rock_Ice"
    },
    {
      "x": -12,
      "y": 21,
      "z": -8,
      "name": "Rock_Ice_Permafrost"
    },
    {
      "x": -12,
      "y": 22,
      "z": -8,
      "name": "Rock_Ice"
    },
    {
      "x": -12,
      "y": 23,
      "z": -8,
      "name": "Rock_Ice"
    },
    {
      "x": -12,
      "y": 24,
      "z": -8,
      "name": "Rock_Ice_Permafrost"
    },
    {
      "x": -12,
      "y": 25,
      "z": -8,
      "name": "Rock_Ice"
    },
    {
      "x": -12,
      "y": 26,
      "z": -8,
      "name": "Rock_Ice_Permafrost"
    },
    {
      "x": -12,
      "y": 27,
      "z": -8,
      "name": "Rock_Ice_Permafrost"
    },
    {
      "x": -12,
      "y": 28,
      "z": -8,
      "name": "Rock_Ice"
    },
    {
      "x": -12,
      "y": 29,
      "z": -8,
      "name": "Rock_Ice"
    },
    {
      "x": -12,
      "y": 20,
      "z": -7,
      "name": "Rock_Ice"
    },
    {
      "x": -12,
      "y": 21,
      "z": -7,
      "name": "Rock_Ice"
    },
    {
      "x": -12,
      "y": 22,
      "z": -7,
      "name": "Rock_Ice"
    },
    {
      "x": -12,
      "y": 23,
      "z": -7,
      "name": "Rock_Ice"
    },
    {
      "x": -12,
      "y": 24,
      "z": -7,
      "name": "Rock_Ice"
    },
    {
      "x": -12,
      "y": 25,
      "z": -7,
      "name": "Rock_Ice_Permafrost"
    },
    {
      "x": -12,
      "y": 26,
      "z": -7,
      "name": "Rock_Ice"
    },
    {
      "x": -12,
      "y": 27,
      "z": -7,
      "name": "Rock_Ice_Permafrost"
    },
    {
      "x": -12,
      "y": 28,
      "z": -7,
      "name": "Rock_Ice"
    },
    {
      "x": -12,
      "y": 29,
      "z": -7,
      "name": "Rock_Ice_Permafrost"
    },
    {
      "x": -12,
      "y": 20,
      "z": -6,
      "name": "Rock_Ice"
    },
    {
      "x": -12,
      "y": 21,
      "z": -6,
      "name": "Rock_Ice"
    },
    {
      "x": -12,
      "y": 22,
      "z": -6,
      "name": "Rock_Ice"
    },
    {
      "x": -12,
      "y": 23,
      "z": -6,
      "name": "Rock_Ice"
    },
    {
      "x": -12,
      "y": 24,
      "z": -6,
      "name": "Rock_Ice"
    },
    {
      "x": -12,
      "y": 25,
      "z": -6,
      "name": "Rock_Ice"
    },
    {
      "x": -12,
      "y": 26,
      "z": -6,
      "name": "Rock_Ice_Permafrost"
    },
    {
      "x": -12,
      "y": 27,
      "z": -6,
      "name": "Rock_Ice"
    },
    {
      "x": -12,
      "y": 28,
      "z": -6,
      "name": "Rock_Ice_Permafrost"
    },
    {
      "x": -12,
      "y": 29,
      "z": -6,
      "name": "Rock_Ice_Permafrost"
    },
    {
      "x": -12,
      "y": 30,
      "z": -6,
      "name": "Rock_Ice_Permafrost"
    },
    {
      "x": -12,
      "y": 20,
      "z": -5,
      "name": "Rock_Ice"
    },
    {
      "x": -12,
      "y": 21,
      "z": -5,
      "name": "Rock_Ice"
    },
    {
      "x": -12,
      "y": 22,
      "z": -5,
      "name": "Rock_Ice"
    },
    {
      "x": -12,
      "y": 23,
      "z": -5,
      "name": "Rock_Ice"
    },
    {
      "x": -12,
      "y": 24,
      "z": -5,
      "name": "Rock_Ice"
    },
    {
      "x": -12,
      "y": 25,
      "z": -5,
      "name": "Rock_Ice"
    },
    {
      "x": -12,
      "y": 26,
      "z": -5,
      "name": "Rock_Ice"
    },
    {
      "x": -12,
      "y": 27,
      "z": -5,
      "name": "Rock_Ice"
    },
    {
      "x": -12,
      "y": 28,
      "z": -5,
      "name": "Rock_Ice_Permafrost"
    },
    {
      "x": -12,
      "y": 29,
      "z": -5,
      "name": "Rock_Ice_Permafrost"
    },
    {
      "x": -12,
      "y": 30,
      "z": -5,
      "name": "Rock_Ice_Permafrost"
    },
    {
      "x": -12,
      "y": 31,
      "z": -5,
      "name": "Soil_Snow"
    },
    {
      "x": -12,
      "y": 19,
      "z": -4,
      "name": "Rock_Ice"
    },
    {
      "x": -12,
      "y": 20,
      "z": -4,
      "name": "Rock_Ice"
    },
    {
      "x": -12,
      "y": 21,
      "z": -4,
      "name": "Rock_Ice"
    },
    {
      "x": -12,
      "y": 22,
      "z": -4,
      "name": "Rock_Ice"
    },
    {
      "x": -12,
      "y": 23,
      "z": -4,
      "name": "Rock_Ice"
    },
    {
      "x": -12,
      "y": 24,
      "z": -4,
      "name": "Rock_Ice"
    },
    {
      "x": -12,
      "y": 25,
      "z": -4,
      "name": "Rock_Ice"
    },
    {
      "x": -12,
      "y": 26,
      "z": -4,
      "name": "Rock_Ice"
    },
    {
      "x": -12,
      "y": 27,
      "z": -4,
      "name": "Rock_Ice"
    },
    {
      "x": -12,
      "y": 28,
      "z": -4,
      "name": "Rock_Ice"
    },
    {
      "x": -12,
      "y": 29,
      "z": -4,
      "name": "Rock_Ice_Permafrost"
    },
    {
      "x": -12,
      "y": 30,
      "z": -4,
      "name": "Rock_Ice_Permafrost"
    },
    {
      "x": -12,
      "y": 31,
      "z": -4,
      "name": "Rock_Ice_Permafrost"
    },
    {
      "x": -12,
      "y": 32,
      "z": -4,
      "name": "Soil_Snow"
    },
    {
      "x": -12,
      "y": 19,
      "z": -3,
      "name": "Rock_Ice"
    },
    {
      "x": -12,
      "y": 20,
      "z": -3,
      "name": "Rock_Ice"
    },
    {
      "x": -12,
      "y": 21,
      "z": -3,
      "name": "Rock_Ice"
    },
    {
      "x": -12,
      "y": 22,
      "z": -3,
      "name": "Rock_Ice"
    },
    {
      "x": -12,
      "y": 23,
      "z": -3,
      "name": "Rock_Ice"
    },
    {
      "x": -12,
      "y": 24,
      "z": -3,
      "name": "Rock_Ice"
    },
    {
      "x": -12,
      "y": 25,
      "z": -3,
      "name": "Rock_Ice"
    },
    {
      "x": -12,
      "y": 26,
      "z": -3,
      "name": "Rock_Ice"
    },
    {
      "x": -12,
      "y": 27,
      "z": -3,
      "name": "Rock_Ice"
    },
    {
      "x": -12,
      "y": 28,
      "z": -3,
      "name": "Rock_Ice"
    },
    {
      "x": -12,
      "y": 29,
      "z": -3,
      "name": "Rock_Ice"
    },
    {
      "x": -12,
      "y": 30,
      "z": -3,
      "name": "Rock_Ice_Permafrost"
    },
    {
      "x": -12,
      "y": 31,
      "z": -3,
      "name": "Rock_Ice_Permafrost"
    },
    {
      "x": -12,
      "y": 32,
      "z": -3,
      "name": "Rock_Ice_Permafrost"
    },
    {
      "x": -12,
      "y": 33,
      "z": -3,
      "name": "Rock_Ice"
    },
    {
      "x": -12,
      "y": 19,
      "z": -2,
      "name": "Rock_Ice"
    },
    {
      "x": -12,
      "y": 20,
      "z": -2,
      "name": "Rock_Ice"
    },
    {
      "x": -12,
      "y": 21,
      "z": -2,
      "name": "Rock_Ice"
    },
    {
      "x": -12,
      "y": 22,
      "z": -2,
      "name": "Rock_Ice"
    },
    {
      "x": -12,
      "y": 23,
      "z": -2,
      "name": "Rock_Ice"
    },
    {
      "x": -12,
      "y": 24,
      "z": -2,
      "name": "Rock_Ice"
    },
    {
      "x": -12,
      "y": 25,
      "z": -2,
      "name": "Rock_Ice"
    },
    {
      "x": -12,
      "y": 26,
      "z": -2,
      "name": "Rock_Ice"
    },
    {
      "x": -12,
      "y": 27,
      "z": -2,
      "name": "Rock_Ice"
    },
    {
      "x": -12,
      "y": 28,
      "z": -2,
      "name": "Rock_Ice"
    },
    {
      "x": -12,
      "y": 29,
      "z": -2,
      "name": "Rock_Ice"
    },
    {
      "x": -12,
      "y": 30,
      "z": -2,
      "name": "Rock_Ice"
    },
    {
      "x": -12,
      "y": 31,
      "z": -2,
      "name": "Rock_Ice"
    },
    {
      "x": -12,
      "y": 32,
      "z": -2,
      "name": "Rock_Ice"
    },
    {
      "x": -12,
      "y": 33,
      "z": -2,
      "name": "Rock_Ice"
    },
    {
      "x": -12,
      "y": 34,
      "z": -2,
      "name": "Rock_Ice"
    },
    {
      "x": -12,
      "y": 19,
      "z": -1,
      "name": "Rock_Ice"
    },
    {
      "x": -12,
      "y": 20,
      "z": -1,
      "name": "Rock_Ice"
    },
    {
      "x": -12,
      "y": 21,
      "z": -1,
      "name": "Rock_Ice"
    },
    {
      "x": -12,
      "y": 22,
      "z": -1,
      "name": "Rock_Ice"
    },
    {
      "x": -12,
      "y": 23,
      "z": -1,
      "name": "Rock_Ice"
    },
    {
      "x": -12,
      "y": 24,
      "z": -1,
      "name": "Rock_Ice"
    },
    {
      "x": -12,
      "y": 25,
      "z": -1,
      "name": "Rock_Ice"
    },
    {
      "x": -12,
      "y": 26,
      "z": -1,
      "name": "Rock_Ice"
    },
    {
      "x": -12,
      "y": 27,
      "z": -1,
      "name": "Rock_Ice"
    },
    {
      "x": -12,
      "y": 28,
      "z": -1,
      "name": "Rock_Ice"
    },
    {
      "x": -12,
      "y": 29,
      "z": -1,
      "name": "Rock_Ice"
    },
    {
      "x": -12,
      "y": 30,
      "z": -1,
      "name": "Rock_Ice"
    },
    {
      "x": -12,
      "y": 31,
      "z": -1,
      "name": "Rock_Ice"
    },
    {
      "x": -12,
      "y": 32,
      "z": -1,
      "name": "Rock_Ice"
    },
    {
      "x": -12,
      "y": 33,
      "z": -1,
      "name": "Rock_Ice"
    },
    {
      "x": -12,
      "y": 34,
      "z": -1,
      "name": "Rock_Ice"
    },
    {
      "x": -12,
      "y": 18,
      "z": 0,
      "name": "Rock_Ice"
    },
    {
      "x": -12,
      "y": 19,
      "z": 0,
      "name": "Rock_Ice"
    },
    {
      "x": -12,
      "y": 20,
      "z": 0,
      "name": "Rock_Ice"
    },
    {
      "x": -12,
      "y": 21,
      "z": 0,
      "name": "Rock_Ice"
    },
    {
      "x": -12,
      "y": 22,
      "z": 0,
      "name": "Rock_Ice"
    },
    {
      "x": -12,
      "y": 23,
      "z": 0,
      "name": "Rock_Ice"
    },
    {
      "x": -12,
      "y": 24,
      "z": 0,
      "name": "Rock_Ice"
    },
    {
      "x": -12,
      "y": 25,
      "z": 0,
      "name": "Rock_Ice"
    },
    {
      "x": -12,
      "y": 26,
      "z": 0,
      "name": "Rock_Ice"
    },
    {
      "x": -12,
      "y": 27,
      "z": 0,
      "name": "Rock_Ice"
    },
    {
      "x": -12,
      "y": 28,
      "z": 0,
      "name": "Rock_Ice"
    },
    {
      "x": -12,
      "y": 29,
      "z": 0,
      "name": "Rock_Ice"
    },
    {
      "x": -12,
      "y": 30,
      "z": 0,
      "name": "Rock_Ice"
    },
    {
      "x": -12,
      "y": 31,
      "z": 0,
      "name": "Rock_Ice"
    },
    {
      "x": -12,
      "y": 32,
      "z": 0,
      "name": "Rock_Ice"
    },
    {
      "x": -12,
      "y": 33,
      "z": 0,
      "name": "Rock_Ice"
    },
    {
      "x": -12,
      "y": 34,
      "z": 0,
      "name": "Rock_Ice"
    },
    {
      "x": -12,
      "y": 35,
      "z": 0,
      "name": "Soil_Snow"
    },
    {
      "x": -12,
      "y": 18,
      "z": 1,
      "name": "Rock_Ice"
    },
    {
      "x": -12,
      "y": 19,
      "z": 1,
      "name": "Rock_Ice"
    },
    {
      "x": -12,
      "y": 20,
      "z": 1,
      "name": "Rock_Ice"
    },
    {
      "x": -12,
      "y": 21,
      "z": 1,
      "name": "Rock_Ice"
    },
    {
      "x": -12,
      "y": 22,
      "z": 1,
      "name": "Rock_Ice"
    },
    {
      "x": -12,
      "y": 23,
      "z": 1,
      "name": "Rock_Ice"
    },
    {
      "x": -12,
      "y": 24,
      "z": 1,
      "name": "Rock_Ice"
    },
    {
      "x": -12,
      "y": 25,
      "z": 1,
      "name": "Rock_Ice"
    },
    {
      "x": -12,
      "y": 26,
      "z": 1,
      "name": "Rock_Ice"
    },
    {
      "x": -12,
      "y": 27,
      "z": 1,
      "name": "Rock_Ice"
    },
    {
      "x": -12,
      "y": 28,
      "z": 1,
      "name": "Rock_Ice"
    },
    {
      "x": -12,
      "y": 29,
      "z": 1,
      "name": "Rock_Ice"
    },
    {
      "x": -12,
      "y": 30,
      "z": 1,
      "name": "Rock_Ice"
    },
    {
      "x": -12,
      "y": 31,
      "z": 1,
      "name": "Rock_Ice"
    },
    {
      "x": -12,
      "y": 32,
      "z": 1,
      "name": "Rock_Ice"
    },
    {
      "x": -12,
      "y": 33,
      "z": 1,
      "name": "Rock_Ice"
    },
    {
      "x": -12,
      "y": 34,
      "z": 1,
      "name": "Rock_Ice"
    },
    {
      "x": -12,
      "y": 35,
      "z": 1,
      "name": "Soil_Snow"
    },
    {
      "x": -12,
      "y": 18,
      "z": 2,
      "name": "Rock_Ice"
    },
    {
      "x": -12,
      "y": 19,
      "z": 2,
      "name": "Rock_Ice"
    },
    {
      "x": -12,
      "y": 20,
      "z": 2,
      "name": "Rock_Ice"
    },
    {
      "x": -12,
      "y": 21,
      "z": 2,
      "name": "Rock_Ice"
    },
    {
      "x": -12,
      "y": 22,
      "z": 2,
      "name": "Rock_Ice"
    },
    {
      "x": -12,
      "y": 23,
      "z": 2,
      "name": "Rock_Ice"
    },
    {
      "x": -12,
      "y": 24,
      "z": 2,
      "name": "Rock_Ice"
    },
    {
      "x": -12,
      "y": 25,
      "z": 2,
      "name": "Rock_Ice"
    },
    {
      "x": -12,
      "y": 26,
      "z": 2,
      "name": "Rock_Ice"
    },
    {
      "x": -12,
      "y": 27,
      "z": 2,
      "name": "Rock_Ice"
    },
    {
      "x": -12,
      "y": 28,
      "z": 2,
      "name": "Rock_Ice"
    },
    {
      "x": -12,
      "y": 29,
      "z": 2,
      "name": "Rock_Ice"
    },
    {
      "x": -12,
      "y": 30,
      "z": 2,
      "name": "Rock_Ice"
    },
    {
      "x": -12,
      "y": 31,
      "z": 2,
      "name": "Rock_Ice"
    },
    {
      "x": -12,
      "y": 32,
      "z": 2,
      "name": "Rock_Ice"
    },
    {
      "x": -12,
      "y": 33,
      "z": 2,
      "name": "Rock_Ice"
    },
    {
      "x": -12,
      "y": 34,
      "z": 2,
      "name": "Rock_Ice"
    },
    {
      "x": -12,
      "y": 35,
      "z": 2,
      "name": "Soil_Snow"
    },
    {
      "x": -12,
      "y": 18,
      "z": 3,
      "name": "Rock_Ice"
    },
    {
      "x": -12,
      "y": 19,
      "z": 3,
      "name": "Rock_Ice"
    },
    {
      "x": -12,
      "y": 20,
      "z": 3,
      "name": "Rock_Ice"
    },
    {
      "x": -12,
      "y": 21,
      "z": 3,
      "name": "Rock_Ice"
    },
    {
      "x": -12,
      "y": 22,
      "z": 3,
      "name": "Rock_Ice"
    },
    {
      "x": -12,
      "y": 23,
      "z": 3,
      "name": "Rock_Ice"
    },
    {
      "x": -12,
      "y": 24,
      "z": 3,
      "name": "Rock_Ice"
    },
    {
      "x": -12,
      "y": 25,
      "z": 3,
      "name": "Rock_Ice"
    },
    {
      "x": -12,
      "y": 26,
      "z": 3,
      "name": "Rock_Ice"
    },
    {
      "x": -12,
      "y": 27,
      "z": 3,
      "name": "Rock_Ice"
    },
    {
      "x": -12,
      "y": 28,
      "z": 3,
      "name": "Rock_Ice"
    },
    {
      "x": -12,
      "y": 29,
      "z": 3,
      "name": "Rock_Ice"
    },
    {
      "x": -12,
      "y": 30,
      "z": 3,
      "name": "Rock_Ice"
    },
    {
      "x": -12,
      "y": 31,
      "z": 3,
      "name": "Rock_Ice"
    },
    {
      "x": -12,
      "y": 32,
      "z": 3,
      "name": "Rock_Ice"
    },
    {
      "x": -12,
      "y": 33,
      "z": 3,
      "name": "Rock_Ice"
    },
    {
      "x": -12,
      "y": 34,
      "z": 3,
      "name": "Rock_Ice"
    },
    {
      "x": -12,
      "y": 19,
      "z": 4,
      "name": "Rock_Ice"
    },
    {
      "x": -12,
      "y": 20,
      "z": 4,
      "name": "Rock_Ice"
    },
    {
      "x": -12,
      "y": 21,
      "z": 4,
      "name": "Rock_Ice"
    },
    {
      "x": -12,
      "y": 22,
      "z": 4,
      "name": "Rock_Ice"
    },
    {
      "x": -12,
      "y": 23,
      "z": 4,
      "name": "Rock_Ice"
    },
    {
      "x": -12,
      "y": 24,
      "z": 4,
      "name": "Rock_Ice"
    },
    {
      "x": -12,
      "y": 25,
      "z": 4,
      "name": "Rock_Ice"
    },
    {
      "x": -12,
      "y": 26,
      "z": 4,
      "name": "Rock_Ice"
    },
    {
      "x": -12,
      "y": 27,
      "z": 4,
      "name": "Rock_Ice"
    },
    {
      "x": -12,
      "y": 28,
      "z": 4,
      "name": "Rock_Ice"
    },
    {
      "x": -12,
      "y": 29,
      "z": 4,
      "name": "Rock_Ice"
    },
    {
      "x": -12,
      "y": 30,
      "z": 4,
      "name": "Rock_Ice"
    },
    {
      "x": -12,
      "y": 31,
      "z": 4,
      "name": "Rock_Ice"
    },
    {
      "x": -12,
      "y": 32,
      "z": 4,
      "name": "Rock_Ice"
    },
    {
      "x": -12,
      "y": 33,
      "z": 4,
      "name": "Rock_Ice"
    },
    {
      "x": -12,
      "y": 34,
      "z": 4,
      "name": "Soil_Snow"
    },
    {
      "x": -12,
      "y": 20,
      "z": 5,
      "name": "Rock_Ice"
    },
    {
      "x": -12,
      "y": 21,
      "z": 5,
      "name": "Rock_Ice"
    },
    {
      "x": -12,
      "y": 22,
      "z": 5,
      "name": "Rock_Ice"
    },
    {
      "x": -12,
      "y": 23,
      "z": 5,
      "name": "Rock_Ice"
    },
    {
      "x": -12,
      "y": 24,
      "z": 5,
      "name": "Rock_Ice"
    },
    {
      "x": -12,
      "y": 25,
      "z": 5,
      "name": "Rock_Ice"
    },
    {
      "x": -12,
      "y": 26,
      "z": 5,
      "name": "Rock_Ice"
    },
    {
      "x": -12,
      "y": 27,
      "z": 5,
      "name": "Rock_Ice"
    },
    {
      "x": -12,
      "y": 28,
      "z": 5,
      "name": "Rock_Ice_Permafrost"
    },
    {
      "x": -12,
      "y": 29,
      "z": 5,
      "name": "Rock_Ice"
    },
    {
      "x": -12,
      "y": 30,
      "z": 5,
      "name": "Rock_Ice"
    },
    {
      "x": -12,
      "y": 31,
      "z": 5,
      "name": "Rock_Ice"
    },
    {
      "x": -12,
      "y": 32,
      "z": 5,
      "name": "Rock_Ice"
    },
    {
      "x": -12,
      "y": 33,
      "z": 5,
      "name": "Rock_Ice_Permafrost"
    },
    {
      "x": -12,
      "y": 29,
      "z": 6,
      "name": "Rock_Ice_Permafrost"
    },
    {
      "x": -12,
      "y": 30,
      "z": 6,
      "name": "Rock_Ice_Permafrost"
    },
    {
      "x": -12,
      "y": 31,
      "z": 6,
      "name": "Rock_Ice_Permafrost"
    },
    {
      "x": -11,
      "y": 24,
      "z": -15,
      "name": "Rock_Ice"
    },
    {
      "x": -11,
      "y": 25,
      "z": -15,
      "name": "Soil_Snow"
    },
    {
      "x": -11,
      "y": 23,
      "z": -14,
      "name": "Rock_Ice"
    },
    {
      "x": -11,
      "y": 24,
      "z": -14,
      "name": "Rock_Ice"
    },
    {
      "x": -11,
      "y": 25,
      "z": -14,
      "name": "Rock_Ice"
    },
    {
      "x": -11,
      "y": 26,
      "z": -14,
      "name": "Rock_Ice"
    },
    {
      "x": -11,
      "y": 22,
      "z": -13,
      "name": "Rock_Ice"
    },
    {
      "x": -11,
      "y": 23,
      "z": -13,
      "name": "Rock_Ice"
    },
    {
      "x": -11,
      "y": 24,
      "z": -13,
      "name": "Rock_Ice"
    },
    {
      "x": -11,
      "y": 25,
      "z": -13,
      "name": "Rock_Ice"
    },
    {
      "x": -11,
      "y": 26,
      "z": -13,
      "name": "Rock_Ice"
    },
    {
      "x": -11,
      "y": 21,
      "z": -12,
      "name": "Rock_Ice_Permafrost"
    },
    {
      "x": -11,
      "y": 22,
      "z": -12,
      "name": "Rock_Ice"
    },
    {
      "x": -11,
      "y": 23,
      "z": -12,
      "name": "Rock_Ice"
    },
    {
      "x": -11,
      "y": 24,
      "z": -12,
      "name": "Rock_Ice"
    },
    {
      "x": -11,
      "y": 25,
      "z": -12,
      "name": "Rock_Ice_Permafrost"
    },
    {
      "x": -11,
      "y": 26,
      "z": -12,
      "name": "Rock_Ice"
    },
    {
      "x": -11,
      "y": 27,
      "z": -12,
      "name": "Rock_Ice"
    },
    {
      "x": -11,
      "y": 21,
      "z": -11,
      "name": "Rock_Ice_Permafrost"
    },
    {
      "x": -11,
      "y": 22,
      "z": -11,
      "name": "Rock_Ice_Permafrost"
    },
    {
      "x": -11,
      "y": 23,
      "z": -11,
      "name": "Rock_Ice"
    },
    {
      "x": -11,
      "y": 24,
      "z": -11,
      "name": "Rock_Ice_Permafrost"
    },
    {
      "x": -11,
      "y": 25,
      "z": -11,
      "name": "Rock_Ice_Permafrost"
    },
    {
      "x": -11,
      "y": 26,
      "z": -11,
      "name": "Rock_Ice"
    },
    {
      "x": -11,
      "y": 27,
      "z": -11,
      "name": "Rock_Ice_Permafrost"
    },
    {
      "x": -11,
      "y": 28,
      "z": -11,
      "name": "Soil_Snow"
    },
    {
      "x": -11,
      "y": 20,
      "z": -10,
      "name": "Rock_Ice_Permafrost"
    },
    {
      "x": -11,
      "y": 21,
      "z": -10,
      "name": "Rock_Ice_Permafrost"
    },
    {
      "x": -11,
      "y": 22,
      "z": -10,
      "name": "Rock_Ice_Permafrost"
    },
    {
      "x": -11,
      "y": 23,
      "z": -10,
      "name": "Rock_Ice_Permafrost"
    },
    {
      "x": -11,
      "y": 24,
      "z": -10,
      "name": "Rock_Ice_Permafrost"
    },
    {
      "x": -11,
      "y": 25,
      "z": -10,
      "name": "Rock_Ice_Permafrost"
    },
    {
      "x": -11,
      "y": 26,
      "z": -10,
      "name": "Rock_Ice_Permafrost"
    },
    {
      "x": -11,
      "y": 27,
      "z": -10,
      "name": "Rock_Ice_Permafrost"
    },
    {
      "x": -11,
      "y": 28,
      "z": -10,
      "name": "Soil_Snow"
    },
    {
      "x": -11,
      "y": 19,
      "z": -9,
      "name": "Rock_Ice_Permafrost"
    },
    {
      "x": -11,
      "y": 20,
      "z": -9,
      "name": "Rock_Ice"
    },
    {
      "x": -11,
      "y": 21,
      "z": -9,
      "name": "Rock_Ice_Permafrost"
    },
    {
      "x": -11,
      "y": 22,
      "z": -9,
      "name": "Rock_Ice"
    },
    {
      "x": -11,
      "y": 23,
      "z": -9,
      "name": "Rock_Ice_Permafrost"
    },
    {
      "x": -11,
      "y": 24,
      "z": -9,
      "name": "Rock_Ice"
    },
    {
      "x": -11,
      "y": 25,
      "z": -9,
      "name": "Rock_Ice_Permafrost"
    },
    {
      "x": -11,
      "y": 26,
      "z": -9,
      "name": "Rock_Ice_Permafrost"
    },
    {
      "x": -11,
      "y": 27,
      "z": -9,
      "name": "Rock_Ice_Permafrost"
    },
    {
      "x": -11,
      "y": 28,
      "z": -9,
      "name": "Rock_Ice"
    },
    {
      "x": -11,
      "y": 29,
      "z": -9,
      "name": "Soil_Snow"
    },
    {
      "x": -11,
      "y": 19,
      "z": -8,
      "name": "Rock_Ice_Permafrost"
    },
    {
      "x": -11,
      "y": 20,
      "z": -8,
      "name": "Rock_Ice_Permafrost"
    },
    {
      "x": -11,
      "y": 21,
      "z": -8,
      "name": "Rock_Ice_Permafrost"
    },
    {
      "x": -11,
      "y": 22,
      "z": -8,
      "name": "Rock_Ice_Permafrost"
    },
    {
      "x": -11,
      "y": 23,
      "z": -8,
      "name": "Rock_Ice_Permafrost"
    },
    {
      "x": -11,
      "y": 24,
      "z": -8,
      "name": "Rock_Ice_Permafrost"
    },
    {
      "x": -11,
      "y": 25,
      "z": -8,
      "name": "Rock_Ice_Permafrost"
    },
    {
      "x": -11,
      "y": 26,
      "z": -8,
      "name": "Rock_Ice_Permafrost"
    },
    {
      "x": -11,
      "y": 27,
      "z": -8,
      "name": "Rock_Ice_Permafrost"
    },
    {
      "x": -11,
      "y": 28,
      "z": -8,
      "name": "Rock_Ice_Permafrost"
    },
    {
      "x": -11,
      "y": 29,
      "z": -8,
      "name": "Rock_Ice"
    },
    {
      "x": -11,
      "y": 30,
      "z": -8,
      "name": "Rock_Ice_Permafrost"
    },
    {
      "x": -11,
      "y": 18,
      "z": -7,
      "name": "Rock_Ice"
    },
    {
      "x": -11,
      "y": 19,
      "z": -7,
      "name": "Rock_Ice"
    },
    {
      "x": -11,
      "y": 20,
      "z": -7,
      "name": "Rock_Ice"
    },
    {
      "x": -11,
      "y": 21,
      "z": -7,
      "name": "Rock_Ice"
    },
    {
      "x": -11,
      "y": 22,
      "z": -7,
      "name": "Rock_Ice_Permafrost"
    },
    {
      "x": -11,
      "y": 23,
      "z": -7,
      "name": "Rock_Ice_Permafrost"
    },
    {
      "x": -11,
      "y": 24,
      "z": -7,
      "name": "Rock_Ice_Permafrost"
    },
    {
      "x": -11,
      "y": 25,
      "z": -7,
      "name": "Rock_Ice_Permafrost"
    },
    {
      "x": -11,
      "y": 26,
      "z": -7,
      "name": "Rock_Ice_Permafrost"
    },
    {
      "x": -11,
      "y": 27,
      "z": -7,
      "name": "Rock_Ice_Permafrost"
    },
    {
      "x": -11,
      "y": 28,
      "z": -7,
      "name": "Rock_Ice_Permafrost"
    },
    {
      "x": -11,
      "y": 29,
      "z": -7,
      "name": "Rock_Ice_Permafrost"
    },
    {
      "x": -11,
      "y": 30,
      "z": -7,
      "name": "Rock_Ice_Permafrost"
    },
    {
      "x": -11,
      "y": 31,
      "z": -7,
      "name": "Rock_Ice_Permafrost"
    },
    {
      "x": -11,
      "y": 18,
      "z": -6,
      "name": "Rock_Ice"
    },
    {
      "x": -11,
      "y": 19,
      "z": -6,
      "name": "Rock_Ice"
    },
    {
      "x": -11,
      "y": 20,
      "z": -6,
      "name": "Rock_Ice"
    },
    {
      "x": -11,
      "y": 21,
      "z": -6,
      "name": "Rock_Ice"
    },
    {
      "x": -11,
      "y": 22,
      "z": -6,
      "name": "Rock_Ice"
    },
    {
      "x": -11,
      "y": 23,
      "z": -6,
      "name": "Rock_Ice"
    },
    {
      "x": -11,
      "y": 24,
      "z": -6,
      "name": "Rock_Ice"
    },
    {
      "x": -11,
      "y": 25,
      "z": -6,
      "name": "Rock_Ice"
    },
    {
      "x": -11,
      "y": 26,
      "z": -6,
      "name": "Rock_Ice"
    },
    {
      "x": -11,
      "y": 27,
      "z": -6,
      "name": "Rock_Ice_Permafrost"
    },
    {
      "x": -11,
      "y": 28,
      "z": -6,
      "name": "Rock_Ice_Permafrost"
    },
    {
      "x": -11,
      "y": 29,
      "z": -6,
      "name": "Rock_Ice_Permafrost"
    },
    {
      "x": -11,
      "y": 30,
      "z": -6,
      "name": "Rock_Ice_Permafrost"
    },
    {
      "x": -11,
      "y": 31,
      "z": -6,
      "name": "Rock_Ice_Permafrost"
    },
    {
      "x": -11,
      "y": 32,
      "z": -6,
      "name": "Rock_Ice_Permafrost"
    },
    {
      "x": -11,
      "y": 17,
      "z": -5,
      "name": "Rock_Ice"
    },
    {
      "x": -11,
      "y": 18,
      "z": -5,
      "name": "Rock_Ice"
    },
    {
      "x": -11,
      "y": 19,
      "z": -5,
      "name": "Rock_Ice"
    },
    {
      "x": -11,
      "y": 20,
      "z": -5,
      "name": "Rock_Ice"
    },
    {
      "x": -11,
      "y": 21,
      "z": -5,
      "name": "Rock_Ice"
    },
    {
      "x": -11,
      "y": 22,
      "z": -5,
      "name": "Rock_Ice"
    },
    {
      "x": -11,
      "y": 23,
      "z": -5,
      "name": "Rock_Ice"
    },
    {
      "x": -11,
      "y": 24,
      "z": -5,
      "name": "Rock_Ice"
    },
    {
      "x": -11,
      "y": 25,
      "z": -5,
      "name": "Rock_Ice_Permafrost"
    },
    {
      "x": -11,
      "y": 26,
      "z": -5,
      "name": "Rock_Ice"
    },
    {
      "x": -11,
      "y": 27,
      "z": -5,
      "name": "Rock_Ice"
    },
    {
      "x": -11,
      "y": 28,
      "z": -5,
      "name": "Rock_Ice_Permafrost"
    },
    {
      "x": -11,
      "y": 29,
      "z": -5,
      "name": "Rock_Ice_Permafrost"
    },
    {
      "x": -11,
      "y": 30,
      "z": -5,
      "name": "Rock_Ice_Permafrost"
    },
    {
      "x": -11,
      "y": 31,
      "z": -5,
      "name": "Rock_Ice_Permafrost"
    },
    {
      "x": -11,
      "y": 32,
      "z": -5,
      "name": "Soil_Snow"
    },
    {
      "x": -11,
      "y": 17,
      "z": -4,
      "name": "Rock_Ice"
    },
    {
      "x": -11,
      "y": 18,
      "z": -4,
      "name": "Rock_Ice"
    },
    {
      "x": -11,
      "y": 19,
      "z": -4,
      "name": "Rock_Ice"
    },
    {
      "x": -11,
      "y": 20,
      "z": -4,
      "name": "Rock_Ice"
    },
    {
      "x": -11,
      "y": 21,
      "z": -4,
      "name": "Rock_Ice"
    },
    {
      "x": -11,
      "y": 22,
      "z": -4,
      "name": "Rock_Ice"
    },
    {
      "x": -11,
      "y": 23,
      "z": -4,
      "name": "Rock_Ice"
    },
    {
      "x": -11,
      "y": 24,
      "z": -4,
      "name": "Rock_Ice"
    },
    {
      "x": -11,
      "y": 25,
      "z": -4,
      "name": "Rock_Ice"
    },
    {
      "x": -11,
      "y": 26,
      "z": -4,
      "name": "Rock_Ice"
    },
    {
      "x": -11,
      "y": 27,
      "z": -4,
      "name": "Rock_Ice_Permafrost"
    },
    {
      "x": -11,
      "y": 28,
      "z": -4,
      "name": "Rock_Ice"
    },
    {
      "x": -11,
      "y": 29,
      "z": -4,
      "name": "Rock_Ice_Permafrost"
    },
    {
      "x": -11,
      "y": 30,
      "z": -4,
      "name": "Rock_Ice_Permafrost"
    },
    {
      "x": -11,
      "y": 31,
      "z": -4,
      "name": "Rock_Ice_Permafrost"
    },
    {
      "x": -11,
      "y": 32,
      "z": -4,
      "name": "Rock_Ice_Permafrost"
    },
    {
      "x": -11,
      "y": 33,
      "z": -4,
      "name": "Rock_Ice_Permafrost"
    },
    {
      "x": -11,
      "y": 17,
      "z": -3,
      "name": "Rock_Ice"
    },
    {
      "x": -11,
      "y": 18,
      "z": -3,
      "name": "Rock_Ice"
    },
    {
      "x": -11,
      "y": 19,
      "z": -3,
      "name": "Rock_Ice"
    },
    {
      "x": -11,
      "y": 20,
      "z": -3,
      "name": "Rock_Ice"
    },
    {
      "x": -11,
      "y": 21,
      "z": -3,
      "name": "Rock_Ice"
    },
    {
      "x": -11,
      "y": 22,
      "z": -3,
      "name": "Rock_Ice"
    },
    {
      "x": -11,
      "y": 23,
      "z": -3,
      "name": "Rock_Ice"
    },
    {
      "x": -11,
      "y": 24,
      "z": -3,
      "name": "Rock_Ice"
    },
    {
      "x": -11,
      "y": 25,
      "z": -3,
      "name": "Rock_Ice"
    },
    {
      "x": -11,
      "y": 26,
      "z": -3,
      "name": "Rock_Ice"
    },
    {
      "x": -11,
      "y": 27,
      "z": -3,
      "name": "Rock_Ice_Permafrost"
    },
    {
      "x": -11,
      "y": 28,
      "z": -3,
      "name": "Rock_Ice_Permafrost"
    },
    {
      "x": -11,
      "y": 29,
      "z": -3,
      "name": "Rock_Ice"
    },
    {
      "x": -11,
      "y": 30,
      "z": -3,
      "name": "Rock_Ice_Permafrost"
    },
    {
      "x": -11,
      "y": 31,
      "z": -3,
      "name": "Rock_Ice_Permafrost"
    },
    {
      "x": -11,
      "y": 32,
      "z": -3,
      "name": "Rock_Ice_Permafrost"
    },
    {
      "x": -11,
      "y": 33,
      "z": -3,
      "name": "Rock_Ice"
    },
    {
      "x": -11,
      "y": 34,
      "z": -3,
      "name": "Rock_Ice_Permafrost"
    },
    {
      "x": -11,
      "y": 17,
      "z": -2,
      "name": "Rock_Ice"
    },
    {
      "x": -11,
      "y": 18,
      "z": -2,
      "name": "Rock_Ice"
    },
    {
      "x": -11,
      "y": 19,
      "z": -2,
      "name": "Rock_Ice"
    },
    {
      "x": -11,
      "y": 20,
      "z": -2,
      "name": "Rock_Ice"
    },
    {
      "x": -11,
      "y": 21,
      "z": -2,
      "name": "Rock_Ice"
    },
    {
      "x": -11,
      "y": 22,
      "z": -2,
      "name": "Rock_Ice"
    },
    {
      "x": -11,
      "y": 23,
      "z": -2,
      "name": "Rock_Ice"
    },
    {
      "x": -11,
      "y": 24,
      "z": -2,
      "name": "Rock_Ice"
    },
    {
      "x": -11,
      "y": 25,
      "z": -2,
      "name": "Rock_Ice"
    },
    {
      "x": -11,
      "y": 26,
      "z": -2,
      "name": "Rock_Ice"
    },
    {
      "x": -11,
      "y": 27,
      "z": -2,
      "name": "Rock_Ice"
    },
    {
      "x": -11,
      "y": 28,
      "z": -2,
      "name": "Rock_Ice_Permafrost"
    },
    {
      "x": -11,
      "y": 29,
      "z": -2,
      "name": "Rock_Ice"
    },
    {
      "x": -11,
      "y": 30,
      "z": -2,
      "name": "Rock_Ice"
    },
    {
      "x": -11,
      "y": 31,
      "z": -2,
      "name": "Rock_Ice"
    },
    {
      "x": -11,
      "y": 32,
      "z": -2,
      "name": "Rock_Ice"
    },
    {
      "x": -11,
      "y": 33,
      "z": -2,
      "name": "Rock_Ice"
    },
    {
      "x": -11,
      "y": 34,
      "z": -2,
      "name": "Rock_Ice"
    },
    {
      "x": -11,
      "y": 35,
      "z": -2,
      "name": "Rock_Ice"
    },
    {
      "x": -11,
      "y": 17,
      "z": -1,
      "name": "Rock_Ice"
    },
    {
      "x": -11,
      "y": 18,
      "z": -1,
      "name": "Rock_Ice"
    },
    {
      "x": -11,
      "y": 19,
      "z": -1,
      "name": "Rock_Ice"
    },
    {
      "x": -11,
      "y": 20,
      "z": -1,
      "name": "Rock_Ice"
    },
    {
      "x": -11,
      "y": 21,
      "z": -1,
      "name": "Rock_Ice"
    },
    {
      "x": -11,
      "y": 22,
      "z": -1,
      "name": "Rock_Ice"
    },
    {
      "x": -11,
      "y": 23,
      "z": -1,
      "name": "Rock_Ice"
    },
    {
      "x": -11,
      "y": 24,
      "z": -1,
      "name": "Rock_Ice"
    },
    {
      "x": -11,
      "y": 25,
      "z": -1,
      "name": "Rock_Ice"
    },
    {
      "x": -11,
      "y": 26,
      "z": -1,
      "name": "Rock_Ice"
    },
    {
      "x": -11,
      "y": 27,
      "z": -1,
      "name": "Rock_Ice"
    },
    {
      "x": -11,
      "y": 28,
      "z": -1,
      "name": "Rock_Ice"
    },
    {
      "x": -11,
      "y": 29,
      "z": -1,
      "name": "Rock_Ice"
    },
    {
      "x": -11,
      "y": 30,
      "z": -1,
      "name": "Rock_Ice"
    },
    {
      "x": -11,
      "y": 31,
      "z": -1,
      "name": "Rock_Ice"
    },
    {
      "x": -11,
      "y": 32,
      "z": -1,
      "name": "Rock_Ice"
    },
    {
      "x": -11,
      "y": 33,
      "z": -1,
      "name": "Rock_Ice"
    },
    {
      "x": -11,
      "y": 34,
      "z": -1,
      "name": "Rock_Ice"
    },
    {
      "x": -11,
      "y": 35,
      "z": -1,
      "name": "Rock_Ice"
    },
    {
      "x": -11,
      "y": 16,
      "z": 0,
      "name": "Rock_Ice"
    },
    {
      "x": -11,
      "y": 17,
      "z": 0,
      "name": "Rock_Ice"
    },
    {
      "x": -11,
      "y": 18,
      "z": 0,
      "name": "Rock_Ice"
    },
    {
      "x": -11,
      "y": 19,
      "z": 0,
      "name": "Rock_Ice"
    },
    {
      "x": -11,
      "y": 20,
      "z": 0,
      "name": "Rock_Ice"
    },
    {
      "x": -11,
      "y": 21,
      "z": 0,
      "name": "Rock_Ice"
    },
    {
      "x": -11,
      "y": 22,
      "z": 0,
      "name": "Rock_Ice"
    },
    {
      "x": -11,
      "y": 23,
      "z": 0,
      "name": "Rock_Ice"
    },
    {
      "x": -11,
      "y": 24,
      "z": 0,
      "name": "Rock_Ice"
    },
    {
      "x": -11,
      "y": 25,
      "z": 0,
      "name": "Rock_Ice"
    },
    {
      "x": -11,
      "y": 26,
      "z": 0,
      "name": "Rock_Ice"
    },
    {
      "x": -11,
      "y": 27,
      "z": 0,
      "name": "Rock_Ice"
    },
    {
      "x": -11,
      "y": 28,
      "z": 0,
      "name": "Rock_Ice"
    },
    {
      "x": -11,
      "y": 29,
      "z": 0,
      "name": "Rock_Ice"
    },
    {
      "x": -11,
      "y": 30,
      "z": 0,
      "name": "Rock_Ice"
    },
    {
      "x": -11,
      "y": 31,
      "z": 0,
      "name": "Rock_Ice"
    },
    {
      "x": -11,
      "y": 32,
      "z": 0,
      "name": "Rock_Ice"
    },
    {
      "x": -11,
      "y": 33,
      "z": 0,
      "name": "Rock_Ice"
    },
    {
      "x": -11,
      "y": 34,
      "z": 0,
      "name": "Rock_Ice"
    },
    {
      "x": -11,
      "y": 35,
      "z": 0,
      "name": "Soil_Snow"
    },
    {
      "x": -11,
      "y": 16,
      "z": 1,
      "name": "Rock_Ice"
    },
    {
      "x": -11,
      "y": 17,
      "z": 1,
      "name": "Rock_Ice"
    },
    {
      "x": -11,
      "y": 18,
      "z": 1,
      "name": "Rock_Ice"
    },
    {
      "x": -11,
      "y": 19,
      "z": 1,
      "name": "Rock_Ice"
    },
    {
      "x": -11,
      "y": 20,
      "z": 1,
      "name": "Rock_Ice"
    },
    {
      "x": -11,
      "y": 21,
      "z": 1,
      "name": "Rock_Ice"
    },
    {
      "x": -11,
      "y": 22,
      "z": 1,
      "name": "Rock_Ice"
    },
    {
      "x": -11,
      "y": 23,
      "z": 1,
      "name": "Rock_Ice"
    },
    {
      "x": -11,
      "y": 24,
      "z": 1,
      "name": "Rock_Ice"
    },
    {
      "x": -11,
      "y": 25,
      "z": 1,
      "name": "Rock_Ice"
    },
    {
      "x": -11,
      "y": 26,
      "z": 1,
      "name": "Rock_Ice"
    },
    {
      "x": -11,
      "y": 27,
      "z": 1,
      "name": "Rock_Ice"
    },
    {
      "x": -11,
      "y": 28,
      "z": 1,
      "name": "Rock_Ice"
    },
    {
      "x": -11,
      "y": 29,
      "z": 1,
      "name": "Rock_Ice"
    },
    {
      "x": -11,
      "y": 30,
      "z": 1,
      "name": "Rock_Ice"
    },
    {
      "x": -11,
      "y": 31,
      "z": 1,
      "name": "Rock_Ice"
    },
    {
      "x": -11,
      "y": 32,
      "z": 1,
      "name": "Rock_Ice"
    },
    {
      "x": -11,
      "y": 33,
      "z": 1,
      "name": "Rock_Ice"
    },
    {
      "x": -11,
      "y": 34,
      "z": 1,
      "name": "Rock_Ice"
    },
    {
      "x": -11,
      "y": 35,
      "z": 1,
      "name": "Rock_Ice"
    },
    {
      "x": -11,
      "y": 36,
      "z": 1,
      "name": "Soil_Snow"
    },
    {
      "x": -11,
      "y": 16,
      "z": 2,
      "name": "Rock_Ice"
    },
    {
      "x": -11,
      "y": 17,
      "z": 2,
      "name": "Rock_Ice"
    },
    {
      "x": -11,
      "y": 18,
      "z": 2,
      "name": "Rock_Ice"
    },
    {
      "x": -11,
      "y": 19,
      "z": 2,
      "name": "Rock_Ice"
    },
    {
      "x": -11,
      "y": 20,
      "z": 2,
      "name": "Rock_Ice"
    },
    {
      "x": -11,
      "y": 21,
      "z": 2,
      "name": "Rock_Ice"
    },
    {
      "x": -11,
      "y": 22,
      "z": 2,
      "name": "Rock_Ice"
    },
    {
      "x": -11,
      "y": 23,
      "z": 2,
      "name": "Rock_Ice"
    },
    {
      "x": -11,
      "y": 24,
      "z": 2,
      "name": "Rock_Ice"
    },
    {
      "x": -11,
      "y": 25,
      "z": 2,
      "name": "Rock_Ice"
    },
    {
      "x": -11,
      "y": 26,
      "z": 2,
      "name": "Rock_Ice"
    },
    {
      "x": -11,
      "y": 27,
      "z": 2,
      "name": "Rock_Ice"
    },
    {
      "x": -11,
      "y": 28,
      "z": 2,
      "name": "Rock_Ice"
    },
    {
      "x": -11,
      "y": 29,
      "z": 2,
      "name": "Rock_Ice"
    },
    {
      "x": -11,
      "y": 30,
      "z": 2,
      "name": "Rock_Ice"
    },
    {
      "x": -11,
      "y": 31,
      "z": 2,
      "name": "Rock_Ice"
    },
    {
      "x": -11,
      "y": 32,
      "z": 2,
      "name": "Rock_Ice"
    },
    {
      "x": -11,
      "y": 33,
      "z": 2,
      "name": "Rock_Ice"
    },
    {
      "x": -11,
      "y": 34,
      "z": 2,
      "name": "Rock_Ice"
    },
    {
      "x": -11,
      "y": 35,
      "z": 2,
      "name": "Rock_Ice"
    },
    {
      "x": -11,
      "y": 36,
      "z": 2,
      "name": "Soil_Snow"
    },
    {
      "x": -11,
      "y": 17,
      "z": 3,
      "name": "Rock_Ice"
    },
    {
      "x": -11,
      "y": 18,
      "z": 3,
      "name": "Rock_Ice"
    },
    {
      "x": -11,
      "y": 19,
      "z": 3,
      "name": "Rock_Ice"
    },
    {
      "x": -11,
      "y": 20,
      "z": 3,
      "name": "Rock_Ice"
    },
    {
      "x": -11,
      "y": 21,
      "z": 3,
      "name": "Rock_Ice"
    },
    {
      "x": -11,
      "y": 22,
      "z": 3,
      "name": "Rock_Ice"
    },
    {
      "x": -11,
      "y": 23,
      "z": 3,
      "name": "Rock_Ice"
    },
    {
      "x": -11,
      "y": 24,
      "z": 3,
      "name": "Rock_Ice"
    },
    {
      "x": -11,
      "y": 25,
      "z": 3,
      "name": "Rock_Ice"
    },
    {
      "x": -11,
      "y": 26,
      "z": 3,
      "name": "Rock_Ice"
    },
    {
      "x": -11,
      "y": 27,
      "z": 3,
      "name": "Rock_Ice"
    },
    {
      "x": -11,
      "y": 28,
      "z": 3,
      "name": "Rock_Ice"
    },
    {
      "x": -11,
      "y": 29,
      "z": 3,
      "name": "Rock_Ice"
    },
    {
      "x": -11,
      "y": 30,
      "z": 3,
      "name": "Rock_Ice"
    },
    {
      "x": -11,
      "y": 31,
      "z": 3,
      "name": "Rock_Ice"
    },
    {
      "x": -11,
      "y": 32,
      "z": 3,
      "name": "Rock_Ice"
    },
    {
      "x": -11,
      "y": 33,
      "z": 3,
      "name": "Rock_Ice"
    },
    {
      "x": -11,
      "y": 34,
      "z": 3,
      "name": "Rock_Ice"
    },
    {
      "x": -11,
      "y": 35,
      "z": 3,
      "name": "Rock_Ice"
    },
    {
      "x": -11,
      "y": 36,
      "z": 3,
      "name": "Rock_Ice"
    },
    {
      "x": -11,
      "y": 17,
      "z": 4,
      "name": "Rock_Ice"
    },
    {
      "x": -11,
      "y": 18,
      "z": 4,
      "name": "Rock_Ice"
    },
    {
      "x": -11,
      "y": 19,
      "z": 4,
      "name": "Rock_Ice"
    },
    {
      "x": -11,
      "y": 20,
      "z": 4,
      "name": "Rock_Ice"
    },
    {
      "x": -11,
      "y": 21,
      "z": 4,
      "name": "Rock_Ice"
    },
    {
      "x": -11,
      "y": 22,
      "z": 4,
      "name": "Rock_Ice"
    },
    {
      "x": -11,
      "y": 23,
      "z": 4,
      "name": "Rock_Ice"
    },
    {
      "x": -11,
      "y": 24,
      "z": 4,
      "name": "Rock_Ice"
    },
    {
      "x": -11,
      "y": 25,
      "z": 4,
      "name": "Rock_Ice"
    },
    {
      "x": -11,
      "y": 26,
      "z": 4,
      "name": "Rock_Ice"
    },
    {
      "x": -11,
      "y": 27,
      "z": 4,
      "name": "Rock_Ice"
    },
    {
      "x": -11,
      "y": 28,
      "z": 4,
      "name": "Rock_Ice"
    },
    {
      "x": -11,
      "y": 29,
      "z": 4,
      "name": "Rock_Ice"
    },
    {
      "x": -11,
      "y": 30,
      "z": 4,
      "name": "Rock_Ice"
    },
    {
      "x": -11,
      "y": 31,
      "z": 4,
      "name": "Rock_Ice"
    },
    {
      "x": -11,
      "y": 32,
      "z": 4,
      "name": "Rock_Ice"
    },
    {
      "x": -11,
      "y": 33,
      "z": 4,
      "name": "Rock_Ice"
    },
    {
      "x": -11,
      "y": 34,
      "z": 4,
      "name": "Rock_Ice"
    },
    {
      "x": -11,
      "y": 35,
      "z": 4,
      "name": "Rock_Ice"
    },
    {
      "x": -11,
      "y": 18,
      "z": 5,
      "name": "Rock_Ice"
    },
    {
      "x": -11,
      "y": 19,
      "z": 5,
      "name": "Rock_Ice"
    },
    {
      "x": -11,
      "y": 20,
      "z": 5,
      "name": "Rock_Ice"
    },
    {
      "x": -11,
      "y": 21,
      "z": 5,
      "name": "Rock_Ice"
    },
    {
      "x": -11,
      "y": 22,
      "z": 5,
      "name": "Rock_Ice"
    },
    {
      "x": -11,
      "y": 23,
      "z": 5,
      "name": "Rock_Ice"
    },
    {
      "x": -11,
      "y": 24,
      "z": 5,
      "name": "Rock_Ice"
    },
    {
      "x": -11,
      "y": 25,
      "z": 5,
      "name": "Rock_Ice"
    },
    {
      "x": -11,
      "y": 26,
      "z": 5,
      "name": "Rock_Ice"
    },
    {
      "x": -11,
      "y": 27,
      "z": 5,
      "name": "Rock_Ice"
    },
    {
      "x": -11,
      "y": 28,
      "z": 5,
      "name": "Rock_Ice_Permafrost"
    },
    {
      "x": -11,
      "y": 29,
      "z": 5,
      "name": "Rock_Ice"
    },
    {
      "x": -11,
      "y": 30,
      "z": 5,
      "name": "Rock_Ice"
    },
    {
      "x": -11,
      "y": 31,
      "z": 5,
      "name": "Rock_Ice"
    },
    {
      "x": -11,
      "y": 32,
      "z": 5,
      "name": "Rock_Ice"
    },
    {
      "x": -11,
      "y": 33,
      "z": 5,
      "name": "Rock_Ice"
    },
    {
      "x": -11,
      "y": 34,
      "z": 5,
      "name": "Rock_Ice"
    },
    {
      "x": -11,
      "y": 35,
      "z": 5,
      "name": "Rock_Ice"
    },
    {
      "x": -11,
      "y": 23,
      "z": 6,
      "name": "Rock_Ice"
    },
    {
      "x": -11,
      "y": 24,
      "z": 6,
      "name": "Rock_Ice"
    },
    {
      "x": -11,
      "y": 25,
      "z": 6,
      "name": "Rock_Ice_Permafrost"
    },
    {
      "x": -11,
      "y": 26,
      "z": 6,
      "name": "Rock_Ice_Permafrost"
    },
    {
      "x": -11,
      "y": 27,
      "z": 6,
      "name": "Rock_Ice_Permafrost"
    },
    {
      "x": -11,
      "y": 28,
      "z": 6,
      "name": "Rock_Ice_Permafrost"
    },
    {
      "x": -11,
      "y": 29,
      "z": 6,
      "name": "Rock_Ice"
    },
    {
      "x": -11,
      "y": 30,
      "z": 6,
      "name": "Rock_Ice"
    },
    {
      "x": -11,
      "y": 31,
      "z": 6,
      "name": "Rock_Ice"
    },
    {
      "x": -11,
      "y": 32,
      "z": 6,
      "name": "Rock_Ice"
    },
    {
      "x": -11,
      "y": 33,
      "z": 6,
      "name": "Rock_Ice"
    },
    {
      "x": -11,
      "y": 30,
      "z": 7,
      "name": "Rock_Ice"
    },
    {
      "x": -10,
      "y": 24,
      "z": -16,
      "name": "Rock_Ice"
    },
    {
      "x": -10,
      "y": 25,
      "z": -16,
      "name": "Soil_Snow"
    },
    {
      "x": -10,
      "y": 22,
      "z": -15,
      "name": "Rock_Ice"
    },
    {
      "x": -10,
      "y": 23,
      "z": -15,
      "name": "Rock_Ice"
    },
    {
      "x": -10,
      "y": 24,
      "z": -15,
      "name": "Rock_Ice"
    },
    {
      "x": -10,
      "y": 25,
      "z": -15,
      "name": "Rock_Ice"
    },
    {
      "x": -10,
      "y": 26,
      "z": -15,
      "name": "Soil_Snow"
    },
    {
      "x": -10,
      "y": 21,
      "z": -14,
      "name": "Rock_Ice"
    },
    {
      "x": -10,
      "y": 22,
      "z": -14,
      "name": "Rock_Ice"
    },
    {
      "x": -10,
      "y": 23,
      "z": -14,
      "name": "Rock_Ice"
    },
    {
      "x": -10,
      "y": 24,
      "z": -14,
      "name": "Rock_Ice"
    },
    {
      "x": -10,
      "y": 25,
      "z": -14,
      "name": "Rock_Ice"
    },
    {
      "x": -10,
      "y": 26,
      "z": -14,
      "name": "Rock_Ice"
    },
    {
      "x": -10,
      "y": 27,
      "z": -14,
      "name": "Rock_Ice"
    },
    {
      "x": -10,
      "y": 20,
      "z": -13,
      "name": "Rock_Ice"
    },
    {
      "x": -10,
      "y": 21,
      "z": -13,
      "name": "Rock_Ice"
    },
    {
      "x": -10,
      "y": 22,
      "z": -13,
      "name": "Rock_Ice"
    },
    {
      "x": -10,
      "y": 23,
      "z": -13,
      "name": "Rock_Ice_Permafrost"
    },
    {
      "x": -10,
      "y": 24,
      "z": -13,
      "name": "Rock_Ice"
    },
    {
      "x": -10,
      "y": 25,
      "z": -13,
      "name": "Rock_Ice"
    },
    {
      "x": -10,
      "y": 26,
      "z": -13,
      "name": "Rock_Ice"
    },
    {
      "x": -10,
      "y": 27,
      "z": -13,
      "name": "Rock_Ice"
    },
    {
      "x": -10,
      "y": 19,
      "z": -12,
      "name": "Rock_Ice_Permafrost"
    },
    {
      "x": -10,
      "y": 20,
      "z": -12,
      "name": "Rock_Ice"
    },
    {
      "x": -10,
      "y": 21,
      "z": -12,
      "name": "Rock_Ice_Permafrost"
    },
    {
      "x": -10,
      "y": 22,
      "z": -12,
      "name": "Rock_Ice_Permafrost"
    },
    {
      "x": -10,
      "y": 23,
      "z": -12,
      "name": "Rock_Ice"
    },
    {
      "x": -10,
      "y": 24,
      "z": -12,
      "name": "Rock_Ice_Permafrost"
    },
    {
      "x": -10,
      "y": 25,
      "z": -12,
      "name": "Rock_Ice_Permafrost"
    },
    {
      "x": -10,
      "y": 26,
      "z": -12,
      "name": "Rock_Ice"
    },
    {
      "x": -10,
      "y": 27,
      "z": -12,
      "name": "Rock_Ice"
    },
    {
      "x": -10,
      "y": 28,
      "z": -12,
      "name": "Soil_Snow"
    },
    {
      "x": -10,
      "y": 19,
      "z": -11,
      "name": "Rock_Ice_Permafrost"
    },
    {
      "x": -10,
      "y": 20,
      "z": -11,
      "name": "Rock_Ice_Permafrost"
    },
    {
      "x": -10,
      "y": 21,
      "z": -11,
      "name": "Rock_Ice_Permafrost"
    },
    {
      "x": -10,
      "y": 22,
      "z": -11,
      "name": "Rock_Ice_Permafrost"
    },
    {
      "x": -10,
      "y": 23,
      "z": -11,
      "name": "Rock_Ice_Permafrost"
    },
    {
      "x": -10,
      "y": 24,
      "z": -11,
      "name": "Rock_Ice_Permafrost"
    },
    {
      "x": -10,
      "y": 25,
      "z": -11,
      "name": "Rock_Ice_Permafrost"
    },
    {
      "x": -10,
      "y": 26,
      "z": -11,
      "name": "Rock_Ice_Permafrost"
    },
    {
      "x": -10,
      "y": 27,
      "z": -11,
      "name": "Rock_Ice_Permafrost"
    },
    {
      "x": -10,
      "y": 28,
      "z": -11,
      "name": "Rock_Ice"
    },
    {
      "x": -10,
      "y": 29,
      "z": -11,
      "name": "Soil_Snow"
    },
    {
      "x": -10,
      "y": 18,
      "z": -10,
      "name": "Rock_Ice_Permafrost"
    },
    {
      "x": -10,
      "y": 19,
      "z": -10,
      "name": "Rock_Ice_Permafrost"
    },
    {
      "x": -10,
      "y": 20,
      "z": -10,
      "name": "Rock_Ice_Permafrost"
    },
    {
      "x": -10,
      "y": 21,
      "z": -10,
      "name": "Rock_Ice_Permafrost"
    },
    {
      "x": -10,
      "y": 22,
      "z": -10,
      "name": "Rock_Ice_Permafrost"
    },
    {
      "x": -10,
      "y": 23,
      "z": -10,
      "name": "Rock_Ice_Permafrost"
    },
    {
      "x": -10,
      "y": 24,
      "z": -10,
      "name": "Rock_Ice_Permafrost"
    },
    {
      "x": -10,
      "y": 25,
      "z": -10,
      "name": "Rock_Ice_Permafrost"
    },
    {
      "x": -10,
      "y": 26,
      "z": -10,
      "name": "Rock_Ice_Permafrost"
    },
    {
      "x": -10,
      "y": 27,
      "z": -10,
      "name": "Rock_Ice_Permafrost"
    },
    {
      "x": -10,
      "y": 28,
      "z": -10,
      "name": "Rock_Ice"
    },
    {
      "x": -10,
      "y": 29,
      "z": -10,
      "name": "Rock_Ice_Permafrost"
    },
    {
      "x": -10,
      "y": 30,
      "z": -10,
      "name": "Soil_Snow"
    },
    {
      "x": -10,
      "y": 17,
      "z": -9,
      "name": "Rock_Ice_Permafrost"
    },
    {
      "x": -10,
      "y": 18,
      "z": -9,
      "name": "Rock_Ice_Permafrost"
    },
    {
      "x": -10,
      "y": 19,
      "z": -9,
      "name": "Rock_Ice_Permafrost"
    },
    {
      "x": -10,
      "y": 20,
      "z": -9,
      "name": "Rock_Ice_Permafrost"
    },
    {
      "x": -10,
      "y": 21,
      "z": -9,
      "name": "Rock_Ice_Permafrost"
    },
    {
      "x": -10,
      "y": 22,
      "z": -9,
      "name": "Rock_Ice_Permafrost"
    },
    {
      "x": -10,
      "y": 23,
      "z": -9,
      "name": "Rock_Ice_Permafrost"
    },
    {
      "x": -10,
      "y": 24,
      "z": -9,
      "name": "Rock_Ice_Permafrost"
    },
    {
      "x": -10,
      "y": 25,
      "z": -9,
      "name": "Rock_Ice_Permafrost"
    },
    {
      "x": -10,
      "y": 26,
      "z": -9,
      "name": "Rock_Ice"
    },
    {
      "x": -10,
      "y": 27,
      "z": -9,
      "name": "Rock_Ice_Permafrost"
    },
    {
      "x": -10,
      "y": 28,
      "z": -9,
      "name": "Rock_Ice_Permafrost"
    },
    {
      "x": -10,
      "y": 29,
      "z": -9,
      "name": "Rock_Ice_Permafrost"
    },
    {
      "x": -10,
      "y": 30,
      "z": -9,
      "name": "Soil_Snow"
    },
    {
      "x": -10,
      "y": 17,
      "z": -8,
      "name": "Rock_Ice_Permafrost"
    },
    {
      "x": -10,
      "y": 18,
      "z": -8,
      "name": "Rock_Ice_Permafrost"
    },
    {
      "x": -10,
      "y": 19,
      "z": -8,
      "name": "Rock_Ice_Permafrost"
    },
    {
      "x": -10,
      "y": 20,
      "z": -8,
      "name": "Rock_Ice_Permafrost"
    },
    {
      "x": -10,
      "y": 21,
      "z": -8,
      "name": "Rock_Ice_Permafrost"
    },
    {
      "x": -10,
      "y": 22,
      "z": -8,
      "name": "Rock_Ice_Permafrost"
    },
    {
      "x": -10,
      "y": 23,
      "z": -8,
      "name": "Rock_Ice_Permafrost"
    },
    {
      "x": -10,
      "y": 24,
      "z": -8,
      "name": "Rock_Ice_Permafrost"
    },
    {
      "x": -10,
      "y": 25,
      "z": -8,
      "name": "Rock_Ice_Permafrost"
    },
    {
      "x": -10,
      "y": 26,
      "z": -8,
      "name": "Rock_Ice_Permafrost"
    },
    {
      "x": -10,
      "y": 27,
      "z": -8,
      "name": "Rock_Ice_Permafrost"
    },
    {
      "x": -10,
      "y": 28,
      "z": -8,
      "name": "Rock_Ice_Permafrost"
    },
    {
      "x": -10,
      "y": 29,
      "z": -8,
      "name": "Rock_Ice_Permafrost"
    },
    {
      "x": -10,
      "y": 30,
      "z": -8,
      "name": "Rock_Ice_Permafrost"
    },
    {
      "x": -10,
      "y": 31,
      "z": -8,
      "name": "Rock_Ice"
    },
    {
      "x": -10,
      "y": 16,
      "z": -7,
      "name": "Rock_Ice_Permafrost"
    },
    {
      "x": -10,
      "y": 17,
      "z": -7,
      "name": "Rock_Ice"
    },
    {
      "x": -10,
      "y": 18,
      "z": -7,
      "name": "Rock_Ice"
    },
    {
      "x": -10,
      "y": 19,
      "z": -7,
      "name": "Rock_Ice_Permafrost"
    },
    {
      "x": -10,
      "y": 20,
      "z": -7,
      "name": "Rock_Ice_Permafrost"
    },
    {
      "x": -10,
      "y": 21,
      "z": -7,
      "name": "Rock_Ice_Permafrost"
    },
    {
      "x": -10,
      "y": 22,
      "z": -7,
      "name": "Rock_Ice_Permafrost"
    },
    {
      "x": -10,
      "y": 23,
      "z": -7,
      "name": "Rock_Ice_Permafrost"
    },
    {
      "x": -10,
      "y": 24,
      "z": -7,
      "name": "Rock_Ice_Permafrost"
    },
    {
      "x": -10,
      "y": 25,
      "z": -7,
      "name": "Rock_Ice_Permafrost"
    },
    {
      "x": -10,
      "y": 26,
      "z": -7,
      "name": "Rock_Ice_Permafrost"
    },
    {
      "x": -10,
      "y": 27,
      "z": -7,
      "name": "Rock_Ice_Permafrost"
    },
    {
      "x": -10,
      "y": 28,
      "z": -7,
      "name": "Rock_Ice_Permafrost"
    },
    {
      "x": -10,
      "y": 29,
      "z": -7,
      "name": "Rock_Ice_Permafrost"
    },
    {
      "x": -10,
      "y": 30,
      "z": -7,
      "name": "Rock_Ice_Permafrost"
    },
    {
      "x": -10,
      "y": 31,
      "z": -7,
      "name": "Rock_Ice_Permafrost"
    },
    {
      "x": -10,
      "y": 32,
      "z": -7,
      "name": "Rock_Ice_Permafrost"
    },
    {
      "x": -10,
      "y": 16,
      "z": -6,
      "name": "Rock_Ice"
    },
    {
      "x": -10,
      "y": 17,
      "z": -6,
      "name": "Rock_Ice"
    },
    {
      "x": -10,
      "y": 18,
      "z": -6,
      "name": "Rock_Ice"
    },
    {
      "x": -10,
      "y": 19,
      "z": -6,
      "name": "Rock_Ice"
    },
    {
      "x": -10,
      "y": 20,
      "z": -6,
      "name": "Rock_Ice"
    },
    {
      "x": -10,
      "y": 21,
      "z": -6,
      "name": "Rock_Ice"
    },
    {
      "x": -10,
      "y": 22,
      "z": -6,
      "name": "Rock_Ice"
    },
    {
      "x": -10,
      "y": 23,
      "z": -6,
      "name": "Rock_Ice_Permafrost"
    },
    {
      "x": -10,
      "y": 24,
      "z": -6,
      "name": "Rock_Ice_Permafrost"
    },
    {
      "x": -10,
      "y": 25,
      "z": -6,
      "name": "Rock_Ice_Permafrost"
    },
    {
      "x": -10,
      "y": 26,
      "z": -6,
      "name": "Rock_Ice_Permafrost"
    },
    {
      "x": -10,
      "y": 27,
      "z": -6,
      "name": "Rock_Ice_Permafrost"
    },
    {
      "x": -10,
      "y": 28,
      "z": -6,
      "name": "Rock_Ice_Permafrost"
    },
    {
      "x": -10,
      "y": 29,
      "z": -6,
      "name": "Rock_Ice_Permafrost"
    },
    {
      "x": -10,
      "y": 30,
      "z": -6,
      "name": "Rock_Ice_Permafrost"
    },
    {
      "x": -10,
      "y": 31,
      "z": -6,
      "name": "Rock_Ice_Permafrost"
    },
    {
      "x": -10,
      "y": 32,
      "z": -6,
      "name": "Rock_Ice_Permafrost"
    },
    {
      "x": -10,
      "y": 33,
      "z": -6,
      "name": "Rock_Ice_Permafrost"
    },
    {
      "x": -10,
      "y": 16,
      "z": -5,
      "name": "Rock_Ice"
    },
    {
      "x": -10,
      "y": 17,
      "z": -5,
      "name": "Rock_Ice"
    },
    {
      "x": -10,
      "y": 18,
      "z": -5,
      "name": "Rock_Ice"
    },
    {
      "x": -10,
      "y": 19,
      "z": -5,
      "name": "Rock_Ice"
    },
    {
      "x": -10,
      "y": 20,
      "z": -5,
      "name": "Rock_Ice"
    },
    {
      "x": -10,
      "y": 21,
      "z": -5,
      "name": "Rock_Ice"
    },
    {
      "x": -10,
      "y": 22,
      "z": -5,
      "name": "Rock_Ice"
    },
    {
      "x": -10,
      "y": 23,
      "z": -5,
      "name": "Rock_Ice_Permafrost"
    },
    {
      "x": -10,
      "y": 24,
      "z": -5,
      "name": "Rock_Ice"
    },
    {
      "x": -10,
      "y": 25,
      "z": -5,
      "name": "Rock_Ice_Permafrost"
    },
    {
      "x": -10,
      "y": 26,
      "z": -5,
      "name": "Rock_Ice"
    },
    {
      "x": -10,
      "y": 27,
      "z": -5,
      "name": "Rock_Ice_Permafrost"
    },
    {
      "x": -10,
      "y": 28,
      "z": -5,
      "name": "Rock_Ice_Permafrost"
    },
    {
      "x": -10,
      "y": 29,
      "z": -5,
      "name": "Rock_Ice_Permafrost"
    },
    {
      "x": -10,
      "y": 30,
      "z": -5,
      "name": "Rock_Ice_Permafrost"
    },
    {
      "x": -10,
      "y": 31,
      "z": -5,
      "name": "Rock_Ice_Permafrost"
    },
    {
      "x": -10,
      "y": 32,
      "z": -5,
      "name": "Rock_Ice_Permafrost"
    },
    {
      "x": -10,
      "y": 33,
      "z": -5,
      "name": "Rock_Ice_Permafrost"
    },
    {
      "x": -10,
      "y": 15,
      "z": -4,
      "name": "Rock_Ice"
    },
    {
      "x": -10,
      "y": 16,
      "z": -4,
      "name": "Rock_Ice"
    },
    {
      "x": -10,
      "y": 17,
      "z": -4,
      "name": "Rock_Ice"
    },
    {
      "x": -10,
      "y": 18,
      "z": -4,
      "name": "Rock_Ice"
    },
    {
      "x": -10,
      "y": 19,
      "z": -4,
      "name": "Rock_Ice"
    },
    {
      "x": -10,
      "y": 20,
      "z": -4,
      "name": "Rock_Ice"
    },
    {
      "x": -10,
      "y": 21,
      "z": -4,
      "name": "Rock_Ice"
    },
    {
      "x": -10,
      "y": 22,
      "z": -4,
      "name": "Rock_Ice"
    },
    {
      "x": -10,
      "y": 23,
      "z": -4,
      "name": "Rock_Ice"
    },
    {
      "x": -10,
      "y": 24,
      "z": -4,
      "name": "Rock_Ice"
    },
    {
      "x": -10,
      "y": 25,
      "z": -4,
      "name": "Rock_Ice_Permafrost"
    },
    {
      "x": -10,
      "y": 26,
      "z": -4,
      "name": "Rock_Ice"
    },
    {
      "x": -10,
      "y": 27,
      "z": -4,
      "name": "Rock_Ice_Permafrost"
    },
    {
      "x": -10,
      "y": 28,
      "z": -4,
      "name": "Rock_Ice_Permafrost"
    },
    {
      "x": -10,
      "y": 29,
      "z": -4,
      "name": "Rock_Ice_Permafrost"
    },
    {
      "x": -10,
      "y": 30,
      "z": -4,
      "name": "Rock_Ice_Permafrost"
    },
    {
      "x": -10,
      "y": 31,
      "z": -4,
      "name": "Rock_Ice_Permafrost"
    },
    {
      "x": -10,
      "y": 32,
      "z": -4,
      "name": "Rock_Ice_Permafrost"
    },
    {
      "x": -10,
      "y": 33,
      "z": -4,
      "name": "Rock_Ice_Permafrost"
    },
    {
      "x": -10,
      "y": 34,
      "z": -4,
      "name": "Rock_Ice_Permafrost"
    },
    {
      "x": -10,
      "y": 15,
      "z": -3,
      "name": "Rock_Ice"
    },
    {
      "x": -10,
      "y": 16,
      "z": -3,
      "name": "Rock_Ice"
    },
    {
      "x": -10,
      "y": 17,
      "z": -3,
      "name": "Rock_Ice"
    },
    {
      "x": -10,
      "y": 18,
      "z": -3,
      "name": "Rock_Ice"
    },
    {
      "x": -10,
      "y": 19,
      "z": -3,
      "name": "Rock_Ice"
    },
    {
      "x": -10,
      "y": 20,
      "z": -3,
      "name": "Rock_Ice"
    },
    {
      "x": -10,
      "y": 21,
      "z": -3,
      "name": "Rock_Ice"
    },
    {
      "x": -10,
      "y": 22,
      "z": -3,
      "name": "Rock_Ice"
    },
    {
      "x": -10,
      "y": 23,
      "z": -3,
      "name": "Rock_Ice"
    },
    {
      "x": -10,
      "y": 24,
      "z": -3,
      "name": "Rock_Ice_Permafrost"
    },
    {
      "x": -10,
      "y": 25,
      "z": -3,
      "name": "Rock_Ice_Permafrost"
    },
    {
      "x": -10,
      "y": 26,
      "z": -3,
      "name": "Rock_Ice"
    },
    {
      "x": -10,
      "y": 27,
      "z": -3,
      "name": "Rock_Ice_Permafrost"
    },
    {
      "x": -10,
      "y": 28,
      "z": -3,
      "name": "Rock_Ice_Permafrost"
    },
    {
      "x": -10,
      "y": 29,
      "z": -3,
      "name": "Rock_Ice_Permafrost"
    },
    {
      "x": -10,
      "y": 30,
      "z": -3,
      "name": "Rock_Ice_Permafrost"
    },
    {
      "x": -10,
      "y": 31,
      "z": -3,
      "name": "Rock_Ice"
    },
    {
      "x": -10,
      "y": 32,
      "z": -3,
      "name": "Rock_Ice_Permafrost"
    },
    {
      "x": -10,
      "y": 33,
      "z": -3,
      "name": "Rock_Ice_Permafrost"
    },
    {
      "x": -10,
      "y": 34,
      "z": -3,
      "name": "Rock_Ice"
    },
    {
      "x": -10,
      "y": 35,
      "z": -3,
      "name": "Rock_Ice"
    },
    {
      "x": -10,
      "y": 15,
      "z": -2,
      "name": "Rock_Ice"
    },
    {
      "x": -10,
      "y": 16,
      "z": -2,
      "name": "Rock_Ice"
    },
    {
      "x": -10,
      "y": 17,
      "z": -2,
      "name": "Rock_Ice"
    },
    {
      "x": -10,
      "y": 18,
      "z": -2,
      "name": "Rock_Ice"
    },
    {
      "x": -10,
      "y": 19,
      "z": -2,
      "name": "Rock_Ice"
    },
    {
      "x": -10,
      "y": 20,
      "z": -2,
      "name": "Rock_Ice"
    },
    {
      "x": -10,
      "y": 21,
      "z": -2,
      "name": "Rock_Ice"
    },
    {
      "x": -10,
      "y": 22,
      "z": -2,
      "name": "Rock_Ice_Permafrost"
    },
    {
      "x": -10,
      "y": 23,
      "z": -2,
      "name": "Rock_Ice"
    },
    {
      "x": -10,
      "y": 24,
      "z": -2,
      "name": "Rock_Ice"
    },
    {
      "x": -10,
      "y": 25,
      "z": -2,
      "name": "Rock_Ice"
    },
    {
      "x": -10,
      "y": 26,
      "z": -2,
      "name": "Rock_Ice"
    },
    {
      "x": -10,
      "y": 27,
      "z": -2,
      "name": "Rock_Ice"
    },
    {
      "x": -10,
      "y": 28,
      "z": -2,
      "name": "Rock_Ice"
    },
    {
      "x": -10,
      "y": 29,
      "z": -2,
      "name": "Rock_Ice_Permafrost"
    },
    {
      "x": -10,
      "y": 30,
      "z": -2,
      "name": "Rock_Ice"
    },
    {
      "x": -10,
      "y": 31,
      "z": -2,
      "name": "Rock_Ice"
    },
    {
      "x": -10,
      "y": 32,
      "z": -2,
      "name": "Rock_Ice"
    },
    {
      "x": -10,
      "y": 33,
      "z": -2,
      "name": "Rock_Ice"
    },
    {
      "x": -10,
      "y": 34,
      "z": -2,
      "name": "Rock_Ice"
    },
    {
      "x": -10,
      "y": 35,
      "z": -2,
      "name": "Rock_Ice"
    },
    {
      "x": -10,
      "y": 14,
      "z": -1,
      "name": "Rock_Ice"
    },
    {
      "x": -10,
      "y": 15,
      "z": -1,
      "name": "Rock_Ice"
    },
    {
      "x": -10,
      "y": 16,
      "z": -1,
      "name": "Rock_Ice"
    },
    {
      "x": -10,
      "y": 17,
      "z": -1,
      "name": "Rock_Ice"
    },
    {
      "x": -10,
      "y": 18,
      "z": -1,
      "name": "Rock_Ice"
    },
    {
      "x": -10,
      "y": 19,
      "z": -1,
      "name": "Rock_Ice"
    },
    {
      "x": -10,
      "y": 20,
      "z": -1,
      "name": "Rock_Ice"
    },
    {
      "x": -10,
      "y": 21,
      "z": -1,
      "name": "Rock_Ice"
    },
    {
      "x": -10,
      "y": 22,
      "z": -1,
      "name": "Rock_Ice"
    },
    {
      "x": -10,
      "y": 23,
      "z": -1,
      "name": "Rock_Ice"
    },
    {
      "x": -10,
      "y": 24,
      "z": -1,
      "name": "Rock_Ice"
    },
    {
      "x": -10,
      "y": 25,
      "z": -1,
      "name": "Rock_Ice"
    },
    {
      "x": -10,
      "y": 26,
      "z": -1,
      "name": "Rock_Ice"
    },
    {
      "x": -10,
      "y": 27,
      "z": -1,
      "name": "Rock_Ice"
    },
    {
      "x": -10,
      "y": 28,
      "z": -1,
      "name": "Rock_Ice"
    },
    {
      "x": -10,
      "y": 29,
      "z": -1,
      "name": "Rock_Ice"
    },
    {
      "x": -10,
      "y": 30,
      "z": -1,
      "name": "Rock_Ice"
    },
    {
      "x": -10,
      "y": 31,
      "z": -1,
      "name": "Rock_Ice"
    },
    {
      "x": -10,
      "y": 32,
      "z": -1,
      "name": "Rock_Ice"
    },
    {
      "x": -10,
      "y": 33,
      "z": -1,
      "name": "Rock_Ice"
    },
    {
      "x": -10,
      "y": 34,
      "z": -1,
      "name": "Rock_Ice"
    },
    {
      "x": -10,
      "y": 35,
      "z": -1,
      "name": "Rock_Ice"
    },
    {
      "x": -10,
      "y": 36,
      "z": -1,
      "name": "Soil_Snow"
    },
    {
      "x": -10,
      "y": 14,
      "z": 0,
      "name": "Rock_Ice"
    },
    {
      "x": -10,
      "y": 15,
      "z": 0,
      "name": "Rock_Ice"
    },
    {
      "x": -10,
      "y": 16,
      "z": 0,
      "name": "Rock_Ice"
    },
    {
      "x": -10,
      "y": 17,
      "z": 0,
      "name": "Rock_Ice"
    },
    {
      "x": -10,
      "y": 18,
      "z": 0,
      "name": "Rock_Ice"
    },
    {
      "x": -10,
      "y": 19,
      "z": 0,
      "name": "Rock_Ice"
    },
    {
      "x": -10,
      "y": 20,
      "z": 0,
      "name": "Rock_Ice"
    },
    {
      "x": -10,
      "y": 21,
      "z": 0,
      "name": "Rock_Ice"
    },
    {
      "x": -10,
      "y": 22,
      "z": 0,
      "name": "Rock_Ice"
    },
    {
      "x": -10,
      "y": 23,
      "z": 0,
      "name": "Rock_Ice"
    },
    {
      "x": -10,
      "y": 24,
      "z": 0,
      "name": "Rock_Ice"
    },
    {
      "x": -10,
      "y": 25,
      "z": 0,
      "name": "Rock_Ice"
    },
    {
      "x": -10,
      "y": 26,
      "z": 0,
      "name": "Rock_Ice"
    },
    {
      "x": -10,
      "y": 27,
      "z": 0,
      "name": "Rock_Ice"
    },
    {
      "x": -10,
      "y": 28,
      "z": 0,
      "name": "Rock_Ice"
    },
    {
      "x": -10,
      "y": 29,
      "z": 0,
      "name": "Rock_Ice"
    },
    {
      "x": -10,
      "y": 30,
      "z": 0,
      "name": "Rock_Ice"
    },
    {
      "x": -10,
      "y": 31,
      "z": 0,
      "name": "Rock_Ice"
    },
    {
      "x": -10,
      "y": 32,
      "z": 0,
      "name": "Rock_Ice"
    },
    {
      "x": -10,
      "y": 33,
      "z": 0,
      "name": "Rock_Ice"
    },
    {
      "x": -10,
      "y": 34,
      "z": 0,
      "name": "Rock_Ice"
    },
    {
      "x": -10,
      "y": 35,
      "z": 0,
      "name": "Rock_Ice"
    },
    {
      "x": -10,
      "y": 36,
      "z": 0,
      "name": "Soil_Snow"
    },
    {
      "x": -10,
      "y": 14,
      "z": 1,
      "name": "Rock_Ice"
    },
    {
      "x": -10,
      "y": 15,
      "z": 1,
      "name": "Rock_Ice"
    },
    {
      "x": -10,
      "y": 16,
      "z": 1,
      "name": "Rock_Ice"
    },
    {
      "x": -10,
      "y": 17,
      "z": 1,
      "name": "Rock_Ice"
    },
    {
      "x": -10,
      "y": 18,
      "z": 1,
      "name": "Rock_Ice"
    },
    {
      "x": -10,
      "y": 19,
      "z": 1,
      "name": "Rock_Ice"
    },
    {
      "x": -10,
      "y": 20,
      "z": 1,
      "name": "Rock_Ice"
    },
    {
      "x": -10,
      "y": 21,
      "z": 1,
      "name": "Rock_Ice"
    },
    {
      "x": -10,
      "y": 22,
      "z": 1,
      "name": "Rock_Ice"
    },
    {
      "x": -10,
      "y": 23,
      "z": 1,
      "name": "Rock_Ice"
    },
    {
      "x": -10,
      "y": 24,
      "z": 1,
      "name": "Rock_Ice"
    },
    {
      "x": -10,
      "y": 25,
      "z": 1,
      "name": "Rock_Ice"
    },
    {
      "x": -10,
      "y": 26,
      "z": 1,
      "name": "Rock_Ice"
    },
    {
      "x": -10,
      "y": 27,
      "z": 1,
      "name": "Rock_Ice"
    },
    {
      "x": -10,
      "y": 28,
      "z": 1,
      "name": "Rock_Ice"
    },
    {
      "x": -10,
      "y": 29,
      "z": 1,
      "name": "Rock_Ice"
    },
    {
      "x": -10,
      "y": 30,
      "z": 1,
      "name": "Rock_Ice"
    },
    {
      "x": -10,
      "y": 31,
      "z": 1,
      "name": "Rock_Ice"
    },
    {
      "x": -10,
      "y": 32,
      "z": 1,
      "name": "Rock_Ice"
    },
    {
      "x": -10,
      "y": 33,
      "z": 1,
      "name": "Rock_Ice"
    },
    {
      "x": -10,
      "y": 34,
      "z": 1,
      "name": "Rock_Ice"
    },
    {
      "x": -10,
      "y": 35,
      "z": 1,
      "name": "Rock_Ice"
    },
    {
      "x": -10,
      "y": 36,
      "z": 1,
      "name": "Soil_Snow"
    },
    {
      "x": -10,
      "y": 14,
      "z": 2,
      "name": "Rock_Ice"
    },
    {
      "x": -10,
      "y": 15,
      "z": 2,
      "name": "Rock_Ice"
    },
    {
      "x": -10,
      "y": 16,
      "z": 2,
      "name": "Rock_Ice"
    },
    {
      "x": -10,
      "y": 17,
      "z": 2,
      "name": "Rock_Ice"
    },
    {
      "x": -10,
      "y": 18,
      "z": 2,
      "name": "Rock_Ice"
    },
    {
      "x": -10,
      "y": 19,
      "z": 2,
      "name": "Rock_Ice"
    },
    {
      "x": -10,
      "y": 20,
      "z": 2,
      "name": "Rock_Ice"
    },
    {
      "x": -10,
      "y": 21,
      "z": 2,
      "name": "Rock_Ice"
    },
    {
      "x": -10,
      "y": 22,
      "z": 2,
      "name": "Rock_Ice"
    },
    {
      "x": -10,
      "y": 23,
      "z": 2,
      "name": "Rock_Ice"
    },
    {
      "x": -10,
      "y": 24,
      "z": 2,
      "name": "Rock_Ice"
    },
    {
      "x": -10,
      "y": 25,
      "z": 2,
      "name": "Rock_Ice"
    },
    {
      "x": -10,
      "y": 26,
      "z": 2,
      "name": "Rock_Ice"
    },
    {
      "x": -10,
      "y": 27,
      "z": 2,
      "name": "Rock_Ice"
    },
    {
      "x": -10,
      "y": 28,
      "z": 2,
      "name": "Rock_Ice"
    },
    {
      "x": -10,
      "y": 29,
      "z": 2,
      "name": "Rock_Ice"
    },
    {
      "x": -10,
      "y": 30,
      "z": 2,
      "name": "Rock_Ice"
    },
    {
      "x": -10,
      "y": 31,
      "z": 2,
      "name": "Rock_Ice"
    },
    {
      "x": -10,
      "y": 32,
      "z": 2,
      "name": "Rock_Ice"
    },
    {
      "x": -10,
      "y": 33,
      "z": 2,
      "name": "Rock_Ice"
    },
    {
      "x": -10,
      "y": 34,
      "z": 2,
      "name": "Rock_Ice"
    },
    {
      "x": -10,
      "y": 35,
      "z": 2,
      "name": "Rock_Ice"
    },
    {
      "x": -10,
      "y": 36,
      "z": 2,
      "name": "Rock_Ice"
    },
    {
      "x": -10,
      "y": 37,
      "z": 2,
      "name": "Rock_Ice"
    },
    {
      "x": -10,
      "y": 14,
      "z": 3,
      "name": "Rock_Ice"
    },
    {
      "x": -10,
      "y": 15,
      "z": 3,
      "name": "Rock_Ice"
    },
    {
      "x": -10,
      "y": 16,
      "z": 3,
      "name": "Rock_Ice"
    },
    {
      "x": -10,
      "y": 17,
      "z": 3,
      "name": "Rock_Ice"
    },
    {
      "x": -10,
      "y": 18,
      "z": 3,
      "name": "Rock_Ice"
    },
    {
      "x": -10,
      "y": 19,
      "z": 3,
      "name": "Rock_Ice"
    },
    {
      "x": -10,
      "y": 20,
      "z": 3,
      "name": "Rock_Ice"
    },
    {
      "x": -10,
      "y": 21,
      "z": 3,
      "name": "Rock_Ice"
    },
    {
      "x": -10,
      "y": 22,
      "z": 3,
      "name": "Rock_Ice"
    },
    {
      "x": -10,
      "y": 23,
      "z": 3,
      "name": "Rock_Ice"
    },
    {
      "x": -10,
      "y": 24,
      "z": 3,
      "name": "Rock_Ice"
    },
    {
      "x": -10,
      "y": 25,
      "z": 3,
      "name": "Rock_Ice"
    },
    {
      "x": -10,
      "y": 26,
      "z": 3,
      "name": "Rock_Ice"
    },
    {
      "x": -10,
      "y": 27,
      "z": 3,
      "name": "Rock_Ice"
    },
    {
      "x": -10,
      "y": 28,
      "z": 3,
      "name": "Rock_Ice"
    },
    {
      "x": -10,
      "y": 29,
      "z": 3,
      "name": "Rock_Ice"
    },
    {
      "x": -10,
      "y": 30,
      "z": 3,
      "name": "Rock_Ice"
    },
    {
      "x": -10,
      "y": 31,
      "z": 3,
      "name": "Rock_Ice"
    },
    {
      "x": -10,
      "y": 32,
      "z": 3,
      "name": "Rock_Ice"
    },
    {
      "x": -10,
      "y": 33,
      "z": 3,
      "name": "Rock_Ice"
    },
    {
      "x": -10,
      "y": 34,
      "z": 3,
      "name": "Rock_Ice"
    },
    {
      "x": -10,
      "y": 35,
      "z": 3,
      "name": "Rock_Ice"
    },
    {
      "x": -10,
      "y": 36,
      "z": 3,
      "name": "Rock_Ice"
    },
    {
      "x": -10,
      "y": 37,
      "z": 3,
      "name": "Rock_Ice"
    },
    {
      "x": -10,
      "y": 15,
      "z": 4,
      "name": "Rock_Ice"
    },
    {
      "x": -10,
      "y": 16,
      "z": 4,
      "name": "Rock_Ice"
    },
    {
      "x": -10,
      "y": 17,
      "z": 4,
      "name": "Rock_Ice"
    },
    {
      "x": -10,
      "y": 18,
      "z": 4,
      "name": "Rock_Ice"
    },
    {
      "x": -10,
      "y": 19,
      "z": 4,
      "name": "Rock_Ice"
    },
    {
      "x": -10,
      "y": 20,
      "z": 4,
      "name": "Rock_Ice"
    },
    {
      "x": -10,
      "y": 21,
      "z": 4,
      "name": "Rock_Ice"
    },
    {
      "x": -10,
      "y": 22,
      "z": 4,
      "name": "Rock_Ice"
    },
    {
      "x": -10,
      "y": 23,
      "z": 4,
      "name": "Rock_Ice"
    },
    {
      "x": -10,
      "y": 24,
      "z": 4,
      "name": "Rock_Ice"
    },
    {
      "x": -10,
      "y": 25,
      "z": 4,
      "name": "Rock_Ice"
    },
    {
      "x": -10,
      "y": 26,
      "z": 4,
      "name": "Rock_Ice"
    },
    {
      "x": -10,
      "y": 27,
      "z": 4,
      "name": "Rock_Ice"
    },
    {
      "x": -10,
      "y": 28,
      "z": 4,
      "name": "Rock_Ice"
    },
    {
      "x": -10,
      "y": 29,
      "z": 4,
      "name": "Rock_Ice"
    },
    {
      "x": -10,
      "y": 30,
      "z": 4,
      "name": "Rock_Ice"
    },
    {
      "x": -10,
      "y": 31,
      "z": 4,
      "name": "Rock_Ice"
    },
    {
      "x": -10,
      "y": 32,
      "z": 4,
      "name": "Rock_Ice"
    },
    {
      "x": -10,
      "y": 33,
      "z": 4,
      "name": "Rock_Ice"
    },
    {
      "x": -10,
      "y": 34,
      "z": 4,
      "name": "Rock_Ice"
    },
    {
      "x": -10,
      "y": 35,
      "z": 4,
      "name": "Rock_Ice"
    },
    {
      "x": -10,
      "y": 36,
      "z": 4,
      "name": "Rock_Ice"
    },
    {
      "x": -10,
      "y": 37,
      "z": 4,
      "name": "Rock_Ice"
    },
    {
      "x": -10,
      "y": 16,
      "z": 5,
      "name": "Rock_Ice"
    },
    {
      "x": -10,
      "y": 17,
      "z": 5,
      "name": "Rock_Ice"
    },
    {
      "x": -10,
      "y": 18,
      "z": 5,
      "name": "Rock_Ice"
    },
    {
      "x": -10,
      "y": 19,
      "z": 5,
      "name": "Rock_Ice"
    },
    {
      "x": -10,
      "y": 20,
      "z": 5,
      "name": "Rock_Ice"
