{
  "version": 8,
  "blockIdVersion": 11,
  "anchorX": 6,
  "anchorY": 11,
  "anchorZ": 0,
  "blocks": [
    {
      "x": -26,
      "y": 24,
      "z": -1,
      "name": "Soil_Snow"
    },
    {
      "x": -25,
      "y": 26,
      "z": -3,
      "name": "Soil_Snow"
    },
    {
      "x": -25,
      "y": 24,
      "z": -2,
      "name": "Rock_Ice"
    },
    {
      "x": -25,
      "y": 25,
      "z": -2,
      "name": "Soil_Snow"
    },
    {
      "x": -25,
      "y": 22,
      "z": -1,
      "name": "Rock_Ice_Permafrost"
    },
    {
      "x": -25,
      "y": 23,
      "z": -1,
      "name": "Rock_Ice"
    },
    {
      "x": -25,
      "y": 24,
      "z": -1,
      "name": "Soil_Snow"
    },
    {
      "x": -25,
      "y": 21,
      "z": 0,
      "name": "Rock_Ice"
    },
    {
      "x": -25,
      "y": 22,
      "z": 0,
      "name": "Soil_Snow"
    },
    {
      "x": -25,
      "y": 21,
      "z": 1,
      "name": "Rock_Ice"
    },
    {
      "x": -25,
      "y": 22,
      "z": 1,
      "name": "Soil_Snow"
    },
    {
      "x": -24,
      "y": 24,
      "z": -3,
      "name": "Rock_Ice"
    },
    {
      "x": -24,
      "y": 25,
      "z": -3,
      "name": "Soil_Snow"
    },
    {
      "x": -24,
      "y": 22,
      "z": -2,
      "name": "Rock_Ice_Permafrost"
    },
    {
      "x": -24,
      "y": 23,
      "z": -2,
      "name": "Rock_Ice_Permafrost"
    },
    {
      "x": -24,
      "y": 24,
      "z": -2,
      "name": "Rock_Ice"
    },
    {
      "x": -24,
      "y": 25,
      "z": -2,
      "name": "Soil_Snow"
    },
    {
      "x": -24,
      "y": 20,
      "z": -1,
      "name": "Rock_Ice_Permafrost"
    },
    {
      "x": -24,
      "y": 21,
      "z": -1,
      "name": "Rock_Ice_Permafrost"
    },
    {
      "x": -24,
      "y": 22,
      "z": -1,
      "name": "Rock_Ice"
    },
    {
      "x": -24,
      "y": 23,
      "z": -1,
      "name": "Soil_Snow"
    },
    {
      "x": -24,
      "y": 20,
      "z": 0,
      "name": "Rock_Ice_Permafrost"
    },
    {
      "x": -24,
      "y": 21,
      "z": 0,
      "name": "Rock_Ice"
    },
    {
      "x": -24,
      "y": 22,
      "z": 0,
      "name": "Soil_Snow"
    },
    {
      "x": -24,
      "y": 20,
      "z": 1,
      "name": "Rock_Ice"
    },
    {
      "x": -24,
      "y": 21,
      "z": 1,
      "name": "Soil_Snow"
    },
    {
      "x": -23,
      "y": 24,
      "z": -4,
      "name": "Rock_Ice"
    },
    {
      "x": -23,
      "y": 25,
      "z": -4,
      "name": "Soil_Snow"
    },
    {
      "x": -23,
      "y": 22,
      "z": -3,
      "name": "Rock_Ice_Permafrost"
    },
    {
      "x": -23,
      "y": 23,
      "z": -3,
      "name": "Rock_Ice_Permafrost"
    },
    {
      "x": -23,
      "y": 24,
      "z": -3,
      "name": "Rock_Ice"
    },
    {
      "x": -23,
      "y": 25,
      "z": -3,
      "name": "Soil_Snow"
    },
    {
      "x": -23,
      "y": 20,
      "z": -2,
      "name": "Rock_Ice_Permafrost"
    },
    {
      "x": -23,
      "y": 21,
      "z": -2,
      "name": "Rock_Ice_Permafrost"
    },
    {
      "x": -23,
      "y": 22,
      "z": -2,
      "name": "Rock_Ice_Permafrost"
    },
    {
      "x": -23,
      "y": 23,
      "z": -2,
      "name": "Rock_Ice"
    },
    {
      "x": -23,
      "y": 24,
      "z": -2,
      "name": "Rock_Ice"
    },
    {
      "x": -23,
      "y": 25,
      "z": -2,
      "name": "Soil_Snow"
    },
    {
      "x": -23,
      "y": 18,
      "z": -1,
      "name": "Rock_Ice_Permafrost"
    },
    {
      "x": -23,
      "y": 19,
      "z": -1,
      "name": "Rock_Ice_Permafrost"
    },
    {
      "x": -23,
      "y": 20,
      "z": -1,
      "name": "Rock_Ice_Permafrost"
    },
    {
      "x": -23,
      "y": 21,
      "z": -1,
      "name": "Rock_Ice_Permafrost"
    },
    {
      "x": -23,
      "y": 22,
      "z": -1,
      "name": "Rock_Ice"
    },
    {
      "x": -23,
      "y": 23,
      "z": -1,
      "name": "Soil_Snow"
    },
    {
      "x": -23,
      "y": 18,
      "z": 0,
      "name": "Rock_Ice_Permafrost"
    },
    {
      "x": -23,
      "y": 19,
      "z": 0,
      "name": "Rock_Ice_Permafrost"
    },
    {
      "x": -23,
      "y": 20,
      "z": 0,
      "name": "Rock_Ice_Permafrost"
    },
    {
      "x": -23,
      "y": 21,
      "z": 0,
      "name": "Rock_Ice"
    },
    {
      "x": -23,
      "y": 22,
      "z": 0,
      "name": "Soil_Snow"
    },
    {
      "x": -23,
      "y": 19,
      "z": 1,
      "name": "Rock_Ice_Permafrost"
    },
    {
      "x": -23,
      "y": 20,
      "z": 1,
      "name": "Rock_Ice_Permafrost"
    },
    {
      "x": -23,
      "y": 21,
      "z": 1,
      "name": "Soil_Snow"
    },
    {
      "x": -22,
      "y": 24,
      "z": -5,
      "name": "Rock_Ice"
    },
    {
      "x": -22,
      "y": 25,
      "z": -5,
      "name": "Soil_Snow"
    },
    {
      "x": -22,
      "y": 22,
      "z": -4,
      "name": "Rock_Ice_Permafrost"
    },
    {
      "x": -22,
      "y": 23,
      "z": -4,
      "name": "Rock_Ice_Permafrost"
    },
    {
      "x": -22,
      "y": 24,
      "z": -4,
      "name": "Rock_Ice"
    },
    {
      "x": -22,
      "y": 25,
      "z": -4,
      "name": "Soil_Snow"
    },
    {
      "x": -22,
      "y": 20,
      "z": -3,
      "name": "Rock_Ice_Permafrost"
    },
    {
      "x": -22,
      "y": 21,
      "z": -3,
      "name": "Rock_Ice_Permafrost"
    },
    {
      "x": -22,
      "y": 22,
      "z": -3,
      "name": "Rock_Ice_Permafrost"
    },
    {
      "x": -22,
      "y": 23,
      "z": -3,
      "name": "Rock_Ice"
    },
    {
      "x": -22,
      "y": 24,
      "z": -3,
      "name": "Rock_Ice"
    },
    {
      "x": -22,
      "y": 25,
      "z": -3,
      "name": "Soil_Snow"
    },
    {
      "x": -22,
      "y": 18,
      "z": -2,
      "name": "Rock_Ice_Permafrost"
    },
    {
      "x": -22,
      "y": 19,
      "z": -2,
      "name": "Rock_Ice_Permafrost"
    },
    {
      "x": -22,
      "y": 20,
      "z": -2,
      "name": "Rock_Ice_Permafrost"
    },
    {
      "x": -22,
      "y": 21,
      "z": -2,
      "name": "Rock_Ice_Permafrost"
    },
    {
      "x": -22,
      "y": 22,
      "z": -2,
      "name": "Rock_Ice_Permafrost"
    },
    {
      "x": -22,
      "y": 23,
      "z": -2,
      "name": "Rock_Ice"
    },
    {
      "x": -22,
      "y": 24,
      "z": -2,
      "name": "Soil_Snow"
    },
    {
      "x": -22,
      "y": 16,
      "z": -1,
      "name": "Rock_Ice_Permafrost"
    },
    {
      "x": -22,
      "y": 17,
      "z": -1,
      "name": "Rock_Ice_Permafrost"
    },
    {
      "x": -22,
      "y": 18,
      "z": -1,
      "name": "Rock_Ice_Permafrost"
    },
    {
      "x": -22,
      "y": 19,
      "z": -1,
      "name": "Rock_Ice_Permafrost"
    },
    {
      "x": -22,
      "y": 20,
      "z": -1,
      "name": "Rock_Ice_Permafrost"
    },
    {
      "x": -22,
      "y": 21,
      "z": -1,
      "name": "Rock_Ice_Permafrost"
    },
    {
      "x": -22,
      "y": 22,
      "z": -1,
      "name": "Rock_Ice"
    },
    {
      "x": -22,
      "y": 23,
      "z": -1,
      "name": "Soil_Snow"
    },
    {
      "x": -22,
      "y": 17,
      "z": 0,
      "name": "Rock_Ice_Permafrost"
    },
    {
      "x": -22,
      "y": 18,
      "z": 0,
      "name": "Rock_Ice_Permafrost"
    },
    {
      "x": -22,
      "y": 19,
      "z": 0,
      "name": "Rock_Ice_Permafrost"
    },
    {
      "x": -22,
      "y": 20,
      "z": 0,
      "name": "Rock_Ice_Permafrost"
    },
    {
      "x": -22,
      "y": 21,
      "z": 0,
      "name": "Rock_Ice"
    },
    {
      "x": -22,
      "y": 22,
      "z": 0,
      "name": "Soil_Snow"
    },
    {
      "x": -22,
      "y": 17,
      "z": 1,
      "name": "Rock_Ice_Permafrost"
    },
    {
      "x": -22,
      "y": 18,
      "z": 1,
      "name": "Rock_Ice_Permafrost"
    },
    {
      "x": -22,
      "y": 19,
      "z": 1,
      "name": "Rock_Ice_Permafrost"
    },
    {
      "x": -22,
      "y": 20,
      "z": 1,
      "name": "Rock_Ice"
    },
    {
      "x": -22,
      "y": 21,
      "z": 1,
      "name": "Soil_Snow"
    },
    {
      "x": -22,
      "y": 18,
      "z": 2,
      "name": "Soil_Snow"
    },
    {
      "x": -21,
      "y": 22,
      "z": -5,
      "name": "Rock_Ice_Permafrost"
    },
    {
      "x": -21,
      "y": 23,
      "z": -5,
      "name": "Rock_Ice"
    },
    {
      "x": -21,
      "y": 24,
      "z": -5,
      "name": "Rock_Ice"
    },
    {
      "x": -21,
      "y": 25,
      "z": -5,
      "name": "Soil_Snow"
    },
    {
      "x": -21,
      "y": 20,
      "z": -4,
      "name": "Rock_Ice_Permafrost"
    },
    {
      "x": -21,
      "y": 21,
      "z": -4,
      "name": "Rock_Ice"
    },
    {
      "x": -21,
      "y": 22,
      "z": -4,
      "name": "Rock_Ice_Permafrost"
    },
    {
      "x": -21,
      "y": 23,
      "z": -4,
      "name": "Rock_Ice_Permafrost"
    },
    {
      "x": -21,
      "y": 24,
      "z": -4,
      "name": "Rock_Ice"
    },
    {
      "x": -21,
      "y": 25,
      "z": -4,
      "name": "Soil_Snow"
    },
    {
      "x": -21,
      "y": 18,
      "z": -3,
      "name": "Rock_Ice_Permafrost"
    },
    {
      "x": -21,
      "y": 19,
      "z": -3,
      "name": "Rock_Ice_Permafrost"
    },
    {
      "x": -21,
      "y": 20,
      "z": -3,
      "name": "Rock_Ice_Permafrost"
    },
    {
      "x": -21,
      "y": 21,
      "z": -3,
      "name": "Rock_Ice_Permafrost"
    },
    {
      "x": -21,
      "y": 22,
      "z": -3,
      "name": "Rock_Ice_Permafrost"
    },
    {
      "x": -21,
      "y": 23,
      "z": -3,
      "name": "Rock_Ice"
    },
    {
      "x": -21,
      "y": 24,
      "z": -3,
      "name": "Soil_Snow"
    },
    {
      "x": -21,
      "y": 16,
      "z": -2,
      "name": "Rock_Ice_Permafrost"
    },
    {
      "x": -21,
      "y": 17,
      "z": -2,
      "name": "Rock_Ice_Permafrost"
    },
    {
      "x": -21,
      "y": 18,
      "z": -2,
      "name": "Rock_Ice_Permafrost"
    },
    {
      "x": -21,
      "y": 19,
      "z": -2,
      "name": "Rock_Ice_Permafrost"
    },
    {
      "x": -21,
      "y": 20,
      "z": -2,
      "name": "Rock_Ice_Permafrost"
    },
    {
      "x": -21,
      "y": 21,
      "z": -2,
      "name": "Rock_Ice_Permafrost"
    },
    {
      "x": -21,
      "y": 22,
      "z": -2,
      "name": "Rock_Ice_Permafrost"
    },
    {
      "x": -21,
      "y": 23,
      "z": -2,
      "name": "Rock_Ice"
    },
    {
      "x": -21,
      "y": 24,
      "z": -2,
      "name": "Soil_Snow"
    },
    {
      "x": -21,
      "y": 15,
      "z": -1,
      "name": "Rock_Ice_Permafrost"
    },
    {
      "x": -21,
      "y": 16,
      "z": -1,
      "name": "Rock_Ice_Permafrost"
    },
    {
      "x": -21,
      "y": 17,
      "z": -1,
      "name": "Rock_Ice_Permafrost"
    },
    {
      "x": -21,
      "y": 18,
      "z": -1,
      "name": "Rock_Ice_Permafrost"
    },
    {
      "x": -21,
      "y": 19,
      "z": -1,
      "name": "Rock_Ice_Permafrost"
    },
    {
      "x": -21,
      "y": 20,
      "z": -1,
      "name": "Rock_Ice_Permafrost"
    },
    {
      "x": -21,
      "y": 21,
      "z": -1,
      "name": "Rock_Ice_Permafrost"
    },
    {
      "x": -21,
      "y": 22,
      "z": -1,
      "name": "Rock_Ice"
    },
    {
      "x": -21,
      "y": 23,
      "z": -1,
      "name": "Soil_Snow"
    },
    {
      "x": -21,
      "y": 15,
      "z": 0,
      "name": "Rock_Ice_Permafrost"
    },
    {
      "x": -21,
      "y": 16,
      "z": 0,
      "name": "Rock_Ice_Permafrost"
    },
    {
      "x": -21,
      "y": 17,
      "z": 0,
      "name": "Rock_Ice_Permafrost"
    },
    {
      "x": -21,
      "y": 18,
      "z": 0,
      "name": "Rock_Ice_Permafrost"
    },
    {
      "x": -21,
      "y": 19,
      "z": 0,
      "name": "Rock_Ice_Permafrost"
    },
    {
      "x": -21,
      "y": 20,
      "z": 0,
      "name": "Rock_Ice_Permafrost"
    },
    {
      "x": -21,
      "y": 21,
      "z": 0,
      "name": "Rock_Ice"
    },
    {
      "x": -21,
      "y": 22,
      "z": 0,
      "name": "Soil_Snow"
    },
    {
      "x": -21,
      "y": 16,
      "z": 1,
      "name": "Rock_Ice_Permafrost"
    },
    {
      "x": -21,
      "y": 17,
      "z": 1,
      "name": "Rock_Ice_Permafrost"
    },
    {
      "x": -21,
      "y": 18,
      "z": 1,
      "name": "Rock_Ice_Permafrost"
    },
    {
      "x": -21,
      "y": 19,
      "z": 1,
      "name": "Rock_Ice_Permafrost"
    },
    {
      "x": -21,
      "y": 20,
      "z": 1,
      "name": "Rock_Ice"
    },
    {
      "x": -21,
      "y": 21,
      "z": 1,
      "name": "Soil_Snow"
    },
    {
      "x": -21,
      "y": 17,
      "z": 2,
      "name": "Rock_Ice_Permafrost"
    },
    {
      "x": -21,
      "y": 18,
      "z": 2,
      "name": "Rock_Ice"
    },
    {
      "x": -21,
      "y": 19,
      "z": 2,
      "name": "Rock_Ice_Permafrost"
    },
    {
      "x": -20,
      "y": 23,
      "z": -6,
      "name": "Rock_Ice"
    },
    {
      "x": -20,
      "y": 24,
      "z": -6,
      "name": "Soil_Snow"
    },
    {
      "x": -20,
      "y": 21,
      "z": -5,
      "name": "Rock_Ice_Permafrost"
    },
    {
      "x": -20,
      "y": 22,
      "z": -5,
      "name": "Rock_Ice"
    },
    {
      "x": -20,
      "y": 23,
      "z": -5,
      "name": "Rock_Ice"
    },
    {
      "x": -20,
      "y": 24,
      "z": -5,
      "name": "Rock_Ice"
    },
    {
      "x": -20,
      "y": 25,
      "z": -5,
      "name": "Soil_Snow"
    },
    {
      "x": -20,
      "y": 18,
      "z": -4,
      "name": "Rock_Ice_Permafrost"
    },
    {
      "x": -20,
      "y": 19,
      "z": -4,
      "name": "Rock_Ice_Permafrost"
    },
    {
      "x": -20,
      "y": 20,
      "z": -4,
      "name": "Rock_Ice_Permafrost"
    },
    {
      "x": -20,
      "y": 21,
      "z": -4,
      "name": "Rock_Ice_Permafrost"
    },
    {
      "x": -20,
      "y": 22,
      "z": -4,
      "name": "Rock_Ice_Permafrost"
    },
    {
      "x": -20,
      "y": 23,
      "z": -4,
      "name": "Rock_Ice"
    },
    {
      "x": -20,
      "y": 24,
      "z": -4,
      "name": "Soil_Snow"
    },
    {
      "x": -20,
      "y": 16,
      "z": -3,
      "name": "Rock_Ice_Permafrost"
    },
    {
      "x": -20,
      "y": 17,
      "z": -3,
      "name": "Rock_Ice_Permafrost"
    },
    {
      "x": -20,
      "y": 18,
      "z": -3,
      "name": "Rock_Ice_Permafrost"
    },
    {
      "x": -20,
      "y": 19,
      "z": -3,
      "name": "Rock_Ice_Permafrost"
    },
    {
      "x": -20,
      "y": 20,
      "z": -3,
      "name": "Rock_Ice_Permafrost"
    },
    {
      "x": -20,
      "y": 21,
      "z": -3,
      "name": "Rock_Ice_Permafrost"
    },
    {
      "x": -20,
      "y": 22,
      "z": -3,
      "name": "Rock_Ice_Permafrost"
    },
    {
      "x": -20,
      "y": 23,
      "z": -3,
      "name": "Rock_Ice"
    },
    {
      "x": -20,
      "y": 24,
      "z": -3,
      "name": "Soil_Snow"
    },
    {
      "x": -20,
      "y": 15,
      "z": -2,
      "name": "Rock_Ice_Permafrost"
    },
    {
      "x": -20,
      "y": 16,
      "z": -2,
      "name": "Rock_Ice_Permafrost"
    },
    {
      "x": -20,
      "y": 17,
      "z": -2,
      "name": "Rock_Ice_Permafrost"
    },
    {
      "x": -20,
      "y": 18,
      "z": -2,
      "name": "Rock_Ice_Permafrost"
    },
    {
      "x": -20,
      "y": 19,
      "z": -2,
      "name": "Rock_Ice_Permafrost"
    },
    {
      "x": -20,
      "y": 20,
      "z": -2,
      "name": "Rock_Ice_Permafrost"
    },
    {
      "x": -20,
      "y": 21,
      "z": -2,
      "name": "Rock_Ice_Permafrost"
    },
    {
      "x": -20,
      "y": 22,
      "z": -2,
      "name": "Rock_Ice"
    },
    {
      "x": -20,
      "y": 23,
      "z": -2,
      "name": "Soil_Snow"
    },
    {
      "x": -20,
      "y": 14,
      "z": -1,
      "name": "Rock_Ice_Permafrost"
    },
    {
      "x": -20,
      "y": 15,
      "z": -1,
      "name": "Rock_Ice_Permafrost"
    },
    {
      "x": -20,
      "y": 16,
      "z": -1,
      "name": "Rock_Ice_Permafrost"
    },
    {
      "x": -20,
      "y": 17,
      "z": -1,
      "name": "Rock_Ice_Permafrost"
    },
    {
      "x": -20,
      "y": 18,
      "z": -1,
      "name": "Rock_Ice_Permafrost"
    },
    {
      "x": -20,
      "y": 19,
      "z": -1,
      "name": "Rock_Ice_Permafrost"
    },
    {
      "x": -20,
      "y": 20,
      "z": -1,
      "name": "Rock_Ice_Permafrost"
    },
    {
      "x": -20,
      "y": 21,
      "z": -1,
      "name": "Rock_Ice_Permafrost"
    },
    {
      "x": -20,
      "y": 22,
      "z": -1,
      "name": "Rock_Ice"
    },
    {
      "x": -20,
      "y": 23,
      "z": -1,
      "name": "Soil_Snow"
    },
    {
      "x": -20,
      "y": 14,
      "z": 0,
      "name": "Rock_Ice_Permafrost"
    },
    {
      "x": -20,
      "y": 15,
      "z": 0,
      "name": "Rock_Ice_Permafrost"
    },
    {
      "x": -20,
      "y": 16,
      "z": 0,
      "name": "Rock_Ice_Permafrost"
    },
    {
      "x": -20,
      "y": 17,
      "z": 0,
      "name": "Rock_Ice_Permafrost"
    },
    {
      "x": -20,
      "y": 18,
      "z": 0,
      "name": "Rock_Ice_Permafrost"
    },
    {
      "x": -20,
      "y": 19,
      "z": 0,
      "name": "Rock_Ice_Permafrost"
    },
    {
      "x": -20,
      "y": 20,
      "z": 0,
      "name": "Rock_Ice_Permafrost"
    },
    {
      "x": -20,
      "y": 21,
      "z": 0,
      "name": "Rock_Ice"
    },
    {
      "x": -20,
      "y": 22,
      "z": 0,
      "name": "Soil_Snow"
    },
    {
      "x": -20,
      "y": 14,
      "z": 1,
      "name": "Rock_Ice_Permafrost"
    },
    {
      "x": -20,
      "y": 15,
      "z": 1,
      "name": "Rock_Ice_Permafrost"
    },
    {
      "x": -20,
      "y": 16,
      "z": 1,
      "name": "Rock_Ice_Permafrost"
    },
    {
      "x": -20,
      "y": 17,
      "z": 1,
      "name": "Rock_Ice_Permafrost"
    },
    {
      "x": -20,
      "y": 18,
      "z": 1,
      "name": "Rock_Ice_Permafrost"
    },
    {
      "x": -20,
      "y": 19,
      "z": 1,
      "name": "Rock_Ice_Permafrost"
    },
    {
      "x": -20,
      "y": 20,
      "z": 1,
      "name": "Soil_Snow"
    },
    {
      "x": -20,
      "y": 15,
      "z": 2,
      "name": "Rock_Ice_Permafrost"
    },
    {
      "x": -20,
      "y": 16,
      "z": 2,
      "name": "Rock_Ice_Permafrost"
    },
    {
      "x": -20,
      "y": 17,
      "z": 2,
      "name": "Rock_Ice_Permafrost"
    },
    {
      "x": -20,
      "y": 18,
      "z": 2,
      "name": "Rock_Ice_Permafrost"
    },
    {
      "x": -20,
      "y": 19,
      "z": 2,
      "name": "Rock_Ice_Permafrost"
    },
    {
      "x": -19,
      "y": 21,
      "z": -6,
      "name": "Rock_Ice"
    },
    {
      "x": -19,
      "y": 22,
      "z": -6,
      "name": "Rock_Ice_Permafrost"
    },
    {
      "x": -19,
      "y": 23,
      "z": -6,
      "name": "Rock_Ice"
    },
    {
      "x": -19,
      "y": 24,
      "z": -6,
      "name": "Rock_Ice"
    },
    {
      "x": -19,
      "y": 25,
      "z": -6,
      "name": "Soil_Snow"
    },
    {
      "x": -19,
      "y": 19,
      "z": -5,
      "name": "Rock_Ice_Permafrost"
    },
    {
      "x": -19,
      "y": 20,
      "z": -5,
      "name": "Rock_Ice_Permafrost"
    },
    {
      "x": -19,
      "y": 21,
      "z": -5,
      "name": "Rock_Ice"
    },
    {
      "x": -19,
      "y": 22,
      "z": -5,
      "name": "Rock_Ice"
    },
    {
      "x": -19,
      "y": 23,
      "z": -5,
      "name": "Rock_Ice"
    },
    {
      "x": -19,
      "y": 24,
      "z": -5,
      "name": "Soil_Snow"
    },
    {
      "x": -19,
      "y": 17,
      "z": -4,
      "name": "Rock_Ice_Permafrost"
    },
    {
      "x": -19,
      "y": 18,
      "z": -4,
      "name": "Rock_Ice_Permafrost"
    },
    {
      "x": -19,
      "y": 19,
      "z": -4,
      "name": "Rock_Ice_Permafrost"
    },
    {
      "x": -19,
      "y": 20,
      "z": -4,
      "name": "Rock_Ice_Permafrost"
    },
    {
      "x": -19,
      "y": 21,
      "z": -4,
      "name": "Rock_Ice_Permafrost"
    },
    {
      "x": -19,
      "y": 22,
      "z": -4,
      "name": "Rock_Ice"
    },
    {
      "x": -19,
      "y": 23,
      "z": -4,
      "name": "Rock_Ice"
    },
    {
      "x": -19,
      "y": 24,
      "z": -4,
      "name": "Soil_Snow"
    },
    {
      "x": -19,
      "y": 15,
      "z": -3,
      "name": "Rock_Ice_Permafrost"
    },
    {
      "x": -19,
      "y": 16,
      "z": -3,
      "name": "Rock_Ice_Permafrost"
    },
    {
      "x": -19,
      "y": 17,
      "z": -3,
      "name": "Rock_Ice_Permafrost"
    },
    {
      "x": -19,
      "y": 18,
      "z": -3,
      "name": "Rock_Ice_Permafrost"
    },
    {
      "x": -19,
      "y": 19,
      "z": -3,
      "name": "Rock_Ice_Permafrost"
    },
    {
      "x": -19,
      "y": 20,
      "z": -3,
      "name": "Rock_Ice_Permafrost"
    },
    {
      "x": -19,
      "y": 21,
      "z": -3,
      "name": "Rock_Ice"
    },
    {
      "x": -19,
      "y": 22,
      "z": -3,
      "name": "Rock_Ice"
    },
    {
      "x": -19,
      "y": 23,
      "z": -3,
      "name": "Soil_Snow"
    },
    {
      "x": -19,
      "y": 14,
      "z": -2,
      "name": "Rock_Ice_Permafrost"
    },
    {
      "x": -19,
      "y": 15,
      "z": -2,
      "name": "Rock_Ice_Permafrost"
    },
    {
      "x": -19,
      "y": 16,
      "z": -2,
      "name": "Rock_Ice_Permafrost"
    },
    {
      "x": -19,
      "y": 17,
      "z": -2,
      "name": "Rock_Ice_Permafrost"
    },
    {
      "x": -19,
      "y": 18,
      "z": -2,
      "name": "Rock_Ice_Permafrost"
    },
    {
      "x": -19,
      "y": 19,
      "z": -2,
      "name": "Rock_Ice_Permafrost"
    },
    {
      "x": -19,
      "y": 20,
      "z": -2,
      "name": "Rock_Ice_Permafrost"
    },
    {
      "x": -19,
      "y": 21,
      "z": -2,
      "name": "Rock_Ice_Permafrost"
    },
    {
      "x": -19,
      "y": 22,
      "z": -2,
      "name": "Rock_Ice"
    },
    {
      "x": -19,
      "y": 23,
      "z": -2,
      "name": "Soil_Snow"
    },
    {
      "x": -19,
      "y": 13,
      "z": -1,
      "name": "Rock_Ice_Permafrost"
    },
    {
      "x": -19,
      "y": 14,
      "z": -1,
      "name": "Rock_Ice_Permafrost"
    },
    {
      "x": -19,
      "y": 15,
      "z": -1,
      "name": "Rock_Ice_Permafrost"
    },
    {
      "x": -19,
      "y": 16,
      "z": -1,
      "name": "Rock_Ice_Permafrost"
    },
    {
      "x": -19,
      "y": 17,
      "z": -1,
      "name": "Rock_Ice_Permafrost"
    },
    {
      "x": -19,
      "y": 18,
      "z": -1,
      "name": "Rock_Ice_Permafrost"
    },
    {
      "x": -19,
      "y": 19,
      "z": -1,
      "name": "Rock_Ice_Permafrost"
    },
    {
      "x": -19,
      "y": 20,
      "z": -1,
      "name": "Rock_Ice_Permafrost"
    },
    {
      "x": -19,
      "y": 21,
      "z": -1,
      "name": "Rock_Ice"
    },
    {
      "x": -19,
      "y": 22,
      "z": -1,
      "name": "Soil_Snow"
    },
    {
      "x": -19,
      "y": 13,
      "z": 0,
      "name": "Rock_Ice_Permafrost"
    },
    {
      "x": -19,
      "y": 14,
      "z": 0,
      "name": "Rock_Ice_Permafrost"
    },
    {
      "x": -19,
      "y": 15,
      "z": 0,
      "name": "Rock_Ice_Permafrost"
    },
    {
      "x": -19,
      "y": 16,
      "z": 0,
      "name": "Rock_Ice_Permafrost"
    },
    {
      "x": -19,
      "y": 17,
      "z": 0,
      "name": "Rock_Ice_Permafrost"
    },
    {
      "x": -19,
      "y": 18,
      "z": 0,
      "name": "Rock_Ice_Permafrost"
    },
    {
      "x": -19,
      "y": 19,
      "z": 0,
      "name": "Rock_Ice_Permafrost"
    },
    {
      "x": -19,
      "y": 20,
      "z": 0,
      "name": "Rock_Ice_Permafrost"
    },
    {
      "x": -19,
      "y": 21,
      "z": 0,
      "name": "Rock_Ice"
    },
    {
      "x": -19,
      "y": 22,
      "z": 0,
      "name": "Soil_Snow"
    },
    {
      "x": -19,
      "y": 13,
      "z": 1,
      "name": "Rock_Ice"
    },
    {
      "x": -19,
      "y": 14,
      "z": 1,
      "name": "Rock_Ice_Permafrost"
    },
    {
      "x": -19,
      "y": 15,
      "z": 1,
      "name": "Rock_Ice_Permafrost"
    },
    {
      "x": -19,
      "y": 16,
      "z": 1,
      "name": "Rock_Ice_Permafrost"
    },
    {
      "x": -19,
      "y": 17,
      "z": 1,
      "name": "Rock_Ice_Permafrost"
    },
    {
      "x": -19,
      "y": 18,
      "z": 1,
      "name": "Rock_Ice_Permafrost"
    },
    {
      "x": -19,
      "y": 19,
      "z": 1,
      "name": "Rock_Ice_Permafrost"
    },
    {
      "x": -19,
      "y": 20,
      "z": 1,
      "name": "Rock_Ice_Permafrost"
    },
    {
      "x": -19,
      "y": 13,
      "z": 2,
      "name": "Rock_Ice"
    },
    {
      "x": -19,
      "y": 14,
      "z": 2,
      "name": "Rock_Ice"
    },
    {
      "x": -19,
      "y": 15,
      "z": 2,
      "name": "Rock_Ice_Permafrost"
    },
    {
      "x": -19,
      "y": 16,
      "z": 2,
      "name": "Rock_Ice_Permafrost"
    },
    {
      "x": -19,
      "y": 17,
      "z": 2,
      "name": "Rock_Ice_Permafrost"
    },
    {
      "x": -19,
      "y": 18,
      "z": 2,
      "name": "Rock_Ice_Permafrost"
    },
    {
      "x": -19,
      "y": 19,
      "z": 2,
      "name": "Rock_Ice_Permafrost"
    },
    {
      "x": -19,
      "y": 14,
      "z": 3,
      "name": "Soil_Snow"
    },
    {
      "x": -18,
      "y": 22,
      "z": -7,
      "name": "Rock_Ice"
    },
    {
      "x": -18,
      "y": 23,
      "z": -7,
      "name": "Rock_Ice"
    },
    {
      "x": -18,
      "y": 24,
      "z": -7,
      "name": "Soil_Snow"
    },
    {
      "x": -18,
      "y": 19,
      "z": -6,
      "name": "Rock_Ice"
    },
    {
      "x": -18,
      "y": 20,
      "z": -6,
      "name": "Rock_Ice_Permafrost"
    },
    {
      "x": -18,
      "y": 21,
      "z": -6,
      "name": "Rock_Ice"
    },
    {
      "x": -18,
      "y": 22,
      "z": -6,
      "name": "Rock_Ice"
    },
    {
      "x": -18,
      "y": 23,
      "z": -6,
      "name": "Rock_Ice"
    },
    {
      "x": -18,
      "y": 24,
      "z": -6,
      "name": "Soil_Snow"
    },
    {
      "x": -18,
      "y": 17,
      "z": -5,
      "name": "Rock_Ice_Permafrost"
    },
    {
      "x": -18,
      "y": 18,
      "z": -5,
      "name": "Rock_Ice_Permafrost"
    },
    {
      "x": -18,
      "y": 19,
      "z": -5,
      "name": "Rock_Ice_Permafrost"
    },
    {
      "x": -18,
      "y": 20,
      "z": -5,
      "name": "Rock_Ice_Permafrost"
    },
    {
      "x": -18,
      "y": 21,
      "z": -5,
      "name": "Rock_Ice"
    },
    {
      "x": -18,
      "y": 22,
      "z": -5,
      "name": "Rock_Ice"
    },
    {
      "x": -18,
      "y": 23,
      "z": -5,
      "name": "Rock_Ice"
    },
    {
      "x": -18,
      "y": 24,
      "z": -5,
      "name": "Soil_Snow"
    },
    {
      "x": -18,
      "y": 15,
      "z": -4,
      "name": "Rock_Ice_Permafrost"
    },
    {
      "x": -18,
      "y": 16,
      "z": -4,
      "name": "Rock_Ice_Permafrost"
    },
    {
      "x": -18,
      "y": 17,
      "z": -4,
      "name": "Rock_Ice_Permafrost"
    },
    {
      "x": -18,
      "y": 18,
      "z": -4,
      "name": "Rock_Ice_Permafrost"
    },
    {
      "x": -18,
      "y": 19,
      "z": -4,
      "name": "Rock_Ice_Permafrost"
    },
    {
      "x": -18,
      "y": 20,
      "z": -4,
      "name": "Rock_Ice_Permafrost"
    },
    {
      "x": -18,
      "y": 21,
      "z": -4,
      "name": "Rock_Ice_Permafrost"
    },
    {
      "x": -18,
      "y": 22,
      "z": -4,
      "name": "Rock_Ice"
    },
    {
      "x": -18,
      "y": 23,
      "z": -4,
      "name": "Rock_Ice"
    },
    {
      "x": -18,
      "y": 24,
      "z": -4,
      "name": "Soil_Snow"
    },
    {
      "x": -18,
      "y": 14,
      "z": -3,
      "name": "Rock_Ice_Permafrost"
    },
    {
      "x": -18,
      "y": 15,
      "z": -3,
      "name": "Rock_Ice_Permafrost"
    },
    {
      "x": -18,
      "y": 16,
      "z": -3,
      "name": "Rock_Ice_Permafrost"
    },
    {
      "x": -18,
      "y": 17,
      "z": -3,
      "name": "Rock_Ice_Permafrost"
    },
    {
      "x": -18,
      "y": 18,
      "z": -3,
      "name": "Rock_Ice_Permafrost"
    },
    {
      "x": -18,
      "y": 19,
      "z": -3,
      "name": "Rock_Ice_Permafrost"
    },
    {
      "x": -18,
      "y": 20,
      "z": -3,
      "name": "Rock_Ice_Permafrost"
    },
    {
      "x": -18,
      "y": 21,
      "z": -3,
      "name": "Rock_Ice"
    },
    {
      "x": -18,
      "y": 22,
      "z": -3,
      "name": "Rock_Ice"
    },
    {
      "x": -18,
      "y": 23,
      "z": -3,
      "name": "Soil_Snow"
    },
    {
      "x": -18,
      "y": 12,
      "z": -2,
      "name": "Rock_Ice_Permafrost"
    },
    {
      "x": -18,
      "y": 13,
      "z": -2,
      "name": "Rock_Ice_Permafrost"
    },
    {
      "x": -18,
      "y": 14,
      "z": -2,
      "name": "Rock_Ice_Permafrost"
    },
    {
      "x": -18,
      "y": 15,
      "z": -2,
      "name": "Rock_Ice_Permafrost"
    },
    {
      "x": -18,
      "y": 16,
      "z": -2,
      "name": "Rock_Ice_Permafrost"
    },
    {
      "x": -18,
      "y": 17,
      "z": -2,
      "name": "Rock_Ice_Permafrost"
    },
    {
      "x": -18,
      "y": 18,
      "z": -2,
      "name": "Rock_Ice_Permafrost"
    },
    {
      "x": -18,
      "y": 19,
      "z": -2,
      "name": "Rock_Ice_Permafrost"
    },
    {
      "x": -18,
      "y": 20,
      "z": -2,
      "name": "Rock_Ice_Permafrost"
    },
    {
      "x": -18,
      "y": 21,
      "z": -2,
      "name": "Rock_Ice_Permafrost"
    },
    {
      "x": -18,
      "y": 22,
      "z": -2,
      "name": "Rock_Ice"
    },
    {
      "x": -18,
      "y": 23,
      "z": -2,
      "name": "Soil_Snow"
    },
    {
      "x": -18,
      "y": 12,
      "z": -1,
      "name": "Rock_Ice_Permafrost"
    },
    {
      "x": -18,
      "y": 13,
      "z": -1,
      "name": "Rock_Ice_Permafrost"
    },
    {
      "x": -18,
      "y": 14,
      "z": -1,
      "name": "Rock_Ice_Permafrost"
    },
    {
      "x": -18,
      "y": 15,
      "z": -1,
      "name": "Rock_Ice_Permafrost"
    },
    {
      "x": -18,
      "y": 16,
      "z": -1,
      "name": "Rock_Ice_Permafrost"
    },
    {
      "x": -18,
      "y": 17,
      "z": -1,
      "name": "Rock_Ice_Permafrost"
    },
    {
      "x": -18,
      "y": 18,
      "z": -1,
      "name": "Rock_Ice_Permafrost"
    },
    {
      "x": -18,
      "y": 19,
      "z": -1,
      "name": "Rock_Ice_Permafrost"
    },
    {
      "x": -18,
      "y": 20,
      "z": -1,
      "name": "Rock_Ice_Permafrost"
    },
    {
      "x": -18,
      "y": 21,
      "z": -1,
      "name": "Rock_Ice"
    },
    {
      "x": -18,
      "y": 22,
      "z": -1,
      "name": "Soil_Snow"
    },
    {
      "x": -18,
      "y": 12,
      "z": 0,
      "name": "Rock_Ice_Permafrost"
    },
    {
      "x": -18,
      "y": 13,
      "z": 0,
      "name": "Rock_Ice_Permafrost"
    },
    {
      "x": -18,
      "y": 14,
      "z": 0,
      "name": "Rock_Ice_Permafrost"
    },
    {
      "x": -18,
      "y": 15,
      "z": 0,
      "name": "Rock_Ice_Permafrost"
    },
    {
      "x": -18,
      "y": 16,
      "z": 0,
      "name": "Rock_Ice_Permafrost"
    },
    {
      "x": -18,
      "y": 17,
      "z": 0,
      "name": "Rock_Ice_Permafrost"
    },
    {
      "x": -18,
      "y": 18,
      "z": 0,
      "name": "Rock_Ice_Permafrost"
    },
    {
      "x": -18,
      "y": 19,
      "z": 0,
      "name": "Rock_Ice_Permafrost"
    },
    {
      "x": -18,
      "y": 20,
      "z": 0,
      "name": "Rock_Ice_Permafrost"
    },
    {
      "x": -18,
      "y": 21,
      "z": 0,
      "name": "Rock_Ice"
    },
    {
      "x": -18,
      "y": 22,
      "z": 0,
      "name": "Soil_Snow"
    },
    {
      "x": -18,
      "y": 11,
      "z": 1,
      "name": "Rock_Ice_Permafrost"
    },
    {
      "x": -18,
      "y": 12,
      "z": 1,
      "name": "Rock_Ice"
    },
    {
      "x": -18,
      "y": 13,
      "z": 1,
      "name": "Rock_Ice_Permafrost"
    },
    {
      "x": -18,
      "y": 14,
      "z": 1,
      "name": "Rock_Ice"
    },
    {
      "x": -18,
      "y": 15,
      "z": 1,
      "name": "Rock_Ice_Permafrost"
    },
    {
      "x": -18,
      "y": 16,
      "z": 1,
      "name": "Rock_Ice_Permafrost"
    },
    {
      "x": -18,
      "y": 17,
      "z": 1,
      "name": "Rock_Ice_Permafrost"
    },
    {
      "x": -18,
      "y": 18,
      "z": 1,
      "name": "Rock_Ice_Permafrost"
    },
    {
      "x": -18,
      "y": 19,
      "z": 1,
      "name": "Rock_Ice_Permafrost"
    },
    {
      "x": -18,
      "y": 20,
      "z": 1,
      "name": "Rock_Ice_Permafrost"
    },
    {
      "x": -18,
      "y": 12,
      "z": 2,
      "name": "Rock_Ice"
    },
    {
      "x": -18,
      "y": 13,
      "z": 2,
      "name": "Rock_Ice"
    },
    {
      "x": -18,
      "y": 14,
      "z": 2,
      "name": "Rock_Ice"
    },
    {
      "x": -18,
      "y": 15,
      "z": 2,
      "name": "Rock_Ice"
    },
    {
      "x": -18,
      "y": 16,
      "z": 2,
      "name": "Rock_Ice_Permafrost"
    },
    {
      "x": -18,
      "y": 17,
      "z": 2,
      "name": "Rock_Ice_Permafrost"
    },
    {
      "x": -18,
      "y": 18,
      "z": 2,
      "name": "Rock_Ice_Permafrost"
    },
    {
      "x": -18,
      "y": 13,
      "z": 3,
      "name": "Rock_Ice"
    },
    {
      "x": -18,
      "y": 14,
      "z": 3,
      "name": "Rock_Ice"
    },
    {
      "x": -18,
      "y": 15,
      "z": 3,
      "name": "Soil_Snow"
    },
    {
      "x": -17,
      "y": 20,
      "z": -7,
      "name": "Rock_Ice_Permafrost"
    },
    {
      "x": -17,
      "y": 21,
      "z": -7,
      "name": "Rock_Ice_Permafrost"
    },
    {
      "x": -17,
      "y": 22,
      "z": -7,
      "name": "Rock_Ice"
    },
    {
      "x": -17,
      "y": 23,
      "z": -7,
      "name": "Rock_Ice"
    },
    {
      "x": -17,
      "y": 24,
      "z": -7,
      "name": "Soil_Snow"
    },
    {
      "x": -17,
      "y": 18,
      "z": -6,
      "name": "Rock_Ice_Permafrost"
    },
    {
      "x": -17,
      "y": 19,
      "z": -6,
      "name": "Rock_Ice_Permafrost"
    },
    {
      "x": -17,
      "y": 20,
      "z": -6,
      "name": "Rock_Ice"
    },
    {
      "x": -17,
      "y": 21,
      "z": -6,
      "name": "Rock_Ice_Permafrost"
    },
    {
      "x": -17,
      "y": 22,
      "z": -6,
      "name": "Rock_Ice"
    },
    {
      "x": -17,
      "y": 23,
      "z": -6,
      "name": "Rock_Ice"
    },
    {
      "x": -17,
      "y": 24,
      "z": -6,
      "name": "Soil_Snow"
    },
    {
      "x": -17,
      "y": 16,
      "z": -5,
      "name": "Rock_Ice_Permafrost"
    },
    {
      "x": -17,
      "y": 17,
      "z": -5,
      "name": "Rock_Ice_Permafrost"
    },
    {
      "x": -17,
      "y": 18,
      "z": -5,
      "name": "Rock_Ice_Permafrost"
    },
    {
      "x": -17,
      "y": 19,
      "z": -5,
      "name": "Rock_Ice_Permafrost"
    },
    {
      "x": -17,
      "y": 20,
      "z": -5,
      "name": "Rock_Ice_Permafrost"
    },
    {
      "x": -17,
      "y": 21,
      "z": -5,
      "name": "Rock_Ice"
    },
    {
      "x": -17,
      "y": 22,
      "z": -5,
      "name": "Rock_Ice_Permafrost"
    },
    {
      "x": -17,
      "y": 23,
      "z": -5,
      "name": "Rock_Ice"
    },
    {
      "x": -17,
      "y": 24,
      "z": -5,
      "name": "Soil_Snow"
    },
    {
      "x": -17,
      "y": 14,
      "z": -4,
      "name": "Rock_Ice_Permafrost"
    },
    {
      "x": -17,
      "y": 15,
      "z": -4,
      "name": "Rock_Ice_Permafrost"
    },
    {
      "x": -17,
      "y": 16,
      "z": -4,
      "name": "Rock_Ice_Permafrost"
    },
    {
      "x": -17,
      "y": 17,
      "z": -4,
      "name": "Rock_Ice_Permafrost"
    },
    {
      "x": -17,
      "y": 18,
      "z": -4,
      "name": "Rock_Ice_Permafrost"
    },
    {
      "x": -17,
      "y": 19,
      "z": -4,
      "name": "Rock_Ice_Permafrost"
    },
    {
      "x": -17,
      "y": 20,
      "z": -4,
      "name": "Rock_Ice_Permafrost"
    },
    {
      "x": -17,
      "y": 21,
      "z": -4,
      "name": "Rock_Ice_Permafrost"
    },
    {
      "x": -17,
      "y": 22,
      "z": -4,
      "name": "Rock_Ice"
    },
    {
      "x": -17,
      "y": 23,
      "z": -4,
      "name": "Soil_Snow"
    },
    {
      "x": -17,
      "y": 13,
      "z": -3,
      "name": "Rock_Ice_Permafrost"
    },
    {
      "x": -17,
      "y": 14,
      "z": -3,
      "name": "Rock_Ice_Permafrost"
    },
    {
      "x": -17,
      "y": 15,
      "z": -3,
      "name": "Rock_Ice_Permafrost"
    },
    {
      "x": -17,
      "y": 16,
      "z": -3,
      "name": "Rock_Ice_Permafrost"
    },
    {
      "x": -17,
      "y": 17,
      "z": -3,
      "name": "Rock_Ice_Permafrost"
    },
    {
      "x": -17,
      "y": 18,
      "z": -3,
      "name": "Rock_Ice_Permafrost"
    },
    {
      "x": -17,
      "y": 19,
      "z": -3,
      "name": "Rock_Ice_Permafrost"
    },
    {
      "x": -17,
      "y": 20,
      "z": -3,
      "name": "Rock_Ice_Permafrost"
    },
    {
      "x": -17,
      "y": 21,
      "z": -3,
      "name": "Rock_Ice_Permafrost"
    },
    {
      "x": -17,
      "y": 22,
      "z": -3,
      "name": "Rock_Ice"
    },
    {
      "x": -17,
      "y": 23,
      "z": -3,
      "name": "Soil_Snow"
    },
    {
      "x": -17,
      "y": 11,
      "z": -2,
      "name": "Rock_Ice_Permafrost"
    },
    {
      "x": -17,
      "y": 12,
      "z": -2,
      "name": "Rock_Ice_Permafrost"
    },
    {
      "x": -17,
      "y": 13,
      "z": -2,
      "name": "Rock_Ice_Permafrost"
    },
    {
      "x": -17,
      "y": 14,
      "z": -2,
      "name": "Rock_Ice_Permafrost"
    },
    {
      "x": -17,
      "y": 15,
      "z": -2,
      "name": "Rock_Ice_Permafrost"
    },
    {
      "x": -17,
      "y": 16,
      "z": -2,
      "name": "Rock_Ice_Permafrost"
    },
    {
      "x": -17,
      "y": 17,
      "z": -2,
      "name": "Rock_Ice_Permafrost"
    },
    {
      "x": -17,
      "y": 18,
      "z": -2,
      "name": "Rock_Ice_Permafrost"
    },
    {
      "x": -17,
      "y": 19,
      "z": -2,
      "name": "Rock_Ice_Permafrost"
    },
    {
      "x": -17,
      "y": 20,
      "z": -2,
      "name": "Rock_Ice_Permafrost"
    },
    {
      "x": -17,
      "y": 21,
      "z": -2,
      "name": "Rock_Ice"
    },
    {
      "x": -17,
      "y": 22,
      "z": -2,
      "name": "Soil_Snow"
    },
    {
      "x": -17,
      "y": 11,
      "z": -1,
      "name": "Rock_Ice_Permafrost"
    },
    {
      "x": -17,
      "y": 12,
      "z": -1,
      "name": "Rock_Ice_Permafrost"
    },
    {
      "x": -17,
      "y": 13,
      "z": -1,
      "name": "Rock_Ice_Permafrost"
    },
    {
      "x": -17,
      "y": 14,
      "z": -1,
      "name": "Rock_Ice_Permafrost"
    },
    {
      "x": -17,
      "y": 15,
      "z": -1,
      "name": "Rock_Ice_Permafrost"
    },
    {
      "x": -17,
      "y": 16,
      "z": -1,
      "name": "Rock_Ice_Permafrost"
    },
    {
      "x": -17,
      "y": 17,
      "z": -1,
      "name": "Rock_Ice_Permafrost"
    },
    {
      "x": -17,
      "y": 18,
      "z": -1,
      "name": "Rock_Ice_Permafrost"
    },
    {
      "x": -17,
      "y": 19,
      "z": -1,
      "name": "Rock_Ice_Permafrost"
    },
    {
      "x": -17,
      "y": 20,
      "z": -1,
      "name": "Rock_Ice_Permafrost"
    },
    {
      "x": -17,
      "y": 21,
      "z": -1,
      "name": "Rock_Ice"
    },
    {
      "x": -17,
      "y": 22,
      "z": -1,
      "name": "Soil_Snow"
    },
    {
      "x": -17,
      "y": 10,
      "z": 0,
      "name": "Rock_Ice_Permafrost"
    },
    {
      "x": -17,
      "y": 11,
      "z": 0,
      "name": "Rock_Ice"
    },
    {
      "x": -17,
      "y": 12,
      "z": 0,
      "name": "Rock_Ice"
    },
    {
      "x": -17,
      "y": 13,
      "z": 0,
      "name": "Rock_Ice_Permafrost"
    },
    {
      "x": -17,
      "y": 14,
      "z": 0,
      "name": "Rock_Ice_Permafrost"
    },
    {
      "x": -17,
      "y": 15,
      "z": 0,
      "name": "Rock_Ice_Permafrost"
    },
    {
      "x": -17,
      "y": 16,
      "z": 0,
      "name": "Rock_Ice_Permafrost"
    },
    {
      "x": -17,
      "y": 17,
      "z": 0,
      "name": "Rock_Ice_Permafrost"
    },
    {
      "x": -17,
      "y": 18,
      "z": 0,
      "name": "Rock_Ice_Permafrost"
    },
    {
      "x": -17,
      "y": 19,
      "z": 0,
      "name": "Rock_Ice_Permafrost"
    },
    {
      "x": -17,
      "y": 20,
      "z": 0,
      "name": "Rock_Ice"
    },
    {
      "x": -17,
      "y": 21,
      "z": 0,
      "name": "Soil_Snow"
    },
    {
      "x": -17,
      "y": 10,
      "z": 1,
      "name": "Rock_Ice"
    },
    {
      "x": -17,
      "y": 11,
      "z": 1,
      "name": "Rock_Ice"
    },
    {
      "x": -17,
      "y": 12,
      "z": 1,
      "name": "Rock_Ice_Permafrost"
    },
    {
      "x": -17,
      "y": 13,
      "z": 1,
      "name": "Rock_Ice"
    },
    {
      "x": -17,
      "y": 14,
      "z": 1,
      "name": "Rock_Ice_Permafrost"
    },
    {
      "x": -17,
      "y": 15,
      "z": 1,
      "name": "Rock_Ice_Permafrost"
    },
    {
      "x": -17,
      "y": 16,
      "z": 1,
      "name": "Rock_Ice_Permafrost"
    },
    {
      "x": -17,
      "y": 17,
      "z": 1,
      "name": "Rock_Ice_Permafrost"
    },
    {
      "x": -17,
      "y": 18,
      "z": 1,
      "name": "Rock_Ice_Permafrost"
    },
    {
      "x": -17,
      "y": 19,
      "z": 1,
      "name": "Rock_Ice_Permafrost"
    },
    {
      "x": -17,
      "y": 20,
      "z": 1,
      "name": "Rock_Ice_Permafrost"
    },
    {
      "x": -17,
      "y": 10,
      "z": 2,
      "name": "Rock_Ice"
    },
    {
      "x": -17,
      "y": 11,
      "z": 2,
      "name": "Rock_Ice"
    },
    {
      "x": -17,
      "y": 12,
      "z": 2,
      "name": "Rock_Ice"
    },
    {
      "x": -17,
      "y": 13,
      "z": 2,
      "name": "Rock_Ice"
    },
    {
      "x": -17,
      "y": 14,
      "z": 2,
      "name": "Rock_Ice_Permafrost"
    },
    {
      "x": -17,
      "y": 15,
      "z": 2,
      "name": "Rock_Ice_Permafrost"
    },
    {
      "x": -17,
      "y": 16,
      "z": 2,
      "name": "Rock_Ice_Permafrost"
    },
    {
      "x": -17,
      "y": 17,
      "z": 2,
      "name": "Rock_Ice"
    },
    {
      "x": -17,
      "y": 18,
      "z": 2,
      "name": "Rock_Ice_Permafrost"
    },
    {
      "x": -17,
      "y": 11,
      "z": 3,
      "name": "Rock_Ice"
    },
    {
      "x": -17,
      "y": 12,
      "z": 3,
      "name": "Rock_Ice"
    },
    {
      "x": -17,
      "y": 13,
      "z": 3,
      "name": "Rock_Ice"
    },
    {
      "x": -17,
      "y": 14,
      "z": 3,
      "name": "Rock_Ice"
    },
    {
      "x": -17,
      "y": 15,
      "z": 3,
      "name": "Rock_Ice_Permafrost"
    },
    {
      "x": -17,
      "y": 16,
      "z": 3,
      "name": "Rock_Ice_Permafrost"
    },
    {
      "x": -17,
      "y": 17,
      "z": 3,
      "name": "Rock_Ice_Permafrost"
    },
    {
      "x": -17,
      "y": 13,
      "z": 4,
      "name": "Soil_Snow"
    },
    {
      "x": -16,
      "y": 21,
      "z": -8,
      "name": "Rock_Ice_Permafrost"
    },
    {
      "x": -16,
      "y": 22,
      "z": -8,
      "name": "Rock_Ice"
    },
    {
      "x": -16,
      "y": 23,
      "z": -8,
      "name": "Soil_Snow"
    },
    {
      "x": -16,
      "y": 19,
      "z": -7,
      "name": "Rock_Ice_Permafrost"
    },
    {
      "x": -16,
      "y": 20,
      "z": -7,
      "name": "Rock_Ice_Permafrost"
    },
    {
      "x": -16,
      "y": 21,
      "z": -7,
      "name": "Rock_Ice_Permafrost"
    },
    {
      "x": -16,
      "y": 22,
      "z": -7,
      "name": "Rock_Ice_Permafrost"
    },
    {
      "x": -16,
      "y": 23,
      "z": -7,
      "name": "Rock_Ice"
    },
    {
      "x": -16,
      "y": 24,
      "z": -7,
      "name": "Soil_Snow"
    },
    {
      "x": -16,
      "y": 17,
      "z": -6,
      "name": "Rock_Ice_Permafrost"
    },
    {
      "x": -16,
      "y": 18,
      "z": -6,
      "name": "Rock_Ice_Permafrost"
    },
    {
      "x": -16,
      "y": 19,
      "z": -6,
      "name": "Rock_Ice_Permafrost"
    },
    {
      "x": -16,
      "y": 20,
      "z": -6,
      "name": "Rock_Ice_Permafrost"
    },
    {
      "x": -16,
      "y": 21,
      "z": -6,
      "name": "Rock_Ice_Permafrost"
    },
    {
      "x": -16,
      "y": 22,
      "z": -6,
      "name": "Rock_Ice_Permafrost"
    },
    {
      "x": -16,
      "y": 23,
      "z": -6,
      "name": "Rock_Ice"
    },
    {
      "x": -16,
      "y": 24,
      "z": -6,
      "name": "Soil_Snow"
    },
    {
      "x": -16,
      "y": 14,
      "z": -5,
      "name": "Rock_Ice_Permafrost"
    },
    {
      "x": -16,
      "y": 15,
      "z": -5,
      "name": "Rock_Ice_Permafrost"
    },
    {
      "x": -16,
      "y": 16,
      "z": -5,
      "name": "Rock_Ice"
    },
    {
      "x": -16,
      "y": 17,
      "z": -5,
      "name": "Rock_Ice_Permafrost"
    },
    {
      "x": -16,
      "y": 18,
      "z": -5,
      "name": "Rock_Ice_Permafrost"
    },
    {
      "x": -16,
      "y": 19,
      "z": -5,
      "name": "Rock_Ice_Permafrost"
    },
    {
      "x": -16,
      "y": 20,
      "z": -5,
      "name": "Rock_Ice_Permafrost"
    },
    {
      "x": -16,
      "y": 21,
      "z": -5,
      "name": "Rock_Ice"
    },
    {
      "x": -16,
      "y": 22,
      "z": -5,
      "name": "Rock_Ice_Permafrost"
    },
    {
      "x": -16,
      "y": 23,
      "z": -5,
      "name": "Rock_Ice"
    },
    {
      "x": -16,
      "y": 24,
      "z": -5,
      "name": "Soil_Snow"
    },
    {
      "x": -16,
      "y": 13,
      "z": -4,
      "name": "Rock_Ice_Permafrost"
    },
    {
      "x": -16,
      "y": 14,
      "z": -4,
      "name": "Rock_Ice_Permafrost"
    },
    {
      "x": -16,
      "y": 15,
      "z": -4,
      "name": "Rock_Ice_Permafrost"
    },
    {
      "x": -16,
      "y": 16,
      "z": -4,
      "name": "Rock_Ice_Permafrost"
    },
    {
      "x": -16,
      "y": 17,
      "z": -4,
      "name": "Rock_Ice_Permafrost"
    },
    {
      "x": -16,
      "y": 18,
      "z": -4,
      "name": "Rock_Ice_Permafrost"
    },
    {
      "x": -16,
      "y": 19,
      "z": -4,
      "name": "Rock_Ice_Permafrost"
    },
    {
      "x": -16,
      "y": 20,
      "z": -4,
      "name": "Rock_Ice_Permafrost"
    },
    {
      "x": -16,
      "y": 21,
      "z": -4,
      "name": "Rock_Ice"
    },
    {
      "x": -16,
      "y": 22,
      "z": -4,
      "name": "Rock_Ice"
    },
    {
      "x": -16,
      "y": 23,
      "z": -4,
      "name": "Soil_Snow"
    },
    {
      "x": -16,
      "y": 11,
      "z": -3,
      "name": "Rock_Ice_Permafrost"
    },
    {
      "x": -16,
      "y": 12,
      "z": -3,
      "name": "Rock_Ice_Permafrost"
    },
    {
      "x": -16,
      "y": 13,
      "z": -3,
      "name": "Rock_Ice_Permafrost"
    },
    {
      "x": -16,
      "y": 14,
      "z": -3,
      "name": "Rock_Ice_Permafrost"
    },
    {
      "x": -16,
      "y": 15,
      "z": -3,
      "name": "Rock_Ice_Permafrost"
    },
    {
      "x": -16,
      "y": 16,
      "z": -3,
      "name": "Rock_Ice_Permafrost"
    },
    {
      "x": -16,
      "y": 17,
      "z": -3,
      "name": "Rock_Ice_Permafrost"
    },
    {
      "x": -16,
      "y": 18,
      "z": -3,
      "name": "Rock_Ice_Permafrost"
    },
    {
      "x": -16,
      "y": 19,
      "z": -3,
      "name": "Rock_Ice_Permafrost"
    },
    {
      "x": -16,
      "y": 20,
      "z": -3,
      "name": "Rock_Ice_Permafrost"
    },
    {
      "x": -16,
      "y": 21,
      "z": -3,
      "name": "Rock_Ice_Permafrost"
    },
    {
      "x": -16,
      "y": 22,
      "z": -3,
      "name": "Rock_Ice"
    },
    {
      "x": -16,
      "y": 23,
      "z": -3,
      "name": "Soil_Snow"
    },
    {
      "x": -16,
      "y": 10,
      "z": -2,
      "name": "Rock_Ice"
    },
    {
      "x": -16,
      "y": 11,
      "z": -2,
      "name": "Rock_Ice_Permafrost"
    },
    {
      "x": -16,
      "y": 12,
      "z": -2,
      "name": "Rock_Ice_Permafrost"
    },
    {
      "x": -16,
      "y": 13,
      "z": -2,
      "name": "Rock_Ice_Permafrost"
    },
    {
      "x": -16,
      "y": 14,
      "z": -2,
      "name": "Rock_Ice_Permafrost"
    },
    {
      "x": -16,
      "y": 15,
      "z": -2,
      "name": "Rock_Ice_Permafrost"
    },
    {
      "x": -16,
      "y": 16,
      "z": -2,
      "name": "Rock_Ice_Permafrost"
    },
    {
      "x": -16,
      "y": 17,
      "z": -2,
      "name": "Rock_Ice_Permafrost"
    },
    {
      "x": -16,
      "y": 18,
      "z": -2,
      "name": "Rock_Ice_Permafrost"
    },
    {
      "x": -16,
      "y": 19,
      "z": -2,
      "name": "Rock_Ice_Permafrost"
    },
    {
      "x": -16,
      "y": 20,
      "z": -2,
      "name": "Rock_Ice_Permafrost"
    },
    {
      "x": -16,
      "y": 21,
      "z": -2,
      "name": "Rock_Ice"
    },
    {
      "x": -16,
      "y": 22,
      "z": -2,
      "name": "Soil_Snow"
    },
    {
      "x": -16,
      "y": 9,
      "z": -1,
      "name": "Rock_Ice"
    },
    {
      "x": -16,
      "y": 10,
      "z": -1,
      "name": "Rock_Ice_Permafrost"
    },
    {
      "x": -16,
      "y": 11,
      "z": -1,
      "name": "Rock_Ice_Permafrost"
    },
    {
      "x": -16,
      "y": 12,
      "z": -1,
      "name": "Rock_Ice_Permafrost"
    },
    {
      "x": -16,
      "y": 13,
      "z": -1,
      "name": "Rock_Ice_Permafrost"
    },
    {
      "x": -16,
      "y": 14,
      "z": -1,
      "name": "Rock_Ice_Permafrost"
    },
    {
      "x": -16,
      "y": 15,
      "z": -1,
      "name": "Rock_Ice_Permafrost"
    },
    {
      "x": -16,
      "y": 16,
      "z": -1,
      "name": "Rock_Ice_Permafrost"
    },
    {
      "x": -16,
      "y": 17,
      "z": -1,
      "name": "Rock_Ice_Permafrost"
    },
    {
      "x": -16,
      "y": 18,
      "z": -1,
      "name": "Rock_Ice_Permafrost"
    },
    {
      "x": -16,
      "y": 19,
      "z": -1,
      "name": "Rock_Ice_Permafrost"
    },
    {
      "x": -16,
      "y": 20,
      "z": -1,
      "name": "Rock_Ice_Permafrost"
    },
    {
      "x": -16,
      "y": 21,
      "z": -1,
      "name": "Rock_Ice"
    },
    {
      "x": -16,
      "y": 22,
      "z": -1,
      "name": "Soil_Snow"
    },
    {
      "x": -16,
      "y": 9,
      "z": 0,
      "name": "Rock_Ice"
    },
    {
      "x": -16,
      "y": 10,
      "z": 0,
      "name": "Rock_Ice"
    },
    {
      "x": -16,
      "y": 11,
      "z": 0,
      "name": "Rock_Ice_Permafrost"
    },
    {
      "x": -16,
      "y": 12,
      "z": 0,
      "name": "Rock_Ice"
    },
    {
      "x": -16,
      "y": 13,
      "z": 0,
      "name": "Rock_Ice"
    },
    {
      "x": -16,
      "y": 14,
      "z": 0,
      "name": "Rock_Ice_Permafrost"
    },
    {
      "x": -16,
      "y": 15,
      "z": 0,
      "name": "Rock_Ice_Permafrost"
    },
    {
      "x": -16,
      "y": 16,
      "z": 0,
      "name": "Rock_Ice_Permafrost"
    },
    {
      "x": -16,
      "y": 17,
      "z": 0,
      "name": "Rock_Ice_Permafrost"
    },
    {
      "x": -16,
      "y": 18,
      "z": 0,
      "name": "Rock_Ice_Permafrost"
    },
    {
      "x": -16,
      "y": 19,
      "z": 0,
      "name": "Rock_Ice_Permafrost"
    },
    {
      "x": -16,
      "y": 20,
      "z": 0,
      "name": "Rock_Ice"
    },
    {
      "x": -16,
      "y": 21,
      "z": 0,
      "name": "Soil_Snow"
    },
    {
      "x": -16,
      "y": 9,
      "z": 1,
      "name": "Rock_Ice"
    },
    {
      "x": -16,
      "y": 10,
      "z": 1,
      "name": "Rock_Ice_Permafrost"
    },
    {
      "x": -16,
      "y": 11,
      "z": 1,
      "name": "Rock_Ice_Permafrost"
    },
    {
      "x": -16,
      "y": 12,
      "z": 1,
      "name": "Rock_Ice"
    },
    {
      "x": -16,
      "y": 13,
      "z": 1,
      "name": "Rock_Ice_Permafrost"
    },
    {
      "x": -16,
      "y": 14,
      "z": 1,
      "name": "Rock_Ice"
    },
    {
      "x": -16,
      "y": 15,
      "z": 1,
      "name": "Rock_Ice_Permafrost"
    },
    {
      "x": -16,
      "y": 16,
      "z": 1,
      "name": "Rock_Ice_Permafrost"
    },
    {
      "x": -16,
      "y": 17,
      "z": 1,
      "name": "Rock_Ice_Permafrost"
    },
    {
      "x": -16,
      "y": 18,
      "z": 1,
      "name": "Rock_Ice_Permafrost"
    },
    {
      "x": -16,
      "y": 19,
      "z": 1,
      "name": "Rock_Ice_Permafrost"
    },
    {
      "x": -16,
      "y": 20,
      "z": 1,
      "name": "Rock_Ice_Permafrost"
    },
    {
      "x": -16,
      "y": 9,
      "z": 2,
      "name": "Rock_Ice"
    },
    {
      "x": -16,
      "y": 10,
      "z": 2,
      "name": "Rock_Ice"
    },
    {
      "x": -16,
      "y": 11,
      "z": 2,
      "name": "Rock_Ice"
    },
    {
      "x": -16,
      "y": 12,
      "z": 2,
      "name": "Rock_Ice"
    },
    {
      "x": -16,
      "y": 13,
      "z": 2,
      "name": "Rock_Ice"
    },
    {
      "x": -16,
      "y": 14,
      "z": 2,
      "name": "Rock_Ice"
    },
    {
      "x": -16,
      "y": 15,
      "z": 2,
      "name": "Rock_Ice_Permafrost"
    },
    {
      "x": -16,
      "y": 16,
      "z": 2,
      "name": "Rock_Ice_Permafrost"
    },
    {
      "x": -16,
      "y": 17,
      "z": 2,
      "name": "Rock_Ice_Permafrost"
    },
    {
      "x": -16,
      "y": 18,
      "z": 2,
      "name": "Rock_Ice_Permafrost"
    },
    {
      "x": -16,
      "y": 19,
      "z": 2,
      "name": "Rock_Ice"
    },
    {
      "x": -16,
      "y": 10,
      "z": 3,
      "name": "Rock_Ice"
    },
    {
      "x": -16,
      "y": 11,
      "z": 3,
      "name": "Rock_Ice"
    },
    {
      "x": -16,
      "y": 12,
      "z": 3,
      "name": "Rock_Ice"
    },
    {
      "x": -16,
      "y": 13,
      "z": 3,
      "name": "Rock_Ice"
    },
    {
      "x": -16,
      "y": 14,
      "z": 3,
      "name": "Rock_Ice"
    },
    {
      "x": -16,
      "y": 15,
      "z": 3,
      "name": "Rock_Ice_Permafrost"
    },
    {
      "x": -16,
      "y": 16,
      "z": 3,
      "name": "Rock_Ice"
    },
    {
      "x": -16,
      "y": 17,
      "z": 3,
      "name": "Rock_Ice_Permafrost"
    },
    {
      "x": -16,
      "y": 11,
      "z": 4,
      "name": "Rock_Ice"
    },
    {
      "x": -16,
      "y": 12,
      "z": 4,
      "name": "Rock_Ice"
    },
    {
      "x": -16,
      "y": 13,
      "z": 4,
      "name": "Soil_Snow"
    },
    {
      "x": -15,
      "y": 20,
      "z": -8,
      "name": "Rock_Ice"
    },
    {
      "x": -15,
      "y": 21,
      "z": -8,
      "name": "Rock_Ice"
    },
    {
      "x": -15,
      "y": 22,
      "z": -8,
      "name": "Rock_Ice_Permafrost"
    },
    {
      "x": -15,
      "y": 23,
      "z": -8,
      "name": "Rock_Ice"
    },
    {
      "x": -15,
      "y": 24,
      "z": -8,
      "name": "Soil_Snow"
    },
    {
      "x": -15,
      "y": 17,
      "z": -7,
      "name": "Rock_Ice_Permafrost"
    },
    {
      "x": -15,
      "y": 18,
      "z": -7,
      "name": "Rock_Ice_Permafrost"
    },
    {
      "x": -15,
      "y": 19,
      "z": -7,
      "name": "Rock_Ice_Permafrost"
    },
    {
      "x": -15,
      "y": 20,
      "z": -7,
      "name": "Rock_Ice_Permafrost"
    },
    {
      "x": -15,
      "y": 21,
      "z": -7,
      "name": "Rock_Ice"
    },
    {
      "x": -15,
      "y": 22,
      "z": -7,
      "name": "Rock_Ice"
    },
    {
      "x": -15,
      "y": 23,
      "z": -7,
      "name": "Rock_Ice"
    },
    {
      "x": -15,
      "y": 24,
      "z": -7,
      "name": "Soil_Snow"
    },
    {
      "x": -15,
      "y": 15,
      "z": -6,
      "name": "Rock_Ice_Permafrost"
    },
    {
      "x": -15,
      "y": 16,
      "z": -6,
      "name": "Rock_Ice_Permafrost"
    },
    {
      "x": -15,
      "y": 17,
      "z": -6,
      "name": "Rock_Ice_Permafrost"
    },
    {
      "x": -15,
      "y": 18,
      "z": -6,
      "name": "Rock_Ice_Permafrost"
    },
    {
      "x": -15,
      "y": 19,
      "z": -6,
      "name": "Rock_Ice_Permafrost"
    },
    {
      "x": -15,
      "y": 20,
      "z": -6,
      "name": "Rock_Ice"
    },
    {
      "x": -15,
      "y": 21,
      "z": -6,
      "name": "Rock_Ice_Permafrost"
    },
    {
      "x": -15,
      "y": 22,
      "z": -6,
      "name": "Rock_Ice"
    },
    {
      "x": -15,
      "y": 23,
      "z": -6,
      "name": "Rock_Ice"
    },
    {
      "x": -15,
      "y": 24,
      "z": -6,
      "name": "Soil_Snow"
    },
    {
      "x": -15,
      "y": 13,
      "z": -5,
      "name": "Rock_Ice_Permafrost"
    },
    {
      "x": -15,
      "y": 14,
      "z": -5,
      "name": "Rock_Ice_Permafrost"
    },
    {
      "x": -15,
      "y": 15,
      "z": -5,
      "name": "Rock_Ice_Permafrost"
    },
    {
      "x": -15,
      "y": 16,
      "z": -5,
      "name": "Rock_Ice_Permafrost"
    },
    {
      "x": -15,
      "y": 17,
      "z": -5,
      "name": "Rock_Ice_Permafrost"
    },
    {
      "x": -15,
      "y": 18,
      "z": -5,
      "name": "Rock_Ice_Permafrost"
    },
    {
      "x": -15,
      "y": 19,
      "z": -5,
      "name": "Rock_Ice_Permafrost"
    },
    {
      "x": -15,
      "y": 20,
      "z": -5,
      "name": "Rock_Ice"
    },
    {
      "x": -15,
      "y": 21,
      "z": -5,
      "name": "Rock_Ice"
    },
    {
      "x": -15,
      "y": 22,
      "z": -5,
      "name": "Rock_Ice"
    },
    {
      "x": -15,
      "y": 23,
      "z": -5,
      "name": "Soil_Snow"
    },
    {
      "x": -15,
      "y": 12,
      "z": -4,
      "name": "Rock_Ice_Permafrost"
    },
    {
      "x": -15,
      "y": 13,
      "z": -4,
      "name": "Rock_Ice_Permafrost"
    },
    {
      "x": -15,
      "y": 14,
      "z": -4,
      "name": "Rock_Ice_Permafrost"
    },
    {
      "x": -15,
      "y": 15,
      "z": -4,
      "name": "Rock_Ice_Permafrost"
    },
    {
      "x": -15,
      "y": 16,
      "z": -4,
      "name": "Rock_Ice_Permafrost"
    },
    {
      "x": -15,
      "y": 17,
      "z": -4,
      "name": "Rock_Ice_Permafrost"
    },
    {
      "x": -15,
      "y": 18,
      "z": -4,
      "name": "Rock_Ice_Permafrost"
    },
    {
      "x": -15,
      "y": 19,
      "z": -4,
      "name": "Rock_Ice_Permafrost"
    },
    {
      "x": -15,
      "y": 20,
      "z": -4,
      "name": "Rock_Ice_Permafrost"
    },
    {
      "x": -15,
      "y": 21,
      "z": -4,
      "name": "Rock_Ice_Permafrost"
    },
    {
      "x": -15,
      "y": 22,
      "z": -4,
      "name": "Rock_Ice"
    },
    {
      "x": -15,
      "y": 23,
      "z": -4,
      "name": "Soil_Snow"
    },
    {
      "x": -15,
      "y": 10,
      "z": -3,
      "name": "Rock_Ice_Permafrost"
    },
    {
      "x": -15,
      "y": 11,
      "z": -3,
      "name": "Rock_Ice_Permafrost"
    },
    {
      "x": -15,
      "y": 12,
      "z": -3,
      "name": "Rock_Ice_Permafrost"
    },
    {
      "x": -15,
      "y": 13,
      "z": -3,
      "name": "Rock_Ice_Permafrost"
    },
    {
      "x": -15,
      "y": 14,
      "z": -3,
      "name": "Rock_Ice_Permafrost"
    },
    {
      "x": -15,
      "y": 15,
      "z": -3,
      "name": "Rock_Ice_Permafrost"
    },
    {
      "x": -15,
      "y": 16,
      "z": -3,
      "name": "Rock_Ice_Permafrost"
    },
    {
      "x": -15,
      "y": 17,
      "z": -3,
      "name": "Rock_Ice"
    },
    {
      "x": -15,
      "y": 18,
      "z": -3,
      "name": "Rock_Ice_Permafrost"
    },
    {
      "x": -15,
      "y": 19,
      "z": -3,
      "name": "Rock_Ice"
    },
    {
      "x": -15,
      "y": 20,
      "z": -3,
      "name": "Rock_Ice_Permafrost"
    },
    {
      "x": -15,
      "y": 21,
      "z": -3,
      "name": "Rock_Ice_Permafrost"
    },
    {
      "x": -15,
      "y": 22,
      "z": -3,
      "name": "Rock_Ice"
    },
    {
      "x": -15,
      "y": 23,
      "z": -3,
      "name": "Soil_Snow"
    },
    {
      "x": -15,
      "y": 9,
      "z": -2,
      "name": "Rock_Ice"
    },
    {
      "x": -15,
      "y": 10,
      "z": -2,
      "name": "Rock_Ice_Permafrost"
    },
    {
      "x": -15,
      "y": 11,
      "z": -2,
      "name": "Rock_Ice_Permafrost"
    },
    {
      "x": -15,
      "y": 12,
      "z": -2,
      "name": "Rock_Ice_Permafrost"
    },
    {
      "x": -15,
      "y": 13,
      "z": -2,
      "name": "Rock_Ice_Permafrost"
    },
    {
      "x": -15,
      "y": 14,
      "z": -2,
      "name": "Rock_Ice_Permafrost"
    },
    {
      "x": -15,
      "y": 15,
      "z": -2,
      "name": "Rock_Ice_Permafrost"
    },
    {
      "x": -15,
      "y": 16,
      "z": -2,
      "name": "Rock_Ice_Permafrost"
    },
    {
      "x": -15,
      "y": 17,
      "z": -2,
      "name": "Rock_Ice_Permafrost"
    },
    {
      "x": -15,
      "y": 18,
      "z": -2,
      "name": "Rock_Ice_Permafrost"
    },
    {
      "x": -15,
      "y": 19,
      "z": -2,
      "name": "Rock_Ice"
    },
    {
      "x": -15,
      "y": 20,
      "z": -2,
      "name": "Rock_Ice_Permafrost"
    },
    {
      "x": -15,
      "y": 21,
      "z": -2,
      "name": "Rock_Ice"
    },
    {
      "x": -15,
      "y": 22,
      "z": -2,
      "name": "Soil_Snow"
    },
    {
      "x": -15,
      "y": 8,
      "z": -1,
      "name": "Rock_Ice"
    },
    {
      "x": -15,
      "y": 9,
      "z": -1,
      "name": "Rock_Ice"
    },
    {
      "x": -15,
      "y": 10,
      "z": -1,
      "name": "Rock_Ice"
    },
    {
      "x": -15,
      "y": 11,
      "z": -1,
      "name": "Rock_Ice_Permafrost"
    },
    {
      "x": -15,
      "y": 12,
      "z": -1,
      "name": "Rock_Ice_Permafrost"
    },
    {
      "x": -15,
      "y": 13,
      "z": -1,
      "name": "Rock_Ice_Permafrost"
    },
    {
      "x": -15,
      "y": 14,
      "z": -1,
      "name": "Rock_Ice_Permafrost"
    },
    {
      "x": -15,
      "y": 15,
      "z": -1,
      "name": "Rock_Ice_Permafrost"
    },
    {
      "x": -15,
      "y": 16,
      "z": -1,
      "name": "Rock_Ice_Permafrost"
    },
    {
      "x": -15,
      "y": 17,
      "z": -1,
      "name": "Rock_Ice_Permafrost"
    },
    {
      "x": -15,
      "y": 18,
      "z": -1,
      "name": "Rock_Ice_Permafrost"
    },
    {
      "x": -15,
      "y": 19,
      "z": -1,
      "name": "Rock_Ice_Permafrost"
    },
    {
      "x": -15,
      "y": 20,
      "z": -1,
      "name": "Rock_Ice_Permafrost"
    },
    {
      "x": -15,
      "y": 21,
      "z": -1,
      "name": "Rock_Ice"
    },
    {
      "x": -15,
      "y": 22,
      "z": -1,
      "name": "Soil_Snow"
    },
    {
      "x": -15,
      "y": 8,
      "z": 0,
      "name": "Rock_Ice"
    },
    {
      "x": -15,
      "y": 9,
      "z": 0,
      "name": "Rock_Ice"
    },
    {
      "x": -15,
      "y": 10,
      "z": 0,
      "name": "Rock_Ice_Permafrost"
    },
    {
      "x": -15,
      "y": 11,
      "z": 0,
      "name": "Rock_Ice_Permafrost"
    },
    {
      "x": -15,
      "y": 12,
      "z": 0,
      "name": "Rock_Ice_Permafrost"
    },
    {
      "x": -15,
      "y": 13,
      "z": 0,
      "name": "Rock_Ice_Permafrost"
    },
    {
      "x": -15,
      "y": 14,
      "z": 0,
      "name": "Rock_Ice_Permafrost"
    },
    {
      "x": -15,
      "y": 15,
      "z": 0,
      "name": "Rock_Ice_Permafrost"
    },
    {
      "x": -15,
      "y": 16,
      "z": 0,
      "name": "Rock_Ice_Permafrost"
    },
    {
      "x": -15,
      "y": 17,
      "z": 0,
      "name": "Rock_Ice_Permafrost"
    },
    {
      "x": -15,
      "y": 18,
      "z": 0,
      "name": "Rock_Ice_Permafrost"
    },
    {
      "x": -15,
      "y": 19,
      "z": 0,
      "name": "Rock_Ice_Permafrost"
    },
    {
      "x": -15,
      "y": 20,
      "z": 0,
      "name": "Rock_Ice"
    },
    {
      "x": -15,
      "y": 21,
      "z": 0,
      "name": "Soil_Snow"
    },
    {
      "x": -15,
      "y": 8,
      "z": 1,
      "name": "Rock_Ice"
    },
    {
      "x": -15,
      "y": 9,
      "z": 1,
      "name": "Rock_Ice_Permafrost"
    },
    {
      "x": -15,
      "y": 10,
      "z": 1,
      "name": "Rock_Ice"
    },
    {
      "x": -15,
      "y": 11,
      "z": 1,
      "name": "Rock_Ice"
    },
    {
      "x": -15,
      "y": 12,
      "z": 1,
      "name": "Rock_Ice_Permafrost"
    },
    {
      "x": -15,
      "y": 13,
      "z": 1,
      "name": "Rock_Ice_Permafrost"
    },
    {
      "x": -15,
      "y": 14,
      "z": 1,
      "name": "Rock_Ice_Permafrost"
    },
    {
      "x": -15,
      "y": 15,
      "z": 1,
      "name": "Rock_Ice_Permafrost"
    },
    {
      "x": -15,
      "y": 16,
      "z": 1,
      "name": "Rock_Ice_Permafrost"
    },
    {
      "x": -15,
      "y": 17,
      "z": 1,
      "name": "Rock_Ice_Permafrost"
    },
    {
      "x": -15,
      "y": 18,
      "z": 1,
      "name": "Rock_Ice_Permafrost"
    },
    {
      "x": -15,
      "y": 19,
      "z": 1,
      "name": "Rock_Ice_Permafrost"
    },
    {
      "x": -15,
      "y": 20,
      "z": 1,
      "name": "Rock_Ice_Permafrost"
    },
    {
      "x": -15,
      "y": 8,
      "z": 2,
      "name": "Rock_Ice"
    },
    {
      "x": -15,
      "y": 9,
      "z": 2,
      "name": "Rock_Ice"
    },
    {
      "x": -15,
      "y": 10,
      "z": 2,
      "name": "Rock_Ice"
    },
    {
      "x": -15,
      "y": 11,
      "z": 2,
      "name": "Rock_Ice_Permafrost"
    },
    {
      "x": -15,
      "y": 12,
      "z": 2,
      "name": "Rock_Ice"
    },
    {
      "x": -15,
      "y": 13,
      "z": 2,
      "name": "Rock_Ice"
    },
    {
      "x": -15,
      "y": 14,
      "z": 2,
      "name": "Rock_Ice"
    },
    {
      "x": -15,
      "y": 15,
      "z": 2,
      "name": "Rock_Ice_Permafrost"
    },
    {
      "x": -15,
      "y": 16,
      "z": 2,
      "name": "Rock_Ice_Permafrost"
    },
    {
      "x": -15,
      "y": 17,
      "z": 2,
      "name": "Rock_Ice_Permafrost"
    },
    {
      "x": -15,
      "y": 18,
      "z": 2,
      "name": "Rock_Ice_Permafrost"
    },
    {
      "x": -15,
      "y": 19,
      "z": 2,
      "name": "Rock_Ice_Permafrost"
    },
    {
      "x": -15,
      "y": 9,
      "z": 3,
      "name": "Rock_Ice"
    },
    {
      "x": -15,
      "y": 10,
      "z": 3,
      "name": "Rock_Ice"
    },
    {
      "x": -15,
      "y": 11,
      "z": 3,
      "name": "Rock_Ice"
    },
    {
      "x": -15,
      "y": 12,
      "z": 3,
      "name": "Rock_Ice"
    },
    {
      "x": -15,
      "y": 13,
      "z": 3,
      "name": "Rock_Ice"
    },
    {
      "x": -15,
      "y": 14,
      "z": 3,
      "name": "Rock_Ice"
    },
    {
      "x": -15,
      "y": 15,
      "z": 3,
      "name": "Rock_Ice_Permafrost"
    },
    {
      "x": -15,
      "y": 16,
      "z": 3,
      "name": "Rock_Ice_Permafrost"
    },
    {
      "x": -15,
      "y": 17,
      "z": 3,
      "name": "Rock_Ice_Permafrost"
    },
    {
      "x": -15,
      "y": 9,
      "z": 4,
      "name": "Rock_Ice"
    },
    {
      "x": -15,
      "y": 10,
      "z": 4,
      "name": "Rock_Ice"
    },
    {
      "x": -15,
      "y": 11,
      "z": 4,
      "name": "Rock_Ice"
    },
    {
      "x": -15,
      "y": 12,
      "z": 4,
      "name": "Rock_Ice"
    },
    {
      "x": -15,
      "y": 13,
      "z": 4,
      "name": "Soil_Snow"
    },
    {
      "x": -15,
      "y": 11,
      "z": 5,
      "name": "Soil_Snow"
    },
    {
      "x": -14,
      "y": 21,
      "z": -9,
      "name": "Rock_Ice"
    },
    {
      "x": -14,
      "y": 22,
      "z": -9,
      "name": "Soil_Snow"
    },
    {
      "x": -14,
      "y": 18,
      "z": -8,
      "name": "Rock_Ice_Permafrost"
    },
    {
      "x": -14,
      "y": 19,
      "z": -8,
      "name": "Rock_Ice_Permafrost"
    },
    {
      "x": -14,
      "y": 20,
      "z": -8,
      "name": "Rock_Ice"
    },
    {
      "x": -14,
      "y": 21,
      "z": -8,
      "name": "Rock_Ice"
    },
    {
      "x": -14,
      "y": 22,
      "z": -8,
      "name": "Rock_Ice"
    },
    {
      "x": -14,
      "y": 23,
      "z": -8,
      "name": "Rock_Ice"
    },
    {
      "x": -14,
      "y": 24,
      "z": -8,
      "name": "Soil_Snow"
    },
    {
      "x": -14,
      "y": 16,
      "z": -7,
      "name": "Rock_Ice_Permafrost"
    },
    {
      "x": -14,
      "y": 17,
      "z": -7,
      "name": "Rock_Ice_Permafrost"
    },
    {
      "x": -14,
      "y": 18,
      "z": -7,
      "name": "Rock_Ice_Permafrost"
    },
    {
      "x": -14,
      "y": 19,
      "z": -7,
      "name": "Rock_Ice_Permafrost"
    },
    {
      "x": -14,
      "y": 20,
      "z": -7,
      "name": "Rock_Ice_Permafrost"
    },
    {
      "x": -14,
      "y": 21,
      "z": -7,
      "name": "Rock_Ice"
    },
    {
      "x": -14,
      "y": 22,
      "z": -7,
      "name": "Rock_Ice"
    },
    {
      "x": -14,
      "y": 23,
      "z": -7,
      "name": "Rock_Ice"
    },
    {
      "x": -14,
      "y": 24,
      "z": -7,
      "name": "Soil_Snow"
    },
    {
      "x": -14,
      "y": 14,
      "z": -6,
      "name": "Rock_Ice_Permafrost"
    },
    {
      "x": -14,
      "y": 15,
      "z": -6,
      "name": "Rock_Ice"
    },
    {
      "x": -14,
      "y": 16,
      "z": -6,
      "name": "Rock_Ice_Permafrost"
    },
    {
      "x": -14,
      "y": 17,
      "z": -6,
      "name": "Rock_Ice_Permafrost"
    },
    {
      "x": -14,
      "y": 18,
      "z": -6,
      "name": "Rock_Ice_Permafrost"
    },
    {
      "x": -14,
      "y": 19,
      "z": -6,
      "name": "Rock_Ice_Permafrost"
    },
    {
      "x": -14,
      "y": 20,
      "z": -6,
      "name": "Rock_Ice_Permafrost"
    },
    {
      "x": -14,
      "y": 21,
      "z": -6,
      "name": "Rock_Ice"
    },
    {
      "x": -14,
      "y": 22,
      "z": -6,
      "name": "Rock_Ice"
    },
    {
      "x": -14,
      "y": 23,
      "z": -6,
      "name": "Rock_Ice"
    },
    {
      "x": -14,
      "y": 24,
      "z": -6,
      "name": "Soil_Snow"
    },
    {
      "x": -14,
      "y": 12,
      "z": -5,
      "name": "Rock_Ice_Permafrost"
    },
    {
      "x": -14,
      "y": 13,
      "z": -5,
      "name": "Rock_Ice_Permafrost"
    },
    {
      "x": -14,
      "y": 14,
      "z": -5,
      "name": "Rock_Ice_Permafrost"
    },
    {
      "x": -14,
      "y": 15,
      "z": -5,
      "name": "Rock_Ice_Permafrost"
    },
    {
      "x": -14,
      "y": 16,
      "z": -5,
      "name": "Rock_Ice_Permafrost"
    },
    {
      "x": -14,
      "y": 17,
      "z": -5,
      "name": "Rock_Ice_Permafrost"
    },
    {
      "x": -14,
      "y": 18,
      "z": -5,
      "name": "Rock_Ice_Permafrost"
    },
    {
      "x": -14,
      "y": 19,
      "z": -5,
      "name": "Rock_Ice_Permafrost"
    },
    {
      "x": -14,
      "y": 20,
      "z": -5,
      "name": "Rock_Ice_Permafrost"
    },
    {
      "x": -14,
      "y": 21,
      "z": -5,
      "name": "Rock_Ice"
    },
    {
      "x": -14,
      "y": 22,
      "z": -5,
      "name": "Rock_Ice"
    },
    {
      "x": -14,
      "y": 23,
      "z": -5,
      "name": "Soil_Snow"
    },
    {
      "x": -14,
      "y": 11,
      "z": -4,
      "name": "Rock_Ice_Permafrost"
    },
    {
      "x": -14,
      "y": 12,
      "z": -4,
      "name": "Rock_Ice_Permafrost"
    },
    {
      "x": -14,
      "y": 13,
      "z": -4,
      "name": "Rock_Ice_Permafrost"
    },
    {
      "x": -14,
      "y": 14,
      "z": -4,
      "name": "Rock_Ice_Permafrost"
    },
    {
      "x": -14,
      "y": 15,
      "z": -4,
      "name": "Rock_Ice_Permafrost"
    },
    {
      "x": -14,
      "y": 16,
      "z": -4,
      "name": "Rock_Ice_Permafrost"
    },
    {
      "x": -14,
      "y": 17,
      "z": -4,
      "name": "Rock_Ice_Permafrost"
    },
    {
      "x": -14,
      "y": 18,
      "z": -4,
      "name": "Rock_Ice_Permafrost"
    },
    {
      "x": -14,
      "y": 19,
      "z": -4,
      "name": "Rock_Ice_Permafrost"
    },
    {
      "x": -14,
      "y": 20,
      "z": -4,
      "name": "Rock_Ice_Permafrost"
    },
    {
      "x": -14,
      "y": 21,
      "z": -4,
      "name": "Rock_Ice_Permafrost"
    },
    {
      "x": -14,
      "y": 22,
      "z": -4,
      "name": "Rock_Ice"
    },
    {
      "x": -14,
      "y": 23,
      "z": -4,
      "name": "Soil_Snow"
    },
    {
      "x": -14,
      "y": 9,
      "z": -3,
      "name": "Rock_Ice_Permafrost"
    },
    {
      "x": -14,
      "y": 10,
      "z": -3,
      "name": "Rock_Ice_Permafrost"
    },
    {
      "x": -14,
      "y": 11,
      "z": -3,
      "name": "Rock_Ice_Permafrost"
    },
    {
      "x": -14,
      "y": 12,
      "z": -3,
      "name": "Rock_Ice_Permafrost"
    },
    {
      "x": -14,
      "y": 13,
      "z": -3,
      "name": "Rock_Ice_Permafrost"
    },
    {
      "x": -14,
      "y": 14,
      "z": -3,
      "name": "Rock_Ice_Permafrost"
    },
    {
      "x": -14,
      "y": 15,
      "z": -3,
      "name": "Rock_Ice_Permafrost"
    },
    {
      "x": -14,
      "y": 16,
      "z": -3,
      "name": "Rock_Ice_Permafrost"
    },
    {
      "x": -14,
      "y": 17,
      "z": -3,
      "name": "Rock_Ice_Permafrost"
    },
    {
      "x": -14,
      "y": 18,
      "z": -3,
      "name": "Rock_Ice_Permafrost"
    },
    {
      "x": -14,
      "y": 19,
      "z": -3,
      "name": "Rock_Ice_Permafrost"
    },
    {
      "x": -14,
      "y": 20,
      "z": -3,
      "name": "Rock_Ice_Permafrost"
    },
    {
      "x": -14,
      "y": 21,
      "z": -3,
      "name": "Rock_Ice_Permafrost"
    },
    {
      "x": -14,
      "y": 22,
      "z": -3,
      "name": "Rock_Ice"
    },
    {
      "x": -14,
      "y": 23,
      "z": -3,
      "name": "Soil_Snow"
    },
    {
      "x": -14,
      "y": 8,
      "z": -2,
      "name": "Rock_Ice_Permafrost"
    },
    {
      "x": -14,
      "y": 9,
      "z": -2,
      "name": "Rock_Ice_Permafrost"
    },
    {
      "x": -14,
      "y": 10,
      "z": -2,
      "name": "Rock_Ice_Permafrost"
    },
    {
      "x": -14,
      "y": 11,
      "z": -2,
      "name": "Rock_Ice_Permafrost"
    },
    {
      "x": -14,
      "y": 12,
      "z": -2,
      "name": "Rock_Ice_Permafrost"
    },
    {
      "x": -14,
      "y": 13,
      "z": -2,
      "name": "Rock_Ice_Permafrost"
    },
    {
      "x": -14,
      "y": 14,
      "z": -2,
      "name": "Rock_Ice_Permafrost"
    },
    {
      "x": -14,
      "y": 15,
      "z": -2,
      "name": "Rock_Ice_Permafrost"
    },
    {
      "x": -14,
      "y": 16,
      "z": -2,
      "name": "Rock_Ice_Permafrost"
    },
    {
      "x": -14,
      "y": 17,
      "z": -2,
      "name": "Rock_Ice_Permafrost"
    },
    {
      "x": -14,
      "y": 18,
      "z": -2,
      "name": "Rock_Ice_Permafrost"
    },
    {
      "x": -14,
      "y": 19,
      "z": -2,
      "name": "Rock_Ice_Permafrost"
    },
    {
      "x": -14,
      "y": 20,
      "z": -2,
      "name": "Rock_Ice_Permafrost"
    },
    {
      "x": -14,
      "y": 21,
      "z": -2,
      "name": "Rock_Ice"
    },
    {
      "x": -14,
      "y": 22,
      "z": -2,
      "name": "Soil_Snow"
    },
    {
      "x": -14,
      "y": 8,
      "z": -1,
      "name": "Rock_Ice"
    },
    {
      "x": -14,
      "y": 9,
      "z": -1,
      "name": "Rock_Ice_Permafrost"
    },
    {
      "x": -14,
      "y": 10,
      "z": -1,
      "name": "Rock_Ice_Permafrost"
    },
    {
      "x": -14,
      "y": 11,
      "z": -1,
      "name": "Rock_Ice_Permafrost"
    },
    {
      "x": -14,
      "y": 12,
      "z": -1,
      "name": "Rock_Ice_Permafrost"
    },
    {
      "x": -14,
      "y": 13,
      "z": -1,
      "name": "Rock_Ice_Permafrost"
    },
    {
      "x": -14,
      "y": 14,
      "z": -1,
      "name": "Rock_Ice_Permafrost"
    },
    {
      "x": -14,
      "y": 15,
      "z": -1,
      "name": "Rock_Ice_Permafrost"
    },
    {
      "x": -14,
      "y": 16,
      "z": -1,
      "name": "Rock_Ice_Permafrost"
    },
    {
      "x": -14,
      "y": 17,
      "z": -1,
      "name": "Rock_Ice_Permafrost"
    },
    {
      "x": -14,
      "y": 18,
      "z": -1,
      "name": "Rock_Ice_Permafrost"
    },
    {
      "x": -14,
      "y": 19,
      "z": -1,
      "name": "Rock_Ice_Permafrost"
    },
    {
      "x": -14,
      "y": 20,
      "z": -1,
      "name": "Rock_Ice_Permafrost"
    },
    {
      "x": -14,
      "y": 21,
      "z": -1,
      "name": "Rock_Ice"
    },
    {
      "x": -14,
      "y": 22,
      "z": -1,
      "name": "Soil_Snow"
    },
    {
      "x": -14,
      "y": 7,
      "z": 0,
      "name": "Rock_Ice"
    },
    {
      "x": -14,
      "y": 8,
      "z": 0,
      "name": "Rock_Ice_Permafrost"
    },
    {
      "x": -14,
      "y": 9,
      "z": 0,
      "name": "Rock_Ice"
    },
    {
      "x": -14,
      "y": 10,
      "z": 0,
      "name": "Rock_Ice"
    },
    {
      "x": -14,
      "y": 11,
      "z": 0,
      "name": "Rock_Ice_Permafrost"
    },
    {
      "x": -14,
      "y": 12,
      "z": 0,
      "name": "Rock_Ice_Permafrost"
    },
    {
      "x": -14,
      "y": 13,
      "z": 0,
      "name": "Rock_Ice_Permafrost"
    },
    {
      "x": -14,
      "y": 14,
      "z": 0,
      "name": "Rock_Ice_Permafrost"
    },
    {
      "x": -14,
      "y": 15,
      "z": 0,
      "name": "Rock_Ice_Permafrost"
    },
    {
      "x": -14,
      "y": 16,
      "z": 0,
      "name": "Rock_Ice_Permafrost"
    },
    {
      "x": -14,
      "y": 17,
      "z": 0,
      "name": "Rock_Ice_Permafrost"
    },
    {
      "x": -14,
      "y": 18,
      "z": 0,
      "name": "Rock_Ice_Permafrost"
    },
    {
      "x": -14,
      "y": 19,
      "z": 0,
      "name": "Rock_Ice_Permafrost"
    },
    {
      "x": -14,
      "y": 20,
      "z": 0,
      "name": "Rock_Ice"
    },
    {
      "x": -14,
      "y": 21,
      "z": 0,
      "name": "Soil_Snow"
    },
    {
      "x": -14,
      "y": 7,
      "z": 1,
      "name": "Rock_Ice"
    },
    {
      "x": -14,
      "y": 8,
      "z": 1,
      "name": "Rock_Ice"
    },
    {
      "x": -14,
      "y": 9,
      "z": 1,
      "name": "Rock_Ice"
    },
    {
      "x": -14,
      "y": 10,
      "z": 1,
      "name": "Rock_Ice"
    },
    {
      "x": -14,
      "y": 11,
      "z": 1,
      "name": "Rock_Ice"
    },
    {
      "x": -14,
      "y": 12,
      "z": 1,
      "name": "Rock_Ice_Permafrost"
    },
    {
      "x": -14,
      "y": 13,
      "z": 1,
      "name": "Rock_Ice_Permafrost"
    },
    {
      "x": -14,
      "y": 14,
      "z": 1,
      "name": "Rock_Ice_Permafrost"
    },
    {
      "x": -14,
      "y": 15,
      "z": 1,
      "name": "Rock_Ice_Permafrost"
    },
    {
      "x": -14,
      "y": 16,
      "z": 1,
      "name": "Rock_Ice_Permafrost"
    },
    {
      "x": -14,
      "y": 17,
      "z": 1,
      "name": "Rock_Ice_Permafrost"
    },
    {
      "x": -14,
      "y": 18,
      "z": 1,
      "name": "Rock_Ice"
    },
    {
      "x": -14,
      "y": 19,
      "z": 1,
      "name": "Rock_Ice_Permafrost"
    },
    {
      "x": -14,
      "y": 20,
      "z": 1,
      "name": "Rock_Ice"
    },
    {
      "x": -14,
      "y": 7,
      "z": 2,
      "name": "Rock_Ice"
    },
    {
      "x": -14,
      "y": 8,
      "z": 2,
      "name": "Rock_Ice_Permafrost"
    },
    {
      "x": -14,
      "y": 9,
      "z": 2,
      "name": "Rock_Ice"
    },
    {
      "x": -14,
      "y": 10,
      "z": 2,
      "name": "Rock_Ice"
    },
    {
      "x": -14,
      "y": 11,
      "z": 2,
      "name": "Rock_Ice"
    },
    {
      "x": -14,
      "y": 12,
      "z": 2,
      "name": "Rock_Ice_Permafrost"
    },
    {
      "x": -14,
      "y": 13,
      "z": 2,
      "name": "Rock_Ice_Permafrost"
    },
    {
      "x": -14,
      "y": 14,
      "z": 2,
      "name": "Rock_Ice_Permafrost"
    },
    {
      "x": -14,
      "y": 15,
      "z": 2,
      "name": "Rock_Ice_Permafrost"
    },
    {
      "x": -14,
      "y": 16,
      "z": 2,
      "name": "Rock_Ice_Permafrost"
    },
    {
      "x": -14,
      "y": 17,
      "z": 2,
      "name": "Rock_Ice_Permafrost"
    },
    {
      "x": -14,
      "y": 18,
      "z": 2,
      "name": "Rock_Ice_Permafrost"
    },
    {
      "x": -14,
      "y": 19,
      "z": 2,
      "name": "Rock_Ice_Permafrost"
    },
    {
      "x": -14,
      "y": 8,
      "z": 3,
      "name": "Rock_Ice"
    },
    {
      "x": -14,
      "y": 9,
      "z": 3,
      "name": "Rock_Ice"
    },
    {
      "x": -14,
      "y": 10,
      "z": 3,
      "name": "Rock_Ice"
    },
    {
      "x": -14,
      "y": 11,
      "z": 3,
      "name": "Rock_Ice"
    },
    {
      "x": -14,
      "y": 12,
      "z": 3,
      "name": "Rock_Ice"
    },
    {
      "x": -14,
      "y": 13,
      "z": 3,
      "name": "Rock_Ice"
    },
    {
      "x": -14,
      "y": 14,
      "z": 3,
      "name": "Rock_Ice"
    },
    {
      "x": -14,
      "y": 15,
      "z": 3,
      "name": "Rock_Ice"
    },
    {
      "x": -14,
      "y": 16,
      "z": 3,
      "name": "Rock_Ice_Permafrost"
    },
    {
      "x": -14,
      "y": 17,
      "z": 3,
      "name": "Rock_Ice_Permafrost"
    },
    {
      "x": -14,
      "y": 8,
      "z": 4,
      "name": "Rock_Ice"
    },
    {
      "x": -14,
      "y": 9,
      "z": 4,
      "name": "Rock_Ice"
    },
    {
      "x": -14,
      "y": 10,
      "z": 4,
      "name": "Rock_Ice_Permafrost"
    },
    {
      "x": -14,
      "y": 11,
      "z": 4,
      "name": "Rock_Ice"
    },
    {
      "x": -14,
      "y": 12,
      "z": 4,
      "name": "Rock_Ice"
    },
    {
      "x": -14,
      "y": 13,
      "z": 4,
      "name": "Rock_Ice"
    },
    {
      "x": -14,
      "y": 14,
      "z": 4,
      "name": "Rock_Ice"
    },
    {
      "x": -14,
      "y": 15,
      "z": 4,
      "name": "Rock_Ice_Permafrost"
    },
    {
      "x": -14,
      "y": 9,
      "z": 5,
      "name": "Rock_Ice_Permafrost"
    },
    {
      "x": -14,
      "y": 10,
      "z": 5,
      "name": "Rock_Ice_Permafrost"
    },
    {
      "x": -14,
      "y": 11,
      "z": 5,
      "name": "Rock_Ice"
    },
    {
      "x": -14,
      "y": 12,
      "z": 5,
      "name": "Rock_Ice"
    },
    {
      "x": -13,
      "y": 19,
      "z": -9,
      "name": "Rock_Ice_Permafrost"
    },
    {
      "x": -13,
      "y": 20,
      "z": -9,
      "name": "Rock_Ice_Permafrost"
    },
    {
      "x": -13,
      "y": 21,
      "z": -9,
      "name": "Rock_Ice"
    },
    {
      "x": -13,
      "y": 22,
      "z": -9,
      "name": "Rock_Ice"
    },
    {
      "x": -13,
      "y": 23,
      "z": -9,
      "name": "Soil_Snow"
    },
    {
      "x": -13,
      "y": 17,
      "z": -8,
      "name": "Rock_Ice_Permafrost"
    },
    {
      "x": -13,
      "y": 18,
      "z": -8,
      "name": "Rock_Ice_Permafrost"
    },
    {
      "x": -13,
      "y": 19,
      "z": -8,
      "name": "Rock_Ice_Permafrost"
    },
    {
      "x": -13,
      "y": 20,
      "z": -8,
      "name": "Rock_Ice_Permafrost"
    },
    {
      "x": -13,
      "y": 21,
      "z": -8,
      "name": "Rock_Ice"
    },
    {
      "x": -13,
      "y": 22,
      "z": -8,
      "name": "Rock_Ice_Permafrost"
    },
    {
      "x": -13,
      "y": 23,
      "z": -8,
      "name": "Rock_Ice"
    },
    {
      "x": -13,
      "y": 24,
      "z": -8,
      "name": "Soil_Snow"
    },
    {
      "x": -13,
      "y": 15,
      "z": -7,
      "name": "Rock_Ice_Permafrost"
    },
    {
      "x": -13,
      "y": 16,
      "z": -7,
      "name": "Rock_Ice_Permafrost"
    },
    {
      "x": -13,
      "y": 17,
      "z": -7,
      "name": "Rock_Ice_Permafrost"
    },
    {
      "x": -13,
      "y": 18,
      "z": -7,
      "name": "Rock_Ice_Permafrost"
    },
    {
      "x": -13,
      "y": 19,
      "z": -7,
      "name": "Rock_Ice_Permafrost"
    },
    {
      "x": -13,
      "y": 20,
      "z": -7,
      "name": "Rock_Ice"
    },
    {
      "x": -13,
      "y": 21,
      "z": -7,
      "name": "Rock_Ice"
    },
    {
      "x": -13,
      "y": 22,
      "z": -7,
      "name": "Rock_Ice"
    },
    {
      "x": -13,
      "y": 23,
      "z": -7,
      "name": "Rock_Ice"
    },
    {
      "x": -13,
      "y": 24,
      "z": -7,
      "name": "Soil_Snow"
    },
    {
      "x": -13,
      "y": 13,
      "z": -6,
      "name": "Rock_Ice_Permafrost"
    },
    {
      "x": -13,
      "y": 14,
      "z": -6,
      "name": "Rock_Ice_Permafrost"
    },
    {
      "x": -13,
      "y": 15,
      "z": -6,
      "name": "Rock_Ice_Permafrost"
    },
    {
      "x": -13,
      "y": 16,
      "z": -6,
      "name": "Rock_Ice_Permafrost"
    },
    {
      "x": -13,
      "y": 17,
      "z": -6,
      "name": "Rock_Ice_Permafrost"
    },
    {
      "x": -13,
      "y": 18,
      "z": -6,
      "name": "Rock_Ice_Permafrost"
    },
    {
      "x": -13,
      "y": 19,
      "z": -6,
      "name": "Rock_Ice_Permafrost"
    },
    {
      "x": -13,
      "y": 20,
      "z": -6,
      "name": "Rock_Ice_Permafrost"
    },
    {
      "x": -13,
      "y": 21,
      "z": -6,
      "name": "Rock_Ice_Permafrost"
    },
    {
      "x": -13,
      "y": 22,
      "z": -6,
      "name": "Rock_Ice_Permafrost"
    },
    {
      "x": -13,
      "y": 23,
      "z": -6,
      "name": "Rock_Ice"
    },
    {
      "x": -13,
      "y": 24,
      "z": -6,
      "name": "Soil_Snow"
    },
    {
      "x": -13,
      "y": 11,
      "z": -5,
      "name": "Rock_Ice_Permafrost"
    },
    {
      "x": -13,
      "y": 12,
      "z": -5,
      "name": "Rock_Ice_Permafrost"
    },
    {
      "x": -13,
      "y": 13,
      "z": -5,
      "name": "Rock_Ice_Permafrost"
    },
    {
      "x": -13,
      "y": 14,
      "z": -5,
      "name": "Rock_Ice_Permafrost"
    },
    {
      "x": -13,
      "y": 15,
      "z": -5,
      "name": "Rock_Ice_Permafrost"
    },
    {
      "x": -13,
      "y": 16,
      "z": -5,
      "name": "Rock_Ice_Permafrost"
    },
    {
      "x": -13,
      "y": 17,
      "z": -5,
      "name": "Rock_Ice"
    },
    {
      "x": -13,
      "y": 18,
      "z": -5,
      "name": "Rock_Ice_Permafrost"
    },
    {
      "x": -13,
      "y": 19,
      "z": -5,
      "name": "Rock_Ice_Permafrost"
    },
    {
      "x": -13,
      "y": 20,
      "z": -5,
      "name": "Rock_Ice_Permafrost"
    },
    {
      "x": -13,
      "y": 21,
      "z": -5,
      "name": "Rock_Ice_Permafrost"
    },
    {
      "x": -13,
      "y": 22,
      "z": -5,
      "name": "Rock_Ice"
    },
    {
      "x": -13,
      "y": 23,
      "z": -5,
      "name": "Soil_Snow"
    },
    {
      "x": -13,
      "y": 10,
      "z": -4,
      "name": "Rock_Ice_Permafrost"
    },
    {
      "x": -13,
      "y": 11,
      "z": -4,
      "name": "Rock_Ice_Permafrost"
    },
    {
      "x": -13,
      "y": 12,
      "z": -4,
      "name": "Rock_Ice_Permafrost"
    },
    {
      "x": -13,
      "y": 13,
      "z": -4,
      "name": "Rock_Ice_Permafrost"
    },
    {
      "x": -13,
      "y": 14,
      "z": -4,
      "name": "Rock_Ice_Permafrost"
    },
    {
      "x": -13,
      "y": 15,
      "z": -4,
      "name": "Rock_Ice_Permafrost"
    },
    {
      "x": -13,
      "y": 16,
      "z": -4,
      "name": "Rock_Ice_Permafrost"
    },
    {
      "x": -13,
      "y": 17,
      "z": -4,
      "name": "Rock_Ice"
    },
    {
      "x": -13,
      "y": 18,
      "z": -4,
      "name": "Rock_Ice_Permafrost"
    },
    {
      "x": -13,
      "y": 19,
      "z": -4,
      "name": "Rock_Ice_Permafrost"
    },
    {
      "x": -13,
      "y": 20,
      "z": -4,
      "name": "Rock_Ice_Permafrost"
    },
    {
      "x": -13,
      "y": 21,
      "z": -4,
      "name": "Rock_Ice"
    },
    {
      "x": -13,
      "y": 22,
      "z": -4,
      "name": "Rock_Ice"
    },
    {
      "x": -13,
      "y": 23,
      "z": -4,
      "name": "Soil_Snow"
    },
    {
      "x": -13,
      "y": 8,
      "z": -3,
      "name": "Rock_Ice"
    },
    {
      "x": -13,
      "y": 9,
      "z": -3,
      "name": "Rock_Ice_Permafrost"
    },
    {
      "x": -13,
      "y": 10,
      "z": -3,
      "name": "Rock_Ice_Permafrost"
    },
    {
      "x": -13,
      "y": 11,
      "z": -3,
      "name": "Rock_Ice_Permafrost"
    },
    {
      "x": -13,
      "y": 12,
      "z": -3,
      "name": "Rock_Ice_Permafrost"
    },
    {
      "x": -13,
      "y": 13,
      "z": -3,
      "name": "Rock_Ice_Permafrost"
    },
    {
      "x": -13,
      "y": 14,
      "z": -3,
      "name": "Rock_Ice_Permafrost"
    },
    {
      "x": -13,
      "y": 15,
      "z": -3,
      "name": "Rock_Ice_Permafrost"
    },
    {
      "x": -13,
      "y": 16,
      "z": -3,
      "name": "Rock_Ice_Permafrost"
    },
    {
      "x": -13,
      "y": 17,
      "z": -3,
      "name": "Rock_Ice_Permafrost"
    },
    {
      "x": -13,
      "y": 18,
      "z": -3,
      "name": "Rock_Ice_Permafrost"
    },
    {
      "x": -13,
      "y": 19,
      "z": -3,
      "name": "Rock_Ice"
    },
    {
      "x": -13,
      "y": 20,
      "z": -3,
      "name": "Rock_Ice_Permafrost"
    },
    {
      "x": -13,
      "y": 21,
      "z": -3,
      "name": "Rock_Ice_Permafrost"
    },
    {
      "x": -13,
      "y": 22,
      "z": -3,
      "name": "Rock_Ice"
    },
    {
      "x": -13,
      "y": 23,
      "z": -3,
      "name": "Soil_Snow"
    },
    {
      "x": -13,
      "y": 7,
      "z": -2,
      "name": "Rock_Ice_Permafrost"
    },
    {
      "x": -13,
      "y": 8,
      "z": -2,
      "name": "Rock_Ice_Permafrost"
    },
    {
      "x": -13,
      "y": 9,
      "z": -2,
      "name": "Rock_Ice_Permafrost"
    },
    {
      "x": -13,
      "y": 10,
      "z": -2,
      "name": "Rock_Ice_Permafrost"
    },
    {
      "x": -13,
      "y": 11,
      "z": -2,
      "name": "Rock_Ice_Permafrost"
    },
    {
      "x": -13,
      "y": 12,
      "z": -2,
      "name": "Rock_Ice_Permafrost"
    },
    {
      "x": -13,
      "y": 13,
      "z": -2,
      "name": "Rock_Ice_Permafrost"
    },
    {
      "x": -13,
      "y": 14,
      "z": -2,
      "name": "Rock_Ice_Permafrost"
    },
    {
      "x": -13,
      "y": 15,
      "z": -2,
      "name": "Rock_Ice_Permafrost"
    },
    {
      "x": -13,
      "y": 16,
      "z": -2,
      "name": "Rock_Ice_Permafrost"
    },
    {
      "x": -13,
      "y": 17,
      "z": -2,
      "name": "Rock_Ice_Permafrost"
    },
    {
      "x": -13,
      "y": 18,
      "z": -2,
      "name": "Rock_Ice_Permafrost"
    },
    {
      "x": -13,
      "y": 19,
      "z": -2,
      "name": "Rock_Ice"
    },
    {
      "x": -13,
      "y": 20,
      "z": -2,
      "name": "Rock_Ice"
    },
    {
      "x": -13,
      "y": 21,
      "z": -2,
      "name": "Rock_Ice"
    },
    {
      "x": -13,
      "y": 22,
      "z": -2,
      "name": "Soil_Snow"
    },
    {
      "x": -13,
      "y": 7,
      "z": -1,
      "name": "Rock_Ice"
    },
    {
      "x": -13,
      "y": 8,
      "z": -1,
      "name": "Rock_Ice"
    },
    {
      "x": -13,
      "y": 9,
      "z": -1,
      "name": "Rock_Ice_Permafrost"
    },
    {
      "x": -13,
      "y": 10,
      "z": -1,
      "name": "Rock_Ice"
    },
    {
      "x": -13,
      "y": 11,
      "z": -1,
      "name": "Rock_Ice_Permafrost"
    },
    {
      "x": -13,
      "y": 12,
      "z": -1,
      "name": "Rock_Ice_Permafrost"
    },
    {
      "x": -13,
      "y": 13,
      "z": -1,
      "name": "Rock_Ice_Permafrost"
    },
    {
      "x": -13,
      "y": 14,
      "z": -1,
      "name": "Rock_Ice_Permafrost"
    },
    {
      "x": -13,
      "y": 15,
      "z": -1,
      "name": "Rock_Ice_Permafrost"
    },
    {
      "x": -13,
      "y": 16,
      "z": -1,
      "name": "Rock_Ice_Permafrost"
    },
    {
      "x": -13,
      "y": 17,
      "z": -1,
      "name": "Rock_Ice_Permafrost"
    },
    {
      "x": -13,
      "y": 18,
      "z": -1,
      "name": "Rock_Ice_Permafrost"
    },
    {
      "x": -13,
      "y": 19,
      "z": -1,
      "name": "Rock_Ice_Permafrost"
    },
    {
      "x": -13,
      "y": 20,
      "z": -1,
      "name": "Rock_Ice"
    },
    {
      "x": -13,
      "y": 21,
      "z": -1,
      "name": "Rock_Ice"
    },
    {
      "x": -13,
      "y": 22,
      "z": -1,
      "name": "Soil_Snow"
    },
    {
      "x": -13,
      "y": 6,
      "z": 0,
      "name": "Rock_Ice"
    },
    {
      "x": -13,
      "y": 7,
      "z": 0,
      "name": "Rock_Ice"
    },
    {
      "x": -13,
      "y": 8,
      "z": 0,
      "name": "Rock_Ice"
    },
    {
      "x": -13,
      "y": 9,
      "z": 0,
      "name": "Rock_Ice"
    },
    {
      "x": -13,
      "y": 10,
      "z": 0,
      "name": "Rock_Ice_Permafrost"
    },
    {
      "x": -13,
      "y": 11,
      "z": 0,
      "name": "Rock_Ice_Permafrost"
    },
    {
      "x": -13,
      "y": 12,
      "z": 0,
      "name": "Rock_Ice_Permafrost"
    },
    {
      "x": -13,
      "y": 13,
      "z": 0,
      "name": "Rock_Ice_Permafrost"
    },
    {
      "x": -13,
      "y": 14,
      "z": 0,
      "name": "Rock_Ice_Permafrost"
    },
    {
      "x": -13,
      "y": 15,
      "z": 0,
      "name": "Rock_Ice_Permafrost"
    },
    {
      "x": -13,
      "y": 16,
      "z": 0,
      "name": "Rock_Ice_Permafrost"
    },
    {
      "x": -13,
      "y": 17,
      "z": 0,
      "name": "Rock_Ice_Permafrost"
    },
    {
      "x": -13,
      "y": 18,
      "z": 0,
      "name": "Rock_Ice_Permafrost"
    },
    {
      "x": -13,
      "y": 19,
      "z": 0,
      "name": "Rock_Ice_Permafrost"
    },
    {
      "x": -13,
      "y": 20,
      "z": 0,
      "name": "Rock_Ice"
    },
    {
      "x": -13,
      "y": 21,
      "z": 0,
      "name": "Soil_Snow"
    },
    {
      "x": -13,
      "y": 6,
      "z": 1,
      "name": "Rock_Ice_Permafrost"
    },
    {
      "x": -13,
      "y": 7,
      "z": 1,
      "name": "Rock_Ice_Permafrost"
    },
    {
      "x": -13,
      "y": 8,
      "z": 1,
      "name": "Rock_Ice"
    },
    {
      "x": -13,
      "y": 9,
      "z": 1,
      "name": "Rock_Ice"
    },
    {
      "x": -13,
      "y": 10,
      "z": 1,
      "name": "Rock_Ice"
    },
    {
      "x": -13,
      "y": 11,
      "z": 1,
      "name": "Rock_Ice"
    },
    {
      "x": -13,
      "y": 12,
      "z": 1,
      "name": "Rock_Ice_Permafrost"
    },
    {
      "x": -13,
      "y": 13,
      "z": 1,
      "name": "Rock_Ice_Permafrost"
    },
    {
      "x": -13,
      "y": 14,
      "z": 1,
      "name": "Rock_Ice_Permafrost"
    },
    {
      "x": -13,
      "y": 15,
      "z": 1,
      "name": "Rock_Ice_Permafrost"
    },
    {
      "x": -13,
      "y": 16,
      "z": 1,
      "name": "Rock_Ice_Permafrost"
    },
    {
      "x": -13,
      "y": 17,
      "z": 1,
      "name": "Rock_Ice_Permafrost"
    },
    {
      "x": -13,
      "y": 18,
      "z": 1,
      "name": "Rock_Ice_Permafrost"
    },
    {
      "x": -13,
      "y": 19,
      "z": 1,
      "name": "Rock_Ice_Permafrost"
    },
    {
      "x": -13,
      "y": 20,
      "z": 1,
      "name": "Rock_Ice_Permafrost"
    },
    {
      "x": -13,
      "y": 6,
      "z": 2,
      "name": "Rock_Ice_Permafrost"
    },
    {
      "x": -13,
      "y": 7,
      "z": 2,
      "name": "Rock_Ice"
    },
    {
      "x": -13,
      "y": 8,
      "z": 2,
      "name": "Rock_Ice"
    },
    {
      "x": -13,
      "y": 9,
      "z": 2,
      "name": "Rock_Ice"
    },
    {
      "x": -13,
      "y": 10,
      "z": 2,
      "name": "Rock_Ice_Permafrost"
    },
    {
      "x": -13,
      "y": 11,
      "z": 2,
      "name": "Rock_Ice_Permafrost"
    },
    {
      "x": -13,
      "y": 12,
      "z": 2,
      "name": "Rock_Ice"
    },
    {
      "x": -13,
      "y": 13,
      "z": 2,
      "name": "Rock_Ice_Permafrost"
    },
    {
      "x": -13,
      "y": 14,
      "z": 2,
      "name": "Rock_Ice"
    },
    {
      "x": -13,
      "y": 15,
      "z": 2,
      "name": "Rock_Ice_Permafrost"
    },
    {
      "x": -13,
      "y": 16,
      "z": 2,
      "name": "Rock_Ice_Permafrost"
    },
    {
      "x": -13,
      "y": 17,
      "z": 2,
      "name": "Rock_Ice_Permafrost"
    },
    {
      "x": -13,
      "y": 18,
      "z": 2,
      "name": "Rock_Ice"
    },
    {
      "x": -13,
      "y": 19,
      "z": 2,
      "name": "Rock_Ice_Permafrost"
    },
    {
      "x": -13,
      "y": 6,
      "z": 3,
      "name": "Rock_Ice"
    },
    {
      "x": -13,
      "y": 7,
      "z": 3,
      "name": "Rock_Ice"
    },
    {
      "x": -13,
      "y": 8,
      "z": 3,
      "name": "Rock_Ice_Permafrost"
    },
    {
      "x": -13,
      "y": 9,
      "z": 3,
      "name": "Rock_Ice"
    },
    {
      "x": -13,
      "y": 10,
      "z": 3,
      "name": "Rock_Ice"
    },
    {
      "x": -13,
      "y": 11,
      "z": 3,
      "name": "Rock_Ice"
    },
    {
      "x": -13,
      "y": 12,
      "z": 3,
      "name": "Rock_Ice_Permafrost"
    },
    {
      "x": -13,
      "y": 13,
      "z": 3,
      "name": "Rock_Ice"
    },
    {
      "x": -13,
      "y": 14,
      "z": 3,
      "name": "Rock_Ice_Permafrost"
    },
    {
      "x": -13,
      "y": 15,
      "z": 3,
      "name": "Rock_Ice_Permafrost"
    },
    {
      "x": -13,
      "y": 16,
      "z": 3,
      "name": "Rock_Ice_Permafrost"
    },
    {
      "x": -13,
      "y": 17,
      "z": 3,
      "name": "Rock_Ice"
    },
    {
      "x": -13,
      "y": 18,
      "z": 3,
      "name": "Rock_Ice"
    },
    {
      "x": -13,
      "y": 19,
      "z": 3,
      "name": "Rock_Ice"
    },
    {
      "x": -13,
      "y": 7,
      "z": 4,
      "name": "Rock_Ice_Permafrost"
    },
    {
      "x": -13,
      "y": 8,
      "z": 4,
      "name": "Rock_Ice"
    },
    {
      "x": -13,
      "y": 9,
      "z": 4,
      "name": "Rock_Ice_Permafrost"
    },
    {
      "x": -13,
      "y": 10,
      "z": 4,
      "name": "Rock_Ice"
    },
    {
      "x": -13,
      "y": 11,
      "z": 4,
      "name": "Rock_Ice"
    },
    {
      "x": -13,
      "y": 12,
      "z": 4,
      "name": "Rock_Ice"
    },
    {
      "x": -13,
      "y": 13,
      "z": 4,
      "name": "Rock_Ice"
    },
    {
      "x": -13,
      "y": 14,
      "z": 4,
      "name": "Rock_Ice"
    },
    {
      "x": -13,
      "y": 15,
      "z": 4,
      "name": "Rock_Ice_Permafrost"
    },
    {
      "x": -13,
      "y": 16,
      "z": 4,
      "name": "Rock_Ice"
    },
    {
      "x": -13,
      "y": 8,
      "z": 5,
      "name": "Rock_Ice_Permafrost"
    },
    {
      "x": -13,
      "y": 9,
      "z": 5,
      "name": "Rock_Ice_Permafrost"
    },
    {
      "x": -13,
      "y": 10,
      "z": 5,
      "name": "Rock_Ice_Permafrost"
    },
    {
      "x": -13,
      "y": 11,
      "z": 5,
      "name": "Rock_Ice"
    },
    {
      "x": -13,
      "y": 12,
      "z": 5,
      "name": "Soil_Snow"
    },
    {
      "x": -13,
      "y": 9,
      "z": 6,
      "name": "Rock_Ice"
    },
    {
      "x": -13,
      "y": 10,
      "z": 6,
      "name": "Soil_Snow"
    },
    {
      "x": -12,
      "y": 20,
      "z": -10,
      "name": "Rock_Ice"
    },
    {
      "x": -12,
      "y": 21,
      "z": -10,
      "name": "Soil_Snow"
    },
    {
      "x": -12,
      "y": 18,
      "z": -9,
      "name": "Rock_Ice_Permafrost"
    },
    {
      "x": -12,
      "y": 19,
      "z": -9,
      "name": "Rock_Ice_Permafrost"
    },
    {
      "x": -12,
      "y": 20,
      "z": -9,
      "name": "Rock_Ice_Permafrost"
    },
    {
      "x": -12,
      "y": 21,
      "z": -9,
      "name": "Rock_Ice_Permafrost"
    },
    {
      "x": -12,
      "y": 22,
      "z": -9,
      "name": "Rock_Ice_Permafrost"
    },
    {
      "x": -12,
      "y": 23,
