{
  "version": 8,
  "blockIdVersion": 11,
  "anchorX": -1,
  "anchorY": 24,
  "anchorZ": -4,
  "blocks": [
    {
      "x": -51,
      "y": 37,
      "z": -23,
      "name": "Rock_Ice_Stalactite_Large",
      "filler": 31744,
      "rotation": 8
    },
    {
      "x": -51,
      "y": 38,
      "z": -23,
      "name": "Rock_Ice_Stalactite_Large",
      "rotation": 8
    },
    {
      "x": -51,
      "y": 39,
      "z": -23,
      "name": "Soil_Snow"
    },
    {
      "x": -50,
      "y": 39,
      "z": -24,
      "name": "Rock_Ice"
    },
    {
      "x": -50,
      "y": 40,
      "z": -24,
      "name": "Soil_Snow"
    },
    {
      "x": -50,
      "y": 39,
      "z": -23,
      "name": "Rock_Ice"
    },
    {
      "x": -50,
      "y": 40,
      "z": -23,
      "name": "Soil_Snow"
    },
    {
      "x": -50,
      "y": 0,
      "z": 18,
      "name": "Soil_Snow"
    },
    {
      "x": -50,
      "y": 0,
      "z": 19,
      "name": "Soil_Snow"
    },
    {
      "x": -49,
      "y": 38,
      "z": -25,
      "name": "Rock_Ice"
    },
    {
      "x": -49,
      "y": 39,
      "z": -25,
      "name": "Soil_Snow"
    },
    {
      "x": -49,
      "y": 38,
      "z": -24,
      "name": "Rock_Ice_Permafrost"
    },
    {
      "x": -49,
      "y": 39,
      "z": -24,
      "name": "Rock_Ice"
    },
    {
      "x": -49,
      "y": 40,
      "z": -24,
      "name": "Rock_Ice_Permafrost"
    },
    {
      "x": -49,
      "y": 38,
      "z": -23,
      "name": "Rock_Ice_Icicles",
      "rotation": 8
    },
    {
      "x": -49,
      "y": 39,
      "z": -23,
      "name": "Rock_Ice_Permafrost"
    },
    {
      "x": -49,
      "y": 40,
      "z": -23,
      "name": "Rock_Ice"
    },
    {
      "x": -49,
      "y": 41,
      "z": -23,
      "name": "Soil_Snow"
    },
    {
      "x": -49,
      "y": 39,
      "z": -22,
      "name": "Rock_Ice_Permafrost"
    },
    {
      "x": -49,
      "y": 40,
      "z": -22,
      "name": "Soil_Snow"
    },
    {
      "x": -49,
      "y": 0,
      "z": 9,
      "name": "Rock_Ice_Permafrost"
    },
    {
      "x": -49,
      "y": 1,
      "z": 9,
      "name": "Soil_Snow"
    },
    {
      "x": -49,
      "y": 0,
      "z": 10,
      "name": "Rock_Ice_Permafrost"
    },
    {
      "x": -49,
      "y": 1,
      "z": 10,
      "name": "Soil_Snow"
    },
    {
      "x": -49,
      "y": 0,
      "z": 11,
      "name": "Rock_Ice_Permafrost"
    },
    {
      "x": -49,
      "y": 1,
      "z": 11,
      "name": "Rock_Ice_Permafrost"
    },
    {
      "x": -49,
      "y": 2,
      "z": 11,
      "name": "Soil_Snow"
    },
    {
      "x": -49,
      "y": 0,
      "z": 12,
      "name": "Rock_Ice"
    },
    {
      "x": -49,
      "y": 1,
      "z": 12,
      "name": "Rock_Ice_Permafrost"
    },
    {
      "x": -49,
      "y": 2,
      "z": 12,
      "name": "Soil_Snow"
    },
    {
      "x": -49,
      "y": 0,
      "z": 13,
      "name": "Rock_Ice"
    },
    {
      "x": -49,
      "y": 1,
      "z": 13,
      "name": "Rock_Ice_Permafrost"
    },
    {
      "x": -49,
      "y": 2,
      "z": 13,
      "name": "Soil_Snow"
    },
    {
      "x": -49,
      "y": 0,
      "z": 14,
      "name": "Rock_Ice_Permafrost"
    },
    {
      "x": -49,
      "y": 1,
      "z": 14,
      "name": "Rock_Ice_Permafrost"
    },
    {
      "x": -49,
      "y": 2,
      "z": 14,
      "name": "Soil_Snow"
    },
    {
      "x": -49,
      "y": 0,
      "z": 15,
      "name": "Rock_Ice"
    },
    {
      "x": -49,
      "y": 1,
      "z": 15,
      "name": "Rock_Ice_Permafrost"
    },
    {
      "x": -49,
      "y": 2,
      "z": 15,
      "name": "Rock_Ice_Permafrost"
    },
    {
      "x": -49,
      "y": 3,
      "z": 15,
      "name": "Soil_Snow"
    },
    {
      "x": -49,
      "y": 0,
      "z": 16,
      "name": "Rock_Ice_Permafrost"
    },
    {
      "x": -49,
      "y": 1,
      "z": 16,
      "name": "Rock_Ice_Permafrost"
    },
    {
      "x": -49,
      "y": 2,
      "z": 16,
      "name": "Rock_Ice_Permafrost"
    },
    {
      "x": -49,
      "y": 3,
      "z": 16,
      "name": "Soil_Snow"
    },
    {
      "x": -49,
      "y": 0,
      "z": 17,
      "name": "Rock_Ice_Permafrost"
    },
    {
      "x": -49,
      "y": 1,
      "z": 17,
      "name": "Rock_Ice_Permafrost"
    },
    {
      "x": -49,
      "y": 2,
      "z": 17,
      "name": "Soil_Snow"
    },
    {
      "x": -49,
      "y": 0,
      "z": 18,
      "name": "Rock_Ice_Permafrost"
    },
    {
      "x": -49,
      "y": 1,
      "z": 18,
      "name": "Rock_Ice_Permafrost"
    },
    {
      "x": -49,
      "y": 2,
      "z": 18,
      "name": "Soil_Snow"
    },
    {
      "x": -49,
      "y": 0,
      "z": 19,
      "name": "Rock_Ice_Permafrost"
    },
    {
      "x": -49,
      "y": 1,
      "z": 19,
      "name": "Soil_Snow"
    },
    {
      "x": -49,
      "y": 0,
      "z": 20,
      "name": "Rock_Ice_Permafrost"
    },
    {
      "x": -49,
      "y": 1,
      "z": 20,
      "name": "Soil_Snow"
    },
    {
      "x": -49,
      "y": 0,
      "z": 21,
      "name": "Rock_Ice_Permafrost"
    },
    {
      "x": -49,
      "y": 1,
      "z": 21,
      "name": "Soil_Snow"
    },
    {
      "x": -49,
      "y": 0,
      "z": 22,
      "name": "Soil_Snow"
    },
    {
      "x": -48,
      "y": 37,
      "z": -26,
      "name": "Rock_Ice"
    },
    {
      "x": -48,
      "y": 38,
      "z": -26,
      "name": "Soil_Snow"
    },
    {
      "x": -48,
      "y": 37,
      "z": -25,
      "name": "Rock_Ice"
    },
    {
      "x": -48,
      "y": 38,
      "z": -25,
      "name": "Rock_Ice"
    },
    {
      "x": -48,
      "y": 39,
      "z": -25,
      "name": "Soil_Snow"
    },
    {
      "x": -48,
      "y": 38,
      "z": -24,
      "name": "Rock_Ice_Permafrost"
    },
    {
      "x": -48,
      "y": 39,
      "z": -24,
      "name": "Rock_Ice_Permafrost"
    },
    {
      "x": -48,
      "y": 40,
      "z": -24,
      "name": "Rock_Ice"
    },
    {
      "x": -48,
      "y": 41,
      "z": -24,
      "name": "Soil_Snow"
    },
    {
      "x": -48,
      "y": 38,
      "z": -23,
      "name": "Rock_Ice"
    },
    {
      "x": -48,
      "y": 39,
      "z": -23,
      "name": "Rock_Ice_Permafrost"
    },
    {
      "x": -48,
      "y": 40,
      "z": -23,
      "name": "Rock_Ice"
    },
    {
      "x": -48,
      "y": 41,
      "z": -23,
      "name": "Rock_Ice"
    },
    {
      "x": -48,
      "y": 42,
      "z": -23,
      "name": "Soil_Snow"
    },
    {
      "x": -48,
      "y": 39,
      "z": -22,
      "name": "Rock_Ice"
    },
    {
      "x": -48,
      "y": 40,
      "z": -22,
      "name": "Rock_Ice"
    },
    {
      "x": -48,
      "y": 41,
      "z": -22,
      "name": "Soil_Snow"
    },
    {
      "x": -48,
      "y": 2,
      "z": 6,
      "name": "Rock_Ice"
    },
    {
      "x": -48,
      "y": 3,
      "z": 6,
      "name": "Soil_Snow"
    },
    {
      "x": -48,
      "y": 0,
      "z": 7,
      "name": "Rock_Ice"
    },
    {
      "x": -48,
      "y": 1,
      "z": 7,
      "name": "Rock_Ice"
    },
    {
      "x": -48,
      "y": 2,
      "z": 7,
      "name": "Rock_Ice_Permafrost"
    },
    {
      "x": -48,
      "y": 3,
      "z": 7,
      "name": "Soil_Snow"
    },
    {
      "x": -48,
      "y": 0,
      "z": 8,
      "name": "Rock_Ice"
    },
    {
      "x": -48,
      "y": 1,
      "z": 8,
      "name": "Rock_Ice"
    },
    {
      "x": -48,
      "y": 2,
      "z": 8,
      "name": "Rock_Ice"
    },
    {
      "x": -48,
      "y": 3,
      "z": 8,
      "name": "Soil_Snow"
    },
    {
      "x": -48,
      "y": 0,
      "z": 9,
      "name": "Rock_Ice"
    },
    {
      "x": -48,
      "y": 1,
      "z": 9,
      "name": "Rock_Ice"
    },
    {
      "x": -48,
      "y": 2,
      "z": 9,
      "name": "Rock_Ice_Permafrost"
    },
    {
      "x": -48,
      "y": 3,
      "z": 9,
      "name": "Soil_Snow"
    },
    {
      "x": -48,
      "y": 0,
      "z": 10,
      "name": "Rock_Ice"
    },
    {
      "x": -48,
      "y": 1,
      "z": 10,
      "name": "Rock_Ice"
    },
    {
      "x": -48,
      "y": 2,
      "z": 10,
      "name": "Rock_Ice_Permafrost"
    },
    {
      "x": -48,
      "y": 3,
      "z": 10,
      "name": "Rock_Ice"
    },
    {
      "x": -48,
      "y": 4,
      "z": 10,
      "name": "Soil_Snow"
    },
    {
      "x": -48,
      "y": 0,
      "z": 11,
      "name": "Rock_Ice"
    },
    {
      "x": -48,
      "y": 1,
      "z": 11,
      "name": "Rock_Ice"
    },
    {
      "x": -48,
      "y": 2,
      "z": 11,
      "name": "Rock_Ice_Permafrost"
    },
    {
      "x": -48,
      "y": 3,
      "z": 11,
      "name": "Rock_Ice"
    },
    {
      "x": -48,
      "y": 4,
      "z": 11,
      "name": "Soil_Snow"
    },
    {
      "x": -48,
      "y": 0,
      "z": 12,
      "name": "Rock_Ice"
    },
    {
      "x": -48,
      "y": 1,
      "z": 12,
      "name": "Rock_Ice_Permafrost"
    },
    {
      "x": -48,
      "y": 2,
      "z": 12,
      "name": "Rock_Ice_Permafrost"
    },
    {
      "x": -48,
      "y": 3,
      "z": 12,
      "name": "Rock_Ice"
    },
    {
      "x": -48,
      "y": 4,
      "z": 12,
      "name": "Soil_Snow"
    },
    {
      "x": -48,
      "y": 0,
      "z": 13,
      "name": "Rock_Ice"
    },
    {
      "x": -48,
      "y": 1,
      "z": 13,
      "name": "Rock_Ice"
    },
    {
      "x": -48,
      "y": 2,
      "z": 13,
      "name": "Rock_Ice_Permafrost"
    },
    {
      "x": -48,
      "y": 3,
      "z": 13,
      "name": "Rock_Ice"
    },
    {
      "x": -48,
      "y": 4,
      "z": 13,
      "name": "Soil_Snow"
    },
    {
      "x": -48,
      "y": 0,
      "z": 14,
      "name": "Rock_Ice_Permafrost"
    },
    {
      "x": -48,
      "y": 1,
      "z": 14,
      "name": "Rock_Ice"
    },
    {
      "x": -48,
      "y": 2,
      "z": 14,
      "name": "Rock_Ice_Permafrost"
    },
    {
      "x": -48,
      "y": 3,
      "z": 14,
      "name": "Rock_Ice_Permafrost"
    },
    {
      "x": -48,
      "y": 4,
      "z": 14,
      "name": "Soil_Snow"
    },
    {
      "x": -48,
      "y": 0,
      "z": 15,
      "name": "Rock_Ice_Permafrost"
    },
    {
      "x": -48,
      "y": 1,
      "z": 15,
      "name": "Rock_Ice_Permafrost"
    },
    {
      "x": -48,
      "y": 2,
      "z": 15,
      "name": "Rock_Ice_Permafrost"
    },
    {
      "x": -48,
      "y": 3,
      "z": 15,
      "name": "Rock_Ice_Permafrost"
    },
    {
      "x": -48,
      "y": 4,
      "z": 15,
      "name": "Soil_Snow"
    },
    {
      "x": -48,
      "y": 0,
      "z": 16,
      "name": "Rock_Ice_Permafrost"
    },
    {
      "x": -48,
      "y": 1,
      "z": 16,
      "name": "Rock_Ice_Permafrost"
    },
    {
      "x": -48,
      "y": 2,
      "z": 16,
      "name": "Rock_Ice_Permafrost"
    },
    {
      "x": -48,
      "y": 3,
      "z": 16,
      "name": "Rock_Ice_Permafrost"
    },
    {
      "x": -48,
      "y": 4,
      "z": 16,
      "name": "Soil_Snow"
    },
    {
      "x": -48,
      "y": 0,
      "z": 17,
      "name": "Rock_Ice_Permafrost"
    },
    {
      "x": -48,
      "y": 1,
      "z": 17,
      "name": "Rock_Ice_Permafrost"
    },
    {
      "x": -48,
      "y": 2,
      "z": 17,
      "name": "Rock_Ice_Permafrost"
    },
    {
      "x": -48,
      "y": 3,
      "z": 17,
      "name": "Rock_Ice_Permafrost"
    },
    {
      "x": -48,
      "y": 4,
      "z": 17,
      "name": "Soil_Snow"
    },
    {
      "x": -48,
      "y": 0,
      "z": 18,
      "name": "Rock_Ice_Permafrost"
    },
    {
      "x": -48,
      "y": 1,
      "z": 18,
      "name": "Rock_Ice_Permafrost"
    },
    {
      "x": -48,
      "y": 2,
      "z": 18,
      "name": "Rock_Ice_Permafrost"
    },
    {
      "x": -48,
      "y": 3,
      "z": 18,
      "name": "Soil_Snow"
    },
    {
      "x": -48,
      "y": 0,
      "z": 19,
      "name": "Rock_Ice_Permafrost"
    },
    {
      "x": -48,
      "y": 1,
      "z": 19,
      "name": "Rock_Ice_Permafrost"
    },
    {
      "x": -48,
      "y": 2,
      "z": 19,
      "name": "Rock_Ice_Permafrost"
    },
    {
      "x": -48,
      "y": 3,
      "z": 19,
      "name": "Soil_Snow"
    },
    {
      "x": -48,
      "y": 0,
      "z": 20,
      "name": "Rock_Ice_Permafrost"
    },
    {
      "x": -48,
      "y": 1,
      "z": 20,
      "name": "Rock_Ice_Permafrost"
    },
    {
      "x": -48,
      "y": 2,
      "z": 20,
      "name": "Rock_Ice_Permafrost"
    },
    {
      "x": -48,
      "y": 3,
      "z": 20,
      "name": "Soil_Snow"
    },
    {
      "x": -48,
      "y": 0,
      "z": 21,
      "name": "Rock_Ice_Permafrost"
    },
    {
      "x": -48,
      "y": 1,
      "z": 21,
      "name": "Rock_Ice"
    },
    {
      "x": -48,
      "y": 2,
      "z": 21,
      "name": "Soil_Snow"
    },
    {
      "x": -48,
      "y": 0,
      "z": 22,
      "name": "Rock_Ice_Permafrost"
    },
    {
      "x": -48,
      "y": 1,
      "z": 22,
      "name": "Rock_Ice"
    },
    {
      "x": -48,
      "y": 2,
      "z": 22,
      "name": "Soil_Snow"
    },
    {
      "x": -48,
      "y": 0,
      "z": 23,
      "name": "Rock_Ice"
    },
    {
      "x": -48,
      "y": 1,
      "z": 23,
      "name": "Soil_Snow"
    },
    {
      "x": -48,
      "y": 0,
      "z": 24,
      "name": "Rock_Ice"
    },
    {
      "x": -48,
      "y": 1,
      "z": 24,
      "name": "Soil_Snow"
    },
    {
      "x": -47,
      "y": 33,
      "z": -26,
      "name": "Rock_Ice_Icicles",
      "rotation": 8
    },
    {
      "x": -47,
      "y": 34,
      "z": -26,
      "name": "Rock_Ice_Permafrost"
    },
    {
      "x": -47,
      "y": 35,
      "z": -26,
      "name": "Rock_Ice_Permafrost"
    },
    {
      "x": -47,
      "y": 36,
      "z": -26,
      "name": "Rock_Ice_Permafrost"
    },
    {
      "x": -47,
      "y": 37,
      "z": -26,
      "name": "Rock_Ice"
    },
    {
      "x": -47,
      "y": 38,
      "z": -26,
      "name": "Soil_Snow"
    },
    {
      "x": -47,
      "y": 36,
      "z": -25,
      "name": "Rock_Ice_Permafrost"
    },
    {
      "x": -47,
      "y": 37,
      "z": -25,
      "name": "Rock_Ice_Permafrost"
    },
    {
      "x": -47,
      "y": 38,
      "z": -25,
      "name": "Rock_Ice_Permafrost"
    },
    {
      "x": -47,
      "y": 39,
      "z": -25,
      "name": "Rock_Ice"
    },
    {
      "x": -47,
      "y": 40,
      "z": -25,
      "name": "Soil_Snow"
    },
    {
      "x": -47,
      "y": 38,
      "z": -24,
      "name": "Rock_Ice"
    },
    {
      "x": -47,
      "y": 39,
      "z": -24,
      "name": "Rock_Ice"
    },
    {
      "x": -47,
      "y": 40,
      "z": -24,
      "name": "Rock_Ice"
    },
    {
      "x": -47,
      "y": 41,
      "z": -24,
      "name": "Soil_Snow"
    },
    {
      "x": -47,
      "y": 38,
      "z": -23,
      "name": "Rock_Ice"
    },
    {
      "x": -47,
      "y": 39,
      "z": -23,
      "name": "Rock_Ice"
    },
    {
      "x": -47,
      "y": 40,
      "z": -23,
      "name": "Rock_Ice_Permafrost"
    },
    {
      "x": -47,
      "y": 41,
      "z": -23,
      "name": "Rock_Ice_Permafrost"
    },
    {
      "x": -47,
      "y": 42,
      "z": -23,
      "name": "Rock_Ice"
    },
    {
      "x": -47,
      "y": 43,
      "z": -23,
      "name": "Rock_Ice_Permafrost"
    },
    {
      "x": -47,
      "y": 39,
      "z": -22,
      "name": "Rock_Ice"
    },
    {
      "x": -47,
      "y": 40,
      "z": -22,
      "name": "Rock_Ice"
    },
    {
      "x": -47,
      "y": 41,
      "z": -22,
      "name": "Rock_Ice"
    },
    {
      "x": -47,
      "y": 42,
      "z": -22,
      "name": "Soil_Snow"
    },
    {
      "x": -47,
      "y": 0,
      "z": 4,
      "name": "Rock_Ice"
    },
    {
      "x": -47,
      "y": 3,
      "z": 4,
      "name": "Rock_Ice"
    },
    {
      "x": -47,
      "y": 4,
      "z": 4,
      "name": "Rock_Ice"
    },
    {
      "x": -47,
      "y": 0,
      "z": 5,
      "name": "Rock_Ice"
    },
    {
      "x": -47,
      "y": 1,
      "z": 5,
      "name": "Rock_Ice"
    },
    {
      "x": -47,
      "y": 2,
      "z": 5,
      "name": "Rock_Ice"
    },
    {
      "x": -47,
      "y": 3,
      "z": 5,
      "name": "Rock_Ice"
    },
    {
      "x": -47,
      "y": 4,
      "z": 5,
      "name": "Soil_Snow"
    },
    {
      "x": -47,
      "y": 0,
      "z": 6,
      "name": "Rock_Ice"
    },
    {
      "x": -47,
      "y": 1,
      "z": 6,
      "name": "Rock_Ice"
    },
    {
      "x": -47,
      "y": 2,
      "z": 6,
      "name": "Rock_Ice"
    },
    {
      "x": -47,
      "y": 3,
      "z": 6,
      "name": "Rock_Ice"
    },
    {
      "x": -47,
      "y": 4,
      "z": 6,
      "name": "Rock_Ice"
    },
    {
      "x": -47,
      "y": 5,
      "z": 6,
      "name": "Soil_Snow"
    },
    {
      "x": -47,
      "y": 0,
      "z": 7,
      "name": "Rock_Ice"
    },
    {
      "x": -47,
      "y": 1,
      "z": 7,
      "name": "Rock_Ice"
    },
    {
      "x": -47,
      "y": 2,
      "z": 7,
      "name": "Rock_Ice"
    },
    {
      "x": -47,
      "y": 3,
      "z": 7,
      "name": "Rock_Ice"
    },
    {
      "x": -47,
      "y": 4,
      "z": 7,
      "name": "Rock_Ice"
    },
    {
      "x": -47,
      "y": 5,
      "z": 7,
      "name": "Soil_Snow"
    },
    {
      "x": -47,
      "y": 0,
      "z": 8,
      "name": "Rock_Ice"
    },
    {
      "x": -47,
      "y": 1,
      "z": 8,
      "name": "Rock_Ice"
    },
    {
      "x": -47,
      "y": 2,
      "z": 8,
      "name": "Rock_Ice"
    },
    {
      "x": -47,
      "y": 3,
      "z": 8,
      "name": "Rock_Ice"
    },
    {
      "x": -47,
      "y": 4,
      "z": 8,
      "name": "Rock_Ice"
    },
    {
      "x": -47,
      "y": 5,
      "z": 8,
      "name": "Soil_Snow"
    },
    {
      "x": -47,
      "y": 0,
      "z": 9,
      "name": "Rock_Ice_Permafrost"
    },
    {
      "x": -47,
      "y": 1,
      "z": 9,
      "name": "Rock_Ice"
    },
    {
      "x": -47,
      "y": 2,
      "z": 9,
      "name": "Rock_Ice"
    },
    {
      "x": -47,
      "y": 3,
      "z": 9,
      "name": "Rock_Ice_Permafrost"
    },
    {
      "x": -47,
      "y": 4,
      "z": 9,
      "name": "Rock_Ice_Permafrost"
    },
    {
      "x": -47,
      "y": 5,
      "z": 9,
      "name": "Rock_Ice"
    },
    {
      "x": -47,
      "y": 0,
      "z": 10,
      "name": "Rock_Ice"
    },
    {
      "x": -47,
      "y": 1,
      "z": 10,
      "name": "Rock_Ice"
    },
    {
      "x": -47,
      "y": 2,
      "z": 10,
      "name": "Rock_Ice"
    },
    {
      "x": -47,
      "y": 3,
      "z": 10,
      "name": "Rock_Ice_Permafrost"
    },
    {
      "x": -47,
      "y": 4,
      "z": 10,
      "name": "Rock_Ice"
    },
    {
      "x": -47,
      "y": 5,
      "z": 10,
      "name": "Rock_Ice"
    },
    {
      "x": -47,
      "y": 6,
      "z": 10,
      "name": "Soil_Snow"
    },
    {
      "x": -47,
      "y": 0,
      "z": 11,
      "name": "Rock_Ice"
    },
    {
      "x": -47,
      "y": 1,
      "z": 11,
      "name": "Rock_Ice"
    },
    {
      "x": -47,
      "y": 2,
      "z": 11,
      "name": "Rock_Ice"
    },
    {
      "x": -47,
      "y": 3,
      "z": 11,
      "name": "Rock_Ice_Permafrost"
    },
    {
      "x": -47,
      "y": 4,
      "z": 11,
      "name": "Rock_Ice_Permafrost"
    },
    {
      "x": -47,
      "y": 5,
      "z": 11,
      "name": "Rock_Ice"
    },
    {
      "x": -47,
      "y": 6,
      "z": 11,
      "name": "Soil_Snow"
    },
    {
      "x": -47,
      "y": 0,
      "z": 12,
      "name": "Rock_Ice"
    },
    {
      "x": -47,
      "y": 1,
      "z": 12,
      "name": "Rock_Ice"
    },
    {
      "x": -47,
      "y": 2,
      "z": 12,
      "name": "Rock_Ice_Permafrost"
    },
    {
      "x": -47,
      "y": 3,
      "z": 12,
      "name": "Rock_Ice_Permafrost"
    },
    {
      "x": -47,
      "y": 4,
      "z": 12,
      "name": "Rock_Ice_Permafrost"
    },
    {
      "x": -47,
      "y": 5,
      "z": 12,
      "name": "Rock_Ice_Permafrost"
    },
    {
      "x": -47,
      "y": 6,
      "z": 12,
      "name": "Soil_Snow"
    },
    {
      "x": -47,
      "y": 0,
      "z": 13,
      "name": "Rock_Ice_Permafrost"
    },
    {
      "x": -47,
      "y": 1,
      "z": 13,
      "name": "Rock_Ice"
    },
    {
      "x": -47,
      "y": 2,
      "z": 13,
      "name": "Rock_Ice_Permafrost"
    },
    {
      "x": -47,
      "y": 3,
      "z": 13,
      "name": "Rock_Ice_Permafrost"
    },
    {
      "x": -47,
      "y": 4,
      "z": 13,
      "name": "Rock_Ice_Permafrost"
    },
    {
      "x": -47,
      "y": 5,
      "z": 13,
      "name": "Rock_Ice"
    },
    {
      "x": -47,
      "y": 6,
      "z": 13,
      "name": "Soil_Snow"
    },
    {
      "x": -47,
      "y": 0,
      "z": 14,
      "name": "Rock_Ice_Permafrost"
    },
    {
      "x": -47,
      "y": 1,
      "z": 14,
      "name": "Rock_Ice_Permafrost"
    },
    {
      "x": -47,
      "y": 2,
      "z": 14,
      "name": "Rock_Ice_Permafrost"
    },
    {
      "x": -47,
      "y": 3,
      "z": 14,
      "name": "Rock_Ice_Permafrost"
    },
    {
      "x": -47,
      "y": 4,
      "z": 14,
      "name": "Rock_Ice_Permafrost"
    },
    {
      "x": -47,
      "y": 5,
      "z": 14,
      "name": "Soil_Snow"
    },
    {
      "x": -47,
      "y": 0,
      "z": 15,
      "name": "Rock_Ice_Permafrost"
    },
    {
      "x": -47,
      "y": 1,
      "z": 15,
      "name": "Rock_Ice"
    },
    {
      "x": -47,
      "y": 2,
      "z": 15,
      "name": "Rock_Ice_Permafrost"
    },
    {
      "x": -47,
      "y": 3,
      "z": 15,
      "name": "Rock_Ice_Permafrost"
    },
    {
      "x": -47,
      "y": 4,
      "z": 15,
      "name": "Rock_Ice_Permafrost"
    },
    {
      "x": -47,
      "y": 5,
      "z": 15,
      "name": "Soil_Snow"
    },
    {
      "x": -47,
      "y": 0,
      "z": 16,
      "name": "Rock_Ice_Permafrost"
    },
    {
      "x": -47,
      "y": 1,
      "z": 16,
      "name": "Rock_Ice_Permafrost"
    },
    {
      "x": -47,
      "y": 2,
      "z": 16,
      "name": "Rock_Ice_Permafrost"
    },
    {
      "x": -47,
      "y": 3,
      "z": 16,
      "name": "Rock_Ice_Permafrost"
    },
    {
      "x": -47,
      "y": 4,
      "z": 16,
      "name": "Rock_Ice_Permafrost"
    },
    {
      "x": -47,
      "y": 5,
      "z": 16,
      "name": "Soil_Snow"
    },
    {
      "x": -47,
      "y": 0,
      "z": 17,
      "name": "Rock_Ice_Permafrost"
    },
    {
      "x": -47,
      "y": 1,
      "z": 17,
      "name": "Rock_Ice_Permafrost"
    },
    {
      "x": -47,
      "y": 2,
      "z": 17,
      "name": "Rock_Ice_Permafrost"
    },
    {
      "x": -47,
      "y": 3,
      "z": 17,
      "name": "Rock_Ice_Permafrost"
    },
    {
      "x": -47,
      "y": 4,
      "z": 17,
      "name": "Rock_Ice"
    },
    {
      "x": -47,
      "y": 5,
      "z": 17,
      "name": "Soil_Snow"
    },
    {
      "x": -47,
      "y": 0,
      "z": 18,
      "name": "Rock_Ice_Permafrost"
    },
    {
      "x": -47,
      "y": 1,
      "z": 18,
      "name": "Rock_Ice_Permafrost"
    },
    {
      "x": -47,
      "y": 2,
      "z": 18,
      "name": "Rock_Ice_Permafrost"
    },
    {
      "x": -47,
      "y": 3,
      "z": 18,
      "name": "Rock_Ice_Permafrost"
    },
    {
      "x": -47,
      "y": 4,
      "z": 18,
      "name": "Rock_Ice_Permafrost"
    },
    {
      "x": -47,
      "y": 5,
      "z": 18,
      "name": "Soil_Snow"
    },
    {
      "x": -47,
      "y": 0,
      "z": 19,
      "name": "Rock_Ice_Permafrost"
    },
    {
      "x": -47,
      "y": 1,
      "z": 19,
      "name": "Rock_Ice_Permafrost"
    },
    {
      "x": -47,
      "y": 2,
      "z": 19,
      "name": "Rock_Ice_Permafrost"
    },
    {
      "x": -47,
      "y": 3,
      "z": 19,
      "name": "Rock_Ice_Permafrost"
    },
    {
      "x": -47,
      "y": 4,
      "z": 19,
      "name": "Soil_Snow"
    },
    {
      "x": -47,
      "y": 0,
      "z": 20,
      "name": "Rock_Ice_Permafrost"
    },
    {
      "x": -47,
      "y": 1,
      "z": 20,
      "name": "Rock_Ice_Permafrost"
    },
    {
      "x": -47,
      "y": 2,
      "z": 20,
      "name": "Rock_Ice_Permafrost"
    },
    {
      "x": -47,
      "y": 3,
      "z": 20,
      "name": "Rock_Ice"
    },
    {
      "x": -47,
      "y": 4,
      "z": 20,
      "name": "Soil_Snow"
    },
    {
      "x": -47,
      "y": 0,
      "z": 21,
      "name": "Rock_Ice_Permafrost"
    },
    {
      "x": -47,
      "y": 1,
      "z": 21,
      "name": "Rock_Ice_Permafrost"
    },
    {
      "x": -47,
      "y": 2,
      "z": 21,
      "name": "Rock_Ice_Permafrost"
    },
    {
      "x": -47,
      "y": 3,
      "z": 21,
      "name": "Rock_Ice"
    },
    {
      "x": -47,
      "y": 4,
      "z": 21,
      "name": "Soil_Snow"
    },
    {
      "x": -47,
      "y": 0,
      "z": 22,
      "name": "Rock_Ice_Permafrost"
    },
    {
      "x": -47,
      "y": 1,
      "z": 22,
      "name": "Rock_Ice_Permafrost"
    },
    {
      "x": -47,
      "y": 2,
      "z": 22,
      "name": "Rock_Ice"
    },
    {
      "x": -47,
      "y": 3,
      "z": 22,
      "name": "Soil_Snow"
    },
    {
      "x": -47,
      "y": 0,
      "z": 23,
      "name": "Rock_Ice_Permafrost"
    },
    {
      "x": -47,
      "y": 1,
      "z": 23,
      "name": "Rock_Ice_Permafrost"
    },
    {
      "x": -47,
      "y": 2,
      "z": 23,
      "name": "Rock_Ice"
    },
    {
      "x": -47,
      "y": 3,
      "z": 23,
      "name": "Soil_Snow"
    },
    {
      "x": -47,
      "y": 0,
      "z": 24,
      "name": "Rock_Ice_Permafrost"
    },
    {
      "x": -47,
      "y": 1,
      "z": 24,
      "name": "Rock_Ice_Permafrost"
    },
    {
      "x": -47,
      "y": 2,
      "z": 24,
      "name": "Rock_Ice"
    },
    {
      "x": -47,
      "y": 3,
      "z": 24,
      "name": "Soil_Snow"
    },
    {
      "x": -47,
      "y": 0,
      "z": 25,
      "name": "Rock_Ice_Permafrost"
    },
    {
      "x": -47,
      "y": 1,
      "z": 25,
      "name": "Rock_Ice"
    },
    {
      "x": -47,
      "y": 2,
      "z": 25,
      "name": "Soil_Snow"
    },
    {
      "x": -47,
      "y": 0,
      "z": 26,
      "name": "Soil_Snow"
    },
    {
      "x": -46,
      "y": 35,
      "z": -28,
      "name": "Soil_Snow"
    },
    {
      "x": -46,
      "y": 33,
      "z": -27,
      "name": "Rock_Ice_Icicles",
      "rotation": 8
    },
    {
      "x": -46,
      "y": 34,
      "z": -27,
      "name": "Rock_Ice_Permafrost"
    },
    {
      "x": -46,
      "y": 35,
      "z": -27,
      "name": "Rock_Ice_Permafrost"
    },
    {
      "x": -46,
      "y": 36,
      "z": -27,
      "name": "Rock_Ice"
    },
    {
      "x": -46,
      "y": 37,
      "z": -27,
      "name": "Soil_Snow"
    },
    {
      "x": -46,
      "y": 30,
      "z": -26,
      "name": "Rock_Ice_Stalactite_Large",
      "filler": 31744,
      "rotation": 8
    },
    {
      "x": -46,
      "y": 31,
      "z": -26,
      "name": "Rock_Ice_Stalactite_Large",
      "rotation": 8
    },
    {
      "x": -46,
      "y": 32,
      "z": -26,
      "name": "Rock_Ice_Permafrost"
    },
    {
      "x": -46,
      "y": 33,
      "z": -26,
      "name": "Rock_Ice_Permafrost"
    },
    {
      "x": -46,
      "y": 34,
      "z": -26,
      "name": "Rock_Ice_Permafrost"
    },
    {
      "x": -46,
      "y": 35,
      "z": -26,
      "name": "Rock_Ice_Permafrost"
    },
    {
      "x": -46,
      "y": 36,
      "z": -26,
      "name": "Rock_Ice"
    },
    {
      "x": -46,
      "y": 37,
      "z": -26,
      "name": "Rock_Ice"
    },
    {
      "x": -46,
      "y": 38,
      "z": -26,
      "name": "Rock_Ice"
    },
    {
      "x": -46,
      "y": 39,
      "z": -26,
      "name": "Soil_Snow"
    },
    {
      "x": -46,
      "y": 32,
      "z": -25,
      "name": "Rock_Ice_Stalactite_Large",
      "filler": 31744,
      "rotation": 8
    },
    {
      "x": -46,
      "y": 33,
      "z": -25,
      "name": "Rock_Ice_Stalactite_Large",
      "rotation": 8
    },
    {
      "x": -46,
      "y": 34,
      "z": -25,
      "name": "Rock_Ice_Permafrost"
    },
    {
      "x": -46,
      "y": 35,
      "z": -25,
      "name": "Rock_Ice_Permafrost"
    },
    {
      "x": -46,
      "y": 36,
      "z": -25,
      "name": "Rock_Ice_Permafrost"
    },
    {
      "x": -46,
      "y": 37,
      "z": -25,
      "name": "Rock_Ice_Permafrost"
    },
    {
      "x": -46,
      "y": 38,
      "z": -25,
      "name": "Rock_Ice_Permafrost"
    },
    {
      "x": -46,
      "y": 39,
      "z": -25,
      "name": "Rock_Ice"
    },
    {
      "x": -46,
      "y": 40,
      "z": -25,
      "name": "Soil_Snow"
    },
    {
      "x": -46,
      "y": 37,
      "z": -24,
      "name": "Rock_Ice"
    },
    {
      "x": -46,
      "y": 38,
      "z": -24,
      "name": "Rock_Ice"
    },
    {
      "x": -46,
      "y": 39,
      "z": -24,
      "name": "Rock_Ice"
    },
    {
      "x": -46,
      "y": 40,
      "z": -24,
      "name": "Rock_Ice_Permafrost"
    },
    {
      "x": -46,
      "y": 41,
      "z": -24,
      "name": "Rock_Ice"
    },
    {
      "x": -46,
      "y": 42,
      "z": -24,
      "name": "Soil_Snow"
    },
    {
      "x": -46,
      "y": 38,
      "z": -23,
      "name": "Rock_Ice"
    },
    {
      "x": -46,
      "y": 39,
      "z": -23,
      "name": "Rock_Ice_Permafrost"
    },
    {
      "x": -46,
      "y": 40,
      "z": -23,
      "name": "Rock_Ice"
    },
    {
      "x": -46,
      "y": 41,
      "z": -23,
      "name": "Rock_Ice_Permafrost"
    },
    {
      "x": -46,
      "y": 42,
      "z": -23,
      "name": "Rock_Ice_Permafrost"
    },
    {
      "x": -46,
      "y": 43,
      "z": -23,
      "name": "Rock_Ice"
    },
    {
      "x": -46,
      "y": 44,
      "z": -23,
      "name": "Rock_Ice_Permafrost"
    },
    {
      "x": -46,
      "y": 39,
      "z": -22,
      "name": "Rock_Ice"
    },
    {
      "x": -46,
      "y": 40,
      "z": -22,
      "name": "Rock_Ice"
    },
    {
      "x": -46,
      "y": 41,
      "z": -22,
      "name": "Rock_Ice"
    },
    {
      "x": -46,
      "y": 42,
      "z": -22,
      "name": "Rock_Ice"
    },
    {
      "x": -46,
      "y": 43,
      "z": -22,
      "name": "Soil_Snow"
    },
    {
      "x": -46,
      "y": 0,
      "z": -1,
      "name": "Soil_Snow"
    },
    {
      "x": -46,
      "y": 0,
      "z": 0,
      "name": "Rock_Ice"
    },
    {
      "x": -46,
      "y": 1,
      "z": 0,
      "name": "Soil_Snow"
    },
    {
      "x": -46,
      "y": 0,
      "z": 1,
      "name": "Rock_Ice_Permafrost"
    },
    {
      "x": -46,
      "y": 1,
      "z": 1,
      "name": "Soil_Snow"
    },
    {
      "x": -46,
      "y": 0,
      "z": 2,
      "name": "Rock_Ice"
    },
    {
      "x": -46,
      "y": 1,
      "z": 2,
      "name": "Rock_Ice"
    },
    {
      "x": -46,
      "y": 2,
      "z": 2,
      "name": "Rock_Ice"
    },
    {
      "x": -46,
      "y": 0,
      "z": 3,
      "name": "Rock_Ice"
    },
    {
      "x": -46,
      "y": 1,
      "z": 3,
      "name": "Rock_Ice"
    },
    {
      "x": -46,
      "y": 2,
      "z": 3,
      "name": "Rock_Ice"
    },
    {
      "x": -46,
      "y": 3,
      "z": 3,
      "name": "Rock_Ice"
    },
    {
      "x": -46,
      "y": 4,
      "z": 3,
      "name": "Rock_Ice"
    },
    {
      "x": -46,
      "y": 5,
      "z": 3,
      "name": "Rock_Ice"
    },
    {
      "x": -46,
      "y": 0,
      "z": 4,
      "name": "Rock_Ice"
    },
    {
      "x": -46,
      "y": 1,
      "z": 4,
      "name": "Rock_Ice"
    },
    {
      "x": -46,
      "y": 2,
      "z": 4,
      "name": "Rock_Ice"
    },
    {
      "x": -46,
      "y": 3,
      "z": 4,
      "name": "Rock_Ice"
    },
    {
      "x": -46,
      "y": 4,
      "z": 4,
      "name": "Rock_Ice"
    },
    {
      "x": -46,
      "y": 5,
      "z": 4,
      "name": "Rock_Ice"
    },
    {
      "x": -46,
      "y": 6,
      "z": 4,
      "name": "Soil_Snow"
    },
    {
      "x": -46,
      "y": 0,
      "z": 5,
      "name": "Rock_Ice"
    },
    {
      "x": -46,
      "y": 1,
      "z": 5,
      "name": "Rock_Ice"
    },
    {
      "x": -46,
      "y": 2,
      "z": 5,
      "name": "Rock_Ice"
    },
    {
      "x": -46,
      "y": 3,
      "z": 5,
      "name": "Rock_Ice"
    },
    {
      "x": -46,
      "y": 4,
      "z": 5,
      "name": "Rock_Ice"
    },
    {
      "x": -46,
      "y": 5,
      "z": 5,
      "name": "Rock_Ice"
    },
    {
      "x": -46,
      "y": 6,
      "z": 5,
      "name": "Soil_Snow"
    },
    {
      "x": -46,
      "y": 0,
      "z": 6,
      "name": "Rock_Ice"
    },
    {
      "x": -46,
      "y": 1,
      "z": 6,
      "name": "Rock_Ice"
    },
    {
      "x": -46,
      "y": 2,
      "z": 6,
      "name": "Rock_Ice"
    },
    {
      "x": -46,
      "y": 3,
      "z": 6,
      "name": "Rock_Ice"
    },
    {
      "x": -46,
      "y": 4,
      "z": 6,
      "name": "Rock_Ice"
    },
    {
      "x": -46,
      "y": 5,
      "z": 6,
      "name": "Rock_Ice"
    },
    {
      "x": -46,
      "y": 6,
      "z": 6,
      "name": "Soil_Snow"
    },
    {
      "x": -46,
      "y": 0,
      "z": 7,
      "name": "Rock_Ice_Permafrost"
    },
    {
      "x": -46,
      "y": 1,
      "z": 7,
      "name": "Rock_Ice"
    },
    {
      "x": -46,
      "y": 2,
      "z": 7,
      "name": "Rock_Ice"
    },
    {
      "x": -46,
      "y": 3,
      "z": 7,
      "name": "Rock_Ice"
    },
    {
      "x": -46,
      "y": 4,
      "z": 7,
      "name": "Rock_Ice"
    },
    {
      "x": -46,
      "y": 5,
      "z": 7,
      "name": "Rock_Ice"
    },
    {
      "x": -46,
      "y": 6,
      "z": 7,
      "name": "Soil_Snow"
    },
    {
      "x": -46,
      "y": 0,
      "z": 8,
      "name": "Rock_Ice"
    },
    {
      "x": -46,
      "y": 1,
      "z": 8,
      "name": "Rock_Ice"
    },
    {
      "x": -46,
      "y": 2,
      "z": 8,
      "name": "Rock_Ice"
    },
    {
      "x": -46,
      "y": 3,
      "z": 8,
      "name": "Rock_Ice"
    },
    {
      "x": -46,
      "y": 4,
      "z": 8,
      "name": "Rock_Ice"
    },
    {
      "x": -46,
      "y": 5,
      "z": 8,
      "name": "Rock_Ice"
    },
    {
      "x": -46,
      "y": 6,
      "z": 8,
      "name": "Rock_Ice"
    },
    {
      "x": -46,
      "y": 0,
      "z": 9,
      "name": "Rock_Ice"
    },
    {
      "x": -46,
      "y": 1,
      "z": 9,
      "name": "Rock_Ice"
    },
    {
      "x": -46,
      "y": 2,
      "z": 9,
      "name": "Rock_Ice"
    },
    {
      "x": -46,
      "y": 3,
      "z": 9,
      "name": "Rock_Ice"
    },
    {
      "x": -46,
      "y": 4,
      "z": 9,
      "name": "Rock_Ice"
    },
    {
      "x": -46,
      "y": 5,
      "z": 9,
      "name": "Rock_Ice"
    },
    {
      "x": -46,
      "y": 6,
      "z": 9,
      "name": "Rock_Ice"
    },
    {
      "x": -46,
      "y": 7,
      "z": 9,
      "name": "Soil_Snow"
    },
    {
      "x": -46,
      "y": 0,
      "z": 10,
      "name": "Rock_Ice_Permafrost"
    },
    {
      "x": -46,
      "y": 1,
      "z": 10,
      "name": "Rock_Ice"
    },
    {
      "x": -46,
      "y": 2,
      "z": 10,
      "name": "Rock_Ice"
    },
    {
      "x": -46,
      "y": 3,
      "z": 10,
      "name": "Rock_Ice"
    },
    {
      "x": -46,
      "y": 4,
      "z": 10,
      "name": "Rock_Ice_Permafrost"
    },
    {
      "x": -46,
      "y": 5,
      "z": 10,
      "name": "Rock_Ice"
    },
    {
      "x": -46,
      "y": 6,
      "z": 10,
      "name": "Rock_Ice"
    },
    {
      "x": -46,
      "y": 7,
      "z": 10,
      "name": "Soil_Snow"
    },
    {
      "x": -46,
      "y": 0,
      "z": 11,
      "name": "Rock_Ice_Permafrost"
    },
    {
      "x": -46,
      "y": 1,
      "z": 11,
      "name": "Rock_Ice"
    },
    {
      "x": -46,
      "y": 2,
      "z": 11,
      "name": "Rock_Ice"
    },
    {
      "x": -46,
      "y": 3,
      "z": 11,
      "name": "Rock_Ice_Permafrost"
    },
    {
      "x": -46,
      "y": 4,
      "z": 11,
      "name": "Rock_Ice_Permafrost"
    },
    {
      "x": -46,
      "y": 5,
      "z": 11,
      "name": "Rock_Ice_Permafrost"
    },
    {
      "x": -46,
      "y": 6,
      "z": 11,
      "name": "Rock_Ice_Permafrost"
    },
    {
      "x": -46,
      "y": 7,
      "z": 11,
      "name": "Soil_Snow"
    },
    {
      "x": -46,
      "y": 0,
      "z": 12,
      "name": "Rock_Ice_Permafrost"
    },
    {
      "x": -46,
      "y": 1,
      "z": 12,
      "name": "Rock_Ice"
    },
    {
      "x": -46,
      "y": 2,
      "z": 12,
      "name": "Rock_Ice"
    },
    {
      "x": -46,
      "y": 3,
      "z": 12,
      "name": "Rock_Ice"
    },
    {
      "x": -46,
      "y": 4,
      "z": 12,
      "name": "Rock_Ice_Permafrost"
    },
    {
      "x": -46,
      "y": 5,
      "z": 12,
      "name": "Rock_Ice_Permafrost"
    },
    {
      "x": -46,
      "y": 6,
      "z": 12,
      "name": "Rock_Ice_Permafrost"
    },
    {
      "x": -46,
      "y": 7,
      "z": 12,
      "name": "Soil_Snow"
    },
    {
      "x": -46,
      "y": 0,
      "z": 13,
      "name": "Rock_Ice"
    },
    {
      "x": -46,
      "y": 1,
      "z": 13,
      "name": "Rock_Ice_Permafrost"
    },
    {
      "x": -46,
      "y": 2,
      "z": 13,
      "name": "Rock_Ice"
    },
    {
      "x": -46,
      "y": 3,
      "z": 13,
      "name": "Rock_Ice_Permafrost"
    },
    {
      "x": -46,
      "y": 4,
      "z": 13,
      "name": "Rock_Ice_Permafrost"
    },
    {
      "x": -46,
      "y": 5,
      "z": 13,
      "name": "Rock_Ice_Permafrost"
    },
    {
      "x": -46,
      "y": 6,
      "z": 13,
      "name": "Rock_Ice_Permafrost"
    },
    {
      "x": -46,
      "y": 7,
      "z": 13,
      "name": "Soil_Snow"
    },
    {
      "x": -46,
      "y": 0,
      "z": 14,
      "name": "Rock_Ice_Permafrost"
    },
    {
      "x": -46,
      "y": 1,
      "z": 14,
      "name": "Rock_Ice_Permafrost"
    },
    {
      "x": -46,
      "y": 2,
      "z": 14,
      "name": "Rock_Ice"
    },
    {
      "x": -46,
      "y": 3,
      "z": 14,
      "name": "Rock_Ice_Permafrost"
    },
    {
      "x": -46,
      "y": 4,
      "z": 14,
      "name": "Rock_Ice_Permafrost"
    },
    {
      "x": -46,
      "y": 5,
      "z": 14,
      "name": "Rock_Ice_Permafrost"
    },
    {
      "x": -46,
      "y": 6,
      "z": 14,
      "name": "Rock_Ice_Permafrost"
    },
    {
      "x": -46,
      "y": 7,
      "z": 14,
      "name": "Soil_Snow"
    },
    {
      "x": -46,
      "y": 0,
      "z": 15,
      "name": "Rock_Ice_Permafrost"
    },
    {
      "x": -46,
      "y": 1,
      "z": 15,
      "name": "Rock_Ice_Permafrost"
    },
    {
      "x": -46,
      "y": 2,
      "z": 15,
      "name": "Rock_Ice"
    },
    {
      "x": -46,
      "y": 3,
      "z": 15,
      "name": "Rock_Ice_Permafrost"
    },
    {
      "x": -46,
      "y": 4,
      "z": 15,
      "name": "Rock_Ice_Permafrost"
    },
    {
      "x": -46,
      "y": 5,
      "z": 15,
      "name": "Rock_Ice_Permafrost"
    },
    {
      "x": -46,
      "y": 6,
      "z": 15,
      "name": "Rock_Ice"
    },
    {
      "x": -46,
      "y": 7,
      "z": 15,
      "name": "Soil_Snow"
    },
    {
      "x": -46,
      "y": 0,
      "z": 16,
      "name": "Rock_Ice_Permafrost"
    },
    {
      "x": -46,
      "y": 1,
      "z": 16,
      "name": "Rock_Ice_Permafrost"
    },
    {
      "x": -46,
      "y": 2,
      "z": 16,
      "name": "Rock_Ice"
    },
    {
      "x": -46,
      "y": 3,
      "z": 16,
      "name": "Rock_Ice_Permafrost"
    },
    {
      "x": -46,
      "y": 4,
      "z": 16,
      "name": "Rock_Ice_Permafrost"
    },
    {
      "x": -46,
      "y": 5,
      "z": 16,
      "name": "Rock_Ice_Permafrost"
    },
    {
      "x": -46,
      "y": 6,
      "z": 16,
      "name": "Soil_Snow"
    },
    {
      "x": -46,
      "y": 0,
      "z": 17,
      "name": "Rock_Ice_Permafrost"
    },
    {
      "x": -46,
      "y": 1,
      "z": 17,
      "name": "Rock_Ice_Permafrost"
    },
    {
      "x": -46,
      "y": 2,
      "z": 17,
      "name": "Rock_Ice_Permafrost"
    },
    {
      "x": -46,
      "y": 3,
      "z": 17,
      "name": "Rock_Ice_Permafrost"
    },
    {
      "x": -46,
      "y": 4,
      "z": 17,
      "name": "Rock_Ice_Permafrost"
    },
    {
      "x": -46,
      "y": 5,
      "z": 17,
      "name": "Rock_Ice_Permafrost"
    },
    {
      "x": -46,
      "y": 6,
      "z": 17,
      "name": "Soil_Snow"
    },
    {
      "x": -46,
      "y": 0,
      "z": 18,
      "name": "Rock_Ice_Permafrost"
    },
    {
      "x": -46,
      "y": 1,
      "z": 18,
      "name": "Rock_Ice_Permafrost"
    },
    {
      "x": -46,
      "y": 2,
      "z": 18,
      "name": "Rock_Ice_Permafrost"
    },
    {
      "x": -46,
      "y": 3,
      "z": 18,
      "name": "Rock_Ice_Permafrost"
    },
    {
      "x": -46,
      "y": 4,
      "z": 18,
      "name": "Rock_Ice_Permafrost"
    },
    {
      "x": -46,
      "y": 5,
      "z": 18,
      "name": "Rock_Ice_Permafrost"
    },
    {
      "x": -46,
      "y": 6,
      "z": 18,
      "name": "Soil_Snow"
    },
    {
      "x": -46,
      "y": 0,
      "z": 19,
      "name": "Rock_Ice"
    },
    {
      "x": -46,
      "y": 1,
      "z": 19,
      "name": "Rock_Ice_Permafrost"
    },
    {
      "x": -46,
      "y": 2,
      "z": 19,
      "name": "Rock_Ice_Permafrost"
    },
    {
      "x": -46,
      "y": 3,
      "z": 19,
      "name": "Rock_Ice_Permafrost"
    },
    {
      "x": -46,
      "y": 4,
      "z": 19,
      "name": "Rock_Ice_Permafrost"
    },
    {
      "x": -46,
      "y": 5,
      "z": 19,
      "name": "Rock_Ice_Permafrost"
    },
    {
      "x": -46,
      "y": 6,
      "z": 19,
      "name": "Soil_Snow"
    },
    {
      "x": -46,
      "y": 0,
      "z": 20,
      "name": "Rock_Ice_Permafrost"
    },
    {
      "x": -46,
      "y": 1,
      "z": 20,
      "name": "Rock_Ice_Permafrost"
    },
    {
      "x": -46,
      "y": 2,
      "z": 20,
      "name": "Rock_Ice_Permafrost"
    },
    {
      "x": -46,
      "y": 3,
      "z": 20,
      "name": "Rock_Ice_Permafrost"
    },
    {
      "x": -46,
      "y": 4,
      "z": 20,
      "name": "Rock_Ice"
    },
    {
      "x": -46,
      "y": 5,
      "z": 20,
      "name": "Rock_Ice"
    },
    {
      "x": -46,
      "y": 6,
      "z": 20,
      "name": "Rock_Ice"
    },
    {
      "x": -46,
      "y": 0,
      "z": 21,
      "name": "Rock_Ice_Permafrost"
    },
    {
      "x": -46,
      "y": 1,
      "z": 21,
      "name": "Rock_Ice_Permafrost"
    },
    {
      "x": -46,
      "y": 2,
      "z": 21,
      "name": "Rock_Ice_Permafrost"
    },
    {
      "x": -46,
      "y": 3,
      "z": 21,
      "name": "Rock_Ice_Permafrost"
    },
    {
      "x": -46,
      "y": 4,
      "z": 21,
      "name": "Rock_Ice"
    },
    {
      "x": -46,
      "y": 5,
      "z": 21,
      "name": "Soil_Snow"
    },
    {
      "x": -46,
      "y": 0,
      "z": 22,
      "name": "Rock_Ice_Permafrost"
    },
    {
      "x": -46,
      "y": 1,
      "z": 22,
      "name": "Rock_Ice_Permafrost"
    },
    {
      "x": -46,
      "y": 2,
      "z": 22,
      "name": "Rock_Ice_Permafrost"
    },
    {
      "x": -46,
      "y": 3,
      "z": 22,
      "name": "Rock_Ice_Permafrost"
    },
    {
      "x": -46,
      "y": 4,
      "z": 22,
      "name": "Rock_Ice"
    },
    {
      "x": -46,
      "y": 5,
      "z": 22,
      "name": "Rock_Ice"
    },
    {
      "x": -46,
      "y": 0,
      "z": 23,
      "name": "Rock_Ice_Permafrost"
    },
    {
      "x": -46,
      "y": 1,
      "z": 23,
      "name": "Rock_Ice_Permafrost"
    },
    {
      "x": -46,
      "y": 2,
      "z": 23,
      "name": "Rock_Ice_Permafrost"
    },
    {
      "x": -46,
      "y": 3,
      "z": 23,
      "name": "Rock_Ice_Permafrost"
    },
    {
      "x": -46,
      "y": 4,
      "z": 23,
      "name": "Rock_Ice"
    },
    {
      "x": -46,
      "y": 5,
      "z": 23,
      "name": "Rock_Ice"
    },
    {
      "x": -46,
      "y": 0,
      "z": 24,
      "name": "Rock_Ice_Permafrost"
    },
    {
      "x": -46,
      "y": 1,
      "z": 24,
      "name": "Rock_Ice_Permafrost"
    },
    {
      "x": -46,
      "y": 2,
      "z": 24,
      "name": "Rock_Ice_Permafrost"
    },
    {
      "x": -46,
      "y": 3,
      "z": 24,
      "name": "Rock_Ice"
    },
    {
      "x": -46,
      "y": 4,
      "z": 24,
      "name": "Soil_Snow"
    },
    {
      "x": -46,
      "y": 0,
      "z": 25,
      "name": "Rock_Ice_Permafrost"
    },
    {
      "x": -46,
      "y": 1,
      "z": 25,
      "name": "Rock_Ice_Permafrost"
    },
    {
      "x": -46,
      "y": 2,
      "z": 25,
      "name": "Rock_Ice_Permafrost"
    },
    {
      "x": -46,
      "y": 3,
      "z": 25,
      "name": "Rock_Ice"
    },
    {
      "x": -46,
      "y": 4,
      "z": 25,
      "name": "Soil_Snow"
    },
    {
      "x": -46,
      "y": 0,
      "z": 26,
      "name": "Rock_Ice_Permafrost"
    },
    {
      "x": -46,
      "y": 1,
      "z": 26,
      "name": "Rock_Ice"
    },
    {
      "x": -46,
      "y": 2,
      "z": 26,
      "name": "Soil_Snow"
    },
    {
      "x": -46,
      "y": 0,
      "z": 27,
      "name": "Soil_Snow"
    },
    {
      "x": -45,
      "y": 34,
      "z": -29,
      "name": "Soil_Snow"
    },
    {
      "x": -45,
      "y": 35,
      "z": -28,
      "name": "Rock_Ice"
    },
    {
      "x": -45,
      "y": 36,
      "z": -28,
      "name": "Soil_Snow"
    },
    {
      "x": -45,
      "y": 35,
      "z": -27,
      "name": "Rock_Ice"
    },
    {
      "x": -45,
      "y": 36,
      "z": -27,
      "name": "Rock_Ice_Permafrost"
    },
    {
      "x": -45,
      "y": 37,
      "z": -27,
      "name": "Rock_Ice"
    },
    {
      "x": -45,
      "y": 38,
      "z": -27,
      "name": "Soil_Snow"
    },
    {
      "x": -45,
      "y": 34,
      "z": -26,
      "name": "Rock_Ice_Stalactite_Large",
      "filler": 31744,
      "rotation": 8
    },
    {
      "x": -45,
      "y": 35,
      "z": -26,
      "name": "Rock_Ice_Stalactite_Large",
      "rotation": 8
    },
    {
      "x": -45,
      "y": 36,
      "z": -26,
      "name": "Rock_Ice"
    },
    {
      "x": -45,
      "y": 37,
      "z": -26,
      "name": "Rock_Ice_Permafrost"
    },
    {
      "x": -45,
      "y": 38,
      "z": -26,
      "name": "Rock_Ice"
    },
    {
      "x": -45,
      "y": 39,
      "z": -26,
      "name": "Soil_Snow"
    },
    {
      "x": -45,
      "y": 37,
      "z": -25,
      "name": "Rock_Ice"
    },
    {
      "x": -45,
      "y": 38,
      "z": -25,
      "name": "Rock_Ice_Permafrost"
    },
    {
      "x": -45,
      "y": 39,
      "z": -25,
      "name": "Rock_Ice_Permafrost"
    },
    {
      "x": -45,
      "y": 40,
      "z": -25,
      "name": "Rock_Ice_Permafrost"
    },
    {
      "x": -45,
      "y": 41,
      "z": -25,
      "name": "Soil_Snow"
    },
    {
      "x": -45,
      "y": 37,
      "z": -24,
      "name": "Rock_Ice"
    },
    {
      "x": -45,
      "y": 38,
      "z": -24,
      "name": "Rock_Ice"
    },
    {
      "x": -45,
      "y": 39,
      "z": -24,
      "name": "Rock_Ice_Permafrost"
    },
    {
      "x": -45,
      "y": 40,
      "z": -24,
      "name": "Rock_Ice_Permafrost"
    },
    {
      "x": -45,
      "y": 41,
      "z": -24,
      "name": "Rock_Ice_Permafrost"
    },
    {
      "x": -45,
      "y": 42,
      "z": -24,
      "name": "Rock_Ice_Permafrost"
    },
    {
      "x": -45,
      "y": 43,
      "z": -24,
      "name": "Soil_Snow"
    },
    {
      "x": -45,
      "y": 38,
      "z": -23,
      "name": "Rock_Ice"
    },
    {
      "x": -45,
      "y": 39,
      "z": -23,
      "name": "Rock_Ice"
    },
    {
      "x": -45,
      "y": 40,
      "z": -23,
      "name": "Rock_Ice_Permafrost"
    },
    {
      "x": -45,
      "y": 41,
      "z": -23,
      "name": "Rock_Ice"
    },
    {
      "x": -45,
      "y": 42,
      "z": -23,
      "name": "Rock_Ice_Permafrost"
    },
    {
      "x": -45,
      "y": 43,
      "z": -23,
      "name": "Rock_Ice"
    },
    {
      "x": -45,
      "y": 44,
      "z": -23,
      "name": "Rock_Ice_Permafrost"
    },
    {
      "x": -45,
      "y": 39,
      "z": -22,
      "name": "Rock_Ice"
    },
    {
      "x": -45,
      "y": 40,
      "z": -22,
      "name": "Rock_Ice"
    },
    {
      "x": -45,
      "y": 41,
      "z": -22,
      "name": "Rock_Ice"
    },
    {
      "x": -45,
      "y": 42,
      "z": -22,
      "name": "Rock_Ice"
    },
    {
      "x": -45,
      "y": 43,
      "z": -22,
      "name": "Rock_Ice"
    },
    {
      "x": -45,
      "y": 44,
      "z": -22,
      "name": "Soil_Snow"
    },
    {
      "x": -45,
      "y": 42,
      "z": -21,
      "name": "Rock_Ice"
    },
    {
      "x": -45,
      "y": 43,
      "z": -21,
      "name": "Soil_Snow"
    },
    {
      "x": -45,
      "y": 2,
      "z": -5,
      "name": "Soil_Snow"
    },
    {
      "x": -45,
      "y": 2,
      "z": -4,
      "name": "Soil_Snow"
    },
    {
      "x": -45,
      "y": 1,
      "z": -3,
      "name": "Rock_Ice"
    },
    {
      "x": -45,
      "y": 2,
      "z": -3,
      "name": "Soil_Snow"
    },
    {
      "x": -45,
      "y": 0,
      "z": -2,
      "name": "Rock_Ice"
    },
    {
      "x": -45,
      "y": 1,
      "z": -2,
      "name": "Rock_Ice"
    },
    {
      "x": -45,
      "y": 2,
      "z": -2,
      "name": "Soil_Snow"
    },
    {
      "x": -45,
      "y": 0,
      "z": -1,
      "name": "Rock_Ice"
    },
    {
      "x": -45,
      "y": 1,
      "z": -1,
      "name": "Rock_Ice_Permafrost"
    },
    {
      "x": -45,
      "y": 2,
      "z": -1,
      "name": "Rock_Ice"
    },
    {
      "x": -45,
      "y": 3,
      "z": -1,
      "name": "Soil_Snow"
    },
    {
      "x": -45,
      "y": 0,
      "z": 0,
      "name": "Rock_Ice"
    },
    {
      "x": -45,
      "y": 1,
      "z": 0,
      "name": "Rock_Ice"
    },
    {
      "x": -45,
      "y": 2,
      "z": 0,
      "name": "Rock_Ice"
    },
    {
      "x": -45,
      "y": 3,
      "z": 0,
      "name": "Soil_Snow"
    },
    {
      "x": -45,
      "y": 0,
      "z": 1,
      "name": "Rock_Ice"
    },
    {
      "x": -45,
      "y": 1,
      "z": 1,
      "name": "Rock_Ice_Permafrost"
    },
    {
      "x": -45,
      "y": 2,
      "z": 1,
      "name": "Rock_Ice"
    },
    {
      "x": -45,
      "y": 3,
      "z": 1,
      "name": "Rock_Ice"
    },
    {
      "x": -45,
      "y": 4,
      "z": 1,
      "name": "Soil_Snow"
    },
    {
      "x": -45,
      "y": 0,
      "z": 2,
      "name": "Rock_Ice_Permafrost"
    },
    {
      "x": -45,
      "y": 1,
      "z": 2,
      "name": "Rock_Ice"
    },
    {
      "x": -45,
      "y": 2,
      "z": 2,
      "name": "Rock_Ice"
    },
    {
      "x": -45,
      "y": 3,
      "z": 2,
      "name": "Rock_Ice"
    },
    {
      "x": -45,
      "y": 4,
      "z": 2,
      "name": "Rock_Ice"
    },
    {
      "x": -45,
      "y": 5,
      "z": 2,
      "name": "Rock_Ice"
    },
    {
      "x": -45,
      "y": 6,
      "z": 2,
      "name": "Soil_Snow"
    },
    {
      "x": -45,
      "y": 0,
      "z": 3,
      "name": "Rock_Ice"
    },
    {
      "x": -45,
      "y": 1,
      "z": 3,
      "name": "Rock_Ice"
    },
    {
      "x": -45,
      "y": 2,
      "z": 3,
      "name": "Rock_Ice"
    },
    {
      "x": -45,
      "y": 3,
      "z": 3,
      "name": "Rock_Ice"
    },
    {
      "x": -45,
      "y": 4,
      "z": 3,
      "name": "Rock_Ice"
    },
    {
      "x": -45,
      "y": 5,
      "z": 3,
      "name": "Rock_Ice"
    },
    {
      "x": -45,
      "y": 6,
      "z": 3,
      "name": "Rock_Ice"
    },
    {
      "x": -45,
      "y": 0,
      "z": 4,
      "name": "Rock_Ice_Permafrost"
    },
    {
      "x": -45,
      "y": 1,
      "z": 4,
      "name": "Rock_Ice"
    },
    {
      "x": -45,
      "y": 2,
      "z": 4,
      "name": "Rock_Ice"
    },
    {
      "x": -45,
      "y": 3,
      "z": 4,
      "name": "Rock_Ice"
    },
    {
      "x": -45,
      "y": 4,
      "z": 4,
      "name": "Rock_Ice"
    },
    {
      "x": -45,
      "y": 5,
      "z": 4,
      "name": "Rock_Ice"
    },
    {
      "x": -45,
      "y": 6,
      "z": 4,
      "name": "Rock_Ice_Permafrost"
    },
    {
      "x": -45,
      "y": 7,
      "z": 4,
      "name": "Soil_Snow"
    },
    {
      "x": -45,
      "y": 0,
      "z": 5,
      "name": "Rock_Ice"
    },
    {
      "x": -45,
      "y": 1,
      "z": 5,
      "name": "Rock_Ice"
    },
    {
      "x": -45,
      "y": 2,
      "z": 5,
      "name": "Rock_Ice"
    },
    {
      "x": -45,
      "y": 3,
      "z": 5,
      "name": "Rock_Ice"
    },
    {
      "x": -45,
      "y": 4,
      "z": 5,
      "name": "Rock_Ice"
    },
    {
      "x": -45,
      "y": 5,
      "z": 5,
      "name": "Rock_Ice"
    },
    {
      "x": -45,
      "y": 6,
      "z": 5,
      "name": "Rock_Ice"
    },
    {
      "x": -45,
      "y": 7,
      "z": 5,
      "name": "Soil_Snow"
    },
    {
      "x": -45,
      "y": 0,
      "z": 6,
      "name": "Rock_Ice"
    },
    {
      "x": -45,
      "y": 1,
      "z": 6,
      "name": "Rock_Ice"
    },
    {
      "x": -45,
      "y": 2,
      "z": 6,
      "name": "Rock_Ice"
    },
    {
      "x": -45,
      "y": 3,
      "z": 6,
      "name": "Rock_Ice"
    },
    {
      "x": -45,
      "y": 4,
      "z": 6,
      "name": "Rock_Ice"
    },
    {
      "x": -45,
      "y": 5,
      "z": 6,
      "name": "Rock_Ice"
    },
    {
      "x": -45,
      "y": 6,
      "z": 6,
      "name": "Rock_Ice_Permafrost"
    },
    {
      "x": -45,
      "y": 7,
      "z": 6,
      "name": "Soil_Snow"
    },
    {
      "x": -45,
      "y": 0,
      "z": 7,
      "name": "Rock_Ice"
    },
    {
      "x": -45,
      "y": 1,
      "z": 7,
      "name": "Rock_Ice"
    },
    {
      "x": -45,
      "y": 2,
      "z": 7,
      "name": "Rock_Ice"
    },
    {
      "x": -45,
      "y": 3,
      "z": 7,
      "name": "Rock_Ice"
    },
    {
      "x": -45,
      "y": 4,
      "z": 7,
      "name": "Rock_Ice"
    },
    {
      "x": -45,
      "y": 5,
      "z": 7,
      "name": "Rock_Ice"
    },
    {
      "x": -45,
      "y": 6,
      "z": 7,
      "name": "Rock_Ice"
    },
    {
      "x": -45,
      "y": 7,
      "z": 7,
      "name": "Soil_Snow"
    },
    {
      "x": -45,
      "y": 0,
      "z": 8,
      "name": "Rock_Ice"
    },
    {
      "x": -45,
      "y": 1,
      "z": 8,
      "name": "Rock_Ice"
    },
    {
      "x": -45,
      "y": 2,
      "z": 8,
      "name": "Rock_Ice"
    },
    {
      "x": -45,
      "y": 3,
      "z": 8,
      "name": "Rock_Ice"
    },
    {
      "x": -45,
      "y": 4,
      "z": 8,
      "name": "Rock_Ice"
    },
    {
      "x": -45,
      "y": 5,
      "z": 8,
      "name": "Rock_Ice"
    },
    {
      "x": -45,
      "y": 6,
      "z": 8,
      "name": "Rock_Ice"
    },
    {
      "x": -45,
      "y": 7,
      "z": 8,
      "name": "Rock_Ice_Permafrost"
    },
    {
      "x": -45,
      "y": 8,
      "z": 8,
      "name": "Soil_Snow"
    },
    {
      "x": -45,
      "y": 0,
      "z": 9,
      "name": "Rock_Ice_Permafrost"
    },
    {
      "x": -45,
      "y": 1,
      "z": 9,
      "name": "Rock_Ice_Permafrost"
    },
    {
      "x": -45,
      "y": 2,
      "z": 9,
      "name": "Rock_Ice"
    },
    {
      "x": -45,
      "y": 3,
      "z": 9,
      "name": "Rock_Ice"
    },
    {
      "x": -45,
      "y": 4,
      "z": 9,
      "name": "Rock_Ice"
    },
    {
      "x": -45,
      "y": 5,
      "z": 9,
      "name": "Rock_Ice"
    },
    {
      "x": -45,
      "y": 6,
      "z": 9,
      "name": "Rock_Ice"
    },
    {
      "x": -45,
      "y": 7,
      "z": 9,
      "name": "Rock_Ice_Permafrost"
    },
    {
      "x": -45,
      "y": 8,
      "z": 9,
      "name": "Soil_Snow"
    },
    {
      "x": -45,
      "y": 0,
      "z": 10,
      "name": "Rock_Ice_Permafrost"
    },
    {
      "x": -45,
      "y": 1,
      "z": 10,
      "name": "Rock_Ice"
    },
    {
      "x": -45,
      "y": 2,
      "z": 10,
      "name": "Rock_Ice"
    },
    {
      "x": -45,
      "y": 3,
      "z": 10,
      "name": "Rock_Ice"
    },
    {
      "x": -45,
      "y": 4,
      "z": 10,
      "name": "Rock_Ice_Permafrost"
    },
    {
      "x": -45,
      "y": 5,
      "z": 10,
      "name": "Rock_Ice_Permafrost"
    },
    {
      "x": -45,
      "y": 6,
      "z": 10,
      "name": "Rock_Ice_Permafrost"
    },
    {
      "x": -45,
      "y": 7,
      "z": 10,
      "name": "Rock_Ice_Permafrost"
    },
    {
      "x": -45,
      "y": 8,
      "z": 10,
      "name": "Soil_Snow"
    },
    {
      "x": -45,
      "y": 0,
      "z": 11,
      "name": "Rock_Ice_Permafrost"
    },
    {
      "x": -45,
      "y": 1,
      "z": 11,
      "name": "Rock_Ice"
    },
    {
      "x": -45,
      "y": 2,
      "z": 11,
      "name": "Rock_Ice_Permafrost"
    },
    {
      "x": -45,
      "y": 3,
      "z": 11,
      "name": "Rock_Ice"
    },
    {
      "x": -45,
      "y": 4,
      "z": 11,
      "name": "Rock_Ice_Permafrost"
    },
    {
      "x": -45,
      "y": 5,
      "z": 11,
      "name": "Rock_Ice_Permafrost"
    },
    {
      "x": -45,
      "y": 6,
      "z": 11,
      "name": "Rock_Ice_Permafrost"
    },
    {
      "x": -45,
      "y": 7,
      "z": 11,
      "name": "Rock_Ice"
    },
    {
      "x": -45,
      "y": 8,
      "z": 11,
      "name": "Soil_Snow"
    },
    {
      "x": -45,
      "y": 0,
      "z": 12,
      "name": "Rock_Ice_Permafrost"
    },
    {
      "x": -45,
      "y": 1,
      "z": 12,
      "name": "Rock_Ice_Permafrost"
    },
    {
      "x": -45,
      "y": 2,
      "z": 12,
      "name": "Rock_Ice"
    },
    {
      "x": -45,
      "y": 3,
      "z": 12,
      "name": "Rock_Ice"
    },
    {
      "x": -45,
      "y": 4,
      "z": 12,
      "name": "Rock_Ice"
    },
    {
      "x": -45,
      "y": 5,
      "z": 12,
      "name": "Rock_Ice_Permafrost"
    },
    {
      "x": -45,
      "y": 6,
      "z": 12,
      "name": "Rock_Ice_Permafrost"
    },
    {
      "x": -45,
      "y": 7,
      "z": 12,
      "name": "Rock_Ice_Permafrost"
    },
    {
      "x": -45,
      "y": 8,
      "z": 12,
      "name": "Soil_Snow"
    },
    {
      "x": -45,
      "y": 0,
      "z": 13,
      "name": "Rock_Ice_Permafrost"
    },
    {
      "x": -45,
      "y": 1,
      "z": 13,
      "name": "Rock_Ice_Permafrost"
    },
    {
      "x": -45,
      "y": 2,
      "z": 13,
      "name": "Rock_Ice_Permafrost"
    },
    {
      "x": -45,
      "y": 3,
      "z": 13,
      "name": "Rock_Ice"
    },
    {
      "x": -45,
      "y": 4,
      "z": 13,
      "name": "Rock_Ice_Permafrost"
    },
    {
      "x": -45,
      "y": 5,
      "z": 13,
      "name": "Rock_Ice_Permafrost"
    },
    {
      "x": -45,
      "y": 6,
      "z": 13,
      "name": "Rock_Ice_Permafrost"
    },
    {
      "x": -45,
      "y": 7,
      "z": 13,
      "name": "Rock_Ice_Permafrost"
    },
    {
      "x": -45,
      "y": 8,
      "z": 13,
      "name": "Soil_Snow"
    },
    {
      "x": -45,
      "y": 0,
      "z": 14,
      "name": "Rock_Ice_Permafrost"
    },
    {
      "x": -45,
      "y": 1,
      "z": 14,
      "name": "Rock_Ice_Permafrost"
    },
    {
      "x": -45,
      "y": 2,
      "z": 14,
      "name": "Rock_Ice_Permafrost"
    },
    {
      "x": -45,
      "y": 3,
      "z": 14,
      "name": "Rock_Ice_Permafrost"
    },
    {
      "x": -45,
      "y": 4,
      "z": 14,
      "name": "Rock_Ice"
    },
    {
      "x": -45,
      "y": 5,
      "z": 14,
      "name": "Rock_Ice_Permafrost"
    },
    {
      "x": -45,
      "y": 6,
      "z": 14,
      "name": "Rock_Ice_Permafrost"
    },
    {
      "x": -45,
      "y": 7,
      "z": 14,
      "name": "Rock_Ice_Permafrost"
    },
    {
      "x": -45,
      "y": 8,
      "z": 14,
      "name": "Soil_Snow"
    },
    {
      "x": -45,
      "y": 0,
      "z": 15,
      "name": "Rock_Ice_Permafrost"
    },
    {
      "x": -45,
      "y": 1,
      "z": 15,
      "name": "Rock_Ice_Permafrost"
    },
    {
      "x": -45,
      "y": 2,
      "z": 15,
      "name": "Rock_Ice_Permafrost"
    },
    {
      "x": -45,
      "y": 3,
      "z": 15,
      "name": "Rock_Ice_Permafrost"
    },
    {
      "x": -45,
      "y": 4,
      "z": 15,
      "name": "Rock_Ice_Permafrost"
    },
    {
      "x": -45,
      "y": 5,
      "z": 15,
      "name": "Rock_Ice_Permafrost"
    },
    {
      "x": -45,
      "y": 6,
      "z": 15,
      "name": "Rock_Ice_Permafrost"
    },
    {
      "x": -45,
      "y": 7,
      "z": 15,
      "name": "Rock_Ice"
    },
    {
      "x": -45,
      "y": 8,
      "z": 15,
      "name": "Soil_Snow"
    },
    {
      "x": -45,
      "y": 0,
      "z": 16,
      "name": "Rock_Ice_Permafrost"
    },
    {
      "x": -45,
      "y": 1,
      "z": 16,
      "name": "Rock_Ice_Permafrost"
    },
    {
      "x": -45,
      "y": 2,
      "z": 16,
      "name": "Rock_Ice_Permafrost"
    },
    {
      "x": -45,
      "y": 3,
      "z": 16,
      "name": "Rock_Ice_Permafrost"
    },
    {
      "x": -45,
      "y": 4,
      "z": 16,
      "name": "Rock_Ice_Permafrost"
    },
    {
      "x": -45,
      "y": 5,
      "z": 16,
      "name": "Rock_Ice_Permafrost"
    },
    {
      "x": -45,
      "y": 6,
      "z": 16,
      "name": "Rock_Ice_Permafrost"
    },
    {
      "x": -45,
      "y": 7,
      "z": 16,
      "name": "Rock_Ice_Permafrost"
    },
    {
      "x": -45,
      "y": 8,
      "z": 16,
      "name": "Soil_Snow"
    },
    {
      "x": -45,
      "y": 0,
      "z": 17,
      "name": "Rock_Ice_Permafrost"
    },
    {
      "x": -45,
      "y": 1,
      "z": 17,
      "name": "Rock_Ice_Permafrost"
    },
    {
      "x": -45,
      "y": 2,
      "z": 17,
      "name": "Rock_Ice_Permafrost"
    },
    {
      "x": -45,
      "y": 3,
      "z": 17,
      "name": "Rock_Ice_Permafrost"
    },
    {
      "x": -45,
      "y": 4,
      "z": 17,
      "name": "Rock_Ice_Permafrost"
    },
    {
      "x": -45,
      "y": 5,
      "z": 17,
      "name": "Rock_Ice_Permafrost"
    },
    {
      "x": -45,
      "y": 6,
      "z": 17,
      "name": "Rock_Ice_Permafrost"
    },
    {
      "x": -45,
      "y": 7,
      "z": 17,
      "name": "Soil_Snow"
    },
    {
      "x": -45,
      "y": 0,
      "z": 18,
      "name": "Rock_Ice_Permafrost"
    },
    {
      "x": -45,
      "y": 1,
      "z": 18,
      "name": "Rock_Ice_Permafrost"
    },
    {
      "x": -45,
      "y": 2,
      "z": 18,
      "name": "Rock_Ice_Permafrost"
    },
    {
      "x": -45,
      "y": 3,
      "z": 18,
      "name": "Rock_Ice_Permafrost"
    },
    {
      "x": -45,
      "y": 4,
      "z": 18,
      "name": "Rock_Ice_Permafrost"
    },
    {
      "x": -45,
      "y": 5,
      "z": 18,
      "name": "Rock_Ice_Permafrost"
    },
    {
      "x": -45,
      "y": 6,
      "z": 18,
      "name": "Rock_Ice"
    },
    {
      "x": -45,
      "y": 7,
      "z": 18,
      "name": "Soil_Snow"
    },
    {
      "x": -45,
      "y": 0,
      "z": 19,
      "name": "Rock_Ice_Permafrost"
    },
    {
      "x": -45,
      "y": 1,
      "z": 19,
      "name": "Rock_Ice_Permafrost"
    },
    {
      "x": -45,
      "y": 2,
      "z": 19,
      "name": "Rock_Ice_Permafrost"
    },
    {
      "x": -45,
      "y": 3,
      "z": 19,
      "name": "Rock_Ice_Permafrost"
    },
    {
      "x": -45,
      "y": 4,
      "z": 19,
      "name": "Rock_Ice_Permafrost"
    },
    {
      "x": -45,
      "y": 5,
      "z": 19,
      "name": "Rock_Ice_Permafrost"
    },
    {
      "x": -45,
      "y": 6,
      "z": 19,
      "name": "Rock_Ice"
    },
    {
      "x": -45,
      "y": 7,
      "z": 19,
      "name": "Rock_Ice"
    },
    {
      "x": -45,
      "y": 0,
      "z": 20,
      "name": "Rock_Ice_Permafrost"
    },
    {
      "x": -45,
      "y": 1,
      "z": 20,
      "name": "Rock_Ice_Permafrost"
    },
    {
      "x": -45,
      "y": 2,
      "z": 20,
      "name": "Rock_Ice_Permafrost"
    },
    {
      "x": -45,
      "y": 3,
      "z": 20,
      "name": "Rock_Ice_Permafrost"
    },
    {
      "x": -45,
      "y": 4,
      "z": 20,
      "name": "Rock_Ice_Permafrost"
    },
    {
      "x": -45,
      "y": 5,
      "z": 20,
      "name": "Rock_Ice_Permafrost"
    },
    {
      "x": -45,
      "y": 6,
      "z": 20,
      "name": "Rock_Ice"
    },
    {
      "x": -45,
      "y": 7,
      "z": 20,
      "name": "Rock_Ice"
    },
    {
      "x": -45,
      "y": 0,
      "z": 21,
      "name": "Rock_Ice_Permafrost"
    },
    {
      "x": -45,
      "y": 1,
      "z": 21,
      "name": "Rock_Ice_Permafrost"
    },
    {
      "x": -45,
      "y": 2,
      "z": 21,
      "name": "Rock_Ice_Permafrost"
    },
    {
      "x": -45,
      "y": 3,
      "z": 21,
      "name": "Rock_Ice_Permafrost"
    },
    {
      "x": -45,
      "y": 4,
      "z": 21,
      "name": "Rock_Ice"
    },
    {
      "x": -45,
      "y": 5,
      "z": 21,
      "name": "Rock_Ice_Permafrost"
    },
    {
      "x": -45,
      "y": 6,
      "z": 21,
      "name": "Rock_Ice_Permafrost"
    },
    {
      "x": -45,
      "y": 7,
      "z": 21,
      "name": "Rock_Ice"
    },
    {
      "x": -45,
      "y": 0,
      "z": 22,
      "name": "Rock_Ice_Permafrost"
    },
    {
      "x": -45,
      "y": 1,
      "z": 22,
      "name": "Rock_Ice_Permafrost"
    },
    {
      "x": -45,
      "y": 2,
      "z": 22,
      "name": "Rock_Ice_Permafrost"
    },
    {
      "x": -45,
      "y": 3,
      "z": 22,
      "name": "Rock_Ice_Permafrost"
    },
    {
      "x": -45,
      "y": 4,
      "z": 22,
      "name": "Rock_Ice_Permafrost"
    },
    {
      "x": -45,
      "y": 5,
      "z": 22,
      "name": "Rock_Ice_Permafrost"
    },
    {
      "x": -45,
      "y": 6,
      "z": 22,
      "name": "Rock_Ice"
    },
    {
      "x": -45,
      "y": 7,
      "z": 22,
      "name": "Soil_Snow"
    },
    {
      "x": -45,
      "y": 0,
      "z": 23,
      "name": "Rock_Ice_Permafrost"
    },
    {
      "x": -45,
      "y": 1,
      "z": 23,
      "name": "Rock_Ice_Permafrost"
    },
    {
      "x": -45,
      "y": 2,
      "z": 23,
      "name": "Rock_Ice_Permafrost"
    },
    {
      "x": -45,
      "y": 3,
      "z": 23,
      "name": "Rock_Ice_Permafrost"
    },
    {
      "x": -45,
      "y": 4,
      "z": 23,
      "name": "Rock_Ice_Permafrost"
    },
    {
      "x": -45,
      "y": 5,
      "z": 23,
      "name": "Rock_Ice"
    },
    {
      "x": -45,
      "y": 6,
      "z": 23,
      "name": "Rock_Ice"
    },
    {
      "x": -45,
      "y": 0,
      "z": 24,
      "name": "Rock_Ice_Permafrost"
    },
    {
      "x": -45,
      "y": 1,
      "z": 24,
      "name": "Rock_Ice_Permafrost"
    },
    {
      "x": -45,
      "y": 2,
      "z": 24,
      "name": "Rock_Ice_Permafrost"
    },
    {
      "x": -45,
      "y": 3,
      "z": 24,
      "name": "Rock_Ice_Permafrost"
    },
    {
      "x": -45,
      "y": 4,
      "z": 24,
      "name": "Rock_Ice_Permafrost"
    },
    {
      "x": -45,
      "y": 5,
      "z": 24,
      "name": "Rock_Ice"
    },
    {
      "x": -45,
      "y": 6,
      "z": 24,
      "name": "Rock_Ice_Permafrost"
    },
    {
      "x": -45,
      "y": 0,
      "z": 25,
      "name": "Rock_Ice_Permafrost"
    },
    {
      "x": -45,
      "y": 1,
      "z": 25,
      "name": "Rock_Ice_Permafrost"
    },
    {
      "x": -45,
      "y": 2,
      "z": 25,
      "name": "Rock_Ice_Permafrost"
    },
    {
      "x": -45,
      "y": 3,
      "z": 25,
      "name": "Rock_Ice_Permafrost"
    },
    {
      "x": -45,
      "y": 4,
      "z": 25,
      "name": "Rock_Ice"
    },
    {
      "x": -45,
      "y": 5,
      "z": 25,
      "name": "Soil_Snow"
    },
    {
      "x": -45,
      "y": 0,
      "z": 26,
      "name": "Rock_Ice_Permafrost"
    },
    {
      "x": -45,
      "y": 1,
      "z": 26,
      "name": "Rock_Ice_Permafrost"
    },
    {
      "x": -45,
      "y": 2,
      "z": 26,
      "name": "Rock_Ice_Permafrost"
    },
    {
      "x": -45,
      "y": 3,
      "z": 26,
      "name": "Rock_Ice"
    },
    {
      "x": -45,
      "y": 4,
      "z": 26,
      "name": "Soil_Snow"
    },
    {
      "x": -45,
      "y": 0,
      "z": 27,
      "name": "Rock_Ice_Permafrost"
    },
    {
      "x": -45,
      "y": 1,
      "z": 27,
      "name": "Rock_Ice"
    },
    {
      "x": -45,
      "y": 2,
      "z": 27,
      "name": "Rock_Ice_Permafrost"
    },
    {
      "x": -45,
      "y": 0,
      "z": 28,
      "name": "Soil_Snow"
    },
    {
      "x": -44,
      "y": 33,
      "z": -30,
      "name": "Rock_Ice_Permafrost"
    },
    {
      "x": -44,
      "y": 33,
      "z": -29,
      "name": "Rock_Ice"
    },
    {
      "x": -44,
      "y": 34,
      "z": -29,
      "name": "Rock_Ice"
    },
    {
      "x": -44,
      "y": 35,
      "z": -29,
      "name": "Rock_Ice_Permafrost"
    },
    {
      "x": -44,
      "y": 34,
      "z": -28,
      "name": "Rock_Ice"
    },
    {
      "x": -44,
      "y": 35,
      "z": -28,
      "name": "Rock_Ice_Permafrost"
    },
    {
      "x": -44,
      "y": 36,
      "z": -28,
      "name": "Rock_Ice_Permafrost"
    },
    {
      "x": -44,
      "y": 37,
      "z": -28,
      "name": "Soil_Snow"
    },
    {
      "x": -44,
      "y": 35,
      "z": -27,
      "name": "Rock_Ice"
    },
    {
      "x": -44,
      "y": 36,
      "z": -27,
      "name": "Rock_Ice_Permafrost"
    },
    {
      "x": -44,
      "y": 37,
      "z": -27,
      "name": "Rock_Ice"
    },
    {
      "x": -44,
      "y": 38,
      "z": -27,
      "name": "Soil_Snow"
    },
    {
      "x": -44,
      "y": 36,
      "z": -26,
      "name": "Rock_Ice"
    },
    {
      "x": -44,
      "y": 37,
      "z": -26,
      "name": "Rock_Ice_Permafrost"
    },
    {
      "x": -44,
      "y": 38,
      "z": -26,
      "name": "Rock_Ice_Permafrost"
    },
    {
      "x": -44,
      "y": 39,
      "z": -26,
      "name": "Rock_Ice"
    },
    {
      "x": -44,
      "y": 40,
      "z": -26,
      "name": "Soil_Snow"
    },
    {
      "x": -44,
      "y": 36,
      "z": -25,
      "name": "Rock_Ice"
    },
    {
      "x": -44,
      "y": 37,
      "z": -25,
      "name": "Rock_Ice"
    },
    {
      "x": -44,
      "y": 38,
      "z": -25,
      "name": "Rock_Ice_Permafrost"
    },
    {
      "x": -44,
      "y": 39,
      "z": -25,
      "name": "Rock_Ice_Permafrost"
    },
    {
      "x": -44,
      "y": 40,
      "z": -25,
      "name": "Rock_Ice"
    },
    {
      "x": -44,
      "y": 41,
      "z": -25,
      "name": "Soil_Snow"
    },
    {
      "x": -44,
      "y": 37,
      "z": -24,
      "name": "Rock_Ice"
    },
    {
      "x": -44,
      "y": 38,
      "z": -24,
      "name": "Rock_Ice"
    },
    {
      "x": -44,
      "y": 39,
      "z": -24,
      "name": "Rock_Ice_Permafrost"
    },
    {
      "x": -44,
      "y": 40,
      "z": -24,
      "name": "Rock_Ice"
    },
    {
      "x": -44,
      "y": 41,
      "z": -24,
      "name": "Rock_Ice_Permafrost"
    },
    {
      "x": -44,
      "y": 42,
      "z": -24,
      "name": "Rock_Ice"
    },
    {
      "x": -44,
      "y": 43,
      "z": -24,
      "name": "Rock_Ice_Permafrost"
    },
    {
      "x": -44,
      "y": 38,
      "z": -23,
      "name": "Rock_Ice"
    },
    {
      "x": -44,
      "y": 39,
      "z": -23,
      "name": "Rock_Ice"
    },
    {
      "x": -44,
      "y": 40,
      "z": -23,
      "name": "Rock_Ice_Permafrost"
    },
    {
      "x": -44,
      "y": 41,
      "z": -23,
      "name": "Rock_Ice"
    },
    {
      "x": -44,
      "y": 42,
      "z": -23,
      "name": "Rock_Ice_Permafrost"
    },
    {
      "x": -44,
      "y": 43,
      "z": -23,
      "name": "Rock_Ice"
    },
    {
      "x": -44,
      "y": 44,
      "z": -23,
      "name": "Rock_Ice"
    },
    {
      "x": -44,
      "y": 45,
      "z": -23,
      "name": "Rock_Ice_Permafrost"
    },
    {
      "x": -44,
      "y": 39,
      "z": -22,
      "name": "Rock_Ice"
    },
    {
      "x": -44,
      "y": 40,
      "z": -22,
      "name": "Rock_Ice"
    },
    {
      "x": -44,
      "y": 41,
      "z": -22,
      "name": "Rock_Ice"
    },
    {
      "x": -44,
      "y": 42,
      "z": -22,
      "name": "Rock_Ice"
    },
    {
      "x": -44,
      "y": 43,
      "z": -22,
      "name": "Rock_Ice"
    },
    {
      "x": -44,
      "y": 44,
      "z": -22,
      "name": "Rock_Ice_Permafrost"
    },
    {
      "x": -44,
      "y": 45,
      "z": -22,
      "name": "Rock_Ice"
    },
    {
      "x": -44,
      "y": 46,
      "z": -22,
      "name": "Soil_Snow"
    },
    {
      "x": -44,
      "y": 42,
      "z": -21,
      "name": "Rock_Ice"
    },
    {
      "x": -44,
      "y": 43,
      "z": -21,
      "name": "Rock_Ice"
    },
    {
      "x": -44,
      "y": 44,
      "z": -21,
      "name": "Soil_Snow"
    },
    {
      "x": -44,
      "y": 3,
      "z": -7,
      "name": "Soil_Snow"
    },
    {
      "x": -44,
      "y": 2,
      "z": -6,
      "name": "Rock_Ice"
    },
    {
      "x": -44,
      "y": 3,
      "z": -6,
      "name": "Soil_Snow"
    },
    {
      "x": -44,
      "y": 2,
      "z": -5,
      "name": "Rock_Ice"
    },
    {
      "x": -44,
      "y": 3,
      "z": -5,
      "name": "Soil_Snow"
    },
    {
      "x": -44,
      "y": 2,
      "z": -4,
      "name": "Rock_Ice"
    },
    {
      "x": -44,
      "y": 3,
      "z": -4,
      "name": "Rock_Ice"
    },
    {
      "x": -44,
      "y": 4,
      "z": -4,
      "name": "Soil_Snow"
    },
    {
      "x": -44,
      "y": 1,
      "z": -3,
      "name": "Rock_Ice"
    },
    {
      "x": -44,
      "y": 2,
      "z": -3,
      "name": "Rock_Ice"
    },
    {
      "x": -44,
      "y": 3,
      "z": -3,
      "name": "Rock_Ice"
    },
    {
      "x": -44,
      "y": 4,
      "z": -3,
      "name": "Soil_Snow"
    },
    {
      "x": -44,
      "y": 1,
      "z": -2,
      "name": "Rock_Ice"
    },
    {
      "x": -44,
      "y": 2,
      "z": -2,
      "name": "Rock_Ice"
    },
    {
      "x": -44,
      "y": 3,
      "z": -2,
      "name": "Rock_Ice"
    },
    {
      "x": -44,
      "y": 4,
      "z": -2,
      "name": "Soil_Snow"
    },
    {
      "x": -44,
      "y": 1,
      "z": -1,
      "name": "Rock_Ice_Permafrost"
    },
    {
      "x": -44,
      "y": 2,
      "z": -1,
      "name": "Rock_Ice"
    },
    {
      "x": -44,
      "y": 3,
      "z": -1,
      "name": "Rock_Ice"
    },
    {
      "x": -44,
      "y": 4,
      "z": -1,
      "name": "Soil_Snow"
    },
    {
      "x": -44,
      "y": 0,
      "z": 0,
      "name": "Rock_Ice"
    },
    {
      "x": -44,
      "y": 1,
      "z": 0,
      "name": "Rock_Ice_Permafrost"
    },
    {
      "x": -44,
      "y": 2,
      "z": 0,
      "name": "Rock_Ice"
    },
    {
      "x": -44,
      "y": 3,
      "z": 0,
      "name": "Rock_Ice"
    },
    {
      "x": -44,
      "y": 4,
      "z": 0,
      "name": "Rock_Ice"
    },
    {
      "x": -44,
      "y": 5,
      "z": 0,
      "name": "Soil_Snow"
    },
    {
      "x": -44,
      "y": 0,
      "z": 1,
      "name": "Rock_Ice"
    },
    {
      "x": -44,
      "y": 1,
      "z": 1,
      "name": "Rock_Ice_Permafrost"
    },
    {
      "x": -44,
      "y": 2,
      "z": 1,
      "name": "Rock_Ice"
    },
    {
      "x": -44,
      "y": 3,
      "z": 1,
      "name": "Rock_Ice"
    },
    {
      "x": -44,
      "y": 4,
      "z": 1,
      "name": "Rock_Ice"
    },
    {
      "x": -44,
      "y": 5,
      "z": 1,
      "name": "Rock_Ice"
    },
    {
      "x": -44,
      "y": 6,
      "z": 1,
      "name": "Rock_Ice"
    },
    {
      "x": -44,
      "y": 7,
      "z": 1,
      "name": "Soil_Snow"
    },
    {
      "x": -44,
      "y": 0,
      "z": 2,
      "name": "Rock_Ice"
    },
    {
      "x": -44,
      "y": 1,
      "z": 2,
      "name": "Rock_Ice_Permafrost"
    },
    {
      "x": -44,
      "y": 2,
      "z": 2,
      "name": "Rock_Ice"
    },
    {
      "x": -44,
      "y": 3,
      "z": 2,
      "name": "Rock_Ice"
    },
    {
      "x": -44,
      "y": 4,
      "z": 2,
      "name": "Rock_Ice"
    },
    {
      "x": -44,
      "y": 5,
      "z": 2,
      "name": "Rock_Ice"
    },
    {
      "x": -44,
      "y": 6,
      "z": 2,
      "name": "Rock_Ice"
    },
    {
      "x": -44,
      "y": 7,
      "z": 2,
      "name": "Rock_Ice"
    },
    {
      "x": -44,
      "y": 0,
      "z": 3,
      "name": "Rock_Ice_Permafrost"
    },
    {
      "x": -44,
      "y": 1,
      "z": 3,
      "name": "Rock_Ice"
    },
    {
      "x": -44,
      "y": 2,
      "z": 3,
      "name": "Rock_Ice"
    },
    {
      "x": -44,
      "y": 3,
      "z": 3,
      "name": "Rock_Ice"
    },
    {
      "x": -44,
      "y": 4,
      "z": 3,
      "name": "Rock_Ice"
    },
    {
      "x": -44,
      "y": 5,
      "z": 3,
      "name": "Rock_Ice"
    },
    {
      "x": -44,
      "y": 6,
      "z": 3,
      "name": "Rock_Ice"
    },
    {
      "x": -44,
      "y": 7,
      "z": 3,
      "name": "Rock_Ice_Permafrost"
    },
    {
      "x": -44,
      "y": 8,
      "z": 3,
      "name": "Soil_Snow"
    },
    {
      "x": -44,
      "y": 0,
      "z": 4,
      "name": "Rock_Ice_Permafrost"
    },
    {
      "x": -44,
      "y": 1,
      "z": 4,
      "name": "Rock_Ice"
    },
    {
      "x": -44,
      "y": 2,
      "z": 4,
      "name": "Rock_Ice"
    },
    {
      "x": -44,
      "y": 3,
      "z": 4,
      "name": "Rock_Ice"
    },
    {
      "x": -44,
      "y": 4,
      "z": 4,
      "name": "Rock_Ice"
    },
    {
      "x": -44,
      "y": 5,
      "z": 4,
      "name": "Rock_Ice"
    },
    {
      "x": -44,
      "y": 6,
      "z": 4,
      "name": "Rock_Ice"
    },
    {
      "x": -44,
      "y": 7,
      "z": 4,
      "name": "Rock_Ice_Permafrost"
    },
    {
      "x": -44,
      "y": 8,
      "z": 4,
      "name": "Soil_Snow"
    },
    {
      "x": -44,
      "y": 0,
      "z": 5,
      "name": "Rock_Ice_Permafrost"
    },
    {
      "x": -44,
      "y": 1,
      "z": 5,
      "name": "Rock_Ice"
    },
    {
      "x": -44,
      "y": 2,
      "z": 5,
      "name": "Rock_Ice"
    },
    {
      "x": -44,
      "y": 3,
      "z": 5,
      "name": "Rock_Ice"
    },
    {
      "x": -44,
      "y": 4,
      "z": 5,
      "name": "Rock_Ice"
    },
    {
      "x": -44,
      "y": 5,
      "z": 5,
      "name": "Rock_Ice"
    },
    {
      "x": -44,
      "y": 6,
      "z": 5,
      "name": "Rock_Ice"
    },
    {
      "x": -44,
      "y": 7,
      "z": 5,
      "name": "Rock_Ice_Permafrost"
    },
    {
      "x": -44,
      "y": 8,
      "z": 5,
      "name": "Soil_Snow"
    },
    {
      "x": -44,
      "y": 0,
      "z": 6,
      "name": "Rock_Ice_Permafrost"
    },
    {
      "x": -44,
      "y": 1,
      "z": 6,
      "name": "Rock_Ice"
    },
    {
      "x": -44,
      "y": 2,
      "z": 6,
      "name": "Rock_Ice"
    },
    {
      "x": -44,
      "y": 3,
      "z": 6,
      "name": "Rock_Ice"
    },
    {
      "x": -44,
      "y": 4,
      "z": 6,
      "name": "Rock_Ice"
    },
    {
      "x": -44,
      "y": 5,
      "z": 6,
      "name": "Rock_Ice"
    },
    {
      "x": -44,
      "y": 6,
      "z": 6,
      "name": "Rock_Ice"
    },
    {
      "x": -44,
      "y": 7,
      "z": 6,
      "name": "Rock_Ice"
    },
    {
      "x": -44,
      "y": 8,
      "z": 6,
      "name": "Soil_Snow"
    },
    {
      "x": -44,
      "y": 0,
      "z": 7,
      "name": "Rock_Ice_Permafrost"
    },
    {
      "x": -44,
      "y": 1,
      "z": 7,
      "name": "Rock_Ice_Permafrost"
    },
    {
      "x": -44,
      "y": 2,
      "z": 7,
      "name": "Rock_Ice"
    },
    {
      "x": -44,
      "y": 3,
      "z": 7,
      "name": "Rock_Ice"
    },
    {
      "x": -44,
      "y": 4,
      "z": 7,
      "name": "Rock_Ice"
    },
    {
      "x": -44,
      "y": 5,
      "z": 7,
      "name": "Rock_Ice"
    },
    {
      "x": -44,
      "y": 6,
      "z": 7,
      "name": "Rock_Ice"
    },
    {
      "x": -44,
      "y": 7,
      "z": 7,
      "name": "Rock_Ice"
    },
    {
      "x": -44,
      "y": 8,
      "z": 7,
      "name": "Rock_Ice"
    },
    {
      "x": -44,
      "y": 9,
      "z": 7,
      "name": "Soil_Snow"
    },
    {
      "x": -44,
      "y": 0,
      "z": 8,
      "name": "Rock_Ice"
    },
    {
      "x": -44,
      "y": 1,
      "z": 8,
      "name": "Rock_Ice_Permafrost"
    },
    {
      "x": -44,
      "y": 2,
      "z": 8,
      "name": "Rock_Ice"
    },
    {
      "x": -44,
      "y": 3,
      "z": 8,
      "name": "Rock_Ice"
    },
    {
      "x": -44,
      "y": 4,
      "z": 8,
      "name": "Rock_Ice"
    },
    {
      "x": -44,
      "y": 5,
      "z": 8,
      "name": "Rock_Ice"
    },
    {
      "x": -44,
      "y": 6,
      "z": 8,
      "name": "Rock_Ice"
    },
    {
      "x": -44,
      "y": 7,
      "z": 8,
      "name": "Rock_Ice"
    },
    {
      "x": -44,
      "y": 8,
      "z": 8,
      "name": "Rock_Ice_Permafrost"
    },
    {
      "x": -44,
      "y": 9,
      "z": 8,
      "name": "Soil_Snow"
    },
    {
      "x": -44,
      "y": 0,
      "z": 9,
      "name": "Rock_Ice"
    },
    {
      "x": -44,
      "y": 1,
      "z": 9,
      "name": "Rock_Ice_Permafrost"
    },
    {
      "x": -44,
      "y": 2,
      "z": 9,
      "name": "Rock_Ice"
    },
    {
      "x": -44,
      "y": 3,
      "z": 9,
      "name": "Rock_Ice"
    },
    {
      "x": -44,
      "y": 4,
      "z": 9,
      "name": "Rock_Ice"
    },
    {
      "x": -44,
      "y": 5,
      "z": 9,
      "name": "Rock_Ice"
    },
    {
      "x": -44,
      "y": 6,
      "z": 9,
      "name": "Rock_Ice_Permafrost"
    },
    {
      "x": -44,
      "y": 7,
      "z": 9,
      "name": "Rock_Ice_Permafrost"
    },
    {
      "x": -44,
      "y": 8,
      "z": 9,
      "name": "Rock_Ice"
    },
    {
      "x": -44,
      "y": 9,
      "z": 9,
      "name": "Soil_Snow"
    },
    {
      "x": -44,
      "y": 0,
      "z": 10,
      "name": "Rock_Ice_Permafrost"
    },
    {
      "x": -44,
      "y": 1,
      "z": 10,
      "name": "Rock_Ice"
    },
    {
      "x": -44,
      "y": 2,
      "z": 10,
      "name": "Rock_Ice_Permafrost"
    },
    {
      "x": -44,
      "y": 3,
      "z": 10,
      "name": "Rock_Ice"
    },
    {
      "x": -44,
      "y": 4,
      "z": 10,
      "name": "Rock_Ice"
    },
    {
      "x": -44,
      "y": 5,
      "z": 10,
      "name": "Rock_Ice_Permafrost"
    },
    {
      "x": -44,
      "y": 6,
      "z": 10,
      "name": "Rock_Ice_Permafrost"
    },
    {
      "x": -44,
      "y": 7,
      "z": 10,
      "name": "Rock_Ice_Permafrost"
    },
    {
      "x": -44,
      "y": 8,
      "z": 10,
      "name": "Rock_Ice_Permafrost"
    },
    {
      "x": -44,
      "y": 9,
      "z": 10,
      "name": "Soil_Snow"
    },
    {
      "x": -44,
      "y": 0,
      "z": 11,
      "name": "Rock_Ice_Permafrost"
    },
    {
      "x": -44,
      "y": 1,
      "z": 11,
      "name": "Rock_Ice_Permafrost"
    },
    {
      "x": -44,
      "y": 2,
      "z": 11,
      "name": "Rock_Ice"
    },
    {
      "x": -44,
      "y": 3,
      "z": 11,
      "name": "Rock_Ice_Permafrost"
    },
    {
      "x": -44,
      "y": 4,
      "z": 11,
      "name": "Rock_Ice"
    },
    {
      "x": -44,
      "y": 5,
      "z": 11,
      "name": "Rock_Ice"
    },
    {
      "x": -44,
      "y": 6,
      "z": 11,
      "name": "Rock_Ice_Permafrost"
    },
    {
      "x": -44,
      "y": 7,
      "z": 11,
      "name": "Rock_Ice_Permafrost"
    },
    {
      "x": -44,
      "y": 8,
      "z": 11,
      "name": "Rock_Ice_Permafrost"
    },
    {
      "x": -44,
      "y": 9,
      "z": 11,
      "name": "Soil_Snow"
    },
    {
      "x": -44,
      "y": 0,
      "z": 12,
      "name": "Rock_Ice_Permafrost"
    },
    {
      "x": -44,
      "y": 1,
      "z": 12,
      "name": "Rock_Ice_Permafrost"
    },
    {
      "x": -44,
      "y": 2,
      "z": 12,
      "name": "Rock_Ice_Permafrost"
    },
    {
      "x": -44,
      "y": 3,
      "z": 12,
      "name": "Rock_Ice"
    },
    {
      "x": -44,
      "y": 4,
      "z": 12,
      "name": "Rock_Ice_Permafrost"
    },
    {
      "x": -44,
      "y": 5,
      "z": 12,
      "name": "Rock_Ice"
    },
    {
      "x": -44,
      "y": 6,
      "z": 12,
      "name": "Rock_Ice_Permafrost"
    },
    {
      "x": -44,
      "y": 7,
      "z": 12,
      "name": "Rock_Ice_Permafrost"
    },
    {
      "x": -44,
      "y": 8,
      "z": 12,
      "name": "Rock_Ice"
    },
    {
      "x": -44,
      "y": 9,
      "z": 12,
      "name": "Soil_Snow"
    },
    {
      "x": -44,
      "y": 0,
      "z": 13,
      "name": "Rock_Ice_Permafrost"
    },
    {
      "x": -44,
      "y": 1,
      "z": 13,
      "name": "Rock_Ice_Permafrost"
    },
    {
      "x": -44,
      "y": 2,
      "z": 13,
      "name": "Rock_Ice"
    },
    {
      "x": -44,
      "y": 3,
      "z": 13,
      "name": "Rock_Ice_Permafrost"
    },
    {
      "x": -44,
      "y": 4,
      "z": 13,
      "name": "Rock_Ice"
    },
    {
      "x": -44,
      "y": 5,
      "z": 13,
      "name": "Rock_Ice_Permafrost"
    },
    {
      "x": -44,
      "y": 6,
      "z": 13,
      "name": "Rock_Ice_Permafrost"
    },
    {
      "x": -44,
      "y": 7,
      "z": 13,
      "name": "Rock_Ice_Permafrost"
    },
    {
      "x": -44,
      "y": 8,
      "z": 13,
      "name": "Rock_Ice_Permafrost"
    },
    {
      "x": -44,
      "y": 9,
      "z": 13,
      "name": "Soil_Snow"
    },
    {
      "x": -44,
      "y": 0,
      "z": 14,
      "name": "Rock_Ice_Permafrost"
    },
    {
      "x": -44,
      "y": 1,
      "z": 14,
      "name": "Rock_Ice_Permafrost"
    },
    {
      "x": -44,
      "y": 2,
      "z": 14,
      "name": "Rock_Ice_Permafrost"
    },
    {
      "x": -44,
      "y": 3,
      "z": 14,
      "name": "Rock_Ice"
    },
    {
      "x": -44,
      "y": 4,
      "z": 14,
      "name": "Rock_Ice"
    },
    {
      "x": -44,
      "y": 5,
      "z": 14,
      "name": "Rock_Ice_Permafrost"
    },
    {
      "x": -44,
      "y": 6,
      "z": 14,
      "name": "Rock_Ice_Permafrost"
    },
    {
      "x": -44,
      "y": 7,
      "z": 14,
      "name": "Rock_Ice_Permafrost"
    },
    {
      "x": -44,
      "y": 8,
      "z": 14,
      "name": "Rock_Ice"
    },
    {
      "x": -44,
      "y": 9,
      "z": 14,
      "name": "Soil_Snow"
    },
    {
      "x": -44,
      "y": 0,
      "z": 15,
      "name": "Rock_Ice_Permafrost"
    },
    {
      "x": -44,
      "y": 1,
      "z": 15,
      "name": "Rock_Ice_Permafrost"
    },
    {
      "x": -44,
      "y": 2,
      "z": 15,
      "name": "Rock_Ice_Permafrost"
    },
    {
      "x": -44,
      "y": 3,
      "z": 15,
      "name": "Rock_Ice_Permafrost"
    },
    {
      "x": -44,
      "y": 4,
      "z": 15,
      "name": "Rock_Ice_Permafrost"
    },
    {
      "x": -44,
      "y": 5,
      "z": 15,
      "name": "Rock_Ice_Permafrost"
    },
    {
      "x": -44,
      "y": 6,
      "z": 15,
      "name": "Rock_Ice_Permafrost"
    },
    {
      "x": -44,
      "y": 7,
      "z": 15,
      "name": "Rock_Ice_Permafrost"
    },
    {
      "x": -44,
      "y": 8,
      "z": 15,
      "name": "Rock_Ice"
    },
    {
      "x": -44,
      "y": 9,
      "z": 15,
      "name": "Soil_Snow"
    },
    {
      "x": -44,
      "y": 0,
      "z": 16,
      "name": "Rock_Ice_Permafrost"
    },
    {
      "x": -44,
      "y": 1,
      "z": 16,
      "name": "Rock_Ice_Permafrost"
    },
    {
      "x": -44,
      "y": 2,
      "z": 16,
      "name": "Rock_Ice_Permafrost"
    },
    {
      "x": -44,
      "y": 3,
      "z": 16,
      "name": "Rock_Ice_Permafrost"
    },
    {
      "x": -44,
      "y": 4,
      "z": 16,
      "name": "Rock_Ice_Permafrost"
    },
    {
      "x": -44,
      "y": 5,
      "z": 16,
      "name": "Rock_Ice_Permafrost"
    },
    {
      "x": -44,
      "y": 6,
      "z": 16,
      "name": "Rock_Ice_Permafrost"
    },
    {
      "x": -44,
      "y": 7,
      "z": 16,
      "name": "Rock_Ice_Permafrost"
    },
    {
      "x": -44,
      "y": 8,
      "z": 16,
      "name": "Rock_Ice"
    },
    {
      "x": -44,
      "y": 9,
      "z": 16,
      "name": "Soil_Snow"
    },
    {
      "x": -44,
      "y": 0,
      "z": 17,
      "name": "Rock_Ice_Permafrost"
    },
    {
      "x": -44,
      "y": 1,
      "z": 17,
      "name": "Rock_Ice_Permafrost"
    },
    {
      "x": -44,
      "y": 2,
      "z": 17,
      "name": "Rock_Ice_Permafrost"
    },
    {
      "x": -44,
      "y": 3,
      "z": 17,
      "name": "Rock_Ice_Permafrost"
    },
    {
      "x": -44,
      "y": 4,
      "z": 17,
      "name": "Rock_Ice_Permafrost"
    },
    {
      "x": -44,
      "y": 5,
      "z": 17,
      "name": "Rock_Ice_Permafrost"
    },
    {
      "x": -44,
      "y": 6,
      "z": 17,
      "name": "Rock_Ice_Permafrost"
    },
    {
      "x": -44,
      "y": 7,
      "z": 17,
      "name": "Rock_Ice"
    },
    {
      "x": -44,
      "y": 8,
      "z": 17,
      "name": "Rock_Ice"
    },
    {
      "x": -44,
      "y": 9,
      "z": 17,
      "name": "Rock_Ice"
    },
    {
      "x": -44,
      "y": 0,
      "z": 18,
      "name": "Rock_Ice_Permafrost"
    },
    {
      "x": -44,
      "y": 1,
      "z": 18,
      "name": "Rock_Ice_Permafrost"
    },
    {
      "x": -44,
      "y": 2,
      "z": 18,
      "name": "Rock_Ice_Permafrost"
    },
    {
      "x": -44,
      "y": 3,
      "z": 18,
      "name": "Rock_Ice_Permafrost"
    },
    {
      "x": -44,
      "y": 4,
      "z": 18,
      "name": "Rock_Ice_Permafrost"
    },
    {
      "x": -44,
      "y": 5,
      "z": 18,
      "name": "Rock_Ice_Permafrost"
    },
    {
      "x": -44,
      "y": 6,
      "z": 18,
      "name": "Rock_Ice_Permafrost"
    },
    {
      "x": -44,
      "y": 7,
      "z": 18,
      "name": "Rock_Ice"
    },
    {
      "x": -44,
      "y": 8,
      "z": 18,
      "name": "Rock_Ice"
    },
    {
      "x": -44,
      "y": 9,
      "z": 18,
      "name": "Soil_Snow"
    },
    {
      "x": -44,
      "y": 0,
      "z": 19,
      "name": "Rock_Ice_Permafrost"
    },
    {
      "x": -44,
      "y": 1,
      "z": 19,
      "name": "Rock_Ice_Permafrost"
    },
    {
      "x": -44,
      "y": 2,
      "z": 19,
      "name": "Rock_Ice_Permafrost"
    },
    {
      "x": -44,
      "y": 3,
      "z": 19,
      "name": "Rock_Ice_Permafrost"
    },
    {
      "x": -44,
      "y": 4,
      "z": 19,
      "name": "Rock_Ice_Permafrost"
    },
    {
      "x": -44,
      "y": 5,
      "z": 19,
      "name": "Rock_Ice_Permafrost"
    },
    {
      "x": -44,
      "y": 6,
      "z": 19,
      "name": "Rock_Ice"
    },
    {
      "x": -44,
      "y": 7,
      "z": 19,
      "name": "Rock_Ice_Permafrost"
    },
    {
      "x": -44,
      "y": 8,
      "z": 19,
      "name": "Rock_Ice"
    },
    {
      "x": -44,
      "y": 9,
      "z": 19,
      "name": "Soil_Snow"
    },
    {
      "x": -44,
      "y": 0,
      "z": 20,
      "name": "Rock_Ice_Permafrost"
    },
    {
      "x": -44,
      "y": 1,
      "z": 20,
      "name": "Rock_Ice_Permafrost"
    },
    {
      "x": -44,
      "y": 2,
      "z": 20,
      "name": "Rock_Ice_Permafrost"
    },
    {
      "x": -44,
      "y": 3,
      "z": 20,
      "name": "Rock_Ice_Permafrost"
    },
    {
      "x": -44,
      "y": 4,
      "z": 20,
      "name": "Rock_Ice_Permafrost"
    },
    {
      "x": -44,
      "y": 5,
      "z": 20,
      "name": "Rock_Ice_Permafrost"
    },
    {
      "x": -44,
      "y": 6,
      "z": 20,
      "name": "Rock_Ice"
    },
    {
      "x": -44,
      "y": 7,
      "z": 20,
      "name": "Rock_Ice"
    },
    {
      "x": -44,
      "y": 8,
      "z": 20,
      "name": "Rock_Ice"
    },
    {
      "x": -44,
      "y": 9,
      "z": 20,
      "name": "Soil_Snow"
    },
    {
      "x": -44,
      "y": 0,
      "z": 21,
      "name": "Rock_Ice_Permafrost"
    },
    {
      "x": -44,
      "y": 1,
      "z": 21,
      "name": "Rock_Ice_Permafrost"
    },
    {
      "x": -44,
      "y": 2,
      "z": 21,
      "name": "Rock_Ice_Permafrost"
    },
    {
      "x": -44,
      "y": 3,
      "z": 21,
      "name": "Rock_Ice_Permafrost"
    },
    {
      "x": -44,
      "y": 4,
      "z": 21,
      "name": "Rock_Ice_Permafrost"
    },
    {
      "x": -44,
      "y": 5,
      "z": 21,
      "name": "Rock_Ice_Permafrost"
    },
    {
      "x": -44,
      "y": 6,
      "z": 21,
      "name": "Rock_Ice"
    },
    {
      "x": -44,
      "y": 7,
      "z": 21,
      "name": "Rock_Ice"
    },
    {
      "x": -44,
      "y": 8,
      "z": 21,
      "name": "Rock_Ice"
    },
    {
      "x": -44,
      "y": 9,
      "z": 21,
      "name": "Soil_Snow"
    },
    {
      "x": -44,
      "y": 0,
      "z": 22,
      "name": "Rock_Ice_Permafrost"
    },
    {
      "x": -44,
      "y": 1,
      "z": 22,
      "name": "Rock_Ice_Permafrost"
    },
    {
      "x": -44,
      "y": 2,
      "z": 22,
      "name": "Rock_Ice_Permafrost"
    },
    {
      "x": -44,
      "y": 3,
      "z": 22,
      "name": "Rock_Ice_Permafrost"
    },
    {
      "x": -44,
      "y": 4,
      "z": 22,
      "name": "Rock_Ice_Permafrost"
    },
    {
      "x": -44,
      "y": 5,
      "z": 22,
      "name": "Rock_Ice_Permafrost"
    },
    {
      "x": -44,
      "y": 6,
      "z": 22,
      "name": "Rock_Ice_Permafrost"
    },
    {
      "x": -44,
      "y": 7,
      "z": 22,
      "name": "Rock_Ice"
    },
    {
      "x": -44,
      "y": 8,
      "z": 22,
      "name": "Soil_Snow"
    },
    {
      "x": -44,
      "y": 0,
      "z": 23,
      "name": "Rock_Ice_Permafrost"
    },
    {
      "x": -44,
      "y": 1,
      "z": 23,
      "name": "Rock_Ice_Permafrost"
    },
    {
      "x": -44,
      "y": 2,
      "z": 23,
      "name": "Rock_Ice_Permafrost"
    },
    {
      "x": -44,
      "y": 3,
      "z": 23,
      "name": "Rock_Ice_Permafrost"
    },
    {
      "x": -44,
      "y": 4,
      "z": 23,
      "name": "Rock_Ice_Permafrost"
    },
    {
      "x": -44,
      "y": 5,
      "z": 23,
      "name": "Rock_Ice_Permafrost"
    },
    {
      "x": -44,
      "y": 6,
      "z": 23,
      "name": "Rock_Ice_Permafrost"
    },
    {
      "x": -44,
      "y": 7,
      "z": 23,
      "name": "Rock_Ice_Permafrost"
    },
    {
      "x": -44,
      "y": 8,
      "z": 23,
      "name": "Soil_Snow"
    },
    {
      "x": -44,
      "y": 0,
      "z": 24,
      "name": "Rock_Ice_Permafrost"
    },
    {
      "x": -44,
      "y": 1,
      "z": 24,
      "name": "Rock_Ice_Permafrost"
    },
    {
      "x": -44,
      "y": 2,
      "z": 24,
      "name": "Rock_Ice_Permafrost"
    },
    {
      "x": -44,
      "y": 3,
      "z": 24,
      "name": "Rock_Ice_Permafrost"
    },
    {
      "x": -44,
      "y": 4,
      "z": 24,
      "name": "Rock_Ice_Permafrost"
    },
    {
      "x": -44,
      "y": 5,
      "z": 24,
      "name": "Rock_Ice_Permafrost"
    },
    {
      "x": -44,
      "y": 6,
      "z": 24,
      "name": "Rock_Ice"
    },
    {
      "x": -44,
      "y": 7,
      "z": 24,
      "name": "Soil_Snow"
    },
    {
      "x": -44,
      "y": 0,
      "z": 25,
      "name": "Rock_Ice_Permafrost"
    },
    {
      "x": -44,
      "y": 1,
      "z": 25,
      "name": "Rock_Ice_Permafrost"
    },
    {
      "x": -44,
      "y": 2,
      "z": 25,
      "name": "Rock_Ice_Permafrost"
    },
    {
      "x": -44,
      "y": 3,
      "z": 25,
      "name": "Rock_Ice_Permafrost"
    },
    {
      "x": -44,
      "y": 4,
      "z": 25,
      "name": "Rock_Ice_Permafrost"
    },
    {
      "x": -44,
      "y": 5,
      "z": 25,
      "name": "Rock_Ice"
    },
    {
      "x": -44,
      "y": 6,
      "z": 25,
      "name": "Soil_Snow"
    },
    {
      "x": -44,
      "y": 0,
      "z": 26,
      "name": "Rock_Ice_Permafrost"
    },
    {
      "x": -44,
      "y": 1,
      "z": 26,
      "name": "Rock_Ice_Permafrost"
    },
    {
      "x": -44,
      "y": 2,
      "z": 26,
      "name": "Rock_Ice_Permafrost"
    },
    {
      "x": -44,
      "y": 3,
      "z": 26,
      "name": "Rock_Ice_Permafrost"
    },
    {
      "x": -44,
      "y": 4,
      "z": 26,
      "name": "Rock_Ice"
    },
    {
      "x": -44,
      "y": 5,
      "z": 26,
      "name": "Soil_Snow"
    },
    {
      "x": -44,
      "y": 0,
      "z": 27,
      "name": "Rock_Ice_Permafrost"
    },
    {
      "x": -44,
      "y": 1,
      "z": 27,
      "name": "Rock_Ice_Permafrost"
    },
    {
      "x": -44,
      "y": 2,
      "z": 27,
      "name": "Rock_Ice_Permafrost"
    },
    {
      "x": -44,
      "y": 3,
      "z": 27,
      "name": "Rock_Ice"
    },
    {
      "x": -44,
      "y": 4,
      "z": 27,
      "name": "Soil_Snow"
    },
    {
      "x": -44,
      "y": 0,
      "z": 28,
      "name": "Rock_Ice"
    },
    {
      "x": -44,
      "y": 1,
      "z": 28,
      "name": "Soil_Snow"
    },
    {
      "x": -43,
      "y": 32,
      "z": -30,
      "name": "Rock_Ice_Permafrost"
    },
    {
      "x": -43,
      "y": 33,
      "z": -30,
      "name": "Rock_Ice"
    },
    {
      "x": -43,
      "y": 34,
      "z": -30,
      "name": "Soil_Snow"
    },
    {
      "x": -43,
      "y": 33,
      "z": -29,
      "name": "Rock_Ice"
    },
    {
      "x": -43,
      "y": 34,
      "z": -29,
      "name": "Rock_Ice"
    },
    {
      "x": -43,
      "y": 35,
      "z": -29,
      "name": "Rock_Ice_Permafrost"
    },
    {
      "x": -43,
      "y": 34,
      "z": -28,
      "name": "Rock_Ice"
    },
    {
      "x": -43,
      "y": 35,
      "z": -28,
      "name": "Rock_Ice"
    },
    {
      "x": -43,
      "y": 36,
      "z": -28,
      "name": "Rock_Ice"
    },
    {
      "x": -43,
      "y": 37,
      "z": -28,
      "name": "Soil_Snow"
    },
    {
      "x": -43,
      "y": 34,
      "z": -27,
      "name": "Rock_Ice"
    },
    {
      "x": -43,
      "y": 35,
      "z": -27,
      "name": "Rock_Ice"
    },
    {
      "x": -43,
      "y": 36,
      "z": -27,
      "name": "Rock_Ice"
    },
    {
      "x": -43,
      "y": 37,
      "z": -27,
      "name": "Rock_Ice"
    },
    {
      "x": -43,
      "y": 38,
      "z": -27,
      "name": "Soil_Snow"
    },
    {
      "x": -43,
      "y": 35,
      "z": -26,
      "name": "Rock_Ice"
    },
    {
      "x": -43,
      "y": 36,
      "z": -26,
      "name": "Rock_Ice"
    },
    {
      "x": -43,
      "y": 37,
      "z": -26,
      "name": "Rock_Ice"
    },
    {
      "x": -43,
      "y": 38,
      "z": -26,
      "name": "Rock_Ice_Permafrost"
    },
    {
      "x": -43,
      "y": 39,
      "z": -26,
      "name": "Rock_Ice_Permafrost"
    },
    {
      "x": -43,
      "y": 40,
      "z": -26,
      "name": "Soil_Snow"
    },
    {
      "x": -43,
      "y": 36,
      "z": -25,
      "name": "Rock_Ice"
    },
    {
      "x": -43,
      "y": 37,
      "z": -25,
      "name": "Rock_Ice"
    },
    {
      "x": -43,
      "y": 38,
      "z": -25,
      "name": "Rock_Ice"
    },
    {
      "x": -43,
      "y": 39,
      "z": -25,
      "name": "Rock_Ice_Permafrost"
    },
    {
      "x": -43,
      "y": 40,
      "z": -25,
      "name": "Rock_Ice_Permafrost"
    },
    {
      "x": -43,
      "y": 41,
      "z": -25,
      "name": "Rock_Ice_Permafrost"
    },
    {
      "x": -43,
      "y": 42,
      "z": -25,
      "name": "Soil_Snow"
    },
    {
      "x": -43,
      "y": 37,
      "z": -24,
      "name": "Rock_Ice"
    },
    {
      "x": -43,
      "y": 38,
      "z": -24,
      "name": "Rock_Ice"
    },
    {
      "x": -43,
      "y": 39,
