{
  "version": 8,
  "blockIdVersion": 11,
  "anchorX": 1,
  "anchorY": 20,
  "anchorZ": 4,
  "blocks": [
    {
      "x": -43,
      "y": 0,
      "z": -29,
      "name": "Rock_Ice"
    },
    {
      "x": -43,
      "y": 0,
      "z": -28,
      "name": "Rock_Ice"
    },
    {
      "x": -43,
      "y": 1,
      "z": -28,
      "name": "Soil_Snow"
    },
    {
      "x": -43,
      "y": 0,
      "z": -27,
      "name": "Rock_Ice"
    },
    {
      "x": -43,
      "y": 1,
      "z": -27,
      "name": "Rock_Ice"
    },
    {
      "x": -43,
      "y": 2,
      "z": -27,
      "name": "Soil_Snow"
    },
    {
      "x": -43,
      "y": 0,
      "z": -26,
      "name": "Rock_Ice"
    },
    {
      "x": -43,
      "y": 1,
      "z": -26,
      "name": "Rock_Ice"
    },
    {
      "x": -43,
      "y": 2,
      "z": -26,
      "name": "Soil_Snow"
    },
    {
      "x": -42,
      "y": 0,
      "z": -31,
      "name": "Soil_Snow"
    },
    {
      "x": -42,
      "y": 0,
      "z": -30,
      "name": "Rock_Ice"
    },
    {
      "x": -42,
      "y": 1,
      "z": -30,
      "name": "Soil_Snow"
    },
    {
      "x": -42,
      "y": 0,
      "z": -29,
      "name": "Rock_Ice"
    },
    {
      "x": -42,
      "y": 1,
      "z": -29,
      "name": "Rock_Ice_Permafrost"
    },
    {
      "x": -42,
      "y": 2,
      "z": -29,
      "name": "Rock_Ice"
    },
    {
      "x": -42,
      "y": 3,
      "z": -29,
      "name": "Soil_Snow"
    },
    {
      "x": -42,
      "y": 0,
      "z": -28,
      "name": "Rock_Ice"
    },
    {
      "x": -42,
      "y": 1,
      "z": -28,
      "name": "Rock_Ice_Permafrost"
    },
    {
      "x": -42,
      "y": 2,
      "z": -28,
      "name": "Rock_Ice"
    },
    {
      "x": -42,
      "y": 3,
      "z": -28,
      "name": "Rock_Ice"
    },
    {
      "x": -42,
      "y": 4,
      "z": -28,
      "name": "Soil_Snow"
    },
    {
      "x": -42,
      "y": 0,
      "z": -27,
      "name": "Rock_Ice"
    },
    {
      "x": -42,
      "y": 1,
      "z": -27,
      "name": "Rock_Ice"
    },
    {
      "x": -42,
      "y": 2,
      "z": -27,
      "name": "Rock_Ice"
    },
    {
      "x": -42,
      "y": 3,
      "z": -27,
      "name": "Rock_Ice"
    },
    {
      "x": -42,
      "y": 4,
      "z": -27,
      "name": "Soil_Snow"
    },
    {
      "x": -42,
      "y": 0,
      "z": -26,
      "name": "Rock_Ice"
    },
    {
      "x": -42,
      "y": 1,
      "z": -26,
      "name": "Rock_Ice"
    },
    {
      "x": -42,
      "y": 2,
      "z": -26,
      "name": "Rock_Ice"
    },
    {
      "x": -42,
      "y": 3,
      "z": -26,
      "name": "Rock_Ice"
    },
    {
      "x": -42,
      "y": 4,
      "z": -26,
      "name": "Rock_Ice"
    },
    {
      "x": -42,
      "y": 5,
      "z": -26,
      "name": "Soil_Snow"
    },
    {
      "x": -42,
      "y": 0,
      "z": -25,
      "name": "Rock_Ice"
    },
    {
      "x": -42,
      "y": 1,
      "z": -25,
      "name": "Rock_Ice"
    },
    {
      "x": -42,
      "y": 2,
      "z": -25,
      "name": "Rock_Ice"
    },
    {
      "x": -42,
      "y": 3,
      "z": -25,
      "name": "Rock_Ice"
    },
    {
      "x": -42,
      "y": 4,
      "z": -25,
      "name": "Rock_Ice"
    },
    {
      "x": -42,
      "y": 5,
      "z": -25,
      "name": "Rock_Ice"
    },
    {
      "x": -42,
      "y": 6,
      "z": -25,
      "name": "Soil_Snow"
    },
    {
      "x": -42,
      "y": 0,
      "z": -24,
      "name": "Rock_Ice"
    },
    {
      "x": -42,
      "y": 1,
      "z": -24,
      "name": "Rock_Ice"
    },
    {
      "x": -42,
      "y": 2,
      "z": -24,
      "name": "Rock_Ice"
    },
    {
      "x": -42,
      "y": 3,
      "z": -24,
      "name": "Rock_Ice"
    },
    {
      "x": -42,
      "y": 4,
      "z": -24,
      "name": "Rock_Ice"
    },
    {
      "x": -42,
      "y": 5,
      "z": -24,
      "name": "Rock_Ice"
    },
    {
      "x": -42,
      "y": 6,
      "z": -24,
      "name": "Soil_Snow"
    },
    {
      "x": -42,
      "y": 2,
      "z": -23,
      "name": "Rock_Ice"
    },
    {
      "x": -42,
      "y": 3,
      "z": -23,
      "name": "Rock_Ice_Permafrost"
    },
    {
      "x": -42,
      "y": 4,
      "z": -23,
      "name": "Rock_Ice_Permafrost"
    },
    {
      "x": -42,
      "y": 5,
      "z": -23,
      "name": "Rock_Ice"
    },
    {
      "x": -42,
      "y": 6,
      "z": -23,
      "name": "Rock_Ice"
    },
    {
      "x": -42,
      "y": 7,
      "z": -23,
      "name": "Rock_Ice_Permafrost"
    },
    {
      "x": -42,
      "y": 5,
      "z": -22,
      "name": "Rock_Ice_Permafrost"
    },
    {
      "x": -42,
      "y": 6,
      "z": -22,
      "name": "Rock_Ice"
    },
    {
      "x": -42,
      "y": 7,
      "z": -22,
      "name": "Rock_Ice"
    },
    {
      "x": -42,
      "y": 8,
      "z": -22,
      "name": "Rock_Ice"
    },
    {
      "x": -42,
      "y": 7,
      "z": -21,
      "name": "Rock_Ice_Permafrost"
    },
    {
      "x": -42,
      "y": 8,
      "z": -21,
      "name": "Rock_Ice_Permafrost"
    },
    {
      "x": -42,
      "y": 9,
      "z": -21,
      "name": "Rock_Ice"
    },
    {
      "x": -41,
      "y": 0,
      "z": -32,
      "name": "Soil_Snow"
    },
    {
      "x": -41,
      "y": 0,
      "z": -31,
      "name": "Rock_Ice_Permafrost"
    },
    {
      "x": -41,
      "y": 1,
      "z": -31,
      "name": "Rock_Ice"
    },
    {
      "x": -41,
      "y": 2,
      "z": -31,
      "name": "Soil_Snow"
    },
    {
      "x": -41,
      "y": 0,
      "z": -30,
      "name": "Rock_Ice"
    },
    {
      "x": -41,
      "y": 1,
      "z": -30,
      "name": "Rock_Ice"
    },
    {
      "x": -41,
      "y": 2,
      "z": -30,
      "name": "Rock_Ice"
    },
    {
      "x": -41,
      "y": 3,
      "z": -30,
      "name": "Rock_Ice_Permafrost"
    },
    {
      "x": -41,
      "y": 0,
      "z": -29,
      "name": "Rock_Ice"
    },
    {
      "x": -41,
      "y": 1,
      "z": -29,
      "name": "Rock_Ice_Permafrost"
    },
    {
      "x": -41,
      "y": 2,
      "z": -29,
      "name": "Rock_Ice"
    },
    {
      "x": -41,
      "y": 3,
      "z": -29,
      "name": "Rock_Ice"
    },
    {
      "x": -41,
      "y": 4,
      "z": -29,
      "name": "Rock_Ice"
    },
    {
      "x": -41,
      "y": 5,
      "z": -29,
      "name": "Soil_Snow"
    },
    {
      "x": -41,
      "y": 0,
      "z": -28,
      "name": "Rock_Ice"
    },
    {
      "x": -41,
      "y": 1,
      "z": -28,
      "name": "Rock_Ice"
    },
    {
      "x": -41,
      "y": 2,
      "z": -28,
      "name": "Rock_Ice"
    },
    {
      "x": -41,
      "y": 3,
      "z": -28,
      "name": "Rock_Ice"
    },
    {
      "x": -41,
      "y": 4,
      "z": -28,
      "name": "Rock_Ice_Permafrost"
    },
    {
      "x": -41,
      "y": 5,
      "z": -28,
      "name": "Rock_Ice"
    },
    {
      "x": -41,
      "y": 6,
      "z": -28,
      "name": "Rock_Ice_Permafrost"
    },
    {
      "x": -41,
      "y": 0,
      "z": -27,
      "name": "Rock_Ice"
    },
    {
      "x": -41,
      "y": 1,
      "z": -27,
      "name": "Rock_Ice"
    },
    {
      "x": -41,
      "y": 2,
      "z": -27,
      "name": "Rock_Ice"
    },
    {
      "x": -41,
      "y": 3,
      "z": -27,
      "name": "Rock_Ice"
    },
    {
      "x": -41,
      "y": 4,
      "z": -27,
      "name": "Rock_Ice"
    },
    {
      "x": -41,
      "y": 5,
      "z": -27,
      "name": "Rock_Ice"
    },
    {
      "x": -41,
      "y": 6,
      "z": -27,
      "name": "Rock_Ice_Permafrost"
    },
    {
      "x": -41,
      "y": 7,
      "z": -27,
      "name": "Rock_Ice"
    },
    {
      "x": -41,
      "y": 8,
      "z": -27,
      "name": "Soil_Snow"
    },
    {
      "x": -41,
      "y": 0,
      "z": -26,
      "name": "Rock_Ice"
    },
    {
      "x": -41,
      "y": 1,
      "z": -26,
      "name": "Rock_Ice"
    },
    {
      "x": -41,
      "y": 2,
      "z": -26,
      "name": "Rock_Ice"
    },
    {
      "x": -41,
      "y": 3,
      "z": -26,
      "name": "Rock_Ice"
    },
    {
      "x": -41,
      "y": 4,
      "z": -26,
      "name": "Rock_Ice"
    },
    {
      "x": -41,
      "y": 5,
      "z": -26,
      "name": "Rock_Ice"
    },
    {
      "x": -41,
      "y": 6,
      "z": -26,
      "name": "Rock_Ice"
    },
    {
      "x": -41,
      "y": 7,
      "z": -26,
      "name": "Rock_Ice_Permafrost"
    },
    {
      "x": -41,
      "y": 8,
      "z": -26,
      "name": "Rock_Ice"
    },
    {
      "x": -41,
      "y": 9,
      "z": -26,
      "name": "Soil_Snow"
    },
    {
      "x": -41,
      "y": 0,
      "z": -25,
      "name": "Rock_Ice"
    },
    {
      "x": -41,
      "y": 1,
      "z": -25,
      "name": "Rock_Ice"
    },
    {
      "x": -41,
      "y": 2,
      "z": -25,
      "name": "Rock_Ice"
    },
    {
      "x": -41,
      "y": 3,
      "z": -25,
      "name": "Rock_Ice"
    },
    {
      "x": -41,
      "y": 4,
      "z": -25,
      "name": "Rock_Ice"
    },
    {
      "x": -41,
      "y": 5,
      "z": -25,
      "name": "Rock_Ice"
    },
    {
      "x": -41,
      "y": 6,
      "z": -25,
      "name": "Rock_Ice"
    },
    {
      "x": -41,
      "y": 7,
      "z": -25,
      "name": "Soil_Snow"
    },
    {
      "x": -41,
      "y": 0,
      "z": -24,
      "name": "Rock_Ice"
    },
    {
      "x": -41,
      "y": 1,
      "z": -24,
      "name": "Rock_Ice"
    },
    {
      "x": -41,
      "y": 2,
      "z": -24,
      "name": "Rock_Ice"
    },
    {
      "x": -41,
      "y": 3,
      "z": -24,
      "name": "Rock_Ice"
    },
    {
      "x": -41,
      "y": 4,
      "z": -24,
      "name": "Rock_Ice"
    },
    {
      "x": -41,
      "y": 5,
      "z": -24,
      "name": "Rock_Ice"
    },
    {
      "x": -41,
      "y": 6,
      "z": -24,
      "name": "Rock_Ice"
    },
    {
      "x": -41,
      "y": 7,
      "z": -24,
      "name": "Rock_Ice"
    },
    {
      "x": -41,
      "y": 8,
      "z": -24,
      "name": "Soil_Snow"
    },
    {
      "x": -41,
      "y": 0,
      "z": -23,
      "name": "Rock_Ice"
    },
    {
      "x": -41,
      "y": 1,
      "z": -23,
      "name": "Rock_Ice"
    },
    {
      "x": -41,
      "y": 2,
      "z": -23,
      "name": "Rock_Ice"
    },
    {
      "x": -41,
      "y": 3,
      "z": -23,
      "name": "Rock_Ice"
    },
    {
      "x": -41,
      "y": 4,
      "z": -23,
      "name": "Rock_Ice"
    },
    {
      "x": -41,
      "y": 5,
      "z": -23,
      "name": "Rock_Ice"
    },
    {
      "x": -41,
      "y": 6,
      "z": -23,
      "name": "Rock_Ice"
    },
    {
      "x": -41,
      "y": 7,
      "z": -23,
      "name": "Rock_Ice"
    },
    {
      "x": -41,
      "y": 8,
      "z": -23,
      "name": "Rock_Ice"
    },
    {
      "x": -41,
      "y": 9,
      "z": -23,
      "name": "Rock_Ice"
    },
    {
      "x": -41,
      "y": 2,
      "z": -22,
      "name": "Rock_Ice"
    },
    {
      "x": -41,
      "y": 3,
      "z": -22,
      "name": "Rock_Ice"
    },
    {
      "x": -41,
      "y": 4,
      "z": -22,
      "name": "Rock_Ice"
    },
    {
      "x": -41,
      "y": 5,
      "z": -22,
      "name": "Rock_Ice"
    },
    {
      "x": -41,
      "y": 6,
      "z": -22,
      "name": "Rock_Ice"
    },
    {
      "x": -41,
      "y": 7,
      "z": -22,
      "name": "Rock_Ice"
    },
    {
      "x": -41,
      "y": 8,
      "z": -22,
      "name": "Rock_Ice"
    },
    {
      "x": -41,
      "y": 9,
      "z": -22,
      "name": "Rock_Ice"
    },
    {
      "x": -41,
      "y": 10,
      "z": -22,
      "name": "Rock_Ice"
    },
    {
      "x": -41,
      "y": 4,
      "z": -21,
      "name": "Rock_Ice"
    },
    {
      "x": -41,
      "y": 5,
      "z": -21,
      "name": "Rock_Ice"
    },
    {
      "x": -41,
      "y": 6,
      "z": -21,
      "name": "Rock_Ice"
    },
    {
      "x": -41,
      "y": 7,
      "z": -21,
      "name": "Rock_Ice"
    },
    {
      "x": -41,
      "y": 8,
      "z": -21,
      "name": "Rock_Ice"
    },
    {
      "x": -41,
      "y": 9,
      "z": -21,
      "name": "Rock_Ice"
    },
    {
      "x": -41,
      "y": 10,
      "z": -21,
      "name": "Rock_Ice"
    },
    {
      "x": -41,
      "y": 11,
      "z": -21,
      "name": "Rock_Ice"
    },
    {
      "x": -41,
      "y": 6,
      "z": -20,
      "name": "Rock_Ice"
    },
    {
      "x": -41,
      "y": 7,
      "z": -20,
      "name": "Rock_Ice"
    },
    {
      "x": -41,
      "y": 8,
      "z": -20,
      "name": "Rock_Ice"
    },
    {
      "x": -41,
      "y": 9,
      "z": -20,
      "name": "Rock_Ice"
    },
    {
      "x": -41,
      "y": 10,
      "z": -20,
      "name": "Rock_Ice"
    },
    {
      "x": -41,
      "y": 11,
      "z": -20,
      "name": "Rock_Ice"
    },
    {
      "x": -41,
      "y": 12,
      "z": -20,
      "name": "Rock_Ice"
    },
    {
      "x": -41,
      "y": 13,
      "z": -20,
      "name": "Rock_Ice"
    },
    {
      "x": -41,
      "y": 8,
      "z": -19,
      "name": "Rock_Ice_Permafrost"
    },
    {
      "x": -41,
      "y": 9,
      "z": -19,
      "name": "Rock_Ice_Permafrost"
    },
    {
      "x": -41,
      "y": 10,
      "z": -19,
      "name": "Rock_Ice"
    },
    {
      "x": -41,
      "y": 11,
      "z": -19,
      "name": "Rock_Ice"
    },
    {
      "x": -41,
      "y": 12,
      "z": -19,
      "name": "Rock_Ice"
    },
    {
      "x": -41,
      "y": 13,
      "z": -19,
      "name": "Rock_Ice"
    },
    {
      "x": -41,
      "y": 14,
      "z": -19,
      "name": "Rock_Ice_Permafrost"
    },
    {
      "x": -41,
      "y": 11,
      "z": -18,
      "name": "Rock_Ice_Permafrost"
    },
    {
      "x": -41,
      "y": 12,
      "z": -18,
      "name": "Rock_Ice"
    },
    {
      "x": -41,
      "y": 13,
      "z": -18,
      "name": "Rock_Ice_Permafrost"
    },
    {
      "x": -41,
      "y": 14,
      "z": -18,
      "name": "Rock_Ice_Permafrost"
    },
    {
      "x": -41,
      "y": 15,
      "z": -18,
      "name": "Rock_Ice_Permafrost"
    },
    {
      "x": -41,
      "y": 13,
      "z": -17,
      "name": "Rock_Ice"
    },
    {
      "x": -41,
      "y": 14,
      "z": -17,
      "name": "Rock_Ice_Permafrost"
    },
    {
      "x": -41,
      "y": 15,
      "z": -17,
      "name": "Rock_Ice_Permafrost"
    },
    {
      "x": -40,
      "y": 0,
      "z": -33,
      "name": "Soil_Snow"
    },
    {
      "x": -40,
      "y": 0,
      "z": -32,
      "name": "Rock_Ice_Permafrost"
    },
    {
      "x": -40,
      "y": 1,
      "z": -32,
      "name": "Soil_Snow"
    },
    {
      "x": -40,
      "y": 0,
      "z": -31,
      "name": "Rock_Ice"
    },
    {
      "x": -40,
      "y": 1,
      "z": -31,
      "name": "Rock_Ice_Permafrost"
    },
    {
      "x": -40,
      "y": 2,
      "z": -31,
      "name": "Rock_Ice_Permafrost"
    },
    {
      "x": -40,
      "y": 3,
      "z": -31,
      "name": "Soil_Snow"
    },
    {
      "x": -40,
      "y": 0,
      "z": -30,
      "name": "Rock_Ice"
    },
    {
      "x": -40,
      "y": 1,
      "z": -30,
      "name": "Rock_Ice"
    },
    {
      "x": -40,
      "y": 2,
      "z": -30,
      "name": "Rock_Ice_Permafrost"
    },
    {
      "x": -40,
      "y": 3,
      "z": -30,
      "name": "Rock_Ice"
    },
    {
      "x": -40,
      "y": 4,
      "z": -30,
      "name": "Soil_Snow"
    },
    {
      "x": -40,
      "y": 0,
      "z": -29,
      "name": "Rock_Ice"
    },
    {
      "x": -40,
      "y": 1,
      "z": -29,
      "name": "Rock_Ice"
    },
    {
      "x": -40,
      "y": 2,
      "z": -29,
      "name": "Rock_Ice"
    },
    {
      "x": -40,
      "y": 3,
      "z": -29,
      "name": "Rock_Ice_Permafrost"
    },
    {
      "x": -40,
      "y": 4,
      "z": -29,
      "name": "Rock_Ice"
    },
    {
      "x": -40,
      "y": 5,
      "z": -29,
      "name": "Rock_Ice"
    },
    {
      "x": -40,
      "y": 6,
      "z": -29,
      "name": "Soil_Snow"
    },
    {
      "x": -40,
      "y": 0,
      "z": -28,
      "name": "Rock_Ice"
    },
    {
      "x": -40,
      "y": 1,
      "z": -28,
      "name": "Rock_Ice"
    },
    {
      "x": -40,
      "y": 2,
      "z": -28,
      "name": "Rock_Ice"
    },
    {
      "x": -40,
      "y": 3,
      "z": -28,
      "name": "Rock_Ice"
    },
    {
      "x": -40,
      "y": 4,
      "z": -28,
      "name": "Rock_Ice_Permafrost"
    },
    {
      "x": -40,
      "y": 5,
      "z": -28,
      "name": "Rock_Ice_Permafrost"
    },
    {
      "x": -40,
      "y": 6,
      "z": -28,
      "name": "Rock_Ice"
    },
    {
      "x": -40,
      "y": 7,
      "z": -28,
      "name": "Rock_Ice_Permafrost"
    },
    {
      "x": -40,
      "y": 0,
      "z": -27,
      "name": "Rock_Ice"
    },
    {
      "x": -40,
      "y": 1,
      "z": -27,
      "name": "Rock_Ice"
    },
    {
      "x": -40,
      "y": 2,
      "z": -27,
      "name": "Rock_Ice"
    },
    {
      "x": -40,
      "y": 3,
      "z": -27,
      "name": "Rock_Ice"
    },
    {
      "x": -40,
      "y": 4,
      "z": -27,
      "name": "Rock_Ice"
    },
    {
      "x": -40,
      "y": 5,
      "z": -27,
      "name": "Rock_Ice"
    },
    {
      "x": -40,
      "y": 6,
      "z": -27,
      "name": "Rock_Ice_Permafrost"
    },
    {
      "x": -40,
      "y": 7,
      "z": -27,
      "name": "Rock_Ice_Permafrost"
    },
    {
      "x": -40,
      "y": 8,
      "z": -27,
      "name": "Rock_Ice"
    },
    {
      "x": -40,
      "y": 9,
      "z": -27,
      "name": "Soil_Snow"
    },
    {
      "x": -40,
      "y": 0,
      "z": -26,
      "name": "Rock_Ice"
    },
    {
      "x": -40,
      "y": 1,
      "z": -26,
      "name": "Rock_Ice"
    },
    {
      "x": -40,
      "y": 2,
      "z": -26,
      "name": "Rock_Ice"
    },
    {
      "x": -40,
      "y": 3,
      "z": -26,
      "name": "Rock_Ice"
    },
    {
      "x": -40,
      "y": 4,
      "z": -26,
      "name": "Rock_Ice"
    },
    {
      "x": -40,
      "y": 5,
      "z": -26,
      "name": "Rock_Ice"
    },
    {
      "x": -40,
      "y": 6,
      "z": -26,
      "name": "Rock_Ice"
    },
    {
      "x": -40,
      "y": 7,
      "z": -26,
      "name": "Rock_Ice"
    },
    {
      "x": -40,
      "y": 8,
      "z": -26,
      "name": "Rock_Ice_Permafrost"
    },
    {
      "x": -40,
      "y": 9,
      "z": -26,
      "name": "Rock_Ice"
    },
    {
      "x": -40,
      "y": 10,
      "z": -26,
      "name": "Rock_Ice_Permafrost"
    },
    {
      "x": -40,
      "y": 0,
      "z": -25,
      "name": "Rock_Ice"
    },
    {
      "x": -40,
      "y": 1,
      "z": -25,
      "name": "Rock_Ice"
    },
    {
      "x": -40,
      "y": 2,
      "z": -25,
      "name": "Rock_Ice"
    },
    {
      "x": -40,
      "y": 3,
      "z": -25,
      "name": "Rock_Ice"
    },
    {
      "x": -40,
      "y": 4,
      "z": -25,
      "name": "Rock_Ice"
    },
    {
      "x": -40,
      "y": 5,
      "z": -25,
      "name": "Rock_Ice"
    },
    {
      "x": -40,
      "y": 6,
      "z": -25,
      "name": "Rock_Ice"
    },
    {
      "x": -40,
      "y": 7,
      "z": -25,
      "name": "Rock_Ice"
    },
    {
      "x": -40,
      "y": 8,
      "z": -25,
      "name": "Rock_Ice"
    },
    {
      "x": -40,
      "y": 9,
      "z": -25,
      "name": "Rock_Ice"
    },
    {
      "x": -40,
      "y": 10,
      "z": -25,
      "name": "Rock_Ice"
    },
    {
      "x": -40,
      "y": 11,
      "z": -25,
      "name": "Soil_Snow"
    },
    {
      "x": -40,
      "y": 0,
      "z": -24,
      "name": "Rock_Ice"
    },
    {
      "x": -40,
      "y": 1,
      "z": -24,
      "name": "Rock_Ice"
    },
    {
      "x": -40,
      "y": 2,
      "z": -24,
      "name": "Rock_Ice"
    },
    {
      "x": -40,
      "y": 3,
      "z": -24,
      "name": "Rock_Ice"
    },
    {
      "x": -40,
      "y": 4,
      "z": -24,
      "name": "Rock_Ice"
    },
    {
      "x": -40,
      "y": 5,
      "z": -24,
      "name": "Rock_Ice"
    },
    {
      "x": -40,
      "y": 6,
      "z": -24,
      "name": "Rock_Ice"
    },
    {
      "x": -40,
      "y": 7,
      "z": -24,
      "name": "Rock_Ice"
    },
    {
      "x": -40,
      "y": 8,
      "z": -24,
      "name": "Rock_Ice"
    },
    {
      "x": -40,
      "y": 9,
      "z": -24,
      "name": "Rock_Ice"
    },
    {
      "x": -40,
      "y": 10,
      "z": -24,
      "name": "Rock_Ice"
    },
    {
      "x": -40,
      "y": 11,
      "z": -24,
      "name": "Soil_Snow"
    },
    {
      "x": -40,
      "y": 0,
      "z": -23,
      "name": "Rock_Ice"
    },
    {
      "x": -40,
      "y": 1,
      "z": -23,
      "name": "Rock_Ice"
    },
    {
      "x": -40,
      "y": 2,
      "z": -23,
      "name": "Rock_Ice"
    },
    {
      "x": -40,
      "y": 3,
      "z": -23,
      "name": "Rock_Ice"
    },
    {
      "x": -40,
      "y": 4,
      "z": -23,
      "name": "Rock_Ice"
    },
    {
      "x": -40,
      "y": 5,
      "z": -23,
      "name": "Rock_Ice"
    },
    {
      "x": -40,
      "y": 6,
      "z": -23,
      "name": "Rock_Ice"
    },
    {
      "x": -40,
      "y": 7,
      "z": -23,
      "name": "Rock_Ice"
    },
    {
      "x": -40,
      "y": 8,
      "z": -23,
      "name": "Rock_Ice"
    },
    {
      "x": -40,
      "y": 9,
      "z": -23,
      "name": "Rock_Ice"
    },
    {
      "x": -40,
      "y": 10,
      "z": -23,
      "name": "Soil_Snow"
    },
    {
      "x": -40,
      "y": 0,
      "z": -22,
      "name": "Rock_Ice"
    },
    {
      "x": -40,
      "y": 1,
      "z": -22,
      "name": "Rock_Ice"
    },
    {
      "x": -40,
      "y": 2,
      "z": -22,
      "name": "Rock_Ice"
    },
    {
      "x": -40,
      "y": 3,
      "z": -22,
      "name": "Rock_Ice"
    },
    {
      "x": -40,
      "y": 4,
      "z": -22,
      "name": "Rock_Ice"
    },
    {
      "x": -40,
      "y": 5,
      "z": -22,
      "name": "Rock_Ice"
    },
    {
      "x": -40,
      "y": 6,
      "z": -22,
      "name": "Rock_Ice"
    },
    {
      "x": -40,
      "y": 7,
      "z": -22,
      "name": "Rock_Ice"
    },
    {
      "x": -40,
      "y": 8,
      "z": -22,
      "name": "Rock_Ice"
    },
    {
      "x": -40,
      "y": 9,
      "z": -22,
      "name": "Rock_Ice"
    },
    {
      "x": -40,
      "y": 10,
      "z": -22,
      "name": "Rock_Ice"
    },
    {
      "x": -40,
      "y": 11,
      "z": -22,
      "name": "Rock_Ice"
    },
    {
      "x": -40,
      "y": 12,
      "z": -22,
      "name": "Soil_Snow"
    },
    {
      "x": -40,
      "y": 2,
      "z": -21,
      "name": "Rock_Ice"
    },
    {
      "x": -40,
      "y": 3,
      "z": -21,
      "name": "Rock_Ice"
    },
    {
      "x": -40,
      "y": 4,
      "z": -21,
      "name": "Rock_Ice"
    },
    {
      "x": -40,
      "y": 5,
      "z": -21,
      "name": "Rock_Ice"
    },
    {
      "x": -40,
      "y": 6,
      "z": -21,
      "name": "Rock_Ice"
    },
    {
      "x": -40,
      "y": 7,
      "z": -21,
      "name": "Rock_Ice"
    },
    {
      "x": -40,
      "y": 8,
      "z": -21,
      "name": "Rock_Ice"
    },
    {
      "x": -40,
      "y": 9,
      "z": -21,
      "name": "Rock_Ice"
    },
    {
      "x": -40,
      "y": 10,
      "z": -21,
      "name": "Rock_Ice"
    },
    {
      "x": -40,
      "y": 11,
      "z": -21,
      "name": "Rock_Ice"
    },
    {
      "x": -40,
      "y": 12,
      "z": -21,
      "name": "Rock_Ice"
    },
    {
      "x": -40,
      "y": 13,
      "z": -21,
      "name": "Soil_Snow"
    },
    {
      "x": -40,
      "y": 4,
      "z": -20,
      "name": "Rock_Ice"
    },
    {
      "x": -40,
      "y": 5,
      "z": -20,
      "name": "Rock_Ice"
    },
    {
      "x": -40,
      "y": 6,
      "z": -20,
      "name": "Rock_Ice"
    },
    {
      "x": -40,
      "y": 7,
      "z": -20,
      "name": "Rock_Ice"
    },
    {
      "x": -40,
      "y": 8,
      "z": -20,
      "name": "Rock_Ice"
    },
    {
      "x": -40,
      "y": 9,
      "z": -20,
      "name": "Rock_Ice"
    },
    {
      "x": -40,
      "y": 10,
      "z": -20,
      "name": "Rock_Ice"
    },
    {
      "x": -40,
      "y": 11,
      "z": -20,
      "name": "Rock_Ice"
    },
    {
      "x": -40,
      "y": 12,
      "z": -20,
      "name": "Rock_Ice"
    },
    {
      "x": -40,
      "y": 13,
      "z": -20,
      "name": "Rock_Ice"
    },
    {
      "x": -40,
      "y": 14,
      "z": -20,
      "name": "Rock_Ice"
    },
    {
      "x": -40,
      "y": 6,
      "z": -19,
      "name": "Rock_Ice"
    },
    {
      "x": -40,
      "y": 7,
      "z": -19,
      "name": "Rock_Ice"
    },
    {
      "x": -40,
      "y": 8,
      "z": -19,
      "name": "Rock_Ice"
    },
    {
      "x": -40,
      "y": 9,
      "z": -19,
      "name": "Rock_Ice"
    },
    {
      "x": -40,
      "y": 10,
      "z": -19,
      "name": "Rock_Ice"
    },
    {
      "x": -40,
      "y": 11,
      "z": -19,
      "name": "Rock_Ice"
    },
    {
      "x": -40,
      "y": 12,
      "z": -19,
      "name": "Rock_Ice"
    },
    {
      "x": -40,
      "y": 13,
      "z": -19,
      "name": "Rock_Ice"
    },
    {
      "x": -40,
      "y": 14,
      "z": -19,
      "name": "Rock_Ice"
    },
    {
      "x": -40,
      "y": 15,
      "z": -19,
      "name": "Rock_Ice"
    },
    {
      "x": -40,
      "y": 8,
      "z": -18,
      "name": "Rock_Ice"
    },
    {
      "x": -40,
      "y": 9,
      "z": -18,
      "name": "Rock_Ice"
    },
    {
      "x": -40,
      "y": 10,
      "z": -18,
      "name": "Rock_Ice"
    },
    {
      "x": -40,
      "y": 11,
      "z": -18,
      "name": "Rock_Ice"
    },
    {
      "x": -40,
      "y": 12,
      "z": -18,
      "name": "Rock_Ice"
    },
    {
      "x": -40,
      "y": 13,
      "z": -18,
      "name": "Rock_Ice"
    },
    {
      "x": -40,
      "y": 14,
      "z": -18,
      "name": "Rock_Ice"
    },
    {
      "x": -40,
      "y": 15,
      "z": -18,
      "name": "Rock_Ice"
    },
    {
      "x": -40,
      "y": 16,
      "z": -18,
      "name": "Rock_Ice"
    },
    {
      "x": -40,
      "y": 10,
      "z": -17,
      "name": "Rock_Ice"
    },
    {
      "x": -40,
      "y": 11,
      "z": -17,
      "name": "Rock_Ice"
    },
    {
      "x": -40,
      "y": 12,
      "z": -17,
      "name": "Rock_Ice"
    },
    {
      "x": -40,
      "y": 13,
      "z": -17,
      "name": "Rock_Ice"
    },
    {
      "x": -40,
      "y": 14,
      "z": -17,
      "name": "Rock_Ice"
    },
    {
      "x": -40,
      "y": 15,
      "z": -17,
      "name": "Rock_Ice"
    },
    {
      "x": -40,
      "y": 16,
      "z": -17,
      "name": "Rock_Ice"
    },
    {
      "x": -40,
      "y": 17,
      "z": -17,
      "name": "Rock_Ice"
    },
    {
      "x": -40,
      "y": 12,
      "z": -16,
      "name": "Rock_Ice"
    },
    {
      "x": -40,
      "y": 13,
      "z": -16,
      "name": "Rock_Ice"
    },
    {
      "x": -40,
      "y": 14,
      "z": -16,
      "name": "Rock_Ice"
    },
    {
      "x": -40,
      "y": 15,
      "z": -16,
      "name": "Rock_Ice"
    },
    {
      "x": -40,
      "y": 16,
      "z": -16,
      "name": "Rock_Ice"
    },
    {
      "x": -40,
      "y": 17,
      "z": -16,
      "name": "Rock_Ice"
    },
    {
      "x": -40,
      "y": 18,
      "z": -16,
      "name": "Rock_Ice"
    },
    {
      "x": -40,
      "y": 15,
      "z": -15,
      "name": "Rock_Ice"
    },
    {
      "x": -40,
      "y": 16,
      "z": -15,
      "name": "Rock_Ice"
    },
    {
      "x": -40,
      "y": 17,
      "z": -15,
      "name": "Rock_Ice"
    },
    {
      "x": -40,
      "y": 18,
      "z": -15,
      "name": "Rock_Ice"
    },
    {
      "x": -40,
      "y": 19,
      "z": -15,
      "name": "Rock_Ice"
    },
    {
      "x": -40,
      "y": 17,
      "z": -14,
      "name": "Rock_Ice"
    },
    {
      "x": -40,
      "y": 18,
      "z": -14,
      "name": "Rock_Ice_Permafrost"
    },
    {
      "x": -40,
      "y": 19,
      "z": -14,
      "name": "Rock_Ice"
    },
    {
      "x": -40,
      "y": 20,
      "z": -14,
      "name": "Rock_Ice"
    },
    {
      "x": -39,
      "y": 0,
      "z": -33,
      "name": "Rock_Ice"
    },
    {
      "x": -39,
      "y": 1,
      "z": -33,
      "name": "Soil_Snow"
    },
    {
      "x": -39,
      "y": 0,
      "z": -32,
      "name": "Rock_Ice_Permafrost"
    },
    {
      "x": -39,
      "y": 1,
      "z": -32,
      "name": "Rock_Ice"
    },
    {
      "x": -39,
      "y": 2,
      "z": -32,
      "name": "Soil_Snow"
    },
    {
      "x": -39,
      "y": 0,
      "z": -31,
      "name": "Rock_Ice"
    },
    {
      "x": -39,
      "y": 1,
      "z": -31,
      "name": "Rock_Ice_Permafrost"
    },
    {
      "x": -39,
      "y": 2,
      "z": -31,
      "name": "Rock_Ice_Permafrost"
    },
    {
      "x": -39,
      "y": 3,
      "z": -31,
      "name": "Rock_Ice"
    },
    {
      "x": -39,
      "y": 4,
      "z": -31,
      "name": "Soil_Snow"
    },
    {
      "x": -39,
      "y": 0,
      "z": -30,
      "name": "Rock_Ice"
    },
    {
      "x": -39,
      "y": 1,
      "z": -30,
      "name": "Rock_Ice"
    },
    {
      "x": -39,
      "y": 2,
      "z": -30,
      "name": "Rock_Ice_Permafrost"
    },
    {
      "x": -39,
      "y": 3,
      "z": -30,
      "name": "Rock_Ice_Permafrost"
    },
    {
      "x": -39,
      "y": 4,
      "z": -30,
      "name": "Rock_Ice"
    },
    {
      "x": -39,
      "y": 5,
      "z": -30,
      "name": "Soil_Snow"
    },
    {
      "x": -39,
      "y": 0,
      "z": -29,
      "name": "Rock_Ice"
    },
    {
      "x": -39,
      "y": 1,
      "z": -29,
      "name": "Rock_Ice"
    },
    {
      "x": -39,
      "y": 2,
      "z": -29,
      "name": "Rock_Ice"
    },
    {
      "x": -39,
      "y": 3,
      "z": -29,
      "name": "Rock_Ice"
    },
    {
      "x": -39,
      "y": 4,
      "z": -29,
      "name": "Rock_Ice_Permafrost"
    },
    {
      "x": -39,
      "y": 5,
      "z": -29,
      "name": "Rock_Ice_Permafrost"
    },
    {
      "x": -39,
      "y": 6,
      "z": -29,
      "name": "Rock_Ice_Permafrost"
    },
    {
      "x": -39,
      "y": 7,
      "z": -29,
      "name": "Soil_Snow"
    },
    {
      "x": -39,
      "y": 0,
      "z": -28,
      "name": "Rock_Ice"
    },
    {
      "x": -39,
      "y": 1,
      "z": -28,
      "name": "Rock_Ice"
    },
    {
      "x": -39,
      "y": 2,
      "z": -28,
      "name": "Rock_Ice"
    },
    {
      "x": -39,
      "y": 3,
      "z": -28,
      "name": "Rock_Ice"
    },
    {
      "x": -39,
      "y": 4,
      "z": -28,
      "name": "Rock_Ice"
    },
    {
      "x": -39,
      "y": 5,
      "z": -28,
      "name": "Rock_Ice"
    },
    {
      "x": -39,
      "y": 6,
      "z": -28,
      "name": "Rock_Ice_Permafrost"
    },
    {
      "x": -39,
      "y": 7,
      "z": -28,
      "name": "Rock_Ice"
    },
    {
      "x": -39,
      "y": 8,
      "z": -28,
      "name": "Soil_Snow"
    },
    {
      "x": -39,
      "y": 0,
      "z": -27,
      "name": "Rock_Ice"
    },
    {
      "x": -39,
      "y": 1,
      "z": -27,
      "name": "Rock_Ice"
    },
    {
      "x": -39,
      "y": 2,
      "z": -27,
      "name": "Rock_Ice"
    },
    {
      "x": -39,
      "y": 3,
      "z": -27,
      "name": "Rock_Ice"
    },
    {
      "x": -39,
      "y": 4,
      "z": -27,
      "name": "Rock_Ice"
    },
    {
      "x": -39,
      "y": 5,
      "z": -27,
      "name": "Rock_Ice"
    },
    {
      "x": -39,
      "y": 6,
      "z": -27,
      "name": "Rock_Ice"
    },
    {
      "x": -39,
      "y": 7,
      "z": -27,
      "name": "Rock_Ice"
    },
    {
      "x": -39,
      "y": 8,
      "z": -27,
      "name": "Rock_Ice"
    },
    {
      "x": -39,
      "y": 9,
      "z": -27,
      "name": "Rock_Ice_Permafrost"
    },
    {
      "x": -39,
      "y": 0,
      "z": -26,
      "name": "Rock_Ice"
    },
    {
      "x": -39,
      "y": 1,
      "z": -26,
      "name": "Rock_Ice"
    },
    {
      "x": -39,
      "y": 2,
      "z": -26,
      "name": "Rock_Ice"
    },
    {
      "x": -39,
      "y": 3,
      "z": -26,
      "name": "Rock_Ice"
    },
    {
      "x": -39,
      "y": 4,
      "z": -26,
      "name": "Rock_Ice"
    },
    {
      "x": -39,
      "y": 5,
      "z": -26,
      "name": "Rock_Ice"
    },
    {
      "x": -39,
      "y": 6,
      "z": -26,
      "name": "Rock_Ice"
    },
    {
      "x": -39,
      "y": 7,
      "z": -26,
      "name": "Rock_Ice"
    },
    {
      "x": -39,
      "y": 8,
      "z": -26,
      "name": "Rock_Ice"
    },
    {
      "x": -39,
      "y": 9,
      "z": -26,
      "name": "Rock_Ice"
    },
    {
      "x": -39,
      "y": 10,
      "z": -26,
      "name": "Rock_Ice"
    },
    {
      "x": -39,
      "y": 11,
      "z": -26,
      "name": "Soil_Snow"
    },
    {
      "x": -39,
      "y": 0,
      "z": -25,
      "name": "Rock_Ice"
    },
    {
      "x": -39,
      "y": 1,
      "z": -25,
      "name": "Rock_Ice"
    },
    {
      "x": -39,
      "y": 2,
      "z": -25,
      "name": "Rock_Ice"
    },
    {
      "x": -39,
      "y": 3,
      "z": -25,
      "name": "Rock_Ice"
    },
    {
      "x": -39,
      "y": 4,
      "z": -25,
      "name": "Rock_Ice"
    },
    {
      "x": -39,
      "y": 5,
      "z": -25,
      "name": "Rock_Ice"
    },
    {
      "x": -39,
      "y": 6,
      "z": -25,
      "name": "Rock_Ice"
    },
    {
      "x": -39,
      "y": 7,
      "z": -25,
      "name": "Rock_Ice"
    },
    {
      "x": -39,
      "y": 8,
      "z": -25,
      "name": "Rock_Ice"
    },
    {
      "x": -39,
      "y": 9,
      "z": -25,
      "name": "Rock_Ice"
    },
    {
      "x": -39,
      "y": 10,
      "z": -25,
      "name": "Rock_Ice"
    },
    {
      "x": -39,
      "y": 11,
      "z": -25,
      "name": "Rock_Ice"
    },
    {
      "x": -39,
      "y": 12,
      "z": -25,
      "name": "Rock_Ice_Permafrost"
    },
    {
      "x": -39,
      "y": 0,
      "z": -24,
      "name": "Rock_Ice"
    },
    {
      "x": -39,
      "y": 1,
      "z": -24,
      "name": "Rock_Ice"
    },
    {
      "x": -39,
      "y": 2,
      "z": -24,
      "name": "Rock_Ice"
    },
    {
      "x": -39,
      "y": 3,
      "z": -24,
      "name": "Rock_Ice"
    },
    {
      "x": -39,
      "y": 4,
      "z": -24,
      "name": "Rock_Ice"
    },
    {
      "x": -39,
      "y": 5,
      "z": -24,
      "name": "Rock_Ice"
    },
    {
      "x": -39,
      "y": 6,
      "z": -24,
      "name": "Rock_Ice"
    },
    {
      "x": -39,
      "y": 7,
      "z": -24,
      "name": "Rock_Ice"
    },
    {
      "x": -39,
      "y": 8,
      "z": -24,
      "name": "Rock_Ice"
    },
    {
      "x": -39,
      "y": 9,
      "z": -24,
      "name": "Rock_Ice"
    },
    {
      "x": -39,
      "y": 10,
      "z": -24,
      "name": "Rock_Ice"
    },
    {
      "x": -39,
      "y": 11,
      "z": -24,
      "name": "Rock_Ice"
    },
    {
      "x": -39,
      "y": 12,
      "z": -24,
      "name": "Rock_Ice"
    },
    {
      "x": -39,
      "y": 13,
      "z": -24,
      "name": "Soil_Snow"
    },
    {
      "x": -39,
      "y": 0,
      "z": -23,
      "name": "Rock_Ice"
    },
    {
      "x": -39,
      "y": 1,
      "z": -23,
      "name": "Rock_Ice"
    },
    {
      "x": -39,
      "y": 2,
      "z": -23,
      "name": "Rock_Ice"
    },
    {
      "x": -39,
      "y": 3,
      "z": -23,
      "name": "Rock_Ice"
    },
    {
      "x": -39,
      "y": 4,
      "z": -23,
      "name": "Rock_Ice"
    },
    {
      "x": -39,
      "y": 5,
      "z": -23,
      "name": "Rock_Ice"
    },
    {
      "x": -39,
      "y": 6,
      "z": -23,
      "name": "Rock_Ice"
    },
    {
      "x": -39,
      "y": 7,
      "z": -23,
      "name": "Rock_Ice"
    },
    {
      "x": -39,
      "y": 8,
      "z": -23,
      "name": "Rock_Ice"
    },
    {
      "x": -39,
      "y": 9,
      "z": -23,
      "name": "Rock_Ice"
    },
    {
      "x": -39,
      "y": 10,
      "z": -23,
      "name": "Rock_Ice"
    },
    {
      "x": -39,
      "y": 11,
      "z": -23,
      "name": "Rock_Ice"
    },
    {
      "x": -39,
      "y": 12,
      "z": -23,
      "name": "Rock_Ice"
    },
    {
      "x": -39,
      "y": 13,
      "z": -23,
      "name": "Soil_Snow"
    },
    {
      "x": -39,
      "y": 0,
      "z": -22,
      "name": "Rock_Ice"
    },
    {
      "x": -39,
      "y": 1,
      "z": -22,
      "name": "Rock_Ice"
    },
    {
      "x": -39,
      "y": 2,
      "z": -22,
      "name": "Rock_Ice"
    },
    {
      "x": -39,
      "y": 3,
      "z": -22,
      "name": "Rock_Ice"
    },
    {
      "x": -39,
      "y": 4,
      "z": -22,
      "name": "Rock_Ice"
    },
    {
      "x": -39,
      "y": 5,
      "z": -22,
      "name": "Rock_Ice"
    },
    {
      "x": -39,
      "y": 6,
      "z": -22,
      "name": "Rock_Ice"
    },
    {
      "x": -39,
      "y": 7,
      "z": -22,
      "name": "Rock_Ice"
    },
    {
      "x": -39,
      "y": 8,
      "z": -22,
      "name": "Rock_Ice"
    },
    {
      "x": -39,
      "y": 9,
      "z": -22,
      "name": "Rock_Ice"
    },
    {
      "x": -39,
      "y": 10,
      "z": -22,
      "name": "Rock_Ice"
    },
    {
      "x": -39,
      "y": 11,
      "z": -22,
      "name": "Rock_Ice"
    },
    {
      "x": -39,
      "y": 12,
      "z": -22,
      "name": "Rock_Ice"
    },
    {
      "x": -39,
      "y": 13,
      "z": -22,
      "name": "Soil_Snow"
    },
    {
      "x": -39,
      "y": 0,
      "z": -21,
      "name": "Rock_Ice"
    },
    {
      "x": -39,
      "y": 1,
      "z": -21,
      "name": "Rock_Ice"
    },
    {
      "x": -39,
      "y": 2,
      "z": -21,
      "name": "Rock_Ice"
    },
    {
      "x": -39,
      "y": 3,
      "z": -21,
      "name": "Rock_Ice"
    },
    {
      "x": -39,
      "y": 4,
      "z": -21,
      "name": "Rock_Ice"
    },
    {
      "x": -39,
      "y": 5,
      "z": -21,
      "name": "Rock_Ice"
    },
    {
      "x": -39,
      "y": 6,
      "z": -21,
      "name": "Rock_Ice"
    },
    {
      "x": -39,
      "y": 7,
      "z": -21,
      "name": "Rock_Ice"
    },
    {
      "x": -39,
      "y": 8,
      "z": -21,
      "name": "Rock_Ice"
    },
    {
      "x": -39,
      "y": 9,
      "z": -21,
      "name": "Rock_Ice"
    },
    {
      "x": -39,
      "y": 10,
      "z": -21,
      "name": "Rock_Ice"
    },
    {
      "x": -39,
      "y": 11,
      "z": -21,
      "name": "Rock_Ice"
    },
    {
      "x": -39,
      "y": 12,
      "z": -21,
      "name": "Rock_Ice"
    },
    {
      "x": -39,
      "y": 13,
      "z": -21,
      "name": "Rock_Ice"
    },
    {
      "x": -39,
      "y": 14,
      "z": -21,
      "name": "Soil_Snow"
    },
    {
      "x": -39,
      "y": 2,
      "z": -20,
      "name": "Rock_Ice"
    },
    {
      "x": -39,
      "y": 3,
      "z": -20,
      "name": "Rock_Ice"
    },
    {
      "x": -39,
      "y": 4,
      "z": -20,
      "name": "Rock_Ice"
    },
    {
      "x": -39,
      "y": 5,
      "z": -20,
      "name": "Rock_Ice"
    },
    {
      "x": -39,
      "y": 6,
      "z": -20,
      "name": "Rock_Ice"
    },
    {
      "x": -39,
      "y": 7,
      "z": -20,
      "name": "Rock_Ice"
    },
    {
      "x": -39,
      "y": 8,
      "z": -20,
      "name": "Rock_Ice"
    },
    {
      "x": -39,
      "y": 9,
      "z": -20,
      "name": "Rock_Ice"
    },
    {
      "x": -39,
      "y": 10,
      "z": -20,
      "name": "Rock_Ice"
    },
    {
      "x": -39,
      "y": 11,
      "z": -20,
      "name": "Rock_Ice"
    },
    {
      "x": -39,
      "y": 12,
      "z": -20,
      "name": "Rock_Ice"
    },
    {
      "x": -39,
      "y": 13,
      "z": -20,
      "name": "Rock_Ice"
    },
    {
      "x": -39,
      "y": 14,
      "z": -20,
      "name": "Rock_Ice"
    },
    {
      "x": -39,
      "y": 15,
      "z": -20,
      "name": "Soil_Snow"
    },
    {
      "x": -39,
      "y": 4,
      "z": -19,
      "name": "Rock_Ice"
    },
    {
      "x": -39,
      "y": 5,
      "z": -19,
      "name": "Rock_Ice"
    },
    {
      "x": -39,
      "y": 6,
      "z": -19,
      "name": "Rock_Ice"
    },
    {
      "x": -39,
      "y": 7,
      "z": -19,
      "name": "Rock_Ice"
    },
    {
      "x": -39,
      "y": 8,
      "z": -19,
      "name": "Rock_Ice"
    },
    {
      "x": -39,
      "y": 9,
      "z": -19,
      "name": "Rock_Ice"
    },
    {
      "x": -39,
      "y": 10,
      "z": -19,
      "name": "Rock_Ice"
    },
    {
      "x": -39,
      "y": 11,
      "z": -19,
      "name": "Rock_Ice"
    },
    {
      "x": -39,
      "y": 12,
      "z": -19,
      "name": "Rock_Ice"
    },
    {
      "x": -39,
      "y": 13,
      "z": -19,
      "name": "Rock_Ice"
    },
    {
      "x": -39,
      "y": 14,
      "z": -19,
      "name": "Rock_Ice"
    },
    {
      "x": -39,
      "y": 15,
      "z": -19,
      "name": "Rock_Ice"
    },
    {
      "x": -39,
      "y": 16,
      "z": -19,
      "name": "Soil_Snow"
    },
    {
      "x": -39,
      "y": 6,
      "z": -18,
      "name": "Rock_Ice"
    },
    {
      "x": -39,
      "y": 7,
      "z": -18,
      "name": "Rock_Ice"
    },
    {
      "x": -39,
      "y": 8,
      "z": -18,
      "name": "Rock_Ice"
    },
    {
      "x": -39,
      "y": 9,
      "z": -18,
      "name": "Rock_Ice"
    },
    {
      "x": -39,
      "y": 10,
      "z": -18,
      "name": "Rock_Ice"
    },
    {
      "x": -39,
      "y": 11,
      "z": -18,
      "name": "Rock_Ice"
    },
    {
      "x": -39,
      "y": 12,
      "z": -18,
      "name": "Rock_Ice"
    },
    {
      "x": -39,
      "y": 13,
      "z": -18,
      "name": "Rock_Ice"
    },
    {
      "x": -39,
      "y": 14,
      "z": -18,
      "name": "Rock_Ice"
    },
    {
      "x": -39,
      "y": 15,
      "z": -18,
      "name": "Rock_Ice"
    },
    {
      "x": -39,
      "y": 16,
      "z": -18,
      "name": "Rock_Ice"
    },
    {
      "x": -39,
      "y": 17,
      "z": -18,
      "name": "Rock_Ice"
    },
    {
      "x": -39,
      "y": 18,
      "z": -18,
      "name": "Soil_Snow"
    },
    {
      "x": -39,
      "y": 8,
      "z": -17,
      "name": "Rock_Ice"
    },
    {
      "x": -39,
      "y": 9,
      "z": -17,
      "name": "Rock_Ice"
    },
    {
      "x": -39,
      "y": 10,
      "z": -17,
      "name": "Rock_Ice"
    },
    {
      "x": -39,
      "y": 11,
      "z": -17,
      "name": "Rock_Ice"
    },
    {
      "x": -39,
      "y": 12,
      "z": -17,
      "name": "Rock_Ice"
    },
    {
      "x": -39,
      "y": 13,
      "z": -17,
      "name": "Rock_Ice"
    },
    {
      "x": -39,
      "y": 14,
      "z": -17,
      "name": "Rock_Ice"
    },
    {
      "x": -39,
      "y": 15,
      "z": -17,
      "name": "Rock_Ice"
    },
    {
      "x": -39,
      "y": 16,
      "z": -17,
      "name": "Rock_Ice"
    },
    {
      "x": -39,
      "y": 17,
      "z": -17,
      "name": "Rock_Ice"
    },
    {
      "x": -39,
      "y": 18,
      "z": -17,
      "name": "Rock_Ice"
    },
    {
      "x": -39,
      "y": 19,
      "z": -17,
      "name": "Soil_Snow"
    },
    {
      "x": -39,
      "y": 10,
      "z": -16,
      "name": "Rock_Ice"
    },
    {
      "x": -39,
      "y": 11,
      "z": -16,
      "name": "Rock_Ice"
    },
    {
      "x": -39,
      "y": 12,
      "z": -16,
      "name": "Rock_Ice"
    },
    {
      "x": -39,
      "y": 13,
      "z": -16,
      "name": "Rock_Ice"
    },
    {
      "x": -39,
      "y": 14,
      "z": -16,
      "name": "Rock_Ice"
    },
    {
      "x": -39,
      "y": 15,
      "z": -16,
      "name": "Rock_Ice"
    },
    {
      "x": -39,
      "y": 16,
      "z": -16,
      "name": "Rock_Ice"
    },
    {
      "x": -39,
      "y": 17,
      "z": -16,
      "name": "Rock_Ice"
    },
    {
      "x": -39,
      "y": 18,
      "z": -16,
      "name": "Rock_Ice"
    },
    {
      "x": -39,
      "y": 19,
      "z": -16,
      "name": "Rock_Ice"
    },
    {
      "x": -39,
      "y": 20,
      "z": -16,
      "name": "Soil_Snow"
    },
    {
      "x": -39,
      "y": 12,
      "z": -15,
      "name": "Rock_Ice"
    },
    {
      "x": -39,
      "y": 13,
      "z": -15,
      "name": "Rock_Ice"
    },
    {
      "x": -39,
      "y": 14,
      "z": -15,
      "name": "Rock_Ice"
    },
    {
      "x": -39,
      "y": 15,
      "z": -15,
      "name": "Rock_Ice"
    },
    {
      "x": -39,
      "y": 16,
      "z": -15,
      "name": "Rock_Ice"
    },
    {
      "x": -39,
      "y": 17,
      "z": -15,
      "name": "Rock_Ice"
    },
    {
      "x": -39,
      "y": 18,
      "z": -15,
      "name": "Rock_Ice"
    },
    {
      "x": -39,
      "y": 19,
      "z": -15,
      "name": "Rock_Ice"
    },
    {
      "x": -39,
      "y": 20,
      "z": -15,
      "name": "Rock_Ice"
    },
    {
      "x": -39,
      "y": 21,
      "z": -15,
      "name": "Soil_Snow"
    },
    {
      "x": -39,
      "y": 15,
      "z": -14,
      "name": "Rock_Ice"
    },
    {
      "x": -39,
      "y": 16,
      "z": -14,
      "name": "Rock_Ice"
    },
    {
      "x": -39,
      "y": 17,
      "z": -14,
      "name": "Rock_Ice"
    },
    {
      "x": -39,
      "y": 18,
      "z": -14,
      "name": "Rock_Ice"
    },
    {
      "x": -39,
      "y": 19,
      "z": -14,
      "name": "Rock_Ice"
    },
    {
      "x": -39,
      "y": 20,
      "z": -14,
      "name": "Rock_Ice"
    },
    {
      "x": -39,
      "y": 21,
      "z": -14,
      "name": "Rock_Ice"
    },
    {
      "x": -39,
      "y": 22,
      "z": -14,
      "name": "Rock_Ice"
    },
    {
      "x": -39,
      "y": 17,
      "z": -13,
      "name": "Rock_Ice"
    },
    {
      "x": -39,
      "y": 18,
      "z": -13,
      "name": "Rock_Ice"
    },
    {
      "x": -39,
      "y": 19,
      "z": -13,
      "name": "Rock_Ice"
    },
    {
      "x": -39,
      "y": 20,
      "z": -13,
      "name": "Rock_Ice"
    },
    {
      "x": -39,
      "y": 21,
      "z": -13,
      "name": "Rock_Ice"
    },
    {
      "x": -39,
      "y": 22,
      "z": -13,
      "name": "Rock_Ice"
    },
    {
      "x": -39,
      "y": 23,
      "z": -13,
      "name": "Rock_Ice"
    },
    {
      "x": -39,
      "y": 19,
      "z": -12,
      "name": "Rock_Ice_Permafrost"
    },
    {
      "x": -39,
      "y": 20,
      "z": -12,
      "name": "Rock_Ice"
    },
    {
      "x": -39,
      "y": 21,
      "z": -12,
      "name": "Rock_Ice"
    },
    {
      "x": -39,
      "y": 22,
      "z": -12,
      "name": "Rock_Ice"
    },
    {
      "x": -39,
      "y": 23,
      "z": -12,
      "name": "Rock_Ice"
    },
    {
      "x": -39,
      "y": 24,
      "z": -12,
      "name": "Rock_Ice"
    },
    {
      "x": -39,
      "y": 22,
      "z": -11,
      "name": "Rock_Ice"
    },
    {
      "x": -39,
      "y": 23,
      "z": -11,
      "name": "Rock_Ice"
    },
    {
      "x": -39,
      "y": 24,
      "z": -11,
      "name": "Rock_Ice_Permafrost"
    },
    {
      "x": -38,
      "y": 0,
      "z": -34,
      "name": "Soil_Snow"
    },
    {
      "x": -38,
      "y": 0,
      "z": -33,
      "name": "Rock_Ice"
    },
    {
      "x": -38,
      "y": 1,
      "z": -33,
      "name": "Soil_Snow"
    },
    {
      "x": -38,
      "y": 0,
      "z": -32,
      "name": "Rock_Ice"
    },
    {
      "x": -38,
      "y": 1,
      "z": -32,
      "name": "Rock_Ice_Permafrost"
    },
    {
      "x": -38,
      "y": 2,
      "z": -32,
      "name": "Rock_Ice"
    },
    {
      "x": -38,
      "y": 3,
      "z": -32,
      "name": "Soil_Snow"
    },
    {
      "x": -38,
      "y": 0,
      "z": -31,
      "name": "Rock_Ice"
    },
    {
      "x": -38,
      "y": 1,
      "z": -31,
      "name": "Rock_Ice_Permafrost"
    },
    {
      "x": -38,
      "y": 2,
      "z": -31,
      "name": "Rock_Ice_Permafrost"
    },
    {
      "x": -38,
      "y": 3,
      "z": -31,
      "name": "Rock_Ice_Permafrost"
    },
    {
      "x": -38,
      "y": 4,
      "z": -31,
      "name": "Soil_Snow"
    },
    {
      "x": -38,
      "y": 0,
      "z": -30,
      "name": "Rock_Ice"
    },
    {
      "x": -38,
      "y": 1,
      "z": -30,
      "name": "Rock_Ice"
    },
    {
      "x": -38,
      "y": 2,
      "z": -30,
      "name": "Rock_Ice"
    },
    {
      "x": -38,
      "y": 3,
      "z": -30,
      "name": "Rock_Ice"
    },
    {
      "x": -38,
      "y": 4,
      "z": -30,
      "name": "Rock_Ice_Permafrost"
    },
    {
      "x": -38,
      "y": 5,
      "z": -30,
      "name": "Rock_Ice"
    },
    {
      "x": -38,
      "y": 6,
      "z": -30,
      "name": "Soil_Snow"
    },
    {
      "x": -38,
      "y": 0,
      "z": -29,
      "name": "Rock_Ice"
    },
    {
      "x": -38,
      "y": 1,
      "z": -29,
      "name": "Rock_Ice"
    },
    {
      "x": -38,
      "y": 2,
      "z": -29,
      "name": "Rock_Ice"
    },
    {
      "x": -38,
      "y": 3,
      "z": -29,
      "name": "Rock_Ice"
    },
    {
      "x": -38,
      "y": 4,
      "z": -29,
      "name": "Rock_Ice_Permafrost"
    },
    {
      "x": -38,
      "y": 5,
      "z": -29,
      "name": "Rock_Ice_Permafrost"
    },
    {
      "x": -38,
      "y": 6,
      "z": -29,
      "name": "Rock_Ice"
    },
    {
      "x": -38,
      "y": 7,
      "z": -29,
      "name": "Soil_Snow"
    },
    {
      "x": -38,
      "y": 0,
      "z": -28,
      "name": "Rock_Ice"
    },
    {
      "x": -38,
      "y": 1,
      "z": -28,
      "name": "Rock_Ice"
    },
    {
      "x": -38,
      "y": 2,
      "z": -28,
      "name": "Rock_Ice"
    },
    {
      "x": -38,
      "y": 3,
      "z": -28,
      "name": "Rock_Ice"
    },
    {
      "x": -38,
      "y": 4,
      "z": -28,
      "name": "Rock_Ice"
    },
    {
      "x": -38,
      "y": 5,
      "z": -28,
      "name": "Rock_Ice"
    },
    {
      "x": -38,
      "y": 6,
      "z": -28,
      "name": "Rock_Ice_Permafrost"
    },
    {
      "x": -38,
      "y": 7,
      "z": -28,
      "name": "Rock_Ice"
    },
    {
      "x": -38,
      "y": 8,
      "z": -28,
      "name": "Rock_Ice_Permafrost"
    },
    {
      "x": -38,
      "y": 9,
      "z": -28,
      "name": "Soil_Snow"
    },
    {
      "x": -38,
      "y": 0,
      "z": -27,
      "name": "Rock_Ice"
    },
    {
      "x": -38,
      "y": 1,
      "z": -27,
      "name": "Rock_Ice"
    },
    {
      "x": -38,
      "y": 2,
      "z": -27,
      "name": "Rock_Ice"
    },
    {
      "x": -38,
      "y": 3,
      "z": -27,
      "name": "Rock_Ice"
    },
    {
      "x": -38,
      "y": 4,
      "z": -27,
      "name": "Rock_Ice"
    },
    {
      "x": -38,
      "y": 5,
      "z": -27,
      "name": "Rock_Ice"
    },
    {
      "x": -38,
      "y": 6,
      "z": -27,
      "name": "Rock_Ice"
    },
    {
      "x": -38,
      "y": 7,
      "z": -27,
      "name": "Rock_Ice"
    },
    {
      "x": -38,
      "y": 8,
      "z": -27,
      "name": "Rock_Ice"
    },
    {
      "x": -38,
      "y": 9,
      "z": -27,
      "name": "Rock_Ice"
    },
    {
      "x": -38,
      "y": 10,
      "z": -27,
      "name": "Soil_Snow"
    },
    {
      "x": -38,
      "y": 0,
      "z": -26,
      "name": "Rock_Ice"
    },
    {
      "x": -38,
      "y": 1,
      "z": -26,
      "name": "Rock_Ice"
    },
    {
      "x": -38,
      "y": 2,
      "z": -26,
      "name": "Rock_Ice"
    },
    {
      "x": -38,
      "y": 3,
      "z": -26,
      "name": "Rock_Ice"
    },
    {
      "x": -38,
      "y": 4,
      "z": -26,
      "name": "Rock_Ice"
    },
    {
      "x": -38,
      "y": 5,
      "z": -26,
      "name": "Rock_Ice"
    },
    {
      "x": -38,
      "y": 6,
      "z": -26,
      "name": "Rock_Ice"
    },
    {
      "x": -38,
      "y": 7,
      "z": -26,
      "name": "Rock_Ice"
    },
    {
      "x": -38,
      "y": 8,
      "z": -26,
      "name": "Rock_Ice"
    },
    {
      "x": -38,
      "y": 9,
      "z": -26,
      "name": "Rock_Ice_Permafrost"
    },
    {
      "x": -38,
      "y": 10,
      "z": -26,
      "name": "Rock_Ice"
    },
    {
      "x": -38,
      "y": 11,
      "z": -26,
      "name": "Rock_Ice_Permafrost"
    },
    {
      "x": -38,
      "y": 0,
      "z": -25,
      "name": "Rock_Ice"
    },
    {
      "x": -38,
      "y": 1,
      "z": -25,
      "name": "Rock_Ice"
    },
    {
      "x": -38,
      "y": 2,
      "z": -25,
      "name": "Rock_Ice"
    },
    {
      "x": -38,
      "y": 3,
      "z": -25,
      "name": "Rock_Ice"
    },
    {
      "x": -38,
      "y": 4,
      "z": -25,
      "name": "Rock_Ice"
    },
    {
      "x": -38,
      "y": 5,
      "z": -25,
      "name": "Rock_Ice"
    },
    {
      "x": -38,
      "y": 6,
      "z": -25,
      "name": "Rock_Ice"
    },
    {
      "x": -38,
      "y": 7,
      "z": -25,
      "name": "Rock_Ice"
    },
    {
      "x": -38,
      "y": 8,
      "z": -25,
      "name": "Rock_Ice"
    },
    {
      "x": -38,
      "y": 9,
      "z": -25,
      "name": "Rock_Ice"
    },
    {
      "x": -38,
      "y": 10,
      "z": -25,
      "name": "Rock_Ice"
    },
    {
      "x": -38,
      "y": 11,
      "z": -25,
      "name": "Rock_Ice"
    },
    {
      "x": -38,
      "y": 12,
      "z": -25,
      "name": "Rock_Ice"
    },
    {
      "x": -38,
      "y": 13,
      "z": -25,
      "name": "Soil_Snow"
    },
    {
      "x": -38,
      "y": 0,
      "z": -24,
      "name": "Rock_Ice"
    },
    {
      "x": -38,
      "y": 1,
      "z": -24,
      "name": "Rock_Ice"
    },
    {
      "x": -38,
      "y": 2,
      "z": -24,
      "name": "Rock_Ice"
    },
    {
      "x": -38,
      "y": 3,
      "z": -24,
      "name": "Rock_Ice"
    },
    {
      "x": -38,
      "y": 4,
      "z": -24,
      "name": "Rock_Ice"
    },
    {
      "x": -38,
      "y": 5,
      "z": -24,
      "name": "Rock_Ice"
    },
    {
      "x": -38,
      "y": 6,
      "z": -24,
      "name": "Rock_Ice"
    },
    {
      "x": -38,
      "y": 7,
      "z": -24,
      "name": "Rock_Ice"
    },
    {
      "x": -38,
      "y": 8,
      "z": -24,
      "name": "Rock_Ice"
    },
    {
      "x": -38,
      "y": 9,
      "z": -24,
      "name": "Rock_Ice"
    },
    {
      "x": -38,
      "y": 10,
      "z": -24,
      "name": "Rock_Ice"
    },
    {
      "x": -38,
      "y": 11,
      "z": -24,
      "name": "Rock_Ice"
    },
    {
      "x": -38,
      "y": 12,
      "z": -24,
      "name": "Rock_Ice_Permafrost"
    },
    {
      "x": -38,
      "y": 13,
      "z": -24,
      "name": "Rock_Ice"
    },
    {
      "x": -38,
      "y": 14,
      "z": -24,
      "name": "Rock_Ice_Permafrost"
    },
    {
      "x": -38,
      "y": 0,
      "z": -23,
      "name": "Rock_Ice"
    },
    {
      "x": -38,
      "y": 1,
      "z": -23,
      "name": "Rock_Ice"
    },
    {
      "x": -38,
      "y": 2,
      "z": -23,
      "name": "Rock_Ice"
    },
    {
      "x": -38,
      "y": 3,
      "z": -23,
      "name": "Rock_Ice"
    },
    {
      "x": -38,
      "y": 4,
      "z": -23,
      "name": "Rock_Ice"
    },
    {
      "x": -38,
      "y": 5,
      "z": -23,
      "name": "Rock_Ice"
    },
    {
      "x": -38,
      "y": 6,
      "z": -23,
      "name": "Rock_Ice"
    },
    {
      "x": -38,
      "y": 7,
      "z": -23,
      "name": "Rock_Ice"
    },
    {
      "x": -38,
      "y": 8,
      "z": -23,
      "name": "Rock_Ice"
    },
    {
      "x": -38,
      "y": 9,
      "z": -23,
      "name": "Rock_Ice"
    },
    {
      "x": -38,
      "y": 10,
      "z": -23,
      "name": "Rock_Ice"
    },
    {
      "x": -38,
      "y": 11,
      "z": -23,
      "name": "Rock_Ice"
    },
    {
      "x": -38,
      "y": 12,
      "z": -23,
      "name": "Rock_Ice"
    },
    {
      "x": -38,
      "y": 13,
      "z": -23,
      "name": "Rock_Ice"
    },
    {
      "x": -38,
      "y": 14,
      "z": -23,
      "name": "Rock_Ice"
    },
    {
      "x": -38,
      "y": 15,
      "z": -23,
      "name": "Soil_Snow"
    },
    {
      "x": -38,
      "y": 0,
      "z": -22,
      "name": "Rock_Ice"
    },
    {
      "x": -38,
      "y": 1,
      "z": -22,
      "name": "Rock_Ice"
    },
    {
      "x": -38,
      "y": 2,
      "z": -22,
      "name": "Rock_Ice"
    },
    {
      "x": -38,
      "y": 3,
      "z": -22,
      "name": "Rock_Ice"
    },
    {
      "x": -38,
      "y": 4,
      "z": -22,
      "name": "Rock_Ice"
    },
    {
      "x": -38,
      "y": 5,
      "z": -22,
      "name": "Rock_Ice"
    },
    {
      "x": -38,
      "y": 6,
      "z": -22,
      "name": "Rock_Ice"
    },
    {
      "x": -38,
      "y": 7,
      "z": -22,
      "name": "Rock_Ice"
    },
    {
      "x": -38,
      "y": 8,
      "z": -22,
      "name": "Rock_Ice"
    },
    {
      "x": -38,
      "y": 9,
      "z": -22,
      "name": "Rock_Ice"
    },
    {
      "x": -38,
      "y": 10,
      "z": -22,
      "name": "Rock_Ice"
    },
    {
      "x": -38,
      "y": 11,
      "z": -22,
      "name": "Rock_Ice"
    },
    {
      "x": -38,
      "y": 12,
      "z": -22,
      "name": "Rock_Ice"
    },
    {
      "x": -38,
      "y": 13,
      "z": -22,
      "name": "Rock_Ice"
    },
    {
      "x": -38,
      "y": 14,
      "z": -22,
      "name": "Rock_Ice"
    },
    {
      "x": -38,
      "y": 15,
      "z": -22,
      "name": "Soil_Snow"
    },
    {
      "x": -38,
      "y": 0,
      "z": -21,
      "name": "Rock_Ice"
    },
    {
      "x": -38,
      "y": 1,
      "z": -21,
      "name": "Rock_Ice"
    },
    {
      "x": -38,
      "y": 2,
      "z": -21,
      "name": "Rock_Ice"
    },
    {
      "x": -38,
      "y": 3,
      "z": -21,
      "name": "Rock_Ice"
    },
    {
      "x": -38,
      "y": 4,
      "z": -21,
      "name": "Rock_Ice"
    },
    {
      "x": -38,
      "y": 5,
      "z": -21,
      "name": "Rock_Ice"
    },
    {
      "x": -38,
      "y": 6,
      "z": -21,
      "name": "Rock_Ice"
    },
    {
      "x": -38,
      "y": 7,
      "z": -21,
      "name": "Rock_Ice"
    },
    {
      "x": -38,
      "y": 8,
      "z": -21,
      "name": "Rock_Ice"
    },
    {
      "x": -38,
      "y": 9,
      "z": -21,
      "name": "Rock_Ice"
    },
    {
      "x": -38,
      "y": 10,
      "z": -21,
      "name": "Rock_Ice"
    },
    {
      "x": -38,
      "y": 11,
      "z": -21,
      "name": "Rock_Ice"
    },
    {
      "x": -38,
      "y": 12,
      "z": -21,
      "name": "Rock_Ice"
    },
    {
      "x": -38,
      "y": 13,
      "z": -21,
      "name": "Rock_Ice"
    },
    {
      "x": -38,
      "y": 14,
      "z": -21,
      "name": "Rock_Ice"
    },
    {
      "x": -38,
      "y": 15,
      "z": -21,
      "name": "Rock_Ice"
    },
    {
      "x": -38,
      "y": 16,
      "z": -21,
      "name": "Soil_Snow"
    },
    {
      "x": -38,
      "y": 0,
      "z": -20,
      "name": "Rock_Ice"
    },
    {
      "x": -38,
      "y": 1,
      "z": -20,
      "name": "Rock_Ice"
    },
    {
      "x": -38,
      "y": 2,
      "z": -20,
      "name": "Rock_Ice"
    },
    {
      "x": -38,
      "y": 3,
      "z": -20,
      "name": "Rock_Ice"
    },
    {
      "x": -38,
      "y": 4,
      "z": -20,
      "name": "Rock_Ice"
    },
    {
      "x": -38,
      "y": 5,
      "z": -20,
      "name": "Rock_Ice"
    },
    {
      "x": -38,
      "y": 6,
      "z": -20,
      "name": "Rock_Ice"
    },
    {
      "x": -38,
      "y": 7,
      "z": -20,
      "name": "Rock_Ice"
    },
    {
      "x": -38,
      "y": 8,
      "z": -20,
      "name": "Rock_Ice"
    },
    {
      "x": -38,
      "y": 9,
      "z": -20,
      "name": "Rock_Ice"
    },
    {
      "x": -38,
      "y": 10,
      "z": -20,
      "name": "Rock_Ice"
    },
    {
      "x": -38,
      "y": 11,
      "z": -20,
      "name": "Rock_Ice"
    },
    {
      "x": -38,
      "y": 12,
      "z": -20,
      "name": "Rock_Ice"
    },
    {
      "x": -38,
      "y": 13,
      "z": -20,
      "name": "Rock_Ice"
    },
    {
      "x": -38,
      "y": 14,
      "z": -20,
      "name": "Rock_Ice"
    },
    {
      "x": -38,
      "y": 15,
      "z": -20,
      "name": "Rock_Ice"
    },
    {
      "x": -38,
      "y": 16,
      "z": -20,
      "name": "Rock_Ice"
    },
    {
      "x": -38,
      "y": 17,
      "z": -20,
      "name": "Soil_Snow"
    },
    {
      "x": -38,
      "y": 1,
      "z": -19,
      "name": "Rock_Ice"
    },
    {
      "x": -38,
      "y": 2,
      "z": -19,
      "name": "Rock_Ice"
    },
    {
      "x": -38,
      "y": 3,
      "z": -19,
      "name": "Rock_Ice"
    },
    {
      "x": -38,
      "y": 4,
      "z": -19,
      "name": "Rock_Ice"
    },
    {
      "x": -38,
      "y": 5,
      "z": -19,
      "name": "Rock_Ice"
    },
    {
      "x": -38,
      "y": 6,
      "z": -19,
      "name": "Rock_Ice"
    },
    {
      "x": -38,
      "y": 7,
      "z": -19,
      "name": "Rock_Ice"
    },
    {
      "x": -38,
      "y": 8,
      "z": -19,
      "name": "Rock_Ice"
    },
    {
      "x": -38,
      "y": 9,
      "z": -19,
      "name": "Rock_Ice"
    },
    {
      "x": -38,
      "y": 10,
      "z": -19,
      "name": "Rock_Ice"
    },
    {
      "x": -38,
      "y": 11,
      "z": -19,
      "name": "Rock_Ice"
    },
    {
      "x": -38,
      "y": 12,
      "z": -19,
      "name": "Rock_Ice"
    },
    {
      "x": -38,
      "y": 13,
      "z": -19,
      "name": "Rock_Ice"
    },
    {
      "x": -38,
      "y": 14,
      "z": -19,
      "name": "Rock_Ice"
    },
    {
      "x": -38,
      "y": 15,
      "z": -19,
      "name": "Rock_Ice"
    },
    {
      "x": -38,
      "y": 16,
      "z": -19,
      "name": "Rock_Ice"
    },
    {
      "x": -38,
      "y": 17,
      "z": -19,
      "name": "Rock_Ice"
    },
    {
      "x": -38,
      "y": 18,
      "z": -19,
      "name": "Soil_Snow"
    },
    {
      "x": -38,
      "y": 3,
      "z": -18,
      "name": "Rock_Ice"
    },
    {
      "x": -38,
      "y": 4,
      "z": -18,
      "name": "Rock_Ice"
    },
    {
      "x": -38,
      "y": 5,
      "z": -18,
      "name": "Rock_Ice"
    },
    {
      "x": -38,
      "y": 6,
      "z": -18,
      "name": "Rock_Ice"
    },
    {
      "x": -38,
      "y": 7,
      "z": -18,
      "name": "Rock_Ice"
    },
    {
      "x": -38,
      "y": 8,
      "z": -18,
      "name": "Rock_Ice"
    },
    {
      "x": -38,
      "y": 9,
      "z": -18,
      "name": "Rock_Ice"
    },
    {
      "x": -38,
      "y": 10,
      "z": -18,
      "name": "Rock_Ice"
    },
    {
      "x": -38,
      "y": 11,
      "z": -18,
      "name": "Rock_Ice"
    },
    {
      "x": -38,
      "y": 12,
      "z": -18,
      "name": "Rock_Ice"
    },
    {
      "x": -38,
      "y": 13,
      "z": -18,
      "name": "Rock_Ice"
    },
    {
      "x": -38,
      "y": 14,
      "z": -18,
      "name": "Rock_Ice"
    },
    {
      "x": -38,
      "y": 15,
      "z": -18,
      "name": "Rock_Ice"
    },
    {
      "x": -38,
      "y": 16,
      "z": -18,
      "name": "Rock_Ice"
    },
    {
      "x": -38,
      "y": 17,
      "z": -18,
      "name": "Rock_Ice"
    },
    {
      "x": -38,
      "y": 18,
      "z": -18,
      "name": "Soil_Snow"
    },
    {
      "x": -38,
      "y": 6,
      "z": -17,
      "name": "Rock_Ice"
    },
    {
      "x": -38,
      "y": 7,
      "z": -17,
      "name": "Rock_Ice"
    },
    {
      "x": -38,
      "y": 8,
      "z": -17,
      "name": "Rock_Ice"
    },
    {
      "x": -38,
      "y": 9,
      "z": -17,
      "name": "Rock_Ice"
    },
    {
      "x": -38,
      "y": 10,
      "z": -17,
      "name": "Rock_Ice"
    },
    {
      "x": -38,
      "y": 11,
      "z": -17,
      "name": "Rock_Ice"
    },
    {
      "x": -38,
      "y": 12,
      "z": -17,
      "name": "Rock_Ice"
    },
    {
      "x": -38,
      "y": 13,
      "z": -17,
      "name": "Rock_Ice"
    },
    {
      "x": -38,
      "y": 14,
      "z": -17,
      "name": "Rock_Ice"
    },
    {
      "x": -38,
      "y": 15,
      "z": -17,
      "name": "Rock_Ice"
    },
    {
      "x": -38,
      "y": 16,
      "z": -17,
      "name": "Rock_Ice"
    },
    {
      "x": -38,
      "y": 17,
      "z": -17,
      "name": "Rock_Ice"
    },
    {
      "x": -38,
      "y": 18,
      "z": -17,
      "name": "Rock_Ice"
    },
    {
      "x": -38,
      "y": 19,
      "z": -17,
      "name": "Rock_Ice"
    },
    {
      "x": -38,
      "y": 20,
      "z": -17,
      "name": "Soil_Snow"
    },
    {
      "x": -38,
      "y": 8,
      "z": -16,
      "name": "Rock_Ice"
    },
    {
      "x": -38,
      "y": 9,
      "z": -16,
      "name": "Rock_Ice"
    },
    {
      "x": -38,
      "y": 10,
      "z": -16,
      "name": "Rock_Ice"
    },
    {
      "x": -38,
      "y": 11,
      "z": -16,
      "name": "Rock_Ice"
    },
    {
      "x": -38,
      "y": 12,
      "z": -16,
      "name": "Rock_Ice"
    },
    {
      "x": -38,
      "y": 13,
      "z": -16,
      "name": "Rock_Ice"
    },
    {
      "x": -38,
      "y": 14,
      "z": -16,
      "name": "Rock_Ice"
    },
    {
      "x": -38,
      "y": 15,
      "z": -16,
      "name": "Rock_Ice"
    },
    {
      "x": -38,
      "y": 16,
      "z": -16,
      "name": "Rock_Ice"
    },
    {
      "x": -38,
      "y": 17,
      "z": -16,
      "name": "Rock_Ice"
    },
    {
      "x": -38,
      "y": 18,
      "z": -16,
      "name": "Rock_Ice"
    },
    {
      "x": -38,
      "y": 19,
      "z": -16,
      "name": "Rock_Ice"
    },
    {
      "x": -38,
      "y": 20,
      "z": -16,
      "name": "Rock_Ice"
    },
    {
      "x": -38,
      "y": 21,
      "z": -16,
      "name": "Soil_Snow"
    },
    {
      "x": -38,
      "y": 10,
      "z": -15,
      "name": "Rock_Ice"
    },
    {
      "x": -38,
      "y": 11,
      "z": -15,
      "name": "Rock_Ice"
    },
    {
      "x": -38,
      "y": 12,
      "z": -15,
      "name": "Rock_Ice"
    },
    {
      "x": -38,
      "y": 13,
      "z": -15,
      "name": "Rock_Ice"
    },
    {
      "x": -38,
      "y": 14,
      "z": -15,
      "name": "Rock_Ice"
    },
    {
      "x": -38,
      "y": 15,
      "z": -15,
      "name": "Rock_Ice"
    },
    {
      "x": -38,
      "y": 16,
      "z": -15,
      "name": "Rock_Ice"
    },
    {
      "x": -38,
      "y": 17,
      "z": -15,
      "name": "Rock_Ice"
    },
    {
      "x": -38,
      "y": 18,
      "z": -15,
      "name": "Rock_Ice"
    },
    {
      "x": -38,
      "y": 19,
      "z": -15,
      "name": "Rock_Ice"
    },
    {
      "x": -38,
      "y": 20,
      "z": -15,
      "name": "Rock_Ice"
    },
    {
      "x": -38,
      "y": 21,
      "z": -15,
      "name": "Rock_Ice"
    },
    {
      "x": -38,
      "y": 22,
      "z": -15,
      "name": "Soil_Snow"
    },
    {
      "x": -38,
      "y": 13,
      "z": -14,
      "name": "Rock_Ice"
    },
    {
      "x": -38,
      "y": 14,
      "z": -14,
      "name": "Rock_Ice"
    },
    {
      "x": -38,
      "y": 15,
      "z": -14,
      "name": "Rock_Ice"
    },
    {
      "x": -38,
      "y": 16,
      "z": -14,
      "name": "Rock_Ice"
    },
    {
      "x": -38,
      "y": 17,
      "z": -14,
      "name": "Rock_Ice"
    },
    {
      "x": -38,
      "y": 18,
      "z": -14,
      "name": "Rock_Ice"
    },
    {
      "x": -38,
      "y": 19,
      "z": -14,
      "name": "Rock_Ice"
    },
    {
      "x": -38,
      "y": 20,
      "z": -14,
      "name": "Rock_Ice"
    },
    {
      "x": -38,
      "y": 21,
      "z": -14,
      "name": "Rock_Ice"
    },
    {
      "x": -38,
      "y": 22,
      "z": -14,
      "name": "Rock_Ice"
    },
    {
      "x": -38,
      "y": 23,
      "z": -14,
      "name": "Soil_Snow"
    },
    {
      "x": -38,
      "y": 15,
      "z": -13,
      "name": "Rock_Ice"
    },
    {
      "x": -38,
      "y": 16,
      "z": -13,
      "name": "Rock_Ice"
    },
    {
      "x": -38,
      "y": 17,
      "z": -13,
      "name": "Rock_Ice"
    },
    {
      "x": -38,
      "y": 18,
      "z": -13,
      "name": "Rock_Ice"
    },
    {
      "x": -38,
      "y": 19,
      "z": -13,
      "name": "Rock_Ice"
    },
    {
      "x": -38,
      "y": 20,
      "z": -13,
      "name": "Rock_Ice"
    },
    {
      "x": -38,
      "y": 21,
      "z": -13,
      "name": "Rock_Ice"
    },
    {
      "x": -38,
      "y": 22,
      "z": -13,
      "name": "Rock_Ice"
    },
    {
      "x": -38,
      "y": 23,
      "z": -13,
      "name": "Rock_Ice"
    },
    {
      "x": -38,
      "y": 24,
      "z": -13,
      "name": "Soil_Snow"
    },
    {
      "x": -38,
      "y": 17,
      "z": -12,
      "name": "Rock_Ice"
    },
    {
      "x": -38,
      "y": 18,
      "z": -12,
      "name": "Rock_Ice"
    },
    {
      "x": -38,
      "y": 19,
      "z": -12,
      "name": "Rock_Ice"
    },
    {
      "x": -38,
      "y": 20,
      "z": -12,
      "name": "Rock_Ice"
    },
    {
      "x": -38,
      "y": 21,
      "z": -12,
      "name": "Rock_Ice"
    },
    {
      "x": -38,
      "y": 22,
      "z": -12,
      "name": "Rock_Ice"
    },
    {
      "x": -38,
      "y": 23,
      "z": -12,
      "name": "Rock_Ice"
    },
    {
      "x": -38,
      "y": 24,
      "z": -12,
      "name": "Rock_Ice"
    },
    {
      "x": -38,
      "y": 25,
      "z": -12,
      "name": "Soil_Snow"
    },
    {
      "x": -38,
      "y": 19,
      "z": -11,
      "name": "Rock_Ice"
    },
    {
      "x": -38,
      "y": 20,
      "z": -11,
      "name": "Rock_Ice"
    },
    {
      "x": -38,
      "y": 21,
      "z": -11,
      "name": "Rock_Ice"
    },
    {
      "x": -38,
      "y": 22,
      "z": -11,
      "name": "Rock_Ice"
    },
    {
      "x": -38,
      "y": 23,
      "z": -11,
      "name": "Rock_Ice"
    },
    {
      "x": -38,
      "y": 24,
      "z": -11,
      "name": "Rock_Ice"
    },
    {
      "x": -38,
      "y": 25,
      "z": -11,
      "name": "Rock_Ice"
    },
    {
      "x": -38,
      "y": 26,
      "z": -11,
      "name": "Soil_Snow"
    },
    {
      "x": -38,
      "y": 22,
      "z": -10,
      "name": "Rock_Ice"
    },
    {
      "x": -38,
      "y": 23,
      "z": -10,
      "name": "Rock_Ice_Permafrost"
    },
    {
      "x": -38,
      "y": 24,
      "z": -10,
      "name": "Rock_Ice_Permafrost"
    },
    {
      "x": -38,
      "y": 25,
      "z": -10,
      "name": "Rock_Ice"
    },
    {
      "x": -38,
      "y": 26,
      "z": -10,
      "name": "Rock_Ice_Permafrost"
    },
    {
      "x": -38,
      "y": 27,
      "z": -10,
      "name": "Rock_Ice_Permafrost"
    },
    {
      "x": -38,
      "y": 25,
      "z": -9,
      "name": "Rock_Ice"
    },
    {
      "x": -38,
      "y": 26,
      "z": -9,
      "name": "Rock_Ice_Permafrost"
    },
    {
      "x": -38,
      "y": 27,
      "z": -9,
      "name": "Rock_Ice"
    },
    {
      "x": -37,
      "y": 0,
      "z": -34,
      "name": "Soil_Snow"
    },
    {
      "x": -37,
      "y": 0,
      "z": -33,
      "name": "Rock_Ice_Permafrost"
    },
    {
      "x": -37,
      "y": 1,
      "z": -33,
      "name": "Rock_Ice"
    },
    {
      "x": -37,
      "y": 2,
      "z": -33,
      "name": "Soil_Snow"
    },
    {
      "x": -37,
      "y": 0,
      "z": -32,
      "name": "Rock_Ice"
    },
    {
      "x": -37,
      "y": 1,
      "z": -32,
      "name": "Rock_Ice_Permafrost"
    },
    {
      "x": -37,
      "y": 2,
      "z": -32,
      "name": "Rock_Ice"
    },
    {
      "x": -37,
      "y": 3,
      "z": -32,
      "name": "Soil_Snow"
    },
    {
      "x": -37,
      "y": 0,
      "z": -31,
      "name": "Rock_Ice"
    },
    {
      "x": -37,
      "y": 1,
      "z": -31,
      "name": "Rock_Ice_Permafrost"
    },
    {
      "x": -37,
      "y": 2,
      "z": -31,
      "name": "Rock_Ice_Permafrost"
    },
    {
      "x": -37,
      "y": 3,
      "z": -31,
      "name": "Rock_Ice_Permafrost"
    },
    {
      "x": -37,
      "y": 4,
      "z": -31,
      "name": "Rock_Ice"
    },
    {
      "x": -37,
      "y": 5,
      "z": -31,
      "name": "Soil_Snow"
    },
    {
      "x": -37,
      "y": 0,
      "z": -30,
      "name": "Rock_Ice"
    },
    {
      "x": -37,
      "y": 1,
      "z": -30,
      "name": "Rock_Ice"
    },
    {
      "x": -37,
      "y": 2,
      "z": -30,
      "name": "Rock_Ice"
    },
    {
      "x": -37,
      "y": 3,
      "z": -30,
      "name": "Rock_Ice"
    },
    {
      "x": -37,
      "y": 4,
      "z": -30,
      "name": "Rock_Ice_Permafrost"
    },
    {
      "x": -37,
      "y": 5,
      "z": -30,
      "name": "Rock_Ice_Permafrost"
    },
    {
      "x": -37,
      "y": 6,
      "z": -30,
      "name": "Soil_Snow"
    },
    {
      "x": -37,
      "y": 0,
      "z": -29,
      "name": "Rock_Ice"
    },
    {
      "x": -37,
      "y": 1,
      "z": -29,
      "name": "Rock_Ice"
    },
    {
      "x": -37,
      "y": 2,
      "z": -29,
      "name": "Rock_Ice"
    },
    {
      "x": -37,
      "y": 3,
      "z": -29,
      "name": "Rock_Ice"
    },
    {
      "x": -37,
      "y": 4,
      "z": -29,
      "name": "Rock_Ice"
    },
    {
      "x": -37,
      "y": 5,
      "z": -29,
      "name": "Rock_Ice"
    },
    {
      "x": -37,
      "y": 6,
      "z": -29,
      "name": "Rock_Ice_Permafrost"
    },
    {
      "x": -37,
      "y": 7,
      "z": -29,
      "name": "Rock_Ice"
    },
    {
      "x": -37,
      "y": 8,
      "z": -29,
      "name": "Soil_Snow"
    },
    {
      "x": -37,
      "y": 0,
      "z": -28,
      "name": "Rock_Ice"
    },
    {
      "x": -37,
      "y": 1,
      "z": -28,
      "name": "Rock_Ice"
    },
    {
      "x": -37,
      "y": 2,
      "z": -28,
      "name": "Rock_Ice"
    },
    {
      "x": -37,
      "y": 3,
      "z": -28,
      "name": "Rock_Ice"
    },
    {
      "x": -37,
      "y": 4,
      "z": -28,
      "name": "Rock_Ice"
    },
    {
      "x": -37,
      "y": 5,
      "z": -28,
      "name": "Rock_Ice"
    },
    {
      "x": -37,
      "y": 6,
      "z": -28,
      "name": "Rock_Ice"
    },
    {
      "x": -37,
      "y": 7,
      "z": -28,
      "name": "Rock_Ice"
    },
    {
      "x": -37,
      "y": 8,
      "z": -28,
      "name": "Rock_Ice"
    },
    {
      "x": -37,
      "y": 9,
      "z": -28,
      "name": "Soil_Snow"
    },
    {
      "x": -37,
      "y": 0,
      "z": -27,
      "name": "Rock_Ice"
    },
    {
      "x": -37,
      "y": 1,
      "z": -27,
      "name": "Rock_Ice"
    },
    {
      "x": -37,
      "y": 2,
      "z": -27,
      "name": "Rock_Ice"
    },
    {
      "x": -37,
      "y": 3,
      "z": -27,
      "name": "Rock_Ice"
    },
    {
      "x": -37,
      "y": 4,
      "z": -27,
      "name": "Rock_Ice"
    },
    {
      "x": -37,
      "y": 5,
      "z": -27,
      "name": "Rock_Ice"
    },
    {
      "x": -37,
      "y": 6,
      "z": -27,
      "name": "Rock_Ice"
    },
    {
      "x": -37,
      "y": 7,
      "z": -27,
      "name": "Rock_Ice"
    },
    {
      "x": -37,
      "y": 8,
      "z": -27,
      "name": "Rock_Ice"
    },
    {
      "x": -37,
      "y": 9,
      "z": -27,
      "name": "Rock_Ice"
    },
    {
      "x": -37,
      "y": 10,
      "z": -27,
      "name": "Soil_Snow"
    },
    {
      "x": -37,
      "y": 0,
      "z": -26,
      "name": "Rock_Ice"
    },
    {
      "x": -37,
      "y": 1,
      "z": -26,
      "name": "Rock_Ice"
    },
    {
      "x": -37,
      "y": 2,
      "z": -26,
      "name": "Rock_Ice"
    },
    {
      "x": -37,
      "y": 3,
      "z": -26,
      "name": "Rock_Ice"
    },
    {
      "x": -37,
      "y": 4,
      "z": -26,
      "name": "Rock_Ice"
    },
    {
      "x": -37,
      "y": 5,
      "z": -26,
      "name": "Rock_Ice"
    },
    {
      "x": -37,
      "y": 6,
      "z": -26,
      "name": "Rock_Ice"
    },
    {
      "x": -37,
      "y": 7,
      "z": -26,
      "name": "Rock_Ice"
    },
    {
      "x": -37,
      "y": 8,
      "z": -26,
      "name": "Rock_Ice"
    },
    {
      "x": -37,
      "y": 9,
      "z": -26,
      "name": "Rock_Ice"
    },
    {
      "x": -37,
      "y": 10,
      "z": -26,
      "name": "Rock_Ice"
    },
    {
      "x": -37,
      "y": 11,
      "z": -26,
      "name": "Rock_Ice"
    },
    {
      "x": -37,
      "y": 12,
      "z": -26,
      "name": "Soil_Snow"
    },
    {
      "x": -37,
      "y": 0,
      "z": -25,
      "name": "Rock_Ice"
    },
    {
      "x": -37,
      "y": 1,
      "z": -25,
      "name": "Rock_Ice"
    },
    {
      "x": -37,
      "y": 2,
      "z": -25,
      "name": "Rock_Ice"
    },
    {
      "x": -37,
      "y": 3,
      "z": -25,
      "name": "Rock_Ice"
    },
    {
      "x": -37,
      "y": 4,
      "z": -25,
      "name": "Rock_Ice"
    },
    {
      "x": -37,
      "y": 5,
      "z": -25,
      "name": "Rock_Ice"
    },
    {
      "x": -37,
      "y": 6,
      "z": -25,
      "name": "Rock_Ice"
    },
    {
      "x": -37,
      "y": 7,
      "z": -25,
      "name": "Rock_Ice"
    },
    {
      "x": -37,
      "y": 8,
      "z": -25,
      "name": "Rock_Ice"
    },
    {
      "x": -37,
      "y": 9,
      "z": -25,
      "name": "Rock_Ice"
    },
    {
      "x": -37,
      "y": 10,
      "z": -25,
      "name": "Rock_Ice"
    },
    {
      "x": -37,
      "y": 11,
      "z": -25,
      "name": "Rock_Ice"
    },
    {
      "x": -37,
      "y": 12,
      "z": -25,
      "name": "Rock_Ice"
    },
    {
      "x": -37,
      "y": 13,
      "z": -25,
      "name": "Soil_Snow"
    },
    {
      "x": -37,
      "y": 0,
      "z": -24,
      "name": "Rock_Ice"
    },
    {
      "x": -37,
      "y": 1,
      "z": -24,
      "name": "Rock_Ice"
    },
    {
      "x": -37,
      "y": 2,
      "z": -24,
      "name": "Rock_Ice"
    },
    {
      "x": -37,
      "y": 3,
      "z": -24,
      "name": "Rock_Ice"
    },
    {
      "x": -37,
      "y": 4,
      "z": -24,
      "name": "Rock_Ice"
    },
    {
      "x": -37,
      "y": 5,
      "z": -24,
      "name": "Rock_Ice"
    },
    {
      "x": -37,
      "y": 6,
      "z": -24,
      "name": "Rock_Ice"
    },
    {
      "x": -37,
      "y": 7,
      "z": -24,
      "name": "Rock_Ice"
    },
    {
      "x": -37,
      "y": 8,
      "z": -24,
      "name": "Rock_Ice"
    },
    {
      "x": -37,
      "y": 9,
      "z": -24,
      "name": "Rock_Ice"
    },
    {
      "x": -37,
      "y": 10,
      "z": -24,
      "name": "Rock_Ice"
    },
    {
      "x": -37,
      "y": 11,
      "z": -24,
      "name": "Rock_Ice"
    },
    {
      "x": -37,
      "y": 12,
      "z": -24,
      "name": "Rock_Ice"
    },
    {
      "x": -37,
      "y": 13,
      "z": -24,
      "name": "Rock_Ice"
    },
    {
      "x": -37,
      "y": 14,
      "z": -24,
      "name": "Soil_Snow"
    },
    {
      "x": -37,
      "y": 0,
      "z": -23,
      "name": "Rock_Ice"
    },
    {
      "x": -37,
      "y": 1,
      "z": -23,
      "name": "Rock_Ice"
    },
    {
      "x": -37,
      "y": 2,
      "z": -23,
      "name": "Rock_Ice"
    },
    {
      "x": -37,
      "y": 3,
      "z": -23,
      "name": "Rock_Ice"
    },
    {
      "x": -37,
      "y": 4,
      "z": -23,
      "name": "Rock_Ice"
    },
    {
      "x": -37,
      "y": 5,
      "z": -23,
      "name": "Rock_Ice"
    },
    {
      "x": -37,
      "y": 6,
      "z": -23,
      "name": "Rock_Ice"
    },
    {
      "x": -37,
      "y": 7,
      "z": -23,
      "name": "Rock_Ice"
    },
    {
      "x": -37,
      "y": 8,
      "z": -23,
      "name": "Rock_Ice"
    },
    {
      "x": -37,
      "y": 9,
      "z": -23,
      "name": "Rock_Ice"
    },
    {
      "x": -37,
      "y": 10,
      "z": -23,
      "name": "Rock_Ice"
    },
    {
      "x": -37,
      "y": 11,
      "z": -23,
      "name": "Rock_Ice"
    },
    {
      "x": -37,
      "y": 12,
      "z": -23,
      "name": "Rock_Ice"
    },
    {
      "x": -37,
      "y": 13,
      "z": -23,
      "name": "Rock_Ice"
    },
    {
      "x": -37,
      "y": 14,
      "z": -23,
      "name": "Rock_Ice"
    },
    {
      "x": -37,
      "y": 15,
      "z": -23,
      "name": "Rock_Ice"
    },
    {
      "x": -37,
      "y": 16,
      "z": -23,
      "name": "Soil_Snow"
    },
    {
      "x": -37,
      "y": 0,
      "z": -22,
      "name": "Rock_Ice"
    },
    {
      "x": -37,
      "y": 1,
      "z": -22,
      "name": "Rock_Ice"
    },
    {
      "x": -37,
      "y": 2,
      "z": -22,
      "name": "Rock_Ice"
    },
    {
      "x": -37,
      "y": 3,
      "z": -22,
      "name": "Rock_Ice"
    },
    {
      "x": -37,
      "y": 4,
      "z": -22,
      "name": "Rock_Ice"
    },
    {
      "x": -37,
      "y": 5,
      "z": -22,
      "name": "Rock_Ice"
    },
    {
      "x": -37,
      "y": 6,
      "z": -22,
      "name": "Rock_Ice"
    },
    {
      "x": -37,
      "y": 7,
      "z": -22,
      "name": "Rock_Ice"
    },
    {
      "x": -37,
      "y": 8,
      "z": -22,
      "name": "Rock_Ice"
    },
    {
      "x": -37,
      "y": 9,
      "z": -22,
      "name": "Rock_Ice"
    },
    {
      "x": -37,
      "y": 10,
      "z": -22,
      "name": "Rock_Ice"
    },
    {
      "x": -37,
      "y": 11,
      "z": -22,
      "name": "Rock_Ice"
    },
    {
      "x": -37,
      "y": 12,
      "z": -22,
      "name": "Rock_Ice"
    },
    {
      "x": -37,
      "y": 13,
      "z": -22,
      "name": "Rock_Ice"
    },
    {
      "x": -37,
      "y": 14,
      "z": -22,
      "name": "Rock_Ice"
    },
    {
      "x": -37,
      "y": 15,
      "z": -22,
      "name": "Rock_Ice"
    },
    {
      "x": -37,
      "y": 16,
      "z": -22,
      "name": "Rock_Ice"
    },
    {
      "x": -37,
      "y": 17,
      "z": -22,
      "name": "Rock_Ice_Permafrost"
    },
    {
      "x": -37,
      "y": 0,
      "z": -21,
      "name": "Rock_Ice"
    },
    {
      "x": -37,
      "y": 1,
      "z": -21,
      "name": "Rock_Ice"
    },
    {
      "x": -37,
      "y": 2,
      "z": -21,
      "name": "Rock_Ice"
    },
    {
      "x": -37,
      "y": 3,
      "z": -21,
      "name": "Rock_Ice"
    },
    {
      "x": -37,
      "y": 4,
      "z": -21,
      "name": "Rock_Ice"
    },
    {
      "x": -37,
      "y": 5,
      "z": -21,
      "name": "Rock_Ice"
    },
    {
      "x": -37,
      "y": 6,
      "z": -21,
      "name": "Rock_Ice"
    },
    {
      "x": -37,
      "y": 7,
      "z": -21,
      "name": "Rock_Ice"
    },
    {
      "x": -37,
      "y": 8,
      "z": -21,
      "name": "Rock_Ice"
    },
    {
      "x": -37,
      "y": 9,
      "z": -21,
      "name": "Rock_Ice"
    },
    {
      "x": -37,
      "y": 10,
      "z": -21,
      "name": "Rock_Ice"
    },
    {
      "x": -37,
      "y": 11,
      "z": -21,
      "name": "Rock_Ice"
    },
    {
      "x": -37,
      "y": 12,
      "z": -21,
      "name": "Rock_Ice"
    },
    {
      "x": -37,
      "y": 13,
      "z": -21,
      "name": "Rock_Ice"
    },
    {
      "x": -37,
      "y": 14,
      "z": -21,
      "name": "Rock_Ice"
    },
    {
      "x": -37,
      "y": 15,
      "z": -21,
      "name": "Rock_Ice"
    },
    {
      "x": -37,
      "y": 16,
      "z": -21,
      "name": "Rock_Ice"
    },
    {
      "x": -37,
      "y": 17,
      "z": -21,
      "name": "Soil_Snow"
    },
    {
      "x": -37,
      "y": 0,
      "z": -20,
      "name": "Rock_Ice"
    },
    {
      "x": -37,
      "y": 1,
      "z": -20,
      "name": "Rock_Ice"
    },
    {
      "x": -37,
      "y": 2,
      "z": -20,
      "name": "Rock_Ice"
    },
    {
      "x": -37,
      "y": 3,
      "z": -20,
      "name": "Rock_Ice"
    },
    {
      "x": -37,
      "y": 4,
      "z": -20,
      "name": "Rock_Ice"
    },
    {
      "x": -37,
      "y": 5,
      "z": -20,
      "name": "Rock_Ice"
    },
    {
      "x": -37,
      "y": 6,
      "z": -20,
      "name": "Rock_Ice"
    },
    {
      "x": -37,
      "y": 7,
      "z": -20,
      "name": "Rock_Ice"
    },
    {
      "x": -37,
      "y": 8,
      "z": -20,
      "name": "Rock_Ice"
    },
    {
      "x": -37,
      "y": 9,
      "z": -20,
      "name": "Rock_Ice"
    },
    {
      "x": -37,
      "y": 10,
      "z": -20,
      "name": "Rock_Ice"
    },
    {
      "x": -37,
      "y": 11,
      "z": -20,
      "name": "Rock_Ice"
    },
    {
      "x": -37,
      "y": 12,
      "z": -20,
      "name": "Rock_Ice"
    },
    {
      "x": -37,
      "y": 13,
      "z": -20,
      "name": "Rock_Ice"
    },
    {
      "x": -37,
      "y": 14,
      "z": -20,
      "name": "Rock_Ice"
    },
    {
      "x": -37,
      "y": 15,
      "z": -20,
      "name": "Rock_Ice"
    },
    {
      "x": -37,
      "y": 16,
      "z": -20,
      "name": "Rock_Ice"
    },
    {
      "x": -37,
      "y": 17,
      "z": -20,
      "name": "Rock_Ice"
    },
    {
      "x": -37,
      "y": 18,
      "z": -20,
      "name": "Soil_Snow"
    },
    {
      "x": -37,
      "y": 0,
      "z": -19,
      "name": "Rock_Ice"
    },
    {
      "x": -37,
      "y": 1,
      "z": -19,
      "name": "Rock_Ice"
    },
    {
      "x": -37,
      "y": 2,
      "z": -19,
      "name": "Rock_Ice"
    },
    {
      "x": -37,
      "y": 3,
      "z": -19,
      "name": "Rock_Ice"
    },
    {
      "x": -37,
      "y": 4,
      "z": -19,
      "name": "Rock_Ice"
    },
    {
      "x": -37,
      "y": 5,
      "z": -19,
      "name": "Rock_Ice"
    },
    {
      "x": -37,
      "y": 6,
      "z": -19,
      "name": "Rock_Ice"
    },
    {
      "x": -37,
      "y": 7,
      "z": -19,
      "name": "Rock_Ice"
    },
    {
      "x": -37,
      "y": 8,
      "z": -19,
      "name": "Rock_Ice"
    },
    {
      "x": -37,
      "y": 9,
      "z": -19,
      "name": "Rock_Ice"
    },
    {
      "x": -37,
      "y": 10,
      "z": -19,
      "name": "Rock_Ice"
    },
    {
      "x": -37,
      "y": 11,
      "z": -19,
      "name": "Rock_Ice"
    },
    {
      "x": -37,
      "y": 12,
      "z": -19,
      "name": "Rock_Ice"
    },
    {
      "x": -37,
      "y": 13,
      "z": -19,
      "name": "Rock_Ice"
    },
    {
      "x": -37,
      "y": 14,
      "z": -19,
      "name": "Rock_Ice"
    },
    {
      "x": -37,
      "y": 15,
      "z": -19,
      "name": "Rock_Ice"
    },
    {
      "x": -37,
      "y": 16,
      "z": -19,
      "name": "Rock_Ice"
    },
    {
      "x": -37,
      "y": 17,
      "z": -19,
      "name": "Rock_Ice"
    },
    {
      "x": -37,
      "y": 18,
      "z": -19,
      "name": "Rock_Ice"
    },
    {
      "x": -37,
      "y": 19,
      "z": -19,
      "name": "Soil_Snow"
    },
    {
      "x": -37,
      "y": 0,
      "z": -18,
      "name": "Rock_Ice"
    },
    {
      "x": -37,
      "y": 1,
      "z": -18,
      "name": "Rock_Ice"
    },
    {
      "x": -37,
      "y": 2,
      "z": -18,
      "name": "Rock_Ice"
    },
    {
      "x": -37,
      "y": 3,
      "z": -18,
      "name": "Rock_Ice"
    },
    {
      "x": -37,
      "y": 4,
      "z": -18,
      "name": "Rock_Ice"
    },
    {
      "x": -37,
      "y": 5,
      "z": -18,
      "name": "Rock_Ice"
    },
    {
      "x": -37,
      "y": 6,
      "z": -18,
      "name": "Rock_Ice"
    },
    {
      "x": -37,
      "y": 7,
      "z": -18,
      "name": "Rock_Ice"
    },
    {
      "x": -37,
      "y": 8,
      "z": -18,
      "name": "Rock_Ice"
    },
    {
      "x": -37,
      "y": 9,
      "z": -18,
      "name": "Rock_Ice"
    },
    {
      "x": -37,
      "y": 10,
      "z": -18,
      "name": "Rock_Ice"
    },
    {
      "x": -37,
      "y": 11,
      "z": -18,
      "name": "Rock_Ice"
    },
    {
      "x": -37,
      "y": 12,
      "z": -18,
      "name": "Rock_Ice"
    },
    {
      "x": -37,
      "y": 13,
      "z": -18,
      "name": "Rock_Ice"
    },
    {
      "x": -37,
      "y": 14,
      "z": -18,
      "name": "Rock_Ice"
    },
    {
      "x": -37,
      "y": 15,
      "z": -18,
      "name": "Rock_Ice"
    },
    {
      "x": -37,
      "y": 16,
      "z": -18,
      "name": "Rock_Ice"
    },
    {
      "x": -37,
      "y": 17,
      "z": -18,
      "name": "Rock_Ice"
    },
    {
      "x": -37,
      "y": 18,
      "z": -18,
      "name": "Rock_Ice"
    },
    {
      "x": -37,
      "y": 19,
      "z": -18,
      "name": "Rock_Ice"
    },
    {
      "x": -37,
      "y": 20,
      "z": -18,
      "name": "Soil_Snow"
    },
    {
      "x": -37,
      "y": 0,
      "z": -17,
      "name": "Rock_Ice"
    },
    {
      "x": -37,
      "y": 1,
      "z": -17,
      "name": "Rock_Ice"
    },
    {
      "x": -37,
      "y": 2,
      "z": -17,
      "name": "Rock_Ice"
    },
    {
      "x": -37,
      "y": 3,
      "z": -17,
      "name": "Rock_Ice"
    },
    {
      "x": -37,
      "y": 4,
      "z": -17,
      "name": "Rock_Ice"
    },
    {
      "x": -37,
      "y": 5,
      "z": -17,
      "name": "Rock_Ice"
    },
    {
      "x": -37,
      "y": 6,
      "z": -17,
      "name": "Rock_Ice"
    },
    {
      "x": -37,
      "y": 7,
      "z": -17,
      "name": "Rock_Ice"
    },
    {
      "x": -37,
      "y": 8,
      "z": -17,
      "name": "Rock_Ice"
    },
    {
      "x": -37,
      "y": 9,
      "z": -17,
      "name": "Rock_Ice"
    },
    {
      "x": -37,
      "y": 10,
      "z": -17,
      "name": "Rock_Ice"
    },
    {
      "x": -37,
      "y": 11,
      "z": -17,
      "name": "Rock_Ice"
    },
    {
      "x": -37,
      "y": 12,
      "z": -17,
      "name": "Rock_Ice"
    },
    {
      "x": -37,
      "y": 13,
      "z": -17,
      "name": "Rock_Ice"
    },
    {
      "x": -37,
      "y": 14,
      "z": -17,
      "name": "Rock_Ice"
    },
    {
      "x": -37,
      "y": 15,
      "z": -17,
      "name": "Rock_Ice"
    },
    {
      "x": -37,
      "y": 16,
      "z": -17,
      "name": "Rock_Ice"
    },
    {
      "x": -37,
      "y": 17,
      "z": -17,
      "name": "Rock_Ice"
    },
    {
      "x": -37,
      "y": 18,
      "z": -17,
      "name": "Rock_Ice"
    },
    {
      "x": -37,
      "y": 19,
      "z": -17,
      "name": "Rock_Ice"
    },
    {
      "x": -37,
      "y": 20,
      "z": -17,
      "name": "Rock_Ice"
    },
    {
      "x": -37,
      "y": 21,
      "z": -17,
      "name": "Soil_Snow"
    },
    {
      "x": -37,
      "y": 1,
      "z": -16,
      "name": "Rock_Ice"
    },
    {
      "x": -37,
      "y": 2,
      "z": -16,
      "name": "Rock_Ice"
    },
    {
      "x": -37,
      "y": 3,
      "z": -16,
      "name": "Rock_Ice"
    },
    {
      "x": -37,
      "y": 4,
      "z": -16,
      "name": "Rock_Ice"
    },
    {
      "x": -37,
      "y": 5,
      "z": -16,
      "name": "Rock_Ice"
    },
    {
      "x": -37,
      "y": 6,
      "z": -16,
      "name": "Rock_Ice"
    },
    {
      "x": -37,
      "y": 7,
      "z": -16,
      "name": "Rock_Ice"
    },
    {
      "x": -37,
      "y": 8,
      "z": -16,
      "name": "Rock_Ice"
    },
    {
      "x": -37,
      "y": 9,
      "z": -16,
      "name": "Rock_Ice"
    },
    {
      "x": -37,
      "y": 10,
      "z": -16,
      "name": "Rock_Ice"
    },
    {
      "x": -37,
      "y": 11,
      "z": -16,
      "name": "Rock_Ice"
    },
    {
      "x": -37,
      "y": 12,
      "z": -16,
      "name": "Rock_Ice"
    },
    {
      "x": -37,
      "y": 13,
      "z": -16,
      "name": "Rock_Ice"
    },
    {
      "x": -37,
      "y": 14,
      "z": -16,
      "name": "Rock_Ice"
    },
    {
      "x": -37,
      "y": 15,
      "z": -16,
      "name": "Rock_Ice"
    },
    {
      "x": -37,
      "y": 16,
      "z": -16,
      "name": "Rock_Ice"
    },
    {
      "x": -37,
      "y": 17,
      "z": -16,
      "name": "Rock_Ice"
    },
    {
      "x": -37,
      "y": 18,
      "z": -16,
      "name": "Rock_Ice"
    },
    {
      "x": -37,
      "y": 19,
      "z": -16,
      "name": "Rock_Ice"
    },
    {
      "x": -37,
      "y": 20,
      "z": -16,
      "name": "Rock_Ice"
    },
    {
      "x": -37,
      "y": 21,
      "z": -16,
      "name": "Rock_Ice"
    },
    {
      "x": -37,
      "y": 22,
      "z": -16,
      "name": "Soil_Snow"
    },
    {
      "x": -37,
      "y": 3,
      "z": -15,
      "name": "Rock_Ice_Permafrost"
    },
    {
      "x": -37,
      "y": 4,
      "z": -15,
      "name": "Rock_Ice"
    },
    {
      "x": -37,
      "y": 5,
      "z": -15,
      "name": "Rock_Ice"
    },
    {
      "x": -37,
      "y": 6,
      "z": -15,
      "name": "Rock_Ice"
    },
    {
      "x": -37,
      "y": 7,
      "z": -15,
      "name": "Rock_Ice"
    },
    {
      "x": -37,
      "y": 8,
      "z": -15,
      "name": "Rock_Ice"
    },
    {
      "x": -37,
      "y": 9,
      "z": -15,
      "name": "Rock_Ice"
    },
    {
      "x": -37,
      "y": 10,
      "z": -15,
      "name": "Rock_Ice"
    },
    {
      "x": -37,
      "y": 11,
      "z": -15,
      "name": "Rock_Ice"
    },
    {
      "x": -37,
      "y": 12,
      "z": -15,
      "name": "Rock_Ice"
    },
    {
      "x": -37,
      "y": 13,
      "z": -15,
      "name": "Rock_Ice"
    },
    {
      "x": -37,
      "y": 14,
      "z": -15,
      "name": "Rock_Ice"
    },
    {
      "x": -37,
      "y": 15,
      "z": -15,
      "name": "Rock_Ice"
    },
    {
      "x": -37,
      "y": 16,
      "z": -15,
      "name": "Rock_Ice"
    },
    {
      "x": -37,
      "y": 17,
      "z": -15,
      "name": "Rock_Ice"
    },
    {
      "x": -37,
      "y": 18,
      "z": -15,
      "name": "Rock_Ice"
    },
    {
      "x": -37,
      "y": 19,
      "z": -15,
      "name": "Rock_Ice"
    },
    {
      "x": -37,
      "y": 20,
      "z": -15,
      "name": "Rock_Ice"
    },
    {
      "x": -37,
      "y": 21,
      "z": -15,
      "name": "Rock_Ice"
    },
    {
      "x": -37,
      "y": 22,
      "z": -15,
      "name": "Rock_Ice"
    },
    {
      "x": -37,
      "y": 23,
      "z": -15,
      "name": "Soil_Snow"
    },
    {
      "x": -37,
      "y": 8,
      "z": -14,
      "name": "Rock_Ice"
    },
    {
      "x": -37,
      "y": 9,
      "z": -14,
      "name": "Rock_Ice"
    },
    {
      "x": -37,
      "y": 10,
      "z": -14,
      "name": "Rock_Ice"
    },
    {
      "x": -37,
      "y": 11,
      "z": -14,
      "name": "Rock_Ice"
    },
    {
      "x": -37,
      "y": 12,
      "z": -14,
      "name": "Rock_Ice"
    },
    {
      "x": -37,
      "y": 13,
      "z": -14,
      "name": "Rock_Ice"
    },
    {
      "x": -37,
      "y": 14,
      "z": -14,
      "name": "Rock_Ice"
    },
    {
      "x": -37,
      "y": 15,
      "z": -14,
      "name": "Rock_Ice"
    },
    {
      "x": -37,
      "y": 16,
      "z": -14,
      "name": "Rock_Ice"
    },
    {
      "x": -37,
      "y": 17,
      "z": -14,
      "name": "Rock_Ice"
    },
    {
      "x": -37,
      "y": 18,
      "z": -14,
      "name": "Rock_Ice"
    },
    {
      "x": -37,
      "y": 19,
      "z": -14,
      "name": "Rock_Ice"
    },
    {
      "x": -37,
      "y": 20,
      "z": -14,
      "name": "Rock_Ice"
    },
    {
      "x": -37,
      "y": 21,
      "z": -14,
      "name": "Rock_Ice"
    },
    {
      "x": -37,
      "y": 22,
      "z": -14,
      "name": "Rock_Ice"
    },
    {
      "x": -37,
      "y": 23,
      "z": -14,
      "name": "Rock_Ice"
    },
    {
      "x": -37,
      "y": 24,
      "z": -14,
      "name": "Soil_Snow"
    },
    {
      "x": -37,
      "y": 11,
      "z": -13,
      "name": "Rock_Ice"
    },
    {
      "x": -37,
      "y": 12,
      "z": -13,
      "name": "Rock_Ice"
    },
    {
      "x": -37,
      "y": 13,
      "z": -13,
      "name": "Rock_Ice"
    },
    {
      "x": -37,
      "y": 14,
      "z": -13,
      "name": "Rock_Ice"
    },
    {
      "x": -37,
      "y": 15,
      "z": -13,
      "name": "Rock_Ice"
    },
    {
      "x": -37,
      "y": 16,
      "z": -13,
      "name": "Rock_Ice"
    },
    {
      "x": -37,
      "y": 17,
      "z": -13,
      "name": "Rock_Ice"
    },
    {
      "x": -37,
      "y": 18,
      "z": -13,
      "name": "Rock_Ice"
    },
    {
      "x": -37,
      "y": 19,
      "z": -13,
      "name": "Rock_Ice"
    },
    {
      "x": -37,
      "y": 20,
      "z": -13,
      "name": "Rock_Ice"
    },
    {
      "x": -37,
      "y": 21,
      "z": -13,
      "name": "Rock_Ice"
    },
    {
      "x": -37,
      "y": 22,
      "z": -13,
      "name": "Rock_Ice"
    },
    {
      "x": -37,
      "y": 23,
      "z": -13,
      "name": "Rock_Ice"
    },
    {
      "x": -37,
      "y": 24,
      "z": -13,
      "name": "Rock_Ice"
    },
    {
      "x": -37,
      "y": 25,
      "z": -13,
      "name": "Soil_Snow"
    },
    {
      "x": -37,
      "y": 14,
      "z": -12,
      "name": "Rock_Ice"
    },
    {
      "x": -37,
      "y": 15,
      "z": -12,
      "name": "Rock_Ice"
    },
    {
      "x": -37,
      "y": 16,
      "z": -12,
      "name": "Rock_Ice"
    },
    {
      "x": -37,
      "y": 17,
      "z": -12,
      "name": "Rock_Ice"
    },
    {
      "x": -37,
      "y": 18,
      "z": -12,
      "name": "Rock_Ice"
    },
    {
      "x": -37,
      "y": 19,
      "z": -12,
      "name": "Rock_Ice"
    },
    {
      "x": -37,
      "y": 20,
      "z": -12,
      "name": "Rock_Ice"
    },
    {
      "x": -37,
      "y": 21,
      "z": -12,
      "name": "Rock_Ice"
    },
    {
      "x": -37,
      "y": 22,
      "z": -12,
      "name": "Rock_Ice"
    },
    {
      "x": -37,
      "y": 23,
      "z": -12,
      "name": "Rock_Ice"
    },
    {
      "x": -37,
      "y": 24,
      "z": -12,
      "name": "Rock_Ice"
    },
    {
      "x": -37,
      "y": 25,
      "z": -12,
      "name": "Rock_Ice"
    },
    {
      "x": -37,
      "y": 26,
      "z": -12,
      "name": "Soil_Snow"
    },
    {
      "x": -37,
      "y": 17,
      "z": -11,
      "name": "Rock_Ice"
    },
    {
      "x": -37,
      "y": 18,
      "z": -11,
      "name": "Rock_Ice"
    },
    {
      "x": -37,
      "y": 19,
      "z": -11,
      "name": "Rock_Ice"
    },
    {
      "x": -37,
      "y": 20,
      "z": -11,
      "name": "Rock_Ice"
    },
    {
      "x": -37,
      "y": 21,
      "z": -11,
      "name": "Rock_Ice"
    },
    {
      "x": -37,
      "y": 22,
      "z": -11,
      "name": "Rock_Ice"
    },
    {
      "x": -37,
      "y": 23,
      "z": -11,
      "name": "Rock_Ice"
    },
    {
      "x": -37,
      "y": 24,
      "z": -11,
      "name": "Rock_Ice"
    },
    {
      "x": -37,
      "y": 25,
      "z": -11,
      "name": "Rock_Ice"
    },
    {
      "x": -37,
      "y": 26,
      "z": -11,
      "name": "Rock_Ice"
    },
    {
      "x": -37,
      "y": 27,
      "z": -11,
      "name": "Rock_Ice"
    },
    {
      "x": -37,
      "y": 28,
      "z": -11,
      "name": "Soil_Snow"
    },
    {
      "x": -37,
      "y": 19,
      "z": -10,
      "name": "Rock_Ice"
    },
    {
      "x": -37,
      "y": 20,
      "z": -10,
      "name": "Rock_Ice"
    },
    {
      "x": -37,
      "y": 21,
      "z": -10,
      "name": "Rock_Ice"
    },
    {
      "x": -37,
      "y": 22,
      "z": -10,
      "name": "Rock_Ice"
    },
    {
      "x": -37,
      "y": 23,
      "z": -10,
      "name": "Rock_Ice"
    },
    {
      "x": -37,
      "y": 24,
      "z": -10,
      "name": "Rock_Ice"
    },
    {
      "x": -37,
      "y": 25,
      "z": -10,
      "name": "Rock_Ice"
    },
    {
      "x": -37,
      "y": 26,
      "z": -10,
      "name": "Rock_Ice"
    },
    {
      "x": -37,
      "y": 27,
      "z": -10,
      "name": "Rock_Ice"
    },
    {
      "x": -37,
      "y": 28,
      "z": -10,
      "name": "Rock_Ice"
    },
    {
      "x": -37,
      "y": 29,
      "z": -10,
      "name": "Soil_Snow"
    },
    {
      "x": -37,
      "y": 22,
      "z": -9,
      "name": "Rock_Ice"
    },
    {
      "x": -37,
      "y": 23,
      "z": -9,
      "name": "Rock_Ice"
    },
    {
      "x": -37,
      "y": 24,
      "z": -9,
      "name": "Rock_Ice"
    },
    {
      "x": -37,
      "y": 25,
      "z": -9,
      "name": "Rock_Ice"
    },
    {
