{
  "version": 8,
  "blockIdVersion": 11,
  "anchorX": -1,
  "anchorY": 13,
  "anchorZ": 6,
  "blocks": [
    {
      "x": -10,
      "y": 17,
      "z": -2,
      "name": "Rock_Ice"
    },
    {
      "x": -10,
      "y": 14,
      "z": -1,
      "name": "Rock_Ice_Permafrost"
    },
    {
      "x": -10,
      "y": 15,
      "z": -1,
      "name": "Rock_Ice"
    },
    {
      "x": -10,
      "y": 17,
      "z": -1,
      "name": "Rock_Ice"
    },
    {
      "x": -10,
      "y": 18,
      "z": -1,
      "name": "Rock_Ice"
    },
    {
      "x": -10,
      "y": 19,
      "z": -1,
      "name": "Rock_Ice"
    },
    {
      "x": -10,
      "y": 20,
      "z": -1,
      "name": "Rock_Ice"
    },
    {
      "x": -10,
      "y": 13,
      "z": 0,
      "name": "Rock_Ice_Permafrost"
    },
    {
      "x": -10,
      "y": 14,
      "z": 0,
      "name": "Rock_Ice"
    },
    {
      "x": -10,
      "y": 18,
      "z": 0,
      "name": "Rock_Ice"
    },
    {
      "x": -10,
      "y": 19,
      "z": 0,
      "name": "Rock_Ice_Permafrost"
    },
    {
      "x": -10,
      "y": 20,
      "z": 0,
      "name": "Rock_Ice"
    },
    {
      "x": -10,
      "y": 21,
      "z": 0,
      "name": "Rock_Ice"
    },
    {
      "x": -10,
      "y": 22,
      "z": 0,
      "name": "Soil_Snow"
    },
    {
      "x": -10,
      "y": 11,
      "z": 1,
      "name": "Rock_Ice_Permafrost"
    },
    {
      "x": -10,
      "y": 12,
      "z": 1,
      "name": "Rock_Ice_Permafrost"
    },
    {
      "x": -10,
      "y": 13,
      "z": 1,
      "name": "Rock_Ice_Permafrost"
    },
    {
      "x": -10,
      "y": 18,
      "z": 1,
      "name": "Rock_Ice_Permafrost"
    },
    {
      "x": -10,
      "y": 19,
      "z": 1,
      "name": "Rock_Ice_Permafrost"
    },
    {
      "x": -10,
      "y": 20,
      "z": 1,
      "name": "Rock_Ice_Permafrost"
    },
    {
      "x": -10,
      "y": 21,
      "z": 1,
      "name": "Rock_Ice_Permafrost"
    },
    {
      "x": -10,
      "y": 22,
      "z": 1,
      "name": "Rock_Ice"
    },
    {
      "x": -10,
      "y": 23,
      "z": 1,
      "name": "Soil_Snow"
    },
    {
      "x": -10,
      "y": 10,
      "z": 2,
      "name": "Rock_Ice_Permafrost"
    },
    {
      "x": -10,
      "y": 11,
      "z": 2,
      "name": "Rock_Ice_Permafrost"
    },
    {
      "x": -10,
      "y": 12,
      "z": 2,
      "name": "Rock_Ice_Permafrost"
    },
    {
      "x": -10,
      "y": 19,
      "z": 2,
      "name": "Rock_Ice_Permafrost"
    },
    {
      "x": -10,
      "y": 20,
      "z": 2,
      "name": "Rock_Ice_Permafrost"
    },
    {
      "x": -10,
      "y": 21,
      "z": 2,
      "name": "Rock_Ice_Permafrost"
    },
    {
      "x": -10,
      "y": 22,
      "z": 2,
      "name": "Rock_Ice"
    },
    {
      "x": -10,
      "y": 23,
      "z": 2,
      "name": "Soil_Snow"
    },
    {
      "x": -10,
      "y": 8,
      "z": 3,
      "name": "Rock_Ice"
    },
    {
      "x": -10,
      "y": 9,
      "z": 3,
      "name": "Rock_Ice"
    },
    {
      "x": -10,
      "y": 10,
      "z": 3,
      "name": "Rock_Ice_Permafrost"
    },
    {
      "x": -10,
      "y": 11,
      "z": 3,
      "name": "Rock_Ice_Permafrost"
    },
    {
      "x": -10,
      "y": 20,
      "z": 3,
      "name": "Rock_Ice_Permafrost"
    },
    {
      "x": -10,
      "y": 21,
      "z": 3,
      "name": "Rock_Ice_Permafrost"
    },
    {
      "x": -10,
      "y": 22,
      "z": 3,
      "name": "Rock_Ice_Permafrost"
    },
    {
      "x": -10,
      "y": 23,
      "z": 3,
      "name": "Rock_Ice"
    },
    {
      "x": -10,
      "y": 24,
      "z": 3,
      "name": "Soil_Snow"
    },
    {
      "x": -10,
      "y": 7,
      "z": 4,
      "name": "Rock_Ice"
    },
    {
      "x": -10,
      "y": 8,
      "z": 4,
      "name": "Rock_Ice"
    },
    {
      "x": -10,
      "y": 9,
      "z": 4,
      "name": "Rock_Ice_Permafrost"
    },
    {
      "x": -10,
      "y": 22,
      "z": 4,
      "name": "Rock_Ice_Permafrost"
    },
    {
      "x": -10,
      "y": 23,
      "z": 4,
      "name": "Rock_Ice"
    },
    {
      "x": -10,
      "y": 24,
      "z": 4,
      "name": "Rock_Ice"
    },
    {
      "x": -10,
      "y": 25,
      "z": 4,
      "name": "Soil_Snow"
    },
    {
      "x": -10,
      "y": 6,
      "z": 5,
      "name": "Rock_Ice"
    },
    {
      "x": -10,
      "y": 7,
      "z": 5,
      "name": "Rock_Ice"
    },
    {
      "x": -10,
      "y": 8,
      "z": 5,
      "name": "Rock_Ice"
    },
    {
      "x": -10,
      "y": 24,
      "z": 5,
      "name": "Rock_Ice"
    },
    {
      "x": -10,
      "y": 25,
      "z": 5,
      "name": "Rock_Ice"
    },
    {
      "x": -10,
      "y": 26,
      "z": 5,
      "name": "Soil_Snow"
    },
    {
      "x": -10,
      "y": 5,
      "z": 6,
      "name": "Rock_Ice"
    },
    {
      "x": -10,
      "y": 6,
      "z": 6,
      "name": "Rock_Ice"
    },
    {
      "x": -10,
      "y": 7,
      "z": 6,
      "name": "Soil_Snow"
    },
    {
      "x": -10,
      "y": 26,
      "z": 6,
      "name": "Rock_Ice"
    },
    {
      "x": -10,
      "y": 27,
      "z": 6,
      "name": "Soil_Snow"
    },
    {
      "x": -10,
      "y": 28,
      "z": 7,
      "name": "Soil_Snow"
    },
    {
      "x": -10,
      "y": 29,
      "z": 8,
      "name": "Soil_Snow"
    },
    {
      "x": -9,
      "y": 27,
      "z": -7,
      "name": "Soil_Snow"
    },
    {
      "x": -9,
      "y": 25,
      "z": -6,
      "name": "Rock_Ice"
    },
    {
      "x": -9,
      "y": 26,
      "z": -6,
      "name": "Rock_Ice"
    },
    {
      "x": -9,
      "y": 27,
      "z": -6,
      "name": "Rock_Ice"
    },
    {
      "x": -9,
      "y": 28,
      "z": -6,
      "name": "Soil_Snow"
    },
    {
      "x": -9,
      "y": 24,
      "z": -5,
      "name": "Rock_Ice"
    },
    {
      "x": -9,
      "y": 25,
      "z": -5,
      "name": "Rock_Ice"
    },
    {
      "x": -9,
      "y": 26,
      "z": -5,
      "name": "Rock_Ice"
    },
    {
      "x": -9,
      "y": 27,
      "z": -5,
      "name": "Rock_Ice"
    },
    {
      "x": -9,
      "y": 28,
      "z": -5,
      "name": "Rock_Ice"
    },
    {
      "x": -9,
      "y": 29,
      "z": -5,
      "name": "Rock_Ice"
    },
    {
      "x": -9,
      "y": 30,
      "z": -5,
      "name": "Rock_Ice"
    },
    {
      "x": -9,
      "y": 31,
      "z": -5,
      "name": "Rock_Ice"
    },
    {
      "x": -9,
      "y": 32,
      "z": -5,
      "name": "Rock_Ice"
    },
    {
      "x": -9,
      "y": 33,
      "z": -5,
      "name": "Rock_Ice"
    },
    {
      "x": -9,
      "y": 34,
      "z": -5,
      "name": "Rock_Ice"
    },
    {
      "x": -9,
      "y": 35,
      "z": -5,
      "name": "Rock_Ice"
    },
    {
      "x": -9,
      "y": 36,
      "z": -5,
      "name": "Rock_Ice"
    },
    {
      "x": -9,
      "y": 37,
      "z": -5,
      "name": "Rock_Ice_Permafrost"
    },
    {
      "x": -9,
      "y": 38,
      "z": -5,
      "name": "Rock_Ice_Permafrost"
    },
    {
      "x": -9,
      "y": 39,
      "z": -5,
      "name": "Rock_Ice_Permafrost"
    },
    {
      "x": -9,
      "y": 40,
      "z": -5,
      "name": "Rock_Ice_Permafrost"
    },
    {
      "x": -9,
      "y": 41,
      "z": -5,
      "name": "Soil_Snow"
    },
    {
      "x": -9,
      "y": 13,
      "z": -4,
      "name": "Rock_Ice_Permafrost"
    },
    {
      "x": -9,
      "y": 20,
      "z": -4,
      "name": "Rock_Ice"
    },
    {
      "x": -9,
      "y": 21,
      "z": -4,
      "name": "Rock_Ice"
    },
    {
      "x": -9,
      "y": 22,
      "z": -4,
      "name": "Rock_Ice"
    },
    {
      "x": -9,
      "y": 23,
      "z": -4,
      "name": "Rock_Ice"
    },
    {
      "x": -9,
      "y": 24,
      "z": -4,
      "name": "Rock_Ice"
    },
    {
      "x": -9,
      "y": 25,
      "z": -4,
      "name": "Rock_Ice"
    },
    {
      "x": -9,
      "y": 26,
      "z": -4,
      "name": "Rock_Ice"
    },
    {
      "x": -9,
      "y": 41,
      "z": -4,
      "name": "Rock_Ice_Permafrost"
    },
    {
      "x": -9,
      "y": 42,
      "z": -4,
      "name": "Rock_Ice_Permafrost"
    },
    {
      "x": -9,
      "y": 43,
      "z": -4,
      "name": "Rock_Ice_Permafrost"
    },
    {
      "x": -9,
      "y": 44,
      "z": -4,
      "name": "Soil_Snow"
    },
    {
      "x": -9,
      "y": 14,
      "z": -3,
      "name": "Rock_Ice_Permafrost"
    },
    {
      "x": -9,
      "y": 15,
      "z": -3,
      "name": "Rock_Ice"
    },
    {
      "x": -9,
      "y": 16,
      "z": -3,
      "name": "Rock_Ice"
    },
    {
      "x": -9,
      "y": 17,
      "z": -3,
      "name": "Rock_Ice"
    },
    {
      "x": -9,
      "y": 18,
      "z": -3,
      "name": "Rock_Ice"
    },
    {
      "x": -9,
      "y": 19,
      "z": -3,
      "name": "Rock_Ice"
    },
    {
      "x": -9,
      "y": 20,
      "z": -3,
      "name": "Rock_Ice"
    },
    {
      "x": -9,
      "y": 21,
      "z": -3,
      "name": "Rock_Ice"
    },
    {
      "x": -9,
      "y": 22,
      "z": -3,
      "name": "Rock_Ice"
    },
    {
      "x": -9,
      "y": 23,
      "z": -3,
      "name": "Rock_Ice"
    },
    {
      "x": -9,
      "y": 14,
      "z": -2,
      "name": "Rock_Ice"
    },
    {
      "x": -9,
      "y": 15,
      "z": -2,
      "name": "Rock_Ice"
    },
    {
      "x": -9,
      "y": 16,
      "z": -2,
      "name": "Rock_Ice"
    },
    {
      "x": -9,
      "y": 17,
      "z": -2,
      "name": "Rock_Ice"
    },
    {
      "x": -9,
      "y": 18,
      "z": -2,
      "name": "Rock_Ice"
    },
    {
      "x": -9,
      "y": 19,
      "z": -2,
      "name": "Rock_Ice"
    },
    {
      "x": -9,
      "y": 20,
      "z": -2,
      "name": "Rock_Ice"
    },
    {
      "x": -9,
      "y": 21,
      "z": -2,
      "name": "Rock_Ice"
    },
    {
      "x": -9,
      "y": 22,
      "z": -2,
      "name": "Rock_Ice"
    },
    {
      "x": -9,
      "y": 23,
      "z": -2,
      "name": "Soil_Snow"
    },
    {
      "x": -9,
      "y": 12,
      "z": -1,
      "name": "Rock_Ice_Permafrost"
    },
    {
      "x": -9,
      "y": 13,
      "z": -1,
      "name": "Rock_Ice_Permafrost"
    },
    {
      "x": -9,
      "y": 14,
      "z": -1,
      "name": "Rock_Ice"
    },
    {
      "x": -9,
      "y": 15,
      "z": -1,
      "name": "Rock_Ice"
    },
    {
      "x": -9,
      "y": 16,
      "z": -1,
      "name": "Rock_Ice"
    },
    {
      "x": -9,
      "y": 17,
      "z": -1,
      "name": "Rock_Ice"
    },
    {
      "x": -9,
      "y": 18,
      "z": -1,
      "name": "Rock_Ice"
    },
    {
      "x": -9,
      "y": 19,
      "z": -1,
      "name": "Rock_Ice"
    },
    {
      "x": -9,
      "y": 20,
      "z": -1,
      "name": "Rock_Ice"
    },
    {
      "x": -9,
      "y": 21,
      "z": -1,
      "name": "Rock_Ice"
    },
    {
      "x": -9,
      "y": 22,
      "z": -1,
      "name": "Rock_Ice"
    },
    {
      "x": -9,
      "y": 23,
      "z": -1,
      "name": "Rock_Ice"
    },
    {
      "x": -9,
      "y": 24,
      "z": -1,
      "name": "Soil_Snow"
    },
    {
      "x": -9,
      "y": 11,
      "z": 0,
      "name": "Rock_Ice_Permafrost"
    },
    {
      "x": -9,
      "y": 12,
      "z": 0,
      "name": "Rock_Ice_Permafrost"
    },
    {
      "x": -9,
      "y": 13,
      "z": 0,
      "name": "Rock_Ice_Permafrost"
    },
    {
      "x": -9,
      "y": 14,
      "z": 0,
      "name": "Rock_Ice_Permafrost"
    },
    {
      "x": -9,
      "y": 15,
      "z": 0,
      "name": "Rock_Ice"
    },
    {
      "x": -9,
      "y": 16,
      "z": 0,
      "name": "Rock_Ice"
    },
    {
      "x": -9,
      "y": 17,
      "z": 0,
      "name": "Rock_Ice"
    },
    {
      "x": -9,
      "y": 18,
      "z": 0,
      "name": "Rock_Ice"
    },
    {
      "x": -9,
      "y": 19,
      "z": 0,
      "name": "Rock_Ice"
    },
    {
      "x": -9,
      "y": 20,
      "z": 0,
      "name": "Rock_Ice"
    },
    {
      "x": -9,
      "y": 21,
      "z": 0,
      "name": "Rock_Ice"
    },
    {
      "x": -9,
      "y": 22,
      "z": 0,
      "name": "Rock_Ice"
    },
    {
      "x": -9,
      "y": 23,
      "z": 0,
      "name": "Rock_Ice"
    },
    {
      "x": -9,
      "y": 24,
      "z": 0,
      "name": "Rock_Ice"
    },
    {
      "x": -9,
      "y": 25,
      "z": 0,
      "name": "Soil_Snow"
    },
    {
      "x": -9,
      "y": 9,
      "z": 1,
      "name": "Rock_Ice"
    },
    {
      "x": -9,
      "y": 10,
      "z": 1,
      "name": "Rock_Ice"
    },
    {
      "x": -9,
      "y": 11,
      "z": 1,
      "name": "Rock_Ice_Permafrost"
    },
    {
      "x": -9,
      "y": 12,
      "z": 1,
      "name": "Rock_Ice_Permafrost"
    },
    {
      "x": -9,
      "y": 13,
      "z": 1,
      "name": "Rock_Ice_Permafrost"
    },
    {
      "x": -9,
      "y": 14,
      "z": 1,
      "name": "Rock_Ice"
    },
    {
      "x": -9,
      "y": 15,
      "z": 1,
      "name": "Rock_Ice"
    },
    {
      "x": -9,
      "y": 16,
      "z": 1,
      "name": "Rock_Ice"
    },
    {
      "x": -9,
      "y": 17,
      "z": 1,
      "name": "Rock_Ice"
    },
    {
      "x": -9,
      "y": 18,
      "z": 1,
      "name": "Rock_Ice"
    },
    {
      "x": -9,
      "y": 19,
      "z": 1,
      "name": "Rock_Ice"
    },
    {
      "x": -9,
      "y": 20,
      "z": 1,
      "name": "Rock_Ice"
    },
    {
      "x": -9,
      "y": 21,
      "z": 1,
      "name": "Rock_Ice"
    },
    {
      "x": -9,
      "y": 22,
      "z": 1,
      "name": "Rock_Ice"
    },
    {
      "x": -9,
      "y": 23,
      "z": 1,
      "name": "Rock_Ice"
    },
    {
      "x": -9,
      "y": 24,
      "z": 1,
      "name": "Rock_Ice"
    },
    {
      "x": -9,
      "y": 25,
      "z": 1,
      "name": "Soil_Snow"
    },
    {
      "x": -9,
      "y": 8,
      "z": 2,
      "name": "Rock_Ice"
    },
    {
      "x": -9,
      "y": 9,
      "z": 2,
      "name": "Rock_Ice"
    },
    {
      "x": -9,
      "y": 10,
      "z": 2,
      "name": "Rock_Ice_Permafrost"
    },
    {
      "x": -9,
      "y": 11,
      "z": 2,
      "name": "Rock_Ice_Permafrost"
    },
    {
      "x": -9,
      "y": 12,
      "z": 2,
      "name": "Rock_Ice_Permafrost"
    },
    {
      "x": -9,
      "y": 13,
      "z": 2,
      "name": "Rock_Ice"
    },
    {
      "x": -9,
      "y": 14,
      "z": 2,
      "name": "Rock_Ice"
    },
    {
      "x": -9,
      "y": 15,
      "z": 2,
      "name": "Rock_Ice"
    },
    {
      "x": -9,
      "y": 16,
      "z": 2,
      "name": "Rock_Ice"
    },
    {
      "x": -9,
      "y": 17,
      "z": 2,
      "name": "Rock_Ice"
    },
    {
      "x": -9,
      "y": 18,
      "z": 2,
      "name": "Rock_Ice"
    },
    {
      "x": -9,
      "y": 19,
      "z": 2,
      "name": "Rock_Ice"
    },
    {
      "x": -9,
      "y": 20,
      "z": 2,
      "name": "Rock_Ice"
    },
    {
      "x": -9,
      "y": 21,
      "z": 2,
      "name": "Rock_Ice"
    },
    {
      "x": -9,
      "y": 22,
      "z": 2,
      "name": "Rock_Ice"
    },
    {
      "x": -9,
      "y": 23,
      "z": 2,
      "name": "Rock_Ice_Permafrost"
    },
    {
      "x": -9,
      "y": 24,
      "z": 2,
      "name": "Rock_Ice"
    },
    {
      "x": -9,
      "y": 25,
      "z": 2,
      "name": "Rock_Ice"
    },
    {
      "x": -9,
      "y": 26,
      "z": 2,
      "name": "Soil_Snow"
    },
    {
      "x": -9,
      "y": 6,
      "z": 3,
      "name": "Rock_Ice"
    },
    {
      "x": -9,
      "y": 7,
      "z": 3,
      "name": "Rock_Ice"
    },
    {
      "x": -9,
      "y": 8,
      "z": 3,
      "name": "Rock_Ice"
    },
    {
      "x": -9,
      "y": 9,
      "z": 3,
      "name": "Rock_Ice"
    },
    {
      "x": -9,
      "y": 10,
      "z": 3,
      "name": "Rock_Ice_Permafrost"
    },
    {
      "x": -9,
      "y": 11,
      "z": 3,
      "name": "Rock_Ice_Permafrost"
    },
    {
      "x": -9,
      "y": 12,
      "z": 3,
      "name": "Rock_Ice_Permafrost"
    },
    {
      "x": -9,
      "y": 13,
      "z": 3,
      "name": "Rock_Ice_Permafrost"
    },
    {
      "x": -9,
      "y": 14,
      "z": 3,
      "name": "Rock_Ice"
    },
    {
      "x": -9,
      "y": 15,
      "z": 3,
      "name": "Rock_Ice"
    },
    {
      "x": -9,
      "y": 16,
      "z": 3,
      "name": "Rock_Ice_Permafrost"
    },
    {
      "x": -9,
      "y": 17,
      "z": 3,
      "name": "Rock_Ice_Permafrost"
    },
    {
      "x": -9,
      "y": 18,
      "z": 3,
      "name": "Rock_Ice_Permafrost"
    },
    {
      "x": -9,
      "y": 19,
      "z": 3,
      "name": "Rock_Ice_Permafrost"
    },
    {
      "x": -9,
      "y": 20,
      "z": 3,
      "name": "Rock_Ice"
    },
    {
      "x": -9,
      "y": 21,
      "z": 3,
      "name": "Rock_Ice_Permafrost"
    },
    {
      "x": -9,
      "y": 22,
      "z": 3,
      "name": "Rock_Ice_Permafrost"
    },
    {
      "x": -9,
      "y": 23,
      "z": 3,
      "name": "Rock_Ice_Permafrost"
    },
    {
      "x": -9,
      "y": 24,
      "z": 3,
      "name": "Rock_Ice_Permafrost"
    },
    {
      "x": -9,
      "y": 25,
      "z": 3,
      "name": "Rock_Ice_Permafrost"
    },
    {
      "x": -9,
      "y": 26,
      "z": 3,
      "name": "Rock_Ice"
    },
    {
      "x": -9,
      "y": 27,
      "z": 3,
      "name": "Soil_Snow"
    },
    {
      "x": -9,
      "y": 5,
      "z": 4,
      "name": "Rock_Ice"
    },
    {
      "x": -9,
      "y": 6,
      "z": 4,
      "name": "Rock_Ice"
    },
    {
      "x": -9,
      "y": 7,
      "z": 4,
      "name": "Rock_Ice"
    },
    {
      "x": -9,
      "y": 8,
      "z": 4,
      "name": "Rock_Ice_Permafrost"
    },
    {
      "x": -9,
      "y": 9,
      "z": 4,
      "name": "Rock_Ice_Permafrost"
    },
    {
      "x": -9,
      "y": 10,
      "z": 4,
      "name": "Rock_Ice_Permafrost"
    },
    {
      "x": -9,
      "y": 11,
      "z": 4,
      "name": "Rock_Ice_Permafrost"
    },
    {
      "x": -9,
      "y": 12,
      "z": 4,
      "name": "Rock_Ice_Permafrost"
    },
    {
      "x": -9,
      "y": 13,
      "z": 4,
      "name": "Rock_Ice_Permafrost"
    },
    {
      "x": -9,
      "y": 15,
      "z": 4,
      "name": "Rock_Ice_Permafrost"
    },
    {
      "x": -9,
      "y": 16,
      "z": 4,
      "name": "Rock_Ice"
    },
    {
      "x": -9,
      "y": 17,
      "z": 4,
      "name": "Rock_Ice_Permafrost"
    },
    {
      "x": -9,
      "y": 18,
      "z": 4,
      "name": "Rock_Ice_Permafrost"
    },
    {
      "x": -9,
      "y": 19,
      "z": 4,
      "name": "Rock_Ice_Permafrost"
    },
    {
      "x": -9,
      "y": 20,
      "z": 4,
      "name": "Rock_Ice_Permafrost"
    },
    {
      "x": -9,
      "y": 21,
      "z": 4,
      "name": "Rock_Ice_Permafrost"
    },
    {
      "x": -9,
      "y": 22,
      "z": 4,
      "name": "Rock_Ice_Permafrost"
    },
    {
      "x": -9,
      "y": 23,
      "z": 4,
      "name": "Rock_Ice_Permafrost"
    },
    {
      "x": -9,
      "y": 24,
      "z": 4,
      "name": "Rock_Ice_Permafrost"
    },
    {
      "x": -9,
      "y": 25,
      "z": 4,
      "name": "Rock_Ice_Permafrost"
    },
    {
      "x": -9,
      "y": 26,
      "z": 4,
      "name": "Rock_Ice"
    },
    {
      "x": -9,
      "y": 27,
      "z": 4,
      "name": "Soil_Snow"
    },
    {
      "x": -9,
      "y": 4,
      "z": 5,
      "name": "Rock_Ice"
    },
    {
      "x": -9,
      "y": 5,
      "z": 5,
      "name": "Rock_Ice"
    },
    {
      "x": -9,
      "y": 6,
      "z": 5,
      "name": "Rock_Ice"
    },
    {
      "x": -9,
      "y": 7,
      "z": 5,
      "name": "Rock_Ice"
    },
    {
      "x": -9,
      "y": 8,
      "z": 5,
      "name": "Rock_Ice_Permafrost"
    },
    {
      "x": -9,
      "y": 9,
      "z": 5,
      "name": "Rock_Ice_Permafrost"
    },
    {
      "x": -9,
      "y": 10,
      "z": 5,
      "name": "Rock_Ice_Permafrost"
    },
    {
      "x": -9,
      "y": 11,
      "z": 5,
      "name": "Rock_Ice_Permafrost"
    },
    {
      "x": -9,
      "y": 12,
      "z": 5,
      "name": "Rock_Ice_Permafrost"
    },
    {
      "x": -9,
      "y": 17,
      "z": 5,
      "name": "Rock_Ice_Permafrost"
    },
    {
      "x": -9,
      "y": 18,
      "z": 5,
      "name": "Rock_Ice_Permafrost"
    },
    {
      "x": -9,
      "y": 19,
      "z": 5,
      "name": "Rock_Ice_Permafrost"
    },
    {
      "x": -9,
      "y": 20,
      "z": 5,
      "name": "Rock_Ice_Permafrost"
    },
    {
      "x": -9,
      "y": 21,
      "z": 5,
      "name": "Rock_Ice_Permafrost"
    },
    {
      "x": -9,
      "y": 22,
      "z": 5,
      "name": "Rock_Ice_Permafrost"
    },
    {
      "x": -9,
      "y": 23,
      "z": 5,
      "name": "Rock_Ice_Permafrost"
    },
    {
      "x": -9,
      "y": 24,
      "z": 5,
      "name": "Rock_Ice_Permafrost"
    },
    {
      "x": -9,
      "y": 25,
      "z": 5,
      "name": "Rock_Ice_Permafrost"
    },
    {
      "x": -9,
      "y": 26,
      "z": 5,
      "name": "Rock_Ice_Permafrost"
    },
    {
      "x": -9,
      "y": 27,
      "z": 5,
      "name": "Rock_Ice"
    },
    {
      "x": -9,
      "y": 28,
      "z": 5,
      "name": "Soil_Snow"
    },
    {
      "x": -9,
      "y": 4,
      "z": 6,
      "name": "Rock_Ice"
    },
    {
      "x": -9,
      "y": 5,
      "z": 6,
      "name": "Rock_Ice"
    },
    {
      "x": -9,
      "y": 6,
      "z": 6,
      "name": "Rock_Ice"
    },
    {
      "x": -9,
      "y": 7,
      "z": 6,
      "name": "Rock_Ice_Permafrost"
    },
    {
      "x": -9,
      "y": 8,
      "z": 6,
      "name": "Rock_Ice_Permafrost"
    },
    {
      "x": -9,
      "y": 9,
      "z": 6,
      "name": "Rock_Ice_Permafrost"
    },
    {
      "x": -9,
      "y": 10,
      "z": 6,
      "name": "Rock_Ice_Permafrost"
    },
    {
      "x": -9,
      "y": 19,
      "z": 6,
      "name": "Rock_Ice_Permafrost"
    },
    {
      "x": -9,
      "y": 20,
      "z": 6,
      "name": "Rock_Ice_Permafrost"
    },
    {
      "x": -9,
      "y": 21,
      "z": 6,
      "name": "Rock_Ice_Permafrost"
    },
    {
      "x": -9,
      "y": 22,
      "z": 6,
      "name": "Rock_Ice_Permafrost"
    },
    {
      "x": -9,
      "y": 23,
      "z": 6,
      "name": "Rock_Ice_Permafrost"
    },
    {
      "x": -9,
      "y": 24,
      "z": 6,
      "name": "Rock_Ice_Permafrost"
    },
    {
      "x": -9,
      "y": 25,
      "z": 6,
      "name": "Rock_Ice_Permafrost"
    },
    {
      "x": -9,
      "y": 26,
      "z": 6,
      "name": "Rock_Ice_Permafrost"
    },
    {
      "x": -9,
      "y": 27,
      "z": 6,
      "name": "Rock_Ice_Permafrost"
    },
    {
      "x": -9,
      "y": 28,
      "z": 6,
      "name": "Rock_Ice"
    },
    {
      "x": -9,
      "y": 29,
      "z": 6,
      "name": "Soil_Snow"
    },
    {
      "x": -9,
      "y": 4,
      "z": 7,
      "name": "Rock_Ice"
    },
    {
      "x": -9,
      "y": 5,
      "z": 7,
      "name": "Rock_Ice"
    },
    {
      "x": -9,
      "y": 6,
      "z": 7,
      "name": "Rock_Ice"
    },
    {
      "x": -9,
      "y": 7,
      "z": 7,
      "name": "Rock_Ice_Permafrost"
    },
    {
      "x": -9,
      "y": 8,
      "z": 7,
      "name": "Rock_Ice_Permafrost"
    },
    {
      "x": -9,
      "y": 9,
      "z": 7,
      "name": "Rock_Ice_Permafrost"
    },
    {
      "x": -9,
      "y": 22,
      "z": 7,
      "name": "Rock_Ice_Permafrost"
    },
    {
      "x": -9,
      "y": 23,
      "z": 7,
      "name": "Rock_Ice_Permafrost"
    },
    {
      "x": -9,
      "y": 24,
      "z": 7,
      "name": "Rock_Ice_Permafrost"
    },
    {
      "x": -9,
      "y": 25,
      "z": 7,
      "name": "Rock_Ice_Permafrost"
    },
    {
      "x": -9,
      "y": 26,
      "z": 7,
      "name": "Rock_Ice_Permafrost"
    },
    {
      "x": -9,
      "y": 27,
      "z": 7,
      "name": "Rock_Ice_Permafrost"
    },
    {
      "x": -9,
      "y": 28,
      "z": 7,
      "name": "Rock_Ice_Permafrost"
    },
    {
      "x": -9,
      "y": 29,
      "z": 7,
      "name": "Rock_Ice"
    },
    {
      "x": -9,
      "y": 30,
      "z": 7,
      "name": "Soil_Snow"
    },
    {
      "x": -9,
      "y": 25,
      "z": 8,
      "name": "Rock_Ice_Permafrost"
    },
    {
      "x": -9,
      "y": 26,
      "z": 8,
      "name": "Rock_Ice_Permafrost"
    },
    {
      "x": -9,
      "y": 27,
      "z": 8,
      "name": "Rock_Ice_Permafrost"
    },
    {
      "x": -9,
      "y": 28,
      "z": 8,
      "name": "Rock_Ice_Permafrost"
    },
    {
      "x": -9,
      "y": 29,
      "z": 8,
      "name": "Rock_Ice_Permafrost"
    },
    {
      "x": -9,
      "y": 30,
      "z": 8,
      "name": "Rock_Ice_Permafrost"
    },
    {
      "x": -9,
      "y": 31,
      "z": 8,
      "name": "Rock_Ice"
    },
    {
      "x": -9,
      "y": 32,
      "z": 8,
      "name": "Soil_Snow"
    },
    {
      "x": -9,
      "y": 2,
      "z": 9,
      "name": "Soil_Snow"
    },
    {
      "x": -9,
      "y": 27,
      "z": 9,
      "name": "Rock_Ice_Permafrost"
    },
    {
      "x": -9,
      "y": 28,
      "z": 9,
      "name": "Rock_Ice_Permafrost"
    },
    {
      "x": -9,
      "y": 29,
      "z": 9,
      "name": "Rock_Ice_Permafrost"
    },
    {
      "x": -9,
      "y": 30,
      "z": 9,
      "name": "Rock_Ice_Permafrost"
    },
    {
      "x": -9,
      "y": 31,
      "z": 9,
      "name": "Rock_Ice_Permafrost"
    },
    {
      "x": -9,
      "y": 32,
      "z": 9,
      "name": "Rock_Ice"
    },
    {
      "x": -9,
      "y": 33,
      "z": 9,
      "name": "Soil_Snow"
    },
    {
      "x": -9,
      "y": 28,
      "z": 10,
      "name": "Rock_Ice_Permafrost"
    },
    {
      "x": -9,
      "y": 29,
      "z": 10,
      "name": "Rock_Ice_Permafrost"
    },
    {
      "x": -9,
      "y": 30,
      "z": 10,
      "name": "Rock_Ice_Permafrost"
    },
    {
      "x": -9,
      "y": 31,
      "z": 10,
      "name": "Rock_Ice_Permafrost"
    },
    {
      "x": -9,
      "y": 32,
      "z": 10,
      "name": "Rock_Ice_Permafrost"
    },
    {
      "x": -9,
      "y": 33,
      "z": 10,
      "name": "Rock_Ice"
    },
    {
      "x": -9,
      "y": 34,
      "z": 10,
      "name": "Soil_Snow"
    },
    {
      "x": -9,
      "y": 30,
      "z": 11,
      "name": "Rock_Ice_Permafrost"
    },
    {
      "x": -9,
      "y": 31,
      "z": 11,
      "name": "Rock_Ice_Permafrost"
    },
    {
      "x": -9,
      "y": 32,
      "z": 11,
      "name": "Rock_Ice_Permafrost"
    },
    {
      "x": -9,
      "y": 33,
      "z": 11,
      "name": "Rock_Ice_Permafrost"
    },
    {
      "x": -9,
      "y": 34,
      "z": 11,
      "name": "Rock_Ice"
    },
    {
      "x": -9,
      "y": 35,
      "z": 11,
      "name": "Soil_Snow"
    },
    {
      "x": -9,
      "y": 31,
      "z": 12,
      "name": "Rock_Ice_Permafrost"
    },
    {
      "x": -9,
      "y": 32,
      "z": 12,
      "name": "Rock_Ice_Permafrost"
    },
    {
      "x": -9,
      "y": 33,
      "z": 12,
      "name": "Rock_Ice_Permafrost"
    },
    {
      "x": -9,
      "y": 34,
      "z": 12,
      "name": "Rock_Ice"
    },
    {
      "x": -9,
      "y": 35,
      "z": 12,
      "name": "Rock_Ice"
    },
    {
      "x": -9,
      "y": 36,
      "z": 12,
      "name": "Soil_Snow"
    },
    {
      "x": -9,
      "y": 33,
      "z": 13,
      "name": "Rock_Ice_Permafrost"
    },
    {
      "x": -9,
      "y": 34,
      "z": 13,
      "name": "Rock_Ice_Permafrost"
    },
    {
      "x": -9,
      "y": 35,
      "z": 13,
      "name": "Rock_Ice"
    },
    {
      "x": -9,
      "y": 36,
      "z": 13,
      "name": "Rock_Ice"
    },
    {
      "x": -9,
      "y": 37,
      "z": 13,
      "name": "Rock_Ice"
    },
    {
      "x": -9,
      "y": 38,
      "z": 13,
      "name": "Soil_Snow"
    },
    {
      "x": -9,
      "y": 33,
      "z": 14,
      "name": "Rock_Ice_Permafrost"
    },
    {
      "x": -9,
      "y": 34,
      "z": 14,
      "name": "Rock_Ice"
    },
    {
      "x": -9,
      "y": 35,
      "z": 14,
      "name": "Soil_Snow"
    },
    {
      "x": -9,
      "y": 32,
      "z": 15,
      "name": "Rock_Ice_Permafrost"
    },
    {
      "x": -9,
      "y": 33,
      "z": 15,
      "name": "Rock_Ice_Permafrost"
    },
    {
      "x": -9,
      "y": 34,
      "z": 15,
      "name": "Soil_Snow"
    },
    {
      "x": -9,
      "y": 31,
      "z": 16,
      "name": "Rock_Ice_Permafrost"
    },
    {
      "x": -9,
      "y": 32,
      "z": 16,
      "name": "Rock_Ice"
    },
    {
      "x": -9,
      "y": 33,
      "z": 16,
      "name": "Soil_Snow"
    },
    {
      "x": -8,
      "y": 28,
      "z": -9,
      "name": "Rock_Ice"
    },
    {
      "x": -8,
      "y": 29,
      "z": -9,
      "name": "Soil_Snow"
    },
    {
      "x": -8,
      "y": 27,
      "z": -8,
      "name": "Rock_Ice"
    },
    {
      "x": -8,
      "y": 28,
      "z": -8,
      "name": "Rock_Ice"
    },
    {
      "x": -8,
      "y": 29,
      "z": -8,
      "name": "Rock_Ice"
    },
    {
      "x": -8,
      "y": 30,
      "z": -8,
      "name": "Soil_Snow"
    },
    {
      "x": -8,
      "y": 25,
      "z": -7,
      "name": "Rock_Ice"
    },
    {
      "x": -8,
      "y": 26,
      "z": -7,
      "name": "Rock_Ice"
    },
    {
      "x": -8,
      "y": 27,
      "z": -7,
      "name": "Rock_Ice"
    },
    {
      "x": -8,
      "y": 28,
      "z": -7,
      "name": "Rock_Ice"
    },
    {
      "x": -8,
      "y": 29,
      "z": -7,
      "name": "Rock_Ice"
    },
    {
      "x": -8,
      "y": 30,
      "z": -7,
      "name": "Rock_Ice"
    },
    {
      "x": -8,
      "y": 31,
      "z": -7,
      "name": "Soil_Snow"
    },
    {
      "x": -8,
      "y": 24,
      "z": -6,
      "name": "Rock_Ice"
    },
    {
      "x": -8,
      "y": 25,
      "z": -6,
      "name": "Rock_Ice"
    },
    {
      "x": -8,
      "y": 26,
      "z": -6,
      "name": "Rock_Ice"
    },
    {
      "x": -8,
      "y": 27,
      "z": -6,
      "name": "Rock_Ice"
    },
    {
      "x": -8,
      "y": 28,
      "z": -6,
      "name": "Rock_Ice"
    },
    {
      "x": -8,
      "y": 29,
      "z": -6,
      "name": "Rock_Ice"
    },
    {
      "x": -8,
      "y": 30,
      "z": -6,
      "name": "Rock_Ice"
    },
    {
      "x": -8,
      "y": 31,
      "z": -6,
      "name": "Rock_Ice"
    },
    {
      "x": -8,
      "y": 32,
      "z": -6,
      "name": "Rock_Ice"
    },
    {
      "x": -8,
      "y": 38,
      "z": -6,
      "name": "Rock_Ice"
    },
    {
      "x": -8,
      "y": 39,
      "z": -6,
      "name": "Rock_Ice"
    },
    {
      "x": -8,
      "y": 40,
      "z": -6,
      "name": "Rock_Ice_Permafrost"
    },
    {
      "x": -8,
      "y": 41,
      "z": -6,
      "name": "Rock_Ice_Permafrost"
    },
    {
      "x": -8,
      "y": 42,
      "z": -6,
      "name": "Rock_Ice"
    },
    {
      "x": -8,
      "y": 10,
      "z": -5,
      "name": "Rock_Ice"
    },
    {
      "x": -8,
      "y": 23,
      "z": -5,
      "name": "Rock_Ice"
    },
    {
      "x": -8,
      "y": 24,
      "z": -5,
      "name": "Rock_Ice"
    },
    {
      "x": -8,
      "y": 25,
      "z": -5,
      "name": "Rock_Ice"
    },
    {
      "x": -8,
      "y": 26,
      "z": -5,
      "name": "Rock_Ice"
    },
    {
      "x": -8,
      "y": 27,
      "z": -5,
      "name": "Rock_Ice"
    },
    {
      "x": -8,
      "y": 28,
      "z": -5,
      "name": "Rock_Ice"
    },
    {
      "x": -8,
      "y": 29,
      "z": -5,
      "name": "Rock_Ice"
    },
    {
      "x": -8,
      "y": 30,
      "z": -5,
      "name": "Rock_Ice"
    },
    {
      "x": -8,
      "y": 31,
      "z": -5,
      "name": "Rock_Ice"
    },
    {
      "x": -8,
      "y": 32,
      "z": -5,
      "name": "Rock_Ice"
    },
    {
      "x": -8,
      "y": 33,
      "z": -5,
      "name": "Rock_Ice"
    },
    {
      "x": -8,
      "y": 34,
      "z": -5,
      "name": "Rock_Ice"
    },
    {
      "x": -8,
      "y": 35,
      "z": -5,
      "name": "Rock_Ice"
    },
    {
      "x": -8,
      "y": 36,
      "z": -5,
      "name": "Rock_Ice"
    },
    {
      "x": -8,
      "y": 37,
      "z": -5,
      "name": "Rock_Ice"
    },
    {
      "x": -8,
      "y": 38,
      "z": -5,
      "name": "Rock_Ice_Permafrost"
    },
    {
      "x": -8,
      "y": 39,
      "z": -5,
      "name": "Rock_Ice_Permafrost"
    },
    {
      "x": -8,
      "y": 40,
      "z": -5,
      "name": "Rock_Ice_Permafrost"
    },
    {
      "x": -8,
      "y": 41,
      "z": -5,
      "name": "Rock_Ice_Permafrost"
    },
    {
      "x": -8,
      "y": 42,
      "z": -5,
      "name": "Rock_Ice"
    },
    {
      "x": -8,
      "y": 43,
      "z": -5,
      "name": "Rock_Ice"
    },
    {
      "x": -8,
      "y": 44,
      "z": -5,
      "name": "Rock_Ice"
    },
    {
      "x": -8,
      "y": 45,
      "z": -5,
      "name": "Rock_Ice"
    },
    {
      "x": -8,
      "y": 46,
      "z": -5,
      "name": "Soil_Snow"
    },
    {
      "x": -8,
      "y": 10,
      "z": -4,
      "name": "Rock_Ice"
    },
    {
      "x": -8,
      "y": 11,
      "z": -4,
      "name": "Rock_Ice"
    },
    {
      "x": -8,
      "y": 12,
      "z": -4,
      "name": "Rock_Ice"
    },
    {
      "x": -8,
      "y": 13,
      "z": -4,
      "name": "Rock_Ice_Permafrost"
    },
    {
      "x": -8,
      "y": 14,
      "z": -4,
      "name": "Rock_Ice_Permafrost"
    },
    {
      "x": -8,
      "y": 15,
      "z": -4,
      "name": "Rock_Ice_Permafrost"
    },
    {
      "x": -8,
      "y": 16,
      "z": -4,
      "name": "Rock_Ice"
    },
    {
      "x": -8,
      "y": 18,
      "z": -4,
      "name": "Rock_Ice"
    },
    {
      "x": -8,
      "y": 19,
      "z": -4,
      "name": "Rock_Ice"
    },
    {
      "x": -8,
      "y": 20,
      "z": -4,
      "name": "Rock_Ice"
    },
    {
      "x": -8,
      "y": 21,
      "z": -4,
      "name": "Rock_Ice"
    },
    {
      "x": -8,
      "y": 22,
      "z": -4,
      "name": "Rock_Ice"
    },
    {
      "x": -8,
      "y": 23,
      "z": -4,
      "name": "Rock_Ice"
    },
    {
      "x": -8,
      "y": 24,
      "z": -4,
      "name": "Rock_Ice"
    },
    {
      "x": -8,
      "y": 25,
      "z": -4,
      "name": "Rock_Ice"
    },
    {
      "x": -8,
      "y": 26,
      "z": -4,
      "name": "Rock_Ice"
    },
    {
      "x": -8,
      "y": 27,
      "z": -4,
      "name": "Rock_Ice"
    },
    {
      "x": -8,
      "y": 28,
      "z": -4,
      "name": "Rock_Ice"
    },
    {
      "x": -8,
      "y": 29,
      "z": -4,
      "name": "Rock_Ice"
    },
    {
      "x": -8,
      "y": 30,
      "z": -4,
      "name": "Rock_Ice"
    },
    {
      "x": -8,
      "y": 31,
      "z": -4,
      "name": "Rock_Ice"
    },
    {
      "x": -8,
      "y": 32,
      "z": -4,
      "name": "Rock_Ice"
    },
    {
      "x": -8,
      "y": 33,
      "z": -4,
      "name": "Rock_Ice"
    },
    {
      "x": -8,
      "y": 34,
      "z": -4,
      "name": "Rock_Ice"
    },
    {
      "x": -8,
      "y": 35,
      "z": -4,
      "name": "Rock_Ice_Permafrost"
    },
    {
      "x": -8,
      "y": 36,
      "z": -4,
      "name": "Rock_Ice_Permafrost"
    },
    {
      "x": -8,
      "y": 37,
      "z": -4,
      "name": "Rock_Ice_Permafrost"
    },
    {
      "x": -8,
      "y": 38,
      "z": -4,
      "name": "Rock_Ice_Permafrost"
    },
    {
      "x": -8,
      "y": 39,
      "z": -4,
      "name": "Rock_Ice_Permafrost"
    },
    {
      "x": -8,
      "y": 40,
      "z": -4,
      "name": "Rock_Ice_Permafrost"
    },
    {
      "x": -8,
      "y": 41,
      "z": -4,
      "name": "Rock_Ice_Permafrost"
    },
    {
      "x": -8,
      "y": 42,
      "z": -4,
      "name": "Rock_Ice_Permafrost"
    },
    {
      "x": -8,
      "y": 43,
      "z": -4,
      "name": "Rock_Ice"
    },
    {
      "x": -8,
      "y": 44,
      "z": -4,
      "name": "Rock_Ice"
    },
    {
      "x": -8,
      "y": 45,
      "z": -4,
      "name": "Rock_Ice"
    },
    {
      "x": -8,
      "y": 46,
      "z": -4,
      "name": "Rock_Ice"
    },
    {
      "x": -8,
      "y": 47,
      "z": -4,
      "name": "Rock_Ice"
    },
    {
      "x": -8,
      "y": 48,
      "z": -4,
      "name": "Soil_Snow"
    },
    {
      "x": -8,
      "y": 11,
      "z": -3,
      "name": "Rock_Ice"
    },
    {
      "x": -8,
      "y": 12,
      "z": -3,
      "name": "Rock_Ice"
    },
    {
      "x": -8,
      "y": 13,
      "z": -3,
      "name": "Rock_Ice_Permafrost"
    },
    {
      "x": -8,
      "y": 14,
      "z": -3,
      "name": "Rock_Ice_Permafrost"
    },
    {
      "x": -8,
      "y": 15,
      "z": -3,
      "name": "Rock_Ice"
    },
    {
      "x": -8,
      "y": 16,
      "z": -3,
      "name": "Rock_Ice"
    },
    {
      "x": -8,
      "y": 17,
      "z": -3,
      "name": "Rock_Ice"
    },
    {
      "x": -8,
      "y": 18,
      "z": -3,
      "name": "Rock_Ice"
    },
    {
      "x": -8,
      "y": 19,
      "z": -3,
      "name": "Rock_Ice"
    },
    {
      "x": -8,
      "y": 20,
      "z": -3,
      "name": "Rock_Ice"
    },
    {
      "x": -8,
      "y": 21,
      "z": -3,
      "name": "Rock_Ice"
    },
    {
      "x": -8,
      "y": 22,
      "z": -3,
      "name": "Rock_Ice"
    },
    {
      "x": -8,
      "y": 23,
      "z": -3,
      "name": "Rock_Ice"
    },
    {
      "x": -8,
      "y": 24,
      "z": -3,
      "name": "Rock_Ice"
    },
    {
      "x": -8,
      "y": 25,
      "z": -3,
      "name": "Rock_Ice"
    },
    {
      "x": -8,
      "y": 26,
      "z": -3,
      "name": "Rock_Ice"
    },
    {
      "x": -8,
      "y": 27,
      "z": -3,
      "name": "Rock_Ice"
    },
    {
      "x": -8,
      "y": 28,
      "z": -3,
      "name": "Rock_Ice"
    },
    {
      "x": -8,
      "y": 29,
      "z": -3,
      "name": "Rock_Ice"
    },
    {
      "x": -8,
      "y": 30,
      "z": -3,
      "name": "Rock_Ice_Permafrost"
    },
    {
      "x": -8,
      "y": 31,
      "z": -3,
      "name": "Rock_Ice_Permafrost"
    },
    {
      "x": -8,
      "y": 32,
      "z": -3,
      "name": "Rock_Ice_Permafrost"
    },
    {
      "x": -8,
      "y": 33,
      "z": -3,
      "name": "Rock_Ice_Permafrost"
    },
    {
      "x": -8,
      "y": 34,
      "z": -3,
      "name": "Rock_Ice_Permafrost"
    },
    {
      "x": -8,
      "y": 35,
      "z": -3,
      "name": "Rock_Ice_Permafrost"
    },
    {
      "x": -8,
      "y": 36,
      "z": -3,
      "name": "Rock_Ice"
    },
    {
      "x": -8,
      "y": 37,
      "z": -3,
      "name": "Rock_Ice_Permafrost"
    },
    {
      "x": -8,
      "y": 38,
      "z": -3,
      "name": "Rock_Ice_Permafrost"
    },
    {
      "x": -8,
      "y": 39,
      "z": -3,
      "name": "Rock_Ice_Permafrost"
    },
    {
      "x": -8,
      "y": 40,
      "z": -3,
      "name": "Rock_Ice_Permafrost"
    },
    {
      "x": -8,
      "y": 41,
      "z": -3,
      "name": "Rock_Ice_Permafrost"
    },
    {
      "x": -8,
      "y": 42,
      "z": -3,
      "name": "Rock_Ice_Permafrost"
    },
    {
      "x": -8,
      "y": 43,
      "z": -3,
      "name": "Rock_Ice"
    },
    {
      "x": -8,
      "y": 44,
      "z": -3,
      "name": "Rock_Ice"
    },
    {
      "x": -8,
      "y": 45,
      "z": -3,
      "name": "Rock_Ice"
    },
    {
      "x": -8,
      "y": 46,
      "z": -3,
      "name": "Soil_Snow"
    },
    {
      "x": -8,
      "y": 11,
      "z": -2,
      "name": "Rock_Ice"
    },
    {
      "x": -8,
      "y": 12,
      "z": -2,
      "name": "Rock_Ice_Permafrost"
    },
    {
      "x": -8,
      "y": 13,
      "z": -2,
      "name": "Rock_Ice_Permafrost"
    },
    {
      "x": -8,
      "y": 14,
      "z": -2,
      "name": "Rock_Ice_Permafrost"
    },
    {
      "x": -8,
      "y": 15,
      "z": -2,
      "name": "Rock_Ice"
    },
    {
      "x": -8,
      "y": 16,
      "z": -2,
      "name": "Rock_Ice"
    },
    {
      "x": -8,
      "y": 17,
      "z": -2,
      "name": "Rock_Ice"
    },
    {
      "x": -8,
      "y": 18,
      "z": -2,
      "name": "Rock_Ice"
    },
    {
      "x": -8,
      "y": 19,
      "z": -2,
      "name": "Rock_Ice"
    },
    {
      "x": -8,
      "y": 20,
      "z": -2,
      "name": "Rock_Ice"
    },
    {
      "x": -8,
      "y": 21,
      "z": -2,
      "name": "Rock_Ice"
    },
    {
      "x": -8,
      "y": 22,
      "z": -2,
      "name": "Rock_Ice"
    },
    {
      "x": -8,
      "y": 23,
      "z": -2,
      "name": "Rock_Ice"
    },
    {
      "x": -8,
      "y": 24,
      "z": -2,
      "name": "Rock_Ice"
    },
    {
      "x": -8,
      "y": 25,
      "z": -2,
      "name": "Rock_Ice"
    },
    {
      "x": -8,
      "y": 26,
      "z": -2,
      "name": "Rock_Ice"
    },
    {
      "x": -8,
      "y": 27,
      "z": -2,
      "name": "Rock_Ice"
    },
    {
      "x": -8,
      "y": 43,
      "z": -2,
      "name": "Rock_Ice_Permafrost"
    },
    {
      "x": -8,
      "y": 10,
      "z": -1,
      "name": "Rock_Ice"
    },
    {
      "x": -8,
      "y": 11,
      "z": -1,
      "name": "Rock_Ice"
    },
    {
      "x": -8,
      "y": 12,
      "z": -1,
      "name": "Rock_Ice_Permafrost"
    },
    {
      "x": -8,
      "y": 13,
      "z": -1,
      "name": "Rock_Ice_Permafrost"
    },
    {
      "x": -8,
      "y": 14,
      "z": -1,
      "name": "Rock_Ice"
    },
    {
      "x": -8,
      "y": 15,
      "z": -1,
      "name": "Rock_Ice"
    },
    {
      "x": -8,
      "y": 16,
      "z": -1,
      "name": "Rock_Ice"
    },
    {
      "x": -8,
      "y": 17,
      "z": -1,
      "name": "Rock_Ice"
    },
    {
      "x": -8,
      "y": 18,
      "z": -1,
      "name": "Rock_Ice"
    },
    {
      "x": -8,
      "y": 19,
      "z": -1,
      "name": "Rock_Ice"
    },
    {
      "x": -8,
      "y": 20,
      "z": -1,
      "name": "Rock_Ice"
    },
    {
      "x": -8,
      "y": 21,
      "z": -1,
      "name": "Rock_Ice"
    },
    {
      "x": -8,
      "y": 22,
      "z": -1,
      "name": "Rock_Ice"
    },
    {
      "x": -8,
      "y": 23,
      "z": -1,
      "name": "Rock_Ice"
    },
    {
      "x": -8,
      "y": 24,
      "z": -1,
      "name": "Rock_Ice"
    },
    {
      "x": -8,
      "y": 25,
      "z": -1,
      "name": "Rock_Ice"
    },
    {
      "x": -8,
      "y": 26,
      "z": -1,
      "name": "Rock_Ice_Permafrost"
    },
    {
      "x": -8,
      "y": 27,
      "z": -1,
      "name": "Rock_Ice"
    },
    {
      "x": -8,
      "y": 28,
      "z": -1,
      "name": "Soil_Snow"
    },
    {
      "x": -8,
      "y": 9,
      "z": 0,
      "name": "Rock_Ice"
    },
    {
      "x": -8,
      "y": 10,
      "z": 0,
      "name": "Rock_Ice"
    },
    {
      "x": -8,
      "y": 11,
      "z": 0,
      "name": "Rock_Ice_Permafrost"
    },
    {
      "x": -8,
      "y": 12,
      "z": 0,
      "name": "Rock_Ice_Permafrost"
    },
    {
      "x": -8,
      "y": 13,
      "z": 0,
      "name": "Rock_Ice_Permafrost"
    },
    {
      "x": -8,
      "y": 14,
      "z": 0,
      "name": "Rock_Ice_Permafrost"
    },
    {
      "x": -8,
      "y": 15,
      "z": 0,
      "name": "Rock_Ice"
    },
    {
      "x": -8,
      "y": 16,
      "z": 0,
      "name": "Rock_Ice"
    },
    {
      "x": -8,
      "y": 17,
      "z": 0,
      "name": "Rock_Ice"
    },
    {
      "x": -8,
      "y": 18,
      "z": 0,
      "name": "Rock_Ice"
    },
    {
      "x": -8,
      "y": 19,
      "z": 0,
      "name": "Rock_Ice"
    },
    {
      "x": -8,
      "y": 20,
      "z": 0,
      "name": "Rock_Ice"
    },
    {
      "x": -8,
      "y": 21,
      "z": 0,
      "name": "Rock_Ice"
    },
    {
      "x": -8,
      "y": 22,
      "z": 0,
      "name": "Rock_Ice"
    },
    {
      "x": -8,
      "y": 23,
      "z": 0,
      "name": "Rock_Ice"
    },
    {
      "x": -8,
      "y": 24,
      "z": 0,
      "name": "Rock_Ice"
    },
    {
      "x": -8,
      "y": 25,
      "z": 0,
      "name": "Rock_Ice_Permafrost"
    },
    {
      "x": -8,
      "y": 26,
      "z": 0,
      "name": "Rock_Ice_Permafrost"
    },
    {
      "x": -8,
      "y": 27,
      "z": 0,
      "name": "Rock_Ice"
    },
    {
      "x": -8,
      "y": 28,
      "z": 0,
      "name": "Soil_Snow"
    },
    {
      "x": -8,
      "y": 7,
      "z": 1,
      "name": "Rock_Ice"
    },
    {
      "x": -8,
      "y": 8,
      "z": 1,
      "name": "Rock_Ice"
    },
    {
      "x": -8,
      "y": 9,
      "z": 1,
      "name": "Rock_Ice"
    },
    {
      "x": -8,
      "y": 10,
      "z": 1,
      "name": "Rock_Ice_Permafrost"
    },
    {
      "x": -8,
      "y": 11,
      "z": 1,
      "name": "Rock_Ice_Permafrost"
    },
    {
      "x": -8,
      "y": 12,
      "z": 1,
      "name": "Rock_Ice_Permafrost"
    },
    {
      "x": -8,
      "y": 13,
      "z": 1,
      "name": "Rock_Ice"
    },
    {
      "x": -8,
      "y": 14,
      "z": 1,
      "name": "Rock_Ice"
    },
    {
      "x": -8,
      "y": 15,
      "z": 1,
      "name": "Rock_Ice"
    },
    {
      "x": -8,
      "y": 16,
      "z": 1,
      "name": "Rock_Ice"
    },
    {
      "x": -8,
      "y": 17,
      "z": 1,
      "name": "Rock_Ice"
    },
    {
      "x": -8,
      "y": 18,
      "z": 1,
      "name": "Rock_Ice"
    },
    {
      "x": -8,
      "y": 19,
      "z": 1,
      "name": "Rock_Ice"
    },
    {
      "x": -8,
      "y": 20,
      "z": 1,
      "name": "Rock_Ice"
    },
    {
      "x": -8,
      "y": 21,
      "z": 1,
      "name": "Rock_Ice"
    },
    {
      "x": -8,
      "y": 22,
      "z": 1,
      "name": "Rock_Ice"
    },
    {
      "x": -8,
      "y": 23,
      "z": 1,
      "name": "Rock_Ice"
    },
    {
      "x": -8,
      "y": 24,
      "z": 1,
      "name": "Rock_Ice_Permafrost"
    },
    {
      "x": -8,
      "y": 25,
      "z": 1,
      "name": "Rock_Ice_Permafrost"
    },
    {
      "x": -8,
      "y": 26,
      "z": 1,
      "name": "Rock_Ice_Permafrost"
    },
    {
      "x": -8,
      "y": 27,
      "z": 1,
      "name": "Rock_Ice_Permafrost"
    },
    {
      "x": -8,
      "y": 28,
      "z": 1,
      "name": "Rock_Ice"
    },
    {
      "x": -8,
      "y": 29,
      "z": 1,
      "name": "Soil_Snow"
    },
    {
      "x": -8,
      "y": 5,
      "z": 2,
      "name": "Rock_Ice"
    },
    {
      "x": -8,
      "y": 6,
      "z": 2,
      "name": "Rock_Ice"
    },
    {
      "x": -8,
      "y": 7,
      "z": 2,
      "name": "Rock_Ice"
    },
    {
      "x": -8,
      "y": 8,
      "z": 2,
      "name": "Rock_Ice"
    },
    {
      "x": -8,
      "y": 9,
      "z": 2,
      "name": "Rock_Ice"
    },
    {
      "x": -8,
      "y": 10,
      "z": 2,
      "name": "Rock_Ice_Permafrost"
    },
    {
      "x": -8,
      "y": 11,
      "z": 2,
      "name": "Rock_Ice_Permafrost"
    },
    {
      "x": -8,
      "y": 12,
      "z": 2,
      "name": "Rock_Ice_Permafrost"
    },
    {
      "x": -8,
      "y": 13,
      "z": 2,
      "name": "Rock_Ice"
    },
    {
      "x": -8,
      "y": 14,
      "z": 2,
      "name": "Rock_Ice"
    },
    {
      "x": -8,
      "y": 15,
      "z": 2,
      "name": "Rock_Ice"
    },
    {
      "x": -8,
      "y": 16,
      "z": 2,
      "name": "Rock_Ice"
    },
    {
      "x": -8,
      "y": 17,
      "z": 2,
      "name": "Rock_Ice"
    },
    {
      "x": -8,
      "y": 18,
      "z": 2,
      "name": "Rock_Ice"
    },
    {
      "x": -8,
      "y": 19,
      "z": 2,
      "name": "Rock_Ice"
    },
    {
      "x": -8,
      "y": 20,
      "z": 2,
      "name": "Rock_Ice"
    },
    {
      "x": -8,
      "y": 21,
      "z": 2,
      "name": "Rock_Ice"
    },
    {
      "x": -8,
      "y": 22,
      "z": 2,
      "name": "Rock_Ice_Permafrost"
    },
    {
      "x": -8,
      "y": 23,
      "z": 2,
      "name": "Rock_Ice_Permafrost"
    },
    {
      "x": -8,
      "y": 24,
      "z": 2,
      "name": "Rock_Ice_Permafrost"
    },
    {
      "x": -8,
      "y": 25,
      "z": 2,
      "name": "Rock_Ice_Permafrost"
    },
    {
      "x": -8,
      "y": 26,
      "z": 2,
      "name": "Rock_Ice_Permafrost"
    },
    {
      "x": -8,
      "y": 27,
      "z": 2,
      "name": "Rock_Ice"
    },
    {
      "x": -8,
      "y": 28,
      "z": 2,
      "name": "Rock_Ice"
    },
    {
      "x": -8,
      "y": 29,
      "z": 2,
      "name": "Soil_Snow"
    },
    {
      "x": -8,
      "y": 3,
      "z": 3,
      "name": "Rock_Ice"
    },
    {
      "x": -8,
      "y": 4,
      "z": 3,
      "name": "Rock_Ice"
    },
    {
      "x": -8,
      "y": 5,
      "z": 3,
      "name": "Rock_Ice"
    },
    {
      "x": -8,
      "y": 6,
      "z": 3,
      "name": "Rock_Ice"
    },
    {
      "x": -8,
      "y": 7,
      "z": 3,
      "name": "Rock_Ice"
    },
    {
      "x": -8,
      "y": 8,
      "z": 3,
      "name": "Rock_Ice"
    },
    {
      "x": -8,
      "y": 9,
      "z": 3,
      "name": "Rock_Ice"
    },
    {
      "x": -8,
      "y": 10,
      "z": 3,
      "name": "Rock_Ice_Permafrost"
    },
    {
      "x": -8,
      "y": 11,
      "z": 3,
      "name": "Rock_Ice_Permafrost"
    },
    {
      "x": -8,
      "y": 12,
      "z": 3,
      "name": "Rock_Ice_Permafrost"
    },
    {
      "x": -8,
      "y": 13,
      "z": 3,
      "name": "Rock_Ice"
    },
    {
      "x": -8,
      "y": 14,
      "z": 3,
      "name": "Rock_Ice"
    },
    {
      "x": -8,
      "y": 15,
      "z": 3,
      "name": "Rock_Ice"
    },
    {
      "x": -8,
      "y": 16,
      "z": 3,
      "name": "Rock_Ice"
    },
    {
      "x": -8,
      "y": 17,
      "z": 3,
      "name": "Rock_Ice"
    },
    {
      "x": -8,
      "y": 18,
      "z": 3,
      "name": "Rock_Ice"
    },
    {
      "x": -8,
      "y": 19,
      "z": 3,
      "name": "Rock_Ice"
    },
    {
      "x": -8,
      "y": 20,
      "z": 3,
      "name": "Rock_Ice"
    },
    {
      "x": -8,
      "y": 21,
      "z": 3,
      "name": "Rock_Ice_Permafrost"
    },
    {
      "x": -8,
      "y": 22,
      "z": 3,
      "name": "Rock_Ice_Permafrost"
    },
    {
      "x": -8,
      "y": 23,
      "z": 3,
      "name": "Rock_Ice_Permafrost"
    },
    {
      "x": -8,
      "y": 24,
      "z": 3,
      "name": "Rock_Ice_Permafrost"
    },
    {
      "x": -8,
      "y": 25,
      "z": 3,
      "name": "Rock_Ice"
    },
    {
      "x": -8,
      "y": 26,
      "z": 3,
      "name": "Rock_Ice_Permafrost"
    },
    {
      "x": -8,
      "y": 27,
      "z": 3,
      "name": "Rock_Ice"
    },
    {
      "x": -8,
      "y": 28,
      "z": 3,
      "name": "Rock_Ice"
    },
    {
      "x": -8,
      "y": 29,
      "z": 3,
      "name": "Rock_Ice"
    },
    {
      "x": -8,
      "y": 30,
      "z": 3,
      "name": "Soil_Snow"
    },
    {
      "x": -8,
      "y": 2,
      "z": 4,
      "name": "Rock_Ice"
    },
    {
      "x": -8,
      "y": 3,
      "z": 4,
      "name": "Rock_Ice"
    },
    {
      "x": -8,
      "y": 4,
      "z": 4,
      "name": "Rock_Ice"
    },
    {
      "x": -8,
      "y": 5,
      "z": 4,
      "name": "Rock_Ice"
    },
    {
      "x": -8,
      "y": 6,
      "z": 4,
      "name": "Rock_Ice"
    },
    {
      "x": -8,
      "y": 7,
      "z": 4,
      "name": "Rock_Ice"
    },
    {
      "x": -8,
      "y": 8,
      "z": 4,
      "name": "Rock_Ice"
    },
    {
      "x": -8,
      "y": 9,
      "z": 4,
      "name": "Rock_Ice_Permafrost"
    },
    {
      "x": -8,
      "y": 10,
      "z": 4,
      "name": "Rock_Ice_Permafrost"
    },
    {
      "x": -8,
      "y": 11,
      "z": 4,
      "name": "Rock_Ice_Permafrost"
    },
    {
      "x": -8,
      "y": 12,
      "z": 4,
      "name": "Rock_Ice"
    },
    {
      "x": -8,
      "y": 13,
      "z": 4,
      "name": "Rock_Ice_Permafrost"
    },
    {
      "x": -8,
      "y": 14,
      "z": 4,
      "name": "Rock_Ice"
    },
    {
      "x": -8,
      "y": 15,
      "z": 4,
      "name": "Rock_Ice_Permafrost"
    },
    {
      "x": -8,
      "y": 16,
      "z": 4,
      "name": "Rock_Ice"
    },
    {
      "x": -8,
      "y": 17,
      "z": 4,
      "name": "Rock_Ice_Permafrost"
    },
    {
      "x": -8,
      "y": 18,
      "z": 4,
      "name": "Rock_Ice_Permafrost"
    },
    {
      "x": -8,
      "y": 19,
      "z": 4,
      "name": "Rock_Ice_Permafrost"
    },
    {
      "x": -8,
      "y": 20,
      "z": 4,
      "name": "Rock_Ice_Permafrost"
    },
    {
      "x": -8,
      "y": 21,
      "z": 4,
      "name": "Rock_Ice_Permafrost"
    },
    {
      "x": -8,
      "y": 22,
      "z": 4,
      "name": "Rock_Ice_Permafrost"
    },
    {
      "x": -8,
      "y": 23,
      "z": 4,
      "name": "Rock_Ice_Permafrost"
    },
    {
      "x": -8,
      "y": 24,
      "z": 4,
      "name": "Rock_Ice_Permafrost"
    },
    {
      "x": -8,
      "y": 25,
      "z": 4,
      "name": "Rock_Ice_Permafrost"
    },
    {
      "x": -8,
      "y": 26,
      "z": 4,
      "name": "Rock_Ice"
    },
    {
      "x": -8,
      "y": 27,
      "z": 4,
      "name": "Rock_Ice"
    },
    {
      "x": -8,
      "y": 28,
      "z": 4,
      "name": "Rock_Ice"
    },
    {
      "x": -8,
      "y": 29,
      "z": 4,
      "name": "Rock_Ice"
    },
    {
      "x": -8,
      "y": 30,
      "z": 4,
      "name": "Rock_Ice"
    },
    {
      "x": -8,
      "y": 31,
      "z": 4,
      "name": "Soil_Snow"
    },
    {
      "x": -8,
      "y": 2,
      "z": 5,
      "name": "Rock_Ice"
    },
    {
      "x": -8,
      "y": 3,
      "z": 5,
      "name": "Rock_Ice"
    },
    {
      "x": -8,
      "y": 4,
      "z": 5,
      "name": "Rock_Ice"
    },
    {
      "x": -8,
      "y": 5,
      "z": 5,
      "name": "Rock_Ice"
    },
    {
      "x": -8,
      "y": 6,
      "z": 5,
      "name": "Rock_Ice"
    },
    {
      "x": -8,
      "y": 7,
      "z": 5,
      "name": "Rock_Ice"
    },
    {
      "x": -8,
      "y": 8,
      "z": 5,
      "name": "Rock_Ice_Permafrost"
    },
    {
      "x": -8,
      "y": 9,
      "z": 5,
      "name": "Rock_Ice_Permafrost"
    },
    {
      "x": -8,
      "y": 10,
      "z": 5,
      "name": "Rock_Ice_Permafrost"
    },
    {
      "x": -8,
      "y": 11,
      "z": 5,
      "name": "Rock_Ice_Permafrost"
    },
    {
      "x": -8,
      "y": 12,
      "z": 5,
      "name": "Rock_Ice_Permafrost"
    },
    {
      "x": -8,
      "y": 13,
      "z": 5,
      "name": "Rock_Ice_Permafrost"
    },
    {
      "x": -8,
      "y": 14,
      "z": 5,
      "name": "Rock_Ice_Permafrost"
    },
    {
      "x": -8,
      "y": 15,
      "z": 5,
      "name": "Rock_Ice_Permafrost"
    },
    {
      "x": -8,
      "y": 16,
      "z": 5,
      "name": "Rock_Ice_Permafrost"
    },
    {
      "x": -8,
      "y": 17,
      "z": 5,
      "name": "Rock_Ice_Permafrost"
    },
    {
      "x": -8,
      "y": 18,
      "z": 5,
      "name": "Rock_Ice_Permafrost"
    },
    {
      "x": -8,
      "y": 19,
      "z": 5,
      "name": "Rock_Ice_Permafrost"
    },
    {
      "x": -8,
      "y": 20,
      "z": 5,
      "name": "Rock_Ice_Permafrost"
    },
    {
      "x": -8,
      "y": 21,
      "z": 5,
      "name": "Rock_Ice_Permafrost"
    },
    {
      "x": -8,
      "y": 22,
      "z": 5,
      "name": "Rock_Ice_Permafrost"
    },
    {
      "x": -8,
      "y": 23,
      "z": 5,
      "name": "Rock_Ice_Permafrost"
    },
    {
      "x": -8,
      "y": 24,
      "z": 5,
      "name": "Rock_Ice_Permafrost"
    },
    {
      "x": -8,
      "y": 25,
      "z": 5,
      "name": "Rock_Ice"
    },
    {
      "x": -8,
      "y": 26,
      "z": 5,
      "name": "Rock_Ice"
    },
    {
      "x": -8,
      "y": 27,
      "z": 5,
      "name": "Rock_Ice"
    },
    {
      "x": -8,
      "y": 28,
      "z": 5,
      "name": "Rock_Ice"
    },
    {
      "x": -8,
      "y": 29,
      "z": 5,
      "name": "Rock_Ice"
    },
    {
      "x": -8,
      "y": 30,
      "z": 5,
      "name": "Rock_Ice"
    },
    {
      "x": -8,
      "y": 31,
      "z": 5,
      "name": "Rock_Ice"
    },
    {
      "x": -8,
      "y": 32,
      "z": 5,
      "name": "Soil_Snow"
    },
    {
      "x": -8,
      "y": 2,
      "z": 6,
      "name": "Rock_Ice"
    },
    {
      "x": -8,
      "y": 3,
      "z": 6,
      "name": "Rock_Ice"
    },
    {
      "x": -8,
      "y": 4,
      "z": 6,
      "name": "Rock_Ice"
    },
    {
      "x": -8,
      "y": 5,
      "z": 6,
      "name": "Rock_Ice"
    },
    {
      "x": -8,
      "y": 6,
      "z": 6,
      "name": "Rock_Ice"
    },
    {
      "x": -8,
      "y": 7,
      "z": 6,
      "name": "Rock_Ice"
    },
    {
      "x": -8,
      "y": 8,
      "z": 6,
      "name": "Rock_Ice_Permafrost"
    },
    {
      "x": -8,
      "y": 9,
      "z": 6,
      "name": "Rock_Ice_Permafrost"
    },
    {
      "x": -8,
      "y": 10,
      "z": 6,
      "name": "Rock_Ice_Permafrost"
    },
    {
      "x": -8,
      "y": 11,
      "z": 6,
      "name": "Rock_Ice_Permafrost"
    },
    {
      "x": -8,
      "y": 12,
      "z": 6,
      "name": "Rock_Ice_Permafrost"
    },
    {
      "x": -8,
      "y": 13,
      "z": 6,
      "name": "Rock_Ice_Permafrost"
    },
    {
      "x": -8,
      "y": 14,
      "z": 6,
      "name": "Rock_Ice_Permafrost"
    },
    {
      "x": -8,
      "y": 15,
      "z": 6,
      "name": "Rock_Ice_Permafrost"
    },
    {
      "x": -8,
      "y": 16,
      "z": 6,
      "name": "Rock_Ice_Permafrost"
    },
    {
      "x": -8,
      "y": 17,
      "z": 6,
      "name": "Rock_Ice_Permafrost"
    },
    {
      "x": -8,
      "y": 18,
      "z": 6,
      "name": "Rock_Ice_Permafrost"
    },
    {
      "x": -8,
      "y": 19,
      "z": 6,
      "name": "Rock_Ice_Permafrost"
    },
    {
      "x": -8,
      "y": 20,
      "z": 6,
      "name": "Rock_Ice_Permafrost"
    },
    {
      "x": -8,
      "y": 21,
      "z": 6,
      "name": "Rock_Ice_Permafrost"
    },
    {
      "x": -8,
      "y": 22,
      "z": 6,
      "name": "Rock_Ice_Permafrost"
    },
    {
      "x": -8,
      "y": 23,
      "z": 6,
      "name": "Rock_Ice_Permafrost"
    },
    {
      "x": -8,
      "y": 24,
      "z": 6,
      "name": "Rock_Ice"
    },
    {
      "x": -8,
      "y": 25,
      "z": 6,
      "name": "Rock_Ice"
    },
    {
      "x": -8,
      "y": 26,
      "z": 6,
      "name": "Rock_Ice"
    },
    {
      "x": -8,
      "y": 27,
      "z": 6,
      "name": "Rock_Ice"
    },
    {
      "x": -8,
      "y": 28,
      "z": 6,
      "name": "Rock_Ice"
    },
    {
      "x": -8,
      "y": 29,
      "z": 6,
      "name": "Rock_Ice"
    },
    {
      "x": -8,
      "y": 30,
      "z": 6,
      "name": "Rock_Ice"
    },
    {
      "x": -8,
      "y": 31,
      "z": 6,
      "name": "Rock_Ice"
    },
    {
      "x": -8,
      "y": 32,
      "z": 6,
      "name": "Rock_Ice"
    },
    {
      "x": -8,
      "y": 33,
      "z": 6,
      "name": "Soil_Snow"
    },
    {
      "x": -8,
      "y": 3,
      "z": 7,
      "name": "Rock_Ice"
    },
    {
      "x": -8,
      "y": 4,
      "z": 7,
      "name": "Rock_Ice"
    },
    {
      "x": -8,
      "y": 5,
      "z": 7,
      "name": "Rock_Ice"
    },
    {
      "x": -8,
      "y": 6,
      "z": 7,
      "name": "Rock_Ice"
    },
    {
      "x": -8,
      "y": 7,
      "z": 7,
      "name": "Rock_Ice_Permafrost"
    },
    {
      "x": -8,
      "y": 8,
      "z": 7,
      "name": "Rock_Ice_Permafrost"
    },
    {
      "x": -8,
      "y": 9,
      "z": 7,
      "name": "Rock_Ice_Permafrost"
    },
    {
      "x": -8,
      "y": 10,
      "z": 7,
      "name": "Rock_Ice_Permafrost"
    },
    {
      "x": -8,
      "y": 11,
      "z": 7,
      "name": "Rock_Ice_Permafrost"
    },
    {
      "x": -8,
      "y": 12,
      "z": 7,
      "name": "Rock_Ice"
    },
    {
      "x": -8,
      "y": 13,
      "z": 7,
      "name": "Rock_Ice_Permafrost"
    },
    {
      "x": -8,
      "y": 14,
      "z": 7,
      "name": "Rock_Ice_Permafrost"
    },
    {
      "x": -8,
      "y": 15,
      "z": 7,
      "name": "Rock_Ice_Permafrost"
    },
    {
      "x": -8,
      "y": 16,
      "z": 7,
      "name": "Rock_Ice_Permafrost"
    },
    {
      "x": -8,
      "y": 17,
      "z": 7,
      "name": "Rock_Ice_Permafrost"
    },
    {
      "x": -8,
      "y": 18,
      "z": 7,
      "name": "Rock_Ice_Permafrost"
    },
    {
      "x": -8,
      "y": 19,
      "z": 7,
      "name": "Rock_Ice_Permafrost"
    },
    {
      "x": -8,
      "y": 20,
      "z": 7,
      "name": "Rock_Ice_Permafrost"
    },
    {
      "x": -8,
      "y": 21,
      "z": 7,
      "name": "Rock_Ice_Permafrost"
    },
    {
      "x": -8,
      "y": 22,
      "z": 7,
      "name": "Rock_Ice_Permafrost"
    },
    {
      "x": -8,
      "y": 23,
      "z": 7,
      "name": "Rock_Ice_Permafrost"
    },
    {
      "x": -8,
      "y": 24,
      "z": 7,
      "name": "Rock_Ice_Permafrost"
    },
    {
      "x": -8,
      "y": 25,
      "z": 7,
      "name": "Rock_Ice"
    },
    {
      "x": -8,
      "y": 26,
      "z": 7,
      "name": "Rock_Ice_Permafrost"
    },
    {
      "x": -8,
      "y": 27,
      "z": 7,
      "name": "Rock_Ice"
    },
    {
      "x": -8,
      "y": 28,
      "z": 7,
      "name": "Rock_Ice"
    },
    {
      "x": -8,
      "y": 29,
      "z": 7,
      "name": "Rock_Ice"
    },
    {
      "x": -8,
      "y": 30,
      "z": 7,
      "name": "Rock_Ice"
    },
    {
      "x": -8,
      "y": 31,
      "z": 7,
      "name": "Rock_Ice"
    },
    {
      "x": -8,
      "y": 32,
      "z": 7,
      "name": "Rock_Ice"
    },
    {
      "x": -8,
      "y": 33,
      "z": 7,
      "name": "Rock_Ice"
    },
    {
      "x": -8,
      "y": 34,
      "z": 7,
      "name": "Soil_Snow"
    },
    {
      "x": -8,
      "y": 4,
      "z": 8,
      "name": "Rock_Ice"
    },
    {
      "x": -8,
      "y": 5,
      "z": 8,
      "name": "Rock_Ice_Permafrost"
    },
    {
      "x": -8,
      "y": 6,
      "z": 8,
      "name": "Rock_Ice_Permafrost"
    },
    {
      "x": -8,
      "y": 7,
      "z": 8,
      "name": "Rock_Ice_Permafrost"
    },
    {
      "x": -8,
      "y": 8,
      "z": 8,
      "name": "Rock_Ice_Permafrost"
    },
    {
      "x": -8,
      "y": 9,
      "z": 8,
      "name": "Rock_Ice_Permafrost"
    },
    {
      "x": -8,
      "y": 10,
      "z": 8,
      "name": "Rock_Ice"
    },
    {
      "x": -8,
      "y": 11,
      "z": 8,
      "name": "Rock_Ice"
    },
    {
      "x": -8,
      "y": 12,
      "z": 8,
      "name": "Rock_Ice"
    },
    {
      "x": -8,
      "y": 13,
      "z": 8,
      "name": "Rock_Ice"
    },
    {
      "x": -8,
      "y": 14,
      "z": 8,
      "name": "Rock_Ice"
    },
    {
      "x": -8,
      "y": 15,
      "z": 8,
      "name": "Rock_Ice"
    },
    {
      "x": -8,
      "y": 16,
      "z": 8,
      "name": "Rock_Ice"
    },
    {
      "x": -8,
      "y": 17,
      "z": 8,
      "name": "Rock_Ice"
    },
    {
      "x": -8,
      "y": 18,
      "z": 8,
      "name": "Rock_Ice"
    },
    {
      "x": -8,
      "y": 19,
      "z": 8,
      "name": "Rock_Ice"
    },
    {
      "x": -8,
      "y": 20,
      "z": 8,
      "name": "Rock_Ice_Permafrost"
    },
    {
      "x": -8,
      "y": 21,
      "z": 8,
      "name": "Rock_Ice_Permafrost"
    },
    {
      "x": -8,
      "y": 22,
      "z": 8,
      "name": "Rock_Ice_Permafrost"
    },
    {
      "x": -8,
      "y": 23,
      "z": 8,
      "name": "Rock_Ice_Permafrost"
    },
    {
      "x": -8,
      "y": 24,
      "z": 8,
      "name": "Rock_Ice_Permafrost"
    },
    {
      "x": -8,
      "y": 25,
      "z": 8,
      "name": "Rock_Ice_Permafrost"
    },
    {
      "x": -8,
      "y": 26,
      "z": 8,
      "name": "Rock_Ice_Permafrost"
    },
    {
      "x": -8,
      "y": 27,
      "z": 8,
      "name": "Rock_Ice_Permafrost"
    },
    {
      "x": -8,
      "y": 28,
      "z": 8,
      "name": "Rock_Ice"
    },
    {
      "x": -8,
      "y": 29,
      "z": 8,
      "name": "Rock_Ice_Permafrost"
    },
    {
      "x": -8,
      "y": 30,
      "z": 8,
      "name": "Rock_Ice"
    },
    {
      "x": -8,
      "y": 31,
      "z": 8,
      "name": "Rock_Ice"
    },
    {
      "x": -8,
      "y": 32,
      "z": 8,
      "name": "Rock_Ice_Permafrost"
    },
    {
      "x": -8,
      "y": 33,
      "z": 8,
      "name": "Rock_Ice"
    },
    {
      "x": -8,
      "y": 34,
      "z": 8,
      "name": "Rock_Ice"
    },
    {
      "x": -8,
      "y": 35,
      "z": 8,
      "name": "Soil_Snow"
    },
    {
      "x": -8,
      "y": 1,
      "z": 9,
      "name": "Rock_Ice"
    },
    {
      "x": -8,
      "y": 2,
      "z": 9,
      "name": "Rock_Ice"
    },
    {
      "x": -8,
      "y": 3,
      "z": 9,
      "name": "Rock_Ice"
    },
    {
      "x": -8,
      "y": 4,
      "z": 9,
      "name": "Rock_Ice_Permafrost"
    },
    {
      "x": -8,
      "y": 9,
      "z": 9,
      "name": "Rock_Ice"
    },
    {
      "x": -8,
      "y": 10,
      "z": 9,
      "name": "Rock_Ice"
    },
    {
      "x": -8,
      "y": 11,
      "z": 9,
      "name": "Rock_Ice"
    },
    {
      "x": -8,
      "y": 12,
      "z": 9,
      "name": "Rock_Ice"
    },
    {
      "x": -8,
      "y": 13,
      "z": 9,
      "name": "Rock_Ice"
    },
    {
      "x": -8,
      "y": 14,
      "z": 9,
      "name": "Rock_Ice"
    },
    {
      "x": -8,
      "y": 15,
      "z": 9,
      "name": "Rock_Ice"
    },
    {
      "x": -8,
      "y": 16,
      "z": 9,
      "name": "Rock_Ice"
    },
    {
      "x": -8,
      "y": 17,
      "z": 9,
      "name": "Rock_Ice"
    },
    {
      "x": -8,
      "y": 18,
      "z": 9,
      "name": "Rock_Ice"
    },
    {
      "x": -8,
      "y": 19,
      "z": 9,
      "name": "Rock_Ice"
    },
    {
      "x": -8,
      "y": 20,
      "z": 9,
      "name": "Rock_Ice"
    },
    {
      "x": -8,
      "y": 21,
      "z": 9,
      "name": "Rock_Ice_Permafrost"
    },
    {
      "x": -8,
      "y": 22,
      "z": 9,
      "name": "Rock_Ice_Permafrost"
    },
    {
      "x": -8,
      "y": 23,
      "z": 9,
      "name": "Rock_Ice_Permafrost"
    },
    {
      "x": -8,
      "y": 24,
      "z": 9,
      "name": "Rock_Ice_Permafrost"
    },
    {
      "x": -8,
      "y": 25,
      "z": 9,
      "name": "Rock_Ice_Permafrost"
    },
    {
      "x": -8,
      "y": 26,
      "z": 9,
      "name": "Rock_Ice_Permafrost"
    },
    {
      "x": -8,
      "y": 27,
      "z": 9,
      "name": "Rock_Ice_Permafrost"
    },
    {
      "x": -8,
      "y": 28,
      "z": 9,
      "name": "Rock_Ice_Permafrost"
    },
    {
      "x": -8,
      "y": 29,
      "z": 9,
      "name": "Rock_Ice"
    },
    {
      "x": -8,
      "y": 30,
      "z": 9,
      "name": "Rock_Ice"
    },
    {
      "x": -8,
      "y": 31,
      "z": 9,
      "name": "Rock_Ice_Permafrost"
    },
    {
      "x": -8,
      "y": 32,
      "z": 9,
      "name": "Rock_Ice_Permafrost"
    },
    {
      "x": -8,
      "y": 33,
      "z": 9,
      "name": "Rock_Ice_Permafrost"
    },
    {
      "x": -8,
      "y": 34,
      "z": 9,
      "name": "Rock_Ice_Permafrost"
    },
    {
      "x": -8,
      "y": 35,
      "z": 9,
      "name": "Rock_Ice_Permafrost"
    },
    {
      "x": -8,
      "y": 36,
      "z": 9,
      "name": "Rock_Ice"
    },
    {
      "x": -8,
      "y": 37,
      "z": 9,
      "name": "Soil_Snow"
    },
    {
      "x": -8,
      "y": 1,
      "z": 10,
      "name": "Rock_Ice"
    },
    {
      "x": -8,
      "y": 2,
      "z": 10,
      "name": "Rock_Ice"
    },
    {
      "x": -8,
      "y": 3,
      "z": 10,
      "name": "Rock_Ice_Permafrost"
    },
    {
      "x": -8,
      "y": 4,
      "z": 10,
      "name": "Rock_Ice_Permafrost"
    },
    {
      "x": -8,
      "y": 5,
      "z": 10,
      "name": "Rock_Ice_Permafrost"
    },
    {
      "x": -8,
      "y": 13,
      "z": 10,
      "name": "Rock_Ice"
    },
    {
      "x": -8,
      "y": 14,
      "z": 10,
      "name": "Rock_Ice"
    },
    {
      "x": -8,
      "y": 15,
      "z": 10,
      "name": "Rock_Ice"
    },
    {
      "x": -8,
      "y": 16,
      "z": 10,
      "name": "Rock_Ice"
    },
    {
      "x": -8,
      "y": 17,
      "z": 10,
      "name": "Rock_Ice"
    },
    {
      "x": -8,
      "y": 18,
      "z": 10,
      "name": "Rock_Ice"
    },
    {
      "x": -8,
      "y": 19,
      "z": 10,
      "name": "Rock_Ice"
    },
    {
      "x": -8,
      "y": 20,
      "z": 10,
      "name": "Rock_Ice"
    },
    {
      "x": -8,
      "y": 21,
      "z": 10,
      "name": "Rock_Ice"
    },
    {
      "x": -8,
      "y": 22,
      "z": 10,
      "name": "Rock_Ice"
    },
    {
      "x": -8,
      "y": 23,
      "z": 10,
      "name": "Rock_Ice_Permafrost"
    },
    {
      "x": -8,
      "y": 24,
      "z": 10,
      "name": "Rock_Ice_Permafrost"
    },
    {
      "x": -8,
      "y": 25,
      "z": 10,
      "name": "Rock_Ice_Permafrost"
    },
    {
      "x": -8,
      "y": 26,
      "z": 10,
      "name": "Rock_Ice_Permafrost"
    },
    {
      "x": -8,
      "y": 27,
      "z": 10,
      "name": "Rock_Ice_Permafrost"
    },
    {
      "x": -8,
      "y": 28,
      "z": 10,
      "name": "Rock_Ice_Permafrost"
    },
    {
      "x": -8,
      "y": 29,
      "z": 10,
      "name": "Rock_Ice_Permafrost"
    },
    {
      "x": -8,
      "y": 30,
      "z": 10,
      "name": "Rock_Ice_Permafrost"
    },
    {
      "x": -8,
      "y": 31,
      "z": 10,
      "name": "Rock_Ice_Permafrost"
    },
    {
      "x": -8,
      "y": 32,
      "z": 10,
      "name": "Rock_Ice_Permafrost"
    },
    {
      "x": -8,
      "y": 33,
      "z": 10,
      "name": "Rock_Ice_Permafrost"
    },
    {
      "x": -8,
      "y": 34,
      "z": 10,
      "name": "Rock_Ice_Permafrost"
    },
    {
      "x": -8,
      "y": 35,
      "z": 10,
      "name": "Rock_Ice_Permafrost"
    },
    {
      "x": -8,
      "y": 36,
      "z": 10,
      "name": "Rock_Ice"
    },
    {
      "x": -8,
      "y": 37,
      "z": 10,
      "name": "Soil_Snow"
    },
    {
      "x": -8,
      "y": 4,
      "z": 11,
      "name": "Rock_Ice_Permafrost"
    },
    {
      "x": -8,
      "y": 5,
      "z": 11,
      "name": "Rock_Ice_Permafrost"
    },
    {
      "x": -8,
      "y": 6,
      "z": 11,
      "name": "Rock_Ice"
    },
    {
      "x": -8,
      "y": 16,
      "z": 11,
      "name": "Rock_Ice"
    },
    {
      "x": -8,
      "y": 17,
      "z": 11,
      "name": "Rock_Ice"
    },
    {
      "x": -8,
      "y": 18,
      "z": 11,
      "name": "Rock_Ice"
    },
    {
      "x": -8,
      "y": 19,
      "z": 11,
      "name": "Rock_Ice"
    },
    {
      "x": -8,
      "y": 20,
      "z": 11,
      "name": "Rock_Ice"
    },
    {
      "x": -8,
      "y": 21,
      "z": 11,
      "name": "Rock_Ice"
    },
    {
      "x": -8,
      "y": 22,
      "z": 11,
      "name": "Rock_Ice"
    },
    {
      "x": -8,
      "y": 23,
      "z": 11,
      "name": "Rock_Ice"
    },
    {
      "x": -8,
      "y": 24,
      "z": 11,
      "name": "Rock_Ice_Permafrost"
    },
    {
      "x": -8,
      "y": 25,
      "z": 11,
      "name": "Rock_Ice_Permafrost"
    },
    {
      "x": -8,
      "y": 26,
      "z": 11,
      "name": "Rock_Ice_Permafrost"
    },
    {
      "x": -8,
      "y": 27,
      "z": 11,
      "name": "Rock_Ice_Permafrost"
    },
    {
      "x": -8,
      "y": 28,
      "z": 11,
      "name": "Rock_Ice_Permafrost"
    },
    {
      "x": -8,
      "y": 29,
      "z": 11,
      "name": "Rock_Ice_Permafrost"
    },
    {
      "x": -8,
      "y": 30,
      "z": 11,
      "name": "Rock_Ice_Permafrost"
    },
    {
      "x": -8,
      "y": 31,
      "z": 11,
      "name": "Rock_Ice_Permafrost"
    },
    {
      "x": -8,
      "y": 32,
      "z": 11,
      "name": "Rock_Ice_Permafrost"
    },
    {
      "x": -8,
      "y": 33,
      "z": 11,
      "name": "Rock_Ice"
    },
    {
      "x": -8,
      "y": 34,
      "z": 11,
      "name": "Rock_Ice"
    },
    {
      "x": -8,
      "y": 35,
      "z": 11,
      "name": "Rock_Ice"
    },
    {
      "x": -8,
      "y": 36,
      "z": 11,
      "name": "Rock_Ice"
    },
    {
      "x": -8,
      "y": 37,
      "z": 11,
      "name": "Rock_Ice"
    },
    {
      "x": -8,
      "y": 38,
      "z": 11,
      "name": "Soil_Snow"
    },
    {
      "x": -8,
      "y": 6,
      "z": 12,
      "name": "Rock_Ice"
    },
    {
      "x": -8,
      "y": 7,
      "z": 12,
      "name": "Rock_Ice"
    },
    {
      "x": -8,
      "y": 8,
      "z": 12,
      "name": "Rock_Ice"
    },
    {
      "x": -8,
      "y": 22,
      "z": 12,
      "name": "Rock_Ice_Permafrost"
    },
    {
      "x": -8,
      "y": 23,
      "z": 12,
      "name": "Rock_Ice_Permafrost"
    },
    {
      "x": -8,
      "y": 24,
      "z": 12,
      "name": "Rock_Ice_Permafrost"
    },
    {
      "x": -8,
      "y": 25,
      "z": 12,
      "name": "Rock_Ice_Permafrost"
    },
    {
      "x": -8,
      "y": 26,
      "z": 12,
      "name": "Rock_Ice_Permafrost"
    },
    {
      "x": -8,
      "y": 27,
      "z": 12,
      "name": "Rock_Ice_Permafrost"
    },
    {
      "x": -8,
      "y": 28,
      "z": 12,
      "name": "Rock_Ice_Permafrost"
    },
    {
      "x": -8,
      "y": 29,
      "z": 12,
      "name": "Rock_Ice_Permafrost"
    },
    {
      "x": -8,
      "y": 30,
      "z": 12,
      "name": "Rock_Ice_Permafrost"
    },
    {
      "x": -8,
      "y": 31,
      "z": 12,
      "name": "Rock_Ice_Permafrost"
    },
    {
      "x": -8,
      "y": 32,
      "z": 12,
      "name": "Rock_Ice_Permafrost"
    },
    {
      "x": -8,
      "y": 33,
      "z": 12,
      "name": "Rock_Ice_Permafrost"
    },
    {
      "x": -8,
      "y": 34,
      "z": 12,
      "name": "Rock_Ice"
    },
    {
      "x": -8,
      "y": 35,
      "z": 12,
      "name": "Rock_Ice"
    },
    {
      "x": -8,
      "y": 36,
      "z": 12,
      "name": "Rock_Ice"
    },
    {
      "x": -8,
      "y": 37,
      "z": 12,
      "name": "Rock_Ice"
    },
    {
      "x": -8,
      "y": 38,
      "z": 12,
      "name": "Rock_Ice"
    },
    {
      "x": -8,
      "y": 39,
      "z": 12,
      "name": "Soil_Snow"
    },
    {
      "x": -8,
      "y": 7,
      "z": 13,
      "name": "Rock_Ice"
    },
    {
      "x": -8,
      "y": 8,
      "z": 13,
      "name": "Rock_Ice"
    },
    {
      "x": -8,
      "y": 9,
      "z": 13,
      "name": "Rock_Ice"
    },
    {
      "x": -8,
      "y": 10,
      "z": 13,
      "name": "Rock_Ice"
    },
    {
      "x": -8,
      "y": 11,
      "z": 13,
      "name": "Rock_Ice"
    },
    {
      "x": -8,
      "y": 25,
      "z": 13,
      "name": "Rock_Ice_Permafrost"
    },
    {
      "x": -8,
      "y": 26,
      "z": 13,
      "name": "Rock_Ice_Permafrost"
    },
    {
      "x": -8,
      "y": 27,
      "z": 13,
      "name": "Rock_Ice_Permafrost"
    },
    {
      "x": -8,
      "y": 28,
      "z": 13,
      "name": "Rock_Ice"
    },
    {
      "x": -8,
      "y": 29,
      "z": 13,
      "name": "Rock_Ice"
    },
    {
      "x": -8,
      "y": 30,
      "z": 13,
      "name": "Rock_Ice_Permafrost"
    },
    {
      "x": -8,
      "y": 31,
      "z": 13,
      "name": "Rock_Ice_Permafrost"
    },
    {
      "x": -8,
      "y": 32,
      "z": 13,
      "name": "Rock_Ice_Permafrost"
    },
    {
      "x": -8,
      "y": 33,
      "z": 13,
      "name": "Rock_Ice_Permafrost"
    },
    {
      "x": -8,
      "y": 34,
      "z": 13,
      "name": "Rock_Ice"
    },
    {
      "x": -8,
      "y": 35,
      "z": 13,
      "name": "Rock_Ice"
    },
    {
      "x": -8,
      "y": 36,
      "z": 13,
      "name": "Rock_Ice"
    },
    {
      "x": -8,
      "y": 37,
      "z": 13,
      "name": "Rock_Ice"
    },
    {
      "x": -8,
      "y": 38,
      "z": 13,
      "name": "Rock_Ice"
    },
    {
      "x": -8,
      "y": 39,
      "z": 13,
      "name": "Rock_Ice"
    },
    {
      "x": -8,
      "y": 40,
      "z": 13,
      "name": "Soil_Snow"
    },
    {
      "x": -8,
      "y": 8,
      "z": 14,
      "name": "Rock_Ice"
    },
    {
      "x": -8,
      "y": 9,
      "z": 14,
      "name": "Rock_Ice"
    },
    {
      "x": -8,
      "y": 10,
      "z": 14,
      "name": "Rock_Ice"
    },
    {
      "x": -8,
      "y": 11,
      "z": 14,
      "name": "Rock_Ice"
    },
    {
      "x": -8,
      "y": 12,
      "z": 14,
      "name": "Rock_Ice"
    },
    {
      "x": -8,
      "y": 13,
      "z": 14,
      "name": "Rock_Ice"
    },
    {
      "x": -8,
      "y": 26,
      "z": 14,
      "name": "Rock_Ice_Permafrost"
    },
    {
      "x": -8,
      "y": 27,
      "z": 14,
      "name": "Rock_Ice"
    },
    {
      "x": -8,
      "y": 28,
      "z": 14,
      "name": "Rock_Ice_Permafrost"
    },
    {
      "x": -8,
      "y": 29,
      "z": 14,
      "name": "Rock_Ice_Permafrost"
    },
    {
      "x": -8,
      "y": 30,
      "z": 14,
      "name": "Rock_Ice_Permafrost"
    },
    {
      "x": -8,
      "y": 31,
      "z": 14,
      "name": "Rock_Ice_Permafrost"
    },
    {
      "x": -8,
      "y": 32,
      "z": 14,
      "name": "Rock_Ice_Permafrost"
    },
    {
      "x": -8,
      "y": 33,
      "z": 14,
      "name": "Rock_Ice_Permafrost"
    },
    {
      "x": -8,
      "y": 34,
      "z": 14,
      "name": "Rock_Ice"
    },
    {
      "x": -8,
      "y": 35,
      "z": 14,
      "name": "Rock_Ice"
    },
    {
      "x": -8,
      "y": 36,
      "z": 14,
      "name": "Rock_Ice"
    },
    {
      "x": -8,
      "y": 37,
      "z": 14,
      "name": "Rock_Ice"
    },
    {
      "x": -8,
      "y": 38,
      "z": 14,
      "name": "Rock_Ice"
    },
    {
      "x": -8,
      "y": 39,
      "z": 14,
      "name": "Soil_Snow"
    },
    {
      "x": -8,
      "y": 9,
      "z": 15,
      "name": "Rock_Ice"
    },
    {
      "x": -8,
      "y": 10,
      "z": 15,
      "name": "Rock_Ice"
    },
    {
      "x": -8,
      "y": 11,
      "z": 15,
      "name": "Rock_Ice"
    },
    {
      "x": -8,
      "y": 12,
      "z": 15,
      "name": "Rock_Ice"
    },
    {
      "x": -8,
      "y": 13,
      "z": 15,
      "name": "Rock_Ice"
    },
    {
      "x": -8,
      "y": 14,
      "z": 15,
      "name": "Rock_Ice"
    },
    {
      "x": -8,
      "y": 15,
      "z": 15,
      "name": "Rock_Ice"
    },
    {
      "x": -8,
      "y": 16,
      "z": 15,
      "name": "Rock_Ice"
    },
    {
      "x": -8,
      "y": 27,
      "z": 15,
      "name": "Rock_Ice"
    },
    {
      "x": -8,
      "y": 28,
      "z": 15,
      "name": "Rock_Ice"
    },
    {
      "x": -8,
      "y": 29,
      "z": 15,
      "name": "Rock_Ice_Permafrost"
    },
    {
      "x": -8,
      "y": 30,
      "z": 15,
      "name": "Rock_Ice_Permafrost"
    },
    {
      "x": -8,
      "y": 31,
      "z": 15,
      "name": "Rock_Ice_Permafrost"
    },
    {
      "x": -8,
      "y": 32,
      "z": 15,
      "name": "Rock_Ice_Permafrost"
    },
    {
      "x": -8,
      "y": 33,
      "z": 15,
      "name": "Rock_Ice"
    },
    {
      "x": -8,
      "y": 34,
      "z": 15,
      "name": "Rock_Ice"
    },
    {
      "x": -8,
      "y": 35,
      "z": 15,
      "name": "Rock_Ice"
    },
    {
      "x": -8,
      "y": 36,
      "z": 15,
      "name": "Soil_Snow"
    },
    {
      "x": -8,
      "y": 10,
      "z": 16,
      "name": "Rock_Ice"
    },
    {
      "x": -8,
      "y": 11,
      "z": 16,
      "name": "Rock_Ice"
    },
    {
      "x": -8,
      "y": 12,
      "z": 16,
      "name": "Rock_Ice"
    },
    {
      "x": -8,
      "y": 13,
      "z": 16,
      "name": "Rock_Ice"
    },
    {
      "x": -8,
      "y": 14,
      "z": 16,
      "name": "Rock_Ice"
    },
    {
      "x": -8,
      "y": 15,
      "z": 16,
      "name": "Rock_Ice"
    },
    {
      "x": -8,
      "y": 16,
      "z": 16,
      "name": "Rock_Ice"
    },
    {
      "x": -8,
      "y": 17,
      "z": 16,
      "name": "Rock_Ice"
    },
    {
      "x": -8,
      "y": 18,
      "z": 16,
      "name": "Rock_Ice"
    },
    {
      "x": -8,
      "y": 28,
      "z": 16,
      "name": "Rock_Ice"
    },
    {
      "x": -8,
      "y": 29,
      "z": 16,
      "name": "Rock_Ice_Permafrost"
    },
    {
      "x": -8,
      "y": 30,
      "z": 16,
      "name": "Rock_Ice_Permafrost"
    },
    {
      "x": -8,
      "y": 31,
      "z": 16,
      "name": "Rock_Ice_Permafrost"
    },
    {
      "x": -8,
      "y": 32,
      "z": 16,
      "name": "Rock_Ice_Permafrost"
    },
    {
      "x": -8,
      "y": 33,
      "z": 16,
      "name": "Rock_Ice_Permafrost"
    },
    {
      "x": -8,
      "y": 34,
      "z": 16,
      "name": "Rock_Ice"
    },
    {
      "x": -8,
      "y": 35,
      "z": 16,
      "name": "Soil_Snow"
    },
    {
      "x": -8,
      "y": 11,
      "z": 17,
      "name": "Rock_Ice"
    },
    {
      "x": -8,
      "y": 12,
      "z": 17,
      "name": "Rock_Ice"
    },
    {
      "x": -8,
      "y": 13,
      "z": 17,
      "name": "Rock_Ice"
    },
    {
      "x": -8,
      "y": 14,
      "z": 17,
      "name": "Rock_Ice"
    },
    {
      "x": -8,
      "y": 15,
      "z": 17,
      "name": "Rock_Ice"
    },
    {
      "x": -8,
      "y": 16,
      "z": 17,
      "name": "Rock_Ice"
    },
    {
      "x": -8,
      "y": 17,
      "z": 17,
      "name": "Rock_Ice"
    },
    {
      "x": -8,
      "y": 18,
      "z": 17,
      "name": "Rock_Ice_Permafrost"
    },
    {
      "x": -8,
      "y": 19,
      "z": 17,
      "name": "Rock_Ice_Permafrost"
    },
    {
      "x": -8,
      "y": 20,
      "z": 17,
      "name": "Rock_Ice_Permafrost"
    },
    {
      "x": -8,
      "y": 30,
      "z": 17,
      "name": "Rock_Ice_Permafrost"
    },
    {
      "x": -8,
      "y": 31,
      "z": 17,
      "name": "Rock_Ice_Permafrost"
    },
    {
      "x": -8,
      "y": 32,
      "z": 17,
      "name": "Rock_Ice_Permafrost"
    },
    {
      "x": -8,
      "y": 33,
      "z": 17,
      "name": "Rock_Ice"
    },
    {
      "x": -8,
      "y": 34,
      "z": 17,
      "name": "Soil_Snow"
    },
    {
      "x": -8,
      "y": 12,
      "z": 18,
      "name": "Rock_Ice"
    },
    {
      "x": -8,
      "y": 13,
      "z": 18,
      "name": "Rock_Ice"
    },
    {
      "x": -8,
      "y": 14,
      "z": 18,
      "name": "Rock_Ice"
    },
    {
      "x": -8,
      "y": 15,
      "z": 18,
      "name": "Rock_Ice"
    },
    {
      "x": -8,
      "y": 16,
      "z": 18,
      "name": "Rock_Ice"
    },
    {
      "x": -8,
      "y": 17,
      "z": 18,
      "name": "Rock_Ice_Permafrost"
    },
    {
      "x": -8,
      "y": 18,
      "z": 18,
      "name": "Rock_Ice_Permafrost"
    },
    {
      "x": -8,
      "y": 19,
      "z": 18,
      "name": "Rock_Ice_Permafrost"
    },
    {
      "x": -8,
      "y": 20,
      "z": 18,
      "name": "Rock_Ice"
    },
    {
      "x": -8,
      "y": 21,
      "z": 18,
      "name": "Soil_Snow"
    },
    {
      "x": -8,
      "y": 13,
      "z": 19,
      "name": "Rock_Ice"
    },
    {
      "x": -8,
      "y": 14,
      "z": 19,
      "name": "Rock_Ice"
    },
    {
      "x": -8,
      "y": 15,
      "z": 19,
      "name": "Rock_Ice"
    },
    {
      "x": -8,
      "y": 16,
      "z": 19,
      "name": "Rock_Ice_Permafrost"
    },
    {
      "x": -8,
      "y": 17,
      "z": 19,
      "name": "Rock_Ice_Permafrost"
    },
    {
      "x": -8,
      "y": 18,
      "z": 19,
      "name": "Rock_Ice"
    },
    {
      "x": -8,
      "y": 19,
      "z": 19,
      "name": "Rock_Ice"
    },
    {
      "x": -8,
      "y": 20,
      "z": 19,
      "name": "Rock_Ice"
    },
    {
      "x": -8,
      "y": 21,
      "z": 19,
      "name": "Rock_Ice"
    },
    {
      "x": -8,
      "y": 22,
      "z": 19,
      "name": "Rock_Ice"
    },
    {
      "x": -8,
      "y": 23,
      "z": 19,
      "name": "Rock_Ice"
    },
    {
      "x": -8,
      "y": 24,
      "z": 19,
      "name": "Soil_Snow"
    },
    {
      "x": -8,
      "y": 14,
      "z": 20,
      "name": "Rock_Ice"
    },
    {
      "x": -8,
      "y": 15,
      "z": 20,
      "name": "Rock_Ice_Permafrost"
    },
    {
      "x": -8,
      "y": 16,
      "z": 20,
      "name": "Rock_Ice_Permafrost"
    },
    {
      "x": -8,
      "y": 17,
      "z": 20,
      "name": "Rock_Ice_Permafrost"
    },
    {
      "x": -8,
      "y": 18,
      "z": 20,
      "name": "Rock_Ice"
    },
    {
      "x": -8,
      "y": 19,
      "z": 20,
      "name": "Rock_Ice"
    },
    {
      "x": -8,
      "y": 20,
      "z": 20,
      "name": "Rock_Ice"
    },
    {
      "x": -8,
      "y": 21,
      "z": 20,
      "name": "Rock_Ice"
    },
    {
      "x": -8,
      "y": 22,
      "z": 20,
      "name": "Rock_Ice"
    },
    {
      "x": -8,
      "y": 23,
      "z": 20,
      "name": "Rock_Ice"
    },
    {
      "x": -8,
      "y": 24,
      "z": 20,
      "name": "Rock_Ice"
    },
    {
      "x": -8,
      "y": 25,
      "z": 20,
      "name": "Rock_Ice"
    },
    {
      "x": -8,
      "y": 26,
      "z": 20,
      "name": "Rock_Ice"
    },
    {
      "x": -8,
      "y": 27,
      "z": 20,
      "name": "Soil_Snow"
    },
    {
      "x": -8,
      "y": 16,
      "z": 21,
      "name": "Rock_Ice"
    },
    {
      "x": -8,
      "y": 17,
      "z": 21,
      "name": "Rock_Ice"
    },
    {
      "x": -8,
      "y": 18,
      "z": 21,
      "name": "Rock_Ice"
    },
    {
      "x": -8,
      "y": 19,
      "z": 21,
      "name": "Rock_Ice"
    },
    {
      "x": -8,
      "y": 20,
      "z": 21,
      "name": "Rock_Ice"
    },
    {
      "x": -8,
      "y": 21,
      "z": 21,
      "name": "Rock_Ice"
    },
    {
      "x": -8,
      "y": 22,
      "z": 21,
      "name": "Rock_Ice"
    },
    {
      "x": -8,
      "y": 23,
      "z": 21,
      "name": "Rock_Ice"
    },
    {
      "x": -8,
      "y": 24,
      "z": 21,
      "name": "Rock_Ice"
    },
    {
      "x": -8,
      "y": 25,
      "z": 21,
      "name": "Rock_Ice"
    },
    {
      "x": -8,
      "y": 26,
      "z": 21,
      "name": "Soil_Snow"
    },
    {
      "x": -8,
      "y": 24,
      "z": 22,
      "name": "Soil_Snow"
    },
    {
      "x": -7,
      "y": 56,
      "z": -14,
      "name": "Soil_Snow"
    },
    {
      "x": -7,
      "y": 55,
      "z": -13,
      "name": "Rock_Ice"
    },
    {
      "x": -7,
      "y": 56,
      "z": -13,
      "name": "Soil_Snow"
    },
    {
      "x": -7,
      "y": 54,
      "z": -12,
      "name": "Rock_Ice"
    },
    {
      "x": -7,
      "y": 55,
      "z": -12,
      "name": "Rock_Ice"
    },
    {
      "x": -7,
      "y": 56,
      "z": -12,
      "name": "Soil_Snow"
    },
    {
      "x": -7,
      "y": 53,
      "z": -11,
      "name": "Rock_Ice"
    },
    {
      "x": -7,
      "y": 54,
      "z": -11,
      "name": "Rock_Ice"
    },
    {
      "x": -7,
      "y": 55,
      "z": -11,
      "name": "Rock_Ice"
    },
    {
      "x": -7,
      "y": 56,
      "z": -11,
      "name": "Soil_Snow"
    },
    {
      "x": -7,
      "y": 29,
      "z": -10,
      "name": "Rock_Ice"
    },
    {
      "x": -7,
      "y": 30,
      "z": -10,
      "name": "Rock_Ice"
    },
    {
      "x": -7,
      "y": 31,
      "z": -10,
      "name": "Soil_Snow"
    },
    {
      "x": -7,
      "y": 52,
      "z": -10,
      "name": "Rock_Ice"
    },
    {
      "x": -7,
      "y": 53,
      "z": -10,
      "name": "Rock_Ice"
    },
    {
      "x": -7,
      "y": 54,
      "z": -10,
      "name": "Rock_Ice"
    },
    {
      "x": -7,
      "y": 55,
      "z": -10,
      "name": "Rock_Ice"
    },
    {
      "x": -7,
      "y": 56,
      "z": -10,
      "name": "Soil_Snow"
    },
    {
      "x": -7,
      "y": 27,
      "z": -9,
      "name": "Rock_Ice"
    },
    {
      "x": -7,
      "y": 28,
      "z": -9,
      "name": "Rock_Ice"
    },
    {
      "x": -7,
      "y": 29,
      "z": -9,
      "name": "Rock_Ice"
    },
    {
      "x": -7,
      "y": 30,
      "z": -9,
      "name": "Rock_Ice"
    },
    {
      "x": -7,
      "y": 31,
      "z": -9,
      "name": "Rock_Ice"
    },
    {
      "x": -7,
      "y": 32,
      "z": -9,
      "name": "Rock_Ice"
    },
    {
      "x": -7,
      "y": 33,
      "z": -9,
      "name": "Rock_Ice"
    },
    {
      "x": -7,
      "y": 45,
      "z": -9,
      "name": "Rock_Ice"
    },
    {
      "x": -7,
      "y": 46,
      "z": -9,
      "name": "Rock_Ice"
    },
    {
      "x": -7,
      "y": 47,
      "z": -9,
      "name": "Rock_Ice"
    },
    {
      "x": -7,
      "y": 48,
      "z": -9,
      "name": "Rock_Ice"
    },
    {
      "x": -7,
      "y": 49,
      "z": -9,
      "name": "Rock_Ice"
    },
    {
      "x": -7,
      "y": 50,
      "z": -9,
      "name": "Rock_Ice"
    },
    {
      "x": -7,
      "y": 51,
      "z": -9,
      "name": "Rock_Ice"
    },
    {
      "x": -7,
      "y": 52,
      "z": -9,
      "name": "Rock_Ice"
    },
    {
      "x": -7,
      "y": 53,
      "z": -9,
      "name": "Rock_Ice"
    },
    {
      "x": -7,
      "y": 54,
      "z": -9,
      "name": "Rock_Ice"
    },
    {
      "x": -7,
      "y": 55,
      "z": -9,
      "name": "Soil_Snow"
    },
    {
      "x": -7,
      "y": 26,
      "z": -8,
      "name": "Rock_Ice"
    },
    {
      "x": -7,
      "y": 27,
      "z": -8,
      "name": "Rock_Ice"
    },
    {
      "x": -7,
      "y": 28,
      "z": -8,
      "name": "Rock_Ice"
    },
    {
      "x": -7,
      "y": 29,
      "z": -8,
      "name": "Rock_Ice"
    },
    {
      "x": -7,
      "y": 30,
      "z": -8,
      "name": "Rock_Ice"
    },
    {
      "x": -7,
      "y": 31,
      "z": -8,
      "name": "Rock_Ice"
    },
    {
      "x": -7,
      "y": 32,
      "z": -8,
      "name": "Rock_Ice"
    },
    {
      "x": -7,
      "y": 33,
      "z": -8,
      "name": "Rock_Ice"
    },
    {
      "x": -7,
      "y": 34,
      "z": -8,
      "name": "Rock_Ice"
    },
    {
      "x": -7,
      "y": 35,
      "z": -8,
      "name": "Rock_Ice"
    },
    {
      "x": -7,
      "y": 48,
      "z": -8,
      "name": "Rock_Ice"
    },
    {
      "x": -7,
      "y": 49,
      "z": -8,
      "name": "Rock_Ice"
    },
    {
      "x": -7,
      "y": 50,
      "z": -8,
      "name": "Rock_Ice"
    },
    {
      "x": -7,
      "y": 51,
      "z": -8,
      "name": "Rock_Ice"
    },
    {
      "x": -7,
      "y": 52,
      "z": -8,
      "name": "Rock_Ice"
    },
    {
      "x": -7,
      "y": 53,
      "z": -8,
      "name": "Rock_Ice"
    },
    {
      "x": -7,
      "y": 54,
      "z": -8,
      "name": "Rock_Ice"
    },
    {
      "x": -7,
      "y": 55,
      "z": -8,
      "name": "Soil_Snow"
    },
    {
      "x": -7,
      "y": 24,
      "z": -7,
      "name": "Rock_Ice"
    },
    {
      "x": -7,
      "y": 25,
      "z": -7,
      "name": "Rock_Ice"
    },
    {
      "x": -7,
      "y": 26,
      "z": -7,
      "name": "Rock_Ice"
    },
    {
      "x": -7,
      "y": 27,
      "z": -7,
      "name": "Rock_Ice"
    },
    {
      "x": -7,
      "y": 28,
      "z": -7,
      "name": "Rock_Ice"
    },
    {
      "x": -7,
      "y": 29,
      "z": -7,
      "name": "Rock_Ice"
    },
    {
      "x": -7,
      "y": 30,
      "z": -7,
      "name": "Rock_Ice"
    },
    {
      "x": -7,
      "y": 31,
      "z": -7,
      "name": "Rock_Ice"
    },
    {
      "x": -7,
      "y": 32,
      "z": -7,
      "name": "Rock_Ice_Permafrost"
    },
    {
      "x": -7,
      "y": 33,
      "z": -7,
      "name": "Rock_Ice"
    },
    {
      "x": -7,
      "y": 34,
      "z": -7,
      "name": "Rock_Ice_Permafrost"
    },
    {
      "x": -7,
      "y": 35,
      "z": -7,
      "name": "Rock_Ice_Permafrost"
    },
    {
      "x": -7,
      "y": 36,
      "z": -7,
      "name": "Rock_Ice_Permafrost"
    },
    {
      "x": -7,
      "y": 37,
      "z": -7,
      "name": "Rock_Ice_Permafrost"
    },
    {
      "x": -7,
      "y": 38,
      "z": -7,
      "name": "Rock_Ice_Permafrost"
    },
    {
      "x": -7,
      "y": 39,
      "z": -7,
      "name": "Rock_Ice_Permafrost"
    },
    {
      "x": -7,
      "y": 40,
      "z": -7,
      "name": "Rock_Ice_Permafrost"
    },
    {
      "x": -7,
      "y": 41,
      "z": -7,
      "name": "Rock_Ice"
    },
    {
      "x": -7,
      "y": 42,
      "z": -7,
      "name": "Rock_Ice"
    },
    {
      "x": -7,
      "y": 43,
      "z": -7,
      "name": "Rock_Ice"
    },
    {
      "x": -7,
      "y": 53,
      "z": -7,
      "name": "Rock_Ice"
    },
    {
      "x": -7,
      "y": 54,
      "z": -7,
      "name": "Soil_Snow"
    },
    {
      "x": -7,
      "y": 23,
      "z": -6,
      "name": "Rock_Ice"
    },
    {
      "x": -7,
      "y": 24,
      "z": -6,
      "name": "Rock_Ice"
    },
    {
      "x": -7,
      "y": 25,
      "z": -6,
      "name": "Rock_Ice"
    },
    {
      "x": -7,
      "y": 26,
      "z": -6,
      "name": "Rock_Ice"
    },
    {
      "x": -7,
      "y": 27,
      "z": -6,
      "name": "Rock_Ice"
    },
    {
      "x": -7,
      "y": 28,
      "z": -6,
      "name": "Rock_Ice"
    },
    {
      "x": -7,
      "y": 29,
      "z": -6,
      "name": "Rock_Ice"
    },
    {
      "x": -7,
      "y": 30,
      "z": -6,
      "name": "Rock_Ice_Permafrost"
    },
    {
      "x": -7,
      "y": 31,
      "z": -6,
      "name": "Rock_Ice_Permafrost"
    },
    {
      "x": -7,
      "y": 32,
      "z": -6,
      "name": "Rock_Ice_Permafrost"
    },
    {
      "x": -7,
      "y": 33,
      "z": -6,
      "name": "Rock_Ice_Permafrost"
    },
    {
      "x": -7,
      "y": 34,
      "z": -6,
      "name": "Rock_Ice_Permafrost"
    },
    {
      "x": -7,
      "y": 35,
      "z": -6,
      "name": "Rock_Ice"
    },
    {
      "x": -7,
      "y": 36,
      "z": -6,
      "name": "Rock_Ice"
    },
    {
      "x": -7,
      "y": 37,
      "z": -6,
      "name": "Rock_Ice"
    },
    {
      "x": -7,
      "y": 38,
      "z": -6,
      "name": "Rock_Ice"
    },
    {
      "x": -7,
      "y": 39,
      "z": -6,
      "name": "Rock_Ice"
    },
    {
      "x": -7,
      "y": 40,
      "z": -6,
      "name": "Rock_Ice_Permafrost"
    },
    {
      "x": -7,
      "y": 41,
      "z": -6,
      "name": "Rock_Ice_Permafrost"
    },
    {
      "x": -7,
      "y": 42,
      "z": -6,
      "name": "Rock_Ice"
    },
    {
      "x": -7,
      "y": 43,
      "z": -6,
      "name": "Rock_Ice"
    },
    {
      "x": -7,
      "y": 44,
      "z": -6,
      "name": "Rock_Ice"
    },
    {
      "x": -7,
      "y": 45,
      "z": -6,
      "name": "Rock_Ice"
    },
    {
      "x": -7,
      "y": 46,
      "z": -6,
      "name": "Rock_Ice"
    },
    {
      "x": -7,
      "y": 47,
      "z": -6,
      "name": "Soil_Snow"
    },
    {
      "x": -7,
      "y": 8,
      "z": -5,
      "name": "Rock_Ice"
    },
    {
      "x": -7,
      "y": 9,
      "z": -5,
      "name": "Rock_Ice"
    },
    {
      "x": -7,
      "y": 10,
      "z": -5,
      "name": "Rock_Ice"
    },
    {
      "x": -7,
      "y": 11,
      "z": -5,
      "name": "Rock_Ice"
    },
    {
      "x": -7,
      "y": 12,
      "z": -5,
      "name": "Rock_Ice_Permafrost"
    },
    {
      "x": -7,
      "y": 21,
      "z": -5,
      "name": "Rock_Ice"
    },
    {
      "x": -7,
      "y": 22,
      "z": -5,
      "name": "Rock_Ice"
    },
    {
      "x": -7,
      "y": 23,
      "z": -5,
      "name": "Rock_Ice"
    },
    {
      "x": -7,
      "y": 24,
      "z": -5,
      "name": "Rock_Ice"
    },
    {
      "x": -7,
      "y": 25,
      "z": -5,
      "name": "Rock_Ice"
    },
    {
      "x": -7,
      "y": 26,
      "z": -5,
      "name": "Rock_Ice"
    },
    {
      "x": -7,
      "y": 27,
      "z": -5,
      "name": "Rock_Ice_Permafrost"
    },
    {
      "x": -7,
      "y": 28,
      "z": -5,
      "name": "Rock_Ice_Permafrost"
    },
    {
      "x": -7,
      "y": 29,
      "z": -5,
      "name": "Rock_Ice_Permafrost"
    },
    {
      "x": -7,
      "y": 30,
      "z": -5,
      "name": "Rock_Ice_Permafrost"
    },
    {
      "x": -7,
      "y": 31,
      "z": -5,
      "name": "Rock_Ice"
    },
    {
      "x": -7,
      "y": 32,
      "z": -5,
      "name": "Rock_Ice"
    },
    {
      "x": -7,
      "y": 33,
      "z": -5,
      "name": "Rock_Ice"
    },
    {
      "x": -7,
      "y": 34,
      "z": -5,
      "name": "Rock_Ice"
    },
    {
      "x": -7,
      "y": 35,
      "z": -5,
      "name": "Rock_Ice"
    },
    {
      "x": -7,
      "y": 36,
      "z": -5,
      "name": "Rock_Ice"
    },
    {
      "x": -7,
      "y": 37,
      "z": -5,
      "name": "Rock_Ice"
    },
    {
      "x": -7,
      "y": 38,
      "z": -5,
      "name": "Rock_Ice"
    },
    {
      "x": -7,
      "y": 39,
      "z": -5,
      "name": "Rock_Ice"
    },
    {
      "x": -7,
      "y": 40,
      "z": -5,
      "name": "Rock_Ice"
    },
    {
      "x": -7,
      "y": 41,
      "z": -5,
      "name": "Rock_Ice_Permafrost"
    },
    {
      "x": -7,
      "y": 42,
      "z": -5,
      "name": "Rock_Ice_Permafrost"
    },
    {
      "x": -7,
      "y": 43,
      "z": -5,
      "name": "Rock_Ice_Permafrost"
    },
    {
      "x": -7,
      "y": 44,
      "z": -5,
      "name": "Rock_Ice_Permafrost"
    },
    {
      "x": -7,
      "y": 45,
      "z": -5,
      "name": "Rock_Ice"
    },
    {
      "x": -7,
      "y": 46,
      "z": -5,
      "name": "Rock_Ice"
    },
    {
      "x": -7,
      "y": 47,
      "z": -5,
      "name": "Rock_Ice"
    },
    {
      "x": -7,
      "y": 48,
      "z": -5,
      "name": "Rock_Ice"
    },
    {
      "x": -7,
      "y": 49,
      "z": -5,
      "name": "Rock_Ice"
    },
    {
      "x": -7,
      "y": 50,
      "z": -5,
      "name": "Soil_Snow"
    },
    {
      "x": -7,
      "y": 8,
      "z": -4,
      "name": "Rock_Ice"
    },
    {
      "x": -7,
      "y": 9,
      "z": -4,
      "name": "Rock_Ice"
    },
    {
      "x": -7,
      "y": 10,
      "z": -4,
      "name": "Rock_Ice"
    },
    {
      "x": -7,
      "y": 11,
      "z": -4,
      "name": "Rock_Ice"
    },
    {
      "x": -7,
      "y": 12,
      "z": -4,
      "name": "Rock_Ice"
    },
    {
      "x": -7,
      "y": 13,
      "z": -4,
      "name": "Rock_Ice_Permafrost"
    },
    {
      "x": -7,
      "y": 14,
      "z": -4,
      "name": "Rock_Ice_Permafrost"
    },
    {
      "x": -7,
      "y": 15,
      "z": -4,
      "name": "Rock_Ice"
    },
    {
      "x": -7,
      "y": 16,
      "z": -4,
      "name": "Rock_Ice"
    },
    {
      "x": -7,
      "y": 17,
      "z": -4,
      "name": "Rock_Ice"
    },
    {
      "x": -7,
      "y": 18,
      "z": -4,
      "name": "Rock_Ice"
    },
    {
      "x": -7,
      "y": 19,
      "z": -4,
      "name": "Rock_Ice"
    },
    {
      "x": -7,
      "y": 20,
      "z": -4,
      "name": "Rock_Ice"
    },
    {
      "x": -7,
      "y": 21,
      "z": -4,
      "name": "Rock_Ice"
    },
    {
      "x": -7,
      "y": 22,
      "z": -4,
      "name": "Rock_Ice"
    },
    {
      "x": -7,
      "y": 23,
      "z": -4,
      "name": "Rock_Ice"
    },
    {
      "x": -7,
      "y": 24,
      "z": -4,
      "name": "Rock_Ice"
    },
    {
      "x": -7,
      "y": 25,
      "z": -4,
      "name": "Rock_Ice_Permafrost"
    },
    {
      "x": -7,
      "y": 26,
      "z": -4,
      "name": "Rock_Ice_Permafrost"
    },
    {
      "x": -7,
      "y": 27,
      "z": -4,
      "name": "Rock_Ice_Permafrost"
    },
    {
      "x": -7,
      "y": 28,
      "z": -4,
      "name": "Rock_Ice"
    },
    {
      "x": -7,
      "y": 29,
      "z": -4,
      "name": "Rock_Ice"
    },
    {
      "x": -7,
      "y": 30,
      "z": -4,
      "name": "Rock_Ice"
    },
    {
      "x": -7,
      "y": 31,
      "z": -4,
      "name": "Rock_Ice"
    },
    {
      "x": -7,
      "y": 32,
      "z": -4,
      "name": "Rock_Ice"
    },
    {
      "x": -7,
      "y": 33,
      "z": -4,
      "name": "Rock_Ice"
    },
    {
      "x": -7,
      "y": 34,
      "z": -4,
      "name": "Rock_Ice"
    },
    {
      "x": -7,
