{
  "version": 8,
  "blockIdVersion": 11,
  "anchorX": 0,
  "anchorY": 0,
  "anchorZ": 0,
  "blocks": [
    {
      "x": -19,
      "y": 20,
      "z": -3,
      "name": "Rock_Ice"
    },
    {
      "x": -19,
      "y": 21,
      "z": -3,
      "name": "Soil_Snow"
    },
    {
      "x": -19,
      "y": 19,
      "z": -2,
      "name": "Rock_Ice"
    },
    {
      "x": -19,
      "y": 20,
      "z": -2,
      "name": "Rock_Ice"
    },
    {
      "x": -19,
      "y": 21,
      "z": -2,
      "name": "Rock_Ice"
    },
    {
      "x": -19,
      "y": 22,
      "z": -2,
      "name": "Rock_Ice"
    },
    {
      "x": -19,
      "y": 23,
      "z": -2,
      "name": "Rock_Ice"
    },
    {
      "x": -19,
      "y": 24,
      "z": -2,
      "name": "Rock_Ice"
    },
    {
      "x": -19,
      "y": 25,
      "z": -2,
      "name": "Rock_Ice"
    },
    {
      "x": -19,
      "y": 26,
      "z": -2,
      "name": "Rock_Ice"
    },
    {
      "x": -19,
      "y": 35,
      "z": -2,
      "name": "Rock_Ice"
    },
    {
      "x": -19,
      "y": 36,
      "z": -2,
      "name": "Rock_Ice"
    },
    {
      "x": -19,
      "y": 37,
      "z": -2,
      "name": "Soil_Snow"
    },
    {
      "x": -19,
      "y": 19,
      "z": -1,
      "name": "Rock_Ice"
    },
    {
      "x": -19,
      "y": 20,
      "z": -1,
      "name": "Rock_Ice"
    },
    {
      "x": -19,
      "y": 21,
      "z": -1,
      "name": "Rock_Ice"
    },
    {
      "x": -19,
      "y": 22,
      "z": -1,
      "name": "Rock_Ice"
    },
    {
      "x": -19,
      "y": 23,
      "z": -1,
      "name": "Rock_Ice"
    },
    {
      "x": -19,
      "y": 24,
      "z": -1,
      "name": "Rock_Ice"
    },
    {
      "x": -19,
      "y": 25,
      "z": -1,
      "name": "Rock_Ice_Permafrost"
    },
    {
      "x": -19,
      "y": 26,
      "z": -1,
      "name": "Rock_Ice_Permafrost"
    },
    {
      "x": -19,
      "y": 27,
      "z": -1,
      "name": "Rock_Ice"
    },
    {
      "x": -19,
      "y": 28,
      "z": -1,
      "name": "Rock_Ice"
    },
    {
      "x": -19,
      "y": 29,
      "z": -1,
      "name": "Rock_Ice"
    },
    {
      "x": -19,
      "y": 30,
      "z": -1,
      "name": "Rock_Ice"
    },
    {
      "x": -19,
      "y": 31,
      "z": -1,
      "name": "Rock_Ice"
    },
    {
      "x": -19,
      "y": 32,
      "z": -1,
      "name": "Rock_Ice"
    },
    {
      "x": -19,
      "y": 33,
      "z": -1,
      "name": "Rock_Ice"
    },
    {
      "x": -19,
      "y": 34,
      "z": -1,
      "name": "Rock_Ice"
    },
    {
      "x": -19,
      "y": 35,
      "z": -1,
      "name": "Rock_Ice"
    },
    {
      "x": -19,
      "y": 36,
      "z": -1,
      "name": "Rock_Ice"
    },
    {
      "x": -19,
      "y": 37,
      "z": -1,
      "name": "Soil_Snow"
    },
    {
      "x": -19,
      "y": 19,
      "z": 0,
      "name": "Rock_Ice"
    },
    {
      "x": -19,
      "y": 20,
      "z": 0,
      "name": "Rock_Ice_Permafrost"
    },
    {
      "x": -19,
      "y": 21,
      "z": 0,
      "name": "Rock_Ice_Permafrost"
    },
    {
      "x": -19,
      "y": 22,
      "z": 0,
      "name": "Rock_Ice_Permafrost"
    },
    {
      "x": -19,
      "y": 23,
      "z": 0,
      "name": "Rock_Ice_Permafrost"
    },
    {
      "x": -19,
      "y": 24,
      "z": 0,
      "name": "Rock_Ice_Permafrost"
    },
    {
      "x": -19,
      "y": 25,
      "z": 0,
      "name": "Rock_Ice"
    },
    {
      "x": -19,
      "y": 26,
      "z": 0,
      "name": "Rock_Ice"
    },
    {
      "x": -19,
      "y": 27,
      "z": 0,
      "name": "Rock_Ice"
    },
    {
      "x": -19,
      "y": 28,
      "z": 0,
      "name": "Rock_Ice"
    },
    {
      "x": -19,
      "y": 29,
      "z": 0,
      "name": "Rock_Ice"
    },
    {
      "x": -19,
      "y": 30,
      "z": 0,
      "name": "Rock_Ice"
    },
    {
      "x": -19,
      "y": 31,
      "z": 0,
      "name": "Rock_Ice"
    },
    {
      "x": -19,
      "y": 32,
      "z": 0,
      "name": "Rock_Ice"
    },
    {
      "x": -19,
      "y": 33,
      "z": 0,
      "name": "Rock_Ice"
    },
    {
      "x": -19,
      "y": 34,
      "z": 0,
      "name": "Rock_Ice"
    },
    {
      "x": -19,
      "y": 35,
      "z": 0,
      "name": "Rock_Ice"
    },
    {
      "x": -19,
      "y": 20,
      "z": 1,
      "name": "Rock_Ice_Permafrost"
    },
    {
      "x": -19,
      "y": 21,
      "z": 1,
      "name": "Rock_Ice_Permafrost"
    },
    {
      "x": -19,
      "y": 22,
      "z": 1,
      "name": "Rock_Ice"
    },
    {
      "x": -19,
      "y": 23,
      "z": 1,
      "name": "Rock_Ice"
    },
    {
      "x": -19,
      "y": 24,
      "z": 1,
      "name": "Rock_Ice"
    },
    {
      "x": -19,
      "y": 25,
      "z": 1,
      "name": "Rock_Ice"
    },
    {
      "x": -19,
      "y": 26,
      "z": 1,
      "name": "Rock_Ice"
    },
    {
      "x": -19,
      "y": 27,
      "z": 1,
      "name": "Rock_Ice"
    },
    {
      "x": -19,
      "y": 28,
      "z": 1,
      "name": "Rock_Ice"
    },
    {
      "x": -19,
      "y": 29,
      "z": 1,
      "name": "Rock_Ice"
    },
    {
      "x": -19,
      "y": 30,
      "z": 1,
      "name": "Rock_Ice"
    },
    {
      "x": -19,
      "y": 31,
      "z": 1,
      "name": "Rock_Ice"
    },
    {
      "x": -19,
      "y": 32,
      "z": 1,
      "name": "Rock_Ice"
    },
    {
      "x": -19,
      "y": 33,
      "z": 1,
      "name": "Rock_Ice"
    },
    {
      "x": -19,
      "y": 19,
      "z": 2,
      "name": "Rock_Ice"
    },
    {
      "x": -19,
      "y": 20,
      "z": 2,
      "name": "Rock_Ice"
    },
    {
      "x": -19,
      "y": 21,
      "z": 2,
      "name": "Rock_Ice"
    },
    {
      "x": -19,
      "y": 22,
      "z": 2,
      "name": "Rock_Ice"
    },
    {
      "x": -19,
      "y": 23,
      "z": 2,
      "name": "Rock_Ice"
    },
    {
      "x": -19,
      "y": 24,
      "z": 2,
      "name": "Rock_Ice"
    },
    {
      "x": -19,
      "y": 25,
      "z": 2,
      "name": "Rock_Ice"
    },
    {
      "x": -19,
      "y": 26,
      "z": 2,
      "name": "Rock_Ice"
    },
    {
      "x": -19,
      "y": 27,
      "z": 2,
      "name": "Rock_Ice"
    },
    {
      "x": -19,
      "y": 28,
      "z": 2,
      "name": "Rock_Ice"
    },
    {
      "x": -19,
      "y": 29,
      "z": 2,
      "name": "Rock_Ice"
    },
    {
      "x": -19,
      "y": 30,
      "z": 2,
      "name": "Rock_Ice"
    },
    {
      "x": -19,
      "y": 31,
      "z": 2,
      "name": "Soil_Snow"
    },
    {
      "x": -19,
      "y": 19,
      "z": 3,
      "name": "Rock_Ice"
    },
    {
      "x": -19,
      "y": 20,
      "z": 3,
      "name": "Rock_Ice"
    },
    {
      "x": -19,
      "y": 21,
      "z": 3,
      "name": "Rock_Ice"
    },
    {
      "x": -19,
      "y": 22,
      "z": 3,
      "name": "Rock_Ice"
    },
    {
      "x": -19,
      "y": 23,
      "z": 3,
      "name": "Rock_Ice"
    },
    {
      "x": -19,
      "y": 24,
      "z": 3,
      "name": "Rock_Ice"
    },
    {
      "x": -19,
      "y": 25,
      "z": 3,
      "name": "Rock_Ice"
    },
    {
      "x": -19,
      "y": 26,
      "z": 3,
      "name": "Rock_Ice"
    },
    {
      "x": -19,
      "y": 27,
      "z": 3,
      "name": "Rock_Ice"
    },
    {
      "x": -19,
      "y": 28,
      "z": 3,
      "name": "Rock_Ice"
    },
    {
      "x": -19,
      "y": 29,
      "z": 3,
      "name": "Soil_Snow"
    },
    {
      "x": -19,
      "y": 19,
      "z": 4,
      "name": "Rock_Ice"
    },
    {
      "x": -19,
      "y": 20,
      "z": 4,
      "name": "Rock_Ice"
    },
    {
      "x": -19,
      "y": 21,
      "z": 4,
      "name": "Rock_Ice"
    },
    {
      "x": -19,
      "y": 22,
      "z": 4,
      "name": "Rock_Ice"
    },
    {
      "x": -19,
      "y": 23,
      "z": 4,
      "name": "Rock_Ice"
    },
    {
      "x": -19,
      "y": 24,
      "z": 4,
      "name": "Rock_Ice"
    },
    {
      "x": -19,
      "y": 25,
      "z": 4,
      "name": "Rock_Ice"
    },
    {
      "x": -19,
      "y": 26,
      "z": 4,
      "name": "Rock_Ice"
    },
    {
      "x": -19,
      "y": 27,
      "z": 4,
      "name": "Rock_Ice"
    },
    {
      "x": -19,
      "y": 28,
      "z": 4,
      "name": "Soil_Snow"
    },
    {
      "x": -19,
      "y": 18,
      "z": 5,
      "name": "Rock_Ice"
    },
    {
      "x": -19,
      "y": 19,
      "z": 5,
      "name": "Rock_Ice"
    },
    {
      "x": -19,
      "y": 20,
      "z": 5,
      "name": "Rock_Ice"
    },
    {
      "x": -19,
      "y": 21,
      "z": 5,
      "name": "Rock_Ice"
    },
    {
      "x": -19,
      "y": 22,
      "z": 5,
      "name": "Rock_Ice"
    },
    {
      "x": -19,
      "y": 23,
      "z": 5,
      "name": "Rock_Ice"
    },
    {
      "x": -19,
      "y": 24,
      "z": 5,
      "name": "Rock_Ice"
    },
    {
      "x": -19,
      "y": 25,
      "z": 5,
      "name": "Rock_Ice"
    },
    {
      "x": -19,
      "y": 26,
      "z": 5,
      "name": "Rock_Ice"
    },
    {
      "x": -19,
      "y": 27,
      "z": 5,
      "name": "Rock_Ice"
    },
    {
      "x": -19,
      "y": 28,
      "z": 5,
      "name": "Soil_Snow"
    },
    {
      "x": -19,
      "y": 18,
      "z": 6,
      "name": "Rock_Ice"
    },
    {
      "x": -19,
      "y": 19,
      "z": 6,
      "name": "Rock_Ice"
    },
    {
      "x": -19,
      "y": 20,
      "z": 6,
      "name": "Rock_Ice"
    },
    {
      "x": -19,
      "y": 21,
      "z": 6,
      "name": "Rock_Ice"
    },
    {
      "x": -19,
      "y": 22,
      "z": 6,
      "name": "Rock_Ice"
    },
    {
      "x": -19,
      "y": 23,
      "z": 6,
      "name": "Rock_Ice"
    },
    {
      "x": -19,
      "y": 24,
      "z": 6,
      "name": "Rock_Ice"
    },
    {
      "x": -19,
      "y": 25,
      "z": 6,
      "name": "Rock_Ice"
    },
    {
      "x": -19,
      "y": 26,
      "z": 6,
      "name": "Rock_Ice"
    },
    {
      "x": -19,
      "y": 27,
      "z": 6,
      "name": "Soil_Snow"
    },
    {
      "x": -19,
      "y": 20,
      "z": 7,
      "name": "Rock_Ice_Permafrost"
    },
    {
      "x": -19,
      "y": 21,
      "z": 7,
      "name": "Rock_Ice"
    },
    {
      "x": -19,
      "y": 22,
      "z": 7,
      "name": "Rock_Ice"
    },
    {
      "x": -19,
      "y": 23,
      "z": 7,
      "name": "Rock_Ice"
    },
    {
      "x": -19,
      "y": 24,
      "z": 7,
      "name": "Rock_Ice"
    },
    {
      "x": -19,
      "y": 25,
      "z": 7,
      "name": "Rock_Ice"
    },
    {
      "x": -19,
      "y": 26,
      "z": 7,
      "name": "Rock_Ice"
    },
    {
      "x": -19,
      "y": 27,
      "z": 7,
      "name": "Soil_Snow"
    },
    {
      "x": -19,
      "y": 22,
      "z": 8,
      "name": "Rock_Ice_Permafrost"
    },
    {
      "x": -19,
      "y": 23,
      "z": 8,
      "name": "Rock_Ice_Permafrost"
    },
    {
      "x": -19,
      "y": 24,
      "z": 8,
      "name": "Rock_Ice_Permafrost"
    },
    {
      "x": -19,
      "y": 25,
      "z": 8,
      "name": "Rock_Ice_Permafrost"
    },
    {
      "x": -19,
      "y": 26,
      "z": 8,
      "name": "Rock_Ice"
    },
    {
      "x": -19,
      "y": 27,
      "z": 8,
      "name": "Rock_Ice"
    },
    {
      "x": -19,
      "y": 28,
      "z": 8,
      "name": "Soil_Snow"
    },
    {
      "x": -19,
      "y": 25,
      "z": 9,
      "name": "Rock_Ice_Permafrost"
    },
    {
      "x": -19,
      "y": 26,
      "z": 9,
      "name": "Rock_Ice_Permafrost"
    },
    {
      "x": -19,
      "y": 27,
      "z": 9,
      "name": "Rock_Ice_Permafrost"
    },
    {
      "x": -19,
      "y": 28,
      "z": 9,
      "name": "Rock_Ice_Permafrost"
    },
    {
      "x": -18,
      "y": 16,
      "z": -4,
      "name": "Rock_Ice"
    },
    {
      "x": -18,
      "y": 17,
      "z": -4,
      "name": "Rock_Ice"
    },
    {
      "x": -18,
      "y": 18,
      "z": -4,
      "name": "Rock_Ice"
    },
    {
      "x": -18,
      "y": 19,
      "z": -4,
      "name": "Rock_Ice"
    },
    {
      "x": -18,
      "y": 20,
      "z": -4,
      "name": "Rock_Ice"
    },
    {
      "x": -18,
      "y": 21,
      "z": -4,
      "name": "Soil_Snow"
    },
    {
      "x": -18,
      "y": 40,
      "z": -4,
      "name": "Soil_Snow"
    },
    {
      "x": -18,
      "y": 17,
      "z": -3,
      "name": "Rock_Ice"
    },
    {
      "x": -18,
      "y": 18,
      "z": -3,
      "name": "Rock_Ice"
    },
    {
      "x": -18,
      "y": 19,
      "z": -3,
      "name": "Rock_Ice"
    },
    {
      "x": -18,
      "y": 20,
      "z": -3,
      "name": "Rock_Ice"
    },
    {
      "x": -18,
      "y": 21,
      "z": -3,
      "name": "Rock_Ice"
    },
    {
      "x": -18,
      "y": 22,
      "z": -3,
      "name": "Rock_Ice"
    },
    {
      "x": -18,
      "y": 23,
      "z": -3,
      "name": "Rock_Ice"
    },
    {
      "x": -18,
      "y": 24,
      "z": -3,
      "name": "Rock_Ice"
    },
    {
      "x": -18,
      "y": 25,
      "z": -3,
      "name": "Rock_Ice"
    },
    {
      "x": -18,
      "y": 26,
      "z": -3,
      "name": "Rock_Ice"
    },
    {
      "x": -18,
      "y": 27,
      "z": -3,
      "name": "Rock_Ice"
    },
    {
      "x": -18,
      "y": 36,
      "z": -3,
      "name": "Rock_Ice"
    },
    {
      "x": -18,
      "y": 37,
      "z": -3,
      "name": "Rock_Ice"
    },
    {
      "x": -18,
      "y": 38,
      "z": -3,
      "name": "Rock_Ice"
    },
    {
      "x": -18,
      "y": 39,
      "z": -3,
      "name": "Soil_Snow"
    },
    {
      "x": -18,
      "y": 17,
      "z": -2,
      "name": "Rock_Ice"
    },
    {
      "x": -18,
      "y": 18,
      "z": -2,
      "name": "Rock_Ice"
    },
    {
      "x": -18,
      "y": 19,
      "z": -2,
      "name": "Rock_Ice"
    },
    {
      "x": -18,
      "y": 20,
      "z": -2,
      "name": "Rock_Ice"
    },
    {
      "x": -18,
      "y": 21,
      "z": -2,
      "name": "Rock_Ice"
    },
    {
      "x": -18,
      "y": 22,
      "z": -2,
      "name": "Rock_Ice"
    },
    {
      "x": -18,
      "y": 23,
      "z": -2,
      "name": "Rock_Ice"
    },
    {
      "x": -18,
      "y": 24,
      "z": -2,
      "name": "Rock_Ice"
    },
    {
      "x": -18,
      "y": 25,
      "z": -2,
      "name": "Rock_Ice"
    },
    {
      "x": -18,
      "y": 26,
      "z": -2,
      "name": "Rock_Ice"
    },
    {
      "x": -18,
      "y": 27,
      "z": -2,
      "name": "Rock_Ice"
    },
    {
      "x": -18,
      "y": 28,
      "z": -2,
      "name": "Rock_Ice"
    },
    {
      "x": -18,
      "y": 29,
      "z": -2,
      "name": "Rock_Ice"
    },
    {
      "x": -18,
      "y": 30,
      "z": -2,
      "name": "Rock_Ice"
    },
    {
      "x": -18,
      "y": 31,
      "z": -2,
      "name": "Rock_Ice"
    },
    {
      "x": -18,
      "y": 32,
      "z": -2,
      "name": "Rock_Ice"
    },
    {
      "x": -18,
      "y": 33,
      "z": -2,
      "name": "Rock_Ice"
    },
    {
      "x": -18,
      "y": 34,
      "z": -2,
      "name": "Rock_Ice"
    },
    {
      "x": -18,
      "y": 35,
      "z": -2,
      "name": "Rock_Ice"
    },
    {
      "x": -18,
      "y": 36,
      "z": -2,
      "name": "Rock_Ice"
    },
    {
      "x": -18,
      "y": 37,
      "z": -2,
      "name": "Rock_Ice"
    },
    {
      "x": -18,
      "y": 38,
      "z": -2,
      "name": "Rock_Ice"
    },
    {
      "x": -18,
      "y": 39,
      "z": -2,
      "name": "Soil_Snow"
    },
    {
      "x": -18,
      "y": 18,
      "z": -1,
      "name": "Rock_Ice"
    },
    {
      "x": -18,
      "y": 19,
      "z": -1,
      "name": "Rock_Ice"
    },
    {
      "x": -18,
      "y": 20,
      "z": -1,
      "name": "Rock_Ice"
    },
    {
      "x": -18,
      "y": 21,
      "z": -1,
      "name": "Rock_Ice"
    },
    {
      "x": -18,
      "y": 22,
      "z": -1,
      "name": "Rock_Ice"
    },
    {
      "x": -18,
      "y": 23,
      "z": -1,
      "name": "Rock_Ice"
    },
    {
      "x": -18,
      "y": 24,
      "z": -1,
      "name": "Rock_Ice"
    },
    {
      "x": -18,
      "y": 25,
      "z": -1,
      "name": "Rock_Ice"
    },
    {
      "x": -18,
      "y": 26,
      "z": -1,
      "name": "Rock_Ice_Permafrost"
    },
    {
      "x": -18,
      "y": 27,
      "z": -1,
      "name": "Rock_Ice_Permafrost"
    },
    {
      "x": -18,
      "y": 28,
      "z": -1,
      "name": "Rock_Ice_Permafrost"
    },
    {
      "x": -18,
      "y": 29,
      "z": -1,
      "name": "Rock_Ice"
    },
    {
      "x": -18,
      "y": 30,
      "z": -1,
      "name": "Rock_Ice"
    },
    {
      "x": -18,
      "y": 31,
      "z": -1,
      "name": "Rock_Ice"
    },
    {
      "x": -18,
      "y": 32,
      "z": -1,
      "name": "Rock_Ice"
    },
    {
      "x": -18,
      "y": 33,
      "z": -1,
      "name": "Rock_Ice"
    },
    {
      "x": -18,
      "y": 34,
      "z": -1,
      "name": "Rock_Ice"
    },
    {
      "x": -18,
      "y": 35,
      "z": -1,
      "name": "Rock_Ice"
    },
    {
      "x": -18,
      "y": 36,
      "z": -1,
      "name": "Rock_Ice"
    },
    {
      "x": -18,
      "y": 37,
      "z": -1,
      "name": "Rock_Ice"
    },
    {
      "x": -18,
      "y": 38,
      "z": -1,
      "name": "Rock_Ice"
    },
    {
      "x": -18,
      "y": 39,
      "z": -1,
      "name": "Soil_Snow"
    },
    {
      "x": -18,
      "y": 18,
      "z": 0,
      "name": "Rock_Ice"
    },
    {
      "x": -18,
      "y": 19,
      "z": 0,
      "name": "Rock_Ice"
    },
    {
      "x": -18,
      "y": 20,
      "z": 0,
      "name": "Rock_Ice"
    },
    {
      "x": -18,
      "y": 21,
      "z": 0,
      "name": "Rock_Ice"
    },
    {
      "x": -18,
      "y": 22,
      "z": 0,
      "name": "Rock_Ice"
    },
    {
      "x": -18,
      "y": 23,
      "z": 0,
      "name": "Rock_Ice_Permafrost"
    },
    {
      "x": -18,
      "y": 24,
      "z": 0,
      "name": "Rock_Ice_Permafrost"
    },
    {
      "x": -18,
      "y": 25,
      "z": 0,
      "name": "Rock_Ice_Permafrost"
    },
    {
      "x": -18,
      "y": 26,
      "z": 0,
      "name": "Rock_Ice_Permafrost"
    },
    {
      "x": -18,
      "y": 27,
      "z": 0,
      "name": "Rock_Ice"
    },
    {
      "x": -18,
      "y": 28,
      "z": 0,
      "name": "Rock_Ice"
    },
    {
      "x": -18,
      "y": 29,
      "z": 0,
      "name": "Rock_Ice"
    },
    {
      "x": -18,
      "y": 30,
      "z": 0,
      "name": "Rock_Ice"
    },
    {
      "x": -18,
      "y": 31,
      "z": 0,
      "name": "Rock_Ice"
    },
    {
      "x": -18,
      "y": 32,
      "z": 0,
      "name": "Rock_Ice"
    },
    {
      "x": -18,
      "y": 33,
      "z": 0,
      "name": "Rock_Ice"
    },
    {
      "x": -18,
      "y": 34,
      "z": 0,
      "name": "Rock_Ice"
    },
    {
      "x": -18,
      "y": 35,
      "z": 0,
      "name": "Rock_Ice"
    },
    {
      "x": -18,
      "y": 36,
      "z": 0,
      "name": "Rock_Ice"
    },
    {
      "x": -18,
      "y": 37,
      "z": 0,
      "name": "Rock_Ice"
    },
    {
      "x": -18,
      "y": 38,
      "z": 0,
      "name": "Rock_Ice"
    },
    {
      "x": -18,
      "y": 39,
      "z": 0,
      "name": "Soil_Snow"
    },
    {
      "x": -18,
      "y": 18,
      "z": 1,
      "name": "Rock_Ice"
    },
    {
      "x": -18,
      "y": 19,
      "z": 1,
      "name": "Rock_Ice"
    },
    {
      "x": -18,
      "y": 20,
      "z": 1,
      "name": "Rock_Ice_Permafrost"
    },
    {
      "x": -18,
      "y": 21,
      "z": 1,
      "name": "Rock_Ice_Permafrost"
    },
    {
      "x": -18,
      "y": 22,
      "z": 1,
      "name": "Rock_Ice_Permafrost"
    },
    {
      "x": -18,
      "y": 23,
      "z": 1,
      "name": "Rock_Ice_Permafrost"
    },
    {
      "x": -18,
      "y": 24,
      "z": 1,
      "name": "Rock_Ice"
    },
    {
      "x": -18,
      "y": 25,
      "z": 1,
      "name": "Rock_Ice"
    },
    {
      "x": -18,
      "y": 26,
      "z": 1,
      "name": "Rock_Ice"
    },
    {
      "x": -18,
      "y": 27,
      "z": 1,
      "name": "Rock_Ice"
    },
    {
      "x": -18,
      "y": 28,
      "z": 1,
      "name": "Rock_Ice"
    },
    {
      "x": -18,
      "y": 29,
      "z": 1,
      "name": "Rock_Ice"
    },
    {
      "x": -18,
      "y": 30,
      "z": 1,
      "name": "Rock_Ice"
    },
    {
      "x": -18,
      "y": 31,
      "z": 1,
      "name": "Rock_Ice"
    },
    {
      "x": -18,
      "y": 32,
      "z": 1,
      "name": "Rock_Ice"
    },
    {
      "x": -18,
      "y": 33,
      "z": 1,
      "name": "Rock_Ice"
    },
    {
      "x": -18,
      "y": 34,
      "z": 1,
      "name": "Rock_Ice"
    },
    {
      "x": -18,
      "y": 35,
      "z": 1,
      "name": "Rock_Ice"
    },
    {
      "x": -18,
      "y": 36,
      "z": 1,
      "name": "Rock_Ice"
    },
    {
      "x": -18,
      "y": 37,
      "z": 1,
      "name": "Rock_Ice"
    },
    {
      "x": -18,
      "y": 38,
      "z": 1,
      "name": "Rock_Ice"
    },
    {
      "x": -18,
      "y": 39,
      "z": 1,
      "name": "Soil_Snow"
    },
    {
      "x": -18,
      "y": 18,
      "z": 2,
      "name": "Rock_Ice_Permafrost"
    },
    {
      "x": -18,
      "y": 19,
      "z": 2,
      "name": "Rock_Ice_Permafrost"
    },
    {
      "x": -18,
      "y": 20,
      "z": 2,
      "name": "Rock_Crystal_Cyan_Block_WhiteLight"
    },
    {
      "x": -18,
      "y": 21,
      "z": 2,
      "name": "Rock_Ice_Permafrost"
    },
    {
      "x": -18,
      "y": 22,
      "z": 2,
      "name": "Rock_Ice"
    },
    {
      "x": -18,
      "y": 23,
      "z": 2,
      "name": "Rock_Ice"
    },
    {
      "x": -18,
      "y": 24,
      "z": 2,
      "name": "Rock_Ice"
    },
    {
      "x": -18,
      "y": 25,
      "z": 2,
      "name": "Rock_Ice"
    },
    {
      "x": -18,
      "y": 26,
      "z": 2,
      "name": "Rock_Ice"
    },
    {
      "x": -18,
      "y": 27,
      "z": 2,
      "name": "Rock_Ice"
    },
    {
      "x": -18,
      "y": 28,
      "z": 2,
      "name": "Rock_Ice"
    },
    {
      "x": -18,
      "y": 29,
      "z": 2,
      "name": "Rock_Ice"
    },
    {
      "x": -18,
      "y": 30,
      "z": 2,
      "name": "Rock_Ice"
    },
    {
      "x": -18,
      "y": 31,
      "z": 2,
      "name": "Rock_Ice"
    },
    {
      "x": -18,
      "y": 32,
      "z": 2,
      "name": "Rock_Ice"
    },
    {
      "x": -18,
      "y": 33,
      "z": 2,
      "name": "Rock_Ice"
    },
    {
      "x": -18,
      "y": 34,
      "z": 2,
      "name": "Rock_Ice"
    },
    {
      "x": -18,
      "y": 35,
      "z": 2,
      "name": "Rock_Ice"
    },
    {
      "x": -18,
      "y": 36,
      "z": 2,
      "name": "Rock_Ice"
    },
    {
      "x": -18,
      "y": 37,
      "z": 2,
      "name": "Rock_Ice"
    },
    {
      "x": -18,
      "y": 38,
      "z": 2,
      "name": "Rock_Ice"
    },
    {
      "x": -18,
      "y": 39,
      "z": 2,
      "name": "Rock_Ice"
    },
    {
      "x": -18,
      "y": 17,
      "z": 3,
      "name": "Rock_Ice_Permafrost"
    },
    {
      "x": -18,
      "y": 18,
      "z": 3,
      "name": "Rock_Ice_Permafrost"
    },
    {
      "x": -18,
      "y": 19,
      "z": 3,
      "name": "Rock_Ice_Permafrost"
    },
    {
      "x": -18,
      "y": 20,
      "z": 3,
      "name": "Rock_Ice"
    },
    {
      "x": -18,
      "y": 21,
      "z": 3,
      "name": "Rock_Ice"
    },
    {
      "x": -18,
      "y": 22,
      "z": 3,
      "name": "Rock_Ice_Permafrost"
    },
    {
      "x": -18,
      "y": 23,
      "z": 3,
      "name": "Rock_Ice"
    },
    {
      "x": -18,
      "y": 24,
      "z": 3,
      "name": "Rock_Ice"
    },
    {
      "x": -18,
      "y": 25,
      "z": 3,
      "name": "Rock_Ice"
    },
    {
      "x": -18,
      "y": 26,
      "z": 3,
      "name": "Rock_Ice"
    },
    {
      "x": -18,
      "y": 27,
      "z": 3,
      "name": "Rock_Ice"
    },
    {
      "x": -18,
      "y": 28,
      "z": 3,
      "name": "Rock_Ice"
    },
    {
      "x": -18,
      "y": 29,
      "z": 3,
      "name": "Rock_Ice"
    },
    {
      "x": -18,
      "y": 30,
      "z": 3,
      "name": "Rock_Ice"
    },
    {
      "x": -18,
      "y": 31,
      "z": 3,
      "name": "Rock_Ice"
    },
    {
      "x": -18,
      "y": 32,
      "z": 3,
      "name": "Rock_Ice"
    },
    {
      "x": -18,
      "y": 33,
      "z": 3,
      "name": "Rock_Ice"
    },
    {
      "x": -18,
      "y": 34,
      "z": 3,
      "name": "Rock_Ice"
    },
    {
      "x": -18,
      "y": 17,
      "z": 4,
      "name": "Rock_Ice_Permafrost"
    },
    {
      "x": -18,
      "y": 18,
      "z": 4,
      "name": "Rock_Ice"
    },
    {
      "x": -18,
      "y": 19,
      "z": 4,
      "name": "Rock_Ice_Permafrost"
    },
    {
      "x": -18,
      "y": 20,
      "z": 4,
      "name": "Rock_Ice_Permafrost"
    },
    {
      "x": -18,
      "y": 21,
      "z": 4,
      "name": "Rock_Ice"
    },
    {
      "x": -18,
      "y": 22,
      "z": 4,
      "name": "Rock_Ice_Permafrost"
    },
    {
      "x": -18,
      "y": 23,
      "z": 4,
      "name": "Rock_Ice"
    },
    {
      "x": -18,
      "y": 24,
      "z": 4,
      "name": "Rock_Ice"
    },
    {
      "x": -18,
      "y": 25,
      "z": 4,
      "name": "Rock_Ice"
    },
    {
      "x": -18,
      "y": 26,
      "z": 4,
      "name": "Rock_Ice"
    },
    {
      "x": -18,
      "y": 27,
      "z": 4,
      "name": "Rock_Ice"
    },
    {
      "x": -18,
      "y": 28,
      "z": 4,
      "name": "Rock_Ice"
    },
    {
      "x": -18,
      "y": 29,
      "z": 4,
      "name": "Rock_Ice"
    },
    {
      "x": -18,
      "y": 30,
      "z": 4,
      "name": "Rock_Ice"
    },
    {
      "x": -18,
      "y": 31,
      "z": 4,
      "name": "Rock_Ice"
    },
    {
      "x": -18,
      "y": 32,
      "z": 4,
      "name": "Soil_Snow"
    },
    {
      "x": -18,
      "y": 16,
      "z": 5,
      "name": "Rock_Ice"
    },
    {
      "x": -18,
      "y": 17,
      "z": 5,
      "name": "Rock_Ice_Permafrost"
    },
    {
      "x": -18,
      "y": 18,
      "z": 5,
      "name": "Rock_Ice_Permafrost"
    },
    {
      "x": -18,
      "y": 19,
      "z": 5,
      "name": "Rock_Ice_Permafrost"
    },
    {
      "x": -18,
      "y": 20,
      "z": 5,
      "name": "Rock_Ice_Permafrost"
    },
    {
      "x": -18,
      "y": 21,
      "z": 5,
      "name": "Rock_Ice_Permafrost"
    },
    {
      "x": -18,
      "y": 22,
      "z": 5,
      "name": "Rock_Ice_Permafrost"
    },
    {
      "x": -18,
      "y": 23,
      "z": 5,
      "name": "Rock_Ice_Permafrost"
    },
    {
      "x": -18,
      "y": 24,
      "z": 5,
      "name": "Rock_Ice"
    },
    {
      "x": -18,
      "y": 25,
      "z": 5,
      "name": "Rock_Ice"
    },
    {
      "x": -18,
      "y": 26,
      "z": 5,
      "name": "Rock_Ice"
    },
    {
      "x": -18,
      "y": 27,
      "z": 5,
      "name": "Rock_Ice"
    },
    {
      "x": -18,
      "y": 28,
      "z": 5,
      "name": "Rock_Ice"
    },
    {
      "x": -18,
      "y": 29,
      "z": 5,
      "name": "Rock_Ice"
    },
    {
      "x": -18,
      "y": 30,
      "z": 5,
      "name": "Rock_Ice"
    },
    {
      "x": -18,
      "y": 31,
      "z": 5,
      "name": "Soil_Snow"
    },
    {
      "x": -18,
      "y": 16,
      "z": 6,
      "name": "Rock_Ice"
    },
    {
      "x": -18,
      "y": 17,
      "z": 6,
      "name": "Rock_Ice"
    },
    {
      "x": -18,
      "y": 18,
      "z": 6,
      "name": "Rock_Ice_Permafrost"
    },
    {
      "x": -18,
      "y": 19,
      "z": 6,
      "name": "Rock_Ice"
    },
    {
      "x": -18,
      "y": 20,
      "z": 6,
      "name": "Rock_Ice_Permafrost"
    },
    {
      "x": -18,
      "y": 21,
      "z": 6,
      "name": "Rock_Ice_Permafrost"
    },
    {
      "x": -18,
      "y": 22,
      "z": 6,
      "name": "Rock_Ice_Permafrost"
    },
    {
      "x": -18,
      "y": 23,
      "z": 6,
      "name": "Rock_Ice_Permafrost"
    },
    {
      "x": -18,
      "y": 24,
      "z": 6,
      "name": "Rock_Ice"
    },
    {
      "x": -18,
      "y": 25,
      "z": 6,
      "name": "Rock_Ice"
    },
    {
      "x": -18,
      "y": 26,
      "z": 6,
      "name": "Rock_Ice"
    },
    {
      "x": -18,
      "y": 27,
      "z": 6,
      "name": "Rock_Ice"
    },
    {
      "x": -18,
      "y": 28,
      "z": 6,
      "name": "Rock_Ice"
    },
    {
      "x": -18,
      "y": 29,
      "z": 6,
      "name": "Rock_Ice"
    },
    {
      "x": -18,
      "y": 30,
      "z": 6,
      "name": "Rock_Ice"
    },
    {
      "x": -18,
      "y": 31,
      "z": 6,
      "name": "Soil_Snow"
    },
    {
      "x": -18,
      "y": 17,
      "z": 7,
      "name": "Rock_Ice"
    },
    {
      "x": -18,
      "y": 18,
      "z": 7,
      "name": "Rock_Ice"
    },
    {
      "x": -18,
      "y": 19,
      "z": 7,
      "name": "Rock_Ice"
    },
    {
      "x": -18,
      "y": 20,
      "z": 7,
      "name": "Rock_Ice"
    },
    {
      "x": -18,
      "y": 21,
      "z": 7,
      "name": "Rock_Ice_Permafrost"
    },
    {
      "x": -18,
      "y": 22,
      "z": 7,
      "name": "Rock_Crystal_Cyan_Block_WhiteLight"
    },
    {
      "x": -18,
      "y": 23,
      "z": 7,
      "name": "Rock_Crystal_Cyan_Block_WhiteLight"
    },
    {
      "x": -18,
      "y": 24,
      "z": 7,
      "name": "Rock_Ice"
    },
    {
      "x": -18,
      "y": 25,
      "z": 7,
      "name": "Rock_Ice"
    },
    {
      "x": -18,
      "y": 26,
      "z": 7,
      "name": "Rock_Ice"
    },
    {
      "x": -18,
      "y": 27,
      "z": 7,
      "name": "Rock_Ice"
    },
    {
      "x": -18,
      "y": 28,
      "z": 7,
      "name": "Rock_Ice"
    },
    {
      "x": -18,
      "y": 29,
      "z": 7,
      "name": "Rock_Ice"
    },
    {
      "x": -18,
      "y": 30,
      "z": 7,
      "name": "Rock_Ice"
    },
    {
      "x": -18,
      "y": 31,
      "z": 7,
      "name": "Soil_Snow"
    },
    {
      "x": -18,
      "y": 19,
      "z": 8,
      "name": "Rock_Ice"
    },
    {
      "x": -18,
      "y": 20,
      "z": 8,
      "name": "Rock_Ice"
    },
    {
      "x": -18,
      "y": 21,
      "z": 8,
      "name": "Rock_Ice_Permafrost"
    },
    {
      "x": -18,
      "y": 22,
      "z": 8,
      "name": "Rock_Ice_Permafrost"
    },
    {
      "x": -18,
      "y": 23,
      "z": 8,
      "name": "Rock_Ice_Permafrost"
    },
    {
      "x": -18,
      "y": 24,
      "z": 8,
      "name": "Rock_Ice_Permafrost"
    },
    {
      "x": -18,
      "y": 25,
      "z": 8,
      "name": "Rock_Ice_Permafrost"
    },
    {
      "x": -18,
      "y": 26,
      "z": 8,
      "name": "Rock_Ice"
    },
    {
      "x": -18,
      "y": 27,
      "z": 8,
      "name": "Rock_Ice_Permafrost"
    },
    {
      "x": -18,
      "y": 28,
      "z": 8,
      "name": "Rock_Ice"
    },
    {
      "x": -18,
      "y": 29,
      "z": 8,
      "name": "Rock_Ice"
    },
    {
      "x": -18,
      "y": 30,
      "z": 8,
      "name": "Rock_Ice"
    },
    {
      "x": -18,
      "y": 31,
      "z": 8,
      "name": "Soil_Snow"
    },
    {
      "x": -18,
      "y": 20,
      "z": 9,
      "name": "Rock_Ice"
    },
    {
      "x": -18,
      "y": 21,
      "z": 9,
      "name": "Rock_Ice"
    },
    {
      "x": -18,
      "y": 22,
      "z": 9,
      "name": "Rock_Ice"
    },
    {
      "x": -18,
      "y": 23,
      "z": 9,
      "name": "Rock_Ice"
    },
    {
      "x": -18,
      "y": 24,
      "z": 9,
      "name": "Rock_Ice"
    },
    {
      "x": -18,
      "y": 25,
      "z": 9,
      "name": "Rock_Ice"
    },
    {
      "x": -18,
      "y": 26,
      "z": 9,
      "name": "Rock_Ice_Permafrost"
    },
    {
      "x": -18,
      "y": 27,
      "z": 9,
      "name": "Rock_Crystal_Cyan_Block_WhiteLight"
    },
    {
      "x": -18,
      "y": 28,
      "z": 9,
      "name": "Rock_Ice_Permafrost"
    },
    {
      "x": -18,
      "y": 29,
      "z": 9,
      "name": "Rock_Ice_Permafrost"
    },
    {
      "x": -18,
      "y": 30,
      "z": 9,
      "name": "Rock_Crystal_Cyan_Block_WhiteLight"
    },
    {
      "x": -18,
      "y": 31,
      "z": 9,
      "name": "Rock_Ice"
    },
    {
      "x": -18,
      "y": 32,
      "z": 9,
      "name": "Soil_Snow"
    },
    {
      "x": -18,
      "y": 24,
      "z": 10,
      "name": "Rock_Ice"
    },
    {
      "x": -18,
      "y": 25,
      "z": 10,
      "name": "Rock_Ice"
    },
    {
      "x": -18,
      "y": 26,
      "z": 10,
      "name": "Rock_Ice_Permafrost"
    },
    {
      "x": -18,
      "y": 27,
      "z": 10,
      "name": "Rock_Ice"
    },
    {
      "x": -18,
      "y": 28,
      "z": 10,
      "name": "Rock_Ice_Permafrost"
    },
    {
      "x": -17,
      "y": 14,
      "z": -5,
      "name": "Rock_Ice"
    },
    {
      "x": -17,
      "y": 15,
      "z": -5,
      "name": "Rock_Ice"
    },
    {
      "x": -17,
      "y": 16,
      "z": -5,
      "name": "Rock_Ice"
    },
    {
      "x": -17,
      "y": 17,
      "z": -5,
      "name": "Rock_Ice"
    },
    {
      "x": -17,
      "y": 18,
      "z": -5,
      "name": "Rock_Ice"
    },
    {
      "x": -17,
      "y": 19,
      "z": -5,
      "name": "Rock_Ice"
    },
    {
      "x": -17,
      "y": 20,
      "z": -5,
      "name": "Rock_Ice"
    },
    {
      "x": -17,
      "y": 21,
      "z": -5,
      "name": "Rock_Ice"
    },
    {
      "x": -17,
      "y": 40,
      "z": -5,
      "name": "Rock_Ice"
    },
    {
      "x": -17,
      "y": 41,
      "z": -5,
      "name": "Rock_Ice"
    },
    {
      "x": -17,
      "y": 42,
      "z": -5,
      "name": "Soil_Snow"
    },
    {
      "x": -17,
      "y": 15,
      "z": -4,
      "name": "Rock_Ice"
    },
    {
      "x": -17,
      "y": 16,
      "z": -4,
      "name": "Rock_Ice"
    },
    {
      "x": -17,
      "y": 17,
      "z": -4,
      "name": "Rock_Ice"
    },
    {
      "x": -17,
      "y": 18,
      "z": -4,
      "name": "Rock_Ice"
    },
    {
      "x": -17,
      "y": 19,
      "z": -4,
      "name": "Rock_Ice"
    },
    {
      "x": -17,
      "y": 20,
      "z": -4,
      "name": "Rock_Ice"
    },
    {
      "x": -17,
      "y": 21,
      "z": -4,
      "name": "Rock_Ice"
    },
    {
      "x": -17,
      "y": 22,
      "z": -4,
      "name": "Rock_Ice"
    },
    {
      "x": -17,
      "y": 23,
      "z": -4,
      "name": "Rock_Ice"
    },
    {
      "x": -17,
      "y": 24,
      "z": -4,
      "name": "Rock_Ice"
    },
    {
      "x": -17,
      "y": 25,
      "z": -4,
      "name": "Rock_Ice"
    },
    {
      "x": -17,
      "y": 26,
      "z": -4,
      "name": "Rock_Ice"
    },
    {
      "x": -17,
      "y": 27,
      "z": -4,
      "name": "Rock_Ice"
    },
    {
      "x": -17,
      "y": 34,
      "z": -4,
      "name": "Rock_Ice"
    },
    {
      "x": -17,
      "y": 35,
      "z": -4,
      "name": "Rock_Ice"
    },
    {
      "x": -17,
      "y": 36,
      "z": -4,
      "name": "Rock_Ice"
    },
    {
      "x": -17,
      "y": 37,
      "z": -4,
      "name": "Rock_Ice"
    },
    {
      "x": -17,
      "y": 38,
      "z": -4,
      "name": "Rock_Ice"
    },
    {
      "x": -17,
      "y": 39,
      "z": -4,
      "name": "Rock_Ice"
    },
    {
      "x": -17,
      "y": 40,
      "z": -4,
      "name": "Rock_Ice"
    },
    {
      "x": -17,
      "y": 41,
      "z": -4,
      "name": "Rock_Ice"
    },
    {
      "x": -17,
      "y": 42,
      "z": -4,
      "name": "Rock_Ice"
    },
    {
      "x": -17,
      "y": 43,
      "z": -4,
      "name": "Rock_Ice"
    },
    {
      "x": -17,
      "y": 16,
      "z": -3,
      "name": "Rock_Ice"
    },
    {
      "x": -17,
      "y": 17,
      "z": -3,
      "name": "Rock_Ice"
    },
    {
      "x": -17,
      "y": 18,
      "z": -3,
      "name": "Rock_Ice"
    },
    {
      "x": -17,
      "y": 19,
      "z": -3,
      "name": "Rock_Ice"
    },
    {
      "x": -17,
      "y": 20,
      "z": -3,
      "name": "Rock_Ice"
    },
    {
      "x": -17,
      "y": 21,
      "z": -3,
      "name": "Rock_Ice"
    },
    {
      "x": -17,
      "y": 22,
      "z": -3,
      "name": "Rock_Ice"
    },
    {
      "x": -17,
      "y": 23,
      "z": -3,
      "name": "Rock_Ice"
    },
    {
      "x": -17,
      "y": 24,
      "z": -3,
      "name": "Rock_Ice"
    },
    {
      "x": -17,
      "y": 25,
      "z": -3,
      "name": "Rock_Ice"
    },
    {
      "x": -17,
      "y": 26,
      "z": -3,
      "name": "Rock_Ice"
    },
    {
      "x": -17,
      "y": 27,
      "z": -3,
      "name": "Rock_Ice"
    },
    {
      "x": -17,
      "y": 28,
      "z": -3,
      "name": "Rock_Ice"
    },
    {
      "x": -17,
      "y": 29,
      "z": -3,
      "name": "Rock_Ice"
    },
    {
      "x": -17,
      "y": 30,
      "z": -3,
      "name": "Rock_Ice"
    },
    {
      "x": -17,
      "y": 31,
      "z": -3,
      "name": "Rock_Ice"
    },
    {
      "x": -17,
      "y": 32,
      "z": -3,
      "name": "Rock_Ice"
    },
    {
      "x": -17,
      "y": 33,
      "z": -3,
      "name": "Rock_Ice"
    },
    {
      "x": -17,
      "y": 34,
      "z": -3,
      "name": "Rock_Ice"
    },
    {
      "x": -17,
      "y": 35,
      "z": -3,
      "name": "Rock_Ice"
    },
    {
      "x": -17,
      "y": 36,
      "z": -3,
      "name": "Rock_Ice"
    },
    {
      "x": -17,
      "y": 37,
      "z": -3,
      "name": "Rock_Ice"
    },
    {
      "x": -17,
      "y": 38,
      "z": -3,
      "name": "Rock_Ice"
    },
    {
      "x": -17,
      "y": 39,
      "z": -3,
      "name": "Rock_Ice"
    },
    {
      "x": -17,
      "y": 40,
      "z": -3,
      "name": "Rock_Ice"
    },
    {
      "x": -17,
      "y": 41,
      "z": -3,
      "name": "Soil_Snow"
    },
    {
      "x": -17,
      "y": 16,
      "z": -2,
      "name": "Rock_Ice"
    },
    {
      "x": -17,
      "y": 17,
      "z": -2,
      "name": "Rock_Ice"
    },
    {
      "x": -17,
      "y": 18,
      "z": -2,
      "name": "Rock_Ice"
    },
    {
      "x": -17,
      "y": 19,
      "z": -2,
      "name": "Rock_Ice"
    },
    {
      "x": -17,
      "y": 20,
      "z": -2,
      "name": "Rock_Ice"
    },
    {
      "x": -17,
      "y": 21,
      "z": -2,
      "name": "Rock_Ice"
    },
    {
      "x": -17,
      "y": 22,
      "z": -2,
      "name": "Rock_Ice"
    },
    {
      "x": -17,
      "y": 23,
      "z": -2,
      "name": "Rock_Ice"
    },
    {
      "x": -17,
      "y": 24,
      "z": -2,
      "name": "Rock_Ice"
    },
    {
      "x": -17,
      "y": 25,
      "z": -2,
      "name": "Rock_Ice"
    },
    {
      "x": -17,
      "y": 26,
      "z": -2,
      "name": "Rock_Ice"
    },
    {
      "x": -17,
      "y": 27,
      "z": -2,
      "name": "Rock_Ice"
    },
    {
      "x": -17,
      "y": 28,
      "z": -2,
      "name": "Rock_Ice"
    },
    {
      "x": -17,
      "y": 29,
      "z": -2,
      "name": "Rock_Ice"
    },
    {
      "x": -17,
      "y": 30,
      "z": -2,
      "name": "Rock_Ice"
    },
    {
      "x": -17,
      "y": 31,
      "z": -2,
      "name": "Rock_Ice"
    },
    {
      "x": -17,
      "y": 32,
      "z": -2,
      "name": "Rock_Ice"
    },
    {
      "x": -17,
      "y": 33,
      "z": -2,
      "name": "Rock_Ice"
    },
    {
      "x": -17,
      "y": 34,
      "z": -2,
      "name": "Rock_Ice"
    },
    {
      "x": -17,
      "y": 35,
      "z": -2,
      "name": "Rock_Ice"
    },
    {
      "x": -17,
      "y": 36,
      "z": -2,
      "name": "Rock_Ice"
    },
    {
      "x": -17,
      "y": 37,
      "z": -2,
      "name": "Rock_Ice"
    },
    {
      "x": -17,
      "y": 38,
      "z": -2,
      "name": "Rock_Ice"
    },
    {
      "x": -17,
      "y": 39,
      "z": -2,
      "name": "Rock_Ice"
    },
    {
      "x": -17,
      "y": 40,
      "z": -2,
      "name": "Rock_Ice"
    },
    {
      "x": -17,
      "y": 41,
      "z": -2,
      "name": "Soil_Snow"
    },
    {
      "x": -17,
      "y": 16,
      "z": -1,
      "name": "Rock_Ice"
    },
    {
      "x": -17,
      "y": 17,
      "z": -1,
      "name": "Rock_Ice"
    },
    {
      "x": -17,
      "y": 18,
      "z": -1,
      "name": "Rock_Ice"
    },
    {
      "x": -17,
      "y": 19,
      "z": -1,
      "name": "Rock_Ice"
    },
    {
      "x": -17,
      "y": 20,
      "z": -1,
      "name": "Rock_Ice"
    },
    {
      "x": -17,
      "y": 21,
      "z": -1,
      "name": "Rock_Ice"
    },
    {
      "x": -17,
      "y": 22,
      "z": -1,
      "name": "Rock_Ice"
    },
    {
      "x": -17,
      "y": 23,
      "z": -1,
      "name": "Rock_Ice"
    },
    {
      "x": -17,
      "y": 24,
      "z": -1,
      "name": "Rock_Ice"
    },
    {
      "x": -17,
      "y": 25,
      "z": -1,
      "name": "Rock_Ice"
    },
    {
      "x": -17,
      "y": 26,
      "z": -1,
      "name": "Rock_Ice"
    },
    {
      "x": -17,
      "y": 27,
      "z": -1,
      "name": "Rock_Ice_Permafrost"
    },
    {
      "x": -17,
      "y": 28,
      "z": -1,
      "name": "Rock_Ice"
    },
    {
      "x": -17,
      "y": 29,
      "z": -1,
      "name": "Rock_Ice"
    },
    {
      "x": -17,
      "y": 30,
      "z": -1,
      "name": "Rock_Ice"
    },
    {
      "x": -17,
      "y": 31,
      "z": -1,
      "name": "Rock_Ice_Permafrost"
    },
    {
      "x": -17,
      "y": 32,
      "z": -1,
      "name": "Rock_Ice"
    },
    {
      "x": -17,
      "y": 33,
      "z": -1,
      "name": "Rock_Ice"
    },
    {
      "x": -17,
      "y": 34,
      "z": -1,
      "name": "Rock_Ice"
    },
    {
      "x": -17,
      "y": 35,
      "z": -1,
      "name": "Rock_Ice"
    },
    {
      "x": -17,
      "y": 36,
      "z": -1,
      "name": "Rock_Ice"
    },
    {
      "x": -17,
      "y": 37,
      "z": -1,
      "name": "Rock_Ice"
    },
    {
      "x": -17,
      "y": 38,
      "z": -1,
      "name": "Rock_Ice"
    },
    {
      "x": -17,
      "y": 39,
      "z": -1,
      "name": "Rock_Ice"
    },
    {
      "x": -17,
      "y": 40,
      "z": -1,
      "name": "Rock_Ice"
    },
    {
      "x": -17,
      "y": 41,
      "z": -1,
      "name": "Soil_Snow"
    },
    {
      "x": -17,
      "y": 17,
      "z": 0,
      "name": "Rock_Ice"
    },
    {
      "x": -17,
      "y": 18,
      "z": 0,
      "name": "Rock_Ice"
    },
    {
      "x": -17,
      "y": 19,
      "z": 0,
      "name": "Rock_Ice"
    },
    {
      "x": -17,
      "y": 20,
      "z": 0,
      "name": "Rock_Ice"
    },
    {
      "x": -17,
      "y": 21,
      "z": 0,
      "name": "Rock_Ice"
    },
    {
      "x": -17,
      "y": 22,
      "z": 0,
      "name": "Rock_Ice"
    },
    {
      "x": -17,
      "y": 23,
      "z": 0,
      "name": "Rock_Ice"
    },
    {
      "x": -17,
      "y": 24,
      "z": 0,
      "name": "Rock_Ice_Permafrost"
    },
    {
      "x": -17,
      "y": 25,
      "z": 0,
      "name": "Rock_Ice_Permafrost"
    },
    {
      "x": -17,
      "y": 26,
      "z": 0,
      "name": "Rock_Ice_Permafrost"
    },
    {
      "x": -17,
      "y": 27,
      "z": 0,
      "name": "Rock_Ice_Permafrost"
    },
    {
      "x": -17,
      "y": 28,
      "z": 0,
      "name": "Rock_Ice_Permafrost"
    },
    {
      "x": -17,
      "y": 29,
      "z": 0,
      "name": "Rock_Ice"
    },
    {
      "x": -17,
      "y": 30,
      "z": 0,
      "name": "Rock_Ice"
    },
    {
      "x": -17,
      "y": 31,
      "z": 0,
      "name": "Rock_Ice"
    },
    {
      "x": -17,
      "y": 32,
      "z": 0,
      "name": "Rock_Ice"
    },
    {
      "x": -17,
      "y": 33,
      "z": 0,
      "name": "Rock_Ice"
    },
    {
      "x": -17,
      "y": 34,
      "z": 0,
      "name": "Rock_Ice"
    },
    {
      "x": -17,
      "y": 35,
      "z": 0,
      "name": "Rock_Ice"
    },
    {
      "x": -17,
      "y": 36,
      "z": 0,
      "name": "Rock_Ice"
    },
    {
      "x": -17,
      "y": 37,
      "z": 0,
      "name": "Rock_Ice"
    },
    {
      "x": -17,
      "y": 38,
      "z": 0,
      "name": "Rock_Ice"
    },
    {
      "x": -17,
      "y": 39,
      "z": 0,
      "name": "Rock_Ice"
    },
    {
      "x": -17,
      "y": 40,
      "z": 0,
      "name": "Rock_Ice"
    },
    {
      "x": -17,
      "y": 41,
      "z": 0,
      "name": "Soil_Snow"
    },
    {
      "x": -17,
      "y": 17,
      "z": 1,
      "name": "Rock_Ice"
    },
    {
      "x": -17,
      "y": 18,
      "z": 1,
      "name": "Rock_Ice"
    },
    {
      "x": -17,
      "y": 19,
      "z": 1,
      "name": "Rock_Ice"
    },
    {
      "x": -17,
      "y": 20,
      "z": 1,
      "name": "Rock_Ice"
    },
    {
      "x": -17,
      "y": 21,
      "z": 1,
      "name": "Rock_Ice"
    },
    {
      "x": -17,
      "y": 22,
      "z": 1,
      "name": "Rock_Ice_Permafrost"
    },
    {
      "x": -17,
      "y": 23,
      "z": 1,
      "name": "Rock_Ice_Permafrost"
    },
    {
      "x": -17,
      "y": 24,
      "z": 1,
      "name": "Rock_Crystal_Cyan_Block_WhiteLight"
    },
    {
      "x": -17,
      "y": 25,
      "z": 1,
      "name": "Rock_Ice_Permafrost"
    },
    {
      "x": -17,
      "y": 26,
      "z": 1,
      "name": "Rock_Ice_Permafrost"
    },
    {
      "x": -17,
      "y": 27,
      "z": 1,
      "name": "Rock_Ice"
    },
    {
      "x": -17,
      "y": 28,
      "z": 1,
      "name": "Rock_Ice"
    },
    {
      "x": -17,
      "y": 29,
      "z": 1,
      "name": "Rock_Ice"
    },
    {
      "x": -17,
      "y": 30,
      "z": 1,
      "name": "Rock_Ice"
    },
    {
      "x": -17,
      "y": 31,
      "z": 1,
      "name": "Rock_Ice"
    },
    {
      "x": -17,
      "y": 32,
      "z": 1,
      "name": "Rock_Ice"
    },
    {
      "x": -17,
      "y": 33,
      "z": 1,
      "name": "Rock_Ice"
    },
    {
      "x": -17,
      "y": 34,
      "z": 1,
      "name": "Rock_Ice"
    },
    {
      "x": -17,
      "y": 35,
      "z": 1,
      "name": "Rock_Ice"
    },
    {
      "x": -17,
      "y": 36,
      "z": 1,
      "name": "Rock_Ice"
    },
    {
      "x": -17,
      "y": 37,
      "z": 1,
      "name": "Rock_Ice"
    },
    {
      "x": -17,
      "y": 38,
      "z": 1,
      "name": "Rock_Ice"
    },
    {
      "x": -17,
      "y": 39,
      "z": 1,
      "name": "Rock_Ice"
    },
    {
      "x": -17,
      "y": 40,
      "z": 1,
      "name": "Rock_Ice"
    },
    {
      "x": -17,
      "y": 41,
      "z": 1,
      "name": "Rock_Ice"
    },
    {
      "x": -17,
      "y": 42,
      "z": 1,
      "name": "Soil_Snow"
    },
    {
      "x": -17,
      "y": 17,
      "z": 2,
      "name": "Rock_Ice_Permafrost"
    },
    {
      "x": -17,
      "y": 18,
      "z": 2,
      "name": "Rock_Ice_Permafrost"
    },
    {
      "x": -17,
      "y": 19,
      "z": 2,
      "name": "Rock_Ice_Permafrost"
    },
    {
      "x": -17,
      "y": 20,
      "z": 2,
      "name": "Rock_Ice_Permafrost"
    },
    {
      "x": -17,
      "y": 21,
      "z": 2,
      "name": "Rock_Ice_Permafrost"
    },
    {
      "x": -17,
      "y": 22,
      "z": 2,
      "name": "Rock_Ice_Permafrost"
    },
    {
      "x": -17,
      "y": 23,
      "z": 2,
      "name": "Rock_Ice_Permafrost"
    },
    {
      "x": -17,
      "y": 24,
      "z": 2,
      "name": "Rock_Ice_Permafrost"
    },
    {
      "x": -17,
      "y": 25,
      "z": 2,
      "name": "Rock_Ice"
    },
    {
      "x": -17,
      "y": 26,
      "z": 2,
      "name": "Rock_Ice"
    },
    {
      "x": -17,
      "y": 27,
      "z": 2,
      "name": "Rock_Ice"
    },
    {
      "x": -17,
      "y": 28,
      "z": 2,
      "name": "Rock_Ice"
    },
    {
      "x": -17,
      "y": 29,
      "z": 2,
      "name": "Rock_Ice"
    },
    {
      "x": -17,
      "y": 30,
      "z": 2,
      "name": "Rock_Ice"
    },
    {
      "x": -17,
      "y": 31,
      "z": 2,
      "name": "Rock_Ice"
    },
    {
      "x": -17,
      "y": 32,
      "z": 2,
      "name": "Rock_Ice"
    },
    {
      "x": -17,
      "y": 33,
      "z": 2,
      "name": "Rock_Ice"
    },
    {
      "x": -17,
      "y": 34,
      "z": 2,
      "name": "Rock_Ice"
    },
    {
      "x": -17,
      "y": 35,
      "z": 2,
      "name": "Rock_Ice"
    },
    {
      "x": -17,
      "y": 36,
      "z": 2,
      "name": "Rock_Ice"
    },
    {
      "x": -17,
      "y": 37,
      "z": 2,
      "name": "Rock_Ice"
    },
    {
      "x": -17,
      "y": 38,
      "z": 2,
      "name": "Rock_Ice"
    },
    {
      "x": -17,
      "y": 39,
      "z": 2,
      "name": "Rock_Ice"
    },
    {
      "x": -17,
      "y": 40,
      "z": 2,
      "name": "Rock_Ice"
    },
    {
      "x": -17,
      "y": 41,
      "z": 2,
      "name": "Rock_Ice"
    },
    {
      "x": -17,
      "y": 42,
      "z": 2,
      "name": "Soil_Snow"
    },
    {
      "x": -17,
      "y": 16,
      "z": 3,
      "name": "Rock_Ice_Permafrost"
    },
    {
      "x": -17,
      "y": 17,
      "z": 3,
      "name": "Rock_Ice_Permafrost"
    },
    {
      "x": -17,
      "y": 18,
      "z": 3,
      "name": "Rock_Ice_Permafrost"
    },
    {
      "x": -17,
      "y": 19,
      "z": 3,
      "name": "Rock_Crystal_Cyan_Block_WhiteLight"
    },
    {
      "x": -17,
      "y": 20,
      "z": 3,
      "name": "Rock_Ice_Permafrost"
    },
    {
      "x": -17,
      "y": 21,
      "z": 3,
      "name": "Rock_Ice_Permafrost"
    },
    {
      "x": -17,
      "y": 22,
      "z": 3,
      "name": "Rock_Ice_Permafrost"
    },
    {
      "x": -17,
      "y": 23,
      "z": 3,
      "name": "Rock_Ice"
    },
    {
      "x": -17,
      "y": 24,
      "z": 3,
      "name": "Rock_Ice_Permafrost"
    },
    {
      "x": -17,
      "y": 25,
      "z": 3,
      "name": "Rock_Ice"
    },
    {
      "x": -17,
      "y": 26,
      "z": 3,
      "name": "Rock_Ice"
    },
    {
      "x": -17,
      "y": 27,
      "z": 3,
      "name": "Rock_Ice"
    },
    {
      "x": -17,
      "y": 28,
      "z": 3,
      "name": "Rock_Ice"
    },
    {
      "x": -17,
      "y": 29,
      "z": 3,
      "name": "Rock_Ice"
    },
    {
      "x": -17,
      "y": 30,
      "z": 3,
      "name": "Rock_Ice"
    },
    {
      "x": -17,
      "y": 31,
      "z": 3,
      "name": "Rock_Ice"
    },
    {
      "x": -17,
      "y": 32,
      "z": 3,
      "name": "Rock_Ice"
    },
    {
      "x": -17,
      "y": 33,
      "z": 3,
      "name": "Rock_Ice"
    },
    {
      "x": -17,
      "y": 34,
      "z": 3,
      "name": "Rock_Ice"
    },
    {
      "x": -17,
      "y": 35,
      "z": 3,
      "name": "Rock_Ice"
    },
    {
      "x": -17,
      "y": 36,
      "z": 3,
      "name": "Rock_Ice"
    },
    {
      "x": -17,
      "y": 37,
      "z": 3,
      "name": "Rock_Ice"
    },
    {
      "x": -17,
      "y": 38,
      "z": 3,
      "name": "Rock_Ice"
    },
    {
      "x": -17,
      "y": 39,
      "z": 3,
      "name": "Rock_Ice"
    },
    {
      "x": -17,
      "y": 40,
      "z": 3,
      "name": "Rock_Ice"
    },
    {
      "x": -17,
      "y": 41,
      "z": 3,
      "name": "Rock_Ice"
    },
    {
      "x": -17,
      "y": 42,
      "z": 3,
      "name": "Soil_Snow"
    },
    {
      "x": -17,
      "y": 15,
      "z": 4,
      "name": "Rock_Ice_Icicles",
      "rotation": 8
    },
    {
      "x": -17,
      "y": 16,
      "z": 4,
      "name": "Rock_Ice_Permafrost"
    },
    {
      "x": -17,
      "y": 17,
      "z": 4,
      "name": "Rock_Crystal_Cyan_Block_WhiteLight"
    },
    {
      "x": -17,
      "y": 18,
      "z": 4,
      "name": "Rock_Ice_Permafrost"
    },
    {
      "x": -17,
      "y": 19,
      "z": 4,
      "name": "Rock_Ice_Permafrost"
    },
    {
      "x": -17,
      "y": 20,
      "z": 4,
      "name": "Rock_Crystal_Cyan_Block_WhiteLight"
    },
    {
      "x": -17,
      "y": 21,
      "z": 4,
      "name": "Rock_Ice_Permafrost"
    },
    {
      "x": -17,
      "y": 22,
      "z": 4,
      "name": "Rock_Ice_Permafrost"
    },
    {
      "x": -17,
      "y": 23,
      "z": 4,
      "name": "Rock_Ice_Permafrost"
    },
    {
      "x": -17,
      "y": 24,
      "z": 4,
      "name": "Rock_Crystal_Cyan_Block_WhiteLight"
    },
    {
      "x": -17,
      "y": 25,
      "z": 4,
      "name": "Rock_Ice"
    },
    {
      "x": -17,
      "y": 26,
      "z": 4,
      "name": "Rock_Ice"
    },
    {
      "x": -17,
      "y": 27,
      "z": 4,
      "name": "Rock_Ice"
    },
    {
      "x": -17,
      "y": 28,
      "z": 4,
      "name": "Rock_Ice"
    },
    {
      "x": -17,
      "y": 29,
      "z": 4,
      "name": "Rock_Ice"
    },
    {
      "x": -17,
      "y": 30,
      "z": 4,
      "name": "Rock_Ice"
    },
    {
      "x": -17,
      "y": 31,
      "z": 4,
      "name": "Rock_Ice"
    },
    {
      "x": -17,
      "y": 32,
      "z": 4,
      "name": "Rock_Ice"
    },
    {
      "x": -17,
      "y": 33,
      "z": 4,
      "name": "Rock_Ice"
    },
    {
      "x": -17,
      "y": 34,
      "z": 4,
      "name": "Rock_Ice"
    },
    {
      "x": -17,
      "y": 35,
      "z": 4,
      "name": "Rock_Ice"
    },
    {
      "x": -17,
      "y": 36,
      "z": 4,
      "name": "Rock_Ice"
    },
    {
      "x": -17,
      "y": 37,
      "z": 4,
      "name": "Rock_Ice"
    },
    {
      "x": -17,
      "y": 38,
      "z": 4,
      "name": "Rock_Ice"
    },
    {
      "x": -17,
      "y": 39,
      "z": 4,
      "name": "Rock_Ice"
    },
    {
      "x": -17,
      "y": 40,
      "z": 4,
      "name": "Rock_Ice"
    },
    {
      "x": -17,
      "y": 41,
      "z": 4,
      "name": "Rock_Ice"
    },
    {
      "x": -17,
      "y": 42,
      "z": 4,
      "name": "Soil_Snow"
    },
    {
      "x": -17,
      "y": 15,
      "z": 5,
      "name": "Rock_Ice"
    },
    {
      "x": -17,
      "y": 16,
      "z": 5,
      "name": "Rock_Ice"
    },
    {
      "x": -17,
      "y": 17,
      "z": 5,
      "name": "Rock_Ice"
    },
    {
      "x": -17,
      "y": 18,
      "z": 5,
      "name": "Rock_Ice_Permafrost"
    },
    {
      "x": -17,
      "y": 19,
      "z": 5,
      "name": "Rock_Ice_Permafrost"
    },
    {
      "x": -17,
      "y": 20,
      "z": 5,
      "name": "Rock_Ice_Permafrost"
    },
    {
      "x": -17,
      "y": 21,
      "z": 5,
      "name": "Rock_Crystal_Cyan_Block_WhiteLight"
    },
    {
      "x": -17,
      "y": 22,
      "z": 5,
      "name": "Rock_Ice_Permafrost"
    },
    {
      "x": -17,
      "y": 23,
      "z": 5,
      "name": "Rock_Ice_Permafrost"
    },
    {
      "x": -17,
      "y": 24,
      "z": 5,
      "name": "Rock_Crystal_Cyan_Block_WhiteLight"
    },
    {
      "x": -17,
      "y": 25,
      "z": 5,
      "name": "Rock_Ice_Permafrost"
    },
    {
      "x": -17,
      "y": 26,
      "z": 5,
      "name": "Rock_Ice"
    },
    {
      "x": -17,
      "y": 27,
      "z": 5,
      "name": "Rock_Ice"
    },
    {
      "x": -17,
      "y": 28,
      "z": 5,
      "name": "Rock_Ice"
    },
    {
      "x": -17,
      "y": 29,
      "z": 5,
      "name": "Rock_Ice"
    },
    {
      "x": -17,
      "y": 30,
      "z": 5,
      "name": "Rock_Ice"
    },
    {
      "x": -17,
      "y": 31,
      "z": 5,
      "name": "Rock_Ice"
    },
    {
      "x": -17,
      "y": 32,
      "z": 5,
      "name": "Rock_Ice"
    },
    {
      "x": -17,
      "y": 33,
      "z": 5,
      "name": "Rock_Ice"
    },
    {
      "x": -17,
      "y": 34,
      "z": 5,
      "name": "Rock_Ice"
    },
    {
      "x": -17,
      "y": 35,
      "z": 5,
      "name": "Rock_Ice"
    },
    {
      "x": -17,
      "y": 36,
      "z": 5,
      "name": "Rock_Ice"
    },
    {
      "x": -17,
      "y": 37,
      "z": 5,
      "name": "Rock_Ice"
    },
    {
      "x": -17,
      "y": 38,
      "z": 5,
      "name": "Rock_Ice"
    },
    {
      "x": -17,
      "y": 39,
      "z": 5,
      "name": "Rock_Ice"
    },
    {
      "x": -17,
      "y": 40,
      "z": 5,
      "name": "Rock_Ice"
    },
    {
      "x": -17,
      "y": 41,
      "z": 5,
      "name": "Rock_Ice"
    },
    {
      "x": -17,
      "y": 15,
      "z": 6,
      "name": "Rock_Ice"
    },
    {
      "x": -17,
      "y": 16,
      "z": 6,
      "name": "Rock_Ice"
    },
    {
      "x": -17,
      "y": 17,
      "z": 6,
      "name": "Rock_Ice"
    },
    {
      "x": -17,
      "y": 18,
      "z": 6,
      "name": "Rock_Ice"
    },
    {
      "x": -17,
      "y": 19,
      "z": 6,
      "name": "Rock_Ice"
    },
    {
      "x": -17,
      "y": 20,
      "z": 6,
      "name": "Rock_Ice"
    },
    {
      "x": -17,
      "y": 21,
      "z": 6,
      "name": "Rock_Ice"
    },
    {
      "x": -17,
      "y": 22,
      "z": 6,
      "name": "Rock_Ice_Permafrost"
    },
    {
      "x": -17,
      "y": 23,
      "z": 6,
      "name": "Rock_Ice_Permafrost"
    },
    {
      "x": -17,
      "y": 24,
      "z": 6,
      "name": "Rock_Ice_Permafrost"
    },
    {
      "x": -17,
      "y": 25,
      "z": 6,
      "name": "Rock_Ice_Permafrost"
    },
    {
      "x": -17,
      "y": 26,
      "z": 6,
      "name": "Rock_Ice_Permafrost"
    },
    {
      "x": -17,
      "y": 27,
      "z": 6,
      "name": "Rock_Ice"
    },
    {
      "x": -17,
      "y": 28,
      "z": 6,
      "name": "Rock_Ice"
    },
    {
      "x": -17,
      "y": 29,
      "z": 6,
      "name": "Rock_Ice"
    },
    {
      "x": -17,
      "y": 30,
      "z": 6,
      "name": "Rock_Ice"
    },
    {
      "x": -17,
      "y": 31,
      "z": 6,
      "name": "Rock_Ice"
    },
    {
      "x": -17,
      "y": 32,
      "z": 6,
      "name": "Rock_Ice"
    },
    {
      "x": -17,
      "y": 33,
      "z": 6,
      "name": "Rock_Ice"
    },
    {
      "x": -17,
      "y": 34,
      "z": 6,
      "name": "Rock_Ice"
    },
    {
      "x": -17,
      "y": 35,
      "z": 6,
      "name": "Rock_Ice"
    },
    {
      "x": -17,
      "y": 36,
      "z": 6,
      "name": "Rock_Ice"
    },
    {
      "x": -17,
      "y": 37,
      "z": 6,
      "name": "Rock_Ice"
    },
    {
      "x": -17,
      "y": 38,
      "z": 6,
      "name": "Rock_Ice"
    },
    {
      "x": -17,
      "y": 15,
      "z": 7,
      "name": "Rock_Ice"
    },
    {
      "x": -17,
      "y": 16,
      "z": 7,
      "name": "Rock_Ice"
    },
    {
      "x": -17,
      "y": 17,
      "z": 7,
      "name": "Rock_Ice"
    },
    {
      "x": -17,
      "y": 18,
      "z": 7,
      "name": "Rock_Ice"
    },
    {
      "x": -17,
      "y": 19,
      "z": 7,
      "name": "Rock_Ice"
    },
    {
      "x": -17,
      "y": 20,
      "z": 7,
      "name": "Rock_Ice"
    },
    {
      "x": -17,
      "y": 21,
      "z": 7,
      "name": "Rock_Ice"
    },
    {
      "x": -17,
      "y": 22,
      "z": 7,
      "name": "Rock_Ice"
    },
    {
      "x": -17,
      "y": 23,
      "z": 7,
      "name": "Rock_Ice"
    },
    {
      "x": -17,
      "y": 24,
      "z": 7,
      "name": "Rock_Ice"
    },
    {
      "x": -17,
      "y": 25,
      "z": 7,
      "name": "Rock_Ice"
    },
    {
      "x": -17,
      "y": 26,
      "z": 7,
      "name": "Rock_Ice"
    },
    {
      "x": -17,
      "y": 27,
      "z": 7,
      "name": "Rock_Ice"
    },
    {
      "x": -17,
      "y": 28,
      "z": 7,
      "name": "Rock_Ice"
    },
    {
      "x": -17,
      "y": 29,
      "z": 7,
      "name": "Rock_Ice_Permafrost"
    },
    {
      "x": -17,
      "y": 30,
      "z": 7,
      "name": "Rock_Ice"
    },
    {
      "x": -17,
      "y": 31,
      "z": 7,
      "name": "Rock_Ice"
    },
    {
      "x": -17,
      "y": 32,
      "z": 7,
      "name": "Rock_Ice"
    },
    {
      "x": -17,
      "y": 33,
      "z": 7,
      "name": "Rock_Ice"
    },
    {
      "x": -17,
      "y": 34,
      "z": 7,
      "name": "Rock_Ice"
    },
    {
      "x": -17,
      "y": 35,
      "z": 7,
      "name": "Rock_Ice"
    },
    {
      "x": -17,
      "y": 36,
      "z": 7,
      "name": "Rock_Ice"
    },
    {
      "x": -17,
      "y": 17,
      "z": 8,
      "name": "Rock_Ice"
    },
    {
      "x": -17,
      "y": 18,
      "z": 8,
      "name": "Rock_Ice"
    },
    {
      "x": -17,
      "y": 19,
      "z": 8,
      "name": "Rock_Ice"
    },
    {
      "x": -17,
      "y": 20,
      "z": 8,
      "name": "Rock_Ice"
    },
    {
      "x": -17,
      "y": 21,
      "z": 8,
      "name": "Rock_Ice"
    },
    {
      "x": -17,
      "y": 22,
      "z": 8,
      "name": "Rock_Ice"
    },
    {
      "x": -17,
      "y": 23,
      "z": 8,
      "name": "Rock_Ice"
    },
    {
      "x": -17,
      "y": 24,
      "z": 8,
      "name": "Rock_Ice"
    },
    {
      "x": -17,
      "y": 25,
      "z": 8,
      "name": "Rock_Ice"
    },
    {
      "x": -17,
      "y": 26,
      "z": 8,
      "name": "Rock_Ice"
    },
    {
      "x": -17,
      "y": 27,
      "z": 8,
      "name": "Rock_Ice"
    },
    {
      "x": -17,
      "y": 28,
      "z": 8,
      "name": "Rock_Ice"
    },
    {
      "x": -17,
      "y": 29,
      "z": 8,
      "name": "Rock_Ice"
    },
    {
      "x": -17,
      "y": 30,
      "z": 8,
      "name": "Rock_Ice"
    },
    {
      "x": -17,
      "y": 31,
      "z": 8,
      "name": "Rock_Ice"
    },
    {
      "x": -17,
      "y": 32,
      "z": 8,
      "name": "Rock_Ice"
    },
    {
      "x": -17,
      "y": 33,
      "z": 8,
      "name": "Rock_Ice"
    },
    {
      "x": -17,
      "y": 34,
      "z": 8,
      "name": "Rock_Ice"
    },
    {
      "x": -17,
      "y": 35,
      "z": 8,
      "name": "Rock_Ice"
    },
    {
      "x": -17,
      "y": 36,
      "z": 8,
      "name": "Soil_Snow"
    },
    {
      "x": -17,
      "y": 18,
      "z": 9,
      "name": "Rock_Ice"
    },
    {
      "x": -17,
      "y": 19,
      "z": 9,
      "name": "Rock_Ice"
    },
    {
      "x": -17,
      "y": 20,
      "z": 9,
      "name": "Rock_Ice"
    },
    {
      "x": -17,
      "y": 21,
      "z": 9,
      "name": "Rock_Ice"
    },
    {
      "x": -17,
      "y": 22,
      "z": 9,
      "name": "Rock_Ice"
    },
    {
      "x": -17,
      "y": 23,
      "z": 9,
      "name": "Rock_Ice"
    },
    {
      "x": -17,
      "y": 24,
      "z": 9,
      "name": "Rock_Ice"
    },
    {
      "x": -17,
      "y": 25,
      "z": 9,
      "name": "Rock_Ice"
    },
    {
      "x": -17,
      "y": 26,
      "z": 9,
      "name": "Rock_Ice"
    },
    {
      "x": -17,
      "y": 27,
      "z": 9,
      "name": "Rock_Ice"
    },
    {
      "x": -17,
      "y": 28,
      "z": 9,
      "name": "Rock_Ice"
    },
    {
      "x": -17,
      "y": 29,
      "z": 9,
      "name": "Rock_Ice"
    },
    {
      "x": -17,
      "y": 30,
      "z": 9,
      "name": "Rock_Ice"
    },
    {
      "x": -17,
      "y": 31,
      "z": 9,
      "name": "Rock_Ice"
    },
    {
      "x": -17,
      "y": 32,
      "z": 9,
      "name": "Rock_Ice"
    },
    {
      "x": -17,
      "y": 33,
      "z": 9,
      "name": "Rock_Ice_Permafrost"
    },
    {
      "x": -17,
      "y": 34,
      "z": 9,
      "name": "Rock_Ice_Permafrost"
    },
    {
      "x": -17,
      "y": 35,
      "z": 9,
      "name": "Rock_Ice_Permafrost"
    },
    {
      "x": -17,
      "y": 36,
      "z": 9,
      "name": "Rock_Ice"
    },
    {
      "x": -17,
      "y": 37,
      "z": 9,
      "name": "Soil_Snow"
    },
    {
      "x": -17,
      "y": 19,
      "z": 10,
      "name": "Rock_Ice"
    },
    {
      "x": -17,
      "y": 20,
      "z": 10,
      "name": "Rock_Ice"
    },
    {
      "x": -17,
      "y": 21,
      "z": 10,
      "name": "Rock_Ice"
    },
    {
      "x": -17,
      "y": 22,
      "z": 10,
      "name": "Rock_Ice"
    },
    {
      "x": -17,
      "y": 23,
      "z": 10,
      "name": "Rock_Ice"
    },
    {
      "x": -17,
      "y": 24,
      "z": 10,
      "name": "Rock_Ice"
    },
    {
      "x": -17,
      "y": 25,
      "z": 10,
      "name": "Rock_Ice"
    },
    {
      "x": -17,
      "y": 26,
      "z": 10,
      "name": "Rock_Ice"
    },
    {
      "x": -17,
      "y": 27,
      "z": 10,
      "name": "Rock_Ice"
    },
    {
      "x": -17,
      "y": 28,
      "z": 10,
      "name": "Rock_Ice"
    },
    {
      "x": -17,
      "y": 29,
      "z": 10,
      "name": "Rock_Ice"
    },
    {
      "x": -17,
      "y": 30,
      "z": 10,
      "name": "Rock_Ice"
    },
    {
      "x": -17,
      "y": 31,
      "z": 10,
      "name": "Rock_Ice"
    },
    {
      "x": -17,
      "y": 32,
      "z": 10,
      "name": "Rock_Ice"
    },
    {
      "x": -17,
      "y": 33,
      "z": 10,
      "name": "Rock_Ice"
    },
    {
      "x": -17,
      "y": 34,
      "z": 10,
      "name": "Rock_Ice"
    },
    {
      "x": -17,
      "y": 35,
      "z": 10,
      "name": "Rock_Ice_Permafrost"
    },
    {
      "x": -17,
      "y": 36,
      "z": 10,
      "name": "Rock_Ice_Permafrost"
    },
    {
      "x": -17,
      "y": 23,
      "z": 11,
      "name": "Rock_Ice"
    },
    {
      "x": -17,
      "y": 24,
      "z": 11,
      "name": "Rock_Ice_Permafrost"
    },
    {
      "x": -17,
      "y": 25,
      "z": 11,
      "name": "Rock_Ice"
    },
    {
      "x": -17,
      "y": 26,
      "z": 11,
      "name": "Rock_Ice"
    },
    {
      "x": -17,
      "y": 27,
      "z": 11,
      "name": "Rock_Ice_Permafrost"
    },
    {
      "x": -17,
      "y": 28,
      "z": 11,
      "name": "Rock_Ice"
    },
    {
      "x": -17,
      "y": 29,
      "z": 11,
      "name": "Soil_Snow"
    },
    {
      "x": -17,
      "y": 27,
      "z": 12,
      "name": "Soil_Snow"
    },
    {
      "x": -16,
      "y": 13,
      "z": -6,
      "name": "Rock_Ice"
    },
    {
      "x": -16,
      "y": 14,
      "z": -6,
      "name": "Rock_Ice"
    },
    {
      "x": -16,
      "y": 15,
      "z": -6,
      "name": "Rock_Ice"
    },
    {
      "x": -16,
      "y": 16,
      "z": -6,
      "name": "Rock_Ice"
    },
    {
      "x": -16,
      "y": 17,
      "z": -6,
      "name": "Rock_Ice"
    },
    {
      "x": -16,
      "y": 18,
      "z": -6,
      "name": "Rock_Ice"
    },
    {
      "x": -16,
      "y": 19,
      "z": -6,
      "name": "Rock_Ice"
    },
    {
      "x": -16,
      "y": 20,
      "z": -6,
      "name": "Rock_Ice"
    },
    {
      "x": -16,
      "y": 21,
      "z": -6,
      "name": "Rock_Ice"
    },
    {
      "x": -16,
      "y": 38,
      "z": -6,
      "name": "Rock_Ice"
    },
    {
      "x": -16,
      "y": 39,
      "z": -6,
      "name": "Rock_Ice"
    },
    {
      "x": -16,
      "y": 40,
      "z": -6,
      "name": "Rock_Ice"
    },
    {
      "x": -16,
      "y": 41,
      "z": -6,
      "name": "Rock_Ice"
    },
    {
      "x": -16,
      "y": 42,
      "z": -6,
      "name": "Rock_Ice"
    },
    {
      "x": -16,
      "y": 43,
      "z": -6,
      "name": "Soil_Snow"
    },
    {
      "x": -16,
      "y": 14,
      "z": -5,
      "name": "Rock_Ice"
    },
    {
      "x": -16,
      "y": 15,
      "z": -5,
      "name": "Rock_Ice"
    },
    {
      "x": -16,
      "y": 16,
      "z": -5,
      "name": "Rock_Ice"
    },
    {
      "x": -16,
      "y": 17,
      "z": -5,
      "name": "Rock_Ice"
    },
    {
      "x": -16,
      "y": 18,
      "z": -5,
      "name": "Rock_Ice"
    },
    {
      "x": -16,
      "y": 19,
      "z": -5,
      "name": "Rock_Ice"
    },
    {
      "x": -16,
      "y": 20,
      "z": -5,
      "name": "Rock_Ice"
    },
    {
      "x": -16,
      "y": 21,
      "z": -5,
      "name": "Rock_Ice"
    },
    {
      "x": -16,
      "y": 22,
      "z": -5,
      "name": "Rock_Ice"
    },
    {
      "x": -16,
      "y": 23,
      "z": -5,
      "name": "Rock_Ice"
    },
    {
      "x": -16,
      "y": 24,
      "z": -5,
      "name": "Rock_Ice"
    },
    {
      "x": -16,
      "y": 25,
      "z": -5,
      "name": "Rock_Ice"
    },
    {
      "x": -16,
      "y": 26,
      "z": -5,
      "name": "Rock_Ice"
    },
    {
      "x": -16,
      "y": 27,
      "z": -5,
      "name": "Rock_Ice"
    },
    {
      "x": -16,
      "y": 28,
      "z": -5,
      "name": "Rock_Ice"
    },
    {
      "x": -16,
      "y": 29,
      "z": -5,
      "name": "Rock_Ice"
    },
    {
      "x": -16,
      "y": 30,
      "z": -5,
      "name": "Rock_Ice"
    },
    {
      "x": -16,
      "y": 31,
      "z": -5,
      "name": "Rock_Ice"
    },
    {
      "x": -16,
      "y": 32,
      "z": -5,
      "name": "Rock_Ice"
    },
    {
      "x": -16,
      "y": 33,
      "z": -5,
      "name": "Rock_Ice"
    },
    {
      "x": -16,
      "y": 34,
      "z": -5,
      "name": "Rock_Ice"
    },
    {
      "x": -16,
      "y": 35,
      "z": -5,
      "name": "Rock_Ice"
    },
    {
      "x": -16,
      "y": 36,
      "z": -5,
      "name": "Rock_Ice"
    },
    {
      "x": -16,
      "y": 37,
      "z": -5,
      "name": "Rock_Ice"
    },
    {
      "x": -16,
      "y": 38,
      "z": -5,
      "name": "Rock_Ice"
    },
    {
      "x": -16,
      "y": 39,
      "z": -5,
      "name": "Rock_Ice"
    },
    {
      "x": -16,
      "y": 40,
      "z": -5,
      "name": "Rock_Ice"
    },
    {
      "x": -16,
      "y": 41,
      "z": -5,
      "name": "Rock_Ice"
    },
    {
      "x": -16,
      "y": 42,
      "z": -5,
      "name": "Rock_Ice"
    },
    {
      "x": -16,
      "y": 43,
      "z": -5,
      "name": "Rock_Ice"
    },
    {
      "x": -16,
      "y": 44,
      "z": -5,
      "name": "Rock_Ice"
    },
    {
      "x": -16,
      "y": 45,
      "z": -5,
      "name": "Rock_Ice"
    },
    {
      "x": -16,
      "y": 46,
      "z": -5,
      "name": "Rock_Ice"
    },
    {
      "x": -16,
      "y": 47,
      "z": -5,
      "name": "Rock_Ice"
    },
    {
      "x": -16,
      "y": 48,
      "z": -5,
      "name": "Soil_Snow"
    },
    {
      "x": -16,
      "y": 14,
      "z": -4,
      "name": "Rock_Ice"
    },
    {
      "x": -16,
      "y": 15,
      "z": -4,
      "name": "Rock_Ice"
    },
    {
      "x": -16,
      "y": 16,
      "z": -4,
      "name": "Rock_Ice"
    },
    {
      "x": -16,
      "y": 17,
      "z": -4,
      "name": "Rock_Ice"
    },
    {
      "x": -16,
      "y": 18,
      "z": -4,
      "name": "Rock_Ice"
    },
    {
      "x": -16,
      "y": 19,
      "z": -4,
      "name": "Rock_Ice"
    },
    {
      "x": -16,
      "y": 20,
      "z": -4,
      "name": "Rock_Ice"
    },
    {
      "x": -16,
      "y": 21,
      "z": -4,
      "name": "Rock_Ice"
    },
    {
      "x": -16,
      "y": 22,
      "z": -4,
      "name": "Rock_Ice"
    },
    {
      "x": -16,
      "y": 23,
      "z": -4,
      "name": "Rock_Ice"
    },
    {
      "x": -16,
      "y": 24,
      "z": -4,
      "name": "Rock_Ice"
    },
    {
      "x": -16,
      "y": 25,
      "z": -4,
      "name": "Rock_Ice"
    },
    {
      "x": -16,
      "y": 26,
      "z": -4,
      "name": "Rock_Ice"
    },
    {
      "x": -16,
      "y": 27,
      "z": -4,
      "name": "Rock_Ice"
    },
    {
      "x": -16,
      "y": 28,
      "z": -4,
      "name": "Rock_Ice"
    },
    {
      "x": -16,
      "y": 29,
      "z": -4,
      "name": "Rock_Ice"
    },
    {
      "x": -16,
      "y": 30,
      "z": -4,
      "name": "Rock_Ice"
    },
    {
      "x": -16,
      "y": 31,
      "z": -4,
      "name": "Rock_Ice"
    },
    {
      "x": -16,
      "y": 32,
      "z": -4,
      "name": "Rock_Ice"
    },
    {
      "x": -16,
      "y": 33,
      "z": -4,
      "name": "Rock_Ice"
    },
    {
      "x": -16,
      "y": 34,
      "z": -4,
      "name": "Rock_Ice"
    },
    {
      "x": -16,
      "y": 35,
      "z": -4,
      "name": "Rock_Ice"
    },
    {
      "x": -16,
      "y": 36,
      "z": -4,
      "name": "Rock_Ice"
    },
    {
      "x": -16,
      "y": 37,
      "z": -4,
      "name": "Rock_Ice"
    },
    {
      "x": -16,
      "y": 38,
      "z": -4,
      "name": "Rock_Ice"
    },
    {
      "x": -16,
      "y": 39,
      "z": -4,
      "name": "Rock_Ice"
    },
    {
      "x": -16,
      "y": 40,
      "z": -4,
      "name": "Rock_Ice"
    },
    {
      "x": -16,
      "y": 41,
      "z": -4,
      "name": "Rock_Ice"
    },
    {
      "x": -16,
      "y": 42,
      "z": -4,
      "name": "Rock_Ice"
    },
    {
      "x": -16,
      "y": 43,
      "z": -4,
      "name": "Rock_Ice"
    },
    {
      "x": -16,
      "y": 44,
      "z": -4,
      "name": "Rock_Ice"
    },
    {
      "x": -16,
      "y": 45,
      "z": -4,
      "name": "Rock_Ice"
    },
    {
      "x": -16,
      "y": 46,
      "z": -4,
      "name": "Rock_Ice"
    },
    {
      "x": -16,
      "y": 47,
      "z": -4,
      "name": "Rock_Ice"
    },
    {
      "x": -16,
      "y": 48,
      "z": -4,
      "name": "Rock_Ice"
    },
    {
      "x": -16,
      "y": 49,
      "z": -4,
      "name": "Rock_Ice"
    },
    {
      "x": -16,
      "y": 50,
      "z": -4,
      "name": "Rock_Ice"
    },
    {
      "x": -16,
      "y": 51,
      "z": -4,
      "name": "Soil_Snow"
    },
    {
      "x": -16,
      "y": 15,
      "z": -3,
      "name": "Rock_Ice"
    },
    {
      "x": -16,
      "y": 16,
      "z": -3,
      "name": "Rock_Ice"
    },
    {
      "x": -16,
      "y": 17,
      "z": -3,
      "name": "Rock_Ice"
    },
    {
      "x": -16,
      "y": 18,
      "z": -3,
      "name": "Rock_Ice"
    },
    {
      "x": -16,
      "y": 19,
      "z": -3,
      "name": "Rock_Ice"
    },
    {
      "x": -16,
      "y": 20,
      "z": -3,
      "name": "Rock_Ice"
    },
    {
      "x": -16,
      "y": 21,
      "z": -3,
      "name": "Rock_Ice"
    },
    {
      "x": -16,
      "y": 22,
      "z": -3,
      "name": "Rock_Ice"
    },
    {
      "x": -16,
      "y": 23,
      "z": -3,
      "name": "Rock_Ice"
    },
    {
      "x": -16,
      "y": 24,
      "z": -3,
      "name": "Rock_Ice"
    },
    {
      "x": -16,
      "y": 25,
      "z": -3,
      "name": "Rock_Ice"
    },
    {
      "x": -16,
      "y": 26,
      "z": -3,
      "name": "Rock_Ice"
    },
    {
      "x": -16,
      "y": 27,
      "z": -3,
      "name": "Rock_Ice"
    },
    {
      "x": -16,
      "y": 28,
      "z": -3,
      "name": "Rock_Ice"
    },
    {
      "x": -16,
      "y": 29,
      "z": -3,
      "name": "Rock_Ice"
    },
    {
      "x": -16,
      "y": 30,
      "z": -3,
      "name": "Rock_Ice"
    },
    {
      "x": -16,
      "y": 31,
      "z": -3,
      "name": "Rock_Ice"
    },
    {
      "x": -16,
      "y": 32,
      "z": -3,
      "name": "Rock_Ice"
    },
    {
      "x": -16,
      "y": 33,
      "z": -3,
      "name": "Rock_Ice"
    },
    {
      "x": -16,
      "y": 34,
      "z": -3,
      "name": "Rock_Ice"
    },
    {
      "x": -16,
      "y": 35,
      "z": -3,
      "name": "Rock_Ice"
    },
    {
      "x": -16,
      "y": 36,
      "z": -3,
      "name": "Rock_Ice"
    },
    {
      "x": -16,
      "y": 37,
      "z": -3,
      "name": "Rock_Ice"
    },
    {
      "x": -16,
      "y": 38,
      "z": -3,
      "name": "Rock_Ice"
    },
    {
      "x": -16,
      "y": 39,
      "z": -3,
      "name": "Rock_Ice"
    },
    {
      "x": -16,
      "y": 40,
      "z": -3,
      "name": "Rock_Ice"
    },
    {
      "x": -16,
      "y": 41,
      "z": -3,
      "name": "Rock_Ice"
    },
    {
      "x": -16,
      "y": 42,
      "z": -3,
      "name": "Rock_Ice"
    },
    {
      "x": -16,
      "y": 43,
      "z": -3,
      "name": "Rock_Ice"
    },
    {
      "x": -16,
      "y": 44,
      "z": -3,
      "name": "Rock_Ice"
    },
    {
      "x": -16,
      "y": 45,
      "z": -3,
      "name": "Rock_Ice"
    },
    {
      "x": -16,
      "y": 46,
      "z": -3,
      "name": "Rock_Ice"
    },
    {
      "x": -16,
      "y": 47,
      "z": -3,
      "name": "Rock_Ice"
    },
    {
      "x": -16,
      "y": 48,
      "z": -3,
      "name": "Rock_Ice"
    },
    {
      "x": -16,
      "y": 15,
      "z": -2,
      "name": "Rock_Ice"
    },
    {
      "x": -16,
      "y": 16,
      "z": -2,
      "name": "Rock_Ice"
    },
    {
      "x": -16,
      "y": 17,
      "z": -2,
      "name": "Rock_Ice"
    },
    {
      "x": -16,
      "y": 18,
      "z": -2,
      "name": "Rock_Ice"
    },
    {
      "x": -16,
      "y": 19,
      "z": -2,
      "name": "Rock_Ice"
    },
    {
      "x": -16,
      "y": 20,
      "z": -2,
      "name": "Rock_Ice"
    },
    {
      "x": -16,
      "y": 21,
      "z": -2,
      "name": "Rock_Ice"
    },
    {
      "x": -16,
      "y": 22,
      "z": -2,
      "name": "Rock_Ice"
    },
    {
      "x": -16,
      "y": 23,
      "z": -2,
      "name": "Rock_Ice"
    },
    {
      "x": -16,
      "y": 24,
      "z": -2,
      "name": "Rock_Ice"
    },
    {
      "x": -16,
      "y": 25,
      "z": -2,
      "name": "Rock_Ice"
    },
    {
      "x": -16,
      "y": 26,
      "z": -2,
      "name": "Rock_Ice"
    },
    {
      "x": -16,
      "y": 27,
      "z": -2,
      "name": "Rock_Ice"
    },
    {
      "x": -16,
      "y": 28,
      "z": -2,
      "name": "Rock_Ice"
    },
    {
      "x": -16,
      "y": 29,
      "z": -2,
      "name": "Rock_Ice"
    },
    {
      "x": -16,
      "y": 30,
      "z": -2,
      "name": "Rock_Ice"
    },
    {
      "x": -16,
      "y": 31,
      "z": -2,
      "name": "Rock_Ice"
    },
    {
      "x": -16,
      "y": 32,
      "z": -2,
      "name": "Rock_Ice"
    },
    {
      "x": -16,
      "y": 33,
      "z": -2,
      "name": "Rock_Ice"
    },
    {
      "x": -16,
      "y": 34,
      "z": -2,
      "name": "Rock_Ice"
    },
    {
      "x": -16,
      "y": 35,
      "z": -2,
      "name": "Rock_Ice"
    },
    {
      "x": -16,
      "y": 36,
      "z": -2,
      "name": "Rock_Ice"
    },
    {
      "x": -16,
      "y": 37,
      "z": -2,
      "name": "Rock_Ice"
    },
    {
      "x": -16,
      "y": 38,
      "z": -2,
      "name": "Rock_Ice"
    },
    {
      "x": -16,
      "y": 39,
      "z": -2,
      "name": "Rock_Ice"
    },
    {
      "x": -16,
      "y": 40,
      "z": -2,
      "name": "Rock_Ice"
    },
    {
      "x": -16,
      "y": 41,
      "z": -2,
      "name": "Rock_Ice"
    },
    {
      "x": -16,
      "y": 42,
      "z": -2,
      "name": "Rock_Ice"
    },
    {
      "x": -16,
      "y": 43,
      "z": -2,
      "name": "Rock_Ice"
    },
    {
      "x": -16,
      "y": 44,
      "z": -2,
      "name": "Rock_Ice"
    },
    {
      "x": -16,
      "y": 45,
      "z": -2,
      "name": "Rock_Ice"
    },
    {
      "x": -16,
      "y": 46,
      "z": -2,
      "name": "Rock_Ice"
    },
    {
      "x": -16,
      "y": 17,
      "z": -1,
      "name": "Rock_Ice"
    },
    {
      "x": -16,
      "y": 18,
      "z": -1,
      "name": "Rock_Ice"
    },
    {
      "x": -16,
      "y": 19,
      "z": -1,
      "name": "Rock_Ice"
    },
    {
      "x": -16,
      "y": 20,
      "z": -1,
      "name": "Rock_Ice"
    },
    {
      "x": -16,
      "y": 21,
      "z": -1,
      "name": "Rock_Ice"
    },
    {
      "x": -16,
      "y": 22,
      "z": -1,
      "name": "Rock_Ice"
    },
    {
      "x": -16,
      "y": 23,
      "z": -1,
      "name": "Rock_Ice"
    },
    {
      "x": -16,
      "y": 24,
      "z": -1,
      "name": "Rock_Ice"
    },
    {
      "x": -16,
      "y": 25,
      "z": -1,
      "name": "Rock_Ice"
    },
    {
      "x": -16,
      "y": 26,
      "z": -1,
      "name": "Rock_Ice"
    },
    {
      "x": -16,
      "y": 27,
      "z": -1,
      "name": "Rock_Ice"
    },
    {
      "x": -16,
      "y": 28,
      "z": -1,
      "name": "Rock_Ice"
    },
    {
      "x": -16,
      "y": 29,
      "z": -1,
      "name": "Rock_Ice"
    },
    {
      "x": -16,
      "y": 30,
      "z": -1,
      "name": "Rock_Ice"
    },
    {
      "x": -16,
      "y": 31,
      "z": -1,
      "name": "Rock_Ice"
    },
    {
      "x": -16,
      "y": 32,
      "z": -1,
      "name": "Rock_Ice"
    },
    {
      "x": -16,
      "y": 33,
      "z": -1,
      "name": "Rock_Ice"
    },
    {
      "x": -16,
      "y": 34,
      "z": -1,
      "name": "Rock_Ice"
    },
    {
      "x": -16,
      "y": 35,
      "z": -1,
      "name": "Rock_Ice"
    },
    {
      "x": -16,
      "y": 36,
      "z": -1,
      "name": "Rock_Ice"
    },
    {
      "x": -16,
      "y": 37,
      "z": -1,
      "name": "Rock_Ice"
    },
    {
      "x": -16,
      "y": 38,
      "z": -1,
      "name": "Rock_Ice"
    },
    {
      "x": -16,
      "y": 39,
      "z": -1,
      "name": "Rock_Ice_Permafrost"
    },
    {
      "x": -16,
      "y": 40,
      "z": -1,
      "name": "Rock_Ice"
    },
    {
      "x": -16,
      "y": 41,
      "z": -1,
      "name": "Rock_Ice"
    },
    {
      "x": -16,
      "y": 42,
      "z": -1,
      "name": "Rock_Ice"
    },
    {
      "x": -16,
      "y": 43,
      "z": -1,
      "name": "Rock_Ice"
    },
    {
      "x": -16,
      "y": 44,
      "z": -1,
      "name": "Rock_Ice"
    },
    {
      "x": -16,
      "y": 45,
      "z": -1,
      "name": "Soil_Snow"
    },
    {
      "x": -16,
      "y": 16,
      "z": 0,
      "name": "Rock_Ice"
    },
    {
      "x": -16,
      "y": 17,
      "z": 0,
      "name": "Rock_Ice"
    },
    {
      "x": -16,
      "y": 18,
      "z": 0,
      "name": "Rock_Ice"
    },
    {
      "x": -16,
      "y": 19,
      "z": 0,
      "name": "Rock_Ice"
    },
    {
      "x": -16,
      "y": 20,
      "z": 0,
      "name": "Rock_Ice"
    },
    {
      "x": -16,
      "y": 21,
      "z": 0,
      "name": "Rock_Ice"
    },
    {
      "x": -16,
      "y": 22,
      "z": 0,
      "name": "Rock_Ice"
    },
    {
      "x": -16,
      "y": 23,
      "z": 0,
      "name": "Rock_Ice"
    },
    {
      "x": -16,
      "y": 24,
      "z": 0,
      "name": "Rock_Ice"
    },
    {
      "x": -16,
      "y": 25,
      "z": 0,
      "name": "Rock_Ice"
    },
    {
      "x": -16,
      "y": 26,
      "z": 0,
      "name": "Rock_Ice_Permafrost"
    },
    {
      "x": -16,
      "y": 27,
      "z": 0,
      "name": "Rock_Ice_Permafrost"
    },
    {
      "x": -16,
      "y": 28,
      "z": 0,
      "name": "Rock_Ice_Permafrost"
    },
    {
      "x": -16,
      "y": 29,
      "z": 0,
      "name": "Rock_Ice_Permafrost"
    },
    {
      "x": -16,
      "y": 30,
      "z": 0,
      "name": "Rock_Ice_Permafrost"
    },
    {
      "x": -16,
      "y": 31,
      "z": 0,
      "name": "Rock_Ice_Permafrost"
    },
    {
      "x": -16,
      "y": 32,
      "z": 0,
      "name": "Rock_Ice_Permafrost"
    },
    {
      "x": -16,
      "y": 33,
      "z": 0,
      "name": "Rock_Ice_Permafrost"
    },
    {
      "x": -16,
      "y": 34,
      "z": 0,
      "name": "Rock_Ice_Permafrost"
    },
    {
      "x": -16,
      "y": 35,
      "z": 0,
      "name": "Rock_Ice_Permafrost"
    },
    {
      "x": -16,
      "y": 36,
      "z": 0,
      "name": "Rock_Ice"
    },
    {
      "x": -16,
      "y": 37,
      "z": 0,
      "name": "Rock_Ice"
    },
    {
      "x": -16,
      "y": 38,
      "z": 0,
      "name": "Rock_Ice"
    },
    {
      "x": -16,
      "y": 39,
      "z": 0,
      "name": "Rock_Ice"
    },
    {
      "x": -16,
      "y": 40,
      "z": 0,
      "name": "Rock_Ice"
    },
    {
      "x": -16,
      "y": 41,
      "z": 0,
      "name": "Rock_Ice"
    },
    {
      "x": -16,
      "y": 42,
      "z": 0,
      "name": "Rock_Ice"
    },
    {
      "x": -16,
      "y": 43,
      "z": 0,
      "name": "Rock_Ice"
    },
    {
      "x": -16,
      "y": 44,
      "z": 0,
      "name": "Rock_Ice"
    },
    {
      "x": -16,
      "y": 45,
      "z": 0,
      "name": "Soil_Snow"
    },
    {
      "x": -16,
      "y": 16,
      "z": 1,
      "name": "Rock_Ice"
    },
    {
      "x": -16,
      "y": 17,
      "z": 1,
      "name": "Rock_Ice"
    },
    {
      "x": -16,
      "y": 18,
      "z": 1,
      "name": "Rock_Ice"
    },
    {
      "x": -16,
      "y": 19,
      "z": 1,
      "name": "Rock_Ice"
    },
    {
      "x": -16,
      "y": 20,
      "z": 1,
      "name": "Rock_Ice"
    },
    {
      "x": -16,
      "y": 21,
      "z": 1,
      "name": "Rock_Ice"
    },
    {
      "x": -16,
      "y": 22,
      "z": 1,
      "name": "Rock_Ice_Permafrost"
    },
    {
      "x": -16,
      "y": 23,
      "z": 1,
      "name": "Rock_Ice"
    },
    {
      "x": -16,
      "y": 24,
      "z": 1,
      "name": "Rock_Ice_Permafrost"
    },
    {
      "x": -16,
      "y": 25,
      "z": 1,
      "name": "Rock_Crystal_Cyan_Block_WhiteLight"
    },
    {
      "x": -16,
      "y": 26,
      "z": 1,
      "name": "Rock_Ice_Permafrost"
    },
    {
      "x": -16,
      "y": 27,
      "z": 1,
      "name": "Rock_Crystal_Cyan_Block_WhiteLight"
    },
    {
      "x": -16,
      "y": 28,
      "z": 1,
      "name": "Rock_Crystal_Cyan_Block_WhiteLight"
    },
    {
      "x": -16,
      "y": 29,
      "z": 1,
      "name": "Rock_Ice_Permafrost"
    },
    {
      "x": -16,
      "y": 30,
      "z": 1,
      "name": "Rock_Ice_Permafrost"
    },
    {
      "x": -16,
      "y": 31,
      "z": 1,
      "name": "Rock_Ice_Permafrost"
    },
    {
      "x": -16,
      "y": 32,
      "z": 1,
      "name": "Rock_Ice_Permafrost"
    },
    {
      "x": -16,
      "y": 33,
      "z": 1,
      "name": "Rock_Ice"
    },
    {
      "x": -16,
      "y": 34,
      "z": 1,
      "name": "Rock_Ice"
    },
    {
      "x": -16,
      "y": 35,
      "z": 1,
      "name": "Rock_Ice"
    },
    {
      "x": -16,
      "y": 36,
      "z": 1,
      "name": "Rock_Ice"
    },
    {
      "x": -16,
      "y": 37,
      "z": 1,
      "name": "Rock_Ice"
    },
    {
      "x": -16,
      "y": 38,
      "z": 1,
      "name": "Rock_Ice"
    },
    {
      "x": -16,
      "y": 39,
      "z": 1,
      "name": "Rock_Ice"
    },
    {
      "x": -16,
      "y": 40,
      "z": 1,
      "name": "Rock_Ice"
    },
    {
      "x": -16,
      "y": 41,
      "z": 1,
      "name": "Rock_Ice"
    },
    {
      "x": -16,
      "y": 42,
      "z": 1,
      "name": "Rock_Ice"
    },
    {
      "x": -16,
      "y": 43,
      "z": 1,
      "name": "Rock_Ice"
    },
    {
      "x": -16,
      "y": 44,
      "z": 1,
      "name": "Rock_Ice"
    },
    {
      "x": -16,
      "y": 45,
      "z": 1,
      "name": "Soil_Snow"
    },
    {
      "x": -16,
      "y": 16,
      "z": 2,
      "name": "Rock_Ice_Permafrost"
    },
    {
      "x": -16,
      "y": 17,
      "z": 2,
      "name": "Rock_Ice_Permafrost"
    },
    {
      "x": -16,
      "y": 18,
      "z": 2,
      "name": "Rock_Ice_Permafrost"
    },
    {
      "x": -16,
      "y": 19,
      "z": 2,
      "name": "Rock_Ice_Permafrost"
    },
    {
      "x": -16,
      "y": 20,
      "z": 2,
      "name": "Rock_Ice_Permafrost"
    },
    {
      "x": -16,
      "y": 21,
      "z": 2,
      "name": "Rock_Ice_Permafrost"
    },
    {
      "x": -16,
      "y": 22,
      "z": 2,
      "name": "Rock_Crystal_Cyan_Block_WhiteLight"
    },
    {
      "x": -16,
      "y": 23,
      "z": 2,
      "name": "Rock_Crystal_Cyan_Block_WhiteLight"
    },
    {
      "x": -16,
      "y": 24,
      "z": 2,
      "name": "Rock_Ice_Permafrost"
    },
    {
      "x": -16,
      "y": 25,
      "z": 2,
      "name": "Rock_Ice_Permafrost"
    },
    {
      "x": -16,
      "y": 26,
      "z": 2,
      "name": "Rock_Ice_Permafrost"
    },
    {
      "x": -16,
      "y": 27,
      "z": 2,
      "name": "Rock_Ice_Permafrost"
    },
    {
      "x": -16,
      "y": 28,
      "z": 2,
      "name": "Rock_Ice"
    },
    {
      "x": -16,
      "y": 29,
      "z": 2,
      "name": "Rock_Ice_Permafrost"
    },
    {
      "x": -16,
      "y": 30,
      "z": 2,
      "name": "Rock_Ice"
    },
    {
      "x": -16,
      "y": 31,
      "z": 2,
      "name": "Rock_Ice"
    },
    {
      "x": -16,
      "y": 32,
      "z": 2,
      "name": "Rock_Ice"
    },
    {
      "x": -16,
      "y": 33,
      "z": 2,
      "name": "Rock_Ice"
    },
    {
      "x": -16,
      "y": 34,
      "z": 2,
      "name": "Rock_Ice"
    },
    {
      "x": -16,
      "y": 35,
      "z": 2,
      "name": "Rock_Ice"
    },
    {
      "x": -16,
      "y": 36,
      "z": 2,
      "name": "Rock_Ice"
    },
    {
      "x": -16,
      "y": 37,
      "z": 2,
      "name": "Rock_Ice"
    },
    {
      "x": -16,
      "y": 38,
      "z": 2,
      "name": "Rock_Ice"
    },
    {
      "x": -16,
      "y": 39,
      "z": 2,
      "name": "Rock_Ice"
    },
    {
      "x": -16,
      "y": 40,
      "z": 2,
      "name": "Rock_Ice"
    },
    {
      "x": -16,
      "y": 41,
      "z": 2,
      "name": "Rock_Ice"
    },
    {
      "x": -16,
      "y": 42,
      "z": 2,
      "name": "Rock_Ice"
    },
    {
      "x": -16,
      "y": 43,
      "z": 2,
      "name": "Rock_Ice"
    },
    {
      "x": -16,
      "y": 44,
      "z": 2,
      "name": "Soil_Snow"
    },
    {
      "x": -16,
      "y": 15,
      "z": 3,
      "name": "Rock_Ice_Permafrost"
    },
    {
      "x": -16,
      "y": 16,
      "z": 3,
      "name": "Rock_Ice_Permafrost"
    },
    {
      "x": -16,
      "y": 17,
      "z": 3,
      "name": "Rock_Ice_Permafrost"
    },
    {
      "x": -16,
      "y": 18,
      "z": 3,
      "name": "Rock_Ice_Permafrost"
    },
    {
      "x": -16,
      "y": 19,
      "z": 3,
      "name": "Rock_Ice_Permafrost"
    },
    {
      "x": -16,
      "y": 20,
      "z": 3,
      "name": "Rock_Ice_Permafrost"
    },
    {
      "x": -16,
      "y": 21,
      "z": 3,
      "name": "Rock_Ice"
    },
    {
      "x": -16,
      "y": 22,
      "z": 3,
      "name": "Rock_Ice_Permafrost"
    },
    {
      "x": -16,
      "y": 23,
      "z": 3,
      "name": "Rock_Crystal_Cyan_Block_WhiteLight"
    },
    {
      "x": -16,
      "y": 24,
      "z": 3,
      "name": "Rock_Ice_Permafrost"
    },
    {
      "x": -16,
      "y": 25,
      "z": 3,
      "name": "Rock_Ice_Permafrost"
    },
    {
      "x": -16,
      "y": 26,
      "z": 3,
      "name": "Rock_Ice_Permafrost"
    },
    {
      "x": -16,
      "y": 27,
      "z": 3,
      "name": "Rock_Ice_Permafrost"
    },
    {
      "x": -16,
      "y": 28,
      "z": 3,
      "name": "Rock_Ice_Permafrost"
    },
    {
      "x": -16,
      "y": 29,
      "z": 3,
      "name": "Rock_Ice"
    },
    {
      "x": -16,
      "y": 30,
      "z": 3,
      "name": "Rock_Ice"
    },
    {
      "x": -16,
      "y": 31,
      "z": 3,
      "name": "Rock_Ice"
    },
    {
      "x": -16,
      "y": 32,
      "z": 3,
      "name": "Rock_Ice"
    },
    {
      "x": -16,
      "y": 33,
      "z": 3,
      "name": "Rock_Ice"
    },
    {
      "x": -16,
      "y": 34,
      "z": 3,
      "name": "Rock_Ice"
    },
    {
      "x": -16,
      "y": 35,
      "z": 3,
      "name": "Rock_Ice"
    },
    {
      "x": -16,
      "y": 36,
      "z": 3,
      "name": "Rock_Ice"
    },
    {
      "x": -16,
      "y": 37,
      "z": 3,
      "name": "Rock_Ice"
    },
    {
      "x": -16,
      "y": 38,
      "z": 3,
      "name": "Rock_Ice"
    },
    {
      "x": -16,
      "y": 39,
      "z": 3,
      "name": "Rock_Ice"
    },
    {
      "x": -16,
      "y": 40,
      "z": 3,
      "name": "Rock_Ice"
    },
    {
      "x": -16,
      "y": 41,
      "z": 3,
      "name": "Rock_Ice"
    },
    {
      "x": -16,
      "y": 42,
      "z": 3,
      "name": "Rock_Ice"
    },
    {
      "x": -16,
      "y": 43,
      "z": 3,
      "name": "Rock_Ice"
    },
    {
      "x": -16,
      "y": 44,
      "z": 3,
      "name": "Soil_Snow"
    },
    {
      "x": -16,
      "y": 15,
      "z": 4,
      "name": "Rock_Ice_Permafrost"
    },
    {
      "x": -16,
      "y": 16,
      "z": 4,
      "name": "Rock_Ice_Permafrost"
    },
    {
      "x": -16,
      "y": 17,
      "z": 4,
      "name": "Rock_Ice"
    },
    {
      "x": -16,
      "y": 18,
      "z": 4,
      "name": "Rock_Ice"
    },
    {
      "x": -16,
      "y": 19,
      "z": 4,
      "name": "Rock_Ice"
    },
    {
      "x": -16,
      "y": 20,
      "z": 4,
      "name": "Rock_Ice_Permafrost"
    },
    {
      "x": -16,
      "y": 21,
      "z": 4,
      "name": "Rock_Ice"
    },
    {
      "x": -16,
      "y": 22,
      "z": 4,
      "name": "Rock_Ice_Permafrost"
    },
    {
      "x": -16,
      "y": 23,
      "z": 4,
      "name": "Rock_Ice"
    },
    {
      "x": -16,
      "y": 24,
      "z": 4,
      "name": "Rock_Ice_Permafrost"
    },
    {
      "x": -16,
      "y": 25,
      "z": 4,
      "name": "Rock_Crystal_Cyan_Block_WhiteLight"
    },
    {
      "x": -16,
      "y": 26,
      "z": 4,
      "name": "Rock_Ice_Permafrost"
    },
    {
      "x": -16,
      "y": 27,
      "z": 4,
      "name": "Rock_Ice_Permafrost"
    },
    {
      "x": -16,
      "y": 28,
      "z": 4,
      "name": "Rock_Ice"
    },
    {
      "x": -16,
      "y": 29,
      "z": 4,
      "name": "Rock_Ice"
    },
    {
      "x": -16,
      "y": 30,
      "z": 4,
      "name": "Rock_Ice"
    },
    {
      "x": -16,
      "y": 31,
      "z": 4,
      "name": "Rock_Ice"
    },
    {
      "x": -16,
      "y": 32,
      "z": 4,
      "name": "Rock_Ice"
    },
    {
      "x": -16,
      "y": 33,
      "z": 4,
      "name": "Rock_Ice"
    },
    {
      "x": -16,
      "y": 34,
      "z": 4,
      "name": "Rock_Ice"
    },
    {
      "x": -16,
      "y": 35,
      "z": 4,
      "name": "Rock_Ice"
    },
    {
      "x": -16,
      "y": 36,
      "z": 4,
      "name": "Rock_Ice"
    },
    {
      "x": -16,
      "y": 37,
      "z": 4,
      "name": "Rock_Ice"
    },
    {
      "x": -16,
      "y": 38,
      "z": 4,
      "name": "Rock_Ice"
    },
    {
      "x": -16,
      "y": 39,
      "z": 4,
      "name": "Rock_Ice"
    },
    {
      "x": -16,
      "y": 40,
      "z": 4,
      "name": "Rock_Ice"
    },
    {
      "x": -16,
      "y": 41,
      "z": 4,
      "name": "Rock_Ice"
    },
    {
      "x": -16,
      "y": 42,
      "z": 4,
      "name": "Rock_Ice"
    },
    {
      "x": -16,
      "y": 43,
      "z": 4,
      "name": "Rock_Ice"
    },
    {
      "x": -16,
      "y": 44,
      "z": 4,
      "name": "Soil_Snow"
    },
    {
      "x": -16,
      "y": 14,
      "z": 5,
      "name": "Rock_Ice"
    },
    {
      "x": -16,
      "y": 15,
      "z": 5,
      "name": "Rock_Ice"
    },
    {
      "x": -16,
      "y": 16,
      "z": 5,
      "name": "Rock_Ice_Permafrost"
    },
    {
      "x": -16,
      "y": 17,
      "z": 5,
      "name": "Rock_Ice"
    },
    {
      "x": -16,
      "y": 18,
      "z": 5,
      "name": "Rock_Ice"
    },
    {
      "x": -16,
      "y": 19,
      "z": 5,
      "name": "Rock_Ice"
    },
    {
      "x": -16,
      "y": 20,
      "z": 5,
      "name": "Rock_Ice"
    },
    {
      "x": -16,
      "y": 21,
      "z": 5,
      "name": "Rock_Ice"
    },
    {
      "x": -16,
      "y": 22,
      "z": 5,
      "name": "Rock_Ice"
    },
    {
      "x": -16,
      "y": 23,
      "z": 5,
      "name": "Rock_Ice"
    },
    {
      "x": -16,
      "y": 24,
      "z": 5,
      "name": "Rock_Ice_Permafrost"
    },
    {
      "x": -16,
      "y": 25,
      "z": 5,
      "name": "Rock_Ice_Permafrost"
    },
    {
      "x": -16,
      "y": 26,
      "z": 5,
      "name": "Rock_Ice_Permafrost"
    },
    {
      "x": -16,
      "y": 27,
      "z": 5,
      "name": "Rock_Ice_Permafrost"
    },
    {
      "x": -16,
      "y": 28,
      "z": 5,
      "name": "Rock_Ice"
    },
    {
      "x": -16,
      "y": 29,
      "z": 5,
      "name": "Rock_Ice"
    },
    {
      "x": -16,
      "y": 30,
      "z": 5,
      "name": "Rock_Ice"
    },
    {
      "x": -16,
      "y": 31,
      "z": 5,
      "name": "Rock_Ice"
    },
    {
      "x": -16,
      "y": 32,
      "z": 5,
      "name": "Rock_Ice"
    },
    {
      "x": -16,
      "y": 33,
      "z": 5,
      "name": "Rock_Ice"
    },
    {
      "x": -16,
      "y": 34,
      "z": 5,
      "name": "Rock_Ice"
    },
    {
      "x": -16,
      "y": 35,
      "z": 5,
      "name": "Rock_Ice"
    },
    {
      "x": -16,
      "y": 36,
      "z": 5,
      "name": "Rock_Ice"
    },
    {
      "x": -16,
      "y": 37,
      "z": 5,
      "name": "Rock_Ice"
    },
    {
      "x": -16,
      "y": 38,
      "z": 5,
      "name": "Rock_Ice"
    },
    {
      "x": -16,
      "y": 39,
      "z": 5,
      "name": "Rock_Ice"
    },
    {
      "x": -16,
      "y": 40,
      "z": 5,
      "name": "Rock_Ice"
    },
    {
      "x": -16,
      "y": 41,
      "z": 5,
      "name": "Rock_Ice"
    },
    {
      "x": -16,
      "y": 42,
      "z": 5,
      "name": "Rock_Ice"
    },
    {
      "x": -16,
      "y": 43,
      "z": 5,
      "name": "Rock_Ice"
    },
    {
      "x": -16,
      "y": 44,
      "z": 5,
      "name": "Soil_Snow"
    },
    {
      "x": -16,
      "y": 14,
      "z": 6,
      "name": "Rock_Ice"
    },
    {
      "x": -16,
      "y": 15,
      "z": 6,
      "name": "Rock_Ice"
    },
    {
      "x": -16,
      "y": 16,
      "z": 6,
      "name": "Rock_Ice"
    },
    {
      "x": -16,
      "y": 17,
      "z": 6,
      "name": "Rock_Ice"
    },
    {
      "x": -16,
      "y": 18,
      "z": 6,
      "name": "Rock_Ice"
    },
    {
      "x": -16,
      "y": 19,
      "z": 6,
      "name": "Rock_Ice"
    },
    {
      "x": -16,
      "y": 20,
      "z": 6,
      "name": "Rock_Ice"
    },
    {
      "x": -16,
      "y": 21,
      "z": 6,
      "name": "Rock_Ice"
    },
    {
      "x": -16,
      "y": 22,
      "z": 6,
      "name": "Rock_Ice"
    },
    {
      "x": -16,
      "y": 23,
      "z": 6,
      "name": "Rock_Ice"
    },
    {
      "x": -16,
      "y": 24,
      "z": 6,
      "name": "Rock_Ice"
    },
    {
      "x": -16,
      "y": 25,
      "z": 6,
      "name": "Rock_Ice"
    },
    {
      "x": -16,
      "y": 26,
      "z": 6,
      "name": "Rock_Ice"
    },
    {
      "x": -16,
      "y": 27,
      "z": 6,
      "name": "Rock_Ice"
    },
    {
      "x": -16,
      "y": 28,
      "z": 6,
      "name": "Rock_Ice"
    },
    {
      "x": -16,
      "y": 29,
      "z": 6,
      "name": "Rock_Ice"
    },
    {
      "x": -16,
      "y": 30,
      "z": 6,
      "name": "Rock_Ice"
    },
    {
      "x": -16,
      "y": 31,
      "z": 6,
      "name": "Rock_Ice"
    },
    {
      "x": -16,
      "y": 32,
      "z": 6,
      "name": "Rock_Ice"
    },
    {
      "x": -16,
      "y": 33,
      "z": 6,
      "name": "Rock_Ice"
    },
    {
      "x": -16,
      "y": 34,
      "z": 6,
      "name": "Rock_Ice"
    },
    {
      "x": -16,
      "y": 35,
      "z": 6,
      "name": "Rock_Ice"
    },
    {
      "x": -16,
      "y": 36,
      "z": 6,
      "name": "Rock_Ice"
    },
    {
      "x": -16,
      "y": 37,
      "z": 6,
      "name": "Rock_Ice"
    },
    {
      "x": -16,
      "y": 38,
      "z": 6,
      "name": "Rock_Ice"
    },
    {
      "x": -16,
      "y": 39,
      "z": 6,
      "name": "Rock_Ice"
    },
    {
      "x": -16,
      "y": 40,
      "z": 6,
      "name": "Rock_Ice"
    },
    {
      "x": -16,
      "y": 41,
      "z": 6,
      "name": "Rock_Ice"
    },
    {
      "x": -16,
      "y": 42,
      "z": 6,
      "name": "Rock_Ice"
    },
    {
      "x": -16,
      "y": 43,
      "z": 6,
      "name": "Rock_Ice"
    },
    {
      "x": -16,
      "y": 44,
      "z": 6,
      "name": "Soil_Snow"
    },
    {
      "x": -16,
      "y": 14,
      "z": 7,
      "name": "Rock_Ice"
    },
    {
      "x": -16,
      "y": 15,
      "z": 7,
      "name": "Rock_Ice"
    },
    {
      "x": -16,
      "y": 16,
      "z": 7,
      "name": "Rock_Ice"
    },
    {
      "x": -16,
      "y": 17,
      "z": 7,
      "name": "Rock_Ice"
    },
    {
      "x": -16,
      "y": 18,
      "z": 7,
      "name": "Rock_Ice"
    },
    {
      "x": -16,
      "y": 19,
      "z": 7,
      "name": "Rock_Ice"
    },
    {
      "x": -16,
      "y": 20,
      "z": 7,
      "name": "Rock_Ice"
    },
    {
      "x": -16,
      "y": 21,
      "z": 7,
      "name": "Rock_Ice"
    },
    {
      "x": -16,
      "y": 22,
      "z": 7,
      "name": "Rock_Ice"
    },
    {
      "x": -16,
      "y": 23,
      "z": 7,
      "name": "Rock_Ice"
    },
    {
      "x": -16,
