{
  "version": 8,
  "blockIdVersion": 11,
  "anchorX": 0,
  "anchorY": 0,
  "anchorZ": 0,
  "blocks": [
    {
      "x": -20,
      "y": 132,
      "z": -5,
      "name": "Rock_Ice"
    },
    {
      "x": -20,
      "y": 133,
      "z": -5,
      "name": "Rock_Ice_Permafrost"
    },
    {
      "x": -20,
      "y": 134,
      "z": -5,
      "name": "Soil_Snow"
    },
    {
      "x": -20,
      "y": 130,
      "z": -4,
      "name": "Rock_Ice"
    },
    {
      "x": -20,
      "y": 131,
      "z": -4,
      "name": "Rock_Ice"
    },
    {
      "x": -20,
      "y": 132,
      "z": -4,
      "name": "Rock_Ice"
    },
    {
      "x": -20,
      "y": 133,
      "z": -4,
      "name": "Rock_Ice"
    },
    {
      "x": -20,
      "y": 134,
      "z": -4,
      "name": "Rock_Ice_Permafrost"
    },
    {
      "x": -20,
      "y": 133,
      "z": -3,
      "name": "Rock_Ice_Permafrost"
    },
    {
      "x": -20,
      "y": 134,
      "z": -3,
      "name": "Rock_Ice_Permafrost"
    },
    {
      "x": -20,
      "y": 127,
      "z": -2,
      "name": "Rock_Ice"
    },
    {
      "x": -20,
      "y": 128,
      "z": -2,
      "name": "Rock_Ice"
    },
    {
      "x": -20,
      "y": 129,
      "z": -2,
      "name": "Rock_Ice"
    },
    {
      "x": -20,
      "y": 130,
      "z": -2,
      "name": "Rock_Ice"
    },
    {
      "x": -20,
      "y": 133,
      "z": -2,
      "name": "Rock_Ice"
    },
    {
      "x": -20,
      "y": 134,
      "z": -2,
      "name": "Rock_Ice"
    },
    {
      "x": -20,
      "y": 127,
      "z": -1,
      "name": "Rock_Ice"
    },
    {
      "x": -20,
      "y": 128,
      "z": -1,
      "name": "Rock_Ice"
    },
    {
      "x": -20,
      "y": 129,
      "z": -1,
      "name": "Rock_Ice"
    },
    {
      "x": -20,
      "y": 130,
      "z": -1,
      "name": "Rock_Ice"
    },
    {
      "x": -20,
      "y": 131,
      "z": -1,
      "name": "Rock_Ice"
    },
    {
      "x": -20,
      "y": 132,
      "z": -1,
      "name": "Rock_Ice"
    },
    {
      "x": -20,
      "y": 133,
      "z": -1,
      "name": "Rock_Ice"
    },
    {
      "x": -20,
      "y": 134,
      "z": -1,
      "name": "Rock_Ice"
    },
    {
      "x": -20,
      "y": 129,
      "z": 0,
      "name": "Rock_Ice"
    },
    {
      "x": -20,
      "y": 130,
      "z": 0,
      "name": "Rock_Ice"
    },
    {
      "x": -20,
      "y": 131,
      "z": 0,
      "name": "Rock_Ice"
    },
    {
      "x": -20,
      "y": 132,
      "z": 0,
      "name": "Rock_Ice_Permafrost"
    },
    {
      "x": -20,
      "y": 133,
      "z": 0,
      "name": "Rock_Ice"
    },
    {
      "x": -20,
      "y": 134,
      "z": 0,
      "name": "Rock_Ice_Permafrost"
    },
    {
      "x": -20,
      "y": 135,
      "z": 0,
      "name": "Soil_Snow"
    },
    {
      "x": -20,
      "y": 133,
      "z": 1,
      "name": "Rock_Ice_Permafrost"
    },
    {
      "x": -20,
      "y": 134,
      "z": 1,
      "name": "Rock_Ice"
    },
    {
      "x": -19,
      "y": 134,
      "z": -7,
      "name": "Rock_Ice"
    },
    {
      "x": -19,
      "y": 131,
      "z": -6,
      "name": "Rock_Ice"
    },
    {
      "x": -19,
      "y": 132,
      "z": -6,
      "name": "Rock_Ice"
    },
    {
      "x": -19,
      "y": 133,
      "z": -6,
      "name": "Rock_Ice"
    },
    {
      "x": -19,
      "y": 134,
      "z": -6,
      "name": "Rock_Ice"
    },
    {
      "x": -19,
      "y": 135,
      "z": -6,
      "name": "Rock_Ice"
    },
    {
      "x": -19,
      "y": 136,
      "z": -6,
      "name": "Soil_Snow"
    },
    {
      "x": -19,
      "y": 124,
      "z": -5,
      "name": "Rock_Ice"
    },
    {
      "x": -19,
      "y": 125,
      "z": -5,
      "name": "Rock_Ice"
    },
    {
      "x": -19,
      "y": 126,
      "z": -5,
      "name": "Rock_Ice"
    },
    {
      "x": -19,
      "y": 127,
      "z": -5,
      "name": "Rock_Ice"
    },
    {
      "x": -19,
      "y": 128,
      "z": -5,
      "name": "Rock_Ice"
    },
    {
      "x": -19,
      "y": 129,
      "z": -5,
      "name": "Rock_Ice"
    },
    {
      "x": -19,
      "y": 130,
      "z": -5,
      "name": "Rock_Ice"
    },
    {
      "x": -19,
      "y": 131,
      "z": -5,
      "name": "Rock_Ice"
    },
    {
      "x": -19,
      "y": 132,
      "z": -5,
      "name": "Rock_Ice"
    },
    {
      "x": -19,
      "y": 133,
      "z": -5,
      "name": "Rock_Ice_Permafrost"
    },
    {
      "x": -19,
      "y": 134,
      "z": -5,
      "name": "Rock_Ice_Permafrost"
    },
    {
      "x": -19,
      "y": 135,
      "z": -5,
      "name": "Rock_Ice_Permafrost"
    },
    {
      "x": -19,
      "y": 136,
      "z": -5,
      "name": "Rock_Ice_Permafrost"
    },
    {
      "x": -19,
      "y": 137,
      "z": -5,
      "name": "Soil_Snow"
    },
    {
      "x": -19,
      "y": 123,
      "z": -4,
      "name": "Rock_Ice"
    },
    {
      "x": -19,
      "y": 124,
      "z": -4,
      "name": "Rock_Ice"
    },
    {
      "x": -19,
      "y": 125,
      "z": -4,
      "name": "Rock_Ice"
    },
    {
      "x": -19,
      "y": 126,
      "z": -4,
      "name": "Rock_Ice"
    },
    {
      "x": -19,
      "y": 127,
      "z": -4,
      "name": "Rock_Ice"
    },
    {
      "x": -19,
      "y": 128,
      "z": -4,
      "name": "Rock_Ice"
    },
    {
      "x": -19,
      "y": 129,
      "z": -4,
      "name": "Rock_Ice"
    },
    {
      "x": -19,
      "y": 130,
      "z": -4,
      "name": "Rock_Ice"
    },
    {
      "x": -19,
      "y": 131,
      "z": -4,
      "name": "Rock_Ice"
    },
    {
      "x": -19,
      "y": 132,
      "z": -4,
      "name": "Rock_Ice_Permafrost"
    },
    {
      "x": -19,
      "y": 133,
      "z": -4,
      "name": "Rock_Ice_Permafrost"
    },
    {
      "x": -19,
      "y": 134,
      "z": -4,
      "name": "Rock_Ice_Permafrost"
    },
    {
      "x": -19,
      "y": 135,
      "z": -4,
      "name": "Rock_Ice_Permafrost"
    },
    {
      "x": -19,
      "y": 136,
      "z": -4,
      "name": "Rock_Ice_Permafrost"
    },
    {
      "x": -19,
      "y": 137,
      "z": -4,
      "name": "Soil_Snow"
    },
    {
      "x": -19,
      "y": 118,
      "z": -3,
      "name": "Rock_Ice"
    },
    {
      "x": -19,
      "y": 119,
      "z": -3,
      "name": "Rock_Ice"
    },
    {
      "x": -19,
      "y": 120,
      "z": -3,
      "name": "Rock_Ice_Permafrost"
    },
    {
      "x": -19,
      "y": 121,
      "z": -3,
      "name": "Rock_Ice"
    },
    {
      "x": -19,
      "y": 122,
      "z": -3,
      "name": "Rock_Ice"
    },
    {
      "x": -19,
      "y": 123,
      "z": -3,
      "name": "Rock_Ice_Permafrost"
    },
    {
      "x": -19,
      "y": 124,
      "z": -3,
      "name": "Rock_Ice_Permafrost"
    },
    {
      "x": -19,
      "y": 125,
      "z": -3,
      "name": "Rock_Ice"
    },
    {
      "x": -19,
      "y": 126,
      "z": -3,
      "name": "Rock_Ice"
    },
    {
      "x": -19,
      "y": 127,
      "z": -3,
      "name": "Rock_Ice"
    },
    {
      "x": -19,
      "y": 128,
      "z": -3,
      "name": "Rock_Ice"
    },
    {
      "x": -19,
      "y": 129,
      "z": -3,
      "name": "Rock_Ice"
    },
    {
      "x": -19,
      "y": 130,
      "z": -3,
      "name": "Rock_Ice"
    },
    {
      "x": -19,
      "y": 131,
      "z": -3,
      "name": "Rock_Ice"
    },
    {
      "x": -19,
      "y": 132,
      "z": -3,
      "name": "Rock_Ice_Permafrost"
    },
    {
      "x": -19,
      "y": 133,
      "z": -3,
      "name": "Rock_Crystal_Cyan_Block_WhiteLight"
    },
    {
      "x": -19,
      "y": 134,
      "z": -3,
      "name": "Rock_Ice_Permafrost"
    },
    {
      "x": -19,
      "y": 135,
      "z": -3,
      "name": "Rock_Ice_Permafrost"
    },
    {
      "x": -19,
      "y": 136,
      "z": -3,
      "name": "Rock_Ice_Permafrost"
    },
    {
      "x": -19,
      "y": 137,
      "z": -3,
      "name": "Soil_Snow"
    },
    {
      "x": -19,
      "y": 118,
      "z": -2,
      "name": "Rock_Ice"
    },
    {
      "x": -19,
      "y": 119,
      "z": -2,
      "name": "Rock_Ice_Permafrost"
    },
    {
      "x": -19,
      "y": 120,
      "z": -2,
      "name": "Rock_Ice_Permafrost"
    },
    {
      "x": -19,
      "y": 121,
      "z": -2,
      "name": "Rock_Ice_Permafrost"
    },
    {
      "x": -19,
      "y": 122,
      "z": -2,
      "name": "Rock_Ice_Permafrost"
    },
    {
      "x": -19,
      "y": 123,
      "z": -2,
      "name": "Rock_Ice_Permafrost"
    },
    {
      "x": -19,
      "y": 124,
      "z": -2,
      "name": "Rock_Ice"
    },
    {
      "x": -19,
      "y": 125,
      "z": -2,
      "name": "Rock_Ice"
    },
    {
      "x": -19,
      "y": 126,
      "z": -2,
      "name": "Rock_Ice"
    },
    {
      "x": -19,
      "y": 127,
      "z": -2,
      "name": "Rock_Ice"
    },
    {
      "x": -19,
      "y": 128,
      "z": -2,
      "name": "Rock_Ice"
    },
    {
      "x": -19,
      "y": 129,
      "z": -2,
      "name": "Rock_Ice"
    },
    {
      "x": -19,
      "y": 130,
      "z": -2,
      "name": "Rock_Ice"
    },
    {
      "x": -19,
      "y": 131,
      "z": -2,
      "name": "Rock_Ice"
    },
    {
      "x": -19,
      "y": 132,
      "z": -2,
      "name": "Rock_Ice_Permafrost"
    },
    {
      "x": -19,
      "y": 133,
      "z": -2,
      "name": "Rock_Ice"
    },
    {
      "x": -19,
      "y": 134,
      "z": -2,
      "name": "Rock_Ice"
    },
    {
      "x": -19,
      "y": 135,
      "z": -2,
      "name": "Rock_Ice"
    },
    {
      "x": -19,
      "y": 136,
      "z": -2,
      "name": "Rock_Ice"
    },
    {
      "x": -19,
      "y": 137,
      "z": -2,
      "name": "Soil_Snow"
    },
    {
      "x": -19,
      "y": 119,
      "z": -1,
      "name": "Rock_Ice_Permafrost"
    },
    {
      "x": -19,
      "y": 120,
      "z": -1,
      "name": "Rock_Ice_Permafrost"
    },
    {
      "x": -19,
      "y": 121,
      "z": -1,
      "name": "Rock_Ice_Permafrost"
    },
    {
      "x": -19,
      "y": 122,
      "z": -1,
      "name": "Rock_Ice_Permafrost"
    },
    {
      "x": -19,
      "y": 123,
      "z": -1,
      "name": "Rock_Crystal_Cyan_Block_WhiteLight"
    },
    {
      "x": -19,
      "y": 124,
      "z": -1,
      "name": "Rock_Ice"
    },
    {
      "x": -19,
      "y": 125,
      "z": -1,
      "name": "Rock_Ice"
    },
    {
      "x": -19,
      "y": 126,
      "z": -1,
      "name": "Rock_Ice"
    },
    {
      "x": -19,
      "y": 127,
      "z": -1,
      "name": "Rock_Ice"
    },
    {
      "x": -19,
      "y": 128,
      "z": -1,
      "name": "Rock_Ice"
    },
    {
      "x": -19,
      "y": 129,
      "z": -1,
      "name": "Rock_Ice"
    },
    {
      "x": -19,
      "y": 130,
      "z": -1,
      "name": "Rock_Ice"
    },
    {
      "x": -19,
      "y": 131,
      "z": -1,
      "name": "Rock_Ice"
    },
    {
      "x": -19,
      "y": 132,
      "z": -1,
      "name": "Rock_Ice"
    },
    {
      "x": -19,
      "y": 133,
      "z": -1,
      "name": "Rock_Ice"
    },
    {
      "x": -19,
      "y": 134,
      "z": -1,
      "name": "Rock_Ice"
    },
    {
      "x": -19,
      "y": 135,
      "z": -1,
      "name": "Rock_Ice"
    },
    {
      "x": -19,
      "y": 136,
      "z": -1,
      "name": "Soil_Snow"
    },
    {
      "x": -19,
      "y": 118,
      "z": 0,
      "name": "Rock_Ice_Icicles",
      "rotation": 8
    },
    {
      "x": -19,
      "y": 119,
      "z": 0,
      "name": "Rock_Ice_Permafrost"
    },
    {
      "x": -19,
      "y": 120,
      "z": 0,
      "name": "Rock_Ice_Permafrost"
    },
    {
      "x": -19,
      "y": 121,
      "z": 0,
      "name": "Rock_Crystal_Cyan_Block_WhiteLight"
    },
    {
      "x": -19,
      "y": 122,
      "z": 0,
      "name": "Rock_Ice_Permafrost"
    },
    {
      "x": -19,
      "y": 123,
      "z": 0,
      "name": "Rock_Ice_Permafrost"
    },
    {
      "x": -19,
      "y": 124,
      "z": 0,
      "name": "Rock_Ice_Permafrost"
    },
    {
      "x": -19,
      "y": 125,
      "z": 0,
      "name": "Rock_Ice"
    },
    {
      "x": -19,
      "y": 126,
      "z": 0,
      "name": "Rock_Ice"
    },
    {
      "x": -19,
      "y": 127,
      "z": 0,
      "name": "Rock_Ice"
    },
    {
      "x": -19,
      "y": 128,
      "z": 0,
      "name": "Rock_Ice"
    },
    {
      "x": -19,
      "y": 129,
      "z": 0,
      "name": "Rock_Ice"
    },
    {
      "x": -19,
      "y": 130,
      "z": 0,
      "name": "Rock_Ice"
    },
    {
      "x": -19,
      "y": 131,
      "z": 0,
      "name": "Rock_Ice"
    },
    {
      "x": -19,
      "y": 132,
      "z": 0,
      "name": "Rock_Ice"
    },
    {
      "x": -19,
      "y": 133,
      "z": 0,
      "name": "Rock_Ice_Permafrost"
    },
    {
      "x": -19,
      "y": 134,
      "z": 0,
      "name": "Rock_Ice"
    },
    {
      "x": -19,
      "y": 135,
      "z": 0,
      "name": "Rock_Ice"
    },
    {
      "x": -19,
      "y": 136,
      "z": 0,
      "name": "Soil_Snow"
    },
    {
      "x": -19,
      "y": 120,
      "z": 1,
      "name": "Rock_Ice"
    },
    {
      "x": -19,
      "y": 121,
      "z": 1,
      "name": "Rock_Ice_Permafrost"
    },
    {
      "x": -19,
      "y": 122,
      "z": 1,
      "name": "Rock_Ice_Permafrost"
    },
    {
      "x": -19,
      "y": 123,
      "z": 1,
      "name": "Rock_Ice_Permafrost"
    },
    {
      "x": -19,
      "y": 124,
      "z": 1,
      "name": "Rock_Ice_Permafrost"
    },
    {
      "x": -19,
      "y": 125,
      "z": 1,
      "name": "Rock_Ice"
    },
    {
      "x": -19,
      "y": 126,
      "z": 1,
      "name": "Rock_Ice"
    },
    {
      "x": -19,
      "y": 127,
      "z": 1,
      "name": "Rock_Ice"
    },
    {
      "x": -19,
      "y": 128,
      "z": 1,
      "name": "Rock_Ice"
    },
    {
      "x": -19,
      "y": 129,
      "z": 1,
      "name": "Rock_Ice"
    },
    {
      "x": -19,
      "y": 130,
      "z": 1,
      "name": "Rock_Ice_Permafrost"
    },
    {
      "x": -19,
      "y": 131,
      "z": 1,
      "name": "Rock_Ice_Permafrost"
    },
    {
      "x": -19,
      "y": 132,
      "z": 1,
      "name": "Rock_Ice_Permafrost"
    },
    {
      "x": -19,
      "y": 133,
      "z": 1,
      "name": "Rock_Ice"
    },
    {
      "x": -19,
      "y": 134,
      "z": 1,
      "name": "Rock_Ice"
    },
    {
      "x": -19,
      "y": 135,
      "z": 1,
      "name": "Rock_Ice"
    },
    {
      "x": -19,
      "y": 136,
      "z": 1,
      "name": "Soil_Snow"
    },
    {
      "x": -19,
      "y": 121,
      "z": 2,
      "name": "Rock_Ice"
    },
    {
      "x": -19,
      "y": 129,
      "z": 2,
      "name": "Rock_Ice_Permafrost"
    },
    {
      "x": -19,
      "y": 130,
      "z": 2,
      "name": "Rock_Ice_Permafrost"
    },
    {
      "x": -19,
      "y": 131,
      "z": 2,
      "name": "Rock_Ice_Permafrost"
    },
    {
      "x": -19,
      "y": 132,
      "z": 2,
      "name": "Rock_Ice"
    },
    {
      "x": -19,
      "y": 133,
      "z": 2,
      "name": "Rock_Ice"
    },
    {
      "x": -19,
      "y": 134,
      "z": 2,
      "name": "Rock_Ice"
    },
    {
      "x": -19,
      "y": 135,
      "z": 2,
      "name": "Rock_Ice"
    },
    {
      "x": -19,
      "y": 136,
      "z": 2,
      "name": "Soil_Snow"
    },
    {
      "x": -18,
      "y": 133,
      "z": -8,
      "name": "Rock_Ice"
    },
    {
      "x": -18,
      "y": 134,
      "z": -8,
      "name": "Rock_Ice"
    },
    {
      "x": -18,
      "y": 135,
      "z": -8,
      "name": "Soil_Snow"
    },
    {
      "x": -18,
      "y": 129,
      "z": -7,
      "name": "Rock_Ice"
    },
    {
      "x": -18,
      "y": 130,
      "z": -7,
      "name": "Rock_Ice"
    },
    {
      "x": -18,
      "y": 131,
      "z": -7,
      "name": "Rock_Ice"
    },
    {
      "x": -18,
      "y": 132,
      "z": -7,
      "name": "Rock_Ice"
    },
    {
      "x": -18,
      "y": 133,
      "z": -7,
      "name": "Rock_Ice"
    },
    {
      "x": -18,
      "y": 134,
      "z": -7,
      "name": "Rock_Ice"
    },
    {
      "x": -18,
      "y": 135,
      "z": -7,
      "name": "Rock_Ice"
    },
    {
      "x": -18,
      "y": 136,
      "z": -7,
      "name": "Rock_Ice"
    },
    {
      "x": -18,
      "y": 137,
      "z": -7,
      "name": "Soil_Snow"
    },
    {
      "x": -18,
      "y": 119,
      "z": -6,
      "name": "Rock_Ice"
    },
    {
      "x": -18,
      "y": 120,
      "z": -6,
      "name": "Rock_Ice"
    },
    {
      "x": -18,
      "y": 121,
      "z": -6,
      "name": "Rock_Ice"
    },
    {
      "x": -18,
      "y": 122,
      "z": -6,
      "name": "Rock_Ice"
    },
    {
      "x": -18,
      "y": 123,
      "z": -6,
      "name": "Rock_Ice"
    },
    {
      "x": -18,
      "y": 124,
      "z": -6,
      "name": "Rock_Ice"
    },
    {
      "x": -18,
      "y": 125,
      "z": -6,
      "name": "Rock_Ice"
    },
    {
      "x": -18,
      "y": 126,
      "z": -6,
      "name": "Rock_Ice"
    },
    {
      "x": -18,
      "y": 127,
      "z": -6,
      "name": "Rock_Ice"
    },
    {
      "x": -18,
      "y": 128,
      "z": -6,
      "name": "Rock_Ice"
    },
    {
      "x": -18,
      "y": 129,
      "z": -6,
      "name": "Rock_Ice"
    },
    {
      "x": -18,
      "y": 130,
      "z": -6,
      "name": "Rock_Ice"
    },
    {
      "x": -18,
      "y": 131,
      "z": -6,
      "name": "Rock_Ice"
    },
    {
      "x": -18,
      "y": 132,
      "z": -6,
      "name": "Rock_Ice"
    },
    {
      "x": -18,
      "y": 133,
      "z": -6,
      "name": "Rock_Ice"
    },
    {
      "x": -18,
      "y": 134,
      "z": -6,
      "name": "Rock_Ice"
    },
    {
      "x": -18,
      "y": 135,
      "z": -6,
      "name": "Rock_Ice_Permafrost"
    },
    {
      "x": -18,
      "y": 136,
      "z": -6,
      "name": "Rock_Ice_Permafrost"
    },
    {
      "x": -18,
      "y": 137,
      "z": -6,
      "name": "Rock_Ice_Permafrost"
    },
    {
      "x": -18,
      "y": 138,
      "z": -6,
      "name": "Soil_Snow"
    },
    {
      "x": -18,
      "y": 26,
      "z": -5,
      "name": "Soil_Snow"
    },
    {
      "x": -18,
      "y": 116,
      "z": -5,
      "name": "Rock_Ice"
    },
    {
      "x": -18,
      "y": 117,
      "z": -5,
      "name": "Rock_Ice"
    },
    {
      "x": -18,
      "y": 118,
      "z": -5,
      "name": "Rock_Ice"
    },
    {
      "x": -18,
      "y": 119,
      "z": -5,
      "name": "Rock_Ice"
    },
    {
      "x": -18,
      "y": 120,
      "z": -5,
      "name": "Rock_Ice"
    },
    {
      "x": -18,
      "y": 121,
      "z": -5,
      "name": "Rock_Ice"
    },
    {
      "x": -18,
      "y": 122,
      "z": -5,
      "name": "Rock_Ice"
    },
    {
      "x": -18,
      "y": 123,
      "z": -5,
      "name": "Rock_Ice"
    },
    {
      "x": -18,
      "y": 124,
      "z": -5,
      "name": "Rock_Ice"
    },
    {
      "x": -18,
      "y": 125,
      "z": -5,
      "name": "Rock_Ice"
    },
    {
      "x": -18,
      "y": 126,
      "z": -5,
      "name": "Rock_Ice"
    },
    {
      "x": -18,
      "y": 127,
      "z": -5,
      "name": "Rock_Ice"
    },
    {
      "x": -18,
      "y": 128,
      "z": -5,
      "name": "Rock_Ice"
    },
    {
      "x": -18,
      "y": 129,
      "z": -5,
      "name": "Rock_Ice"
    },
    {
      "x": -18,
      "y": 130,
      "z": -5,
      "name": "Rock_Ice"
    },
    {
      "x": -18,
      "y": 131,
      "z": -5,
      "name": "Rock_Ice"
    },
    {
      "x": -18,
      "y": 132,
      "z": -5,
      "name": "Rock_Ice"
    },
    {
      "x": -18,
      "y": 133,
      "z": -5,
      "name": "Rock_Ice_Permafrost"
    },
    {
      "x": -18,
      "y": 134,
      "z": -5,
      "name": "Rock_Crystal_Cyan_Block_WhiteLight"
    },
    {
      "x": -18,
      "y": 135,
      "z": -5,
      "name": "Rock_Ice_Permafrost"
    },
    {
      "x": -18,
      "y": 136,
      "z": -5,
      "name": "Rock_Crystal_Cyan_Block_WhiteLight"
    },
    {
      "x": -18,
      "y": 137,
      "z": -5,
      "name": "Rock_Crystal_Cyan_Block_WhiteLight"
    },
    {
      "x": -18,
      "y": 138,
      "z": -5,
      "name": "Soil_Snow"
    },
    {
      "x": -18,
      "y": 26,
      "z": -4,
      "name": "Soil_Snow"
    },
    {
      "x": -18,
      "y": 112,
      "z": -4,
      "name": "Rock_Ice"
    },
    {
      "x": -18,
      "y": 113,
      "z": -4,
      "name": "Rock_Ice"
    },
    {
      "x": -18,
      "y": 114,
      "z": -4,
      "name": "Rock_Ice"
    },
    {
      "x": -18,
      "y": 115,
      "z": -4,
      "name": "Rock_Ice"
    },
    {
      "x": -18,
      "y": 116,
      "z": -4,
      "name": "Rock_Ice"
    },
    {
      "x": -18,
      "y": 117,
      "z": -4,
      "name": "Rock_Ice"
    },
    {
      "x": -18,
      "y": 118,
      "z": -4,
      "name": "Rock_Ice"
    },
    {
      "x": -18,
      "y": 119,
      "z": -4,
      "name": "Rock_Ice"
    },
    {
      "x": -18,
      "y": 120,
      "z": -4,
      "name": "Rock_Ice"
    },
    {
      "x": -18,
      "y": 121,
      "z": -4,
      "name": "Rock_Ice"
    },
    {
      "x": -18,
      "y": 122,
      "z": -4,
      "name": "Rock_Ice"
    },
    {
      "x": -18,
      "y": 123,
      "z": -4,
      "name": "Rock_Ice"
    },
    {
      "x": -18,
      "y": 124,
      "z": -4,
      "name": "Rock_Ice"
    },
    {
      "x": -18,
      "y": 125,
      "z": -4,
      "name": "Rock_Ice"
    },
    {
      "x": -18,
      "y": 126,
      "z": -4,
      "name": "Rock_Ice_Permafrost"
    },
    {
      "x": -18,
      "y": 127,
      "z": -4,
      "name": "Rock_Ice"
    },
    {
      "x": -18,
      "y": 128,
      "z": -4,
      "name": "Rock_Ice"
    },
    {
      "x": -18,
      "y": 129,
      "z": -4,
      "name": "Rock_Ice"
    },
    {
      "x": -18,
      "y": 130,
      "z": -4,
      "name": "Rock_Ice"
    },
    {
      "x": -18,
      "y": 131,
      "z": -4,
      "name": "Rock_Ice"
    },
    {
      "x": -18,
      "y": 132,
      "z": -4,
      "name": "Rock_Ice_Permafrost"
    },
    {
      "x": -18,
      "y": 133,
      "z": -4,
      "name": "Rock_Ice_Permafrost"
    },
    {
      "x": -18,
      "y": 134,
      "z": -4,
      "name": "Rock_Ice_Permafrost"
    },
    {
      "x": -18,
      "y": 135,
      "z": -4,
      "name": "Rock_Crystal_Cyan_Block_WhiteLight"
    },
    {
      "x": -18,
      "y": 136,
      "z": -4,
      "name": "Rock_Ice_Permafrost"
    },
    {
      "x": -18,
      "y": 137,
      "z": -4,
      "name": "Rock_Ice"
    },
    {
      "x": -18,
      "y": 138,
      "z": -4,
      "name": "Soil_Snow"
    },
    {
      "x": -18,
      "y": 26,
      "z": -3,
      "name": "Rock_Ice"
    },
    {
      "x": -18,
      "y": 27,
      "z": -3,
      "name": "Soil_Snow"
    },
    {
      "x": -18,
      "y": 110,
      "z": -3,
      "name": "Rock_Ice"
    },
    {
      "x": -18,
      "y": 111,
      "z": -3,
      "name": "Rock_Ice"
    },
    {
      "x": -18,
      "y": 112,
      "z": -3,
      "name": "Rock_Ice"
    },
    {
      "x": -18,
      "y": 113,
      "z": -3,
      "name": "Rock_Ice"
    },
    {
      "x": -18,
      "y": 114,
      "z": -3,
      "name": "Rock_Ice"
    },
    {
      "x": -18,
      "y": 115,
      "z": -3,
      "name": "Rock_Ice"
    },
    {
      "x": -18,
      "y": 116,
      "z": -3,
      "name": "Rock_Ice"
    },
    {
      "x": -18,
      "y": 117,
      "z": -3,
      "name": "Rock_Ice"
    },
    {
      "x": -18,
      "y": 118,
      "z": -3,
      "name": "Rock_Ice"
    },
    {
      "x": -18,
      "y": 119,
      "z": -3,
      "name": "Rock_Ice_Permafrost"
    },
    {
      "x": -18,
      "y": 120,
      "z": -3,
      "name": "Rock_Ice_Permafrost"
    },
    {
      "x": -18,
      "y": 121,
      "z": -3,
      "name": "Rock_Ice"
    },
    {
      "x": -18,
      "y": 122,
      "z": -3,
      "name": "Rock_Ice"
    },
    {
      "x": -18,
      "y": 123,
      "z": -3,
      "name": "Rock_Ice"
    },
    {
      "x": -18,
      "y": 124,
      "z": -3,
      "name": "Rock_Ice"
    },
    {
      "x": -18,
      "y": 125,
      "z": -3,
      "name": "Rock_Ice_Permafrost"
    },
    {
      "x": -18,
      "y": 126,
      "z": -3,
      "name": "Rock_Ice"
    },
    {
      "x": -18,
      "y": 127,
      "z": -3,
      "name": "Rock_Ice"
    },
    {
      "x": -18,
      "y": 128,
      "z": -3,
      "name": "Rock_Ice"
    },
    {
      "x": -18,
      "y": 129,
      "z": -3,
      "name": "Rock_Ice"
    },
    {
      "x": -18,
      "y": 130,
      "z": -3,
      "name": "Rock_Ice_Permafrost"
    },
    {
      "x": -18,
      "y": 131,
      "z": -3,
      "name": "Rock_Ice_Permafrost"
    },
    {
      "x": -18,
      "y": 132,
      "z": -3,
      "name": "Rock_Ice_Permafrost"
    },
    {
      "x": -18,
      "y": 133,
      "z": -3,
      "name": "Rock_Ice_Permafrost"
    },
    {
      "x": -18,
      "y": 134,
      "z": -3,
      "name": "Rock_Ice_Permafrost"
    },
    {
      "x": -18,
      "y": 135,
      "z": -3,
      "name": "Rock_Ice"
    },
    {
      "x": -18,
      "y": 136,
      "z": -3,
      "name": "Rock_Ice"
    },
    {
      "x": -18,
      "y": 137,
      "z": -3,
      "name": "Rock_Ice"
    },
    {
      "x": -18,
      "y": 138,
      "z": -3,
      "name": "Soil_Snow"
    },
    {
      "x": -18,
      "y": 25,
      "z": -2,
      "name": "Rock_Ice_Permafrost"
    },
    {
      "x": -18,
      "y": 26,
      "z": -2,
      "name": "Rock_Ice"
    },
    {
      "x": -18,
      "y": 27,
      "z": -2,
      "name": "Soil_Snow"
    },
    {
      "x": -18,
      "y": 111,
      "z": -2,
      "name": "Rock_Ice"
    },
    {
      "x": -18,
      "y": 112,
      "z": -2,
      "name": "Rock_Ice"
    },
    {
      "x": -18,
      "y": 113,
      "z": -2,
      "name": "Rock_Ice"
    },
    {
      "x": -18,
      "y": 114,
      "z": -2,
      "name": "Rock_Ice"
    },
    {
      "x": -18,
      "y": 115,
      "z": -2,
      "name": "Rock_Ice"
    },
    {
      "x": -18,
      "y": 116,
      "z": -2,
      "name": "Rock_Ice"
    },
    {
      "x": -18,
      "y": 117,
      "z": -2,
      "name": "Rock_Ice"
    },
    {
      "x": -18,
      "y": 118,
      "z": -2,
      "name": "Rock_Ice_Permafrost"
    },
    {
      "x": -18,
      "y": 119,
      "z": -2,
      "name": "Rock_Ice"
    },
    {
      "x": -18,
      "y": 120,
      "z": -2,
      "name": "Rock_Ice_Permafrost"
    },
    {
      "x": -18,
      "y": 121,
      "z": -2,
      "name": "Rock_Crystal_Cyan_Block_WhiteLight"
    },
    {
      "x": -18,
      "y": 122,
      "z": -2,
      "name": "Rock_Ice_Permafrost"
    },
    {
      "x": -18,
      "y": 123,
      "z": -2,
      "name": "Rock_Ice_Permafrost"
    },
    {
      "x": -18,
      "y": 124,
      "z": -2,
      "name": "Rock_Ice_Permafrost"
    },
    {
      "x": -18,
      "y": 125,
      "z": -2,
      "name": "Rock_Ice_Permafrost"
    },
    {
      "x": -18,
      "y": 126,
      "z": -2,
      "name": "Rock_Ice"
    },
    {
      "x": -18,
      "y": 127,
      "z": -2,
      "name": "Rock_Ice"
    },
    {
      "x": -18,
      "y": 128,
      "z": -2,
      "name": "Rock_Ice"
    },
    {
      "x": -18,
      "y": 129,
      "z": -2,
      "name": "Rock_Ice"
    },
    {
      "x": -18,
      "y": 130,
      "z": -2,
      "name": "Rock_Ice_Permafrost"
    },
    {
      "x": -18,
      "y": 131,
      "z": -2,
      "name": "Rock_Ice_Permafrost"
    },
    {
      "x": -18,
      "y": 132,
      "z": -2,
      "name": "Rock_Ice_Permafrost"
    },
    {
      "x": -18,
      "y": 133,
      "z": -2,
      "name": "Rock_Ice_Permafrost"
    },
    {
      "x": -18,
      "y": 134,
      "z": -2,
      "name": "Rock_Ice_Permafrost"
    },
    {
      "x": -18,
      "y": 135,
      "z": -2,
      "name": "Rock_Ice"
    },
    {
      "x": -18,
      "y": 136,
      "z": -2,
      "name": "Rock_Ice"
    },
    {
      "x": -18,
      "y": 137,
      "z": -2,
      "name": "Soil_Snow"
    },
    {
      "x": -18,
      "y": 24,
      "z": -1,
      "name": "Rock_Ice_Permafrost"
    },
    {
      "x": -18,
      "y": 25,
      "z": -1,
      "name": "Rock_Ice_Permafrost"
    },
    {
      "x": -18,
      "y": 26,
      "z": -1,
      "name": "Rock_Ice"
    },
    {
      "x": -18,
      "y": 27,
      "z": -1,
      "name": "Soil_Snow"
    },
    {
      "x": -18,
      "y": 112,
      "z": -1,
      "name": "Rock_Ice"
    },
    {
      "x": -18,
      "y": 113,
      "z": -1,
      "name": "Rock_Ice"
    },
    {
      "x": -18,
      "y": 114,
      "z": -1,
      "name": "Rock_Ice"
    },
    {
      "x": -18,
      "y": 115,
      "z": -1,
      "name": "Rock_Ice"
    },
    {
      "x": -18,
      "y": 116,
      "z": -1,
      "name": "Rock_Ice"
    },
    {
      "x": -18,
      "y": 117,
      "z": -1,
      "name": "Rock_Ice"
    },
    {
      "x": -18,
      "y": 118,
      "z": -1,
      "name": "Rock_Ice_Permafrost"
    },
    {
      "x": -18,
      "y": 119,
      "z": -1,
      "name": "Rock_Crystal_Cyan_Block_WhiteLight"
    },
    {
      "x": -18,
      "y": 120,
      "z": -1,
      "name": "Rock_Crystal_Cyan_Block_WhiteLight"
    },
    {
      "x": -18,
      "y": 121,
      "z": -1,
      "name": "Rock_Crystal_Cyan_Block_WhiteLight"
    },
    {
      "x": -18,
      "y": 122,
      "z": -1,
      "name": "Rock_Ice_Permafrost"
    },
    {
      "x": -18,
      "y": 123,
      "z": -1,
      "name": "Rock_Ice_Permafrost"
    },
    {
      "x": -18,
      "y": 124,
      "z": -1,
      "name": "Rock_Ice_Permafrost"
    },
    {
      "x": -18,
      "y": 125,
      "z": -1,
      "name": "Rock_Ice_Permafrost"
    },
    {
      "x": -18,
      "y": 126,
      "z": -1,
      "name": "Rock_Ice_Permafrost"
    },
    {
      "x": -18,
      "y": 127,
      "z": -1,
      "name": "Rock_Ice"
    },
    {
      "x": -18,
      "y": 128,
      "z": -1,
      "name": "Rock_Ice"
    },
    {
      "x": -18,
      "y": 129,
      "z": -1,
      "name": "Rock_Ice"
    },
    {
      "x": -18,
      "y": 130,
      "z": -1,
      "name": "Rock_Ice_Permafrost"
    },
    {
      "x": -18,
      "y": 131,
      "z": -1,
      "name": "Rock_Ice"
    },
    {
      "x": -18,
      "y": 132,
      "z": -1,
      "name": "Rock_Ice"
    },
    {
      "x": -18,
      "y": 133,
      "z": -1,
      "name": "Rock_Ice"
    },
    {
      "x": -18,
      "y": 134,
      "z": -1,
      "name": "Rock_Ice_Permafrost"
    },
    {
      "x": -18,
      "y": 135,
      "z": -1,
      "name": "Rock_Ice"
    },
    {
      "x": -18,
      "y": 136,
      "z": -1,
      "name": "Rock_Ice"
    },
    {
      "x": -18,
      "y": 137,
      "z": -1,
      "name": "Soil_Snow"
    },
    {
      "x": -18,
      "y": 23,
      "z": 0,
      "name": "Rock_Ice"
    },
    {
      "x": -18,
      "y": 24,
      "z": 0,
      "name": "Rock_Ice"
    },
    {
      "x": -18,
      "y": 25,
      "z": 0,
      "name": "Rock_Ice"
    },
    {
      "x": -18,
      "y": 26,
      "z": 0,
      "name": "Rock_Ice"
    },
    {
      "x": -18,
      "y": 27,
      "z": 0,
      "name": "Soil_Snow"
    },
    {
      "x": -18,
      "y": 112,
      "z": 0,
      "name": "Rock_Ice"
    },
    {
      "x": -18,
      "y": 113,
      "z": 0,
      "name": "Rock_Ice"
    },
    {
      "x": -18,
      "y": 114,
      "z": 0,
      "name": "Rock_Ice"
    },
    {
      "x": -18,
      "y": 115,
      "z": 0,
      "name": "Rock_Ice"
    },
    {
      "x": -18,
      "y": 116,
      "z": 0,
      "name": "Rock_Ice"
    },
    {
      "x": -18,
      "y": 117,
      "z": 0,
      "name": "Rock_Ice"
    },
    {
      "x": -18,
      "y": 118,
      "z": 0,
      "name": "Rock_Ice"
    },
    {
      "x": -18,
      "y": 119,
      "z": 0,
      "name": "Rock_Ice"
    },
    {
      "x": -18,
      "y": 120,
      "z": 0,
      "name": "Rock_Ice_Permafrost"
    },
    {
      "x": -18,
      "y": 121,
      "z": 0,
      "name": "Rock_Ice_Permafrost"
    },
    {
      "x": -18,
      "y": 122,
      "z": 0,
      "name": "Rock_Ice_Permafrost"
    },
    {
      "x": -18,
      "y": 123,
      "z": 0,
      "name": "Rock_Ice_Permafrost"
    },
    {
      "x": -18,
      "y": 124,
      "z": 0,
      "name": "Rock_Ice_Permafrost"
    },
    {
      "x": -18,
      "y": 125,
      "z": 0,
      "name": "Rock_Ice_Permafrost"
    },
    {
      "x": -18,
      "y": 126,
      "z": 0,
      "name": "Rock_Ice"
    },
    {
      "x": -18,
      "y": 127,
      "z": 0,
      "name": "Rock_Ice"
    },
    {
      "x": -18,
      "y": 128,
      "z": 0,
      "name": "Rock_Ice"
    },
    {
      "x": -18,
      "y": 129,
      "z": 0,
      "name": "Rock_Ice"
    },
    {
      "x": -18,
      "y": 130,
      "z": 0,
      "name": "Rock_Ice"
    },
    {
      "x": -18,
      "y": 131,
      "z": 0,
      "name": "Rock_Ice"
    },
    {
      "x": -18,
      "y": 132,
      "z": 0,
      "name": "Rock_Ice"
    },
    {
      "x": -18,
      "y": 133,
      "z": 0,
      "name": "Rock_Ice"
    },
    {
      "x": -18,
      "y": 134,
      "z": 0,
      "name": "Rock_Ice"
    },
    {
      "x": -18,
      "y": 135,
      "z": 0,
      "name": "Rock_Ice"
    },
    {
      "x": -18,
      "y": 136,
      "z": 0,
      "name": "Rock_Ice"
    },
    {
      "x": -18,
      "y": 137,
      "z": 0,
      "name": "Soil_Snow"
    },
    {
      "x": -18,
      "y": 22,
      "z": 1,
      "name": "Rock_Ice"
    },
    {
      "x": -18,
      "y": 23,
      "z": 1,
      "name": "Rock_Ice"
    },
    {
      "x": -18,
      "y": 24,
      "z": 1,
      "name": "Rock_Ice"
    },
    {
      "x": -18,
      "y": 27,
      "z": 1,
      "name": "Soil_Snow"
    },
    {
      "x": -18,
      "y": 112,
      "z": 1,
      "name": "Rock_Ice"
    },
    {
      "x": -18,
      "y": 113,
      "z": 1,
      "name": "Rock_Ice"
    },
    {
      "x": -18,
      "y": 114,
      "z": 1,
      "name": "Rock_Ice"
    },
    {
      "x": -18,
      "y": 115,
      "z": 1,
      "name": "Rock_Ice"
    },
    {
      "x": -18,
      "y": 116,
      "z": 1,
      "name": "Rock_Ice_Permafrost"
    },
    {
      "x": -18,
      "y": 117,
      "z": 1,
      "name": "Rock_Ice_Permafrost"
    },
    {
      "x": -18,
      "y": 118,
      "z": 1,
      "name": "Rock_Ice"
    },
    {
      "x": -18,
      "y": 119,
      "z": 1,
      "name": "Rock_Ice"
    },
    {
      "x": -18,
      "y": 120,
      "z": 1,
      "name": "Rock_Ice"
    },
    {
      "x": -18,
      "y": 121,
      "z": 1,
      "name": "Rock_Ice"
    },
    {
      "x": -18,
      "y": 122,
      "z": 1,
      "name": "Rock_Ice"
    },
    {
      "x": -18,
      "y": 123,
      "z": 1,
      "name": "Rock_Ice_Permafrost"
    },
    {
      "x": -18,
      "y": 124,
      "z": 1,
      "name": "Rock_Ice_Permafrost"
    },
    {
      "x": -18,
      "y": 125,
      "z": 1,
      "name": "Rock_Crystal_Cyan_Block_WhiteLight"
    },
    {
      "x": -18,
      "y": 126,
      "z": 1,
      "name": "Rock_Ice_Permafrost"
    },
    {
      "x": -18,
      "y": 127,
      "z": 1,
      "name": "Rock_Ice"
    },
    {
      "x": -18,
      "y": 128,
      "z": 1,
      "name": "Rock_Ice"
    },
    {
      "x": -18,
      "y": 129,
      "z": 1,
      "name": "Rock_Ice"
    },
    {
      "x": -18,
      "y": 130,
      "z": 1,
      "name": "Rock_Ice_Permafrost"
    },
    {
      "x": -18,
      "y": 131,
      "z": 1,
      "name": "Rock_Ice"
    },
    {
      "x": -18,
      "y": 132,
      "z": 1,
      "name": "Rock_Ice"
    },
    {
      "x": -18,
      "y": 133,
      "z": 1,
      "name": "Rock_Ice"
    },
    {
      "x": -18,
      "y": 134,
      "z": 1,
      "name": "Rock_Ice"
    },
    {
      "x": -18,
      "y": 135,
      "z": 1,
      "name": "Rock_Ice"
    },
    {
      "x": -18,
      "y": 136,
      "z": 1,
      "name": "Rock_Ice"
    },
    {
      "x": -18,
      "y": 137,
      "z": 1,
      "name": "Soil_Snow"
    },
    {
      "x": -18,
      "y": 23,
      "z": 2,
      "name": "Rock_Ice"
    },
    {
      "x": -18,
      "y": 24,
      "z": 2,
      "name": "Rock_Ice"
    },
    {
      "x": -18,
      "y": 25,
      "z": 2,
      "name": "Rock_Ice"
    },
    {
      "x": -18,
      "y": 26,
      "z": 2,
      "name": "Rock_Ice"
    },
    {
      "x": -18,
      "y": 27,
      "z": 2,
      "name": "Rock_Ice"
    },
    {
      "x": -18,
      "y": 28,
      "z": 2,
      "name": "Soil_Snow"
    },
    {
      "x": -18,
      "y": 115,
      "z": 2,
      "name": "Rock_Ice_Permafrost"
    },
    {
      "x": -18,
      "y": 116,
      "z": 2,
      "name": "Rock_Ice"
    },
    {
      "x": -18,
      "y": 117,
      "z": 2,
      "name": "Rock_Ice"
    },
    {
      "x": -18,
      "y": 118,
      "z": 2,
      "name": "Rock_Ice"
    },
    {
      "x": -18,
      "y": 119,
      "z": 2,
      "name": "Rock_Ice"
    },
    {
      "x": -18,
      "y": 120,
      "z": 2,
      "name": "Rock_Ice"
    },
    {
      "x": -18,
      "y": 121,
      "z": 2,
      "name": "Rock_Ice"
    },
    {
      "x": -18,
      "y": 122,
      "z": 2,
      "name": "Rock_Ice_Permafrost"
    },
    {
      "x": -18,
      "y": 123,
      "z": 2,
      "name": "Rock_Ice_Permafrost"
    },
    {
      "x": -18,
      "y": 124,
      "z": 2,
      "name": "Rock_Ice_Permafrost"
    },
    {
      "x": -18,
      "y": 125,
      "z": 2,
      "name": "Rock_Ice_Permafrost"
    },
    {
      "x": -18,
      "y": 126,
      "z": 2,
      "name": "Rock_Ice_Permafrost"
    },
    {
      "x": -18,
      "y": 127,
      "z": 2,
      "name": "Rock_Ice_Permafrost"
    },
    {
      "x": -18,
      "y": 128,
      "z": 2,
      "name": "Rock_Ice_Permafrost"
    },
    {
      "x": -18,
      "y": 129,
      "z": 2,
      "name": "Rock_Ice_Permafrost"
    },
    {
      "x": -18,
      "y": 130,
      "z": 2,
      "name": "Rock_Ice_Permafrost"
    },
    {
      "x": -18,
      "y": 131,
      "z": 2,
      "name": "Rock_Ice"
    },
    {
      "x": -18,
      "y": 132,
      "z": 2,
      "name": "Rock_Ice"
    },
    {
      "x": -18,
      "y": 133,
      "z": 2,
      "name": "Rock_Ice"
    },
    {
      "x": -18,
      "y": 134,
      "z": 2,
      "name": "Rock_Ice"
    },
    {
      "x": -18,
      "y": 135,
      "z": 2,
      "name": "Rock_Ice"
    },
    {
      "x": -18,
      "y": 136,
      "z": 2,
      "name": "Rock_Ice"
    },
    {
      "x": -18,
      "y": 137,
      "z": 2,
      "name": "Soil_Snow"
    },
    {
      "x": -18,
      "y": 23,
      "z": 3,
      "name": "Rock_Ice"
    },
    {
      "x": -18,
      "y": 24,
      "z": 3,
      "name": "Rock_Ice"
    },
    {
      "x": -18,
      "y": 25,
      "z": 3,
      "name": "Rock_Ice"
    },
    {
      "x": -18,
      "y": 26,
      "z": 3,
      "name": "Rock_Ice"
    },
    {
      "x": -18,
      "y": 27,
      "z": 3,
      "name": "Rock_Ice"
    },
    {
      "x": -18,
      "y": 28,
      "z": 3,
      "name": "Soil_Snow"
    },
    {
      "x": -18,
      "y": 107,
      "z": 3,
      "name": "Rock_Ice_Permafrost"
    },
    {
      "x": -18,
      "y": 116,
      "z": 3,
      "name": "Rock_Ice"
    },
    {
      "x": -18,
      "y": 117,
      "z": 3,
      "name": "Rock_Ice"
    },
    {
      "x": -18,
      "y": 118,
      "z": 3,
      "name": "Rock_Ice"
    },
    {
      "x": -18,
      "y": 119,
      "z": 3,
      "name": "Rock_Ice"
    },
    {
      "x": -18,
      "y": 120,
      "z": 3,
      "name": "Rock_Ice"
    },
    {
      "x": -18,
      "y": 121,
      "z": 3,
      "name": "Rock_Ice"
    },
    {
      "x": -18,
      "y": 122,
      "z": 3,
      "name": "Rock_Ice"
    },
    {
      "x": -18,
      "y": 123,
      "z": 3,
      "name": "Rock_Ice"
    },
    {
      "x": -18,
      "y": 124,
      "z": 3,
      "name": "Rock_Ice_Permafrost"
    },
    {
      "x": -18,
      "y": 125,
      "z": 3,
      "name": "Rock_Ice_Permafrost"
    },
    {
      "x": -18,
      "y": 126,
      "z": 3,
      "name": "Rock_Ice_Permafrost"
    },
    {
      "x": -18,
      "y": 127,
      "z": 3,
      "name": "Rock_Ice_Permafrost"
    },
    {
      "x": -18,
      "y": 128,
      "z": 3,
      "name": "Rock_Crystal_Cyan_Block_WhiteLight"
    },
    {
      "x": -18,
      "y": 129,
      "z": 3,
      "name": "Rock_Ice_Permafrost"
    },
    {
      "x": -18,
      "y": 130,
      "z": 3,
      "name": "Rock_Ice_Permafrost"
    },
    {
      "x": -18,
      "y": 131,
      "z": 3,
      "name": "Rock_Ice"
    },
    {
      "x": -18,
      "y": 132,
      "z": 3,
      "name": "Rock_Ice"
    },
    {
      "x": -18,
      "y": 133,
      "z": 3,
      "name": "Rock_Ice"
    },
    {
      "x": -18,
      "y": 134,
      "z": 3,
      "name": "Rock_Ice"
    },
    {
      "x": -18,
      "y": 135,
      "z": 3,
      "name": "Rock_Ice"
    },
    {
      "x": -18,
      "y": 136,
      "z": 3,
      "name": "Soil_Snow"
    },
    {
      "x": -18,
      "y": 23,
      "z": 4,
      "name": "Rock_Ice"
    },
    {
      "x": -18,
      "y": 24,
      "z": 4,
      "name": "Rock_Ice"
    },
    {
      "x": -18,
      "y": 25,
      "z": 4,
      "name": "Rock_Ice"
    },
    {
      "x": -18,
      "y": 26,
      "z": 4,
      "name": "Rock_Ice"
    },
    {
      "x": -18,
      "y": 27,
      "z": 4,
      "name": "Rock_Ice"
    },
    {
      "x": -18,
      "y": 28,
      "z": 4,
      "name": "Rock_Ice"
    },
    {
      "x": -18,
      "y": 29,
      "z": 4,
      "name": "Soil_Snow"
    },
    {
      "x": -18,
      "y": 116,
      "z": 4,
      "name": "Rock_Ice"
    },
    {
      "x": -18,
      "y": 117,
      "z": 4,
      "name": "Rock_Ice"
    },
    {
      "x": -18,
      "y": 118,
      "z": 4,
      "name": "Rock_Ice"
    },
    {
      "x": -18,
      "y": 119,
      "z": 4,
      "name": "Rock_Ice"
    },
    {
      "x": -18,
      "y": 120,
      "z": 4,
      "name": "Rock_Ice"
    },
    {
      "x": -18,
      "y": 121,
      "z": 4,
      "name": "Rock_Ice"
    },
    {
      "x": -18,
      "y": 122,
      "z": 4,
      "name": "Rock_Ice"
    },
    {
      "x": -18,
      "y": 126,
      "z": 4,
      "name": "Rock_Ice_Permafrost"
    },
    {
      "x": -18,
      "y": 127,
      "z": 4,
      "name": "Rock_Ice_Permafrost"
    },
    {
      "x": -18,
      "y": 128,
      "z": 4,
      "name": "Rock_Ice_Permafrost"
    },
    {
      "x": -18,
      "y": 129,
      "z": 4,
      "name": "Rock_Ice_Permafrost"
    },
    {
      "x": -18,
      "y": 130,
      "z": 4,
      "name": "Rock_Ice"
    },
    {
      "x": -18,
      "y": 131,
      "z": 4,
      "name": "Rock_Ice"
    },
    {
      "x": -18,
      "y": 133,
      "z": 4,
      "name": "Rock_Ice"
    },
    {
      "x": -18,
      "y": 134,
      "z": 4,
      "name": "Rock_Ice"
    },
    {
      "x": -18,
      "y": 135,
      "z": 4,
      "name": "Rock_Ice"
    },
    {
      "x": -18,
      "y": 116,
      "z": 5,
      "name": "Rock_Ice"
    },
    {
      "x": -18,
      "y": 117,
      "z": 5,
      "name": "Rock_Ice"
    },
    {
      "x": -17,
      "y": 133,
      "z": -9,
      "name": "Rock_Ice"
    },
    {
      "x": -17,
      "y": 134,
      "z": -9,
      "name": "Rock_Ice"
    },
    {
      "x": -17,
      "y": 135,
      "z": -9,
      "name": "Rock_Ice"
    },
    {
      "x": -17,
      "y": 136,
      "z": -9,
      "name": "Soil_Snow"
    },
    {
      "x": -17,
      "y": 115,
      "z": -8,
      "name": "Rock_Crystal_Cyan_Block_WhiteLight"
    },
    {
      "x": -17,
      "y": 116,
      "z": -8,
      "name": "Rock_Crystal_Cyan_Block_WhiteLight"
    },
    {
      "x": -17,
      "y": 117,
      "z": -8,
      "name": "Rock_Ice"
    },
    {
      "x": -17,
      "y": 118,
      "z": -8,
      "name": "Rock_Ice"
    },
    {
      "x": -17,
      "y": 130,
      "z": -8,
      "name": "Rock_Ice"
    },
    {
      "x": -17,
      "y": 131,
      "z": -8,
      "name": "Rock_Ice"
    },
    {
      "x": -17,
      "y": 132,
      "z": -8,
      "name": "Rock_Ice"
    },
    {
      "x": -17,
      "y": 133,
      "z": -8,
      "name": "Rock_Ice"
    },
    {
      "x": -17,
      "y": 134,
      "z": -8,
      "name": "Rock_Ice"
    },
    {
      "x": -17,
      "y": 135,
      "z": -8,
      "name": "Rock_Ice"
    },
    {
      "x": -17,
      "y": 136,
      "z": -8,
      "name": "Rock_Ice"
    },
    {
      "x": -17,
      "y": 137,
      "z": -8,
      "name": "Rock_Ice"
    },
    {
      "x": -17,
      "y": 138,
      "z": -8,
      "name": "Soil_Snow"
    },
    {
      "x": -17,
      "y": 26,
      "z": -7,
      "name": "Soil_Snow"
    },
    {
      "x": -17,
      "y": 115,
      "z": -7,
      "name": "Rock_Ice"
    },
    {
      "x": -17,
      "y": 116,
      "z": -7,
      "name": "Rock_Ice_Permafrost"
    },
    {
      "x": -17,
      "y": 117,
      "z": -7,
      "name": "Rock_Ice"
    },
    {
      "x": -17,
      "y": 118,
      "z": -7,
      "name": "Rock_Ice"
    },
    {
      "x": -17,
      "y": 119,
      "z": -7,
      "name": "Rock_Ice"
    },
    {
      "x": -17,
      "y": 120,
      "z": -7,
      "name": "Rock_Ice"
    },
    {
      "x": -17,
      "y": 121,
      "z": -7,
      "name": "Rock_Ice"
    },
    {
      "x": -17,
      "y": 122,
      "z": -7,
      "name": "Rock_Ice"
    },
    {
      "x": -17,
      "y": 123,
      "z": -7,
      "name": "Rock_Ice"
    },
    {
      "x": -17,
      "y": 124,
      "z": -7,
      "name": "Rock_Ice"
    },
    {
      "x": -17,
      "y": 125,
      "z": -7,
      "name": "Rock_Ice"
    },
    {
      "x": -17,
      "y": 126,
      "z": -7,
      "name": "Rock_Ice"
    },
    {
      "x": -17,
      "y": 127,
      "z": -7,
      "name": "Rock_Ice"
    },
    {
      "x": -17,
      "y": 128,
      "z": -7,
      "name": "Rock_Ice"
    },
    {
      "x": -17,
      "y": 129,
      "z": -7,
      "name": "Rock_Ice"
    },
    {
      "x": -17,
      "y": 130,
      "z": -7,
      "name": "Rock_Ice"
    },
    {
      "x": -17,
      "y": 131,
      "z": -7,
      "name": "Rock_Ice"
    },
    {
      "x": -17,
      "y": 132,
      "z": -7,
      "name": "Rock_Ice"
    },
    {
      "x": -17,
      "y": 133,
      "z": -7,
      "name": "Rock_Ice"
    },
    {
      "x": -17,
      "y": 134,
      "z": -7,
      "name": "Rock_Ice"
    },
    {
      "x": -17,
      "y": 135,
      "z": -7,
      "name": "Rock_Ice"
    },
    {
      "x": -17,
      "y": 136,
      "z": -7,
      "name": "Rock_Ice_Permafrost"
    },
    {
      "x": -17,
      "y": 137,
      "z": -7,
      "name": "Rock_Ice_Permafrost"
    },
    {
      "x": -17,
      "y": 138,
      "z": -7,
      "name": "Rock_Ice_Permafrost"
    },
    {
      "x": -17,
      "y": 139,
      "z": -7,
      "name": "Soil_Snow"
    },
    {
      "x": -17,
      "y": 26,
      "z": -6,
      "name": "Soil_Snow"
    },
    {
      "x": -17,
      "y": 106,
      "z": -6,
      "name": "Rock_Ice"
    },
    {
      "x": -17,
      "y": 107,
      "z": -6,
      "name": "Rock_Ice"
    },
    {
      "x": -17,
      "y": 113,
      "z": -6,
      "name": "Rock_Ice"
    },
    {
      "x": -17,
      "y": 114,
      "z": -6,
      "name": "Rock_Ice"
    },
    {
      "x": -17,
      "y": 115,
      "z": -6,
      "name": "Rock_Ice"
    },
    {
      "x": -17,
      "y": 116,
      "z": -6,
      "name": "Rock_Ice"
    },
    {
      "x": -17,
      "y": 117,
      "z": -6,
      "name": "Rock_Ice"
    },
    {
      "x": -17,
      "y": 118,
      "z": -6,
      "name": "Rock_Ice"
    },
    {
      "x": -17,
      "y": 119,
      "z": -6,
      "name": "Rock_Ice"
    },
    {
      "x": -17,
      "y": 120,
      "z": -6,
      "name": "Rock_Ice"
    },
    {
      "x": -17,
      "y": 121,
      "z": -6,
      "name": "Rock_Ice"
    },
    {
      "x": -17,
      "y": 122,
      "z": -6,
      "name": "Rock_Ice"
    },
    {
      "x": -17,
      "y": 123,
      "z": -6,
      "name": "Rock_Ice"
    },
    {
      "x": -17,
      "y": 124,
      "z": -6,
      "name": "Rock_Ice"
    },
    {
      "x": -17,
      "y": 125,
      "z": -6,
      "name": "Rock_Ice"
    },
    {
      "x": -17,
      "y": 126,
      "z": -6,
      "name": "Rock_Ice"
    },
    {
      "x": -17,
      "y": 127,
      "z": -6,
      "name": "Rock_Ice"
    },
    {
      "x": -17,
      "y": 128,
      "z": -6,
      "name": "Rock_Ice"
    },
    {
      "x": -17,
      "y": 129,
      "z": -6,
      "name": "Rock_Ice"
    },
    {
      "x": -17,
      "y": 130,
      "z": -6,
      "name": "Rock_Ice"
    },
    {
      "x": -17,
      "y": 131,
      "z": -6,
      "name": "Rock_Ice"
    },
    {
      "x": -17,
      "y": 132,
      "z": -6,
      "name": "Rock_Ice"
    },
    {
      "x": -17,
      "y": 133,
      "z": -6,
      "name": "Rock_Ice"
    },
    {
      "x": -17,
      "y": 134,
      "z": -6,
      "name": "Rock_Ice_Permafrost"
    },
    {
      "x": -17,
      "y": 135,
      "z": -6,
      "name": "Rock_Ice_Permafrost"
    },
    {
      "x": -17,
      "y": 136,
      "z": -6,
      "name": "Rock_Crystal_Cyan_Block_WhiteLight"
    },
    {
      "x": -17,
      "y": 137,
      "z": -6,
      "name": "Rock_Crystal_Cyan_Block_WhiteLight"
    },
    {
      "x": -17,
      "y": 138,
      "z": -6,
      "name": "Rock_Ice_Permafrost"
    },
    {
      "x": -17,
      "y": 139,
      "z": -6,
      "name": "Rock_Ice_Permafrost"
    },
    {
      "x": -17,
      "y": 140,
      "z": -6,
      "name": "Soil_Snow"
    },
    {
      "x": -17,
      "y": 25,
      "z": -5,
      "name": "Rock_Ice"
    },
    {
      "x": -17,
      "y": 26,
      "z": -5,
      "name": "Rock_Ice"
    },
    {
      "x": -17,
      "y": 27,
      "z": -5,
      "name": "Soil_Snow"
    },
    {
      "x": -17,
      "y": 106,
      "z": -5,
      "name": "Rock_Ice"
    },
    {
      "x": -17,
      "y": 107,
      "z": -5,
      "name": "Rock_Ice"
    },
    {
      "x": -17,
      "y": 108,
      "z": -5,
      "name": "Rock_Ice"
    },
    {
      "x": -17,
      "y": 109,
      "z": -5,
      "name": "Rock_Ice"
    },
    {
      "x": -17,
      "y": 110,
      "z": -5,
      "name": "Rock_Ice"
    },
    {
      "x": -17,
      "y": 111,
      "z": -5,
      "name": "Rock_Ice"
    },
    {
      "x": -17,
      "y": 112,
      "z": -5,
      "name": "Rock_Ice"
    },
    {
      "x": -17,
      "y": 113,
      "z": -5,
      "name": "Rock_Ice"
    },
    {
      "x": -17,
      "y": 114,
      "z": -5,
      "name": "Rock_Ice"
    },
    {
      "x": -17,
      "y": 115,
      "z": -5,
      "name": "Rock_Ice"
    },
    {
      "x": -17,
      "y": 116,
      "z": -5,
      "name": "Rock_Ice"
    },
    {
      "x": -17,
      "y": 117,
      "z": -5,
      "name": "Rock_Ice"
    },
    {
      "x": -17,
      "y": 118,
      "z": -5,
      "name": "Rock_Ice"
    },
    {
      "x": -17,
      "y": 119,
      "z": -5,
      "name": "Rock_Ice"
    },
    {
      "x": -17,
      "y": 120,
      "z": -5,
      "name": "Rock_Ice"
    },
    {
      "x": -17,
      "y": 121,
      "z": -5,
      "name": "Rock_Ice"
    },
    {
      "x": -17,
      "y": 122,
      "z": -5,
      "name": "Rock_Ice"
    },
    {
      "x": -17,
      "y": 123,
      "z": -5,
      "name": "Rock_Ice"
    },
    {
      "x": -17,
      "y": 124,
      "z": -5,
      "name": "Rock_Ice"
    },
    {
      "x": -17,
      "y": 125,
      "z": -5,
      "name": "Rock_Ice"
    },
    {
      "x": -17,
      "y": 126,
      "z": -5,
      "name": "Rock_Ice"
    },
    {
      "x": -17,
      "y": 127,
      "z": -5,
      "name": "Rock_Ice"
    },
    {
      "x": -17,
      "y": 128,
      "z": -5,
      "name": "Rock_Ice"
    },
    {
      "x": -17,
      "y": 129,
      "z": -5,
      "name": "Rock_Ice"
    },
    {
      "x": -17,
      "y": 130,
      "z": -5,
      "name": "Rock_Ice"
    },
    {
      "x": -17,
      "y": 131,
      "z": -5,
      "name": "Rock_Ice"
    },
    {
      "x": -17,
      "y": 132,
      "z": -5,
      "name": "Rock_Ice"
    },
    {
      "x": -17,
      "y": 133,
      "z": -5,
      "name": "Rock_Ice_Permafrost"
    },
    {
      "x": -17,
      "y": 134,
      "z": -5,
      "name": "Rock_Ice_Permafrost"
    },
    {
      "x": -17,
      "y": 135,
      "z": -5,
      "name": "Rock_Crystal_Cyan_Block_WhiteLight"
    },
    {
      "x": -17,
      "y": 136,
      "z": -5,
      "name": "Rock_Ice_Permafrost"
    },
    {
      "x": -17,
      "y": 137,
      "z": -5,
      "name": "Rock_Ice_Permafrost"
    },
    {
      "x": -17,
      "y": 138,
      "z": -5,
      "name": "Rock_Ice"
    },
    {
      "x": -17,
      "y": 139,
      "z": -5,
      "name": "Soil_Snow"
    },
    {
      "x": -17,
      "y": 25,
      "z": -4,
      "name": "Rock_Ice"
    },
    {
      "x": -17,
      "y": 26,
      "z": -4,
      "name": "Rock_Ice"
    },
    {
      "x": -17,
      "y": 27,
      "z": -4,
      "name": "Rock_Ice"
    },
    {
      "x": -17,
      "y": 28,
      "z": -4,
      "name": "Soil_Snow"
    },
    {
      "x": -17,
      "y": 106,
      "z": -4,
      "name": "Rock_Ice"
    },
    {
      "x": -17,
      "y": 107,
      "z": -4,
      "name": "Rock_Ice"
    },
    {
      "x": -17,
      "y": 108,
      "z": -4,
      "name": "Rock_Ice"
    },
    {
      "x": -17,
      "y": 109,
      "z": -4,
      "name": "Rock_Ice"
    },
    {
      "x": -17,
      "y": 110,
      "z": -4,
      "name": "Rock_Ice"
    },
    {
      "x": -17,
      "y": 111,
      "z": -4,
      "name": "Rock_Ice"
    },
    {
      "x": -17,
      "y": 112,
      "z": -4,
      "name": "Rock_Ice"
    },
    {
      "x": -17,
      "y": 113,
      "z": -4,
      "name": "Rock_Ice"
    },
    {
      "x": -17,
      "y": 114,
      "z": -4,
      "name": "Rock_Ice"
    },
    {
      "x": -17,
      "y": 115,
      "z": -4,
      "name": "Rock_Ice"
    },
    {
      "x": -17,
      "y": 116,
      "z": -4,
      "name": "Rock_Ice"
    },
    {
      "x": -17,
      "y": 117,
      "z": -4,
      "name": "Rock_Ice"
    },
    {
      "x": -17,
      "y": 118,
      "z": -4,
      "name": "Rock_Ice"
    },
    {
      "x": -17,
      "y": 119,
      "z": -4,
      "name": "Rock_Ice"
    },
    {
      "x": -17,
      "y": 120,
      "z": -4,
      "name": "Rock_Ice"
    },
    {
      "x": -17,
      "y": 121,
      "z": -4,
      "name": "Rock_Ice"
    },
    {
      "x": -17,
      "y": 122,
      "z": -4,
      "name": "Rock_Ice"
    },
    {
      "x": -17,
      "y": 123,
      "z": -4,
      "name": "Rock_Ice"
    },
    {
      "x": -17,
      "y": 124,
      "z": -4,
      "name": "Rock_Ice"
    },
    {
      "x": -17,
      "y": 125,
      "z": -4,
      "name": "Rock_Ice"
    },
    {
      "x": -17,
      "y": 126,
      "z": -4,
      "name": "Rock_Ice_Permafrost"
    },
    {
      "x": -17,
      "y": 127,
      "z": -4,
      "name": "Rock_Ice"
    },
    {
      "x": -17,
      "y": 128,
      "z": -4,
      "name": "Rock_Ice_Permafrost"
    },
    {
      "x": -17,
      "y": 129,
      "z": -4,
      "name": "Rock_Ice"
    },
    {
      "x": -17,
      "y": 130,
      "z": -4,
      "name": "Rock_Ice"
    },
    {
      "x": -17,
      "y": 131,
      "z": -4,
      "name": "Rock_Ice"
    },
    {
      "x": -17,
      "y": 132,
      "z": -4,
      "name": "Rock_Ice_Permafrost"
    },
    {
      "x": -17,
      "y": 133,
      "z": -4,
      "name": "Rock_Ice_Permafrost"
    },
    {
      "x": -17,
      "y": 134,
      "z": -4,
      "name": "Rock_Ice_Permafrost"
    },
    {
      "x": -17,
      "y": 135,
      "z": -4,
      "name": "Rock_Crystal_Cyan_Block_WhiteLight"
    },
    {
      "x": -17,
      "y": 136,
      "z": -4,
      "name": "Rock_Ice_Permafrost"
    },
    {
      "x": -17,
      "y": 137,
      "z": -4,
      "name": "Rock_Ice"
    },
    {
      "x": -17,
      "y": 138,
      "z": -4,
      "name": "Rock_Ice"
    },
    {
      "x": -17,
      "y": 139,
      "z": -4,
      "name": "Soil_Snow"
    },
    {
      "x": -17,
      "y": 24,
      "z": -3,
      "name": "Rock_Ice"
    },
    {
      "x": -17,
      "y": 25,
      "z": -3,
      "name": "Rock_Ice"
    },
    {
      "x": -17,
      "y": 26,
      "z": -3,
      "name": "Rock_Ice"
    },
    {
      "x": -17,
      "y": 27,
      "z": -3,
      "name": "Rock_Ice"
    },
    {
      "x": -17,
      "y": 28,
      "z": -3,
      "name": "Soil_Snow"
    },
    {
      "x": -17,
      "y": 105,
      "z": -3,
      "name": "Rock_Ice_Permafrost"
    },
    {
      "x": -17,
      "y": 106,
      "z": -3,
      "name": "Rock_Ice"
    },
    {
      "x": -17,
      "y": 107,
      "z": -3,
      "name": "Rock_Ice"
    },
    {
      "x": -17,
      "y": 108,
      "z": -3,
      "name": "Rock_Ice"
    },
    {
      "x": -17,
      "y": 109,
      "z": -3,
      "name": "Rock_Ice"
    },
    {
      "x": -17,
      "y": 110,
      "z": -3,
      "name": "Rock_Ice"
    },
    {
      "x": -17,
      "y": 111,
      "z": -3,
      "name": "Rock_Ice"
    },
    {
      "x": -17,
      "y": 112,
      "z": -3,
      "name": "Rock_Ice"
    },
    {
      "x": -17,
      "y": 113,
      "z": -3,
      "name": "Rock_Ice"
    },
    {
      "x": -17,
      "y": 114,
      "z": -3,
      "name": "Rock_Ice"
    },
    {
      "x": -17,
      "y": 115,
      "z": -3,
      "name": "Rock_Ice"
    },
    {
      "x": -17,
      "y": 116,
      "z": -3,
      "name": "Rock_Ice"
    },
    {
      "x": -17,
      "y": 117,
      "z": -3,
      "name": "Rock_Ice_Permafrost"
    },
    {
      "x": -17,
      "y": 118,
      "z": -3,
      "name": "Rock_Ice"
    },
    {
      "x": -17,
      "y": 119,
      "z": -3,
      "name": "Rock_Ice_Permafrost"
    },
    {
      "x": -17,
      "y": 120,
      "z": -3,
      "name": "Rock_Ice_Permafrost"
    },
    {
      "x": -17,
      "y": 121,
      "z": -3,
      "name": "Rock_Ice_Permafrost"
    },
    {
      "x": -17,
      "y": 122,
      "z": -3,
      "name": "Rock_Ice"
    },
    {
      "x": -17,
      "y": 123,
      "z": -3,
      "name": "Rock_Ice"
    },
    {
      "x": -17,
      "y": 124,
      "z": -3,
      "name": "Rock_Ice_Permafrost"
    },
    {
      "x": -17,
      "y": 125,
      "z": -3,
      "name": "Rock_Ice_Permafrost"
    },
    {
      "x": -17,
      "y": 126,
      "z": -3,
      "name": "Rock_Ice_Permafrost"
    },
    {
      "x": -17,
      "y": 127,
      "z": -3,
      "name": "Rock_Ice"
    },
    {
      "x": -17,
      "y": 128,
      "z": -3,
      "name": "Rock_Ice_Permafrost"
    },
    {
      "x": -17,
      "y": 129,
      "z": -3,
      "name": "Rock_Ice"
    },
    {
      "x": -17,
      "y": 130,
      "z": -3,
      "name": "Rock_Ice_Permafrost"
    },
    {
      "x": -17,
      "y": 131,
      "z": -3,
      "name": "Rock_Ice_Permafrost"
    },
    {
      "x": -17,
      "y": 132,
      "z": -3,
      "name": "Rock_Ice_Permafrost"
    },
    {
      "x": -17,
      "y": 133,
      "z": -3,
      "name": "Rock_Ice_Permafrost"
    },
    {
      "x": -17,
      "y": 134,
      "z": -3,
      "name": "Rock_Ice_Permafrost"
    },
    {
      "x": -17,
      "y": 135,
      "z": -3,
      "name": "Rock_Ice_Permafrost"
    },
    {
      "x": -17,
      "y": 136,
      "z": -3,
      "name": "Rock_Ice"
    },
    {
      "x": -17,
      "y": 137,
      "z": -3,
      "name": "Rock_Ice"
    },
    {
      "x": -17,
      "y": 138,
      "z": -3,
      "name": "Rock_Ice"
    },
    {
      "x": -17,
      "y": 139,
      "z": -3,
      "name": "Soil_Snow"
    },
    {
      "x": -17,
      "y": 23,
      "z": -2,
      "name": "Rock_Ice"
    },
    {
      "x": -17,
      "y": 24,
      "z": -2,
      "name": "Rock_Ice"
    },
    {
      "x": -17,
      "y": 25,
      "z": -2,
      "name": "Rock_Ice"
    },
    {
      "x": -17,
      "y": 26,
      "z": -2,
      "name": "Rock_Ice"
    },
    {
      "x": -17,
      "y": 27,
      "z": -2,
      "name": "Rock_Ice"
    },
    {
      "x": -17,
      "y": 28,
      "z": -2,
      "name": "Soil_Snow"
    },
    {
      "x": -17,
      "y": 102,
      "z": -2,
      "name": "Rock_Ice_Permafrost"
    },
    {
      "x": -17,
      "y": 103,
      "z": -2,
      "name": "Rock_Crystal_Cyan_Block_WhiteLight"
    },
    {
      "x": -17,
      "y": 104,
      "z": -2,
      "name": "Rock_Ice_Permafrost"
    },
    {
      "x": -17,
      "y": 105,
      "z": -2,
      "name": "Rock_Ice"
    },
    {
      "x": -17,
      "y": 106,
      "z": -2,
      "name": "Rock_Ice"
    },
    {
      "x": -17,
      "y": 107,
      "z": -2,
      "name": "Rock_Ice"
    },
    {
      "x": -17,
      "y": 108,
      "z": -2,
      "name": "Rock_Ice"
    },
    {
      "x": -17,
      "y": 109,
      "z": -2,
      "name": "Rock_Ice"
    },
    {
      "x": -17,
      "y": 110,
      "z": -2,
      "name": "Rock_Ice"
    },
    {
      "x": -17,
      "y": 111,
      "z": -2,
      "name": "Rock_Ice"
    },
    {
      "x": -17,
      "y": 112,
      "z": -2,
      "name": "Rock_Ice"
    },
    {
      "x": -17,
      "y": 113,
      "z": -2,
      "name": "Rock_Ice"
    },
    {
      "x": -17,
      "y": 114,
      "z": -2,
      "name": "Rock_Ice"
    },
    {
      "x": -17,
      "y": 115,
      "z": -2,
      "name": "Rock_Ice"
    },
    {
      "x": -17,
      "y": 116,
      "z": -2,
      "name": "Rock_Ice"
    },
    {
      "x": -17,
      "y": 117,
      "z": -2,
      "name": "Rock_Ice_Permafrost"
    },
    {
      "x": -17,
      "y": 118,
      "z": -2,
      "name": "Rock_Ice_Permafrost"
    },
    {
      "x": -17,
      "y": 119,
      "z": -2,
      "name": "Rock_Ice_Permafrost"
    },
    {
      "x": -17,
      "y": 120,
      "z": -2,
      "name": "Rock_Ice_Permafrost"
    },
    {
      "x": -17,
      "y": 121,
      "z": -2,
      "name": "Rock_Ice_Permafrost"
    },
    {
      "x": -17,
      "y": 122,
      "z": -2,
      "name": "Rock_Ice_Permafrost"
    },
    {
      "x": -17,
      "y": 123,
      "z": -2,
      "name": "Rock_Ice_Permafrost"
    },
    {
      "x": -17,
      "y": 124,
      "z": -2,
      "name": "Rock_Crystal_Cyan_Block_WhiteLight"
    },
    {
      "x": -17,
      "y": 125,
      "z": -2,
      "name": "Rock_Ice_Permafrost"
    },
    {
      "x": -17,
      "y": 126,
      "z": -2,
      "name": "Rock_Ice_Permafrost"
    },
    {
      "x": -17,
      "y": 127,
      "z": -2,
      "name": "Rock_Ice_Permafrost"
    },
    {
      "x": -17,
      "y": 128,
      "z": -2,
      "name": "Rock_Ice_Permafrost"
    },
    {
      "x": -17,
      "y": 129,
      "z": -2,
      "name": "Rock_Ice_Permafrost"
    },
    {
      "x": -17,
      "y": 130,
      "z": -2,
      "name": "Rock_Ice_Permafrost"
    },
    {
      "x": -17,
      "y": 131,
      "z": -2,
      "name": "Rock_Ice_Permafrost"
    },
    {
      "x": -17,
      "y": 132,
      "z": -2,
      "name": "Rock_Ice_Permafrost"
    },
    {
      "x": -17,
      "y": 133,
      "z": -2,
      "name": "Rock_Ice"
    },
    {
      "x": -17,
      "y": 134,
      "z": -2,
      "name": "Rock_Ice"
    },
    {
      "x": -17,
      "y": 135,
      "z": -2,
      "name": "Rock_Ice"
    },
    {
      "x": -17,
      "y": 136,
      "z": -2,
      "name": "Rock_Ice"
    },
    {
      "x": -17,
      "y": 137,
      "z": -2,
      "name": "Rock_Ice"
    },
    {
      "x": -17,
      "y": 138,
      "z": -2,
      "name": "Soil_Snow"
    },
    {
      "x": -17,
      "y": 21,
      "z": -1,
      "name": "Rock_Ice"
    },
    {
      "x": -17,
      "y": 22,
      "z": -1,
      "name": "Rock_Ice"
    },
    {
      "x": -17,
      "y": 23,
      "z": -1,
      "name": "Rock_Ice"
    },
    {
      "x": -17,
      "y": 24,
      "z": -1,
      "name": "Rock_Ice"
    },
    {
      "x": -17,
      "y": 25,
      "z": -1,
      "name": "Rock_Ice"
    },
    {
      "x": -17,
      "y": 26,
      "z": -1,
      "name": "Rock_Ice"
    },
    {
      "x": -17,
      "y": 27,
      "z": -1,
      "name": "Rock_Ice"
    },
    {
      "x": -17,
      "y": 28,
      "z": -1,
      "name": "Soil_Snow"
    },
    {
      "x": -17,
      "y": 103,
      "z": -1,
      "name": "Rock_Ice"
    },
    {
      "x": -17,
      "y": 104,
      "z": -1,
      "name": "Rock_Ice_Permafrost"
    },
    {
      "x": -17,
      "y": 105,
      "z": -1,
      "name": "Rock_Ice_Permafrost"
    },
    {
      "x": -17,
      "y": 106,
      "z": -1,
      "name": "Rock_Ice"
    },
    {
      "x": -17,
      "y": 107,
      "z": -1,
      "name": "Rock_Ice"
    },
    {
      "x": -17,
      "y": 108,
      "z": -1,
      "name": "Rock_Ice"
    },
    {
      "x": -17,
      "y": 109,
      "z": -1,
      "name": "Rock_Ice"
    },
    {
      "x": -17,
      "y": 110,
      "z": -1,
      "name": "Rock_Ice"
    },
    {
      "x": -17,
      "y": 111,
      "z": -1,
      "name": "Rock_Ice"
    },
    {
      "x": -17,
      "y": 112,
      "z": -1,
      "name": "Rock_Ice"
    },
    {
      "x": -17,
      "y": 113,
      "z": -1,
      "name": "Rock_Ice"
    },
    {
      "x": -17,
      "y": 114,
      "z": -1,
      "name": "Rock_Ice"
    },
    {
      "x": -17,
      "y": 115,
      "z": -1,
      "name": "Rock_Ice"
    },
    {
      "x": -17,
      "y": 116,
      "z": -1,
      "name": "Rock_Ice"
    },
    {
      "x": -17,
      "y": 117,
      "z": -1,
      "name": "Rock_Ice"
    },
    {
      "x": -17,
      "y": 118,
      "z": -1,
      "name": "Rock_Ice_Permafrost"
    },
    {
      "x": -17,
      "y": 119,
      "z": -1,
      "name": "Rock_Ice_Permafrost"
    },
    {
      "x": -17,
      "y": 120,
      "z": -1,
      "name": "Rock_Ice_Permafrost"
    },
    {
      "x": -17,
      "y": 121,
      "z": -1,
      "name": "Rock_Crystal_Cyan_Block_WhiteLight"
    },
    {
      "x": -17,
      "y": 122,
      "z": -1,
      "name": "Rock_Crystal_Cyan_Block_WhiteLight"
    },
    {
      "x": -17,
      "y": 123,
      "z": -1,
      "name": "Rock_Ice_Permafrost"
    },
    {
      "x": -17,
      "y": 124,
      "z": -1,
      "name": "Rock_Crystal_Cyan_Block_WhiteLight"
    },
    {
      "x": -17,
      "y": 125,
      "z": -1,
      "name": "Rock_Crystal_Cyan_Block_WhiteLight"
    },
    {
      "x": -17,
      "y": 126,
      "z": -1,
      "name": "Rock_Ice_Permafrost"
    },
    {
      "x": -17,
      "y": 127,
      "z": -1,
      "name": "Rock_Ice_Permafrost"
    },
    {
      "x": -17,
      "y": 128,
      "z": -1,
      "name": "Rock_Ice_Permafrost"
    },
    {
      "x": -17,
      "y": 129,
      "z": -1,
      "name": "Rock_Ice_Permafrost"
    },
    {
      "x": -17,
      "y": 130,
      "z": -1,
      "name": "Rock_Ice_Permafrost"
    },
    {
      "x": -17,
      "y": 131,
      "z": -1,
      "name": "Rock_Ice_Permafrost"
    },
    {
      "x": -17,
      "y": 132,
      "z": -1,
      "name": "Rock_Ice_Permafrost"
    },
    {
      "x": -17,
      "y": 133,
      "z": -1,
      "name": "Rock_Ice"
    },
    {
      "x": -17,
      "y": 134,
      "z": -1,
      "name": "Rock_Ice"
    },
    {
      "x": -17,
      "y": 135,
      "z": -1,
      "name": "Rock_Ice"
    },
    {
      "x": -17,
      "y": 136,
      "z": -1,
      "name": "Rock_Ice"
    },
    {
      "x": -17,
      "y": 137,
      "z": -1,
      "name": "Rock_Ice"
    },
    {
      "x": -17,
      "y": 138,
      "z": -1,
      "name": "Soil_Snow"
    },
    {
      "x": -17,
      "y": 18,
      "z": 0,
      "name": "Rock_Ice_Permafrost"
    },
    {
      "x": -17,
      "y": 19,
      "z": 0,
      "name": "Rock_Ice_Permafrost"
    },
    {
      "x": -17,
      "y": 20,
      "z": 0,
      "name": "Rock_Ice"
    },
    {
      "x": -17,
      "y": 21,
      "z": 0,
      "name": "Rock_Ice_Permafrost"
    },
    {
      "x": -17,
      "y": 22,
      "z": 0,
      "name": "Rock_Ice_Permafrost"
    },
    {
      "x": -17,
      "y": 23,
      "z": 0,
      "name": "Rock_Ice"
    },
    {
      "x": -17,
      "y": 24,
      "z": 0,
      "name": "Rock_Ice"
    },
    {
      "x": -17,
      "y": 25,
      "z": 0,
      "name": "Rock_Ice"
    },
    {
      "x": -17,
      "y": 26,
      "z": 0,
      "name": "Rock_Ice"
    },
    {
      "x": -17,
      "y": 27,
      "z": 0,
      "name": "Rock_Ice"
    },
    {
      "x": -17,
      "y": 28,
      "z": 0,
      "name": "Rock_Ice"
    },
    {
      "x": -17,
      "y": 29,
      "z": 0,
      "name": "Soil_Snow"
    },
    {
      "x": -17,
      "y": 103,
      "z": 0,
      "name": "Rock_Ice"
    },
    {
      "x": -17,
      "y": 104,
      "z": 0,
      "name": "Rock_Ice"
    },
    {
      "x": -17,
      "y": 105,
      "z": 0,
      "name": "Rock_Ice_Permafrost"
    },
    {
      "x": -17,
      "y": 106,
      "z": 0,
      "name": "Rock_Ice"
    },
    {
      "x": -17,
      "y": 107,
      "z": 0,
      "name": "Rock_Ice"
    },
    {
      "x": -17,
      "y": 108,
      "z": 0,
      "name": "Rock_Ice"
    },
    {
      "x": -17,
      "y": 109,
      "z": 0,
      "name": "Rock_Ice"
    },
    {
      "x": -17,
      "y": 110,
      "z": 0,
      "name": "Rock_Ice"
    },
    {
      "x": -17,
      "y": 111,
      "z": 0,
      "name": "Rock_Ice"
    },
    {
      "x": -17,
      "y": 112,
      "z": 0,
      "name": "Rock_Ice"
    },
    {
      "x": -17,
      "y": 113,
      "z": 0,
      "name": "Rock_Ice"
    },
    {
      "x": -17,
      "y": 114,
      "z": 0,
      "name": "Rock_Ice"
    },
    {
      "x": -17,
      "y": 115,
      "z": 0,
      "name": "Rock_Ice"
    },
    {
      "x": -17,
      "y": 116,
      "z": 0,
      "name": "Rock_Ice"
    },
    {
      "x": -17,
      "y": 117,
      "z": 0,
      "name": "Rock_Ice"
    },
    {
      "x": -17,
      "y": 118,
      "z": 0,
      "name": "Rock_Ice_Permafrost"
    },
    {
      "x": -17,
      "y": 119,
      "z": 0,
      "name": "Rock_Ice_Permafrost"
    },
    {
      "x": -17,
      "y": 120,
      "z": 0,
      "name": "Rock_Ice"
    },
    {
      "x": -17,
      "y": 121,
      "z": 0,
      "name": "Rock_Ice_Permafrost"
    },
    {
      "x": -17,
      "y": 122,
      "z": 0,
      "name": "Rock_Ice_Permafrost"
    },
    {
      "x": -17,
      "y": 123,
      "z": 0,
      "name": "Rock_Crystal_Cyan_Block_WhiteLight"
    },
    {
      "x": -17,
      "y": 124,
      "z": 0,
      "name": "Rock_Ice_Permafrost"
    },
    {
      "x": -17,
      "y": 125,
      "z": 0,
      "name": "Rock_Ice_Permafrost"
    },
    {
      "x": -17,
      "y": 126,
      "z": 0,
      "name": "Rock_Ice_Permafrost"
    },
    {
      "x": -17,
      "y": 127,
      "z": 0,
      "name": "Rock_Ice_Permafrost"
    },
    {
      "x": -17,
      "y": 128,
      "z": 0,
      "name": "Rock_Crystal_Cyan_Block_WhiteLight"
    },
    {
      "x": -17,
      "y": 129,
      "z": 0,
      "name": "Rock_Ice_Permafrost"
    },
    {
      "x": -17,
      "y": 130,
      "z": 0,
      "name": "Rock_Ice"
    },
    {
      "x": -17,
      "y": 131,
      "z": 0,
      "name": "Rock_Ice"
    },
    {
      "x": -17,
      "y": 132,
      "z": 0,
      "name": "Rock_Ice_Permafrost"
    },
    {
      "x": -17,
      "y": 133,
      "z": 0,
      "name": "Rock_Ice"
    },
    {
      "x": -17,
      "y": 134,
      "z": 0,
      "name": "Rock_Ice"
    },
    {
      "x": -17,
      "y": 135,
      "z": 0,
      "name": "Rock_Ice"
    },
    {
      "x": -17,
      "y": 136,
      "z": 0,
      "name": "Rock_Ice"
    },
    {
      "x": -17,
      "y": 137,
      "z": 0,
      "name": "Soil_Snow"
    },
    {
      "x": -17,
      "y": 15,
      "z": 1,
      "name": "Rock_Ice_Permafrost"
    },
    {
      "x": -17,
      "y": 16,
      "z": 1,
      "name": "Rock_Crystal_Cyan_Block_WhiteLight"
    },
    {
      "x": -17,
      "y": 17,
      "z": 1,
      "name": "Rock_Ice_Permafrost"
    },
    {
      "x": -17,
      "y": 18,
      "z": 1,
      "name": "Rock_Crystal_Cyan_Block_WhiteLight"
    },
    {
      "x": -17,
      "y": 19,
      "z": 1,
      "name": "Rock_Ice_Permafrost"
    },
    {
      "x": -17,
      "y": 20,
      "z": 1,
      "name": "Rock_Ice_Permafrost"
    },
    {
      "x": -17,
      "y": 21,
      "z": 1,
      "name": "Rock_Crystal_Cyan_Block_WhiteLight"
    },
    {
      "x": -17,
      "y": 22,
      "z": 1,
      "name": "Rock_Ice_Permafrost"
    },
    {
      "x": -17,
      "y": 23,
      "z": 1,
      "name": "Rock_Ice"
    },
    {
      "x": -17,
      "y": 24,
      "z": 1,
      "name": "Rock_Ice"
    },
    {
      "x": -17,
      "y": 25,
      "z": 1,
      "name": "Rock_Ice"
    },
    {
      "x": -17,
      "y": 26,
      "z": 1,
      "name": "Rock_Ice"
    },
    {
      "x": -17,
      "y": 27,
      "z": 1,
      "name": "Rock_Ice"
    },
    {
      "x": -17,
      "y": 28,
      "z": 1,
      "name": "Rock_Ice"
    },
    {
      "x": -17,
      "y": 29,
      "z": 1,
      "name": "Soil_Snow"
    },
    {
      "x": -17,
      "y": 102,
      "z": 1,
      "name": "Rock_Ice"
    },
    {
      "x": -17,
      "y": 103,
      "z": 1,
      "name": "Rock_Ice"
    },
    {
      "x": -17,
      "y": 104,
      "z": 1,
      "name": "Rock_Ice"
    },
    {
      "x": -17,
      "y": 105,
      "z": 1,
      "name": "Rock_Ice"
    },
    {
      "x": -17,
      "y": 106,
      "z": 1,
      "name": "Rock_Ice"
    },
    {
      "x": -17,
      "y": 107,
      "z": 1,
      "name": "Rock_Ice"
    },
    {
      "x": -17,
      "y": 108,
      "z": 1,
      "name": "Rock_Ice"
    },
    {
      "x": -17,
      "y": 109,
      "z": 1,
      "name": "Rock_Ice"
    },
    {
      "x": -17,
      "y": 110,
      "z": 1,
      "name": "Rock_Ice"
    },
    {
      "x": -17,
      "y": 111,
      "z": 1,
      "name": "Rock_Ice"
    },
    {
      "x": -17,
      "y": 112,
      "z": 1,
      "name": "Rock_Ice"
    },
    {
      "x": -17,
      "y": 113,
      "z": 1,
      "name": "Rock_Ice"
    },
    {
      "x": -17,
      "y": 114,
      "z": 1,
      "name": "Rock_Ice"
    },
    {
      "x": -17,
      "y": 115,
      "z": 1,
      "name": "Rock_Ice"
    },
    {
      "x": -17,
      "y": 116,
      "z": 1,
      "name": "Rock_Ice"
    },
    {
      "x": -17,
      "y": 117,
      "z": 1,
      "name": "Rock_Ice_Permafrost"
    },
    {
      "x": -17,
      "y": 118,
      "z": 1,
      "name": "Rock_Ice_Permafrost"
    },
    {
      "x": -17,
      "y": 119,
      "z": 1,
      "name": "Rock_Ice"
    },
    {
      "x": -17,
      "y": 120,
      "z": 1,
      "name": "Rock_Ice"
    },
    {
      "x": -17,
      "y": 121,
      "z": 1,
      "name": "Rock_Ice"
    },
    {
      "x": -17,
      "y": 122,
      "z": 1,
      "name": "Rock_Ice_Permafrost"
    },
    {
      "x": -17,
      "y": 123,
      "z": 1,
      "name": "Rock_Ice_Permafrost"
    },
    {
      "x": -17,
      "y": 124,
      "z": 1,
      "name": "Rock_Ice_Permafrost"
    },
    {
      "x": -17,
      "y": 125,
      "z": 1,
      "name": "Rock_Crystal_Cyan_Block_WhiteLight"
    },
    {
      "x": -17,
      "y": 126,
      "z": 1,
      "name": "Rock_Ice_Permafrost"
    },
    {
      "x": -17,
      "y": 127,
      "z": 1,
      "name": "Rock_Ice_Permafrost"
    },
    {
      "x": -17,
      "y": 128,
      "z": 1,
      "name": "Rock_Ice_Permafrost"
    },
    {
      "x": -17,
      "y": 129,
      "z": 1,
      "name": "Rock_Ice"
    },
    {
      "x": -17,
      "y": 130,
      "z": 1,
      "name": "Rock_Ice"
    },
    {
      "x": -17,
      "y": 131,
      "z": 1,
      "name": "Rock_Ice"
    },
    {
      "x": -17,
      "y": 132,
      "z": 1,
      "name": "Rock_Ice"
    },
    {
      "x": -17,
      "y": 133,
      "z": 1,
      "name": "Rock_Ice"
    },
    {
      "x": -17,
      "y": 134,
      "z": 1,
      "name": "Rock_Ice"
    },
    {
      "x": -17,
      "y": 135,
      "z": 1,
      "name": "Rock_Ice"
    },
    {
      "x": -17,
      "y": 136,
      "z": 1,
      "name": "Rock_Ice"
    },
    {
      "x": -17,
      "y": 137,
      "z": 1,
      "name": "Soil_Snow"
    },
    {
      "x": -17,
      "y": 15,
      "z": 2,
      "name": "Rock_Crystal_Cyan_Block_WhiteLight"
    },
    {
      "x": -17,
      "y": 16,
      "z": 2,
      "name": "Rock_Ice_Permafrost"
    },
    {
      "x": -17,
      "y": 17,
      "z": 2,
      "name": "Rock_Ice_Permafrost"
    },
    {
      "x": -17,
      "y": 18,
      "z": 2,
      "name": "Rock_Ice_Permafrost"
    },
    {
      "x": -17,
      "y": 19,
      "z": 2,
      "name": "Rock_Ice_Permafrost"
    },
    {
      "x": -17,
      "y": 20,
      "z": 2,
      "name": "Rock_Ice_Permafrost"
    },
    {
      "x": -17,
      "y": 21,
      "z": 2,
      "name": "Rock_Ice_Permafrost"
    },
    {
      "x": -17,
      "y": 22,
      "z": 2,
      "name": "Rock_Ice"
    },
    {
      "x": -17,
      "y": 23,
      "z": 2,
      "name": "Rock_Ice"
    },
    {
      "x": -17,
      "y": 24,
      "z": 2,
      "name": "Rock_Ice"
    },
    {
      "x": -17,
      "y": 25,
      "z": 2,
      "name": "Rock_Ice"
    },
    {
      "x": -17,
      "y": 26,
      "z": 2,
      "name": "Rock_Ice"
    },
    {
      "x": -17,
      "y": 27,
      "z": 2,
      "name": "Rock_Ice"
    },
    {
      "x": -17,
      "y": 28,
      "z": 2,
      "name": "Rock_Ice"
    },
    {
      "x": -17,
      "y": 29,
      "z": 2,
      "name": "Rock_Ice"
    },
    {
      "x": -17,
      "y": 30,
      "z": 2,
      "name": "Soil_Snow"
    },
    {
      "x": -17,
      "y": 103,
      "z": 2,
      "name": "Rock_Ice"
    },
    {
      "x": -17,
      "y": 104,
      "z": 2,
      "name": "Rock_Ice"
    },
    {
      "x": -17,
      "y": 105,
      "z": 2,
      "name": "Rock_Ice"
    },
    {
      "x": -17,
      "y": 106,
      "z": 2,
      "name": "Rock_Ice"
    },
    {
      "x": -17,
      "y": 107,
      "z": 2,
      "name": "Rock_Ice"
    },
    {
      "x": -17,
      "y": 108,
      "z": 2,
      "name": "Rock_Ice"
    },
    {
      "x": -17,
      "y": 109,
      "z": 2,
      "name": "Rock_Ice"
    },
    {
      "x": -17,
      "y": 110,
      "z": 2,
      "name": "Rock_Ice_Permafrost"
    },
    {
      "x": -17,
      "y": 111,
      "z": 2,
      "name": "Rock_Ice_Permafrost"
    },
    {
      "x": -17,
      "y": 112,
      "z": 2,
      "name": "Rock_Ice"
    },
    {
      "x": -17,
      "y": 113,
      "z": 2,
      "name": "Rock_Ice"
    },
    {
      "x": -17,
      "y": 114,
      "z": 2,
      "name": "Rock_Ice"
    },
    {
      "x": -17,
      "y": 115,
      "z": 2,
      "name": "Rock_Ice_Permafrost"
    },
    {
      "x": -17,
      "y": 116,
      "z": 2,
      "name": "Rock_Ice_Permafrost"
    },
    {
      "x": -17,
      "y": 117,
      "z": 2,
      "name": "Rock_Ice_Permafrost"
    },
    {
      "x": -17,
      "y": 118,
      "z": 2,
      "name": "Rock_Ice"
    },
    {
      "x": -17,
      "y": 119,
      "z": 2,
      "name": "Rock_Ice"
    },
    {
      "x": -17,
      "y": 120,
      "z": 2,
      "name": "Rock_Ice"
    },
    {
      "x": -17,
      "y": 121,
      "z": 2,
      "name": "Rock_Ice_Permafrost"
    },
    {
      "x": -17,
      "y": 122,
      "z": 2,
      "name": "Rock_Ice"
    },
    {
      "x": -17,
      "y": 123,
      "z": 2,
      "name": "Rock_Ice_Permafrost"
    },
    {
      "x": -17,
      "y": 124,
      "z": 2,
      "name": "Rock_Ice_Permafrost"
    },
    {
      "x": -17,
      "y": 125,
      "z": 2,
      "name": "Rock_Crystal_Cyan_Block_WhiteLight"
    },
    {
      "x": -17,
      "y": 126,
      "z": 2,
      "name": "Rock_Crystal_Cyan_Block_WhiteLight"
    },
    {
      "x": -17,
      "y": 127,
      "z": 2,
      "name": "Rock_Crystal_Cyan_Block_WhiteLight"
    },
    {
      "x": -17,
      "y": 128,
      "z": 2,
      "name": "Rock_Ice_Permafrost"
    },
    {
      "x": -17,
      "y": 129,
      "z": 2,
      "name": "Rock_Ice_Permafrost"
    },
    {
      "x": -17,
      "y": 130,
      "z": 2,
      "name": "Rock_Ice_Permafrost"
    },
    {
      "x": -17,
      "y": 131,
      "z": 2,
      "name": "Rock_Ice_Permafrost"
    },
    {
      "x": -17,
      "y": 132,
      "z": 2,
      "name": "Rock_Ice"
    },
    {
      "x": -17,
      "y": 133,
      "z": 2,
      "name": "Rock_Ice"
    },
    {
      "x": -17,
      "y": 134,
      "z": 2,
      "name": "Rock_Ice"
    },
    {
      "x": -17,
      "y": 135,
      "z": 2,
      "name": "Rock_Ice"
    },
    {
      "x": -17,
      "y": 136,
      "z": 2,
      "name": "Rock_Ice"
    },
    {
      "x": -17,
      "y": 137,
      "z": 2,
      "name": "Soil_Snow"
    },
    {
      "x": -17,
      "y": 14,
      "z": 3,
      "name": "Rock_Ice_Permafrost"
    },
    {
      "x": -17,
      "y": 15,
      "z": 3,
      "name": "Rock_Ice_Permafrost"
    },
    {
      "x": -17,
      "y": 16,
      "z": 3,
      "name": "Rock_Ice_Permafrost"
    },
    {
      "x": -17,
      "y": 17,
      "z": 3,
      "name": "Rock_Ice"
    },
    {
      "x": -17,
      "y": 18,
      "z": 3,
      "name": "Rock_Ice"
    },
    {
      "x": -17,
      "y": 19,
      "z": 3,
      "name": "Rock_Ice"
    },
    {
      "x": -17,
      "y": 20,
      "z": 3,
      "name": "Rock_Ice"
    },
    {
      "x": -17,
      "y": 21,
      "z": 3,
      "name": "Rock_Ice_Permafrost"
    },
    {
      "x": -17,
      "y": 22,
      "z": 3,
      "name": "Rock_Ice"
    },
    {
      "x": -17,
      "y": 23,
      "z": 3,
      "name": "Rock_Ice"
    },
    {
      "x": -17,
      "y": 24,
      "z": 3,
      "name": "Rock_Ice"
    },
    {
      "x": -17,
      "y": 25,
      "z": 3,
      "name": "Rock_Ice"
    },
    {
      "x": -17,
      "y": 26,
      "z": 3,
      "name": "Rock_Ice"
    },
    {
      "x": -17,
      "y": 27,
      "z": 3,
      "name": "Rock_Ice"
    },
    {
      "x": -17,
      "y": 28,
      "z": 3,
      "name": "Rock_Ice"
    },
    {
      "x": -17,
      "y": 29,
      "z": 3,
      "name": "Rock_Ice"
    },
    {
      "x": -17,
      "y": 30,
      "z": 3,
      "name": "Rock_Ice"
    },
    {
      "x": -17,
      "y": 31,
      "z": 3,
      "name": "Soil_Snow"
    },
    {
      "x": -17,
      "y": 104,
      "z": 3,
      "name": "Rock_Ice"
    },
    {
      "x": -17,
      "y": 105,
      "z": 3,
      "name": "Rock_Ice"
    },
    {
      "x": -17,
      "y": 106,
      "z": 3,
      "name": "Rock_Ice"
    },
    {
      "x": -17,
      "y": 107,
      "z": 3,
      "name": "Rock_Ice"
    },
    {
      "x": -17,
      "y": 108,
      "z": 3,
      "name": "Rock_Ice"
    },
    {
      "x": -17,
      "y": 109,
      "z": 3,
      "name": "Rock_Ice"
    },
    {
      "x": -17,
      "y": 110,
      "z": 3,
      "name": "Rock_Ice"
    },
    {
      "x": -17,
      "y": 111,
      "z": 3,
      "name": "Rock_Ice"
    },
    {
      "x": -17,
      "y": 112,
      "z": 3,
      "name": "Rock_Ice_Permafrost"
    },
    {
      "x": -17,
      "y": 113,
      "z": 3,
      "name": "Rock_Ice_Permafrost"
    },
    {
      "x": -17,
      "y": 114,
      "z": 3,
      "name": "Rock_Ice_Permafrost"
    },
    {
      "x": -17,
      "y": 115,
      "z": 3,
      "name": "Rock_Ice_Permafrost"
    },
    {
      "x": -17,
      "y": 116,
      "z": 3,
      "name": "Rock_Ice_Permafrost"
    },
    {
      "x": -17,
      "y": 117,
      "z": 3,
      "name": "Rock_Ice_Permafrost"
    },
    {
      "x": -17,
      "y": 118,
      "z": 3,
      "name": "Rock_Ice"
    },
    {
      "x": -17,
      "y": 119,
      "z": 3,
      "name": "Rock_Ice"
    },
    {
      "x": -17,
      "y": 120,
      "z": 3,
      "name": "Rock_Ice"
    },
    {
      "x": -17,
      "y": 121,
      "z": 3,
      "name": "Rock_Ice"
    },
    {
      "x": -17,
      "y": 122,
      "z": 3,
      "name": "Rock_Ice"
    },
    {
      "x": -17,
      "y": 123,
      "z": 3,
      "name": "Rock_Ice"
    },
    {
      "x": -17,
      "y": 124,
      "z": 3,
      "name": "Rock_Ice"
    },
    {
      "x": -17,
      "y": 125,
      "z": 3,
      "name": "Rock_Crystal_Cyan_Block_WhiteLight"
    },
    {
      "x": -17,
      "y": 126,
      "z": 3,
      "name": "Rock_Crystal_Cyan_Block_WhiteLight"
    },
    {
      "x": -17,
      "y": 127,
      "z": 3,
      "name": "Rock_Ice_Permafrost"
    },
    {
      "x": -17,
      "y": 128,
      "z": 3,
      "name": "Rock_Crystal_Cyan_Block_WhiteLight"
    },
    {
      "x": -17,
      "y": 129,
      "z": 3,
      "name": "Rock_Crystal_Cyan_Block_WhiteLight"
    },
    {
      "x": -17,
      "y": 130,
      "z": 3,
      "name": "Rock_Ice"
    },
    {
      "x": -17,
      "y": 131,
      "z": 3,
      "name": "Rock_Ice"
    },
    {
      "x": -17,
      "y": 132,
      "z": 3,
      "name": "Rock_Ice"
    },
    {
      "x": -17,
      "y": 133,
      "z": 3,
      "name": "Rock_Ice"
    },
    {
      "x": -17,
      "y": 134,
      "z": 3,
      "name": "Rock_Ice"
    },
    {
      "x": -17,
      "y": 135,
      "z": 3,
      "name": "Rock_Ice"
    },
    {
      "x": -17,
      "y": 136,
      "z": 3,
      "name": "Rock_Ice"
    },
    {
      "x": -17,
      "y": 137,
      "z": 3,
      "name": "Soil_Snow"
    },
    {
      "x": -17,
      "y": 14,
      "z": 4,
      "name": "Rock_Ice"
    },
    {
      "x": -17,
      "y": 15,
      "z": 4,
      "name": "Rock_Ice"
    },
    {
      "x": -17,
      "y": 16,
      "z": 4,
      "name": "Rock_Ice"
    },
    {
      "x": -17,
      "y": 17,
      "z": 4,
      "name": "Rock_Ice"
    },
    {
      "x": -17,
      "y": 18,
      "z": 4,
      "name": "Rock_Ice"
    },
    {
      "x": -17,
      "y": 19,
      "z": 4,
      "name": "Rock_Ice"
    },
    {
      "x": -17,
      "y": 20,
      "z": 4,
      "name": "Rock_Ice"
    },
    {
      "x": -17,
      "y": 21,
      "z": 4,
      "name": "Rock_Ice"
    },
    {
      "x": -17,
      "y": 22,
      "z": 4,
      "name": "Rock_Ice"
    },
    {
      "x": -17,
      "y": 23,
      "z": 4,
      "name": "Rock_Ice"
    },
    {
      "x": -17,
      "y": 24,
      "z": 4,
      "name": "Rock_Ice"
    },
    {
      "x": -17,
      "y": 25,
      "z": 4,
      "name": "Rock_Ice"
    },
    {
      "x": -17,
      "y": 26,
      "z": 4,
      "name": "Rock_Ice"
    },
    {
      "x": -17,
      "y": 27,
      "z": 4,
      "name": "Rock_Ice"
    },
    {
      "x": -17,
      "y": 28,
      "z": 4,
      "name": "Rock_Ice"
    },
    {
      "x": -17,
      "y": 29,
      "z": 4,
      "name": "Rock_Ice"
    },
    {
      "x": -17,
      "y": 30,
      "z": 4,
      "name": "Rock_Ice"
    },
    {
      "x": -17,
      "y": 31,
      "z": 4,
      "name": "Rock_Ice"
    },
    {
      "x": -17,
      "y": 32,
      "z": 4,
      "name": "Rock_Ice"
    },
    {
      "x": -17,
      "y": 33,
      "z": 4,
      "name": "Rock_Ice"
    },
    {
      "x": -17,
      "y": 34,
      "z": 4,
      "name": "Soil_Snow"
    },
    {
      "x": -17,
      "y": 105,
      "z": 4,
      "name": "Rock_Ice"
    },
    {
      "x": -17,
      "y": 106,
      "z": 4,
      "name": "Rock_Ice"
    },
    {
      "x": -17,
      "y": 107,
      "z": 4,
      "name": "Rock_Ice"
    },
    {
      "x": -17,
      "y": 108,
      "z": 4,
      "name": "Rock_Ice"
    },
    {
      "x": -17,
      "y": 109,
      "z": 4,
      "name": "Rock_Ice"
    },
    {
      "x": -17,
      "y": 110,
      "z": 4,
      "name": "Rock_Ice"
    },
    {
      "x": -17,
      "y": 111,
      "z": 4,
      "name": "Rock_Ice"
    },
    {
      "x": -17,
      "y": 112,
      "z": 4,
      "name": "Rock_Ice_Permafrost"
    },
    {
      "x": -17,
      "y": 113,
      "z": 4,
      "name": "Rock_Crystal_Cyan_Block_WhiteLight"
    },
    {
      "x": -17,
      "y": 114,
      "z": 4,
      "name": "Rock_Crystal_Cyan_Block_WhiteLight"
    },
    {
      "x": -17,
      "y": 115,
      "z": 4,
      "name": "Rock_Crystal_Cyan_Block_WhiteLight"
    },
    {
      "x": -17,
      "y": 116,
      "z": 4,
      "name": "Rock_Ice_Permafrost"
    },
    {
      "x": -17,
      "y": 117,
      "z": 4,
      "name": "Rock_Ice_Permafrost"
    },
    {
      "x": -17,
      "y": 118,
      "z": 4,
      "name": "Rock_Ice"
    },
    {
      "x": -17,
      "y": 119,
      "z": 4,
      "name": "Rock_Ice"
    },
    {
      "x": -17,
      "y": 120,
      "z": 4,
      "name": "Rock_Ice"
    },
    {
      "x": -17,
      "y": 121,
      "z": 4,
      "name": "Rock_Ice"
    },
    {
      "x": -17,
      "y": 122,
      "z": 4,
      "name": "Rock_Ice"
    },
    {
      "x": -17,
      "y": 123,
      "z": 4,
      "name": "Rock_Ice_Permafrost"
    },
    {
      "x": -17,
      "y": 124,
      "z": 4,
      "name": "Rock_Ice"
    },
    {
      "x": -17,
      "y": 125,
      "z": 4,
      "name": "Rock_Ice_Permafrost"
    },
    {
      "x": -17,
      "y": 126,
      "z": 4,
      "name": "Rock_Ice_Permafrost"
    },
    {
      "x": -17,
      "y": 127,
      "z": 4,
      "name": "Rock_Ice_Permafrost"
    },
    {
      "x": -17,
      "y": 128,
      "z": 4,
      "name": "Rock_Ice_Permafrost"
    },
    {
      "x": -17,
      "y": 129,
      "z": 4,
      "name": "Rock_Ice_Permafrost"
    },
    {
      "x": -17,
      "y": 130,
      "z": 4,
      "name": "Rock_Ice_Permafrost"
    },
    {
      "x": -17,
      "y": 131,
      "z": 4,
      "name": "Rock_Ice"
    },
    {
      "x": -17,
      "y": 132,
      "z": 4,
      "name": "Rock_Ice"
    },
    {
      "x": -17,
      "y": 133,
      "z": 4,
      "name": "Rock_Ice"
    },
    {
      "x": -17,
      "y": 134,
      "z": 4,
      "name": "Rock_Ice"
    },
    {
      "x": -17,
      "y": 135,
      "z": 4,
      "name": "Rock_Ice"
    },
    {
      "x": -17,
      "y": 136,
      "z": 4,
      "name": "Rock_Ice"
    },
    {
      "x": -17,
      "y": 137,
      "z": 4,
      "name": "Soil_Snow"
    },
    {
      "x": -17,
      "y": 13,
      "z": 5,
      "name": "Rock_Ice"
    },
    {
      "x": -17,
      "y": 14,
      "z": 5,
      "name": "Rock_Ice"
    },
    {
      "x": -17,
      "y": 15,
      "z": 5,
      "name": "Rock_Ice"
    },
    {
      "x": -17,
      "y": 16,
      "z": 5,
      "name": "Rock_Ice"
    },
    {
      "x": -17,
      "y": 17,
      "z": 5,
      "name": "Rock_Ice"
    },
    {
      "x": -17,
      "y": 18,
      "z": 5,
      "name": "Rock_Ice"
    },
    {
      "x": -17,
      "y": 19,
      "z": 5,
      "name": "Rock_Ice"
    },
    {
      "x": -17,
      "y": 20,
      "z": 5,
      "name": "Rock_Ice"
    },
    {
      "x": -17,
      "y": 21,
      "z": 5,
      "name": "Rock_Ice"
    },
    {
      "x": -17,
      "y": 22,
      "z": 5,
      "name": "Rock_Ice"
    },
    {
      "x": -17,
      "y": 23,
      "z": 5,
      "name": "Rock_Ice"
    },
    {
      "x": -17,
      "y": 24,
      "z": 5,
      "name": "Rock_Ice"
    },
    {
      "x": -17,
      "y": 25,
      "z": 5,
      "name": "Rock_Ice"
    },
    {
      "x": -17,
      "y": 26,
      "z": 5,
      "name": "Rock_Ice"
    },
    {
      "x": -17,
      "y": 27,
      "z": 5,
      "name": "Rock_Ice"
    },
    {
      "x": -17,
      "y": 28,
      "z": 5,
      "name": "Rock_Ice"
    },
    {
      "x": -17,
      "y": 29,
      "z": 5,
      "name": "Rock_Ice"
    },
    {
      "x": -17,
      "y": 105,
      "z": 5,
      "name": "Rock_Ice"
    },
    {
      "x": -17,
      "y": 106,
      "z": 5,
      "name": "Rock_Ice"
    },
    {
      "x": -17,
      "y": 107,
      "z": 5,
      "name": "Rock_Ice"
    },
    {
      "x": -17,
      "y": 108,
      "z": 5,
      "name": "Rock_Ice"
    },
    {
      "x": -17,
      "y": 109,
      "z": 5,
      "name": "Rock_Ice"
    },
    {
      "x": -17,
      "y": 110,
      "z": 5,
      "name": "Rock_Ice"
    },
    {
      "x": -17,
      "y": 111,
      "z": 5,
      "name": "Rock_Ice_Permafrost"
    },
    {
      "x": -17,
      "y": 112,
      "z": 5,
      "name": "Rock_Ice_Permafrost"
    },
    {
      "x": -17,
      "y": 113,
      "z": 5,
      "name": "Rock_Ice_Permafrost"
    },
    {
      "x": -17,
      "y": 114,
      "z": 5,
      "name": "Rock_Ice_Permafrost"
    },
    {
      "x": -17,
      "y": 115,
      "z": 5,
      "name": "Rock_Ice_Permafrost"
    },
    {
      "x": -17,
      "y": 116,
      "z": 5,
      "name": "Rock_Ice"
    },
    {
      "x": -17,
      "y": 117,
      "z": 5,
      "name": "Rock_Ice"
    },
    {
      "x": -17,
      "y": 118,
      "z": 5,
      "name": "Rock_Ice"
    },
    {
      "x": -17,
      "y": 119,
      "z": 5,
      "name": "Rock_Ice"
    },
    {
      "x": -17,
      "y": 120,
      "z": 5,
      "name": "Rock_Ice"
    },
    {
      "x": -17,
      "y": 121,
      "z": 5,
      "name": "Rock_Ice"
    },
    {
      "x": -17,
      "y": 122,
      "z": 5,
      "name": "Rock_Ice"
    },
    {
      "x": -17,
      "y": 123,
      "z": 5,
      "name": "Rock_Ice"
    },
    {
      "x": -17,
      "y": 124,
      "z": 5,
      "name": "Rock_Ice_Permafrost"
    },
    {
      "x": -17,
      "y": 125,
      "z": 5,
      "name": "Rock_Ice_Permafrost"
    },
    {
      "x": -17,
      "y": 126,
      "z": 5,
      "name": "Rock_Ice_Permafrost"
    },
    {
      "x": -17,
      "y": 127,
      "z": 5,
      "name": "Rock_Ice_Permafrost"
    },
    {
      "x": -17,
      "y": 128,
      "z": 5,
      "name": "Rock_Crystal_Cyan_Block_WhiteLight"
    },
    {
      "x": -17,
      "y": 129,
      "z": 5,
      "name": "Rock_Ice_Permafrost"
    },
    {
      "x": -17,
      "y": 130,
      "z": 5,
      "name": "Rock_Ice_Permafrost"
    },
    {
      "x": -17,
      "y": 131,
      "z": 5,
      "name": "Rock_Ice"
    },
    {
      "x": -17,
      "y": 132,
      "z": 5,
      "name": "Rock_Ice"
    },
    {
      "x": -17,
      "y": 133,
      "z": 5,
      "name": "Rock_Ice"
    },
    {
      "x": -17,
      "y": 134,
      "z": 5,
      "name": "Rock_Ice"
    },
    {
      "x": -17,
      "y": 135,
      "z": 5,
      "name": "Rock_Ice"
    },
    {
      "x": -17,
      "y": 136,
      "z": 5,
      "name": "Soil_Snow"
    },
    {
      "x": -17,
      "y": 15,
      "z": 6,
      "name": "Rock_Ice"
    },
    {
      "x": -17,
      "y": 16,
      "z": 6,
      "name": "Rock_Ice"
    },
    {
      "x": -17,
      "y": 104,
      "z": 6,
      "name": "Rock_Ice"
    },
    {
      "x": -17,
      "y": 105,
      "z": 6,
      "name": "Rock_Ice"
    },
    {
      "x": -17,
      "y": 106,
      "z": 6,
      "name": "Rock_Ice"
    },
    {
      "x": -17,
      "y": 107,
      "z": 6,
      "name": "Rock_Ice"
    },
    {
      "x": -17,
      "y": 108,
      "z": 6,
      "name": "Rock_Ice"
    },
    {
      "x": -17,
      "y": 109,
      "z": 6,
      "name": "Rock_Ice"
    },
    {
      "x": -17,
      "y": 110,
      "z": 6,
      "name": "Rock_Ice"
    },
    {
      "x": -17,
      "y": 111,
      "z": 6,
      "name": "Rock_Ice"
    },
    {
      "x": -17,
      "y": 112,
      "z": 6,
      "name": "Rock_Ice_Permafrost"
    },
    {
      "x": -17,
      "y": 113,
      "z": 6,
      "name": "Rock_Ice_Permafrost"
    },
    {
      "x": -17,
      "y": 114,
      "z": 6,
      "name": "Rock_Ice_Permafrost"
    },
    {
      "x": -17,
      "y": 115,
      "z": 6,
      "name": "Rock_Ice"
    },
    {
      "x": -17,
      "y": 116,
      "z": 6,
      "name": "Rock_Ice"
    },
    {
      "x": -17,
      "y": 117,
      "z": 6,
      "name": "Rock_Ice"
    },
    {
      "x": -17,
      "y": 118,
      "z": 6,
      "name": "Rock_Ice"
    },
    {
      "x": -17,
      "y": 119,
      "z": 6,
      "name": "Rock_Ice"
    },
    {
      "x": -17,
      "y": 120,
      "z": 6,
      "name": "Rock_Ice"
    },
    {
      "x": -17,
      "y": 121,
      "z": 6,
      "name": "Rock_Ice"
    },
    {
      "x": -17,
      "y": 122,
      "z": 6,
      "name": "Rock_Ice_Permafrost"
    },
    {
      "x": -17,
      "y": 123,
      "z": 6,
      "name": "Rock_Ice_Permafrost"
    },
    {
      "x": -17,
      "y": 124,
      "z": 6,
      "name": "Rock_Crystal_Cyan_Block_WhiteLight"
    },
    {
      "x": -17,
      "y": 125,
      "z": 6,
      "name": "Rock_Ice_Permafrost"
    },
    {
      "x": -17,
      "y": 126,
      "z": 6,
      "name": "Rock_Ice_Permafrost"
    },
    {
      "x": -17,
      "y": 127,
      "z": 6,
      "name": "Rock_Ice_Permafrost"
    },
    {
      "x": -17,
      "y": 128,
      "z": 6,
      "name": "Rock_Ice_Permafrost"
    },
    {
      "x": -17,
      "y": 129,
      "z": 6,
      "name": "Rock_Crystal_Cyan_Block_WhiteLight"
    },
    {
      "x": -17,
      "y": 130,
      "z": 6,
      "name": "Rock_Ice_Permafrost"
    },
    {
      "x": -17,
      "y": 131,
      "z": 6,
      "name": "Rock_Ice_Permafrost"
    },
    {
      "x": -17,
      "y": 132,
      "z": 6,
      "name": "Rock_Ice_Permafrost"
    },
    {
      "x": -17,
      "y": 108,
      "z": 7,
      "name": "Rock_Ice_Permafrost"
    },
    {
      "x": -17,
      "y": 109,
      "z": 7,
      "name": "Rock_Ice_Permafrost"
    },
    {
      "x": -17,
      "y": 110,
      "z": 7,
      "name": "Rock_Ice_Permafrost"
    },
    {
      "x": -17,
      "y": 111,
      "z": 7,
      "name": "Rock_Ice_Permafrost"
    },
    {
      "x": -17,
      "y": 112,
      "z": 7,
      "name": "Rock_Ice_Permafrost"
    },
    {
      "x": -17,
      "y": 113,
      "z": 7,
      "name": "Rock_Ice_Permafrost"
    },
    {
      "x": -17,
      "y": 114,
      "z": 7,
      "name": "Rock_Ice_Permafrost"
    },
    {
      "x": -17,
      "y": 115,
      "z": 7,
      "name": "Rock_Ice_Permafrost"
    },
    {
      "x": -17,
      "y": 116,
      "z": 7,
      "name": "Rock_Ice"
    },
    {
      "x": -17,
      "y": 117,
      "z": 7,
      "name": "Rock_Ice"
    },
    {
      "x": -17,
      "y": 118,
      "z": 7,
      "name": "Rock_Ice"
    },
    {
      "x": -17,
      "y": 119,
      "z": 7,
      "name": "Rock_Ice"
    },
    {
      "x": -17,
      "y": 120,
      "z": 7,
      "name": "Rock_Ice_Permafrost"
    },
    {
      "x": -17,
      "y": 121,
      "z": 7,
      "name": "Rock_Ice_Permafrost"
    },
    {
      "x": -17,
      "y": 122,
      "z": 7,
      "name": "Rock_Ice_Permafrost"
    },
    {
      "x": -17,
      "y": 123,
      "z": 7,
      "name": "Rock_Ice_Permafrost"
    },
    {
      "x": -17,
      "y": 124,
      "z": 7,
      "name": "Rock_Ice"
    },
    {
      "x": -17,
      "y": 125,
      "z": 7,
      "name": "Rock_Ice"
    },
    {
      "x": -17,
      "y": 126,
      "z": 7,
      "name": "Rock_Ice"
    },
    {
      "x": -17,
      "y": 127,
      "z": 7,
      "name": "Rock_Ice"
    },
    {
      "x": -17,
      "y": 128,
      "z": 7,
      "name": "Rock_Ice"
    },
    {
      "x": -17,
      "y": 115,
      "z": 8,
      "name": "Rock_Ice"
    },
    {
      "x": -17,
      "y": 116,
      "z": 8,
      "name": "Rock_Ice"
    },
    {
      "x": -16,
      "y": 132,
      "z": -10,
      "name": "Rock_Ice"
    },
    {
      "x": -16,
      "y": 133,
      "z": -10,
      "name": "Rock_Ice"
    },
    {
      "x": -16,
      "y": 134,
      "z": -10,
      "name": "Rock_Ice"
    },
    {
      "x": -16,
      "y": 135,
      "z": -10,
      "name": "Rock_Ice"
    },
    {
      "x": -16,
      "y": 136,
      "z": -10,
      "name": "Rock_Ice"
    },
    {
      "x": -16,
      "y": 137,
      "z": -10,
      "name": "Soil_Snow"
    },
    {
      "x": -16,
      "y": 25,
      "z": -9,
      "name": "Soil_Snow"
    },
    {
      "x": -16,
      "y": 110,
      "z": -9,
