{
  "version": 8,
  "blockIdVersion": 11,
  "anchorX": 0,
  "anchorY": 0,
  "anchorZ": 0,
  "blocks": [
    {
      "x": -13,
      "y": 46,
      "z": -3,
      "name": "Soil_Snow"
    },
    {
      "x": -13,
      "y": 44,
      "z": -2,
      "name": "Soil_Snow"
    },
    {
      "x": -13,
      "y": 30,
      "z": -1,
      "name": "Rock_Ice"
    },
    {
      "x": -13,
      "y": 34,
      "z": -1,
      "name": "Rock_Ice"
    },
    {
      "x": -13,
      "y": 35,
      "z": -1,
      "name": "Rock_Ice"
    },
    {
      "x": -13,
      "y": 36,
      "z": -1,
      "name": "Rock_Ice"
    },
    {
      "x": -13,
      "y": 37,
      "z": -1,
      "name": "Rock_Ice"
    },
    {
      "x": -13,
      "y": 38,
      "z": -1,
      "name": "Rock_Ice"
    },
    {
      "x": -13,
      "y": 39,
      "z": -1,
      "name": "Rock_Ice"
    },
    {
      "x": -13,
      "y": 40,
      "z": -1,
      "name": "Soil_Snow"
    },
    {
      "x": -13,
      "y": 30,
      "z": 0,
      "name": "Rock_Ice"
    },
    {
      "x": -13,
      "y": 31,
      "z": 0,
      "name": "Rock_Ice"
    },
    {
      "x": -13,
      "y": 32,
      "z": 0,
      "name": "Rock_Ice"
    },
    {
      "x": -13,
      "y": 33,
      "z": 0,
      "name": "Rock_Ice"
    },
    {
      "x": -13,
      "y": 34,
      "z": 0,
      "name": "Rock_Ice"
    },
    {
      "x": -13,
      "y": 35,
      "z": 0,
      "name": "Rock_Ice"
    },
    {
      "x": -13,
      "y": 36,
      "z": 0,
      "name": "Rock_Ice"
    },
    {
      "x": -13,
      "y": 37,
      "z": 0,
      "name": "Rock_Ice"
    },
    {
      "x": -13,
      "y": 38,
      "z": 0,
      "name": "Rock_Ice"
    },
    {
      "x": -13,
      "y": 39,
      "z": 0,
      "name": "Rock_Ice"
    },
    {
      "x": -13,
      "y": 40,
      "z": 0,
      "name": "Soil_Snow"
    },
    {
      "x": -13,
      "y": 31,
      "z": 1,
      "name": "Rock_Ice"
    },
    {
      "x": -13,
      "y": 32,
      "z": 1,
      "name": "Rock_Ice"
    },
    {
      "x": -13,
      "y": 33,
      "z": 1,
      "name": "Rock_Ice"
    },
    {
      "x": -13,
      "y": 34,
      "z": 1,
      "name": "Rock_Ice"
    },
    {
      "x": -13,
      "y": 35,
      "z": 1,
      "name": "Rock_Ice"
    },
    {
      "x": -13,
      "y": 78,
      "z": 1,
      "name": "Soil_Snow"
    },
    {
      "x": -13,
      "y": 31,
      "z": 2,
      "name": "Soil_Snow"
    },
    {
      "x": -13,
      "y": 78,
      "z": 2,
      "name": "Soil_Snow"
    },
    {
      "x": -13,
      "y": 78,
      "z": 3,
      "name": "Soil_Snow"
    },
    {
      "x": -13,
      "y": 30,
      "z": 4,
      "name": "Soil_Snow"
    },
    {
      "x": -13,
      "y": 28,
      "z": 8,
      "name": "Rock_Ice"
    },
    {
      "x": -13,
      "y": 29,
      "z": 8,
      "name": "Rock_Ice"
    },
    {
      "x": -13,
      "y": 30,
      "z": 8,
      "name": "Soil_Snow"
    },
    {
      "x": -13,
      "y": 28,
      "z": 9,
      "name": "Soil_Snow"
    },
    {
      "x": -12,
      "y": 49,
      "z": -6,
      "name": "Soil_Snow"
    },
    {
      "x": -12,
      "y": 46,
      "z": -5,
      "name": "Rock_Ice"
    },
    {
      "x": -12,
      "y": 47,
      "z": -5,
      "name": "Rock_Ice"
    },
    {
      "x": -12,
      "y": 48,
      "z": -5,
      "name": "Rock_Ice"
    },
    {
      "x": -12,
      "y": 49,
      "z": -5,
      "name": "Rock_Ice"
    },
    {
      "x": -12,
      "y": 50,
      "z": -5,
      "name": "Soil_Snow"
    },
    {
      "x": -12,
      "y": 41,
      "z": -4,
      "name": "Rock_Ice"
    },
    {
      "x": -12,
      "y": 42,
      "z": -4,
      "name": "Rock_Ice"
    },
    {
      "x": -12,
      "y": 43,
      "z": -4,
      "name": "Rock_Ice"
    },
    {
      "x": -12,
      "y": 44,
      "z": -4,
      "name": "Rock_Ice"
    },
    {
      "x": -12,
      "y": 45,
      "z": -4,
      "name": "Rock_Ice"
    },
    {
      "x": -12,
      "y": 46,
      "z": -4,
      "name": "Rock_Ice"
    },
    {
      "x": -12,
      "y": 47,
      "z": -4,
      "name": "Rock_Ice"
    },
    {
      "x": -12,
      "y": 48,
      "z": -4,
      "name": "Rock_Ice"
    },
    {
      "x": -12,
      "y": 49,
      "z": -4,
      "name": "Rock_Ice"
    },
    {
      "x": -12,
      "y": 50,
      "z": -4,
      "name": "Soil_Snow"
    },
    {
      "x": -12,
      "y": 29,
      "z": -3,
      "name": "Rock_Ice"
    },
    {
      "x": -12,
      "y": 36,
      "z": -3,
      "name": "Rock_Ice"
    },
    {
      "x": -12,
      "y": 37,
      "z": -3,
      "name": "Rock_Ice"
    },
    {
      "x": -12,
      "y": 38,
      "z": -3,
      "name": "Rock_Ice"
    },
    {
      "x": -12,
      "y": 39,
      "z": -3,
      "name": "Rock_Ice"
    },
    {
      "x": -12,
      "y": 40,
      "z": -3,
      "name": "Rock_Ice"
    },
    {
      "x": -12,
      "y": 41,
      "z": -3,
      "name": "Rock_Ice"
    },
    {
      "x": -12,
      "y": 42,
      "z": -3,
      "name": "Rock_Ice"
    },
    {
      "x": -12,
      "y": 43,
      "z": -3,
      "name": "Rock_Ice"
    },
    {
      "x": -12,
      "y": 44,
      "z": -3,
      "name": "Rock_Ice"
    },
    {
      "x": -12,
      "y": 45,
      "z": -3,
      "name": "Rock_Ice"
    },
    {
      "x": -12,
      "y": 46,
      "z": -3,
      "name": "Rock_Ice"
    },
    {
      "x": -12,
      "y": 47,
      "z": -3,
      "name": "Soil_Snow"
    },
    {
      "x": -12,
      "y": 27,
      "z": -2,
      "name": "Rock_Ice"
    },
    {
      "x": -12,
      "y": 28,
      "z": -2,
      "name": "Rock_Ice"
    },
    {
      "x": -12,
      "y": 29,
      "z": -2,
      "name": "Rock_Ice"
    },
    {
      "x": -12,
      "y": 30,
      "z": -2,
      "name": "Rock_Ice"
    },
    {
      "x": -12,
      "y": 31,
      "z": -2,
      "name": "Rock_Ice"
    },
    {
      "x": -12,
      "y": 32,
      "z": -2,
      "name": "Rock_Ice"
    },
    {
      "x": -12,
      "y": 33,
      "z": -2,
      "name": "Rock_Ice"
    },
    {
      "x": -12,
      "y": 34,
      "z": -2,
      "name": "Rock_Ice"
    },
    {
      "x": -12,
      "y": 35,
      "z": -2,
      "name": "Rock_Ice"
    },
    {
      "x": -12,
      "y": 36,
      "z": -2,
      "name": "Rock_Ice"
    },
    {
      "x": -12,
      "y": 37,
      "z": -2,
      "name": "Rock_Ice"
    },
    {
      "x": -12,
      "y": 38,
      "z": -2,
      "name": "Rock_Ice"
    },
    {
      "x": -12,
      "y": 39,
      "z": -2,
      "name": "Rock_Ice"
    },
    {
      "x": -12,
      "y": 40,
      "z": -2,
      "name": "Rock_Ice"
    },
    {
      "x": -12,
      "y": 41,
      "z": -2,
      "name": "Rock_Ice"
    },
    {
      "x": -12,
      "y": 42,
      "z": -2,
      "name": "Rock_Ice"
    },
    {
      "x": -12,
      "y": 43,
      "z": -2,
      "name": "Rock_Ice"
    },
    {
      "x": -12,
      "y": 44,
      "z": -2,
      "name": "Rock_Ice"
    },
    {
      "x": -12,
      "y": 45,
      "z": -2,
      "name": "Soil_Snow"
    },
    {
      "x": -12,
      "y": 77,
      "z": -2,
      "name": "Rock_Ice"
    },
    {
      "x": -12,
      "y": 78,
      "z": -2,
      "name": "Rock_Ice"
    },
    {
      "x": -12,
      "y": 79,
      "z": -2,
      "name": "Soil_Snow"
    },
    {
      "x": -12,
      "y": 26,
      "z": -1,
      "name": "Rock_Ice"
    },
    {
      "x": -12,
      "y": 27,
      "z": -1,
      "name": "Rock_Ice"
    },
    {
      "x": -12,
      "y": 28,
      "z": -1,
      "name": "Rock_Ice"
    },
    {
      "x": -12,
      "y": 29,
      "z": -1,
      "name": "Rock_Ice"
    },
    {
      "x": -12,
      "y": 30,
      "z": -1,
      "name": "Rock_Ice"
    },
    {
      "x": -12,
      "y": 31,
      "z": -1,
      "name": "Rock_Ice"
    },
    {
      "x": -12,
      "y": 32,
      "z": -1,
      "name": "Rock_Ice"
    },
    {
      "x": -12,
      "y": 33,
      "z": -1,
      "name": "Rock_Ice"
    },
    {
      "x": -12,
      "y": 34,
      "z": -1,
      "name": "Rock_Ice"
    },
    {
      "x": -12,
      "y": 35,
      "z": -1,
      "name": "Rock_Ice"
    },
    {
      "x": -12,
      "y": 36,
      "z": -1,
      "name": "Rock_Ice"
    },
    {
      "x": -12,
      "y": 37,
      "z": -1,
      "name": "Rock_Ice"
    },
    {
      "x": -12,
      "y": 38,
      "z": -1,
      "name": "Rock_Ice"
    },
    {
      "x": -12,
      "y": 39,
      "z": -1,
      "name": "Rock_Ice"
    },
    {
      "x": -12,
      "y": 40,
      "z": -1,
      "name": "Rock_Ice"
    },
    {
      "x": -12,
      "y": 41,
      "z": -1,
      "name": "Rock_Ice"
    },
    {
      "x": -12,
      "y": 42,
      "z": -1,
      "name": "Rock_Ice"
    },
    {
      "x": -12,
      "y": 43,
      "z": -1,
      "name": "Rock_Ice"
    },
    {
      "x": -12,
      "y": 44,
      "z": -1,
      "name": "Soil_Snow"
    },
    {
      "x": -12,
      "y": 77,
      "z": -1,
      "name": "Rock_Ice"
    },
    {
      "x": -12,
      "y": 78,
      "z": -1,
      "name": "Rock_Ice"
    },
    {
      "x": -12,
      "y": 79,
      "z": -1,
      "name": "Soil_Snow"
    },
    {
      "x": -12,
      "y": 28,
      "z": 0,
      "name": "Rock_Ice"
    },
    {
      "x": -12,
      "y": 29,
      "z": 0,
      "name": "Rock_Ice"
    },
    {
      "x": -12,
      "y": 30,
      "z": 0,
      "name": "Rock_Ice"
    },
    {
      "x": -12,
      "y": 31,
      "z": 0,
      "name": "Rock_Ice"
    },
    {
      "x": -12,
      "y": 32,
      "z": 0,
      "name": "Rock_Ice"
    },
    {
      "x": -12,
      "y": 33,
      "z": 0,
      "name": "Rock_Ice"
    },
    {
      "x": -12,
      "y": 34,
      "z": 0,
      "name": "Rock_Ice"
    },
    {
      "x": -12,
      "y": 35,
      "z": 0,
      "name": "Rock_Ice"
    },
    {
      "x": -12,
      "y": 36,
      "z": 0,
      "name": "Rock_Ice"
    },
    {
      "x": -12,
      "y": 37,
      "z": 0,
      "name": "Rock_Ice"
    },
    {
      "x": -12,
      "y": 38,
      "z": 0,
      "name": "Rock_Ice"
    },
    {
      "x": -12,
      "y": 39,
      "z": 0,
      "name": "Rock_Ice"
    },
    {
      "x": -12,
      "y": 42,
      "z": 0,
      "name": "Rock_Ice"
    },
    {
      "x": -12,
      "y": 43,
      "z": 0,
      "name": "Soil_Snow"
    },
    {
      "x": -12,
      "y": 76,
      "z": 0,
      "name": "Rock_Ice"
    },
    {
      "x": -12,
      "y": 77,
      "z": 0,
      "name": "Rock_Ice"
    },
    {
      "x": -12,
      "y": 78,
      "z": 0,
      "name": "Rock_Ice"
    },
    {
      "x": -12,
      "y": 79,
      "z": 0,
      "name": "Soil_Snow"
    },
    {
      "x": -12,
      "y": 29,
      "z": 1,
      "name": "Rock_Ice"
    },
    {
      "x": -12,
      "y": 30,
      "z": 1,
      "name": "Rock_Ice"
    },
    {
      "x": -12,
      "y": 31,
      "z": 1,
      "name": "Rock_Ice"
    },
    {
      "x": -12,
      "y": 32,
      "z": 1,
      "name": "Rock_Ice"
    },
    {
      "x": -12,
      "y": 33,
      "z": 1,
      "name": "Rock_Ice"
    },
    {
      "x": -12,
      "y": 34,
      "z": 1,
      "name": "Rock_Ice"
    },
    {
      "x": -12,
      "y": 35,
      "z": 1,
      "name": "Soil_Snow"
    },
    {
      "x": -12,
      "y": 76,
      "z": 1,
      "name": "Rock_Ice"
    },
    {
      "x": -12,
      "y": 77,
      "z": 1,
      "name": "Rock_Ice"
    },
    {
      "x": -12,
      "y": 78,
      "z": 1,
      "name": "Rock_Ice"
    },
    {
      "x": -12,
      "y": 79,
      "z": 1,
      "name": "Rock_Ice"
    },
    {
      "x": -12,
      "y": 80,
      "z": 1,
      "name": "Rock_Ice"
    },
    {
      "x": -12,
      "y": 28,
      "z": 2,
      "name": "Rock_Ice"
    },
    {
      "x": -12,
      "y": 29,
      "z": 2,
      "name": "Rock_Ice_Permafrost"
    },
    {
      "x": -12,
      "y": 30,
      "z": 2,
      "name": "Rock_Ice"
    },
    {
      "x": -12,
      "y": 31,
      "z": 2,
      "name": "Rock_Ice"
    },
    {
      "x": -12,
      "y": 32,
      "z": 2,
      "name": "Soil_Snow"
    },
    {
      "x": -12,
      "y": 76,
      "z": 2,
      "name": "Rock_Ice"
    },
    {
      "x": -12,
      "y": 77,
      "z": 2,
      "name": "Rock_Ice"
    },
    {
      "x": -12,
      "y": 78,
      "z": 2,
      "name": "Rock_Ice"
    },
    {
      "x": -12,
      "y": 79,
      "z": 2,
      "name": "Rock_Ice"
    },
    {
      "x": -12,
      "y": 80,
      "z": 2,
      "name": "Rock_Ice"
    },
    {
      "x": -12,
      "y": 81,
      "z": 2,
      "name": "Rock_Ice"
    },
    {
      "x": -12,
      "y": 82,
      "z": 2,
      "name": "Soil_Snow"
    },
    {
      "x": -12,
      "y": 26,
      "z": 3,
      "name": "Rock_Crystal_Cyan_Block_WhiteLight"
    },
    {
      "x": -12,
      "y": 27,
      "z": 3,
      "name": "Rock_Crystal_Cyan_Block_WhiteLight"
    },
    {
      "x": -12,
      "y": 28,
      "z": 3,
      "name": "Rock_Ice_Permafrost"
    },
    {
      "x": -12,
      "y": 29,
      "z": 3,
      "name": "Rock_Ice_Permafrost"
    },
    {
      "x": -12,
      "y": 30,
      "z": 3,
      "name": "Rock_Ice_Permafrost"
    },
    {
      "x": -12,
      "y": 31,
      "z": 3,
      "name": "Rock_Ice"
    },
    {
      "x": -12,
      "y": 32,
      "z": 3,
      "name": "Soil_Snow"
    },
    {
      "x": -12,
      "y": 75,
      "z": 3,
      "name": "Rock_Ice"
    },
    {
      "x": -12,
      "y": 76,
      "z": 3,
      "name": "Rock_Ice"
    },
    {
      "x": -12,
      "y": 77,
      "z": 3,
      "name": "Rock_Ice"
    },
    {
      "x": -12,
      "y": 78,
      "z": 3,
      "name": "Rock_Ice"
    },
    {
      "x": -12,
      "y": 79,
      "z": 3,
      "name": "Rock_Ice"
    },
    {
      "x": -12,
      "y": 80,
      "z": 3,
      "name": "Rock_Ice"
    },
    {
      "x": -12,
      "y": 81,
      "z": 3,
      "name": "Soil_Snow"
    },
    {
      "x": -12,
      "y": 25,
      "z": 4,
      "name": "Rock_Ice"
    },
    {
      "x": -12,
      "y": 26,
      "z": 4,
      "name": "Rock_Ice"
    },
    {
      "x": -12,
      "y": 27,
      "z": 4,
      "name": "Rock_Ice_Permafrost"
    },
    {
      "x": -12,
      "y": 28,
      "z": 4,
      "name": "Rock_Ice_Permafrost"
    },
    {
      "x": -12,
      "y": 29,
      "z": 4,
      "name": "Rock_Crystal_Cyan_Block_WhiteLight"
    },
    {
      "x": -12,
      "y": 30,
      "z": 4,
      "name": "Rock_Ice"
    },
    {
      "x": -12,
      "y": 31,
      "z": 4,
      "name": "Soil_Snow"
    },
    {
      "x": -12,
      "y": 77,
      "z": 4,
      "name": "Rock_Ice"
    },
    {
      "x": -12,
      "y": 78,
      "z": 4,
      "name": "Rock_Ice"
    },
    {
      "x": -12,
      "y": 79,
      "z": 4,
      "name": "Soil_Snow"
    },
    {
      "x": -12,
      "y": 25,
      "z": 5,
      "name": "Rock_Ice"
    },
    {
      "x": -12,
      "y": 26,
      "z": 5,
      "name": "Rock_Ice"
    },
    {
      "x": -12,
      "y": 27,
      "z": 5,
      "name": "Rock_Ice"
    },
    {
      "x": -12,
      "y": 28,
      "z": 5,
      "name": "Rock_Ice"
    },
    {
      "x": -12,
      "y": 29,
      "z": 5,
      "name": "Rock_Ice"
    },
    {
      "x": -12,
      "y": 30,
      "z": 5,
      "name": "Rock_Ice"
    },
    {
      "x": -12,
      "y": 31,
      "z": 5,
      "name": "Soil_Snow"
    },
    {
      "x": -12,
      "y": 77,
      "z": 5,
      "name": "Rock_Ice"
    },
    {
      "x": -12,
      "y": 78,
      "z": 5,
      "name": "Rock_Ice"
    },
    {
      "x": -12,
      "y": 79,
      "z": 5,
      "name": "Soil_Snow"
    },
    {
      "x": -12,
      "y": 77,
      "z": 6,
      "name": "Rock_Ice"
    },
    {
      "x": -12,
      "y": 78,
      "z": 6,
      "name": "Rock_Ice"
    },
    {
      "x": -12,
      "y": 79,
      "z": 6,
      "name": "Soil_Snow"
    },
    {
      "x": -12,
      "y": 77,
      "z": 7,
      "name": "Rock_Ice"
    },
    {
      "x": -12,
      "y": 78,
      "z": 7,
      "name": "Soil_Snow"
    },
    {
      "x": -12,
      "y": 25,
      "z": 8,
      "name": "Rock_Ice"
    },
    {
      "x": -12,
      "y": 26,
      "z": 8,
      "name": "Rock_Ice"
    },
    {
      "x": -12,
      "y": 27,
      "z": 8,
      "name": "Rock_Ice"
    },
    {
      "x": -12,
      "y": 28,
      "z": 8,
      "name": "Rock_Ice"
    },
    {
      "x": -12,
      "y": 29,
      "z": 8,
      "name": "Rock_Ice"
    },
    {
      "x": -12,
      "y": 30,
      "z": 8,
      "name": "Rock_Ice"
    },
    {
      "x": -12,
      "y": 31,
      "z": 8,
      "name": "Soil_Snow"
    },
    {
      "x": -12,
      "y": 25,
      "z": 9,
      "name": "Rock_Ice_Permafrost"
    },
    {
      "x": -12,
      "y": 26,
      "z": 9,
      "name": "Rock_Ice"
    },
    {
      "x": -12,
      "y": 27,
      "z": 9,
      "name": "Rock_Ice"
    },
    {
      "x": -12,
      "y": 28,
      "z": 9,
      "name": "Rock_Ice"
    },
    {
      "x": -12,
      "y": 29,
      "z": 9,
      "name": "Rock_Ice"
    },
    {
      "x": -12,
      "y": 30,
      "z": 9,
      "name": "Soil_Snow"
    },
    {
      "x": -12,
      "y": 24,
      "z": 10,
      "name": "Rock_Ice_Permafrost"
    },
    {
      "x": -12,
      "y": 25,
      "z": 10,
      "name": "Rock_Ice"
    },
    {
      "x": -12,
      "y": 26,
      "z": 10,
      "name": "Rock_Ice_Permafrost"
    },
    {
      "x": -12,
      "y": 27,
      "z": 10,
      "name": "Rock_Ice_Permafrost"
    },
    {
      "x": -12,
      "y": 28,
      "z": 10,
      "name": "Soil_Snow"
    },
    {
      "x": -11,
      "y": 46,
      "z": -8,
      "name": "Rock_Ice"
    },
    {
      "x": -11,
      "y": 47,
      "z": -8,
      "name": "Rock_Ice"
    },
    {
      "x": -11,
      "y": 48,
      "z": -8,
      "name": "Rock_Ice"
    },
    {
      "x": -11,
      "y": 49,
      "z": -8,
      "name": "Soil_Snow"
    },
    {
      "x": -11,
      "y": 24,
      "z": -7,
      "name": "Soil_Snow"
    },
    {
      "x": -11,
      "y": 45,
      "z": -7,
      "name": "Rock_Ice"
    },
    {
      "x": -11,
      "y": 46,
      "z": -7,
      "name": "Rock_Ice"
    },
    {
      "x": -11,
      "y": 47,
      "z": -7,
      "name": "Rock_Ice"
    },
    {
      "x": -11,
      "y": 48,
      "z": -7,
      "name": "Rock_Ice"
    },
    {
      "x": -11,
      "y": 49,
      "z": -7,
      "name": "Rock_Ice"
    },
    {
      "x": -11,
      "y": 50,
      "z": -7,
      "name": "Rock_Ice"
    },
    {
      "x": -11,
      "y": 51,
      "z": -7,
      "name": "Soil_Snow"
    },
    {
      "x": -11,
      "y": 23,
      "z": -6,
      "name": "Rock_Ice"
    },
    {
      "x": -11,
      "y": 44,
      "z": -6,
      "name": "Rock_Ice"
    },
    {
      "x": -11,
      "y": 45,
      "z": -6,
      "name": "Rock_Ice"
    },
    {
      "x": -11,
      "y": 46,
      "z": -6,
      "name": "Rock_Ice"
    },
    {
      "x": -11,
      "y": 47,
      "z": -6,
      "name": "Rock_Ice"
    },
    {
      "x": -11,
      "y": 48,
      "z": -6,
      "name": "Rock_Ice"
    },
    {
      "x": -11,
      "y": 49,
      "z": -6,
      "name": "Rock_Ice"
    },
    {
      "x": -11,
      "y": 50,
      "z": -6,
      "name": "Rock_Ice"
    },
    {
      "x": -11,
      "y": 51,
      "z": -6,
      "name": "Rock_Ice"
    },
    {
      "x": -11,
      "y": 52,
      "z": -6,
      "name": "Rock_Ice"
    },
    {
      "x": -11,
      "y": 53,
      "z": -6,
      "name": "Soil_Snow"
    },
    {
      "x": -11,
      "y": 23,
      "z": -5,
      "name": "Rock_Ice"
    },
    {
      "x": -11,
      "y": 24,
      "z": -5,
      "name": "Rock_Ice"
    },
    {
      "x": -11,
      "y": 40,
      "z": -5,
      "name": "Rock_Ice"
    },
    {
      "x": -11,
      "y": 41,
      "z": -5,
      "name": "Rock_Ice"
    },
    {
      "x": -11,
      "y": 42,
      "z": -5,
      "name": "Rock_Ice"
    },
    {
      "x": -11,
      "y": 43,
      "z": -5,
      "name": "Rock_Ice"
    },
    {
      "x": -11,
      "y": 44,
      "z": -5,
      "name": "Rock_Ice"
    },
    {
      "x": -11,
      "y": 45,
      "z": -5,
      "name": "Rock_Ice"
    },
    {
      "x": -11,
      "y": 46,
      "z": -5,
      "name": "Rock_Ice"
    },
    {
      "x": -11,
      "y": 47,
      "z": -5,
      "name": "Rock_Ice"
    },
    {
      "x": -11,
      "y": 48,
      "z": -5,
      "name": "Rock_Ice"
    },
    {
      "x": -11,
      "y": 49,
      "z": -5,
      "name": "Rock_Ice"
    },
    {
      "x": -11,
      "y": 50,
      "z": -5,
      "name": "Rock_Ice"
    },
    {
      "x": -11,
      "y": 51,
      "z": -5,
      "name": "Rock_Ice"
    },
    {
      "x": -11,
      "y": 52,
      "z": -5,
      "name": "Rock_Ice"
    },
    {
      "x": -11,
      "y": 53,
      "z": -5,
      "name": "Rock_Ice"
    },
    {
      "x": -11,
      "y": 54,
      "z": -5,
      "name": "Rock_Ice"
    },
    {
      "x": -11,
      "y": 55,
      "z": -5,
      "name": "Rock_Ice"
    },
    {
      "x": -11,
      "y": 56,
      "z": -5,
      "name": "Rock_Ice"
    },
    {
      "x": -11,
      "y": 57,
      "z": -5,
      "name": "Soil_Snow"
    },
    {
      "x": -11,
      "y": 23,
      "z": -4,
      "name": "Rock_Ice"
    },
    {
      "x": -11,
      "y": 24,
      "z": -4,
      "name": "Rock_Ice"
    },
    {
      "x": -11,
      "y": 25,
      "z": -4,
      "name": "Rock_Ice"
    },
    {
      "x": -11,
      "y": 26,
      "z": -4,
      "name": "Rock_Ice"
    },
    {
      "x": -11,
      "y": 28,
      "z": -4,
      "name": "Rock_Ice"
    },
    {
      "x": -11,
      "y": 29,
      "z": -4,
      "name": "Rock_Ice"
    },
    {
      "x": -11,
      "y": 30,
      "z": -4,
      "name": "Rock_Ice"
    },
    {
      "x": -11,
      "y": 34,
      "z": -4,
      "name": "Rock_Ice"
    },
    {
      "x": -11,
      "y": 35,
      "z": -4,
      "name": "Rock_Ice"
    },
    {
      "x": -11,
      "y": 36,
      "z": -4,
      "name": "Rock_Ice"
    },
    {
      "x": -11,
      "y": 37,
      "z": -4,
      "name": "Rock_Ice"
    },
    {
      "x": -11,
      "y": 38,
      "z": -4,
      "name": "Rock_Ice"
    },
    {
      "x": -11,
      "y": 39,
      "z": -4,
      "name": "Rock_Ice"
    },
    {
      "x": -11,
      "y": 40,
      "z": -4,
      "name": "Rock_Ice"
    },
    {
      "x": -11,
      "y": 41,
      "z": -4,
      "name": "Rock_Ice"
    },
    {
      "x": -11,
      "y": 42,
      "z": -4,
      "name": "Rock_Ice"
    },
    {
      "x": -11,
      "y": 43,
      "z": -4,
      "name": "Rock_Ice"
    },
    {
      "x": -11,
      "y": 44,
      "z": -4,
      "name": "Rock_Ice"
    },
    {
      "x": -11,
      "y": 45,
      "z": -4,
      "name": "Rock_Ice"
    },
    {
      "x": -11,
      "y": 46,
      "z": -4,
      "name": "Rock_Ice"
    },
    {
      "x": -11,
      "y": 47,
      "z": -4,
      "name": "Rock_Ice"
    },
    {
      "x": -11,
      "y": 48,
      "z": -4,
      "name": "Rock_Ice"
    },
    {
      "x": -11,
      "y": 49,
      "z": -4,
      "name": "Rock_Ice"
    },
    {
      "x": -11,
      "y": 50,
      "z": -4,
      "name": "Rock_Ice"
    },
    {
      "x": -11,
      "y": 51,
      "z": -4,
      "name": "Rock_Ice"
    },
    {
      "x": -11,
      "y": 52,
      "z": -4,
      "name": "Rock_Ice"
    },
    {
      "x": -11,
      "y": 53,
      "z": -4,
      "name": "Rock_Ice"
    },
    {
      "x": -11,
      "y": 54,
      "z": -4,
      "name": "Rock_Ice"
    },
    {
      "x": -11,
      "y": 55,
      "z": -4,
      "name": "Rock_Ice"
    },
    {
      "x": -11,
      "y": 56,
      "z": -4,
      "name": "Rock_Ice"
    },
    {
      "x": -11,
      "y": 57,
      "z": -4,
      "name": "Rock_Ice"
    },
    {
      "x": -11,
      "y": 74,
      "z": -4,
      "name": "Rock_Ice"
    },
    {
      "x": -11,
      "y": 75,
      "z": -4,
      "name": "Rock_Ice"
    },
    {
      "x": -11,
      "y": 76,
      "z": -4,
      "name": "Rock_Ice"
    },
    {
      "x": -11,
      "y": 77,
      "z": -4,
      "name": "Rock_Ice"
    },
    {
      "x": -11,
      "y": 78,
      "z": -4,
      "name": "Rock_Ice"
    },
    {
      "x": -11,
      "y": 79,
      "z": -4,
      "name": "Rock_Ice"
    },
    {
      "x": -11,
      "y": 80,
      "z": -4,
      "name": "Rock_Ice"
    },
    {
      "x": -11,
      "y": 81,
      "z": -4,
      "name": "Soil_Snow"
    },
    {
      "x": -11,
      "y": 20,
      "z": -3,
      "name": "Rock_Ice"
    },
    {
      "x": -11,
      "y": 21,
      "z": -3,
      "name": "Rock_Ice"
    },
    {
      "x": -11,
      "y": 22,
      "z": -3,
      "name": "Rock_Ice"
    },
    {
      "x": -11,
      "y": 23,
      "z": -3,
      "name": "Rock_Ice"
    },
    {
      "x": -11,
      "y": 24,
      "z": -3,
      "name": "Rock_Ice"
    },
    {
      "x": -11,
      "y": 25,
      "z": -3,
      "name": "Rock_Ice"
    },
    {
      "x": -11,
      "y": 26,
      "z": -3,
      "name": "Rock_Ice"
    },
    {
      "x": -11,
      "y": 27,
      "z": -3,
      "name": "Rock_Ice"
    },
    {
      "x": -11,
      "y": 28,
      "z": -3,
      "name": "Rock_Ice"
    },
    {
      "x": -11,
      "y": 29,
      "z": -3,
      "name": "Rock_Ice"
    },
    {
      "x": -11,
      "y": 30,
      "z": -3,
      "name": "Rock_Ice"
    },
    {
      "x": -11,
      "y": 31,
      "z": -3,
      "name": "Rock_Ice"
    },
    {
      "x": -11,
      "y": 32,
      "z": -3,
      "name": "Rock_Ice"
    },
    {
      "x": -11,
      "y": 33,
      "z": -3,
      "name": "Rock_Ice"
    },
    {
      "x": -11,
      "y": 34,
      "z": -3,
      "name": "Rock_Ice"
    },
    {
      "x": -11,
      "y": 35,
      "z": -3,
      "name": "Rock_Ice"
    },
    {
      "x": -11,
      "y": 36,
      "z": -3,
      "name": "Rock_Ice"
    },
    {
      "x": -11,
      "y": 37,
      "z": -3,
      "name": "Rock_Ice"
    },
    {
      "x": -11,
      "y": 38,
      "z": -3,
      "name": "Rock_Ice"
    },
    {
      "x": -11,
      "y": 39,
      "z": -3,
      "name": "Rock_Ice"
    },
    {
      "x": -11,
      "y": 40,
      "z": -3,
      "name": "Rock_Ice"
    },
    {
      "x": -11,
      "y": 41,
      "z": -3,
      "name": "Rock_Ice"
    },
    {
      "x": -11,
      "y": 42,
      "z": -3,
      "name": "Rock_Ice"
    },
    {
      "x": -11,
      "y": 43,
      "z": -3,
      "name": "Rock_Ice"
    },
    {
      "x": -11,
      "y": 44,
      "z": -3,
      "name": "Rock_Ice"
    },
    {
      "x": -11,
      "y": 45,
      "z": -3,
      "name": "Rock_Ice"
    },
    {
      "x": -11,
      "y": 46,
      "z": -3,
      "name": "Rock_Ice"
    },
    {
      "x": -11,
      "y": 47,
      "z": -3,
      "name": "Rock_Ice"
    },
    {
      "x": -11,
      "y": 48,
      "z": -3,
      "name": "Rock_Ice"
    },
    {
      "x": -11,
      "y": 49,
      "z": -3,
      "name": "Rock_Ice"
    },
    {
      "x": -11,
      "y": 50,
      "z": -3,
      "name": "Soil_Snow"
    },
    {
      "x": -11,
      "y": 75,
      "z": -3,
      "name": "Rock_Ice"
    },
    {
      "x": -11,
      "y": 76,
      "z": -3,
      "name": "Rock_Ice"
    },
    {
      "x": -11,
      "y": 77,
      "z": -3,
      "name": "Rock_Ice"
    },
    {
      "x": -11,
      "y": 78,
      "z": -3,
      "name": "Rock_Ice"
    },
    {
      "x": -11,
      "y": 79,
      "z": -3,
      "name": "Rock_Ice"
    },
    {
      "x": -11,
      "y": 80,
      "z": -3,
      "name": "Rock_Ice"
    },
    {
      "x": -11,
      "y": 81,
      "z": -3,
      "name": "Rock_Ice_Permafrost"
    },
    {
      "x": -11,
      "y": 82,
      "z": -3,
      "name": "Rock_Ice_Permafrost"
    },
    {
      "x": -11,
      "y": 83,
      "z": -3,
      "name": "Rock_Ice"
    },
    {
      "x": -11,
      "y": 84,
      "z": -3,
      "name": "Soil_Snow"
    },
    {
      "x": -11,
      "y": 20,
      "z": -2,
      "name": "Rock_Ice"
    },
    {
      "x": -11,
      "y": 21,
      "z": -2,
      "name": "Rock_Ice_Permafrost"
    },
    {
      "x": -11,
      "y": 22,
      "z": -2,
      "name": "Rock_Ice_Permafrost"
    },
    {
      "x": -11,
      "y": 23,
      "z": -2,
      "name": "Rock_Ice_Permafrost"
    },
    {
      "x": -11,
      "y": 24,
      "z": -2,
      "name": "Rock_Ice_Permafrost"
    },
    {
      "x": -11,
      "y": 25,
      "z": -2,
      "name": "Rock_Ice"
    },
    {
      "x": -11,
      "y": 26,
      "z": -2,
      "name": "Rock_Ice_Permafrost"
    },
    {
      "x": -11,
      "y": 27,
      "z": -2,
      "name": "Rock_Ice_Permafrost"
    },
    {
      "x": -11,
      "y": 28,
      "z": -2,
      "name": "Rock_Ice"
    },
    {
      "x": -11,
      "y": 29,
      "z": -2,
      "name": "Rock_Ice"
    },
    {
      "x": -11,
      "y": 30,
      "z": -2,
      "name": "Rock_Ice"
    },
    {
      "x": -11,
      "y": 31,
      "z": -2,
      "name": "Rock_Ice"
    },
    {
      "x": -11,
      "y": 32,
      "z": -2,
      "name": "Rock_Ice"
    },
    {
      "x": -11,
      "y": 33,
      "z": -2,
      "name": "Rock_Ice"
    },
    {
      "x": -11,
      "y": 34,
      "z": -2,
      "name": "Rock_Ice"
    },
    {
      "x": -11,
      "y": 35,
      "z": -2,
      "name": "Rock_Ice"
    },
    {
      "x": -11,
      "y": 36,
      "z": -2,
      "name": "Rock_Ice"
    },
    {
      "x": -11,
      "y": 37,
      "z": -2,
      "name": "Rock_Ice"
    },
    {
      "x": -11,
      "y": 38,
      "z": -2,
      "name": "Rock_Ice"
    },
    {
      "x": -11,
      "y": 39,
      "z": -2,
      "name": "Rock_Ice"
    },
    {
      "x": -11,
      "y": 40,
      "z": -2,
      "name": "Rock_Ice"
    },
    {
      "x": -11,
      "y": 41,
      "z": -2,
      "name": "Rock_Ice"
    },
    {
      "x": -11,
      "y": 42,
      "z": -2,
      "name": "Rock_Ice"
    },
    {
      "x": -11,
      "y": 43,
      "z": -2,
      "name": "Rock_Ice"
    },
    {
      "x": -11,
      "y": 44,
      "z": -2,
      "name": "Rock_Ice"
    },
    {
      "x": -11,
      "y": 45,
      "z": -2,
      "name": "Rock_Ice"
    },
    {
      "x": -11,
      "y": 46,
      "z": -2,
      "name": "Rock_Ice"
    },
    {
      "x": -11,
      "y": 47,
      "z": -2,
      "name": "Soil_Snow"
    },
    {
      "x": -11,
      "y": 75,
      "z": -2,
      "name": "Rock_Ice"
    },
    {
      "x": -11,
      "y": 76,
      "z": -2,
      "name": "Rock_Ice"
    },
    {
      "x": -11,
      "y": 77,
      "z": -2,
      "name": "Rock_Ice"
    },
    {
      "x": -11,
      "y": 78,
      "z": -2,
      "name": "Rock_Ice"
    },
    {
      "x": -11,
      "y": 79,
      "z": -2,
      "name": "Rock_Ice"
    },
    {
      "x": -11,
      "y": 80,
      "z": -2,
      "name": "Rock_Ice"
    },
    {
      "x": -11,
      "y": 81,
      "z": -2,
      "name": "Rock_Ice"
    },
    {
      "x": -11,
      "y": 82,
      "z": -2,
      "name": "Rock_Ice_Permafrost"
    },
    {
      "x": -11,
      "y": 83,
      "z": -2,
      "name": "Rock_Ice"
    },
    {
      "x": -11,
      "y": 84,
      "z": -2,
      "name": "Soil_Snow"
    },
    {
      "x": -11,
      "y": 21,
      "z": -1,
      "name": "Rock_Ice"
    },
    {
      "x": -11,
      "y": 22,
      "z": -1,
      "name": "Rock_Ice_Permafrost"
    },
    {
      "x": -11,
      "y": 23,
      "z": -1,
      "name": "Rock_Ice_Permafrost"
    },
    {
      "x": -11,
      "y": 24,
      "z": -1,
      "name": "Rock_Ice_Permafrost"
    },
    {
      "x": -11,
      "y": 25,
      "z": -1,
      "name": "Rock_Ice_Permafrost"
    },
    {
      "x": -11,
      "y": 26,
      "z": -1,
      "name": "Rock_Crystal_Cyan_Block_WhiteLight"
    },
    {
      "x": -11,
      "y": 27,
      "z": -1,
      "name": "Rock_Ice_Permafrost"
    },
    {
      "x": -11,
      "y": 28,
      "z": -1,
      "name": "Rock_Ice_Permafrost"
    },
    {
      "x": -11,
      "y": 29,
      "z": -1,
      "name": "Rock_Ice"
    },
    {
      "x": -11,
      "y": 30,
      "z": -1,
      "name": "Rock_Ice"
    },
    {
      "x": -11,
      "y": 31,
      "z": -1,
      "name": "Rock_Ice"
    },
    {
      "x": -11,
      "y": 32,
      "z": -1,
      "name": "Rock_Ice"
    },
    {
      "x": -11,
      "y": 33,
      "z": -1,
      "name": "Rock_Ice"
    },
    {
      "x": -11,
      "y": 34,
      "z": -1,
      "name": "Rock_Ice"
    },
    {
      "x": -11,
      "y": 35,
      "z": -1,
      "name": "Rock_Ice"
    },
    {
      "x": -11,
      "y": 36,
      "z": -1,
      "name": "Rock_Ice"
    },
    {
      "x": -11,
      "y": 37,
      "z": -1,
      "name": "Rock_Ice"
    },
    {
      "x": -11,
      "y": 38,
      "z": -1,
      "name": "Rock_Ice"
    },
    {
      "x": -11,
      "y": 39,
      "z": -1,
      "name": "Rock_Ice"
    },
    {
      "x": -11,
      "y": 40,
      "z": -1,
      "name": "Rock_Ice"
    },
    {
      "x": -11,
      "y": 41,
      "z": -1,
      "name": "Rock_Ice"
    },
    {
      "x": -11,
      "y": 42,
      "z": -1,
      "name": "Rock_Ice"
    },
    {
      "x": -11,
      "y": 43,
      "z": -1,
      "name": "Rock_Ice"
    },
    {
      "x": -11,
      "y": 44,
      "z": -1,
      "name": "Rock_Ice"
    },
    {
      "x": -11,
      "y": 45,
      "z": -1,
      "name": "Rock_Ice"
    },
    {
      "x": -11,
      "y": 46,
      "z": -1,
      "name": "Soil_Snow"
    },
    {
      "x": -11,
      "y": 75,
      "z": -1,
      "name": "Rock_Ice"
    },
    {
      "x": -11,
      "y": 76,
      "z": -1,
      "name": "Rock_Ice"
    },
    {
      "x": -11,
      "y": 77,
      "z": -1,
      "name": "Rock_Ice"
    },
    {
      "x": -11,
      "y": 78,
      "z": -1,
      "name": "Rock_Ice"
    },
    {
      "x": -11,
      "y": 79,
      "z": -1,
      "name": "Rock_Ice"
    },
    {
      "x": -11,
      "y": 80,
      "z": -1,
      "name": "Rock_Ice"
    },
    {
      "x": -11,
      "y": 81,
      "z": -1,
      "name": "Rock_Ice"
    },
    {
      "x": -11,
      "y": 82,
      "z": -1,
      "name": "Rock_Ice"
    },
    {
      "x": -11,
      "y": 83,
      "z": -1,
      "name": "Soil_Snow"
    },
    {
      "x": -11,
      "y": 20,
      "z": 0,
      "name": "Rock_Ice_Permafrost"
    },
    {
      "x": -11,
      "y": 21,
      "z": 0,
      "name": "Rock_Ice_Permafrost"
    },
    {
      "x": -11,
      "y": 22,
      "z": 0,
      "name": "Rock_Ice_Permafrost"
    },
    {
      "x": -11,
      "y": 23,
      "z": 0,
      "name": "Rock_Ice_Permafrost"
    },
    {
      "x": -11,
      "y": 24,
      "z": 0,
      "name": "Rock_Crystal_Cyan_Block_WhiteLight"
    },
    {
      "x": -11,
      "y": 25,
      "z": 0,
      "name": "Rock_Ice_Permafrost"
    },
    {
      "x": -11,
      "y": 26,
      "z": 0,
      "name": "Rock_Crystal_Cyan_Block_WhiteLight"
    },
    {
      "x": -11,
      "y": 27,
      "z": 0,
      "name": "Rock_Ice_Permafrost"
    },
    {
      "x": -11,
      "y": 28,
      "z": 0,
      "name": "Rock_Ice_Permafrost"
    },
    {
      "x": -11,
      "y": 29,
      "z": 0,
      "name": "Rock_Ice_Permafrost"
    },
    {
      "x": -11,
      "y": 30,
      "z": 0,
      "name": "Rock_Ice_Permafrost"
    },
    {
      "x": -11,
      "y": 31,
      "z": 0,
      "name": "Rock_Ice"
    },
    {
      "x": -11,
      "y": 32,
      "z": 0,
      "name": "Rock_Ice"
    },
    {
      "x": -11,
      "y": 33,
      "z": 0,
      "name": "Rock_Ice"
    },
    {
      "x": -11,
      "y": 34,
      "z": 0,
      "name": "Rock_Ice"
    },
    {
      "x": -11,
      "y": 35,
      "z": 0,
      "name": "Rock_Ice"
    },
    {
      "x": -11,
      "y": 36,
      "z": 0,
      "name": "Rock_Ice"
    },
    {
      "x": -11,
      "y": 37,
      "z": 0,
      "name": "Rock_Ice"
    },
    {
      "x": -11,
      "y": 38,
      "z": 0,
      "name": "Rock_Ice"
    },
    {
      "x": -11,
      "y": 39,
      "z": 0,
      "name": "Rock_Ice"
    },
    {
      "x": -11,
      "y": 40,
      "z": 0,
      "name": "Rock_Ice"
    },
    {
      "x": -11,
      "y": 41,
      "z": 0,
      "name": "Rock_Ice"
    },
    {
      "x": -11,
      "y": 42,
      "z": 0,
      "name": "Rock_Ice"
    },
    {
      "x": -11,
      "y": 43,
      "z": 0,
      "name": "Rock_Ice"
    },
    {
      "x": -11,
      "y": 44,
      "z": 0,
      "name": "Rock_Ice"
    },
    {
      "x": -11,
      "y": 45,
      "z": 0,
      "name": "Soil_Snow"
    },
    {
      "x": -11,
      "y": 74,
      "z": 0,
      "name": "Rock_Ice"
    },
    {
      "x": -11,
      "y": 75,
      "z": 0,
      "name": "Rock_Ice"
    },
    {
      "x": -11,
      "y": 76,
      "z": 0,
      "name": "Rock_Ice"
    },
    {
      "x": -11,
      "y": 77,
      "z": 0,
      "name": "Rock_Ice"
    },
    {
      "x": -11,
      "y": 78,
      "z": 0,
      "name": "Rock_Ice"
    },
    {
      "x": -11,
      "y": 79,
      "z": 0,
      "name": "Rock_Ice"
    },
    {
      "x": -11,
      "y": 80,
      "z": 0,
      "name": "Rock_Ice"
    },
    {
      "x": -11,
      "y": 81,
      "z": 0,
      "name": "Rock_Ice"
    },
    {
      "x": -11,
      "y": 82,
      "z": 0,
      "name": "Soil_Snow"
    },
    {
      "x": -11,
      "y": 19,
      "z": 1,
      "name": "Rock_Crystal_Cyan_Block_WhiteLight"
    },
    {
      "x": -11,
      "y": 20,
      "z": 1,
      "name": "Rock_Ice_Permafrost"
    },
    {
      "x": -11,
      "y": 21,
      "z": 1,
      "name": "Rock_Ice_Permafrost"
    },
    {
      "x": -11,
      "y": 22,
      "z": 1,
      "name": "Rock_Ice"
    },
    {
      "x": -11,
      "y": 23,
      "z": 1,
      "name": "Rock_Ice"
    },
    {
      "x": -11,
      "y": 24,
      "z": 1,
      "name": "Rock_Ice"
    },
    {
      "x": -11,
      "y": 25,
      "z": 1,
      "name": "Rock_Ice_Permafrost"
    },
    {
      "x": -11,
      "y": 26,
      "z": 1,
      "name": "Rock_Ice_Permafrost"
    },
    {
      "x": -11,
      "y": 27,
      "z": 1,
      "name": "Rock_Ice_Permafrost"
    },
    {
      "x": -11,
      "y": 28,
      "z": 1,
      "name": "Rock_Ice_Permafrost"
    },
    {
      "x": -11,
      "y": 29,
      "z": 1,
      "name": "Rock_Ice_Permafrost"
    },
    {
      "x": -11,
      "y": 30,
      "z": 1,
      "name": "Rock_Crystal_Cyan_Block_WhiteLight"
    },
    {
      "x": -11,
      "y": 31,
      "z": 1,
      "name": "Rock_Ice_Permafrost"
    },
    {
      "x": -11,
      "y": 32,
      "z": 1,
      "name": "Rock_Ice_Permafrost"
    },
    {
      "x": -11,
      "y": 33,
      "z": 1,
      "name": "Rock_Ice"
    },
    {
      "x": -11,
      "y": 34,
      "z": 1,
      "name": "Rock_Ice"
    },
    {
      "x": -11,
      "y": 35,
      "z": 1,
      "name": "Rock_Ice"
    },
    {
      "x": -11,
      "y": 36,
      "z": 1,
      "name": "Rock_Ice"
    },
    {
      "x": -11,
      "y": 43,
      "z": 1,
      "name": "Rock_Ice"
    },
    {
      "x": -11,
      "y": 44,
      "z": 1,
      "name": "Soil_Snow"
    },
    {
      "x": -11,
      "y": 74,
      "z": 1,
      "name": "Rock_Ice"
    },
    {
      "x": -11,
      "y": 75,
      "z": 1,
      "name": "Rock_Ice"
    },
    {
      "x": -11,
      "y": 76,
      "z": 1,
      "name": "Rock_Ice"
    },
    {
      "x": -11,
      "y": 77,
      "z": 1,
      "name": "Rock_Ice"
    },
    {
      "x": -11,
      "y": 78,
      "z": 1,
      "name": "Rock_Ice"
    },
    {
      "x": -11,
      "y": 79,
      "z": 1,
      "name": "Rock_Ice"
    },
    {
      "x": -11,
      "y": 80,
      "z": 1,
      "name": "Rock_Ice"
    },
    {
      "x": -11,
      "y": 81,
      "z": 1,
      "name": "Rock_Ice"
    },
    {
      "x": -11,
      "y": 82,
      "z": 1,
      "name": "Soil_Snow"
    },
    {
      "x": -11,
      "y": 21,
      "z": 2,
      "name": "Rock_Ice"
    },
    {
      "x": -11,
      "y": 22,
      "z": 2,
      "name": "Rock_Ice"
    },
    {
      "x": -11,
      "y": 23,
      "z": 2,
      "name": "Rock_Ice"
    },
    {
      "x": -11,
      "y": 24,
      "z": 2,
      "name": "Rock_Ice"
    },
    {
      "x": -11,
      "y": 25,
      "z": 2,
      "name": "Rock_Ice"
    },
    {
      "x": -11,
      "y": 26,
      "z": 2,
      "name": "Rock_Ice"
    },
    {
      "x": -11,
      "y": 27,
      "z": 2,
      "name": "Rock_Ice"
    },
    {
      "x": -11,
      "y": 28,
      "z": 2,
      "name": "Rock_Ice"
    },
    {
      "x": -11,
      "y": 29,
      "z": 2,
      "name": "Rock_Ice_Permafrost"
    },
    {
      "x": -11,
      "y": 30,
      "z": 2,
      "name": "Rock_Ice_Permafrost"
    },
    {
      "x": -11,
      "y": 31,
      "z": 2,
      "name": "Rock_Crystal_Cyan_Block_WhiteLight"
    },
    {
      "x": -11,
      "y": 32,
      "z": 2,
      "name": "Rock_Ice_Permafrost"
    },
    {
      "x": -11,
      "y": 33,
      "z": 2,
      "name": "Rock_Ice"
    },
    {
      "x": -11,
      "y": 34,
      "z": 2,
      "name": "Soil_Snow"
    },
    {
      "x": -11,
      "y": 72,
      "z": 2,
      "name": "Rock_Ice"
    },
    {
      "x": -11,
      "y": 73,
      "z": 2,
      "name": "Rock_Ice"
    },
    {
      "x": -11,
      "y": 74,
      "z": 2,
      "name": "Rock_Ice"
    },
    {
      "x": -11,
      "y": 75,
      "z": 2,
      "name": "Rock_Ice"
    },
    {
      "x": -11,
      "y": 76,
      "z": 2,
      "name": "Rock_Ice"
    },
    {
      "x": -11,
      "y": 77,
      "z": 2,
      "name": "Rock_Ice"
    },
    {
      "x": -11,
      "y": 78,
      "z": 2,
      "name": "Rock_Ice"
    },
    {
      "x": -11,
      "y": 79,
      "z": 2,
      "name": "Rock_Ice"
    },
    {
      "x": -11,
      "y": 80,
      "z": 2,
      "name": "Rock_Ice"
    },
    {
      "x": -11,
      "y": 81,
      "z": 2,
      "name": "Rock_Ice"
    },
    {
      "x": -11,
      "y": 82,
      "z": 2,
      "name": "Rock_Ice"
    },
    {
      "x": -11,
      "y": 83,
      "z": 2,
      "name": "Rock_Ice"
    },
    {
      "x": -11,
      "y": 84,
      "z": 2,
      "name": "Soil_Snow"
    },
    {
      "x": -11,
      "y": 22,
      "z": 3,
      "name": "Rock_Ice"
    },
    {
      "x": -11,
      "y": 23,
      "z": 3,
      "name": "Rock_Ice"
    },
    {
      "x": -11,
      "y": 24,
      "z": 3,
      "name": "Rock_Ice"
    },
    {
      "x": -11,
      "y": 25,
      "z": 3,
      "name": "Rock_Ice"
    },
    {
      "x": -11,
      "y": 26,
      "z": 3,
      "name": "Rock_Ice"
    },
    {
      "x": -11,
      "y": 27,
      "z": 3,
      "name": "Rock_Ice"
    },
    {
      "x": -11,
      "y": 28,
      "z": 3,
      "name": "Rock_Ice"
    },
    {
      "x": -11,
      "y": 29,
      "z": 3,
      "name": "Rock_Ice"
    },
    {
      "x": -11,
      "y": 30,
      "z": 3,
      "name": "Rock_Ice"
    },
    {
      "x": -11,
      "y": 31,
      "z": 3,
      "name": "Rock_Ice"
    },
    {
      "x": -11,
      "y": 32,
      "z": 3,
      "name": "Rock_Ice"
    },
    {
      "x": -11,
      "y": 33,
      "z": 3,
      "name": "Soil_Snow"
    },
    {
      "x": -11,
      "y": 73,
      "z": 3,
      "name": "Rock_Ice"
    },
    {
      "x": -11,
      "y": 74,
      "z": 3,
      "name": "Rock_Ice"
    },
    {
      "x": -11,
      "y": 75,
      "z": 3,
      "name": "Rock_Ice"
    },
    {
      "x": -11,
      "y": 76,
      "z": 3,
      "name": "Rock_Ice"
    },
    {
      "x": -11,
      "y": 77,
      "z": 3,
      "name": "Rock_Ice"
    },
    {
      "x": -11,
      "y": 78,
      "z": 3,
      "name": "Rock_Ice"
    },
    {
      "x": -11,
      "y": 79,
      "z": 3,
      "name": "Rock_Ice"
    },
    {
      "x": -11,
      "y": 80,
      "z": 3,
      "name": "Rock_Ice"
    },
    {
      "x": -11,
      "y": 81,
      "z": 3,
      "name": "Rock_Ice"
    },
    {
      "x": -11,
      "y": 82,
      "z": 3,
      "name": "Rock_Ice"
    },
    {
      "x": -11,
      "y": 83,
      "z": 3,
      "name": "Rock_Ice"
    },
    {
      "x": -11,
      "y": 84,
      "z": 3,
      "name": "Rock_Ice"
    },
    {
      "x": -11,
      "y": 23,
      "z": 4,
      "name": "Rock_Ice"
    },
    {
      "x": -11,
      "y": 24,
      "z": 4,
      "name": "Rock_Ice"
    },
    {
      "x": -11,
      "y": 25,
      "z": 4,
      "name": "Rock_Ice"
    },
    {
      "x": -11,
      "y": 26,
      "z": 4,
      "name": "Rock_Ice"
    },
    {
      "x": -11,
      "y": 27,
      "z": 4,
      "name": "Rock_Ice"
    },
    {
      "x": -11,
      "y": 28,
      "z": 4,
      "name": "Rock_Ice"
    },
    {
      "x": -11,
      "y": 29,
      "z": 4,
      "name": "Rock_Ice"
    },
    {
      "x": -11,
      "y": 30,
      "z": 4,
      "name": "Rock_Ice"
    },
    {
      "x": -11,
      "y": 31,
      "z": 4,
      "name": "Rock_Ice"
    },
    {
      "x": -11,
      "y": 32,
      "z": 4,
      "name": "Rock_Ice"
    },
    {
      "x": -11,
      "y": 33,
      "z": 4,
      "name": "Soil_Snow"
    },
    {
      "x": -11,
      "y": 75,
      "z": 4,
      "name": "Rock_Ice"
    },
    {
      "x": -11,
      "y": 76,
      "z": 4,
      "name": "Rock_Ice"
    },
    {
      "x": -11,
      "y": 77,
      "z": 4,
      "name": "Rock_Ice"
    },
    {
      "x": -11,
      "y": 78,
      "z": 4,
      "name": "Rock_Ice"
    },
    {
      "x": -11,
      "y": 79,
      "z": 4,
      "name": "Rock_Ice"
    },
    {
      "x": -11,
      "y": 80,
      "z": 4,
      "name": "Rock_Ice"
    },
    {
      "x": -11,
      "y": 81,
      "z": 4,
      "name": "Rock_Ice"
    },
    {
      "x": -11,
      "y": 82,
      "z": 4,
      "name": "Soil_Snow"
    },
    {
      "x": -11,
      "y": 23,
      "z": 5,
      "name": "Rock_Ice"
    },
    {
      "x": -11,
      "y": 24,
      "z": 5,
      "name": "Rock_Ice"
    },
    {
      "x": -11,
      "y": 25,
      "z": 5,
      "name": "Rock_Ice"
    },
    {
      "x": -11,
      "y": 26,
      "z": 5,
      "name": "Rock_Ice"
    },
    {
      "x": -11,
      "y": 27,
      "z": 5,
      "name": "Rock_Ice"
    },
    {
      "x": -11,
      "y": 28,
      "z": 5,
      "name": "Rock_Ice"
    },
    {
      "x": -11,
      "y": 29,
      "z": 5,
      "name": "Rock_Ice"
    },
    {
      "x": -11,
      "y": 30,
      "z": 5,
      "name": "Rock_Ice"
    },
    {
      "x": -11,
      "y": 31,
      "z": 5,
      "name": "Rock_Ice"
    },
    {
      "x": -11,
      "y": 32,
      "z": 5,
      "name": "Rock_Ice"
    },
    {
      "x": -11,
      "y": 33,
      "z": 5,
      "name": "Soil_Snow"
    },
    {
      "x": -11,
      "y": 76,
      "z": 5,
      "name": "Rock_Ice"
    },
    {
      "x": -11,
      "y": 77,
      "z": 5,
      "name": "Rock_Ice"
    },
    {
      "x": -11,
      "y": 78,
      "z": 5,
      "name": "Rock_Ice"
    },
    {
      "x": -11,
      "y": 79,
      "z": 5,
      "name": "Rock_Ice"
    },
    {
      "x": -11,
      "y": 80,
      "z": 5,
      "name": "Rock_Ice"
    },
    {
      "x": -11,
      "y": 81,
      "z": 5,
      "name": "Soil_Snow"
    },
    {
      "x": -11,
      "y": 25,
      "z": 6,
      "name": "Rock_Ice"
    },
    {
      "x": -11,
      "y": 26,
      "z": 6,
      "name": "Rock_Ice"
    },
    {
      "x": -11,
      "y": 27,
      "z": 6,
      "name": "Rock_Ice"
    },
    {
      "x": -11,
      "y": 28,
      "z": 6,
      "name": "Rock_Ice"
    },
    {
      "x": -11,
      "y": 29,
      "z": 6,
      "name": "Rock_Ice"
    },
    {
      "x": -11,
      "y": 30,
      "z": 6,
      "name": "Rock_Ice"
    },
    {
      "x": -11,
      "y": 31,
      "z": 6,
      "name": "Rock_Ice"
    },
    {
      "x": -11,
      "y": 32,
      "z": 6,
      "name": "Rock_Ice"
    },
    {
      "x": -11,
      "y": 33,
      "z": 6,
      "name": "Soil_Snow"
    },
    {
      "x": -11,
      "y": 76,
      "z": 6,
      "name": "Rock_Ice"
    },
    {
      "x": -11,
      "y": 77,
      "z": 6,
      "name": "Rock_Ice"
    },
    {
      "x": -11,
      "y": 78,
      "z": 6,
      "name": "Rock_Ice"
    },
    {
      "x": -11,
      "y": 79,
      "z": 6,
      "name": "Rock_Ice"
    },
    {
      "x": -11,
      "y": 80,
      "z": 6,
      "name": "Soil_Snow"
    },
    {
      "x": -11,
      "y": 77,
      "z": 7,
      "name": "Rock_Ice"
    },
    {
      "x": -11,
      "y": 78,
      "z": 7,
      "name": "Rock_Ice"
    },
    {
      "x": -11,
      "y": 79,
      "z": 7,
      "name": "Rock_Ice"
    },
    {
      "x": -11,
      "y": 80,
      "z": 7,
      "name": "Soil_Snow"
    },
    {
      "x": -11,
      "y": 26,
      "z": 8,
      "name": "Rock_Ice"
    },
    {
      "x": -11,
      "y": 27,
      "z": 8,
      "name": "Rock_Ice"
    },
    {
      "x": -11,
      "y": 28,
      "z": 8,
      "name": "Rock_Ice"
    },
    {
      "x": -11,
      "y": 29,
      "z": 8,
      "name": "Soil_Snow"
    },
    {
      "x": -11,
      "y": 77,
      "z": 8,
      "name": "Rock_Ice"
    },
    {
      "x": -11,
      "y": 78,
      "z": 8,
      "name": "Rock_Ice"
    },
    {
      "x": -11,
      "y": 79,
      "z": 8,
      "name": "Soil_Snow"
    },
    {
      "x": -11,
      "y": 22,
      "z": 9,
      "name": "Rock_Ice_Permafrost"
    },
    {
      "x": -11,
      "y": 23,
      "z": 9,
      "name": "Rock_Ice"
    },
    {
      "x": -11,
      "y": 24,
      "z": 9,
      "name": "Rock_Ice_Permafrost"
    },
    {
      "x": -11,
      "y": 25,
      "z": 9,
      "name": "Rock_Ice"
    },
    {
      "x": -11,
      "y": 26,
      "z": 9,
      "name": "Rock_Ice"
    },
    {
      "x": -11,
      "y": 27,
      "z": 9,
      "name": "Rock_Ice"
    },
    {
      "x": -11,
      "y": 28,
      "z": 9,
      "name": "Rock_Ice"
    },
    {
      "x": -11,
      "y": 29,
      "z": 9,
      "name": "Rock_Ice"
    },
    {
      "x": -11,
      "y": 30,
      "z": 9,
      "name": "Rock_Ice"
    },
    {
      "x": -11,
      "y": 31,
      "z": 9,
      "name": "Rock_Ice"
    },
    {
      "x": -11,
      "y": 32,
      "z": 9,
      "name": "Rock_Ice"
    },
    {
      "x": -11,
      "y": 33,
      "z": 9,
      "name": "Rock_Ice"
    },
    {
      "x": -11,
      "y": 34,
      "z": 9,
      "name": "Rock_Ice"
    },
    {
      "x": -11,
      "y": 35,
      "z": 9,
      "name": "Soil_Snow"
    },
    {
      "x": -11,
      "y": 77,
      "z": 9,
      "name": "Rock_Ice"
    },
    {
      "x": -11,
      "y": 78,
      "z": 9,
      "name": "Rock_Ice"
    },
    {
      "x": -11,
      "y": 79,
      "z": 9,
      "name": "Soil_Snow"
    },
    {
      "x": -11,
      "y": 21,
      "z": 10,
      "name": "Rock_Ice"
    },
    {
      "x": -11,
      "y": 22,
      "z": 10,
      "name": "Rock_Ice_Permafrost"
    },
    {
      "x": -11,
      "y": 23,
      "z": 10,
      "name": "Rock_Ice_Permafrost"
    },
    {
      "x": -11,
      "y": 24,
      "z": 10,
      "name": "Rock_Ice_Permafrost"
    },
    {
      "x": -11,
      "y": 25,
      "z": 10,
      "name": "Rock_Ice_Permafrost"
    },
    {
      "x": -11,
      "y": 26,
      "z": 10,
      "name": "Rock_Ice"
    },
    {
      "x": -11,
      "y": 27,
      "z": 10,
      "name": "Rock_Ice_Permafrost"
    },
    {
      "x": -11,
      "y": 28,
      "z": 10,
      "name": "Rock_Ice_Permafrost"
    },
    {
      "x": -11,
      "y": 29,
      "z": 10,
      "name": "Rock_Ice"
    },
    {
      "x": -11,
      "y": 30,
      "z": 10,
      "name": "Rock_Ice"
    },
    {
      "x": -11,
      "y": 31,
      "z": 10,
      "name": "Rock_Ice"
    },
    {
      "x": -11,
      "y": 22,
      "z": 11,
      "name": "Rock_Ice"
    },
    {
      "x": -11,
      "y": 23,
      "z": 11,
      "name": "Rock_Ice_Permafrost"
    },
    {
      "x": -11,
      "y": 24,
      "z": 11,
      "name": "Rock_Ice"
    },
    {
      "x": -11,
      "y": 25,
      "z": 11,
      "name": "Rock_Ice"
    },
    {
      "x": -11,
      "y": 26,
      "z": 11,
      "name": "Rock_Ice"
    },
    {
      "x": -11,
      "y": 27,
      "z": 11,
      "name": "Rock_Ice"
    },
    {
      "x": -11,
      "y": 28,
      "z": 11,
      "name": "Rock_Ice"
    },
    {
      "x": -11,
      "y": 29,
      "z": 11,
      "name": "Soil_Snow"
    },
    {
      "x": -10,
      "y": 43,
      "z": -10,
      "name": "Rock_Ice"
    },
    {
      "x": -10,
      "y": 44,
      "z": -10,
      "name": "Rock_Ice"
    },
    {
      "x": -10,
      "y": 45,
      "z": -10,
      "name": "Rock_Ice"
    },
    {
      "x": -10,
      "y": 46,
      "z": -10,
      "name": "Rock_Ice"
    },
    {
      "x": -10,
      "y": 47,
      "z": -10,
      "name": "Soil_Snow"
    },
    {
      "x": -10,
      "y": 43,
      "z": -9,
      "name": "Rock_Ice"
    },
    {
      "x": -10,
      "y": 44,
      "z": -9,
      "name": "Rock_Ice"
    },
    {
      "x": -10,
      "y": 45,
      "z": -9,
      "name": "Rock_Ice"
    },
    {
      "x": -10,
      "y": 46,
      "z": -9,
      "name": "Rock_Ice"
    },
    {
      "x": -10,
      "y": 47,
      "z": -9,
      "name": "Rock_Ice"
    },
    {
      "x": -10,
      "y": 48,
      "z": -9,
      "name": "Rock_Ice"
    },
    {
      "x": -10,
      "y": 49,
      "z": -9,
      "name": "Rock_Ice"
    },
    {
      "x": -10,
      "y": 50,
      "z": -9,
      "name": "Rock_Ice"
    },
    {
      "x": -10,
      "y": 67,
      "z": -9,
      "name": "Soil_Snow"
    },
    {
      "x": -10,
      "y": 24,
      "z": -8,
      "name": "Rock_Ice"
    },
    {
      "x": -10,
      "y": 25,
      "z": -8,
      "name": "Rock_Ice"
    },
    {
      "x": -10,
      "y": 42,
      "z": -8,
      "name": "Rock_Ice"
    },
    {
      "x": -10,
      "y": 43,
      "z": -8,
      "name": "Rock_Ice"
    },
    {
      "x": -10,
      "y": 44,
      "z": -8,
      "name": "Rock_Ice"
    },
    {
      "x": -10,
      "y": 45,
      "z": -8,
      "name": "Rock_Ice"
    },
    {
      "x": -10,
      "y": 46,
      "z": -8,
      "name": "Rock_Ice"
    },
    {
      "x": -10,
      "y": 47,
      "z": -8,
      "name": "Rock_Ice"
    },
    {
      "x": -10,
      "y": 48,
      "z": -8,
      "name": "Rock_Ice"
    },
    {
      "x": -10,
      "y": 49,
      "z": -8,
      "name": "Rock_Ice"
    },
    {
      "x": -10,
      "y": 50,
      "z": -8,
      "name": "Rock_Ice"
    },
    {
      "x": -10,
      "y": 51,
      "z": -8,
      "name": "Rock_Ice"
    },
    {
      "x": -10,
      "y": 52,
      "z": -8,
      "name": "Rock_Ice"
    },
    {
      "x": -10,
      "y": 67,
      "z": -8,
      "name": "Rock_Ice"
    },
    {
      "x": -10,
      "y": 68,
      "z": -8,
      "name": "Rock_Ice"
    },
    {
      "x": -10,
      "y": 69,
      "z": -8,
      "name": "Rock_Ice"
    },
    {
      "x": -10,
      "y": 70,
      "z": -8,
      "name": "Rock_Ice"
    },
    {
      "x": -10,
      "y": 71,
      "z": -8,
      "name": "Soil_Snow"
    },
    {
      "x": -10,
      "y": 21,
      "z": -7,
      "name": "Rock_Ice"
    },
    {
      "x": -10,
      "y": 22,
      "z": -7,
      "name": "Rock_Ice"
    },
    {
      "x": -10,
      "y": 23,
      "z": -7,
      "name": "Rock_Ice"
    },
    {
      "x": -10,
      "y": 24,
      "z": -7,
      "name": "Rock_Ice"
    },
    {
      "x": -10,
      "y": 25,
      "z": -7,
      "name": "Rock_Ice"
    },
    {
      "x": -10,
      "y": 26,
      "z": -7,
      "name": "Rock_Ice"
    },
    {
      "x": -10,
      "y": 40,
      "z": -7,
      "name": "Rock_Ice"
    },
    {
      "x": -10,
      "y": 41,
      "z": -7,
      "name": "Rock_Ice"
    },
    {
      "x": -10,
      "y": 42,
      "z": -7,
      "name": "Rock_Ice"
    },
    {
      "x": -10,
      "y": 43,
      "z": -7,
      "name": "Rock_Ice"
    },
    {
      "x": -10,
      "y": 44,
      "z": -7,
      "name": "Rock_Ice"
    },
    {
      "x": -10,
      "y": 45,
      "z": -7,
      "name": "Rock_Ice"
    },
    {
      "x": -10,
      "y": 46,
      "z": -7,
      "name": "Rock_Ice"
    },
    {
      "x": -10,
      "y": 47,
      "z": -7,
      "name": "Rock_Ice"
    },
    {
      "x": -10,
      "y": 48,
      "z": -7,
      "name": "Rock_Ice"
    },
    {
      "x": -10,
      "y": 49,
      "z": -7,
      "name": "Rock_Ice"
    },
    {
      "x": -10,
      "y": 50,
      "z": -7,
      "name": "Rock_Ice"
    },
    {
      "x": -10,
      "y": 51,
      "z": -7,
      "name": "Rock_Ice"
    },
    {
      "x": -10,
      "y": 52,
      "z": -7,
      "name": "Rock_Ice"
    },
    {
      "x": -10,
      "y": 53,
      "z": -7,
      "name": "Rock_Ice"
    },
    {
      "x": -10,
      "y": 55,
      "z": -7,
      "name": "Rock_Ice"
    },
    {
      "x": -10,
      "y": 56,
      "z": -7,
      "name": "Rock_Ice"
    },
    {
      "x": -10,
      "y": 57,
      "z": -7,
      "name": "Rock_Ice"
    },
    {
      "x": -10,
      "y": 68,
      "z": -7,
      "name": "Rock_Ice"
    },
    {
      "x": -10,
      "y": 69,
      "z": -7,
      "name": "Rock_Ice"
    },
    {
      "x": -10,
      "y": 70,
      "z": -7,
      "name": "Rock_Ice"
    },
    {
      "x": -10,
      "y": 71,
      "z": -7,
      "name": "Rock_Ice"
    },
    {
      "x": -10,
      "y": 72,
      "z": -7,
      "name": "Rock_Ice"
    },
    {
      "x": -10,
      "y": 73,
      "z": -7,
      "name": "Rock_Ice"
    },
    {
      "x": -10,
      "y": 74,
      "z": -7,
      "name": "Rock_Ice"
    },
    {
      "x": -10,
      "y": 75,
      "z": -7,
      "name": "Soil_Snow"
    },
    {
      "x": -10,
      "y": 20,
      "z": -6,
      "name": "Rock_Ice"
    },
    {
      "x": -10,
      "y": 21,
      "z": -6,
      "name": "Rock_Ice"
    },
    {
      "x": -10,
      "y": 22,
      "z": -6,
      "name": "Rock_Ice"
    },
    {
      "x": -10,
      "y": 23,
      "z": -6,
      "name": "Rock_Ice"
    },
    {
      "x": -10,
      "y": 24,
      "z": -6,
      "name": "Rock_Ice"
    },
    {
      "x": -10,
      "y": 25,
      "z": -6,
      "name": "Rock_Ice"
    },
    {
      "x": -10,
      "y": 26,
      "z": -6,
      "name": "Rock_Ice"
    },
    {
      "x": -10,
      "y": 27,
      "z": -6,
      "name": "Rock_Ice"
    },
    {
      "x": -10,
      "y": 28,
      "z": -6,
      "name": "Rock_Ice"
    },
    {
      "x": -10,
      "y": 38,
      "z": -6,
      "name": "Rock_Ice"
    },
    {
      "x": -10,
      "y": 39,
      "z": -6,
      "name": "Rock_Ice"
    },
    {
      "x": -10,
      "y": 40,
      "z": -6,
      "name": "Rock_Ice"
    },
    {
      "x": -10,
      "y": 41,
      "z": -6,
      "name": "Rock_Ice"
    },
    {
      "x": -10,
      "y": 42,
      "z": -6,
      "name": "Rock_Ice"
    },
    {
      "x": -10,
      "y": 43,
      "z": -6,
      "name": "Rock_Ice"
    },
    {
      "x": -10,
      "y": 44,
      "z": -6,
      "name": "Rock_Ice"
    },
    {
      "x": -10,
      "y": 45,
      "z": -6,
      "name": "Rock_Ice"
    },
    {
      "x": -10,
      "y": 46,
      "z": -6,
      "name": "Rock_Ice"
    },
    {
      "x": -10,
      "y": 47,
      "z": -6,
      "name": "Rock_Ice"
    },
    {
      "x": -10,
      "y": 48,
      "z": -6,
      "name": "Rock_Ice"
    },
    {
      "x": -10,
      "y": 49,
      "z": -6,
      "name": "Rock_Ice"
    },
    {
      "x": -10,
      "y": 50,
      "z": -6,
      "name": "Rock_Ice"
    },
    {
      "x": -10,
      "y": 51,
      "z": -6,
      "name": "Rock_Ice"
    },
    {
      "x": -10,
      "y": 52,
      "z": -6,
      "name": "Rock_Ice"
    },
    {
      "x": -10,
      "y": 53,
      "z": -6,
      "name": "Rock_Ice"
    },
    {
      "x": -10,
      "y": 54,
      "z": -6,
      "name": "Rock_Ice"
    },
    {
      "x": -10,
      "y": 55,
      "z": -6,
      "name": "Rock_Ice"
    },
    {
      "x": -10,
      "y": 56,
      "z": -6,
      "name": "Rock_Ice"
    },
    {
      "x": -10,
      "y": 57,
      "z": -6,
      "name": "Rock_Ice"
    },
    {
      "x": -10,
      "y": 58,
      "z": -6,
      "name": "Rock_Ice"
    },
    {
      "x": -10,
      "y": 59,
      "z": -6,
      "name": "Rock_Ice"
    },
    {
      "x": -10,
      "y": 60,
      "z": -6,
      "name": "Rock_Ice"
    },
    {
      "x": -10,
      "y": 71,
      "z": -6,
      "name": "Rock_Ice"
    },
    {
      "x": -10,
      "y": 72,
      "z": -6,
      "name": "Rock_Ice"
    },
    {
      "x": -10,
      "y": 73,
      "z": -6,
      "name": "Rock_Ice"
    },
    {
      "x": -10,
      "y": 74,
      "z": -6,
      "name": "Rock_Ice"
    },
    {
      "x": -10,
      "y": 75,
      "z": -6,
      "name": "Rock_Ice"
    },
    {
      "x": -10,
      "y": 76,
      "z": -6,
      "name": "Rock_Ice"
    },
    {
      "x": -10,
      "y": 77,
      "z": -6,
      "name": "Rock_Ice"
    },
    {
      "x": -10,
      "y": 78,
      "z": -6,
      "name": "Rock_Ice_Permafrost"
    },
    {
      "x": -10,
      "y": 79,
      "z": -6,
      "name": "Rock_Ice"
    },
    {
      "x": -10,
      "y": 80,
      "z": -6,
      "name": "Soil_Snow"
    },
    {
      "x": -10,
      "y": 18,
      "z": -5,
      "name": "Rock_Ice"
    },
    {
      "x": -10,
      "y": 19,
      "z": -5,
      "name": "Rock_Ice"
    },
    {
      "x": -10,
      "y": 20,
      "z": -5,
      "name": "Rock_Ice"
    },
    {
      "x": -10,
      "y": 21,
      "z": -5,
      "name": "Rock_Ice"
    },
    {
      "x": -10,
      "y": 22,
      "z": -5,
      "name": "Rock_Ice"
    },
    {
      "x": -10,
      "y": 23,
      "z": -5,
      "name": "Rock_Ice"
    },
    {
      "x": -10,
      "y": 24,
      "z": -5,
      "name": "Rock_Ice"
    },
    {
      "x": -10,
      "y": 25,
      "z": -5,
      "name": "Rock_Ice"
    },
    {
      "x": -10,
      "y": 26,
      "z": -5,
      "name": "Rock_Ice"
    },
    {
      "x": -10,
      "y": 27,
      "z": -5,
      "name": "Rock_Ice"
    },
    {
      "x": -10,
      "y": 28,
      "z": -5,
      "name": "Rock_Ice"
    },
    {
      "x": -10,
      "y": 29,
      "z": -5,
      "name": "Rock_Ice"
    },
    {
      "x": -10,
      "y": 30,
      "z": -5,
      "name": "Rock_Ice"
    },
    {
      "x": -10,
      "y": 31,
      "z": -5,
      "name": "Rock_Ice"
    },
    {
      "x": -10,
      "y": 32,
      "z": -5,
      "name": "Rock_Ice"
    },
    {
      "x": -10,
      "y": 33,
      "z": -5,
      "name": "Rock_Ice"
    },
    {
      "x": -10,
      "y": 34,
      "z": -5,
      "name": "Rock_Ice"
    },
    {
      "x": -10,
      "y": 35,
      "z": -5,
      "name": "Rock_Ice"
    },
    {
      "x": -10,
      "y": 36,
      "z": -5,
      "name": "Rock_Ice"
    },
    {
      "x": -10,
      "y": 37,
      "z": -5,
      "name": "Rock_Ice"
    },
    {
      "x": -10,
      "y": 38,
      "z": -5,
      "name": "Rock_Ice"
    },
    {
      "x": -10,
      "y": 39,
      "z": -5,
      "name": "Rock_Ice"
    },
    {
      "x": -10,
      "y": 40,
      "z": -5,
      "name": "Rock_Ice"
    },
    {
      "x": -10,
      "y": 41,
      "z": -5,
      "name": "Rock_Ice"
    },
    {
      "x": -10,
      "y": 42,
      "z": -5,
      "name": "Rock_Ice"
    },
    {
      "x": -10,
      "y": 43,
      "z": -5,
      "name": "Rock_Ice"
    },
    {
      "x": -10,
      "y": 44,
      "z": -5,
      "name": "Rock_Ice"
    },
    {
      "x": -10,
      "y": 45,
      "z": -5,
      "name": "Rock_Ice"
    },
    {
      "x": -10,
      "y": 46,
      "z": -5,
      "name": "Rock_Ice"
    },
    {
      "x": -10,
      "y": 47,
      "z": -5,
      "name": "Rock_Ice"
    },
    {
      "x": -10,
      "y": 48,
      "z": -5,
      "name": "Rock_Ice"
    },
    {
      "x": -10,
      "y": 49,
      "z": -5,
      "name": "Rock_Ice"
    },
    {
      "x": -10,
      "y": 50,
      "z": -5,
      "name": "Rock_Ice"
    },
    {
      "x": -10,
      "y": 51,
      "z": -5,
      "name": "Rock_Ice"
    },
    {
      "x": -10,
      "y": 52,
      "z": -5,
      "name": "Rock_Ice"
    },
    {
      "x": -10,
      "y": 53,
      "z": -5,
      "name": "Rock_Ice"
    },
    {
      "x": -10,
      "y": 54,
      "z": -5,
      "name": "Rock_Ice"
    },
    {
      "x": -10,
      "y": 55,
      "z": -5,
      "name": "Rock_Ice"
    },
    {
      "x": -10,
      "y": 56,
      "z": -5,
      "name": "Rock_Ice"
    },
    {
      "x": -10,
      "y": 57,
      "z": -5,
      "name": "Rock_Ice"
    },
    {
      "x": -10,
      "y": 58,
      "z": -5,
      "name": "Rock_Ice"
    },
    {
      "x": -10,
      "y": 59,
      "z": -5,
      "name": "Rock_Ice"
    },
    {
      "x": -10,
      "y": 60,
      "z": -5,
      "name": "Rock_Ice"
    },
    {
      "x": -10,
      "y": 61,
      "z": -5,
      "name": "Rock_Ice"
    },
    {
      "x": -10,
      "y": 72,
      "z": -5,
      "name": "Rock_Ice"
    },
    {
      "x": -10,
      "y": 73,
      "z": -5,
      "name": "Rock_Ice"
    },
    {
      "x": -10,
      "y": 74,
      "z": -5,
      "name": "Rock_Ice"
    },
    {
      "x": -10,
      "y": 75,
      "z": -5,
      "name": "Rock_Ice"
    },
    {
      "x": -10,
      "y": 76,
      "z": -5,
      "name": "Rock_Ice"
    },
    {
      "x": -10,
      "y": 77,
      "z": -5,
      "name": "Rock_Ice"
    },
    {
      "x": -10,
      "y": 78,
      "z": -5,
      "name": "Rock_Ice"
    },
    {
      "x": -10,
      "y": 79,
      "z": -5,
      "name": "Rock_Ice"
    },
    {
      "x": -10,
      "y": 80,
      "z": -5,
      "name": "Rock_Ice"
    },
    {
      "x": -10,
      "y": 81,
      "z": -5,
      "name": "Rock_Ice_Permafrost"
    },
    {
      "x": -10,
      "y": 82,
      "z": -5,
      "name": "Rock_Ice_Permafrost"
    },
    {
      "x": -10,
      "y": 83,
      "z": -5,
      "name": "Rock_Crystal_Cyan_Block_WhiteLight"
    },
    {
      "x": -10,
      "y": 84,
      "z": -5,
      "name": "Rock_Ice"
    },
    {
      "x": -10,
      "y": 85,
      "z": -5,
      "name": "Soil_Snow"
    },
    {
      "x": -10,
      "y": 17,
      "z": -4,
      "name": "Rock_Ice"
    },
    {
      "x": -10,
      "y": 18,
      "z": -4,
      "name": "Rock_Ice"
    },
    {
      "x": -10,
      "y": 19,
      "z": -4,
      "name": "Rock_Ice"
    },
    {
      "x": -10,
      "y": 20,
      "z": -4,
      "name": "Rock_Ice"
    },
    {
      "x": -10,
      "y": 21,
      "z": -4,
      "name": "Rock_Ice"
    },
    {
      "x": -10,
      "y": 22,
      "z": -4,
      "name": "Rock_Ice"
    },
    {
      "x": -10,
      "y": 23,
      "z": -4,
      "name": "Rock_Ice"
    },
    {
      "x": -10,
      "y": 24,
      "z": -4,
      "name": "Rock_Ice"
    },
    {
      "x": -10,
      "y": 25,
      "z": -4,
      "name": "Rock_Ice"
    },
    {
      "x": -10,
      "y": 26,
      "z": -4,
      "name": "Rock_Ice"
    },
    {
      "x": -10,
      "y": 27,
      "z": -4,
      "name": "Rock_Ice"
    },
    {
      "x": -10,
      "y": 28,
      "z": -4,
      "name": "Rock_Ice"
    },
    {
      "x": -10,
      "y": 29,
      "z": -4,
      "name": "Rock_Ice"
    },
    {
      "x": -10,
      "y": 30,
      "z": -4,
      "name": "Rock_Ice"
    },
    {
      "x": -10,
      "y": 31,
      "z": -4,
      "name": "Rock_Ice"
    },
    {
      "x": -10,
      "y": 32,
      "z": -4,
      "name": "Rock_Ice"
    },
    {
      "x": -10,
      "y": 33,
      "z": -4,
      "name": "Rock_Ice"
    },
    {
      "x": -10,
      "y": 34,
      "z": -4,
      "name": "Rock_Ice"
    },
    {
      "x": -10,
      "y": 35,
      "z": -4,
      "name": "Rock_Ice"
    },
    {
      "x": -10,
      "y": 36,
      "z": -4,
      "name": "Rock_Ice"
    },
    {
      "x": -10,
      "y": 37,
      "z": -4,
      "name": "Rock_Ice"
    },
    {
      "x": -10,
      "y": 38,
      "z": -4,
      "name": "Rock_Ice"
    },
    {
      "x": -10,
      "y": 39,
      "z": -4,
      "name": "Rock_Ice"
    },
    {
      "x": -10,
      "y": 40,
      "z": -4,
      "name": "Rock_Ice"
    },
    {
      "x": -10,
      "y": 41,
      "z": -4,
      "name": "Rock_Ice"
    },
    {
      "x": -10,
      "y": 42,
      "z": -4,
      "name": "Rock_Ice"
    },
    {
      "x": -10,
      "y": 43,
      "z": -4,
      "name": "Rock_Ice"
    },
    {
      "x": -10,
      "y": 44,
      "z": -4,
      "name": "Rock_Ice"
    },
    {
      "x": -10,
      "y": 45,
      "z": -4,
      "name": "Rock_Ice"
    },
    {
      "x": -10,
      "y": 46,
      "z": -4,
      "name": "Rock_Ice"
    },
    {
      "x": -10,
      "y": 47,
      "z": -4,
      "name": "Rock_Ice"
    },
    {
      "x": -10,
      "y": 48,
      "z": -4,
      "name": "Rock_Ice"
    },
    {
      "x": -10,
      "y": 49,
      "z": -4,
      "name": "Rock_Ice"
    },
    {
      "x": -10,
      "y": 50,
      "z": -4,
      "name": "Rock_Ice"
    },
    {
      "x": -10,
      "y": 51,
      "z": -4,
      "name": "Rock_Ice"
    },
    {
      "x": -10,
      "y": 52,
      "z": -4,
      "name": "Rock_Ice"
    },
    {
      "x": -10,
      "y": 53,
      "z": -4,
      "name": "Rock_Ice"
    },
    {
      "x": -10,
      "y": 54,
      "z": -4,
      "name": "Rock_Ice"
    },
    {
      "x": -10,
      "y": 55,
      "z": -4,
      "name": "Rock_Ice"
    },
    {
      "x": -10,
      "y": 56,
      "z": -4,
      "name": "Rock_Ice"
    },
    {
      "x": -10,
      "y": 57,
      "z": -4,
      "name": "Rock_Ice"
    },
    {
      "x": -10,
      "y": 58,
      "z": -4,
      "name": "Rock_Ice"
    },
    {
      "x": -10,
      "y": 59,
      "z": -4,
      "name": "Rock_Ice"
    },
    {
      "x": -10,
      "y": 60,
      "z": -4,
      "name": "Rock_Ice"
    },
    {
      "x": -10,
      "y": 71,
      "z": -4,
      "name": "Rock_Ice"
    },
    {
      "x": -10,
      "y": 72,
      "z": -4,
      "name": "Rock_Ice"
    },
    {
      "x": -10,
      "y": 73,
      "z": -4,
      "name": "Rock_Ice"
    },
    {
      "x": -10,
      "y": 74,
      "z": -4,
      "name": "Rock_Ice"
    },
    {
      "x": -10,
      "y": 75,
      "z": -4,
      "name": "Rock_Ice"
    },
    {
      "x": -10,
      "y": 76,
      "z": -4,
      "name": "Rock_Ice"
    },
    {
      "x": -10,
      "y": 77,
      "z": -4,
      "name": "Rock_Ice"
    },
    {
      "x": -10,
      "y": 78,
      "z": -4,
      "name": "Rock_Ice"
    },
    {
      "x": -10,
      "y": 79,
      "z": -4,
      "name": "Rock_Ice"
    },
    {
      "x": -10,
      "y": 80,
      "z": -4,
      "name": "Rock_Ice"
    },
    {
      "x": -10,
      "y": 81,
      "z": -4,
      "name": "Rock_Ice_Permafrost"
    },
    {
      "x": -10,
      "y": 82,
      "z": -4,
      "name": "Rock_Ice_Permafrost"
    },
    {
      "x": -10,
      "y": 83,
      "z": -4,
      "name": "Rock_Ice_Permafrost"
    },
    {
      "x": -10,
      "y": 84,
      "z": -4,
      "name": "Rock_Crystal_Cyan_Block_WhiteLight"
    },
    {
      "x": -10,
      "y": 85,
      "z": -4,
      "name": "Rock_Ice_Permafrost"
    },
    {
      "x": -10,
      "y": 86,
      "z": -4,
      "name": "Rock_Ice_Permafrost"
    },
    {
      "x": -10,
      "y": 87,
      "z": -4,
      "name": "Rock_Ice"
    },
    {
      "x": -10,
      "y": 88,
      "z": -4,
      "name": "Rock_Ice"
    },
    {
      "x": -10,
      "y": 89,
      "z": -4,
      "name": "Rock_Ice"
    },
    {
      "x": -10,
      "y": 90,
      "z": -4,
      "name": "Soil_Snow"
    },
    {
      "x": -10,
      "y": 17,
      "z": -3,
      "name": "Rock_Ice"
    },
    {
      "x": -10,
      "y": 18,
      "z": -3,
      "name": "Rock_Ice"
    },
    {
      "x": -10,
      "y": 19,
      "z": -3,
      "name": "Rock_Ice"
    },
    {
      "x": -10,
      "y": 20,
      "z": -3,
      "name": "Rock_Ice"
    },
    {
      "x": -10,
      "y": 21,
      "z": -3,
      "name": "Rock_Ice"
    },
    {
      "x": -10,
      "y": 22,
      "z": -3,
      "name": "Rock_Ice"
    },
    {
      "x": -10,
      "y": 23,
      "z": -3,
      "name": "Rock_Ice"
    },
    {
      "x": -10,
      "y": 24,
      "z": -3,
      "name": "Rock_Ice_Permafrost"
    },
    {
      "x": -10,
      "y": 25,
      "z": -3,
      "name": "Rock_Ice_Permafrost"
    },
    {
      "x": -10,
      "y": 26,
      "z": -3,
      "name": "Rock_Ice"
    },
    {
      "x": -10,
      "y": 27,
      "z": -3,
      "name": "Rock_Ice_Permafrost"
    },
    {
      "x": -10,
      "y": 28,
      "z": -3,
      "name": "Rock_Ice_Permafrost"
    },
    {
      "x": -10,
      "y": 29,
      "z": -3,
      "name": "Rock_Ice_Permafrost"
    },
    {
      "x": -10,
      "y": 30,
      "z": -3,
      "name": "Rock_Ice"
    },
    {
      "x": -10,
      "y": 31,
      "z": -3,
      "name": "Rock_Ice"
    },
    {
      "x": -10,
      "y": 32,
      "z": -3,
      "name": "Rock_Ice"
    },
    {
      "x": -10,
      "y": 33,
      "z": -3,
      "name": "Rock_Ice"
    },
    {
      "x": -10,
      "y": 34,
      "z": -3,
      "name": "Rock_Ice"
    },
    {
      "x": -10,
      "y": 35,
      "z": -3,
      "name": "Rock_Ice"
    },
    {
      "x": -10,
      "y": 36,
      "z": -3,
      "name": "Rock_Ice"
    },
    {
      "x": -10,
      "y": 37,
      "z": -3,
      "name": "Rock_Ice"
    },
    {
      "x": -10,
      "y": 38,
      "z": -3,
      "name": "Rock_Ice"
    },
    {
      "x": -10,
      "y": 39,
      "z": -3,
      "name": "Rock_Ice"
    },
    {
      "x": -10,
      "y": 40,
      "z": -3,
      "name": "Rock_Ice"
    },
    {
      "x": -10,
      "y": 41,
      "z": -3,
      "name": "Rock_Ice"
    },
    {
      "x": -10,
      "y": 42,
      "z": -3,
      "name": "Rock_Ice"
    },
    {
      "x": -10,
      "y": 43,
      "z": -3,
      "name": "Rock_Ice"
    },
    {
      "x": -10,
      "y": 44,
      "z": -3,
      "name": "Rock_Ice"
    },
    {
      "x": -10,
      "y": 45,
      "z": -3,
      "name": "Rock_Ice"
    },
    {
      "x": -10,
      "y": 46,
      "z": -3,
      "name": "Rock_Ice"
    },
    {
      "x": -10,
      "y": 47,
      "z": -3,
      "name": "Rock_Ice"
    },
    {
      "x": -10,
      "y": 48,
      "z": -3,
      "name": "Rock_Ice"
    },
    {
      "x": -10,
      "y": 49,
      "z": -3,
      "name": "Rock_Ice"
    },
    {
      "x": -10,
      "y": 50,
      "z": -3,
      "name": "Rock_Ice"
    },
    {
      "x": -10,
      "y": 51,
      "z": -3,
      "name": "Rock_Ice"
    },
    {
      "x": -10,
      "y": 52,
      "z": -3,
      "name": "Rock_Ice"
    },
    {
      "x": -10,
      "y": 53,
      "z": -3,
      "name": "Rock_Ice"
    },
    {
      "x": -10,
      "y": 54,
      "z": -3,
      "name": "Rock_Ice"
    },
    {
      "x": -10,
      "y": 55,
      "z": -3,
      "name": "Rock_Ice"
    },
    {
      "x": -10,
      "y": 56,
      "z": -3,
      "name": "Rock_Ice"
    },
    {
      "x": -10,
      "y": 57,
      "z": -3,
      "name": "Rock_Ice"
    },
    {
      "x": -10,
      "y": 58,
      "z": -3,
      "name": "Rock_Ice"
    },
    {
      "x": -10,
      "y": 59,
      "z": -3,
      "name": "Rock_Ice"
    },
    {
      "x": -10,
      "y": 60,
      "z": -3,
      "name": "Rock_Ice"
    },
    {
      "x": -10,
      "y": 71,
      "z": -3,
      "name": "Rock_Ice"
    },
    {
      "x": -10,
      "y": 72,
      "z": -3,
      "name": "Rock_Ice"
    },
    {
      "x": -10,
      "y": 73,
      "z": -3,
      "name": "Rock_Ice"
    },
    {
      "x": -10,
      "y": 74,
      "z": -3,
      "name": "Rock_Ice"
    },
    {
      "x": -10,
      "y": 75,
      "z": -3,
      "name": "Rock_Ice"
    },
    {
      "x": -10,
      "y": 76,
      "z": -3,
      "name": "Rock_Ice"
    },
    {
      "x": -10,
      "y": 77,
      "z": -3,
      "name": "Rock_Ice"
    },
    {
      "x": -10,
      "y": 78,
      "z": -3,
      "name": "Rock_Ice"
    },
    {
      "x": -10,
      "y": 79,
      "z": -3,
      "name": "Rock_Ice"
    },
    {
      "x": -10,
      "y": 80,
      "z": -3,
      "name": "Rock_Ice"
    },
    {
      "x": -10,
      "y": 81,
      "z": -3,
      "name": "Rock_Ice"
    },
    {
      "x": -10,
      "y": 82,
      "z": -3,
      "name": "Rock_Ice"
    },
    {
      "x": -10,
      "y": 83,
      "z": -3,
      "name": "Rock_Ice"
    },
    {
      "x": -10,
      "y": 84,
      "z": -3,
      "name": "Rock_Ice_Permafrost"
    },
    {
      "x": -10,
      "y": 85,
      "z": -3,
      "name": "Rock_Ice_Permafrost"
    },
    {
      "x": -10,
      "y": 86,
      "z": -3,
      "name": "Rock_Ice_Permafrost"
    },
    {
      "x": -10,
      "y": 87,
      "z": -3,
      "name": "Rock_Ice_Permafrost"
    },
    {
      "x": -10,
      "y": 88,
      "z": -3,
      "name": "Rock_Ice"
    },
    {
      "x": -10,
      "y": 89,
      "z": -3,
      "name": "Rock_Ice"
    },
    {
      "x": -10,
      "y": 17,
      "z": -2,
      "name": "Rock_Ice"
    },
    {
      "x": -10,
      "y": 18,
      "z": -2,
      "name": "Rock_Ice"
    },
    {
      "x": -10,
      "y": 19,
      "z": -2,
      "name": "Rock_Ice"
    },
    {
      "x": -10,
      "y": 20,
      "z": -2,
      "name": "Rock_Ice"
    },
    {
      "x": -10,
      "y": 21,
      "z": -2,
      "name": "Rock_Ice"
    },
    {
      "x": -10,
      "y": 22,
      "z": -2,
      "name": "Rock_Ice"
    },
    {
      "x": -10,
      "y": 23,
      "z": -2,
      "name": "Rock_Ice"
    },
    {
      "x": -10,
      "y": 24,
      "z": -2,
      "name": "Rock_Ice"
    },
    {
      "x": -10,
      "y": 25,
      "z": -2,
      "name": "Rock_Ice"
    },
    {
      "x": -10,
      "y": 26,
      "z": -2,
      "name": "Rock_Ice"
    },
    {
      "x": -10,
      "y": 27,
      "z": -2,
      "name": "Rock_Ice_Permafrost"
    },
    {
      "x": -10,
      "y": 28,
      "z": -2,
      "name": "Rock_Ice_Permafrost"
    },
    {
      "x": -10,
      "y": 29,
      "z": -2,
      "name": "Rock_Ice_Permafrost"
    },
    {
      "x": -10,
      "y": 30,
      "z": -2,
      "name": "Rock_Ice_Permafrost"
    },
    {
      "x": -10,
      "y": 31,
      "z": -2,
      "name": "Rock_Ice_Permafrost"
    },
    {
      "x": -10,
      "y": 32,
      "z": -2,
      "name": "Rock_Ice_Permafrost"
    },
    {
      "x": -10,
      "y": 33,
      "z": -2,
      "name": "Rock_Ice"
    },
    {
      "x": -10,
      "y": 34,
      "z": -2,
      "name": "Rock_Ice"
    },
    {
      "x": -10,
      "y": 35,
      "z": -2,
      "name": "Rock_Ice"
    },
    {
      "x": -10,
      "y": 36,
      "z": -2,
      "name": "Rock_Ice"
    },
    {
      "x": -10,
      "y": 37,
      "z": -2,
      "name": "Rock_Ice"
    },
    {
      "x": -10,
      "y": 38,
      "z": -2,
      "name": "Rock_Ice"
    },
    {
      "x": -10,
      "y": 39,
      "z": -2,
      "name": "Rock_Ice"
    },
    {
      "x": -10,
      "y": 40,
      "z": -2,
      "name": "Rock_Ice"
    },
    {
      "x": -10,
      "y": 41,
      "z": -2,
      "name": "Rock_Ice"
    },
    {
      "x": -10,
      "y": 42,
      "z": -2,
      "name": "Rock_Ice"
    },
    {
      "x": -10,
      "y": 43,
      "z": -2,
      "name": "Rock_Ice"
    },
    {
      "x": -10,
      "y": 44,
      "z": -2,
      "name": "Rock_Ice"
    },
    {
      "x": -10,
      "y": 45,
      "z": -2,
      "name": "Rock_Ice"
    },
    {
      "x": -10,
      "y": 46,
      "z": -2,
      "name": "Rock_Ice"
    },
    {
      "x": -10,
      "y": 47,
      "z": -2,
      "name": "Rock_Ice"
    },
    {
      "x": -10,
      "y": 48,
      "z": -2,
      "name": "Rock_Ice"
    },
    {
      "x": -10,
      "y": 49,
      "z": -2,
      "name": "Rock_Ice"
    },
    {
      "x": -10,
      "y": 50,
      "z": -2,
      "name": "Rock_Ice"
    },
    {
      "x": -10,
      "y": 58,
      "z": -2,
      "name": "Rock_Ice"
    },
    {
      "x": -10,
      "y": 59,
      "z": -2,
      "name": "Rock_Ice"
    },
    {
      "x": -10,
      "y": 72,
      "z": -2,
      "name": "Rock_Ice"
    },
    {
      "x": -10,
      "y": 73,
      "z": -2,
      "name": "Rock_Ice"
    },
    {
      "x": -10,
      "y": 74,
      "z": -2,
      "name": "Rock_Ice"
    },
    {
      "x": -10,
      "y": 75,
      "z": -2,
      "name": "Rock_Ice"
    },
    {
      "x": -10,
      "y": 76,
      "z": -2,
      "name": "Rock_Ice"
    },
    {
      "x": -10,
      "y": 77,
      "z": -2,
      "name": "Rock_Ice"
    },
    {
      "x": -10,
      "y": 78,
      "z": -2,
      "name": "Rock_Ice"
    },
    {
      "x": -10,
      "y": 79,
      "z": -2,
      "name": "Rock_Ice"
    },
    {
      "x": -10,
      "y": 80,
      "z": -2,
      "name": "Rock_Ice"
    },
    {
      "x": -10,
      "y": 81,
      "z": -2,
      "name": "Rock_Ice"
    },
    {
      "x": -10,
      "y": 82,
      "z": -2,
      "name": "Rock_Ice_Permafrost"
    },
    {
      "x": -10,
      "y": 83,
      "z": -2,
      "name": "Rock_Ice_Permafrost"
    },
    {
      "x": -10,
      "y": 84,
      "z": -2,
      "name": "Rock_Ice_Permafrost"
    },
    {
      "x": -10,
      "y": 85,
      "z": -2,
      "name": "Rock_Ice_Permafrost"
    },
    {
      "x": -10,
      "y": 86,
      "z": -2,
      "name": "Rock_Ice"
    },
    {
      "x": -10,
      "y": 87,
      "z": -2,
      "name": "Soil_Snow"
    },
    {
      "x": -10,
      "y": 17,
      "z": -1,
      "name": "Rock_Ice"
    },
    {
      "x": -10,
      "y": 18,
      "z": -1,
      "name": "Rock_Ice"
    },
    {
      "x": -10,
      "y": 19,
      "z": -1,
      "name": "Rock_Ice"
    },
    {
      "x": -10,
      "y": 20,
      "z": -1,
      "name": "Rock_Ice"
    },
    {
      "x": -10,
      "y": 21,
      "z": -1,
      "name": "Rock_Ice"
    },
    {
      "x": -10,
      "y": 22,
      "z": -1,
      "name": "Rock_Ice"
    },
    {
      "x": -10,
      "y": 23,
      "z": -1,
      "name": "Rock_Ice"
    },
    {
      "x": -10,
      "y": 24,
      "z": -1,
      "name": "Rock_Ice"
    },
    {
      "x": -10,
      "y": 25,
      "z": -1,
      "name": "Rock_Ice"
    },
    {
      "x": -10,
      "y": 26,
      "z": -1,
      "name": "Rock_Ice"
    },
    {
      "x": -10,
      "y": 27,
      "z": -1,
      "name": "Rock_Ice_Permafrost"
    },
    {
      "x": -10,
      "y": 28,
      "z": -1,
      "name": "Rock_Ice_Permafrost"
    },
    {
      "x": -10,
      "y": 29,
      "z": -1,
      "name": "Rock_Crystal_Cyan_Block_WhiteLight"
    },
    {
      "x": -10,
      "y": 30,
      "z": -1,
      "name": "Rock_Ice_Permafrost"
    },
    {
      "x": -10,
      "y": 31,
      "z": -1,
      "name": "Rock_Ice_Permafrost"
    },
    {
      "x": -10,
      "y": 32,
      "z": -1,
      "name": "Rock_Ice_Permafrost"
    },
    {
      "x": -10,
      "y": 33,
      "z": -1,
      "name": "Rock_Ice_Permafrost"
    },
    {
      "x": -10,
      "y": 34,
      "z": -1,
      "name": "Rock_Ice_Permafrost"
    },
    {
      "x": -10,
      "y": 35,
      "z": -1,
      "name": "Rock_Ice"
    },
    {
      "x": -10,
      "y": 36,
      "z": -1,
      "name": "Rock_Ice"
    },
    {
      "x": -10,
      "y": 37,
      "z": -1,
      "name": "Rock_Ice"
    },
    {
      "x": -10,
      "y": 38,
      "z": -1,
      "name": "Rock_Ice"
    },
    {
      "x": -10,
      "y": 39,
      "z": -1,
      "name": "Rock_Ice"
    },
    {
      "x": -10,
      "y": 40,
      "z": -1,
      "name": "Rock_Ice"
    },
    {
      "x": -10,
      "y": 41,
      "z": -1,
      "name": "Rock_Ice"
    },
    {
      "x": -10,
      "y": 42,
      "z": -1,
      "name": "Rock_Ice"
    },
    {
      "x": -10,
      "y": 43,
      "z": -1,
      "name": "Rock_Ice"
    },
    {
      "x": -10,
      "y": 44,
      "z": -1,
      "name": "Rock_Ice"
    },
    {
      "x": -10,
      "y": 45,
      "z": -1,
      "name": "Rock_Ice"
    },
    {
      "x": -10,
      "y": 46,
      "z": -1,
      "name": "Rock_Ice"
    },
    {
      "x": -10,
      "y": 47,
      "z": -1,
      "name": "Rock_Ice"
    },
    {
      "x": -10,
      "y": 48,
      "z": -1,
      "name": "Soil_Snow"
    },
    {
      "x": -10,
      "y": 71,
      "z": -1,
      "name": "Rock_Ice"
    },
    {
      "x": -10,
      "y": 72,
      "z": -1,
      "name": "Rock_Ice"
    },
    {
      "x": -10,
      "y": 73,
      "z": -1,
      "name": "Rock_Ice"
    },
    {
      "x": -10,
      "y": 74,
      "z": -1,
      "name": "Rock_Ice"
    },
    {
      "x": -10,
      "y": 75,
      "z": -1,
      "name": "Rock_Ice"
    },
    {
      "x": -10,
      "y": 76,
      "z": -1,
      "name": "Rock_Ice"
    },
    {
      "x": -10,
      "y": 77,
      "z": -1,
      "name": "Rock_Ice"
    },
    {
      "x": -10,
      "y": 78,
      "z": -1,
      "name": "Rock_Ice"
    },
    {
      "x": -10,
      "y": 79,
      "z": -1,
      "name": "Rock_Ice"
    },
    {
      "x": -10,
      "y": 80,
      "z": -1,
      "name": "Rock_Ice"
    },
    {
      "x": -10,
      "y": 81,
      "z": -1,
      "name": "Rock_Ice"
    },
    {
      "x": -10,
      "y": 82,
      "z": -1,
      "name": "Rock_Ice_Permafrost"
    },
    {
      "x": -10,
      "y": 83,
      "z": -1,
      "name": "Rock_Ice_Permafrost"
    },
    {
      "x": -10,
      "y": 84,
      "z": -1,
      "name": "Rock_Ice_Permafrost"
    },
    {
      "x": -10,
      "y": 85,
      "z": -1,
      "name": "Rock_Ice"
    },
    {
      "x": -10,
      "y": 86,
      "z": -1,
      "name": "Soil_Snow"
    },
    {
      "x": -10,
      "y": 17,
      "z": 0,
      "name": "Rock_Ice"
    },
    {
      "x": -10,
      "y": 18,
      "z": 0,
      "name": "Rock_Ice_Permafrost"
    },
    {
      "x": -10,
      "y": 19,
      "z": 0,
      "name": "Rock_Ice"
    },
    {
      "x": -10,
      "y": 20,
      "z": 0,
      "name": "Rock_Ice_Permafrost"
    },
    {
      "x": -10,
      "y": 21,
      "z": 0,
      "name": "Rock_Ice_Permafrost"
    },
    {
      "x": -10,
      "y": 22,
      "z": 0,
      "name": "Rock_Ice_Permafrost"
    },
    {
      "x": -10,
      "y": 23,
      "z": 0,
      "name": "Rock_Ice_Permafrost"
    },
    {
      "x": -10,
      "y": 24,
      "z": 0,
      "name": "Rock_Ice_Permafrost"
    },
    {
      "x": -10,
      "y": 25,
      "z": 0,
      "name": "Rock_Ice_Permafrost"
    },
    {
      "x": -10,
      "y": 26,
      "z": 0,
      "name": "Rock_Ice_Permafrost"
    },
    {
      "x": -10,
      "y": 27,
      "z": 0,
      "name": "Rock_Ice_Permafrost"
    },
    {
      "x": -10,
      "y": 28,
      "z": 0,
      "name": "Rock_Ice_Permafrost"
    },
    {
      "x": -10,
      "y": 29,
      "z": 0,
      "name": "Rock_Ice_Permafrost"
    },
    {
      "x": -10,
      "y": 30,
      "z": 0,
      "name": "Rock_Crystal_Cyan_Block_WhiteLight"
    },
    {
      "x": -10,
      "y": 31,
      "z": 0,
      "name": "Rock_Ice_Permafrost"
    },
    {
      "x": -10,
      "y": 32,
      "z": 0,
      "name": "Rock_Ice_Permafrost"
    },
    {
      "x": -10,
      "y": 33,
      "z": 0,
      "name": "Rock_Ice_Permafrost"
    },
    {
      "x": -10,
      "y": 34,
      "z": 0,
      "name": "Rock_Ice_Permafrost"
    },
    {
      "x": -10,
      "y": 35,
      "z": 0,
      "name": "Rock_Ice_Permafrost"
    },
    {
      "x": -10,
      "y": 36,
      "z": 0,
      "name": "Rock_Ice_Permafrost"
    },
    {
      "x": -10,
      "y": 37,
      "z": 0,
      "name": "Rock_Ice_Permafrost"
    },
    {
      "x": -10,
      "y": 38,
      "z": 0,
      "name": "Rock_Ice_Permafrost"
    },
    {
      "x": -10,
      "y": 39,
      "z": 0,
      "name": "Rock_Ice"
    },
    {
      "x": -10,
      "y": 40,
      "z": 0,
      "name": "Rock_Ice"
    },
    {
      "x": -10,
      "y": 41,
      "z": 0,
      "name": "Rock_Ice"
    },
    {
      "x": -10,
      "y": 42,
      "z": 0,
      "name": "Rock_Ice"
    },
    {
      "x": -10,
      "y": 43,
      "z": 0,
      "name": "Rock_Ice"
    },
    {
      "x": -10,
      "y": 44,
      "z": 0,
      "name": "Rock_Ice"
    },
    {
      "x": -10,
      "y": 45,
      "z": 0,
      "name": "Rock_Ice"
    },
    {
      "x": -10,
      "y": 46,
      "z": 0,
      "name": "Rock_Ice"
    },
    {
      "x": -10,
      "y": 47,
      "z": 0,
      "name": "Soil_Snow"
    },
    {
      "x": -10,
      "y": 71,
      "z": 0,
      "name": "Rock_Ice"
    },
    {
      "x": -10,
      "y": 72,
      "z": 0,
      "name": "Rock_Ice"
    },
    {
      "x": -10,
      "y": 73,
      "z": 0,
      "name": "Rock_Ice"
    },
    {
      "x": -10,
      "y": 74,
      "z": 0,
      "name": "Rock_Ice"
    },
    {
      "x": -10,
      "y": 75,
      "z": 0,
      "name": "Rock_Ice"
    },
    {
      "x": -10,
      "y": 76,
      "z": 0,
      "name": "Rock_Ice"
    },
    {
      "x": -10,
      "y": 77,
      "z": 0,
      "name": "Rock_Ice"
    },
    {
      "x": -10,
      "y": 78,
      "z": 0,
      "name": "Rock_Ice"
    },
    {
      "x": -10,
      "y": 79,
      "z": 0,
      "name": "Rock_Ice"
    },
    {
      "x": -10,
      "y": 80,
      "z": 0,
      "name": "Rock_Ice"
    },
    {
      "x": -10,
      "y": 81,
      "z": 0,
      "name": "Rock_Ice"
    },
    {
      "x": -10,
      "y": 82,
      "z": 0,
      "name": "Rock_Ice"
    },
    {
      "x": -10,
      "y": 83,
      "z": 0,
      "name": "Rock_Ice"
    },
    {
      "x": -10,
      "y": 84,
      "z": 0,
      "name": "Rock_Ice"
    },
    {
      "x": -10,
      "y": 85,
      "z": 0,
      "name": "Soil_Snow"
    },
    {
      "x": -10,
      "y": 17,
      "z": 1,
      "name": "Rock_Ice"
    },
    {
      "x": -10,
      "y": 18,
      "z": 1,
      "name": "Rock_Ice_Permafrost"
    },
    {
      "x": -10,
      "y": 19,
      "z": 1,
      "name": "Rock_Ice_Permafrost"
    },
    {
      "x": -10,
      "y": 20,
      "z": 1,
      "name": "Rock_Ice_Permafrost"
    },
    {
      "x": -10,
      "y": 21,
      "z": 1,
      "name": "Rock_Ice_Permafrost"
    },
    {
      "x": -10,
      "y": 22,
      "z": 1,
      "name": "Rock_Ice_Permafrost"
    },
    {
      "x": -10,
      "y": 23,
      "z": 1,
      "name": "Rock_Ice_Permafrost"
    },
    {
      "x": -10,
      "y": 24,
      "z": 1,
      "name": "Rock_Ice"
    },
    {
      "x": -10,
      "y": 25,
      "z": 1,
      "name": "Rock_Ice"
    },
    {
      "x": -10,
      "y": 26,
      "z": 1,
      "name": "Rock_Ice"
    },
    {
      "x": -10,
      "y": 27,
      "z": 1,
      "name": "Rock_Ice"
    },
    {
      "x": -10,
      "y": 28,
      "z": 1,
      "name": "Rock_Ice"
    },
    {
      "x": -10,
      "y": 29,
      "z": 1,
      "name": "Rock_Ice"
    },
    {
      "x": -10,
      "y": 30,
      "z": 1,
      "name": "Rock_Ice"
    },
    {
      "x": -10,
      "y": 31,
      "z": 1,
      "name": "Rock_Ice"
    },
    {
      "x": -10,
      "y": 32,
      "z": 1,
      "name": "Rock_Ice_Permafrost"
    },
    {
      "x": -10,
      "y": 33,
      "z": 1,
      "name": "Rock_Ice_Permafrost"
    },
    {
      "x": -10,
      "y": 34,
      "z": 1,
      "name": "Rock_Ice_Permafrost"
    },
    {
      "x": -10,
      "y": 35,
      "z": 1,
      "name": "Rock_Crystal_Cyan_Block_WhiteLight"
    },
    {
      "x": -10,
      "y": 36,
      "z": 1,
      "name": "Rock_Crystal_Cyan_Block_WhiteLight"
    },
    {
      "x": -10,
      "y": 37,
      "z": 1,
      "name": "Rock_Crystal_Cyan_Block_WhiteLight"
    },
    {
      "x": -10,
      "y": 38,
      "z": 1,
      "name": "Rock_Ice_Permafrost"
    },
    {
      "x": -10,
      "y": 39,
      "z": 1,
      "name": "Rock_Ice_Permafrost"
    },
    {
      "x": -10,
      "y": 40,
      "z": 1,
      "name": "Rock_Ice_Permafrost"
    },
    {
      "x": -10,
      "y": 41,
      "z": 1,
      "name": "Rock_Ice_Permafrost"
    },
    {
      "x": -10,
      "y": 42,
      "z": 1,
      "name": "Rock_Ice_Permafrost"
    },
    {
      "x": -10,
      "y": 43,
      "z": 1,
      "name": "Rock_Ice_Permafrost"
    },
    {
      "x": -10,
      "y": 44,
      "z": 1,
      "name": "Rock_Ice_Permafrost"
    },
    {
      "x": -10,
      "y": 45,
      "z": 1,
      "name": "Rock_Ice"
    },
    {
      "x": -10,
      "y": 46,
      "z": 1,
      "name": "Soil_Snow"
    },
    {
      "x": -10,
      "y": 70,
      "z": 1,
      "name": "Rock_Ice"
    },
    {
      "x": -10,
      "y": 71,
      "z": 1,
      "name": "Rock_Ice"
    },
    {
      "x": -10,
      "y": 72,
      "z": 1,
      "name": "Rock_Ice"
    },
    {
      "x": -10,
      "y": 73,
      "z": 1,
      "name": "Rock_Ice"
    },
    {
      "x": -10,
      "y": 74,
      "z": 1,
      "name": "Rock_Ice"
    },
    {
      "x": -10,
      "y": 75,
      "z": 1,
      "name": "Rock_Ice"
    },
    {
      "x": -10,
      "y": 76,
      "z": 1,
      "name": "Rock_Ice"
    },
    {
      "x": -10,
      "y": 77,
      "z": 1,
      "name": "Rock_Ice"
    },
    {
      "x": -10,
      "y": 78,
      "z": 1,
      "name": "Rock_Ice"
    },
    {
      "x": -10,
      "y": 79,
      "z": 1,
      "name": "Rock_Ice"
    },
    {
      "x": -10,
      "y": 80,
      "z": 1,
      "name": "Rock_Ice"
    },
    {
      "x": -10,
      "y": 81,
      "z": 1,
      "name": "Rock_Ice"
    },
    {
      "x": -10,
      "y": 82,
      "z": 1,
      "name": "Rock_Ice"
    },
    {
      "x": -10,
      "y": 83,
      "z": 1,
      "name": "Rock_Ice"
    },
    {
      "x": -10,
      "y": 84,
      "z": 1,
      "name": "Soil_Snow"
    },
    {
      "x": -10,
      "y": 17,
      "z": 2,
      "name": "Rock_Ice"
    },
    {
      "x": -10,
      "y": 18,
      "z": 2,
      "name": "Rock_Ice"
    },
    {
      "x": -10,
      "y": 19,
      "z": 2,
      "name": "Rock_Ice"
    },
    {
      "x": -10,
      "y": 20,
      "z": 2,
      "name": "Rock_Ice_Permafrost"
    },
    {
      "x": -10,
      "y": 21,
      "z": 2,
      "name": "Rock_Ice_Permafrost"
    },
    {
      "x": -10,
      "y": 22,
      "z": 2,
      "name": "Rock_Ice"
    },
    {
      "x": -10,
      "y": 23,
      "z": 2,
      "name": "Rock_Ice"
    },
    {
      "x": -10,
      "y": 24,
      "z": 2,
      "name": "Rock_Ice"
    },
    {
      "x": -10,
      "y": 25,
      "z": 2,
      "name": "Rock_Ice"
    },
    {
      "x": -10,
      "y": 26,
      "z": 2,
      "name": "Rock_Ice"
    },
    {
      "x": -10,
      "y": 27,
      "z": 2,
      "name": "Rock_Ice"
    },
    {
      "x": -10,
      "y": 28,
      "z": 2,
      "name": "Rock_Ice"
    },
    {
      "x": -10,
      "y": 29,
      "z": 2,
      "name": "Rock_Ice"
    },
    {
      "x": -10,
      "y": 30,
      "z": 2,
      "name": "Rock_Ice"
    },
    {
      "x": -10,
      "y": 31,
      "z": 2,
      "name": "Rock_Ice"
    },
    {
      "x": -10,
      "y": 32,
      "z": 2,
      "name": "Rock_Ice"
    },
    {
      "x": -10,
      "y": 33,
      "z": 2,
      "name": "Rock_Ice"
    },
    {
      "x": -10,
      "y": 34,
      "z": 2,
      "name": "Rock_Ice_Permafrost"
    },
    {
      "x": -10,
      "y": 35,
      "z": 2,
      "name": "Rock_Ice"
    },
    {
      "x": -10,
      "y": 36,
      "z": 2,
      "name": "Rock_Ice_Permafrost"
    },
    {
      "x": -10,
      "y": 44,
      "z": 2,
      "name": "Rock_Ice"
    },
    {
      "x": -10,
      "y": 45,
      "z": 2,
      "name": "Soil_Snow"
    },
    {
      "x": -10,
      "y": 68,
      "z": 2,
      "name": "Rock_Ice"
    },
    {
      "x": -10,
      "y": 69,
      "z": 2,
      "name": "Rock_Ice"
    },
    {
      "x": -10,
      "y": 70,
      "z": 2,
      "name": "Rock_Ice"
    },
    {
      "x": -10,
      "y": 71,
      "z": 2,
      "name": "Rock_Ice"
    },
    {
      "x": -10,
      "y": 72,
      "z": 2,
      "name": "Rock_Ice"
    },
    {
      "x": -10,
      "y": 73,
      "z": 2,
      "name": "Rock_Ice"
    },
    {
      "x": -10,
      "y": 74,
      "z": 2,
      "name": "Rock_Ice"
    },
    {
      "x": -10,
      "y": 75,
      "z": 2,
      "name": "Rock_Ice"
    },
    {
      "x": -10,
      "y": 76,
      "z": 2,
      "name": "Rock_Ice"
    },
    {
      "x": -10,
      "y": 77,
      "z": 2,
      "name": "Rock_Ice"
    },
    {
      "x": -10,
      "y": 78,
      "z": 2,
      "name": "Rock_Ice"
    },
    {
      "x": -10,
      "y": 79,
      "z": 2,
      "name": "Rock_Ice"
    },
    {
      "x": -10,
      "y": 80,
      "z": 2,
      "name": "Rock_Ice"
    },
    {
      "x": -10,
      "y": 81,
      "z": 2,
      "name": "Rock_Ice"
    },
    {
      "x": -10,
      "y": 82,
      "z": 2,
      "name": "Rock_Ice"
    },
    {
      "x": -10,
      "y": 83,
      "z": 2,
      "name": "Rock_Ice"
    },
    {
      "x": -10,
      "y": 84,
      "z": 2,
      "name": "Rock_Ice_Permafrost"
    },
    {
      "x": -10,
      "y": 85,
      "z": 2,
      "name": "Rock_Ice"
    },
    {
      "x": -10,
      "y": 86,
      "z": 2,
      "name": "Soil_Snow"
    },
    {
      "x": -10,
      "y": 18,
      "z": 3,
      "name": "Rock_Ice"
    },
    {
      "x": -10,
      "y": 19,
      "z": 3,
      "name": "Rock_Ice"
    },
    {
      "x": -10,
      "y": 20,
      "z": 3,
      "name": "Rock_Ice_Permafrost"
    },
    {
      "x": -10,
      "y": 21,
      "z": 3,
      "name": "Rock_Ice"
    },
    {
      "x": -10,
      "y": 22,
      "z": 3,
      "name": "Rock_Ice"
    },
    {
      "x": -10,
      "y": 23,
      "z": 3,
      "name": "Rock_Ice"
    },
    {
      "x": -10,
      "y": 24,
      "z": 3,
      "name": "Rock_Ice"
    },
    {
      "x": -10,
      "y": 25,
      "z": 3,
      "name": "Rock_Ice"
    },
    {
      "x": -10,
      "y": 26,
      "z": 3,
      "name": "Rock_Ice"
    },
    {
      "x": -10,
      "y": 27,
      "z": 3,
      "name": "Rock_Ice"
    },
    {
      "x": -10,
      "y": 28,
      "z": 3,
      "name": "Rock_Ice"
    },
    {
      "x": -10,
      "y": 29,
      "z": 3,
      "name": "Rock_Ice"
    },
    {
      "x": -10,
      "y": 30,
      "z": 3,
      "name": "Rock_Ice"
    },
    {
      "x": -10,
      "y": 31,
      "z": 3,
      "name": "Rock_Ice"
    },
    {
      "x": -10,
      "y": 32,
      "z": 3,
      "name": "Rock_Ice"
    },
    {
      "x": -10,
      "y": 33,
      "z": 3,
      "name": "Rock_Ice"
    },
    {
      "x": -10,
      "y": 34,
      "z": 3,
      "name": "Rock_Ice"
    },
    {
      "x": -10,
      "y": 35,
      "z": 3,
      "name": "Soil_Snow"
    },
    {
      "x": -10,
      "y": 71,
      "z": 3,
      "name": "Rock_Ice"
    },
    {
      "x": -10,
      "y": 72,
      "z": 3,
      "name": "Rock_Ice"
    },
    {
      "x": -10,
      "y": 73,
      "z": 3,
      "name": "Rock_Ice"
    },
    {
      "x": -10,
      "y": 74,
      "z": 3,
      "name": "Rock_Ice"
    },
    {
      "x": -10,
      "y": 75,
      "z": 3,
      "name": "Rock_Ice"
    },
    {
      "x": -10,
      "y": 76,
      "z": 3,
      "name": "Rock_Ice"
    },
    {
      "x": -10,
      "y": 77,
      "z": 3,
      "name": "Rock_Ice"
    },
    {
      "x": -10,
      "y": 78,
      "z": 3,
      "name": "Rock_Ice"
    },
    {
      "x": -10,
      "y": 79,
      "z": 3,
      "name": "Rock_Ice"
    },
    {
      "x": -10,
      "y": 80,
      "z": 3,
      "name": "Rock_Ice"
    },
    {
      "x": -10,
      "y": 81,
      "z": 3,
      "name": "Rock_Ice"
    },
    {
      "x": -10,
      "y": 82,
      "z": 3,
      "name": "Rock_Ice"
    },
    {
      "x": -10,
      "y": 83,
      "z": 3,
      "name": "Rock_Ice"
    },
    {
      "x": -10,
      "y": 84,
      "z": 3,
      "name": "Rock_Ice"
    },
    {
      "x": -10,
      "y": 85,
      "z": 3,
      "name": "Rock_Ice"
    },
    {
      "x": -10,
      "y": 86,
      "z": 3,
      "name": "Soil_Snow"
    },
    {
      "x": -10,
      "y": 19,
