{
  "version": 8,
  "blockIdVersion": 11,
  "anchorX": 0,
  "anchorY": 0,
  "anchorZ": 0,
  "blocks": [
    {
      "x": -21,
      "y": 39,
      "z": -6,
      "name": "Rock_Ice_Permafrost"
    },
    {
      "x": -21,
      "y": 40,
      "z": -6,
      "name": "Rock_Ice"
    },
    {
      "x": -21,
      "y": 41,
      "z": -6,
      "name": "Rock_Ice"
    },
    {
      "x": -21,
      "y": 42,
      "z": -6,
      "name": "Rock_Ice"
    },
    {
      "x": -21,
      "y": 43,
      "z": -6,
      "name": "Rock_Ice"
    },
    {
      "x": -21,
      "y": 44,
      "z": -6,
      "name": "Rock_Ice_Permafrost"
    },
    {
      "x": -21,
      "y": 45,
      "z": -6,
      "name": "Soil_Snow"
    },
    {
      "x": -21,
      "y": 40,
      "z": -5,
      "name": "Rock_Ice_Permafrost"
    },
    {
      "x": -21,
      "y": 41,
      "z": -5,
      "name": "Rock_Ice_Permafrost"
    },
    {
      "x": -21,
      "y": 42,
      "z": -5,
      "name": "Rock_Ice_Permafrost"
    },
    {
      "x": -21,
      "y": 43,
      "z": -5,
      "name": "Rock_Crystal_Cyan_Block_WhiteLight"
    },
    {
      "x": -21,
      "y": 44,
      "z": -5,
      "name": "Rock_Ice_Permafrost"
    },
    {
      "x": -21,
      "y": 45,
      "z": -5,
      "name": "Rock_Ice_Permafrost"
    },
    {
      "x": -21,
      "y": 46,
      "z": -5,
      "name": "Rock_Crystal_Cyan_Block_WhiteLight"
    },
    {
      "x": -21,
      "y": 47,
      "z": -5,
      "name": "Rock_Ice_Permafrost"
    },
    {
      "x": -21,
      "y": 48,
      "z": -5,
      "name": "Rock_Ice_Permafrost"
    },
    {
      "x": -21,
      "y": 41,
      "z": -4,
      "name": "Rock_Ice_Permafrost"
    },
    {
      "x": -21,
      "y": 42,
      "z": -4,
      "name": "Rock_Ice_Permafrost"
    },
    {
      "x": -21,
      "y": 43,
      "z": -4,
      "name": "Rock_Ice_Permafrost"
    },
    {
      "x": -21,
      "y": 44,
      "z": -4,
      "name": "Rock_Crystal_Cyan_Block_WhiteLight"
    },
    {
      "x": -21,
      "y": 45,
      "z": -4,
      "name": "Rock_Ice_Permafrost"
    },
    {
      "x": -21,
      "y": 46,
      "z": -4,
      "name": "Rock_Ice_Permafrost"
    },
    {
      "x": -21,
      "y": 47,
      "z": -4,
      "name": "Rock_Ice_Permafrost"
    },
    {
      "x": -21,
      "y": 55,
      "z": -4,
      "name": "Rock_Ice"
    },
    {
      "x": -21,
      "y": 56,
      "z": -4,
      "name": "Rock_Ice"
    },
    {
      "x": -21,
      "y": 57,
      "z": -4,
      "name": "Rock_Ice"
    },
    {
      "x": -21,
      "y": 58,
      "z": -4,
      "name": "Rock_Ice"
    },
    {
      "x": -21,
      "y": 59,
      "z": -4,
      "name": "Rock_Ice"
    },
    {
      "x": -21,
      "y": 41,
      "z": -3,
      "name": "Rock_Crystal_Cyan_Block_WhiteLight"
    },
    {
      "x": -21,
      "y": 42,
      "z": -3,
      "name": "Rock_Ice_Permafrost"
    },
    {
      "x": -21,
      "y": 43,
      "z": -3,
      "name": "Rock_Ice_Permafrost"
    },
    {
      "x": -21,
      "y": 44,
      "z": -3,
      "name": "Rock_Ice_Permafrost"
    },
    {
      "x": -21,
      "y": 45,
      "z": -3,
      "name": "Rock_Ice_Permafrost"
    },
    {
      "x": -21,
      "y": 46,
      "z": -3,
      "name": "Rock_Ice"
    },
    {
      "x": -21,
      "y": 53,
      "z": -3,
      "name": "Rock_Ice"
    },
    {
      "x": -21,
      "y": 21,
      "z": -2,
      "name": "Rock_Ice"
    },
    {
      "x": -21,
      "y": 22,
      "z": -2,
      "name": "Rock_Ice"
    },
    {
      "x": -21,
      "y": 23,
      "z": -2,
      "name": "Rock_Ice"
    },
    {
      "x": -21,
      "y": 24,
      "z": -2,
      "name": "Soil_Snow"
    },
    {
      "x": -21,
      "y": 22,
      "z": -1,
      "name": "Rock_Ice"
    },
    {
      "x": -21,
      "y": 23,
      "z": -1,
      "name": "Rock_Ice"
    },
    {
      "x": -21,
      "y": 24,
      "z": -1,
      "name": "Soil_Snow"
    },
    {
      "x": -21,
      "y": 23,
      "z": 0,
      "name": "Rock_Ice"
    },
    {
      "x": -21,
      "y": 24,
      "z": 0,
      "name": "Soil_Snow"
    },
    {
      "x": -21,
      "y": 23,
      "z": 1,
      "name": "Rock_Ice"
    },
    {
      "x": -21,
      "y": 24,
      "z": 1,
      "name": "Rock_Ice"
    },
    {
      "x": -21,
      "y": 33,
      "z": 1,
      "name": "Rock_Ice"
    },
    {
      "x": -21,
      "y": 34,
      "z": 1,
      "name": "Rock_Ice"
    },
    {
      "x": -21,
      "y": 35,
      "z": 1,
      "name": "Soil_Snow"
    },
    {
      "x": -21,
      "y": 22,
      "z": 2,
      "name": "Rock_Ice"
    },
    {
      "x": -21,
      "y": 23,
      "z": 2,
      "name": "Rock_Ice"
    },
    {
      "x": -21,
      "y": 22,
      "z": 3,
      "name": "Rock_Ice"
    },
    {
      "x": -21,
      "y": 23,
      "z": 3,
      "name": "Soil_Snow"
    },
    {
      "x": -20,
      "y": 44,
      "z": -14,
      "name": "Rock_Ice"
    },
    {
      "x": -20,
      "y": 45,
      "z": -14,
      "name": "Soil_Snow"
    },
    {
      "x": -20,
      "y": 44,
      "z": -13,
      "name": "Rock_Ice"
    },
    {
      "x": -20,
      "y": 45,
      "z": -13,
      "name": "Rock_Ice"
    },
    {
      "x": -20,
      "y": 46,
      "z": -13,
      "name": "Soil_Snow"
    },
    {
      "x": -20,
      "y": 43,
      "z": -12,
      "name": "Rock_Ice"
    },
    {
      "x": -20,
      "y": 44,
      "z": -12,
      "name": "Rock_Ice"
    },
    {
      "x": -20,
      "y": 45,
      "z": -12,
      "name": "Rock_Ice"
    },
    {
      "x": -20,
      "y": 46,
      "z": -12,
      "name": "Rock_Ice"
    },
    {
      "x": -20,
      "y": 47,
      "z": -12,
      "name": "Soil_Snow"
    },
    {
      "x": -20,
      "y": 43,
      "z": -11,
      "name": "Rock_Ice"
    },
    {
      "x": -20,
      "y": 44,
      "z": -11,
      "name": "Rock_Ice"
    },
    {
      "x": -20,
      "y": 45,
      "z": -11,
      "name": "Rock_Ice"
    },
    {
      "x": -20,
      "y": 46,
      "z": -11,
      "name": "Rock_Ice"
    },
    {
      "x": -20,
      "y": 47,
      "z": -11,
      "name": "Soil_Snow"
    },
    {
      "x": -20,
      "y": 39,
      "z": -10,
      "name": "Rock_Ice"
    },
    {
      "x": -20,
      "y": 40,
      "z": -10,
      "name": "Rock_Ice"
    },
    {
      "x": -20,
      "y": 41,
      "z": -10,
      "name": "Rock_Ice"
    },
    {
      "x": -20,
      "y": 42,
      "z": -10,
      "name": "Rock_Ice"
    },
    {
      "x": -20,
      "y": 43,
      "z": -10,
      "name": "Rock_Ice"
    },
    {
      "x": -20,
      "y": 44,
      "z": -10,
      "name": "Rock_Ice"
    },
    {
      "x": -20,
      "y": 45,
      "z": -10,
      "name": "Rock_Ice"
    },
    {
      "x": -20,
      "y": 46,
      "z": -10,
      "name": "Soil_Snow"
    },
    {
      "x": -20,
      "y": 38,
      "z": -9,
      "name": "Rock_Ice_Permafrost"
    },
    {
      "x": -20,
      "y": 39,
      "z": -9,
      "name": "Rock_Ice"
    },
    {
      "x": -20,
      "y": 40,
      "z": -9,
      "name": "Rock_Ice"
    },
    {
      "x": -20,
      "y": 41,
      "z": -9,
      "name": "Rock_Ice"
    },
    {
      "x": -20,
      "y": 42,
      "z": -9,
      "name": "Rock_Ice"
    },
    {
      "x": -20,
      "y": 43,
      "z": -9,
      "name": "Rock_Ice"
    },
    {
      "x": -20,
      "y": 44,
      "z": -9,
      "name": "Rock_Ice"
    },
    {
      "x": -20,
      "y": 45,
      "z": -9,
      "name": "Rock_Ice"
    },
    {
      "x": -20,
      "y": 46,
      "z": -9,
      "name": "Soil_Snow"
    },
    {
      "x": -20,
      "y": 37,
      "z": -8,
      "name": "Rock_Ice_Permafrost"
    },
    {
      "x": -20,
      "y": 38,
      "z": -8,
      "name": "Rock_Ice_Permafrost"
    },
    {
      "x": -20,
      "y": 39,
      "z": -8,
      "name": "Rock_Ice"
    },
    {
      "x": -20,
      "y": 40,
      "z": -8,
      "name": "Rock_Ice"
    },
    {
      "x": -20,
      "y": 41,
      "z": -8,
      "name": "Rock_Ice"
    },
    {
      "x": -20,
      "y": 42,
      "z": -8,
      "name": "Rock_Ice"
    },
    {
      "x": -20,
      "y": 43,
      "z": -8,
      "name": "Rock_Ice"
    },
    {
      "x": -20,
      "y": 44,
      "z": -8,
      "name": "Rock_Ice"
    },
    {
      "x": -20,
      "y": 45,
      "z": -8,
      "name": "Rock_Ice"
    },
    {
      "x": -20,
      "y": 46,
      "z": -8,
      "name": "Soil_Snow"
    },
    {
      "x": -20,
      "y": 36,
      "z": -7,
      "name": "Rock_Ice_Permafrost"
    },
    {
      "x": -20,
      "y": 37,
      "z": -7,
      "name": "Rock_Ice"
    },
    {
      "x": -20,
      "y": 38,
      "z": -7,
      "name": "Rock_Ice_Permafrost"
    },
    {
      "x": -20,
      "y": 39,
      "z": -7,
      "name": "Rock_Ice_Permafrost"
    },
    {
      "x": -20,
      "y": 40,
      "z": -7,
      "name": "Rock_Ice"
    },
    {
      "x": -20,
      "y": 41,
      "z": -7,
      "name": "Rock_Ice"
    },
    {
      "x": -20,
      "y": 42,
      "z": -7,
      "name": "Rock_Ice"
    },
    {
      "x": -20,
      "y": 43,
      "z": -7,
      "name": "Rock_Ice"
    },
    {
      "x": -20,
      "y": 44,
      "z": -7,
      "name": "Rock_Ice"
    },
    {
      "x": -20,
      "y": 45,
      "z": -7,
      "name": "Rock_Ice"
    },
    {
      "x": -20,
      "y": 46,
      "z": -7,
      "name": "Rock_Ice"
    },
    {
      "x": -20,
      "y": 47,
      "z": -7,
      "name": "Soil_Snow"
    },
    {
      "x": -20,
      "y": 22,
      "z": -6,
      "name": "Rock_Ice_Permafrost"
    },
    {
      "x": -20,
      "y": 23,
      "z": -6,
      "name": "Rock_Ice"
    },
    {
      "x": -20,
      "y": 24,
      "z": -6,
      "name": "Rock_Ice_Permafrost"
    },
    {
      "x": -20,
      "y": 33,
      "z": -6,
      "name": "Rock_Ice"
    },
    {
      "x": -20,
      "y": 34,
      "z": -6,
      "name": "Rock_Ice_Permafrost"
    },
    {
      "x": -20,
      "y": 35,
      "z": -6,
      "name": "Rock_Ice_Permafrost"
    },
    {
      "x": -20,
      "y": 36,
      "z": -6,
      "name": "Rock_Ice_Permafrost"
    },
    {
      "x": -20,
      "y": 37,
      "z": -6,
      "name": "Rock_Ice_Permafrost"
    },
    {
      "x": -20,
      "y": 38,
      "z": -6,
      "name": "Rock_Ice_Permafrost"
    },
    {
      "x": -20,
      "y": 39,
      "z": -6,
      "name": "Rock_Ice_Permafrost"
    },
    {
      "x": -20,
      "y": 40,
      "z": -6,
      "name": "Rock_Ice_Permafrost"
    },
    {
      "x": -20,
      "y": 41,
      "z": -6,
      "name": "Rock_Ice_Permafrost"
    },
    {
      "x": -20,
      "y": 42,
      "z": -6,
      "name": "Rock_Ice"
    },
    {
      "x": -20,
      "y": 43,
      "z": -6,
      "name": "Rock_Ice"
    },
    {
      "x": -20,
      "y": 44,
      "z": -6,
      "name": "Rock_Ice_Permafrost"
    },
    {
      "x": -20,
      "y": 45,
      "z": -6,
      "name": "Rock_Crystal_Cyan_Block_WhiteLight"
    },
    {
      "x": -20,
      "y": 46,
      "z": -6,
      "name": "Rock_Ice_Permafrost"
    },
    {
      "x": -20,
      "y": 47,
      "z": -6,
      "name": "Rock_Ice"
    },
    {
      "x": -20,
      "y": 48,
      "z": -6,
      "name": "Rock_Ice_Permafrost"
    },
    {
      "x": -20,
      "y": 49,
      "z": -6,
      "name": "Rock_Ice"
    },
    {
      "x": -20,
      "y": 50,
      "z": -6,
      "name": "Rock_Ice"
    },
    {
      "x": -20,
      "y": 51,
      "z": -6,
      "name": "Rock_Ice_Permafrost"
    },
    {
      "x": -20,
      "y": 20,
      "z": -5,
      "name": "Rock_Ice"
    },
    {
      "x": -20,
      "y": 21,
      "z": -5,
      "name": "Rock_Ice"
    },
    {
      "x": -20,
      "y": 22,
      "z": -5,
      "name": "Rock_Ice"
    },
    {
      "x": -20,
      "y": 23,
      "z": -5,
      "name": "Rock_Ice"
    },
    {
      "x": -20,
      "y": 24,
      "z": -5,
      "name": "Rock_Ice"
    },
    {
      "x": -20,
      "y": 25,
      "z": -5,
      "name": "Rock_Ice"
    },
    {
      "x": -20,
      "y": 26,
      "z": -5,
      "name": "Rock_Ice"
    },
    {
      "x": -20,
      "y": 27,
      "z": -5,
      "name": "Rock_Ice"
    },
    {
      "x": -20,
      "y": 30,
      "z": -5,
      "name": "Rock_Ice"
    },
    {
      "x": -20,
      "y": 31,
      "z": -5,
      "name": "Rock_Ice"
    },
    {
      "x": -20,
      "y": 32,
      "z": -5,
      "name": "Rock_Ice"
    },
    {
      "x": -20,
      "y": 33,
      "z": -5,
      "name": "Rock_Ice"
    },
    {
      "x": -20,
      "y": 34,
      "z": -5,
      "name": "Rock_Ice"
    },
    {
      "x": -20,
      "y": 35,
      "z": -5,
      "name": "Rock_Ice"
    },
    {
      "x": -20,
      "y": 36,
      "z": -5,
      "name": "Rock_Ice_Permafrost"
    },
    {
      "x": -20,
      "y": 37,
      "z": -5,
      "name": "Rock_Ice"
    },
    {
      "x": -20,
      "y": 38,
      "z": -5,
      "name": "Rock_Ice_Permafrost"
    },
    {
      "x": -20,
      "y": 39,
      "z": -5,
      "name": "Rock_Ice_Permafrost"
    },
    {
      "x": -20,
      "y": 40,
      "z": -5,
      "name": "Rock_Ice_Permafrost"
    },
    {
      "x": -20,
      "y": 41,
      "z": -5,
      "name": "Rock_Ice_Permafrost"
    },
    {
      "x": -20,
      "y": 42,
      "z": -5,
      "name": "Rock_Ice_Permafrost"
    },
    {
      "x": -20,
      "y": 43,
      "z": -5,
      "name": "Rock_Crystal_Cyan_Block_WhiteLight"
    },
    {
      "x": -20,
      "y": 44,
      "z": -5,
      "name": "Rock_Ice_Permafrost"
    },
    {
      "x": -20,
      "y": 45,
      "z": -5,
      "name": "Rock_Ice_Permafrost"
    },
    {
      "x": -20,
      "y": 46,
      "z": -5,
      "name": "Rock_Ice_Permafrost"
    },
    {
      "x": -20,
      "y": 47,
      "z": -5,
      "name": "Rock_Ice_Permafrost"
    },
    {
      "x": -20,
      "y": 48,
      "z": -5,
      "name": "Rock_Ice"
    },
    {
      "x": -20,
      "y": 49,
      "z": -5,
      "name": "Rock_Ice"
    },
    {
      "x": -20,
      "y": 50,
      "z": -5,
      "name": "Rock_Ice"
    },
    {
      "x": -20,
      "y": 51,
      "z": -5,
      "name": "Rock_Ice"
    },
    {
      "x": -20,
      "y": 52,
      "z": -5,
      "name": "Rock_Ice"
    },
    {
      "x": -20,
      "y": 53,
      "z": -5,
      "name": "Rock_Ice"
    },
    {
      "x": -20,
      "y": 54,
      "z": -5,
      "name": "Rock_Ice"
    },
    {
      "x": -20,
      "y": 55,
      "z": -5,
      "name": "Rock_Ice"
    },
    {
      "x": -20,
      "y": 56,
      "z": -5,
      "name": "Rock_Ice"
    },
    {
      "x": -20,
      "y": 57,
      "z": -5,
      "name": "Rock_Ice"
    },
    {
      "x": -20,
      "y": 58,
      "z": -5,
      "name": "Rock_Ice"
    },
    {
      "x": -20,
      "y": 59,
      "z": -5,
      "name": "Rock_Ice"
    },
    {
      "x": -20,
      "y": 60,
      "z": -5,
      "name": "Rock_Ice"
    },
    {
      "x": -20,
      "y": 61,
      "z": -5,
      "name": "Rock_Ice"
    },
    {
      "x": -20,
      "y": 62,
      "z": -5,
      "name": "Soil_Snow"
    },
    {
      "x": -20,
      "y": 18,
      "z": -4,
      "name": "Rock_Ice"
    },
    {
      "x": -20,
      "y": 19,
      "z": -4,
      "name": "Rock_Ice"
    },
    {
      "x": -20,
      "y": 20,
      "z": -4,
      "name": "Rock_Ice"
    },
    {
      "x": -20,
      "y": 21,
      "z": -4,
      "name": "Rock_Ice"
    },
    {
      "x": -20,
      "y": 22,
      "z": -4,
      "name": "Rock_Ice"
    },
    {
      "x": -20,
      "y": 23,
      "z": -4,
      "name": "Rock_Ice"
    },
    {
      "x": -20,
      "y": 24,
      "z": -4,
      "name": "Rock_Ice"
    },
    {
      "x": -20,
      "y": 25,
      "z": -4,
      "name": "Rock_Ice"
    },
    {
      "x": -20,
      "y": 26,
      "z": -4,
      "name": "Rock_Ice"
    },
    {
      "x": -20,
      "y": 27,
      "z": -4,
      "name": "Rock_Ice"
    },
    {
      "x": -20,
      "y": 30,
      "z": -4,
      "name": "Rock_Ice"
    },
    {
      "x": -20,
      "y": 31,
      "z": -4,
      "name": "Rock_Ice"
    },
    {
      "x": -20,
      "y": 32,
      "z": -4,
      "name": "Rock_Ice"
    },
    {
      "x": -20,
      "y": 38,
      "z": -4,
      "name": "Rock_Ice_Permafrost"
    },
    {
      "x": -20,
      "y": 39,
      "z": -4,
      "name": "Rock_Ice_Permafrost"
    },
    {
      "x": -20,
      "y": 40,
      "z": -4,
      "name": "Rock_Ice_Permafrost"
    },
    {
      "x": -20,
      "y": 41,
      "z": -4,
      "name": "Rock_Ice_Permafrost"
    },
    {
      "x": -20,
      "y": 42,
      "z": -4,
      "name": "Rock_Ice_Permafrost"
    },
    {
      "x": -20,
      "y": 43,
      "z": -4,
      "name": "Rock_Ice_Permafrost"
    },
    {
      "x": -20,
      "y": 44,
      "z": -4,
      "name": "Rock_Ice_Permafrost"
    },
    {
      "x": -20,
      "y": 45,
      "z": -4,
      "name": "Rock_Ice_Permafrost"
    },
    {
      "x": -20,
      "y": 46,
      "z": -4,
      "name": "Rock_Ice_Permafrost"
    },
    {
      "x": -20,
      "y": 47,
      "z": -4,
      "name": "Rock_Ice"
    },
    {
      "x": -20,
      "y": 48,
      "z": -4,
      "name": "Rock_Ice"
    },
    {
      "x": -20,
      "y": 49,
      "z": -4,
      "name": "Rock_Ice"
    },
    {
      "x": -20,
      "y": 50,
      "z": -4,
      "name": "Rock_Ice"
    },
    {
      "x": -20,
      "y": 51,
      "z": -4,
      "name": "Rock_Ice"
    },
    {
      "x": -20,
      "y": 52,
      "z": -4,
      "name": "Rock_Ice"
    },
    {
      "x": -20,
      "y": 53,
      "z": -4,
      "name": "Rock_Ice"
    },
    {
      "x": -20,
      "y": 54,
      "z": -4,
      "name": "Rock_Ice"
    },
    {
      "x": -20,
      "y": 55,
      "z": -4,
      "name": "Rock_Ice"
    },
    {
      "x": -20,
      "y": 56,
      "z": -4,
      "name": "Rock_Ice"
    },
    {
      "x": -20,
      "y": 57,
      "z": -4,
      "name": "Rock_Ice"
    },
    {
      "x": -20,
      "y": 58,
      "z": -4,
      "name": "Rock_Ice"
    },
    {
      "x": -20,
      "y": 59,
      "z": -4,
      "name": "Rock_Ice"
    },
    {
      "x": -20,
      "y": 60,
      "z": -4,
      "name": "Rock_Ice"
    },
    {
      "x": -20,
      "y": 61,
      "z": -4,
      "name": "Rock_Ice"
    },
    {
      "x": -20,
      "y": 62,
      "z": -4,
      "name": "Rock_Ice"
    },
    {
      "x": -20,
      "y": 63,
      "z": -4,
      "name": "Soil_Snow"
    },
    {
      "x": -20,
      "y": 16,
      "z": -3,
      "name": "Rock_Ice"
    },
    {
      "x": -20,
      "y": 17,
      "z": -3,
      "name": "Rock_Ice"
    },
    {
      "x": -20,
      "y": 18,
      "z": -3,
      "name": "Rock_Ice"
    },
    {
      "x": -20,
      "y": 19,
      "z": -3,
      "name": "Rock_Ice"
    },
    {
      "x": -20,
      "y": 20,
      "z": -3,
      "name": "Rock_Ice"
    },
    {
      "x": -20,
      "y": 21,
      "z": -3,
      "name": "Rock_Ice"
    },
    {
      "x": -20,
      "y": 22,
      "z": -3,
      "name": "Rock_Ice"
    },
    {
      "x": -20,
      "y": 23,
      "z": -3,
      "name": "Rock_Ice"
    },
    {
      "x": -20,
      "y": 24,
      "z": -3,
      "name": "Rock_Ice"
    },
    {
      "x": -20,
      "y": 25,
      "z": -3,
      "name": "Rock_Ice"
    },
    {
      "x": -20,
      "y": 26,
      "z": -3,
      "name": "Rock_Ice"
    },
    {
      "x": -20,
      "y": 31,
      "z": -3,
      "name": "Rock_Ice"
    },
    {
      "x": -20,
      "y": 39,
      "z": -3,
      "name": "Rock_Ice"
    },
    {
      "x": -20,
      "y": 40,
      "z": -3,
      "name": "Rock_Ice_Permafrost"
    },
    {
      "x": -20,
      "y": 41,
      "z": -3,
      "name": "Rock_Ice_Permafrost"
    },
    {
      "x": -20,
      "y": 42,
      "z": -3,
      "name": "Rock_Ice_Permafrost"
    },
    {
      "x": -20,
      "y": 43,
      "z": -3,
      "name": "Rock_Crystal_Cyan_Block_WhiteLight"
    },
    {
      "x": -20,
      "y": 44,
      "z": -3,
      "name": "Rock_Ice"
    },
    {
      "x": -20,
      "y": 45,
      "z": -3,
      "name": "Rock_Ice"
    },
    {
      "x": -20,
      "y": 46,
      "z": -3,
      "name": "Rock_Ice"
    },
    {
      "x": -20,
      "y": 47,
      "z": -3,
      "name": "Rock_Ice"
    },
    {
      "x": -20,
      "y": 48,
      "z": -3,
      "name": "Rock_Ice"
    },
    {
      "x": -20,
      "y": 49,
      "z": -3,
      "name": "Rock_Ice"
    },
    {
      "x": -20,
      "y": 50,
      "z": -3,
      "name": "Rock_Ice"
    },
    {
      "x": -20,
      "y": 51,
      "z": -3,
      "name": "Rock_Ice"
    },
    {
      "x": -20,
      "y": 52,
      "z": -3,
      "name": "Rock_Ice"
    },
    {
      "x": -20,
      "y": 53,
      "z": -3,
      "name": "Rock_Ice"
    },
    {
      "x": -20,
      "y": 54,
      "z": -3,
      "name": "Rock_Ice"
    },
    {
      "x": -20,
      "y": 55,
      "z": -3,
      "name": "Rock_Ice"
    },
    {
      "x": -20,
      "y": 56,
      "z": -3,
      "name": "Rock_Ice"
    },
    {
      "x": -20,
      "y": 57,
      "z": -3,
      "name": "Rock_Ice"
    },
    {
      "x": -20,
      "y": 58,
      "z": -3,
      "name": "Rock_Ice"
    },
    {
      "x": -20,
      "y": 59,
      "z": -3,
      "name": "Rock_Ice"
    },
    {
      "x": -20,
      "y": 60,
      "z": -3,
      "name": "Rock_Ice"
    },
    {
      "x": -20,
      "y": 61,
      "z": -3,
      "name": "Rock_Ice"
    },
    {
      "x": -20,
      "y": 62,
      "z": -3,
      "name": "Soil_Snow"
    },
    {
      "x": -20,
      "y": 16,
      "z": -2,
      "name": "Rock_Ice"
    },
    {
      "x": -20,
      "y": 17,
      "z": -2,
      "name": "Rock_Ice"
    },
    {
      "x": -20,
      "y": 18,
      "z": -2,
      "name": "Rock_Ice"
    },
    {
      "x": -20,
      "y": 19,
      "z": -2,
      "name": "Rock_Ice"
    },
    {
      "x": -20,
      "y": 20,
      "z": -2,
      "name": "Rock_Ice"
    },
    {
      "x": -20,
      "y": 21,
      "z": -2,
      "name": "Rock_Ice"
    },
    {
      "x": -20,
      "y": 22,
      "z": -2,
      "name": "Rock_Ice"
    },
    {
      "x": -20,
      "y": 23,
      "z": -2,
      "name": "Rock_Ice"
    },
    {
      "x": -20,
      "y": 24,
      "z": -2,
      "name": "Rock_Ice"
    },
    {
      "x": -20,
      "y": 25,
      "z": -2,
      "name": "Rock_Ice"
    },
    {
      "x": -20,
      "y": 26,
      "z": -2,
      "name": "Rock_Ice"
    },
    {
      "x": -20,
      "y": 31,
      "z": -2,
      "name": "Rock_Ice"
    },
    {
      "x": -20,
      "y": 38,
      "z": -2,
      "name": "Rock_Ice"
    },
    {
      "x": -20,
      "y": 39,
      "z": -2,
      "name": "Rock_Ice"
    },
    {
      "x": -20,
      "y": 40,
      "z": -2,
      "name": "Rock_Ice_Permafrost"
    },
    {
      "x": -20,
      "y": 41,
      "z": -2,
      "name": "Rock_Ice_Permafrost"
    },
    {
      "x": -20,
      "y": 42,
      "z": -2,
      "name": "Rock_Ice_Permafrost"
    },
    {
      "x": -20,
      "y": 43,
      "z": -2,
      "name": "Rock_Ice_Permafrost"
    },
    {
      "x": -20,
      "y": 44,
      "z": -2,
      "name": "Rock_Ice"
    },
    {
      "x": -20,
      "y": 45,
      "z": -2,
      "name": "Rock_Ice"
    },
    {
      "x": -20,
      "y": 46,
      "z": -2,
      "name": "Rock_Ice"
    },
    {
      "x": -20,
      "y": 47,
      "z": -2,
      "name": "Rock_Ice"
    },
    {
      "x": -20,
      "y": 48,
      "z": -2,
      "name": "Rock_Ice"
    },
    {
      "x": -20,
      "y": 49,
      "z": -2,
      "name": "Rock_Ice"
    },
    {
      "x": -20,
      "y": 50,
      "z": -2,
      "name": "Rock_Ice"
    },
    {
      "x": -20,
      "y": 51,
      "z": -2,
      "name": "Rock_Ice"
    },
    {
      "x": -20,
      "y": 60,
      "z": -2,
      "name": "Rock_Ice"
    },
    {
      "x": -20,
      "y": 16,
      "z": -1,
      "name": "Rock_Ice"
    },
    {
      "x": -20,
      "y": 17,
      "z": -1,
      "name": "Rock_Ice"
    },
    {
      "x": -20,
      "y": 18,
      "z": -1,
      "name": "Rock_Ice"
    },
    {
      "x": -20,
      "y": 19,
      "z": -1,
      "name": "Rock_Ice"
    },
    {
      "x": -20,
      "y": 20,
      "z": -1,
      "name": "Rock_Ice"
    },
    {
      "x": -20,
      "y": 21,
      "z": -1,
      "name": "Rock_Ice"
    },
    {
      "x": -20,
      "y": 22,
      "z": -1,
      "name": "Rock_Ice"
    },
    {
      "x": -20,
      "y": 23,
      "z": -1,
      "name": "Rock_Ice"
    },
    {
      "x": -20,
      "y": 24,
      "z": -1,
      "name": "Rock_Ice"
    },
    {
      "x": -20,
      "y": 25,
      "z": -1,
      "name": "Rock_Ice"
    },
    {
      "x": -20,
      "y": 31,
      "z": -1,
      "name": "Rock_Ice"
    },
    {
      "x": -20,
      "y": 32,
      "z": -1,
      "name": "Rock_Ice"
    },
    {
      "x": -20,
      "y": 33,
      "z": -1,
      "name": "Rock_Ice"
    },
    {
      "x": -20,
      "y": 34,
      "z": -1,
      "name": "Rock_Ice"
    },
    {
      "x": -20,
      "y": 35,
      "z": -1,
      "name": "Rock_Ice"
    },
    {
      "x": -20,
      "y": 36,
      "z": -1,
      "name": "Rock_Ice"
    },
    {
      "x": -20,
      "y": 37,
      "z": -1,
      "name": "Rock_Ice"
    },
    {
      "x": -20,
      "y": 38,
      "z": -1,
      "name": "Rock_Ice"
    },
    {
      "x": -20,
      "y": 39,
      "z": -1,
      "name": "Rock_Ice_Permafrost"
    },
    {
      "x": -20,
      "y": 40,
      "z": -1,
      "name": "Rock_Ice_Permafrost"
    },
    {
      "x": -20,
      "y": 41,
      "z": -1,
      "name": "Rock_Ice_Permafrost"
    },
    {
      "x": -20,
      "y": 42,
      "z": -1,
      "name": "Rock_Ice"
    },
    {
      "x": -20,
      "y": 43,
      "z": -1,
      "name": "Rock_Ice"
    },
    {
      "x": -20,
      "y": 44,
      "z": -1,
      "name": "Rock_Ice"
    },
    {
      "x": -20,
      "y": 45,
      "z": -1,
      "name": "Rock_Ice"
    },
    {
      "x": -20,
      "y": 46,
      "z": -1,
      "name": "Soil_Snow"
    },
    {
      "x": -20,
      "y": 16,
      "z": 0,
      "name": "Rock_Ice"
    },
    {
      "x": -20,
      "y": 17,
      "z": 0,
      "name": "Rock_Ice_Permafrost"
    },
    {
      "x": -20,
      "y": 18,
      "z": 0,
      "name": "Rock_Ice"
    },
    {
      "x": -20,
      "y": 19,
      "z": 0,
      "name": "Rock_Ice"
    },
    {
      "x": -20,
      "y": 20,
      "z": 0,
      "name": "Rock_Ice"
    },
    {
      "x": -20,
      "y": 21,
      "z": 0,
      "name": "Rock_Ice"
    },
    {
      "x": -20,
      "y": 22,
      "z": 0,
      "name": "Rock_Ice"
    },
    {
      "x": -20,
      "y": 23,
      "z": 0,
      "name": "Rock_Ice"
    },
    {
      "x": -20,
      "y": 24,
      "z": 0,
      "name": "Rock_Ice"
    },
    {
      "x": -20,
      "y": 31,
      "z": 0,
      "name": "Rock_Ice"
    },
    {
      "x": -20,
      "y": 32,
      "z": 0,
      "name": "Rock_Ice"
    },
    {
      "x": -20,
      "y": 33,
      "z": 0,
      "name": "Rock_Ice"
    },
    {
      "x": -20,
      "y": 34,
      "z": 0,
      "name": "Rock_Ice"
    },
    {
      "x": -20,
      "y": 35,
      "z": 0,
      "name": "Rock_Ice"
    },
    {
      "x": -20,
      "y": 36,
      "z": 0,
      "name": "Rock_Ice"
    },
    {
      "x": -20,
      "y": 37,
      "z": 0,
      "name": "Rock_Ice"
    },
    {
      "x": -20,
      "y": 38,
      "z": 0,
      "name": "Rock_Ice_Permafrost"
    },
    {
      "x": -20,
      "y": 39,
      "z": 0,
      "name": "Rock_Ice_Permafrost"
    },
    {
      "x": -20,
      "y": 40,
      "z": 0,
      "name": "Soil_Snow"
    },
    {
      "x": -20,
      "y": 16,
      "z": 1,
      "name": "Rock_Ice_Permafrost"
    },
    {
      "x": -20,
      "y": 17,
      "z": 1,
      "name": "Rock_Ice"
    },
    {
      "x": -20,
      "y": 18,
      "z": 1,
      "name": "Rock_Ice"
    },
    {
      "x": -20,
      "y": 19,
      "z": 1,
      "name": "Rock_Ice"
    },
    {
      "x": -20,
      "y": 20,
      "z": 1,
      "name": "Rock_Ice"
    },
    {
      "x": -20,
      "y": 21,
      "z": 1,
      "name": "Rock_Ice"
    },
    {
      "x": -20,
      "y": 22,
      "z": 1,
      "name": "Rock_Ice"
    },
    {
      "x": -20,
      "y": 23,
      "z": 1,
      "name": "Rock_Ice"
    },
    {
      "x": -20,
      "y": 24,
      "z": 1,
      "name": "Rock_Ice"
    },
    {
      "x": -20,
      "y": 25,
      "z": 1,
      "name": "Rock_Ice"
    },
    {
      "x": -20,
      "y": 30,
      "z": 1,
      "name": "Rock_Ice"
    },
    {
      "x": -20,
      "y": 31,
      "z": 1,
      "name": "Rock_Ice"
    },
    {
      "x": -20,
      "y": 32,
      "z": 1,
      "name": "Rock_Ice"
    },
    {
      "x": -20,
      "y": 33,
      "z": 1,
      "name": "Rock_Ice"
    },
    {
      "x": -20,
      "y": 34,
      "z": 1,
      "name": "Rock_Ice"
    },
    {
      "x": -20,
      "y": 35,
      "z": 1,
      "name": "Rock_Ice"
    },
    {
      "x": -20,
      "y": 36,
      "z": 1,
      "name": "Rock_Ice"
    },
    {
      "x": -20,
      "y": 37,
      "z": 1,
      "name": "Rock_Ice"
    },
    {
      "x": -20,
      "y": 38,
      "z": 1,
      "name": "Rock_Ice_Permafrost"
    },
    {
      "x": -20,
      "y": 39,
      "z": 1,
      "name": "Rock_Crystal_Cyan_Block_WhiteLight"
    },
    {
      "x": -20,
      "y": 40,
      "z": 1,
      "name": "Rock_Ice_Permafrost"
    },
    {
      "x": -20,
      "y": 16,
      "z": 2,
      "name": "Rock_Ice"
    },
    {
      "x": -20,
      "y": 17,
      "z": 2,
      "name": "Rock_Ice"
    },
    {
      "x": -20,
      "y": 18,
      "z": 2,
      "name": "Rock_Ice"
    },
    {
      "x": -20,
      "y": 19,
      "z": 2,
      "name": "Rock_Ice"
    },
    {
      "x": -20,
      "y": 20,
      "z": 2,
      "name": "Rock_Ice"
    },
    {
      "x": -20,
      "y": 21,
      "z": 2,
      "name": "Rock_Ice"
    },
    {
      "x": -20,
      "y": 22,
      "z": 2,
      "name": "Rock_Ice"
    },
    {
      "x": -20,
      "y": 23,
      "z": 2,
      "name": "Rock_Ice"
    },
    {
      "x": -20,
      "y": 24,
      "z": 2,
      "name": "Rock_Ice"
    },
    {
      "x": -20,
      "y": 25,
      "z": 2,
      "name": "Rock_Ice"
    },
    {
      "x": -20,
      "y": 30,
      "z": 2,
      "name": "Rock_Ice"
    },
    {
      "x": -20,
      "y": 31,
      "z": 2,
      "name": "Rock_Ice"
    },
    {
      "x": -20,
      "y": 32,
      "z": 2,
      "name": "Rock_Ice"
    },
    {
      "x": -20,
      "y": 33,
      "z": 2,
      "name": "Rock_Ice"
    },
    {
      "x": -20,
      "y": 34,
      "z": 2,
      "name": "Rock_Ice"
    },
    {
      "x": -20,
      "y": 35,
      "z": 2,
      "name": "Soil_Snow"
    },
    {
      "x": -20,
      "y": 16,
      "z": 3,
      "name": "Rock_Ice"
    },
    {
      "x": -20,
      "y": 17,
      "z": 3,
      "name": "Rock_Ice_Permafrost"
    },
    {
      "x": -20,
      "y": 18,
      "z": 3,
      "name": "Rock_Ice_Permafrost"
    },
    {
      "x": -20,
      "y": 19,
      "z": 3,
      "name": "Rock_Ice"
    },
    {
      "x": -20,
      "y": 20,
      "z": 3,
      "name": "Rock_Ice"
    },
    {
      "x": -20,
      "y": 21,
      "z": 3,
      "name": "Rock_Ice"
    },
    {
      "x": -20,
      "y": 22,
      "z": 3,
      "name": "Rock_Ice"
    },
    {
      "x": -20,
      "y": 23,
      "z": 3,
      "name": "Rock_Ice"
    },
    {
      "x": -20,
      "y": 24,
      "z": 3,
      "name": "Soil_Snow"
    },
    {
      "x": -20,
      "y": 17,
      "z": 4,
      "name": "Rock_Ice_Permafrost"
    },
    {
      "x": -20,
      "y": 18,
      "z": 4,
      "name": "Rock_Ice_Permafrost"
    },
    {
      "x": -20,
      "y": 19,
      "z": 4,
      "name": "Rock_Ice_Permafrost"
    },
    {
      "x": -20,
      "y": 20,
      "z": 4,
      "name": "Rock_Ice"
    },
    {
      "x": -20,
      "y": 21,
      "z": 4,
      "name": "Rock_Ice"
    },
    {
      "x": -20,
      "y": 22,
      "z": 4,
      "name": "Rock_Ice"
    },
    {
      "x": -20,
      "y": 23,
      "z": 4,
      "name": "Soil_Snow"
    },
    {
      "x": -19,
      "y": 45,
      "z": -15,
      "name": "Rock_Ice"
    },
    {
      "x": -19,
      "y": 46,
      "z": -15,
      "name": "Soil_Snow"
    },
    {
      "x": -19,
      "y": 43,
      "z": -14,
      "name": "Rock_Ice"
    },
    {
      "x": -19,
      "y": 44,
      "z": -14,
      "name": "Rock_Ice"
    },
    {
      "x": -19,
      "y": 45,
      "z": -14,
      "name": "Rock_Ice"
    },
    {
      "x": -19,
      "y": 46,
      "z": -14,
      "name": "Rock_Ice"
    },
    {
      "x": -19,
      "y": 47,
      "z": -14,
      "name": "Rock_Ice"
    },
    {
      "x": -19,
      "y": 48,
      "z": -14,
      "name": "Soil_Snow"
    },
    {
      "x": -19,
      "y": 41,
      "z": -13,
      "name": "Rock_Ice"
    },
    {
      "x": -19,
      "y": 42,
      "z": -13,
      "name": "Rock_Ice"
    },
    {
      "x": -19,
      "y": 43,
      "z": -13,
      "name": "Rock_Ice"
    },
    {
      "x": -19,
      "y": 44,
      "z": -13,
      "name": "Rock_Ice"
    },
    {
      "x": -19,
      "y": 45,
      "z": -13,
      "name": "Rock_Ice"
    },
    {
      "x": -19,
      "y": 46,
      "z": -13,
      "name": "Rock_Ice"
    },
    {
      "x": -19,
      "y": 47,
      "z": -13,
      "name": "Rock_Ice"
    },
    {
      "x": -19,
      "y": 48,
      "z": -13,
      "name": "Rock_Ice"
    },
    {
      "x": -19,
      "y": 49,
      "z": -13,
      "name": "Rock_Ice"
    },
    {
      "x": -19,
      "y": 50,
      "z": -13,
      "name": "Soil_Snow"
    },
    {
      "x": -19,
      "y": 39,
      "z": -12,
      "name": "Rock_Ice"
    },
    {
      "x": -19,
      "y": 40,
      "z": -12,
      "name": "Rock_Ice"
    },
    {
      "x": -19,
      "y": 41,
      "z": -12,
      "name": "Rock_Ice"
    },
    {
      "x": -19,
      "y": 42,
      "z": -12,
      "name": "Rock_Ice"
    },
    {
      "x": -19,
      "y": 43,
      "z": -12,
      "name": "Rock_Ice"
    },
    {
      "x": -19,
      "y": 44,
      "z": -12,
      "name": "Rock_Ice"
    },
    {
      "x": -19,
      "y": 45,
      "z": -12,
      "name": "Rock_Ice"
    },
    {
      "x": -19,
      "y": 46,
      "z": -12,
      "name": "Rock_Ice"
    },
    {
      "x": -19,
      "y": 47,
      "z": -12,
      "name": "Rock_Ice"
    },
    {
      "x": -19,
      "y": 48,
      "z": -12,
      "name": "Rock_Ice"
    },
    {
      "x": -19,
      "y": 49,
      "z": -12,
      "name": "Rock_Ice"
    },
    {
      "x": -19,
      "y": 50,
      "z": -12,
      "name": "Rock_Ice"
    },
    {
      "x": -19,
      "y": 51,
      "z": -12,
      "name": "Soil_Snow"
    },
    {
      "x": -19,
      "y": 38,
      "z": -11,
      "name": "Rock_Ice"
    },
    {
      "x": -19,
      "y": 39,
      "z": -11,
      "name": "Rock_Ice"
    },
    {
      "x": -19,
      "y": 40,
      "z": -11,
      "name": "Rock_Ice"
    },
    {
      "x": -19,
      "y": 41,
      "z": -11,
      "name": "Rock_Ice"
    },
    {
      "x": -19,
      "y": 42,
      "z": -11,
      "name": "Rock_Ice"
    },
    {
      "x": -19,
      "y": 43,
      "z": -11,
      "name": "Rock_Ice"
    },
    {
      "x": -19,
      "y": 44,
      "z": -11,
      "name": "Rock_Ice"
    },
    {
      "x": -19,
      "y": 45,
      "z": -11,
      "name": "Rock_Ice"
    },
    {
      "x": -19,
      "y": 46,
      "z": -11,
      "name": "Rock_Ice"
    },
    {
      "x": -19,
      "y": 47,
      "z": -11,
      "name": "Rock_Ice"
    },
    {
      "x": -19,
      "y": 48,
      "z": -11,
      "name": "Rock_Ice"
    },
    {
      "x": -19,
      "y": 49,
      "z": -11,
      "name": "Rock_Ice"
    },
    {
      "x": -19,
      "y": 50,
      "z": -11,
      "name": "Rock_Ice"
    },
    {
      "x": -19,
      "y": 51,
      "z": -11,
      "name": "Rock_Ice_Permafrost"
    },
    {
      "x": -19,
      "y": 37,
      "z": -10,
      "name": "Rock_Crystal_Cyan_Block_WhiteLight"
    },
    {
      "x": -19,
      "y": 38,
      "z": -10,
      "name": "Rock_Ice_Permafrost"
    },
    {
      "x": -19,
      "y": 39,
      "z": -10,
      "name": "Rock_Ice"
    },
    {
      "x": -19,
      "y": 40,
      "z": -10,
      "name": "Rock_Ice"
    },
    {
      "x": -19,
      "y": 41,
      "z": -10,
      "name": "Rock_Ice"
    },
    {
      "x": -19,
      "y": 42,
      "z": -10,
      "name": "Rock_Ice"
    },
    {
      "x": -19,
      "y": 43,
      "z": -10,
      "name": "Rock_Ice"
    },
    {
      "x": -19,
      "y": 44,
      "z": -10,
      "name": "Rock_Ice"
    },
    {
      "x": -19,
      "y": 45,
      "z": -10,
      "name": "Rock_Ice"
    },
    {
      "x": -19,
      "y": 46,
      "z": -10,
      "name": "Rock_Ice"
    },
    {
      "x": -19,
      "y": 47,
      "z": -10,
      "name": "Rock_Ice"
    },
    {
      "x": -19,
      "y": 48,
      "z": -10,
      "name": "Rock_Ice"
    },
    {
      "x": -19,
      "y": 49,
      "z": -10,
      "name": "Rock_Ice"
    },
    {
      "x": -19,
      "y": 50,
      "z": -10,
      "name": "Rock_Ice"
    },
    {
      "x": -19,
      "y": 51,
      "z": -10,
      "name": "Rock_Ice_Permafrost"
    },
    {
      "x": -19,
      "y": 36,
      "z": -9,
      "name": "Rock_Ice_Permafrost"
    },
    {
      "x": -19,
      "y": 37,
      "z": -9,
      "name": "Rock_Ice_Permafrost"
    },
    {
      "x": -19,
      "y": 38,
      "z": -9,
      "name": "Rock_Crystal_Cyan_Block_WhiteLight"
    },
    {
      "x": -19,
      "y": 39,
      "z": -9,
      "name": "Rock_Ice_Permafrost"
    },
    {
      "x": -19,
      "y": 40,
      "z": -9,
      "name": "Rock_Ice"
    },
    {
      "x": -19,
      "y": 41,
      "z": -9,
      "name": "Rock_Ice"
    },
    {
      "x": -19,
      "y": 42,
      "z": -9,
      "name": "Rock_Ice"
    },
    {
      "x": -19,
      "y": 43,
      "z": -9,
      "name": "Rock_Ice"
    },
    {
      "x": -19,
      "y": 44,
      "z": -9,
      "name": "Rock_Ice"
    },
    {
      "x": -19,
      "y": 45,
      "z": -9,
      "name": "Rock_Ice"
    },
    {
      "x": -19,
      "y": 46,
      "z": -9,
      "name": "Rock_Ice"
    },
    {
      "x": -19,
      "y": 47,
      "z": -9,
      "name": "Rock_Ice"
    },
    {
      "x": -19,
      "y": 48,
      "z": -9,
      "name": "Rock_Ice"
    },
    {
      "x": -19,
      "y": 49,
      "z": -9,
      "name": "Rock_Ice_Permafrost"
    },
    {
      "x": -19,
      "y": 50,
      "z": -9,
      "name": "Rock_Ice_Permafrost"
    },
    {
      "x": -19,
      "y": 51,
      "z": -9,
      "name": "Rock_Ice_Permafrost"
    },
    {
      "x": -19,
      "y": 20,
      "z": -8,
      "name": "Rock_Crystal_Cyan_Block_WhiteLight"
    },
    {
      "x": -19,
      "y": 21,
      "z": -8,
      "name": "Rock_Ice_Permafrost"
    },
    {
      "x": -19,
      "y": 22,
      "z": -8,
      "name": "Rock_Ice_Permafrost"
    },
    {
      "x": -19,
      "y": 34,
      "z": -8,
      "name": "Rock_Ice"
    },
    {
      "x": -19,
      "y": 35,
      "z": -8,
      "name": "Rock_Ice"
    },
    {
      "x": -19,
      "y": 36,
      "z": -8,
      "name": "Rock_Ice_Permafrost"
    },
    {
      "x": -19,
      "y": 37,
      "z": -8,
      "name": "Rock_Ice_Permafrost"
    },
    {
      "x": -19,
      "y": 38,
      "z": -8,
      "name": "Rock_Crystal_Cyan_Block_WhiteLight"
    },
    {
      "x": -19,
      "y": 39,
      "z": -8,
      "name": "Rock_Ice_Permafrost"
    },
    {
      "x": -19,
      "y": 40,
      "z": -8,
      "name": "Rock_Ice_Permafrost"
    },
    {
      "x": -19,
      "y": 41,
      "z": -8,
      "name": "Rock_Ice"
    },
    {
      "x": -19,
      "y": 42,
      "z": -8,
      "name": "Rock_Ice_Permafrost"
    },
    {
      "x": -19,
      "y": 43,
      "z": -8,
      "name": "Rock_Ice"
    },
    {
      "x": -19,
      "y": 44,
      "z": -8,
      "name": "Rock_Ice"
    },
    {
      "x": -19,
      "y": 45,
      "z": -8,
      "name": "Rock_Ice"
    },
    {
      "x": -19,
      "y": 46,
      "z": -8,
      "name": "Rock_Ice"
    },
    {
      "x": -19,
      "y": 47,
      "z": -8,
      "name": "Rock_Ice_Permafrost"
    },
    {
      "x": -19,
      "y": 48,
      "z": -8,
      "name": "Rock_Ice"
    },
    {
      "x": -19,
      "y": 49,
      "z": -8,
      "name": "Rock_Ice"
    },
    {
      "x": -19,
      "y": 50,
      "z": -8,
      "name": "Rock_Ice_Permafrost"
    },
    {
      "x": -19,
      "y": 51,
      "z": -8,
      "name": "Rock_Ice_Permafrost"
    },
    {
      "x": -19,
      "y": 52,
      "z": -8,
      "name": "Rock_Ice_Permafrost"
    },
    {
      "x": -19,
      "y": 53,
      "z": -8,
      "name": "Rock_Ice"
    },
    {
      "x": -19,
      "y": 54,
      "z": -8,
      "name": "Rock_Ice"
    },
    {
      "x": -19,
      "y": 55,
      "z": -8,
      "name": "Rock_Ice"
    },
    {
      "x": -19,
      "y": 19,
      "z": -7,
      "name": "Rock_Ice"
    },
    {
      "x": -19,
      "y": 20,
      "z": -7,
      "name": "Rock_Ice"
    },
    {
      "x": -19,
      "y": 21,
      "z": -7,
      "name": "Rock_Ice"
    },
    {
      "x": -19,
      "y": 22,
      "z": -7,
      "name": "Rock_Ice"
    },
    {
      "x": -19,
      "y": 23,
      "z": -7,
      "name": "Rock_Ice"
    },
    {
      "x": -19,
      "y": 24,
      "z": -7,
      "name": "Rock_Ice"
    },
    {
      "x": -19,
      "y": 25,
      "z": -7,
      "name": "Rock_Ice_Permafrost"
    },
    {
      "x": -19,
      "y": 31,
      "z": -7,
      "name": "Rock_Ice"
    },
    {
      "x": -19,
      "y": 32,
      "z": -7,
      "name": "Rock_Ice"
    },
    {
      "x": -19,
      "y": 33,
      "z": -7,
      "name": "Rock_Ice_Permafrost"
    },
    {
      "x": -19,
      "y": 34,
      "z": -7,
      "name": "Rock_Ice_Permafrost"
    },
    {
      "x": -19,
      "y": 35,
      "z": -7,
      "name": "Rock_Ice_Permafrost"
    },
    {
      "x": -19,
      "y": 36,
      "z": -7,
      "name": "Rock_Ice"
    },
    {
      "x": -19,
      "y": 37,
      "z": -7,
      "name": "Rock_Ice_Permafrost"
    },
    {
      "x": -19,
      "y": 38,
      "z": -7,
      "name": "Rock_Ice_Permafrost"
    },
    {
      "x": -19,
      "y": 39,
      "z": -7,
      "name": "Rock_Ice_Permafrost"
    },
    {
      "x": -19,
      "y": 40,
      "z": -7,
      "name": "Rock_Ice_Permafrost"
    },
    {
      "x": -19,
      "y": 41,
      "z": -7,
      "name": "Rock_Ice_Permafrost"
    },
    {
      "x": -19,
      "y": 42,
      "z": -7,
      "name": "Rock_Ice_Permafrost"
    },
    {
      "x": -19,
      "y": 43,
      "z": -7,
      "name": "Rock_Ice"
    },
    {
      "x": -19,
      "y": 44,
      "z": -7,
      "name": "Rock_Ice"
    },
    {
      "x": -19,
      "y": 45,
      "z": -7,
      "name": "Rock_Ice_Permafrost"
    },
    {
      "x": -19,
      "y": 46,
      "z": -7,
      "name": "Rock_Ice_Permafrost"
    },
    {
      "x": -19,
      "y": 47,
      "z": -7,
      "name": "Rock_Ice_Permafrost"
    },
    {
      "x": -19,
      "y": 48,
      "z": -7,
      "name": "Rock_Ice_Permafrost"
    },
    {
      "x": -19,
      "y": 49,
      "z": -7,
      "name": "Rock_Ice_Permafrost"
    },
    {
      "x": -19,
      "y": 50,
      "z": -7,
      "name": "Rock_Ice"
    },
    {
      "x": -19,
      "y": 51,
      "z": -7,
      "name": "Rock_Ice_Permafrost"
    },
    {
      "x": -19,
      "y": 52,
      "z": -7,
      "name": "Rock_Ice"
    },
    {
      "x": -19,
      "y": 53,
      "z": -7,
      "name": "Rock_Ice"
    },
    {
      "x": -19,
      "y": 54,
      "z": -7,
      "name": "Rock_Ice"
    },
    {
      "x": -19,
      "y": 55,
      "z": -7,
      "name": "Rock_Ice"
    },
    {
      "x": -19,
      "y": 56,
      "z": -7,
      "name": "Rock_Ice"
    },
    {
      "x": -19,
      "y": 57,
      "z": -7,
      "name": "Rock_Ice"
    },
    {
      "x": -19,
      "y": 58,
      "z": -7,
      "name": "Rock_Ice"
    },
    {
      "x": -19,
      "y": 17,
      "z": -6,
      "name": "Rock_Ice"
    },
    {
      "x": -19,
      "y": 18,
      "z": -6,
      "name": "Rock_Ice"
    },
    {
      "x": -19,
      "y": 19,
      "z": -6,
      "name": "Rock_Ice"
    },
    {
      "x": -19,
      "y": 20,
      "z": -6,
      "name": "Rock_Ice"
    },
    {
      "x": -19,
      "y": 21,
      "z": -6,
      "name": "Rock_Ice"
    },
    {
      "x": -19,
      "y": 22,
      "z": -6,
      "name": "Rock_Ice"
    },
    {
      "x": -19,
      "y": 23,
      "z": -6,
      "name": "Rock_Ice"
    },
    {
      "x": -19,
      "y": 24,
      "z": -6,
      "name": "Rock_Ice"
    },
    {
      "x": -19,
      "y": 25,
      "z": -6,
      "name": "Rock_Ice"
    },
    {
      "x": -19,
      "y": 26,
      "z": -6,
      "name": "Rock_Ice"
    },
    {
      "x": -19,
      "y": 27,
      "z": -6,
      "name": "Rock_Ice"
    },
    {
      "x": -19,
      "y": 29,
      "z": -6,
      "name": "Rock_Ice"
    },
    {
      "x": -19,
      "y": 30,
      "z": -6,
      "name": "Rock_Ice"
    },
    {
      "x": -19,
      "y": 31,
      "z": -6,
      "name": "Rock_Ice"
    },
    {
      "x": -19,
      "y": 32,
      "z": -6,
      "name": "Rock_Ice"
    },
    {
      "x": -19,
      "y": 33,
      "z": -6,
      "name": "Rock_Ice"
    },
    {
      "x": -19,
      "y": 34,
      "z": -6,
      "name": "Rock_Ice"
    },
    {
      "x": -19,
      "y": 35,
      "z": -6,
      "name": "Rock_Ice_Permafrost"
    },
    {
      "x": -19,
      "y": 36,
      "z": -6,
      "name": "Rock_Ice"
    },
    {
      "x": -19,
      "y": 37,
      "z": -6,
      "name": "Rock_Ice"
    },
    {
      "x": -19,
      "y": 38,
      "z": -6,
      "name": "Rock_Ice_Permafrost"
    },
    {
      "x": -19,
      "y": 39,
      "z": -6,
      "name": "Rock_Ice_Permafrost"
    },
    {
      "x": -19,
      "y": 40,
      "z": -6,
      "name": "Rock_Ice_Permafrost"
    },
    {
      "x": -19,
      "y": 41,
      "z": -6,
      "name": "Rock_Ice_Permafrost"
    },
    {
      "x": -19,
      "y": 42,
      "z": -6,
      "name": "Rock_Crystal_Cyan_Block_WhiteLight"
    },
    {
      "x": -19,
      "y": 43,
      "z": -6,
      "name": "Rock_Ice_Permafrost"
    },
    {
      "x": -19,
      "y": 44,
      "z": -6,
      "name": "Rock_Crystal_Cyan_Block_WhiteLight"
    },
    {
      "x": -19,
      "y": 45,
      "z": -6,
      "name": "Rock_Ice_Permafrost"
    },
    {
      "x": -19,
      "y": 46,
      "z": -6,
      "name": "Rock_Ice"
    },
    {
      "x": -19,
      "y": 47,
      "z": -6,
      "name": "Rock_Ice"
    },
    {
      "x": -19,
      "y": 48,
      "z": -6,
      "name": "Rock_Ice_Permafrost"
    },
    {
      "x": -19,
      "y": 49,
      "z": -6,
      "name": "Rock_Ice"
    },
    {
      "x": -19,
      "y": 50,
      "z": -6,
      "name": "Rock_Ice"
    },
    {
      "x": -19,
      "y": 51,
      "z": -6,
      "name": "Rock_Ice"
    },
    {
      "x": -19,
      "y": 52,
      "z": -6,
      "name": "Rock_Ice"
    },
    {
      "x": -19,
      "y": 53,
      "z": -6,
      "name": "Rock_Ice"
    },
    {
      "x": -19,
      "y": 54,
      "z": -6,
      "name": "Rock_Ice"
    },
    {
      "x": -19,
      "y": 55,
      "z": -6,
      "name": "Rock_Ice"
    },
    {
      "x": -19,
      "y": 56,
      "z": -6,
      "name": "Rock_Ice"
    },
    {
      "x": -19,
      "y": 57,
      "z": -6,
      "name": "Rock_Ice"
    },
    {
      "x": -19,
      "y": 58,
      "z": -6,
      "name": "Rock_Ice"
    },
    {
      "x": -19,
      "y": 59,
      "z": -6,
      "name": "Rock_Ice"
    },
    {
      "x": -19,
      "y": 60,
      "z": -6,
      "name": "Rock_Ice"
    },
    {
      "x": -19,
      "y": 61,
      "z": -6,
      "name": "Rock_Ice"
    },
    {
      "x": -19,
      "y": 62,
      "z": -6,
      "name": "Rock_Ice"
    },
    {
      "x": -19,
      "y": 63,
      "z": -6,
      "name": "Soil_Snow"
    },
    {
      "x": -19,
      "y": 16,
      "z": -5,
      "name": "Rock_Ice"
    },
    {
      "x": -19,
      "y": 17,
      "z": -5,
      "name": "Rock_Ice"
    },
    {
      "x": -19,
      "y": 18,
      "z": -5,
      "name": "Rock_Ice"
    },
    {
      "x": -19,
      "y": 19,
      "z": -5,
      "name": "Rock_Ice"
    },
    {
      "x": -19,
      "y": 20,
      "z": -5,
      "name": "Rock_Ice"
    },
    {
      "x": -19,
      "y": 21,
      "z": -5,
      "name": "Rock_Ice"
    },
    {
      "x": -19,
      "y": 22,
      "z": -5,
      "name": "Rock_Ice"
    },
    {
      "x": -19,
      "y": 23,
      "z": -5,
      "name": "Rock_Ice"
    },
    {
      "x": -19,
      "y": 24,
      "z": -5,
      "name": "Rock_Ice"
    },
    {
      "x": -19,
      "y": 25,
      "z": -5,
      "name": "Rock_Ice"
    },
    {
      "x": -19,
      "y": 26,
      "z": -5,
      "name": "Rock_Ice"
    },
    {
      "x": -19,
      "y": 27,
      "z": -5,
      "name": "Rock_Ice"
    },
    {
      "x": -19,
      "y": 28,
      "z": -5,
      "name": "Rock_Ice"
    },
    {
      "x": -19,
      "y": 29,
      "z": -5,
      "name": "Rock_Ice"
    },
    {
      "x": -19,
      "y": 30,
      "z": -5,
      "name": "Rock_Ice"
    },
    {
      "x": -19,
      "y": 31,
      "z": -5,
      "name": "Rock_Ice"
    },
    {
      "x": -19,
      "y": 32,
      "z": -5,
      "name": "Rock_Ice"
    },
    {
      "x": -19,
      "y": 33,
      "z": -5,
      "name": "Rock_Ice"
    },
    {
      "x": -19,
      "y": 34,
      "z": -5,
      "name": "Rock_Ice"
    },
    {
      "x": -19,
      "y": 35,
      "z": -5,
      "name": "Rock_Ice"
    },
    {
      "x": -19,
      "y": 36,
      "z": -5,
      "name": "Rock_Ice"
    },
    {
      "x": -19,
      "y": 37,
      "z": -5,
      "name": "Rock_Ice"
    },
    {
      "x": -19,
      "y": 38,
      "z": -5,
      "name": "Rock_Ice"
    },
    {
      "x": -19,
      "y": 39,
      "z": -5,
      "name": "Rock_Ice_Permafrost"
    },
    {
      "x": -19,
      "y": 40,
      "z": -5,
      "name": "Rock_Ice_Permafrost"
    },
    {
      "x": -19,
      "y": 41,
      "z": -5,
      "name": "Rock_Ice_Permafrost"
    },
    {
      "x": -19,
      "y": 42,
      "z": -5,
      "name": "Rock_Crystal_Cyan_Block_WhiteLight"
    },
    {
      "x": -19,
      "y": 43,
      "z": -5,
      "name": "Rock_Crystal_Cyan_Block_WhiteLight"
    },
    {
      "x": -19,
      "y": 44,
      "z": -5,
      "name": "Rock_Ice_Permafrost"
    },
    {
      "x": -19,
      "y": 45,
      "z": -5,
      "name": "Rock_Ice"
    },
    {
      "x": -19,
      "y": 46,
      "z": -5,
      "name": "Rock_Ice"
    },
    {
      "x": -19,
      "y": 47,
      "z": -5,
      "name": "Rock_Ice"
    },
    {
      "x": -19,
      "y": 48,
      "z": -5,
      "name": "Rock_Ice"
    },
    {
      "x": -19,
      "y": 49,
      "z": -5,
      "name": "Rock_Ice"
    },
    {
      "x": -19,
      "y": 50,
      "z": -5,
      "name": "Rock_Ice"
    },
    {
      "x": -19,
      "y": 51,
      "z": -5,
      "name": "Rock_Ice"
    },
    {
      "x": -19,
      "y": 52,
      "z": -5,
      "name": "Rock_Ice"
    },
    {
      "x": -19,
      "y": 53,
      "z": -5,
      "name": "Rock_Ice"
    },
    {
      "x": -19,
      "y": 54,
      "z": -5,
      "name": "Rock_Ice"
    },
    {
      "x": -19,
      "y": 55,
      "z": -5,
      "name": "Rock_Ice"
    },
    {
      "x": -19,
      "y": 56,
      "z": -5,
      "name": "Rock_Ice"
    },
    {
      "x": -19,
      "y": 57,
      "z": -5,
      "name": "Rock_Ice"
    },
    {
      "x": -19,
      "y": 58,
      "z": -5,
      "name": "Rock_Ice"
    },
    {
      "x": -19,
      "y": 59,
      "z": -5,
      "name": "Rock_Ice"
    },
    {
      "x": -19,
      "y": 60,
      "z": -5,
      "name": "Rock_Ice"
    },
    {
      "x": -19,
      "y": 61,
      "z": -5,
      "name": "Rock_Ice"
    },
    {
      "x": -19,
      "y": 62,
      "z": -5,
      "name": "Rock_Ice"
    },
    {
      "x": -19,
      "y": 63,
      "z": -5,
      "name": "Rock_Ice"
    },
    {
      "x": -19,
      "y": 64,
      "z": -5,
      "name": "Soil_Snow"
    },
    {
      "x": -19,
      "y": 15,
      "z": -4,
      "name": "Rock_Ice"
    },
    {
      "x": -19,
      "y": 16,
      "z": -4,
      "name": "Rock_Ice"
    },
    {
      "x": -19,
      "y": 17,
      "z": -4,
      "name": "Rock_Ice"
    },
    {
      "x": -19,
      "y": 18,
      "z": -4,
      "name": "Rock_Ice"
    },
    {
      "x": -19,
      "y": 19,
      "z": -4,
      "name": "Rock_Ice"
    },
    {
      "x": -19,
      "y": 20,
      "z": -4,
      "name": "Rock_Ice"
    },
    {
      "x": -19,
      "y": 21,
      "z": -4,
      "name": "Rock_Ice"
    },
    {
      "x": -19,
      "y": 22,
      "z": -4,
      "name": "Rock_Ice"
    },
    {
      "x": -19,
      "y": 23,
      "z": -4,
      "name": "Rock_Ice"
    },
    {
      "x": -19,
      "y": 24,
      "z": -4,
      "name": "Rock_Ice"
    },
    {
      "x": -19,
      "y": 25,
      "z": -4,
      "name": "Rock_Ice"
    },
    {
      "x": -19,
      "y": 26,
      "z": -4,
      "name": "Rock_Ice"
    },
    {
      "x": -19,
      "y": 27,
      "z": -4,
      "name": "Rock_Ice"
    },
    {
      "x": -19,
      "y": 28,
      "z": -4,
      "name": "Rock_Ice"
    },
    {
      "x": -19,
      "y": 29,
      "z": -4,
      "name": "Rock_Ice"
    },
    {
      "x": -19,
      "y": 30,
      "z": -4,
      "name": "Rock_Ice"
    },
    {
      "x": -19,
      "y": 31,
      "z": -4,
      "name": "Rock_Ice"
    },
    {
      "x": -19,
      "y": 32,
      "z": -4,
      "name": "Rock_Ice"
    },
    {
      "x": -19,
      "y": 33,
      "z": -4,
      "name": "Rock_Ice"
    },
    {
      "x": -19,
      "y": 34,
      "z": -4,
      "name": "Rock_Ice"
    },
    {
      "x": -19,
      "y": 35,
      "z": -4,
      "name": "Rock_Ice"
    },
    {
      "x": -19,
      "y": 36,
      "z": -4,
      "name": "Rock_Ice"
    },
    {
      "x": -19,
      "y": 37,
      "z": -4,
      "name": "Rock_Ice"
    },
    {
      "x": -19,
      "y": 38,
      "z": -4,
      "name": "Rock_Ice"
    },
    {
      "x": -19,
      "y": 39,
      "z": -4,
      "name": "Rock_Ice"
    },
    {
      "x": -19,
      "y": 40,
      "z": -4,
      "name": "Rock_Ice_Permafrost"
    },
    {
      "x": -19,
      "y": 41,
      "z": -4,
      "name": "Rock_Crystal_Cyan_Block_WhiteLight"
    },
    {
      "x": -19,
      "y": 42,
      "z": -4,
      "name": "Rock_Ice_Permafrost"
    },
    {
      "x": -19,
      "y": 43,
      "z": -4,
      "name": "Rock_Ice_Permafrost"
    },
    {
      "x": -19,
      "y": 44,
      "z": -4,
      "name": "Rock_Ice_Permafrost"
    },
    {
      "x": -19,
      "y": 45,
      "z": -4,
      "name": "Rock_Ice_Permafrost"
    },
    {
      "x": -19,
      "y": 46,
      "z": -4,
      "name": "Rock_Ice"
    },
    {
      "x": -19,
      "y": 47,
      "z": -4,
      "name": "Rock_Ice"
    },
    {
      "x": -19,
      "y": 48,
      "z": -4,
      "name": "Rock_Ice"
    },
    {
      "x": -19,
      "y": 49,
      "z": -4,
      "name": "Rock_Ice"
    },
    {
      "x": -19,
      "y": 50,
      "z": -4,
      "name": "Rock_Ice"
    },
    {
      "x": -19,
      "y": 51,
      "z": -4,
      "name": "Rock_Ice"
    },
    {
      "x": -19,
      "y": 52,
      "z": -4,
      "name": "Rock_Ice"
    },
    {
      "x": -19,
      "y": 53,
      "z": -4,
      "name": "Rock_Ice"
    },
    {
      "x": -19,
      "y": 54,
      "z": -4,
      "name": "Rock_Ice"
    },
    {
      "x": -19,
      "y": 55,
      "z": -4,
      "name": "Rock_Ice"
    },
    {
      "x": -19,
      "y": 56,
      "z": -4,
      "name": "Rock_Ice"
    },
    {
      "x": -19,
      "y": 57,
      "z": -4,
      "name": "Rock_Ice"
    },
    {
      "x": -19,
      "y": 58,
      "z": -4,
      "name": "Rock_Ice"
    },
    {
      "x": -19,
      "y": 59,
      "z": -4,
      "name": "Rock_Ice"
    },
    {
      "x": -19,
      "y": 60,
      "z": -4,
      "name": "Rock_Ice"
    },
    {
      "x": -19,
      "y": 61,
      "z": -4,
      "name": "Rock_Ice"
    },
    {
      "x": -19,
      "y": 62,
      "z": -4,
      "name": "Rock_Ice"
    },
    {
      "x": -19,
      "y": 63,
      "z": -4,
      "name": "Rock_Ice"
    },
    {
      "x": -19,
      "y": 64,
      "z": -4,
      "name": "Rock_Ice"
    },
    {
      "x": -19,
      "y": 65,
      "z": -4,
      "name": "Rock_Ice"
    },
    {
      "x": -19,
      "y": 66,
      "z": -4,
      "name": "Soil_Snow"
    },
    {
      "x": -19,
      "y": 14,
      "z": -3,
      "name": "Rock_Ice"
    },
    {
      "x": -19,
      "y": 15,
      "z": -3,
      "name": "Rock_Ice"
    },
    {
      "x": -19,
      "y": 16,
      "z": -3,
      "name": "Rock_Ice"
    },
    {
      "x": -19,
      "y": 17,
      "z": -3,
      "name": "Rock_Ice"
    },
    {
      "x": -19,
      "y": 18,
      "z": -3,
      "name": "Rock_Ice"
    },
    {
      "x": -19,
      "y": 19,
      "z": -3,
      "name": "Rock_Ice"
    },
    {
      "x": -19,
      "y": 20,
      "z": -3,
      "name": "Rock_Ice"
    },
    {
      "x": -19,
      "y": 21,
      "z": -3,
      "name": "Rock_Ice"
    },
    {
      "x": -19,
      "y": 22,
      "z": -3,
      "name": "Rock_Ice"
    },
    {
      "x": -19,
      "y": 23,
      "z": -3,
      "name": "Rock_Ice"
    },
    {
      "x": -19,
      "y": 24,
      "z": -3,
      "name": "Rock_Ice"
    },
    {
      "x": -19,
      "y": 25,
      "z": -3,
      "name": "Rock_Ice"
    },
    {
      "x": -19,
      "y": 26,
      "z": -3,
      "name": "Rock_Ice"
    },
    {
      "x": -19,
      "y": 27,
      "z": -3,
      "name": "Rock_Ice"
    },
    {
      "x": -19,
      "y": 28,
      "z": -3,
      "name": "Rock_Ice"
    },
    {
      "x": -19,
      "y": 29,
      "z": -3,
      "name": "Rock_Ice"
    },
    {
      "x": -19,
      "y": 30,
      "z": -3,
      "name": "Rock_Ice"
    },
    {
      "x": -19,
      "y": 31,
      "z": -3,
      "name": "Rock_Ice"
    },
    {
      "x": -19,
      "y": 32,
      "z": -3,
      "name": "Rock_Ice"
    },
    {
      "x": -19,
      "y": 33,
      "z": -3,
      "name": "Rock_Ice"
    },
    {
      "x": -19,
      "y": 34,
      "z": -3,
      "name": "Rock_Ice"
    },
    {
      "x": -19,
      "y": 35,
      "z": -3,
      "name": "Rock_Ice"
    },
    {
      "x": -19,
      "y": 36,
      "z": -3,
      "name": "Rock_Ice"
    },
    {
      "x": -19,
      "y": 37,
      "z": -3,
      "name": "Rock_Ice"
    },
    {
      "x": -19,
      "y": 38,
      "z": -3,
      "name": "Rock_Ice"
    },
    {
      "x": -19,
      "y": 39,
      "z": -3,
      "name": "Rock_Ice"
    },
    {
      "x": -19,
      "y": 40,
      "z": -3,
      "name": "Rock_Ice_Permafrost"
    },
    {
      "x": -19,
      "y": 41,
      "z": -3,
      "name": "Rock_Ice_Permafrost"
    },
    {
      "x": -19,
      "y": 42,
      "z": -3,
      "name": "Rock_Ice"
    },
    {
      "x": -19,
      "y": 43,
      "z": -3,
      "name": "Rock_Ice"
    },
    {
      "x": -19,
      "y": 44,
      "z": -3,
      "name": "Rock_Ice"
    },
    {
      "x": -19,
      "y": 45,
      "z": -3,
      "name": "Rock_Ice"
    },
    {
      "x": -19,
      "y": 46,
      "z": -3,
      "name": "Rock_Ice"
    },
    {
      "x": -19,
      "y": 47,
      "z": -3,
      "name": "Rock_Ice"
    },
    {
      "x": -19,
      "y": 48,
      "z": -3,
      "name": "Rock_Ice"
    },
    {
      "x": -19,
      "y": 49,
      "z": -3,
      "name": "Rock_Ice"
    },
    {
      "x": -19,
      "y": 50,
      "z": -3,
      "name": "Rock_Ice"
    },
    {
      "x": -19,
      "y": 51,
      "z": -3,
      "name": "Rock_Ice"
    },
    {
      "x": -19,
      "y": 52,
      "z": -3,
      "name": "Rock_Ice"
    },
    {
      "x": -19,
      "y": 53,
      "z": -3,
      "name": "Rock_Ice"
    },
    {
      "x": -19,
      "y": 54,
      "z": -3,
      "name": "Rock_Ice"
    },
    {
      "x": -19,
      "y": 55,
      "z": -3,
      "name": "Rock_Ice"
    },
    {
      "x": -19,
      "y": 56,
      "z": -3,
      "name": "Rock_Ice"
    },
    {
      "x": -19,
      "y": 57,
      "z": -3,
      "name": "Rock_Ice"
    },
    {
      "x": -19,
      "y": 58,
      "z": -3,
      "name": "Rock_Ice"
    },
    {
      "x": -19,
      "y": 59,
      "z": -3,
      "name": "Rock_Ice"
    },
    {
      "x": -19,
      "y": 60,
      "z": -3,
      "name": "Rock_Ice"
    },
    {
      "x": -19,
      "y": 61,
      "z": -3,
      "name": "Rock_Ice"
    },
    {
      "x": -19,
      "y": 62,
      "z": -3,
      "name": "Rock_Ice"
    },
    {
      "x": -19,
      "y": 63,
      "z": -3,
      "name": "Rock_Ice"
    },
    {
      "x": -19,
      "y": 64,
      "z": -3,
      "name": "Rock_Ice"
    },
    {
      "x": -19,
      "y": 65,
      "z": -3,
      "name": "Rock_Ice"
    },
    {
      "x": -19,
      "y": 66,
      "z": -3,
      "name": "Soil_Snow"
    },
    {
      "x": -19,
      "y": 14,
      "z": -2,
      "name": "Rock_Ice_Permafrost"
    },
    {
      "x": -19,
      "y": 15,
      "z": -2,
      "name": "Rock_Ice"
    },
    {
      "x": -19,
      "y": 16,
      "z": -2,
      "name": "Rock_Ice"
    },
    {
      "x": -19,
      "y": 17,
      "z": -2,
      "name": "Rock_Ice"
    },
    {
      "x": -19,
      "y": 18,
      "z": -2,
      "name": "Rock_Ice"
    },
    {
      "x": -19,
      "y": 19,
      "z": -2,
      "name": "Rock_Ice"
    },
    {
      "x": -19,
      "y": 20,
      "z": -2,
      "name": "Rock_Ice"
    },
    {
      "x": -19,
      "y": 21,
      "z": -2,
      "name": "Rock_Ice"
    },
    {
      "x": -19,
      "y": 22,
      "z": -2,
      "name": "Rock_Ice"
    },
    {
      "x": -19,
      "y": 23,
      "z": -2,
      "name": "Rock_Ice"
    },
    {
      "x": -19,
      "y": 24,
      "z": -2,
      "name": "Rock_Ice"
    },
    {
      "x": -19,
      "y": 25,
      "z": -2,
      "name": "Rock_Ice"
    },
    {
      "x": -19,
      "y": 26,
      "z": -2,
      "name": "Rock_Ice"
    },
    {
      "x": -19,
      "y": 27,
      "z": -2,
      "name": "Rock_Ice"
    },
    {
      "x": -19,
      "y": 28,
      "z": -2,
      "name": "Rock_Ice"
    },
    {
      "x": -19,
      "y": 29,
      "z": -2,
      "name": "Rock_Ice"
    },
    {
      "x": -19,
      "y": 30,
      "z": -2,
      "name": "Rock_Ice"
    },
    {
      "x": -19,
      "y": 31,
      "z": -2,
      "name": "Rock_Ice"
    },
    {
      "x": -19,
      "y": 32,
      "z": -2,
      "name": "Rock_Ice"
    },
    {
      "x": -19,
      "y": 33,
      "z": -2,
      "name": "Rock_Ice"
    },
    {
      "x": -19,
      "y": 34,
      "z": -2,
      "name": "Rock_Ice"
    },
    {
      "x": -19,
      "y": 35,
      "z": -2,
      "name": "Rock_Ice"
    },
    {
      "x": -19,
      "y": 36,
      "z": -2,
      "name": "Rock_Ice"
    },
    {
      "x": -19,
      "y": 37,
      "z": -2,
      "name": "Rock_Ice"
    },
    {
      "x": -19,
      "y": 38,
      "z": -2,
      "name": "Rock_Ice"
    },
    {
      "x": -19,
      "y": 39,
      "z": -2,
      "name": "Rock_Ice"
    },
    {
      "x": -19,
      "y": 40,
      "z": -2,
      "name": "Rock_Ice"
    },
    {
      "x": -19,
      "y": 41,
      "z": -2,
      "name": "Rock_Ice_Permafrost"
    },
    {
      "x": -19,
      "y": 42,
      "z": -2,
      "name": "Rock_Ice"
    },
    {
      "x": -19,
      "y": 43,
      "z": -2,
      "name": "Rock_Ice"
    },
    {
      "x": -19,
      "y": 44,
      "z": -2,
      "name": "Rock_Ice"
    },
    {
      "x": -19,
      "y": 45,
      "z": -2,
      "name": "Rock_Ice"
    },
    {
      "x": -19,
      "y": 46,
      "z": -2,
      "name": "Rock_Ice"
    },
    {
      "x": -19,
      "y": 47,
      "z": -2,
      "name": "Rock_Ice"
    },
    {
      "x": -19,
      "y": 48,
      "z": -2,
      "name": "Rock_Ice"
    },
    {
      "x": -19,
      "y": 49,
      "z": -2,
      "name": "Rock_Ice"
    },
    {
      "x": -19,
      "y": 50,
      "z": -2,
      "name": "Rock_Ice"
    },
    {
      "x": -19,
      "y": 51,
      "z": -2,
      "name": "Rock_Ice"
    },
    {
      "x": -19,
      "y": 52,
      "z": -2,
      "name": "Rock_Ice"
    },
    {
      "x": -19,
      "y": 53,
      "z": -2,
      "name": "Rock_Ice"
    },
    {
      "x": -19,
      "y": 54,
      "z": -2,
      "name": "Rock_Ice"
    },
    {
      "x": -19,
      "y": 55,
      "z": -2,
      "name": "Rock_Ice"
    },
    {
      "x": -19,
      "y": 56,
      "z": -2,
      "name": "Rock_Ice"
    },
    {
      "x": -19,
      "y": 57,
      "z": -2,
      "name": "Rock_Ice"
    },
    {
      "x": -19,
      "y": 58,
      "z": -2,
      "name": "Rock_Ice"
    },
    {
      "x": -19,
      "y": 59,
      "z": -2,
      "name": "Rock_Ice"
    },
    {
      "x": -19,
      "y": 60,
      "z": -2,
      "name": "Rock_Ice"
    },
    {
      "x": -19,
      "y": 61,
      "z": -2,
      "name": "Rock_Ice"
    },
    {
      "x": -19,
      "y": 62,
      "z": -2,
      "name": "Rock_Ice"
    },
    {
      "x": -19,
      "y": 63,
      "z": -2,
      "name": "Rock_Ice"
    },
    {
      "x": -19,
      "y": 64,
      "z": -2,
      "name": "Soil_Snow"
    },
    {
      "x": -19,
      "y": 14,
      "z": -1,
      "name": "Rock_Ice"
    },
    {
      "x": -19,
      "y": 15,
      "z": -1,
      "name": "Rock_Ice"
    },
    {
      "x": -19,
      "y": 16,
      "z": -1,
      "name": "Rock_Ice"
    },
    {
      "x": -19,
      "y": 17,
      "z": -1,
      "name": "Rock_Ice"
    },
    {
      "x": -19,
      "y": 18,
      "z": -1,
      "name": "Rock_Ice"
    },
    {
      "x": -19,
      "y": 19,
      "z": -1,
      "name": "Rock_Ice"
    },
    {
      "x": -19,
      "y": 20,
      "z": -1,
      "name": "Rock_Ice"
    },
    {
      "x": -19,
      "y": 21,
      "z": -1,
      "name": "Rock_Ice"
    },
    {
      "x": -19,
      "y": 22,
      "z": -1,
      "name": "Rock_Ice"
    },
    {
      "x": -19,
      "y": 23,
      "z": -1,
      "name": "Rock_Ice"
    },
    {
      "x": -19,
      "y": 24,
      "z": -1,
      "name": "Rock_Ice"
    },
    {
      "x": -19,
      "y": 25,
      "z": -1,
      "name": "Rock_Ice"
    },
    {
      "x": -19,
      "y": 26,
      "z": -1,
      "name": "Rock_Ice"
    },
    {
      "x": -19,
      "y": 27,
      "z": -1,
      "name": "Rock_Ice"
    },
    {
      "x": -19,
      "y": 28,
      "z": -1,
      "name": "Rock_Ice"
    },
    {
      "x": -19,
      "y": 29,
      "z": -1,
      "name": "Rock_Ice"
    },
    {
      "x": -19,
      "y": 30,
      "z": -1,
      "name": "Rock_Ice"
    },
    {
      "x": -19,
      "y": 31,
      "z": -1,
      "name": "Rock_Ice"
    },
    {
      "x": -19,
      "y": 32,
      "z": -1,
      "name": "Rock_Ice"
    },
    {
      "x": -19,
      "y": 33,
      "z": -1,
      "name": "Rock_Ice"
    },
    {
      "x": -19,
      "y": 34,
      "z": -1,
      "name": "Rock_Ice"
    },
    {
      "x": -19,
      "y": 35,
      "z": -1,
      "name": "Rock_Ice"
    },
    {
      "x": -19,
      "y": 36,
      "z": -1,
      "name": "Rock_Ice"
    },
    {
      "x": -19,
      "y": 37,
      "z": -1,
      "name": "Rock_Ice"
    },
    {
      "x": -19,
      "y": 38,
      "z": -1,
      "name": "Rock_Ice"
    },
    {
      "x": -19,
      "y": 39,
      "z": -1,
      "name": "Rock_Ice"
    },
    {
      "x": -19,
      "y": 40,
      "z": -1,
      "name": "Rock_Ice_Permafrost"
    },
    {
      "x": -19,
      "y": 41,
      "z": -1,
      "name": "Rock_Ice"
    },
    {
      "x": -19,
      "y": 42,
      "z": -1,
      "name": "Rock_Ice"
    },
    {
      "x": -19,
      "y": 43,
      "z": -1,
      "name": "Rock_Ice"
    },
    {
      "x": -19,
      "y": 44,
      "z": -1,
      "name": "Rock_Ice"
    },
    {
      "x": -19,
      "y": 45,
      "z": -1,
      "name": "Rock_Ice"
    },
    {
      "x": -19,
      "y": 46,
      "z": -1,
      "name": "Rock_Ice"
    },
    {
      "x": -19,
      "y": 47,
      "z": -1,
      "name": "Rock_Ice"
    },
    {
      "x": -19,
      "y": 48,
      "z": -1,
      "name": "Rock_Ice"
    },
    {
      "x": -19,
      "y": 49,
      "z": -1,
      "name": "Rock_Ice"
    },
    {
      "x": -19,
      "y": 50,
      "z": -1,
      "name": "Rock_Ice"
    },
    {
      "x": -19,
      "y": 51,
      "z": -1,
      "name": "Rock_Ice"
    },
    {
      "x": -19,
      "y": 58,
      "z": -1,
      "name": "Rock_Ice"
    },
    {
      "x": -19,
      "y": 59,
      "z": -1,
      "name": "Rock_Ice"
    },
    {
      "x": -19,
      "y": 60,
      "z": -1,
      "name": "Rock_Ice"
    },
    {
      "x": -19,
      "y": 61,
      "z": -1,
      "name": "Rock_Ice"
    },
    {
      "x": -19,
      "y": 62,
      "z": -1,
      "name": "Soil_Snow"
    },
    {
      "x": -19,
      "y": 13,
      "z": 0,
      "name": "Rock_Ice"
    },
    {
      "x": -19,
      "y": 14,
      "z": 0,
      "name": "Rock_Ice"
    },
    {
      "x": -19,
      "y": 15,
      "z": 0,
      "name": "Rock_Ice"
    },
    {
      "x": -19,
      "y": 16,
      "z": 0,
      "name": "Rock_Ice"
    },
    {
      "x": -19,
      "y": 17,
      "z": 0,
      "name": "Rock_Ice"
    },
    {
      "x": -19,
      "y": 18,
      "z": 0,
      "name": "Rock_Ice"
    },
    {
      "x": -19,
      "y": 19,
      "z": 0,
      "name": "Rock_Ice"
    },
    {
      "x": -19,
      "y": 20,
      "z": 0,
      "name": "Rock_Ice"
    },
    {
      "x": -19,
      "y": 21,
      "z": 0,
      "name": "Rock_Ice"
    },
    {
      "x": -19,
      "y": 22,
      "z": 0,
      "name": "Rock_Ice"
    },
    {
      "x": -19,
      "y": 23,
      "z": 0,
      "name": "Rock_Ice"
    },
    {
      "x": -19,
      "y": 24,
      "z": 0,
      "name": "Rock_Ice"
    },
    {
      "x": -19,
      "y": 25,
      "z": 0,
      "name": "Rock_Ice"
    },
    {
      "x": -19,
      "y": 26,
      "z": 0,
      "name": "Rock_Ice"
    },
    {
      "x": -19,
      "y": 27,
      "z": 0,
      "name": "Rock_Ice"
    },
    {
      "x": -19,
      "y": 28,
      "z": 0,
      "name": "Rock_Ice"
    },
    {
      "x": -19,
      "y": 29,
      "z": 0,
      "name": "Rock_Ice"
    },
    {
      "x": -19,
      "y": 30,
      "z": 0,
      "name": "Rock_Ice"
    },
    {
      "x": -19,
      "y": 31,
      "z": 0,
      "name": "Rock_Ice"
    },
    {
      "x": -19,
      "y": 32,
      "z": 0,
      "name": "Rock_Ice"
    },
    {
      "x": -19,
      "y": 33,
      "z": 0,
      "name": "Rock_Ice"
    },
    {
      "x": -19,
      "y": 34,
      "z": 0,
      "name": "Rock_Ice"
    },
    {
      "x": -19,
      "y": 35,
      "z": 0,
      "name": "Rock_Ice"
    },
    {
      "x": -19,
      "y": 36,
      "z": 0,
      "name": "Rock_Ice"
    },
    {
      "x": -19,
      "y": 37,
      "z": 0,
      "name": "Rock_Ice"
    },
    {
      "x": -19,
      "y": 38,
      "z": 0,
      "name": "Rock_Ice"
    },
    {
      "x": -19,
      "y": 39,
      "z": 0,
      "name": "Rock_Ice"
    },
    {
      "x": -19,
      "y": 40,
      "z": 0,
      "name": "Rock_Ice"
    },
    {
      "x": -19,
      "y": 41,
      "z": 0,
      "name": "Rock_Ice"
    },
    {
      "x": -19,
      "y": 42,
      "z": 0,
      "name": "Rock_Ice"
    },
    {
      "x": -19,
      "y": 43,
      "z": 0,
      "name": "Rock_Ice"
    },
    {
      "x": -19,
      "y": 44,
      "z": 0,
      "name": "Rock_Ice"
    },
    {
      "x": -19,
      "y": 45,
      "z": 0,
      "name": "Rock_Ice"
    },
    {
      "x": -19,
      "y": 46,
      "z": 0,
      "name": "Rock_Ice"
    },
    {
      "x": -19,
      "y": 47,
      "z": 0,
      "name": "Rock_Ice"
    },
    {
      "x": -19,
      "y": 61,
      "z": 0,
      "name": "Rock_Ice"
    },
    {
      "x": -19,
      "y": 62,
      "z": 0,
      "name": "Soil_Snow"
    },
    {
      "x": -19,
      "y": 13,
      "z": 1,
      "name": "Rock_Ice"
    },
    {
      "x": -19,
      "y": 14,
      "z": 1,
      "name": "Rock_Ice"
    },
    {
      "x": -19,
      "y": 15,
      "z": 1,
      "name": "Rock_Ice"
    },
    {
      "x": -19,
      "y": 16,
      "z": 1,
      "name": "Rock_Ice"
    },
    {
      "x": -19,
      "y": 17,
      "z": 1,
      "name": "Rock_Ice"
    },
    {
      "x": -19,
      "y": 18,
      "z": 1,
      "name": "Rock_Ice"
    },
    {
      "x": -19,
      "y": 19,
      "z": 1,
      "name": "Rock_Ice"
    },
    {
      "x": -19,
      "y": 20,
      "z": 1,
      "name": "Rock_Ice"
    },
    {
      "x": -19,
      "y": 21,
      "z": 1,
      "name": "Rock_Ice"
    },
    {
      "x": -19,
      "y": 22,
      "z": 1,
      "name": "Rock_Ice"
    },
    {
      "x": -19,
      "y": 23,
      "z": 1,
      "name": "Rock_Ice"
    },
    {
      "x": -19,
      "y": 24,
      "z": 1,
      "name": "Rock_Ice"
    },
    {
      "x": -19,
      "y": 25,
      "z": 1,
      "name": "Rock_Ice"
    },
    {
      "x": -19,
      "y": 27,
      "z": 1,
      "name": "Rock_Ice"
    },
    {
      "x": -19,
      "y": 28,
      "z": 1,
      "name": "Rock_Ice"
    },
    {
      "x": -19,
      "y": 29,
      "z": 1,
      "name": "Rock_Ice"
    },
    {
      "x": -19,
      "y": 30,
      "z": 1,
      "name": "Rock_Ice"
    },
    {
      "x": -19,
      "y": 31,
      "z": 1,
      "name": "Rock_Ice"
    },
    {
      "x": -19,
      "y": 32,
      "z": 1,
      "name": "Rock_Ice"
    },
    {
      "x": -19,
      "y": 33,
      "z": 1,
      "name": "Rock_Ice"
    },
    {
      "x": -19,
      "y": 34,
      "z": 1,
      "name": "Rock_Ice"
    },
    {
      "x": -19,
      "y": 35,
      "z": 1,
      "name": "Rock_Ice"
    },
    {
      "x": -19,
      "y": 36,
      "z": 1,
      "name": "Rock_Ice"
    },
    {
      "x": -19,
      "y": 37,
      "z": 1,
      "name": "Rock_Ice"
    },
    {
      "x": -19,
      "y": 38,
      "z": 1,
      "name": "Rock_Ice"
    },
    {
      "x": -19,
      "y": 39,
      "z": 1,
      "name": "Rock_Ice_Permafrost"
    },
    {
      "x": -19,
      "y": 40,
      "z": 1,
      "name": "Rock_Ice"
    },
    {
      "x": -19,
      "y": 41,
      "z": 1,
      "name": "Rock_Ice"
    },
    {
      "x": -19,
      "y": 42,
      "z": 1,
      "name": "Rock_Ice"
    },
    {
      "x": -19,
      "y": 43,
      "z": 1,
      "name": "Rock_Ice"
    },
    {
      "x": -19,
      "y": 44,
      "z": 1,
      "name": "Soil_Snow"
    },
    {
      "x": -19,
      "y": 14,
      "z": 2,
      "name": "Rock_Ice_Permafrost"
    },
    {
      "x": -19,
      "y": 15,
      "z": 2,
      "name": "Rock_Ice_Permafrost"
    },
    {
      "x": -19,
      "y": 16,
      "z": 2,
      "name": "Rock_Ice"
    },
    {
      "x": -19,
      "y": 17,
      "z": 2,
      "name": "Rock_Ice"
    },
    {
      "x": -19,
      "y": 18,
      "z": 2,
      "name": "Rock_Ice_Permafrost"
    },
    {
      "x": -19,
      "y": 19,
      "z": 2,
      "name": "Rock_Ice"
    },
    {
      "x": -19,
      "y": 20,
      "z": 2,
      "name": "Rock_Ice"
    },
    {
      "x": -19,
      "y": 21,
      "z": 2,
      "name": "Rock_Ice"
    },
    {
      "x": -19,
      "y": 22,
      "z": 2,
      "name": "Rock_Ice"
    },
    {
      "x": -19,
      "y": 23,
      "z": 2,
      "name": "Rock_Ice"
    },
    {
      "x": -19,
      "y": 24,
      "z": 2,
      "name": "Rock_Ice"
    },
    {
      "x": -19,
      "y": 25,
      "z": 2,
      "name": "Rock_Ice"
    },
    {
      "x": -19,
      "y": 28,
      "z": 2,
      "name": "Rock_Ice"
    },
    {
      "x": -19,
      "y": 29,
      "z": 2,
      "name": "Rock_Ice"
    },
    {
      "x": -19,
      "y": 30,
      "z": 2,
      "name": "Rock_Ice"
    },
    {
      "x": -19,
      "y": 31,
      "z": 2,
      "name": "Rock_Ice"
    },
    {
      "x": -19,
      "y": 32,
      "z": 2,
      "name": "Rock_Ice"
    },
    {
      "x": -19,
      "y": 33,
      "z": 2,
      "name": "Rock_Ice"
    },
    {
      "x": -19,
      "y": 34,
      "z": 2,
      "name": "Rock_Ice"
    },
    {
      "x": -19,
      "y": 35,
      "z": 2,
      "name": "Rock_Ice"
    },
    {
      "x": -19,
      "y": 36,
      "z": 2,
      "name": "Rock_Ice"
    },
    {
      "x": -19,
      "y": 37,
      "z": 2,
      "name": "Rock_Ice"
    },
    {
      "x": -19,
      "y": 38,
      "z": 2,
      "name": "Rock_Ice"
    },
    {
      "x": -19,
      "y": 39,
      "z": 2,
      "name": "Rock_Ice_Permafrost"
    },
    {
      "x": -19,
      "y": 40,
      "z": 2,
      "name": "Rock_Ice_Permafrost"
    },
    {
      "x": -19,
      "y": 41,
      "z": 2,
      "name": "Rock_Ice"
    },
    {
      "x": -19,
      "y": 42,
      "z": 2,
      "name": "Rock_Ice_Permafrost"
    },
    {
      "x": -19,
      "y": 43,
      "z": 2,
      "name": "Soil_Snow"
    },
    {
      "x": -19,
      "y": 14,
      "z": 3,
      "name": "Rock_Ice_Permafrost"
    },
    {
      "x": -19,
      "y": 15,
      "z": 3,
      "name": "Rock_Ice_Permafrost"
    },
    {
      "x": -19,
      "y": 16,
      "z": 3,
      "name": "Rock_Ice_Permafrost"
    },
    {
      "x": -19,
      "y": 17,
      "z": 3,
      "name": "Rock_Ice_Permafrost"
    },
    {
      "x": -19,
      "y": 18,
      "z": 3,
      "name": "Rock_Crystal_Cyan_Block_WhiteLight"
    },
    {
      "x": -19,
      "y": 19,
      "z": 3,
      "name": "Rock_Ice_Permafrost"
    },
    {
      "x": -19,
      "y": 20,
      "z": 3,
      "name": "Rock_Ice_Permafrost"
    },
    {
      "x": -19,
      "y": 21,
      "z": 3,
      "name": "Rock_Ice_Permafrost"
    },
    {
      "x": -19,
      "y": 22,
      "z": 3,
      "name": "Rock_Ice_Permafrost"
    },
    {
      "x": -19,
      "y": 23,
      "z": 3,
      "name": "Rock_Ice"
    },
    {
      "x": -19,
      "y": 24,
      "z": 3,
      "name": "Rock_Ice"
    },
    {
      "x": -19,
      "y": 31,
      "z": 3,
      "name": "Rock_Ice"
    },
    {
      "x": -19,
      "y": 32,
      "z": 3,
      "name": "Rock_Ice"
    },
    {
      "x": -19,
      "y": 33,
      "z": 3,
      "name": "Rock_Ice"
    },
    {
      "x": -19,
      "y": 34,
      "z": 3,
      "name": "Rock_Ice"
    },
    {
      "x": -19,
      "y": 35,
      "z": 3,
      "name": "Rock_Ice"
    },
    {
      "x": -19,
      "y": 36,
      "z": 3,
      "name": "Rock_Ice"
    },
    {
      "x": -19,
      "y": 37,
      "z": 3,
      "name": "Soil_Snow"
    },
    {
      "x": -19,
      "y": 15,
      "z": 4,
      "name": "Rock_Ice_Permafrost"
    },
    {
      "x": -19,
      "y": 16,
      "z": 4,
      "name": "Rock_Ice_Permafrost"
    },
    {
      "x": -19,
      "y": 17,
      "z": 4,
      "name": "Rock_Ice_Permafrost"
    },
    {
      "x": -19,
      "y": 18,
      "z": 4,
      "name": "Rock_Ice_Permafrost"
    },
    {
      "x": -19,
      "y": 19,
      "z": 4,
      "name": "Rock_Ice_Permafrost"
    },
    {
      "x": -19,
      "y": 20,
      "z": 4,
      "name": "Rock_Ice_Permafrost"
    },
    {
      "x": -19,
      "y": 21,
      "z": 4,
      "name": "Rock_Ice_Permafrost"
    },
    {
      "x": -19,
      "y": 22,
      "z": 4,
      "name": "Rock_Ice_Permafrost"
    },
    {
      "x": -19,
      "y": 23,
      "z": 4,
      "name": "Soil_Snow"
    },
    {
      "x": -19,
      "y": 17,
      "z": 5,
      "name": "Rock_Ice_Permafrost"
    },
    {
      "x": -19,
      "y": 18,
      "z": 5,
      "name": "Rock_Ice_Permafrost"
    },
    {
      "x": -19,
      "y": 19,
      "z": 5,
      "name": "Rock_Ice"
    },
    {
      "x": -19,
      "y": 20,
      "z": 5,
      "name": "Rock_Ice"
    },
    {
      "x": -19,
      "y": 21,
      "z": 5,
      "name": "Rock_Ice_Permafrost"
    },
    {
      "x": -19,
      "y": 22,
      "z": 5,
      "name": "Soil_Snow"
    },
    {
      "x": -18,
      "y": 45,
      "z": -16,
      "name": "Rock_Ice"
    },
    {
      "x": -18,
      "y": 46,
      "z": -16,
      "name": "Rock_Ice"
    },
    {
      "x": -18,
      "y": 47,
      "z": -16,
      "name": "Rock_Ice"
    },
    {
      "x": -18,
      "y": 48,
      "z": -16,
      "name": "Soil_Snow"
    },
    {
      "x": -18,
      "y": 42,
      "z": -15,
      "name": "Rock_Ice"
    },
    {
      "x": -18,
      "y": 43,
      "z": -15,
      "name": "Rock_Ice"
    },
    {
      "x": -18,
      "y": 44,
      "z": -15,
      "name": "Rock_Ice"
    },
    {
      "x": -18,
      "y": 45,
      "z": -15,
      "name": "Rock_Ice"
    },
    {
      "x": -18,
      "y": 46,
      "z": -15,
      "name": "Rock_Ice"
    },
    {
      "x": -18,
      "y": 47,
      "z": -15,
      "name": "Rock_Ice"
    },
    {
      "x": -18,
      "y": 48,
      "z": -15,
      "name": "Rock_Ice"
    },
    {
      "x": -18,
      "y": 49,
      "z": -15,
      "name": "Soil_Snow"
    },
    {
      "x": -18,
      "y": 40,
      "z": -14,
      "name": "Rock_Ice_Permafrost"
    },
    {
      "x": -18,
      "y": 41,
      "z": -14,
      "name": "Rock_Ice"
    },
    {
      "x": -18,
      "y": 42,
      "z": -14,
      "name": "Rock_Ice"
    },
    {
      "x": -18,
      "y": 43,
      "z": -14,
      "name": "Rock_Ice"
    },
    {
      "x": -18,
      "y": 44,
      "z": -14,
      "name": "Rock_Ice"
    },
    {
      "x": -18,
      "y": 45,
      "z": -14,
      "name": "Rock_Ice"
    },
    {
      "x": -18,
      "y": 46,
      "z": -14,
      "name": "Rock_Ice"
    },
    {
      "x": -18,
      "y": 47,
      "z": -14,
      "name": "Rock_Ice"
    },
    {
      "x": -18,
      "y": 48,
      "z": -14,
      "name": "Rock_Ice"
    },
    {
      "x": -18,
      "y": 49,
      "z": -14,
      "name": "Rock_Ice"
    },
    {
      "x": -18,
      "y": 50,
      "z": -14,
      "name": "Soil_Snow"
    },
    {
      "x": -18,
      "y": 36,
      "z": -13,
      "name": "Rock_Ice_Permafrost"
    },
    {
      "x": -18,
      "y": 37,
      "z": -13,
      "name": "Rock_Ice_Permafrost"
    },
    {
      "x": -18,
      "y": 38,
      "z": -13,
      "name": "Rock_Ice_Permafrost"
    },
    {
      "x": -18,
      "y": 39,
      "z": -13,
      "name": "Rock_Ice_Permafrost"
    },
    {
      "x": -18,
      "y": 40,
      "z": -13,
      "name": "Rock_Ice"
    },
    {
      "x": -18,
      "y": 41,
      "z": -13,
      "name": "Rock_Ice"
    },
    {
      "x": -18,
      "y": 42,
      "z": -13,
      "name": "Rock_Ice"
    },
    {
      "x": -18,
      "y": 43,
      "z": -13,
      "name": "Rock_Ice"
    },
    {
      "x": -18,
      "y": 44,
      "z": -13,
      "name": "Rock_Ice"
    },
    {
      "x": -18,
      "y": 45,
      "z": -13,
      "name": "Rock_Ice"
    },
    {
      "x": -18,
      "y": 46,
      "z": -13,
      "name": "Rock_Ice"
    },
    {
      "x": -18,
      "y": 47,
      "z": -13,
      "name": "Rock_Ice"
    },
    {
      "x": -18,
      "y": 48,
      "z": -13,
      "name": "Rock_Ice"
    },
    {
      "x": -18,
      "y": 49,
      "z": -13,
      "name": "Rock_Ice"
    },
    {
      "x": -18,
      "y": 50,
      "z": -13,
      "name": "Rock_Ice"
    },
    {
      "x": -18,
      "y": 51,
      "z": -13,
      "name": "Rock_Ice"
    },
    {
      "x": -18,
      "y": 52,
      "z": -13,
      "name": "Rock_Ice"
    },
    {
      "x": -18,
      "y": 53,
      "z": -13,
      "name": "Soil_Snow"
    },
    {
      "x": -18,
      "y": 36,
      "z": -12,
      "name": "Rock_Ice_Permafrost"
    },
    {
      "x": -18,
      "y": 37,
      "z": -12,
      "name": "Rock_Crystal_Cyan_Block_WhiteLight"
    },
    {
      "x": -18,
      "y": 38,
      "z": -12,
      "name": "Rock_Crystal_Cyan_Block_WhiteLight"
    },
    {
      "x": -18,
      "y": 39,
      "z": -12,
      "name": "Rock_Ice_Permafrost"
    },
    {
      "x": -18,
      "y": 40,
      "z": -12,
      "name": "Rock_Ice_Permafrost"
    },
    {
      "x": -18,
      "y": 41,
      "z": -12,
      "name": "Rock_Ice"
    },
    {
      "x": -18,
      "y": 42,
      "z": -12,
      "name": "Rock_Ice"
    },
    {
      "x": -18,
      "y": 43,
      "z": -12,
      "name": "Rock_Ice"
    },
    {
      "x": -18,
      "y": 44,
      "z": -12,
      "name": "Rock_Ice"
    },
    {
      "x": -18,
      "y": 45,
      "z": -12,
      "name": "Rock_Ice"
    },
    {
      "x": -18,
      "y": 46,
      "z": -12,
      "name": "Rock_Ice"
    },
    {
      "x": -18,
      "y": 47,
      "z": -12,
      "name": "Rock_Ice"
    },
    {
      "x": -18,
      "y": 48,
      "z": -12,
      "name": "Rock_Ice"
    },
    {
      "x": -18,
      "y": 49,
      "z": -12,
      "name": "Rock_Ice"
    },
    {
      "x": -18,
      "y": 50,
      "z": -12,
      "name": "Rock_Ice"
    },
    {
      "x": -18,
      "y": 51,
      "z": -12,
      "name": "Rock_Ice"
    },
    {
      "x": -18,
      "y": 52,
      "z": -12,
      "name": "Rock_Ice"
    },
    {
      "x": -18,
      "y": 53,
      "z": -12,
      "name": "Rock_Ice_Permafrost"
    },
    {
      "x": -18,
      "y": 54,
      "z": -12,
      "name": "Rock_Ice"
    },
    {
      "x": -18,
      "y": 55,
      "z": -12,
      "name": "Soil_Snow"
    },
    {
      "x": -18,
      "y": 36,
      "z": -11,
      "name": "Rock_Ice_Permafrost"
    },
    {
      "x": -18,
      "y": 37,
      "z": -11,
      "name": "Rock_Ice_Permafrost"
    },
    {
      "x": -18,
      "y": 38,
      "z": -11,
      "name": "Rock_Ice_Permafrost"
    },
    {
      "x": -18,
      "y": 39,
      "z": -11,
      "name": "Rock_Ice_Permafrost"
    },
    {
      "x": -18,
      "y": 40,
      "z": -11,
      "name": "Rock_Ice_Permafrost"
    },
    {
      "x": -18,
      "y": 41,
      "z": -11,
      "name": "Rock_Ice"
    },
    {
      "x": -18,
      "y": 42,
      "z": -11,
      "name": "Rock_Ice"
    },
    {
      "x": -18,
      "y": 43,
      "z": -11,
      "name": "Rock_Ice"
    },
    {
      "x": -18,
      "y": 44,
      "z": -11,
      "name": "Rock_Ice"
    },
    {
      "x": -18,
      "y": 45,
      "z": -11,
      "name": "Rock_Ice"
    },
    {
      "x": -18,
      "y": 46,
      "z": -11,
      "name": "Rock_Ice"
    },
    {
      "x": -18,
      "y": 47,
      "z": -11,
      "name": "Rock_Ice"
    },
    {
      "x": -18,
      "y": 48,
      "z": -11,
      "name": "Rock_Ice"
    },
    {
      "x": -18,
      "y": 49,
      "z": -11,
      "name": "Rock_Ice"
    },
    {
      "x": -18,
      "y": 50,
      "z": -11,
      "name": "Rock_Ice"
    },
    {
      "x": -18,
      "y": 51,
      "z": -11,
      "name": "Rock_Ice_Permafrost"
    },
    {
      "x": -18,
      "y": 52,
      "z": -11,
      "name": "Rock_Ice_Permafrost"
    },
    {
      "x": -18,
      "y": 53,
      "z": -11,
      "name": "Rock_Crystal_Cyan_Block_WhiteLight"
    },
    {
      "x": -18,
      "y": 54,
      "z": -11,
      "name": "Rock_Crystal_Cyan_Block_WhiteLight"
    },
    {
      "x": -18,
      "y": 55,
      "z": -11,
      "name": "Rock_Ice_Permafrost"
    },
    {
      "x": -18,
      "y": 56,
      "z": -11,
      "name": "Rock_Ice"
    },
    {
      "x": -18,
      "y": 57,
      "z": -11,
      "name": "Soil_Snow"
    },
    {
      "x": -18,
      "y": 19,
      "z": -10,
      "name": "Rock_Ice_Permafrost"
    },
    {
      "x": -18,
      "y": 20,
      "z": -10,
      "name": "Rock_Ice_Permafrost"
    },
    {
      "x": -18,
      "y": 21,
      "z": -10,
      "name": "Rock_Ice_Permafrost"
    },
    {
      "x": -18,
      "y": 34,
      "z": -10,
      "name": "Rock_Ice_Permafrost"
    },
    {
      "x": -18,
      "y": 35,
      "z": -10,
      "name": "Rock_Ice_Permafrost"
    },
    {
      "x": -18,
      "y": 36,
      "z": -10,
      "name": "Rock_Ice_Permafrost"
    },
    {
      "x": -18,
      "y": 37,
      "z": -10,
      "name": "Rock_Crystal_Cyan_Block_WhiteLight"
    },
    {
      "x": -18,
      "y": 38,
      "z": -10,
      "name": "Rock_Ice_Permafrost"
    },
    {
      "x": -18,
      "y": 39,
      "z": -10,
      "name": "Rock_Ice_Permafrost"
    },
    {
      "x": -18,
      "y": 40,
      "z": -10,
      "name": "Rock_Crystal_Cyan_Block_WhiteLight"
    },
    {
      "x": -18,
      "y": 41,
      "z": -10,
      "name": "Rock_Ice_Permafrost"
    },
    {
      "x": -18,
      "y": 42,
      "z": -10,
      "name": "Rock_Ice"
    },
    {
      "x": -18,
      "y": 43,
      "z": -10,
      "name": "Rock_Ice"
    },
    {
      "x": -18,
      "y": 44,
      "z": -10,
      "name": "Rock_Ice"
    },
    {
      "x": -18,
      "y": 45,
      "z": -10,
      "name": "Rock_Ice"
    },
    {
      "x": -18,
      "y": 46,
      "z": -10,
      "name": "Rock_Ice"
    },
    {
      "x": -18,
      "y": 47,
      "z": -10,
      "name": "Rock_Ice"
    },
    {
      "x": -18,
      "y": 48,
      "z": -10,
      "name": "Rock_Ice"
    },
    {
      "x": -18,
      "y": 49,
      "z": -10,
      "name": "Rock_Ice_Permafrost"
    },
    {
      "x": -18,
      "y": 50,
      "z": -10,
      "name": "Rock_Ice_Permafrost"
    },
    {
      "x": -18,
      "y": 51,
      "z": -10,
      "name": "Rock_Ice_Permafrost"
    },
    {
      "x": -18,
      "y": 52,
      "z": -10,
      "name": "Rock_Ice_Permafrost"
    },
    {
      "x": -18,
      "y": 53,
      "z": -10,
      "name": "Rock_Ice_Permafrost"
    },
    {
      "x": -18,
      "y": 54,
      "z": -10,
      "name": "Rock_Ice_Permafrost"
    },
    {
      "x": -18,
      "y": 55,
      "z": -10,
      "name": "Rock_Ice"
    },
    {
      "x": -18,
      "y": 56,
      "z": -10,
      "name": "Rock_Ice"
    },
    {
      "x": -18,
      "y": 57,
      "z": -10,
      "name": "Rock_Ice"
    },
    {
      "x": -18,
      "y": 58,
      "z": -10,
      "name": "Soil_Snow"
    },
    {
      "x": -18,
      "y": 17,
      "z": -9,
      "name": "Rock_Ice_Permafrost"
    },
    {
      "x": -18,
      "y": 18,
      "z": -9,
      "name": "Rock_Ice_Permafrost"
    },
    {
      "x": -18,
      "y": 19,
      "z": -9,
      "name": "Rock_Ice_Permafrost"
    },
    {
      "x": -18,
      "y": 20,
      "z": -9,
      "name": "Rock_Crystal_Cyan_Block_WhiteLight"
    },
    {
      "x": -18,
      "y": 21,
      "z": -9,
      "name": "Rock_Ice_Permafrost"
    },
    {
      "x": -18,
      "y": 22,
      "z": -9,
      "name": "Rock_Ice_Permafrost"
    },
    {
      "x": -18,
      "y": 23,
      "z": -9,
      "name": "Rock_Crystal_Cyan_Block_WhiteLight"
    },
    {
      "x": -18,
      "y": 24,
      "z": -9,
      "name": "Rock_Ice_Permafrost"
    },
    {
      "x": -18,
      "y": 25,
      "z": -9,
      "name": "Rock_Ice_Permafrost"
    },
    {
      "x": -18,
      "y": 32,
      "z": -9,
      "name": "Rock_Ice"
    },
    {
      "x": -18,
      "y": 33,
      "z": -9,
      "name": "Rock_Ice"
    },
    {
      "x": -18,
      "y": 34,
      "z": -9,
      "name": "Rock_Ice"
    },
    {
      "x": -18,
      "y": 35,
      "z": -9,
      "name": "Rock_Ice"
    },
    {
      "x": -18,
      "y": 36,
      "z": -9,
      "name": "Rock_Ice_Permafrost"
    },
    {
      "x": -18,
      "y": 37,
      "z": -9,
      "name": "Rock_Ice_Permafrost"
    },
    {
      "x": -18,
      "y": 38,
      "z": -9,
      "name": "Rock_Crystal_Cyan_Block_WhiteLight"
    },
    {
      "x": -18,
      "y": 39,
      "z": -9,
      "name": "Rock_Crystal_Cyan_Block_WhiteLight"
    },
    {
      "x": -18,
      "y": 40,
      "z": -9,
      "name": "Rock_Crystal_Cyan_Block_WhiteLight"
    },
    {
      "x": -18,
      "y": 41,
      "z": -9,
      "name": "Rock_Ice_Permafrost"
    },
    {
      "x": -18,
      "y": 42,
      "z": -9,
      "name": "Rock_Ice_Permafrost"
    },
    {
      "x": -18,
      "y": 43,
      "z": -9,
      "name": "Rock_Ice_Permafrost"
    },
    {
      "x": -18,
      "y": 44,
      "z": -9,
      "name": "Rock_Ice_Permafrost"
    },
    {
      "x": -18,
      "y": 45,
      "z": -9,
      "name": "Rock_Ice_Permafrost"
    },
    {
      "x": -18,
      "y": 46,
      "z": -9,
      "name": "Rock_Ice"
    },
    {
      "x": -18,
      "y": 47,
      "z": -9,
      "name": "Rock_Ice"
    },
    {
      "x": -18,
      "y": 48,
      "z": -9,
      "name": "Rock_Ice_Permafrost"
    },
    {
      "x": -18,
      "y": 49,
      "z": -9,
      "name": "Rock_Ice_Permafrost"
    },
    {
      "x": -18,
      "y": 50,
      "z": -9,
      "name": "Rock_Ice_Permafrost"
    },
    {
      "x": -18,
      "y": 51,
      "z": -9,
      "name": "Rock_Ice_Permafrost"
    },
    {
      "x": -18,
      "y": 52,
      "z": -9,
      "name": "Rock_Ice_Permafrost"
    },
    {
      "x": -18,
      "y": 53,
      "z": -9,
      "name": "Rock_Ice_Permafrost"
    },
    {
      "x": -18,
      "y": 54,
      "z": -9,
      "name": "Rock_Ice"
    },
    {
      "x": -18,
      "y": 55,
      "z": -9,
      "name": "Rock_Ice"
    },
    {
      "x": -18,
      "y": 56,
      "z": -9,
      "name": "Rock_Ice"
    },
    {
      "x": -18,
      "y": 57,
      "z": -9,
      "name": "Rock_Ice"
    },
    {
      "x": -18,
      "y": 58,
      "z": -9,
      "name": "Rock_Ice"
    },
    {
      "x": -18,
      "y": 59,
      "z": -9,
      "name": "Rock_Ice"
    },
    {
      "x": -18,
      "y": 60,
      "z": -9,
      "name": "Rock_Ice"
    },
    {
      "x": -18,
      "y": 16,
      "z": -8,
      "name": "Rock_Ice_Permafrost"
    },
    {
      "x": -18,
      "y": 17,
      "z": -8,
      "name": "Rock_Ice_Permafrost"
    },
    {
      "x": -18,
      "y": 18,
      "z": -8,
      "name": "Rock_Ice_Permafrost"
    },
    {
      "x": -18,
      "y": 19,
      "z": -8,
      "name": "Rock_Ice_Permafrost"
    },
    {
      "x": -18,
      "y": 20,
      "z": -8,
      "name": "Rock_Crystal_Cyan_Block_WhiteLight"
    },
    {
      "x": -18,
      "y": 21,
      "z": -8,
      "name": "Rock_Ice_Permafrost"
    },
    {
      "x": -18,
      "y": 22,
      "z": -8,
      "name": "Rock_Ice_Permafrost"
    },
    {
      "x": -18,
      "y": 23,
      "z": -8,
      "name": "Rock_Ice_Permafrost"
    },
    {
      "x": -18,
      "y": 24,
      "z": -8,
      "name": "Rock_Ice_Permafrost"
    },
    {
      "x": -18,
      "y": 25,
      "z": -8,
      "name": "Rock_Ice_Permafrost"
    },
    {
      "x": -18,
      "y": 26,
      "z": -8,
      "name": "Rock_Ice_Permafrost"
    },
    {
      "x": -18,
      "y": 29,
      "z": -8,
      "name": "Rock_Ice"
    },
    {
      "x": -18,
      "y": 30,
      "z": -8,
      "name": "Rock_Ice"
    },
    {
      "x": -18,
      "y": 31,
      "z": -8,
      "name": "Rock_Ice_Permafrost"
    },
    {
      "x": -18,
      "y": 32,
      "z": -8,
      "name": "Rock_Ice"
    },
    {
      "x": -18,
      "y": 33,
      "z": -8,
      "name": "Rock_Ice"
    },
    {
      "x": -18,
      "y": 34,
      "z": -8,
      "name": "Rock_Ice"
    },
    {
      "x": -18,
      "y": 35,
      "z": -8,
      "name": "Rock_Ice"
    },
    {
      "x": -18,
      "y": 36,
      "z": -8,
      "name": "Rock_Ice_Permafrost"
    },
    {
      "x": -18,
      "y": 37,
      "z": -8,
      "name": "Rock_Ice_Permafrost"
    },
    {
      "x": -18,
      "y": 38,
      "z": -8,
      "name": "Rock_Ice_Permafrost"
    },
    {
      "x": -18,
      "y": 39,
      "z": -8,
      "name": "Rock_Ice_Permafrost"
    },
    {
      "x": -18,
      "y": 40,
      "z": -8,
      "name": "Rock_Ice_Permafrost"
    },
    {
      "x": -18,
      "y": 41,
      "z": -8,
      "name": "Rock_Ice_Permafrost"
    },
    {
      "x": -18,
      "y": 42,
      "z": -8,
      "name": "Rock_Ice_Permafrost"
    },
    {
      "x": -18,
      "y": 43,
      "z": -8,
      "name": "Rock_Ice_Permafrost"
    },
    {
      "x": -18,
      "y": 44,
      "z": -8,
      "name": "Rock_Ice"
    },
    {
      "x": -18,
      "y": 45,
      "z": -8,
      "name": "Rock_Ice_Permafrost"
    },
    {
      "x": -18,
      "y": 46,
      "z": -8,
      "name": "Rock_Ice_Permafrost"
    },
    {
      "x": -18,
      "y": 47,
      "z": -8,
      "name": "Rock_Ice_Permafrost"
    },
    {
      "x": -18,
      "y": 48,
      "z": -8,
      "name": "Rock_Ice_Permafrost"
    },
    {
      "x": -18,
      "y": 49,
      "z": -8,
      "name": "Rock_Ice_Permafrost"
    },
    {
      "x": -18,
      "y": 50,
      "z": -8,
      "name": "Rock_Crystal_Cyan_Block_WhiteLight"
    },
    {
      "x": -18,
      "y": 51,
      "z": -8,
      "name": "Rock_Ice_Permafrost"
    },
    {
      "x": -18,
      "y": 52,
      "z": -8,
      "name": "Rock_Ice"
    },
    {
      "x": -18,
      "y": 53,
      "z": -8,
      "name": "Rock_Ice"
    },
    {
      "x": -18,
      "y": 54,
      "z": -8,
      "name": "Rock_Ice"
    },
    {
      "x": -18,
      "y": 55,
      "z": -8,
      "name": "Rock_Ice"
    },
    {
      "x": -18,
      "y": 56,
      "z": -8,
      "name": "Rock_Ice"
    },
    {
      "x": -18,
      "y": 57,
      "z": -8,
      "name": "Rock_Ice"
    },
    {
      "x": -18,
      "y": 58,
      "z": -8,
      "name": "Rock_Ice"
    },
    {
      "x": -18,
      "y": 59,
      "z": -8,
      "name": "Rock_Ice"
    },
    {
      "x": -18,
      "y": 60,
      "z": -8,
      "name": "Rock_Ice"
    },
    {
      "x": -18,
      "y": 61,
      "z": -8,
      "name": "Rock_Ice"
    },
    {
      "x": -18,
      "y": 15,
      "z": -7,
      "name": "Rock_Ice"
    },
    {
      "x": -18,
      "y": 16,
      "z": -7,
      "name": "Rock_Ice"
    },
    {
      "x": -18,
      "y": 17,
      "z": -7,
      "name": "Rock_Ice_Permafrost"
    },
    {
      "x": -18,
      "y": 18,
      "z": -7,
      "name": "Rock_Ice_Permafrost"
    },
    {
      "x": -18,
      "y": 19,
      "z": -7,
      "name": "Rock_Ice"
    },
    {
      "x": -18,
      "y": 20,
      "z": -7,
      "name": "Rock_Ice"
    },
    {
      "x": -18,
      "y": 21,
      "z": -7,
      "name": "Rock_Ice"
    },
    {
      "x": -18,
      "y": 22,
      "z": -7,
      "name": "Rock_Ice"
    },
    {
      "x": -18,
      "y": 23,
      "z": -7,
      "name": "Rock_Ice"
    },
    {
      "x": -18,
      "y": 24,
      "z": -7,
      "name": "Rock_Ice"
    },
    {
      "x": -18,
      "y": 25,
      "z": -7,
      "name": "Rock_Ice"
    },
    {
      "x": -18,
      "y": 26,
      "z": -7,
      "name": "Rock_Ice"
    },
    {
      "x": -18,
      "y": 27,
      "z": -7,
      "name": "Rock_Ice"
    },
    {
      "x": -18,
      "y": 28,
      "z": -7,
      "name": "Rock_Ice"
    },
    {
      "x": -18,
      "y": 29,
      "z": -7,
      "name": "Rock_Ice"
    },
    {
      "x": -18,
      "y": 30,
      "z": -7,
      "name": "Rock_Ice"
    },
    {
      "x": -18,
      "y": 31,
      "z": -7,
      "name": "Rock_Ice"
    },
    {
      "x": -18,
      "y": 32,
      "z": -7,
      "name": "Rock_Ice"
    },
    {
      "x": -18,
      "y": 33,
      "z": -7,
      "name": "Rock_Ice"
    },
    {
      "x": -18,
      "y": 34,
      "z": -7,
      "name": "Rock_Ice"
    },
    {
      "x": -18,
      "y": 35,
      "z": -7,
      "name": "Rock_Ice"
    },
    {
      "x": -18,
      "y": 36,
      "z": -7,
      "name": "Rock_Ice"
    },
    {
      "x": -18,
      "y": 37,
      "z": -7,
      "name": "Rock_Ice"
    },
    {
      "x": -18,
      "y": 38,
      "z": -7,
      "name": "Rock_Ice_Permafrost"
    },
    {
      "x": -18,
      "y": 39,
      "z": -7,
      "name": "Rock_Ice"
    },
    {
      "x": -18,
      "y": 40,
