{
  "version": 8,
  "blockIdVersion": 11,
  "anchorX": 0,
  "anchorY": 0,
  "anchorZ": 0,
  "blocks": [
    {
      "x": -20,
      "y": 116,
      "z": -12,
      "name": "Soil_Snow"
    },
    {
      "x": -20,
      "y": 95,
      "z": -8,
      "name": "Rock_Ice"
    },
    {
      "x": -20,
      "y": 92,
      "z": -7,
      "name": "Rock_Ice"
    },
    {
      "x": -20,
      "y": 93,
      "z": -7,
      "name": "Rock_Ice"
    },
    {
      "x": -20,
      "y": 94,
      "z": -7,
      "name": "Rock_Ice"
    },
    {
      "x": -20,
      "y": 95,
      "z": -7,
      "name": "Rock_Ice"
    },
    {
      "x": -20,
      "y": 96,
      "z": -7,
      "name": "Rock_Ice"
    },
    {
      "x": -20,
      "y": 97,
      "z": -7,
      "name": "Rock_Ice"
    },
    {
      "x": -20,
      "y": 91,
      "z": -6,
      "name": "Rock_Ice"
    },
    {
      "x": -20,
      "y": 92,
      "z": -6,
      "name": "Rock_Ice"
    },
    {
      "x": -20,
      "y": 93,
      "z": -6,
      "name": "Rock_Ice"
    },
    {
      "x": -20,
      "y": 94,
      "z": -6,
      "name": "Rock_Ice"
    },
    {
      "x": -20,
      "y": 95,
      "z": -6,
      "name": "Rock_Ice"
    },
    {
      "x": -20,
      "y": 96,
      "z": -6,
      "name": "Rock_Ice"
    },
    {
      "x": -20,
      "y": 97,
      "z": -6,
      "name": "Rock_Ice"
    },
    {
      "x": -20,
      "y": 98,
      "z": -6,
      "name": "Rock_Ice"
    },
    {
      "x": -20,
      "y": 99,
      "z": -6,
      "name": "Rock_Ice"
    },
    {
      "x": -20,
      "y": 100,
      "z": -6,
      "name": "Rock_Ice"
    },
    {
      "x": -20,
      "y": 101,
      "z": -6,
      "name": "Rock_Ice"
    },
    {
      "x": -20,
      "y": 102,
      "z": -6,
      "name": "Rock_Ice"
    },
    {
      "x": -20,
      "y": 91,
      "z": -5,
      "name": "Rock_Ice"
    },
    {
      "x": -20,
      "y": 92,
      "z": -5,
      "name": "Rock_Ice"
    },
    {
      "x": -20,
      "y": 93,
      "z": -5,
      "name": "Rock_Ice"
    },
    {
      "x": -20,
      "y": 94,
      "z": -5,
      "name": "Rock_Ice"
    },
    {
      "x": -20,
      "y": 95,
      "z": -5,
      "name": "Rock_Ice"
    },
    {
      "x": -20,
      "y": 96,
      "z": -5,
      "name": "Rock_Ice"
    },
    {
      "x": -20,
      "y": 97,
      "z": -5,
      "name": "Rock_Ice"
    },
    {
      "x": -20,
      "y": 98,
      "z": -5,
      "name": "Rock_Ice"
    },
    {
      "x": -20,
      "y": 99,
      "z": -5,
      "name": "Rock_Ice"
    },
    {
      "x": -20,
      "y": 100,
      "z": -5,
      "name": "Rock_Ice"
    },
    {
      "x": -20,
      "y": 101,
      "z": -5,
      "name": "Rock_Ice"
    },
    {
      "x": -20,
      "y": 102,
      "z": -5,
      "name": "Rock_Ice"
    },
    {
      "x": -20,
      "y": 103,
      "z": -5,
      "name": "Soil_Snow"
    },
    {
      "x": -20,
      "y": 91,
      "z": -4,
      "name": "Rock_Ice"
    },
    {
      "x": -20,
      "y": 92,
      "z": -4,
      "name": "Rock_Ice"
    },
    {
      "x": -20,
      "y": 93,
      "z": -4,
      "name": "Rock_Ice"
    },
    {
      "x": -20,
      "y": 94,
      "z": -4,
      "name": "Rock_Ice"
    },
    {
      "x": -20,
      "y": 95,
      "z": -4,
      "name": "Rock_Ice"
    },
    {
      "x": -20,
      "y": 96,
      "z": -4,
      "name": "Rock_Ice"
    },
    {
      "x": -20,
      "y": 97,
      "z": -4,
      "name": "Rock_Ice"
    },
    {
      "x": -20,
      "y": 98,
      "z": -4,
      "name": "Rock_Ice"
    },
    {
      "x": -20,
      "y": 99,
      "z": -4,
      "name": "Rock_Ice"
    },
    {
      "x": -20,
      "y": 100,
      "z": -4,
      "name": "Rock_Ice"
    },
    {
      "x": -20,
      "y": 101,
      "z": -4,
      "name": "Rock_Ice"
    },
    {
      "x": -20,
      "y": 102,
      "z": -4,
      "name": "Rock_Ice"
    },
    {
      "x": -20,
      "y": 92,
      "z": -3,
      "name": "Rock_Ice"
    },
    {
      "x": -20,
      "y": 93,
      "z": -3,
      "name": "Rock_Ice"
    },
    {
      "x": -20,
      "y": 94,
      "z": -3,
      "name": "Rock_Ice"
    },
    {
      "x": -20,
      "y": 95,
      "z": -3,
      "name": "Rock_Ice"
    },
    {
      "x": -20,
      "y": 96,
      "z": -3,
      "name": "Rock_Ice"
    },
    {
      "x": -20,
      "y": 97,
      "z": -3,
      "name": "Rock_Ice"
    },
    {
      "x": -20,
      "y": 98,
      "z": -3,
      "name": "Rock_Ice"
    },
    {
      "x": -20,
      "y": 99,
      "z": -3,
      "name": "Rock_Ice"
    },
    {
      "x": -20,
      "y": 100,
      "z": -3,
      "name": "Soil_Snow"
    },
    {
      "x": -20,
      "y": 95,
      "z": -2,
      "name": "Rock_Ice"
    },
    {
      "x": -20,
      "y": 96,
      "z": -2,
      "name": "Rock_Ice"
    },
    {
      "x": -20,
      "y": 97,
      "z": -2,
      "name": "Rock_Ice"
    },
    {
      "x": -20,
      "y": 98,
      "z": -2,
      "name": "Rock_Ice"
    },
    {
      "x": -20,
      "y": 99,
      "z": -2,
      "name": "Soil_Snow"
    },
    {
      "x": -20,
      "y": 95,
      "z": -1,
      "name": "Rock_Ice"
    },
    {
      "x": -20,
      "y": 96,
      "z": -1,
      "name": "Rock_Ice"
    },
    {
      "x": -20,
      "y": 97,
      "z": -1,
      "name": "Soil_Snow"
    },
    {
      "x": -19,
      "y": 112,
      "z": -12,
      "name": "Rock_Ice"
    },
    {
      "x": -19,
      "y": 113,
      "z": -12,
      "name": "Rock_Ice"
    },
    {
      "x": -19,
      "y": 114,
      "z": -12,
      "name": "Rock_Ice"
    },
    {
      "x": -19,
      "y": 115,
      "z": -12,
      "name": "Rock_Ice"
    },
    {
      "x": -19,
      "y": 116,
      "z": -12,
      "name": "Rock_Ice"
    },
    {
      "x": -19,
      "y": 117,
      "z": -12,
      "name": "Soil_Snow"
    },
    {
      "x": -19,
      "y": 109,
      "z": -11,
      "name": "Rock_Ice"
    },
    {
      "x": -19,
      "y": 110,
      "z": -11,
      "name": "Rock_Ice"
    },
    {
      "x": -19,
      "y": 111,
      "z": -11,
      "name": "Rock_Ice"
    },
    {
      "x": -19,
      "y": 112,
      "z": -11,
      "name": "Rock_Ice"
    },
    {
      "x": -19,
      "y": 113,
      "z": -11,
      "name": "Rock_Ice"
    },
    {
      "x": -19,
      "y": 114,
      "z": -11,
      "name": "Rock_Ice_Permafrost"
    },
    {
      "x": -19,
      "y": 115,
      "z": -11,
      "name": "Rock_Ice"
    },
    {
      "x": -19,
      "y": 116,
      "z": -11,
      "name": "Rock_Ice"
    },
    {
      "x": -19,
      "y": 117,
      "z": -11,
      "name": "Soil_Snow"
    },
    {
      "x": -19,
      "y": 99,
      "z": -10,
      "name": "Rock_Ice"
    },
    {
      "x": -19,
      "y": 100,
      "z": -10,
      "name": "Rock_Ice"
    },
    {
      "x": -19,
      "y": 101,
      "z": -10,
      "name": "Rock_Ice"
    },
    {
      "x": -19,
      "y": 102,
      "z": -10,
      "name": "Rock_Ice"
    },
    {
      "x": -19,
      "y": 103,
      "z": -10,
      "name": "Rock_Ice"
    },
    {
      "x": -19,
      "y": 96,
      "z": -9,
      "name": "Rock_Ice"
    },
    {
      "x": -19,
      "y": 97,
      "z": -9,
      "name": "Rock_Ice"
    },
    {
      "x": -19,
      "y": 98,
      "z": -9,
      "name": "Rock_Ice"
    },
    {
      "x": -19,
      "y": 99,
      "z": -9,
      "name": "Rock_Ice"
    },
    {
      "x": -19,
      "y": 100,
      "z": -9,
      "name": "Rock_Ice"
    },
    {
      "x": -19,
      "y": 101,
      "z": -9,
      "name": "Rock_Ice"
    },
    {
      "x": -19,
      "y": 102,
      "z": -9,
      "name": "Rock_Ice"
    },
    {
      "x": -19,
      "y": 91,
      "z": -8,
      "name": "Rock_Ice"
    },
    {
      "x": -19,
      "y": 92,
      "z": -8,
      "name": "Rock_Ice"
    },
    {
      "x": -19,
      "y": 93,
      "z": -8,
      "name": "Rock_Ice"
    },
    {
      "x": -19,
      "y": 94,
      "z": -8,
      "name": "Rock_Ice"
    },
    {
      "x": -19,
      "y": 95,
      "z": -8,
      "name": "Rock_Ice"
    },
    {
      "x": -19,
      "y": 96,
      "z": -8,
      "name": "Rock_Ice"
    },
    {
      "x": -19,
      "y": 97,
      "z": -8,
      "name": "Rock_Ice"
    },
    {
      "x": -19,
      "y": 98,
      "z": -8,
      "name": "Rock_Ice"
    },
    {
      "x": -19,
      "y": 99,
      "z": -8,
      "name": "Rock_Ice"
    },
    {
      "x": -19,
      "y": 100,
      "z": -8,
      "name": "Rock_Ice"
    },
    {
      "x": -19,
      "y": 101,
      "z": -8,
      "name": "Rock_Ice"
    },
    {
      "x": -19,
      "y": 102,
      "z": -8,
      "name": "Rock_Ice"
    },
    {
      "x": -19,
      "y": 103,
      "z": -8,
      "name": "Rock_Ice"
    },
    {
      "x": -19,
      "y": 104,
      "z": -8,
      "name": "Rock_Ice"
    },
    {
      "x": -19,
      "y": 105,
      "z": -8,
      "name": "Rock_Ice"
    },
    {
      "x": -19,
      "y": 91,
      "z": -7,
      "name": "Rock_Ice"
    },
    {
      "x": -19,
      "y": 92,
      "z": -7,
      "name": "Rock_Ice"
    },
    {
      "x": -19,
      "y": 93,
      "z": -7,
      "name": "Rock_Ice"
    },
    {
      "x": -19,
      "y": 94,
      "z": -7,
      "name": "Rock_Ice"
    },
    {
      "x": -19,
      "y": 95,
      "z": -7,
      "name": "Rock_Ice"
    },
    {
      "x": -19,
      "y": 96,
      "z": -7,
      "name": "Rock_Ice"
    },
    {
      "x": -19,
      "y": 97,
      "z": -7,
      "name": "Rock_Ice"
    },
    {
      "x": -19,
      "y": 98,
      "z": -7,
      "name": "Rock_Ice"
    },
    {
      "x": -19,
      "y": 99,
      "z": -7,
      "name": "Rock_Ice"
    },
    {
      "x": -19,
      "y": 100,
      "z": -7,
      "name": "Rock_Ice"
    },
    {
      "x": -19,
      "y": 101,
      "z": -7,
      "name": "Rock_Ice"
    },
    {
      "x": -19,
      "y": 102,
      "z": -7,
      "name": "Rock_Ice"
    },
    {
      "x": -19,
      "y": 103,
      "z": -7,
      "name": "Rock_Ice"
    },
    {
      "x": -19,
      "y": 104,
      "z": -7,
      "name": "Rock_Ice"
    },
    {
      "x": -19,
      "y": 105,
      "z": -7,
      "name": "Rock_Ice"
    },
    {
      "x": -19,
      "y": 106,
      "z": -7,
      "name": "Rock_Ice"
    },
    {
      "x": -19,
      "y": 107,
      "z": -7,
      "name": "Soil_Snow"
    },
    {
      "x": -19,
      "y": 90,
      "z": -6,
      "name": "Rock_Ice"
    },
    {
      "x": -19,
      "y": 91,
      "z": -6,
      "name": "Rock_Ice"
    },
    {
      "x": -19,
      "y": 92,
      "z": -6,
      "name": "Rock_Ice"
    },
    {
      "x": -19,
      "y": 93,
      "z": -6,
      "name": "Rock_Ice"
    },
    {
      "x": -19,
      "y": 94,
      "z": -6,
      "name": "Rock_Ice"
    },
    {
      "x": -19,
      "y": 95,
      "z": -6,
      "name": "Rock_Ice"
    },
    {
      "x": -19,
      "y": 96,
      "z": -6,
      "name": "Rock_Ice_Permafrost"
    },
    {
      "x": -19,
      "y": 97,
      "z": -6,
      "name": "Rock_Ice"
    },
    {
      "x": -19,
      "y": 98,
      "z": -6,
      "name": "Rock_Ice"
    },
    {
      "x": -19,
      "y": 99,
      "z": -6,
      "name": "Rock_Ice"
    },
    {
      "x": -19,
      "y": 100,
      "z": -6,
      "name": "Rock_Ice"
    },
    {
      "x": -19,
      "y": 101,
      "z": -6,
      "name": "Rock_Ice"
    },
    {
      "x": -19,
      "y": 102,
      "z": -6,
      "name": "Rock_Ice"
    },
    {
      "x": -19,
      "y": 103,
      "z": -6,
      "name": "Rock_Ice"
    },
    {
      "x": -19,
      "y": 104,
      "z": -6,
      "name": "Rock_Ice"
    },
    {
      "x": -19,
      "y": 105,
      "z": -6,
      "name": "Rock_Ice"
    },
    {
      "x": -19,
      "y": 106,
      "z": -6,
      "name": "Rock_Ice"
    },
    {
      "x": -19,
      "y": 107,
      "z": -6,
      "name": "Soil_Snow"
    },
    {
      "x": -19,
      "y": 90,
      "z": -5,
      "name": "Rock_Ice"
    },
    {
      "x": -19,
      "y": 91,
      "z": -5,
      "name": "Rock_Ice"
    },
    {
      "x": -19,
      "y": 92,
      "z": -5,
      "name": "Rock_Ice"
    },
    {
      "x": -19,
      "y": 93,
      "z": -5,
      "name": "Rock_Ice"
    },
    {
      "x": -19,
      "y": 94,
      "z": -5,
      "name": "Rock_Ice"
    },
    {
      "x": -19,
      "y": 95,
      "z": -5,
      "name": "Rock_Ice"
    },
    {
      "x": -19,
      "y": 96,
      "z": -5,
      "name": "Rock_Ice"
    },
    {
      "x": -19,
      "y": 97,
      "z": -5,
      "name": "Rock_Ice"
    },
    {
      "x": -19,
      "y": 98,
      "z": -5,
      "name": "Rock_Ice"
    },
    {
      "x": -19,
      "y": 99,
      "z": -5,
      "name": "Rock_Ice"
    },
    {
      "x": -19,
      "y": 100,
      "z": -5,
      "name": "Rock_Ice"
    },
    {
      "x": -19,
      "y": 101,
      "z": -5,
      "name": "Rock_Ice"
    },
    {
      "x": -19,
      "y": 102,
      "z": -5,
      "name": "Rock_Ice"
    },
    {
      "x": -19,
      "y": 103,
      "z": -5,
      "name": "Rock_Ice"
    },
    {
      "x": -19,
      "y": 104,
      "z": -5,
      "name": "Rock_Ice"
    },
    {
      "x": -19,
      "y": 105,
      "z": -5,
      "name": "Rock_Ice"
    },
    {
      "x": -19,
      "y": 106,
      "z": -5,
      "name": "Rock_Ice"
    },
    {
      "x": -19,
      "y": 107,
      "z": -5,
      "name": "Soil_Snow"
    },
    {
      "x": -19,
      "y": 90,
      "z": -4,
      "name": "Rock_Ice"
    },
    {
      "x": -19,
      "y": 91,
      "z": -4,
      "name": "Rock_Ice"
    },
    {
      "x": -19,
      "y": 92,
      "z": -4,
      "name": "Rock_Ice"
    },
    {
      "x": -19,
      "y": 93,
      "z": -4,
      "name": "Rock_Ice"
    },
    {
      "x": -19,
      "y": 94,
      "z": -4,
      "name": "Rock_Ice"
    },
    {
      "x": -19,
      "y": 95,
      "z": -4,
      "name": "Rock_Ice"
    },
    {
      "x": -19,
      "y": 96,
      "z": -4,
      "name": "Rock_Ice"
    },
    {
      "x": -19,
      "y": 97,
      "z": -4,
      "name": "Rock_Ice"
    },
    {
      "x": -19,
      "y": 98,
      "z": -4,
      "name": "Rock_Ice"
    },
    {
      "x": -19,
      "y": 99,
      "z": -4,
      "name": "Rock_Ice"
    },
    {
      "x": -19,
      "y": 100,
      "z": -4,
      "name": "Rock_Ice"
    },
    {
      "x": -19,
      "y": 101,
      "z": -4,
      "name": "Rock_Ice"
    },
    {
      "x": -19,
      "y": 102,
      "z": -4,
      "name": "Rock_Ice"
    },
    {
      "x": -19,
      "y": 103,
      "z": -4,
      "name": "Rock_Ice"
    },
    {
      "x": -19,
      "y": 104,
      "z": -4,
      "name": "Rock_Ice"
    },
    {
      "x": -19,
      "y": 105,
      "z": -4,
      "name": "Rock_Ice"
    },
    {
      "x": -19,
      "y": 106,
      "z": -4,
      "name": "Rock_Ice"
    },
    {
      "x": -19,
      "y": 107,
      "z": -4,
      "name": "Soil_Snow"
    },
    {
      "x": -19,
      "y": 91,
      "z": -3,
      "name": "Rock_Ice"
    },
    {
      "x": -19,
      "y": 92,
      "z": -3,
      "name": "Rock_Ice"
    },
    {
      "x": -19,
      "y": 93,
      "z": -3,
      "name": "Rock_Ice"
    },
    {
      "x": -19,
      "y": 94,
      "z": -3,
      "name": "Rock_Ice"
    },
    {
      "x": -19,
      "y": 95,
      "z": -3,
      "name": "Rock_Ice"
    },
    {
      "x": -19,
      "y": 96,
      "z": -3,
      "name": "Rock_Ice"
    },
    {
      "x": -19,
      "y": 97,
      "z": -3,
      "name": "Rock_Ice"
    },
    {
      "x": -19,
      "y": 98,
      "z": -3,
      "name": "Rock_Ice"
    },
    {
      "x": -19,
      "y": 99,
      "z": -3,
      "name": "Rock_Ice"
    },
    {
      "x": -19,
      "y": 100,
      "z": -3,
      "name": "Rock_Ice"
    },
    {
      "x": -19,
      "y": 101,
      "z": -3,
      "name": "Rock_Ice"
    },
    {
      "x": -19,
      "y": 102,
      "z": -3,
      "name": "Rock_Ice"
    },
    {
      "x": -19,
      "y": 103,
      "z": -3,
      "name": "Rock_Ice"
    },
    {
      "x": -19,
      "y": 104,
      "z": -3,
      "name": "Soil_Snow"
    },
    {
      "x": -19,
      "y": 93,
      "z": -2,
      "name": "Rock_Ice"
    },
    {
      "x": -19,
      "y": 94,
      "z": -2,
      "name": "Rock_Ice"
    },
    {
      "x": -19,
      "y": 95,
      "z": -2,
      "name": "Rock_Ice"
    },
    {
      "x": -19,
      "y": 96,
      "z": -2,
      "name": "Rock_Ice"
    },
    {
      "x": -19,
      "y": 97,
      "z": -2,
      "name": "Rock_Ice"
    },
    {
      "x": -19,
      "y": 98,
      "z": -2,
      "name": "Rock_Ice"
    },
    {
      "x": -19,
      "y": 99,
      "z": -2,
      "name": "Rock_Ice"
    },
    {
      "x": -19,
      "y": 100,
      "z": -2,
      "name": "Rock_Ice"
    },
    {
      "x": -19,
      "y": 101,
      "z": -2,
      "name": "Rock_Ice"
    },
    {
      "x": -19,
      "y": 102,
      "z": -2,
      "name": "Soil_Snow"
    },
    {
      "x": -19,
      "y": 93,
      "z": -1,
      "name": "Rock_Ice"
    },
    {
      "x": -19,
      "y": 94,
      "z": -1,
      "name": "Rock_Ice"
    },
    {
      "x": -19,
      "y": 95,
      "z": -1,
      "name": "Rock_Ice"
    },
    {
      "x": -19,
      "y": 96,
      "z": -1,
      "name": "Rock_Ice"
    },
    {
      "x": -19,
      "y": 97,
      "z": -1,
      "name": "Rock_Ice"
    },
    {
      "x": -19,
      "y": 98,
      "z": -1,
      "name": "Rock_Ice"
    },
    {
      "x": -19,
      "y": 99,
      "z": -1,
      "name": "Rock_Ice"
    },
    {
      "x": -19,
      "y": 100,
      "z": -1,
      "name": "Soil_Snow"
    },
    {
      "x": -19,
      "y": 93,
      "z": 0,
      "name": "Rock_Ice"
    },
    {
      "x": -19,
      "y": 94,
      "z": 0,
      "name": "Rock_Ice"
    },
    {
      "x": -19,
      "y": 95,
      "z": 0,
      "name": "Rock_Ice"
    },
    {
      "x": -19,
      "y": 96,
      "z": 0,
      "name": "Rock_Ice"
    },
    {
      "x": -19,
      "y": 97,
      "z": 0,
      "name": "Rock_Ice"
    },
    {
      "x": -19,
      "y": 98,
      "z": 0,
      "name": "Soil_Snow"
    },
    {
      "x": -19,
      "y": 94,
      "z": 1,
      "name": "Rock_Ice"
    },
    {
      "x": -19,
      "y": 95,
      "z": 1,
      "name": "Rock_Ice"
    },
    {
      "x": -19,
      "y": 96,
      "z": 1,
      "name": "Rock_Ice"
    },
    {
      "x": -19,
      "y": 97,
      "z": 1,
      "name": "Soil_Snow"
    },
    {
      "x": -19,
      "y": 95,
      "z": 2,
      "name": "Rock_Ice"
    },
    {
      "x": -19,
      "y": 96,
      "z": 2,
      "name": "Soil_Snow"
    },
    {
      "x": -18,
      "y": 111,
      "z": -13,
      "name": "Rock_Ice"
    },
    {
      "x": -18,
      "y": 112,
      "z": -13,
      "name": "Rock_Ice"
    },
    {
      "x": -18,
      "y": 113,
      "z": -13,
      "name": "Rock_Ice"
    },
    {
      "x": -18,
      "y": 114,
      "z": -13,
      "name": "Rock_Ice"
    },
    {
      "x": -18,
      "y": 115,
      "z": -13,
      "name": "Rock_Ice"
    },
    {
      "x": -18,
      "y": 108,
      "z": -12,
      "name": "Rock_Ice"
    },
    {
      "x": -18,
      "y": 109,
      "z": -12,
      "name": "Rock_Ice"
    },
    {
      "x": -18,
      "y": 110,
      "z": -12,
      "name": "Rock_Ice"
    },
    {
      "x": -18,
      "y": 111,
      "z": -12,
      "name": "Rock_Ice"
    },
    {
      "x": -18,
      "y": 112,
      "z": -12,
      "name": "Rock_Ice"
    },
    {
      "x": -18,
      "y": 113,
      "z": -12,
      "name": "Rock_Ice"
    },
    {
      "x": -18,
      "y": 114,
      "z": -12,
      "name": "Rock_Ice"
    },
    {
      "x": -18,
      "y": 115,
      "z": -12,
      "name": "Rock_Ice"
    },
    {
      "x": -18,
      "y": 116,
      "z": -12,
      "name": "Rock_Ice"
    },
    {
      "x": -18,
      "y": 117,
      "z": -12,
      "name": "Soil_Snow"
    },
    {
      "x": -18,
      "y": 32,
      "z": -11,
      "name": "Soil_Snow"
    },
    {
      "x": -18,
      "y": 100,
      "z": -11,
      "name": "Rock_Ice"
    },
    {
      "x": -18,
      "y": 101,
      "z": -11,
      "name": "Rock_Ice"
    },
    {
      "x": -18,
      "y": 102,
      "z": -11,
      "name": "Rock_Ice"
    },
    {
      "x": -18,
      "y": 103,
      "z": -11,
      "name": "Rock_Ice"
    },
    {
      "x": -18,
      "y": 104,
      "z": -11,
      "name": "Rock_Ice"
    },
    {
      "x": -18,
      "y": 105,
      "z": -11,
      "name": "Rock_Ice"
    },
    {
      "x": -18,
      "y": 106,
      "z": -11,
      "name": "Rock_Ice"
    },
    {
      "x": -18,
      "y": 107,
      "z": -11,
      "name": "Rock_Ice"
    },
    {
      "x": -18,
      "y": 108,
      "z": -11,
      "name": "Rock_Ice"
    },
    {
      "x": -18,
      "y": 109,
      "z": -11,
      "name": "Rock_Ice"
    },
    {
      "x": -18,
      "y": 110,
      "z": -11,
      "name": "Rock_Ice"
    },
    {
      "x": -18,
      "y": 111,
      "z": -11,
      "name": "Rock_Ice"
    },
    {
      "x": -18,
      "y": 112,
      "z": -11,
      "name": "Rock_Ice"
    },
    {
      "x": -18,
      "y": 113,
      "z": -11,
      "name": "Rock_Ice"
    },
    {
      "x": -18,
      "y": 114,
      "z": -11,
      "name": "Rock_Ice"
    },
    {
      "x": -18,
      "y": 115,
      "z": -11,
      "name": "Rock_Ice"
    },
    {
      "x": -18,
      "y": 116,
      "z": -11,
      "name": "Rock_Ice"
    },
    {
      "x": -18,
      "y": 117,
      "z": -11,
      "name": "Rock_Ice"
    },
    {
      "x": -18,
      "y": 118,
      "z": -11,
      "name": "Soil_Snow"
    },
    {
      "x": -18,
      "y": 32,
      "z": -10,
      "name": "Soil_Snow"
    },
    {
      "x": -18,
      "y": 96,
      "z": -10,
      "name": "Rock_Ice_Permafrost"
    },
    {
      "x": -18,
      "y": 97,
      "z": -10,
      "name": "Rock_Ice"
    },
    {
      "x": -18,
      "y": 98,
      "z": -10,
      "name": "Rock_Ice"
    },
    {
      "x": -18,
      "y": 99,
      "z": -10,
      "name": "Rock_Ice"
    },
    {
      "x": -18,
      "y": 100,
      "z": -10,
      "name": "Rock_Ice"
    },
    {
      "x": -18,
      "y": 101,
      "z": -10,
      "name": "Rock_Ice"
    },
    {
      "x": -18,
      "y": 102,
      "z": -10,
      "name": "Rock_Ice"
    },
    {
      "x": -18,
      "y": 103,
      "z": -10,
      "name": "Rock_Ice"
    },
    {
      "x": -18,
      "y": 104,
      "z": -10,
      "name": "Rock_Ice"
    },
    {
      "x": -18,
      "y": 105,
      "z": -10,
      "name": "Rock_Ice"
    },
    {
      "x": -18,
      "y": 106,
      "z": -10,
      "name": "Rock_Ice"
    },
    {
      "x": -18,
      "y": 107,
      "z": -10,
      "name": "Rock_Ice"
    },
    {
      "x": -18,
      "y": 108,
      "z": -10,
      "name": "Rock_Ice"
    },
    {
      "x": -18,
      "y": 109,
      "z": -10,
      "name": "Rock_Ice"
    },
    {
      "x": -18,
      "y": 111,
      "z": -10,
      "name": "Rock_Ice"
    },
    {
      "x": -18,
      "y": 112,
      "z": -10,
      "name": "Rock_Ice"
    },
    {
      "x": -18,
      "y": 113,
      "z": -10,
      "name": "Rock_Ice"
    },
    {
      "x": -18,
      "y": 114,
      "z": -10,
      "name": "Rock_Ice"
    },
    {
      "x": -18,
      "y": 115,
      "z": -10,
      "name": "Rock_Ice"
    },
    {
      "x": -18,
      "y": 116,
      "z": -10,
      "name": "Rock_Ice"
    },
    {
      "x": -18,
      "y": 117,
      "z": -10,
      "name": "Soil_Snow"
    },
    {
      "x": -18,
      "y": 32,
      "z": -9,
      "name": "Soil_Snow"
    },
    {
      "x": -18,
      "y": 92,
      "z": -9,
      "name": "Rock_Ice"
    },
    {
      "x": -18,
      "y": 93,
      "z": -9,
      "name": "Rock_Ice"
    },
    {
      "x": -18,
      "y": 94,
      "z": -9,
      "name": "Rock_Ice"
    },
    {
      "x": -18,
      "y": 95,
      "z": -9,
      "name": "Rock_Ice_Permafrost"
    },
    {
      "x": -18,
      "y": 96,
      "z": -9,
      "name": "Rock_Ice"
    },
    {
      "x": -18,
      "y": 97,
      "z": -9,
      "name": "Rock_Ice"
    },
    {
      "x": -18,
      "y": 98,
      "z": -9,
      "name": "Rock_Ice"
    },
    {
      "x": -18,
      "y": 99,
      "z": -9,
      "name": "Rock_Ice"
    },
    {
      "x": -18,
      "y": 100,
      "z": -9,
      "name": "Rock_Ice"
    },
    {
      "x": -18,
      "y": 101,
      "z": -9,
      "name": "Rock_Ice"
    },
    {
      "x": -18,
      "y": 102,
      "z": -9,
      "name": "Rock_Ice"
    },
    {
      "x": -18,
      "y": 103,
      "z": -9,
      "name": "Rock_Ice"
    },
    {
      "x": -18,
      "y": 104,
      "z": -9,
      "name": "Rock_Ice"
    },
    {
      "x": -18,
      "y": 105,
      "z": -9,
      "name": "Rock_Ice"
    },
    {
      "x": -18,
      "y": 106,
      "z": -9,
      "name": "Rock_Ice"
    },
    {
      "x": -18,
      "y": 107,
      "z": -9,
      "name": "Rock_Ice"
    },
    {
      "x": -18,
      "y": 108,
      "z": -9,
      "name": "Rock_Ice"
    },
    {
      "x": -18,
      "y": 109,
      "z": -9,
      "name": "Rock_Ice"
    },
    {
      "x": -18,
      "y": 32,
      "z": -8,
      "name": "Rock_Ice"
    },
    {
      "x": -18,
      "y": 33,
      "z": -8,
      "name": "Soil_Snow"
    },
    {
      "x": -18,
      "y": 89,
      "z": -8,
      "name": "Rock_Ice"
    },
    {
      "x": -18,
      "y": 90,
      "z": -8,
      "name": "Rock_Ice"
    },
    {
      "x": -18,
      "y": 91,
      "z": -8,
      "name": "Rock_Ice"
    },
    {
      "x": -18,
      "y": 92,
      "z": -8,
      "name": "Rock_Ice"
    },
    {
      "x": -18,
      "y": 93,
      "z": -8,
      "name": "Rock_Ice"
    },
    {
      "x": -18,
      "y": 94,
      "z": -8,
      "name": "Rock_Ice"
    },
    {
      "x": -18,
      "y": 95,
      "z": -8,
      "name": "Rock_Ice"
    },
    {
      "x": -18,
      "y": 96,
      "z": -8,
      "name": "Rock_Ice"
    },
    {
      "x": -18,
      "y": 97,
      "z": -8,
      "name": "Rock_Ice"
    },
    {
      "x": -18,
      "y": 98,
      "z": -8,
      "name": "Rock_Ice"
    },
    {
      "x": -18,
      "y": 99,
      "z": -8,
      "name": "Rock_Ice"
    },
    {
      "x": -18,
      "y": 100,
      "z": -8,
      "name": "Rock_Ice"
    },
    {
      "x": -18,
      "y": 101,
      "z": -8,
      "name": "Rock_Ice"
    },
    {
      "x": -18,
      "y": 102,
      "z": -8,
      "name": "Rock_Ice"
    },
    {
      "x": -18,
      "y": 103,
      "z": -8,
      "name": "Rock_Ice"
    },
    {
      "x": -18,
      "y": 104,
      "z": -8,
      "name": "Rock_Ice"
    },
    {
      "x": -18,
      "y": 105,
      "z": -8,
      "name": "Rock_Ice"
    },
    {
      "x": -18,
      "y": 106,
      "z": -8,
      "name": "Rock_Ice"
    },
    {
      "x": -18,
      "y": 107,
      "z": -8,
      "name": "Rock_Ice"
    },
    {
      "x": -18,
      "y": 108,
      "z": -8,
      "name": "Rock_Ice"
    },
    {
      "x": -18,
      "y": 109,
      "z": -8,
      "name": "Rock_Ice"
    },
    {
      "x": -18,
      "y": 110,
      "z": -8,
      "name": "Rock_Ice"
    },
    {
      "x": -18,
      "y": 111,
      "z": -8,
      "name": "Rock_Ice"
    },
    {
      "x": -18,
      "y": 32,
      "z": -7,
      "name": "Rock_Ice"
    },
    {
      "x": -18,
      "y": 33,
      "z": -7,
      "name": "Soil_Snow"
    },
    {
      "x": -18,
      "y": 89,
      "z": -7,
      "name": "Rock_Ice"
    },
    {
      "x": -18,
      "y": 90,
      "z": -7,
      "name": "Rock_Ice"
    },
    {
      "x": -18,
      "y": 91,
      "z": -7,
      "name": "Rock_Ice"
    },
    {
      "x": -18,
      "y": 92,
      "z": -7,
      "name": "Rock_Ice"
    },
    {
      "x": -18,
      "y": 93,
      "z": -7,
      "name": "Rock_Ice"
    },
    {
      "x": -18,
      "y": 94,
      "z": -7,
      "name": "Rock_Ice"
    },
    {
      "x": -18,
      "y": 95,
      "z": -7,
      "name": "Rock_Ice"
    },
    {
      "x": -18,
      "y": 96,
      "z": -7,
      "name": "Rock_Ice"
    },
    {
      "x": -18,
      "y": 97,
      "z": -7,
      "name": "Rock_Ice"
    },
    {
      "x": -18,
      "y": 98,
      "z": -7,
      "name": "Rock_Ice"
    },
    {
      "x": -18,
      "y": 99,
      "z": -7,
      "name": "Rock_Ice"
    },
    {
      "x": -18,
      "y": 100,
      "z": -7,
      "name": "Rock_Ice"
    },
    {
      "x": -18,
      "y": 101,
      "z": -7,
      "name": "Rock_Ice"
    },
    {
      "x": -18,
      "y": 102,
      "z": -7,
      "name": "Rock_Ice"
    },
    {
      "x": -18,
      "y": 103,
      "z": -7,
      "name": "Rock_Ice"
    },
    {
      "x": -18,
      "y": 104,
      "z": -7,
      "name": "Rock_Ice"
    },
    {
      "x": -18,
      "y": 105,
      "z": -7,
      "name": "Rock_Ice"
    },
    {
      "x": -18,
      "y": 106,
      "z": -7,
      "name": "Rock_Ice"
    },
    {
      "x": -18,
      "y": 107,
      "z": -7,
      "name": "Rock_Ice"
    },
    {
      "x": -18,
      "y": 108,
      "z": -7,
      "name": "Rock_Ice"
    },
    {
      "x": -18,
      "y": 109,
      "z": -7,
      "name": "Rock_Ice"
    },
    {
      "x": -18,
      "y": 110,
      "z": -7,
      "name": "Rock_Ice"
    },
    {
      "x": -18,
      "y": 111,
      "z": -7,
      "name": "Rock_Ice"
    },
    {
      "x": -18,
      "y": 112,
      "z": -7,
      "name": "Rock_Ice"
    },
    {
      "x": -18,
      "y": 113,
      "z": -7,
      "name": "Soil_Snow"
    },
    {
      "x": -18,
      "y": 89,
      "z": -6,
      "name": "Rock_Ice"
    },
    {
      "x": -18,
      "y": 90,
      "z": -6,
      "name": "Rock_Ice"
    },
    {
      "x": -18,
      "y": 91,
      "z": -6,
      "name": "Rock_Ice"
    },
    {
      "x": -18,
      "y": 92,
      "z": -6,
      "name": "Rock_Ice"
    },
    {
      "x": -18,
      "y": 93,
      "z": -6,
      "name": "Rock_Ice"
    },
    {
      "x": -18,
      "y": 94,
      "z": -6,
      "name": "Rock_Ice"
    },
    {
      "x": -18,
      "y": 95,
      "z": -6,
      "name": "Rock_Ice"
    },
    {
      "x": -18,
      "y": 96,
      "z": -6,
      "name": "Rock_Ice"
    },
    {
      "x": -18,
      "y": 97,
      "z": -6,
      "name": "Rock_Ice"
    },
    {
      "x": -18,
      "y": 98,
      "z": -6,
      "name": "Rock_Ice"
    },
    {
      "x": -18,
      "y": 99,
      "z": -6,
      "name": "Rock_Ice"
    },
    {
      "x": -18,
      "y": 100,
      "z": -6,
      "name": "Rock_Ice"
    },
    {
      "x": -18,
      "y": 101,
      "z": -6,
      "name": "Rock_Ice"
    },
    {
      "x": -18,
      "y": 102,
      "z": -6,
      "name": "Rock_Ice"
    },
    {
      "x": -18,
      "y": 103,
      "z": -6,
      "name": "Rock_Ice"
    },
    {
      "x": -18,
      "y": 104,
      "z": -6,
      "name": "Rock_Ice"
    },
    {
      "x": -18,
      "y": 105,
      "z": -6,
      "name": "Rock_Ice"
    },
    {
      "x": -18,
      "y": 106,
      "z": -6,
      "name": "Rock_Ice"
    },
    {
      "x": -18,
      "y": 107,
      "z": -6,
      "name": "Rock_Ice"
    },
    {
      "x": -18,
      "y": 108,
      "z": -6,
      "name": "Rock_Ice"
    },
    {
      "x": -18,
      "y": 109,
      "z": -6,
      "name": "Rock_Ice"
    },
    {
      "x": -18,
      "y": 110,
      "z": -6,
      "name": "Rock_Ice"
    },
    {
      "x": -18,
      "y": 111,
      "z": -6,
      "name": "Rock_Ice"
    },
    {
      "x": -18,
      "y": 112,
      "z": -6,
      "name": "Rock_Ice"
    },
    {
      "x": -18,
      "y": 89,
      "z": -5,
      "name": "Rock_Ice"
    },
    {
      "x": -18,
      "y": 90,
      "z": -5,
      "name": "Rock_Ice"
    },
    {
      "x": -18,
      "y": 91,
      "z": -5,
      "name": "Rock_Ice"
    },
    {
      "x": -18,
      "y": 92,
      "z": -5,
      "name": "Rock_Ice"
    },
    {
      "x": -18,
      "y": 93,
      "z": -5,
      "name": "Rock_Ice"
    },
    {
      "x": -18,
      "y": 94,
      "z": -5,
      "name": "Rock_Ice"
    },
    {
      "x": -18,
      "y": 95,
      "z": -5,
      "name": "Rock_Ice"
    },
    {
      "x": -18,
      "y": 96,
      "z": -5,
      "name": "Rock_Ice"
    },
    {
      "x": -18,
      "y": 97,
      "z": -5,
      "name": "Rock_Ice"
    },
    {
      "x": -18,
      "y": 98,
      "z": -5,
      "name": "Rock_Ice"
    },
    {
      "x": -18,
      "y": 99,
      "z": -5,
      "name": "Rock_Ice"
    },
    {
      "x": -18,
      "y": 100,
      "z": -5,
      "name": "Rock_Ice"
    },
    {
      "x": -18,
      "y": 101,
      "z": -5,
      "name": "Rock_Ice"
    },
    {
      "x": -18,
      "y": 102,
      "z": -5,
      "name": "Rock_Ice"
    },
    {
      "x": -18,
      "y": 103,
      "z": -5,
      "name": "Rock_Ice"
    },
    {
      "x": -18,
      "y": 104,
      "z": -5,
      "name": "Rock_Ice"
    },
    {
      "x": -18,
      "y": 105,
      "z": -5,
      "name": "Rock_Ice"
    },
    {
      "x": -18,
      "y": 106,
      "z": -5,
      "name": "Rock_Ice"
    },
    {
      "x": -18,
      "y": 107,
      "z": -5,
      "name": "Rock_Ice"
    },
    {
      "x": -18,
      "y": 108,
      "z": -5,
      "name": "Rock_Ice"
    },
    {
      "x": -18,
      "y": 109,
      "z": -5,
      "name": "Rock_Ice"
    },
    {
      "x": -18,
      "y": 110,
      "z": -5,
      "name": "Rock_Ice"
    },
    {
      "x": -18,
      "y": 111,
      "z": -5,
      "name": "Soil_Snow"
    },
    {
      "x": -18,
      "y": 89,
      "z": -4,
      "name": "Rock_Ice"
    },
    {
      "x": -18,
      "y": 90,
      "z": -4,
      "name": "Rock_Ice"
    },
    {
      "x": -18,
      "y": 91,
      "z": -4,
      "name": "Rock_Ice"
    },
    {
      "x": -18,
      "y": 92,
      "z": -4,
      "name": "Rock_Ice"
    },
    {
      "x": -18,
      "y": 93,
      "z": -4,
      "name": "Rock_Ice"
    },
    {
      "x": -18,
      "y": 94,
      "z": -4,
      "name": "Rock_Ice"
    },
    {
      "x": -18,
      "y": 95,
      "z": -4,
      "name": "Rock_Ice"
    },
    {
      "x": -18,
      "y": 96,
      "z": -4,
      "name": "Rock_Ice"
    },
    {
      "x": -18,
      "y": 97,
      "z": -4,
      "name": "Rock_Ice"
    },
    {
      "x": -18,
      "y": 98,
      "z": -4,
      "name": "Rock_Ice"
    },
    {
      "x": -18,
      "y": 99,
      "z": -4,
      "name": "Rock_Ice"
    },
    {
      "x": -18,
      "y": 100,
      "z": -4,
      "name": "Rock_Ice"
    },
    {
      "x": -18,
      "y": 101,
      "z": -4,
      "name": "Rock_Ice"
    },
    {
      "x": -18,
      "y": 102,
      "z": -4,
      "name": "Rock_Ice"
    },
    {
      "x": -18,
      "y": 103,
      "z": -4,
      "name": "Rock_Ice"
    },
    {
      "x": -18,
      "y": 104,
      "z": -4,
      "name": "Rock_Ice"
    },
    {
      "x": -18,
      "y": 105,
      "z": -4,
      "name": "Rock_Ice"
    },
    {
      "x": -18,
      "y": 106,
      "z": -4,
      "name": "Rock_Ice"
    },
    {
      "x": -18,
      "y": 107,
      "z": -4,
      "name": "Rock_Ice"
    },
    {
      "x": -18,
      "y": 108,
      "z": -4,
      "name": "Rock_Ice"
    },
    {
      "x": -18,
      "y": 109,
      "z": -4,
      "name": "Rock_Ice"
    },
    {
      "x": -18,
      "y": 110,
      "z": -4,
      "name": "Rock_Ice"
    },
    {
      "x": -18,
      "y": 111,
      "z": -4,
      "name": "Soil_Snow"
    },
    {
      "x": -18,
      "y": 89,
      "z": -3,
      "name": "Rock_Ice"
    },
    {
      "x": -18,
      "y": 90,
      "z": -3,
      "name": "Rock_Ice"
    },
    {
      "x": -18,
      "y": 91,
      "z": -3,
      "name": "Rock_Ice"
    },
    {
      "x": -18,
      "y": 92,
      "z": -3,
      "name": "Rock_Ice"
    },
    {
      "x": -18,
      "y": 93,
      "z": -3,
      "name": "Rock_Ice"
    },
    {
      "x": -18,
      "y": 94,
      "z": -3,
      "name": "Rock_Ice"
    },
    {
      "x": -18,
      "y": 95,
      "z": -3,
      "name": "Rock_Ice"
    },
    {
      "x": -18,
      "y": 96,
      "z": -3,
      "name": "Rock_Ice"
    },
    {
      "x": -18,
      "y": 97,
      "z": -3,
      "name": "Rock_Ice"
    },
    {
      "x": -18,
      "y": 98,
      "z": -3,
      "name": "Rock_Ice"
    },
    {
      "x": -18,
      "y": 99,
      "z": -3,
      "name": "Rock_Ice"
    },
    {
      "x": -18,
      "y": 100,
      "z": -3,
      "name": "Rock_Ice"
    },
    {
      "x": -18,
      "y": 101,
      "z": -3,
      "name": "Rock_Ice"
    },
    {
      "x": -18,
      "y": 102,
      "z": -3,
      "name": "Rock_Ice"
    },
    {
      "x": -18,
      "y": 103,
      "z": -3,
      "name": "Rock_Ice"
    },
    {
      "x": -18,
      "y": 104,
      "z": -3,
      "name": "Rock_Ice"
    },
    {
      "x": -18,
      "y": 105,
      "z": -3,
      "name": "Rock_Ice"
    },
    {
      "x": -18,
      "y": 106,
      "z": -3,
      "name": "Rock_Ice"
    },
    {
      "x": -18,
      "y": 107,
      "z": -3,
      "name": "Rock_Ice"
    },
    {
      "x": -18,
      "y": 108,
      "z": -3,
      "name": "Rock_Ice"
    },
    {
      "x": -18,
      "y": 86,
      "z": -2,
      "name": "Rock_Ice"
    },
    {
      "x": -18,
      "y": 87,
      "z": -2,
      "name": "Rock_Ice"
    },
    {
      "x": -18,
      "y": 89,
      "z": -2,
      "name": "Rock_Ice"
    },
    {
      "x": -18,
      "y": 90,
      "z": -2,
      "name": "Rock_Ice"
    },
    {
      "x": -18,
      "y": 91,
      "z": -2,
      "name": "Rock_Ice"
    },
    {
      "x": -18,
      "y": 92,
      "z": -2,
      "name": "Rock_Ice"
    },
    {
      "x": -18,
      "y": 93,
      "z": -2,
      "name": "Rock_Ice"
    },
    {
      "x": -18,
      "y": 94,
      "z": -2,
      "name": "Rock_Ice"
    },
    {
      "x": -18,
      "y": 95,
      "z": -2,
      "name": "Rock_Ice"
    },
    {
      "x": -18,
      "y": 96,
      "z": -2,
      "name": "Rock_Ice"
    },
    {
      "x": -18,
      "y": 97,
      "z": -2,
      "name": "Rock_Ice"
    },
    {
      "x": -18,
      "y": 98,
      "z": -2,
      "name": "Rock_Ice"
    },
    {
      "x": -18,
      "y": 99,
      "z": -2,
      "name": "Rock_Ice"
    },
    {
      "x": -18,
      "y": 100,
      "z": -2,
      "name": "Rock_Ice"
    },
    {
      "x": -18,
      "y": 101,
      "z": -2,
      "name": "Rock_Ice"
    },
    {
      "x": -18,
      "y": 102,
      "z": -2,
      "name": "Rock_Ice"
    },
    {
      "x": -18,
      "y": 103,
      "z": -2,
      "name": "Rock_Ice"
    },
    {
      "x": -18,
      "y": 104,
      "z": -2,
      "name": "Rock_Ice"
    },
    {
      "x": -18,
      "y": 105,
      "z": -2,
      "name": "Soil_Snow"
    },
    {
      "x": -18,
      "y": 84,
      "z": -1,
      "name": "Rock_Ice"
    },
    {
      "x": -18,
      "y": 85,
      "z": -1,
      "name": "Rock_Ice"
    },
    {
      "x": -18,
      "y": 86,
      "z": -1,
      "name": "Rock_Ice"
    },
    {
      "x": -18,
      "y": 87,
      "z": -1,
      "name": "Rock_Ice"
    },
    {
      "x": -18,
      "y": 90,
      "z": -1,
      "name": "Rock_Ice"
    },
    {
      "x": -18,
      "y": 91,
      "z": -1,
      "name": "Rock_Ice"
    },
    {
      "x": -18,
      "y": 92,
      "z": -1,
      "name": "Rock_Ice"
    },
    {
      "x": -18,
      "y": 93,
      "z": -1,
      "name": "Rock_Ice"
    },
    {
      "x": -18,
      "y": 94,
      "z": -1,
      "name": "Rock_Ice"
    },
    {
      "x": -18,
      "y": 95,
      "z": -1,
      "name": "Rock_Ice"
    },
    {
      "x": -18,
      "y": 96,
      "z": -1,
      "name": "Rock_Ice"
    },
    {
      "x": -18,
      "y": 97,
      "z": -1,
      "name": "Rock_Ice"
    },
    {
      "x": -18,
      "y": 98,
      "z": -1,
      "name": "Rock_Ice"
    },
    {
      "x": -18,
      "y": 99,
      "z": -1,
      "name": "Rock_Ice"
    },
    {
      "x": -18,
      "y": 100,
      "z": -1,
      "name": "Rock_Ice"
    },
    {
      "x": -18,
      "y": 101,
      "z": -1,
      "name": "Rock_Ice"
    },
    {
      "x": -18,
      "y": 102,
      "z": -1,
      "name": "Rock_Ice"
    },
    {
      "x": -18,
      "y": 103,
      "z": -1,
      "name": "Soil_Snow"
    },
    {
      "x": -18,
      "y": 84,
      "z": 0,
      "name": "Rock_Ice"
    },
    {
      "x": -18,
      "y": 85,
      "z": 0,
      "name": "Rock_Ice"
    },
    {
      "x": -18,
      "y": 86,
      "z": 0,
      "name": "Rock_Ice"
    },
    {
      "x": -18,
      "y": 87,
      "z": 0,
      "name": "Rock_Ice"
    },
    {
      "x": -18,
      "y": 88,
      "z": 0,
      "name": "Rock_Ice"
    },
    {
      "x": -18,
      "y": 91,
      "z": 0,
      "name": "Rock_Ice"
    },
    {
      "x": -18,
      "y": 92,
      "z": 0,
      "name": "Rock_Ice"
    },
    {
      "x": -18,
      "y": 93,
      "z": 0,
      "name": "Rock_Ice"
    },
    {
      "x": -18,
      "y": 94,
      "z": 0,
      "name": "Rock_Ice"
    },
    {
      "x": -18,
      "y": 95,
      "z": 0,
      "name": "Rock_Ice"
    },
    {
      "x": -18,
      "y": 96,
      "z": 0,
      "name": "Rock_Ice"
    },
    {
      "x": -18,
      "y": 97,
      "z": 0,
      "name": "Rock_Ice"
    },
    {
      "x": -18,
      "y": 98,
      "z": 0,
      "name": "Rock_Ice"
    },
    {
      "x": -18,
      "y": 99,
      "z": 0,
      "name": "Rock_Ice"
    },
    {
      "x": -18,
      "y": 100,
      "z": 0,
      "name": "Rock_Ice"
    },
    {
      "x": -18,
      "y": 101,
      "z": 0,
      "name": "Soil_Snow"
    },
    {
      "x": -18,
      "y": 92,
      "z": 1,
      "name": "Rock_Ice"
    },
    {
      "x": -18,
      "y": 93,
      "z": 1,
      "name": "Rock_Ice"
    },
    {
      "x": -18,
      "y": 94,
      "z": 1,
      "name": "Rock_Ice"
    },
    {
      "x": -18,
      "y": 95,
      "z": 1,
      "name": "Rock_Ice"
    },
    {
      "x": -18,
      "y": 96,
      "z": 1,
      "name": "Rock_Ice"
    },
    {
      "x": -18,
      "y": 97,
      "z": 1,
      "name": "Rock_Ice"
    },
    {
      "x": -18,
      "y": 98,
      "z": 1,
      "name": "Rock_Ice"
    },
    {
      "x": -18,
      "y": 99,
      "z": 1,
      "name": "Soil_Snow"
    },
    {
      "x": -18,
      "y": 94,
      "z": 2,
      "name": "Rock_Ice"
    },
    {
      "x": -18,
      "y": 95,
      "z": 2,
      "name": "Rock_Ice"
    },
    {
      "x": -18,
      "y": 96,
      "z": 2,
      "name": "Rock_Ice"
    },
    {
      "x": -18,
      "y": 97,
      "z": 2,
      "name": "Rock_Ice"
    },
    {
      "x": -18,
      "y": 98,
      "z": 2,
      "name": "Soil_Snow"
    },
    {
      "x": -18,
      "y": 96,
      "z": 3,
      "name": "Rock_Ice"
    },
    {
      "x": -18,
      "y": 97,
      "z": 3,
      "name": "Soil_Snow"
    },
    {
      "x": -17,
      "y": 111,
      "z": -14,
      "name": "Rock_Ice"
    },
    {
      "x": -17,
      "y": 109,
      "z": -13,
      "name": "Rock_Ice"
    },
    {
      "x": -17,
      "y": 110,
      "z": -13,
      "name": "Rock_Ice"
    },
    {
      "x": -17,
      "y": 111,
      "z": -13,
      "name": "Rock_Ice"
    },
    {
      "x": -17,
      "y": 112,
      "z": -13,
      "name": "Rock_Ice"
    },
    {
      "x": -17,
      "y": 113,
      "z": -13,
      "name": "Rock_Ice"
    },
    {
      "x": -17,
      "y": 114,
      "z": -13,
      "name": "Rock_Ice"
    },
    {
      "x": -17,
      "y": 115,
      "z": -13,
      "name": "Rock_Ice"
    },
    {
      "x": -17,
      "y": 116,
      "z": -13,
      "name": "Soil_Snow"
    },
    {
      "x": -17,
      "y": 31,
      "z": -12,
      "name": "Rock_Ice"
    },
    {
      "x": -17,
      "y": 32,
      "z": -12,
      "name": "Soil_Snow"
    },
    {
      "x": -17,
      "y": 101,
      "z": -12,
      "name": "Rock_Ice"
    },
    {
      "x": -17,
      "y": 102,
      "z": -12,
      "name": "Rock_Ice"
    },
    {
      "x": -17,
      "y": 103,
      "z": -12,
      "name": "Rock_Ice"
    },
    {
      "x": -17,
      "y": 104,
      "z": -12,
      "name": "Rock_Ice"
    },
    {
      "x": -17,
      "y": 105,
      "z": -12,
      "name": "Rock_Ice"
    },
    {
      "x": -17,
      "y": 106,
      "z": -12,
      "name": "Rock_Ice"
    },
    {
      "x": -17,
      "y": 107,
      "z": -12,
      "name": "Rock_Ice"
    },
    {
      "x": -17,
      "y": 108,
      "z": -12,
      "name": "Rock_Ice"
    },
    {
      "x": -17,
      "y": 109,
      "z": -12,
      "name": "Rock_Ice"
    },
    {
      "x": -17,
      "y": 110,
      "z": -12,
      "name": "Rock_Ice"
    },
    {
      "x": -17,
      "y": 111,
      "z": -12,
      "name": "Rock_Ice"
    },
    {
      "x": -17,
      "y": 112,
      "z": -12,
      "name": "Rock_Ice"
    },
    {
      "x": -17,
      "y": 113,
      "z": -12,
      "name": "Rock_Ice"
    },
    {
      "x": -17,
      "y": 114,
      "z": -12,
      "name": "Rock_Ice"
    },
    {
      "x": -17,
      "y": 115,
      "z": -12,
      "name": "Rock_Ice"
    },
    {
      "x": -17,
      "y": 116,
      "z": -12,
      "name": "Rock_Ice"
    },
    {
      "x": -17,
      "y": 117,
      "z": -12,
      "name": "Rock_Ice"
    },
    {
      "x": -17,
      "y": 118,
      "z": -12,
      "name": "Soil_Snow"
    },
    {
      "x": -17,
      "y": 31,
      "z": -11,
      "name": "Rock_Ice"
    },
    {
      "x": -17,
      "y": 32,
      "z": -11,
      "name": "Soil_Snow"
    },
    {
      "x": -17,
      "y": 97,
      "z": -11,
      "name": "Rock_Ice"
    },
    {
      "x": -17,
      "y": 98,
      "z": -11,
      "name": "Rock_Ice"
    },
    {
      "x": -17,
      "y": 99,
      "z": -11,
      "name": "Rock_Ice"
    },
    {
      "x": -17,
      "y": 100,
      "z": -11,
      "name": "Rock_Ice"
    },
    {
      "x": -17,
      "y": 101,
      "z": -11,
      "name": "Rock_Ice"
    },
    {
      "x": -17,
      "y": 102,
      "z": -11,
      "name": "Rock_Ice"
    },
    {
      "x": -17,
      "y": 103,
      "z": -11,
      "name": "Rock_Ice"
    },
    {
      "x": -17,
      "y": 104,
      "z": -11,
      "name": "Rock_Ice"
    },
    {
      "x": -17,
      "y": 105,
      "z": -11,
      "name": "Rock_Ice"
    },
    {
      "x": -17,
      "y": 106,
      "z": -11,
      "name": "Rock_Ice"
    },
    {
      "x": -17,
      "y": 107,
      "z": -11,
      "name": "Rock_Ice"
    },
    {
      "x": -17,
      "y": 108,
      "z": -11,
      "name": "Rock_Ice"
    },
    {
      "x": -17,
      "y": 109,
      "z": -11,
      "name": "Rock_Ice"
    },
    {
      "x": -17,
      "y": 110,
      "z": -11,
      "name": "Rock_Ice"
    },
    {
      "x": -17,
      "y": 111,
      "z": -11,
      "name": "Rock_Ice"
    },
    {
      "x": -17,
      "y": 112,
      "z": -11,
      "name": "Rock_Ice"
    },
    {
      "x": -17,
      "y": 113,
      "z": -11,
      "name": "Rock_Ice"
    },
    {
      "x": -17,
      "y": 114,
      "z": -11,
      "name": "Rock_Ice"
    },
    {
      "x": -17,
      "y": 115,
      "z": -11,
      "name": "Rock_Ice"
    },
    {
      "x": -17,
      "y": 116,
      "z": -11,
      "name": "Rock_Ice"
    },
    {
      "x": -17,
      "y": 117,
      "z": -11,
      "name": "Rock_Ice"
    },
    {
      "x": -17,
      "y": 118,
      "z": -11,
      "name": "Rock_Ice"
    },
    {
      "x": -17,
      "y": 119,
      "z": -11,
      "name": "Soil_Snow"
    },
    {
      "x": -17,
      "y": 31,
      "z": -10,
      "name": "Rock_Ice"
    },
    {
      "x": -17,
      "y": 32,
      "z": -10,
      "name": "Rock_Ice"
    },
    {
      "x": -17,
      "y": 33,
      "z": -10,
      "name": "Soil_Snow"
    },
    {
      "x": -17,
      "y": 94,
      "z": -10,
      "name": "Rock_Ice_Permafrost"
    },
    {
      "x": -17,
      "y": 95,
      "z": -10,
      "name": "Rock_Ice"
    },
    {
      "x": -17,
      "y": 96,
      "z": -10,
      "name": "Rock_Ice"
    },
    {
      "x": -17,
      "y": 97,
      "z": -10,
      "name": "Rock_Ice"
    },
    {
      "x": -17,
      "y": 98,
      "z": -10,
      "name": "Rock_Ice"
    },
    {
      "x": -17,
      "y": 99,
      "z": -10,
      "name": "Rock_Ice"
    },
    {
      "x": -17,
      "y": 100,
      "z": -10,
      "name": "Rock_Ice"
    },
    {
      "x": -17,
      "y": 101,
      "z": -10,
      "name": "Rock_Ice"
    },
    {
      "x": -17,
      "y": 102,
      "z": -10,
      "name": "Rock_Ice"
    },
    {
      "x": -17,
      "y": 103,
      "z": -10,
      "name": "Rock_Ice"
    },
    {
      "x": -17,
      "y": 104,
      "z": -10,
      "name": "Rock_Ice"
    },
    {
      "x": -17,
      "y": 105,
      "z": -10,
      "name": "Rock_Ice"
    },
    {
      "x": -17,
      "y": 106,
      "z": -10,
      "name": "Rock_Ice"
    },
    {
      "x": -17,
      "y": 107,
      "z": -10,
      "name": "Rock_Ice"
    },
    {
      "x": -17,
      "y": 108,
      "z": -10,
      "name": "Rock_Ice"
    },
    {
      "x": -17,
      "y": 109,
      "z": -10,
      "name": "Rock_Ice"
    },
    {
      "x": -17,
      "y": 110,
      "z": -10,
      "name": "Rock_Ice"
    },
    {
      "x": -17,
      "y": 111,
      "z": -10,
      "name": "Rock_Ice"
    },
    {
      "x": -17,
      "y": 112,
      "z": -10,
      "name": "Rock_Ice"
    },
    {
      "x": -17,
      "y": 113,
      "z": -10,
      "name": "Rock_Ice"
    },
    {
      "x": -17,
      "y": 114,
      "z": -10,
      "name": "Rock_Ice"
    },
    {
      "x": -17,
      "y": 115,
      "z": -10,
      "name": "Rock_Ice"
    },
    {
      "x": -17,
      "y": 116,
      "z": -10,
      "name": "Rock_Ice"
    },
    {
      "x": -17,
      "y": 117,
      "z": -10,
      "name": "Rock_Ice"
    },
    {
      "x": -17,
      "y": 118,
      "z": -10,
      "name": "Soil_Snow"
    },
    {
      "x": -17,
      "y": 31,
      "z": -9,
      "name": "Rock_Ice"
    },
    {
      "x": -17,
      "y": 32,
      "z": -9,
      "name": "Rock_Ice"
    },
    {
      "x": -17,
      "y": 33,
      "z": -9,
      "name": "Soil_Snow"
    },
    {
      "x": -17,
      "y": 90,
      "z": -9,
      "name": "Rock_Ice"
    },
    {
      "x": -17,
      "y": 91,
      "z": -9,
      "name": "Rock_Ice"
    },
    {
      "x": -17,
      "y": 92,
      "z": -9,
      "name": "Rock_Ice"
    },
    {
      "x": -17,
      "y": 93,
      "z": -9,
      "name": "Rock_Ice"
    },
    {
      "x": -17,
      "y": 94,
      "z": -9,
      "name": "Rock_Ice"
    },
    {
      "x": -17,
      "y": 95,
      "z": -9,
      "name": "Rock_Ice"
    },
    {
      "x": -17,
      "y": 96,
      "z": -9,
      "name": "Rock_Ice"
    },
    {
      "x": -17,
      "y": 97,
      "z": -9,
      "name": "Rock_Ice"
    },
    {
      "x": -17,
      "y": 98,
      "z": -9,
      "name": "Rock_Ice"
    },
    {
      "x": -17,
      "y": 99,
      "z": -9,
      "name": "Rock_Ice"
    },
    {
      "x": -17,
      "y": 100,
      "z": -9,
      "name": "Rock_Ice"
    },
    {
      "x": -17,
      "y": 101,
      "z": -9,
      "name": "Rock_Ice"
    },
    {
      "x": -17,
      "y": 102,
      "z": -9,
      "name": "Rock_Ice"
    },
    {
      "x": -17,
      "y": 103,
      "z": -9,
      "name": "Rock_Ice"
    },
    {
      "x": -17,
      "y": 104,
      "z": -9,
      "name": "Rock_Ice"
    },
    {
      "x": -17,
      "y": 105,
      "z": -9,
      "name": "Rock_Ice"
    },
    {
      "x": -17,
      "y": 106,
      "z": -9,
      "name": "Rock_Ice"
    },
    {
      "x": -17,
      "y": 107,
      "z": -9,
      "name": "Rock_Ice"
    },
    {
      "x": -17,
      "y": 108,
      "z": -9,
      "name": "Rock_Ice"
    },
    {
      "x": -17,
      "y": 109,
      "z": -9,
      "name": "Rock_Ice"
    },
    {
      "x": -17,
      "y": 110,
      "z": -9,
      "name": "Rock_Ice"
    },
    {
      "x": -17,
      "y": 111,
      "z": -9,
      "name": "Rock_Ice"
    },
    {
      "x": -17,
      "y": 112,
      "z": -9,
      "name": "Rock_Ice"
    },
    {
      "x": -17,
      "y": 113,
      "z": -9,
      "name": "Rock_Ice"
    },
    {
      "x": -17,
      "y": 114,
      "z": -9,
      "name": "Rock_Ice"
    },
    {
      "x": -17,
      "y": 115,
      "z": -9,
      "name": "Rock_Ice"
    },
    {
      "x": -17,
      "y": 116,
      "z": -9,
      "name": "Rock_Ice"
    },
    {
      "x": -17,
      "y": 117,
      "z": -9,
      "name": "Soil_Snow"
    },
    {
      "x": -17,
      "y": 30,
      "z": -8,
      "name": "Rock_Ice"
    },
    {
      "x": -17,
      "y": 31,
      "z": -8,
      "name": "Rock_Ice"
    },
    {
      "x": -17,
      "y": 32,
      "z": -8,
      "name": "Rock_Ice"
    },
    {
      "x": -17,
      "y": 33,
      "z": -8,
      "name": "Rock_Ice"
    },
    {
      "x": -17,
      "y": 34,
      "z": -8,
      "name": "Soil_Snow"
    },
    {
      "x": -17,
      "y": 63,
      "z": -8,
      "name": "Soil_Snow"
    },
    {
      "x": -17,
      "y": 87,
      "z": -8,
      "name": "Rock_Ice_Permafrost"
    },
    {
      "x": -17,
      "y": 88,
      "z": -8,
      "name": "Rock_Crystal_Cyan_Block_WhiteLight"
    },
    {
      "x": -17,
      "y": 89,
      "z": -8,
      "name": "Rock_Ice_Permafrost"
    },
    {
      "x": -17,
      "y": 90,
      "z": -8,
      "name": "Rock_Ice"
    },
    {
      "x": -17,
      "y": 91,
      "z": -8,
      "name": "Rock_Ice"
    },
    {
      "x": -17,
      "y": 92,
      "z": -8,
      "name": "Rock_Ice"
    },
    {
      "x": -17,
      "y": 93,
      "z": -8,
      "name": "Rock_Ice"
    },
    {
      "x": -17,
      "y": 94,
      "z": -8,
      "name": "Rock_Ice"
    },
    {
      "x": -17,
      "y": 95,
      "z": -8,
      "name": "Rock_Ice"
    },
    {
      "x": -17,
      "y": 96,
      "z": -8,
      "name": "Rock_Ice"
    },
    {
      "x": -17,
      "y": 97,
      "z": -8,
      "name": "Rock_Ice"
    },
    {
      "x": -17,
      "y": 98,
      "z": -8,
      "name": "Rock_Ice"
    },
    {
      "x": -17,
      "y": 99,
      "z": -8,
      "name": "Rock_Ice"
    },
    {
      "x": -17,
      "y": 100,
      "z": -8,
      "name": "Rock_Ice"
    },
    {
      "x": -17,
      "y": 101,
      "z": -8,
      "name": "Rock_Ice"
    },
    {
      "x": -17,
      "y": 102,
      "z": -8,
      "name": "Rock_Ice"
    },
    {
      "x": -17,
      "y": 103,
      "z": -8,
      "name": "Rock_Ice"
    },
    {
      "x": -17,
      "y": 104,
      "z": -8,
      "name": "Rock_Ice"
    },
    {
      "x": -17,
      "y": 105,
      "z": -8,
      "name": "Rock_Ice"
    },
    {
      "x": -17,
      "y": 106,
      "z": -8,
      "name": "Rock_Ice"
    },
    {
      "x": -17,
      "y": 107,
      "z": -8,
      "name": "Rock_Ice"
    },
    {
      "x": -17,
      "y": 108,
      "z": -8,
      "name": "Rock_Ice"
    },
    {
      "x": -17,
      "y": 109,
      "z": -8,
      "name": "Rock_Ice"
    },
    {
      "x": -17,
      "y": 110,
      "z": -8,
      "name": "Rock_Ice"
    },
    {
      "x": -17,
      "y": 111,
      "z": -8,
      "name": "Rock_Ice"
    },
    {
      "x": -17,
      "y": 112,
      "z": -8,
      "name": "Rock_Ice"
    },
    {
      "x": -17,
      "y": 113,
      "z": -8,
      "name": "Rock_Ice"
    },
    {
      "x": -17,
      "y": 114,
      "z": -8,
      "name": "Rock_Ice"
    },
    {
      "x": -17,
      "y": 115,
      "z": -8,
      "name": "Rock_Ice"
    },
    {
      "x": -17,
      "y": 116,
      "z": -8,
      "name": "Soil_Snow"
    },
    {
      "x": -17,
      "y": 31,
      "z": -7,
      "name": "Rock_Ice"
    },
    {
      "x": -17,
      "y": 32,
      "z": -7,
      "name": "Rock_Ice"
    },
    {
      "x": -17,
      "y": 33,
      "z": -7,
      "name": "Rock_Ice"
    },
    {
      "x": -17,
      "y": 34,
      "z": -7,
      "name": "Soil_Snow"
    },
    {
      "x": -17,
      "y": 60,
      "z": -7,
      "name": "Rock_Ice"
    },
    {
      "x": -17,
      "y": 61,
      "z": -7,
      "name": "Rock_Ice"
    },
    {
      "x": -17,
      "y": 62,
      "z": -7,
      "name": "Rock_Ice"
    },
    {
      "x": -17,
      "y": 63,
      "z": -7,
      "name": "Rock_Ice"
    },
    {
      "x": -17,
      "y": 64,
      "z": -7,
      "name": "Soil_Snow"
    },
    {
      "x": -17,
      "y": 87,
      "z": -7,
      "name": "Rock_Ice_Permafrost"
    },
    {
      "x": -17,
      "y": 88,
      "z": -7,
      "name": "Rock_Ice_Permafrost"
    },
    {
      "x": -17,
      "y": 89,
      "z": -7,
      "name": "Rock_Ice_Permafrost"
    },
    {
      "x": -17,
      "y": 90,
      "z": -7,
      "name": "Rock_Ice"
    },
    {
      "x": -17,
      "y": 91,
      "z": -7,
      "name": "Rock_Ice"
    },
    {
      "x": -17,
      "y": 92,
      "z": -7,
      "name": "Rock_Ice"
    },
    {
      "x": -17,
      "y": 93,
      "z": -7,
      "name": "Rock_Ice"
    },
    {
      "x": -17,
      "y": 94,
      "z": -7,
      "name": "Rock_Ice"
    },
    {
      "x": -17,
      "y": 95,
      "z": -7,
      "name": "Rock_Ice"
    },
    {
      "x": -17,
      "y": 96,
      "z": -7,
      "name": "Rock_Ice"
    },
    {
      "x": -17,
      "y": 97,
      "z": -7,
      "name": "Rock_Ice"
    },
    {
      "x": -17,
      "y": 98,
      "z": -7,
      "name": "Rock_Ice"
    },
    {
      "x": -17,
      "y": 99,
      "z": -7,
      "name": "Rock_Ice"
    },
    {
      "x": -17,
      "y": 100,
      "z": -7,
      "name": "Rock_Ice"
    },
    {
      "x": -17,
      "y": 101,
      "z": -7,
      "name": "Rock_Ice"
    },
    {
      "x": -17,
      "y": 102,
      "z": -7,
      "name": "Rock_Ice"
    },
    {
      "x": -17,
      "y": 103,
      "z": -7,
      "name": "Rock_Ice"
    },
    {
      "x": -17,
      "y": 104,
      "z": -7,
      "name": "Rock_Ice"
    },
    {
      "x": -17,
      "y": 105,
      "z": -7,
      "name": "Rock_Ice"
    },
    {
      "x": -17,
      "y": 106,
      "z": -7,
      "name": "Rock_Ice"
    },
    {
      "x": -17,
      "y": 107,
      "z": -7,
      "name": "Rock_Ice"
    },
    {
      "x": -17,
      "y": 108,
      "z": -7,
      "name": "Rock_Ice"
    },
    {
      "x": -17,
      "y": 109,
      "z": -7,
      "name": "Rock_Ice"
    },
    {
      "x": -17,
      "y": 110,
      "z": -7,
      "name": "Rock_Ice"
    },
    {
      "x": -17,
      "y": 111,
      "z": -7,
      "name": "Rock_Ice"
    },
    {
      "x": -17,
      "y": 112,
      "z": -7,
      "name": "Rock_Ice_Permafrost"
    },
    {
      "x": -17,
      "y": 113,
      "z": -7,
      "name": "Rock_Ice"
    },
    {
      "x": -17,
      "y": 114,
      "z": -7,
      "name": "Rock_Ice"
    },
    {
      "x": -17,
      "y": 115,
      "z": -7,
      "name": "Rock_Ice"
    },
    {
      "x": -17,
      "y": 116,
      "z": -7,
      "name": "Soil_Snow"
    },
    {
      "x": -17,
      "y": 31,
      "z": -6,
      "name": "Rock_Ice"
    },
    {
      "x": -17,
      "y": 32,
      "z": -6,
      "name": "Rock_Ice"
    },
    {
      "x": -17,
      "y": 33,
      "z": -6,
      "name": "Rock_Ice"
    },
    {
      "x": -17,
      "y": 34,
      "z": -6,
      "name": "Soil_Snow"
    },
    {
      "x": -17,
      "y": 58,
      "z": -6,
      "name": "Rock_Ice"
    },
    {
      "x": -17,
      "y": 59,
      "z": -6,
      "name": "Rock_Ice"
    },
    {
      "x": -17,
      "y": 60,
      "z": -6,
      "name": "Rock_Ice"
    },
    {
      "x": -17,
      "y": 61,
      "z": -6,
      "name": "Rock_Ice"
    },
    {
      "x": -17,
      "y": 62,
      "z": -6,
      "name": "Rock_Ice"
    },
    {
      "x": -17,
      "y": 63,
      "z": -6,
      "name": "Rock_Ice"
    },
    {
      "x": -17,
      "y": 64,
      "z": -6,
      "name": "Soil_Snow"
    },
    {
      "x": -17,
      "y": 87,
      "z": -6,
      "name": "Rock_Crystal_Cyan_Block_WhiteLight"
    },
    {
      "x": -17,
      "y": 88,
      "z": -6,
      "name": "Rock_Ice_Permafrost"
    },
    {
      "x": -17,
      "y": 89,
      "z": -6,
      "name": "Rock_Ice_Permafrost"
    },
    {
      "x": -17,
      "y": 90,
      "z": -6,
      "name": "Rock_Ice"
    },
    {
      "x": -17,
      "y": 91,
      "z": -6,
      "name": "Rock_Ice"
    },
    {
      "x": -17,
      "y": 92,
      "z": -6,
      "name": "Rock_Ice"
    },
    {
      "x": -17,
      "y": 93,
      "z": -6,
      "name": "Rock_Ice"
    },
    {
      "x": -17,
      "y": 94,
      "z": -6,
      "name": "Rock_Ice_Permafrost"
    },
    {
      "x": -17,
      "y": 95,
      "z": -6,
      "name": "Rock_Ice"
    },
    {
      "x": -17,
      "y": 96,
      "z": -6,
      "name": "Rock_Ice"
    },
    {
      "x": -17,
      "y": 97,
      "z": -6,
      "name": "Rock_Ice"
    },
    {
      "x": -17,
      "y": 98,
      "z": -6,
      "name": "Rock_Ice"
    },
    {
      "x": -17,
      "y": 99,
      "z": -6,
      "name": "Rock_Ice"
    },
    {
      "x": -17,
      "y": 100,
      "z": -6,
      "name": "Rock_Ice"
    },
    {
      "x": -17,
      "y": 101,
      "z": -6,
      "name": "Rock_Ice"
    },
    {
      "x": -17,
      "y": 102,
      "z": -6,
      "name": "Rock_Ice"
    },
    {
      "x": -17,
      "y": 103,
      "z": -6,
      "name": "Rock_Ice"
    },
    {
      "x": -17,
      "y": 104,
      "z": -6,
      "name": "Rock_Ice"
    },
    {
      "x": -17,
      "y": 105,
      "z": -6,
      "name": "Rock_Ice"
    },
    {
      "x": -17,
      "y": 106,
      "z": -6,
      "name": "Rock_Ice"
    },
    {
      "x": -17,
      "y": 107,
      "z": -6,
      "name": "Rock_Ice"
    },
    {
      "x": -17,
      "y": 108,
      "z": -6,
      "name": "Rock_Ice"
    },
    {
      "x": -17,
      "y": 109,
      "z": -6,
      "name": "Rock_Ice"
    },
    {
      "x": -17,
      "y": 110,
      "z": -6,
      "name": "Rock_Ice"
    },
    {
      "x": -17,
      "y": 111,
      "z": -6,
      "name": "Rock_Ice"
    },
    {
      "x": -17,
      "y": 112,
      "z": -6,
      "name": "Rock_Ice"
    },
    {
      "x": -17,
      "y": 113,
      "z": -6,
      "name": "Rock_Ice"
    },
    {
      "x": -17,
      "y": 114,
      "z": -6,
      "name": "Rock_Ice"
    },
    {
      "x": -17,
      "y": 115,
      "z": -6,
      "name": "Rock_Ice"
    },
    {
      "x": -17,
      "y": 116,
      "z": -6,
      "name": "Soil_Snow"
    },
    {
      "x": -17,
      "y": 32,
      "z": -5,
      "name": "Rock_Ice"
    },
    {
      "x": -17,
      "y": 57,
      "z": -5,
      "name": "Rock_Ice"
    },
    {
      "x": -17,
      "y": 58,
      "z": -5,
      "name": "Rock_Ice"
    },
    {
      "x": -17,
      "y": 59,
      "z": -5,
      "name": "Rock_Ice"
    },
    {
      "x": -17,
      "y": 60,
      "z": -5,
      "name": "Rock_Ice"
    },
    {
      "x": -17,
      "y": 61,
      "z": -5,
      "name": "Rock_Ice"
    },
    {
      "x": -17,
      "y": 62,
      "z": -5,
      "name": "Rock_Ice"
    },
    {
      "x": -17,
      "y": 63,
      "z": -5,
      "name": "Rock_Ice"
    },
    {
      "x": -17,
      "y": 64,
      "z": -5,
      "name": "Soil_Snow"
    },
    {
      "x": -17,
      "y": 87,
      "z": -5,
      "name": "Rock_Ice_Permafrost"
    },
    {
      "x": -17,
      "y": 88,
      "z": -5,
      "name": "Rock_Ice"
    },
    {
      "x": -17,
      "y": 89,
      "z": -5,
      "name": "Rock_Ice"
    },
    {
      "x": -17,
      "y": 90,
      "z": -5,
      "name": "Rock_Ice"
    },
    {
      "x": -17,
      "y": 91,
      "z": -5,
      "name": "Rock_Ice"
    },
    {
      "x": -17,
      "y": 92,
      "z": -5,
      "name": "Rock_Ice"
    },
    {
      "x": -17,
      "y": 93,
      "z": -5,
      "name": "Rock_Ice"
    },
    {
      "x": -17,
      "y": 94,
      "z": -5,
      "name": "Rock_Ice"
    },
    {
      "x": -17,
      "y": 95,
      "z": -5,
      "name": "Rock_Ice"
    },
    {
      "x": -17,
      "y": 96,
      "z": -5,
      "name": "Rock_Ice"
    },
    {
      "x": -17,
      "y": 97,
      "z": -5,
      "name": "Rock_Ice"
    },
    {
      "x": -17,
      "y": 98,
      "z": -5,
      "name": "Rock_Ice"
    },
    {
      "x": -17,
      "y": 99,
      "z": -5,
      "name": "Rock_Ice"
    },
    {
      "x": -17,
      "y": 100,
      "z": -5,
      "name": "Rock_Ice"
    },
    {
      "x": -17,
      "y": 101,
      "z": -5,
      "name": "Rock_Ice"
    },
    {
      "x": -17,
      "y": 102,
      "z": -5,
      "name": "Rock_Ice"
    },
    {
      "x": -17,
      "y": 103,
      "z": -5,
      "name": "Rock_Ice"
    },
    {
      "x": -17,
      "y": 104,
      "z": -5,
      "name": "Rock_Ice"
    },
    {
      "x": -17,
      "y": 105,
      "z": -5,
      "name": "Rock_Ice"
    },
    {
      "x": -17,
      "y": 106,
      "z": -5,
      "name": "Rock_Ice"
    },
    {
      "x": -17,
      "y": 107,
      "z": -5,
      "name": "Rock_Ice"
    },
    {
      "x": -17,
      "y": 108,
      "z": -5,
      "name": "Rock_Ice"
    },
    {
      "x": -17,
      "y": 109,
      "z": -5,
      "name": "Rock_Ice"
    },
    {
      "x": -17,
      "y": 110,
      "z": -5,
      "name": "Rock_Ice"
    },
    {
      "x": -17,
      "y": 111,
      "z": -5,
      "name": "Rock_Ice"
    },
    {
      "x": -17,
      "y": 112,
      "z": -5,
      "name": "Rock_Ice"
    },
    {
      "x": -17,
      "y": 113,
      "z": -5,
      "name": "Rock_Ice_Permafrost"
    },
    {
      "x": -17,
      "y": 114,
      "z": -5,
      "name": "Rock_Ice_Permafrost"
    },
    {
      "x": -17,
      "y": 115,
      "z": -5,
      "name": "Rock_Ice"
    },
    {
      "x": -17,
      "y": 116,
      "z": -5,
      "name": "Soil_Snow"
    },
    {
      "x": -17,
      "y": 57,
      "z": -4,
      "name": "Rock_Ice"
    },
    {
      "x": -17,
      "y": 58,
      "z": -4,
      "name": "Rock_Ice"
    },
    {
      "x": -17,
      "y": 59,
      "z": -4,
      "name": "Rock_Ice"
    },
    {
      "x": -17,
      "y": 60,
      "z": -4,
      "name": "Rock_Ice"
    },
    {
      "x": -17,
      "y": 61,
      "z": -4,
      "name": "Rock_Ice"
    },
    {
      "x": -17,
      "y": 62,
      "z": -4,
      "name": "Rock_Ice"
    },
    {
      "x": -17,
      "y": 63,
      "z": -4,
      "name": "Rock_Ice"
    },
    {
      "x": -17,
      "y": 64,
      "z": -4,
      "name": "Soil_Snow"
    },
    {
      "x": -17,
      "y": 85,
      "z": -4,
      "name": "Rock_Ice_Permafrost"
    },
    {
      "x": -17,
      "y": 86,
      "z": -4,
      "name": "Rock_Ice_Permafrost"
    },
    {
      "x": -17,
      "y": 87,
      "z": -4,
      "name": "Rock_Ice"
    },
    {
      "x": -17,
      "y": 88,
      "z": -4,
      "name": "Rock_Ice"
    },
    {
      "x": -17,
      "y": 89,
      "z": -4,
      "name": "Rock_Ice"
    },
    {
      "x": -17,
      "y": 90,
      "z": -4,
      "name": "Rock_Ice"
    },
    {
      "x": -17,
      "y": 91,
      "z": -4,
      "name": "Rock_Ice"
    },
    {
      "x": -17,
      "y": 92,
      "z": -4,
      "name": "Rock_Ice"
    },
    {
      "x": -17,
      "y": 93,
      "z": -4,
      "name": "Rock_Ice"
    },
    {
      "x": -17,
      "y": 94,
      "z": -4,
      "name": "Rock_Ice"
    },
    {
      "x": -17,
      "y": 95,
      "z": -4,
      "name": "Rock_Ice"
    },
    {
      "x": -17,
      "y": 96,
      "z": -4,
      "name": "Rock_Ice"
    },
    {
      "x": -17,
      "y": 97,
      "z": -4,
      "name": "Rock_Ice"
    },
    {
      "x": -17,
      "y": 98,
      "z": -4,
      "name": "Rock_Ice"
    },
    {
      "x": -17,
      "y": 99,
      "z": -4,
      "name": "Rock_Ice"
    },
    {
      "x": -17,
      "y": 100,
      "z": -4,
      "name": "Rock_Ice"
    },
    {
      "x": -17,
      "y": 101,
      "z": -4,
      "name": "Rock_Ice"
    },
    {
      "x": -17,
      "y": 102,
      "z": -4,
      "name": "Rock_Ice"
    },
    {
      "x": -17,
      "y": 103,
      "z": -4,
      "name": "Rock_Ice"
    },
    {
      "x": -17,
      "y": 104,
      "z": -4,
      "name": "Rock_Ice"
    },
    {
      "x": -17,
      "y": 105,
      "z": -4,
      "name": "Rock_Ice"
    },
    {
      "x": -17,
      "y": 106,
      "z": -4,
      "name": "Rock_Ice"
    },
    {
      "x": -17,
      "y": 107,
      "z": -4,
      "name": "Rock_Ice"
    },
    {
      "x": -17,
      "y": 108,
      "z": -4,
      "name": "Rock_Ice"
    },
    {
      "x": -17,
      "y": 109,
      "z": -4,
      "name": "Rock_Ice"
    },
    {
      "x": -17,
      "y": 110,
      "z": -4,
      "name": "Rock_Ice"
    },
    {
      "x": -17,
      "y": 111,
      "z": -4,
      "name": "Rock_Ice"
    },
    {
      "x": -17,
      "y": 112,
      "z": -4,
      "name": "Rock_Ice"
    },
    {
      "x": -17,
      "y": 113,
      "z": -4,
      "name": "Rock_Ice"
    },
    {
      "x": -17,
      "y": 114,
      "z": -4,
      "name": "Rock_Ice"
    },
    {
      "x": -17,
      "y": 115,
      "z": -4,
      "name": "Soil_Snow"
    },
    {
      "x": -17,
      "y": 57,
      "z": -3,
      "name": "Rock_Ice"
    },
    {
      "x": -17,
      "y": 58,
      "z": -3,
      "name": "Rock_Ice"
    },
    {
      "x": -17,
      "y": 59,
      "z": -3,
      "name": "Rock_Ice"
    },
    {
      "x": -17,
      "y": 60,
      "z": -3,
      "name": "Rock_Ice"
    },
    {
      "x": -17,
      "y": 61,
      "z": -3,
      "name": "Rock_Ice"
    },
    {
      "x": -17,
      "y": 62,
      "z": -3,
      "name": "Rock_Ice"
    },
    {
      "x": -17,
      "y": 63,
      "z": -3,
      "name": "Rock_Ice"
    },
    {
      "x": -17,
      "y": 64,
      "z": -3,
      "name": "Soil_Snow"
    },
    {
      "x": -17,
      "y": 83,
      "z": -3,
      "name": "Rock_Ice_Permafrost"
    },
    {
      "x": -17,
      "y": 84,
      "z": -3,
      "name": "Rock_Ice_Permafrost"
    },
    {
      "x": -17,
      "y": 85,
      "z": -3,
      "name": "Rock_Ice_Permafrost"
    },
    {
      "x": -17,
      "y": 86,
      "z": -3,
      "name": "Rock_Ice_Permafrost"
    },
    {
      "x": -17,
      "y": 87,
      "z": -3,
      "name": "Rock_Ice_Permafrost"
    },
    {
      "x": -17,
      "y": 88,
      "z": -3,
      "name": "Rock_Ice"
    },
    {
      "x": -17,
      "y": 89,
      "z": -3,
      "name": "Rock_Ice"
    },
    {
      "x": -17,
      "y": 90,
      "z": -3,
      "name": "Rock_Ice"
    },
    {
      "x": -17,
      "y": 91,
      "z": -3,
      "name": "Rock_Ice"
    },
    {
      "x": -17,
      "y": 92,
      "z": -3,
      "name": "Rock_Ice"
    },
    {
      "x": -17,
      "y": 93,
      "z": -3,
      "name": "Rock_Ice"
    },
    {
      "x": -17,
      "y": 94,
      "z": -3,
      "name": "Rock_Ice"
    },
    {
      "x": -17,
      "y": 95,
      "z": -3,
      "name": "Rock_Ice"
    },
    {
      "x": -17,
      "y": 96,
      "z": -3,
      "name": "Rock_Ice"
    },
    {
      "x": -17,
      "y": 97,
      "z": -3,
      "name": "Rock_Ice"
    },
    {
      "x": -17,
      "y": 98,
      "z": -3,
      "name": "Rock_Ice"
    },
    {
      "x": -17,
      "y": 99,
      "z": -3,
      "name": "Rock_Ice"
    },
    {
      "x": -17,
      "y": 100,
      "z": -3,
      "name": "Rock_Ice"
    },
    {
      "x": -17,
      "y": 101,
      "z": -3,
      "name": "Rock_Ice"
    },
    {
      "x": -17,
      "y": 102,
      "z": -3,
      "name": "Rock_Ice"
    },
    {
      "x": -17,
      "y": 103,
      "z": -3,
      "name": "Rock_Ice"
    },
    {
      "x": -17,
      "y": 104,
      "z": -3,
      "name": "Rock_Ice"
    },
    {
      "x": -17,
      "y": 105,
      "z": -3,
      "name": "Rock_Ice"
    },
    {
      "x": -17,
      "y": 106,
      "z": -3,
      "name": "Rock_Ice"
    },
    {
      "x": -17,
      "y": 107,
      "z": -3,
      "name": "Rock_Ice"
    },
    {
      "x": -17,
      "y": 108,
      "z": -3,
      "name": "Rock_Ice"
    },
    {
      "x": -17,
      "y": 109,
      "z": -3,
      "name": "Rock_Ice"
    },
    {
      "x": -17,
      "y": 110,
      "z": -3,
      "name": "Rock_Ice"
    },
    {
      "x": -17,
      "y": 111,
      "z": -3,
      "name": "Rock_Ice"
    },
    {
      "x": -17,
      "y": 112,
      "z": -3,
      "name": "Rock_Ice"
    },
    {
      "x": -17,
      "y": 113,
      "z": -3,
      "name": "Rock_Ice"
    },
    {
      "x": -17,
      "y": 114,
      "z": -3,
      "name": "Soil_Snow"
    },
    {
      "x": -17,
      "y": 57,
      "z": -2,
      "name": "Rock_Ice"
    },
    {
      "x": -17,
      "y": 58,
      "z": -2,
      "name": "Rock_Ice"
    },
    {
      "x": -17,
      "y": 59,
      "z": -2,
      "name": "Rock_Ice"
    },
    {
      "x": -17,
      "y": 60,
      "z": -2,
      "name": "Rock_Ice"
    },
    {
      "x": -17,
      "y": 61,
      "z": -2,
      "name": "Rock_Ice"
    },
    {
      "x": -17,
      "y": 62,
      "z": -2,
      "name": "Rock_Ice"
    },
    {
      "x": -17,
      "y": 63,
      "z": -2,
      "name": "Rock_Ice"
    },
    {
      "x": -17,
      "y": 77,
      "z": -2,
      "name": "Rock_Ice"
    },
    {
      "x": -17,
      "y": 81,
      "z": -2,
      "name": "Rock_Ice_Permafrost"
    },
    {
      "x": -17,
      "y": 82,
      "z": -2,
      "name": "Rock_Ice_Permafrost"
    },
    {
      "x": -17,
      "y": 83,
      "z": -2,
      "name": "Rock_Crystal_Cyan_Block_WhiteLight"
    },
    {
      "x": -17,
      "y": 84,
      "z": -2,
      "name": "Rock_Ice_Permafrost"
    },
    {
      "x": -17,
      "y": 85,
      "z": -2,
      "name": "Rock_Ice_Permafrost"
    },
    {
      "x": -17,
      "y": 86,
      "z": -2,
      "name": "Rock_Ice"
    },
    {
      "x": -17,
      "y": 87,
      "z": -2,
      "name": "Rock_Ice"
    },
    {
      "x": -17,
      "y": 88,
      "z": -2,
      "name": "Rock_Ice"
    },
    {
      "x": -17,
      "y": 89,
      "z": -2,
      "name": "Rock_Ice"
    },
    {
      "x": -17,
      "y": 90,
      "z": -2,
      "name": "Rock_Ice"
    },
    {
      "x": -17,
      "y": 91,
      "z": -2,
      "name": "Rock_Ice"
    },
    {
      "x": -17,
      "y": 92,
      "z": -2,
      "name": "Rock_Ice"
    },
    {
      "x": -17,
      "y": 93,
      "z": -2,
      "name": "Rock_Ice"
    },
    {
      "x": -17,
      "y": 94,
      "z": -2,
      "name": "Rock_Ice"
    },
    {
      "x": -17,
      "y": 95,
      "z": -2,
      "name": "Rock_Ice"
    },
    {
      "x": -17,
      "y": 96,
      "z": -2,
      "name": "Rock_Ice"
    },
    {
      "x": -17,
      "y": 97,
      "z": -2,
      "name": "Rock_Ice"
    },
    {
      "x": -17,
      "y": 98,
      "z": -2,
      "name": "Rock_Ice"
    },
    {
      "x": -17,
      "y": 99,
      "z": -2,
      "name": "Rock_Ice"
    },
    {
      "x": -17,
      "y": 100,
      "z": -2,
      "name": "Rock_Ice"
    },
    {
      "x": -17,
      "y": 101,
      "z": -2,
      "name": "Rock_Ice"
    },
    {
      "x": -17,
      "y": 102,
      "z": -2,
      "name": "Rock_Ice"
    },
    {
      "x": -17,
      "y": 103,
      "z": -2,
      "name": "Rock_Ice"
    },
    {
      "x": -17,
      "y": 104,
      "z": -2,
      "name": "Rock_Ice"
    },
    {
      "x": -17,
      "y": 105,
      "z": -2,
      "name": "Rock_Ice"
    },
    {
      "x": -17,
      "y": 106,
      "z": -2,
      "name": "Rock_Ice"
    },
    {
      "x": -17,
      "y": 107,
      "z": -2,
      "name": "Rock_Ice"
    },
    {
      "x": -17,
      "y": 108,
      "z": -2,
      "name": "Rock_Ice"
    },
    {
      "x": -17,
      "y": 109,
      "z": -2,
      "name": "Soil_Snow"
    },
    {
      "x": -17,
      "y": 61,
      "z": -1,
      "name": "Rock_Ice"
    },
    {
      "x": -17,
      "y": 62,
      "z": -1,
      "name": "Rock_Ice"
    },
    {
      "x": -17,
      "y": 77,
      "z": -1,
      "name": "Rock_Ice"
    },
    {
      "x": -17,
      "y": 78,
      "z": -1,
      "name": "Rock_Ice"
    },
    {
      "x": -17,
      "y": 79,
      "z": -1,
      "name": "Rock_Ice"
    },
    {
      "x": -17,
      "y": 80,
      "z": -1,
      "name": "Rock_Ice_Permafrost"
    },
    {
      "x": -17,
      "y": 81,
      "z": -1,
      "name": "Rock_Ice_Permafrost"
    },
    {
      "x": -17,
      "y": 82,
      "z": -1,
      "name": "Rock_Ice_Permafrost"
    },
    {
      "x": -17,
      "y": 83,
      "z": -1,
      "name": "Rock_Ice_Permafrost"
    },
    {
      "x": -17,
      "y": 84,
      "z": -1,
      "name": "Rock_Ice_Permafrost"
    },
    {
      "x": -17,
      "y": 85,
      "z": -1,
      "name": "Rock_Ice"
    },
    {
      "x": -17,
      "y": 86,
      "z": -1,
      "name": "Rock_Ice_Permafrost"
    },
    {
      "x": -17,
      "y": 87,
      "z": -1,
      "name": "Rock_Ice"
    },
    {
      "x": -17,
      "y": 88,
      "z": -1,
      "name": "Rock_Ice"
    },
    {
      "x": -17,
      "y": 89,
      "z": -1,
      "name": "Rock_Ice"
    },
    {
      "x": -17,
      "y": 90,
      "z": -1,
      "name": "Rock_Ice"
    },
    {
      "x": -17,
      "y": 91,
      "z": -1,
      "name": "Rock_Ice"
    },
    {
      "x": -17,
      "y": 92,
      "z": -1,
      "name": "Rock_Ice"
    },
    {
      "x": -17,
      "y": 93,
      "z": -1,
      "name": "Rock_Ice"
    },
    {
      "x": -17,
      "y": 94,
      "z": -1,
      "name": "Rock_Ice"
    },
    {
      "x": -17,
      "y": 95,
      "z": -1,
      "name": "Rock_Ice"
    },
    {
      "x": -17,
      "y": 96,
      "z": -1,
      "name": "Rock_Ice"
    },
    {
      "x": -17,
      "y": 97,
      "z": -1,
      "name": "Rock_Ice"
    },
    {
      "x": -17,
      "y": 98,
      "z": -1,
      "name": "Rock_Ice"
    },
    {
      "x": -17,
      "y": 99,
      "z": -1,
      "name": "Rock_Ice"
    },
    {
      "x": -17,
      "y": 100,
      "z": -1,
      "name": "Rock_Ice"
    },
    {
      "x": -17,
      "y": 101,
      "z": -1,
      "name": "Rock_Ice"
    },
    {
      "x": -17,
      "y": 102,
      "z": -1,
      "name": "Rock_Ice_Permafrost"
    },
    {
      "x": -17,
      "y": 103,
      "z": -1,
      "name": "Rock_Ice"
    },
    {
      "x": -17,
      "y": 104,
      "z": -1,
      "name": "Rock_Ice_Permafrost"
    },
    {
      "x": -17,
      "y": 105,
      "z": -1,
      "name": "Rock_Ice"
    },
    {
      "x": -17,
      "y": 106,
      "z": -1,
      "name": "Soil_Snow"
    },
    {
      "x": -17,
      "y": 76,
      "z": 0,
      "name": "Rock_Ice"
    },
    {
      "x": -17,
      "y": 77,
      "z": 0,
      "name": "Rock_Ice"
    },
    {
      "x": -17,
      "y": 78,
      "z": 0,
      "name": "Rock_Ice"
    },
    {
      "x": -17,
      "y": 79,
      "z": 0,
      "name": "Rock_Ice_Permafrost"
    },
    {
      "x": -17,
      "y": 80,
      "z": 0,
      "name": "Rock_Crystal_Cyan_Block_WhiteLight"
    },
    {
      "x": -17,
      "y": 81,
      "z": 0,
      "name": "Rock_Crystal_Cyan_Block_WhiteLight"
    },
    {
      "x": -17,
      "y": 82,
      "z": 0,
      "name": "Rock_Crystal_Cyan_Block_WhiteLight"
    },
    {
      "x": -17,
      "y": 83,
      "z": 0,
      "name": "Rock_Ice_Permafrost"
    },
    {
      "x": -17,
      "y": 84,
      "z": 0,
      "name": "Rock_Ice_Permafrost"
    },
    {
      "x": -17,
      "y": 85,
      "z": 0,
      "name": "Rock_Ice"
    },
    {
      "x": -17,
      "y": 86,
      "z": 0,
      "name": "Rock_Ice"
    },
    {
      "x": -17,
      "y": 87,
      "z": 0,
      "name": "Rock_Ice"
    },
    {
      "x": -17,
      "y": 88,
      "z": 0,
      "name": "Rock_Ice"
    },
    {
      "x": -17,
      "y": 89,
      "z": 0,
      "name": "Rock_Ice"
    },
    {
      "x": -17,
      "y": 90,
      "z": 0,
      "name": "Rock_Ice"
    },
    {
      "x": -17,
      "y": 91,
      "z": 0,
      "name": "Rock_Ice"
    },
    {
      "x": -17,
      "y": 92,
      "z": 0,
      "name": "Rock_Ice"
    },
    {
      "x": -17,
      "y": 93,
      "z": 0,
      "name": "Rock_Ice"
    },
    {
      "x": -17,
      "y": 94,
      "z": 0,
      "name": "Rock_Ice"
    },
    {
      "x": -17,
      "y": 95,
      "z": 0,
      "name": "Rock_Ice"
    },
    {
      "x": -17,
      "y": 96,
      "z": 0,
      "name": "Rock_Ice"
    },
    {
      "x": -17,
      "y": 97,
      "z": 0,
      "name": "Rock_Ice"
    },
    {
      "x": -17,
      "y": 98,
      "z": 0,
      "name": "Rock_Ice"
    },
    {
      "x": -17,
      "y": 99,
      "z": 0,
      "name": "Rock_Ice"
    },
    {
      "x": -17,
      "y": 100,
      "z": 0,
      "name": "Rock_Ice_Permafrost"
    },
    {
      "x": -17,
      "y": 101,
      "z": 0,
      "name": "Rock_Ice"
    },
    {
      "x": -17,
      "y": 102,
      "z": 0,
      "name": "Rock_Ice"
    },
    {
      "x": -17,
      "y": 103,
      "z": 0,
      "name": "Rock_Ice"
    },
    {
      "x": -17,
      "y": 104,
      "z": 0,
      "name": "Soil_Snow"
    },
    {
      "x": -17,
      "y": 76,
      "z": 1,
      "name": "Rock_Ice"
    },
    {
      "x": -17,
      "y": 77,
      "z": 1,
      "name": "Rock_Ice"
    },
    {
      "x": -17,
      "y": 81,
      "z": 1,
      "name": "Rock_Ice_Permafrost"
    },
    {
      "x": -17,
      "y": 82,
      "z": 1,
      "name": "Rock_Ice_Permafrost"
    },
    {
      "x": -17,
      "y": 83,
      "z": 1,
      "name": "Rock_Ice_Permafrost"
    },
    {
      "x": -17,
      "y": 84,
      "z": 1,
      "name": "Rock_Ice"
    },
    {
      "x": -17,
      "y": 85,
      "z": 1,
      "name": "Rock_Ice"
    },
    {
      "x": -17,
      "y": 86,
      "z": 1,
      "name": "Rock_Ice"
    },
    {
      "x": -17,
      "y": 87,
      "z": 1,
      "name": "Rock_Ice"
    },
    {
      "x": -17,
      "y": 90,
      "z": 1,
      "name": "Rock_Ice"
    },
    {
      "x": -17,
      "y": 91,
      "z": 1,
      "name": "Rock_Ice"
    },
    {
      "x": -17,
      "y": 92,
      "z": 1,
      "name": "Rock_Ice"
    },
    {
      "x": -17,
      "y": 93,
      "z": 1,
      "name": "Rock_Ice"
    },
    {
      "x": -17,
      "y": 94,
      "z": 1,
      "name": "Rock_Ice"
    },
    {
      "x": -17,
      "y": 95,
      "z": 1,
      "name": "Rock_Ice"
    },
    {
      "x": -17,
      "y": 96,
      "z": 1,
      "name": "Rock_Ice"
    },
    {
      "x": -17,
      "y": 97,
      "z": 1,
      "name": "Rock_Ice"
    },
    {
      "x": -17,
      "y": 98,
      "z": 1,
      "name": "Rock_Ice"
    },
    {
      "x": -17,
      "y": 99,
      "z": 1,
      "name": "Rock_Ice"
    },
    {
      "x": -17,
      "y": 100,
      "z": 1,
      "name": "Rock_Ice_Permafrost"
    },
    {
      "x": -17,
      "y": 101,
      "z": 1,
      "name": "Rock_Ice"
    },
    {
      "x": -17,
      "y": 102,
      "z": 1,
      "name": "Soil_Snow"
    },
    {
      "x": -17,
      "y": 92,
      "z": 2,
      "name": "Rock_Ice"
    },
    {
      "x": -17,
      "y": 93,
      "z": 2,
      "name": "Rock_Ice"
    },
    {
      "x": -17,
      "y": 94,
      "z": 2,
      "name": "Rock_Ice"
    },
    {
      "x": -17,
      "y": 95,
      "z": 2,
      "name": "Rock_Ice_Permafrost"
    },
    {
      "x": -17,
      "y": 96,
      "z": 2,
      "name": "Rock_Ice"
    },
    {
      "x": -17,
      "y": 97,
      "z": 2,
      "name": "Rock_Ice"
    },
    {
      "x": -17,
      "y": 98,
      "z": 2,
      "name": "Rock_Ice"
    },
    {
      "x": -17,
      "y": 99,
      "z": 2,
      "name": "Rock_Ice"
    },
    {
      "x": -17,
      "y": 100,
      "z": 2,
      "name": "Soil_Snow"
    },
    {
      "x": -17,
      "y": 94,
      "z": 3,
      "name": "Rock_Ice"
    },
    {
      "x": -17,
      "y": 95,
      "z": 3,
      "name": "Rock_Ice"
    },
    {
      "x": -17,
      "y": 96,
      "z": 3,
      "name": "Rock_Ice"
    },
    {
      "x": -17,
      "y": 97,
      "z": 3,
      "name": "Rock_Ice"
    },
    {
      "x": -17,
      "y": 98,
      "z": 3,
      "name": "Rock_Ice"
    },
    {
      "x": -17,
      "y": 99,
      "z": 3,
      "name": "Soil_Snow"
    },
    {
      "x": -17,
      "y": 97,
      "z": 4,
      "name": "Rock_Ice_Permafrost"
    },
    {
      "x": -17,
      "y": 98,
      "z": 4,
      "name": "Soil_Snow"
    },
    {
      "x": -16,
      "y": 109,
      "z": -14,
      "name": "Rock_Ice"
    },
    {
      "x": -16,
      "y": 110,
      "z": -14,
      "name": "Rock_Ice"
    },
    {
      "x": -16,
      "y": 111,
      "z": -14,
      "name": "Rock_Ice"
    },
    {
      "x": -16,
      "y": 112,
      "z": -14,
      "name": "Rock_Ice"
    },
    {
      "x": -16,
      "y": 113,
      "z": -14,
      "name": "Rock_Ice"
    },
    {
      "x": -16,
      "y": 114,
      "z": -14,
      "name": "Rock_Ice"
    },
    {
      "x": -16,
      "y": 115,
      "z": -14,
      "name": "Rock_Ice"
    },
    {
      "x": -16,
      "y": 116,
      "z": -14,
      "name": "Soil_Snow"
    },
    {
      "x": -16,
      "y": 30,
      "z": -13,
      "name": "Rock_Ice"
    },
    {
      "x": -16,
      "y": 31,
      "z": -13,
      "name": "Rock_Ice"
    },
    {
      "x": -16,
      "y": 32,
      "z": -13,
      "name": "Soil_Snow"
    },
    {
      "x": -16,
      "y": 103,
      "z": -13,
      "name": "Rock_Ice"
    },
    {
      "x": -16,
      "y": 104,
      "z": -13,
      "name": "Rock_Ice"
    },
    {
      "x": -16,
      "y": 105,
      "z": -13,
      "name": "Rock_Ice"
    },
    {
      "x": -16,
      "y": 106,
      "z": -13,
      "name": "Rock_Ice"
    },
    {
      "x": -16,
      "y": 107,
      "z": -13,
      "name": "Rock_Ice"
    },
    {
      "x": -16,
      "y": 108,
      "z": -13,
      "name": "Rock_Ice"
    },
    {
      "x": -16,
      "y": 109,
      "z": -13,
      "name": "Rock_Ice"
    },
    {
      "x": -16,
      "y": 110,
      "z": -13,
      "name": "Rock_Ice"
    },
    {
      "x": -16,
      "y": 111,
      "z": -13,
      "name": "Rock_Ice"
    },
    {
      "x": -16,
      "y": 112,
      "z": -13,
      "name": "Rock_Ice"
    },
    {
      "x": -16,
      "y": 113,
      "z": -13,
      "name": "Rock_Ice"
    },
    {
      "x": -16,
      "y": 114,
      "z": -13,
      "name": "Rock_Ice"
    },
    {
      "x": -16,
      "y": 115,
      "z": -13,
      "name": "Rock_Ice"
    },
    {
      "x": -16,
      "y": 116,
      "z": -13,
      "name": "Rock_Ice"
    },
    {
      "x": -16,
      "y": 117,
      "z": -13,
      "name": "Soil_Snow"
    },
    {
      "x": -16,
      "y": 30,
      "z": -12,
      "name": "Rock_Ice"
    },
    {
      "x": -16,
      "y": 31,
      "z": -12,
      "name": "Rock_Ice"
    },
    {
      "x": -16,
      "y": 32,
      "z": -12,
      "name": "Rock_Ice"
    },
    {
      "x": -16,
      "y": 33,
      "z": -12,
      "name": "Soil_Snow"
    },
    {
      "x": -16,
      "y": 100,
      "z": -12,
      "name": "Rock_Ice"
    },
    {
      "x": -16,
      "y": 101,
      "z": -12,
      "name": "Rock_Ice"
    },
    {
      "x": -16,
      "y": 102,
      "z": -12,
      "name": "Rock_Ice"
    },
    {
      "x": -16,
      "y": 103,
      "z": -12,
      "name": "Rock_Ice"
    },
    {
      "x": -16,
      "y": 104,
      "z": -12,
      "name": "Rock_Ice"
    },
    {
      "x": -16,
      "y": 105,
      "z": -12,
      "name": "Rock_Ice"
    },
    {
      "x": -16,
      "y": 106,
      "z": -12,
      "name": "Rock_Ice"
    },
    {
      "x": -16,
      "y": 107,
      "z": -12,
      "name": "Rock_Ice"
    },
    {
      "x": -16,
      "y": 108,
      "z": -12,
      "name": "Rock_Ice"
    },
    {
      "x": -16,
      "y": 109,
      "z": -12,
      "name": "Rock_Ice"
    },
    {
      "x": -16,
      "y": 110,
      "z": -12,
      "name": "Rock_Ice"
    },
    {
      "x": -16,
      "y": 111,
      "z": -12,
      "name": "Rock_Ice"
    },
    {
      "x": -16,
      "y": 112,
      "z": -12,
      "name": "Rock_Ice"
    },
    {
      "x": -16,
      "y": 113,
      "z": -12,
      "name": "Rock_Ice"
    },
    {
      "x": -16,
      "y": 114,
      "z": -12,
      "name": "Rock_Ice"
    },
    {
      "x": -16,
      "y": 115,
      "z": -12,
      "name": "Rock_Ice"
    },
    {
      "x": -16,
      "y": 116,
      "z": -12,
      "name": "Rock_Ice"
    },
    {
      "x": -16,
      "y": 117,
      "z": -12,
      "name": "Rock_Ice"
    },
    {
      "x": -16,
      "y": 118,
      "z": -12,
      "name": "Rock_Ice"
    },
    {
      "x": -16,
      "y": 119,
      "z": -12,
      "name": "Soil_Snow"
    },
    {
      "x": -16,
      "y": 29,
      "z": -11,
      "name": "Rock_Ice"
    },
    {
      "x": -16,
      "y": 30,
      "z": -11,
      "name": "Rock_Ice"
    },
    {
      "x": -16,
      "y": 31,
      "z": -11,
      "name": "Rock_Ice"
    },
    {
      "x": -16,
      "y": 32,
      "z": -11,
      "name": "Rock_Ice"
    },
    {
      "x": -16,
      "y": 33,
      "z": -11,
      "name": "Soil_Snow"
    },
    {
      "x": -16,
      "y": 95,
      "z": -11,
      "name": "Rock_Ice"
    },
    {
      "x": -16,
      "y": 96,
      "z": -11,
      "name": "Rock_Ice"
    },
    {
      "x": -16,
      "y": 97,
      "z": -11,
      "name": "Rock_Ice"
    },
    {
      "x": -16,
      "y": 98,
      "z": -11,
      "name": "Rock_Ice"
    },
    {
      "x": -16,
      "y": 99,
      "z": -11,
      "name": "Rock_Ice"
    },
    {
      "x": -16,
      "y": 100,
      "z": -11,
      "name": "Rock_Ice"
    },
    {
      "x": -16,
      "y": 101,
      "z": -11,
      "name": "Rock_Ice"
    },
    {
      "x": -16,
      "y": 102,
      "z": -11,
      "name": "Rock_Ice"
    },
    {
      "x": -16,
      "y": 103,
      "z": -11,
      "name": "Rock_Ice"
    },
    {
      "x": -16,
      "y": 104,
      "z": -11,
      "name": "Rock_Ice"
    },
    {
      "x": -16,
      "y": 105,
      "z": -11,
      "name": "Rock_Ice"
    },
    {
      "x": -16,
      "y": 106,
      "z": -11,
      "name": "Rock_Ice"
    },
    {
      "x": -16,
      "y": 107,
      "z": -11,
      "name": "Rock_Ice"
    },
    {
      "x": -16,
      "y": 108,
      "z": -11,
      "name": "Rock_Ice"
    },
    {
      "x": -16,
      "y": 109,
      "z": -11,
      "name": "Rock_Ice"
    },
    {
      "x": -16,
      "y": 110,
      "z": -11,
      "name": "Rock_Ice"
    },
    {
      "x": -16,
      "y": 111,
      "z": -11,
      "name": "Rock_Ice"
    },
    {
      "x": -16,
      "y": 112,
      "z": -11,
      "name": "Rock_Ice"
    },
    {
      "x": -16,
      "y": 113,
      "z": -11,
      "name": "Rock_Ice"
    },
    {
      "x": -16,
      "y": 114,
      "z": -11,
      "name": "Rock_Ice"
    },
    {
      "x": -16,
      "y": 115,
      "z": -11,
      "name": "Rock_Ice"
    },
    {
      "x": -16,
      "y": 116,
      "z": -11,
      "name": "Rock_Ice"
    },
    {
      "x": -16,
      "y": 117,
      "z": -11,
      "name": "Rock_Ice"
    },
    {
      "x": -16,
      "y": 118,
      "z": -11,
      "name": "Rock_Ice"
    },
    {
      "x": -16,
      "y": 119,
      "z": -11,
      "name": "Rock_Ice"
    },
    {
      "x": -16,
      "y": 120,
      "z": -11,
      "name": "Soil_Snow"
    },
    {
      "x": -16,
      "y": 29,
      "z": -10,
      "name": "Rock_Ice"
    },
    {
      "x": -16,
      "y": 30,
      "z": -10,
      "name": "Rock_Ice"
    },
    {
      "x": -16,
      "y": 31,
      "z": -10,
      "name": "Rock_Ice"
    },
    {
      "x": -16,
      "y": 32,
      "z": -10,
      "name": "Rock_Ice"
    },
    {
      "x": -16,
      "y": 33,
      "z": -10,
      "name": "Rock_Ice"
    },
    {
      "x": -16,
      "y": 34,
      "z": -10,
      "name": "Soil_Snow"
    },
    {
      "x": -16,
      "y": 92,
      "z": -10,
      "name": "Rock_Ice_Permafrost"
    },
    {
      "x": -16,
      "y": 93,
      "z": -10,
      "name": "Rock_Ice_Permafrost"
    },
    {
      "x": -16,
      "y": 94,
      "z": -10,
      "name": "Rock_Ice_Permafrost"
    },
    {
      "x": -16,
      "y": 95,
      "z": -10,
      "name": "Rock_Ice_Permafrost"
    },
    {
      "x": -16,
      "y": 96,
      "z": -10,
      "name": "Rock_Ice"
    },
    {
      "x": -16,
      "y": 97,
      "z": -10,
      "name": "Rock_Ice"
    },
    {
      "x": -16,
      "y": 98,
      "z": -10,
      "name": "Rock_Ice"
    },
    {
      "x": -16,
      "y": 99,
      "z": -10,
      "name": "Rock_Ice"
    },
    {
      "x": -16,
      "y": 100,
      "z": -10,
      "name": "Rock_Ice"
    },
    {
      "x": -16,
      "y": 101,
      "z": -10,
      "name": "Rock_Ice"
    },
    {
      "x": -16,
      "y": 102,
      "z": -10,
      "name": "Rock_Ice"
    },
    {
      "x": -16,
      "y": 103,
      "z": -10,
      "name": "Rock_Ice"
    },
    {
      "x": -16,
      "y": 104,
      "z": -10,
      "name": "Rock_Ice"
    },
    {
      "x": -16,
      "y": 105,
      "z": -10,
      "name": "Rock_Ice"
    },
    {
      "x": -16,
      "y": 106,
      "z": -10,
      "name": "Rock_Ice"
    },
    {
      "x": -16,
      "y": 107,
      "z": -10,
      "name": "Rock_Ice"
    },
    {
      "x": -16,
      "y": 108,
      "z": -10,
      "name": "Rock_Ice"
    },
    {
      "x": -16,
      "y": 109,
      "z": -10,
      "name": "Rock_Ice"
    },
    {
      "x": -16,
      "y": 110,
      "z": -10,
      "name": "Rock_Ice"
    },
    {
      "x": -16,
      "y": 111,
      "z": -10,
      "name": "Rock_Ice"
    },
    {
      "x": -16,
      "y": 112,
      "z": -10,
      "name": "Rock_Ice"
    },
    {
      "x": -16,
      "y": 113,
      "z": -10,
      "name": "Rock_Ice"
    },
    {
      "x": -16,
      "y": 114,
      "z": -10,
      "name": "Rock_Ice"
    },
    {
      "x": -16,
      "y": 115,
      "z": -10,
      "name": "Rock_Ice"
    },
    {
      "x": -16,
      "y": 116,
      "z": -10,
      "name": "Rock_Ice"
    },
    {
      "x": -16,
      "y": 117,
      "z": -10,
      "name": "Rock_Ice"
    },
    {
      "x": -16,
      "y": 118,
      "z": -10,
      "name": "Rock_Ice"
    },
    {
      "x": -16,
      "y": 119,
      "z": -10,
      "name": "Soil_Snow"
    },
    {
      "x": -16,
      "y": 29,
      "z": -9,
      "name": "Rock_Ice"
    },
    {
      "x": -16,
      "y": 30,
      "z": -9,
      "name": "Rock_Ice"
    },
    {
      "x": -16,
      "y": 31,
      "z": -9,
      "name": "Rock_Ice"
    },
    {
      "x": -16,
      "y": 32,
      "z": -9,
      "name": "Rock_Ice"
    },
    {
      "x": -16,
      "y": 33,
      "z": -9,
      "name": "Rock_Ice"
    },
    {
      "x": -16,
      "y": 34,
      "z": -9,
      "name": "Soil_Snow"
    },
    {
      "x": -16,
      "y": 63,
      "z": -9,
      "name": "Soil_Snow"
    },
    {
      "x": -16,
      "y": 88,
      "z": -9,
      "name": "Rock_Ice_Permafrost"
    },
    {
      "x": -16,
      "y": 89,
      "z": -9,
      "name": "Rock_Ice_Permafrost"
    },
    {
      "x": -16,
      "y": 90,
      "z": -9,
      "name": "Rock_Ice_Permafrost"
    },
    {
      "x": -16,
      "y": 91,
      "z": -9,
      "name": "Rock_Ice"
    },
    {
      "x": -16,
      "y": 92,
      "z": -9,
      "name": "Rock_Ice"
    },
    {
      "x": -16,
      "y": 93,
      "z": -9,
      "name": "Rock_Ice_Permafrost"
    },
    {
      "x": -16,
      "y": 94,
      "z": -9,
      "name": "Rock_Ice_Permafrost"
    },
    {
      "x": -16,
      "y": 95,
      "z": -9,
      "name": "Rock_Ice"
    },
    {
      "x": -16,
      "y": 96,
      "z": -9,
      "name": "Rock_Ice"
    },
    {
      "x": -16,
      "y": 97,
      "z": -9,
      "name": "Rock_Ice"
    },
    {
      "x": -16,
      "y": 98,
      "z": -9,
      "name": "Rock_Ice"
    },
    {
      "x": -16,
      "y": 99,
      "z": -9,
      "name": "Rock_Ice"
    },
    {
      "x": -16,
      "y": 100,
      "z": -9,
      "name": "Rock_Ice"
    },
    {
      "x": -16,
      "y": 101,
      "z": -9,
      "name": "Rock_Ice"
    },
    {
      "x": -16,
      "y": 102,
      "z": -9,
      "name": "Rock_Ice"
    },
    {
      "x": -16,
      "y": 103,
      "z": -9,
      "name": "Rock_Ice"
    },
    {
      "x": -16,
      "y": 104,
      "z": -9,
      "name": "Rock_Ice"
    },
    {
      "x": -16,
      "y": 105,
      "z": -9,
      "name": "Rock_Ice"
    },
    {
      "x": -16,
      "y": 106,
      "z": -9,
      "name": "Rock_Ice"
    },
    {
      "x": -16,
      "y": 107,
      "z": -9,
      "name": "Rock_Ice"
    },
    {
      "x": -16,
      "y": 108,
      "z": -9,
      "name": "Rock_Ice"
    },
    {
      "x": -16,
      "y": 109,
      "z": -9,
      "name": "Rock_Ice"
    },
    {
      "x": -16,
      "y": 110,
      "z": -9,
      "name": "Rock_Ice"
    },
    {
      "x": -16,
      "y": 111,
      "z": -9,
      "name": "Rock_Ice"
    },
    {
      "x": -16,
      "y": 112,
      "z": -9,
      "name": "Rock_Ice"
    },
    {
      "x": -16,
      "y": 113,
      "z": -9,
      "name": "Rock_Ice"
    },
    {
      "x": -16,
      "y": 114,
      "z": -9,
      "name": "Rock_Ice"
    },
    {
      "x": -16,
      "y": 115,
      "z": -9,
      "name": "Rock_Ice"
    },
    {
      "x": -16,
      "y": 116,
      "z": -9,
      "name": "Rock_Ice"
    },
    {
      "x": -16,
      "y": 117,
      "z": -9,
      "name": "Rock_Ice"
    },
    {
      "x": -16,
      "y": 118,
      "z": -9,
      "name": "Rock_Ice"
    },
    {
      "x": -16,
      "y": 119,
      "z": -9,
      "name": "Soil_Snow"
    },
    {
      "x": -16,
      "y": 28,
      "z": -8,
      "name": "Rock_Ice_Permafrost"
    },
    {
      "x": -16,
      "y": 29,
      "z": -8,
      "name": "Rock_Ice"
    },
    {
      "x": -16,
      "y": 30,
      "z": -8,
      "name": "Rock_Ice"
    },
    {
      "x": -16,
      "y": 31,
      "z": -8,
      "name": "Rock_Ice"
    },
    {
      "x": -16,
      "y": 32,
      "z": -8,
      "name": "Rock_Ice"
    },
    {
      "x": -16,
      "y": 33,
      "z": -8,
      "name": "Rock_Ice"
    },
    {
      "x": -16,
      "y": 34,
      "z": -8,
      "name": "Rock_Ice"
    },
    {
      "x": -16,
      "y": 35,
      "z": -8,
      "name": "Soil_Snow"
    },
    {
      "x": -16,
      "y": 58,
      "z": -8,
      "name": "Rock_Ice"
    },
    {
      "x": -16,
      "y": 59,
      "z": -8,
      "name": "Rock_Ice"
    },
    {
      "x": -16,
      "y": 60,
      "z": -8,
      "name": "Rock_Ice"
    },
    {
      "x": -16,
      "y": 61,
      "z": -8,
      "name": "Rock_Ice"
    },
    {
      "x": -16,
      "y": 62,
      "z": -8,
      "name": "Rock_Ice"
    },
    {
      "x": -16,
      "y": 63,
      "z": -8,
      "name": "Rock_Ice"
    },
    {
      "x": -16,
      "y": 64,
      "z": -8,
      "name": "Rock_Ice"
    },
    {
      "x": -16,
      "y": 65,
      "z": -8,
      "name": "Soil_Snow"
    },
    {
      "x": -16,
      "y": 86,
      "z": -8,
      "name": "Rock_Ice_Permafrost"
    },
    {
      "x": -16,
      "y": 87,
      "z": -8,
      "name": "Rock_Ice_Permafrost"
    },
    {
      "x": -16,
      "y": 88,
      "z": -8,
      "name": "Rock_Ice_Permafrost"
    },
    {
      "x": -16,
      "y": 89,
      "z": -8,
      "name": "Rock_Ice_Permafrost"
    },
    {
      "x": -16,
      "y": 90,
      "z": -8,
      "name": "Rock_Ice_Permafrost"
    },
    {
      "x": -16,
      "y": 91,
      "z": -8,
      "name": "Rock_Ice_Permafrost"
    },
    {
      "x": -16,
      "y": 92,
      "z": -8,
      "name": "Rock_Ice"
    },
    {
      "x": -16,
      "y": 93,
      "z": -8,
      "name": "Rock_Ice"
    },
    {
      "x": -16,
      "y": 94,
      "z": -8,
      "name": "Rock_Ice"
    },
    {
      "x": -16,
      "y": 95,
      "z": -8,
      "name": "Rock_Ice"
    },
    {
      "x": -16,
      "y": 96,
      "z": -8,
      "name": "Rock_Ice"
