{
  "version": 8,
  "blockIdVersion": 11,
  "anchorX": 0,
  "anchorY": 0,
  "anchorZ": 0,
  "blocks": [
    {
      "x": -19,
      "y": 30,
      "z": 3,
      "name": "Rock_Ice"
    },
    {
      "x": -19,
      "y": 31,
      "z": 3,
      "name": "Soil_Snow"
    },
    {
      "x": -19,
      "y": 26,
      "z": 4,
      "name": "Rock_Ice_Icicles",
      "rotation": 8
    },
    {
      "x": -19,
      "y": 27,
      "z": 4,
      "name": "Rock_Ice_Permafrost"
    },
    {
      "x": -19,
      "y": 28,
      "z": 4,
      "name": "Rock_Ice_Permafrost"
    },
    {
      "x": -19,
      "y": 29,
      "z": 4,
      "name": "Rock_Ice"
    },
    {
      "x": -19,
      "y": 30,
      "z": 4,
      "name": "Soil_Snow"
    },
    {
      "x": -19,
      "y": 22,
      "z": 5,
      "name": "Rock_Ice"
    },
    {
      "x": -19,
      "y": 23,
      "z": 5,
      "name": "Rock_Ice"
    },
    {
      "x": -19,
      "y": 24,
      "z": 5,
      "name": "Rock_Ice_Permafrost"
    },
    {
      "x": -19,
      "y": 25,
      "z": 5,
      "name": "Rock_Crystal_Cyan_Block_WhiteLight"
    },
    {
      "x": -19,
      "y": 26,
      "z": 5,
      "name": "Rock_Ice_Permafrost"
    },
    {
      "x": -19,
      "y": 27,
      "z": 5,
      "name": "Rock_Ice_Permafrost"
    },
    {
      "x": -19,
      "y": 28,
      "z": 5,
      "name": "Rock_Ice"
    },
    {
      "x": -19,
      "y": 29,
      "z": 5,
      "name": "Soil_Snow"
    },
    {
      "x": -19,
      "y": 23,
      "z": 6,
      "name": "Rock_Ice"
    },
    {
      "x": -19,
      "y": 24,
      "z": 6,
      "name": "Rock_Ice_Permafrost"
    },
    {
      "x": -19,
      "y": 25,
      "z": 6,
      "name": "Rock_Ice"
    },
    {
      "x": -19,
      "y": 26,
      "z": 6,
      "name": "Soil_Snow"
    },
    {
      "x": -19,
      "y": 23,
      "z": 7,
      "name": "Rock_Ice_Permafrost"
    },
    {
      "x": -19,
      "y": 21,
      "z": 8,
      "name": "Rock_Ice"
    },
    {
      "x": -19,
      "y": 22,
      "z": 8,
      "name": "Soil_Snow"
    },
    {
      "x": -18,
      "y": 29,
      "z": 1,
      "name": "Rock_Ice_Permafrost"
    },
    {
      "x": -18,
      "y": 30,
      "z": 1,
      "name": "Rock_Ice"
    },
    {
      "x": -18,
      "y": 31,
      "z": 1,
      "name": "Soil_Snow"
    },
    {
      "x": -18,
      "y": 28,
      "z": 2,
      "name": "Rock_Ice_Permafrost"
    },
    {
      "x": -18,
      "y": 29,
      "z": 2,
      "name": "Rock_Ice"
    },
    {
      "x": -18,
      "y": 30,
      "z": 2,
      "name": "Rock_Ice"
    },
    {
      "x": -18,
      "y": 31,
      "z": 2,
      "name": "Rock_Ice"
    },
    {
      "x": -18,
      "y": 32,
      "z": 2,
      "name": "Soil_Snow"
    },
    {
      "x": -18,
      "y": 21,
      "z": 3,
      "name": "Rock_Ice"
    },
    {
      "x": -18,
      "y": 22,
      "z": 3,
      "name": "Rock_Ice"
    },
    {
      "x": -18,
      "y": 23,
      "z": 3,
      "name": "Rock_Ice"
    },
    {
      "x": -18,
      "y": 24,
      "z": 3,
      "name": "Rock_Ice_Permafrost"
    },
    {
      "x": -18,
      "y": 25,
      "z": 3,
      "name": "Rock_Ice_Permafrost"
    },
    {
      "x": -18,
      "y": 26,
      "z": 3,
      "name": "Rock_Ice_Permafrost"
    },
    {
      "x": -18,
      "y": 27,
      "z": 3,
      "name": "Rock_Ice_Permafrost"
    },
    {
      "x": -18,
      "y": 28,
      "z": 3,
      "name": "Rock_Ice_Permafrost"
    },
    {
      "x": -18,
      "y": 29,
      "z": 3,
      "name": "Rock_Ice"
    },
    {
      "x": -18,
      "y": 30,
      "z": 3,
      "name": "Rock_Ice"
    },
    {
      "x": -18,
      "y": 31,
      "z": 3,
      "name": "Rock_Ice"
    },
    {
      "x": -18,
      "y": 32,
      "z": 3,
      "name": "Soil_Snow"
    },
    {
      "x": -18,
      "y": 20,
      "z": 4,
      "name": "Rock_Ice"
    },
    {
      "x": -18,
      "y": 21,
      "z": 4,
      "name": "Rock_Ice"
    },
    {
      "x": -18,
      "y": 22,
      "z": 4,
      "name": "Rock_Ice"
    },
    {
      "x": -18,
      "y": 23,
      "z": 4,
      "name": "Rock_Ice"
    },
    {
      "x": -18,
      "y": 24,
      "z": 4,
      "name": "Rock_Ice_Permafrost"
    },
    {
      "x": -18,
      "y": 25,
      "z": 4,
      "name": "Rock_Crystal_Cyan_Block_WhiteLight"
    },
    {
      "x": -18,
      "y": 26,
      "z": 4,
      "name": "Rock_Ice_Permafrost"
    },
    {
      "x": -18,
      "y": 27,
      "z": 4,
      "name": "Rock_Ice_Permafrost"
    },
    {
      "x": -18,
      "y": 28,
      "z": 4,
      "name": "Rock_Ice"
    },
    {
      "x": -18,
      "y": 29,
      "z": 4,
      "name": "Rock_Ice"
    },
    {
      "x": -18,
      "y": 30,
      "z": 4,
      "name": "Rock_Ice"
    },
    {
      "x": -18,
      "y": 31,
      "z": 4,
      "name": "Rock_Ice"
    },
    {
      "x": -18,
      "y": 32,
      "z": 4,
      "name": "Rock_Ice"
    },
    {
      "x": -18,
      "y": 33,
      "z": 4,
      "name": "Soil_Snow"
    },
    {
      "x": -18,
      "y": 20,
      "z": 5,
      "name": "Rock_Ice"
    },
    {
      "x": -18,
      "y": 21,
      "z": 5,
      "name": "Rock_Ice"
    },
    {
      "x": -18,
      "y": 22,
      "z": 5,
      "name": "Rock_Ice"
    },
    {
      "x": -18,
      "y": 23,
      "z": 5,
      "name": "Rock_Ice"
    },
    {
      "x": -18,
      "y": 24,
      "z": 5,
      "name": "Rock_Ice_Permafrost"
    },
    {
      "x": -18,
      "y": 25,
      "z": 5,
      "name": "Rock_Ice_Permafrost"
    },
    {
      "x": -18,
      "y": 26,
      "z": 5,
      "name": "Rock_Crystal_Cyan_Block_WhiteLight"
    },
    {
      "x": -18,
      "y": 27,
      "z": 5,
      "name": "Rock_Crystal_Cyan_Block_WhiteLight"
    },
    {
      "x": -18,
      "y": 28,
      "z": 5,
      "name": "Rock_Crystal_Cyan_Block_WhiteLight"
    },
    {
      "x": -18,
      "y": 29,
      "z": 5,
      "name": "Rock_Ice_Permafrost"
    },
    {
      "x": -18,
      "y": 30,
      "z": 5,
      "name": "Rock_Ice"
    },
    {
      "x": -18,
      "y": 31,
      "z": 5,
      "name": "Rock_Ice"
    },
    {
      "x": -18,
      "y": 32,
      "z": 5,
      "name": "Rock_Ice"
    },
    {
      "x": -18,
      "y": 33,
      "z": 5,
      "name": "Soil_Snow"
    },
    {
      "x": -18,
      "y": 21,
      "z": 6,
      "name": "Rock_Ice"
    },
    {
      "x": -18,
      "y": 22,
      "z": 6,
      "name": "Rock_Ice"
    },
    {
      "x": -18,
      "y": 23,
      "z": 6,
      "name": "Rock_Ice"
    },
    {
      "x": -18,
      "y": 24,
      "z": 6,
      "name": "Rock_Ice_Permafrost"
    },
    {
      "x": -18,
      "y": 25,
      "z": 6,
      "name": "Rock_Ice_Permafrost"
    },
    {
      "x": -18,
      "y": 26,
      "z": 6,
      "name": "Rock_Ice_Permafrost"
    },
    {
      "x": -18,
      "y": 27,
      "z": 6,
      "name": "Rock_Ice_Permafrost"
    },
    {
      "x": -18,
      "y": 28,
      "z": 6,
      "name": "Rock_Ice_Permafrost"
    },
    {
      "x": -18,
      "y": 29,
      "z": 6,
      "name": "Rock_Ice"
    },
    {
      "x": -18,
      "y": 30,
      "z": 6,
      "name": "Rock_Ice"
    },
    {
      "x": -18,
      "y": 31,
      "z": 6,
      "name": "Rock_Ice"
    },
    {
      "x": -18,
      "y": 32,
      "z": 6,
      "name": "Rock_Ice"
    },
    {
      "x": -18,
      "y": 33,
      "z": 6,
      "name": "Rock_Ice"
    },
    {
      "x": -18,
      "y": 38,
      "z": 6,
      "name": "Rock_Ice"
    },
    {
      "x": -18,
      "y": 39,
      "z": 6,
      "name": "Soil_Snow"
    },
    {
      "x": -18,
      "y": 20,
      "z": 7,
      "name": "Rock_Ice"
    },
    {
      "x": -18,
      "y": 21,
      "z": 7,
      "name": "Rock_Ice"
    },
    {
      "x": -18,
      "y": 22,
      "z": 7,
      "name": "Rock_Ice_Permafrost"
    },
    {
      "x": -18,
      "y": 23,
      "z": 7,
      "name": "Rock_Ice"
    },
    {
      "x": -18,
      "y": 24,
      "z": 7,
      "name": "Rock_Ice"
    },
    {
      "x": -18,
      "y": 25,
      "z": 7,
      "name": "Rock_Ice"
    },
    {
      "x": -18,
      "y": 26,
      "z": 7,
      "name": "Rock_Ice"
    },
    {
      "x": -18,
      "y": 27,
      "z": 7,
      "name": "Rock_Ice"
    },
    {
      "x": -18,
      "y": 31,
      "z": 7,
      "name": "Rock_Ice"
    },
    {
      "x": -18,
      "y": 32,
      "z": 7,
      "name": "Rock_Ice"
    },
    {
      "x": -18,
      "y": 33,
      "z": 7,
      "name": "Rock_Ice"
    },
    {
      "x": -18,
      "y": 39,
      "z": 7,
      "name": "Rock_Ice"
    },
    {
      "x": -18,
      "y": 40,
      "z": 7,
      "name": "Soil_Snow"
    },
    {
      "x": -18,
      "y": 20,
      "z": 8,
      "name": "Rock_Ice"
    },
    {
      "x": -18,
      "y": 21,
      "z": 8,
      "name": "Rock_Ice"
    },
    {
      "x": -18,
      "y": 22,
      "z": 8,
      "name": "Rock_Ice"
    },
    {
      "x": -18,
      "y": 23,
      "z": 8,
      "name": "Rock_Ice"
    },
    {
      "x": -18,
      "y": 24,
      "z": 8,
      "name": "Rock_Ice"
    },
    {
      "x": -18,
      "y": 39,
      "z": 8,
      "name": "Rock_Ice"
    },
    {
      "x": -18,
      "y": 40,
      "z": 8,
      "name": "Rock_Ice"
    },
    {
      "x": -18,
      "y": 41,
      "z": 8,
      "name": "Rock_Ice"
    },
    {
      "x": -18,
      "y": 42,
      "z": 8,
      "name": "Soil_Snow"
    },
    {
      "x": -18,
      "y": 21,
      "z": 9,
      "name": "Rock_Ice"
    },
    {
      "x": -18,
      "y": 22,
      "z": 9,
      "name": "Soil_Snow"
    },
    {
      "x": -18,
      "y": 42,
      "z": 9,
      "name": "Rock_Ice"
    },
    {
      "x": -18,
      "y": 43,
      "z": 9,
      "name": "Soil_Snow"
    },
    {
      "x": -18,
      "y": 21,
      "z": 10,
      "name": "Rock_Ice"
    },
    {
      "x": -18,
      "y": 22,
      "z": 10,
      "name": "Soil_Snow"
    },
    {
      "x": -18,
      "y": 21,
      "z": 11,
      "name": "Soil_Snow"
    },
    {
      "x": -17,
      "y": 22,
      "z": -4,
      "name": "Rock_Ice"
    },
    {
      "x": -17,
      "y": 23,
      "z": -4,
      "name": "Rock_Ice"
    },
    {
      "x": -17,
      "y": 24,
      "z": -4,
      "name": "Rock_Ice"
    },
    {
      "x": -17,
      "y": 30,
      "z": -4,
      "name": "Soil_Snow"
    },
    {
      "x": -17,
      "y": 23,
      "z": -3,
      "name": "Rock_Ice"
    },
    {
      "x": -17,
      "y": 24,
      "z": -3,
      "name": "Rock_Ice"
    },
    {
      "x": -17,
      "y": 25,
      "z": -3,
      "name": "Rock_Ice"
    },
    {
      "x": -17,
      "y": 26,
      "z": -3,
      "name": "Soil_Snow"
    },
    {
      "x": -17,
      "y": 23,
      "z": -2,
      "name": "Rock_Ice"
    },
    {
      "x": -17,
      "y": 24,
      "z": -2,
      "name": "Rock_Ice"
    },
    {
      "x": -17,
      "y": 25,
      "z": -2,
      "name": "Soil_Snow"
    },
    {
      "x": -17,
      "y": 47,
      "z": -1,
      "name": "Soil_Snow"
    },
    {
      "x": -17,
      "y": 21,
      "z": 0,
      "name": "Rock_Ice"
    },
    {
      "x": -17,
      "y": 22,
      "z": 0,
      "name": "Rock_Ice"
    },
    {
      "x": -17,
      "y": 30,
      "z": 0,
      "name": "Rock_Ice"
    },
    {
      "x": -17,
      "y": 31,
      "z": 0,
      "name": "Rock_Ice"
    },
    {
      "x": -17,
      "y": 32,
      "z": 0,
      "name": "Rock_Ice"
    },
    {
      "x": -17,
      "y": 46,
      "z": 0,
      "name": "Rock_Ice_Permafrost"
    },
    {
      "x": -17,
      "y": 47,
      "z": 0,
      "name": "Rock_Ice_Permafrost"
    },
    {
      "x": -17,
      "y": 48,
      "z": 0,
      "name": "Rock_Ice"
    },
    {
      "x": -17,
      "y": 49,
      "z": 0,
      "name": "Soil_Snow"
    },
    {
      "x": -17,
      "y": 20,
      "z": 1,
      "name": "Rock_Ice"
    },
    {
      "x": -17,
      "y": 21,
      "z": 1,
      "name": "Rock_Ice"
    },
    {
      "x": -17,
      "y": 22,
      "z": 1,
      "name": "Rock_Ice"
    },
    {
      "x": -17,
      "y": 23,
      "z": 1,
      "name": "Rock_Ice"
    },
    {
      "x": -17,
      "y": 24,
      "z": 1,
      "name": "Rock_Ice"
    },
    {
      "x": -17,
      "y": 25,
      "z": 1,
      "name": "Rock_Ice"
    },
    {
      "x": -17,
      "y": 26,
      "z": 1,
      "name": "Rock_Ice_Permafrost"
    },
    {
      "x": -17,
      "y": 27,
      "z": 1,
      "name": "Rock_Ice_Permafrost"
    },
    {
      "x": -17,
      "y": 29,
      "z": 1,
      "name": "Rock_Ice"
    },
    {
      "x": -17,
      "y": 30,
      "z": 1,
      "name": "Rock_Ice"
    },
    {
      "x": -17,
      "y": 31,
      "z": 1,
      "name": "Rock_Ice"
    },
    {
      "x": -17,
      "y": 32,
      "z": 1,
      "name": "Rock_Ice"
    },
    {
      "x": -17,
      "y": 33,
      "z": 1,
      "name": "Rock_Ice"
    },
    {
      "x": -17,
      "y": 34,
      "z": 1,
      "name": "Rock_Ice"
    },
    {
      "x": -17,
      "y": 37,
      "z": 1,
      "name": "Rock_Ice"
    },
    {
      "x": -17,
      "y": 47,
      "z": 1,
      "name": "Rock_Ice_Permafrost"
    },
    {
      "x": -17,
      "y": 48,
      "z": 1,
      "name": "Rock_Ice_Permafrost"
    },
    {
      "x": -17,
      "y": 49,
      "z": 1,
      "name": "Rock_Ice"
    },
    {
      "x": -17,
      "y": 50,
      "z": 1,
      "name": "Rock_Ice"
    },
    {
      "x": -17,
      "y": 51,
      "z": 1,
      "name": "Soil_Snow"
    },
    {
      "x": -17,
      "y": 19,
      "z": 2,
      "name": "Rock_Ice"
    },
    {
      "x": -17,
      "y": 20,
      "z": 2,
      "name": "Rock_Ice"
    },
    {
      "x": -17,
      "y": 21,
      "z": 2,
      "name": "Rock_Ice"
    },
    {
      "x": -17,
      "y": 22,
      "z": 2,
      "name": "Rock_Ice"
    },
    {
      "x": -17,
      "y": 23,
      "z": 2,
      "name": "Rock_Ice"
    },
    {
      "x": -17,
      "y": 24,
      "z": 2,
      "name": "Rock_Ice_Permafrost"
    },
    {
      "x": -17,
      "y": 25,
      "z": 2,
      "name": "Rock_Ice_Permafrost"
    },
    {
      "x": -17,
      "y": 26,
      "z": 2,
      "name": "Rock_Crystal_Cyan_Block_WhiteLight"
    },
    {
      "x": -17,
      "y": 27,
      "z": 2,
      "name": "Rock_Ice_Permafrost"
    },
    {
      "x": -17,
      "y": 28,
      "z": 2,
      "name": "Rock_Ice_Permafrost"
    },
    {
      "x": -17,
      "y": 29,
      "z": 2,
      "name": "Rock_Ice"
    },
    {
      "x": -17,
      "y": 30,
      "z": 2,
      "name": "Rock_Ice"
    },
    {
      "x": -17,
      "y": 31,
      "z": 2,
      "name": "Rock_Ice"
    },
    {
      "x": -17,
      "y": 32,
      "z": 2,
      "name": "Rock_Ice"
    },
    {
      "x": -17,
      "y": 33,
      "z": 2,
      "name": "Rock_Ice"
    },
    {
      "x": -17,
      "y": 34,
      "z": 2,
      "name": "Rock_Ice"
    },
    {
      "x": -17,
      "y": 35,
      "z": 2,
      "name": "Rock_Ice"
    },
    {
      "x": -17,
      "y": 36,
      "z": 2,
      "name": "Rock_Ice"
    },
    {
      "x": -17,
      "y": 37,
      "z": 2,
      "name": "Rock_Ice"
    },
    {
      "x": -17,
      "y": 48,
      "z": 2,
      "name": "Rock_Ice_Permafrost"
    },
    {
      "x": -17,
      "y": 49,
      "z": 2,
      "name": "Rock_Ice"
    },
    {
      "x": -17,
      "y": 50,
      "z": 2,
      "name": "Rock_Ice_Permafrost"
    },
    {
      "x": -17,
      "y": 51,
      "z": 2,
      "name": "Rock_Ice"
    },
    {
      "x": -17,
      "y": 52,
      "z": 2,
      "name": "Rock_Ice"
    },
    {
      "x": -17,
      "y": 53,
      "z": 2,
      "name": "Soil_Snow"
    },
    {
      "x": -17,
      "y": 19,
      "z": 3,
      "name": "Rock_Ice"
    },
    {
      "x": -17,
      "y": 20,
      "z": 3,
      "name": "Rock_Ice"
    },
    {
      "x": -17,
      "y": 21,
      "z": 3,
      "name": "Rock_Ice"
    },
    {
      "x": -17,
      "y": 22,
      "z": 3,
      "name": "Rock_Ice"
    },
    {
      "x": -17,
      "y": 23,
      "z": 3,
      "name": "Rock_Ice_Permafrost"
    },
    {
      "x": -17,
      "y": 24,
      "z": 3,
      "name": "Rock_Ice_Permafrost"
    },
    {
      "x": -17,
      "y": 25,
      "z": 3,
      "name": "Rock_Ice_Permafrost"
    },
    {
      "x": -17,
      "y": 26,
      "z": 3,
      "name": "Rock_Ice_Permafrost"
    },
    {
      "x": -17,
      "y": 27,
      "z": 3,
      "name": "Rock_Ice_Permafrost"
    },
    {
      "x": -17,
      "y": 28,
      "z": 3,
      "name": "Rock_Ice"
    },
    {
      "x": -17,
      "y": 29,
      "z": 3,
      "name": "Rock_Ice"
    },
    {
      "x": -17,
      "y": 30,
      "z": 3,
      "name": "Rock_Ice"
    },
    {
      "x": -17,
      "y": 31,
      "z": 3,
      "name": "Rock_Ice"
    },
    {
      "x": -17,
      "y": 32,
      "z": 3,
      "name": "Rock_Ice"
    },
    {
      "x": -17,
      "y": 33,
      "z": 3,
      "name": "Rock_Ice"
    },
    {
      "x": -17,
      "y": 34,
      "z": 3,
      "name": "Rock_Ice"
    },
    {
      "x": -17,
      "y": 35,
      "z": 3,
      "name": "Rock_Ice"
    },
    {
      "x": -17,
      "y": 36,
      "z": 3,
      "name": "Rock_Ice"
    },
    {
      "x": -17,
      "y": 37,
      "z": 3,
      "name": "Rock_Ice"
    },
    {
      "x": -17,
      "y": 38,
      "z": 3,
      "name": "Rock_Ice_Permafrost"
    },
    {
      "x": -17,
      "y": 50,
      "z": 3,
      "name": "Rock_Ice_Permafrost"
    },
    {
      "x": -17,
      "y": 51,
      "z": 3,
      "name": "Rock_Ice"
    },
    {
      "x": -17,
      "y": 52,
      "z": 3,
      "name": "Rock_Ice"
    },
    {
      "x": -17,
      "y": 53,
      "z": 3,
      "name": "Rock_Ice"
    },
    {
      "x": -17,
      "y": 54,
      "z": 3,
      "name": "Rock_Ice"
    },
    {
      "x": -17,
      "y": 55,
      "z": 3,
      "name": "Soil_Snow"
    },
    {
      "x": -17,
      "y": 19,
      "z": 4,
      "name": "Rock_Ice"
    },
    {
      "x": -17,
      "y": 20,
      "z": 4,
      "name": "Rock_Ice"
    },
    {
      "x": -17,
      "y": 21,
      "z": 4,
      "name": "Rock_Ice"
    },
    {
      "x": -17,
      "y": 22,
      "z": 4,
      "name": "Rock_Ice"
    },
    {
      "x": -17,
      "y": 23,
      "z": 4,
      "name": "Rock_Ice_Permafrost"
    },
    {
      "x": -17,
      "y": 24,
      "z": 4,
      "name": "Rock_Ice_Permafrost"
    },
    {
      "x": -17,
      "y": 25,
      "z": 4,
      "name": "Rock_Crystal_Cyan_Block_WhiteLight"
    },
    {
      "x": -17,
      "y": 26,
      "z": 4,
      "name": "Rock_Crystal_Cyan_Block_WhiteLight"
    },
    {
      "x": -17,
      "y": 27,
      "z": 4,
      "name": "Rock_Ice_Permafrost"
    },
    {
      "x": -17,
      "y": 28,
      "z": 4,
      "name": "Rock_Ice"
    },
    {
      "x": -17,
      "y": 29,
      "z": 4,
      "name": "Rock_Ice_Permafrost"
    },
    {
      "x": -17,
      "y": 30,
      "z": 4,
      "name": "Rock_Ice"
    },
    {
      "x": -17,
      "y": 31,
      "z": 4,
      "name": "Rock_Ice"
    },
    {
      "x": -17,
      "y": 32,
      "z": 4,
      "name": "Rock_Ice_Permafrost"
    },
    {
      "x": -17,
      "y": 33,
      "z": 4,
      "name": "Rock_Ice"
    },
    {
      "x": -17,
      "y": 34,
      "z": 4,
      "name": "Rock_Ice_Permafrost"
    },
    {
      "x": -17,
      "y": 35,
      "z": 4,
      "name": "Rock_Ice_Permafrost"
    },
    {
      "x": -17,
      "y": 36,
      "z": 4,
      "name": "Rock_Ice_Permafrost"
    },
    {
      "x": -17,
      "y": 37,
      "z": 4,
      "name": "Rock_Ice"
    },
    {
      "x": -17,
      "y": 38,
      "z": 4,
      "name": "Rock_Ice"
    },
    {
      "x": -17,
      "y": 39,
      "z": 4,
      "name": "Rock_Ice_Permafrost"
    },
    {
      "x": -17,
      "y": 52,
      "z": 4,
      "name": "Rock_Ice_Permafrost"
    },
    {
      "x": -17,
      "y": 53,
      "z": 4,
      "name": "Rock_Ice_Permafrost"
    },
    {
      "x": -17,
      "y": 54,
      "z": 4,
      "name": "Rock_Ice"
    },
    {
      "x": -17,
      "y": 55,
      "z": 4,
      "name": "Rock_Ice"
    },
    {
      "x": -17,
      "y": 56,
      "z": 4,
      "name": "Soil_Snow"
    },
    {
      "x": -17,
      "y": 19,
      "z": 5,
      "name": "Rock_Ice"
    },
    {
      "x": -17,
      "y": 20,
      "z": 5,
      "name": "Rock_Ice"
    },
    {
      "x": -17,
      "y": 21,
      "z": 5,
      "name": "Rock_Ice"
    },
    {
      "x": -17,
      "y": 22,
      "z": 5,
      "name": "Rock_Ice"
    },
    {
      "x": -17,
      "y": 23,
      "z": 5,
      "name": "Rock_Ice_Permafrost"
    },
    {
      "x": -17,
      "y": 24,
      "z": 5,
      "name": "Rock_Ice_Permafrost"
    },
    {
      "x": -17,
      "y": 25,
      "z": 5,
      "name": "Rock_Crystal_Cyan_Block_WhiteLight"
    },
    {
      "x": -17,
      "y": 26,
      "z": 5,
      "name": "Rock_Ice_Permafrost"
    },
    {
      "x": -17,
      "y": 27,
      "z": 5,
      "name": "Rock_Ice_Permafrost"
    },
    {
      "x": -17,
      "y": 28,
      "z": 5,
      "name": "Rock_Ice_Permafrost"
    },
    {
      "x": -17,
      "y": 29,
      "z": 5,
      "name": "Rock_Ice_Permafrost"
    },
    {
      "x": -17,
      "y": 30,
      "z": 5,
      "name": "Rock_Ice_Permafrost"
    },
    {
      "x": -17,
      "y": 31,
      "z": 5,
      "name": "Rock_Ice_Permafrost"
    },
    {
      "x": -17,
      "y": 32,
      "z": 5,
      "name": "Rock_Ice_Permafrost"
    },
    {
      "x": -17,
      "y": 33,
      "z": 5,
      "name": "Rock_Ice_Permafrost"
    },
    {
      "x": -17,
      "y": 34,
      "z": 5,
      "name": "Rock_Ice_Permafrost"
    },
    {
      "x": -17,
      "y": 35,
      "z": 5,
      "name": "Rock_Ice"
    },
    {
      "x": -17,
      "y": 36,
      "z": 5,
      "name": "Rock_Ice"
    },
    {
      "x": -17,
      "y": 37,
      "z": 5,
      "name": "Rock_Ice_Permafrost"
    },
    {
      "x": -17,
      "y": 38,
      "z": 5,
      "name": "Rock_Ice"
    },
    {
      "x": -17,
      "y": 39,
      "z": 5,
      "name": "Rock_Ice_Permafrost"
    },
    {
      "x": -17,
      "y": 40,
      "z": 5,
      "name": "Rock_Ice"
    },
    {
      "x": -17,
      "y": 53,
      "z": 5,
      "name": "Rock_Ice_Permafrost"
    },
    {
      "x": -17,
      "y": 54,
      "z": 5,
      "name": "Rock_Ice_Permafrost"
    },
    {
      "x": -17,
      "y": 55,
      "z": 5,
      "name": "Rock_Ice"
    },
    {
      "x": -17,
      "y": 56,
      "z": 5,
      "name": "Rock_Ice"
    },
    {
      "x": -17,
      "y": 57,
      "z": 5,
      "name": "Soil_Snow"
    },
    {
      "x": -17,
      "y": 20,
      "z": 6,
      "name": "Rock_Ice"
    },
    {
      "x": -17,
      "y": 21,
      "z": 6,
      "name": "Rock_Ice"
    },
    {
      "x": -17,
      "y": 22,
      "z": 6,
      "name": "Rock_Ice"
    },
    {
      "x": -17,
      "y": 23,
      "z": 6,
      "name": "Rock_Ice"
    },
    {
      "x": -17,
      "y": 24,
      "z": 6,
      "name": "Rock_Ice_Permafrost"
    },
    {
      "x": -17,
      "y": 25,
      "z": 6,
      "name": "Rock_Ice_Permafrost"
    },
    {
      "x": -17,
      "y": 26,
      "z": 6,
      "name": "Rock_Ice_Permafrost"
    },
    {
      "x": -17,
      "y": 27,
      "z": 6,
      "name": "Rock_Crystal_Cyan_Block_WhiteLight"
    },
    {
      "x": -17,
      "y": 28,
      "z": 6,
      "name": "Rock_Ice_Permafrost"
    },
    {
      "x": -17,
      "y": 29,
      "z": 6,
      "name": "Rock_Ice_Permafrost"
    },
    {
      "x": -17,
      "y": 30,
      "z": 6,
      "name": "Rock_Ice"
    },
    {
      "x": -17,
      "y": 31,
      "z": 6,
      "name": "Rock_Ice_Permafrost"
    },
    {
      "x": -17,
      "y": 32,
      "z": 6,
      "name": "Rock_Ice"
    },
    {
      "x": -17,
      "y": 33,
      "z": 6,
      "name": "Rock_Ice"
    },
    {
      "x": -17,
      "y": 34,
      "z": 6,
      "name": "Rock_Ice"
    },
    {
      "x": -17,
      "y": 35,
      "z": 6,
      "name": "Rock_Ice_Permafrost"
    },
    {
      "x": -17,
      "y": 36,
      "z": 6,
      "name": "Rock_Ice"
    },
    {
      "x": -17,
      "y": 37,
      "z": 6,
      "name": "Rock_Ice"
    },
    {
      "x": -17,
      "y": 38,
      "z": 6,
      "name": "Rock_Ice"
    },
    {
      "x": -17,
      "y": 39,
      "z": 6,
      "name": "Rock_Ice"
    },
    {
      "x": -17,
      "y": 40,
      "z": 6,
      "name": "Rock_Ice"
    },
    {
      "x": -17,
      "y": 41,
      "z": 6,
      "name": "Rock_Ice"
    },
    {
      "x": -17,
      "y": 54,
      "z": 6,
      "name": "Rock_Ice_Permafrost"
    },
    {
      "x": -17,
      "y": 55,
      "z": 6,
      "name": "Rock_Ice_Permafrost"
    },
    {
      "x": -17,
      "y": 56,
      "z": 6,
      "name": "Rock_Ice"
    },
    {
      "x": -17,
      "y": 57,
      "z": 6,
      "name": "Soil_Snow"
    },
    {
      "x": -17,
      "y": 19,
      "z": 7,
      "name": "Rock_Ice"
    },
    {
      "x": -17,
      "y": 20,
      "z": 7,
      "name": "Rock_Ice"
    },
    {
      "x": -17,
      "y": 21,
      "z": 7,
      "name": "Rock_Ice"
    },
    {
      "x": -17,
      "y": 22,
      "z": 7,
      "name": "Rock_Ice_Permafrost"
    },
    {
      "x": -17,
      "y": 23,
      "z": 7,
      "name": "Rock_Ice"
    },
    {
      "x": -17,
      "y": 24,
      "z": 7,
      "name": "Rock_Ice"
    },
    {
      "x": -17,
      "y": 25,
      "z": 7,
      "name": "Rock_Ice"
    },
    {
      "x": -17,
      "y": 26,
      "z": 7,
      "name": "Rock_Ice"
    },
    {
      "x": -17,
      "y": 27,
      "z": 7,
      "name": "Rock_Ice_Permafrost"
    },
    {
      "x": -17,
      "y": 28,
      "z": 7,
      "name": "Rock_Ice_Permafrost"
    },
    {
      "x": -17,
      "y": 29,
      "z": 7,
      "name": "Rock_Ice"
    },
    {
      "x": -17,
      "y": 30,
      "z": 7,
      "name": "Rock_Ice"
    },
    {
      "x": -17,
      "y": 31,
      "z": 7,
      "name": "Rock_Ice"
    },
    {
      "x": -17,
      "y": 32,
      "z": 7,
      "name": "Rock_Ice"
    },
    {
      "x": -17,
      "y": 33,
      "z": 7,
      "name": "Rock_Ice"
    },
    {
      "x": -17,
      "y": 34,
      "z": 7,
      "name": "Rock_Ice"
    },
    {
      "x": -17,
      "y": 35,
      "z": 7,
      "name": "Rock_Ice"
    },
    {
      "x": -17,
      "y": 36,
      "z": 7,
      "name": "Rock_Ice"
    },
    {
      "x": -17,
      "y": 37,
      "z": 7,
      "name": "Rock_Ice"
    },
    {
      "x": -17,
      "y": 38,
      "z": 7,
      "name": "Rock_Ice"
    },
    {
      "x": -17,
      "y": 39,
      "z": 7,
      "name": "Rock_Ice"
    },
    {
      "x": -17,
      "y": 40,
      "z": 7,
      "name": "Rock_Ice"
    },
    {
      "x": -17,
      "y": 41,
      "z": 7,
      "name": "Rock_Ice"
    },
    {
      "x": -17,
      "y": 42,
      "z": 7,
      "name": "Rock_Ice"
    },
    {
      "x": -17,
      "y": 55,
      "z": 7,
      "name": "Rock_Ice_Permafrost"
    },
    {
      "x": -17,
      "y": 56,
      "z": 7,
      "name": "Rock_Crystal_Cyan_Block_WhiteLight"
    },
    {
      "x": -17,
      "y": 57,
      "z": 7,
      "name": "Soil_Snow"
    },
    {
      "x": -17,
      "y": 18,
      "z": 8,
      "name": "Rock_Ice"
    },
    {
      "x": -17,
      "y": 19,
      "z": 8,
      "name": "Rock_Ice"
    },
    {
      "x": -17,
      "y": 20,
      "z": 8,
      "name": "Rock_Ice"
    },
    {
      "x": -17,
      "y": 21,
      "z": 8,
      "name": "Rock_Ice"
    },
    {
      "x": -17,
      "y": 22,
      "z": 8,
      "name": "Rock_Ice"
    },
    {
      "x": -17,
      "y": 23,
      "z": 8,
      "name": "Rock_Ice"
    },
    {
      "x": -17,
      "y": 24,
      "z": 8,
      "name": "Rock_Ice"
    },
    {
      "x": -17,
      "y": 25,
      "z": 8,
      "name": "Rock_Ice"
    },
    {
      "x": -17,
      "y": 26,
      "z": 8,
      "name": "Rock_Ice"
    },
    {
      "x": -17,
      "y": 27,
      "z": 8,
      "name": "Rock_Ice"
    },
    {
      "x": -17,
      "y": 28,
      "z": 8,
      "name": "Rock_Ice"
    },
    {
      "x": -17,
      "y": 29,
      "z": 8,
      "name": "Rock_Ice"
    },
    {
      "x": -17,
      "y": 30,
      "z": 8,
      "name": "Rock_Ice"
    },
    {
      "x": -17,
      "y": 31,
      "z": 8,
      "name": "Rock_Ice"
    },
    {
      "x": -17,
      "y": 32,
      "z": 8,
      "name": "Rock_Ice"
    },
    {
      "x": -17,
      "y": 33,
      "z": 8,
      "name": "Rock_Ice"
    },
    {
      "x": -17,
      "y": 34,
      "z": 8,
      "name": "Rock_Ice"
    },
    {
      "x": -17,
      "y": 35,
      "z": 8,
      "name": "Rock_Ice"
    },
    {
      "x": -17,
      "y": 36,
      "z": 8,
      "name": "Rock_Ice"
    },
    {
      "x": -17,
      "y": 37,
      "z": 8,
      "name": "Rock_Ice"
    },
    {
      "x": -17,
      "y": 38,
      "z": 8,
      "name": "Rock_Ice"
    },
    {
      "x": -17,
      "y": 39,
      "z": 8,
      "name": "Rock_Ice"
    },
    {
      "x": -17,
      "y": 40,
      "z": 8,
      "name": "Rock_Ice"
    },
    {
      "x": -17,
      "y": 41,
      "z": 8,
      "name": "Rock_Ice"
    },
    {
      "x": -17,
      "y": 42,
      "z": 8,
      "name": "Rock_Ice"
    },
    {
      "x": -17,
      "y": 43,
      "z": 8,
      "name": "Rock_Ice"
    },
    {
      "x": -17,
      "y": 44,
      "z": 8,
      "name": "Rock_Ice"
    },
    {
      "x": -17,
      "y": 57,
      "z": 8,
      "name": "Soil_Snow"
    },
    {
      "x": -17,
      "y": 19,
      "z": 9,
      "name": "Rock_Ice"
    },
    {
      "x": -17,
      "y": 20,
      "z": 9,
      "name": "Rock_Ice"
    },
    {
      "x": -17,
      "y": 21,
      "z": 9,
      "name": "Rock_Ice"
    },
    {
      "x": -17,
      "y": 22,
      "z": 9,
      "name": "Rock_Ice"
    },
    {
      "x": -17,
      "y": 23,
      "z": 9,
      "name": "Rock_Ice"
    },
    {
      "x": -17,
      "y": 24,
      "z": 9,
      "name": "Rock_Ice"
    },
    {
      "x": -17,
      "y": 25,
      "z": 9,
      "name": "Rock_Ice"
    },
    {
      "x": -17,
      "y": 26,
      "z": 9,
      "name": "Rock_Ice"
    },
    {
      "x": -17,
      "y": 27,
      "z": 9,
      "name": "Rock_Ice"
    },
    {
      "x": -17,
      "y": 28,
      "z": 9,
      "name": "Rock_Ice"
    },
    {
      "x": -17,
      "y": 29,
      "z": 9,
      "name": "Rock_Ice"
    },
    {
      "x": -17,
      "y": 30,
      "z": 9,
      "name": "Rock_Ice"
    },
    {
      "x": -17,
      "y": 31,
      "z": 9,
      "name": "Rock_Ice"
    },
    {
      "x": -17,
      "y": 32,
      "z": 9,
      "name": "Rock_Ice"
    },
    {
      "x": -17,
      "y": 39,
      "z": 9,
      "name": "Rock_Ice"
    },
    {
      "x": -17,
      "y": 40,
      "z": 9,
      "name": "Rock_Ice"
    },
    {
      "x": -17,
      "y": 41,
      "z": 9,
      "name": "Rock_Ice"
    },
    {
      "x": -17,
      "y": 42,
      "z": 9,
      "name": "Rock_Ice"
    },
    {
      "x": -17,
      "y": 43,
      "z": 9,
      "name": "Rock_Ice"
    },
    {
      "x": -17,
      "y": 44,
      "z": 9,
      "name": "Rock_Ice"
    },
    {
      "x": -17,
      "y": 45,
      "z": 9,
      "name": "Soil_Snow"
    },
    {
      "x": -17,
      "y": 19,
      "z": 10,
      "name": "Rock_Ice"
    },
    {
      "x": -17,
      "y": 20,
      "z": 10,
      "name": "Rock_Ice"
    },
    {
      "x": -17,
      "y": 21,
      "z": 10,
      "name": "Rock_Ice"
    },
    {
      "x": -17,
      "y": 22,
      "z": 10,
      "name": "Rock_Ice"
    },
    {
      "x": -17,
      "y": 23,
      "z": 10,
      "name": "Rock_Ice"
    },
    {
      "x": -17,
      "y": 30,
      "z": 10,
      "name": "Rock_Ice"
    },
    {
      "x": -17,
      "y": 43,
      "z": 10,
      "name": "Rock_Ice"
    },
    {
      "x": -17,
      "y": 44,
      "z": 10,
      "name": "Rock_Ice_Permafrost"
    },
    {
      "x": -17,
      "y": 45,
      "z": 10,
      "name": "Rock_Ice_Permafrost"
    },
    {
      "x": -17,
      "y": 46,
      "z": 10,
      "name": "Rock_Ice"
    },
    {
      "x": -17,
      "y": 47,
      "z": 10,
      "name": "Soil_Snow"
    },
    {
      "x": -17,
      "y": 20,
      "z": 11,
      "name": "Rock_Ice"
    },
    {
      "x": -17,
      "y": 21,
      "z": 11,
      "name": "Rock_Ice"
    },
    {
      "x": -17,
      "y": 22,
      "z": 11,
      "name": "Soil_Snow"
    },
    {
      "x": -17,
      "y": 21,
      "z": 12,
      "name": "Rock_Ice"
    },
    {
      "x": -17,
      "y": 22,
      "z": 12,
      "name": "Soil_Snow"
    },
    {
      "x": -17,
      "y": 22,
      "z": 13,
      "name": "Soil_Snow"
    },
    {
      "x": -16,
      "y": 25,
      "z": -7,
      "name": "Rock_Ice_Permafrost"
    },
    {
      "x": -16,
      "y": 26,
      "z": -7,
      "name": "Rock_Ice_Permafrost"
    },
    {
      "x": -16,
      "y": 27,
      "z": -7,
      "name": "Rock_Ice_Permafrost"
    },
    {
      "x": -16,
      "y": 28,
      "z": -7,
      "name": "Rock_Ice_Permafrost"
    },
    {
      "x": -16,
      "y": 29,
      "z": -7,
      "name": "Rock_Ice_Permafrost"
    },
    {
      "x": -16,
      "y": 30,
      "z": -7,
      "name": "Soil_Snow"
    },
    {
      "x": -16,
      "y": 22,
      "z": -6,
      "name": "Rock_Ice"
    },
    {
      "x": -16,
      "y": 23,
      "z": -6,
      "name": "Rock_Ice"
    },
    {
      "x": -16,
      "y": 24,
      "z": -6,
      "name": "Rock_Ice"
    },
    {
      "x": -16,
      "y": 25,
      "z": -6,
      "name": "Rock_Ice"
    },
    {
      "x": -16,
      "y": 26,
      "z": -6,
      "name": "Rock_Ice_Permafrost"
    },
    {
      "x": -16,
      "y": 27,
      "z": -6,
      "name": "Rock_Ice_Permafrost"
    },
    {
      "x": -16,
      "y": 28,
      "z": -6,
      "name": "Rock_Ice_Permafrost"
    },
    {
      "x": -16,
      "y": 29,
      "z": -6,
      "name": "Rock_Ice_Permafrost"
    },
    {
      "x": -16,
      "y": 30,
      "z": -6,
      "name": "Rock_Ice"
    },
    {
      "x": -16,
      "y": 31,
      "z": -6,
      "name": "Soil_Snow"
    },
    {
      "x": -16,
      "y": 20,
      "z": -5,
      "name": "Rock_Ice"
    },
    {
      "x": -16,
      "y": 21,
      "z": -5,
      "name": "Rock_Ice"
    },
    {
      "x": -16,
      "y": 22,
      "z": -5,
      "name": "Rock_Ice"
    },
    {
      "x": -16,
      "y": 23,
      "z": -5,
      "name": "Rock_Ice"
    },
    {
      "x": -16,
      "y": 24,
      "z": -5,
      "name": "Rock_Ice"
    },
    {
      "x": -16,
      "y": 25,
      "z": -5,
      "name": "Rock_Ice_Permafrost"
    },
    {
      "x": -16,
      "y": 26,
      "z": -5,
      "name": "Rock_Ice"
    },
    {
      "x": -16,
      "y": 27,
      "z": -5,
      "name": "Rock_Ice_Permafrost"
    },
    {
      "x": -16,
      "y": 28,
      "z": -5,
      "name": "Rock_Crystal_Cyan_Block_WhiteLight"
    },
    {
      "x": -16,
      "y": 29,
      "z": -5,
      "name": "Rock_Ice_Permafrost"
    },
    {
      "x": -16,
      "y": 30,
      "z": -5,
      "name": "Rock_Ice"
    },
    {
      "x": -16,
      "y": 31,
      "z": -5,
      "name": "Soil_Snow"
    },
    {
      "x": -16,
      "y": 19,
      "z": -4,
      "name": "Rock_Ice"
    },
    {
      "x": -16,
      "y": 20,
      "z": -4,
      "name": "Rock_Ice"
    },
    {
      "x": -16,
      "y": 21,
      "z": -4,
      "name": "Rock_Ice"
    },
    {
      "x": -16,
      "y": 22,
      "z": -4,
      "name": "Rock_Ice"
    },
    {
      "x": -16,
      "y": 23,
      "z": -4,
      "name": "Rock_Ice"
    },
    {
      "x": -16,
      "y": 24,
      "z": -4,
      "name": "Rock_Ice_Permafrost"
    },
    {
      "x": -16,
      "y": 25,
      "z": -4,
      "name": "Rock_Ice"
    },
    {
      "x": -16,
      "y": 26,
      "z": -4,
      "name": "Rock_Ice_Permafrost"
    },
    {
      "x": -16,
      "y": 27,
      "z": -4,
      "name": "Rock_Ice"
    },
    {
      "x": -16,
      "y": 28,
      "z": -4,
      "name": "Soil_Snow"
    },
    {
      "x": -16,
      "y": 19,
      "z": -3,
      "name": "Rock_Ice"
    },
    {
      "x": -16,
      "y": 20,
      "z": -3,
      "name": "Rock_Ice"
    },
    {
      "x": -16,
      "y": 21,
      "z": -3,
      "name": "Rock_Ice"
    },
    {
      "x": -16,
      "y": 22,
      "z": -3,
      "name": "Rock_Ice"
    },
    {
      "x": -16,
      "y": 23,
      "z": -3,
      "name": "Rock_Ice"
    },
    {
      "x": -16,
      "y": 24,
      "z": -3,
      "name": "Rock_Ice"
    },
    {
      "x": -16,
      "y": 25,
      "z": -3,
      "name": "Rock_Ice"
    },
    {
      "x": -16,
      "y": 26,
      "z": -3,
      "name": "Rock_Ice"
    },
    {
      "x": -16,
      "y": 27,
      "z": -3,
      "name": "Soil_Snow"
    },
    {
      "x": -16,
      "y": 19,
      "z": -2,
      "name": "Rock_Ice"
    },
    {
      "x": -16,
      "y": 20,
      "z": -2,
      "name": "Rock_Ice"
    },
    {
      "x": -16,
      "y": 21,
      "z": -2,
      "name": "Rock_Ice"
    },
    {
      "x": -16,
      "y": 22,
      "z": -2,
      "name": "Rock_Ice"
    },
    {
      "x": -16,
      "y": 23,
      "z": -2,
      "name": "Rock_Ice"
    },
    {
      "x": -16,
      "y": 24,
      "z": -2,
      "name": "Rock_Ice"
    },
    {
      "x": -16,
      "y": 25,
      "z": -2,
      "name": "Rock_Ice"
    },
    {
      "x": -16,
      "y": 26,
      "z": -2,
      "name": "Rock_Ice"
    },
    {
      "x": -16,
      "y": 27,
      "z": -2,
      "name": "Soil_Snow"
    },
    {
      "x": -16,
      "y": 19,
      "z": -1,
      "name": "Rock_Ice"
    },
    {
      "x": -16,
      "y": 20,
      "z": -1,
      "name": "Rock_Ice"
    },
    {
      "x": -16,
      "y": 21,
      "z": -1,
      "name": "Rock_Ice"
    },
    {
      "x": -16,
      "y": 22,
      "z": -1,
      "name": "Rock_Ice"
    },
    {
      "x": -16,
      "y": 23,
      "z": -1,
      "name": "Rock_Ice"
    },
    {
      "x": -16,
      "y": 24,
      "z": -1,
      "name": "Rock_Ice_Permafrost"
    },
    {
      "x": -16,
      "y": 25,
      "z": -1,
      "name": "Rock_Ice"
    },
    {
      "x": -16,
      "y": 26,
      "z": -1,
      "name": "Rock_Ice_Permafrost"
    },
    {
      "x": -16,
      "y": 27,
      "z": -1,
      "name": "Rock_Ice_Permafrost"
    },
    {
      "x": -16,
      "y": 33,
      "z": -1,
      "name": "Rock_Ice"
    },
    {
      "x": -16,
      "y": 34,
      "z": -1,
      "name": "Rock_Ice"
    },
    {
      "x": -16,
      "y": 35,
      "z": -1,
      "name": "Rock_Ice"
    },
    {
      "x": -16,
      "y": 36,
      "z": -1,
      "name": "Rock_Ice"
    },
    {
      "x": -16,
      "y": 37,
      "z": -1,
      "name": "Rock_Ice"
    },
    {
      "x": -16,
      "y": 38,
      "z": -1,
      "name": "Rock_Ice"
    },
    {
      "x": -16,
      "y": 39,
      "z": -1,
      "name": "Rock_Ice"
    },
    {
      "x": -16,
      "y": 40,
      "z": -1,
      "name": "Rock_Ice"
    },
    {
      "x": -16,
      "y": 41,
      "z": -1,
      "name": "Rock_Ice"
    },
    {
      "x": -16,
      "y": 42,
      "z": -1,
      "name": "Rock_Ice"
    },
    {
      "x": -16,
      "y": 43,
      "z": -1,
      "name": "Rock_Ice"
    },
    {
      "x": -16,
      "y": 44,
      "z": -1,
      "name": "Rock_Ice_Permafrost"
    },
    {
      "x": -16,
      "y": 45,
      "z": -1,
      "name": "Rock_Crystal_Cyan_Block_WhiteLight"
    },
    {
      "x": -16,
      "y": 46,
      "z": -1,
      "name": "Rock_Ice_Permafrost"
    },
    {
      "x": -16,
      "y": 47,
      "z": -1,
      "name": "Rock_Ice_Permafrost"
    },
    {
      "x": -16,
      "y": 48,
      "z": -1,
      "name": "Rock_Ice_Permafrost"
    },
    {
      "x": -16,
      "y": 49,
      "z": -1,
      "name": "Rock_Ice"
    },
    {
      "x": -16,
      "y": 50,
      "z": -1,
      "name": "Soil_Snow"
    },
    {
      "x": -16,
      "y": 18,
      "z": 0,
      "name": "Rock_Ice"
    },
    {
      "x": -16,
      "y": 19,
      "z": 0,
      "name": "Rock_Ice"
    },
    {
      "x": -16,
      "y": 20,
      "z": 0,
      "name": "Rock_Ice"
    },
    {
      "x": -16,
      "y": 21,
      "z": 0,
      "name": "Rock_Ice"
    },
    {
      "x": -16,
      "y": 22,
      "z": 0,
      "name": "Rock_Ice"
    },
    {
      "x": -16,
      "y": 23,
      "z": 0,
      "name": "Rock_Ice"
    },
    {
      "x": -16,
      "y": 24,
      "z": 0,
      "name": "Rock_Ice_Permafrost"
    },
    {
      "x": -16,
      "y": 25,
      "z": 0,
      "name": "Rock_Ice_Permafrost"
    },
    {
      "x": -16,
      "y": 26,
      "z": 0,
      "name": "Rock_Ice_Permafrost"
    },
    {
      "x": -16,
      "y": 27,
      "z": 0,
      "name": "Rock_Ice_Permafrost"
    },
    {
      "x": -16,
      "y": 28,
      "z": 0,
      "name": "Rock_Ice_Permafrost"
    },
    {
      "x": -16,
      "y": 29,
      "z": 0,
      "name": "Rock_Ice"
    },
    {
      "x": -16,
      "y": 30,
      "z": 0,
      "name": "Rock_Ice"
    },
    {
      "x": -16,
      "y": 31,
      "z": 0,
      "name": "Rock_Ice"
    },
    {
      "x": -16,
      "y": 32,
      "z": 0,
      "name": "Rock_Ice"
    },
    {
      "x": -16,
      "y": 33,
      "z": 0,
      "name": "Rock_Ice"
    },
    {
      "x": -16,
      "y": 34,
      "z": 0,
      "name": "Rock_Ice"
    },
    {
      "x": -16,
      "y": 35,
      "z": 0,
      "name": "Rock_Ice"
    },
    {
      "x": -16,
      "y": 36,
      "z": 0,
      "name": "Rock_Ice"
    },
    {
      "x": -16,
      "y": 37,
      "z": 0,
      "name": "Rock_Ice"
    },
    {
      "x": -16,
      "y": 38,
      "z": 0,
      "name": "Rock_Ice"
    },
    {
      "x": -16,
      "y": 39,
      "z": 0,
      "name": "Rock_Ice"
    },
    {
      "x": -16,
      "y": 40,
      "z": 0,
      "name": "Rock_Ice"
    },
    {
      "x": -16,
      "y": 41,
      "z": 0,
      "name": "Rock_Ice"
    },
    {
      "x": -16,
      "y": 42,
      "z": 0,
      "name": "Rock_Ice"
    },
    {
      "x": -16,
      "y": 43,
      "z": 0,
      "name": "Rock_Ice_Permafrost"
    },
    {
      "x": -16,
      "y": 44,
      "z": 0,
      "name": "Rock_Ice_Permafrost"
    },
    {
      "x": -16,
      "y": 45,
      "z": 0,
      "name": "Rock_Crystal_Cyan_Block_WhiteLight"
    },
    {
      "x": -16,
      "y": 46,
      "z": 0,
      "name": "Rock_Crystal_Cyan_Block_WhiteLight"
    },
    {
      "x": -16,
      "y": 47,
      "z": 0,
      "name": "Rock_Ice_Permafrost"
    },
    {
      "x": -16,
      "y": 48,
      "z": 0,
      "name": "Rock_Ice_Permafrost"
    },
    {
      "x": -16,
      "y": 49,
      "z": 0,
      "name": "Rock_Ice"
    },
    {
      "x": -16,
      "y": 50,
      "z": 0,
      "name": "Rock_Ice"
    },
    {
      "x": -16,
      "y": 51,
      "z": 0,
      "name": "Rock_Ice"
    },
    {
      "x": -16,
      "y": 52,
      "z": 0,
      "name": "Soil_Snow"
    },
    {
      "x": -16,
      "y": 17,
      "z": 1,
      "name": "Rock_Ice"
    },
    {
      "x": -16,
      "y": 18,
      "z": 1,
      "name": "Rock_Ice"
    },
    {
      "x": -16,
      "y": 19,
      "z": 1,
      "name": "Rock_Ice"
    },
    {
      "x": -16,
      "y": 20,
      "z": 1,
      "name": "Rock_Ice"
    },
    {
      "x": -16,
      "y": 21,
      "z": 1,
      "name": "Rock_Ice"
    },
    {
      "x": -16,
      "y": 22,
      "z": 1,
      "name": "Rock_Ice"
    },
    {
      "x": -16,
      "y": 23,
      "z": 1,
      "name": "Rock_Ice"
    },
    {
      "x": -16,
      "y": 24,
      "z": 1,
      "name": "Rock_Ice_Permafrost"
    },
    {
      "x": -16,
      "y": 25,
      "z": 1,
      "name": "Rock_Crystal_Cyan_Block_WhiteLight"
    },
    {
      "x": -16,
      "y": 26,
      "z": 1,
      "name": "Rock_Ice_Permafrost"
    },
    {
      "x": -16,
      "y": 27,
      "z": 1,
      "name": "Rock_Ice_Permafrost"
    },
    {
      "x": -16,
      "y": 28,
      "z": 1,
      "name": "Rock_Ice"
    },
    {
      "x": -16,
      "y": 29,
      "z": 1,
      "name": "Rock_Ice"
    },
    {
      "x": -16,
      "y": 30,
      "z": 1,
      "name": "Rock_Ice"
    },
    {
      "x": -16,
      "y": 31,
      "z": 1,
      "name": "Rock_Ice"
    },
    {
      "x": -16,
      "y": 32,
      "z": 1,
      "name": "Rock_Ice"
    },
    {
      "x": -16,
      "y": 33,
      "z": 1,
      "name": "Rock_Ice"
    },
    {
      "x": -16,
      "y": 34,
      "z": 1,
      "name": "Rock_Ice"
    },
    {
      "x": -16,
      "y": 35,
      "z": 1,
      "name": "Rock_Ice"
    },
    {
      "x": -16,
      "y": 36,
      "z": 1,
      "name": "Rock_Ice"
    },
    {
      "x": -16,
      "y": 37,
      "z": 1,
      "name": "Rock_Ice"
    },
    {
      "x": -16,
      "y": 38,
      "z": 1,
      "name": "Rock_Ice"
    },
    {
      "x": -16,
      "y": 39,
      "z": 1,
      "name": "Rock_Ice"
    },
    {
      "x": -16,
      "y": 40,
      "z": 1,
      "name": "Rock_Ice_Permafrost"
    },
    {
      "x": -16,
      "y": 41,
      "z": 1,
      "name": "Rock_Ice"
    },
    {
      "x": -16,
      "y": 42,
      "z": 1,
      "name": "Rock_Ice_Permafrost"
    },
    {
      "x": -16,
      "y": 43,
      "z": 1,
      "name": "Rock_Ice_Permafrost"
    },
    {
      "x": -16,
      "y": 44,
      "z": 1,
      "name": "Rock_Crystal_Cyan_Block_WhiteLight"
    },
    {
      "x": -16,
      "y": 45,
      "z": 1,
      "name": "Rock_Ice_Permafrost"
    },
    {
      "x": -16,
      "y": 46,
      "z": 1,
      "name": "Rock_Ice_Permafrost"
    },
    {
      "x": -16,
      "y": 47,
      "z": 1,
      "name": "Rock_Ice_Permafrost"
    },
    {
      "x": -16,
      "y": 48,
      "z": 1,
      "name": "Rock_Ice_Permafrost"
    },
    {
      "x": -16,
      "y": 49,
      "z": 1,
      "name": "Rock_Ice"
    },
    {
      "x": -16,
      "y": 50,
      "z": 1,
      "name": "Rock_Ice"
    },
    {
      "x": -16,
      "y": 51,
      "z": 1,
      "name": "Rock_Ice"
    },
    {
      "x": -16,
      "y": 52,
      "z": 1,
      "name": "Rock_Ice"
    },
    {
      "x": -16,
      "y": 53,
      "z": 1,
      "name": "Rock_Ice"
    },
    {
      "x": -16,
      "y": 54,
      "z": 1,
      "name": "Soil_Snow"
    },
    {
      "x": -16,
      "y": 16,
      "z": 2,
      "name": "Rock_Ice"
    },
    {
      "x": -16,
      "y": 17,
      "z": 2,
      "name": "Rock_Ice"
    },
    {
      "x": -16,
      "y": 18,
      "z": 2,
      "name": "Rock_Ice"
    },
    {
      "x": -16,
      "y": 19,
      "z": 2,
      "name": "Rock_Ice"
    },
    {
      "x": -16,
      "y": 20,
      "z": 2,
      "name": "Rock_Ice"
    },
    {
      "x": -16,
      "y": 21,
      "z": 2,
      "name": "Rock_Ice"
    },
    {
      "x": -16,
      "y": 22,
      "z": 2,
      "name": "Rock_Ice"
    },
    {
      "x": -16,
      "y": 23,
      "z": 2,
      "name": "Rock_Ice_Permafrost"
    },
    {
      "x": -16,
      "y": 24,
      "z": 2,
      "name": "Rock_Ice_Permafrost"
    },
    {
      "x": -16,
      "y": 25,
      "z": 2,
      "name": "Rock_Ice_Permafrost"
    },
    {
      "x": -16,
      "y": 26,
      "z": 2,
      "name": "Rock_Ice_Permafrost"
    },
    {
      "x": -16,
      "y": 27,
      "z": 2,
      "name": "Rock_Ice_Permafrost"
    },
    {
      "x": -16,
      "y": 28,
      "z": 2,
      "name": "Rock_Ice_Permafrost"
    },
    {
      "x": -16,
      "y": 29,
      "z": 2,
      "name": "Rock_Ice"
    },
    {
      "x": -16,
      "y": 30,
      "z": 2,
      "name": "Rock_Ice"
    },
    {
      "x": -16,
      "y": 31,
      "z": 2,
      "name": "Rock_Ice"
    },
    {
      "x": -16,
      "y": 32,
      "z": 2,
      "name": "Rock_Ice"
    },
    {
      "x": -16,
      "y": 33,
      "z": 2,
      "name": "Rock_Ice"
    },
    {
      "x": -16,
      "y": 34,
      "z": 2,
      "name": "Rock_Ice"
    },
    {
      "x": -16,
      "y": 35,
      "z": 2,
      "name": "Rock_Ice"
    },
    {
      "x": -16,
      "y": 36,
      "z": 2,
      "name": "Rock_Ice"
    },
    {
      "x": -16,
      "y": 37,
      "z": 2,
      "name": "Rock_Ice"
    },
    {
      "x": -16,
      "y": 38,
      "z": 2,
      "name": "Rock_Ice"
    },
    {
      "x": -16,
      "y": 39,
      "z": 2,
      "name": "Rock_Ice"
    },
    {
      "x": -16,
      "y": 40,
      "z": 2,
      "name": "Rock_Ice_Permafrost"
    },
    {
      "x": -16,
      "y": 41,
      "z": 2,
      "name": "Rock_Crystal_Cyan_Block_WhiteLight"
    },
    {
      "x": -16,
      "y": 42,
      "z": 2,
      "name": "Rock_Ice_Permafrost"
    },
    {
      "x": -16,
      "y": 43,
      "z": 2,
      "name": "Rock_Ice_Permafrost"
    },
    {
      "x": -16,
      "y": 44,
      "z": 2,
      "name": "Rock_Ice_Permafrost"
    },
    {
      "x": -16,
      "y": 45,
      "z": 2,
      "name": "Rock_Crystal_Cyan_Block_WhiteLight"
    },
    {
      "x": -16,
      "y": 46,
      "z": 2,
      "name": "Rock_Crystal_Cyan_Block_WhiteLight"
    },
    {
      "x": -16,
      "y": 47,
      "z": 2,
      "name": "Rock_Ice_Permafrost"
    },
    {
      "x": -16,
      "y": 48,
      "z": 2,
      "name": "Rock_Crystal_Cyan_Block_WhiteLight"
    },
    {
      "x": -16,
      "y": 49,
      "z": 2,
      "name": "Rock_Ice_Permafrost"
    },
    {
      "x": -16,
      "y": 50,
      "z": 2,
      "name": "Rock_Ice_Permafrost"
    },
    {
      "x": -16,
      "y": 51,
      "z": 2,
      "name": "Rock_Ice_Permafrost"
    },
    {
      "x": -16,
      "y": 52,
      "z": 2,
      "name": "Rock_Ice_Permafrost"
    },
    {
      "x": -16,
      "y": 53,
      "z": 2,
      "name": "Rock_Ice"
    },
    {
      "x": -16,
      "y": 54,
      "z": 2,
      "name": "Rock_Ice"
    },
    {
      "x": -16,
      "y": 55,
      "z": 2,
      "name": "Rock_Ice"
    },
    {
      "x": -16,
      "y": 56,
      "z": 2,
      "name": "Rock_Ice"
    },
    {
      "x": -16,
      "y": 57,
      "z": 2,
      "name": "Soil_Snow"
    },
    {
      "x": -16,
      "y": 127,
      "z": 2,
      "name": "Rock_Crystal_Cyan_Block_WhiteLight"
    },
    {
      "x": -16,
      "y": 128,
      "z": 2,
      "name": "Rock_Ice_Permafrost"
    },
    {
      "x": -16,
      "y": 129,
      "z": 2,
      "name": "Rock_Ice"
    },
    {
      "x": -16,
      "y": 130,
      "z": 2,
      "name": "Soil_Snow"
    },
    {
      "x": -16,
      "y": 17,
      "z": 3,
      "name": "Rock_Ice"
    },
    {
      "x": -16,
      "y": 18,
      "z": 3,
      "name": "Rock_Ice"
    },
    {
      "x": -16,
      "y": 19,
      "z": 3,
      "name": "Rock_Ice"
    },
    {
      "x": -16,
      "y": 20,
      "z": 3,
      "name": "Rock_Ice"
    },
    {
      "x": -16,
      "y": 21,
      "z": 3,
      "name": "Rock_Ice"
    },
    {
      "x": -16,
      "y": 22,
      "z": 3,
      "name": "Rock_Ice_Permafrost"
    },
    {
      "x": -16,
      "y": 23,
      "z": 3,
      "name": "Rock_Ice_Permafrost"
    },
    {
      "x": -16,
      "y": 24,
      "z": 3,
      "name": "Rock_Ice_Permafrost"
    },
    {
      "x": -16,
      "y": 25,
      "z": 3,
      "name": "Rock_Crystal_Cyan_Block_WhiteLight"
    },
    {
      "x": -16,
      "y": 26,
      "z": 3,
      "name": "Rock_Ice_Permafrost"
    },
    {
      "x": -16,
      "y": 27,
      "z": 3,
      "name": "Rock_Ice_Permafrost"
    },
    {
      "x": -16,
      "y": 28,
      "z": 3,
      "name": "Rock_Ice"
    },
    {
      "x": -16,
      "y": 29,
      "z": 3,
      "name": "Rock_Ice"
    },
    {
      "x": -16,
      "y": 30,
      "z": 3,
      "name": "Rock_Ice"
    },
    {
      "x": -16,
      "y": 31,
      "z": 3,
      "name": "Rock_Ice"
    },
    {
      "x": -16,
      "y": 32,
      "z": 3,
      "name": "Rock_Ice"
    },
    {
      "x": -16,
      "y": 33,
      "z": 3,
      "name": "Rock_Ice"
    },
    {
      "x": -16,
      "y": 34,
      "z": 3,
      "name": "Rock_Ice"
    },
    {
      "x": -16,
      "y": 35,
      "z": 3,
      "name": "Rock_Ice_Permafrost"
    },
    {
      "x": -16,
      "y": 36,
      "z": 3,
      "name": "Rock_Ice"
    },
    {
      "x": -16,
      "y": 37,
      "z": 3,
      "name": "Rock_Ice"
    },
    {
      "x": -16,
      "y": 38,
      "z": 3,
      "name": "Rock_Crystal_Cyan_Block_WhiteLight"
    },
    {
      "x": -16,
      "y": 39,
      "z": 3,
      "name": "Rock_Ice_Permafrost"
    },
    {
      "x": -16,
      "y": 40,
      "z": 3,
      "name": "Rock_Ice_Permafrost"
    },
    {
      "x": -16,
      "y": 41,
      "z": 3,
      "name": "Rock_Crystal_Cyan_Block_WhiteLight"
    },
    {
      "x": -16,
      "y": 42,
      "z": 3,
      "name": "Rock_Crystal_Cyan_Block_WhiteLight"
    },
    {
      "x": -16,
      "y": 43,
      "z": 3,
      "name": "Rock_Ice_Permafrost"
    },
    {
      "x": -16,
      "y": 44,
      "z": 3,
      "name": "Rock_Ice_Permafrost"
    },
    {
      "x": -16,
      "y": 47,
      "z": 3,
      "name": "Rock_Ice_Permafrost"
    },
    {
      "x": -16,
      "y": 48,
      "z": 3,
      "name": "Rock_Ice_Permafrost"
    },
    {
      "x": -16,
      "y": 49,
      "z": 3,
      "name": "Rock_Crystal_Cyan_Block_WhiteLight"
    },
    {
      "x": -16,
      "y": 50,
      "z": 3,
      "name": "Rock_Ice_Permafrost"
    },
    {
      "x": -16,
      "y": 51,
      "z": 3,
      "name": "Rock_Ice_Permafrost"
    },
    {
      "x": -16,
      "y": 52,
      "z": 3,
      "name": "Rock_Ice_Permafrost"
    },
    {
      "x": -16,
      "y": 53,
      "z": 3,
      "name": "Rock_Ice_Permafrost"
    },
    {
      "x": -16,
      "y": 54,
      "z": 3,
      "name": "Rock_Ice_Permafrost"
    },
    {
      "x": -16,
      "y": 55,
      "z": 3,
      "name": "Rock_Ice_Permafrost"
    },
    {
      "x": -16,
      "y": 56,
      "z": 3,
      "name": "Rock_Ice"
    },
    {
      "x": -16,
      "y": 57,
      "z": 3,
      "name": "Rock_Ice"
    },
    {
      "x": -16,
      "y": 58,
      "z": 3,
      "name": "Soil_Snow"
    },
    {
      "x": -16,
      "y": 88,
      "z": 3,
      "name": "Rock_Ice"
    },
    {
      "x": -16,
      "y": 89,
      "z": 3,
      "name": "Rock_Ice"
    },
    {
      "x": -16,
      "y": 90,
      "z": 3,
      "name": "Soil_Snow"
    },
    {
      "x": -16,
      "y": 127,
      "z": 3,
      "name": "Rock_Ice_Permafrost"
    },
    {
      "x": -16,
      "y": 128,
      "z": 3,
      "name": "Rock_Crystal_Cyan_Block_WhiteLight"
    },
    {
      "x": -16,
      "y": 129,
      "z": 3,
      "name": "Rock_Ice_Permafrost"
    },
    {
      "x": -16,
      "y": 130,
      "z": 3,
      "name": "Rock_Ice"
    },
    {
      "x": -16,
      "y": 131,
      "z": 3,
      "name": "Soil_Snow"
    },
    {
      "x": -16,
      "y": 18,
      "z": 4,
      "name": "Rock_Ice"
    },
    {
      "x": -16,
      "y": 19,
      "z": 4,
      "name": "Rock_Ice"
    },
    {
      "x": -16,
      "y": 20,
      "z": 4,
      "name": "Rock_Ice"
    },
    {
      "x": -16,
      "y": 21,
      "z": 4,
      "name": "Rock_Ice"
    },
    {
      "x": -16,
      "y": 22,
      "z": 4,
      "name": "Rock_Ice"
    },
    {
      "x": -16,
      "y": 23,
      "z": 4,
      "name": "Rock_Ice_Permafrost"
    },
    {
      "x": -16,
      "y": 24,
      "z": 4,
      "name": "Rock_Crystal_Cyan_Block_WhiteLight"
    },
    {
      "x": -16,
      "y": 25,
      "z": 4,
      "name": "Rock_Ice_Permafrost"
    },
    {
      "x": -16,
      "y": 26,
      "z": 4,
      "name": "Rock_Ice_Permafrost"
    },
    {
      "x": -16,
      "y": 27,
      "z": 4,
      "name": "Rock_Ice_Permafrost"
    },
    {
      "x": -16,
      "y": 28,
      "z": 4,
      "name": "Rock_Ice_Permafrost"
    },
    {
      "x": -16,
      "y": 29,
      "z": 4,
      "name": "Rock_Ice"
    },
    {
      "x": -16,
      "y": 30,
      "z": 4,
      "name": "Rock_Ice"
    },
    {
      "x": -16,
      "y": 31,
      "z": 4,
      "name": "Rock_Ice"
    },
    {
      "x": -16,
      "y": 32,
      "z": 4,
      "name": "Rock_Ice_Permafrost"
    },
    {
      "x": -16,
      "y": 33,
      "z": 4,
      "name": "Rock_Ice_Permafrost"
    },
    {
      "x": -16,
      "y": 34,
      "z": 4,
      "name": "Rock_Ice_Permafrost"
    },
    {
      "x": -16,
      "y": 35,
      "z": 4,
      "name": "Rock_Crystal_Cyan_Block_WhiteLight"
    },
    {
      "x": -16,
      "y": 36,
      "z": 4,
      "name": "Rock_Ice_Permafrost"
    },
    {
      "x": -16,
      "y": 37,
      "z": 4,
      "name": "Rock_Ice_Permafrost"
    },
    {
      "x": -16,
      "y": 38,
      "z": 4,
      "name": "Rock_Crystal_Cyan_Block_WhiteLight"
    },
    {
      "x": -16,
      "y": 39,
      "z": 4,
      "name": "Rock_Ice_Permafrost"
    },
    {
      "x": -16,
      "y": 40,
      "z": 4,
      "name": "Rock_Ice_Permafrost"
    },
    {
      "x": -16,
      "y": 41,
      "z": 4,
      "name": "Rock_Ice_Permafrost"
    },
    {
      "x": -16,
      "y": 42,
      "z": 4,
      "name": "Rock_Ice_Permafrost"
    },
    {
      "x": -16,
      "y": 43,
      "z": 4,
      "name": "Rock_Ice_Permafrost"
    },
    {
      "x": -16,
      "y": 44,
      "z": 4,
      "name": "Rock_Ice_Permafrost"
    },
    {
      "x": -16,
      "y": 45,
      "z": 4,
      "name": "Rock_Ice"
    },
    {
      "x": -16,
      "y": 48,
      "z": 4,
      "name": "Rock_Ice"
    },
    {
      "x": -16,
      "y": 49,
      "z": 4,
      "name": "Rock_Ice_Permafrost"
    },
    {
      "x": -16,
      "y": 50,
      "z": 4,
      "name": "Rock_Ice_Permafrost"
    },
    {
      "x": -16,
      "y": 51,
      "z": 4,
      "name": "Rock_Ice"
    },
    {
      "x": -16,
      "y": 52,
      "z": 4,
      "name": "Rock_Ice_Permafrost"
    },
    {
      "x": -16,
      "y": 53,
      "z": 4,
      "name": "Rock_Ice_Permafrost"
    },
    {
      "x": -16,
      "y": 54,
      "z": 4,
      "name": "Rock_Ice_Permafrost"
    },
    {
      "x": -16,
      "y": 55,
      "z": 4,
      "name": "Rock_Ice_Permafrost"
    },
    {
      "x": -16,
      "y": 56,
      "z": 4,
      "name": "Rock_Ice_Permafrost"
    },
    {
      "x": -16,
      "y": 57,
      "z": 4,
      "name": "Rock_Ice"
    },
    {
      "x": -16,
      "y": 58,
      "z": 4,
      "name": "Soil_Snow"
    },
    {
      "x": -16,
      "y": 88,
      "z": 4,
      "name": "Rock_Ice"
    },
    {
      "x": -16,
      "y": 89,
      "z": 4,
      "name": "Rock_Ice_Permafrost"
    },
    {
      "x": -16,
      "y": 90,
      "z": 4,
      "name": "Rock_Ice"
    },
    {
      "x": -16,
      "y": 91,
      "z": 4,
      "name": "Rock_Ice"
    },
    {
      "x": -16,
      "y": 95,
      "z": 4,
      "name": "Rock_Ice_Permafrost"
    },
    {
      "x": -16,
      "y": 101,
      "z": 4,
      "name": "Rock_Ice"
    },
    {
      "x": -16,
      "y": 102,
      "z": 4,
      "name": "Rock_Ice"
    },
    {
      "x": -16,
      "y": 103,
      "z": 4,
      "name": "Rock_Ice"
    },
    {
      "x": -16,
      "y": 104,
      "z": 4,
      "name": "Rock_Ice"
    },
    {
      "x": -16,
      "y": 105,
      "z": 4,
      "name": "Soil_Snow"
    },
    {
      "x": -16,
      "y": 127,
      "z": 4,
      "name": "Rock_Ice"
    },
    {
      "x": -16,
      "y": 128,
      "z": 4,
      "name": "Rock_Ice_Permafrost"
    },
    {
      "x": -16,
      "y": 129,
      "z": 4,
      "name": "Rock_Ice_Permafrost"
    },
    {
      "x": -16,
      "y": 130,
      "z": 4,
      "name": "Rock_Ice_Permafrost"
    },
    {
      "x": -16,
      "y": 18,
      "z": 5,
      "name": "Rock_Ice"
    },
    {
      "x": -16,
      "y": 19,
      "z": 5,
      "name": "Rock_Ice"
    },
    {
      "x": -16,
      "y": 20,
      "z": 5,
      "name": "Rock_Ice"
    },
    {
      "x": -16,
      "y": 21,
      "z": 5,
      "name": "Rock_Ice"
    },
    {
      "x": -16,
      "y": 22,
      "z": 5,
      "name": "Rock_Ice"
    },
    {
      "x": -16,
      "y": 23,
      "z": 5,
      "name": "Rock_Ice_Permafrost"
    },
    {
      "x": -16,
      "y": 24,
      "z": 5,
      "name": "Rock_Ice_Permafrost"
    },
    {
      "x": -16,
      "y": 25,
      "z": 5,
      "name": "Rock_Ice_Permafrost"
    },
    {
      "x": -16,
      "y": 26,
      "z": 5,
      "name": "Rock_Ice"
    },
    {
      "x": -16,
      "y": 27,
      "z": 5,
      "name": "Rock_Ice_Permafrost"
    },
    {
      "x": -16,
      "y": 28,
      "z": 5,
      "name": "Rock_Ice_Permafrost"
    },
    {
      "x": -16,
      "y": 29,
      "z": 5,
      "name": "Rock_Crystal_Cyan_Block_WhiteLight"
    },
    {
      "x": -16,
      "y": 30,
      "z": 5,
      "name": "Rock_Crystal_Cyan_Block_WhiteLight"
    },
    {
      "x": -16,
      "y": 31,
      "z": 5,
      "name": "Rock_Crystal_Cyan_Block_WhiteLight"
    },
    {
      "x": -16,
      "y": 32,
      "z": 5,
      "name": "Rock_Ice_Permafrost"
    },
    {
      "x": -16,
      "y": 33,
      "z": 5,
      "name": "Rock_Crystal_Cyan_Block_WhiteLight"
    },
    {
      "x": -16,
      "y": 34,
      "z": 5,
      "name": "Rock_Crystal_Cyan_Block_WhiteLight"
    },
    {
      "x": -16,
      "y": 35,
      "z": 5,
      "name": "Rock_Ice_Permafrost"
    },
    {
      "x": -16,
      "y": 36,
      "z": 5,
      "name": "Rock_Ice_Permafrost"
    },
    {
      "x": -16,
      "y": 37,
      "z": 5,
      "name": "Rock_Ice_Permafrost"
    },
    {
      "x": -16,
      "y": 38,
      "z": 5,
      "name": "Rock_Ice"
    },
    {
      "x": -16,
      "y": 39,
      "z": 5,
      "name": "Rock_Ice_Permafrost"
    },
    {
      "x": -16,
      "y": 40,
      "z": 5,
      "name": "Rock_Ice_Permafrost"
    },
    {
      "x": -16,
      "y": 41,
      "z": 5,
      "name": "Rock_Ice"
    },
    {
      "x": -16,
      "y": 42,
      "z": 5,
      "name": "Rock_Ice"
    },
    {
      "x": -16,
      "y": 43,
      "z": 5,
      "name": "Rock_Ice"
    },
    {
      "x": -16,
      "y": 44,
      "z": 5,
      "name": "Rock_Ice"
    },
    {
      "x": -16,
      "y": 45,
      "z": 5,
      "name": "Rock_Ice"
    },
    {
      "x": -16,
      "y": 49,
      "z": 5,
      "name": "Rock_Ice"
    },
    {
      "x": -16,
      "y": 50,
      "z": 5,
      "name": "Rock_Ice"
    },
    {
      "x": -16,
      "y": 51,
      "z": 5,
      "name": "Rock_Ice"
    },
    {
      "x": -16,
      "y": 52,
      "z": 5,
      "name": "Rock_Ice"
    },
    {
      "x": -16,
      "y": 53,
      "z": 5,
      "name": "Rock_Ice"
    },
    {
      "x": -16,
      "y": 54,
      "z": 5,
      "name": "Rock_Ice_Permafrost"
    },
    {
      "x": -16,
      "y": 55,
      "z": 5,
      "name": "Rock_Ice_Permafrost"
    },
    {
      "x": -16,
      "y": 56,
      "z": 5,
      "name": "Rock_Ice_Permafrost"
    },
    {
      "x": -16,
      "y": 57,
      "z": 5,
      "name": "Rock_Ice"
    },
    {
      "x": -16,
      "y": 58,
      "z": 5,
      "name": "Soil_Snow"
    },
    {
      "x": -16,
      "y": 87,
      "z": 5,
      "name": "Rock_Ice_Permafrost"
    },
    {
      "x": -16,
      "y": 88,
      "z": 5,
      "name": "Rock_Ice"
    },
    {
      "x": -16,
      "y": 89,
      "z": 5,
      "name": "Rock_Ice"
    },
    {
      "x": -16,
      "y": 90,
      "z": 5,
      "name": "Rock_Ice_Permafrost"
    },
    {
      "x": -16,
      "y": 91,
      "z": 5,
      "name": "Rock_Ice_Permafrost"
    },
    {
      "x": -16,
      "y": 92,
      "z": 5,
      "name": "Rock_Crystal_Cyan_Block_WhiteLight"
    },
    {
      "x": -16,
      "y": 93,
      "z": 5,
      "name": "Rock_Crystal_Cyan_Block_WhiteLight"
    },
    {
      "x": -16,
      "y": 94,
      "z": 5,
      "name": "Rock_Crystal_Cyan_Block_WhiteLight"
    },
    {
      "x": -16,
      "y": 95,
      "z": 5,
      "name": "Rock_Ice_Permafrost"
    },
    {
      "x": -16,
      "y": 96,
      "z": 5,
      "name": "Rock_Ice_Permafrost"
    },
    {
      "x": -16,
      "y": 97,
      "z": 5,
      "name": "Rock_Ice_Permafrost"
    },
    {
      "x": -16,
      "y": 98,
      "z": 5,
      "name": "Rock_Ice_Permafrost"
    },
    {
      "x": -16,
      "y": 99,
      "z": 5,
      "name": "Rock_Crystal_Cyan_Block_WhiteLight"
    },
    {
      "x": -16,
      "y": 100,
      "z": 5,
      "name": "Rock_Ice_Permafrost"
    },
    {
      "x": -16,
      "y": 101,
      "z": 5,
      "name": "Rock_Ice"
    },
    {
      "x": -16,
      "y": 102,
      "z": 5,
      "name": "Rock_Ice"
    },
    {
      "x": -16,
      "y": 103,
      "z": 5,
      "name": "Rock_Ice"
    },
    {
      "x": -16,
      "y": 104,
      "z": 5,
      "name": "Rock_Ice"
    },
    {
      "x": -16,
      "y": 105,
      "z": 5,
      "name": "Soil_Snow"
    },
    {
      "x": -16,
      "y": 18,
      "z": 6,
      "name": "Rock_Ice"
    },
    {
      "x": -16,
      "y": 19,
      "z": 6,
      "name": "Rock_Ice"
    },
    {
      "x": -16,
      "y": 20,
      "z": 6,
      "name": "Rock_Ice"
    },
    {
      "x": -16,
      "y": 21,
      "z": 6,
      "name": "Rock_Ice"
    },
    {
      "x": -16,
      "y": 22,
      "z": 6,
      "name": "Rock_Ice"
    },
    {
      "x": -16,
      "y": 23,
      "z": 6,
      "name": "Rock_Ice_Permafrost"
    },
    {
      "x": -16,
      "y": 24,
      "z": 6,
      "name": "Rock_Ice"
    },
    {
      "x": -16,
      "y": 25,
      "z": 6,
      "name": "Rock_Ice"
    },
    {
      "x": -16,
      "y": 26,
      "z": 6,
      "name": "Rock_Ice_Permafrost"
    },
    {
      "x": -16,
      "y": 27,
      "z": 6,
      "name": "Rock_Crystal_Cyan_Block_WhiteLight"
    },
    {
      "x": -16,
      "y": 28,
      "z": 6,
      "name": "Rock_Ice_Permafrost"
    },
    {
      "x": -16,
      "y": 29,
      "z": 6,
      "name": "Rock_Ice_Permafrost"
    },
    {
      "x": -16,
      "y": 30,
      "z": 6,
      "name": "Rock_Ice_Permafrost"
    },
    {
      "x": -16,
      "y": 31,
      "z": 6,
      "name": "Rock_Ice_Permafrost"
    },
    {
      "x": -16,
      "y": 32,
      "z": 6,
      "name": "Rock_Ice"
    },
    {
      "x": -16,
      "y": 33,
      "z": 6,
      "name": "Rock_Ice"
    },
    {
      "x": -16,
      "y": 34,
      "z": 6,
      "name": "Rock_Ice"
    },
    {
      "x": -16,
      "y": 35,
      "z": 6,
      "name": "Rock_Ice"
    },
    {
      "x": -16,
      "y": 36,
      "z": 6,
      "name": "Rock_Ice"
    },
    {
      "x": -16,
      "y": 37,
      "z": 6,
      "name": "Rock_Ice"
    },
    {
      "x": -16,
      "y": 38,
      "z": 6,
      "name": "Rock_Ice"
    },
    {
      "x": -16,
      "y": 39,
      "z": 6,
      "name": "Rock_Ice"
    },
    {
      "x": -16,
      "y": 40,
      "z": 6,
      "name": "Rock_Ice"
    },
    {
      "x": -16,
      "y": 41,
      "z": 6,
      "name": "Rock_Ice"
    },
    {
      "x": -16,
      "y": 42,
      "z": 6,
      "name": "Rock_Ice"
    },
    {
      "x": -16,
      "y": 43,
      "z": 6,
      "name": "Rock_Ice"
    },
    {
      "x": -16,
      "y": 44,
      "z": 6,
      "name": "Rock_Ice"
    },
    {
      "x": -16,
      "y": 45,
      "z": 6,
      "name": "Rock_Ice"
    },
    {
      "x": -16,
      "y": 50,
      "z": 6,
      "name": "Rock_Ice"
    },
    {
      "x": -16,
      "y": 51,
      "z": 6,
      "name": "Rock_Ice"
    },
    {
      "x": -16,
      "y": 52,
      "z": 6,
      "name": "Rock_Ice_Permafrost"
    },
    {
      "x": -16,
      "y": 53,
      "z": 6,
      "name": "Rock_Ice"
    },
    {
      "x": -16,
      "y": 54,
      "z": 6,
      "name": "Rock_Ice_Permafrost"
    },
    {
      "x": -16,
      "y": 55,
      "z": 6,
      "name": "Rock_Ice_Permafrost"
    },
    {
      "x": -16,
      "y": 56,
      "z": 6,
      "name": "Rock_Crystal_Cyan_Block_WhiteLight"
    },
    {
      "x": -16,
      "y": 57,
      "z": 6,
      "name": "Rock_Crystal_Cyan_Block_WhiteLight"
    },
    {
      "x": -16,
      "y": 58,
      "z": 6,
      "name": "Rock_Ice"
    },
    {
      "x": -16,
      "y": 59,
      "z": 6,
      "name": "Soil_Snow"
    },
    {
      "x": -16,
      "y": 85,
      "z": 6,
      "name": "Rock_Ice_Permafrost"
    },
    {
      "x": -16,
      "y": 86,
      "z": 6,
      "name": "Rock_Ice_Permafrost"
    },
    {
      "x": -16,
      "y": 87,
      "z": 6,
      "name": "Rock_Ice_Permafrost"
    },
    {
      "x": -16,
      "y": 88,
      "z": 6,
      "name": "Rock_Ice_Permafrost"
    },
    {
      "x": -16,
      "y": 89,
      "z": 6,
      "name": "Rock_Crystal_Cyan_Block_WhiteLight"
    },
    {
      "x": -16,
      "y": 90,
      "z": 6,
      "name": "Rock_Ice_Permafrost"
    },
    {
      "x": -16,
      "y": 91,
      "z": 6,
      "name": "Rock_Ice_Permafrost"
    },
    {
      "x": -16,
      "y": 92,
      "z": 6,
      "name": "Rock_Ice_Permafrost"
    },
    {
      "x": -16,
      "y": 93,
      "z": 6,
      "name": "Rock_Crystal_Cyan_Block_WhiteLight"
    },
    {
      "x": -16,
      "y": 94,
      "z": 6,
      "name": "Rock_Ice_Permafrost"
    },
    {
      "x": -16,
      "y": 95,
      "z": 6,
      "name": "Rock_Ice_Permafrost"
    },
    {
      "x": -16,
      "y": 96,
      "z": 6,
      "name": "Rock_Ice_Permafrost"
    },
    {
      "x": -16,
      "y": 97,
      "z": 6,
      "name": "Rock_Ice_Permafrost"
    },
    {
      "x": -16,
      "y": 98,
      "z": 6,
      "name": "Rock_Ice_Permafrost"
    },
    {
      "x": -16,
      "y": 99,
      "z": 6,
      "name": "Rock_Ice_Permafrost"
    },
    {
      "x": -16,
      "y": 100,
      "z": 6,
      "name": "Rock_Ice_Permafrost"
    },
    {
      "x": -16,
      "y": 101,
      "z": 6,
      "name": "Rock_Ice"
    },
    {
      "x": -16,
      "y": 102,
      "z": 6,
      "name": "Rock_Ice"
    },
    {
      "x": -16,
      "y": 103,
      "z": 6,
      "name": "Rock_Ice"
    },
    {
      "x": -16,
      "y": 17,
      "z": 7,
      "name": "Rock_Ice"
    },
    {
      "x": -16,
      "y": 18,
      "z": 7,
      "name": "Rock_Ice"
    },
    {
      "x": -16,
      "y": 19,
      "z": 7,
      "name": "Rock_Ice"
    },
    {
      "x": -16,
      "y": 20,
      "z": 7,
      "name": "Rock_Ice"
    },
    {
      "x": -16,
      "y": 21,
      "z": 7,
      "name": "Rock_Ice"
    },
    {
      "x": -16,
      "y": 22,
      "z": 7,
      "name": "Rock_Ice"
    },
    {
      "x": -16,
      "y": 23,
      "z": 7,
      "name": "Rock_Ice_Permafrost"
    },
    {
      "x": -16,
      "y": 24,
      "z": 7,
      "name": "Rock_Ice"
    },
    {
      "x": -16,
      "y": 25,
      "z": 7,
      "name": "Rock_Ice"
    },
    {
      "x": -16,
      "y": 26,
      "z": 7,
      "name": "Rock_Ice_Permafrost"
    },
    {
      "x": -16,
      "y": 27,
      "z": 7,
      "name": "Rock_Ice_Permafrost"
    },
    {
      "x": -16,
      "y": 28,
      "z": 7,
      "name": "Rock_Ice_Permafrost"
    },
    {
      "x": -16,
      "y": 29,
      "z": 7,
      "name": "Rock_Ice"
    },
    {
      "x": -16,
      "y": 30,
      "z": 7,
      "name": "Rock_Ice"
    },
    {
      "x": -16,
      "y": 31,
      "z": 7,
      "name": "Rock_Ice"
    },
    {
      "x": -16,
      "y": 32,
      "z": 7,
      "name": "Rock_Ice"
    },
    {
      "x": -16,
      "y": 33,
      "z": 7,
      "name": "Rock_Ice"
    },
    {
      "x": -16,
      "y": 34,
      "z": 7,
      "name": "Rock_Ice"
    },
    {
      "x": -16,
      "y": 35,
      "z": 7,
      "name": "Rock_Ice"
    },
    {
      "x": -16,
      "y": 36,
      "z": 7,
      "name": "Rock_Ice"
    },
    {
      "x": -16,
      "y": 37,
      "z": 7,
      "name": "Rock_Ice"
    },
    {
      "x": -16,
      "y": 38,
      "z": 7,
      "name": "Rock_Ice"
    },
    {
      "x": -16,
      "y": 39,
      "z": 7,
      "name": "Rock_Ice"
    },
    {
      "x": -16,
      "y": 40,
      "z": 7,
      "name": "Rock_Ice"
    },
    {
      "x": -16,
      "y": 41,
      "z": 7,
      "name": "Rock_Ice"
    },
    {
      "x": -16,
      "y": 42,
      "z": 7,
      "name": "Rock_Ice"
    },
    {
      "x": -16,
      "y": 43,
      "z": 7,
      "name": "Rock_Ice"
    },
    {
      "x": -16,
      "y": 44,
      "z": 7,
      "name": "Rock_Ice"
    },
    {
      "x": -16,
      "y": 45,
      "z": 7,
      "name": "Rock_Ice"
    },
    {
      "x": -16,
      "y": 46,
      "z": 7,
      "name": "Rock_Ice"
    },
    {
      "x": -16,
      "y": 52,
      "z": 7,
      "name": "Rock_Ice"
    },
    {
      "x": -16,
      "y": 53,
      "z": 7,
      "name": "Rock_Crystal_Cyan_Block_WhiteLight"
    },
    {
      "x": -16,
      "y": 54,
      "z": 7,
      "name": "Rock_Ice_Permafrost"
    },
    {
      "x": -16,
      "y": 55,
      "z": 7,
      "name": "Rock_Ice"
    },
    {
      "x": -16,
      "y": 56,
      "z": 7,
      "name": "Rock_Ice_Permafrost"
    },
    {
      "x": -16,
      "y": 57,
      "z": 7,
      "name": "Rock_Ice_Permafrost"
    },
    {
      "x": -16,
      "y": 58,
      "z": 7,
      "name": "Rock_Crystal_Cyan_Block_WhiteLight"
    },
    {
      "x": -16,
      "y": 59,
      "z": 7,
      "name": "Soil_Snow"
    },
    {
      "x": -16,
      "y": 83,
      "z": 7,
      "name": "Rock_Ice"
    },
    {
      "x": -16,
      "y": 84,
      "z": 7,
      "name": "Rock_Ice_Permafrost"
    },
    {
      "x": -16,
      "y": 85,
      "z": 7,
      "name": "Rock_Ice_Permafrost"
    },
    {
      "x": -16,
      "y": 86,
      "z": 7,
      "name": "Rock_Ice_Permafrost"
    },
    {
      "x": -16,
      "y": 87,
      "z": 7,
      "name": "Rock_Ice_Permafrost"
    },
    {
      "x": -16,
      "y": 88,
      "z": 7,
      "name": "Rock_Ice_Permafrost"
    },
    {
      "x": -16,
      "y": 89,
      "z": 7,
      "name": "Rock_Ice_Permafrost"
    },
    {
      "x": -16,
      "y": 91,
      "z": 7,
      "name": "Rock_Ice_Permafrost"
    },
    {
      "x": -16,
      "y": 92,
      "z": 7,
      "name": "Rock_Ice_Permafrost"
    },
    {
      "x": -16,
      "y": 93,
      "z": 7,
      "name": "Rock_Ice_Permafrost"
    },
    {
      "x": -16,
      "y": 94,
      "z": 7,
      "name": "Rock_Ice"
    },
    {
      "x": -16,
      "y": 95,
      "z": 7,
      "name": "Rock_Ice"
    },
    {
      "x": -16,
      "y": 96,
      "z": 7,
      "name": "Rock_Ice"
    },
    {
      "x": -16,
      "y": 97,
      "z": 7,
      "name": "Rock_Ice_Permafrost"
    },
    {
      "x": -16,
      "y": 98,
      "z": 7,
      "name": "Rock_Ice_Permafrost"
    },
    {
      "x": -16,
      "y": 99,
      "z": 7,
      "name": "Rock_Ice_Permafrost"
    },
    {
      "x": -16,
      "y": 100,
      "z": 7,
      "name": "Rock_Ice"
    },
    {
      "x": -16,
      "y": 101,
      "z": 7,
      "name": "Soil_Snow"
    },
    {
      "x": -16,
      "y": 17,
      "z": 8,
      "name": "Rock_Ice"
    },
    {
      "x": -16,
      "y": 18,
      "z": 8,
      "name": "Rock_Ice"
    },
    {
      "x": -16,
      "y": 19,
      "z": 8,
      "name": "Rock_Ice"
    },
    {
      "x": -16,
      "y": 20,
      "z": 8,
      "name": "Rock_Ice_Permafrost"
    },
    {
      "x": -16,
      "y": 21,
      "z": 8,
      "name": "Rock_Ice"
    },
    {
      "x": -16,
      "y": 22,
      "z": 8,
      "name": "Rock_Ice"
    },
    {
      "x": -16,
      "y": 23,
      "z": 8,
      "name": "Rock_Ice"
    },
    {
      "x": -16,
      "y": 24,
      "z": 8,
      "name": "Rock_Ice"
    },
    {
      "x": -16,
      "y": 25,
      "z": 8,
      "name": "Rock_Ice"
    },
    {
      "x": -16,
      "y": 26,
      "z": 8,
      "name": "Rock_Ice"
    },
    {
      "x": -16,
      "y": 27,
      "z": 8,
      "name": "Rock_Ice"
    },
    {
      "x": -16,
      "y": 28,
      "z": 8,
      "name": "Rock_Ice"
    },
    {
      "x": -16,
      "y": 29,
      "z": 8,
      "name": "Rock_Ice"
    },
    {
      "x": -16,
      "y": 30,
      "z": 8,
      "name": "Rock_Ice"
    },
    {
      "x": -16,
      "y": 31,
      "z": 8,
      "name": "Rock_Ice"
    },
    {
      "x": -16,
      "y": 32,
      "z": 8,
      "name": "Rock_Ice"
    },
    {
      "x": -16,
      "y": 33,
      "z": 8,
      "name": "Rock_Ice"
    },
    {
      "x": -16,
      "y": 34,
      "z": 8,
      "name": "Rock_Ice"
    },
    {
      "x": -16,
      "y": 35,
      "z": 8,
      "name": "Rock_Ice"
    },
    {
      "x": -16,
      "y": 36,
      "z": 8,
      "name": "Rock_Ice"
    },
    {
      "x": -16,
      "y": 37,
      "z": 8,
      "name": "Rock_Ice"
    },
    {
      "x": -16,
      "y": 38,
      "z": 8,
      "name": "Rock_Ice"
    },
    {
      "x": -16,
      "y": 39,
      "z": 8,
      "name": "Rock_Ice"
    },
    {
      "x": -16,
      "y": 40,
      "z": 8,
      "name": "Rock_Ice"
    },
    {
      "x": -16,
      "y": 41,
      "z": 8,
      "name": "Rock_Ice"
    },
    {
      "x": -16,
      "y": 42,
      "z": 8,
      "name": "Rock_Ice"
    },
    {
      "x": -16,
      "y": 43,
      "z": 8,
      "name": "Rock_Ice"
    },
    {
      "x": -16,
      "y": 44,
      "z": 8,
      "name": "Rock_Ice"
    },
    {
      "x": -16,
      "y": 45,
      "z": 8,
      "name": "Rock_Ice"
    },
    {
      "x": -16,
      "y": 46,
      "z": 8,
      "name": "Rock_Ice"
    },
    {
      "x": -16,
      "y": 47,
      "z": 8,
      "name": "Rock_Ice_Permafrost"
    },
    {
      "x": -16,
      "y": 53,
      "z": 8,
      "name": "Rock_Ice"
    },
    {
      "x": -16,
      "y": 54,
      "z": 8,
      "name": "Rock_Ice"
    },
    {
      "x": -16,
      "y": 55,
      "z": 8,
      "name": "Rock_Ice"
    },
    {
      "x": -16,
      "y": 56,
      "z": 8,
      "name": "Soil_Snow"
    },
    {
      "x": -16,
      "y": 96,
      "z": 8,
      "name": "Rock_Ice"
    },
    {
      "x": -16,
      "y": 97,
      "z": 8,
      "name": "Rock_Ice"
    },
    {
      "x": -16,
      "y": 98,
      "z": 8,
      "name": "Rock_Ice_Permafrost"
    },
    {
      "x": -16,
      "y": 99,
      "z": 8,
      "name": "Rock_Crystal_Cyan_Block_WhiteLight"
    },
    {
      "x": -16,
      "y": 100,
      "z": 8,
      "name": "Rock_Ice"
    },
    {
      "x": -16,
      "y": 101,
      "z": 8,
      "name": "Soil_Snow"
    },
    {
      "x": -16,
      "y": 18,
      "z": 9,
      "name": "Rock_Ice"
    },
    {
      "x": -16,
      "y": 19,
      "z": 9,
      "name": "Rock_Ice"
    },
    {
      "x": -16,
      "y": 20,
      "z": 9,
      "name": "Rock_Ice"
    },
    {
      "x": -16,
      "y": 21,
      "z": 9,
      "name": "Rock_Ice"
    },
    {
      "x": -16,
      "y": 22,
      "z": 9,
      "name": "Rock_Ice"
    },
    {
      "x": -16,
      "y": 23,
      "z": 9,
      "name": "Rock_Ice"
    },
    {
      "x": -16,
      "y": 24,
      "z": 9,
      "name": "Rock_Ice"
    },
    {
      "x": -16,
      "y": 25,
      "z": 9,
      "name": "Rock_Ice"
    },
    {
      "x": -16,
      "y": 26,
      "z": 9,
      "name": "Rock_Ice"
    },
    {
      "x": -16,
      "y": 27,
      "z": 9,
      "name": "Rock_Ice"
    },
    {
      "x": -16,
      "y": 28,
      "z": 9,
      "name": "Rock_Ice"
    },
    {
      "x": -16,
      "y": 29,
      "z": 9,
      "name": "Rock_Ice"
    },
    {
      "x": -16,
      "y": 30,
      "z": 9,
      "name": "Rock_Ice"
    },
    {
      "x": -16,
      "y": 31,
      "z": 9,
      "name": "Rock_Ice"
    },
    {
      "x": -16,
      "y": 32,
      "z": 9,
      "name": "Rock_Ice"
    },
    {
      "x": -16,
      "y": 33,
      "z": 9,
      "name": "Rock_Ice"
    },
    {
      "x": -16,
      "y": 34,
      "z": 9,
      "name": "Rock_Ice"
    },
    {
      "x": -16,
      "y": 35,
      "z": 9,
      "name": "Rock_Ice"
    },
    {
      "x": -16,
      "y": 36,
      "z": 9,
      "name": "Rock_Ice"
    },
    {
      "x": -16,
      "y": 37,
      "z": 9,
      "name": "Rock_Ice"
    },
    {
      "x": -16,
      "y": 38,
      "z": 9,
      "name": "Rock_Ice"
    },
    {
      "x": -16,
      "y": 39,
      "z": 9,
      "name": "Rock_Ice"
    },
    {
      "x": -16,
      "y": 40,
      "z": 9,
      "name": "Rock_Ice"
    },
    {
      "x": -16,
      "y": 41,
      "z": 9,
      "name": "Rock_Ice"
    },
    {
      "x": -16,
      "y": 42,
      "z": 9,
      "name": "Rock_Ice"
    },
    {
      "x": -16,
      "y": 43,
      "z": 9,
      "name": "Rock_Ice_Permafrost"
    },
    {
      "x": -16,
      "y": 44,
      "z": 9,
      "name": "Rock_Ice_Permafrost"
    },
    {
      "x": -16,
      "y": 45,
      "z": 9,
      "name": "Rock_Ice_Permafrost"
    },
    {
      "x": -16,
      "y": 46,
      "z": 9,
      "name": "Rock_Ice_Permafrost"
    },
    {
      "x": -16,
      "y": 47,
      "z": 9,
      "name": "Rock_Ice"
    },
    {
      "x": -16,
      "y": 48,
      "z": 9,
      "name": "Soil_Snow"
    },
    {
      "x": -16,
      "y": 98,
      "z": 9,
      "name": "Rock_Ice"
    },
    {
      "x": -16,
      "y": 99,
      "z": 9,
      "name": "Rock_Ice"
    },
    {
      "x": -16,
      "y": 100,
      "z": 9,
      "name": "Soil_Snow"
    },
    {
      "x": -16,
      "y": 18,
      "z": 10,
      "name": "Rock_Ice"
    },
    {
      "x": -16,
      "y": 19,
      "z": 10,
      "name": "Rock_Ice"
    },
    {
      "x": -16,
      "y": 20,
      "z": 10,
      "name": "Rock_Ice"
    },
    {
      "x": -16,
      "y": 21,
      "z": 10,
      "name": "Rock_Ice"
    },
    {
      "x": -16,
      "y": 22,
      "z": 10,
      "name": "Rock_Ice"
    },
    {
      "x": -16,
      "y": 23,
      "z": 10,
      "name": "Rock_Ice"
    },
    {
      "x": -16,
      "y": 24,
      "z": 10,
      "name": "Rock_Ice"
    },
    {
      "x": -16,
      "y": 25,
      "z": 10,
      "name": "Rock_Ice"
    },
    {
      "x": -16,
      "y": 26,
      "z": 10,
      "name": "Rock_Ice"
    },
    {
      "x": -16,
      "y": 27,
      "z": 10,
      "name": "Rock_Ice"
    },
    {
      "x": -16,
      "y": 28,
      "z": 10,
      "name": "Rock_Ice"
    },
    {
      "x": -16,
      "y": 29,
      "z": 10,
      "name": "Rock_Ice"
    },
    {
      "x": -16,
      "y": 30,
      "z": 10,
      "name": "Rock_Ice"
    },
    {
      "x": -16,
      "y": 31,
      "z": 10,
      "name": "Rock_Ice"
    },
    {
      "x": -16,
      "y": 32,
      "z": 10,
      "name": "Rock_Ice"
    },
    {
      "x": -16,
      "y": 33,
      "z": 10,
      "name": "Rock_Ice"
    },
    {
      "x": -16,
      "y": 34,
      "z": 10,
      "name": "Rock_Ice"
    },
    {
      "x": -16,
      "y": 35,
      "z": 10,
      "name": "Rock_Ice"
    },
    {
      "x": -16,
      "y": 37,
      "z": 10,
      "name": "Rock_Ice"
    },
    {
      "x": -16,
      "y": 38,
      "z": 10,
      "name": "Rock_Ice"
    },
    {
      "x": -16,
      "y": 39,
      "z": 10,
      "name": "Rock_Ice"
    },
    {
      "x": -16,
      "y": 40,
      "z": 10,
      "name": "Rock_Ice"
    },
    {
      "x": -16,
      "y": 41,
      "z": 10,
      "name": "Rock_Ice"
    },
    {
      "x": -16,
      "y": 42,
      "z": 10,
      "name": "Rock_Ice"
    },
    {
      "x": -16,
      "y": 43,
      "z": 10,
      "name": "Rock_Ice_Permafrost"
    },
    {
      "x": -16,
      "y": 44,
      "z": 10,
      "name": "Rock_Ice_Permafrost"
    },
    {
      "x": -16,
      "y": 45,
      "z": 10,
      "name": "Rock_Ice_Permafrost"
    },
    {
      "x": -16,
      "y": 46,
      "z": 10,
      "name": "Rock_Ice_Permafrost"
    },
    {
      "x": -16,
      "y": 47,
      "z": 10,
      "name": "Rock_Ice_Permafrost"
    },
    {
      "x": -16,
      "y": 48,
      "z": 10,
      "name": "Rock_Ice_Permafrost"
    },
    {
      "x": -16,
      "y": 49,
      "z": 10,
      "name": "Rock_Ice"
    },
    {
      "x": -16,
      "y": 50,
      "z": 10,
      "name": "Rock_Ice"
    },
    {
      "x": -16,
      "y": 99,
      "z": 10,
      "name": "Soil_Snow"
    },
    {
      "x": -16,
      "y": 19,
      "z": 11,
      "name": "Rock_Ice"
    },
    {
      "x": -16,
      "y": 20,
      "z": 11,
      "name": "Rock_Ice"
    },
    {
      "x": -16,
      "y": 21,
      "z": 11,
      "name": "Rock_Ice"
    },
    {
      "x": -16,
      "y": 22,
      "z": 11,
      "name": "Rock_Ice"
    },
    {
      "x": -16,
      "y": 23,
      "z": 11,
      "name": "Rock_Ice"
    },
    {
      "x": -16,
      "y": 24,
      "z": 11,
      "name": "Rock_Ice"
    },
    {
      "x": -16,
      "y": 25,
      "z": 11,
      "name": "Rock_Ice"
    },
    {
      "x": -16,
      "y": 26,
      "z": 11,
      "name": "Rock_Ice"
    },
    {
      "x": -16,
      "y": 27,
      "z": 11,
      "name": "Rock_Ice"
    },
    {
      "x": -16,
      "y": 28,
      "z": 11,
      "name": "Rock_Ice"
    },
    {
      "x": -16,
      "y": 29,
      "z": 11,
      "name": "Rock_Ice"
    },
    {
      "x": -16,
      "y": 30,
      "z": 11,
      "name": "Rock_Ice"
    },
    {
      "x": -16,
      "y": 31,
      "z": 11,
      "name": "Rock_Ice"
    },
    {
      "x": -16,
      "y": 32,
      "z": 11,
      "name": "Rock_Ice"
    },
    {
      "x": -16,
      "y": 43,
      "z": 11,
      "name": "Rock_Ice_Permafrost"
    },
    {
      "x": -16,
      "y": 44,
      "z": 11,
      "name": "Rock_Ice_Permafrost"
    },
    {
      "x": -16,
      "y": 45,
      "z": 11,
      "name": "Rock_Ice_Permafrost"
    },
    {
      "x": -16,
      "y": 46,
      "z": 11,
      "name": "Rock_Ice"
    },
    {
      "x": -16,
      "y": 47,
      "z": 11,
      "name": "Rock_Ice"
    },
    {
      "x": -16,
      "y": 48,
      "z": 11,
      "name": "Rock_Ice"
    },
    {
      "x": -16,
      "y": 49,
      "z": 11,
      "name": "Rock_Ice"
    },
    {
      "x": -16,
      "y": 50,
      "z": 11,
      "name": "Rock_Ice"
    },
    {
      "x": -16,
      "y": 51,
      "z": 11,
      "name": "Rock_Ice"
    },
    {
      "x": -16,
      "y": 52,
      "z": 11,
      "name": "Soil_Snow"
    },
    {
      "x": -16,
      "y": 20,
      "z": 12,
      "name": "Rock_Ice"
    },
    {
      "x": -16,
      "y": 21,
      "z": 12,
      "name": "Rock_Ice"
    },
    {
      "x": -16,
      "y": 22,
      "z": 12,
      "name": "Rock_Ice"
    },
    {
      "x": -16,
      "y": 26,
      "z": 12,
      "name": "Rock_Ice"
    },
    {
      "x": -16,
      "y": 27,
      "z": 12,
      "name": "Rock_Ice"
    },
    {
      "x": -16,
      "y": 28,
      "z": 12,
      "name": "Rock_Ice"
    },
    {
      "x": -16,
      "y": 29,
      "z": 12,
      "name": "Rock_Ice"
    },
    {
      "x": -16,
      "y": 30,
      "z": 12,
      "name": "Soil_Snow"
    },
    {
      "x": -16,
      "y": 21,
      "z": 13,
      "name": "Rock_Ice"
    },
    {
      "x": -16,
      "y": 22,
      "z": 13,
      "name": "Rock_Ice"
    },
    {
      "x": -16,
      "y": 27,
      "z": 13,
      "name": "Rock_Ice"
    },
    {
      "x": -16,
      "y": 28,
      "z": 13,
      "name": "Soil_Snow"
    },
    {
      "x": -15,
      "y": 20,
      "z": -10,
      "name": "Rock_Ice_Permafrost"
    },
    {
      "x": -15,
      "y": 21,
      "z": -10,
      "name": "Rock_Crystal_Cyan_Block_WhiteLight"
    },
    {
      "x": -15,
      "y": 22,
      "z": -10,
      "name": "Rock_Ice_Permafrost"
    },
    {
      "x": -15,
      "y": 23,
      "z": -10,
      "name": "Rock_Ice"
    },
    {
      "x": -15,
      "y": 24,
      "z": -10,
      "name": "Soil_Snow"
    },
    {
      "x": -15,
      "y": 20,
      "z": -9,
      "name": "Rock_Ice"
    },
    {
      "x": -15,
      "y": 21,
      "z": -9,
      "name": "Rock_Ice_Permafrost"
    },
    {
      "x": -15,
      "y": 22,
      "z": -9,
      "name": "Rock_Ice_Permafrost"
    },
    {
      "x": -15,
      "y": 23,
      "z": -9,
      "name": "Rock_Ice_Permafrost"
    },
    {
      "x": -15,
      "y": 24,
      "z": -9,
      "name": "Rock_Crystal_Cyan_Block_WhiteLight"
    },
    {
      "x": -15,
      "y": 25,
      "z": -9,
      "name": "Rock_Ice_Permafrost"
    },
    {
      "x": -15,
      "y": 26,
      "z": -9,
      "name": "Rock_Ice_Permafrost"
    },
    {
      "x": -15,
      "y": 27,
      "z": -9,
      "name": "Rock_Ice_Permafrost"
    },
    {
      "x": -15,
      "y": 28,
      "z": -9,
      "name": "Rock_Ice"
    },
    {
      "x": -15,
      "y": 29,
      "z": -9,
      "name": "Soil_Snow"
    },
    {
      "x": -15,
      "y": 20,
      "z": -8,
      "name": "Rock_Ice"
    },
    {
      "x": -15,
      "y": 21,
      "z": -8,
      "name": "Rock_Ice"
    },
    {
      "x": -15,
      "y": 22,
      "z": -8,
      "name": "Rock_Ice"
    },
    {
      "x": -15,
      "y": 23,
      "z": -8,
      "name": "Rock_Ice_Permafrost"
    },
    {
      "x": -15,
      "y": 24,
      "z": -8,
      "name": "Rock_Ice_Permafrost"
    },
    {
      "x": -15,
      "y": 25,
      "z": -8,
      "name": "Rock_Ice_Permafrost"
    },
    {
      "x": -15,
      "y": 26,
      "z": -8,
      "name": "Rock_Crystal_Cyan_Block_WhiteLight"
    },
    {
      "x": -15,
      "y": 27,
      "z": -8,
      "name": "Rock_Ice_Permafrost"
    },
    {
      "x": -15,
      "y": 28,
      "z": -8,
      "name": "Rock_Ice_Permafrost"
    },
    {
      "x": -15,
      "y": 29,
      "z": -8,
      "name": "Rock_Crystal_Cyan_Block_WhiteLight"
    },
    {
      "x": -15,
      "y": 30,
      "z": -8,
      "name": "Rock_Ice_Permafrost"
    },
    {
      "x": -15,
      "y": 31,
      "z": -8,
      "name": "Rock_Crystal_Cyan_Block_WhiteLight"
    },
    {
      "x": -15,
      "y": 32,
      "z": -8,
      "name": "Rock_Ice_Permafrost"
    },
    {
      "x": -15,
      "y": 33,
      "z": -8,
      "name": "Rock_Ice"
    },
    {
      "x": -15,
      "y": 34,
      "z": -8,
      "name": "Soil_Snow"
    },
    {
      "x": -15,
      "y": 20,
      "z": -7,
      "name": "Rock_Ice"
    },
    {
      "x": -15,
      "y": 21,
      "z": -7,
      "name": "Rock_Ice"
    },
    {
      "x": -15,
      "y": 22,
      "z": -7,
      "name": "Rock_Ice"
    },
    {
      "x": -15,
      "y": 23,
      "z": -7,
      "name": "Rock_Ice"
    },
    {
      "x": -15,
      "y": 24,
      "z": -7,
      "name": "Rock_Ice"
    },
    {
      "x": -15,
      "y": 25,
      "z": -7,
      "name": "Rock_Ice"
    },
    {
      "x": -15,
      "y": 26,
      "z": -7,
      "name": "Rock_Ice_Permafrost"
    },
    {
      "x": -15,
      "y": 27,
      "z": -7,
      "name": "Rock_Ice_Permafrost"
    },
    {
      "x": -15,
      "y": 28,
      "z": -7,
      "name": "Rock_Ice_Permafrost"
    },
    {
      "x": -15,
      "y": 29,
      "z": -7,
      "name": "Rock_Ice_Permafrost"
    },
    {
      "x": -15,
      "y": 30,
      "z": -7,
      "name": "Rock_Ice_Permafrost"
    },
    {
      "x": -15,
      "y": 31,
      "z": -7,
      "name": "Rock_Ice_Permafrost"
    },
    {
      "x": -15,
      "y": 32,
      "z": -7,
      "name": "Rock_Ice_Permafrost"
    },
    {
      "x": -15,
      "y": 33,
      "z": -7,
      "name": "Rock_Ice_Permafrost"
    },
    {
      "x": -15,
      "y": 34,
      "z": -7,
      "name": "Rock_Ice_Permafrost"
    },
    {
      "x": -15,
      "y": 35,
      "z": -7,
      "name": "Rock_Ice_Permafrost"
    },
    {
      "x": -15,
      "y": 19,
      "z": -6,
      "name": "Rock_Ice"
    },
    {
      "x": -15,
      "y": 20,
      "z": -6,
      "name": "Rock_Ice"
    },
    {
      "x": -15,
      "y": 21,
      "z": -6,
      "name": "Rock_Ice"
    },
    {
      "x": -15,
      "y": 22,
      "z": -6,
      "name": "Rock_Ice"
    },
    {
      "x": -15,
      "y": 23,
      "z": -6,
      "name": "Rock_Ice"
    },
    {
      "x": -15,
      "y": 24,
      "z": -6,
      "name": "Rock_Ice"
    },
    {
      "x": -15,
      "y": 25,
      "z": -6,
      "name": "Rock_Ice_Permafrost"
    },
    {
      "x": -15,
      "y": 26,
      "z": -6,
      "name": "Rock_Ice_Permafrost"
    },
    {
      "x": -15,
      "y": 27,
      "z": -6,
      "name": "Rock_Crystal_Cyan_Block_WhiteLight"
    },
    {
      "x": -15,
      "y": 28,
      "z": -6,
      "name": "Rock_Crystal_Cyan_Block_WhiteLight"
    },
    {
      "x": -15,
      "y": 29,
      "z": -6,
      "name": "Rock_Ice_Permafrost"
    },
    {
      "x": -15,
      "y": 30,
      "z": -6,
      "name": "Rock_Ice_Permafrost"
    },
    {
      "x": -15,
      "y": 31,
      "z": -6,
      "name": "Rock_Ice_Permafrost"
    },
    {
      "x": -15,
      "y": 32,
      "z": -6,
      "name": "Rock_Ice_Permafrost"
    },
    {
      "x": -15,
      "y": 33,
      "z": -6,
      "name": "Rock_Ice"
    },
    {
      "x": -15,
      "y": 34,
      "z": -6,
      "name": "Rock_Ice"
    },
    {
      "x": -15,
      "y": 35,
      "z": -6,
      "name": "Soil_Snow"
    },
    {
      "x": -15,
      "y": 17,
      "z": -5,
      "name": "Rock_Ice"
    },
    {
      "x": -15,
      "y": 18,
      "z": -5,
      "name": "Rock_Ice"
    },
    {
      "x": -15,
      "y": 19,
      "z": -5,
      "name": "Rock_Ice"
    },
    {
      "x": -15,
      "y": 20,
      "z": -5,
      "name": "Rock_Ice"
    },
    {
      "x": -15,
      "y": 21,
      "z": -5,
      "name": "Rock_Ice"
    },
    {
      "x": -15,
      "y": 22,
      "z": -5,
      "name": "Rock_Ice"
    },
    {
      "x": -15,
      "y": 23,
      "z": -5,
      "name": "Rock_Ice"
    },
    {
      "x": -15,
      "y": 24,
      "z": -5,
      "name": "Rock_Ice_Permafrost"
    },
    {
      "x": -15,
      "y": 25,
      "z": -5,
      "name": "Rock_Ice_Permafrost"
    },
    {
      "x": -15,
      "y": 26,
      "z": -5,
      "name": "Rock_Crystal_Cyan_Block_WhiteLight"
    },
    {
      "x": -15,
      "y": 27,
      "z": -5,
      "name": "Rock_Ice_Permafrost"
    },
    {
      "x": -15,
      "y": 28,
      "z": -5,
      "name": "Rock_Ice_Permafrost"
    },
    {
      "x": -15,
      "y": 29,
      "z": -5,
      "name": "Rock_Ice_Permafrost"
    },
    {
      "x": -15,
      "y": 30,
      "z": -5,
      "name": "Rock_Ice_Permafrost"
    },
    {
      "x": -15,
      "y": 31,
      "z": -5,
      "name": "Rock_Ice"
    },
    {
      "x": -15,
      "y": 17,
      "z": -4,
      "name": "Rock_Ice"
    },
    {
      "x": -15,
      "y": 18,
      "z": -4,
      "name": "Rock_Ice"
    },
    {
      "x": -15,
      "y": 19,
      "z": -4,
      "name": "Rock_Ice"
    },
    {
      "x": -15,
      "y": 20,
      "z": -4,
      "name": "Rock_Ice"
    },
    {
      "x": -15,
      "y": 21,
      "z": -4,
      "name": "Rock_Ice"
    },
    {
      "x": -15,
      "y": 22,
      "z": -4,
      "name": "Rock_Ice"
    },
    {
      "x": -15,
      "y": 23,
      "z": -4,
      "name": "Rock_Ice"
    },
    {
      "x": -15,
      "y": 24,
      "z": -4,
      "name": "Rock_Ice"
    },
    {
      "x": -15,
      "y": 25,
      "z": -4,
      "name": "Rock_Ice_Permafrost"
    },
    {
      "x": -15,
      "y": 26,
      "z": -4,
      "name": "Rock_Ice_Permafrost"
    },
    {
      "x": -15,
      "y": 27,
      "z": -4,
      "name": "Rock_Ice_Permafrost"
    },
    {
      "x": -15,
      "y": 28,
      "z": -4,
      "name": "Rock_Ice"
    },
    {
      "x": -15,
      "y": 29,
      "z": -4,
      "name": "Soil_Snow"
    },
    {
      "x": -15,
      "y": 16,
      "z": -3,
      "name": "Rock_Ice"
    },
    {
      "x": -15,
      "y": 17,
      "z": -3,
      "name": "Rock_Ice"
    },
    {
      "x": -15,
      "y": 18,
      "z": -3,
      "name": "Rock_Ice"
    },
    {
      "x": -15,
      "y": 19,
      "z": -3,
      "name": "Rock_Ice"
    },
    {
      "x": -15,
      "y": 20,
      "z": -3,
      "name": "Rock_Ice"
    },
    {
      "x": -15,
      "y": 21,
      "z": -3,
      "name": "Rock_Ice"
    },
    {
      "x": -15,
      "y": 22,
      "z": -3,
      "name": "Rock_Ice"
    },
    {
      "x": -15,
      "y": 23,
      "z": -3,
      "name": "Rock_Ice"
    },
    {
      "x": -15,
      "y": 24,
      "z": -3,
      "name": "Rock_Ice"
    },
    {
      "x": -15,
      "y": 25,
      "z": -3,
      "name": "Rock_Ice_Permafrost"
    },
    {
      "x": -15,
      "y": 26,
      "z": -3,
      "name": "Rock_Ice_Permafrost"
    },
    {
      "x": -15,
      "y": 27,
      "z": -3,
      "name": "Rock_Ice_Permafrost"
    },
    {
      "x": -15,
      "y": 28,
      "z": -3,
      "name": "Rock_Ice_Permafrost"
    },
    {
      "x": -15,
      "y": 39,
      "z": -3,
      "name": "Rock_Ice"
    },
    {
      "x": -15,
      "y": 40,
      "z": -3,
      "name": "Rock_Ice"
    },
    {
      "x": -15,
      "y": 41,
      "z": -3,
      "name": "Rock_Ice"
    },
    {
      "x": -15,
      "y": 42,
      "z": -3,
      "name": "Rock_Ice"
    },
    {
      "x": -15,
      "y": 43,
      "z": -3,
      "name": "Rock_Ice"
    },
    {
      "x": -15,
      "y": 44,
      "z": -3,
      "name": "Soil_Snow"
    },
    {
      "x": -15,
      "y": 126,
      "z": -3,
      "name": "Rock_Ice_Permafrost"
    },
    {
      "x": -15,
      "y": 16,
      "z": -2,
      "name": "Rock_Ice"
    },
    {
      "x": -15,
      "y": 17,
      "z": -2,
      "name": "Rock_Ice"
    },
    {
      "x": -15,
      "y": 18,
      "z": -2,
      "name": "Rock_Ice"
    },
    {
      "x": -15,
      "y": 19,
      "z": -2,
      "name": "Rock_Ice"
    },
    {
      "x": -15,
      "y": 20,
      "z": -2,
      "name": "Rock_Ice"
    },
    {
      "x": -15,
      "y": 21,
      "z": -2,
      "name": "Rock_Ice"
    },
    {
      "x": -15,
      "y": 22,
      "z": -2,
      "name": "Rock_Ice"
    },
    {
      "x": -15,
      "y": 23,
      "z": -2,
      "name": "Rock_Ice"
    },
    {
      "x": -15,
      "y": 24,
      "z": -2,
      "name": "Rock_Ice_Permafrost"
    },
    {
      "x": -15,
      "y": 25,
      "z": -2,
      "name": "Rock_Crystal_Cyan_Block_WhiteLight"
    },
    {
      "x": -15,
      "y": 26,
      "z": -2,
      "name": "Rock_Crystal_Cyan_Block_WhiteLight"
    },
    {
      "x": -15,
      "y": 27,
      "z": -2,
      "name": "Rock_Ice_Permafrost"
    },
    {
      "x": -15,
      "y": 28,
      "z": -2,
      "name": "Rock_Ice"
    },
    {
      "x": -15,
      "y": 34,
      "z": -2,
      "name": "Rock_Ice"
    },
    {
      "x": -15,
      "y": 35,
      "z": -2,
      "name": "Rock_Ice"
    },
    {
      "x": -15,
      "y": 36,
      "z": -2,
      "name": "Rock_Ice"
    },
    {
      "x": -15,
      "y": 37,
      "z": -2,
      "name": "Rock_Ice"
    },
    {
      "x": -15,
      "y": 38,
      "z": -2,
      "name": "Rock_Ice"
    },
    {
      "x": -15,
      "y": 39,
      "z": -2,
      "name": "Rock_Ice"
    },
    {
      "x": -15,
      "y": 40,
      "z": -2,
      "name": "Rock_Ice"
    },
    {
      "x": -15,
      "y": 41,
      "z": -2,
      "name": "Rock_Ice"
    },
    {
      "x": -15,
      "y": 42,
      "z": -2,
      "name": "Rock_Ice_Permafrost"
    },
    {
      "x": -15,
      "y": 43,
      "z": -2,
      "name": "Rock_Ice_Permafrost"
    },
    {
      "x": -15,
      "y": 44,
      "z": -2,
      "name": "Rock_Ice_Permafrost"
    },
    {
      "x": -15,
      "y": 45,
      "z": -2,
      "name": "Rock_Ice_Permafrost"
    },
    {
      "x": -15,
      "y": 47,
      "z": -2,
      "name": "Rock_Ice_Permafrost"
    },
    {
      "x": -15,
      "y": 48,
      "z": -2,
      "name": "Rock_Ice_Permafrost"
    },
    {
      "x": -15,
      "y": 49,
      "z": -2,
      "name": "Rock_Ice"
    },
    {
      "x": -15,
      "y": 50,
      "z": -2,
      "name": "Rock_Ice"
    },
    {
      "x": -15,
      "y": 51,
      "z": -2,
      "name": "Soil_Snow"
    },
    {
      "x": -15,
      "y": 126,
      "z": -2,
