{
  "version": 8,
  "blockIdVersion": 11,
  "anchorX": 0,
  "anchorY": 0,
  "anchorZ": 0,
  "blocks": [
    {
      "x": -11,
      "y": 37,
      "z": -3,
      "name": "Rock_Chalk"
    },
    {
      "x": -11,
      "y": 38,
      "z": -3,
      "name": "Rock_Chalk"
    },
    {
      "x": -11,
      "y": 39,
      "z": -3,
      "name": "Rock_Chalk"
    },
    {
      "x": -11,
      "y": 40,
      "z": -3,
      "name": "Rock_Chalk"
    },
    {
      "x": -11,
      "y": 41,
      "z": -3,
      "name": "Rock_Chalk"
    },
    {
      "x": -11,
      "y": 42,
      "z": -3,
      "name": "Soil_Clay_White"
    },
    {
      "x": -11,
      "y": 36,
      "z": -2,
      "name": "Soil_Clay_White"
    },
    {
      "x": -11,
      "y": 37,
      "z": -2,
      "name": "Rock_Chalk"
    },
    {
      "x": -11,
      "y": 38,
      "z": -2,
      "name": "Rock_Chalk"
    },
    {
      "x": -11,
      "y": 39,
      "z": -2,
      "name": "Rock_Chalk"
    },
    {
      "x": -11,
      "y": 40,
      "z": -2,
      "name": "Rock_Chalk"
    },
    {
      "x": -11,
      "y": 41,
      "z": -2,
      "name": "Rock_Chalk"
    },
    {
      "x": -11,
      "y": 42,
      "z": -2,
      "name": "Soil_Clay_White"
    },
    {
      "x": -11,
      "y": 43,
      "z": -2,
      "name": "Soil_Clay_White"
    },
    {
      "x": -11,
      "y": 44,
      "z": -2,
      "name": "Rock_Marble"
    },
    {
      "x": -11,
      "y": 45,
      "z": -2,
      "name": "Rock_Marble"
    },
    {
      "x": -11,
      "y": 35,
      "z": -1,
      "name": "Rock_Marble"
    },
    {
      "x": -11,
      "y": 36,
      "z": -1,
      "name": "Soil_Clay_White"
    },
    {
      "x": -11,
      "y": 37,
      "z": -1,
      "name": "Rock_Chalk"
    },
    {
      "x": -11,
      "y": 38,
      "z": -1,
      "name": "Rock_Chalk"
    },
    {
      "x": -11,
      "y": 39,
      "z": -1,
      "name": "Rock_Chalk"
    },
    {
      "x": -11,
      "y": 40,
      "z": -1,
      "name": "Rock_Chalk"
    },
    {
      "x": -11,
      "y": 41,
      "z": -1,
      "name": "Rock_Chalk"
    },
    {
      "x": -11,
      "y": 42,
      "z": -1,
      "name": "Soil_Clay_White"
    },
    {
      "x": -11,
      "y": 43,
      "z": -1,
      "name": "Soil_Clay_White"
    },
    {
      "x": -11,
      "y": 44,
      "z": -1,
      "name": "Rock_Marble"
    },
    {
      "x": -11,
      "y": 45,
      "z": -1,
      "name": "Rock_Marble"
    },
    {
      "x": -11,
      "y": 46,
      "z": -1,
      "name": "Soil_Clay_White"
    },
    {
      "x": -11,
      "y": 47,
      "z": -1,
      "name": "Soil_Clay_White"
    },
    {
      "x": -11,
      "y": 34,
      "z": 0,
      "name": "Rock_Marble"
    },
    {
      "x": -11,
      "y": 35,
      "z": 0,
      "name": "Rock_Marble"
    },
    {
      "x": -11,
      "y": 36,
      "z": 0,
      "name": "Soil_Clay_White"
    },
    {
      "x": -11,
      "y": 37,
      "z": 0,
      "name": "Rock_Chalk"
    },
    {
      "x": -11,
      "y": 38,
      "z": 0,
      "name": "Rock_Chalk"
    },
    {
      "x": -11,
      "y": 39,
      "z": 0,
      "name": "Rock_Chalk"
    },
    {
      "x": -11,
      "y": 40,
      "z": 0,
      "name": "Rock_Chalk"
    },
    {
      "x": -11,
      "y": 41,
      "z": 0,
      "name": "Rock_Chalk"
    },
    {
      "x": -11,
      "y": 42,
      "z": 0,
      "name": "Soil_Clay_White"
    },
    {
      "x": -11,
      "y": 43,
      "z": 0,
      "name": "Soil_Clay_White"
    },
    {
      "x": -11,
      "y": 44,
      "z": 0,
      "name": "Rock_Marble"
    },
    {
      "x": -11,
      "y": 45,
      "z": 0,
      "name": "Rock_Marble"
    },
    {
      "x": -11,
      "y": 46,
      "z": 0,
      "name": "Soil_Clay_White"
    },
    {
      "x": -11,
      "y": 47,
      "z": 0,
      "name": "Soil_Clay_White"
    },
    {
      "x": -11,
      "y": 34,
      "z": 1,
      "name": "Rock_Marble"
    },
    {
      "x": -11,
      "y": 35,
      "z": 1,
      "name": "Rock_Marble"
    },
    {
      "x": -11,
      "y": 36,
      "z": 1,
      "name": "Soil_Clay_White"
    },
    {
      "x": -11,
      "y": 37,
      "z": 1,
      "name": "Rock_Chalk"
    },
    {
      "x": -11,
      "y": 38,
      "z": 1,
      "name": "Rock_Chalk"
    },
    {
      "x": -11,
      "y": 39,
      "z": 1,
      "name": "Rock_Chalk"
    },
    {
      "x": -11,
      "y": 40,
      "z": 1,
      "name": "Rock_Chalk"
    },
    {
      "x": -11,
      "y": 41,
      "z": 1,
      "name": "Rock_Chalk"
    },
    {
      "x": -11,
      "y": 42,
      "z": 1,
      "name": "Soil_Clay_White"
    },
    {
      "x": -11,
      "y": 43,
      "z": 1,
      "name": "Soil_Clay_White"
    },
    {
      "x": -11,
      "y": 44,
      "z": 1,
      "name": "Rock_Marble"
    },
    {
      "x": -11,
      "y": 45,
      "z": 1,
      "name": "Rock_Marble"
    },
    {
      "x": -11,
      "y": 46,
      "z": 1,
      "name": "Soil_Clay_White"
    },
    {
      "x": -11,
      "y": 34,
      "z": 2,
      "name": "Rock_Marble"
    },
    {
      "x": -11,
      "y": 35,
      "z": 2,
      "name": "Rock_Marble"
    },
    {
      "x": -11,
      "y": 36,
      "z": 2,
      "name": "Soil_Clay_White"
    },
    {
      "x": -11,
      "y": 37,
      "z": 2,
      "name": "Rock_Chalk"
    },
    {
      "x": -11,
      "y": 38,
      "z": 2,
      "name": "Rock_Chalk"
    },
    {
      "x": -11,
      "y": 39,
      "z": 2,
      "name": "Rock_Chalk"
    },
    {
      "x": -11,
      "y": 40,
      "z": 2,
      "name": "Rock_Chalk"
    },
    {
      "x": -11,
      "y": 41,
      "z": 2,
      "name": "Rock_Chalk"
    },
    {
      "x": -11,
      "y": 42,
      "z": 2,
      "name": "Soil_Clay_White"
    },
    {
      "x": -11,
      "y": 43,
      "z": 2,
      "name": "Soil_Clay_White"
    },
    {
      "x": -11,
      "y": 44,
      "z": 2,
      "name": "Rock_Marble"
    },
    {
      "x": -11,
      "y": 45,
      "z": 2,
      "name": "Rock_Marble"
    },
    {
      "x": -11,
      "y": 46,
      "z": 2,
      "name": "Soil_Clay_White"
    },
    {
      "x": -11,
      "y": 36,
      "z": 3,
      "name": "Soil_Clay_White"
    },
    {
      "x": -11,
      "y": 37,
      "z": 3,
      "name": "Rock_Chalk"
    },
    {
      "x": -11,
      "y": 38,
      "z": 3,
      "name": "Rock_Chalk"
    },
    {
      "x": -11,
      "y": 39,
      "z": 3,
      "name": "Rock_Chalk"
    },
    {
      "x": -11,
      "y": 40,
      "z": 3,
      "name": "Rock_Chalk"
    },
    {
      "x": -11,
      "y": 41,
      "z": 3,
      "name": "Rock_Chalk"
    },
    {
      "x": -11,
      "y": 42,
      "z": 3,
      "name": "Rock_Chalk"
    },
    {
      "x": -11,
      "y": 43,
      "z": 3,
      "name": "Soil_Clay_White"
    },
    {
      "x": -11,
      "y": 44,
      "z": 3,
      "name": "Rock_Marble"
    },
    {
      "x": -11,
      "y": 45,
      "z": 3,
      "name": "Rock_Marble"
    },
    {
      "x": -11,
      "y": 38,
      "z": 4,
      "name": "Rock_Chalk"
    },
    {
      "x": -11,
      "y": 39,
      "z": 4,
      "name": "Rock_Chalk"
    },
    {
      "x": -11,
      "y": 40,
      "z": 4,
      "name": "Rock_Chalk"
    },
    {
      "x": -11,
      "y": 41,
      "z": 4,
      "name": "Rock_Chalk"
    },
    {
      "x": -11,
      "y": 42,
      "z": 4,
      "name": "Rock_Chalk"
    },
    {
      "x": -11,
      "y": 43,
      "z": 4,
      "name": "Soil_Clay_White"
    },
    {
      "x": -10,
      "y": 38,
      "z": -6,
      "name": "Rock_Chalk"
    },
    {
      "x": -10,
      "y": 39,
      "z": -6,
      "name": "Rock_Chalk"
    },
    {
      "x": -10,
      "y": 40,
      "z": -6,
      "name": "Rock_Chalk"
    },
    {
      "x": -10,
      "y": 41,
      "z": -6,
      "name": "Rock_Chalk"
    },
    {
      "x": -10,
      "y": 42,
      "z": -6,
      "name": "Soil_Clay_White"
    },
    {
      "x": -10,
      "y": 36,
      "z": -5,
      "name": "Soil_Clay_White"
    },
    {
      "x": -10,
      "y": 37,
      "z": -5,
      "name": "Rock_Chalk"
    },
    {
      "x": -10,
      "y": 38,
      "z": -5,
      "name": "Rock_Chalk"
    },
    {
      "x": -10,
      "y": 39,
      "z": -5,
      "name": "Rock_Chalk"
    },
    {
      "x": -10,
      "y": 40,
      "z": -5,
      "name": "Rock_Chalk"
    },
    {
      "x": -10,
      "y": 41,
      "z": -5,
      "name": "Rock_Chalk"
    },
    {
      "x": -10,
      "y": 42,
      "z": -5,
      "name": "Soil_Clay_White"
    },
    {
      "x": -10,
      "y": 43,
      "z": -5,
      "name": "Rock_Marble"
    },
    {
      "x": -10,
      "y": 44,
      "z": -5,
      "name": "Rock_Marble"
    },
    {
      "x": -10,
      "y": 34,
      "z": -4,
      "name": "Rock_Marble"
    },
    {
      "x": -10,
      "y": 35,
      "z": -4,
      "name": "Rock_Marble"
    },
    {
      "x": -10,
      "y": 36,
      "z": -4,
      "name": "Soil_Clay_White"
    },
    {
      "x": -10,
      "y": 37,
      "z": -4,
      "name": "Rock_Chalk"
    },
    {
      "x": -10,
      "y": 38,
      "z": -4,
      "name": "Rock_Chalk"
    },
    {
      "x": -10,
      "y": 39,
      "z": -4,
      "name": "Rock_Chalk"
    },
    {
      "x": -10,
      "y": 40,
      "z": -4,
      "name": "Rock_Chalk"
    },
    {
      "x": -10,
      "y": 41,
      "z": -4,
      "name": "Rock_Chalk"
    },
    {
      "x": -10,
      "y": 42,
      "z": -4,
      "name": "Soil_Clay_White"
    },
    {
      "x": -10,
      "y": 43,
      "z": -4,
      "name": "Rock_Marble"
    },
    {
      "x": -10,
      "y": 44,
      "z": -4,
      "name": "Rock_Marble"
    },
    {
      "x": -10,
      "y": 45,
      "z": -4,
      "name": "Rock_Marble"
    },
    {
      "x": -10,
      "y": 46,
      "z": -4,
      "name": "Soil_Clay_White"
    },
    {
      "x": -10,
      "y": 47,
      "z": -4,
      "name": "Soil_Clay_White"
    },
    {
      "x": -10,
      "y": 33,
      "z": -3,
      "name": "Rock_Marble"
    },
    {
      "x": -10,
      "y": 34,
      "z": -3,
      "name": "Rock_Marble"
    },
    {
      "x": -10,
      "y": 35,
      "z": -3,
      "name": "Rock_Marble"
    },
    {
      "x": -10,
      "y": 36,
      "z": -3,
      "name": "Soil_Clay_White"
    },
    {
      "x": -10,
      "y": 37,
      "z": -3,
      "name": "Rock_Chalk"
    },
    {
      "x": -10,
      "y": 38,
      "z": -3,
      "name": "Rock_Chalk"
    },
    {
      "x": -10,
      "y": 39,
      "z": -3,
      "name": "Rock_Chalk"
    },
    {
      "x": -10,
      "y": 40,
      "z": -3,
      "name": "Rock_Chalk"
    },
    {
      "x": -10,
      "y": 41,
      "z": -3,
      "name": "Rock_Chalk"
    },
    {
      "x": -10,
      "y": 42,
      "z": -3,
      "name": "Soil_Clay_White"
    },
    {
      "x": -10,
      "y": 43,
      "z": -3,
      "name": "Rock_Marble"
    },
    {
      "x": -10,
      "y": 44,
      "z": -3,
      "name": "Rock_Marble"
    },
    {
      "x": -10,
      "y": 45,
      "z": -3,
      "name": "Rock_Marble"
    },
    {
      "x": -10,
      "y": 46,
      "z": -3,
      "name": "Soil_Clay_White"
    },
    {
      "x": -10,
      "y": 47,
      "z": -3,
      "name": "Soil_Clay_White"
    },
    {
      "x": -10,
      "y": 48,
      "z": -3,
      "name": "Soil_Clay_White"
    },
    {
      "x": -10,
      "y": 49,
      "z": -3,
      "name": "Soil_Clay_White"
    },
    {
      "x": -10,
      "y": 50,
      "z": -3,
      "name": "Soil_Clay_White"
    },
    {
      "x": -10,
      "y": 51,
      "z": -3,
      "name": "Rock_Marble"
    },
    {
      "x": -10,
      "y": 31,
      "z": -2,
      "name": "Rock_Marble"
    },
    {
      "x": -10,
      "y": 32,
      "z": -2,
      "name": "Rock_Marble"
    },
    {
      "x": -10,
      "y": 33,
      "z": -2,
      "name": "Rock_Marble"
    },
    {
      "x": -10,
      "y": 34,
      "z": -2,
      "name": "Rock_Marble"
    },
    {
      "x": -10,
      "y": 35,
      "z": -2,
      "name": "Rock_Marble"
    },
    {
      "x": -10,
      "y": 36,
      "z": -2,
      "name": "Soil_Clay_White"
    },
    {
      "x": -10,
      "y": 37,
      "z": -2,
      "name": "Rock_Chalk"
    },
    {
      "x": -10,
      "y": 38,
      "z": -2,
      "name": "Rock_Chalk"
    },
    {
      "x": -10,
      "y": 39,
      "z": -2,
      "name": "Rock_Chalk"
    },
    {
      "x": -10,
      "y": 40,
      "z": -2,
      "name": "Rock_Chalk"
    },
    {
      "x": -10,
      "y": 41,
      "z": -2,
      "name": "Rock_Chalk"
    },
    {
      "x": -10,
      "y": 42,
      "z": -2,
      "name": "Soil_Clay_White"
    },
    {
      "x": -10,
      "y": 43,
      "z": -2,
      "name": "Soil_Clay_White"
    },
    {
      "x": -10,
      "y": 44,
      "z": -2,
      "name": "Rock_Marble"
    },
    {
      "x": -10,
      "y": 45,
      "z": -2,
      "name": "Rock_Marble"
    },
    {
      "x": -10,
      "y": 46,
      "z": -2,
      "name": "Soil_Clay_White"
    },
    {
      "x": -10,
      "y": 47,
      "z": -2,
      "name": "Soil_Clay_White"
    },
    {
      "x": -10,
      "y": 48,
      "z": -2,
      "name": "Soil_Clay_White"
    },
    {
      "x": -10,
      "y": 49,
      "z": -2,
      "name": "Soil_Clay_White"
    },
    {
      "x": -10,
      "y": 50,
      "z": -2,
      "name": "Soil_Clay_White"
    },
    {
      "x": -10,
      "y": 51,
      "z": -2,
      "name": "Rock_Marble"
    },
    {
      "x": -10,
      "y": 52,
      "z": -2,
      "name": "Rock_Marble"
    },
    {
      "x": -10,
      "y": 53,
      "z": -2,
      "name": "Soil_Clay_White"
    },
    {
      "x": -10,
      "y": 54,
      "z": -2,
      "name": "Soil_Clay_White"
    },
    {
      "x": -10,
      "y": 30,
      "z": -1,
      "name": "Soil_Pebbles"
    },
    {
      "x": -10,
      "y": 31,
      "z": -1,
      "name": "Rock_Marble"
    },
    {
      "x": -10,
      "y": 32,
      "z": -1,
      "name": "Rock_Marble"
    },
    {
      "x": -10,
      "y": 33,
      "z": -1,
      "name": "Rock_Marble"
    },
    {
      "x": -10,
      "y": 34,
      "z": -1,
      "name": "Rock_Marble"
    },
    {
      "x": -10,
      "y": 35,
      "z": -1,
      "name": "Rock_Marble"
    },
    {
      "x": -10,
      "y": 36,
      "z": -1,
      "name": "Soil_Clay_White"
    },
    {
      "x": -10,
      "y": 37,
      "z": -1,
      "name": "Rock_Chalk"
    },
    {
      "x": -10,
      "y": 38,
      "z": -1,
      "name": "Rock_Chalk"
    },
    {
      "x": -10,
      "y": 39,
      "z": -1,
      "name": "Rock_Chalk"
    },
    {
      "x": -10,
      "y": 40,
      "z": -1,
      "name": "Rock_Chalk"
    },
    {
      "x": -10,
      "y": 41,
      "z": -1,
      "name": "Rock_Chalk"
    },
    {
      "x": -10,
      "y": 42,
      "z": -1,
      "name": "Soil_Clay_White"
    },
    {
      "x": -10,
      "y": 43,
      "z": -1,
      "name": "Soil_Clay_White"
    },
    {
      "x": -10,
      "y": 44,
      "z": -1,
      "name": "Rock_Marble"
    },
    {
      "x": -10,
      "y": 45,
      "z": -1,
      "name": "Rock_Marble"
    },
    {
      "x": -10,
      "y": 46,
      "z": -1,
      "name": "Soil_Clay_White"
    },
    {
      "x": -10,
      "y": 47,
      "z": -1,
      "name": "Soil_Clay_White"
    },
    {
      "x": -10,
      "y": 48,
      "z": -1,
      "name": "Soil_Clay_White"
    },
    {
      "x": -10,
      "y": 49,
      "z": -1,
      "name": "Soil_Clay_White"
    },
    {
      "x": -10,
      "y": 50,
      "z": -1,
      "name": "Soil_Clay_White"
    },
    {
      "x": -10,
      "y": 51,
      "z": -1,
      "name": "Rock_Marble"
    },
    {
      "x": -10,
      "y": 52,
      "z": -1,
      "name": "Rock_Marble"
    },
    {
      "x": -10,
      "y": 53,
      "z": -1,
      "name": "Soil_Clay_White"
    },
    {
      "x": -10,
      "y": 54,
      "z": -1,
      "name": "Soil_Clay_White"
    },
    {
      "x": -10,
      "y": 55,
      "z": -1,
      "name": "Soil_Clay_White"
    },
    {
      "x": -10,
      "y": 56,
      "z": -1,
      "name": "Soil_Clay_White"
    },
    {
      "x": -10,
      "y": 57,
      "z": -1,
      "name": "Soil_Clay_White"
    },
    {
      "x": -10,
      "y": 29,
      "z": 0,
      "name": "Rock_Marble"
    },
    {
      "x": -10,
      "y": 30,
      "z": 0,
      "name": "Soil_Pebbles"
    },
    {
      "x": -10,
      "y": 31,
      "z": 0,
      "name": "Rock_Marble"
    },
    {
      "x": -10,
      "y": 32,
      "z": 0,
      "name": "Rock_Marble"
    },
    {
      "x": -10,
      "y": 33,
      "z": 0,
      "name": "Rock_Marble"
    },
    {
      "x": -10,
      "y": 34,
      "z": 0,
      "name": "Rock_Marble"
    },
    {
      "x": -10,
      "y": 35,
      "z": 0,
      "name": "Rock_Marble"
    },
    {
      "x": -10,
      "y": 36,
      "z": 0,
      "name": "Soil_Clay_White"
    },
    {
      "x": -10,
      "y": 37,
      "z": 0,
      "name": "Rock_Chalk"
    },
    {
      "x": -10,
      "y": 38,
      "z": 0,
      "name": "Rock_Chalk"
    },
    {
      "x": -10,
      "y": 39,
      "z": 0,
      "name": "Rock_Chalk"
    },
    {
      "x": -10,
      "y": 40,
      "z": 0,
      "name": "Rock_Chalk"
    },
    {
      "x": -10,
      "y": 41,
      "z": 0,
      "name": "Rock_Chalk"
    },
    {
      "x": -10,
      "y": 42,
      "z": 0,
      "name": "Soil_Clay_White"
    },
    {
      "x": -10,
      "y": 43,
      "z": 0,
      "name": "Soil_Clay_White"
    },
    {
      "x": -10,
      "y": 44,
      "z": 0,
      "name": "Rock_Marble"
    },
    {
      "x": -10,
      "y": 45,
      "z": 0,
      "name": "Rock_Marble"
    },
    {
      "x": -10,
      "y": 46,
      "z": 0,
      "name": "Soil_Clay_White"
    },
    {
      "x": -10,
      "y": 47,
      "z": 0,
      "name": "Soil_Clay_White"
    },
    {
      "x": -10,
      "y": 48,
      "z": 0,
      "name": "Soil_Clay_White"
    },
    {
      "x": -10,
      "y": 49,
      "z": 0,
      "name": "Soil_Clay_White"
    },
    {
      "x": -10,
      "y": 50,
      "z": 0,
      "name": "Soil_Clay_White"
    },
    {
      "x": -10,
      "y": 51,
      "z": 0,
      "name": "Rock_Marble"
    },
    {
      "x": -10,
      "y": 52,
      "z": 0,
      "name": "Rock_Marble"
    },
    {
      "x": -10,
      "y": 53,
      "z": 0,
      "name": "Soil_Clay_White"
    },
    {
      "x": -10,
      "y": 54,
      "z": 0,
      "name": "Soil_Clay_White"
    },
    {
      "x": -10,
      "y": 55,
      "z": 0,
      "name": "Soil_Clay_White"
    },
    {
      "x": -10,
      "y": 56,
      "z": 0,
      "name": "Soil_Clay_White"
    },
    {
      "x": -10,
      "y": 57,
      "z": 0,
      "name": "Soil_Clay_White"
    },
    {
      "x": -10,
      "y": 58,
      "z": 0,
      "name": "Soil_Clay_White"
    },
    {
      "x": -10,
      "y": 28,
      "z": 1,
      "name": "Rock_Marble"
    },
    {
      "x": -10,
      "y": 29,
      "z": 1,
      "name": "Rock_Marble"
    },
    {
      "x": -10,
      "y": 30,
      "z": 1,
      "name": "Soil_Pebbles"
    },
    {
      "x": -10,
      "y": 31,
      "z": 1,
      "name": "Rock_Marble"
    },
    {
      "x": -10,
      "y": 32,
      "z": 1,
      "name": "Rock_Marble"
    },
    {
      "x": -10,
      "y": 33,
      "z": 1,
      "name": "Rock_Marble"
    },
    {
      "x": -10,
      "y": 34,
      "z": 1,
      "name": "Rock_Marble"
    },
    {
      "x": -10,
      "y": 35,
      "z": 1,
      "name": "Rock_Marble"
    },
    {
      "x": -10,
      "y": 36,
      "z": 1,
      "name": "Soil_Clay_White"
    },
    {
      "x": -10,
      "y": 37,
      "z": 1,
      "name": "Rock_Chalk"
    },
    {
      "x": -10,
      "y": 38,
      "z": 1,
      "name": "Rock_Chalk"
    },
    {
      "x": -10,
      "y": 39,
      "z": 1,
      "name": "Rock_Chalk"
    },
    {
      "x": -10,
      "y": 40,
      "z": 1,
      "name": "Rock_Chalk"
    },
    {
      "x": -10,
      "y": 41,
      "z": 1,
      "name": "Rock_Chalk"
    },
    {
      "x": -10,
      "y": 42,
      "z": 1,
      "name": "Soil_Clay_White"
    },
    {
      "x": -10,
      "y": 43,
      "z": 1,
      "name": "Soil_Clay_White"
    },
    {
      "x": -10,
      "y": 44,
      "z": 1,
      "name": "Rock_Marble"
    },
    {
      "x": -10,
      "y": 45,
      "z": 1,
      "name": "Rock_Marble"
    },
    {
      "x": -10,
      "y": 46,
      "z": 1,
      "name": "Soil_Clay_White"
    },
    {
      "x": -10,
      "y": 47,
      "z": 1,
      "name": "Soil_Clay_White"
    },
    {
      "x": -10,
      "y": 48,
      "z": 1,
      "name": "Soil_Clay_White"
    },
    {
      "x": -10,
      "y": 49,
      "z": 1,
      "name": "Soil_Clay_White"
    },
    {
      "x": -10,
      "y": 50,
      "z": 1,
      "name": "Soil_Clay_White"
    },
    {
      "x": -10,
      "y": 51,
      "z": 1,
      "name": "Rock_Marble"
    },
    {
      "x": -10,
      "y": 52,
      "z": 1,
      "name": "Rock_Marble"
    },
    {
      "x": -10,
      "y": 53,
      "z": 1,
      "name": "Soil_Clay_White"
    },
    {
      "x": -10,
      "y": 54,
      "z": 1,
      "name": "Soil_Clay_White"
    },
    {
      "x": -10,
      "y": 55,
      "z": 1,
      "name": "Soil_Clay_White"
    },
    {
      "x": -10,
      "y": 56,
      "z": 1,
      "name": "Soil_Clay_White"
    },
    {
      "x": -10,
      "y": 57,
      "z": 1,
      "name": "Soil_Clay_White"
    },
    {
      "x": -10,
      "y": 58,
      "z": 1,
      "name": "Soil_Clay_White"
    },
    {
      "x": -10,
      "y": 59,
      "z": 1,
      "name": "Soil_Clay_White"
    },
    {
      "x": -10,
      "y": 28,
      "z": 2,
      "name": "Rock_Marble"
    },
    {
      "x": -10,
      "y": 29,
      "z": 2,
      "name": "Rock_Marble"
    },
    {
      "x": -10,
      "y": 30,
      "z": 2,
      "name": "Soil_Pebbles"
    },
    {
      "x": -10,
      "y": 31,
      "z": 2,
      "name": "Rock_Marble"
    },
    {
      "x": -10,
      "y": 32,
      "z": 2,
      "name": "Rock_Marble"
    },
    {
      "x": -10,
      "y": 33,
      "z": 2,
      "name": "Rock_Marble"
    },
    {
      "x": -10,
      "y": 34,
      "z": 2,
      "name": "Rock_Marble"
    },
    {
      "x": -10,
      "y": 35,
      "z": 2,
      "name": "Rock_Marble"
    },
    {
      "x": -10,
      "y": 36,
      "z": 2,
      "name": "Soil_Clay_White"
    },
    {
      "x": -10,
      "y": 37,
      "z": 2,
      "name": "Rock_Chalk"
    },
    {
      "x": -10,
      "y": 38,
      "z": 2,
      "name": "Rock_Chalk"
    },
    {
      "x": -10,
      "y": 39,
      "z": 2,
      "name": "Rock_Chalk"
    },
    {
      "x": -10,
      "y": 40,
      "z": 2,
      "name": "Rock_Chalk"
    },
    {
      "x": -10,
      "y": 41,
      "z": 2,
      "name": "Rock_Chalk"
    },
    {
      "x": -10,
      "y": 42,
      "z": 2,
      "name": "Soil_Clay_White"
    },
    {
      "x": -10,
      "y": 43,
      "z": 2,
      "name": "Soil_Clay_White"
    },
    {
      "x": -10,
      "y": 44,
      "z": 2,
      "name": "Rock_Marble"
    },
    {
      "x": -10,
      "y": 45,
      "z": 2,
      "name": "Rock_Marble"
    },
    {
      "x": -10,
      "y": 46,
      "z": 2,
      "name": "Soil_Clay_White"
    },
    {
      "x": -10,
      "y": 47,
      "z": 2,
      "name": "Soil_Clay_White"
    },
    {
      "x": -10,
      "y": 48,
      "z": 2,
      "name": "Soil_Clay_White"
    },
    {
      "x": -10,
      "y": 49,
      "z": 2,
      "name": "Soil_Clay_White"
    },
    {
      "x": -10,
      "y": 50,
      "z": 2,
      "name": "Soil_Clay_White"
    },
    {
      "x": -10,
      "y": 51,
      "z": 2,
      "name": "Rock_Marble"
    },
    {
      "x": -10,
      "y": 52,
      "z": 2,
      "name": "Rock_Marble"
    },
    {
      "x": -10,
      "y": 53,
      "z": 2,
      "name": "Soil_Clay_White"
    },
    {
      "x": -10,
      "y": 54,
      "z": 2,
      "name": "Soil_Clay_White"
    },
    {
      "x": -10,
      "y": 55,
      "z": 2,
      "name": "Soil_Clay_White"
    },
    {
      "x": -10,
      "y": 56,
      "z": 2,
      "name": "Soil_Clay_White"
    },
    {
      "x": -10,
      "y": 57,
      "z": 2,
      "name": "Soil_Clay_White"
    },
    {
      "x": -10,
      "y": 58,
      "z": 2,
      "name": "Soil_Clay_White"
    },
    {
      "x": -10,
      "y": 31,
      "z": 3,
      "name": "Rock_Marble"
    },
    {
      "x": -10,
      "y": 32,
      "z": 3,
      "name": "Rock_Marble"
    },
    {
      "x": -10,
      "y": 33,
      "z": 3,
      "name": "Rock_Marble"
    },
    {
      "x": -10,
      "y": 34,
      "z": 3,
      "name": "Rock_Marble"
    },
    {
      "x": -10,
      "y": 35,
      "z": 3,
      "name": "Rock_Marble"
    },
    {
      "x": -10,
      "y": 36,
      "z": 3,
      "name": "Soil_Clay_White"
    },
    {
      "x": -10,
      "y": 37,
      "z": 3,
      "name": "Rock_Chalk"
    },
    {
      "x": -10,
      "y": 38,
      "z": 3,
      "name": "Rock_Chalk"
    },
    {
      "x": -10,
      "y": 39,
      "z": 3,
      "name": "Rock_Chalk"
    },
    {
      "x": -10,
      "y": 40,
      "z": 3,
      "name": "Rock_Chalk"
    },
    {
      "x": -10,
      "y": 41,
      "z": 3,
      "name": "Rock_Chalk"
    },
    {
      "x": -10,
      "y": 42,
      "z": 3,
      "name": "Soil_Clay_White"
    },
    {
      "x": -10,
      "y": 43,
      "z": 3,
      "name": "Soil_Clay_White"
    },
    {
      "x": -10,
      "y": 44,
      "z": 3,
      "name": "Rock_Marble"
    },
    {
      "x": -10,
      "y": 45,
      "z": 3,
      "name": "Rock_Marble"
    },
    {
      "x": -10,
      "y": 46,
      "z": 3,
      "name": "Soil_Clay_White"
    },
    {
      "x": -10,
      "y": 47,
      "z": 3,
      "name": "Soil_Clay_White"
    },
    {
      "x": -10,
      "y": 48,
      "z": 3,
      "name": "Soil_Clay_White"
    },
    {
      "x": -10,
      "y": 49,
      "z": 3,
      "name": "Soil_Clay_White"
    },
    {
      "x": -10,
      "y": 50,
      "z": 3,
      "name": "Soil_Clay_White"
    },
    {
      "x": -10,
      "y": 51,
      "z": 3,
      "name": "Rock_Marble"
    },
    {
      "x": -10,
      "y": 52,
      "z": 3,
      "name": "Rock_Marble"
    },
    {
      "x": -10,
      "y": 53,
      "z": 3,
      "name": "Rock_Marble"
    },
    {
      "x": -10,
      "y": 54,
      "z": 3,
      "name": "Soil_Clay_White"
    },
    {
      "x": -10,
      "y": 55,
      "z": 3,
      "name": "Soil_Clay_White"
    },
    {
      "x": -10,
      "y": 33,
      "z": 4,
      "name": "Rock_Marble"
    },
    {
      "x": -10,
      "y": 34,
      "z": 4,
      "name": "Rock_Marble"
    },
    {
      "x": -10,
      "y": 35,
      "z": 4,
      "name": "Rock_Marble"
    },
    {
      "x": -10,
      "y": 36,
      "z": 4,
      "name": "Soil_Clay_White"
    },
    {
      "x": -10,
      "y": 37,
      "z": 4,
      "name": "Rock_Chalk"
    },
    {
      "x": -10,
      "y": 38,
      "z": 4,
      "name": "Rock_Chalk"
    },
    {
      "x": -10,
      "y": 39,
      "z": 4,
      "name": "Rock_Chalk"
    },
    {
      "x": -10,
      "y": 40,
      "z": 4,
      "name": "Rock_Chalk"
    },
    {
      "x": -10,
      "y": 41,
      "z": 4,
      "name": "Rock_Chalk"
    },
    {
      "x": -10,
      "y": 42,
      "z": 4,
      "name": "Rock_Chalk"
    },
    {
      "x": -10,
      "y": 43,
      "z": 4,
      "name": "Soil_Clay_White"
    },
    {
      "x": -10,
      "y": 44,
      "z": 4,
      "name": "Rock_Marble"
    },
    {
      "x": -10,
      "y": 45,
      "z": 4,
      "name": "Rock_Marble"
    },
    {
      "x": -10,
      "y": 46,
      "z": 4,
      "name": "Soil_Clay_White"
    },
    {
      "x": -10,
      "y": 47,
      "z": 4,
      "name": "Soil_Clay_White"
    },
    {
      "x": -10,
      "y": 48,
      "z": 4,
      "name": "Soil_Clay_White"
    },
    {
      "x": -10,
      "y": 49,
      "z": 4,
      "name": "Soil_Clay_White"
    },
    {
      "x": -10,
      "y": 50,
      "z": 4,
      "name": "Soil_Clay_White"
    },
    {
      "x": -10,
      "y": 36,
      "z": 5,
      "name": "Soil_Clay_White"
    },
    {
      "x": -10,
      "y": 37,
      "z": 5,
      "name": "Rock_Chalk"
    },
    {
      "x": -10,
      "y": 38,
      "z": 5,
      "name": "Rock_Chalk"
    },
    {
      "x": -10,
      "y": 39,
      "z": 5,
      "name": "Rock_Chalk"
    },
    {
      "x": -10,
      "y": 40,
      "z": 5,
      "name": "Rock_Chalk"
    },
    {
      "x": -10,
      "y": 41,
      "z": 5,
      "name": "Rock_Chalk"
    },
    {
      "x": -10,
      "y": 42,
      "z": 5,
      "name": "Rock_Chalk"
    },
    {
      "x": -10,
      "y": 43,
      "z": 5,
      "name": "Soil_Clay_White"
    },
    {
      "x": -10,
      "y": 44,
      "z": 5,
      "name": "Rock_Marble"
    },
    {
      "x": -10,
      "y": 45,
      "z": 5,
      "name": "Rock_Marble"
    },
    {
      "x": -10,
      "y": 46,
      "z": 5,
      "name": "Soil_Clay_White"
    },
    {
      "x": -10,
      "y": 38,
      "z": 6,
      "name": "Soil_Clay_White"
    },
    {
      "x": -10,
      "y": 39,
      "z": 6,
      "name": "Rock_Chalk"
    },
    {
      "x": -10,
      "y": 40,
      "z": 6,
      "name": "Rock_Chalk"
    },
    {
      "x": -10,
      "y": 41,
      "z": 6,
      "name": "Rock_Chalk"
    },
    {
      "x": -10,
      "y": 42,
      "z": 6,
      "name": "Rock_Chalk"
    },
    {
      "x": -10,
      "y": 43,
      "z": 6,
      "name": "Soil_Clay_White"
    },
    {
      "x": -9,
      "y": 38,
      "z": -8,
      "name": "Rock_Chalk"
    },
    {
      "x": -9,
      "y": 39,
      "z": -8,
      "name": "Rock_Chalk"
    },
    {
      "x": -9,
      "y": 40,
      "z": -8,
      "name": "Rock_Chalk"
    },
    {
      "x": -9,
      "y": 36,
      "z": -7,
      "name": "Soil_Clay_White"
    },
    {
      "x": -9,
      "y": 37,
      "z": -7,
      "name": "Rock_Chalk"
    },
    {
      "x": -9,
      "y": 38,
      "z": -7,
      "name": "Rock_Chalk"
    },
    {
      "x": -9,
      "y": 39,
      "z": -7,
      "name": "Rock_Chalk"
    },
    {
      "x": -9,
      "y": 40,
      "z": -7,
      "name": "Rock_Chalk"
    },
    {
      "x": -9,
      "y": 41,
      "z": -7,
      "name": "Rock_Chalk"
    },
    {
      "x": -9,
      "y": 42,
      "z": -7,
      "name": "Soil_Clay_White"
    },
    {
      "x": -9,
      "y": 43,
      "z": -7,
      "name": "Rock_Marble"
    },
    {
      "x": -9,
      "y": 44,
      "z": -7,
      "name": "Rock_Marble"
    },
    {
      "x": -9,
      "y": 45,
      "z": -7,
      "name": "Rock_Marble"
    },
    {
      "x": -9,
      "y": 46,
      "z": -7,
      "name": "Soil_Clay_White"
    },
    {
      "x": -9,
      "y": 34,
      "z": -6,
      "name": "Rock_Marble"
    },
    {
      "x": -9,
      "y": 35,
      "z": -6,
      "name": "Rock_Marble"
    },
    {
      "x": -9,
      "y": 36,
      "z": -6,
      "name": "Soil_Clay_White"
    },
    {
      "x": -9,
      "y": 37,
      "z": -6,
      "name": "Rock_Chalk"
    },
    {
      "x": -9,
      "y": 38,
      "z": -6,
      "name": "Rock_Chalk"
    },
    {
      "x": -9,
      "y": 39,
      "z": -6,
      "name": "Rock_Chalk"
    },
    {
      "x": -9,
      "y": 40,
      "z": -6,
      "name": "Rock_Chalk"
    },
    {
      "x": -9,
      "y": 41,
      "z": -6,
      "name": "Rock_Chalk"
    },
    {
      "x": -9,
      "y": 42,
      "z": -6,
      "name": "Soil_Clay_White"
    },
    {
      "x": -9,
      "y": 43,
      "z": -6,
      "name": "Rock_Marble"
    },
    {
      "x": -9,
      "y": 44,
      "z": -6,
      "name": "Rock_Marble"
    },
    {
      "x": -9,
      "y": 45,
      "z": -6,
      "name": "Rock_Marble"
    },
    {
      "x": -9,
      "y": 46,
      "z": -6,
      "name": "Soil_Clay_White"
    },
    {
      "x": -9,
      "y": 47,
      "z": -6,
      "name": "Soil_Clay_White"
    },
    {
      "x": -9,
      "y": 48,
      "z": -6,
      "name": "Soil_Clay_White"
    },
    {
      "x": -9,
      "y": 49,
      "z": -6,
      "name": "Soil_Clay_White"
    },
    {
      "x": -9,
      "y": 32,
      "z": -5,
      "name": "Rock_Marble"
    },
    {
      "x": -9,
      "y": 33,
      "z": -5,
      "name": "Rock_Marble"
    },
    {
      "x": -9,
      "y": 34,
      "z": -5,
      "name": "Rock_Marble"
    },
    {
      "x": -9,
      "y": 35,
      "z": -5,
      "name": "Rock_Marble"
    },
    {
      "x": -9,
      "y": 36,
      "z": -5,
      "name": "Soil_Clay_White"
    },
    {
      "x": -9,
      "y": 37,
      "z": -5,
      "name": "Rock_Chalk"
    },
    {
      "x": -9,
      "y": 38,
      "z": -5,
      "name": "Rock_Chalk"
    },
    {
      "x": -9,
      "y": 39,
      "z": -5,
      "name": "Rock_Chalk"
    },
    {
      "x": -9,
      "y": 40,
      "z": -5,
      "name": "Rock_Chalk"
    },
    {
      "x": -9,
      "y": 41,
      "z": -5,
      "name": "Rock_Chalk"
    },
    {
      "x": -9,
      "y": 42,
      "z": -5,
      "name": "Soil_Clay_White"
    },
    {
      "x": -9,
      "y": 43,
      "z": -5,
      "name": "Rock_Marble"
    },
    {
      "x": -9,
      "y": 44,
      "z": -5,
      "name": "Rock_Marble"
    },
    {
      "x": -9,
      "y": 45,
      "z": -5,
      "name": "Rock_Marble"
    },
    {
      "x": -9,
      "y": 46,
      "z": -5,
      "name": "Soil_Clay_White"
    },
    {
      "x": -9,
      "y": 47,
      "z": -5,
      "name": "Soil_Clay_White"
    },
    {
      "x": -9,
      "y": 48,
      "z": -5,
      "name": "Soil_Clay_White"
    },
    {
      "x": -9,
      "y": 49,
      "z": -5,
      "name": "Soil_Clay_White"
    },
    {
      "x": -9,
      "y": 50,
      "z": -5,
      "name": "Soil_Clay_White"
    },
    {
      "x": -9,
      "y": 51,
      "z": -5,
      "name": "Rock_Marble"
    },
    {
      "x": -9,
      "y": 52,
      "z": -5,
      "name": "Rock_Marble"
    },
    {
      "x": -9,
      "y": 53,
      "z": -5,
      "name": "Soil_Clay_White"
    },
    {
      "x": -9,
      "y": 30,
      "z": -4,
      "name": "Soil_Pebbles"
    },
    {
      "x": -9,
      "y": 31,
      "z": -4,
      "name": "Rock_Marble"
    },
    {
      "x": -9,
      "y": 32,
      "z": -4,
      "name": "Rock_Marble"
    },
    {
      "x": -9,
      "y": 33,
      "z": -4,
      "name": "Rock_Marble"
    },
    {
      "x": -9,
      "y": 34,
      "z": -4,
      "name": "Rock_Marble"
    },
    {
      "x": -9,
      "y": 35,
      "z": -4,
      "name": "Rock_Marble"
    },
    {
      "x": -9,
      "y": 36,
      "z": -4,
      "name": "Soil_Clay_White"
    },
    {
      "x": -9,
      "y": 37,
      "z": -4,
      "name": "Rock_Chalk"
    },
    {
      "x": -9,
      "y": 38,
      "z": -4,
      "name": "Rock_Chalk"
    },
    {
      "x": -9,
      "y": 39,
      "z": -4,
      "name": "Rock_Chalk"
    },
    {
      "x": -9,
      "y": 40,
      "z": -4,
      "name": "Rock_Chalk"
    },
    {
      "x": -9,
      "y": 41,
      "z": -4,
      "name": "Rock_Chalk"
    },
    {
      "x": -9,
      "y": 42,
      "z": -4,
      "name": "Soil_Clay_White"
    },
    {
      "x": -9,
      "y": 43,
      "z": -4,
      "name": "Rock_Marble"
    },
    {
      "x": -9,
      "y": 44,
      "z": -4,
      "name": "Rock_Marble"
    },
    {
      "x": -9,
      "y": 45,
      "z": -4,
      "name": "Rock_Marble"
    },
    {
      "x": -9,
      "y": 46,
      "z": -4,
      "name": "Soil_Clay_White"
    },
    {
      "x": -9,
      "y": 47,
      "z": -4,
      "name": "Soil_Clay_White"
    },
    {
      "x": -9,
      "y": 48,
      "z": -4,
      "name": "Soil_Clay_White"
    },
    {
      "x": -9,
      "y": 49,
      "z": -4,
      "name": "Soil_Clay_White"
    },
    {
      "x": -9,
      "y": 50,
      "z": -4,
      "name": "Soil_Clay_White"
    },
    {
      "x": -9,
      "y": 51,
      "z": -4,
      "name": "Rock_Marble"
    },
    {
      "x": -9,
      "y": 52,
      "z": -4,
      "name": "Rock_Marble"
    },
    {
      "x": -9,
      "y": 53,
      "z": -4,
      "name": "Soil_Clay_White"
    },
    {
      "x": -9,
      "y": 54,
      "z": -4,
      "name": "Soil_Clay_White"
    },
    {
      "x": -9,
      "y": 55,
      "z": -4,
      "name": "Soil_Clay_White"
    },
    {
      "x": -9,
      "y": 56,
      "z": -4,
      "name": "Soil_Clay_White"
    },
    {
      "x": -9,
      "y": 57,
      "z": -4,
      "name": "Soil_Clay_White"
    },
    {
      "x": -9,
      "y": 28,
      "z": -3,
      "name": "Rock_Marble"
    },
    {
      "x": -9,
      "y": 29,
      "z": -3,
      "name": "Rock_Marble"
    },
    {
      "x": -9,
      "y": 30,
      "z": -3,
      "name": "Soil_Pebbles"
    },
    {
      "x": -9,
      "y": 31,
      "z": -3,
      "name": "Rock_Marble"
    },
    {
      "x": -9,
      "y": 32,
      "z": -3,
      "name": "Rock_Marble"
    },
    {
      "x": -9,
      "y": 33,
      "z": -3,
      "name": "Rock_Marble"
    },
    {
      "x": -9,
      "y": 34,
      "z": -3,
      "name": "Rock_Marble"
    },
    {
      "x": -9,
      "y": 35,
      "z": -3,
      "name": "Rock_Marble"
    },
    {
      "x": -9,
      "y": 36,
      "z": -3,
      "name": "Soil_Clay_White"
    },
    {
      "x": -9,
      "y": 37,
      "z": -3,
      "name": "Rock_Chalk"
    },
    {
      "x": -9,
      "y": 38,
      "z": -3,
      "name": "Rock_Chalk"
    },
    {
      "x": -9,
      "y": 39,
      "z": -3,
      "name": "Rock_Chalk"
    },
    {
      "x": -9,
      "y": 40,
      "z": -3,
      "name": "Rock_Chalk"
    },
    {
      "x": -9,
      "y": 41,
      "z": -3,
      "name": "Rock_Chalk"
    },
    {
      "x": -9,
      "y": 42,
      "z": -3,
      "name": "Soil_Clay_White"
    },
    {
      "x": -9,
      "y": 43,
      "z": -3,
      "name": "Rock_Marble"
    },
    {
      "x": -9,
      "y": 44,
      "z": -3,
      "name": "Rock_Marble"
    },
    {
      "x": -9,
      "y": 45,
      "z": -3,
      "name": "Rock_Marble"
    },
    {
      "x": -9,
      "y": 46,
      "z": -3,
      "name": "Soil_Clay_White"
    },
    {
      "x": -9,
      "y": 47,
      "z": -3,
      "name": "Soil_Clay_White"
    },
    {
      "x": -9,
      "y": 48,
      "z": -3,
      "name": "Soil_Clay_White"
    },
    {
      "x": -9,
      "y": 49,
      "z": -3,
      "name": "Soil_Clay_White"
    },
    {
      "x": -9,
      "y": 50,
      "z": -3,
      "name": "Soil_Clay_White"
    },
    {
      "x": -9,
      "y": 51,
      "z": -3,
      "name": "Rock_Marble"
    },
    {
      "x": -9,
      "y": 52,
      "z": -3,
      "name": "Rock_Marble"
    },
    {
      "x": -9,
      "y": 53,
      "z": -3,
      "name": "Soil_Clay_White"
    },
    {
      "x": -9,
      "y": 54,
      "z": -3,
      "name": "Soil_Clay_White"
    },
    {
      "x": -9,
      "y": 55,
      "z": -3,
      "name": "Soil_Clay_White"
    },
    {
      "x": -9,
      "y": 56,
      "z": -3,
      "name": "Soil_Clay_White"
    },
    {
      "x": -9,
      "y": 57,
      "z": -3,
      "name": "Soil_Clay_White"
    },
    {
      "x": -9,
      "y": 58,
      "z": -3,
      "name": "Soil_Clay_White"
    },
    {
      "x": -9,
      "y": 59,
      "z": -3,
      "name": "Soil_Clay_White"
    },
    {
      "x": -9,
      "y": 60,
      "z": -3,
      "name": "Soil_Clay_White"
    },
    {
      "x": -9,
      "y": 61,
      "z": -3,
      "name": "Rock_Chalk"
    },
    {
      "x": -9,
      "y": 62,
      "z": -3,
      "name": "Rock_Chalk"
    },
    {
      "x": -9,
      "y": 26,
      "z": -2,
      "name": "Rock_Marble"
    },
    {
      "x": -9,
      "y": 27,
      "z": -2,
      "name": "Rock_Marble"
    },
    {
      "x": -9,
      "y": 28,
      "z": -2,
      "name": "Rock_Marble"
    },
    {
      "x": -9,
      "y": 29,
      "z": -2,
      "name": "Rock_Marble"
    },
    {
      "x": -9,
      "y": 30,
      "z": -2,
      "name": "Soil_Pebbles"
    },
    {
      "x": -9,
      "y": 31,
      "z": -2,
      "name": "Rock_Marble"
    },
    {
      "x": -9,
      "y": 32,
      "z": -2,
      "name": "Rock_Marble"
    },
    {
      "x": -9,
      "y": 33,
      "z": -2,
      "name": "Rock_Marble"
    },
    {
      "x": -9,
      "y": 34,
      "z": -2,
      "name": "Rock_Marble"
    },
    {
      "x": -9,
      "y": 35,
      "z": -2,
      "name": "Rock_Marble"
    },
    {
      "x": -9,
      "y": 36,
      "z": -2,
      "name": "Soil_Clay_White"
    },
    {
      "x": -9,
      "y": 37,
      "z": -2,
      "name": "Rock_Chalk"
    },
    {
      "x": -9,
      "y": 38,
      "z": -2,
      "name": "Rock_Chalk"
    },
    {
      "x": -9,
      "y": 39,
      "z": -2,
      "name": "Rock_Chalk"
    },
    {
      "x": -9,
      "y": 40,
      "z": -2,
      "name": "Rock_Chalk"
    },
    {
      "x": -9,
      "y": 41,
      "z": -2,
      "name": "Rock_Chalk"
    },
    {
      "x": -9,
      "y": 42,
      "z": -2,
      "name": "Soil_Clay_White"
    },
    {
      "x": -9,
      "y": 43,
      "z": -2,
      "name": "Rock_Marble"
    },
    {
      "x": -9,
      "y": 44,
      "z": -2,
      "name": "Rock_Marble"
    },
    {
      "x": -9,
      "y": 45,
      "z": -2,
      "name": "Rock_Marble"
    },
    {
      "x": -9,
      "y": 46,
      "z": -2,
      "name": "Soil_Clay_White"
    },
    {
      "x": -9,
      "y": 47,
      "z": -2,
      "name": "Soil_Clay_White"
    },
    {
      "x": -9,
      "y": 48,
      "z": -2,
      "name": "Soil_Clay_White"
    },
    {
      "x": -9,
      "y": 49,
      "z": -2,
      "name": "Soil_Clay_White"
    },
    {
      "x": -9,
      "y": 50,
      "z": -2,
      "name": "Soil_Clay_White"
    },
    {
      "x": -9,
      "y": 51,
      "z": -2,
      "name": "Rock_Marble"
    },
    {
      "x": -9,
      "y": 52,
      "z": -2,
      "name": "Rock_Marble"
    },
    {
      "x": -9,
      "y": 53,
      "z": -2,
      "name": "Soil_Clay_White"
    },
    {
      "x": -9,
      "y": 54,
      "z": -2,
      "name": "Soil_Clay_White"
    },
    {
      "x": -9,
      "y": 55,
      "z": -2,
      "name": "Soil_Clay_White"
    },
    {
      "x": -9,
      "y": 56,
      "z": -2,
      "name": "Soil_Clay_White"
    },
    {
      "x": -9,
      "y": 57,
      "z": -2,
      "name": "Soil_Clay_White"
    },
    {
      "x": -9,
      "y": 58,
      "z": -2,
      "name": "Soil_Clay_White"
    },
    {
      "x": -9,
      "y": 59,
      "z": -2,
      "name": "Soil_Clay_White"
    },
    {
      "x": -9,
      "y": 60,
      "z": -2,
      "name": "Soil_Clay_White"
    },
    {
      "x": -9,
      "y": 61,
      "z": -2,
      "name": "Rock_Chalk"
    },
    {
      "x": -9,
      "y": 62,
      "z": -2,
      "name": "Rock_Chalk"
    },
    {
      "x": -9,
      "y": 63,
      "z": -2,
      "name": "Soil_Clay_White"
    },
    {
      "x": -9,
      "y": 25,
      "z": -1,
      "name": "Soil_Clay_White"
    },
    {
      "x": -9,
      "y": 26,
      "z": -1,
      "name": "Rock_Marble"
    },
    {
      "x": -9,
      "y": 27,
      "z": -1,
      "name": "Rock_Marble"
    },
    {
      "x": -9,
      "y": 28,
      "z": -1,
      "name": "Rock_Marble"
    },
    {
      "x": -9,
      "y": 29,
      "z": -1,
      "name": "Rock_Marble"
    },
    {
      "x": -9,
      "y": 30,
      "z": -1,
      "name": "Soil_Pebbles"
    },
    {
      "x": -9,
      "y": 31,
      "z": -1,
      "name": "Rock_Marble"
    },
    {
      "x": -9,
      "y": 32,
      "z": -1,
      "name": "Rock_Marble"
    },
    {
      "x": -9,
      "y": 33,
      "z": -1,
      "name": "Rock_Marble"
    },
    {
      "x": -9,
      "y": 34,
      "z": -1,
      "name": "Rock_Marble"
    },
    {
      "x": -9,
      "y": 35,
      "z": -1,
      "name": "Rock_Marble"
    },
    {
      "x": -9,
      "y": 36,
      "z": -1,
      "name": "Soil_Clay_White"
    },
    {
      "x": -9,
      "y": 37,
      "z": -1,
      "name": "Rock_Chalk"
    },
    {
      "x": -9,
      "y": 38,
      "z": -1,
      "name": "Rock_Chalk"
    },
    {
      "x": -9,
      "y": 39,
      "z": -1,
      "name": "Rock_Chalk"
    },
    {
      "x": -9,
      "y": 40,
      "z": -1,
      "name": "Rock_Chalk"
    },
    {
      "x": -9,
      "y": 41,
      "z": -1,
      "name": "Rock_Chalk"
    },
    {
      "x": -9,
      "y": 42,
      "z": -1,
      "name": "Soil_Clay_White"
    },
    {
      "x": -9,
      "y": 43,
      "z": -1,
      "name": "Rock_Marble"
    },
    {
      "x": -9,
      "y": 44,
      "z": -1,
      "name": "Rock_Marble"
    },
    {
      "x": -9,
      "y": 45,
      "z": -1,
      "name": "Rock_Marble"
    },
    {
      "x": -9,
      "y": 46,
      "z": -1,
      "name": "Soil_Clay_White"
    },
    {
      "x": -9,
      "y": 47,
      "z": -1,
      "name": "Soil_Clay_White"
    },
    {
      "x": -9,
      "y": 48,
      "z": -1,
      "name": "Soil_Clay_White"
    },
    {
      "x": -9,
      "y": 49,
      "z": -1,
      "name": "Soil_Clay_White"
    },
    {
      "x": -9,
      "y": 50,
      "z": -1,
      "name": "Soil_Clay_White"
    },
    {
      "x": -9,
      "y": 51,
      "z": -1,
      "name": "Rock_Marble"
    },
    {
      "x": -9,
      "y": 52,
      "z": -1,
      "name": "Rock_Marble"
    },
    {
      "x": -9,
      "y": 53,
      "z": -1,
      "name": "Soil_Clay_White"
    },
    {
      "x": -9,
      "y": 54,
      "z": -1,
      "name": "Soil_Clay_White"
    },
    {
      "x": -9,
      "y": 55,
      "z": -1,
      "name": "Soil_Clay_White"
    },
    {
      "x": -9,
      "y": 56,
      "z": -1,
      "name": "Soil_Clay_White"
    },
    {
      "x": -9,
      "y": 57,
      "z": -1,
      "name": "Soil_Clay_White"
    },
    {
      "x": -9,
      "y": 58,
      "z": -1,
      "name": "Soil_Clay_White"
    },
    {
      "x": -9,
      "y": 59,
      "z": -1,
      "name": "Soil_Clay_White"
    },
    {
      "x": -9,
      "y": 60,
      "z": -1,
      "name": "Soil_Clay_White"
    },
    {
      "x": -9,
      "y": 61,
      "z": -1,
      "name": "Rock_Chalk"
    },
    {
      "x": -9,
      "y": 62,
      "z": -1,
      "name": "Rock_Chalk"
    },
    {
      "x": -9,
      "y": 63,
      "z": -1,
      "name": "Soil_Clay_White"
    },
    {
      "x": -9,
      "y": 64,
      "z": -1,
      "name": "Soil_Clay_White"
    },
    {
      "x": -9,
      "y": 65,
      "z": -1,
      "name": "Rock_Chalk"
    },
    {
      "x": -9,
      "y": 24,
      "z": 0,
      "name": "Soil_Clay_White"
    },
    {
      "x": -9,
      "y": 25,
      "z": 0,
      "name": "Soil_Clay_White"
    },
    {
      "x": -9,
      "y": 26,
      "z": 0,
      "name": "Rock_Marble"
    },
    {
      "x": -9,
      "y": 27,
      "z": 0,
      "name": "Rock_Marble"
    },
    {
      "x": -9,
      "y": 28,
      "z": 0,
      "name": "Rock_Marble"
    },
    {
      "x": -9,
      "y": 29,
      "z": 0,
      "name": "Rock_Marble"
    },
    {
      "x": -9,
      "y": 30,
      "z": 0,
      "name": "Soil_Pebbles"
    },
    {
      "x": -9,
      "y": 31,
      "z": 0,
      "name": "Rock_Marble"
    },
    {
      "x": -9,
      "y": 32,
      "z": 0,
      "name": "Rock_Marble"
    },
    {
      "x": -9,
      "y": 33,
      "z": 0,
      "name": "Rock_Marble"
    },
    {
      "x": -9,
      "y": 34,
      "z": 0,
      "name": "Rock_Marble"
    },
    {
      "x": -9,
      "y": 35,
      "z": 0,
      "name": "Rock_Marble"
    },
    {
      "x": -9,
      "y": 36,
      "z": 0,
      "name": "Soil_Clay_White"
    },
    {
      "x": -9,
      "y": 37,
      "z": 0,
      "name": "Rock_Chalk"
    },
    {
      "x": -9,
      "y": 38,
      "z": 0,
      "name": "Rock_Chalk"
    },
    {
      "x": -9,
      "y": 39,
      "z": 0,
      "name": "Rock_Chalk"
    },
    {
      "x": -9,
      "y": 40,
      "z": 0,
      "name": "Rock_Chalk"
    },
    {
      "x": -9,
      "y": 41,
      "z": 0,
      "name": "Rock_Chalk"
    },
    {
      "x": -9,
      "y": 42,
      "z": 0,
      "name": "Soil_Clay_White"
    },
    {
      "x": -9,
      "y": 43,
      "z": 0,
      "name": "Soil_Clay_White"
    },
    {
      "x": -9,
      "y": 44,
      "z": 0,
      "name": "Rock_Marble"
    },
    {
      "x": -9,
      "y": 45,
      "z": 0,
      "name": "Rock_Marble"
    },
    {
      "x": -9,
      "y": 46,
      "z": 0,
      "name": "Soil_Clay_White"
    },
    {
      "x": -9,
      "y": 47,
      "z": 0,
      "name": "Soil_Clay_White"
    },
    {
      "x": -9,
      "y": 48,
      "z": 0,
      "name": "Soil_Clay_White"
    },
    {
      "x": -9,
      "y": 49,
      "z": 0,
      "name": "Soil_Clay_White"
    },
    {
      "x": -9,
      "y": 50,
      "z": 0,
      "name": "Soil_Clay_White"
    },
    {
      "x": -9,
      "y": 51,
      "z": 0,
      "name": "Rock_Marble"
    },
    {
      "x": -9,
      "y": 52,
      "z": 0,
      "name": "Rock_Marble"
    },
    {
      "x": -9,
      "y": 53,
      "z": 0,
      "name": "Soil_Clay_White"
    },
    {
      "x": -9,
      "y": 54,
      "z": 0,
      "name": "Soil_Clay_White"
    },
    {
      "x": -9,
      "y": 55,
      "z": 0,
      "name": "Soil_Clay_White"
    },
    {
      "x": -9,
      "y": 56,
      "z": 0,
      "name": "Soil_Clay_White"
    },
    {
      "x": -9,
      "y": 57,
      "z": 0,
      "name": "Soil_Clay_White"
    },
    {
      "x": -9,
      "y": 58,
      "z": 0,
      "name": "Soil_Clay_White"
    },
    {
      "x": -9,
      "y": 59,
      "z": 0,
      "name": "Soil_Clay_White"
    },
    {
      "x": -9,
      "y": 60,
      "z": 0,
      "name": "Soil_Clay_White"
    },
    {
      "x": -9,
      "y": 61,
      "z": 0,
      "name": "Rock_Chalk"
    },
    {
      "x": -9,
      "y": 62,
      "z": 0,
      "name": "Rock_Chalk"
    },
    {
      "x": -9,
      "y": 63,
      "z": 0,
      "name": "Soil_Clay_White"
    },
    {
      "x": -9,
      "y": 64,
      "z": 0,
      "name": "Soil_Clay_White"
    },
    {
      "x": -9,
      "y": 65,
      "z": 0,
      "name": "Rock_Chalk"
    },
    {
      "x": -9,
      "y": 66,
      "z": 0,
      "name": "Soil_Clay_White"
    },
    {
      "x": -9,
      "y": 67,
      "z": 0,
      "name": "Rock_Marble"
    },
    {
      "x": -9,
      "y": 24,
      "z": 1,
      "name": "Soil_Clay_White"
    },
    {
      "x": -9,
      "y": 25,
      "z": 1,
      "name": "Soil_Clay_White"
    },
    {
      "x": -9,
      "y": 26,
      "z": 1,
      "name": "Rock_Marble"
    },
    {
      "x": -9,
      "y": 27,
      "z": 1,
      "name": "Rock_Marble"
    },
    {
      "x": -9,
      "y": 28,
      "z": 1,
      "name": "Rock_Marble"
    },
    {
      "x": -9,
      "y": 29,
      "z": 1,
      "name": "Rock_Marble"
    },
    {
      "x": -9,
      "y": 30,
      "z": 1,
      "name": "Soil_Pebbles"
    },
    {
      "x": -9,
      "y": 31,
      "z": 1,
      "name": "Rock_Marble"
    },
    {
      "x": -9,
      "y": 32,
      "z": 1,
      "name": "Rock_Marble"
    },
    {
      "x": -9,
      "y": 33,
      "z": 1,
      "name": "Rock_Marble"
    },
    {
      "x": -9,
      "y": 34,
      "z": 1,
      "name": "Rock_Marble"
    },
    {
      "x": -9,
      "y": 35,
      "z": 1,
      "name": "Rock_Marble"
    },
    {
      "x": -9,
      "y": 36,
      "z": 1,
      "name": "Soil_Clay_White"
    },
    {
      "x": -9,
      "y": 37,
      "z": 1,
      "name": "Rock_Chalk"
    },
    {
      "x": -9,
      "y": 38,
      "z": 1,
      "name": "Rock_Chalk"
    },
    {
      "x": -9,
      "y": 39,
      "z": 1,
      "name": "Rock_Chalk"
    },
    {
      "x": -9,
      "y": 40,
      "z": 1,
      "name": "Rock_Chalk"
    },
    {
      "x": -9,
      "y": 41,
      "z": 1,
      "name": "Rock_Chalk"
    },
    {
      "x": -9,
      "y": 42,
      "z": 1,
      "name": "Soil_Clay_White"
    },
    {
      "x": -9,
      "y": 43,
      "z": 1,
      "name": "Soil_Clay_White"
    },
    {
      "x": -9,
      "y": 44,
      "z": 1,
      "name": "Rock_Marble"
    },
    {
      "x": -9,
      "y": 45,
      "z": 1,
      "name": "Rock_Marble"
    },
    {
      "x": -9,
      "y": 46,
      "z": 1,
      "name": "Soil_Clay_White"
    },
    {
      "x": -9,
      "y": 47,
      "z": 1,
      "name": "Soil_Clay_White"
    },
    {
      "x": -9,
      "y": 48,
      "z": 1,
      "name": "Soil_Clay_White"
    },
    {
      "x": -9,
      "y": 49,
      "z": 1,
      "name": "Soil_Clay_White"
    },
    {
      "x": -9,
      "y": 50,
      "z": 1,
      "name": "Soil_Clay_White"
    },
    {
      "x": -9,
      "y": 51,
      "z": 1,
      "name": "Rock_Marble"
    },
    {
      "x": -9,
      "y": 52,
      "z": 1,
      "name": "Rock_Marble"
    },
    {
      "x": -9,
      "y": 53,
      "z": 1,
      "name": "Soil_Clay_White"
    },
    {
      "x": -9,
      "y": 54,
      "z": 1,
      "name": "Soil_Clay_White"
    },
    {
      "x": -9,
      "y": 55,
      "z": 1,
      "name": "Soil_Clay_White"
    },
    {
      "x": -9,
      "y": 56,
      "z": 1,
      "name": "Soil_Clay_White"
    },
    {
      "x": -9,
      "y": 57,
      "z": 1,
      "name": "Soil_Clay_White"
    },
    {
      "x": -9,
      "y": 58,
      "z": 1,
      "name": "Soil_Clay_White"
    },
    {
      "x": -9,
      "y": 59,
      "z": 1,
      "name": "Soil_Clay_White"
    },
    {
      "x": -9,
      "y": 60,
      "z": 1,
      "name": "Soil_Clay_White"
    },
    {
      "x": -9,
      "y": 61,
      "z": 1,
      "name": "Rock_Chalk"
    },
    {
      "x": -9,
      "y": 62,
      "z": 1,
      "name": "Rock_Chalk"
    },
    {
      "x": -9,
      "y": 63,
      "z": 1,
      "name": "Soil_Clay_White"
    },
    {
      "x": -9,
      "y": 64,
      "z": 1,
      "name": "Soil_Clay_White"
    },
    {
      "x": -9,
      "y": 65,
      "z": 1,
      "name": "Rock_Chalk"
    },
    {
      "x": -9,
      "y": 66,
      "z": 1,
      "name": "Soil_Clay_White"
    },
    {
      "x": -9,
      "y": 67,
      "z": 1,
      "name": "Rock_Marble"
    },
    {
      "x": -9,
      "y": 68,
      "z": 1,
      "name": "Rock_Marble"
    },
    {
      "x": -9,
      "y": 23,
      "z": 2,
      "name": "Rock_Chalk"
    },
    {
      "x": -9,
      "y": 24,
      "z": 2,
      "name": "Soil_Clay_White"
    },
    {
      "x": -9,
      "y": 25,
      "z": 2,
      "name": "Soil_Clay_White"
    },
    {
      "x": -9,
      "y": 26,
      "z": 2,
      "name": "Rock_Marble"
    },
    {
      "x": -9,
      "y": 27,
      "z": 2,
      "name": "Rock_Marble"
    },
    {
      "x": -9,
      "y": 28,
      "z": 2,
      "name": "Rock_Marble"
    },
    {
      "x": -9,
      "y": 29,
      "z": 2,
      "name": "Rock_Marble"
    },
    {
      "x": -9,
      "y": 30,
      "z": 2,
      "name": "Soil_Pebbles"
    },
    {
      "x": -9,
      "y": 31,
      "z": 2,
      "name": "Rock_Marble"
    },
    {
      "x": -9,
      "y": 32,
      "z": 2,
      "name": "Rock_Marble"
    },
    {
      "x": -9,
      "y": 33,
      "z": 2,
      "name": "Rock_Marble"
    },
    {
      "x": -9,
      "y": 34,
      "z": 2,
      "name": "Rock_Marble"
    },
    {
      "x": -9,
      "y": 35,
      "z": 2,
      "name": "Rock_Marble"
    },
    {
      "x": -9,
      "y": 36,
      "z": 2,
      "name": "Soil_Clay_White"
    },
    {
      "x": -9,
      "y": 37,
      "z": 2,
      "name": "Rock_Chalk"
    },
    {
      "x": -9,
      "y": 38,
      "z": 2,
      "name": "Rock_Chalk"
    },
    {
      "x": -9,
      "y": 39,
      "z": 2,
      "name": "Rock_Chalk"
    },
    {
      "x": -9,
      "y": 40,
      "z": 2,
      "name": "Rock_Chalk"
    },
    {
      "x": -9,
      "y": 41,
      "z": 2,
      "name": "Rock_Chalk"
    },
    {
      "x": -9,
      "y": 42,
      "z": 2,
      "name": "Soil_Clay_White"
    },
    {
      "x": -9,
      "y": 43,
      "z": 2,
      "name": "Soil_Clay_White"
    },
    {
      "x": -9,
      "y": 44,
      "z": 2,
      "name": "Rock_Marble"
    },
    {
      "x": -9,
      "y": 45,
      "z": 2,
      "name": "Rock_Marble"
    },
    {
      "x": -9,
      "y": 46,
      "z": 2,
      "name": "Soil_Clay_White"
    },
    {
      "x": -9,
      "y": 47,
      "z": 2,
      "name": "Soil_Clay_White"
    },
    {
      "x": -9,
      "y": 48,
      "z": 2,
      "name": "Soil_Clay_White"
    },
    {
      "x": -9,
      "y": 49,
      "z": 2,
      "name": "Soil_Clay_White"
    },
    {
      "x": -9,
      "y": 50,
      "z": 2,
      "name": "Soil_Clay_White"
    },
    {
      "x": -9,
      "y": 51,
      "z": 2,
      "name": "Rock_Marble"
    },
    {
      "x": -9,
      "y": 52,
      "z": 2,
      "name": "Rock_Marble"
    },
    {
      "x": -9,
      "y": 53,
      "z": 2,
      "name": "Soil_Clay_White"
    },
    {
      "x": -9,
      "y": 54,
      "z": 2,
      "name": "Soil_Clay_White"
    },
    {
      "x": -9,
      "y": 55,
      "z": 2,
      "name": "Soil_Clay_White"
    },
    {
      "x": -9,
      "y": 56,
      "z": 2,
      "name": "Soil_Clay_White"
    },
    {
      "x": -9,
      "y": 57,
      "z": 2,
      "name": "Soil_Clay_White"
    },
    {
      "x": -9,
      "y": 58,
      "z": 2,
      "name": "Soil_Clay_White"
    },
    {
      "x": -9,
      "y": 59,
      "z": 2,
      "name": "Soil_Clay_White"
    },
    {
      "x": -9,
      "y": 60,
      "z": 2,
      "name": "Soil_Clay_White"
    },
    {
      "x": -9,
      "y": 61,
      "z": 2,
      "name": "Rock_Chalk"
    },
    {
      "x": -9,
      "y": 62,
      "z": 2,
      "name": "Rock_Chalk"
    },
    {
      "x": -9,
      "y": 63,
      "z": 2,
      "name": "Soil_Clay_White"
    },
    {
      "x": -9,
      "y": 64,
      "z": 2,
      "name": "Soil_Clay_White"
    },
    {
      "x": -9,
      "y": 65,
      "z": 2,
      "name": "Rock_Chalk"
    },
    {
      "x": -9,
      "y": 66,
      "z": 2,
      "name": "Soil_Clay_White"
    },
    {
      "x": -9,
      "y": 67,
      "z": 2,
      "name": "Rock_Marble"
    },
    {
      "x": -9,
      "y": 25,
      "z": 3,
      "name": "Soil_Clay_White"
    },
    {
      "x": -9,
      "y": 26,
      "z": 3,
      "name": "Rock_Marble"
    },
    {
      "x": -9,
      "y": 27,
      "z": 3,
      "name": "Rock_Marble"
    },
    {
      "x": -9,
      "y": 28,
      "z": 3,
      "name": "Rock_Marble"
    },
    {
      "x": -9,
      "y": 29,
      "z": 3,
      "name": "Rock_Marble"
    },
    {
      "x": -9,
      "y": 30,
      "z": 3,
      "name": "Soil_Pebbles"
    },
    {
      "x": -9,
      "y": 31,
      "z": 3,
      "name": "Rock_Marble"
    },
    {
      "x": -9,
      "y": 32,
      "z": 3,
      "name": "Rock_Marble"
    },
    {
      "x": -9,
      "y": 33,
      "z": 3,
      "name": "Rock_Marble"
    },
    {
      "x": -9,
      "y": 34,
      "z": 3,
      "name": "Rock_Marble"
    },
    {
      "x": -9,
      "y": 35,
      "z": 3,
      "name": "Rock_Marble"
    },
    {
      "x": -9,
      "y": 36,
      "z": 3,
      "name": "Soil_Clay_White"
    },
    {
      "x": -9,
      "y": 37,
      "z": 3,
      "name": "Rock_Chalk"
    },
    {
      "x": -9,
      "y": 38,
      "z": 3,
      "name": "Rock_Chalk"
    },
    {
      "x": -9,
      "y": 39,
      "z": 3,
      "name": "Rock_Chalk"
    },
    {
      "x": -9,
      "y": 40,
      "z": 3,
      "name": "Rock_Chalk"
    },
    {
      "x": -9,
      "y": 41,
      "z": 3,
      "name": "Rock_Chalk"
    },
    {
      "x": -9,
      "y": 42,
      "z": 3,
      "name": "Soil_Clay_White"
    },
    {
      "x": -9,
      "y": 43,
      "z": 3,
      "name": "Soil_Clay_White"
    },
    {
      "x": -9,
      "y": 44,
      "z": 3,
      "name": "Rock_Marble"
    },
    {
      "x": -9,
      "y": 45,
      "z": 3,
      "name": "Rock_Marble"
    },
    {
      "x": -9,
      "y": 46,
      "z": 3,
      "name": "Soil_Clay_White"
    },
    {
      "x": -9,
      "y": 47,
      "z": 3,
      "name": "Soil_Clay_White"
    },
    {
      "x": -9,
      "y": 48,
      "z": 3,
      "name": "Soil_Clay_White"
    },
    {
      "x": -9,
      "y": 49,
      "z": 3,
      "name": "Soil_Clay_White"
    },
    {
      "x": -9,
      "y": 50,
      "z": 3,
      "name": "Soil_Clay_White"
    },
    {
      "x": -9,
      "y": 51,
      "z": 3,
      "name": "Rock_Marble"
    },
    {
      "x": -9,
      "y": 52,
      "z": 3,
      "name": "Rock_Marble"
    },
    {
      "x": -9,
      "y": 53,
      "z": 3,
      "name": "Rock_Marble"
    },
    {
      "x": -9,
      "y": 54,
      "z": 3,
      "name": "Soil_Clay_White"
    },
    {
      "x": -9,
      "y": 55,
      "z": 3,
      "name": "Soil_Clay_White"
    },
    {
      "x": -9,
      "y": 56,
      "z": 3,
      "name": "Soil_Clay_White"
    },
    {
      "x": -9,
      "y": 57,
      "z": 3,
      "name": "Soil_Clay_White"
    },
    {
      "x": -9,
      "y": 58,
      "z": 3,
      "name": "Soil_Clay_White"
    },
    {
      "x": -9,
      "y": 59,
      "z": 3,
      "name": "Soil_Clay_White"
    },
    {
      "x": -9,
      "y": 60,
      "z": 3,
      "name": "Soil_Clay_White"
    },
    {
      "x": -9,
      "y": 61,
      "z": 3,
      "name": "Rock_Chalk"
    },
    {
      "x": -9,
      "y": 62,
      "z": 3,
      "name": "Rock_Chalk"
    },
    {
      "x": -9,
      "y": 63,
      "z": 3,
      "name": "Soil_Clay_White"
    },
    {
      "x": -9,
      "y": 64,
      "z": 3,
      "name": "Soil_Clay_White"
    },
    {
      "x": -9,
      "y": 65,
      "z": 3,
      "name": "Rock_Chalk"
    },
    {
      "x": -9,
      "y": 28,
      "z": 4,
      "name": "Rock_Marble"
    },
    {
      "x": -9,
      "y": 29,
      "z": 4,
      "name": "Rock_Marble"
    },
    {
      "x": -9,
      "y": 30,
      "z": 4,
      "name": "Soil_Pebbles"
    },
    {
      "x": -9,
      "y": 31,
      "z": 4,
      "name": "Rock_Marble"
    },
    {
      "x": -9,
      "y": 32,
      "z": 4,
      "name": "Rock_Marble"
    },
    {
      "x": -9,
      "y": 33,
      "z": 4,
      "name": "Rock_Marble"
    },
    {
      "x": -9,
      "y": 34,
      "z": 4,
      "name": "Rock_Marble"
    },
    {
      "x": -9,
      "y": 35,
      "z": 4,
      "name": "Rock_Marble"
    },
    {
      "x": -9,
      "y": 36,
      "z": 4,
      "name": "Soil_Clay_White"
    },
    {
      "x": -9,
      "y": 37,
      "z": 4,
      "name": "Rock_Chalk"
    },
    {
      "x": -9,
      "y": 38,
      "z": 4,
      "name": "Rock_Chalk"
    },
    {
      "x": -9,
      "y": 39,
      "z": 4,
      "name": "Rock_Chalk"
    },
    {
      "x": -9,
      "y": 40,
      "z": 4,
      "name": "Rock_Chalk"
    },
    {
      "x": -9,
      "y": 41,
      "z": 4,
      "name": "Rock_Chalk"
    },
    {
      "x": -9,
      "y": 42,
      "z": 4,
      "name": "Soil_Clay_White"
    },
    {
      "x": -9,
      "y": 43,
      "z": 4,
      "name": "Soil_Clay_White"
    },
    {
      "x": -9,
      "y": 44,
      "z": 4,
      "name": "Rock_Marble"
    },
    {
      "x": -9,
      "y": 45,
      "z": 4,
      "name": "Rock_Marble"
    },
    {
      "x": -9,
      "y": 46,
      "z": 4,
      "name": "Soil_Clay_White"
    },
    {
      "x": -9,
      "y": 47,
      "z": 4,
      "name": "Soil_Clay_White"
    },
    {
      "x": -9,
      "y": 48,
      "z": 4,
      "name": "Soil_Clay_White"
    },
    {
      "x": -9,
      "y": 49,
      "z": 4,
      "name": "Soil_Clay_White"
    },
    {
      "x": -9,
      "y": 50,
      "z": 4,
      "name": "Soil_Clay_White"
    },
    {
      "x": -9,
      "y": 51,
      "z": 4,
      "name": "Rock_Marble"
    },
    {
      "x": -9,
      "y": 52,
      "z": 4,
      "name": "Rock_Marble"
    },
    {
      "x": -9,
      "y": 53,
      "z": 4,
      "name": "Rock_Marble"
    },
    {
      "x": -9,
      "y": 54,
      "z": 4,
      "name": "Soil_Clay_White"
    },
    {
      "x": -9,
      "y": 55,
      "z": 4,
      "name": "Soil_Clay_White"
    },
    {
      "x": -9,
      "y": 56,
      "z": 4,
      "name": "Soil_Clay_White"
    },
    {
      "x": -9,
      "y": 57,
      "z": 4,
      "name": "Soil_Clay_White"
    },
    {
      "x": -9,
      "y": 58,
      "z": 4,
      "name": "Soil_Clay_White"
    },
    {
      "x": -9,
      "y": 59,
      "z": 4,
      "name": "Soil_Clay_White"
    },
    {
      "x": -9,
      "y": 60,
      "z": 4,
      "name": "Soil_Clay_White"
    },
    {
      "x": -9,
      "y": 61,
      "z": 4,
      "name": "Rock_Chalk"
    },
    {
      "x": -9,
      "y": 62,
      "z": 4,
      "name": "Rock_Chalk"
    },
    {
      "x": -9,
      "y": 63,
      "z": 4,
      "name": "Soil_Clay_White"
    },
    {
      "x": -9,
      "y": 64,
      "z": 4,
      "name": "Soil_Clay_White"
    },
    {
      "x": -9,
      "y": 31,
      "z": 5,
      "name": "Rock_Marble"
    },
    {
      "x": -9,
      "y": 32,
      "z": 5,
      "name": "Rock_Marble"
    },
    {
      "x": -9,
      "y": 33,
      "z": 5,
      "name": "Rock_Marble"
    },
    {
      "x": -9,
      "y": 34,
      "z": 5,
      "name": "Rock_Marble"
    },
    {
      "x": -9,
      "y": 35,
      "z": 5,
      "name": "Rock_Marble"
    },
    {
      "x": -9,
      "y": 36,
      "z": 5,
      "name": "Soil_Clay_White"
    },
    {
      "x": -9,
      "y": 37,
      "z": 5,
      "name": "Rock_Chalk"
    },
    {
      "x": -9,
      "y": 38,
      "z": 5,
      "name": "Rock_Chalk"
    },
    {
      "x": -9,
      "y": 39,
      "z": 5,
      "name": "Rock_Chalk"
    },
    {
      "x": -9,
      "y": 40,
      "z": 5,
      "name": "Rock_Chalk"
    },
    {
      "x": -9,
      "y": 41,
      "z": 5,
      "name": "Rock_Chalk"
    },
    {
      "x": -9,
      "y": 42,
      "z": 5,
      "name": "Rock_Chalk"
    },
    {
      "x": -9,
      "y": 43,
      "z": 5,
      "name": "Soil_Clay_White"
    },
    {
      "x": -9,
      "y": 44,
      "z": 5,
      "name": "Rock_Marble"
    },
    {
      "x": -9,
      "y": 45,
      "z": 5,
      "name": "Rock_Marble"
    },
    {
      "x": -9,
      "y": 46,
      "z": 5,
      "name": "Soil_Clay_White"
    },
    {
      "x": -9,
      "y": 47,
      "z": 5,
      "name": "Soil_Clay_White"
    },
    {
      "x": -9,
      "y": 48,
      "z": 5,
      "name": "Soil_Clay_White"
    },
    {
      "x": -9,
      "y": 49,
      "z": 5,
      "name": "Soil_Clay_White"
    },
    {
      "x": -9,
      "y": 50,
      "z": 5,
      "name": "Soil_Clay_White"
    },
    {
      "x": -9,
      "y": 51,
      "z": 5,
      "name": "Rock_Marble"
    },
    {
      "x": -9,
      "y": 52,
      "z": 5,
      "name": "Rock_Marble"
    },
    {
      "x": -9,
      "y": 53,
      "z": 5,
      "name": "Rock_Marble"
    },
    {
      "x": -9,
      "y": 54,
      "z": 5,
      "name": "Soil_Clay_White"
    },
    {
      "x": -9,
      "y": 55,
      "z": 5,
      "name": "Soil_Clay_White"
    },
    {
      "x": -9,
      "y": 56,
      "z": 5,
      "name": "Soil_Clay_White"
    },
    {
      "x": -9,
      "y": 57,
      "z": 5,
      "name": "Soil_Clay_White"
    },
    {
      "x": -9,
      "y": 60,
      "z": 5,
      "name": "Soil_Clay_White"
    },
    {
      "x": -9,
      "y": 61,
      "z": 5,
      "name": "Rock_Chalk"
    },
    {
      "x": -9,
      "y": 62,
      "z": 5,
      "name": "Rock_Chalk"
    },
    {
      "x": -9,
      "y": 35,
      "z": 6,
      "name": "Rock_Marble"
    },
    {
      "x": -9,
      "y": 36,
      "z": 6,
      "name": "Soil_Clay_White"
    },
    {
      "x": -9,
      "y": 37,
      "z": 6,
      "name": "Rock_Chalk"
    },
    {
      "x": -9,
      "y": 38,
      "z": 6,
      "name": "Rock_Chalk"
    },
    {
      "x": -9,
      "y": 39,
      "z": 6,
      "name": "Rock_Chalk"
    },
    {
      "x": -9,
      "y": 40,
      "z": 6,
      "name": "Rock_Chalk"
    },
    {
      "x": -9,
      "y": 41,
      "z": 6,
      "name": "Rock_Chalk"
    },
    {
      "x": -9,
      "y": 42,
      "z": 6,
      "name": "Rock_Chalk"
    },
    {
      "x": -9,
      "y": 43,
      "z": 6,
      "name": "Soil_Clay_White"
    },
    {
      "x": -9,
      "y": 44,
      "z": 6,
      "name": "Rock_Marble"
    },
    {
      "x": -9,
      "y": 45,
      "z": 6,
      "name": "Rock_Marble"
    },
    {
      "x": -9,
      "y": 46,
      "z": 6,
      "name": "Soil_Clay_White"
    },
    {
      "x": -9,
      "y": 47,
      "z": 6,
      "name": "Soil_Clay_White"
    },
    {
      "x": -9,
      "y": 48,
      "z": 6,
      "name": "Soil_Clay_White"
    },
    {
      "x": -9,
      "y": 49,
      "z": 6,
      "name": "Soil_Clay_White"
    },
    {
      "x": -9,
      "y": 38,
      "z": 7,
      "name": "Soil_Clay_White"
    },
    {
      "x": -9,
      "y": 39,
      "z": 7,
      "name": "Rock_Chalk"
    },
    {
      "x": -9,
      "y": 40,
      "z": 7,
      "name": "Rock_Chalk"
    },
    {
      "x": -9,
      "y": 41,
      "z": 7,
      "name": "Rock_Chalk"
    },
    {
      "x": -9,
      "y": 42,
      "z": 7,
      "name": "Rock_Chalk"
    },
    {
      "x": -9,
      "y": 43,
      "z": 7,
      "name": "Soil_Clay_White"
    },
    {
      "x": -9,
      "y": 44,
      "z": 7,
      "name": "Rock_Marble"
    },
    {
      "x": -8,
      "y": 38,
      "z": -9,
      "name": "Rock_Chalk"
    },
    {
      "x": -8,
      "y": 39,
      "z": -9,
      "name": "Rock_Chalk"
    },
    {
      "x": -8,
      "y": 40,
      "z": -9,
      "name": "Rock_Chalk"
    },
    {
      "x": -8,
      "y": 41,
      "z": -9,
      "name": "Rock_Chalk"
    },
    {
      "x": -8,
      "y": 42,
      "z": -9,
      "name": "Soil_Clay_White"
    },
    {
      "x": -8,
      "y": 35,
      "z": -8,
      "name": "Rock_Marble"
    },
    {
      "x": -8,
      "y": 36,
      "z": -8,
      "name": "Soil_Clay_White"
    },
    {
      "x": -8,
      "y": 37,
      "z": -8,
      "name": "Rock_Chalk"
    },
    {
      "x": -8,
      "y": 38,
      "z": -8,
      "name": "Rock_Chalk"
    },
    {
      "x": -8,
      "y": 39,
      "z": -8,
      "name": "Rock_Chalk"
    },
    {
      "x": -8,
      "y": 40,
      "z": -8,
      "name": "Rock_Chalk"
    },
    {
      "x": -8,
      "y": 41,
      "z": -8,
      "name": "Rock_Chalk"
    },
    {
      "x": -8,
      "y": 42,
      "z": -8,
      "name": "Soil_Clay_White"
    },
    {
      "x": -8,
      "y": 43,
      "z": -8,
      "name": "Rock_Marble"
    },
    {
      "x": -8,
      "y": 44,
      "z": -8,
      "name": "Rock_Marble"
    },
    {
      "x": -8,
      "y": 45,
      "z": -8,
      "name": "Rock_Marble"
    },
    {
      "x": -8,
      "y": 46,
      "z": -8,
      "name": "Soil_Clay_White"
    },
    {
      "x": -8,
      "y": 47,
      "z": -8,
      "name": "Soil_Clay_White"
    },
    {
      "x": -8,
      "y": 48,
      "z": -8,
      "name": "Soil_Clay_White"
    },
    {
      "x": -8,
      "y": 33,
      "z": -7,
      "name": "Rock_Marble"
    },
    {
      "x": -8,
      "y": 34,
      "z": -7,
      "name": "Rock_Marble"
    },
    {
      "x": -8,
      "y": 35,
      "z": -7,
      "name": "Rock_Marble"
    },
    {
      "x": -8,
      "y": 36,
      "z": -7,
      "name": "Soil_Clay_White"
    },
    {
      "x": -8,
      "y": 37,
      "z": -7,
      "name": "Rock_Chalk"
    },
    {
      "x": -8,
      "y": 38,
      "z": -7,
      "name": "Rock_Chalk"
    },
    {
      "x": -8,
      "y": 39,
      "z": -7,
      "name": "Rock_Chalk"
    },
    {
      "x": -8,
      "y": 40,
      "z": -7,
      "name": "Rock_Chalk"
    },
    {
      "x": -8,
      "y": 41,
      "z": -7,
      "name": "Rock_Chalk"
    },
    {
      "x": -8,
      "y": 42,
      "z": -7,
      "name": "Soil_Clay_White"
    },
    {
      "x": -8,
      "y": 43,
      "z": -7,
      "name": "Rock_Marble"
    },
    {
      "x": -8,
      "y": 44,
      "z": -7,
      "name": "Rock_Marble"
    },
    {
      "x": -8,
      "y": 45,
      "z": -7,
      "name": "Rock_Marble"
    },
    {
      "x": -8,
      "y": 46,
      "z": -7,
      "name": "Soil_Clay_White"
    },
    {
      "x": -8,
      "y": 47,
      "z": -7,
      "name": "Soil_Clay_White"
    },
    {
      "x": -8,
      "y": 48,
      "z": -7,
      "name": "Soil_Clay_White"
    },
    {
      "x": -8,
      "y": 49,
      "z": -7,
      "name": "Soil_Clay_White"
    },
    {
      "x": -8,
      "y": 50,
      "z": -7,
      "name": "Soil_Clay_White"
    },
    {
      "x": -8,
      "y": 51,
      "z": -7,
      "name": "Rock_Marble"
    },
    {
      "x": -8,
      "y": 52,
      "z": -7,
      "name": "Rock_Marble"
    },
    {
      "x": -8,
      "y": 53,
      "z": -7,
      "name": "Soil_Clay_White"
    },
    {
      "x": -8,
      "y": 31,
      "z": -6,
      "name": "Rock_Marble"
    },
    {
      "x": -8,
      "y": 32,
      "z": -6,
      "name": "Rock_Marble"
    },
    {
      "x": -8,
      "y": 33,
      "z": -6,
      "name": "Rock_Marble"
    },
    {
      "x": -8,
      "y": 34,
      "z": -6,
      "name": "Rock_Marble"
    },
    {
      "x": -8,
      "y": 35,
      "z": -6,
      "name": "Rock_Marble"
    },
    {
      "x": -8,
      "y": 36,
      "z": -6,
      "name": "Soil_Clay_White"
    },
    {
      "x": -8,
      "y": 37,
      "z": -6,
      "name": "Rock_Chalk"
    },
    {
      "x": -8,
      "y": 38,
      "z": -6,
      "name": "Rock_Chalk"
    },
    {
      "x": -8,
      "y": 39,
      "z": -6,
      "name": "Rock_Chalk"
    },
    {
      "x": -8,
      "y": 40,
      "z": -6,
      "name": "Rock_Chalk"
    },
    {
      "x": -8,
      "y": 41,
      "z": -6,
      "name": "Rock_Chalk"
    },
    {
      "x": -8,
      "y": 42,
      "z": -6,
      "name": "Soil_Clay_White"
    },
    {
      "x": -8,
      "y": 43,
      "z": -6,
      "name": "Rock_Marble"
    },
    {
      "x": -8,
      "y": 44,
      "z": -6,
      "name": "Rock_Marble"
    },
    {
      "x": -8,
      "y": 45,
      "z": -6,
      "name": "Rock_Marble"
    },
    {
      "x": -8,
      "y": 46,
      "z": -6,
      "name": "Soil_Clay_White"
    },
    {
      "x": -8,
      "y": 47,
      "z": -6,
      "name": "Soil_Clay_White"
    },
    {
      "x": -8,
      "y": 48,
      "z": -6,
      "name": "Soil_Clay_White"
    },
    {
      "x": -8,
      "y": 49,
      "z": -6,
      "name": "Soil_Clay_White"
    },
    {
      "x": -8,
      "y": 50,
      "z": -6,
      "name": "Soil_Clay_White"
    },
    {
      "x": -8,
      "y": 51,
      "z": -6,
      "name": "Rock_Marble"
    },
    {
      "x": -8,
      "y": 52,
      "z": -6,
      "name": "Rock_Marble"
    },
    {
      "x": -8,
      "y": 53,
      "z": -6,
      "name": "Soil_Clay_White"
    },
    {
      "x": -8,
      "y": 54,
      "z": -6,
      "name": "Soil_Clay_White"
    },
    {
      "x": -8,
      "y": 55,
      "z": -6,
      "name": "Soil_Clay_White"
    },
    {
      "x": -8,
      "y": 56,
      "z": -6,
      "name": "Soil_Clay_White"
    },
    {
      "x": -8,
      "y": 57,
      "z": -6,
      "name": "Soil_Clay_White"
    },
    {
      "x": -8,
      "y": 28,
      "z": -5,
      "name": "Rock_Marble"
    },
    {
      "x": -8,
      "y": 29,
      "z": -5,
      "name": "Rock_Marble"
    },
    {
      "x": -8,
      "y": 30,
      "z": -5,
      "name": "Soil_Pebbles"
    },
    {
      "x": -8,
      "y": 31,
      "z": -5,
      "name": "Rock_Marble"
    },
    {
      "x": -8,
      "y": 32,
      "z": -5,
      "name": "Rock_Marble"
    },
    {
      "x": -8,
      "y": 33,
      "z": -5,
      "name": "Rock_Marble"
    },
    {
      "x": -8,
      "y": 34,
      "z": -5,
      "name": "Rock_Marble"
    },
    {
      "x": -8,
      "y": 35,
      "z": -5,
      "name": "Rock_Marble"
    },
    {
      "x": -8,
      "y": 36,
      "z": -5,
      "name": "Soil_Clay_White"
    },
    {
      "x": -8,
      "y": 37,
      "z": -5,
      "name": "Rock_Chalk"
    },
    {
      "x": -8,
      "y": 38,
      "z": -5,
      "name": "Rock_Chalk"
    },
    {
      "x": -8,
      "y": 39,
      "z": -5,
      "name": "Rock_Chalk"
    },
    {
      "x": -8,
      "y": 40,
      "z": -5,
      "name": "Rock_Chalk"
    },
    {
      "x": -8,
      "y": 41,
      "z": -5,
      "name": "Rock_Chalk"
    },
    {
      "x": -8,
      "y": 42,
      "z": -5,
      "name": "Soil_Clay_White"
    },
    {
      "x": -8,
      "y": 43,
      "z": -5,
      "name": "Rock_Marble"
    },
    {
      "x": -8,
      "y": 44,
      "z": -5,
      "name": "Rock_Marble"
    },
    {
      "x": -8,
      "y": 45,
      "z": -5,
      "name": "Rock_Marble"
    },
    {
      "x": -8,
      "y": 46,
      "z": -5,
      "name": "Soil_Clay_White"
    },
    {
      "x": -8,
      "y": 47,
      "z": -5,
      "name": "Soil_Clay_White"
    },
    {
      "x": -8,
      "y": 48,
      "z": -5,
      "name": "Soil_Clay_White"
    },
    {
      "x": -8,
      "y": 49,
      "z": -5,
      "name": "Soil_Clay_White"
    },
    {
      "x": -8,
      "y": 50,
      "z": -5,
      "name": "Soil_Clay_White"
    },
    {
      "x": -8,
      "y": 51,
      "z": -5,
      "name": "Rock_Marble"
    },
    {
      "x": -8,
      "y": 52,
      "z": -5,
      "name": "Rock_Marble"
    },
    {
      "x": -8,
      "y": 53,
      "z": -5,
      "name": "Soil_Clay_White"
    },
    {
      "x": -8,
      "y": 54,
      "z": -5,
      "name": "Soil_Clay_White"
    },
    {
      "x": -8,
      "y": 55,
      "z": -5,
      "name": "Soil_Clay_White"
    },
    {
      "x": -8,
      "y": 56,
      "z": -5,
      "name": "Soil_Clay_White"
    },
    {
      "x": -8,
      "y": 57,
      "z": -5,
      "name": "Soil_Clay_White"
    },
    {
      "x": -8,
      "y": 58,
      "z": -5,
      "name": "Soil_Clay_White"
    },
    {
      "x": -8,
      "y": 59,
      "z": -5,
      "name": "Soil_Clay_White"
    },
    {
      "x": -8,
      "y": 60,
      "z": -5,
      "name": "Soil_Clay_White"
    },
    {
      "x": -8,
      "y": 61,
      "z": -5,
      "name": "Rock_Chalk"
    },
    {
      "x": -8,
      "y": 62,
      "z": -5,
      "name": "Rock_Chalk"
    },
    {
      "x": -8,
      "y": 25,
      "z": -4,
      "name": "Soil_Clay_White"
    },
    {
      "x": -8,
      "y": 26,
      "z": -4,
      "name": "Rock_Marble"
    },
    {
      "x": -8,
      "y": 27,
      "z": -4,
      "name": "Rock_Marble"
    },
    {
      "x": -8,
      "y": 28,
      "z": -4,
      "name": "Rock_Marble"
    },
    {
      "x": -8,
      "y": 29,
      "z": -4,
      "name": "Rock_Marble"
    },
    {
      "x": -8,
      "y": 30,
      "z": -4,
      "name": "Soil_Pebbles"
    },
    {
      "x": -8,
      "y": 31,
      "z": -4,
      "name": "Rock_Marble"
    },
    {
      "x": -8,
      "y": 32,
      "z": -4,
      "name": "Rock_Marble"
    },
    {
      "x": -8,
      "y": 33,
      "z": -4,
      "name": "Rock_Marble"
    },
    {
      "x": -8,
      "y": 34,
      "z": -4,
      "name": "Rock_Marble"
    },
    {
      "x": -8,
      "y": 35,
      "z": -4,
      "name": "Rock_Marble"
    },
    {
      "x": -8,
      "y": 36,
      "z": -4,
      "name": "Soil_Clay_White"
    },
    {
      "x": -8,
      "y": 37,
      "z": -4,
      "name": "Rock_Chalk"
    },
    {
      "x": -8,
      "y": 38,
      "z": -4,
      "name": "Rock_Chalk"
    },
    {
      "x": -8,
      "y": 39,
      "z": -4,
      "name": "Rock_Chalk"
    },
    {
      "x": -8,
      "y": 40,
      "z": -4,
      "name": "Rock_Chalk"
    },
    {
      "x": -8,
      "y": 41,
      "z": -4,
      "name": "Rock_Chalk"
    },
    {
      "x": -8,
      "y": 42,
      "z": -4,
      "name": "Soil_Clay_White"
    },
    {
      "x": -8,
      "y": 43,
      "z": -4,
      "name": "Rock_Marble"
    },
    {
      "x": -8,
      "y": 44,
      "z": -4,
      "name": "Rock_Marble"
    },
    {
      "x": -8,
      "y": 45,
      "z": -4,
      "name": "Rock_Marble"
    },
    {
      "x": -8,
      "y": 46,
      "z": -4,
      "name": "Soil_Clay_White"
    },
    {
      "x": -8,
      "y": 47,
      "z": -4,
      "name": "Soil_Clay_White"
    },
    {
      "x": -8,
      "y": 48,
      "z": -4,
      "name": "Soil_Clay_White"
    },
    {
      "x": -8,
      "y": 49,
      "z": -4,
      "name": "Soil_Clay_White"
    },
    {
      "x": -8,
      "y": 50,
      "z": -4,
      "name": "Soil_Clay_White"
    },
    {
      "x": -8,
      "y": 51,
      "z": -4,
      "name": "Rock_Marble"
    },
    {
      "x": -8,
      "y": 52,
      "z": -4,
      "name": "Rock_Marble"
    },
    {
      "x": -8,
      "y": 53,
      "z": -4,
      "name": "Soil_Clay_White"
    },
    {
      "x": -8,
      "y": 54,
      "z": -4,
      "name": "Soil_Clay_White"
    },
    {
      "x": -8,
      "y": 55,
      "z": -4,
      "name": "Soil_Clay_White"
    },
    {
      "x": -8,
      "y": 56,
      "z": -4,
      "name": "Soil_Clay_White"
    },
    {
      "x": -8,
      "y": 57,
      "z": -4,
      "name": "Soil_Clay_White"
    },
    {
      "x": -8,
      "y": 58,
      "z": -4,
      "name": "Soil_Clay_White"
    },
    {
      "x": -8,
      "y": 59,
      "z": -4,
      "name": "Soil_Clay_White"
    },
    {
      "x": -8,
      "y": 60,
      "z": -4,
      "name": "Soil_Clay_White"
    },
    {
      "x": -8,
      "y": 61,
      "z": -4,
      "name": "Rock_Chalk"
    },
    {
      "x": -8,
      "y": 62,
      "z": -4,
      "name": "Rock_Chalk"
    },
    {
      "x": -8,
      "y": 63,
      "z": -4,
      "name": "Soil_Clay_White"
    },
    {
      "x": -8,
      "y": 64,
      "z": -4,
      "name": "Soil_Clay_White"
    },
    {
      "x": -8,
      "y": 65,
      "z": -4,
      "name": "Rock_Chalk"
    },
    {
      "x": -8,
      "y": 23,
      "z": -3,
      "name": "Rock_Chalk"
    },
    {
      "x": -8,
      "y": 24,
      "z": -3,
      "name": "Soil_Clay_White"
    },
    {
      "x": -8,
      "y": 25,
      "z": -3,
      "name": "Soil_Clay_White"
    },
    {
      "x": -8,
      "y": 26,
      "z": -3,
      "name": "Rock_Marble"
    },
    {
      "x": -8,
      "y": 27,
      "z": -3,
      "name": "Rock_Marble"
    },
    {
      "x": -8,
      "y": 28,
      "z": -3,
      "name": "Rock_Marble"
    },
    {
      "x": -8,
      "y": 29,
      "z": -3,
      "name": "Rock_Marble"
    },
    {
      "x": -8,
      "y": 30,
      "z": -3,
      "name": "Soil_Pebbles"
    },
    {
      "x": -8,
      "y": 31,
      "z": -3,
      "name": "Rock_Marble"
    },
    {
      "x": -8,
      "y": 32,
      "z": -3,
      "name": "Rock_Marble"
    },
    {
      "x": -8,
      "y": 33,
      "z": -3,
      "name": "Rock_Marble"
    },
    {
      "x": -8,
      "y": 34,
      "z": -3,
      "name": "Rock_Marble"
    },
    {
      "x": -8,
      "y": 35,
      "z": -3,
      "name": "Rock_Marble"
    },
    {
      "x": -8,
      "y": 36,
      "z": -3,
      "name": "Soil_Clay_White"
    },
    {
      "x": -8,
      "y": 37,
      "z": -3,
      "name": "Rock_Chalk"
    },
    {
      "x": -8,
      "y": 38,
      "z": -3,
      "name": "Rock_Chalk"
    },
    {
      "x": -8,
      "y": 39,
      "z": -3,
      "name": "Rock_Chalk"
    },
    {
      "x": -8,
      "y": 40,
      "z": -3,
      "name": "Rock_Chalk"
    },
    {
      "x": -8,
      "y": 41,
      "z": -3,
      "name": "Rock_Chalk"
    },
    {
      "x": -8,
      "y": 42,
      "z": -3,
      "name": "Soil_Clay_White"
    },
    {
      "x": -8,
      "y": 43,
      "z": -3,
      "name": "Rock_Marble"
    },
    {
      "x": -8,
      "y": 44,
      "z": -3,
      "name": "Rock_Marble"
    },
    {
      "x": -8,
      "y": 45,
      "z": -3,
      "name": "Rock_Marble"
    },
    {
      "x": -8,
      "y": 46,
      "z": -3,
      "name": "Soil_Clay_White"
    },
    {
      "x": -8,
      "y": 47,
      "z": -3,
      "name": "Soil_Clay_White"
    },
    {
      "x": -8,
      "y": 48,
      "z": -3,
      "name": "Soil_Clay_White"
    },
    {
      "x": -8,
      "y": 49,
      "z": -3,
      "name": "Soil_Clay_White"
    },
    {
      "x": -8,
      "y": 50,
      "z": -3,
      "name": "Soil_Clay_White"
    },
    {
      "x": -8,
      "y": 51,
      "z": -3,
      "name": "Rock_Marble"
    },
    {
      "x": -8,
      "y": 52,
      "z": -3,
      "name": "Rock_Marble"
    },
    {
      "x": -8,
      "y": 53,
      "z": -3,
      "name": "Soil_Clay_White"
    },
    {
      "x": -8,
      "y": 54,
      "z": -3,
      "name": "Soil_Clay_White"
    },
    {
      "x": -8,
      "y": 55,
      "z": -3,
      "name": "Soil_Clay_White"
    },
    {
      "x": -8,
      "y": 56,
      "z": -3,
      "name": "Soil_Clay_White"
    },
    {
      "x": -8,
      "y": 57,
      "z": -3,
      "name": "Soil_Clay_White"
    },
    {
      "x": -8,
      "y": 58,
      "z": -3,
      "name": "Soil_Clay_White"
    },
    {
      "x": -8,
      "y": 59,
      "z": -3,
      "name": "Soil_Clay_White"
    },
    {
      "x": -8,
      "y": 60,
      "z": -3,
      "name": "Soil_Clay_White"
    },
    {
      "x": -8,
      "y": 61,
      "z": -3,
      "name": "Rock_Chalk"
    },
    {
      "x": -8,
      "y": 62,
      "z": -3,
      "name": "Rock_Chalk"
    },
    {
      "x": -8,
      "y": 63,
      "z": -3,
      "name": "Soil_Clay_White"
    },
    {
      "x": -8,
      "y": 64,
      "z": -3,
      "name": "Soil_Clay_White"
    },
    {
      "x": -8,
      "y": 65,
      "z": -3,
      "name": "Rock_Chalk"
    },
    {
      "x": -8,
      "y": 66,
      "z": -3,
      "name": "Soil_Clay_White"
    },
    {
      "x": -8,
      "y": 67,
      "z": -3,
      "name": "Rock_Marble"
    },
    {
      "x": -8,
      "y": 68,
      "z": -3,
      "name": "Rock_Marble"
    },
    {
      "x": -8,
      "y": 69,
      "z": -3,
      "name": "Rock_Marble"
    },
    {
      "x": -8,
      "y": 22,
      "z": -2,
      "name": "Rock_Chalk"
    },
    {
      "x": -8,
      "y": 23,
      "z": -2,
      "name": "Rock_Chalk"
    },
    {
      "x": -8,
      "y": 24,
      "z": -2,
      "name": "Soil_Clay_White"
    },
    {
      "x": -8,
      "y": 25,
      "z": -2,
      "name": "Soil_Clay_White"
    },
    {
      "x": -8,
      "y": 26,
      "z": -2,
      "name": "Rock_Marble"
    },
    {
      "x": -8,
      "y": 27,
      "z": -2,
      "name": "Rock_Marble"
    },
    {
      "x": -8,
      "y": 28,
      "z": -2,
      "name": "Rock_Marble"
    },
    {
      "x": -8,
      "y": 29,
      "z": -2,
      "name": "Rock_Marble"
    },
    {
      "x": -8,
      "y": 30,
      "z": -2,
      "name": "Soil_Pebbles"
    },
    {
      "x": -8,
      "y": 31,
      "z": -2,
      "name": "Rock_Marble"
    },
    {
      "x": -8,
      "y": 32,
      "z": -2,
      "name": "Rock_Marble"
    },
    {
      "x": -8,
      "y": 33,
      "z": -2,
      "name": "Rock_Marble"
    },
    {
      "x": -8,
      "y": 34,
      "z": -2,
      "name": "Rock_Marble"
    },
    {
      "x": -8,
      "y": 35,
      "z": -2,
      "name": "Rock_Marble"
    },
    {
      "x": -8,
      "y": 36,
      "z": -2,
      "name": "Soil_Clay_White"
    },
    {
      "x": -8,
      "y": 37,
      "z": -2,
      "name": "Rock_Chalk"
    },
    {
      "x": -8,
      "y": 38,
      "z": -2,
      "name": "Rock_Chalk"
    },
    {
      "x": -8,
      "y": 39,
      "z": -2,
      "name": "Rock_Chalk"
    },
    {
      "x": -8,
      "y": 40,
      "z": -2,
      "name": "Rock_Chalk"
    },
    {
      "x": -8,
      "y": 41,
      "z": -2,
      "name": "Rock_Chalk"
    },
    {
      "x": -8,
      "y": 42,
      "z": -2,
      "name": "Soil_Clay_White"
    },
    {
      "x": -8,
      "y": 43,
      "z": -2,
      "name": "Rock_Marble"
    },
    {
      "x": -8,
      "y": 44,
      "z": -2,
      "name": "Rock_Marble"
    },
    {
      "x": -8,
      "y": 45,
      "z": -2,
      "name": "Rock_Marble"
    },
    {
      "x": -8,
      "y": 46,
      "z": -2,
      "name": "Soil_Clay_White"
    },
    {
      "x": -8,
      "y": 47,
      "z": -2,
      "name": "Soil_Clay_White"
    },
    {
      "x": -8,
      "y": 48,
      "z": -2,
      "name": "Soil_Clay_White"
    },
    {
      "x": -8,
      "y": 49,
      "z": -2,
      "name": "Soil_Clay_White"
    },
    {
      "x": -8,
      "y": 50,
      "z": -2,
      "name": "Soil_Clay_White"
    },
    {
      "x": -8,
      "y": 51,
      "z": -2,
      "name": "Rock_Marble"
    },
    {
      "x": -8,
      "y": 52,
      "z": -2,
      "name": "Rock_Marble"
    },
    {
      "x": -8,
      "y": 53,
      "z": -2,
      "name": "Soil_Clay_White"
    },
    {
      "x": -8,
      "y": 54,
      "z": -2,
      "name": "Soil_Clay_White"
    },
    {
      "x": -8,
      "y": 55,
      "z": -2,
      "name": "Soil_Clay_White"
    },
    {
      "x": -8,
      "y": 56,
      "z": -2,
      "name": "Soil_Clay_White"
    },
    {
      "x": -8,
      "y": 57,
      "z": -2,
      "name": "Soil_Clay_White"
    },
    {
      "x": -8,
      "y": 58,
      "z": -2,
      "name": "Soil_Clay_White"
    },
    {
      "x": -8,
      "y": 59,
      "z": -2,
      "name": "Soil_Clay_White"
    },
    {
      "x": -8,
      "y": 60,
      "z": -2,
      "name": "Soil_Clay_White"
    },
    {
      "x": -8,
      "y": 61,
      "z": -2,
      "name": "Rock_Chalk"
    },
    {
      "x": -8,
      "y": 62,
      "z": -2,
      "name": "Rock_Chalk"
    },
    {
      "x": -8,
      "y": 63,
      "z": -2,
      "name": "Soil_Clay_White"
    },
    {
      "x": -8,
      "y": 64,
      "z": -2,
      "name": "Soil_Clay_White"
    },
    {
      "x": -8,
      "y": 65,
      "z": -2,
      "name": "Rock_Chalk"
    },
    {
      "x": -8,
      "y": 66,
      "z": -2,
      "name": "Soil_Clay_White"
    },
    {
      "x": -8,
      "y": 67,
      "z": -2,
      "name": "Rock_Marble"
    },
    {
      "x": -8,
      "y": 68,
      "z": -2,
      "name": "Rock_Marble"
    },
    {
      "x": -8,
      "y": 69,
      "z": -2,
      "name": "Rock_Marble"
    },
    {
      "x": -8,
      "y": 70,
      "z": -2,
      "name": "Soil_Pebbles"
    },
    {
      "x": -8,
      "y": 71,
      "z": -2,
      "name": "Soil_Pebbles"
    },
    {
      "x": -8,
      "y": 72,
      "z": -2,
      "name": "Soil_Pebbles"
    },
    {
      "x": -8,
      "y": 73,
      "z": -2,
      "name": "Rock_Marble"
    },
    {
      "x": -8,
      "y": 74,
      "z": -2,
      "name": "Soil_Clay_White"
    },
    {
      "x": -8,
      "y": 75,
      "z": -2,
      "name": "Soil_Clay_White"
    },
    {
      "x": -8,
      "y": 76,
      "z": -2,
      "name": "Soil_Clay_White"
    },
    {
      "x": -8,
      "y": 77,
      "z": -2,
      "name": "Rock_Marble"
    },
    {
      "x": -8,
      "y": 78,
      "z": -2,
      "name": "Soil_Clay_White"
    },
    {
      "x": -8,
      "y": 79,
      "z": -2,
      "name": "Soil_Clay_White"
    },
    {
      "x": -8,
      "y": 80,
      "z": -2,
      "name": "Soil_Clay_White"
    },
    {
      "x": -8,
      "y": 81,
      "z": -2,
      "name": "Soil_Clay_White"
    },
    {
      "x": -8,
      "y": 82,
      "z": -2,
      "name": "Soil_Clay_White"
    },
    {
      "x": -8,
      "y": 21,
      "z": -1,
      "name": "Rock_Chalk"
    },
    {
      "x": -8,
      "y": 22,
      "z": -1,
      "name": "Rock_Chalk"
    },
    {
      "x": -8,
      "y": 23,
      "z": -1,
      "name": "Rock_Chalk"
    },
    {
      "x": -8,
      "y": 24,
      "z": -1,
      "name": "Soil_Clay_White"
    },
    {
      "x": -8,
      "y": 25,
      "z": -1,
      "name": "Soil_Clay_White"
    },
    {
      "x": -8,
      "y": 26,
      "z": -1,
      "name": "Rock_Marble"
    },
    {
      "x": -8,
      "y": 27,
      "z": -1,
      "name": "Rock_Marble"
    },
    {
      "x": -8,
      "y": 28,
      "z": -1,
      "name": "Rock_Marble"
    },
    {
      "x": -8,
      "y": 29,
      "z": -1,
      "name": "Rock_Marble"
    },
    {
      "x": -8,
      "y": 30,
      "z": -1,
      "name": "Soil_Pebbles"
    },
    {
      "x": -8,
      "y": 31,
      "z": -1,
      "name": "Rock_Marble"
    },
    {
      "x": -8,
      "y": 32,
      "z": -1,
      "name": "Rock_Marble"
    },
    {
      "x": -8,
      "y": 33,
      "z": -1,
      "name": "Rock_Marble"
    },
    {
      "x": -8,
      "y": 34,
      "z": -1,
      "name": "Rock_Marble"
    },
    {
      "x": -8,
      "y": 35,
      "z": -1,
      "name": "Rock_Marble"
    },
    {
      "x": -8,
      "y": 36,
      "z": -1,
      "name": "Soil_Clay_White"
    },
    {
      "x": -8,
      "y": 37,
      "z": -1,
      "name": "Rock_Chalk"
    },
    {
      "x": -8,
      "y": 38,
      "z": -1,
      "name": "Rock_Chalk"
    },
    {
      "x": -8,
      "y": 39,
      "z": -1,
      "name": "Rock_Chalk"
    },
    {
      "x": -8,
      "y": 40,
      "z": -1,
      "name": "Rock_Chalk"
    },
    {
      "x": -8,
      "y": 41,
      "z": -1,
      "name": "Rock_Chalk"
    },
    {
      "x": -8,
      "y": 42,
      "z": -1,
      "name": "Soil_Clay_White"
    },
    {
      "x": -8,
      "y": 43,
      "z": -1,
      "name": "Rock_Marble"
    },
    {
      "x": -8,
      "y": 44,
      "z": -1,
      "name": "Rock_Marble"
    },
    {
      "x": -8,
      "y": 45,
      "z": -1,
      "name": "Rock_Marble"
    },
    {
      "x": -8,
      "y": 46,
      "z": -1,
      "name": "Soil_Clay_White"
    },
    {
      "x": -8,
      "y": 47,
      "z": -1,
      "name": "Soil_Clay_White"
    },
    {
      "x": -8,
      "y": 48,
      "z": -1,
      "name": "Soil_Clay_White"
    },
    {
      "x": -8,
      "y": 49,
      "z": -1,
      "name": "Soil_Clay_White"
    },
    {
      "x": -8,
      "y": 50,
      "z": -1,
      "name": "Soil_Clay_White"
    },
    {
      "x": -8,
      "y": 51,
      "z": -1,
      "name": "Rock_Marble"
    },
    {
      "x": -8,
      "y": 52,
      "z": -1,
      "name": "Rock_Marble"
    },
    {
      "x": -8,
      "y": 53,
      "z": -1,
      "name": "Soil_Clay_White"
    },
    {
      "x": -8,
      "y": 54,
      "z": -1,
      "name": "Soil_Clay_White"
    },
    {
      "x": -8,
      "y": 55,
      "z": -1,
      "name": "Soil_Clay_White"
    },
    {
      "x": -8,
      "y": 56,
      "z": -1,
      "name": "Soil_Clay_White"
    },
    {
      "x": -8,
      "y": 57,
      "z": -1,
      "name": "Soil_Clay_White"
    },
    {
      "x": -8,
      "y": 58,
      "z": -1,
      "name": "Soil_Clay_White"
    },
    {
      "x": -8,
      "y": 59,
      "z": -1,
      "name": "Soil_Clay_White"
    },
    {
      "x": -8,
      "y": 60,
      "z": -1,
      "name": "Soil_Clay_White"
    },
    {
      "x": -8,
      "y": 61,
      "z": -1,
      "name": "Rock_Chalk"
    },
    {
      "x": -8,
      "y": 62,
      "z": -1,
      "name": "Rock_Chalk"
    },
    {
      "x": -8,
      "y": 63,
      "z": -1,
      "name": "Soil_Clay_White"
    },
    {
      "x": -8,
      "y": 64,
      "z": -1,
      "name": "Soil_Clay_White"
    },
    {
      "x": -8,
      "y": 65,
      "z": -1,
      "name": "Rock_Chalk"
    },
    {
      "x": -8,
      "y": 66,
      "z": -1,
      "name": "Soil_Clay_White"
    },
    {
      "x": -8,
      "y": 67,
      "z": -1,
      "name": "Rock_Marble"
    },
    {
      "x": -8,
      "y": 68,
      "z": -1,
      "name": "Rock_Marble"
    },
    {
      "x": -8,
      "y": 69,
      "z": -1,
      "name": "Rock_Marble"
    },
    {
      "x": -8,
      "y": 70,
      "z": -1,
      "name": "Soil_Pebbles"
    },
    {
      "x": -8,
      "y": 71,
      "z": -1,
      "name": "Soil_Pebbles"
    },
    {
      "x": -8,
      "y": 72,
      "z": -1,
      "name": "Soil_Pebbles"
    },
    {
      "x": -8,
      "y": 73,
      "z": -1,
      "name": "Rock_Marble"
    },
    {
      "x": -8,
      "y": 74,
      "z": -1,
      "name": "Soil_Clay_White"
    },
    {
      "x": -8,
      "y": 75,
      "z": -1,
      "name": "Soil_Clay_White"
    },
    {
      "x": -8,
      "y": 76,
      "z": -1,
      "name": "Soil_Clay_White"
    },
    {
      "x": -8,
      "y": 77,
      "z": -1,
      "name": "Rock_Marble"
    },
    {
      "x": -8,
      "y": 78,
      "z": -1,
      "name": "Soil_Clay_White"
    },
    {
      "x": -8,
      "y": 79,
      "z": -1,
      "name": "Soil_Clay_White"
    },
    {
      "x": -8,
      "y": 80,
      "z": -1,
      "name": "Soil_Clay_White"
    },
    {
      "x": -8,
      "y": 81,
      "z": -1,
      "name": "Soil_Clay_White"
    },
    {
      "x": -8,
      "y": 82,
      "z": -1,
      "name": "Soil_Clay_White"
    },
    {
      "x": -8,
      "y": 83,
      "z": -1,
      "name": "Rock_Chalk"
    },
    {
      "x": -8,
      "y": 84,
      "z": -1,
      "name": "Soil_Clay_White"
    },
    {
      "x": -8,
      "y": 21,
      "z": 0,
      "name": "Rock_Chalk"
    },
    {
      "x": -8,
      "y": 22,
      "z": 0,
      "name": "Rock_Chalk"
    },
    {
      "x": -8,
      "y": 23,
      "z": 0,
      "name": "Rock_Chalk"
    },
    {
      "x": -8,
      "y": 24,
      "z": 0,
      "name": "Soil_Clay_White"
    },
    {
      "x": -8,
      "y": 25,
      "z": 0,
      "name": "Soil_Clay_White"
    },
    {
      "x": -8,
      "y": 26,
      "z": 0,
      "name": "Rock_Marble"
    },
    {
      "x": -8,
      "y": 27,
      "z": 0,
      "name": "Rock_Marble"
    },
    {
      "x": -8,
      "y": 28,
      "z": 0,
      "name": "Rock_Marble"
    },
    {
      "x": -8,
      "y": 29,
      "z": 0,
      "name": "Rock_Marble"
    },
    {
      "x": -8,
      "y": 30,
      "z": 0,
      "name": "Soil_Pebbles"
    },
    {
      "x": -8,
      "y": 31,
      "z": 0,
      "name": "Rock_Marble"
    },
    {
      "x": -8,
      "y": 32,
      "z": 0,
      "name": "Rock_Marble"
    },
    {
      "x": -8,
      "y": 33,
      "z": 0,
      "name": "Rock_Marble"
    },
    {
      "x": -8,
      "y": 34,
      "z": 0,
      "name": "Rock_Marble"
    },
    {
      "x": -8,
      "y": 35,
      "z": 0,
      "name": "Rock_Marble"
    },
    {
      "x": -8,
      "y": 36,
      "z": 0,
      "name": "Soil_Clay_White"
    },
    {
      "x": -8,
      "y": 37,
      "z": 0,
      "name": "Rock_Chalk"
    },
    {
      "x": -8,
      "y": 38,
      "z": 0,
      "name": "Rock_Chalk"
    },
    {
      "x": -8,
      "y": 39,
      "z": 0,
      "name": "Rock_Chalk"
    },
    {
      "x": -8,
      "y": 40,
      "z": 0,
      "name": "Rock_Chalk"
    },
    {
      "x": -8,
      "y": 41,
      "z": 0,
      "name": "Rock_Chalk"
    },
    {
      "x": -8,
      "y": 42,
      "z": 0,
      "name": "Soil_Clay_White"
    },
    {
      "x": -8,
      "y": 43,
      "z": 0,
      "name": "Rock_Marble"
    },
    {
      "x": -8,
      "y": 44,
      "z": 0,
      "name": "Rock_Marble"
    },
    {
      "x": -8,
      "y": 45,
      "z": 0,
      "name": "Rock_Marble"
    },
    {
      "x": -8,
      "y": 46,
      "z": 0,
      "name": "Soil_Clay_White"
    },
    {
      "x": -8,
      "y": 47,
      "z": 0,
      "name": "Soil_Clay_White"
    },
    {
      "x": -8,
      "y": 48,
      "z": 0,
      "name": "Soil_Clay_White"
    },
    {
      "x": -8,
      "y": 49,
      "z": 0,
      "name": "Soil_Clay_White"
    },
    {
      "x": -8,
      "y": 50,
      "z": 0,
      "name": "Soil_Clay_White"
    },
    {
      "x": -8,
      "y": 51,
      "z": 0,
      "name": "Rock_Marble"
    },
    {
      "x": -8,
      "y": 52,
      "z": 0,
      "name": "Rock_Marble"
    },
    {
      "x": -8,
      "y": 53,
      "z": 0,
      "name": "Soil_Clay_White"
    },
    {
      "x": -8,
      "y": 54,
      "z": 0,
      "name": "Soil_Clay_White"
    },
    {
      "x": -8,
      "y": 55,
      "z": 0,
