{
  "version": 8,
  "blockIdVersion": 11,
  "anchorX": 0,
  "anchorY": 0,
  "anchorZ": 0,
  "blocks": [
    {
      "x": -13,
      "y": 53,
      "z": -5,
      "name": "Rock_Marble"
    },
    {
      "x": -13,
      "y": 54,
      "z": -5,
      "name": "Soil_Pebbles"
    },
    {
      "x": -13,
      "y": 55,
      "z": -5,
      "name": "Soil_Pebbles"
    },
    {
      "x": -13,
      "y": 56,
      "z": -5,
      "name": "Rock_Marble"
    },
    {
      "x": -13,
      "y": 57,
      "z": -5,
      "name": "Rock_Marble"
    },
    {
      "x": -13,
      "y": 58,
      "z": -5,
      "name": "Soil_Clay_White"
    },
    {
      "x": -13,
      "y": 59,
      "z": -5,
      "name": "Soil_Clay_White"
    },
    {
      "x": -13,
      "y": 60,
      "z": -5,
      "name": "Soil_Clay_White"
    },
    {
      "x": -13,
      "y": 50,
      "z": -4,
      "name": "Soil_Clay_White"
    },
    {
      "x": -13,
      "y": 51,
      "z": -4,
      "name": "Rock_Marble"
    },
    {
      "x": -13,
      "y": 52,
      "z": -4,
      "name": "Rock_Marble"
    },
    {
      "x": -13,
      "y": 53,
      "z": -4,
      "name": "Rock_Marble"
    },
    {
      "x": -13,
      "y": 54,
      "z": -4,
      "name": "Soil_Pebbles"
    },
    {
      "x": -13,
      "y": 55,
      "z": -4,
      "name": "Soil_Pebbles"
    },
    {
      "x": -13,
      "y": 56,
      "z": -4,
      "name": "Rock_Marble"
    },
    {
      "x": -13,
      "y": 57,
      "z": -4,
      "name": "Rock_Marble"
    },
    {
      "x": -13,
      "y": 58,
      "z": -4,
      "name": "Soil_Clay_White"
    },
    {
      "x": -13,
      "y": 59,
      "z": -4,
      "name": "Soil_Clay_White"
    },
    {
      "x": -13,
      "y": 60,
      "z": -4,
      "name": "Soil_Clay_White"
    },
    {
      "x": -13,
      "y": 48,
      "z": -3,
      "name": "Rock_Chalk"
    },
    {
      "x": -13,
      "y": 49,
      "z": -3,
      "name": "Rock_Chalk"
    },
    {
      "x": -13,
      "y": 50,
      "z": -3,
      "name": "Soil_Clay_White"
    },
    {
      "x": -13,
      "y": 51,
      "z": -3,
      "name": "Rock_Marble"
    },
    {
      "x": -13,
      "y": 52,
      "z": -3,
      "name": "Rock_Marble"
    },
    {
      "x": -13,
      "y": 53,
      "z": -3,
      "name": "Rock_Marble"
    },
    {
      "x": -13,
      "y": 54,
      "z": -3,
      "name": "Soil_Pebbles"
    },
    {
      "x": -13,
      "y": 55,
      "z": -3,
      "name": "Soil_Pebbles"
    },
    {
      "x": -13,
      "y": 56,
      "z": -3,
      "name": "Rock_Marble"
    },
    {
      "x": -13,
      "y": 57,
      "z": -3,
      "name": "Rock_Marble"
    },
    {
      "x": -13,
      "y": 58,
      "z": -3,
      "name": "Soil_Clay_White"
    },
    {
      "x": -13,
      "y": 59,
      "z": -3,
      "name": "Soil_Clay_White"
    },
    {
      "x": -13,
      "y": 60,
      "z": -3,
      "name": "Soil_Clay_White"
    },
    {
      "x": -13,
      "y": 47,
      "z": -2,
      "name": "Soil_Clay_White"
    },
    {
      "x": -13,
      "y": 48,
      "z": -2,
      "name": "Rock_Chalk"
    },
    {
      "x": -13,
      "y": 49,
      "z": -2,
      "name": "Rock_Chalk"
    },
    {
      "x": -13,
      "y": 50,
      "z": -2,
      "name": "Soil_Clay_White"
    },
    {
      "x": -13,
      "y": 51,
      "z": -2,
      "name": "Rock_Marble"
    },
    {
      "x": -13,
      "y": 52,
      "z": -2,
      "name": "Rock_Marble"
    },
    {
      "x": -13,
      "y": 53,
      "z": -2,
      "name": "Rock_Marble"
    },
    {
      "x": -13,
      "y": 54,
      "z": -2,
      "name": "Soil_Pebbles"
    },
    {
      "x": -13,
      "y": 55,
      "z": -2,
      "name": "Soil_Pebbles"
    },
    {
      "x": -13,
      "y": 56,
      "z": -2,
      "name": "Rock_Marble"
    },
    {
      "x": -13,
      "y": 57,
      "z": -2,
      "name": "Rock_Marble"
    },
    {
      "x": -13,
      "y": 58,
      "z": -2,
      "name": "Soil_Clay_White"
    },
    {
      "x": -13,
      "y": 59,
      "z": -2,
      "name": "Soil_Clay_White"
    },
    {
      "x": -13,
      "y": 60,
      "z": -2,
      "name": "Soil_Clay_White"
    },
    {
      "x": -13,
      "y": 47,
      "z": -1,
      "name": "Soil_Clay_White"
    },
    {
      "x": -13,
      "y": 48,
      "z": -1,
      "name": "Rock_Chalk"
    },
    {
      "x": -13,
      "y": 49,
      "z": -1,
      "name": "Rock_Chalk"
    },
    {
      "x": -13,
      "y": 50,
      "z": -1,
      "name": "Soil_Clay_White"
    },
    {
      "x": -13,
      "y": 51,
      "z": -1,
      "name": "Rock_Marble"
    },
    {
      "x": -13,
      "y": 52,
      "z": -1,
      "name": "Rock_Marble"
    },
    {
      "x": -13,
      "y": 53,
      "z": -1,
      "name": "Rock_Marble"
    },
    {
      "x": -13,
      "y": 54,
      "z": -1,
      "name": "Soil_Pebbles"
    },
    {
      "x": -13,
      "y": 55,
      "z": -1,
      "name": "Soil_Pebbles"
    },
    {
      "x": -13,
      "y": 56,
      "z": -1,
      "name": "Rock_Marble"
    },
    {
      "x": -13,
      "y": 57,
      "z": -1,
      "name": "Rock_Marble"
    },
    {
      "x": -13,
      "y": 58,
      "z": -1,
      "name": "Soil_Clay_White"
    },
    {
      "x": -13,
      "y": 59,
      "z": -1,
      "name": "Soil_Clay_White"
    },
    {
      "x": -13,
      "y": 60,
      "z": -1,
      "name": "Soil_Clay_White"
    },
    {
      "x": -13,
      "y": 47,
      "z": 0,
      "name": "Soil_Clay_White"
    },
    {
      "x": -13,
      "y": 48,
      "z": 0,
      "name": "Rock_Chalk"
    },
    {
      "x": -13,
      "y": 49,
      "z": 0,
      "name": "Rock_Chalk"
    },
    {
      "x": -13,
      "y": 50,
      "z": 0,
      "name": "Soil_Clay_White"
    },
    {
      "x": -13,
      "y": 51,
      "z": 0,
      "name": "Rock_Marble"
    },
    {
      "x": -13,
      "y": 52,
      "z": 0,
      "name": "Rock_Marble"
    },
    {
      "x": -13,
      "y": 53,
      "z": 0,
      "name": "Rock_Marble"
    },
    {
      "x": -13,
      "y": 54,
      "z": 0,
      "name": "Soil_Pebbles"
    },
    {
      "x": -13,
      "y": 55,
      "z": 0,
      "name": "Soil_Pebbles"
    },
    {
      "x": -13,
      "y": 56,
      "z": 0,
      "name": "Rock_Marble"
    },
    {
      "x": -13,
      "y": 57,
      "z": 0,
      "name": "Rock_Marble"
    },
    {
      "x": -13,
      "y": 58,
      "z": 0,
      "name": "Soil_Clay_White"
    },
    {
      "x": -13,
      "y": 59,
      "z": 0,
      "name": "Soil_Clay_White"
    },
    {
      "x": -13,
      "y": 60,
      "z": 0,
      "name": "Soil_Clay_White"
    },
    {
      "x": -13,
      "y": 48,
      "z": 1,
      "name": "Rock_Chalk"
    },
    {
      "x": -13,
      "y": 49,
      "z": 1,
      "name": "Rock_Chalk"
    },
    {
      "x": -13,
      "y": 50,
      "z": 1,
      "name": "Soil_Clay_White"
    },
    {
      "x": -13,
      "y": 51,
      "z": 1,
      "name": "Rock_Marble"
    },
    {
      "x": -13,
      "y": 52,
      "z": 1,
      "name": "Rock_Marble"
    },
    {
      "x": -13,
      "y": 53,
      "z": 1,
      "name": "Rock_Marble"
    },
    {
      "x": -13,
      "y": 54,
      "z": 1,
      "name": "Soil_Pebbles"
    },
    {
      "x": -13,
      "y": 55,
      "z": 1,
      "name": "Soil_Pebbles"
    },
    {
      "x": -13,
      "y": 56,
      "z": 1,
      "name": "Rock_Marble"
    },
    {
      "x": -13,
      "y": 57,
      "z": 1,
      "name": "Rock_Marble"
    },
    {
      "x": -13,
      "y": 58,
      "z": 1,
      "name": "Soil_Clay_White"
    },
    {
      "x": -13,
      "y": 59,
      "z": 1,
      "name": "Soil_Clay_White"
    },
    {
      "x": -13,
      "y": 60,
      "z": 1,
      "name": "Soil_Clay_White"
    },
    {
      "x": -13,
      "y": 49,
      "z": 2,
      "name": "Rock_Chalk"
    },
    {
      "x": -13,
      "y": 50,
      "z": 2,
      "name": "Soil_Clay_White"
    },
    {
      "x": -13,
      "y": 51,
      "z": 2,
      "name": "Rock_Marble"
    },
    {
      "x": -13,
      "y": 52,
      "z": 2,
      "name": "Rock_Marble"
    },
    {
      "x": -13,
      "y": 53,
      "z": 2,
      "name": "Rock_Marble"
    },
    {
      "x": -13,
      "y": 54,
      "z": 2,
      "name": "Soil_Pebbles"
    },
    {
      "x": -13,
      "y": 55,
      "z": 2,
      "name": "Soil_Pebbles"
    },
    {
      "x": -13,
      "y": 56,
      "z": 2,
      "name": "Rock_Marble"
    },
    {
      "x": -13,
      "y": 57,
      "z": 2,
      "name": "Rock_Marble"
    },
    {
      "x": -13,
      "y": 58,
      "z": 2,
      "name": "Soil_Clay_White"
    },
    {
      "x": -13,
      "y": 59,
      "z": 2,
      "name": "Soil_Clay_White"
    },
    {
      "x": -13,
      "y": 50,
      "z": 3,
      "name": "Soil_Clay_White"
    },
    {
      "x": -13,
      "y": 51,
      "z": 3,
      "name": "Rock_Marble"
    },
    {
      "x": -13,
      "y": 52,
      "z": 3,
      "name": "Rock_Marble"
    },
    {
      "x": -13,
      "y": 53,
      "z": 3,
      "name": "Rock_Marble"
    },
    {
      "x": -13,
      "y": 54,
      "z": 3,
      "name": "Soil_Pebbles"
    },
    {
      "x": -13,
      "y": 55,
      "z": 3,
      "name": "Soil_Pebbles"
    },
    {
      "x": -13,
      "y": 56,
      "z": 3,
      "name": "Rock_Marble"
    },
    {
      "x": -13,
      "y": 57,
      "z": 3,
      "name": "Rock_Marble"
    },
    {
      "x": -13,
      "y": 58,
      "z": 3,
      "name": "Soil_Clay_White"
    },
    {
      "x": -13,
      "y": 51,
      "z": 4,
      "name": "Rock_Marble"
    },
    {
      "x": -13,
      "y": 52,
      "z": 4,
      "name": "Rock_Marble"
    },
    {
      "x": -13,
      "y": 53,
      "z": 4,
      "name": "Rock_Marble"
    },
    {
      "x": -13,
      "y": 54,
      "z": 4,
      "name": "Soil_Pebbles"
    },
    {
      "x": -13,
      "y": 55,
      "z": 4,
      "name": "Soil_Pebbles"
    },
    {
      "x": -13,
      "y": 56,
      "z": 4,
      "name": "Rock_Marble"
    },
    {
      "x": -12,
      "y": 53,
      "z": -7,
      "name": "Rock_Marble"
    },
    {
      "x": -12,
      "y": 54,
      "z": -7,
      "name": "Soil_Pebbles"
    },
    {
      "x": -12,
      "y": 55,
      "z": -7,
      "name": "Soil_Pebbles"
    },
    {
      "x": -12,
      "y": 56,
      "z": -7,
      "name": "Rock_Marble"
    },
    {
      "x": -12,
      "y": 57,
      "z": -7,
      "name": "Rock_Marble"
    },
    {
      "x": -12,
      "y": 58,
      "z": -7,
      "name": "Soil_Clay_White"
    },
    {
      "x": -12,
      "y": 59,
      "z": -7,
      "name": "Soil_Clay_White"
    },
    {
      "x": -12,
      "y": 60,
      "z": -7,
      "name": "Soil_Clay_White"
    },
    {
      "x": -12,
      "y": 61,
      "z": -7,
      "name": "Rock_Marble"
    },
    {
      "x": -12,
      "y": 51,
      "z": -6,
      "name": "Rock_Marble"
    },
    {
      "x": -12,
      "y": 52,
      "z": -6,
      "name": "Rock_Marble"
    },
    {
      "x": -12,
      "y": 53,
      "z": -6,
      "name": "Rock_Marble"
    },
    {
      "x": -12,
      "y": 54,
      "z": -6,
      "name": "Soil_Pebbles"
    },
    {
      "x": -12,
      "y": 55,
      "z": -6,
      "name": "Soil_Pebbles"
    },
    {
      "x": -12,
      "y": 56,
      "z": -6,
      "name": "Rock_Marble"
    },
    {
      "x": -12,
      "y": 57,
      "z": -6,
      "name": "Rock_Marble"
    },
    {
      "x": -12,
      "y": 58,
      "z": -6,
      "name": "Soil_Clay_White"
    },
    {
      "x": -12,
      "y": 59,
      "z": -6,
      "name": "Soil_Clay_White"
    },
    {
      "x": -12,
      "y": 60,
      "z": -6,
      "name": "Soil_Clay_White"
    },
    {
      "x": -12,
      "y": 61,
      "z": -6,
      "name": "Rock_Marble"
    },
    {
      "x": -12,
      "y": 62,
      "z": -6,
      "name": "Rock_Marble"
    },
    {
      "x": -12,
      "y": 63,
      "z": -6,
      "name": "Rock_Marble"
    },
    {
      "x": -12,
      "y": 48,
      "z": -5,
      "name": "Rock_Chalk"
    },
    {
      "x": -12,
      "y": 49,
      "z": -5,
      "name": "Rock_Chalk"
    },
    {
      "x": -12,
      "y": 50,
      "z": -5,
      "name": "Soil_Clay_White"
    },
    {
      "x": -12,
      "y": 51,
      "z": -5,
      "name": "Rock_Marble"
    },
    {
      "x": -12,
      "y": 52,
      "z": -5,
      "name": "Rock_Marble"
    },
    {
      "x": -12,
      "y": 53,
      "z": -5,
      "name": "Rock_Marble"
    },
    {
      "x": -12,
      "y": 54,
      "z": -5,
      "name": "Soil_Pebbles"
    },
    {
      "x": -12,
      "y": 55,
      "z": -5,
      "name": "Soil_Pebbles"
    },
    {
      "x": -12,
      "y": 56,
      "z": -5,
      "name": "Rock_Marble"
    },
    {
      "x": -12,
      "y": 57,
      "z": -5,
      "name": "Rock_Marble"
    },
    {
      "x": -12,
      "y": 58,
      "z": -5,
      "name": "Soil_Clay_White"
    },
    {
      "x": -12,
      "y": 59,
      "z": -5,
      "name": "Soil_Clay_White"
    },
    {
      "x": -12,
      "y": 60,
      "z": -5,
      "name": "Soil_Clay_White"
    },
    {
      "x": -12,
      "y": 61,
      "z": -5,
      "name": "Rock_Marble"
    },
    {
      "x": -12,
      "y": 62,
      "z": -5,
      "name": "Rock_Marble"
    },
    {
      "x": -12,
      "y": 63,
      "z": -5,
      "name": "Rock_Marble"
    },
    {
      "x": -12,
      "y": 64,
      "z": -5,
      "name": "Soil_Pebbles"
    },
    {
      "x": -12,
      "y": 65,
      "z": -5,
      "name": "Rock_Marble"
    },
    {
      "x": -12,
      "y": 66,
      "z": -5,
      "name": "Rock_Marble"
    },
    {
      "x": -12,
      "y": 45,
      "z": -4,
      "name": "Rock_Marble"
    },
    {
      "x": -12,
      "y": 46,
      "z": -4,
      "name": "Rock_Marble"
    },
    {
      "x": -12,
      "y": 47,
      "z": -4,
      "name": "Soil_Clay_White"
    },
    {
      "x": -12,
      "y": 48,
      "z": -4,
      "name": "Rock_Chalk"
    },
    {
      "x": -12,
      "y": 49,
      "z": -4,
      "name": "Rock_Chalk"
    },
    {
      "x": -12,
      "y": 50,
      "z": -4,
      "name": "Soil_Clay_White"
    },
    {
      "x": -12,
      "y": 51,
      "z": -4,
      "name": "Rock_Marble"
    },
    {
      "x": -12,
      "y": 52,
      "z": -4,
      "name": "Rock_Marble"
    },
    {
      "x": -12,
      "y": 53,
      "z": -4,
      "name": "Rock_Marble"
    },
    {
      "x": -12,
      "y": 54,
      "z": -4,
      "name": "Soil_Pebbles"
    },
    {
      "x": -12,
      "y": 55,
      "z": -4,
      "name": "Soil_Pebbles"
    },
    {
      "x": -12,
      "y": 56,
      "z": -4,
      "name": "Rock_Marble"
    },
    {
      "x": -12,
      "y": 57,
      "z": -4,
      "name": "Rock_Marble"
    },
    {
      "x": -12,
      "y": 58,
      "z": -4,
      "name": "Soil_Clay_White"
    },
    {
      "x": -12,
      "y": 59,
      "z": -4,
      "name": "Soil_Clay_White"
    },
    {
      "x": -12,
      "y": 60,
      "z": -4,
      "name": "Soil_Clay_White"
    },
    {
      "x": -12,
      "y": 61,
      "z": -4,
      "name": "Rock_Marble"
    },
    {
      "x": -12,
      "y": 62,
      "z": -4,
      "name": "Rock_Marble"
    },
    {
      "x": -12,
      "y": 63,
      "z": -4,
      "name": "Rock_Marble"
    },
    {
      "x": -12,
      "y": 64,
      "z": -4,
      "name": "Soil_Pebbles"
    },
    {
      "x": -12,
      "y": 65,
      "z": -4,
      "name": "Rock_Marble"
    },
    {
      "x": -12,
      "y": 66,
      "z": -4,
      "name": "Rock_Marble"
    },
    {
      "x": -12,
      "y": 43,
      "z": -3,
      "name": "Soil_Clay_White"
    },
    {
      "x": -12,
      "y": 44,
      "z": -3,
      "name": "Rock_Marble"
    },
    {
      "x": -12,
      "y": 45,
      "z": -3,
      "name": "Rock_Marble"
    },
    {
      "x": -12,
      "y": 46,
      "z": -3,
      "name": "Rock_Marble"
    },
    {
      "x": -12,
      "y": 47,
      "z": -3,
      "name": "Soil_Clay_White"
    },
    {
      "x": -12,
      "y": 48,
      "z": -3,
      "name": "Rock_Chalk"
    },
    {
      "x": -12,
      "y": 49,
      "z": -3,
      "name": "Rock_Chalk"
    },
    {
      "x": -12,
      "y": 50,
      "z": -3,
      "name": "Soil_Clay_White"
    },
    {
      "x": -12,
      "y": 51,
      "z": -3,
      "name": "Rock_Marble"
    },
    {
      "x": -12,
      "y": 52,
      "z": -3,
      "name": "Rock_Marble"
    },
    {
      "x": -12,
      "y": 53,
      "z": -3,
      "name": "Rock_Marble"
    },
    {
      "x": -12,
      "y": 54,
      "z": -3,
      "name": "Soil_Pebbles"
    },
    {
      "x": -12,
      "y": 55,
      "z": -3,
      "name": "Soil_Pebbles"
    },
    {
      "x": -12,
      "y": 56,
      "z": -3,
      "name": "Rock_Marble"
    },
    {
      "x": -12,
      "y": 57,
      "z": -3,
      "name": "Rock_Marble"
    },
    {
      "x": -12,
      "y": 58,
      "z": -3,
      "name": "Soil_Clay_White"
    },
    {
      "x": -12,
      "y": 59,
      "z": -3,
      "name": "Soil_Clay_White"
    },
    {
      "x": -12,
      "y": 60,
      "z": -3,
      "name": "Soil_Clay_White"
    },
    {
      "x": -12,
      "y": 61,
      "z": -3,
      "name": "Rock_Marble"
    },
    {
      "x": -12,
      "y": 62,
      "z": -3,
      "name": "Rock_Marble"
    },
    {
      "x": -12,
      "y": 63,
      "z": -3,
      "name": "Rock_Marble"
    },
    {
      "x": -12,
      "y": 64,
      "z": -3,
      "name": "Soil_Pebbles"
    },
    {
      "x": -12,
      "y": 65,
      "z": -3,
      "name": "Rock_Marble"
    },
    {
      "x": -12,
      "y": 66,
      "z": -3,
      "name": "Rock_Marble"
    },
    {
      "x": -12,
      "y": 42,
      "z": -2,
      "name": "Soil_Clay_White"
    },
    {
      "x": -12,
      "y": 43,
      "z": -2,
      "name": "Soil_Clay_White"
    },
    {
      "x": -12,
      "y": 44,
      "z": -2,
      "name": "Rock_Marble"
    },
    {
      "x": -12,
      "y": 45,
      "z": -2,
      "name": "Rock_Marble"
    },
    {
      "x": -12,
      "y": 46,
      "z": -2,
      "name": "Rock_Marble"
    },
    {
      "x": -12,
      "y": 47,
      "z": -2,
      "name": "Soil_Clay_White"
    },
    {
      "x": -12,
      "y": 48,
      "z": -2,
      "name": "Rock_Chalk"
    },
    {
      "x": -12,
      "y": 49,
      "z": -2,
      "name": "Rock_Chalk"
    },
    {
      "x": -12,
      "y": 50,
      "z": -2,
      "name": "Soil_Clay_White"
    },
    {
      "x": -12,
      "y": 51,
      "z": -2,
      "name": "Rock_Marble"
    },
    {
      "x": -12,
      "y": 52,
      "z": -2,
      "name": "Rock_Marble"
    },
    {
      "x": -12,
      "y": 53,
      "z": -2,
      "name": "Rock_Marble"
    },
    {
      "x": -12,
      "y": 54,
      "z": -2,
      "name": "Soil_Pebbles"
    },
    {
      "x": -12,
      "y": 55,
      "z": -2,
      "name": "Soil_Pebbles"
    },
    {
      "x": -12,
      "y": 56,
      "z": -2,
      "name": "Rock_Marble"
    },
    {
      "x": -12,
      "y": 57,
      "z": -2,
      "name": "Rock_Marble"
    },
    {
      "x": -12,
      "y": 58,
      "z": -2,
      "name": "Soil_Clay_White"
    },
    {
      "x": -12,
      "y": 59,
      "z": -2,
      "name": "Soil_Clay_White"
    },
    {
      "x": -12,
      "y": 60,
      "z": -2,
      "name": "Soil_Clay_White"
    },
    {
      "x": -12,
      "y": 61,
      "z": -2,
      "name": "Rock_Marble"
    },
    {
      "x": -12,
      "y": 62,
      "z": -2,
      "name": "Rock_Marble"
    },
    {
      "x": -12,
      "y": 63,
      "z": -2,
      "name": "Rock_Marble"
    },
    {
      "x": -12,
      "y": 64,
      "z": -2,
      "name": "Soil_Pebbles"
    },
    {
      "x": -12,
      "y": 65,
      "z": -2,
      "name": "Rock_Marble"
    },
    {
      "x": -12,
      "y": 66,
      "z": -2,
      "name": "Rock_Marble"
    },
    {
      "x": -12,
      "y": 67,
      "z": -2,
      "name": "Rock_Marble"
    },
    {
      "x": -12,
      "y": 42,
      "z": -1,
      "name": "Soil_Clay_White"
    },
    {
      "x": -12,
      "y": 43,
      "z": -1,
      "name": "Soil_Clay_White"
    },
    {
      "x": -12,
      "y": 44,
      "z": -1,
      "name": "Rock_Marble"
    },
    {
      "x": -12,
      "y": 45,
      "z": -1,
      "name": "Rock_Marble"
    },
    {
      "x": -12,
      "y": 46,
      "z": -1,
      "name": "Rock_Marble"
    },
    {
      "x": -12,
      "y": 47,
      "z": -1,
      "name": "Soil_Clay_White"
    },
    {
      "x": -12,
      "y": 48,
      "z": -1,
      "name": "Rock_Chalk"
    },
    {
      "x": -12,
      "y": 49,
      "z": -1,
      "name": "Rock_Chalk"
    },
    {
      "x": -12,
      "y": 50,
      "z": -1,
      "name": "Soil_Clay_White"
    },
    {
      "x": -12,
      "y": 51,
      "z": -1,
      "name": "Rock_Marble"
    },
    {
      "x": -12,
      "y": 52,
      "z": -1,
      "name": "Rock_Marble"
    },
    {
      "x": -12,
      "y": 53,
      "z": -1,
      "name": "Rock_Marble"
    },
    {
      "x": -12,
      "y": 54,
      "z": -1,
      "name": "Soil_Pebbles"
    },
    {
      "x": -12,
      "y": 55,
      "z": -1,
      "name": "Soil_Pebbles"
    },
    {
      "x": -12,
      "y": 56,
      "z": -1,
      "name": "Rock_Marble"
    },
    {
      "x": -12,
      "y": 57,
      "z": -1,
      "name": "Rock_Marble"
    },
    {
      "x": -12,
      "y": 58,
      "z": -1,
      "name": "Soil_Clay_White"
    },
    {
      "x": -12,
      "y": 59,
      "z": -1,
      "name": "Soil_Clay_White"
    },
    {
      "x": -12,
      "y": 60,
      "z": -1,
      "name": "Soil_Clay_White"
    },
    {
      "x": -12,
      "y": 61,
      "z": -1,
      "name": "Rock_Marble"
    },
    {
      "x": -12,
      "y": 62,
      "z": -1,
      "name": "Rock_Marble"
    },
    {
      "x": -12,
      "y": 63,
      "z": -1,
      "name": "Rock_Marble"
    },
    {
      "x": -12,
      "y": 64,
      "z": -1,
      "name": "Soil_Pebbles"
    },
    {
      "x": -12,
      "y": 65,
      "z": -1,
      "name": "Rock_Marble"
    },
    {
      "x": -12,
      "y": 66,
      "z": -1,
      "name": "Rock_Marble"
    },
    {
      "x": -12,
      "y": 67,
      "z": -1,
      "name": "Rock_Marble"
    },
    {
      "x": -12,
      "y": 42,
      "z": 0,
      "name": "Soil_Clay_White"
    },
    {
      "x": -12,
      "y": 43,
      "z": 0,
      "name": "Soil_Clay_White"
    },
    {
      "x": -12,
      "y": 44,
      "z": 0,
      "name": "Rock_Marble"
    },
    {
      "x": -12,
      "y": 45,
      "z": 0,
      "name": "Rock_Marble"
    },
    {
      "x": -12,
      "y": 46,
      "z": 0,
      "name": "Rock_Marble"
    },
    {
      "x": -12,
      "y": 47,
      "z": 0,
      "name": "Soil_Clay_White"
    },
    {
      "x": -12,
      "y": 48,
      "z": 0,
      "name": "Rock_Chalk"
    },
    {
      "x": -12,
      "y": 49,
      "z": 0,
      "name": "Rock_Chalk"
    },
    {
      "x": -12,
      "y": 50,
      "z": 0,
      "name": "Soil_Clay_White"
    },
    {
      "x": -12,
      "y": 51,
      "z": 0,
      "name": "Rock_Marble"
    },
    {
      "x": -12,
      "y": 52,
      "z": 0,
      "name": "Rock_Marble"
    },
    {
      "x": -12,
      "y": 53,
      "z": 0,
      "name": "Rock_Marble"
    },
    {
      "x": -12,
      "y": 54,
      "z": 0,
      "name": "Soil_Pebbles"
    },
    {
      "x": -12,
      "y": 55,
      "z": 0,
      "name": "Soil_Pebbles"
    },
    {
      "x": -12,
      "y": 56,
      "z": 0,
      "name": "Rock_Marble"
    },
    {
      "x": -12,
      "y": 57,
      "z": 0,
      "name": "Rock_Marble"
    },
    {
      "x": -12,
      "y": 58,
      "z": 0,
      "name": "Soil_Clay_White"
    },
    {
      "x": -12,
      "y": 59,
      "z": 0,
      "name": "Soil_Clay_White"
    },
    {
      "x": -12,
      "y": 60,
      "z": 0,
      "name": "Soil_Clay_White"
    },
    {
      "x": -12,
      "y": 61,
      "z": 0,
      "name": "Rock_Marble"
    },
    {
      "x": -12,
      "y": 62,
      "z": 0,
      "name": "Rock_Marble"
    },
    {
      "x": -12,
      "y": 63,
      "z": 0,
      "name": "Rock_Marble"
    },
    {
      "x": -12,
      "y": 64,
      "z": 0,
      "name": "Soil_Pebbles"
    },
    {
      "x": -12,
      "y": 65,
      "z": 0,
      "name": "Rock_Marble"
    },
    {
      "x": -12,
      "y": 66,
      "z": 0,
      "name": "Rock_Marble"
    },
    {
      "x": -12,
      "y": 67,
      "z": 0,
      "name": "Rock_Marble"
    },
    {
      "x": -12,
      "y": 42,
      "z": 1,
      "name": "Soil_Clay_White"
    },
    {
      "x": -12,
      "y": 43,
      "z": 1,
      "name": "Soil_Clay_White"
    },
    {
      "x": -12,
      "y": 44,
      "z": 1,
      "name": "Rock_Marble"
    },
    {
      "x": -12,
      "y": 45,
      "z": 1,
      "name": "Rock_Marble"
    },
    {
      "x": -12,
      "y": 46,
      "z": 1,
      "name": "Rock_Marble"
    },
    {
      "x": -12,
      "y": 47,
      "z": 1,
      "name": "Soil_Clay_White"
    },
    {
      "x": -12,
      "y": 48,
      "z": 1,
      "name": "Rock_Chalk"
    },
    {
      "x": -12,
      "y": 49,
      "z": 1,
      "name": "Rock_Chalk"
    },
    {
      "x": -12,
      "y": 50,
      "z": 1,
      "name": "Soil_Clay_White"
    },
    {
      "x": -12,
      "y": 51,
      "z": 1,
      "name": "Rock_Marble"
    },
    {
      "x": -12,
      "y": 52,
      "z": 1,
      "name": "Rock_Marble"
    },
    {
      "x": -12,
      "y": 53,
      "z": 1,
      "name": "Rock_Marble"
    },
    {
      "x": -12,
      "y": 54,
      "z": 1,
      "name": "Soil_Pebbles"
    },
    {
      "x": -12,
      "y": 55,
      "z": 1,
      "name": "Soil_Pebbles"
    },
    {
      "x": -12,
      "y": 56,
      "z": 1,
      "name": "Rock_Marble"
    },
    {
      "x": -12,
      "y": 57,
      "z": 1,
      "name": "Rock_Marble"
    },
    {
      "x": -12,
      "y": 58,
      "z": 1,
      "name": "Soil_Clay_White"
    },
    {
      "x": -12,
      "y": 59,
      "z": 1,
      "name": "Soil_Clay_White"
    },
    {
      "x": -12,
      "y": 60,
      "z": 1,
      "name": "Soil_Clay_White"
    },
    {
      "x": -12,
      "y": 61,
      "z": 1,
      "name": "Rock_Marble"
    },
    {
      "x": -12,
      "y": 62,
      "z": 1,
      "name": "Rock_Marble"
    },
    {
      "x": -12,
      "y": 63,
      "z": 1,
      "name": "Rock_Marble"
    },
    {
      "x": -12,
      "y": 64,
      "z": 1,
      "name": "Soil_Pebbles"
    },
    {
      "x": -12,
      "y": 65,
      "z": 1,
      "name": "Rock_Marble"
    },
    {
      "x": -12,
      "y": 43,
      "z": 2,
      "name": "Soil_Clay_White"
    },
    {
      "x": -12,
      "y": 44,
      "z": 2,
      "name": "Rock_Marble"
    },
    {
      "x": -12,
      "y": 45,
      "z": 2,
      "name": "Rock_Marble"
    },
    {
      "x": -12,
      "y": 46,
      "z": 2,
      "name": "Rock_Marble"
    },
    {
      "x": -12,
      "y": 47,
      "z": 2,
      "name": "Soil_Clay_White"
    },
    {
      "x": -12,
      "y": 48,
      "z": 2,
      "name": "Rock_Chalk"
    },
    {
      "x": -12,
      "y": 49,
      "z": 2,
      "name": "Rock_Chalk"
    },
    {
      "x": -12,
      "y": 50,
      "z": 2,
      "name": "Soil_Clay_White"
    },
    {
      "x": -12,
      "y": 51,
      "z": 2,
      "name": "Rock_Marble"
    },
    {
      "x": -12,
      "y": 52,
      "z": 2,
      "name": "Rock_Marble"
    },
    {
      "x": -12,
      "y": 53,
      "z": 2,
      "name": "Rock_Marble"
    },
    {
      "x": -12,
      "y": 54,
      "z": 2,
      "name": "Soil_Pebbles"
    },
    {
      "x": -12,
      "y": 55,
      "z": 2,
      "name": "Soil_Pebbles"
    },
    {
      "x": -12,
      "y": 56,
      "z": 2,
      "name": "Rock_Marble"
    },
    {
      "x": -12,
      "y": 57,
      "z": 2,
      "name": "Rock_Marble"
    },
    {
      "x": -12,
      "y": 58,
      "z": 2,
      "name": "Soil_Clay_White"
    },
    {
      "x": -12,
      "y": 59,
      "z": 2,
      "name": "Soil_Clay_White"
    },
    {
      "x": -12,
      "y": 60,
      "z": 2,
      "name": "Soil_Clay_White"
    },
    {
      "x": -12,
      "y": 61,
      "z": 2,
      "name": "Rock_Marble"
    },
    {
      "x": -12,
      "y": 62,
      "z": 2,
      "name": "Rock_Marble"
    },
    {
      "x": -12,
      "y": 63,
      "z": 2,
      "name": "Rock_Marble"
    },
    {
      "x": -12,
      "y": 64,
      "z": 2,
      "name": "Soil_Pebbles"
    },
    {
      "x": -12,
      "y": 45,
      "z": 3,
      "name": "Rock_Marble"
    },
    {
      "x": -12,
      "y": 46,
      "z": 3,
      "name": "Rock_Marble"
    },
    {
      "x": -12,
      "y": 47,
      "z": 3,
      "name": "Soil_Clay_White"
    },
    {
      "x": -12,
      "y": 48,
      "z": 3,
      "name": "Rock_Chalk"
    },
    {
      "x": -12,
      "y": 49,
      "z": 3,
      "name": "Rock_Chalk"
    },
    {
      "x": -12,
      "y": 50,
      "z": 3,
      "name": "Soil_Clay_White"
    },
    {
      "x": -12,
      "y": 51,
      "z": 3,
      "name": "Rock_Marble"
    },
    {
      "x": -12,
      "y": 52,
      "z": 3,
      "name": "Rock_Marble"
    },
    {
      "x": -12,
      "y": 53,
      "z": 3,
      "name": "Rock_Marble"
    },
    {
      "x": -12,
      "y": 54,
      "z": 3,
      "name": "Soil_Pebbles"
    },
    {
      "x": -12,
      "y": 55,
      "z": 3,
      "name": "Soil_Pebbles"
    },
    {
      "x": -12,
      "y": 56,
      "z": 3,
      "name": "Rock_Marble"
    },
    {
      "x": -12,
      "y": 57,
      "z": 3,
      "name": "Rock_Marble"
    },
    {
      "x": -12,
      "y": 58,
      "z": 3,
      "name": "Soil_Clay_White"
    },
    {
      "x": -12,
      "y": 59,
      "z": 3,
      "name": "Soil_Clay_White"
    },
    {
      "x": -12,
      "y": 60,
      "z": 3,
      "name": "Soil_Clay_White"
    },
    {
      "x": -12,
      "y": 61,
      "z": 3,
      "name": "Rock_Marble"
    },
    {
      "x": -12,
      "y": 62,
      "z": 3,
      "name": "Rock_Marble"
    },
    {
      "x": -12,
      "y": 63,
      "z": 3,
      "name": "Rock_Marble"
    },
    {
      "x": -12,
      "y": 47,
      "z": 4,
      "name": "Soil_Clay_White"
    },
    {
      "x": -12,
      "y": 48,
      "z": 4,
      "name": "Rock_Chalk"
    },
    {
      "x": -12,
      "y": 49,
      "z": 4,
      "name": "Rock_Chalk"
    },
    {
      "x": -12,
      "y": 50,
      "z": 4,
      "name": "Soil_Clay_White"
    },
    {
      "x": -12,
      "y": 51,
      "z": 4,
      "name": "Rock_Marble"
    },
    {
      "x": -12,
      "y": 52,
      "z": 4,
      "name": "Rock_Marble"
    },
    {
      "x": -12,
      "y": 53,
      "z": 4,
      "name": "Rock_Marble"
    },
    {
      "x": -12,
      "y": 54,
      "z": 4,
      "name": "Soil_Pebbles"
    },
    {
      "x": -12,
      "y": 55,
      "z": 4,
      "name": "Soil_Pebbles"
    },
    {
      "x": -12,
      "y": 56,
      "z": 4,
      "name": "Rock_Marble"
    },
    {
      "x": -12,
      "y": 57,
      "z": 4,
      "name": "Rock_Marble"
    },
    {
      "x": -12,
      "y": 58,
      "z": 4,
      "name": "Soil_Clay_White"
    },
    {
      "x": -12,
      "y": 59,
      "z": 4,
      "name": "Soil_Clay_White"
    },
    {
      "x": -12,
      "y": 60,
      "z": 4,
      "name": "Rock_Marble"
    },
    {
      "x": -12,
      "y": 61,
      "z": 4,
      "name": "Rock_Marble"
    },
    {
      "x": -12,
      "y": 50,
      "z": 5,
      "name": "Soil_Clay_White"
    },
    {
      "x": -12,
      "y": 51,
      "z": 5,
      "name": "Rock_Marble"
    },
    {
      "x": -12,
      "y": 52,
      "z": 5,
      "name": "Rock_Marble"
    },
    {
      "x": -12,
      "y": 53,
      "z": 5,
      "name": "Rock_Marble"
    },
    {
      "x": -12,
      "y": 54,
      "z": 5,
      "name": "Soil_Pebbles"
    },
    {
      "x": -12,
      "y": 55,
      "z": 5,
      "name": "Soil_Pebbles"
    },
    {
      "x": -12,
      "y": 56,
      "z": 5,
      "name": "Rock_Marble"
    },
    {
      "x": -12,
      "y": 57,
      "z": 5,
      "name": "Rock_Marble"
    },
    {
      "x": -12,
      "y": 58,
      "z": 5,
      "name": "Soil_Clay_White"
    },
    {
      "x": -12,
      "y": 59,
      "z": 5,
      "name": "Soil_Clay_White"
    },
    {
      "x": -12,
      "y": 53,
      "z": 6,
      "name": "Rock_Marble"
    },
    {
      "x": -12,
      "y": 54,
      "z": 6,
      "name": "Soil_Pebbles"
    },
    {
      "x": -11,
      "y": 52,
      "z": -8,
      "name": "Rock_Marble"
    },
    {
      "x": -11,
      "y": 53,
      "z": -8,
      "name": "Rock_Marble"
    },
    {
      "x": -11,
      "y": 54,
      "z": -8,
      "name": "Soil_Pebbles"
    },
    {
      "x": -11,
      "y": 55,
      "z": -8,
      "name": "Soil_Pebbles"
    },
    {
      "x": -11,
      "y": 56,
      "z": -8,
      "name": "Rock_Marble"
    },
    {
      "x": -11,
      "y": 57,
      "z": -8,
      "name": "Rock_Marble"
    },
    {
      "x": -11,
      "y": 58,
      "z": -8,
      "name": "Soil_Clay_White"
    },
    {
      "x": -11,
      "y": 59,
      "z": -8,
      "name": "Soil_Clay_White"
    },
    {
      "x": -11,
      "y": 60,
      "z": -8,
      "name": "Soil_Clay_White"
    },
    {
      "x": -11,
      "y": 61,
      "z": -8,
      "name": "Rock_Marble"
    },
    {
      "x": -11,
      "y": 62,
      "z": -8,
      "name": "Rock_Marble"
    },
    {
      "x": -11,
      "y": 49,
      "z": -7,
      "name": "Rock_Chalk"
    },
    {
      "x": -11,
      "y": 50,
      "z": -7,
      "name": "Soil_Clay_White"
    },
    {
      "x": -11,
      "y": 51,
      "z": -7,
      "name": "Rock_Marble"
    },
    {
      "x": -11,
      "y": 52,
      "z": -7,
      "name": "Rock_Marble"
    },
    {
      "x": -11,
      "y": 53,
      "z": -7,
      "name": "Rock_Marble"
    },
    {
      "x": -11,
      "y": 54,
      "z": -7,
      "name": "Soil_Pebbles"
    },
    {
      "x": -11,
      "y": 55,
      "z": -7,
      "name": "Soil_Pebbles"
    },
    {
      "x": -11,
      "y": 56,
      "z": -7,
      "name": "Rock_Marble"
    },
    {
      "x": -11,
      "y": 57,
      "z": -7,
      "name": "Rock_Marble"
    },
    {
      "x": -11,
      "y": 58,
      "z": -7,
      "name": "Soil_Clay_White"
    },
    {
      "x": -11,
      "y": 59,
      "z": -7,
      "name": "Soil_Clay_White"
    },
    {
      "x": -11,
      "y": 60,
      "z": -7,
      "name": "Soil_Clay_White"
    },
    {
      "x": -11,
      "y": 61,
      "z": -7,
      "name": "Rock_Marble"
    },
    {
      "x": -11,
      "y": 62,
      "z": -7,
      "name": "Rock_Marble"
    },
    {
      "x": -11,
      "y": 63,
      "z": -7,
      "name": "Rock_Marble"
    },
    {
      "x": -11,
      "y": 64,
      "z": -7,
      "name": "Soil_Pebbles"
    },
    {
      "x": -11,
      "y": 65,
      "z": -7,
      "name": "Rock_Marble"
    },
    {
      "x": -11,
      "y": 66,
      "z": -7,
      "name": "Rock_Marble"
    },
    {
      "x": -11,
      "y": 47,
      "z": -6,
      "name": "Soil_Clay_White"
    },
    {
      "x": -11,
      "y": 48,
      "z": -6,
      "name": "Rock_Chalk"
    },
    {
      "x": -11,
      "y": 49,
      "z": -6,
      "name": "Rock_Chalk"
    },
    {
      "x": -11,
      "y": 50,
      "z": -6,
      "name": "Soil_Clay_White"
    },
    {
      "x": -11,
      "y": 51,
      "z": -6,
      "name": "Rock_Marble"
    },
    {
      "x": -11,
      "y": 52,
      "z": -6,
      "name": "Rock_Marble"
    },
    {
      "x": -11,
      "y": 53,
      "z": -6,
      "name": "Rock_Marble"
    },
    {
      "x": -11,
      "y": 54,
      "z": -6,
      "name": "Soil_Pebbles"
    },
    {
      "x": -11,
      "y": 55,
      "z": -6,
      "name": "Soil_Pebbles"
    },
    {
      "x": -11,
      "y": 56,
      "z": -6,
      "name": "Rock_Marble"
    },
    {
      "x": -11,
      "y": 57,
      "z": -6,
      "name": "Rock_Marble"
    },
    {
      "x": -11,
      "y": 58,
      "z": -6,
      "name": "Soil_Clay_White"
    },
    {
      "x": -11,
      "y": 59,
      "z": -6,
      "name": "Soil_Clay_White"
    },
    {
      "x": -11,
      "y": 60,
      "z": -6,
      "name": "Soil_Clay_White"
    },
    {
      "x": -11,
      "y": 61,
      "z": -6,
      "name": "Rock_Marble"
    },
    {
      "x": -11,
      "y": 62,
      "z": -6,
      "name": "Rock_Marble"
    },
    {
      "x": -11,
      "y": 63,
      "z": -6,
      "name": "Rock_Marble"
    },
    {
      "x": -11,
      "y": 64,
      "z": -6,
      "name": "Soil_Pebbles"
    },
    {
      "x": -11,
      "y": 65,
      "z": -6,
      "name": "Rock_Marble"
    },
    {
      "x": -11,
      "y": 66,
      "z": -6,
      "name": "Rock_Marble"
    },
    {
      "x": -11,
      "y": 67,
      "z": -6,
      "name": "Rock_Marble"
    },
    {
      "x": -11,
      "y": 68,
      "z": -6,
      "name": "Rock_Marble"
    },
    {
      "x": -11,
      "y": 69,
      "z": -6,
      "name": "Rock_Marble"
    },
    {
      "x": -11,
      "y": 70,
      "z": -6,
      "name": "Soil_Clay_White"
    },
    {
      "x": -11,
      "y": 43,
      "z": -5,
      "name": "Soil_Clay_White"
    },
    {
      "x": -11,
      "y": 44,
      "z": -5,
      "name": "Rock_Marble"
    },
    {
      "x": -11,
      "y": 45,
      "z": -5,
      "name": "Rock_Marble"
    },
    {
      "x": -11,
      "y": 46,
      "z": -5,
      "name": "Rock_Marble"
    },
    {
      "x": -11,
      "y": 47,
      "z": -5,
      "name": "Soil_Clay_White"
    },
    {
      "x": -11,
      "y": 48,
      "z": -5,
      "name": "Rock_Chalk"
    },
    {
      "x": -11,
      "y": 49,
      "z": -5,
      "name": "Rock_Chalk"
    },
    {
      "x": -11,
      "y": 50,
      "z": -5,
      "name": "Soil_Clay_White"
    },
    {
      "x": -11,
      "y": 51,
      "z": -5,
      "name": "Rock_Marble"
    },
    {
      "x": -11,
      "y": 52,
      "z": -5,
      "name": "Rock_Marble"
    },
    {
      "x": -11,
      "y": 53,
      "z": -5,
      "name": "Rock_Marble"
    },
    {
      "x": -11,
      "y": 54,
      "z": -5,
      "name": "Soil_Pebbles"
    },
    {
      "x": -11,
      "y": 55,
      "z": -5,
      "name": "Soil_Pebbles"
    },
    {
      "x": -11,
      "y": 56,
      "z": -5,
      "name": "Rock_Marble"
    },
    {
      "x": -11,
      "y": 57,
      "z": -5,
      "name": "Rock_Marble"
    },
    {
      "x": -11,
      "y": 58,
      "z": -5,
      "name": "Soil_Clay_White"
    },
    {
      "x": -11,
      "y": 59,
      "z": -5,
      "name": "Soil_Clay_White"
    },
    {
      "x": -11,
      "y": 60,
      "z": -5,
      "name": "Soil_Clay_White"
    },
    {
      "x": -11,
      "y": 61,
      "z": -5,
      "name": "Rock_Marble"
    },
    {
      "x": -11,
      "y": 62,
      "z": -5,
      "name": "Rock_Marble"
    },
    {
      "x": -11,
      "y": 63,
      "z": -5,
      "name": "Rock_Marble"
    },
    {
      "x": -11,
      "y": 64,
      "z": -5,
      "name": "Soil_Pebbles"
    },
    {
      "x": -11,
      "y": 65,
      "z": -5,
      "name": "Rock_Marble"
    },
    {
      "x": -11,
      "y": 66,
      "z": -5,
      "name": "Rock_Marble"
    },
    {
      "x": -11,
      "y": 67,
      "z": -5,
      "name": "Rock_Marble"
    },
    {
      "x": -11,
      "y": 68,
      "z": -5,
      "name": "Rock_Marble"
    },
    {
      "x": -11,
      "y": 69,
      "z": -5,
      "name": "Rock_Marble"
    },
    {
      "x": -11,
      "y": 70,
      "z": -5,
      "name": "Soil_Clay_White"
    },
    {
      "x": -11,
      "y": 71,
      "z": -5,
      "name": "Soil_Clay_White"
    },
    {
      "x": -11,
      "y": 72,
      "z": -5,
      "name": "Soil_Clay_White"
    },
    {
      "x": -11,
      "y": 73,
      "z": -5,
      "name": "Soil_Clay_White"
    },
    {
      "x": -11,
      "y": 40,
      "z": -4,
      "name": "Soil_Clay_White"
    },
    {
      "x": -11,
      "y": 41,
      "z": -4,
      "name": "Soil_Clay_White"
    },
    {
      "x": -11,
      "y": 42,
      "z": -4,
      "name": "Soil_Clay_White"
    },
    {
      "x": -11,
      "y": 43,
      "z": -4,
      "name": "Soil_Clay_White"
    },
    {
      "x": -11,
      "y": 44,
      "z": -4,
      "name": "Rock_Marble"
    },
    {
      "x": -11,
      "y": 45,
      "z": -4,
      "name": "Rock_Marble"
    },
    {
      "x": -11,
      "y": 46,
      "z": -4,
      "name": "Rock_Marble"
    },
    {
      "x": -11,
      "y": 47,
      "z": -4,
      "name": "Soil_Clay_White"
    },
    {
      "x": -11,
      "y": 48,
      "z": -4,
      "name": "Rock_Chalk"
    },
    {
      "x": -11,
      "y": 49,
      "z": -4,
      "name": "Rock_Chalk"
    },
    {
      "x": -11,
      "y": 50,
      "z": -4,
      "name": "Soil_Clay_White"
    },
    {
      "x": -11,
      "y": 51,
      "z": -4,
      "name": "Rock_Marble"
    },
    {
      "x": -11,
      "y": 52,
      "z": -4,
      "name": "Rock_Marble"
    },
    {
      "x": -11,
      "y": 53,
      "z": -4,
      "name": "Rock_Marble"
    },
    {
      "x": -11,
      "y": 54,
      "z": -4,
      "name": "Soil_Pebbles"
    },
    {
      "x": -11,
      "y": 55,
      "z": -4,
      "name": "Soil_Pebbles"
    },
    {
      "x": -11,
      "y": 56,
      "z": -4,
      "name": "Rock_Marble"
    },
    {
      "x": -11,
      "y": 57,
      "z": -4,
      "name": "Rock_Marble"
    },
    {
      "x": -11,
      "y": 58,
      "z": -4,
      "name": "Soil_Clay_White"
    },
    {
      "x": -11,
      "y": 59,
      "z": -4,
      "name": "Soil_Clay_White"
    },
    {
      "x": -11,
      "y": 60,
      "z": -4,
      "name": "Soil_Clay_White"
    },
    {
      "x": -11,
      "y": 61,
      "z": -4,
      "name": "Rock_Marble"
    },
    {
      "x": -11,
      "y": 62,
      "z": -4,
      "name": "Rock_Marble"
    },
    {
      "x": -11,
      "y": 63,
      "z": -4,
      "name": "Rock_Marble"
    },
    {
      "x": -11,
      "y": 64,
      "z": -4,
      "name": "Soil_Pebbles"
    },
    {
      "x": -11,
      "y": 65,
      "z": -4,
      "name": "Rock_Marble"
    },
    {
      "x": -11,
      "y": 66,
      "z": -4,
      "name": "Rock_Marble"
    },
    {
      "x": -11,
      "y": 67,
      "z": -4,
      "name": "Rock_Marble"
    },
    {
      "x": -11,
      "y": 68,
      "z": -4,
      "name": "Rock_Marble"
    },
    {
      "x": -11,
      "y": 69,
      "z": -4,
      "name": "Rock_Marble"
    },
    {
      "x": -11,
      "y": 70,
      "z": -4,
      "name": "Soil_Clay_White"
    },
    {
      "x": -11,
      "y": 71,
      "z": -4,
      "name": "Soil_Clay_White"
    },
    {
      "x": -11,
      "y": 72,
      "z": -4,
      "name": "Soil_Clay_White"
    },
    {
      "x": -11,
      "y": 73,
      "z": -4,
      "name": "Soil_Clay_White"
    },
    {
      "x": -11,
      "y": 74,
      "z": -4,
      "name": "Rock_Marble"
    },
    {
      "x": -11,
      "y": 75,
      "z": -4,
      "name": "Rock_Marble"
    },
    {
      "x": -11,
      "y": 76,
      "z": -4,
      "name": "Rock_Marble"
    },
    {
      "x": -11,
      "y": 38,
      "z": -3,
      "name": "Rock_Marble"
    },
    {
      "x": -11,
      "y": 39,
      "z": -3,
      "name": "Rock_Marble"
    },
    {
      "x": -11,
      "y": 40,
      "z": -3,
      "name": "Soil_Clay_White"
    },
    {
      "x": -11,
      "y": 41,
      "z": -3,
      "name": "Soil_Clay_White"
    },
    {
      "x": -11,
      "y": 42,
      "z": -3,
      "name": "Soil_Clay_White"
    },
    {
      "x": -11,
      "y": 43,
      "z": -3,
      "name": "Soil_Clay_White"
    },
    {
      "x": -11,
      "y": 44,
      "z": -3,
      "name": "Rock_Marble"
    },
    {
      "x": -11,
      "y": 45,
      "z": -3,
      "name": "Rock_Marble"
    },
    {
      "x": -11,
      "y": 46,
      "z": -3,
      "name": "Rock_Marble"
    },
    {
      "x": -11,
      "y": 47,
      "z": -3,
      "name": "Soil_Clay_White"
    },
    {
      "x": -11,
      "y": 48,
      "z": -3,
      "name": "Rock_Chalk"
    },
    {
      "x": -11,
      "y": 49,
      "z": -3,
      "name": "Rock_Chalk"
    },
    {
      "x": -11,
      "y": 50,
      "z": -3,
      "name": "Soil_Clay_White"
    },
    {
      "x": -11,
      "y": 51,
      "z": -3,
      "name": "Rock_Marble"
    },
    {
      "x": -11,
      "y": 52,
      "z": -3,
      "name": "Rock_Marble"
    },
    {
      "x": -11,
      "y": 53,
      "z": -3,
      "name": "Rock_Marble"
    },
    {
      "x": -11,
      "y": 54,
      "z": -3,
      "name": "Soil_Pebbles"
    },
    {
      "x": -11,
      "y": 55,
      "z": -3,
      "name": "Soil_Pebbles"
    },
    {
      "x": -11,
      "y": 56,
      "z": -3,
      "name": "Rock_Marble"
    },
    {
      "x": -11,
      "y": 57,
      "z": -3,
      "name": "Rock_Marble"
    },
    {
      "x": -11,
      "y": 58,
      "z": -3,
      "name": "Soil_Clay_White"
    },
    {
      "x": -11,
      "y": 59,
      "z": -3,
      "name": "Soil_Clay_White"
    },
    {
      "x": -11,
      "y": 60,
      "z": -3,
      "name": "Soil_Clay_White"
    },
    {
      "x": -11,
      "y": 61,
      "z": -3,
      "name": "Rock_Marble"
    },
    {
      "x": -11,
      "y": 62,
      "z": -3,
      "name": "Rock_Marble"
    },
    {
      "x": -11,
      "y": 63,
      "z": -3,
      "name": "Rock_Marble"
    },
    {
      "x": -11,
      "y": 64,
      "z": -3,
      "name": "Soil_Pebbles"
    },
    {
      "x": -11,
      "y": 65,
      "z": -3,
      "name": "Rock_Marble"
    },
    {
      "x": -11,
      "y": 66,
      "z": -3,
      "name": "Rock_Marble"
    },
    {
      "x": -11,
      "y": 67,
      "z": -3,
      "name": "Rock_Marble"
    },
    {
      "x": -11,
      "y": 68,
      "z": -3,
      "name": "Rock_Marble"
    },
    {
      "x": -11,
      "y": 69,
      "z": -3,
      "name": "Rock_Marble"
    },
    {
      "x": -11,
      "y": 70,
      "z": -3,
      "name": "Soil_Clay_White"
    },
    {
      "x": -11,
      "y": 71,
      "z": -3,
      "name": "Soil_Clay_White"
    },
    {
      "x": -11,
      "y": 72,
      "z": -3,
      "name": "Soil_Clay_White"
    },
    {
      "x": -11,
      "y": 73,
      "z": -3,
      "name": "Soil_Clay_White"
    },
    {
      "x": -11,
      "y": 74,
      "z": -3,
      "name": "Rock_Marble"
    },
    {
      "x": -11,
      "y": 75,
      "z": -3,
      "name": "Rock_Marble"
    },
    {
      "x": -11,
      "y": 76,
      "z": -3,
      "name": "Rock_Marble"
    },
    {
      "x": -11,
      "y": 77,
      "z": -3,
      "name": "Soil_Clay_White"
    },
    {
      "x": -11,
      "y": 78,
      "z": -3,
      "name": "Soil_Clay_White"
    },
    {
      "x": -11,
      "y": 37,
      "z": -2,
      "name": "Rock_Marble"
    },
    {
      "x": -11,
      "y": 38,
      "z": -2,
      "name": "Rock_Marble"
    },
    {
      "x": -11,
      "y": 39,
      "z": -2,
      "name": "Rock_Marble"
    },
    {
      "x": -11,
      "y": 40,
      "z": -2,
      "name": "Soil_Clay_White"
    },
    {
      "x": -11,
      "y": 41,
      "z": -2,
      "name": "Soil_Clay_White"
    },
    {
      "x": -11,
      "y": 42,
      "z": -2,
      "name": "Soil_Clay_White"
    },
    {
      "x": -11,
      "y": 43,
      "z": -2,
      "name": "Soil_Clay_White"
    },
    {
      "x": -11,
      "y": 44,
      "z": -2,
      "name": "Rock_Marble"
    },
    {
      "x": -11,
      "y": 45,
      "z": -2,
      "name": "Rock_Marble"
    },
    {
      "x": -11,
      "y": 46,
      "z": -2,
      "name": "Rock_Marble"
    },
    {
      "x": -11,
      "y": 47,
      "z": -2,
      "name": "Soil_Clay_White"
    },
    {
      "x": -11,
      "y": 48,
      "z": -2,
      "name": "Rock_Chalk"
    },
    {
      "x": -11,
      "y": 49,
      "z": -2,
      "name": "Rock_Chalk"
    },
    {
      "x": -11,
      "y": 50,
      "z": -2,
      "name": "Soil_Clay_White"
    },
    {
      "x": -11,
      "y": 51,
      "z": -2,
      "name": "Rock_Marble"
    },
    {
      "x": -11,
      "y": 52,
      "z": -2,
      "name": "Rock_Marble"
    },
    {
      "x": -11,
      "y": 53,
      "z": -2,
      "name": "Rock_Marble"
    },
    {
      "x": -11,
      "y": 54,
      "z": -2,
      "name": "Soil_Pebbles"
    },
    {
      "x": -11,
      "y": 55,
      "z": -2,
      "name": "Soil_Pebbles"
    },
    {
      "x": -11,
      "y": 56,
      "z": -2,
      "name": "Rock_Marble"
    },
    {
      "x": -11,
      "y": 57,
      "z": -2,
      "name": "Rock_Marble"
    },
    {
      "x": -11,
      "y": 58,
      "z": -2,
      "name": "Soil_Clay_White"
    },
    {
      "x": -11,
      "y": 59,
      "z": -2,
      "name": "Soil_Clay_White"
    },
    {
      "x": -11,
      "y": 60,
      "z": -2,
      "name": "Soil_Clay_White"
    },
    {
      "x": -11,
      "y": 61,
      "z": -2,
      "name": "Rock_Marble"
    },
    {
      "x": -11,
      "y": 62,
      "z": -2,
      "name": "Rock_Marble"
    },
    {
      "x": -11,
      "y": 63,
      "z": -2,
      "name": "Rock_Marble"
    },
    {
      "x": -11,
      "y": 64,
      "z": -2,
      "name": "Soil_Pebbles"
    },
    {
      "x": -11,
      "y": 65,
      "z": -2,
      "name": "Rock_Marble"
    },
    {
      "x": -11,
      "y": 66,
      "z": -2,
      "name": "Rock_Marble"
    },
    {
      "x": -11,
      "y": 67,
      "z": -2,
      "name": "Rock_Marble"
    },
    {
      "x": -11,
      "y": 68,
      "z": -2,
      "name": "Rock_Marble"
    },
    {
      "x": -11,
      "y": 69,
      "z": -2,
      "name": "Rock_Marble"
    },
    {
      "x": -11,
      "y": 70,
      "z": -2,
      "name": "Soil_Clay_White"
    },
    {
      "x": -11,
      "y": 71,
      "z": -2,
      "name": "Soil_Clay_White"
    },
    {
      "x": -11,
      "y": 72,
      "z": -2,
      "name": "Soil_Clay_White"
    },
    {
      "x": -11,
      "y": 73,
      "z": -2,
      "name": "Soil_Clay_White"
    },
    {
      "x": -11,
      "y": 74,
      "z": -2,
      "name": "Rock_Marble"
    },
    {
      "x": -11,
      "y": 75,
      "z": -2,
      "name": "Rock_Marble"
    },
    {
      "x": -11,
      "y": 76,
      "z": -2,
      "name": "Rock_Marble"
    },
    {
      "x": -11,
      "y": 77,
      "z": -2,
      "name": "Soil_Clay_White"
    },
    {
      "x": -11,
      "y": 78,
      "z": -2,
      "name": "Soil_Clay_White"
    },
    {
      "x": -11,
      "y": 37,
      "z": -1,
      "name": "Rock_Marble"
    },
    {
      "x": -11,
      "y": 38,
      "z": -1,
      "name": "Rock_Marble"
    },
    {
      "x": -11,
      "y": 39,
      "z": -1,
      "name": "Rock_Marble"
    },
    {
      "x": -11,
      "y": 40,
      "z": -1,
      "name": "Soil_Clay_White"
    },
    {
      "x": -11,
      "y": 41,
      "z": -1,
      "name": "Soil_Clay_White"
    },
    {
      "x": -11,
      "y": 42,
      "z": -1,
      "name": "Soil_Clay_White"
    },
    {
      "x": -11,
      "y": 43,
      "z": -1,
      "name": "Soil_Clay_White"
    },
    {
      "x": -11,
      "y": 44,
      "z": -1,
      "name": "Rock_Marble"
    },
    {
      "x": -11,
      "y": 45,
      "z": -1,
      "name": "Rock_Marble"
    },
    {
      "x": -11,
      "y": 46,
      "z": -1,
      "name": "Rock_Marble"
    },
    {
      "x": -11,
      "y": 47,
      "z": -1,
      "name": "Soil_Clay_White"
    },
    {
      "x": -11,
      "y": 48,
      "z": -1,
      "name": "Rock_Chalk"
    },
    {
      "x": -11,
      "y": 49,
      "z": -1,
      "name": "Rock_Chalk"
    },
    {
      "x": -11,
      "y": 50,
      "z": -1,
      "name": "Soil_Clay_White"
    },
    {
      "x": -11,
      "y": 51,
      "z": -1,
      "name": "Rock_Marble"
    },
    {
      "x": -11,
      "y": 52,
      "z": -1,
      "name": "Rock_Marble"
    },
    {
      "x": -11,
      "y": 53,
      "z": -1,
      "name": "Rock_Marble"
    },
    {
      "x": -11,
      "y": 54,
      "z": -1,
      "name": "Soil_Pebbles"
    },
    {
      "x": -11,
      "y": 55,
      "z": -1,
      "name": "Soil_Pebbles"
    },
    {
      "x": -11,
      "y": 56,
      "z": -1,
      "name": "Rock_Marble"
    },
    {
      "x": -11,
      "y": 57,
      "z": -1,
      "name": "Rock_Marble"
    },
    {
      "x": -11,
      "y": 58,
      "z": -1,
      "name": "Soil_Clay_White"
    },
    {
      "x": -11,
      "y": 59,
      "z": -1,
      "name": "Soil_Clay_White"
    },
    {
      "x": -11,
      "y": 60,
      "z": -1,
      "name": "Soil_Clay_White"
    },
    {
      "x": -11,
      "y": 61,
      "z": -1,
      "name": "Rock_Marble"
    },
    {
      "x": -11,
      "y": 62,
      "z": -1,
      "name": "Rock_Marble"
    },
    {
      "x": -11,
      "y": 63,
      "z": -1,
      "name": "Rock_Marble"
    },
    {
      "x": -11,
      "y": 64,
      "z": -1,
      "name": "Soil_Pebbles"
    },
    {
      "x": -11,
      "y": 65,
      "z": -1,
      "name": "Rock_Marble"
    },
    {
      "x": -11,
      "y": 66,
      "z": -1,
      "name": "Rock_Marble"
    },
    {
      "x": -11,
      "y": 67,
      "z": -1,
      "name": "Rock_Marble"
    },
    {
      "x": -11,
      "y": 68,
      "z": -1,
      "name": "Rock_Marble"
    },
    {
      "x": -11,
      "y": 69,
      "z": -1,
      "name": "Rock_Marble"
    },
    {
      "x": -11,
      "y": 70,
      "z": -1,
      "name": "Soil_Clay_White"
    },
    {
      "x": -11,
      "y": 71,
      "z": -1,
      "name": "Soil_Clay_White"
    },
    {
      "x": -11,
      "y": 72,
      "z": -1,
      "name": "Soil_Clay_White"
    },
    {
      "x": -11,
      "y": 73,
      "z": -1,
      "name": "Soil_Clay_White"
    },
    {
      "x": -11,
      "y": 74,
      "z": -1,
      "name": "Rock_Marble"
    },
    {
      "x": -11,
      "y": 75,
      "z": -1,
      "name": "Rock_Marble"
    },
    {
      "x": -11,
      "y": 76,
      "z": -1,
      "name": "Rock_Marble"
    },
    {
      "x": -11,
      "y": 77,
      "z": -1,
      "name": "Soil_Clay_White"
    },
    {
      "x": -11,
      "y": 78,
      "z": -1,
      "name": "Soil_Clay_White"
    },
    {
      "x": -11,
      "y": 79,
      "z": -1,
      "name": "Soil_Clay_White"
    },
    {
      "x": -11,
      "y": 37,
      "z": 0,
      "name": "Rock_Marble"
    },
    {
      "x": -11,
      "y": 38,
      "z": 0,
      "name": "Rock_Marble"
    },
    {
      "x": -11,
      "y": 39,
      "z": 0,
      "name": "Rock_Marble"
    },
    {
      "x": -11,
      "y": 40,
      "z": 0,
      "name": "Soil_Clay_White"
    },
    {
      "x": -11,
      "y": 41,
      "z": 0,
      "name": "Soil_Clay_White"
    },
    {
      "x": -11,
      "y": 42,
      "z": 0,
      "name": "Soil_Clay_White"
    },
    {
      "x": -11,
      "y": 43,
      "z": 0,
      "name": "Soil_Clay_White"
    },
    {
      "x": -11,
      "y": 44,
      "z": 0,
      "name": "Rock_Marble"
    },
    {
      "x": -11,
      "y": 45,
      "z": 0,
      "name": "Rock_Marble"
    },
    {
      "x": -11,
      "y": 46,
      "z": 0,
      "name": "Rock_Marble"
    },
    {
      "x": -11,
      "y": 47,
      "z": 0,
      "name": "Soil_Clay_White"
    },
    {
      "x": -11,
      "y": 48,
      "z": 0,
      "name": "Rock_Chalk"
    },
    {
      "x": -11,
      "y": 49,
      "z": 0,
      "name": "Rock_Chalk"
    },
    {
      "x": -11,
      "y": 50,
      "z": 0,
      "name": "Soil_Clay_White"
    },
    {
      "x": -11,
      "y": 51,
      "z": 0,
      "name": "Rock_Marble"
    },
    {
      "x": -11,
      "y": 52,
      "z": 0,
      "name": "Rock_Marble"
    },
    {
      "x": -11,
      "y": 53,
      "z": 0,
      "name": "Rock_Marble"
    },
    {
      "x": -11,
      "y": 54,
      "z": 0,
      "name": "Soil_Pebbles"
    },
    {
      "x": -11,
      "y": 55,
      "z": 0,
      "name": "Soil_Pebbles"
    },
    {
      "x": -11,
      "y": 56,
      "z": 0,
      "name": "Rock_Marble"
    },
    {
      "x": -11,
      "y": 57,
      "z": 0,
      "name": "Rock_Marble"
    },
    {
      "x": -11,
      "y": 58,
      "z": 0,
      "name": "Soil_Clay_White"
    },
    {
      "x": -11,
      "y": 59,
      "z": 0,
      "name": "Soil_Clay_White"
    },
    {
      "x": -11,
      "y": 60,
      "z": 0,
      "name": "Soil_Clay_White"
    },
    {
      "x": -11,
      "y": 61,
      "z": 0,
      "name": "Rock_Marble"
    },
    {
      "x": -11,
      "y": 62,
      "z": 0,
      "name": "Rock_Marble"
    },
    {
      "x": -11,
      "y": 63,
      "z": 0,
      "name": "Rock_Marble"
    },
    {
      "x": -11,
      "y": 64,
      "z": 0,
      "name": "Soil_Pebbles"
    },
    {
      "x": -11,
      "y": 65,
      "z": 0,
      "name": "Rock_Marble"
    },
    {
      "x": -11,
      "y": 66,
      "z": 0,
      "name": "Rock_Marble"
    },
    {
      "x": -11,
      "y": 67,
      "z": 0,
      "name": "Rock_Marble"
    },
    {
      "x": -11,
      "y": 68,
      "z": 0,
      "name": "Rock_Marble"
    },
    {
      "x": -11,
      "y": 69,
      "z": 0,
      "name": "Rock_Marble"
    },
    {
      "x": -11,
      "y": 70,
      "z": 0,
      "name": "Soil_Clay_White"
    },
    {
      "x": -11,
      "y": 71,
      "z": 0,
      "name": "Soil_Clay_White"
    },
    {
      "x": -11,
      "y": 72,
      "z": 0,
      "name": "Soil_Clay_White"
    },
    {
      "x": -11,
      "y": 73,
      "z": 0,
      "name": "Soil_Clay_White"
    },
    {
      "x": -11,
      "y": 74,
      "z": 0,
      "name": "Rock_Marble"
    },
    {
      "x": -11,
      "y": 75,
      "z": 0,
      "name": "Rock_Marble"
    },
    {
      "x": -11,
      "y": 76,
      "z": 0,
      "name": "Rock_Marble"
    },
    {
      "x": -11,
      "y": 77,
      "z": 0,
      "name": "Soil_Clay_White"
    },
    {
      "x": -11,
      "y": 78,
      "z": 0,
      "name": "Soil_Clay_White"
    },
    {
      "x": -11,
      "y": 37,
      "z": 1,
      "name": "Rock_Marble"
    },
    {
      "x": -11,
      "y": 38,
      "z": 1,
      "name": "Rock_Marble"
    },
    {
      "x": -11,
      "y": 39,
      "z": 1,
      "name": "Rock_Marble"
    },
    {
      "x": -11,
      "y": 40,
      "z": 1,
      "name": "Soil_Clay_White"
    },
    {
      "x": -11,
      "y": 41,
      "z": 1,
      "name": "Soil_Clay_White"
    },
    {
      "x": -11,
      "y": 42,
      "z": 1,
      "name": "Soil_Clay_White"
    },
    {
      "x": -11,
      "y": 43,
      "z": 1,
      "name": "Soil_Clay_White"
    },
    {
      "x": -11,
      "y": 44,
      "z": 1,
      "name": "Rock_Marble"
    },
    {
      "x": -11,
      "y": 45,
      "z": 1,
      "name": "Rock_Marble"
    },
    {
      "x": -11,
      "y": 46,
      "z": 1,
      "name": "Rock_Marble"
    },
    {
      "x": -11,
      "y": 47,
      "z": 1,
      "name": "Soil_Clay_White"
    },
    {
      "x": -11,
      "y": 48,
      "z": 1,
      "name": "Rock_Chalk"
    },
    {
      "x": -11,
      "y": 49,
      "z": 1,
      "name": "Rock_Chalk"
    },
    {
      "x": -11,
      "y": 50,
      "z": 1,
      "name": "Soil_Clay_White"
    },
    {
      "x": -11,
      "y": 51,
      "z": 1,
      "name": "Rock_Marble"
    },
    {
      "x": -11,
      "y": 52,
      "z": 1,
      "name": "Rock_Marble"
    },
    {
      "x": -11,
      "y": 53,
      "z": 1,
      "name": "Rock_Marble"
    },
    {
      "x": -11,
      "y": 54,
      "z": 1,
      "name": "Soil_Pebbles"
    },
    {
      "x": -11,
      "y": 55,
      "z": 1,
      "name": "Soil_Pebbles"
    },
    {
      "x": -11,
      "y": 56,
      "z": 1,
      "name": "Rock_Marble"
    },
    {
      "x": -11,
      "y": 57,
      "z": 1,
      "name": "Rock_Marble"
    },
    {
      "x": -11,
      "y": 58,
      "z": 1,
      "name": "Soil_Clay_White"
    },
    {
      "x": -11,
      "y": 59,
      "z": 1,
      "name": "Soil_Clay_White"
    },
    {
      "x": -11,
      "y": 60,
      "z": 1,
      "name": "Soil_Clay_White"
    },
    {
      "x": -11,
      "y": 61,
      "z": 1,
      "name": "Rock_Marble"
    },
    {
      "x": -11,
      "y": 62,
      "z": 1,
      "name": "Rock_Marble"
    },
    {
      "x": -11,
      "y": 63,
      "z": 1,
      "name": "Rock_Marble"
    },
    {
      "x": -11,
      "y": 64,
      "z": 1,
      "name": "Soil_Pebbles"
    },
    {
      "x": -11,
      "y": 65,
      "z": 1,
      "name": "Rock_Marble"
    },
    {
      "x": -11,
      "y": 66,
      "z": 1,
      "name": "Rock_Marble"
    },
    {
      "x": -11,
      "y": 67,
      "z": 1,
      "name": "Rock_Marble"
    },
    {
      "x": -11,
      "y": 68,
      "z": 1,
      "name": "Rock_Marble"
    },
    {
      "x": -11,
      "y": 69,
      "z": 1,
      "name": "Rock_Marble"
    },
    {
      "x": -11,
      "y": 70,
      "z": 1,
      "name": "Soil_Clay_White"
    },
    {
      "x": -11,
      "y": 71,
      "z": 1,
      "name": "Soil_Clay_White"
    },
    {
      "x": -11,
      "y": 72,
      "z": 1,
      "name": "Soil_Clay_White"
    },
    {
      "x": -11,
      "y": 73,
      "z": 1,
      "name": "Soil_Clay_White"
    },
    {
      "x": -11,
      "y": 74,
      "z": 1,
      "name": "Rock_Marble"
    },
    {
      "x": -11,
      "y": 75,
      "z": 1,
      "name": "Rock_Marble"
    },
    {
      "x": -11,
      "y": 76,
      "z": 1,
      "name": "Rock_Marble"
    },
    {
      "x": -11,
      "y": 77,
      "z": 1,
      "name": "Soil_Clay_White"
    },
    {
      "x": -11,
      "y": 38,
      "z": 2,
      "name": "Rock_Marble"
    },
    {
      "x": -11,
      "y": 39,
      "z": 2,
      "name": "Rock_Marble"
    },
    {
      "x": -11,
      "y": 40,
      "z": 2,
      "name": "Soil_Clay_White"
    },
    {
      "x": -11,
      "y": 41,
      "z": 2,
      "name": "Soil_Clay_White"
    },
    {
      "x": -11,
      "y": 42,
      "z": 2,
      "name": "Soil_Clay_White"
    },
    {
      "x": -11,
      "y": 43,
      "z": 2,
      "name": "Soil_Clay_White"
    },
    {
      "x": -11,
      "y": 44,
      "z": 2,
      "name": "Rock_Marble"
    },
    {
      "x": -11,
      "y": 45,
      "z": 2,
      "name": "Rock_Marble"
    },
    {
      "x": -11,
      "y": 46,
      "z": 2,
      "name": "Rock_Marble"
    },
    {
      "x": -11,
      "y": 47,
      "z": 2,
      "name": "Soil_Clay_White"
    },
    {
      "x": -11,
      "y": 48,
      "z": 2,
      "name": "Rock_Chalk"
    },
    {
      "x": -11,
      "y": 49,
      "z": 2,
      "name": "Rock_Chalk"
    },
    {
      "x": -11,
      "y": 50,
      "z": 2,
      "name": "Soil_Clay_White"
    },
    {
      "x": -11,
      "y": 51,
      "z": 2,
      "name": "Rock_Marble"
    },
    {
      "x": -11,
      "y": 52,
      "z": 2,
      "name": "Rock_Marble"
    },
    {
      "x": -11,
      "y": 53,
      "z": 2,
      "name": "Rock_Marble"
    },
    {
      "x": -11,
      "y": 54,
      "z": 2,
      "name": "Soil_Pebbles"
    },
    {
      "x": -11,
      "y": 55,
      "z": 2,
      "name": "Soil_Pebbles"
    },
    {
      "x": -11,
      "y": 56,
      "z": 2,
      "name": "Rock_Marble"
    },
    {
      "x": -11,
      "y": 57,
      "z": 2,
      "name": "Rock_Marble"
    },
    {
      "x": -11,
      "y": 58,
      "z": 2,
      "name": "Soil_Clay_White"
    },
    {
      "x": -11,
      "y": 59,
      "z": 2,
      "name": "Soil_Clay_White"
    },
    {
      "x": -11,
      "y": 60,
      "z": 2,
      "name": "Soil_Clay_White"
    },
    {
      "x": -11,
      "y": 61,
      "z": 2,
      "name": "Rock_Marble"
    },
    {
      "x": -11,
      "y": 62,
      "z": 2,
      "name": "Rock_Marble"
    },
    {
      "x": -11,
      "y": 63,
      "z": 2,
      "name": "Rock_Marble"
    },
    {
      "x": -11,
      "y": 64,
      "z": 2,
      "name": "Soil_Pebbles"
    },
    {
      "x": -11,
      "y": 65,
      "z": 2,
      "name": "Rock_Marble"
    },
    {
      "x": -11,
      "y": 66,
      "z": 2,
      "name": "Rock_Marble"
    },
    {
      "x": -11,
      "y": 67,
      "z": 2,
      "name": "Rock_Marble"
    },
    {
      "x": -11,
      "y": 68,
      "z": 2,
      "name": "Rock_Marble"
    },
    {
      "x": -11,
      "y": 69,
      "z": 2,
      "name": "Rock_Marble"
    },
    {
      "x": -11,
      "y": 70,
      "z": 2,
      "name": "Soil_Clay_White"
    },
    {
      "x": -11,
      "y": 71,
      "z": 2,
      "name": "Soil_Clay_White"
    },
    {
      "x": -11,
      "y": 72,
      "z": 2,
      "name": "Soil_Clay_White"
    },
    {
      "x": -11,
      "y": 73,
      "z": 2,
      "name": "Soil_Clay_White"
    },
    {
      "x": -11,
      "y": 74,
      "z": 2,
      "name": "Rock_Marble"
    },
    {
      "x": -11,
      "y": 75,
      "z": 2,
      "name": "Rock_Marble"
    },
    {
      "x": -11,
      "y": 40,
      "z": 3,
      "name": "Soil_Clay_White"
    },
    {
      "x": -11,
      "y": 41,
      "z": 3,
      "name": "Soil_Clay_White"
    },
    {
      "x": -11,
      "y": 42,
      "z": 3,
      "name": "Soil_Clay_White"
    },
    {
      "x": -11,
      "y": 43,
      "z": 3,
      "name": "Soil_Clay_White"
    },
    {
      "x": -11,
      "y": 44,
      "z": 3,
      "name": "Rock_Marble"
    },
    {
      "x": -11,
      "y": 45,
      "z": 3,
      "name": "Rock_Marble"
    },
    {
      "x": -11,
      "y": 46,
      "z": 3,
      "name": "Rock_Marble"
    },
    {
      "x": -11,
      "y": 47,
      "z": 3,
      "name": "Soil_Clay_White"
    },
    {
      "x": -11,
      "y": 48,
      "z": 3,
      "name": "Rock_Chalk"
    },
    {
      "x": -11,
      "y": 49,
      "z": 3,
      "name": "Rock_Chalk"
    },
    {
      "x": -11,
      "y": 50,
      "z": 3,
      "name": "Soil_Clay_White"
    },
    {
      "x": -11,
      "y": 51,
      "z": 3,
      "name": "Rock_Marble"
    },
    {
      "x": -11,
      "y": 52,
      "z": 3,
      "name": "Rock_Marble"
    },
    {
      "x": -11,
      "y": 53,
      "z": 3,
      "name": "Rock_Marble"
    },
    {
      "x": -11,
      "y": 54,
      "z": 3,
      "name": "Soil_Pebbles"
    },
    {
      "x": -11,
      "y": 55,
      "z": 3,
      "name": "Soil_Pebbles"
    },
    {
      "x": -11,
      "y": 56,
      "z": 3,
      "name": "Rock_Marble"
    },
    {
      "x": -11,
      "y": 57,
      "z": 3,
      "name": "Rock_Marble"
    },
    {
      "x": -11,
      "y": 58,
      "z": 3,
      "name": "Soil_Clay_White"
    },
    {
      "x": -11,
      "y": 59,
      "z": 3,
      "name": "Soil_Clay_White"
    },
    {
      "x": -11,
      "y": 60,
      "z": 3,
      "name": "Soil_Clay_White"
    },
    {
      "x": -11,
      "y": 61,
      "z": 3,
      "name": "Rock_Marble"
    },
    {
      "x": -11,
      "y": 62,
      "z": 3,
      "name": "Rock_Marble"
    },
    {
      "x": -11,
      "y": 63,
      "z": 3,
      "name": "Rock_Marble"
    },
    {
      "x": -11,
      "y": 64,
      "z": 3,
      "name": "Soil_Pebbles"
    },
    {
      "x": -11,
      "y": 65,
      "z": 3,
      "name": "Rock_Marble"
    },
    {
      "x": -11,
      "y": 66,
      "z": 3,
      "name": "Rock_Marble"
    },
    {
      "x": -11,
      "y": 67,
      "z": 3,
      "name": "Rock_Marble"
    },
    {
      "x": -11,
      "y": 68,
      "z": 3,
      "name": "Rock_Marble"
    },
    {
      "x": -11,
      "y": 69,
      "z": 3,
      "name": "Rock_Marble"
    },
    {
      "x": -11,
      "y": 70,
      "z": 3,
      "name": "Soil_Clay_White"
    },
    {
      "x": -11,
      "y": 71,
      "z": 3,
      "name": "Soil_Clay_White"
    },
    {
      "x": -11,
      "y": 41,
      "z": 4,
      "name": "Soil_Clay_White"
    },
    {
      "x": -11,
      "y": 42,
      "z": 4,
      "name": "Soil_Clay_White"
    },
    {
      "x": -11,
      "y": 43,
      "z": 4,
      "name": "Soil_Clay_White"
    },
    {
      "x": -11,
      "y": 44,
      "z": 4,
      "name": "Rock_Marble"
    },
    {
      "x": -11,
      "y": 45,
      "z": 4,
      "name": "Rock_Marble"
    },
    {
      "x": -11,
      "y": 46,
      "z": 4,
      "name": "Rock_Marble"
    },
    {
      "x": -11,
      "y": 47,
      "z": 4,
      "name": "Soil_Clay_White"
    },
    {
      "x": -11,
      "y": 48,
      "z": 4,
      "name": "Rock_Chalk"
    },
    {
      "x": -11,
      "y": 49,
      "z": 4,
      "name": "Rock_Chalk"
    },
    {
      "x": -11,
      "y": 50,
      "z": 4,
      "name": "Soil_Clay_White"
    },
    {
      "x": -11,
      "y": 51,
      "z": 4,
      "name": "Rock_Marble"
    },
    {
      "x": -11,
      "y": 52,
      "z": 4,
      "name": "Rock_Marble"
    },
    {
      "x": -11,
      "y": 53,
      "z": 4,
      "name": "Rock_Marble"
    },
    {
      "x": -11,
      "y": 54,
      "z": 4,
      "name": "Soil_Pebbles"
    },
    {
      "x": -11,
      "y": 55,
      "z": 4,
      "name": "Soil_Pebbles"
    },
    {
      "x": -11,
      "y": 56,
      "z": 4,
      "name": "Rock_Marble"
    },
    {
      "x": -11,
      "y": 57,
      "z": 4,
      "name": "Rock_Marble"
    },
    {
      "x": -11,
      "y": 58,
      "z": 4,
      "name": "Soil_Clay_White"
    },
    {
      "x": -11,
      "y": 59,
      "z": 4,
      "name": "Soil_Clay_White"
    },
    {
      "x": -11,
      "y": 60,
      "z": 4,
      "name": "Rock_Marble"
    },
    {
      "x": -11,
      "y": 61,
      "z": 4,
      "name": "Rock_Marble"
    },
    {
      "x": -11,
      "y": 62,
      "z": 4,
      "name": "Rock_Marble"
    },
    {
      "x": -11,
      "y": 63,
      "z": 4,
      "name": "Rock_Marble"
    },
    {
      "x": -11,
      "y": 64,
      "z": 4,
      "name": "Soil_Pebbles"
    },
    {
      "x": -11,
      "y": 65,
      "z": 4,
      "name": "Rock_Marble"
    },
    {
      "x": -11,
      "y": 66,
      "z": 4,
      "name": "Rock_Marble"
    },
    {
      "x": -11,
      "y": 67,
      "z": 4,
      "name": "Rock_Marble"
    },
    {
      "x": -11,
      "y": 45,
      "z": 5,
      "name": "Rock_Marble"
    },
    {
      "x": -11,
      "y": 46,
      "z": 5,
      "name": "Rock_Marble"
    },
    {
      "x": -11,
      "y": 47,
      "z": 5,
      "name": "Soil_Clay_White"
    },
    {
      "x": -11,
      "y": 48,
      "z": 5,
      "name": "Rock_Chalk"
    },
    {
      "x": -11,
      "y": 49,
      "z": 5,
      "name": "Rock_Chalk"
    },
    {
      "x": -11,
      "y": 50,
      "z": 5,
      "name": "Soil_Clay_White"
    },
    {
      "x": -11,
      "y": 51,
      "z": 5,
      "name": "Rock_Marble"
    },
    {
      "x": -11,
      "y": 52,
      "z": 5,
      "name": "Rock_Marble"
    },
    {
      "x": -11,
      "y": 53,
      "z": 5,
      "name": "Rock_Marble"
    },
    {
      "x": -11,
      "y": 54,
      "z": 5,
      "name": "Soil_Pebbles"
    },
    {
      "x": -11,
      "y": 55,
      "z": 5,
      "name": "Soil_Pebbles"
    },
    {
      "x": -11,
      "y": 56,
      "z": 5,
      "name": "Rock_Marble"
    },
    {
      "x": -11,
      "y": 57,
      "z": 5,
      "name": "Rock_Marble"
    },
    {
      "x": -11,
      "y": 58,
      "z": 5,
      "name": "Soil_Clay_White"
    },
    {
      "x": -11,
      "y": 59,
      "z": 5,
      "name": "Soil_Clay_White"
    },
    {
      "x": -11,
      "y": 60,
      "z": 5,
      "name": "Rock_Marble"
    },
    {
      "x": -11,
      "y": 61,
      "z": 5,
      "name": "Rock_Marble"
    },
    {
      "x": -11,
      "y": 62,
      "z": 5,
      "name": "Rock_Marble"
    },
    {
      "x": -11,
      "y": 63,
      "z": 5,
      "name": "Rock_Marble"
    },
    {
      "x": -11,
      "y": 64,
      "z": 5,
      "name": "Soil_Pebbles"
    },
    {
      "x": -11,
      "y": 49,
      "z": 6,
      "name": "Rock_Chalk"
    },
    {
      "x": -11,
      "y": 50,
      "z": 6,
      "name": "Soil_Clay_White"
    },
    {
      "x": -11,
      "y": 51,
      "z": 6,
      "name": "Rock_Marble"
    },
    {
      "x": -11,
      "y": 52,
      "z": 6,
      "name": "Rock_Marble"
    },
    {
      "x": -11,
      "y": 53,
      "z": 6,
      "name": "Rock_Marble"
    },
    {
      "x": -11,
      "y": 54,
      "z": 6,
      "name": "Soil_Pebbles"
    },
    {
      "x": -11,
      "y": 55,
      "z": 6,
      "name": "Soil_Pebbles"
    },
    {
      "x": -11,
      "y": 56,
      "z": 6,
      "name": "Rock_Marble"
    },
    {
      "x": -11,
      "y": 57,
      "z": 6,
      "name": "Rock_Marble"
    },
    {
      "x": -11,
      "y": 58,
      "z": 6,
      "name": "Soil_Clay_White"
    },
    {
      "x": -11,
      "y": 59,
      "z": 6,
      "name": "Soil_Clay_White"
    },
    {
      "x": -11,
      "y": 60,
      "z": 6,
      "name": "Rock_Marble"
    },
    {
      "x": -11,
      "y": 61,
      "z": 6,
      "name": "Rock_Marble"
    },
    {
      "x": -11,
      "y": 62,
      "z": 6,
      "name": "Rock_Marble"
    },
    {
      "x": -11,
      "y": 52,
      "z": 7,
      "name": "Rock_Marble"
    },
    {
      "x": -11,
      "y": 53,
      "z": 7,
      "name": "Rock_Marble"
    },
    {
      "x": -11,
      "y": 54,
      "z": 7,
      "name": "Soil_Pebbles"
    },
    {
      "x": -11,
      "y": 55,
      "z": 7,
      "name": "Soil_Pebbles"
    },
    {
      "x": -11,
      "y": 56,
      "z": 7,
      "name": "Rock_Marble"
    },
    {
      "x": -11,
      "y": 57,
      "z": 7,
      "name": "Soil_Clay_White"
    },
    {
      "x": -11,
      "y": 58,
      "z": 7,
      "name": "Soil_Clay_White"
    },
    {
      "x": -10,
      "y": 51,
      "z": -9,
      "name": "Rock_Marble"
    },
    {
      "x": -10,
      "y": 52,
      "z": -9,
      "name": "Rock_Marble"
    },
    {
      "x": -10,
      "y": 53,
      "z": -9,
      "name": "Rock_Marble"
    },
    {
      "x": -10,
      "y": 54,
      "z": -9,
      "name": "Soil_Pebbles"
    },
    {
      "x": -10,
      "y": 55,
      "z": -9,
      "name": "Soil_Pebbles"
    },
    {
      "x": -10,
      "y": 56,
      "z": -9,
      "name": "Rock_Marble"
    },
    {
      "x": -10,
      "y": 57,
      "z": -9,
      "name": "Rock_Marble"
    },
    {
      "x": -10,
      "y": 58,
      "z": -9,
      "name": "Soil_Clay_White"
    },
    {
      "x": -10,
      "y": 59,
      "z": -9,
      "name": "Soil_Clay_White"
    },
    {
      "x": -10,
      "y": 60,
      "z": -9,
      "name": "Soil_Clay_White"
    },
    {
      "x": -10,
      "y": 61,
      "z": -9,
      "name": "Rock_Marble"
    },
    {
      "x": -10,
      "y": 62,
      "z": -9,
      "name": "Rock_Marble"
    },
    {
      "x": -10,
      "y": 63,
      "z": -9,
      "name": "Rock_Marble"
    },
    {
      "x": -10,
      "y": 64,
      "z": -9,
      "name": "Soil_Pebbles"
    },
    {
      "x": -10,
      "y": 48,
      "z": -8,
      "name": "Rock_Chalk"
    },
    {
      "x": -10,
      "y": 49,
      "z": -8,
      "name": "Rock_Chalk"
    },
    {
      "x": -10,
      "y": 50,
      "z": -8,
      "name": "Soil_Clay_White"
    },
    {
      "x": -10,
      "y": 51,
      "z": -8,
      "name": "Rock_Marble"
    },
    {
      "x": -10,
      "y": 52,
      "z": -8,
      "name": "Rock_Marble"
    },
    {
      "x": -10,
      "y": 53,
      "z": -8,
      "name": "Rock_Marble"
    },
    {
      "x": -10,
      "y": 54,
      "z": -8,
      "name": "Soil_Pebbles"
    },
    {
      "x": -10,
      "y": 55,
      "z": -8,
      "name": "Soil_Pebbles"
    },
    {
      "x": -10,
      "y": 56,
      "z": -8,
      "name": "Rock_Marble"
    },
    {
      "x": -10,
      "y": 57,
      "z": -8,
      "name": "Rock_Marble"
    },
    {
      "x": -10,
      "y": 58,
      "z": -8,
      "name": "Soil_Clay_White"
    },
    {
      "x": -10,
      "y": 59,
      "z": -8,
      "name": "Soil_Clay_White"
    },
    {
      "x": -10,
      "y": 60,
      "z": -8,
      "name": "Soil_Clay_White"
    },
    {
      "x": -10,
      "y": 61,
      "z": -8,
      "name": "Rock_Marble"
    },
    {
      "x": -10,
      "y": 62,
      "z": -8,
      "name": "Rock_Marble"
    },
    {
      "x": -10,
      "y": 63,
      "z": -8,
      "name": "Rock_Marble"
    },
    {
      "x": -10,
      "y": 64,
      "z": -8,
      "name": "Soil_Pebbles"
    },
    {
      "x": -10,
      "y": 65,
      "z": -8,
      "name": "Rock_Marble"
    },
    {
      "x": -10,
      "y": 66,
      "z": -8,
      "name": "Rock_Marble"
    },
    {
      "x": -10,
      "y": 67,
      "z": -8,
      "name": "Rock_Marble"
    },
    {
      "x": -10,
      "y": 68,
      "z": -8,
      "name": "Rock_Marble"
    },
    {
      "x": -10,
      "y": 44,
      "z": -7,
      "name": "Rock_Marble"
    },
    {
      "x": -10,
      "y": 45,
      "z": -7,
      "name": "Rock_Marble"
    },
    {
      "x": -10,
      "y": 46,
      "z": -7,
      "name": "Rock_Marble"
    },
    {
      "x": -10,
      "y": 47,
      "z": -7,
      "name": "Soil_Clay_White"
    },
    {
      "x": -10,
      "y": 48,
      "z": -7,
      "name": "Rock_Chalk"
    },
    {
      "x": -10,
      "y": 49,
      "z": -7,
      "name": "Rock_Chalk"
    },
    {
      "x": -10,
      "y": 50,
      "z": -7,
      "name": "Soil_Clay_White"
    },
    {
      "x": -10,
      "y": 51,
      "z": -7,
      "name": "Rock_Marble"
    },
    {
      "x": -10,
      "y": 52,
      "z": -7,
      "name": "Rock_Marble"
    },
    {
      "x": -10,
      "y": 53,
      "z": -7,
      "name": "Rock_Marble"
    },
    {
      "x": -10,
      "y": 54,
      "z": -7,
      "name": "Soil_Pebbles"
    },
    {
      "x": -10,
      "y": 55,
      "z": -7,
      "name": "Soil_Pebbles"
    },
    {
      "x": -10,
      "y": 56,
      "z": -7,
      "name": "Rock_Marble"
    },
    {
      "x": -10,
      "y": 57,
      "z": -7,
      "name": "Rock_Marble"
    },
    {
      "x": -10,
      "y": 58,
      "z": -7,
      "name": "Soil_Clay_White"
    },
    {
      "x": -10,
      "y": 59,
      "z": -7,
      "name": "Soil_Clay_White"
    },
    {
      "x": -10,
      "y": 60,
      "z": -7,
      "name": "Soil_Clay_White"
    },
    {
      "x": -10,
      "y": 61,
      "z": -7,
      "name": "Rock_Marble"
    },
    {
      "x": -10,
      "y": 62,
      "z": -7,
      "name": "Rock_Marble"
    },
    {
      "x": -10,
      "y": 63,
      "z": -7,
      "name": "Rock_Marble"
    },
    {
      "x": -10,
      "y": 64,
      "z": -7,
      "name": "Soil_Pebbles"
    },
    {
      "x": -10,
      "y": 65,
      "z": -7,
      "name": "Rock_Marble"
    },
    {
      "x": -10,
      "y": 66,
      "z": -7,
      "name": "Rock_Marble"
    },
    {
      "x": -10,
      "y": 67,
      "z": -7,
      "name": "Rock_Marble"
    },
    {
      "x": -10,
      "y": 68,
      "z": -7,
      "name": "Rock_Marble"
    },
    {
      "x": -10,
      "y": 69,
      "z": -7,
      "name": "Rock_Marble"
    },
    {
      "x": -10,
      "y": 70,
      "z": -7,
      "name": "Soil_Clay_White"
    },
    {
      "x": -10,
      "y": 71,
      "z": -7,
      "name": "Soil_Clay_White"
    },
    {
      "x": -10,
      "y": 72,
      "z": -7,
      "name": "Soil_Clay_White"
    },
    {
      "x": -10,
      "y": 73,
      "z": -7,
      "name": "Soil_Clay_White"
    },
    {
      "x": -10,
      "y": 74,
      "z": -7,
      "name": "Rock_Marble"
    },
    {
      "x": -10,
      "y": 75,
      "z": -7,
      "name": "Rock_Marble"
    },
    {
      "x": -10,
      "y": 40,
      "z": -6,
      "name": "Soil_Clay_White"
    },
    {
      "x": -10,
      "y": 41,
      "z": -6,
      "name": "Soil_Clay_White"
    },
    {
      "x": -10,
      "y": 42,
      "z": -6,
      "name": "Soil_Clay_White"
    },
    {
      "x": -10,
      "y": 43,
      "z": -6,
      "name": "Soil_Clay_White"
    },
    {
      "x": -10,
      "y": 44,
      "z": -6,
      "name": "Rock_Marble"
    },
    {
      "x": -10,
      "y": 45,
      "z": -6,
      "name": "Rock_Marble"
    },
    {
      "x": -10,
      "y": 46,
      "z": -6,
      "name": "Rock_Marble"
    },
    {
      "x": -10,
      "y": 47,
      "z": -6,
      "name": "Soil_Clay_White"
    },
    {
      "x": -10,
      "y": 48,
      "z": -6,
      "name": "Rock_Chalk"
    },
    {
      "x": -10,
      "y": 49,
      "z": -6,
      "name": "Rock_Chalk"
    },
    {
      "x": -10,
      "y": 50,
      "z": -6,
      "name": "Soil_Clay_White"
    },
    {
      "x": -10,
      "y": 51,
      "z": -6,
      "name": "Rock_Marble"
    },
    {
      "x": -10,
      "y": 52,
      "z": -6,
      "name": "Rock_Marble"
    },
    {
      "x": -10,
      "y": 53,
      "z": -6,
      "name": "Rock_Marble"
    },
    {
      "x": -10,
      "y": 54,
      "z": -6,
      "name": "Soil_Pebbles"
    },
    {
      "x": -10,
      "y": 55,
      "z": -6,
      "name": "Soil_Pebbles"
    },
    {
      "x": -10,
      "y": 56,
      "z": -6,
      "name": "Rock_Marble"
    },
    {
      "x": -10,
      "y": 57,
      "z": -6,
      "name": "Rock_Marble"
    },
    {
      "x": -10,
      "y": 58,
      "z": -6,
      "name": "Soil_Clay_White"
    },
    {
      "x": -10,
      "y": 59,
      "z": -6,
      "name": "Soil_Clay_White"
    },
    {
      "x": -10,
      "y": 60,
      "z": -6,
      "name": "Soil_Clay_White"
    },
    {
      "x": -10,
      "y": 61,
      "z": -6,
      "name": "Rock_Marble"
    },
    {
      "x": -10,
      "y": 62,
      "z": -6,
      "name": "Rock_Marble"
    },
    {
      "x": -10,
      "y": 63,
      "z": -6,
      "name": "Rock_Marble"
    },
    {
      "x": -10,
      "y": 64,
      "z": -6,
      "name": "Soil_Pebbles"
    },
    {
      "x": -10,
      "y": 65,
      "z": -6,
      "name": "Rock_Marble"
    },
    {
      "x": -10,
      "y": 66,
      "z": -6,
      "name": "Rock_Marble"
    },
    {
      "x": -10,
      "y": 67,
      "z": -6,
      "name": "Rock_Marble"
    },
    {
      "x": -10,
      "y": 68,
      "z": -6,
      "name": "Rock_Marble"
    },
    {
      "x": -10,
      "y": 69,
      "z": -6,
      "name": "Rock_Marble"
    },
    {
      "x": -10,
      "y": 70,
      "z": -6,
      "name": "Soil_Clay_White"
    },
    {
      "x": -10,
      "y": 71,
      "z": -6,
      "name": "Soil_Clay_White"
    },
    {
      "x": -10,
      "y": 72,
      "z": -6,
      "name": "Soil_Clay_White"
    },
    {
      "x": -10,
      "y": 73,
      "z": -6,
      "name": "Soil_Clay_White"
    },
    {
      "x": -10,
      "y": 74,
      "z": -6,
      "name": "Rock_Marble"
    },
    {
      "x": -10,
      "y": 75,
      "z": -6,
      "name": "Rock_Marble"
    },
    {
      "x": -10,
      "y": 76,
      "z": -6,
      "name": "Rock_Marble"
    },
    {
      "x": -10,
      "y": 77,
      "z": -6,
      "name": "Soil_Clay_White"
    },
    {
      "x": -10,
      "y": 78,
      "z": -6,
      "name": "Soil_Clay_White"
    },
    {
      "x": -10,
      "y": 79,
      "z": -6,
      "name": "Soil_Clay_White"
    },
    {
      "x": -10,
      "y": 37,
      "z": -5,
      "name": "Rock_Marble"
    },
    {
      "x": -10,
      "y": 38,
      "z": -5,
      "name": "Rock_Marble"
    },
    {
      "x": -10,
      "y": 39,
      "z": -5,
      "name": "Rock_Marble"
    },
    {
      "x": -10,
      "y": 40,
      "z": -5,
      "name": "Soil_Clay_White"
    },
    {
      "x": -10,
      "y": 41,
      "z": -5,
      "name": "Soil_Clay_White"
    },
    {
      "x": -10,
      "y": 42,
      "z": -5,
      "name": "Soil_Clay_White"
    },
    {
      "x": -10,
      "y": 43,
      "z": -5,
      "name": "Soil_Clay_White"
    },
    {
      "x": -10,
      "y": 44,
      "z": -5,
      "name": "Rock_Marble"
    },
    {
      "x": -10,
      "y": 45,
      "z": -5,
      "name": "Rock_Marble"
    },
    {
      "x": -10,
      "y": 46,
      "z": -5,
      "name": "Rock_Marble"
    },
    {
      "x": -10,
      "y": 47,
      "z": -5,
      "name": "Soil_Clay_White"
    },
    {
      "x": -10,
      "y": 48,
      "z": -5,
      "name": "Rock_Chalk"
    },
    {
      "x": -10,
      "y": 49,
      "z": -5,
      "name": "Rock_Chalk"
    },
    {
      "x": -10,
      "y": 50,
      "z": -5,
      "name": "Soil_Clay_White"
    },
    {
      "x": -10,
      "y": 51,
      "z": -5,
      "name": "Rock_Marble"
    },
    {
      "x": -10,
      "y": 52,
      "z": -5,
      "name": "Rock_Marble"
    },
    {
      "x": -10,
      "y": 53,
      "z": -5,
      "name": "Rock_Marble"
    },
    {
      "x": -10,
      "y": 54,
      "z": -5,
      "name": "Soil_Pebbles"
    },
    {
      "x": -10,
      "y": 55,
      "z": -5,
      "name": "Soil_Pebbles"
    },
    {
      "x": -10,
      "y": 56,
      "z": -5,
      "name": "Rock_Marble"
    },
    {
      "x": -10,
      "y": 57,
      "z": -5,
      "name": "Rock_Marble"
    },
    {
      "x": -10,
      "y": 58,
      "z": -5,
      "name": "Soil_Clay_White"
    },
    {
      "x": -10,
      "y": 59,
      "z": -5,
      "name": "Soil_Clay_White"
    },
    {
      "x": -10,
      "y": 60,
      "z": -5,
      "name": "Soil_Clay_White"
    },
    {
      "x": -10,
      "y": 61,
      "z": -5,
      "name": "Rock_Marble"
    },
    {
      "x": -10,
      "y": 62,
      "z": -5,
      "name": "Rock_Marble"
    },
    {
      "x": -10,
      "y": 63,
      "z": -5,
      "name": "Rock_Marble"
    },
    {
      "x": -10,
      "y": 64,
      "z": -5,
      "name": "Soil_Pebbles"
    },
    {
      "x": -10,
      "y": 65,
      "z": -5,
      "name": "Rock_Marble"
    },
    {
      "x": -10,
      "y": 66,
      "z": -5,
      "name": "Rock_Marble"
    },
    {
      "x": -10,
      "y": 67,
      "z": -5,
      "name": "Rock_Marble"
    },
    {
      "x": -10,
      "y": 68,
      "z": -5,
      "name": "Rock_Marble"
    },
    {
      "x": -10,
      "y": 69,
      "z": -5,
      "name": "Rock_Marble"
    },
    {
      "x": -10,
      "y": 70,
      "z": -5,
      "name": "Soil_Clay_White"
    },
    {
      "x": -10,
      "y": 71,
      "z": -5,
      "name": "Soil_Clay_White"
    },
    {
      "x": -10,
      "y": 72,
      "z": -5,
      "name": "Soil_Clay_White"
    },
    {
      "x": -10,
      "y": 73,
      "z": -5,
      "name": "Soil_Clay_White"
    },
    {
      "x": -10,
      "y": 74,
      "z": -5,
      "name": "Rock_Marble"
    },
    {
      "x": -10,
      "y": 75,
      "z": -5,
      "name": "Rock_Marble"
    },
    {
      "x": -10,
      "y": 76,
      "z": -5,
      "name": "Rock_Marble"
    },
    {
      "x": -10,
      "y": 77,
      "z": -5,
      "name": "Soil_Clay_White"
    },
    {
      "x": -10,
      "y": 78,
      "z": -5,
      "name": "Soil_Clay_White"
    },
    {
      "x": -10,
      "y": 79,
      "z": -5,
      "name": "Soil_Clay_White"
    },
    {
      "x": -10,
      "y": 80,
      "z": -5,
      "name": "Soil_Clay_White"
    },
    {
      "x": -10,
      "y": 81,
      "z": -5,
      "name": "Soil_Clay_White"
    },
    {
      "x": -10,
      "y": 82,
      "z": -5,
      "name": "Soil_Clay_White"
    },
    {
      "x": -10,
      "y": 83,
      "z": -5,
      "name": "Soil_Clay_White"
    },
    {
      "x": -10,
      "y": 84,
      "z": -5,
      "name": "Soil_Clay_White"
    },
    {
      "x": -10,
      "y": 85,
      "z": -5,
      "name": "Soil_Clay_White"
    },
    {
      "x": -10,
      "y": 86,
      "z": -5,
      "name": "Rock_Marble"
    },
    {
      "x": -10,
      "y": 36,
      "z": -4,
      "name": "Rock_Marble"
    },
    {
      "x": -10,
      "y": 37,
      "z": -4,
      "name": "Rock_Marble"
    },
    {
      "x": -10,
      "y": 38,
      "z": -4,
      "name": "Rock_Marble"
    },
    {
      "x": -10,
      "y": 39,
      "z": -4,
      "name": "Rock_Marble"
    },
    {
      "x": -10,
      "y": 40,
      "z": -4,
      "name": "Soil_Clay_White"
    },
    {
      "x": -10,
      "y": 41,
      "z": -4,
      "name": "Soil_Clay_White"
    },
    {
      "x": -10,
      "y": 42,
      "z": -4,
      "name": "Soil_Clay_White"
    },
    {
      "x": -10,
      "y": 43,
      "z": -4,
      "name": "Soil_Clay_White"
    },
    {
      "x": -10,
      "y": 44,
      "z": -4,
      "name": "Rock_Marble"
    },
    {
      "x": -10,
      "y": 45,
      "z": -4,
      "name": "Rock_Marble"
    },
    {
      "x": -10,
      "y": 46,
      "z": -4,
      "name": "Rock_Marble"
    },
    {
      "x": -10,
      "y": 47,
      "z": -4,
      "name": "Soil_Clay_White"
    },
    {
      "x": -10,
      "y": 48,
      "z": -4,
      "name": "Rock_Chalk"
    },
    {
      "x": -10,
      "y": 49,
      "z": -4,
      "name": "Rock_Chalk"
    },
    {
      "x": -10,
      "y": 50,
      "z": -4,
      "name": "Soil_Clay_White"
    },
    {
      "x": -10,
      "y": 51,
      "z": -4,
      "name": "Rock_Marble"
    },
    {
      "x": -10,
      "y": 52,
      "z": -4,
      "name": "Rock_Marble"
    },
    {
      "x": -10,
      "y": 53,
      "z": -4,
      "name": "Rock_Marble"
    },
    {
      "x": -10,
      "y": 54,
      "z": -4,
      "name": "Soil_Pebbles"
    },
    {
      "x": -10,
      "y": 55,
      "z": -4,
      "name": "Soil_Pebbles"
    },
    {
      "x": -10,
      "y": 56,
      "z": -4,
      "name": "Rock_Marble"
    },
    {
      "x": -10,
      "y": 57,
      "z": -4,
      "name": "Rock_Marble"
    },
    {
      "x": -10,
      "y": 58,
      "z": -4,
      "name": "Soil_Clay_White"
    },
    {
      "x": -10,
      "y": 59,
      "z": -4,
      "name": "Soil_Clay_White"
    },
    {
      "x": -10,
      "y": 60,
      "z": -4,
      "name": "Soil_Clay_White"
    },
    {
      "x": -10,
      "y": 61,
      "z": -4,
      "name": "Rock_Marble"
    },
    {
      "x": -10,
      "y": 62,
      "z": -4,
      "name": "Rock_Marble"
    },
    {
      "x": -10,
      "y": 63,
      "z": -4,
      "name": "Rock_Marble"
    },
    {
      "x": -10,
      "y": 64,
      "z": -4,
      "name": "Soil_Pebbles"
    },
    {
      "x": -10,
      "y": 65,
      "z": -4,
      "name": "Rock_Marble"
    },
    {
      "x": -10,
      "y": 66,
      "z": -4,
      "name": "Rock_Marble"
    },
    {
      "x": -10,
      "y": 67,
      "z": -4,
      "name": "Rock_Marble"
    },
    {
      "x": -10,
      "y": 68,
      "z": -4,
      "name": "Rock_Marble"
    },
    {
      "x": -10,
      "y": 69,
      "z": -4,
      "name": "Rock_Marble"
    },
    {
      "x": -10,
      "y": 70,
      "z": -4,
      "name": "Soil_Clay_White"
    },
    {
      "x": -10,
      "y": 71,
      "z": -4,
      "name": "Soil_Clay_White"
    },
    {
      "x": -10,
      "y": 72,
      "z": -4,
      "name": "Soil_Clay_White"
    },
    {
      "x": -10,
      "y": 73,
      "z": -4,
      "name": "Soil_Clay_White"
    },
    {
      "x": -10,
      "y": 74,
      "z": -4,
      "name": "Rock_Marble"
    },
    {
      "x": -10,
      "y": 75,
      "z": -4,
      "name": "Rock_Marble"
    },
    {
      "x": -10,
      "y": 76,
      "z": -4,
      "name": "Rock_Marble"
    },
    {
      "x": -10,
      "y": 77,
      "z": -4,
      "name": "Soil_Clay_White"
    },
    {
      "x": -10,
      "y": 78,
      "z": -4,
      "name": "Soil_Clay_White"
    },
    {
      "x": -10,
      "y": 79,
      "z": -4,
      "name": "Soil_Clay_White"
    },
    {
      "x": -10,
      "y": 80,
      "z": -4,
      "name": "Soil_Clay_White"
    },
    {
      "x": -10,
      "y": 81,
      "z": -4,
      "name": "Soil_Clay_White"
    },
    {
      "x": -10,
      "y": 82,
      "z": -4,
      "name": "Soil_Clay_White"
    },
    {
      "x": -10,
      "y": 83,
      "z": -4,
      "name": "Soil_Clay_White"
    },
    {
      "x": -10,
      "y": 84,
      "z": -4,
      "name": "Soil_Clay_White"
    },
    {
      "x": -10,
      "y": 85,
      "z": -4,
      "name": "Soil_Clay_White"
    },
    {
      "x": -10,
      "y": 86,
      "z": -4,
      "name": "Rock_Marble"
    },
    {
      "x": -10,
      "y": 87,
      "z": -4,
      "name": "Soil_Pebbles"
    },
    {
      "x": -10,
      "y": 35,
      "z": -3,
      "name": "Rock_Marble"
    },
    {
      "x": -10,
      "y": 36,
      "z": -3,
      "name": "Rock_Marble"
    },
    {
      "x": -10,
      "y": 37,
      "z": -3,
      "name": "Rock_Marble"
    },
    {
      "x": -10,
      "y": 38,
      "z": -3,
      "name": "Rock_Marble"
    },
    {
      "x": -10,
      "y": 39,
      "z": -3,
      "name": "Rock_Marble"
    },
    {
      "x": -10,
      "y": 40,
      "z": -3,
      "name": "Soil_Clay_White"
    },
    {
      "x": -10,
      "y": 41,
      "z": -3,
      "name": "Soil_Clay_White"
    },
    {
      "x": -10,
      "y": 42,
      "z": -3,
      "name": "Soil_Clay_White"
    },
    {
      "x": -10,
      "y": 43,
      "z": -3,
      "name": "Soil_Clay_White"
    },
    {
      "x": -10,
      "y": 44,
      "z": -3,
      "name": "Rock_Marble"
    },
    {
      "x": -10,
      "y": 45,
      "z": -3,
      "name": "Rock_Marble"
    },
    {
      "x": -10,
      "y": 46,
      "z": -3,
      "name": "Rock_Marble"
    },
    {
      "x": -10,
      "y": 47,
      "z": -3,
      "name": "Soil_Clay_White"
    },
    {
      "x": -10,
      "y": 48,
      "z": -3,
      "name": "Rock_Chalk"
    },
    {
      "x": -10,
      "y": 49,
      "z": -3,
      "name": "Rock_Chalk"
    },
    {
      "x": -10,
      "y": 50,
      "z": -3,
      "name": "Soil_Clay_White"
    },
    {
      "x": -10,
      "y": 51,
      "z": -3,
      "name": "Rock_Marble"
    },
    {
      "x": -10,
      "y": 52,
      "z": -3,
      "name": "Rock_Marble"
    },
    {
      "x": -10,
      "y": 53,
      "z": -3,
      "name": "Rock_Marble"
    },
    {
      "x": -10,
      "y": 54,
      "z": -3,
      "name": "Soil_Pebbles"
    },
    {
      "x": -10,
      "y": 55,
      "z": -3,
      "name": "Soil_Pebbles"
    },
    {
      "x": -10,
      "y": 56,
      "z": -3,
      "name": "Rock_Marble"
    },
    {
      "x": -10,
      "y": 57,
      "z": -3,
      "name": "Rock_Marble"
    },
    {
      "x": -10,
      "y": 58,
      "z": -3,
      "name": "Soil_Clay_White"
    },
    {
      "x": -10,
      "y": 59,
      "z": -3,
      "name": "Soil_Clay_White"
    },
    {
      "x": -10,
      "y": 60,
      "z": -3,
      "name": "Soil_Clay_White"
    },
    {
      "x": -10,
      "y": 61,
      "z": -3,
      "name": "Rock_Marble"
    },
    {
      "x": -10,
      "y": 62,
      "z": -3,
      "name": "Rock_Marble"
    },
    {
      "x": -10,
      "y": 63,
      "z": -3,
      "name": "Rock_Marble"
    },
    {
      "x": -10,
      "y": 64,
      "z": -3,
      "name": "Soil_Pebbles"
    },
    {
      "x": -10,
      "y": 65,
      "z": -3,
      "name": "Rock_Marble"
    },
    {
      "x": -10,
      "y": 66,
      "z": -3,
      "name": "Rock_Marble"
    },
    {
      "x": -10,
      "y": 67,
      "z": -3,
      "name": "Rock_Marble"
    },
    {
      "x": -10,
      "y": 68,
      "z": -3,
      "name": "Rock_Marble"
    },
    {
      "x": -10,
      "y": 69,
      "z": -3,
      "name": "Rock_Marble"
    },
    {
      "x": -10,
      "y": 70,
      "z": -3,
      "name": "Soil_Clay_White"
    },
    {
      "x": -10,
      "y": 71,
      "z": -3,
      "name": "Soil_Clay_White"
    },
    {
      "x": -10,
      "y": 72,
      "z": -3,
      "name": "Soil_Clay_White"
    },
    {
      "x": -10,
      "y": 73,
      "z": -3,
      "name": "Soil_Clay_White"
    },
    {
      "x": -10,
      "y": 74,
      "z": -3,
      "name": "Rock_Marble"
    },
    {
      "x": -10,
      "y": 75,
      "z": -3,
      "name": "Rock_Marble"
    },
    {
      "x": -10,
      "y": 76,
      "z": -3,
      "name": "Rock_Marble"
    },
    {
      "x": -10,
      "y": 77,
      "z": -3,
      "name": "Soil_Clay_White"
    },
    {
      "x": -10,
      "y": 78,
      "z": -3,
      "name": "Soil_Clay_White"
    },
    {
      "x": -10,
      "y": 79,
      "z": -3,
      "name": "Soil_Clay_White"
    },
    {
      "x": -10,
      "y": 80,
      "z": -3,
      "name": "Soil_Clay_White"
    },
    {
      "x": -10,
      "y": 81,
      "z": -3,
      "name": "Soil_Clay_White"
    },
    {
      "x": -10,
      "y": 82,
      "z": -3,
      "name": "Soil_Clay_White"
    },
    {
      "x": -10,
      "y": 83,
      "z": -3,
      "name": "Soil_Clay_White"
    },
    {
      "x": -10,
      "y": 84,
      "z": -3,
      "name": "Soil_Clay_White"
    },
    {
      "x": -10,
      "y": 85,
      "z": -3,
      "name": "Soil_Clay_White"
    },
    {
      "x": -10,
      "y": 86,
      "z": -3,
      "name": "Rock_Marble"
    },
    {
      "x": -10,
      "y": 87,
      "z": -3,
      "name": "Soil_Pebbles"
    },
    {
      "x": -10,
      "y": 88,
      "z": -3,
      "name": "Soil_Pebbles"
    },
    {
      "x": -10,
      "y": 35,
      "z": -2,
      "name": "Rock_Marble"
    },
    {
      "x": -10,
      "y": 36,
      "z": -2,
      "name": "Rock_Marble"
    },
    {
      "x": -10,
      "y": 37,
      "z": -2,
      "name": "Rock_Marble"
    },
    {
      "x": -10,
      "y": 38,
      "z": -2,
      "name": "Rock_Marble"
    },
    {
      "x": -10,
      "y": 39,
      "z": -2,
      "name": "Rock_Marble"
    },
    {
      "x": -10,
      "y": 40,
      "z": -2,
      "name": "Soil_Clay_White"
    },
    {
      "x": -10,
      "y": 41,
      "z": -2,
      "name": "Soil_Clay_White"
    },
    {
      "x": -10,
      "y": 42,
      "z": -2,
      "name": "Soil_Clay_White"
    },
    {
      "x": -10,
      "y": 43,
      "z": -2,
      "name": "Soil_Clay_White"
    },
    {
      "x": -10,
      "y": 44,
      "z": -2,
      "name": "Rock_Marble"
    },
    {
      "x": -10,
      "y": 45,
      "z": -2,
      "name": "Rock_Marble"
    },
    {
      "x": -10,
      "y": 46,
      "z": -2,
      "name": "Rock_Marble"
    },
    {
      "x": -10,
      "y": 47,
      "z": -2,
      "name": "Soil_Clay_White"
    },
    {
      "x": -10,
      "y": 48,
      "z": -2,
      "name": "Rock_Chalk"
    },
    {
      "x": -10,
      "y": 49,
      "z": -2,
      "name": "Rock_Chalk"
    },
    {
      "x": -10,
      "y": 50,
      "z": -2,
      "name": "Soil_Clay_White"
    },
    {
      "x": -10,
      "y": 51,
      "z": -2,
      "name": "Rock_Marble"
    },
    {
      "x": -10,
      "y": 52,
      "z": -2,
      "name": "Rock_Marble"
    },
    {
      "x": -10,
      "y": 53,
      "z": -2,
      "name": "Rock_Marble"
    },
    {
      "x": -10,
      "y": 54,
      "z": -2,
      "name": "Soil_Pebbles"
    },
    {
      "x": -10,
      "y": 55,
      "z": -2,
      "name": "Soil_Pebbles"
    },
    {
      "x": -10,
      "y": 56,
      "z": -2,
      "name": "Rock_Marble"
    },
    {
      "x": -10,
      "y": 57,
      "z": -2,
      "name": "Rock_Marble"
    },
    {
      "x": -10,
      "y": 58,
      "z": -2,
      "name": "Soil_Clay_White"
    },
    {
      "x": -10,
      "y": 59,
      "z": -2,
      "name": "Soil_Clay_White"
    },
    {
      "x": -10,
      "y": 60,
      "z": -2,
      "name": "Soil_Clay_White"
    },
    {
      "x": -10,
      "y": 61,
      "z": -2,
      "name": "Rock_Marble"
    },
    {
      "x": -10,
      "y": 62,
      "z": -2,
      "name": "Rock_Marble"
    },
    {
      "x": -10,
      "y": 63,
      "z": -2,
      "name": "Rock_Marble"
    },
    {
      "x": -10,
      "y": 64,
      "z": -2,
      "name": "Soil_Pebbles"
    },
    {
      "x": -10,
      "y": 65,
      "z": -2,
      "name": "Rock_Marble"
    },
    {
      "x": -10,
      "y": 66,
      "z": -2,
      "name": "Rock_Marble"
    },
    {
      "x": -10,
      "y": 67,
      "z": -2,
      "name": "Rock_Marble"
    },
    {
      "x": -10,
      "y": 68,
      "z": -2,
      "name": "Rock_Marble"
    },
    {
      "x": -10,
      "y": 69,
