{
  "version": 8,
  "blockIdVersion": 11,
  "anchorX": 9,
  "anchorY": 4,
  "anchorZ": 6,
  "blocks": [
    {
      "x": 6,
      "y": 5,
      "z": 4,
      "name": "Plant_Bush"
    },
    {
      "x": 6,
      "y": 4,
      "z": 5,
      "name": "Plant_Bush"
    },
    {
      "x": 6,
      "y": 5,
      "z": 5,
      "name": "Plant_Bush"
    },
    {
      "x": 6,
      "y": 3,
      "z": 6,
      "name": "Plant_Bush"
    },
    {
      "x": 6,
      "y": 4,
      "z": 6,
      "name": "Plant_Bush"
    },
    {
      "x": 6,
      "y": 5,
      "z": 6,
      "name": "Plant_Bush"
    },
    {
      "x": 6,
      "y": 3,
      "z": 7,
      "name": "Plant_Bush"
    },
    {
      "x": 6,
      "y": 4,
      "z": 7,
      "name": "Plant_Bush"
    },
    {
      "x": 6,
      "y": 5,
      "z": 7,
      "name": "Plant_Bush"
    },
    {
      "x": 7,
      "y": 4,
      "z": 3,
      "name": "Plant_Bush"
    },
    {
      "x": 7,
      "y": 5,
      "z": 3,
      "name": "Plant_Bush"
    },
    {
      "x": 7,
      "y": 3,
      "z": 4,
      "name": "Plant_Bush"
    },
    {
      "x": 7,
      "y": 4,
      "z": 4,
      "name": "Plant_Bush"
    },
    {
      "x": 7,
      "y": 5,
      "z": 4,
      "name": "Plant_Bush"
    },
    {
      "x": 7,
      "y": 6,
      "z": 4,
      "name": "Plant_Bush"
    },
    {
      "x": 7,
      "y": 3,
      "z": 5,
      "name": "Plant_Bush"
    },
    {
      "x": 7,
      "y": 4,
      "z": 5,
      "name": "Plant_Bush"
    },
    {
      "x": 7,
      "y": 5,
      "z": 5,
      "name": "Plant_Bush"
    },
    {
      "x": 7,
      "y": 3,
      "z": 6,
      "name": "Plant_Bush"
    },
    {
      "x": 7,
      "y": 4,
      "z": 6,
      "name": "Plant_Bush"
    },
    {
      "x": 7,
      "y": 5,
      "z": 6,
      "name": "Plant_Bush"
    },
    {
      "x": 7,
      "y": 3,
      "z": 7,
      "name": "Plant_Bush"
    },
    {
      "x": 7,
      "y": 4,
      "z": 7,
      "name": "Plant_Bush"
    },
    {
      "x": 7,
      "y": 5,
      "z": 7,
      "name": "Plant_Bush"
    },
    {
      "x": 7,
      "y": 6,
      "z": 7,
      "name": "Plant_Bush"
    },
    {
      "x": 7,
      "y": 3,
      "z": 8,
      "name": "Plant_Bush"
    },
    {
      "x": 7,
      "y": 4,
      "z": 8,
      "name": "Plant_Bush"
    },
    {
      "x": 7,
      "y": 5,
      "z": 8,
      "name": "Plant_Bush"
    },
    {
      "x": 8,
      "y": 5,
      "z": 2,
      "name": "Plant_Bush"
    },
    {
      "x": 8,
      "y": 3,
      "z": 3,
      "name": "Plant_Bush"
    },
    {
      "x": 8,
      "y": 4,
      "z": 3,
      "name": "Plant_Bush"
    },
    {
      "x": 8,
      "y": 5,
      "z": 3,
      "name": "Plant_Bush"
    },
    {
      "x": 8,
      "y": 6,
      "z": 3,
      "name": "Plant_Bush"
    },
    {
      "x": 8,
      "y": 2,
      "z": 4,
      "name": "Plant_Bush"
    },
    {
      "x": 8,
      "y": 3,
      "z": 4,
      "name": "Plant_Bush"
    },
    {
      "x": 8,
      "y": 4,
      "z": 4,
      "name": "Plant_Bush"
    },
    {
      "x": 8,
      "y": 5,
      "z": 4,
      "name": "Plant_Bush"
    },
    {
      "x": 8,
      "y": 6,
      "z": 4,
      "name": "Plant_Bush"
    },
    {
      "x": 8,
      "y": 2,
      "z": 5,
      "name": "Plant_Bush"
    },
    {
      "x": 8,
      "y": 3,
      "z": 5,
      "name": "Plant_Bush"
    },
    {
      "x": 8,
      "y": 4,
      "z": 5,
      "name": "Plant_Bush"
    },
    {
      "x": 8,
      "y": 5,
      "z": 5,
      "name": "Plant_Bush"
    },
    {
      "x": 8,
      "y": 6,
      "z": 5,
      "name": "Plant_Bush"
    },
    {
      "x": 8,
      "y": 2,
      "z": 6,
      "name": "Plant_Bush"
    },
    {
      "x": 8,
      "y": 3,
      "z": 6,
      "name": "Plant_Bush"
    },
    {
      "x": 8,
      "y": 4,
      "z": 6,
      "name": "Plant_Bush"
    },
    {
      "x": 8,
      "y": 5,
      "z": 6,
      "name": "Plant_Bush"
    },
    {
      "x": 8,
      "y": 6,
      "z": 6,
      "name": "Plant_Bush"
    },
    {
      "x": 8,
      "y": 2,
      "z": 7,
      "name": "Plant_Bush"
    },
    {
      "x": 8,
      "y": 3,
      "z": 7,
      "name": "Plant_Bush"
    },
    {
      "x": 8,
      "y": 4,
      "z": 7,
      "name": "Plant_Bush"
    },
    {
      "x": 8,
      "y": 5,
      "z": 7,
      "name": "Plant_Bush"
    },
    {
      "x": 8,
      "y": 6,
      "z": 7,
      "name": "Plant_Bush"
    },
    {
      "x": 8,
      "y": 2,
      "z": 8,
      "name": "Plant_Bush"
    },
    {
      "x": 8,
      "y": 3,
      "z": 8,
      "name": "Plant_Bush"
    },
    {
      "x": 8,
      "y": 4,
      "z": 8,
      "name": "Plant_Bush"
    },
    {
      "x": 8,
      "y": 5,
      "z": 8,
      "name": "Plant_Bush"
    },
    {
      "x": 8,
      "y": 6,
      "z": 8,
      "name": "Plant_Bush"
    },
    {
      "x": 8,
      "y": 4,
      "z": 9,
      "name": "Plant_Bush"
    },
    {
      "x": 8,
      "y": 5,
      "z": 9,
      "name": "Plant_Bush"
    },
    {
      "x": 9,
      "y": 3,
      "z": 3,
      "name": "Plant_Bush"
    },
    {
      "x": 9,
      "y": 4,
      "z": 3,
      "name": "Plant_Bush"
    },
    {
      "x": 9,
      "y": 5,
      "z": 3,
      "name": "Plant_Bush"
    },
    {
      "x": 9,
      "y": 2,
      "z": 4,
      "name": "Plant_Bush"
    },
    {
      "x": 9,
      "y": 3,
      "z": 4,
      "name": "Plant_Bush"
    },
    {
      "x": 9,
      "y": 4,
      "z": 4,
      "name": "Plant_Bush"
    },
    {
      "x": 9,
      "y": 5,
      "z": 4,
      "name": "Plant_Bush"
    },
    {
      "x": 9,
      "y": 6,
      "z": 4,
      "name": "Plant_Bush"
    },
    {
      "x": 9,
      "y": 3,
      "z": 5,
      "name": "Plant_Bush"
    },
    {
      "x": 9,
      "y": 4,
      "z": 5,
      "name": "Plant_Bush"
    },
    {
      "x": 9,
      "y": 5,
      "z": 5,
      "name": "Plant_Bush"
    },
    {
      "x": 9,
      "y": 6,
      "z": 5,
      "name": "Plant_Bush"
    },
    {
      "x": 9,
      "y": 2,
      "z": 6,
      "name": "Plant_Bush"
    },
    {
      "x": 9,
      "y": 3,
      "z": 6,
      "name": "Plant_Bush"
    },
    {
      "x": 9,
      "y": 4,
      "z": 6,
      "name": "Plant_Bush"
    },
    {
      "x": 9,
      "y": 5,
      "z": 6,
      "name": "Plant_Bush"
    },
    {
      "x": 9,
      "y": 6,
      "z": 6,
      "name": "Plant_Bush"
    },
    {
      "x": 9,
      "y": 2,
      "z": 7,
      "name": "Plant_Bush"
    },
    {
      "x": 9,
      "y": 3,
      "z": 7,
      "name": "Plant_Bush"
    },
    {
      "x": 9,
      "y": 4,
      "z": 7,
      "name": "Plant_Bush"
    },
    {
      "x": 9,
      "y": 5,
      "z": 7,
      "name": "Plant_Bush"
    },
    {
      "x": 9,
      "y": 6,
      "z": 7,
      "name": "Plant_Bush"
    },
    {
      "x": 9,
      "y": 3,
      "z": 8,
      "name": "Plant_Bush"
    },
    {
      "x": 9,
      "y": 4,
      "z": 8,
      "name": "Plant_Bush"
    },
    {
      "x": 9,
      "y": 5,
      "z": 8,
      "name": "Plant_Bush"
    },
    {
      "x": 9,
      "y": 4,
      "z": 9,
      "name": "Plant_Bush"
    },
    {
      "x": 10,
      "y": 3,
      "z": 4,
      "name": "Plant_Bush"
    },
    {
      "x": 10,
      "y": 4,
      "z": 4,
      "name": "Plant_Bush"
    },
    {
      "x": 10,
      "y": 5,
      "z": 4,
      "name": "Plant_Bush"
    },
    {
      "x": 10,
      "y": 3,
      "z": 5,
      "name": "Plant_Bush"
    },
    {
      "x": 10,
      "y": 4,
      "z": 5,
      "name": "Plant_Bush"
    },
    {
      "x": 10,
      "y": 5,
      "z": 5,
      "name": "Plant_Bush"
    },
    {
      "x": 10,
      "y": 6,
      "z": 5,
      "name": "Plant_Bush"
    },
    {
      "x": 10,
      "y": 3,
      "z": 6,
      "name": "Plant_Bush"
    },
    {
      "x": 10,
      "y": 4,
      "z": 6,
      "name": "Plant_Bush"
    },
    {
      "x": 10,
      "y": 5,
      "z": 6,
      "name": "Plant_Bush"
    },
    {
      "x": 10,
      "y": 6,
      "z": 6,
      "name": "Plant_Bush"
    },
    {
      "x": 10,
      "y": 3,
      "z": 7,
      "name": "Plant_Bush"
    },
    {
      "x": 10,
      "y": 4,
      "z": 7,
      "name": "Plant_Bush"
    },
    {
      "x": 10,
      "y": 5,
      "z": 7,
      "name": "Plant_Bush"
    },
    {
      "x": 10,
      "y": 6,
      "z": 7,
      "name": "Plant_Bush"
    },
    {
      "x": 10,
      "y": 4,
      "z": 8,
      "name": "Plant_Bush"
    },
    {
      "x": 10,
      "y": 5,
      "z": 9,
      "name": "Plant_Bush"
    },
    {
      "x": 11,
      "y": 5,
      "z": 6,
      "name": "Plant_Bush"
    }
  ]
}