{
  "version": 8,
  "blockIdVersion": 11,
  "anchorX": 6,
  "anchorY": 3,
  "anchorZ": 3,
  "blocks": [
    {
      "x": 3,
      "y": 3,
      "z": 3,
      "name": "Plant_Bush"
    },
    {
      "x": 3,
      "y": 4,
      "z": 3,
      "name": "Plant_Bush"
    },
    {
      "x": 3,
      "y": 4,
      "z": 4,
      "name": "Plant_Bush"
    },
    {
      "x": 3,
      "y": 3,
      "z": 5,
      "name": "Plant_Bush"
    },
    {
      "x": 3,
      "y": 4,
      "z": 5,
      "name": "Plant_Bush"
    },
    {
      "x": 4,
      "y": 3,
      "z": 2,
      "name": "Plant_Bush"
    },
    {
      "x": 4,
      "y": 4,
      "z": 2,
      "name": "Plant_Bush"
    },
    {
      "x": 4,
      "y": 2,
      "z": 3,
      "name": "Plant_Bush"
    },
    {
      "x": 4,
      "y": 3,
      "z": 3,
      "name": "Plant_Bush"
    },
    {
      "x": 4,
      "y": 4,
      "z": 3,
      "name": "Plant_Bush"
    },
    {
      "x": 4,
      "y": 5,
      "z": 3,
      "name": "Plant_Bush"
    },
    {
      "x": 4,
      "y": 2,
      "z": 4,
      "name": "Plant_Bush"
    },
    {
      "x": 4,
      "y": 3,
      "z": 4,
      "name": "Plant_Bush"
    },
    {
      "x": 4,
      "y": 4,
      "z": 4,
      "name": "Plant_Bush"
    },
    {
      "x": 4,
      "y": 5,
      "z": 4,
      "name": "Plant_Bush"
    },
    {
      "x": 4,
      "y": 3,
      "z": 5,
      "name": "Plant_Bush"
    },
    {
      "x": 4,
      "y": 4,
      "z": 5,
      "name": "Plant_Bush"
    },
    {
      "x": 5,
      "y": 3,
      "z": 1,
      "name": "Plant_Bush"
    },
    {
      "x": 5,
      "y": 2,
      "z": 2,
      "name": "Plant_Bush"
    },
    {
      "x": 5,
      "y": 3,
      "z": 2,
      "name": "Plant_Bush"
    },
    {
      "x": 5,
      "y": 4,
      "z": 2,
      "name": "Plant_Bush"
    },
    {
      "x": 5,
      "y": 2,
      "z": 3,
      "name": "Plant_Bush"
    },
    {
      "x": 5,
      "y": 3,
      "z": 3,
      "name": "Plant_Bush"
    },
    {
      "x": 5,
      "y": 4,
      "z": 3,
      "name": "Plant_Bush"
    },
    {
      "x": 5,
      "y": 5,
      "z": 3,
      "name": "Plant_Bush"
    },
    {
      "x": 5,
      "y": 1,
      "z": 4,
      "name": "Plant_Bush"
    },
    {
      "x": 5,
      "y": 2,
      "z": 4,
      "name": "Plant_Bush"
    },
    {
      "x": 5,
      "y": 3,
      "z": 4,
      "name": "Plant_Bush"
    },
    {
      "x": 5,
      "y": 4,
      "z": 4,
      "name": "Plant_Bush"
    },
    {
      "x": 5,
      "y": 5,
      "z": 4,
      "name": "Plant_Bush"
    },
    {
      "x": 5,
      "y": 2,
      "z": 5,
      "name": "Plant_Bush"
    },
    {
      "x": 5,
      "y": 3,
      "z": 5,
      "name": "Plant_Bush"
    },
    {
      "x": 5,
      "y": 4,
      "z": 5,
      "name": "Plant_Bush"
    },
    {
      "x": 5,
      "y": 3,
      "z": 6,
      "name": "Plant_Bush"
    },
    {
      "x": 6,
      "y": 3,
      "z": 1,
      "name": "Plant_Bush"
    },
    {
      "x": 6,
      "y": 4,
      "z": 1,
      "name": "Plant_Bush"
    },
    {
      "x": 6,
      "y": 2,
      "z": 2,
      "name": "Plant_Bush"
    },
    {
      "x": 6,
      "y": 3,
      "z": 2,
      "name": "Plant_Bush"
    },
    {
      "x": 6,
      "y": 4,
      "z": 2,
      "name": "Plant_Bush"
    },
    {
      "x": 6,
      "y": 5,
      "z": 2,
      "name": "Plant_Bush"
    },
    {
      "x": 6,
      "y": 1,
      "z": 3,
      "name": "Plant_Bush"
    },
    {
      "x": 6,
      "y": 2,
      "z": 3,
      "name": "Plant_Bush"
    },
    {
      "x": 6,
      "y": 3,
      "z": 3,
      "name": "Plant_Bush"
    },
    {
      "x": 6,
      "y": 4,
      "z": 3,
      "name": "Plant_Bush"
    },
    {
      "x": 6,
      "y": 5,
      "z": 3,
      "name": "Plant_Bush"
    },
    {
      "x": 6,
      "y": 2,
      "z": 4,
      "name": "Plant_Bush"
    },
    {
      "x": 6,
      "y": 3,
      "z": 4,
      "name": "Plant_Bush"
    },
    {
      "x": 6,
      "y": 4,
      "z": 4,
      "name": "Plant_Bush"
    },
    {
      "x": 6,
      "y": 5,
      "z": 4,
      "name": "Plant_Bush"
    },
    {
      "x": 6,
      "y": 3,
      "z": 5,
      "name": "Plant_Bush"
    },
    {
      "x": 6,
      "y": 4,
      "z": 5,
      "name": "Plant_Bush"
    },
    {
      "x": 6,
      "y": 5,
      "z": 5,
      "name": "Plant_Bush"
    },
    {
      "x": 6,
      "y": 4,
      "z": 6,
      "name": "Plant_Bush"
    },
    {
      "x": 7,
      "y": 3,
      "z": 2,
      "name": "Plant_Bush"
    },
    {
      "x": 7,
      "y": 4,
      "z": 2,
      "name": "Plant_Bush"
    },
    {
      "x": 7,
      "y": 2,
      "z": 3,
      "name": "Plant_Bush"
    },
    {
      "x": 7,
      "y": 3,
      "z": 3,
      "name": "Plant_Bush"
    },
    {
      "x": 7,
      "y": 4,
      "z": 3,
      "name": "Plant_Bush"
    },
    {
      "x": 7,
      "y": 5,
      "z": 3,
      "name": "Plant_Bush"
    },
    {
      "x": 7,
      "y": 2,
      "z": 4,
      "name": "Plant_Bush"
    },
    {
      "x": 7,
      "y": 3,
      "z": 4,
      "name": "Plant_Bush"
    },
    {
      "x": 7,
      "y": 4,
      "z": 4,
      "name": "Plant_Bush"
    },
    {
      "x": 7,
      "y": 5,
      "z": 4,
      "name": "Plant_Bush"
    },
    {
      "x": 7,
      "y": 2,
      "z": 5,
      "name": "Plant_Bush"
    },
    {
      "x": 7,
      "y": 3,
      "z": 5,
      "name": "Plant_Bush"
    },
    {
      "x": 7,
      "y": 4,
      "z": 5,
      "name": "Plant_Bush"
    },
    {
      "x": 7,
      "y": 3,
      "z": 6,
      "name": "Plant_Bush"
    },
    {
      "x": 8,
      "y": 3,
      "z": 3,
      "name": "Plant_Bush"
    },
    {
      "x": 8,
      "y": 4,
      "z": 3,
      "name": "Plant_Bush"
    },
    {
      "x": 8,
      "y": 2,
      "z": 4,
      "name": "Plant_Bush"
    },
    {
      "x": 8,
      "y": 3,
      "z": 4,
      "name": "Plant_Bush"
    },
    {
      "x": 8,
      "y": 4,
      "z": 4,
      "name": "Plant_Bush"
    },
    {
      "x": 8,
      "y": 3,
      "z": 5,
      "name": "Plant_Bush"
    }
  ]
}