{
  "version": 8,
  "blockIdVersion": 11,
  "anchorX": 0,
  "anchorY": 0,
  "anchorZ": 0,
  "blocks": [
    {
      "x": -39,
      "y": 22,
      "z": 0,
      "name": "Rail",
      "rotation": 50
    },
    {
      "x": -38,
      "y": 22,
      "z": -1,
      "name": "Rail",
      "rotation": 49
    },
    {
      "x": -38,
      "y": 21,
      "z": 0,
      "name": "Wood_Fir_Trunk_Half",
      "rotation": 34
    },
    {
      "x": -38,
      "y": 22,
      "z": 0,
      "name": "Rock_Shale_Brick_Decorative",
      "support": 15
    },
    {
      "x": -38,
      "y": 23,
      "z": 0,
      "name": "Furniture_Temple_Dark_Statue_Gaia",
      "rotation": 3
    },
    {
      "x": -38,
      "y": 24,
      "z": 0,
      "name": "Furniture_Temple_Dark_Statue_Gaia",
      "filler": 1024,
      "rotation": 3
    },
    {
      "x": -38,
      "y": 25,
      "z": 0,
      "name": "Furniture_Temple_Dark_Statue_Gaia",
      "filler": 2048,
      "rotation": 3
    },
    {
      "x": -38,
      "y": 22,
      "z": 1,
      "name": "Rail",
      "rotation": 17
    },
    {
      "x": -37,
      "y": 20,
      "z": 0,
      "name": "Rock_Ice_Icicles",
      "rotation": 8
    },
    {
      "x": -37,
      "y": 21,
      "z": 0,
      "name": "Wood_Fir_Trunk_Full_Locked",
      "support": 15,
      "rotation": 5
    },
    {
      "x": -37,
      "y": 22,
      "z": 0,
      "name": "Wood_Fir_Trunk_Half"
    },
    {
      "x": -36,
      "y": 20,
      "z": 0,
      "name": "Wood_Fir_Trunk_Half",
      "rotation": 34
    },
    {
      "x": -36,
      "y": 21,
      "z": 0,
      "name": "Wood_Fir_Trunk_Full_Locked",
      "support": 15,
      "rotation": 5
    },
    {
      "x": -35,
      "y": 19,
      "z": 0,
      "name": "Wood_Fir_Trunk_Stairs",
      "rotation": 35
    },
    {
      "x": -35,
      "y": 20,
      "z": 0,
      "name": "Wood_Fir_Trunk_Full_Locked",
      "support": 15,
      "rotation": 5
    },
    {
      "x": -35,
      "y": 21,
      "z": 0,
      "name": "Wood_Fir_Trunk_Half"
    },
    {
      "x": -34,
      "y": 18,
      "z": 0,
      "name": "Wood_Fir_Trunk_Stairs",
      "rotation": 35
    },
    {
      "x": -34,
      "y": 19,
      "z": 0,
      "name": "Wood_Fir_Trunk_Full_Locked",
      "support": 15
    },
    {
      "x": -34,
      "y": 20,
      "z": 0,
      "name": "Wood_Fir_Trunk_Full_Locked",
      "support": 15,
      "rotation": 5
    },
    {
      "x": -33,
      "y": 17,
      "z": 0,
      "name": "Wood_Fir_Trunk_Stairs",
      "rotation": 35
    },
    {
      "x": -33,
      "y": 18,
      "z": 0,
      "name": "Wood_Fir_Trunk_Stairs",
      "rotation": 1
    },
    {
      "x": -33,
      "y": 19,
      "z": 0,
      "name": "Wood_Fir_Trunk_Full_Locked",
      "support": 15,
      "rotation": 5
    },
    {
      "x": -33,
      "y": 20,
      "z": 0,
      "name": "Wood_Fir_Trunk_Half"
    },
    {
      "x": -32,
      "y": 16,
      "z": 0,
      "name": "Wood_Fir_Trunk_Stairs",
      "rotation": 35
    },
    {
      "x": -32,
      "y": 17,
      "z": 0,
      "name": "Wood_Fir_Trunk_Stairs",
      "rotation": 1
    },
    {
      "x": -32,
      "y": 18,
      "z": 0,
      "name": "Wood_Fir_Trunk_Half",
      "rotation": 34
    },
    {
      "x": -32,
      "y": 19,
      "z": 0,
      "name": "Wood_Fir_Trunk_Full_Locked",
      "support": 15,
      "rotation": 5
    },
    {
      "x": -31,
      "y": 15,
      "z": 0,
      "name": "Wood_Fir_Trunk_Stairs",
      "rotation": 35
    },
    {
      "x": -31,
      "y": 16,
      "z": 0,
      "name": "Wood_Fir_Trunk_Stairs",
      "rotation": 1
    },
    {
      "x": -31,
      "y": 18,
      "z": 0,
      "name": "Wood_Fir_Trunk_Full_Locked",
      "support": 15
    },
    {
      "x": -31,
      "y": 19,
      "z": 0,
      "name": "Wood_Fir_Trunk_Half"
    },
    {
      "x": -30,
      "y": 15,
      "z": -1,
      "name": "Wood_Fir_Trunk_Half",
      "rotation": 6
    },
    {
      "x": -30,
      "y": 14,
      "z": 0,
      "name": "Wood_Fir_Trunk_Stairs",
      "rotation": 35
    },
    {
      "x": -30,
      "y": 15,
      "z": 0,
      "name": "Wood_Fir_Trunk_Stairs",
      "rotation": 1
    },
    {
      "x": -30,
      "y": 17,
      "z": 0,
      "name": "Wood_Fir_Trunk_Half",
      "rotation": 34
    },
    {
      "x": -30,
      "y": 18,
      "z": 0,
      "name": "Wood_Fir_Trunk_Full_Locked",
      "support": 15,
      "rotation": 5
    },
    {
      "x": -30,
      "y": 15,
      "z": 1,
      "name": "Wood_Fir_Trunk_Half",
      "rotation": 4
    },
    {
      "x": -29,
      "y": 15,
      "z": -1,
      "name": "Wood_Fir_Trunk_Full_Locked",
      "support": 15,
      "rotation": 6
    },
    {
      "x": -29,
      "y": 13,
      "z": 0,
      "name": "Wood_Fir_Trunk_Stairs",
      "rotation": 35
    },
    {
      "x": -29,
      "y": 14,
      "z": 0,
      "name": "Wood_Fir_Trunk_Stairs",
      "rotation": 1
    },
    {
      "x": -29,
      "y": 17,
      "z": 0,
      "name": "Wood_Fir_Trunk_Full_Locked",
      "support": 15,
      "rotation": 5
    },
    {
      "x": -29,
      "y": 18,
      "z": 0,
      "name": "Wood_Fir_Trunk_Half"
    },
    {
      "x": -29,
      "y": 15,
      "z": 1,
      "name": "Wood_Fir_Trunk_Full_Locked",
      "support": 15,
      "rotation": 4
    },
    {
      "x": -28,
      "y": 15,
      "z": -2,
      "name": "Wood_Fir_Trunk_Half",
      "rotation": 6
    },
    {
      "x": -28,
      "y": 15,
      "z": -1,
      "name": "Wood_Fir_Trunk_Half",
      "rotation": 4
    },
    {
      "x": -28,
      "y": 12,
      "z": 0,
      "name": "Wood_Fir_Trunk_Stairs",
      "rotation": 35
    },
    {
      "x": -28,
      "y": 13,
      "z": 0,
      "name": "Wood_Fir_Trunk_Stairs",
      "rotation": 1
    },
    {
      "x": -28,
      "y": 16,
      "z": 0,
      "name": "Wood_Fir_Trunk_Half",
      "rotation": 34
    },
    {
      "x": -28,
      "y": 17,
      "z": 0,
      "name": "Wood_Fir_Trunk_Full_Locked",
      "support": 15,
      "rotation": 5
    },
    {
      "x": -28,
      "y": 18,
      "z": 0,
      "name": "Deco_Rope_Diagonal",
      "rotation": 3
    },
    {
      "x": -28,
      "y": 15,
      "z": 1,
      "name": "Wood_Fir_Trunk_Half",
      "rotation": 6
    },
    {
      "x": -28,
      "y": 15,
      "z": 2,
      "name": "Wood_Fir_Trunk_Half",
      "rotation": 4
    },
    {
      "x": -27,
      "y": 15,
      "z": -2,
      "name": "*Wood_Fir_Trunk_Half_State_Definitions_Block",
      "rotation": 4
    },
    {
      "x": -27,
      "y": 11,
      "z": 0,
      "name": "Wood_Fir_Trunk_Stairs",
      "rotation": 35
    },
    {
      "x": -27,
      "y": 12,
      "z": 0,
      "name": "Wood_Fir_Trunk_Stairs",
      "rotation": 1
    },
    {
      "x": -27,
      "y": 16,
      "z": 0,
      "name": "Wood_Fir_Trunk_Full_Locked",
      "support": 15,
      "rotation": 5
    },
    {
      "x": -27,
      "y": 17,
      "z": 0,
      "name": "Wood_Fir_Trunk_Half"
    },
    {
      "x": -27,
      "y": 19,
      "z": 0,
      "name": "Deco_Rope_Diagonal",
      "rotation": 3
    },
    {
      "x": -27,
      "y": 13,
      "z": 2,
      "name": "Rock_Ice_Stalactite_Large",
      "filler": 31744,
      "rotation": 8
    },
    {
      "x": -27,
      "y": 14,
      "z": 2,
      "name": "Rock_Ice_Stalactite_Large",
      "rotation": 8
    },
    {
      "x": -27,
      "y": 15,
      "z": 2,
      "name": "*Wood_Fir_Trunk_Half_State_Definitions_Block",
      "rotation": 6
    },
    {
      "x": -26,
      "y": 15,
      "z": -3,
      "name": "Wood_Fir_Trunk_Half",
      "rotation": 6
    },
    {
      "x": -26,
      "y": 15,
      "z": -2,
      "name": "Wood_Fir_Trunk_Half",
      "rotation": 4
    },
    {
      "x": -26,
      "y": 10,
      "z": 0,
      "name": "Wood_Fir_Trunk_Stairs",
      "rotation": 35
    },
    {
      "x": -26,
      "y": 11,
      "z": 0,
      "name": "Wood_Fir_Trunk_Stairs",
      "rotation": 1
    },
    {
      "x": -26,
      "y": 15,
      "z": 0,
      "name": "Wood_Fir_Trunk_Half",
      "rotation": 32
    },
    {
      "x": -26,
      "y": 16,
      "z": 0,
      "name": "Wood_Fir_Trunk_Full_Locked",
      "support": 15,
      "rotation": 5
    },
    {
      "x": -26,
      "y": 20,
      "z": 0,
      "name": "Deco_Rope_Diagonal",
      "rotation": 3
    },
    {
      "x": -26,
      "y": 15,
      "z": 2,
      "name": "Wood_Fir_Trunk_Half",
      "rotation": 6
    },
    {
      "x": -26,
      "y": 15,
      "z": 3,
      "name": "Wood_Fir_Trunk_Half",
      "rotation": 4
    },
    {
      "x": -25,
      "y": 15,
      "z": -3,
      "name": "Wood_Fir_Trunk_Full_Locked",
      "support": 15,
      "rotation": 5
    },
    {
      "x": -25,
      "y": 11,
      "z": -1,
      "name": "Wood_Blackwood_Planks",
      "rotation": 2
    },
    {
      "x": -25,
      "y": 12,
      "z": -1,
      "name": "Wood_Fir_Trunk_Full_Locked",
      "support": 15,
      "rotation": 6
    },
    {
      "x": -25,
      "y": 13,
      "z": -1,
      "name": "Wood_Blackwood_Planks",
      "rotation": 2
    },
    {
      "x": -25,
      "y": 14,
      "z": -1,
      "name": "Wood_Blackwood_Planks",
      "rotation": 2
    },
    {
      "x": -25,
      "y": 15,
      "z": -1,
      "name": "Wood_Fir_Trunk_Full_Locked",
      "support": 15,
      "rotation": 2
    },
    {
      "x": -25,
      "y": 16,
      "z": -1,
      "name": "Wood_Fir_Trunk_Full_Locked",
      "support": 15,
      "rotation": 2
    },
    {
      "x": -25,
      "y": 9,
      "z": 0,
      "name": "Wood_Fir_Trunk_Stairs",
      "rotation": 35
    },
    {
      "x": -25,
      "y": 10,
      "z": 0,
      "name": "Wood_Fir_Trunk_Full_Locked",
      "support": 15,
      "rotation": 2
    },
    {
      "x": -25,
      "y": 11,
      "z": 0,
      "name": "Wood_Blackwood_Planks"
    },
    {
      "x": -25,
      "y": 12,
      "z": 0,
      "name": "Wood_Fir_Trunk_Full_Locked",
      "support": 15,
      "rotation": 6
    },
    {
      "x": -25,
      "y": 13,
      "z": 0,
      "name": "Wood_Fir_Trunk_Full_Locked",
      "support": 15
    },
    {
      "x": -25,
      "y": 14,
      "z": 0,
      "name": "Wood_Fir_Trunk_Full_Locked",
      "support": 15
    },
    {
      "x": -25,
      "y": 15,
      "z": 0,
      "name": "Wood_Fir_Trunk_Full_Locked",
      "support": 15
    },
    {
      "x": -25,
      "y": 16,
      "z": 0,
      "name": "Wood_Fir_Trunk_Full_Locked",
      "support": 15
    },
    {
      "x": -25,
      "y": 21,
      "z": 0,
      "name": "Deco_Rope_Diagonal",
      "rotation": 3
    },
    {
      "x": -25,
      "y": 11,
      "z": 1,
      "name": "Wood_Blackwood_Planks"
    },
    {
      "x": -25,
      "y": 12,
      "z": 1,
      "name": "Wood_Fir_Trunk_Full_Locked",
      "support": 15,
      "rotation": 4
    },
    {
      "x": -25,
      "y": 13,
      "z": 1,
      "name": "Wood_Blackwood_Planks"
    },
    {
      "x": -25,
      "y": 14,
      "z": 1,
      "name": "Wood_Blackwood_Planks"
    },
    {
      "x": -25,
      "y": 15,
      "z": 1,
      "name": "Wood_Fir_Trunk_Full_Locked",
      "support": 15
    },
    {
      "x": -25,
      "y": 16,
      "z": 1,
      "name": "Wood_Fir_Trunk_Full_Locked",
      "support": 15
    },
    {
      "x": -25,
      "y": 15,
      "z": 3,
      "name": "Wood_Fir_Trunk_Full_Locked",
      "support": 15,
      "rotation": 5
    },
    {
      "x": -24,
      "y": 15,
      "z": -4,
      "name": "Wood_Fir_Trunk_Half",
      "rotation": 6
    },
    {
      "x": -24,
      "y": 11,
      "z": -3,
      "name": "Wood_Fir_Trunk_Full_Locked",
      "support": 15,
      "rotation": 5
    },
    {
      "x": -24,
      "y": 12,
      "z": -3,
      "name": "Wood_Fir_Trunk_Full_Locked",
      "support": 15,
      "rotation": 6
    },
    {
      "x": -24,
      "y": 13,
      "z": -3,
      "name": "Wood_Fir_Trunk_Full_Locked",
      "support": 15,
      "rotation": 2
    },
    {
      "x": -24,
      "y": 14,
      "z": -3,
      "name": "Wood_Fir_Trunk_Full_Locked",
      "support": 15,
      "rotation": 2
    },
    {
      "x": -24,
      "y": 15,
      "z": -3,
      "name": "Wood_Fir_Trunk_Full_Locked",
      "support": 15,
      "rotation": 6
    },
    {
      "x": -24,
      "y": 16,
      "z": -3,
      "name": "*Wood_Blackwood_Fence_State_Definitions_Corner",
      "rotation": 1
    },
    {
      "x": -24,
      "y": 11,
      "z": -2,
      "name": "Wood_Blackwood_Planks",
      "rotation": 2
    },
    {
      "x": -24,
      "y": 12,
      "z": -2,
      "name": "Wood_Fir_Trunk_Full_Locked",
      "support": 15,
      "rotation": 6
    },
    {
      "x": -24,
      "y": 13,
      "z": -2,
      "name": "Wood_Blackwood_Planks",
      "rotation": 2
    },
    {
      "x": -24,
      "y": 14,
      "z": -2,
      "name": "Wood_Blackwood_Planks",
      "rotation": 2
    },
    {
      "x": -24,
      "y": 15,
      "z": -2,
      "name": "Wood_Fir_Trunk_Full_Locked",
      "support": 15,
      "rotation": 2
    },
    {
      "x": -24,
      "y": 16,
      "z": -2,
      "name": "Wood_Blackwood_Fence",
      "rotation": 3
    },
    {
      "x": -24,
      "y": 10,
      "z": -1,
      "name": "Wood_Blackwood_Planks",
      "rotation": 2
    },
    {
      "x": -24,
      "y": 11,
      "z": -1,
      "name": "Wood_Blackwood_Planks",
      "rotation": 2
    },
    {
      "x": -24,
      "y": 12,
      "z": -1,
      "name": "Wood_Fir_Trunk_Full_Locked",
      "support": 15,
      "rotation": 6
    },
    {
      "x": -24,
      "y": 15,
      "z": -1,
      "name": "Wood_Fir_Trunk_Full_Locked",
      "support": 15,
      "rotation": 6
    },
    {
      "x": -24,
      "y": 16,
      "z": -1,
      "name": "Wood_Fir_Trunk_Full_Locked",
      "support": 15,
      "rotation": 2
    },
    {
      "x": -24,
      "y": 8,
      "z": 0,
      "name": "Wood_Fir_Trunk_Stairs",
      "rotation": 35
    },
    {
      "x": -24,
      "y": 9,
      "z": 0,
      "name": "Wood_Fir_Trunk_Full_Locked",
      "support": 15,
      "rotation": 2
    },
    {
      "x": -24,
      "y": 12,
      "z": 0,
      "name": "Wood_Fir_Trunk_Full_Locked",
      "support": 15,
      "rotation": 5
    },
    {
      "x": -24,
      "y": 15,
      "z": 0,
      "name": "Wood_Fir_Trunk_Full_Locked",
      "support": 15,
      "rotation": 5
    },
    {
      "x": -24,
      "y": 22,
      "z": 0,
      "name": "Deco_Rope_Diagonal",
      "rotation": 3
    },
    {
      "x": -24,
      "y": 10,
      "z": 1,
      "name": "Wood_Blackwood_Planks"
    },
    {
      "x": -24,
      "y": 11,
      "z": 1,
      "name": "Wood_Blackwood_Planks"
    },
    {
      "x": -24,
      "y": 12,
      "z": 1,
      "name": "Wood_Fir_Trunk_Full_Locked",
      "support": 15,
      "rotation": 4
    },
    {
      "x": -24,
      "y": 15,
      "z": 1,
      "name": "Wood_Fir_Trunk_Full_Locked",
      "support": 15,
      "rotation": 4
    },
    {
      "x": -24,
      "y": 16,
      "z": 1,
      "name": "Wood_Fir_Trunk_Full_Locked",
      "support": 15
    },
    {
      "x": -24,
      "y": 11,
      "z": 2,
      "name": "Wood_Blackwood_Planks"
    },
    {
      "x": -24,
      "y": 12,
      "z": 2,
      "name": "Wood_Fir_Trunk_Full_Locked",
      "support": 15,
      "rotation": 4
    },
    {
      "x": -24,
      "y": 13,
      "z": 2,
      "name": "Wood_Blackwood_Planks"
    },
    {
      "x": -24,
      "y": 14,
      "z": 2,
      "name": "Wood_Blackwood_Planks"
    },
    {
      "x": -24,
      "y": 15,
      "z": 2,
      "name": "Wood_Fir_Trunk_Full_Locked",
      "support": 15
    },
    {
      "x": -24,
      "y": 16,
      "z": 2,
      "name": "Wood_Blackwood_Fence",
      "rotation": 3
    },
    {
      "x": -24,
      "y": 11,
      "z": 3,
      "name": "Wood_Fir_Trunk_Full_Locked",
      "support": 15,
      "rotation": 5
    },
    {
      "x": -24,
      "y": 12,
      "z": 3,
      "name": "Wood_Fir_Trunk_Full_Locked",
      "support": 15,
      "rotation": 4
    },
    {
      "x": -24,
      "y": 13,
      "z": 3,
      "name": "Wood_Fir_Trunk_Full_Locked",
      "support": 15
    },
    {
      "x": -24,
      "y": 14,
      "z": 3,
      "name": "Wood_Fir_Trunk_Full_Locked",
      "support": 15
    },
    {
      "x": -24,
      "y": 15,
      "z": 3,
      "name": "Wood_Fir_Trunk_Full_Locked",
      "support": 15,
      "rotation": 4
    },
    {
      "x": -24,
      "y": 16,
      "z": 3,
      "name": "*Wood_Blackwood_Fence_State_Definitions_Corner",
      "rotation": 2
    },
    {
      "x": -24,
      "y": 15,
      "z": 4,
      "name": "Wood_Fir_Trunk_Half",
      "rotation": 4
    },
    {
      "x": -23,
      "y": 12,
      "z": -5,
      "name": "Wood_Fir_Trunk_Full_Locked",
      "support": 15,
      "rotation": 5
    },
    {
      "x": -23,
      "y": 13,
      "z": -5,
      "name": "Wood_Blackwood_Planks",
      "rotation": 2
    },
    {
      "x": -23,
      "y": 14,
      "z": -5,
      "name": "Wood_Blackwood_Planks",
      "rotation": 2
    },
    {
      "x": -23,
      "y": 15,
      "z": -5,
      "name": "Wood_Fir_Trunk_Full_Locked",
      "support": 15,
      "rotation": 6
    },
    {
      "x": -23,
      "y": 16,
      "z": -5,
      "name": "*Wood_Blackwood_Fence_State_Definitions_Corner",
      "rotation": 1
    },
    {
      "x": -23,
      "y": 11,
      "z": -4,
      "name": "Wood_Blackwood_Planks",
      "rotation": 2
    },
    {
      "x": -23,
      "y": 12,
      "z": -4,
      "name": "Wood_Fir_Trunk_Full_Locked",
      "support": 15,
      "rotation": 6
    },
    {
      "x": -23,
      "y": 13,
      "z": -4,
      "name": "Wood_Blackwood_Planks",
      "rotation": 2
    },
    {
      "x": -23,
      "y": 14,
      "z": -4,
      "name": "Wood_Blackwood_Planks",
      "rotation": 2
    },
    {
      "x": -23,
      "y": 15,
      "z": -4,
      "name": "Wood_Fir_Trunk_Full_Locked",
      "support": 15,
      "rotation": 6
    },
    {
      "x": -23,
      "y": 16,
      "z": -4,
      "name": "Wood_Blackwood_Fence",
      "rotation": 3
    },
    {
      "x": -23,
      "y": 10,
      "z": -3,
      "name": "Wood_Fir_Trunk_Full_Locked",
      "support": 15,
      "rotation": 5
    },
    {
      "x": -23,
      "y": 11,
      "z": -3,
      "name": "Wood_Fir_Trunk_Full_Locked",
      "support": 15,
      "rotation": 5
    },
    {
      "x": -23,
      "y": 12,
      "z": -3,
      "name": "Wood_Fir_Trunk_Full_Locked",
      "support": 15,
      "rotation": 5
    },
    {
      "x": -23,
      "y": 15,
      "z": -3,
      "name": "Wood_Fir_Trunk_Full_Locked",
      "support": 15,
      "rotation": 5
    },
    {
      "x": -23,
      "y": 16,
      "z": -3,
      "name": "*Wood_Blackwood_Fence_State_Definitions_Corner",
      "rotation": 3
    },
    {
      "x": -23,
      "y": 10,
      "z": -2,
      "name": "Wood_Blackwood_Planks",
      "rotation": 2
    },
    {
      "x": -23,
      "y": 12,
      "z": -2,
      "name": "Wood_Deadwood_Planks",
      "rotation": 2
    },
    {
      "x": -23,
      "y": 15,
      "z": -2,
      "name": "Wood_Deadwood_Planks_Half",
      "rotation": 32
    },
    {
      "x": -23,
      "y": 9,
      "z": -1,
      "name": "Wood_Blackwood_Planks",
      "rotation": 2
    },
    {
      "x": -23,
      "y": 10,
      "z": -1,
      "name": "Wood_Blackwood_Planks",
      "rotation": 2
    },
    {
      "x": -23,
      "y": 12,
      "z": -1,
      "name": "Wood_Deadwood_Planks",
      "rotation": 2
    },
    {
      "x": -23,
      "y": 15,
      "z": -1,
      "name": "Wood_Deadwood_Planks_Half",
      "rotation": 32
    },
    {
      "x": -23,
      "y": 7,
      "z": 0,
      "name": "Wood_Fir_Trunk_Stairs",
      "rotation": 35
    },
    {
      "x": -23,
      "y": 8,
      "z": 0,
      "name": "Wood_Fir_Trunk_Full_Locked",
      "support": 15,
      "rotation": 2
    },
    {
      "x": -23,
      "y": 12,
      "z": 0,
      "name": "Wood_Fir_Trunk_Full_Locked",
      "support": 15,
      "rotation": 5
    },
    {
      "x": -23,
      "y": 15,
      "z": 0,
      "name": "Wood_Fir_Trunk_Full_Locked",
      "support": 15,
      "rotation": 5
    },
    {
      "x": -23,
      "y": 23,
      "z": 0,
      "name": "Deco_Rope_Diagonal",
      "rotation": 3
    },
    {
      "x": -23,
      "y": 9,
      "z": 1,
      "name": "Wood_Blackwood_Planks"
    },
    {
      "x": -23,
      "y": 10,
      "z": 1,
      "name": "Wood_Blackwood_Planks"
    },
    {
      "x": -23,
      "y": 12,
      "z": 1,
      "name": "Wood_Deadwood_Planks"
    },
    {
      "x": -23,
      "y": 15,
      "z": 1,
      "name": "Wood_Deadwood_Planks_Half",
      "rotation": 8
    },
    {
      "x": -23,
      "y": 10,
      "z": 2,
      "name": "Wood_Blackwood_Planks"
    },
    {
      "x": -23,
      "y": 12,
      "z": 2,
      "name": "Wood_Deadwood_Planks"
    },
    {
      "x": -23,
      "y": 15,
      "z": 2,
      "name": "Wood_Deadwood_Planks_Half",
      "rotation": 8
    },
    {
      "x": -23,
      "y": 10,
      "z": 3,
      "name": "Wood_Fir_Trunk_Full_Locked",
      "support": 15,
      "rotation": 5
    },
    {
      "x": -23,
      "y": 11,
      "z": 3,
      "name": "Wood_Fir_Trunk_Full_Locked",
      "support": 15,
      "rotation": 5
    },
    {
      "x": -23,
      "y": 12,
      "z": 3,
      "name": "Wood_Fir_Trunk_Full_Locked",
      "support": 15,
      "rotation": 5
    },
    {
      "x": -23,
      "y": 15,
      "z": 3,
      "name": "Wood_Fir_Trunk_Full_Locked",
      "support": 15,
      "rotation": 5
    },
    {
      "x": -23,
      "y": 16,
      "z": 3,
      "name": "*Wood_Blackwood_Fence_State_Definitions_Corner"
    },
    {
      "x": -23,
      "y": 11,
      "z": 4,
      "name": "Wood_Blackwood_Planks"
    },
    {
      "x": -23,
      "y": 12,
      "z": 4,
      "name": "Wood_Fir_Trunk_Full_Locked",
      "support": 15,
      "rotation": 4
    },
    {
      "x": -23,
      "y": 13,
      "z": 4,
      "name": "Wood_Blackwood_Planks"
    },
    {
      "x": -23,
      "y": 14,
      "z": 4,
      "name": "Wood_Blackwood_Planks"
    },
    {
      "x": -23,
      "y": 15,
      "z": 4,
      "name": "Wood_Fir_Trunk_Full_Locked",
      "support": 15,
      "rotation": 4
    },
    {
      "x": -23,
      "y": 16,
      "z": 4,
      "name": "Wood_Blackwood_Fence",
      "rotation": 3
    },
    {
      "x": -23,
      "y": 12,
      "z": 5,
      "name": "Wood_Fir_Trunk_Full_Locked",
      "support": 15,
      "rotation": 5
    },
    {
      "x": -23,
      "y": 13,
      "z": 5,
      "name": "Wood_Blackwood_Planks"
    },
    {
      "x": -23,
      "y": 14,
      "z": 5,
      "name": "Wood_Blackwood_Planks"
    },
    {
      "x": -23,
      "y": 15,
      "z": 5,
      "name": "Wood_Fir_Trunk_Full_Locked",
      "support": 15,
      "rotation": 4
    },
    {
      "x": -23,
      "y": 16,
      "z": 5,
      "name": "*Wood_Blackwood_Fence_State_Definitions_Corner",
      "rotation": 2
    },
    {
      "x": -22,
      "y": 12,
      "z": -6,
      "name": "Wood_Fir_Trunk_Full_Locked",
      "support": 15,
      "rotation": 5
    },
    {
      "x": -22,
      "y": 13,
      "z": -6,
      "name": "Wood_Fir_Trunk_Full_Locked",
      "support": 15,
      "rotation": 2
    },
    {
      "x": -22,
      "y": 14,
      "z": -6,
      "name": "Wood_Fir_Trunk_Full_Locked",
      "support": 15,
      "rotation": 2
    },
    {
      "x": -22,
      "y": 15,
      "z": -6,
      "name": "Wood_Fir_Trunk_Full_Locked",
      "support": 15,
      "rotation": 2
    },
    {
      "x": -22,
      "y": 16,
      "z": -6,
      "name": "*Wood_Blackwood_Fence_State_Definitions_Corner",
      "rotation": 1
    },
    {
      "x": -22,
      "y": 11,
      "z": -5,
      "name": "Wood_Blackwood_Planks",
      "rotation": 2
    },
    {
      "x": -22,
      "y": 12,
      "z": -5,
      "name": "Wood_Fir_Trunk_Full_Locked",
      "support": 15,
      "rotation": 6
    },
    {
      "x": -22,
      "y": 15,
      "z": -5,
      "name": "Wood_Fir_Trunk_Full_Locked",
      "support": 15,
      "rotation": 6
    },
    {
      "x": -22,
      "y": 16,
      "z": -5,
      "name": "*Wood_Blackwood_Fence_State_Definitions_Corner",
      "rotation": 3
    },
    {
      "x": -22,
      "y": 10,
      "z": -4,
      "name": "Wood_Blackwood_Planks",
      "rotation": 2
    },
    {
      "x": -22,
      "y": 12,
      "z": -4,
      "name": "Wood_Fir_Trunk_Full_Locked",
      "support": 15,
      "rotation": 6
    },
    {
      "x": -22,
      "y": 15,
      "z": -4,
      "name": "Wood_Deadwood_Planks_Half",
      "rotation": 32
    },
    {
      "x": -22,
      "y": 9,
      "z": -3,
      "name": "Wood_Fir_Trunk_Full_Locked",
      "support": 15,
      "rotation": 5
    },
    {
      "x": -22,
      "y": 10,
      "z": -3,
      "name": "Wood_Fir_Trunk_Full_Locked",
      "support": 15,
      "rotation": 5
    },
    {
      "x": -22,
      "y": 12,
      "z": -3,
      "name": "Wood_Fir_Trunk_Full_Locked",
      "support": 15,
      "rotation": 5
    },
    {
      "x": -22,
      "y": 15,
      "z": -3,
      "name": "Wood_Fir_Trunk_Full_Locked",
      "support": 15,
      "rotation": 5
    },
    {
      "x": -22,
      "y": 9,
      "z": -2,
      "name": "Wood_Blackwood_Planks",
      "rotation": 2
    },
    {
      "x": -22,
      "y": 12,
      "z": -2,
      "name": "Wood_Deadwood_Planks",
      "rotation": 2
    },
    {
      "x": -22,
      "y": 15,
      "z": -2,
      "name": "Wood_Deadwood_Planks_Half",
      "rotation": 32
    },
    {
      "x": -22,
      "y": 8,
      "z": -1,
      "name": "Wood_Blackwood_Planks",
      "rotation": 2
    },
    {
      "x": -22,
      "y": 9,
      "z": -1,
      "name": "Wood_Blackwood_Planks",
      "rotation": 2
    },
    {
      "x": -22,
      "y": 12,
      "z": -1,
      "name": "Wood_Deadwood_Planks",
      "rotation": 2
    },
    {
      "x": -22,
      "y": 15,
      "z": -1,
      "name": "Wood_Deadwood_Planks_Half",
      "rotation": 32
    },
    {
      "x": -22,
      "y": 6,
      "z": 0,
      "name": "Wood_Fir_Trunk_Stairs",
      "rotation": 35
    },
    {
      "x": -22,
      "y": 7,
      "z": 0,
      "name": "Wood_Fir_Trunk_Full_Locked",
      "support": 15,
      "rotation": 2
    },
    {
      "x": -22,
      "y": 8,
      "z": 0,
      "name": "Wood_Fir_Trunk_Full_Locked",
      "support": 15,
      "rotation": 5
    },
    {
      "x": -22,
      "y": 12,
      "z": 0,
      "name": "Wood_Fir_Trunk_Full_Locked",
      "support": 15,
      "rotation": 5
    },
    {
      "x": -22,
      "y": 15,
      "z": 0,
      "name": "Wood_Fir_Trunk_Full_Locked",
      "support": 15,
      "rotation": 5
    },
    {
      "x": -22,
      "y": 24,
      "z": 0,
      "name": "Deco_Rope_Diagonal",
      "rotation": 3
    },
    {
      "x": -22,
      "y": 8,
      "z": 1,
      "name": "Wood_Blackwood_Planks"
    },
    {
      "x": -22,
      "y": 9,
      "z": 1,
      "name": "Wood_Blackwood_Planks"
    },
    {
      "x": -22,
      "y": 12,
      "z": 1,
      "name": "Wood_Deadwood_Planks"
    },
    {
      "x": -22,
      "y": 15,
      "z": 1,
      "name": "Wood_Deadwood_Planks_Half",
      "rotation": 8
    },
    {
      "x": -22,
      "y": 9,
      "z": 2,
      "name": "Wood_Blackwood_Planks"
    },
    {
      "x": -22,
      "y": 12,
      "z": 2,
      "name": "Wood_Deadwood_Planks"
    },
    {
      "x": -22,
      "y": 15,
      "z": 2,
      "name": "Wood_Deadwood_Planks_Half",
      "rotation": 8
    },
    {
      "x": -22,
      "y": 9,
      "z": 3,
      "name": "Wood_Fir_Trunk_Full_Locked",
      "support": 15,
      "rotation": 5
    },
    {
      "x": -22,
      "y": 10,
      "z": 3,
      "name": "Wood_Fir_Trunk_Full_Locked",
      "support": 15,
      "rotation": 5
    },
    {
      "x": -22,
      "y": 12,
      "z": 3,
      "name": "Wood_Fir_Trunk_Full_Locked",
      "support": 15,
      "rotation": 5
    },
    {
      "x": -22,
      "y": 15,
      "z": 3,
      "name": "Wood_Fir_Trunk_Full_Locked",
      "support": 15,
      "rotation": 5
    },
    {
      "x": -22,
      "y": 9,
      "z": 4,
      "name": "Rock_Ice_Icicles",
      "rotation": 8
    },
    {
      "x": -22,
      "y": 10,
      "z": 4,
      "name": "Wood_Blackwood_Planks"
    },
    {
      "x": -22,
      "y": 12,
      "z": 4,
      "name": "Wood_Fir_Trunk_Full_Locked",
      "support": 15,
      "rotation": 4
    },
    {
      "x": -22,
      "y": 15,
      "z": 4,
      "name": "Wood_Deadwood_Planks_Half",
      "rotation": 8
    },
    {
      "x": -22,
      "y": 11,
      "z": 5,
      "name": "Wood_Blackwood_Planks"
    },
    {
      "x": -22,
      "y": 12,
      "z": 5,
      "name": "Wood_Fir_Trunk_Full_Locked",
      "support": 15,
      "rotation": 4
    },
    {
      "x": -22,
      "y": 15,
      "z": 5,
      "name": "Wood_Fir_Trunk_Full_Locked",
      "support": 15,
      "rotation": 4
    },
    {
      "x": -22,
      "y": 16,
      "z": 5,
      "name": "*Wood_Blackwood_Fence_State_Definitions_Corner"
    },
    {
      "x": -22,
      "y": 12,
      "z": 6,
      "name": "Wood_Fir_Trunk_Full_Locked",
      "support": 15,
      "rotation": 5
    },
    {
      "x": -22,
      "y": 13,
      "z": 6,
      "name": "Wood_Fir_Trunk_Full_Locked",
      "support": 15
    },
    {
      "x": -22,
      "y": 14,
      "z": 6,
      "name": "Wood_Fir_Trunk_Full_Locked",
      "support": 15
    },
    {
      "x": -22,
      "y": 15,
      "z": 6,
      "name": "Wood_Fir_Trunk_Full_Locked",
      "support": 15
    },
    {
      "x": -22,
      "y": 16,
      "z": 6,
      "name": "*Wood_Blackwood_Fence_State_Definitions_Corner",
      "rotation": 2
    },
    {
      "x": -21,
      "y": 11,
      "z": -6,
      "name": "Wood_Fir_Trunk_Full_Locked",
      "support": 15,
      "rotation": 5
    },
    {
      "x": -21,
      "y": 12,
      "z": -6,
      "name": "Wood_Fir_Trunk_Full_Locked",
      "support": 15,
      "rotation": 5
    },
    {
      "x": -21,
      "y": 13,
      "z": -6,
      "name": "Wood_Blackwood_Planks",
      "rotation": 2
    },
    {
      "x": -21,
      "y": 14,
      "z": -6,
      "name": "Wood_Blackwood_Planks",
      "rotation": 2
    },
    {
      "x": -21,
      "y": 15,
      "z": -6,
      "name": "Wood_Fir_Trunk_Full_Locked",
      "support": 15,
      "rotation": 5
    },
    {
      "x": -21,
      "y": 16,
      "z": -6,
      "name": "Wood_Blackwood_Fence",
      "rotation": 2
    },
    {
      "x": -21,
      "y": 10,
      "z": -5,
      "name": "Wood_Blackwood_Planks",
      "rotation": 2
    },
    {
      "x": -21,
      "y": 12,
      "z": -5,
      "name": "Wood_Deadwood_Planks_Half",
      "rotation": 32
    },
    {
      "x": -21,
      "y": 15,
      "z": -5,
      "name": "Wood_Deadwood_Planks_Half",
      "rotation": 32
    },
    {
      "x": -21,
      "y": 9,
      "z": -4,
      "name": "Wood_Blackwood_Planks",
      "rotation": 2
    },
    {
      "x": -21,
      "y": 12,
      "z": -4,
      "name": "Wood_Deadwood_Planks_Half",
      "rotation": 32
    },
    {
      "x": -21,
      "y": 15,
      "z": -4,
      "name": "Wood_Deadwood_Planks_Half",
      "rotation": 32
    },
    {
      "x": -21,
      "y": 17,
      "z": -4,
      "name": "Metal_Bronze_Pipe_Large",
      "rotation": 7
    },
    {
      "x": -21,
      "y": 8,
      "z": -3,
      "name": "Wood_Fir_Trunk_Full_Locked",
      "support": 15,
      "rotation": 5
    },
    {
      "x": -21,
      "y": 9,
      "z": -3,
      "name": "Wood_Fir_Trunk_Full_Locked",
      "support": 15,
      "rotation": 5
    },
    {
      "x": -21,
      "y": 12,
      "z": -3,
      "name": "Wood_Fir_Trunk_Full_Locked",
      "support": 15,
      "rotation": 5
    },
    {
      "x": -21,
      "y": 15,
      "z": -3,
      "name": "Wood_Fir_Trunk_Full_Locked",
      "support": 15,
      "rotation": 5
    },
    {
      "x": -21,
      "y": 8,
      "z": -2,
      "name": "Wood_Blackwood_Planks",
      "rotation": 2
    },
    {
      "x": -21,
      "y": 12,
      "z": -2,
      "name": "Wood_Deadwood_Planks_Half",
      "rotation": 32
    },
    {
      "x": -21,
      "y": 15,
      "z": -2,
      "name": "Wood_Deadwood_Planks_Half",
      "rotation": 32
    },
    {
      "x": -21,
      "y": 7,
      "z": -1,
      "name": "Wood_Blackwood_Planks",
      "rotation": 2
    },
    {
      "x": -21,
      "y": 8,
      "z": -1,
      "name": "Wood_Blackwood_Planks",
      "rotation": 2
    },
    {
      "x": -21,
      "y": 12,
      "z": -1,
      "name": "Wood_Deadwood_Planks_Half",
      "rotation": 32
    },
    {
      "x": -21,
      "y": 15,
      "z": -1,
      "name": "Wood_Deadwood_Planks_Half",
      "rotation": 32
    },
    {
      "x": -21,
      "y": 5,
      "z": 0,
      "name": "Wood_Fir_Trunk_Half",
      "rotation": 34
    },
    {
      "x": -21,
      "y": 6,
      "z": 0,
      "name": "Wood_Fir_Trunk_Full_Locked",
      "support": 15,
      "rotation": 2
    },
    {
      "x": -21,
      "y": 8,
      "z": 0,
      "name": "Wood_Fir_Trunk_Full_Locked",
      "support": 15,
      "rotation": 5
    },
    {
      "x": -21,
      "y": 12,
      "z": 0,
      "name": "Wood_Fir_Trunk_Full_Locked",
      "support": 15,
      "rotation": 5
    },
    {
      "x": -21,
      "y": 15,
      "z": 0,
      "name": "Wood_Fir_Trunk_Full_Locked",
      "support": 15,
      "rotation": 5
    },
    {
      "x": -21,
      "y": 25,
      "z": 0,
      "name": "Deco_Rope_Diagonal",
      "rotation": 3
    },
    {
      "x": -21,
      "y": 7,
      "z": 1,
      "name": "Wood_Blackwood_Planks"
    },
    {
      "x": -21,
      "y": 8,
      "z": 1,
      "name": "Wood_Blackwood_Planks"
    },
    {
      "x": -21,
      "y": 12,
      "z": 1,
      "name": "Wood_Deadwood_Planks_Half",
      "rotation": 8
    },
    {
      "x": -21,
      "y": 15,
      "z": 1,
      "name": "Wood_Deadwood_Planks_Half",
      "rotation": 8
    },
    {
      "x": -21,
      "y": 8,
      "z": 2,
      "name": "Wood_Blackwood_Planks"
    },
    {
      "x": -21,
      "y": 12,
      "z": 2,
      "name": "Wood_Deadwood_Planks_Half",
      "rotation": 8
    },
    {
      "x": -21,
      "y": 15,
      "z": 2,
      "name": "Wood_Deadwood_Planks_Half",
      "rotation": 8
    },
    {
      "x": -21,
      "y": 8,
      "z": 3,
      "name": "Wood_Fir_Trunk_Full_Locked",
      "support": 15,
      "rotation": 5
    },
    {
      "x": -21,
      "y": 12,
      "z": 3,
      "name": "Wood_Fir_Trunk_Full_Locked",
      "support": 15,
      "rotation": 5
    },
    {
      "x": -21,
      "y": 15,
      "z": 3,
      "name": "Wood_Fir_Trunk_Full_Locked",
      "support": 15,
      "rotation": 5
    },
    {
      "x": -21,
      "y": 9,
      "z": 4,
      "name": "Wood_Blackwood_Planks"
    },
    {
      "x": -21,
      "y": 12,
      "z": 4,
      "name": "Wood_Deadwood_Planks_Half",
      "rotation": 8
    },
    {
      "x": -21,
      "y": 15,
      "z": 4,
      "name": "Wood_Deadwood_Planks_Half",
      "rotation": 8
    },
    {
      "x": -21,
      "y": 17,
      "z": 4,
      "name": "Metal_Bronze_Pipe_Large",
      "rotation": 7
    },
    {
      "x": -21,
      "y": 10,
      "z": 5,
      "name": "Wood_Blackwood_Planks"
    },
    {
      "x": -21,
      "y": 12,
      "z": 5,
      "name": "Wood_Deadwood_Planks_Half",
      "rotation": 8
    },
    {
      "x": -21,
      "y": 15,
      "z": 5,
      "name": "Wood_Deadwood_Planks_Half",
      "rotation": 8
    },
    {
      "x": -21,
      "y": 11,
      "z": 6,
      "name": "Wood_Fir_Trunk_Full_Locked",
      "support": 15,
      "rotation": 5
    },
    {
      "x": -21,
      "y": 12,
      "z": 6,
      "name": "Wood_Fir_Trunk_Full_Locked",
      "support": 15,
      "rotation": 5
    },
    {
      "x": -21,
      "y": 13,
      "z": 6,
      "name": "Wood_Blackwood_Planks"
    },
    {
      "x": -21,
      "y": 14,
      "z": 6,
      "name": "Wood_Blackwood_Planks"
    },
    {
      "x": -21,
      "y": 15,
      "z": 6,
      "name": "Wood_Fir_Trunk_Full_Locked",
      "support": 15,
      "rotation": 5
    },
    {
      "x": -21,
      "y": 16,
      "z": 6,
      "name": "Wood_Blackwood_Fence"
    },
    {
      "x": -20,
      "y": 12,
      "z": -7,
      "name": "Wood_Fir_Trunk_Full_Locked",
      "support": 15,
      "rotation": 5
    },
    {
      "x": -20,
      "y": 13,
      "z": -7,
      "name": "Wood_Blackwood_Planks",
      "rotation": 2
    },
    {
      "x": -20,
      "y": 14,
      "z": -7,
      "name": "Wood_Blackwood_Planks",
      "rotation": 2
    },
    {
      "x": -20,
      "y": 15,
      "z": -7,
      "name": "Wood_Fir_Trunk_Full_Locked",
      "support": 15,
      "rotation": 5
    },
    {
      "x": -20,
      "y": 16,
      "z": -7,
      "name": "*Wood_Blackwood_Fence_State_Definitions_Corner",
      "rotation": 1
    },
    {
      "x": -20,
      "y": 10,
      "z": -6,
      "name": "Wood_Fir_Trunk_Full_Locked",
      "support": 15,
      "rotation": 5
    },
    {
      "x": -20,
      "y": 11,
      "z": -6,
      "name": "Wood_Fir_Trunk_Full_Locked",
      "support": 15,
      "rotation": 5
    },
    {
      "x": -20,
      "y": 12,
      "z": -6,
      "name": "Wood_Fir_Trunk_Full_Locked",
      "support": 15,
      "rotation": 5
    },
    {
      "x": -20,
      "y": 13,
      "z": -6,
      "name": "Wood_Blackwood_Planks",
      "rotation": 2
    },
    {
      "x": -20,
      "y": 14,
      "z": -6,
      "name": "Wood_Blackwood_Planks",
      "rotation": 2
    },
    {
      "x": -20,
      "y": 15,
      "z": -6,
      "name": "Wood_Fir_Trunk_Full_Locked",
      "support": 15,
      "rotation": 5
    },
    {
      "x": -20,
      "y": 16,
      "z": -6,
      "name": "*Wood_Blackwood_Fence_State_Definitions_Corner",
      "rotation": 3
    },
    {
      "x": -20,
      "y": 9,
      "z": -5,
      "name": "Wood_Blackwood_Planks",
      "rotation": 2
    },
    {
      "x": -20,
      "y": 12,
      "z": -5,
      "name": "Wood_Deadwood_Planks_Half",
      "rotation": 32
    },
    {
      "x": -20,
      "y": 15,
      "z": -5,
      "name": "Wood_Deadwood_Planks_Half",
      "rotation": 32
    },
    {
      "x": -20,
      "y": 16,
      "z": -5,
      "name": "Deco_Rope_Diagonal",
      "rotation": 2
    },
    {
      "x": -20,
      "y": 7,
      "z": -4,
      "name": "Rock_Ice_Icicles",
      "rotation": 8
    },
    {
      "x": -20,
      "y": 8,
      "z": -4,
      "name": "Wood_Blackwood_Planks",
      "rotation": 2
    },
    {
      "x": -20,
      "y": 12,
      "z": -4,
      "name": "Wood_Deadwood_Planks_Half",
      "rotation": 32
    },
    {
      "x": -20,
      "y": 15,
      "z": -4,
      "name": "Wood_Deadwood_Planks_Half",
      "rotation": 32
    },
    {
      "x": -20,
      "y": 16,
      "z": -4,
      "name": "Bench_Farming",
      "filler": 31
    },
    {
      "x": -20,
      "y": 17,
      "z": -4,
      "name": "Metal_Bronze_Pipe_Large",
      "rotation": 5
    },
    {
      "x": -20,
      "y": 7,
      "z": -3,
      "name": "Wood_Fir_Trunk_Full_Locked",
      "support": 15,
      "rotation": 5
    },
    {
      "x": -20,
      "y": 8,
      "z": -3,
      "name": "Wood_Fir_Trunk_Full_Locked",
      "support": 15,
      "rotation": 5
    },
    {
      "x": -20,
      "y": 12,
      "z": -3,
      "name": "Wood_Fir_Trunk_Full_Locked",
      "support": 15,
      "rotation": 5
    },
    {
      "x": -20,
      "y": 15,
      "z": -3,
      "name": "Wood_Fir_Trunk_Full_Locked",
      "support": 15,
      "rotation": 5
    },
    {
      "x": -20,
      "y": 16,
      "z": -3,
      "name": "Deco_Rope_Diagonal"
    },
    {
      "x": -20,
      "y": 7,
      "z": -2,
      "name": "Wood_Blackwood_Planks",
      "rotation": 2
    },
    {
      "x": -20,
      "y": 8,
      "z": -2,
      "name": "Wood_Deadwood_Planks_Half",
      "rotation": 32
    },
    {
      "x": -20,
      "y": 12,
      "z": -2,
      "name": "Wood_Deadwood_Planks_Half",
      "rotation": 32
    },
    {
      "x": -20,
      "y": 15,
      "z": -2,
      "name": "Wood_Deadwood_Planks_Half",
      "rotation": 32
    },
    {
      "x": -20,
      "y": 6,
      "z": -1,
      "name": "Wood_Blackwood_Planks",
      "rotation": 2
    },
    {
      "x": -20,
      "y": 7,
      "z": -1,
      "name": "Wood_Blackwood_Planks",
      "rotation": 2
    },
    {
      "x": -20,
      "y": 8,
      "z": -1,
      "name": "Wood_Deadwood_Planks_Half",
      "rotation": 32
    },
    {
      "x": -20,
      "y": 12,
      "z": -1,
      "name": "Wood_Deadwood_Planks_Half",
      "rotation": 32
    },
    {
      "x": -20,
      "y": 15,
      "z": -1,
      "name": "Wood_Deadwood_Planks_Half",
      "rotation": 32
    },
    {
      "x": -20,
      "y": 5,
      "z": 0,
      "name": "Wood_Fir_Trunk_Full_Locked",
      "support": 15,
      "rotation": 5
    },
    {
      "x": -20,
      "y": 6,
      "z": 0,
      "name": "Wood_Fir_Trunk_Full_Locked",
      "support": 15,
      "rotation": 5
    },
    {
      "x": -20,
      "y": 8,
      "z": 0,
      "name": "Wood_Fir_Trunk_Full_Locked",
      "support": 15,
      "rotation": 5
    },
    {
      "x": -20,
      "y": 12,
      "z": 0,
      "name": "Wood_Fir_Trunk_Full_Locked",
      "support": 15,
      "rotation": 5
    },
    {
      "x": -20,
      "y": 15,
      "z": 0,
      "name": "Wood_Fir_Trunk_Full_Locked",
      "support": 15,
      "rotation": 5
    },
    {
      "x": -20,
      "y": 26,
      "z": 0,
      "name": "Deco_Rope_Diagonal",
      "rotation": 3
    },
    {
      "x": -20,
      "y": 6,
      "z": 1,
      "name": "Wood_Blackwood_Planks"
    },
    {
      "x": -20,
      "y": 7,
      "z": 1,
      "name": "Wood_Blackwood_Planks"
    },
    {
      "x": -20,
      "y": 8,
      "z": 1,
      "name": "Wood_Deadwood_Planks_Half",
      "rotation": 8
    },
    {
      "x": -20,
      "y": 12,
      "z": 1,
      "name": "Wood_Deadwood_Planks_Half",
      "rotation": 8
    },
    {
      "x": -20,
      "y": 15,
      "z": 1,
      "name": "Wood_Deadwood_Planks_Half",
      "rotation": 8
    },
    {
      "x": -20,
      "y": 7,
      "z": 2,
      "name": "Wood_Blackwood_Planks"
    },
    {
      "x": -20,
      "y": 8,
      "z": 2,
      "name": "Wood_Deadwood_Planks_Half",
      "rotation": 8
    },
    {
      "x": -20,
      "y": 12,
      "z": 2,
      "name": "Wood_Deadwood_Planks_Half",
      "rotation": 8
    },
    {
      "x": -20,
      "y": 15,
      "z": 2,
      "name": "Wood_Deadwood_Planks_Half",
      "rotation": 8
    },
    {
      "x": -20,
      "y": 7,
      "z": 3,
      "name": "Wood_Fir_Trunk_Full_Locked",
      "support": 15,
      "rotation": 5
    },
    {
      "x": -20,
      "y": 8,
      "z": 3,
      "name": "Wood_Fir_Trunk_Full_Locked",
      "support": 15,
      "rotation": 5
    },
    {
      "x": -20,
      "y": 12,
      "z": 3,
      "name": "Wood_Fir_Trunk_Full_Locked",
      "support": 15,
      "rotation": 5
    },
    {
      "x": -20,
      "y": 15,
      "z": 3,
      "name": "Wood_Fir_Trunk_Full_Locked",
      "support": 15,
      "rotation": 5
    },
    {
      "x": -20,
      "y": 16,
      "z": 3,
      "name": "Deco_Rope_Diagonal",
      "rotation": 2
    },
    {
      "x": -20,
      "y": 8,
      "z": 4,
      "name": "Wood_Blackwood_Planks"
    },
    {
      "x": -20,
      "y": 12,
      "z": 4,
      "name": "Wood_Deadwood_Planks_Half",
      "rotation": 8
    },
    {
      "x": -20,
      "y": 15,
      "z": 4,
      "name": "Wood_Deadwood_Planks_Half",
      "rotation": 8
    },
    {
      "x": -20,
      "y": 16,
      "z": 4,
      "name": "Bench_Farming",
      "components": {
        "Components": {
          "BenchBlock": {
            "TierLevel": 1,
            "UpgradeItems": []
          },
          "PlacedByInteraction": {
            "WhoPlacedUuid": {
              "$binary": "+u0Lek23TWiDpMOn5L2LqA==",
              "$type": "04"
            }
          }
        }
      },
      "rotation": 2
    },
    {
      "x": -20,
      "y": 17,
      "z": 4,
      "name": "Metal_Bronze_Pipe_Large",
      "rotation": 5
    },
    {
      "x": -20,
      "y": 9,
      "z": 5,
      "name": "Wood_Blackwood_Planks"
    },
    {
      "x": -20,
      "y": 12,
      "z": 5,
      "name": "Wood_Deadwood_Planks_Half",
      "rotation": 8
    },
    {
      "x": -20,
      "y": 15,
      "z": 5,
      "name": "Wood_Deadwood_Planks_Half",
      "rotation": 8
    },
    {
      "x": -20,
      "y": 16,
      "z": 5,
      "name": "Deco_Rope_Diagonal"
    },
    {
      "x": -20,
      "y": 10,
      "z": 6,
      "name": "Wood_Fir_Trunk_Full_Locked",
      "support": 15,
      "rotation": 5
    },
    {
      "x": -20,
      "y": 11,
      "z": 6,
      "name": "Wood_Fir_Trunk_Full_Locked",
      "support": 15,
      "rotation": 5
    },
    {
      "x": -20,
      "y": 12,
      "z": 6,
      "name": "Wood_Fir_Trunk_Full_Locked",
      "support": 15,
      "rotation": 5
    },
    {
      "x": -20,
      "y": 13,
      "z": 6,
      "name": "Wood_Blackwood_Planks"
    },
    {
      "x": -20,
      "y": 14,
      "z": 6,
      "name": "Wood_Blackwood_Planks"
    },
    {
      "x": -20,
      "y": 15,
      "z": 6,
      "name": "Wood_Fir_Trunk_Full_Locked",
      "support": 15,
      "rotation": 5
    },
    {
      "x": -20,
      "y": 16,
      "z": 6,
      "name": "*Wood_Blackwood_Fence_State_Definitions_Corner"
    },
    {
      "x": -20,
      "y": 12,
      "z": 7,
      "name": "Wood_Fir_Trunk_Full_Locked",
      "support": 15,
      "rotation": 5
    },
    {
      "x": -20,
      "y": 13,
      "z": 7,
      "name": "Wood_Blackwood_Planks"
    },
    {
      "x": -20,
      "y": 14,
      "z": 7,
      "name": "Wood_Blackwood_Planks"
    },
    {
      "x": -20,
      "y": 15,
      "z": 7,
      "name": "Wood_Fir_Trunk_Full_Locked",
      "support": 15,
      "rotation": 5
    },
    {
      "x": -20,
      "y": 16,
      "z": 7,
      "name": "*Wood_Blackwood_Fence_State_Definitions_Corner",
      "rotation": 2
    },
    {
      "x": -19,
      "y": 10,
      "z": -7,
      "name": "Wood_Blackwood_Planks",
      "rotation": 2
    },
    {
      "x": -19,
      "y": 11,
      "z": -7,
      "name": "Wood_Blackwood_Planks",
      "rotation": 2
    },
    {
      "x": -19,
      "y": 12,
      "z": -7,
      "name": "Wood_Fir_Trunk_Full_Locked",
      "support": 15,
      "rotation": 6
    },
    {
      "x": -19,
      "y": 13,
      "z": -7,
      "name": "Wood_Blackwood_Planks",
      "rotation": 2
    },
    {
      "x": -19,
      "y": 14,
      "z": -7,
      "name": "Wood_Blackwood_Planks",
      "rotation": 2
    },
    {
      "x": -19,
      "y": 15,
      "z": -7,
      "name": "Wood_Fir_Trunk_Full_Locked",
      "support": 15,
      "rotation": 5
    },
    {
      "x": -19,
      "y": 16,
      "z": -7,
      "name": "Wood_Blackwood_Fence",
      "rotation": 2
    },
    {
      "x": -19,
      "y": 9,
      "z": -6,
      "name": "Wood_Fir_Trunk_Full_Locked",
      "support": 15,
      "rotation": 5
    },
    {
      "x": -19,
      "y": 10,
      "z": -6,
      "name": "Wood_Fir_Trunk_Full_Locked",
      "support": 15,
      "rotation": 5
    },
    {
      "x": -19,
      "y": 12,
      "z": -6,
      "name": "Wood_Fir_Trunk_Full_Locked",
      "support": 15,
      "rotation": 5
    },
    {
      "x": -19,
      "y": 15,
      "z": -6,
      "name": "Wood_Fir_Trunk_Full_Locked",
      "support": 15,
      "rotation": 5
    },
    {
      "x": -19,
      "y": 8,
      "z": -5,
      "name": "Wood_Blackwood_Planks",
      "rotation": 2
    },
    {
      "x": -19,
      "y": 12,
      "z": -5,
      "name": "Wood_Deadwood_Planks_Half",
      "rotation": 32
    },
    {
      "x": -19,
      "y": 15,
      "z": -5,
      "name": "Wood_Deadwood_Planks_Half",
      "rotation": 32
    },
    {
      "x": -19,
      "y": 16,
      "z": -5,
      "name": "Deco_Rope_Diagonal",
      "rotation": 2
    },
    {
      "x": -19,
      "y": 8,
      "z": -4,
      "name": "Wood_Blackwood_Planks",
      "rotation": 2
    },
    {
      "x": -19,
      "y": 12,
      "z": -4,
      "name": "Wood_Deadwood_Planks_Half",
      "rotation": 32
    },
    {
      "x": -19,
      "y": 15,
      "z": -4,
      "name": "Wood_Deadwood_Planks_Half",
      "rotation": 32
    },
    {
      "x": -19,
      "y": 16,
      "z": -4,
      "name": "Bench_Farming",
      "components": {
        "Components": {
          "BenchBlock": {
            "TierLevel": 1,
            "UpgradeItems": []
          },
          "PlacedByInteraction": {
            "WhoPlacedUuid": {
              "$binary": "+u0Lek23TWiDpMOn5L2LqA==",
              "$type": "04"
            }
          }
        }
      }
    },
    {
      "x": -19,
      "y": 17,
      "z": -4,
      "name": "Metal_Bronze_Pipe_Large_Mouthpiece",
      "rotation": 5
    },
    {
      "x": -19,
      "y": 7,
      "z": -3,
      "name": "Wood_Fir_Trunk_Full_Locked",
      "support": 15,
      "rotation": 5
    },
    {
      "x": -19,
      "y": 8,
      "z": -3,
      "name": "Wood_Fir_Trunk_Full_Locked",
      "support": 15,
      "rotation": 5
    },
    {
      "x": -19,
      "y": 12,
      "z": -3,
      "name": "Wood_Fir_Trunk_Full_Locked",
      "support": 15,
      "rotation": 5
    },
    {
      "x": -19,
      "y": 15,
      "z": -3,
      "name": "Wood_Fir_Trunk_Full_Locked",
      "support": 15,
      "rotation": 5
    },
    {
      "x": -19,
      "y": 16,
      "z": -3,
      "name": "Deco_Rope_Diagonal"
    },
    {
      "x": -19,
      "y": 6,
      "z": -2,
      "name": "Wood_Blackwood_Planks",
      "rotation": 2
    },
    {
      "x": -19,
      "y": 7,
      "z": -2,
      "name": "Wood_Blackwood_Planks",
      "rotation": 2
    },
    {
      "x": -19,
      "y": 8,
      "z": -2,
      "name": "Wood_Deadwood_Planks_Half",
      "rotation": 32
    },
    {
      "x": -19,
      "y": 12,
      "z": -2,
      "name": "Wood_Deadwood_Planks_Half",
      "rotation": 32
    },
    {
      "x": -19,
      "y": 15,
      "z": -2,
      "name": "Wood_Deadwood_Planks_Half",
      "rotation": 32
    },
    {
      "x": -19,
      "y": 6,
      "z": -1,
      "name": "Wood_Blackwood_Planks",
      "rotation": 2
    },
    {
      "x": -19,
      "y": 8,
      "z": -1,
      "name": "Wood_Deadwood_Planks_Half",
      "rotation": 32
    },
    {
      "x": -19,
      "y": 12,
      "z": -1,
      "name": "Wood_Deadwood_Planks_Half",
      "rotation": 32
    },
    {
      "x": -19,
      "y": 15,
      "z": -1,
      "name": "Wood_Deadwood_Planks_Half",
      "rotation": 32
    },
    {
      "x": -19,
      "y": 4,
      "z": 0,
      "name": "Wood_Fir_Trunk_Half",
      "rotation": 34
    },
    {
      "x": -19,
      "y": 5,
      "z": 0,
      "name": "Wood_Fir_Trunk_Full_Locked",
      "support": 15,
      "rotation": 2
    },
    {
      "x": -19,
      "y": 8,
      "z": 0,
      "name": "Wood_Fir_Trunk_Full_Locked",
      "support": 15,
      "rotation": 5
    },
    {
      "x": -19,
      "y": 12,
      "z": 0,
      "name": "Wood_Fir_Trunk_Full_Locked",
      "support": 15,
      "rotation": 5
    },
    {
      "x": -19,
      "y": 15,
      "z": 0,
      "name": "Wood_Fir_Trunk_Full_Locked",
      "support": 15,
      "rotation": 5
    },
    {
      "x": -19,
      "y": 27,
      "z": 0,
      "name": "Deco_Rope_Diagonal",
      "rotation": 3
    },
    {
      "x": -19,
      "y": 6,
      "z": 1,
      "name": "Wood_Blackwood_Planks"
    },
    {
      "x": -19,
      "y": 8,
      "z": 1,
      "name": "Wood_Deadwood_Planks_Half",
      "rotation": 8
    },
    {
      "x": -19,
      "y": 12,
      "z": 1,
      "name": "Wood_Deadwood_Planks_Half",
      "rotation": 8
    },
    {
      "x": -19,
      "y": 15,
      "z": 1,
      "name": "Wood_Deadwood_Planks_Half",
      "rotation": 8
    },
    {
      "x": -19,
      "y": 6,
      "z": 2,
      "name": "Wood_Blackwood_Planks"
    },
    {
      "x": -19,
      "y": 7,
      "z": 2,
      "name": "Wood_Blackwood_Planks"
    },
    {
      "x": -19,
      "y": 8,
      "z": 2,
      "name": "Wood_Deadwood_Planks_Half",
      "rotation": 8
    },
    {
      "x": -19,
      "y": 12,
      "z": 2,
      "name": "Wood_Deadwood_Planks_Half",
      "rotation": 8
    },
    {
      "x": -19,
      "y": 15,
      "z": 2,
      "name": "Wood_Deadwood_Planks_Half",
      "rotation": 8
    },
    {
      "x": -19,
      "y": 7,
      "z": 3,
      "name": "Wood_Fir_Trunk_Full_Locked",
      "support": 15,
      "rotation": 5
    },
    {
      "x": -19,
      "y": 8,
      "z": 3,
      "name": "Wood_Fir_Trunk_Full_Locked",
      "support": 15,
      "rotation": 5
    },
    {
      "x": -19,
      "y": 12,
      "z": 3,
      "name": "Wood_Fir_Trunk_Full_Locked",
      "support": 15,
      "rotation": 5
    },
    {
      "x": -19,
      "y": 15,
      "z": 3,
      "name": "Wood_Fir_Trunk_Full_Locked",
      "support": 15,
      "rotation": 5
    },
    {
      "x": -19,
      "y": 16,
      "z": 3,
      "name": "Deco_Rope_Diagonal",
      "rotation": 2
    },
    {
      "x": -19,
      "y": 8,
      "z": 4,
      "name": "Wood_Blackwood_Planks"
    },
    {
      "x": -19,
      "y": 12,
      "z": 4,
      "name": "Wood_Deadwood_Planks_Half",
      "rotation": 8
    },
    {
      "x": -19,
      "y": 15,
      "z": 4,
      "name": "Wood_Deadwood_Planks_Half",
      "rotation": 8
    },
    {
      "x": -19,
      "y": 16,
      "z": 4,
      "name": "Bench_Farming",
      "filler": 1,
      "rotation": 2
    },
    {
      "x": -19,
      "y": 17,
      "z": 4,
      "name": "Metal_Bronze_Pipe_Large_Mouthpiece",
      "rotation": 5
    },
    {
      "x": -19,
      "y": 8,
      "z": 5,
      "name": "Wood_Blackwood_Planks"
    },
    {
      "x": -19,
      "y": 12,
      "z": 5,
      "name": "Wood_Deadwood_Planks_Half",
      "rotation": 8
    },
    {
      "x": -19,
      "y": 15,
      "z": 5,
      "name": "Wood_Deadwood_Planks_Half",
      "rotation": 8
    },
    {
      "x": -19,
      "y": 16,
      "z": 5,
      "name": "Deco_Rope_Diagonal"
    },
    {
      "x": -19,
      "y": 9,
      "z": 6,
      "name": "Wood_Fir_Trunk_Full_Locked",
      "support": 15,
      "rotation": 5
    },
    {
      "x": -19,
      "y": 10,
      "z": 6,
      "name": "Wood_Fir_Trunk_Full_Locked",
      "support": 15,
      "rotation": 5
    },
    {
      "x": -19,
      "y": 12,
      "z": 6,
      "name": "Wood_Fir_Trunk_Full_Locked",
      "support": 15,
      "rotation": 5
    },
    {
      "x": -19,
      "y": 15,
      "z": 6,
      "name": "Wood_Fir_Trunk_Full_Locked",
      "support": 15,
      "rotation": 5
    },
    {
      "x": -19,
      "y": 10,
      "z": 7,
      "name": "Wood_Blackwood_Planks"
    },
    {
      "x": -19,
      "y": 11,
      "z": 7,
      "name": "Wood_Blackwood_Planks"
    },
    {
      "x": -19,
      "y": 12,
      "z": 7,
      "name": "Wood_Fir_Trunk_Full_Locked",
      "support": 15,
      "rotation": 4
    },
    {
      "x": -19,
      "y": 13,
      "z": 7,
      "name": "Wood_Blackwood_Planks"
    },
    {
      "x": -19,
      "y": 14,
      "z": 7,
      "name": "Wood_Blackwood_Planks"
    },
    {
      "x": -19,
      "y": 15,
      "z": 7,
      "name": "Wood_Fir_Trunk_Full_Locked",
      "support": 15,
      "rotation": 5
    },
    {
      "x": -19,
      "y": 16,
      "z": 7,
      "name": "Wood_Blackwood_Fence"
    },
    {
      "x": -18,
      "y": 11,
      "z": -8,
      "name": "Wood_Fir_Trunk_Full_Locked",
      "support": 15,
      "rotation": 5
    },
    {
      "x": -18,
      "y": 12,
      "z": -8,
      "name": "Wood_Fir_Trunk_Full_Locked",
      "support": 15,
      "rotation": 5
    },
    {
      "x": -18,
      "y": 13,
      "z": -8,
      "name": "Wood_Fir_Trunk_Full_Locked",
      "support": 15,
      "rotation": 2
    },
    {
      "x": -18,
      "y": 14,
      "z": -8,
      "name": "Wood_Fir_Trunk_Full_Locked",
      "support": 15,
      "rotation": 2
    },
    {
      "x": -18,
      "y": 15,
      "z": -8,
      "name": "Wood_Fir_Trunk_Full_Locked",
      "support": 15,
      "rotation": 2
    },
    {
      "x": -18,
      "y": 16,
      "z": -8,
      "name": "*Wood_Blackwood_Fence_State_Definitions_Corner",
      "rotation": 1
    },
    {
      "x": -18,
      "y": 9,
      "z": -7,
      "name": "Wood_Blackwood_Planks",
      "rotation": 2
    },
    {
      "x": -18,
      "y": 10,
      "z": -7,
      "name": "Wood_Blackwood_Planks",
      "rotation": 2
    },
    {
      "x": -18,
      "y": 11,
      "z": -7,
      "name": "Wood_Blackwood_Planks",
      "rotation": 2
    },
    {
      "x": -18,
      "y": 12,
      "z": -7,
      "name": "Wood_Fir_Trunk_Full_Locked",
      "support": 15,
      "rotation": 5
    },
    {
      "x": -18,
      "y": 13,
      "z": -7,
      "name": "Wood_Fir_Trunk_Full_Locked",
      "support": 15,
      "rotation": 2
    },
    {
      "x": -18,
      "y": 14,
      "z": -7,
      "name": "Wood_Fir_Trunk_Full_Locked",
      "support": 15,
      "rotation": 2
    },
    {
      "x": -18,
      "y": 15,
      "z": -7,
      "name": "Wood_Fir_Trunk_Full_Locked",
      "support": 15,
      "rotation": 5
    },
    {
      "x": -18,
      "y": 16,
      "z": -7,
      "name": "*Wood_Blackwood_Fence_State_Definitions_Corner",
      "rotation": 3
    },
    {
      "x": -18,
      "y": 8,
      "z": -6,
      "name": "Wood_Fir_Trunk_Full_Locked",
      "support": 15,
      "rotation": 5
    },
    {
      "x": -18,
      "y": 9,
      "z": -6,
      "name": "Wood_Fir_Trunk_Full_Locked",
      "support": 15,
      "rotation": 5
    },
    {
      "x": -18,
      "y": 12,
      "z": -6,
      "name": "Wood_Fir_Trunk_Full_Locked",
      "support": 15,
      "rotation": 5
    },
    {
      "x": -18,
      "y": 15,
      "z": -6,
      "name": "Wood_Fir_Trunk_Full_Locked",
      "support": 15,
      "rotation": 5
    },
    {
      "x": -18,
      "y": 8,
      "z": -5,
      "name": "Wood_Blackwood_Planks",
      "rotation": 2
    },
    {
      "x": -18,
      "y": 12,
      "z": -5,
      "name": "Wood_Fir_Trunk_Full_Locked",
      "support": 15,
      "rotation": 6
    },
    {
      "x": -18,
      "y": 15,
      "z": -5,
      "name": "Wood_Deadwood_Planks_Half",
      "rotation": 32
    },
    {
      "x": -18,
      "y": 7,
      "z": -4,
      "name": "Wood_Blackwood_Planks",
      "rotation": 2
    },
    {
      "x": -18,
      "y": 8,
      "z": -4,
      "name": "Wood_Fir_Trunk_Full_Locked",
      "support": 15,
      "rotation": 6
    },
    {
      "x": -18,
      "y": 12,
      "z": -4,
      "name": "Wood_Fir_Trunk_Full_Locked",
      "support": 15,
      "rotation": 6
    },
    {
      "x": -18,
      "y": 15,
      "z": -4,
      "name": "Wood_Deadwood_Planks_Half",
      "rotation": 32
    },
    {
      "x": -18,
      "y": 6,
      "z": -3,
      "name": "Wood_Fir_Trunk_Full_Locked",
      "support": 15,
      "rotation": 5
    },
    {
      "x": -18,
      "y": 7,
      "z": -3,
      "name": "Wood_Fir_Trunk_Full_Locked",
      "support": 15,
      "rotation": 5
    },
    {
      "x": -18,
      "y": 8,
      "z": -3,
      "name": "Wood_Fir_Trunk_Full_Locked",
      "support": 15,
      "rotation": 5
    },
    {
      "x": -18,
      "y": 12,
      "z": -3,
      "name": "Wood_Fir_Trunk_Full_Locked",
      "support": 15,
      "rotation": 6
    },
    {
      "x": -18,
      "y": 13,
      "z": -3,
      "name": "Wood_Fir_Trunk_Full_Locked",
      "support": 15,
      "rotation": 2
    },
    {
      "x": -18,
      "y": 14,
      "z": -3,
      "name": "Wood_Fir_Trunk_Full_Locked",
      "support": 15,
      "rotation": 2
    },
    {
      "x": -18,
      "y": 15,
      "z": -3,
      "name": "Wood_Fir_Trunk_Full_Locked",
      "support": 15,
      "rotation": 5
    },
    {
      "x": -18,
      "y": 6,
      "z": -2,
      "name": "Wood_Blackwood_Planks",
      "rotation": 2
    },
    {
      "x": -18,
      "y": 8,
      "z": -2,
      "name": "Wood_Deadwood_Planks_Half",
      "rotation": 32
    },
    {
      "x": -18,
      "y": 12,
      "z": -2,
      "name": "Wood_Fir_Trunk_Full_Locked",
      "support": 15,
      "rotation": 6
    },
    {
      "x": -18,
      "y": 15,
      "z": -2,
      "name": "Wood_Deadwood_Planks_Half",
      "rotation": 32
    },
    {
      "x": -18,
      "y": 5,
      "z": -1,
      "name": "Wood_Blackwood_Planks",
      "rotation": 2
    },
    {
      "x": -18,
      "y": 8,
      "z": -1,
      "name": "Wood_Deadwood_Planks_Half",
      "rotation": 32
    },
    {
      "x": -18,
      "y": 12,
      "z": -1,
      "name": "Wood_Fir_Trunk_Full_Locked",
      "support": 15,
      "rotation": 6
    },
    {
      "x": -18,
      "y": 15,
      "z": -1,
      "name": "Wood_Deadwood_Planks_Half",
      "rotation": 32
    },
    {
      "x": -18,
      "y": 4,
      "z": 0,
      "name": "Wood_Fir_Trunk_Full_Locked",
      "support": 15,
      "rotation": 5
    },
    {
      "x": -18,
      "y": 5,
      "z": 0,
      "name": "Wood_Fir_Trunk_Full_Locked",
      "support": 15,
      "rotation": 5
    },
    {
      "x": -18,
      "y": 8,
      "z": 0,
      "name": "Wood_Fir_Trunk_Full_Locked",
      "support": 15,
      "rotation": 5
    },
    {
      "x": -18,
      "y": 12,
      "z": 0,
      "name": "Wood_Fir_Trunk_Full_Locked",
      "support": 15,
      "rotation": 4
    },
    {
      "x": -18,
      "y": 15,
      "z": 0,
      "name": "Wood_Fir_Trunk_Full_Locked",
      "support": 15,
      "rotation": 5
    },
    {
      "x": -18,
      "y": 28,
      "z": 0,
      "name": "Deco_Rope_Diagonal",
      "rotation": 3
    },
    {
      "x": -18,
      "y": 5,
      "z": 1,
      "name": "Wood_Blackwood_Planks"
    },
    {
      "x": -18,
      "y": 8,
      "z": 1,
      "name": "Wood_Deadwood_Planks_Half",
      "rotation": 8
    },
    {
      "x": -18,
      "y": 12,
      "z": 1,
      "name": "Wood_Fir_Trunk_Full_Locked",
      "support": 15,
      "rotation": 4
    },
    {
      "x": -18,
      "y": 15,
      "z": 1,
      "name": "Wood_Deadwood_Planks_Half",
      "rotation": 8
    },
    {
      "x": -18,
      "y": 6,
      "z": 2,
      "name": "Wood_Blackwood_Planks"
    },
    {
      "x": -18,
      "y": 8,
      "z": 2,
      "name": "Wood_Deadwood_Planks_Half",
      "rotation": 8
    },
    {
      "x": -18,
      "y": 12,
      "z": 2,
      "name": "Wood_Fir_Trunk_Full_Locked",
      "support": 15,
      "rotation": 4
    },
    {
      "x": -18,
      "y": 15,
      "z": 2,
      "name": "Wood_Deadwood_Planks_Half",
      "rotation": 8
    },
    {
      "x": -18,
      "y": 6,
      "z": 3,
      "name": "Wood_Fir_Trunk_Full_Locked",
      "support": 15,
      "rotation": 5
    },
    {
      "x": -18,
      "y": 7,
      "z": 3,
      "name": "Wood_Fir_Trunk_Full_Locked",
      "support": 15,
      "rotation": 5
    },
    {
      "x": -18,
      "y": 8,
      "z": 3,
      "name": "Wood_Fir_Trunk_Full_Locked",
      "support": 15,
      "rotation": 5
    },
    {
      "x": -18,
      "y": 12,
      "z": 3,
      "name": "Wood_Fir_Trunk_Full_Locked",
      "support": 15,
      "rotation": 4
    },
    {
      "x": -18,
      "y": 13,
      "z": 3,
      "name": "Wood_Fir_Trunk_Full_Locked",
      "support": 15
    },
    {
      "x": -18,
      "y": 14,
      "z": 3,
      "name": "Wood_Fir_Trunk_Full_Locked",
      "support": 15
    },
    {
      "x": -18,
      "y": 15,
      "z": 3,
      "name": "Wood_Fir_Trunk_Full_Locked",
      "support": 15,
      "rotation": 5
    },
    {
      "x": -18,
      "y": 7,
      "z": 4,
      "name": "Wood_Blackwood_Planks"
    },
    {
      "x": -18,
      "y": 8,
      "z": 4,
      "name": "Wood_Fir_Trunk_Full_Locked",
      "support": 15,
      "rotation": 4
    },
    {
      "x": -18,
      "y": 12,
      "z": 4,
      "name": "Wood_Fir_Trunk_Full_Locked",
      "support": 15,
      "rotation": 4
    },
    {
      "x": -18,
      "y": 15,
      "z": 4,
      "name": "Wood_Deadwood_Planks_Half",
      "rotation": 8
    },
    {
      "x": -18,
      "y": 8,
      "z": 5,
      "name": "Wood_Blackwood_Planks"
    },
    {
      "x": -18,
      "y": 12,
      "z": 5,
      "name": "Wood_Fir_Trunk_Full_Locked",
      "support": 15,
      "rotation": 4
    },
    {
      "x": -18,
      "y": 15,
      "z": 5,
      "name": "Wood_Deadwood_Planks_Half",
      "rotation": 8
    },
    {
      "x": -18,
      "y": 8,
      "z": 6,
      "name": "Wood_Fir_Trunk_Full_Locked",
      "support": 15,
      "rotation": 5
    },
    {
      "x": -18,
      "y": 9,
      "z": 6,
      "name": "Wood_Fir_Trunk_Full_Locked",
      "support": 15,
      "rotation": 5
    },
    {
      "x": -18,
      "y": 12,
      "z": 6,
      "name": "Wood_Fir_Trunk_Full_Locked",
      "support": 15,
      "rotation": 5
    },
    {
      "x": -18,
      "y": 15,
      "z": 6,
      "name": "Wood_Fir_Trunk_Full_Locked",
      "support": 15,
      "rotation": 5
    },
    {
      "x": -18,
      "y": 9,
      "z": 7,
      "name": "Wood_Blackwood_Planks"
    },
    {
      "x": -18,
      "y": 10,
      "z": 7,
      "name": "Wood_Blackwood_Planks"
    },
    {
      "x": -18,
      "y": 11,
      "z": 7,
      "name": "Wood_Blackwood_Planks"
    },
    {
      "x": -18,
      "y": 12,
      "z": 7,
      "name": "Wood_Fir_Trunk_Full_Locked",
      "support": 15,
      "rotation": 5
    },
    {
      "x": -18,
      "y": 13,
      "z": 7,
      "name": "Wood_Fir_Trunk_Full_Locked",
      "support": 15
    },
    {
      "x": -18,
      "y": 14,
      "z": 7,
      "name": "Wood_Fir_Trunk_Full_Locked",
      "support": 15
    },
    {
      "x": -18,
      "y": 15,
      "z": 7,
      "name": "Wood_Fir_Trunk_Full_Locked",
      "support": 15,
      "rotation": 5
    },
    {
      "x": -18,
      "y": 16,
      "z": 7,
      "name": "*Wood_Blackwood_Fence_State_Definitions_Corner"
    },
    {
      "x": -18,
      "y": 9,
      "z": 8,
      "name": "Rock_Ice_Stalactite_Large",
      "filler": 31744,
      "rotation": 8
    },
    {
      "x": -18,
      "y": 10,
      "z": 8,
      "name": "Rock_Ice_Stalactite_Large",
      "rotation": 8
    },
    {
      "x": -18,
      "y": 11,
      "z": 8,
      "name": "Wood_Fir_Trunk_Full_Locked",
      "support": 15,
      "rotation": 5
    },
    {
      "x": -18,
      "y": 12,
      "z": 8,
      "name": "Wood_Fir_Trunk_Full_Locked",
      "support": 15,
      "rotation": 5
    },
    {
      "x": -18,
      "y": 13,
      "z": 8,
      "name": "Wood_Fir_Trunk_Full_Locked",
      "support": 15
    },
    {
      "x": -18,
      "y": 14,
      "z": 8,
      "name": "Wood_Fir_Trunk_Full_Locked",
      "support": 15
    },
    {
      "x": -18,
      "y": 15,
      "z": 8,
      "name": "Wood_Fir_Trunk_Full_Locked",
      "support": 15
    },
    {
      "x": -18,
      "y": 16,
      "z": 8,
      "name": "*Wood_Blackwood_Fence_State_Definitions_Corner",
      "rotation": 2
    },
    {
      "x": -17,
      "y": 10,
      "z": -8,
      "name": "Wood_Fir_Trunk_Full_Locked",
      "support": 15,
      "rotation": 5
    },
    {
      "x": -17,
      "y": 11,
      "z": -8,
      "name": "Wood_Fir_Trunk_Full_Locked",
      "support": 15,
      "rotation": 5
    },
    {
      "x": -17,
      "y": 12,
      "z": -8,
      "name": "Wood_Fir_Trunk_Full_Locked",
      "support": 15,
      "rotation": 5
    },
    {
      "x": -17,
      "y": 13,
      "z": -8,
      "name": "Wood_Blackwood_Planks",
      "rotation": 2
    },
    {
      "x": -17,
      "y": 14,
      "z": -8,
      "name": "Wood_Blackwood_Planks",
      "rotation": 2
    },
    {
      "x": -17,
      "y": 15,
      "z": -8,
      "name": "Wood_Fir_Trunk_Full_Locked",
      "support": 15,
      "rotation": 5
    },
    {
      "x": -17,
      "y": 16,
      "z": -8,
      "name": "Wood_Blackwood_Fence",
      "rotation": 2
    },
    {
      "x": -17,
      "y": 9,
      "z": -7,
      "name": "Wood_Blackwood_Planks",
      "rotation": 2
    },
    {
      "x": -17,
      "y": 10,
      "z": -7,
      "name": "Wood_Blackwood_Planks",
      "rotation": 2
    },
    {
      "x": -17,
      "y": 12,
      "z": -7,
      "name": "Wood_Deadwood_Planks",
      "rotation": 2
    },
    {
      "x": -17,
      "y": 15,
      "z": -7,
      "name": "Wood_Deadwood_Planks_Half",
      "rotation": 8
    },
    {
      "x": -17,
      "y": 8,
      "z": -6,
      "name": "Wood_Fir_Trunk_Full_Locked",
      "support": 15,
      "rotation": 5
    },
    {
      "x": -17,
      "y": 12,
      "z": -6,
      "name": "Wood_Fir_Trunk_Full_Locked",
      "support": 15,
      "rotation": 5
    },
    {
      "x": -17,
      "y": 15,
      "z": -6,
      "name": "Wood_Fir_Trunk_Full_Locked",
      "support": 15,
      "rotation": 5
    },
    {
      "x": -17,
      "y": 7,
      "z": -5,
      "name": "Wood_Blackwood_Planks",
      "rotation": 2
    },
    {
      "x": -17,
      "y": 8,
      "z": -5,
      "name": "Wood_Deadwood_Planks",
      "rotation": 2
    },
    {
      "x": -17,
      "y": 12,
      "z": -5,
      "name": "Wood_Deadwood_Planks_Half",
      "rotation": 32
    },
    {
      "x": -17,
      "y": 15,
      "z": -5,
      "name": "Wood_Deadwood_Planks_Half",
      "rotation": 32
    },
    {
      "x": -17,
      "y": 7,
      "z": -4,
      "name": "Wood_Blackwood_Planks",
      "rotation": 2
    },
    {
      "x": -17,
      "y": 8,
      "z": -4,
      "name": "Wood_Deadwood_Planks",
      "rotation": 2
    },
    {
      "x": -17,
      "y": 12,
      "z": -4,
      "name": "Wood_Deadwood_Planks_Half",
      "rotation": 32
    },
    {
      "x": -17,
      "y": 15,
      "z": -4,
      "name": "Wood_Deadwood_Planks_Half",
      "rotation": 32
    },
    {
      "x": -17,
      "y": 6,
      "z": -3,
      "name": "Wood_Fir_Trunk_Full_Locked",
      "support": 15,
      "rotation": 5
    },
    {
      "x": -17,
      "y": 8,
      "z": -3,
      "name": "Wood_Fir_Trunk_Full_Locked",
      "support": 15,
      "rotation": 5
    },
    {
      "x": -17,
      "y": 12,
      "z": -3,
      "name": "Wood_Fir_Trunk_Full_Locked",
      "support": 15,
      "rotation": 5
    },
    {
      "x": -17,
      "y": 13,
      "z": -3,
      "name": "Wood_Deadwood_Planks",
      "rotation": 2
    },
    {
      "x": -17,
      "y": 14,
      "z": -3,
      "name": "Wood_Deadwood_Planks",
      "rotation": 2
    },
    {
      "x": -17,
      "y": 15,
      "z": -3,
      "name": "Wood_Fir_Trunk_Full_Locked",
      "support": 15,
      "rotation": 5
    },
    {
      "x": -17,
      "y": 5,
      "z": -2,
      "name": "Wood_Blackwood_Planks",
      "rotation": 2
    },
    {
      "x": -17,
      "y": 8,
      "z": -2,
      "name": "Wood_Deadwood_Planks",
      "rotation": 2
    },
    {
      "x": -17,
      "y": 15,
      "z": -2,
      "name": "Wood_Deadwood_Planks_Half",
      "rotation": 32
    },
    {
      "x": -17,
      "y": 5,
      "z": -1,
      "name": "Wood_Blackwood_Planks",
      "rotation": 2
    },
    {
      "x": -17,
      "y": 8,
      "z": -1,
      "name": "Wood_Deadwood_Planks",
      "rotation": 2
    },
    {
      "x": -17,
      "y": 15,
      "z": -1,
      "name": "Wood_Deadwood_Planks_Half",
      "rotation": 32
    },
    {
      "x": -17,
      "y": 3,
      "z": 0,
      "name": "Wood_Fir_Trunk_Half",
      "rotation": 34
    },
    {
      "x": -17,
      "y": 4,
      "z": 0,
      "name": "Wood_Fir_Trunk_Full_Locked",
      "support": 15,
      "rotation": 5
    },
    {
      "x": -17,
      "y": 8,
      "z": 0,
      "name": "Wood_Fir_Trunk_Full_Locked",
      "support": 15,
      "rotation": 5
    },
    {
      "x": -17,
      "y": 15,
      "z": 0,
      "name": "Wood_Fir_Trunk_Full_Locked",
      "support": 15,
      "rotation": 5
    },
    {
      "x": -17,
      "y": 29,
      "z": 0,
      "name": "Deco_Rope_Diagonal",
      "rotation": 3
    },
    {
      "x": -17,
      "y": 5,
      "z": 1,
      "name": "Wood_Blackwood_Planks"
    },
    {
      "x": -17,
      "y": 8,
      "z": 1,
      "name": "Wood_Deadwood_Planks"
    },
    {
      "x": -17,
      "y": 15,
      "z": 1,
      "name": "Wood_Deadwood_Planks_Half",
      "rotation": 8
    },
    {
      "x": -17,
      "y": 5,
      "z": 2,
      "name": "Wood_Blackwood_Planks"
    },
    {
      "x": -17,
      "y": 8,
      "z": 2,
      "name": "Wood_Deadwood_Planks"
    },
    {
      "x": -17,
      "y": 15,
      "z": 2,
      "name": "Wood_Deadwood_Planks_Half",
      "rotation": 8
    },
    {
      "x": -17,
      "y": 6,
      "z": 3,
      "name": "Wood_Fir_Trunk_Full_Locked",
      "support": 15,
      "rotation": 5
    },
    {
      "x": -17,
      "y": 8,
      "z": 3,
      "name": "Wood_Fir_Trunk_Full_Locked",
      "support": 15,
      "rotation": 5
    },
    {
      "x": -17,
      "y": 12,
      "z": 3,
      "name": "Wood_Fir_Trunk_Full_Locked",
      "support": 15,
      "rotation": 5
    },
    {
      "x": -17,
      "y": 13,
      "z": 3,
      "name": "Wood_Deadwood_Planks"
    },
    {
      "x": -17,
      "y": 14,
      "z": 3,
      "name": "Wood_Deadwood_Planks"
    },
    {
      "x": -17,
      "y": 15,
      "z": 3,
      "name": "Wood_Fir_Trunk_Full_Locked",
      "support": 15,
      "rotation": 5
    },
    {
      "x": -17,
      "y": 7,
      "z": 4,
      "name": "Wood_Blackwood_Planks"
    },
    {
      "x": -17,
      "y": 8,
      "z": 4,
      "name": "Wood_Deadwood_Planks"
    },
    {
      "x": -17,
      "y": 12,
      "z": 4,
      "name": "Wood_Deadwood_Planks_Half",
      "rotation": 8
    },
    {
      "x": -17,
      "y": 15,
      "z": 4,
      "name": "Wood_Deadwood_Planks_Half",
      "rotation": 8
    },
    {
      "x": -17,
      "y": 7,
      "z": 5,
      "name": "Wood_Blackwood_Planks"
    },
    {
      "x": -17,
      "y": 8,
      "z": 5,
      "name": "Wood_Deadwood_Planks"
    },
    {
      "x": -17,
      "y": 12,
      "z": 5,
      "name": "Wood_Deadwood_Planks_Half",
      "rotation": 8
    },
    {
      "x": -17,
      "y": 15,
      "z": 5,
      "name": "Wood_Deadwood_Planks_Half",
      "rotation": 8
    },
    {
      "x": -17,
      "y": 8,
      "z": 6,
      "name": "Wood_Fir_Trunk_Full_Locked",
      "support": 15,
      "rotation": 5
    },
    {
      "x": -17,
      "y": 12,
      "z": 6,
      "name": "Wood_Fir_Trunk_Full_Locked",
      "support": 15,
      "rotation": 5
    },
    {
      "x": -17,
      "y": 15,
      "z": 6,
      "name": "Wood_Fir_Trunk_Full_Locked",
      "support": 15,
      "rotation": 5
    },
    {
      "x": -17,
      "y": 9,
      "z": 7,
      "name": "Wood_Blackwood_Planks"
    },
    {
      "x": -17,
      "y": 10,
      "z": 7,
      "name": "Wood_Blackwood_Planks"
    },
    {
      "x": -17,
      "y": 12,
      "z": 7,
      "name": "Wood_Deadwood_Planks"
    },
    {
      "x": -17,
      "y": 15,
      "z": 7,
      "name": "Wood_Deadwood_Planks_Half",
      "rotation": 8
    },
    {
      "x": -17,
      "y": 10,
      "z": 8,
      "name": "Wood_Fir_Trunk_Full_Locked",
      "support": 15,
      "rotation": 5
    },
    {
      "x": -17,
      "y": 11,
      "z": 8,
      "name": "Wood_Fir_Trunk_Full_Locked",
      "support": 15,
      "rotation": 5
    },
    {
      "x": -17,
      "y": 12,
      "z": 8,
      "name": "Wood_Fir_Trunk_Full_Locked",
      "support": 15,
      "rotation": 5
    },
    {
      "x": -17,
      "y": 13,
      "z": 8,
      "name": "Wood_Blackwood_Planks"
    },
    {
      "x": -17,
      "y": 14,
      "z": 8,
      "name": "Wood_Blackwood_Planks"
    },
    {
      "x": -17,
      "y": 15,
      "z": 8,
      "name": "Wood_Fir_Trunk_Full_Locked",
      "support": 15,
      "rotation": 5
    },
    {
      "x": -17,
      "y": 16,
      "z": 8,
      "name": "Wood_Blackwood_Fence"
    },
    {
      "x": -16,
      "y": 9,
      "z": -8,
      "name": "Wood_Fir_Trunk_Full_Locked",
      "support": 15,
      "rotation": 5
    },
    {
      "x": -16,
      "y": 10,
      "z": -8,
      "name": "Wood_Blackwood_Planks",
      "rotation": 2
    },
    {
      "x": -16,
      "y": 11,
      "z": -8,
      "name": "Wood_Blackwood_Planks",
      "rotation": 2
    },
    {
      "x": -16,
      "y": 12,
      "z": -8,
      "name": "Wood_Fir_Trunk_Full_Locked",
      "rotation": 5
    },
    {
      "x": -16,
      "y": 13,
      "z": -8,
      "name": "Wood_Blackwood_Planks",
      "rotation": 2
    },
    {
      "x": -16,
      "y": 14,
      "z": -8,
      "name": "Wood_Blackwood_Planks",
      "rotation": 2
    },
    {
      "x": -16,
      "y": 15,
      "z": -8,
      "name": "Wood_Fir_Trunk_Full_Locked",
      "support": 15,
      "rotation": 5
    },
    {
      "x": -16,
      "y": 16,
      "z": -8,
      "name": "Wood_Blackwood_Fence",
      "rotation": 2
    },
    {
      "x": -16,
      "y": 8,
      "z": -7,
      "name": "Wood_Blackwood_Planks",
      "rotation": 2
    },
    {
      "x": -16,
      "y": 9,
      "z": -7,
      "name": "Wood_Blackwood_Planks",
      "rotation": 2
    },
    {
      "x": -16,
      "y": 12,
      "z": -7,
      "name": "Wood_Deadwood_Planks",
      "rotation": 2
    },
    {
      "x": -16,
      "y": 15,
      "z": -7,
      "name": "Wood_Deadwood_Planks_Half",
      "rotation": 8
    },
    {
      "x": -16,
      "y": 6,
      "z": -6,
      "name": "Rock_Ice_Icicles",
      "rotation": 8
    },
    {
      "x": -16,
      "y": 7,
      "z": -6,
      "name": "Wood_Fir_Trunk_Full_Locked",
      "support": 15,
      "rotation": 5
    },
    {
      "x": -16,
      "y": 8,
      "z": -6,
      "name": "Wood_Fir_Trunk_Full_Locked",
      "support": 15,
      "rotation": 5
    },
    {
      "x": -16,
      "y": 12,
      "z": -6,
      "name": "Wood_Fir_Trunk_Full_Locked",
      "support": 15,
      "rotation": 5
    },
    {
      "x": -16,
      "y": 15,
      "z": -6,
      "name": "Wood_Fir_Trunk_Full_Locked",
      "support": 15,
      "rotation": 5
    },
    {
      "x": -16,
      "y": 7,
      "z": -5,
      "name": "Wood_Blackwood_Planks",
      "rotation": 2
    },
    {
      "x": -16,
      "y": 8,
      "z": -5,
      "name": "Wood_Deadwood_Planks_Half",
      "rotation": 32
    },
    {
      "x": -16,
      "y": 12,
      "z": -5,
      "name": "Wood_Deadwood_Planks_Half",
      "rotation": 32
    },
    {
      "x": -16,
      "y": 15,
      "z": -5,
      "name": "Wood_Deadwood_Planks_Half",
      "rotation": 32
    },
    {
      "x": -16,
      "y": 6,
      "z": -4,
      "name": "Wood_Blackwood_Planks",
      "rotation": 2
    },
    {
      "x": -16,
      "y": 8,
      "z": -4,
      "name": "Wood_Deadwood_Planks_Half",
      "rotation": 32
    },
    {
      "x": -16,
      "y": 12,
      "z": -4,
      "name": "Wood_Deadwood_Planks_Half",
      "rotation": 32
    },
    {
      "x": -16,
      "y": 15,
      "z": -4,
      "name": "Wood_Deadwood_Planks_Half",
      "rotation": 32
    },
    {
      "x": -16,
      "y": 16,
      "z": -4,
      "name": "Vehicle_Wood_Boat",
      "filler": 991,
      "rotation": 2
    },
    {
      "x": -16,
      "y": 5,
      "z": -3,
      "name": "Wood_Fir_Trunk_Full_Locked",
      "support": 15,
      "rotation": 5
    },
    {
      "x": -16,
      "y": 6,
      "z": -3,
      "name": "Wood_Fir_Trunk_Full_Locked",
      "support": 15,
      "rotation": 5
    },
    {
      "x": -16,
      "y": 8,
      "z": -3,
      "name": "Wood_Fir_Trunk_Full_Locked",
      "support": 15,
      "rotation": 5
    },
    {
      "x": -16,
      "y": 9,
      "z": -3,
      "name": "Wood_Fir_Trunk_Full_Locked",
      "support": 15,
      "rotation": 5
    },
    {
      "x": -16,
      "y": 12,
      "z": -3,
      "name": "Wood_Fir_Trunk_Full_Locked",
      "support": 15,
      "rotation": 5
    },
    {
      "x": -16,
      "y": 13,
      "z": -3,
      "name": "Wood_Deadwood_Planks",
      "rotation": 2
    },
    {
      "x": -16,
      "y": 14,
      "z": -3,
      "name": "Wood_Deadwood_Planks",
      "rotation": 2
    },
    {
      "x": -16,
      "y": 15,
      "z": -3,
      "name": "Wood_Fir_Trunk_Full_Locked",
      "support": 15,
      "rotation": 5
    },
    {
      "x": -16,
      "y": 16,
      "z": -3,
      "name": "Vehicle_Wood_Boat",
      "filler": 1023,
      "rotation": 2
    },
    {
      "x": -16,
      "y": 5,
      "z": -2,
      "name": "Wood_Blackwood_Planks",
      "rotation": 2
    },
    {
      "x": -16,
      "y": 8,
      "z": -2,
      "name": "Wood_Deadwood_Planks",
      "rotation": 2
    },
    {
      "x": -16,
      "y": 9,
      "z": -2,
      "name": "Wood_Deadwood_Planks_Half",
      "rotation": 2
    },
    {
      "x": -16,
      "y": 15,
      "z": -2,
      "name": "Wood_Deadwood_Planks_Half",
      "rotation": 32
    },
    {
      "x": -16,
      "y": 16,
      "z": -2,
      "name": "Vehicle_Wood_Boat",
      "filler": 31,
      "rotation": 2
    },
    {
      "x": -16,
      "y": 4,
      "z": -1,
      "name": "Wood_Blackwood_Planks",
      "rotation": 2
    },
    {
      "x": -16,
      "y": 8,
      "z": -1,
      "name": "Wood_Deadwood_Planks",
      "rotation": 2
    },
    {
      "x": -16,
      "y": 9,
      "z": -1,
      "name": "Wood_Deadwood_Planks_Half",
      "rotation": 2
    },
    {
      "x": -16,
      "y": 15,
      "z": -1,
      "name": "Wood_Deadwood_Planks_Half",
      "rotation": 32
    },
    {
      "x": -16,
      "y": 16,
      "z": -1,
      "name": "Vehicle_Wood_Boat",
      "filler": 63,
      "rotation": 2
    },
    {
      "x": -16,
      "y": 3,
      "z": 0,
      "name": "Wood_Fir_Trunk_Full_Locked",
      "support": 15,
      "rotation": 5
    },
    {
      "x": -16,
      "y": 4,
      "z": 0,
      "name": "Wood_Fir_Trunk_Full_Locked",
      "support": 15,
      "rotation": 2
    },
    {
      "x": -16,
      "y": 8,
      "z": 0,
      "name": "Wood_Fir_Trunk_Full_Locked",
      "support": 15,
      "rotation": 5
    },
    {
      "x": -16,
      "y": 9,
      "z": 0,
      "name": "Wood_Deadwood_Planks_Half"
    },
    {
      "x": -16,
      "y": 15,
      "z": 0,
      "name": "Wood_Fir_Trunk_Full_Locked",
      "support": 15,
      "rotation": 5
    },
    {
      "x": -16,
      "y": 30,
      "z": 0,
      "name": "Deco_Rope_Diagonal",
      "rotation": 3
    },
    {
      "x": -16,
      "y": 4,
      "z": 1,
      "name": "Wood_Blackwood_Planks"
    },
    {
      "x": -16,
      "y": 8,
      "z": 1,
      "name": "Wood_Deadwood_Planks"
    },
    {
      "x": -16,
      "y": 9,
      "z": 1,
      "name": "Wood_Deadwood_Planks_Half"
    },
    {
      "x": -16,
      "y": 15,
      "z": 1,
      "name": "Wood_Deadwood_Planks_Half",
      "rotation": 8
    },
    {
      "x": -16,
      "y": 5,
      "z": 2,
      "name": "Wood_Blackwood_Planks"
    },
    {
      "x": -16,
      "y": 8,
      "z": 2,
      "name": "Wood_Deadwood_Planks"
    },
    {
      "x": -16,
      "y": 9,
      "z": 2,
      "name": "Wood_Deadwood_Planks_Half"
    },
    {
      "x": -16,
      "y": 15,
      "z": 2,
      "name": "Wood_Deadwood_Planks_Half",
      "rotation": 8
    },
    {
      "x": -16,
      "y": 16,
      "z": 2,
      "name": "Vehicle_Wood_Boat",
      "filler": 1023
    },
    {
      "x": -16,
      "y": 5,
      "z": 3,
      "name": "Wood_Fir_Trunk_Full_Locked",
      "support": 15,
      "rotation": 5
    },
    {
      "x": -16,
      "y": 6,
      "z": 3,
      "name": "Wood_Fir_Trunk_Full_Locked",
      "support": 15,
      "rotation": 5
    },
    {
      "x": -16,
      "y": 8,
      "z": 3,
      "name": "Wood_Fir_Trunk_Full_Locked",
      "support": 15,
      "rotation": 5
    },
    {
      "x": -16,
      "y": 9,
      "z": 3,
      "name": "Wood_Fir_Trunk_Full_Locked",
      "support": 15,
      "rotation": 5
    },
    {
      "x": -16,
      "y": 12,
      "z": 3,
      "name": "Wood_Fir_Trunk_Full_Locked",
      "support": 15,
      "rotation": 5
    },
    {
      "x": -16,
      "y": 13,
      "z": 3,
      "name": "Wood_Deadwood_Planks"
    },
    {
      "x": -16,
      "y": 14,
      "z": 3,
      "name": "Wood_Deadwood_Planks"
    },
    {
      "x": -16,
      "y": 15,
      "z": 3,
      "name": "Wood_Fir_Trunk_Full_Locked",
      "support": 15,
      "rotation": 5
    },
    {
      "x": -16,
      "y": 16,
      "z": 3,
      "name": "Vehicle_Wood_Boat",
      "filler": 31
    },
    {
      "x": -16,
      "y": 6,
      "z": 4,
      "name": "Wood_Blackwood_Planks"
    },
    {
      "x": -16,
      "y": 8,
      "z": 4,
      "name": "Wood_Deadwood_Planks_Half",
      "rotation": 8
    },
    {
      "x": -16,
      "y": 12,
      "z": 4,
      "name": "Wood_Deadwood_Planks_Half",
      "rotation": 8
    },
    {
      "x": -16,
      "y": 15,
      "z": 4,
      "name": "Wood_Deadwood_Planks_Half",
      "rotation": 8
    },
    {
      "x": -16,
      "y": 16,
      "z": 4,
      "name": "Vehicle_Wood_Boat",
      "filler": 63
    },
    {
      "x": -16,
      "y": 7,
      "z": 5,
      "name": "Wood_Blackwood_Planks"
    },
    {
      "x": -16,
      "y": 8,
      "z": 5,
      "name": "Wood_Deadwood_Planks_Half",
      "rotation": 8
    },
    {
      "x": -16,
      "y": 12,
      "z": 5,
      "name": "Wood_Deadwood_Planks_Half",
      "rotation": 8
    },
    {
      "x": -16,
      "y": 15,
      "z": 5,
      "name": "Wood_Deadwood_Planks_Half",
      "rotation": 8
    },
    {
      "x": -16,
      "y": 16,
      "z": 5,
      "name": "Vehicle_Wood_Boat",
      "filler": 95
    },
    {
      "x": -16,
      "y": 7,
      "z": 6,
      "name": "Wood_Fir_Trunk_Full_Locked",
      "support": 15,
      "rotation": 5
    },
    {
      "x": -16,
      "y": 8,
      "z": 6,
      "name": "Wood_Fir_Trunk_Full_Locked",
      "support": 15,
      "rotation": 5
    },
    {
      "x": -16,
      "y": 12,
      "z": 6,
      "name": "Wood_Fir_Trunk_Full_Locked",
      "support": 15,
      "rotation": 5
    },
    {
      "x": -16,
      "y": 15,
      "z": 6,
      "name": "Wood_Fir_Trunk_Full_Locked",
      "support": 15,
      "rotation": 5
    },
    {
      "x": -16,
      "y": 8,
      "z": 7,
      "name": "Wood_Blackwood_Planks"
    },
    {
      "x": -16,
      "y": 9,
      "z": 7,
      "name": "Wood_Blackwood_Planks"
    },
    {
      "x": -16,
      "y": 12,
      "z": 7,
      "name": "Wood_Deadwood_Planks"
    },
    {
      "x": -16,
      "y": 15,
      "z": 7,
      "name": "Wood_Deadwood_Planks_Half",
      "rotation": 8
    },
    {
      "x": -16,
      "y": 9,
      "z": 8,
      "name": "Wood_Fir_Trunk_Full_Locked",
      "support": 15,
      "rotation": 5
    },
    {
      "x": -16,
      "y": 10,
      "z": 8,
      "name": "Wood_Blackwood_Planks"
    },
    {
      "x": -16,
      "y": 11,
      "z": 8,
      "name": "Wood_Blackwood_Planks"
    },
    {
      "x": -16,
      "y": 12,
      "z": 8,
      "name": "Wood_Fir_Trunk_Full_Locked",
      "rotation": 5
    },
    {
      "x": -16,
      "y": 13,
      "z": 8,
      "name": "Wood_Blackwood_Planks"
    },
    {
      "x": -16,
      "y": 14,
      "z": 8,
      "name": "Wood_Blackwood_Planks"
    },
    {
      "x": -16,
      "y": 15,
      "z": 8,
      "name": "Wood_Fir_Trunk_Full_Locked",
      "support": 15,
      "rotation": 5
    },
    {
      "x": -16,
      "y": 16,
      "z": 8,
      "name": "Wood_Blackwood_Fence"
    },
    {
      "x": -15,
      "y": 9,
      "z": -8,
      "name": "Wood_Fir_Trunk_Full_Locked",
      "support": 15,
      "rotation": 5
    },
    {
      "x": -15,
      "y": 10,
      "z": -8,
      "name": "Furniture_Temple_Dark_Window",
      "rotation": 2
    },
    {
      "x": -15,
      "y": 11,
      "z": -8,
      "name": "Wood_Blackwood_Planks",
      "rotation": 2
    },
    {
      "x": -15,
      "y": 12,
      "z": -8,
      "name": "Wood_Fir_Trunk_Full_Locked",
      "rotation": 5
    },
    {
      "x": -15,
      "y": 13,
      "z": -8,
      "name": "Wood_Blackwood_Planks",
      "rotation": 2
    },
    {
      "x": -15,
      "y": 14,
      "z": -8,
      "name": "Wood_Blackwood_Planks",
      "rotation": 2
    },
    {
      "x": -15,
      "y": 15,
      "z": -8,
      "name": "Wood_Fir_Trunk_Full_Locked",
      "support": 15,
      "rotation": 5
    },
    {
      "x": -15,
      "y": 16,
      "z": -8,
      "name": "Wood_Blackwood_Fence",
      "rotation": 2
    },
    {
      "x": -15,
      "y": 8,
      "z": -7,
      "name": "Wood_Blackwood_Planks",
      "rotation": 2
    },
    {
      "x": -15,
      "y": 12,
      "z": -7,
      "name": "Wood_Deadwood_Planks",
      "rotation": 2
    },
    {
      "x": -15,
      "y": 15,
      "z": -7,
      "name": "Wood_Deadwood_Planks_Half",
      "rotation": 8
    },
    {
      "x": -15,
      "y": 7,
      "z": -6,
      "name": "Wood_Fir_Trunk_Full_Locked",
      "support": 15,
      "rotation": 5
    },
    {
      "x": -15,
      "y": 8,
      "z": -6,
      "name": "Wood_Fir_Trunk_Full_Locked",
      "support": 15,
      "rotation": 5
    },
    {
      "x": -15,
      "y": 12,
      "z": -6,
      "name": "Wood_Fir_Trunk_Full_Locked",
      "support": 15,
      "rotation": 5
    },
    {
      "x": -15,
      "y": 15,
      "z": -6,
      "name": "Wood_Fir_Trunk_Full_Locked",
      "support": 15,
      "rotation": 5
    },
    {
      "x": -15,
      "y": 6,
      "z": -5,
      "name": "Wood_Blackwood_Planks",
      "rotation": 2
    },
    {
      "x": -15,
      "y": 8,
      "z": -5,
      "name": "Wood_Deadwood_Planks_Half",
      "rotation": 32
    },
    {
      "x": -15,
      "y": 12,
      "z": -5,
      "name": "Wood_Deadwood_Planks_Half",
      "rotation": 32
    },
    {
      "x": -15,
      "y": 15,
      "z": -5,
      "name": "Wood_Deadwood_Planks_Half",
      "rotation": 32
    },
    {
      "x": -15,
      "y": 6,
      "z": -4,
      "name": "Wood_Blackwood_Planks",
      "rotation": 2
    },
    {
      "x": -15,
      "y": 8,
      "z": -4,
      "name": "Wood_Deadwood_Planks_Half",
      "rotation": 32
    },
    {
      "x": -15,
      "y": 12,
      "z": -4,
      "name": "Wood_Deadwood_Planks_Half",
      "rotation": 32
    },
    {
      "x": -15,
      "y": 15,
      "z": -4,
      "name": "Wood_Deadwood_Planks_Half",
      "rotation": 32
    },
    {
      "x": -15,
      "y": 16,
      "z": -4,
      "name": "Vehicle_Wood_Boat",
      "filler": 960,
      "rotation": 2
    },
    {
      "x": -15,
      "y": 5,
      "z": -3,
      "name": "Wood_Fir_Trunk_Full_Locked",
      "support": 15,
      "rotation": 5
    },
    {
      "x": -15,
      "y": 8,
      "z": -3,
      "name": "Wood_Fir_Trunk_Full_Locked",
      "support": 15,
      "rotation": 5
    },
    {
      "x": -15,
      "y": 9,
      "z": -3,
      "name": "Wood_Fir_Trunk_Full_Locked",
      "support": 15,
      "rotation": 5
    },
    {
      "x": -15,
      "y": 10,
      "z": -3,
      "name": "Wood_Fir_Trunk_Half",
      "rotation": 2
    },
    {
      "x": -15,
      "y": 12,
      "z": -3,
      "name": "Wood_Fir_Trunk_Full_Locked",
      "support": 15,
      "rotation": 5
    },
    {
      "x": -15,
      "y": 13,
      "z": -3,
      "name": "Wood_Deadwood_Planks",
      "rotation": 2
    },
    {
      "x": -15,
      "y": 14,
      "z": -3,
      "name": "Wood_Deadwood_Planks",
      "rotation": 2
    },
    {
      "x": -15,
      "y": 15,
      "z": -3,
      "name": "Wood_Fir_Trunk_Full_Locked",
      "support": 15,
      "rotation": 5
    },
    {
      "x": -15,
      "y": 16,
      "z": -3,
      "name": "Vehicle_Wood_Boat",
      "filler": 992,
      "rotation": 2
    },
    {
      "x": -15,
      "y": 4,
      "z": -2,
      "name": "Wood_Blackwood_Planks",
      "rotation": 2
    },
    {
      "x": -15,
      "y": 9,
      "z": -2,
      "name": "Wood_Deadwood_Planks",
      "rotation": 2
    },
    {
      "x": -15,
      "y": 15,
      "z": -2,
      "name": "Wood_Deadwood_Planks_Half",
      "rotation": 32
    },
    {
      "x": -15,
      "y": 16,
      "z": -2,
      "name": "Vehicle_Wood_Boat",
      "rotation": 2
    },
    {
      "x": -15,
      "y": 4,
      "z": -1,
      "name": "Wood_Blackwood_Planks",
      "rotation": 2
    },
    {
      "x": -15,
      "y": 9,
      "z": -1,
      "name": "Wood_Deadwood_Planks",
      "rotation": 2
    },
    {
      "x": -15,
      "y": 15,
      "z": -1,
      "name": "Wood_Deadwood_Planks_Half",
      "rotation": 32
    },
    {
      "x": -15,
      "y": 16,
      "z": -1,
      "name": "Vehicle_Wood_Boat",
      "filler": 32,
      "rotation": 2
    },
    {
      "x": -15,
      "y": 3,
      "z": 0,
      "name": "Wood_Fir_Trunk_Full_Locked",
      "support": 15,
      "rotation": 5
    },
    {
      "x": -15,
      "y": 4,
      "z": 0,
      "name": "Wood_Blackwood_Planks"
    },
    {
      "x": -15,
      "y": 8,
      "z": 0,
      "name": "Wood_Fir_Trunk_Full_Locked",
      "support": 15,
      "rotation": 5
    },
    {
      "x": -15,
      "y": 9,
      "z": 0,
      "name": "Wood_Deadwood_Planks"
    },
    {
      "x": -15,
      "y": 15,
      "z": 0,
      "name": "Wood_Fir_Trunk_Full_Locked",
      "support": 15,
      "rotation": 5
    },
    {
      "x": -15,
      "y": 31,
      "z": 0,
      "name": "Deco_Rope_Diagonal",
      "rotation": 3
    },
    {
      "x": -15,
      "y": 4,
      "z": 1,
      "name": "Wood_Blackwood_Planks"
    },
    {
      "x": -15,
      "y": 9,
      "z": 1,
      "name": "Wood_Deadwood_Planks"
    },
    {
      "x": -15,
      "y": 15,
      "z": 1,
      "name": "Wood_Deadwood_Planks_Half",
      "rotation": 8
    },
    {
      "x": -15,
      "y": 4,
      "z": 2,
      "name": "Wood_Blackwood_Planks"
    },
    {
      "x": -15,
      "y": 9,
      "z": 2,
      "name": "Wood_Deadwood_Planks"
    },
    {
      "x": -15,
      "y": 15,
      "z": 2,
      "name": "Wood_Deadwood_Planks_Half",
      "rotation": 8
    },
    {
      "x": -15,
      "y": 16,
      "z": 2,
      "name": "Vehicle_Wood_Boat",
      "filler": 992
    },
    {
      "x": -15,
      "y": 5,
      "z": 3,
      "name": "Wood_Fir_Trunk_Full_Locked",
      "support": 15,
      "rotation": 5
    },
    {
      "x": -15,
      "y": 8,
      "z": 3,
      "name": "Wood_Fir_Trunk_Full_Locked",
      "support": 15,
      "rotation": 5
    },
    {
      "x": -15,
      "y": 9,
      "z": 3,
      "name": "Wood_Fir_Trunk_Full_Locked",
      "support": 15,
      "rotation": 5
    },
    {
      "x": -15,
      "y": 10,
      "z": 3,
      "name": "Wood_Fir_Trunk_Half"
    },
    {
      "x": -15,
      "y": 12,
      "z": 3,
      "name": "Wood_Fir_Trunk_Full_Locked",
      "support": 15,
      "rotation": 5
    },
    {
      "x": -15,
      "y": 13,
      "z": 3,
      "name": "Wood_Deadwood_Planks"
    },
    {
      "x": -15,
      "y": 14,
      "z": 3,
      "name": "Wood_Deadwood_Planks"
    },
    {
      "x": -15,
      "y": 15,
      "z": 3,
      "name": "Wood_Fir_Trunk_Full_Locked",
      "support": 15,
      "rotation": 5
    },
    {
      "x": -15,
      "y": 16,
      "z": 3,
      "name": "Vehicle_Wood_Boat"
    },
    {
      "x": -15,
      "y": 6,
      "z": 4,
      "name": "Wood_Blackwood_Planks"
    },
    {
      "x": -15,
      "y": 8,
      "z": 4,
      "name": "Wood_Deadwood_Planks_Half",
      "rotation": 8
    },
    {
      "x": -15,
      "y": 12,
      "z": 4,
      "name": "Wood_Deadwood_Planks_Half",
      "rotation": 8
    },
    {
      "x": -15,
      "y": 15,
      "z": 4,
      "name": "Wood_Deadwood_Planks_Half",
      "rotation": 8
    },
    {
      "x": -15,
      "y": 16,
      "z": 4,
      "name": "Vehicle_Wood_Boat",
      "filler": 32
    },
    {
      "x": -15,
      "y": 6,
      "z": 5,
      "name": "Wood_Blackwood_Planks"
    },
    {
      "x": -15,
      "y": 8,
      "z": 5,
      "name": "Wood_Deadwood_Planks_Half",
      "rotation": 8
    },
    {
      "x": -15,
      "y": 12,
      "z": 5,
      "name": "Wood_Deadwood_Planks_Half",
      "rotation": 8
    },
    {
      "x": -15,
      "y": 15,
      "z": 5,
      "name": "Wood_Deadwood_Planks_Half",
      "rotation": 8
    },
    {
      "x": -15,
      "y": 16,
      "z": 5,
      "name": "Vehicle_Wood_Boat",
      "filler": 64
    },
    {
      "x": -15,
      "y": 7,
      "z": 6,
      "name": "Wood_Fir_Trunk_Full_Locked",
      "support": 15,
      "rotation": 5
    },
    {
      "x": -15,
      "y": 8,
      "z": 6,
      "name": "Wood_Fir_Trunk_Full_Locked",
      "support": 15,
      "rotation": 5
    },
    {
      "x": -15,
      "y": 12,
      "z": 6,
      "name": "Wood_Fir_Trunk_Full_Locked",
      "support": 15,
      "rotation": 5
    },
    {
      "x": -15,
      "y": 15,
      "z": 6,
      "name": "Wood_Fir_Trunk_Full_Locked",
      "support": 15,
      "rotation": 5
    },
    {
      "x": -15,
      "y": 8,
      "z": 7,
      "name": "Wood_Blackwood_Planks"
    },
    {
      "x": -15,
      "y": 12,
      "z": 7,
      "name": "Wood_Deadwood_Planks"
    },
    {
      "x": -15,
      "y": 15,
      "z": 7,
      "name": "Wood_Deadwood_Planks_Half",
      "rotation": 8
    },
    {
      "x": -15,
      "y": 9,
      "z": 8,
      "name": "Wood_Fir_Trunk_Full_Locked",
      "support": 15,
      "rotation": 5
    },
    {
      "x": -15,
      "y": 10,
      "z": 8,
      "name": "Furniture_Temple_Dark_Window"
    },
    {
      "x": -15,
      "y": 11,
      "z": 8,
      "name": "Wood_Blackwood_Planks"
    },
    {
      "x": -15,
      "y": 12,
      "z": 8,
      "name": "Wood_Fir_Trunk_Full_Locked",
      "rotation": 5
    },
    {
      "x": -15,
      "y": 13,
      "z": 8,
      "name": "Wood_Blackwood_Planks"
    },
    {
      "x": -15,
      "y": 14,
      "z": 8,
      "name": "Wood_Blackwood_Planks"
    },
    {
      "x": -15,
      "y": 15,
      "z": 8,
      "name": "Wood_Fir_Trunk_Full_Locked",
      "support": 15,
      "rotation": 5
    },
    {
      "x": -15,
      "y": 16,
      "z": 8,
      "name": "Wood_Blackwood_Fence"
    },
    {
      "x": -14,
      "y": 8,
      "z": -8,
      "name": "Wood_Fir_Trunk_Full_Locked",
      "support": 15,
      "rotation": 5
    },
    {
      "x": -14,
      "y": 9,
      "z": -8,
      "name": "Wood_Fir_Trunk_Full_Locked",
      "support": 15,
      "rotation": 5
    },
    {
      "x": -14,
      "y": 10,
      "z": -8,
      "name": "Wood_Blackwood_Planks",
      "rotation": 2
    },
    {
      "x": -14,
      "y": 11,
      "z": -8,
      "name": "Wood_Blackwood_Planks",
      "rotation": 2
    },
    {
      "x": -14,
      "y": 12,
      "z": -8,
      "name": "Wood_Fir_Trunk_Full_Locked",
      "rotation": 5
    },
    {
      "x": -14,
      "y": 13,
      "z": -8,
      "name": "Wood_Blackwood_Planks",
      "rotation": 2
    },
    {
      "x": -14,
      "y": 14,
      "z": -8,
      "name": "Wood_Blackwood_Planks",
      "rotation": 2
    },
    {
      "x": -14,
      "y": 15,
      "z": -8,
      "name": "Wood_Fir_Trunk_Full_Locked",
      "support": 15,
      "rotation": 5
    },
    {
      "x": -14,
      "y": 16,
      "z": -8,
      "name": "Wood_Blackwood_Fence",
      "rotation": 2
    },
    {
      "x": -14,
      "y": 7,
      "z": -7,
      "name": "Wood_Blackwood_Planks",
      "rotation": 2
    },
    {
      "x": -14,
      "y": 8,
      "z": -7,
      "name": "Wood_Blackwood_Planks",
      "rotation": 2
    },
    {
      "x": -14,
      "y": 12,
      "z": -7,
      "name": "Wood_Deadwood_Planks",
