{
  "version": 8,
  "blockIdVersion": 11,
  "anchorX": 0,
  "anchorY": 0,
  "anchorZ": 0,
  "blocks": [
    {
      "x": -36,
      "y": 13,
      "z": -1,
      "name": "Wood_Fir_Trunk_Full",
      "support": 15,
      "rotation": 5
    },
    {
      "x": -35,
      "y": 12,
      "z": -1,
      "name": "Wood_Fir_Trunk_Full",
      "support": 15,
      "rotation": 5
    },
    {
      "x": -35,
      "y": 13,
      "z": -1,
      "name": "Wood_Fir_Trunk_Full",
      "support": 15
    },
    {
      "x": -34,
      "y": 11,
      "z": -1,
      "name": "Wood_Fir_Trunk_Full",
      "support": 15,
      "rotation": 5
    },
    {
      "x": -34,
      "y": 12,
      "z": -1,
      "name": "Wood_Fir_Trunk_Full",
      "support": 15
    },
    {
      "x": -33,
      "y": 10,
      "z": -1,
      "name": "Wood_Fir_Trunk_Full",
      "support": 15,
      "rotation": 5
    },
    {
      "x": -33,
      "y": 11,
      "z": -1,
      "name": "Wood_Fir_Trunk_Full",
      "support": 15
    },
    {
      "x": -32,
      "y": 9,
      "z": -1,
      "name": "Wood_Fir_Trunk_Full",
      "support": 15,
      "rotation": 5
    },
    {
      "x": -32,
      "y": 10,
      "z": -1,
      "name": "Wood_Fir_Trunk_Full",
      "support": 15
    },
    {
      "x": -31,
      "y": 8,
      "z": -1,
      "name": "Wood_Fir_Trunk_Full",
      "support": 15,
      "rotation": 5
    },
    {
      "x": -31,
      "y": 9,
      "z": -1,
      "name": "Wood_Fir_Trunk_Full",
      "support": 15
    },
    {
      "x": -31,
      "y": 11,
      "z": -1,
      "name": "Wood_Fir_Trunk_Full",
      "support": 15,
      "rotation": 4
    },
    {
      "x": -31,
      "y": 11,
      "z": 0,
      "name": "Wood_Fir_Trunk_Full",
      "support": 15,
      "rotation": 4
    },
    {
      "x": -30,
      "y": 7,
      "z": -1,
      "name": "Wood_Fir_Trunk_Full",
      "support": 15,
      "rotation": 5
    },
    {
      "x": -30,
      "y": 8,
      "z": -1,
      "name": "Wood_Fir_Trunk_Full",
      "support": 15
    },
    {
      "x": -30,
      "y": 11,
      "z": 0,
      "name": "Wood_Fir_Trunk_Full",
      "support": 15,
      "rotation": 4
    },
    {
      "x": -30,
      "y": 11,
      "z": 1,
      "name": "Wood_Fir_Trunk_Full",
      "support": 15,
      "rotation": 4
    },
    {
      "x": -30,
      "y": 10,
      "z": 2,
      "name": "Wood_Fir_Trunk_Full",
      "support": 15,
      "rotation": 5
    },
    {
      "x": -30,
      "y": 11,
      "z": 2,
      "name": "Wood_Fir_Trunk_Full",
      "support": 15,
      "rotation": 4
    },
    {
      "x": -29,
      "y": 6,
      "z": -1,
      "name": "Wood_Fir_Trunk_Full",
      "support": 15,
      "rotation": 5
    },
    {
      "x": -29,
      "y": 7,
      "z": -1,
      "name": "Wood_Fir_Trunk_Full",
      "support": 15
    },
    {
      "x": -29,
      "y": 9,
      "z": 2,
      "name": "Wood_Fir_Trunk_Full",
      "support": 15,
      "rotation": 5
    },
    {
      "x": -29,
      "y": 10,
      "z": 2,
      "name": "Wood_Fir_Trunk_Full",
      "support": 15,
      "rotation": 5
    },
    {
      "x": -29,
      "y": 11,
      "z": 3,
      "name": "Wood_Fir_Trunk_Full",
      "support": 15,
      "rotation": 4
    },
    {
      "x": -29,
      "y": 11,
      "z": 4,
      "name": "Wood_Fir_Trunk_Full",
      "support": 15,
      "rotation": 5
    },
    {
      "x": -28,
      "y": 5,
      "z": -1,
      "name": "Wood_Fir_Trunk_Full",
      "support": 15,
      "rotation": 5
    },
    {
      "x": -28,
      "y": 6,
      "z": -1,
      "name": "Wood_Fir_Trunk_Full",
      "support": 15
    },
    {
      "x": -28,
      "y": 8,
      "z": 2,
      "name": "Wood_Fir_Trunk_Full",
      "support": 15,
      "rotation": 5
    },
    {
      "x": -28,
      "y": 9,
      "z": 2,
      "name": "Wood_Fir_Trunk_Full",
      "support": 15,
      "rotation": 5
    },
    {
      "x": -28,
      "y": 11,
      "z": 4,
      "name": "Wood_Fir_Trunk_Full",
      "support": 15,
      "rotation": 5
    },
    {
      "x": -28,
      "y": 11,
      "z": 5,
      "name": "Wood_Fir_Trunk_Full",
      "support": 15,
      "rotation": 5
    },
    {
      "x": -27,
      "y": 5,
      "z": -1,
      "name": "Wood_Fir_Trunk_Full",
      "support": 15
    },
    {
      "x": -27,
      "y": 7,
      "z": 2,
      "name": "Wood_Fir_Trunk_Full",
      "support": 15,
      "rotation": 5
    },
    {
      "x": -27,
      "y": 8,
      "z": 2,
      "name": "Wood_Fir_Trunk_Full",
      "support": 15,
      "rotation": 5
    },
    {
      "x": -27,
      "y": 10,
      "z": 5,
      "name": "Wood_Fir_Trunk_Full",
      "support": 15,
      "rotation": 5
    },
    {
      "x": -27,
      "y": 11,
      "z": 5,
      "name": "Wood_Fir_Trunk_Full",
      "support": 15,
      "rotation": 5
    },
    {
      "x": -26,
      "y": 4,
      "z": -1,
      "name": "Wood_Fir_Trunk_Full",
      "support": 15,
      "rotation": 5
    },
    {
      "x": -26,
      "y": 5,
      "z": -1,
      "name": "Wood_Fir_Trunk_Full",
      "support": 15,
      "rotation": 5
    },
    {
      "x": -26,
      "y": 6,
      "z": 2,
      "name": "Wood_Fir_Trunk_Full",
      "support": 15,
      "rotation": 5
    },
    {
      "x": -26,
      "y": 7,
      "z": 2,
      "name": "Wood_Fir_Trunk_Full",
      "support": 15,
      "rotation": 5
    },
    {
      "x": -26,
      "y": 9,
      "z": 5,
      "name": "Wood_Fir_Trunk_Full",
      "support": 15,
      "rotation": 5
    },
    {
      "x": -26,
      "y": 10,
      "z": 5,
      "name": "Wood_Fir_Trunk_Full",
      "support": 15,
      "rotation": 5
    },
    {
      "x": -26,
      "y": 11,
      "z": 5,
      "name": "Wood_Fir_Trunk_Full",
      "support": 15,
      "rotation": 5
    },
    {
      "x": -26,
      "y": 11,
      "z": 6,
      "name": "Wood_Fir_Trunk_Full",
      "support": 15,
      "rotation": 5
    },
    {
      "x": -25,
      "y": 4,
      "z": -1,
      "name": "Wood_Fir_Trunk_Full",
      "support": 15
    },
    {
      "x": -25,
      "y": 6,
      "z": 2,
      "name": "Wood_Fir_Trunk_Full",
      "support": 15,
      "rotation": 5
    },
    {
      "x": -25,
      "y": 8,
      "z": 5,
      "name": "Wood_Fir_Trunk_Full",
      "support": 15,
      "rotation": 5
    },
    {
      "x": -25,
      "y": 9,
      "z": 5,
      "name": "Wood_Fir_Trunk_Full",
      "support": 15,
      "rotation": 5
    },
    {
      "x": -25,
      "y": 11,
      "z": 6,
      "name": "Wood_Fir_Trunk_Full",
      "support": 15,
      "rotation": 4
    },
    {
      "x": -24,
      "y": 3,
      "z": -1,
      "name": "Wood_Fir_Trunk_Full",
      "support": 15,
      "rotation": 5
    },
    {
      "x": -24,
      "y": 4,
      "z": -1,
      "name": "Wood_Fir_Trunk_Full",
      "support": 15,
      "rotation": 5
    },
    {
      "x": -24,
      "y": 5,
      "z": 2,
      "name": "Wood_Fir_Trunk_Full",
      "support": 15,
      "rotation": 5
    },
    {
      "x": -24,
      "y": 6,
      "z": 2,
      "name": "Wood_Fir_Trunk_Full",
      "support": 15,
      "rotation": 5
    },
    {
      "x": -24,
      "y": 7,
      "z": 5,
      "name": "Wood_Fir_Trunk_Full",
      "support": 15,
      "rotation": 5
    },
    {
      "x": -24,
      "y": 8,
      "z": 5,
      "name": "Wood_Fir_Trunk_Full",
      "support": 15,
      "rotation": 5
    },
    {
      "x": -24,
      "y": 11,
      "z": 6,
      "name": "Wood_Fir_Trunk_Full",
      "support": 15,
      "rotation": 5
    },
    {
      "x": -24,
      "y": 10,
      "z": 7,
      "name": "Wood_Fir_Trunk_Full",
      "support": 15,
      "rotation": 5
    },
    {
      "x": -24,
      "y": 11,
      "z": 7,
      "name": "Wood_Fir_Trunk_Full",
      "support": 15,
      "rotation": 5
    },
    {
      "x": -23,
      "y": 3,
      "z": -1,
      "name": "Wood_Fir_Trunk_Full",
      "support": 15,
      "rotation": 5
    },
    {
      "x": -23,
      "y": 5,
      "z": 2,
      "name": "Wood_Fir_Trunk_Full",
      "support": 15,
      "rotation": 5
    },
    {
      "x": -23,
      "y": 7,
      "z": 5,
      "name": "Wood_Fir_Trunk_Full",
      "support": 15,
      "rotation": 5
    },
    {
      "x": -23,
      "y": 9,
      "z": 7,
      "name": "Wood_Fir_Trunk_Full",
      "support": 15,
      "rotation": 5
    },
    {
      "x": -23,
      "y": 10,
      "z": 7,
      "name": "Wood_Fir_Trunk_Full",
      "support": 15,
      "rotation": 5
    },
    {
      "x": -22,
      "y": 2,
      "z": -1,
      "name": "Wood_Fir_Trunk_Full",
      "support": 15,
      "rotation": 5
    },
    {
      "x": -22,
      "y": 3,
      "z": -1,
      "name": "Wood_Fir_Trunk_Full",
      "support": 15
    },
    {
      "x": -22,
      "y": 4,
      "z": 2,
      "name": "Wood_Fir_Trunk_Full",
      "support": 15,
      "rotation": 5
    },
    {
      "x": -22,
      "y": 5,
      "z": 2,
      "name": "Wood_Fir_Trunk_Full",
      "support": 15,
      "rotation": 5
    },
    {
      "x": -22,
      "y": 6,
      "z": 5,
      "name": "Wood_Fir_Trunk_Full",
      "support": 15,
      "rotation": 5
    },
    {
      "x": -22,
      "y": 7,
      "z": 5,
      "name": "Wood_Fir_Trunk_Full",
      "support": 15,
      "rotation": 5
    },
    {
      "x": -22,
      "y": 8,
      "z": 7,
      "name": "Wood_Fir_Trunk_Full",
      "support": 15,
      "rotation": 5
    },
    {
      "x": -22,
      "y": 9,
      "z": 7,
      "name": "Wood_Fir_Trunk_Full",
      "support": 15,
      "rotation": 5
    },
    {
      "x": -21,
      "y": 2,
      "z": -1,
      "name": "Wood_Fir_Trunk_Full",
      "support": 15,
      "rotation": 5
    },
    {
      "x": -21,
      "y": 4,
      "z": 2,
      "name": "Wood_Fir_Trunk_Full",
      "support": 15,
      "rotation": 5
    },
    {
      "x": -21,
      "y": 6,
      "z": 5,
      "name": "Wood_Fir_Trunk_Full",
      "support": 15,
      "rotation": 5
    },
    {
      "x": -21,
      "y": 8,
      "z": 7,
      "name": "Wood_Fir_Trunk_Full",
      "support": 15,
      "rotation": 5
    },
    {
      "x": -21,
      "y": 9,
      "z": 7,
      "name": "Wood_Fir_Trunk_Full",
      "support": 15,
      "rotation": 5
    },
    {
      "x": -20,
      "y": 2,
      "z": -1,
      "name": "Wood_Fir_Trunk_Full",
      "support": 15,
      "rotation": 5
    },
    {
      "x": -20,
      "y": 3,
      "z": 2,
      "name": "Wood_Fir_Trunk_Full",
      "support": 15,
      "rotation": 5
    },
    {
      "x": -20,
      "y": 4,
      "z": 2,
      "name": "Wood_Fir_Trunk_Full",
      "support": 15,
      "rotation": 5
    },
    {
      "x": -20,
      "y": 5,
      "z": 5,
      "name": "Wood_Fir_Trunk_Full",
      "support": 15,
      "rotation": 5
    },
    {
      "x": -20,
      "y": 6,
      "z": 5,
      "name": "Wood_Fir_Trunk_Full",
      "support": 15,
      "rotation": 5
    },
    {
      "x": -20,
      "y": 7,
      "z": 7,
      "name": "Wood_Fir_Trunk_Full",
      "support": 15,
      "rotation": 5
    },
    {
      "x": -20,
      "y": 8,
      "z": 7,
      "name": "Wood_Fir_Trunk_Full",
      "support": 15,
      "rotation": 5
    },
    {
      "x": -20,
      "y": 9,
      "z": 7,
      "name": "Wood_Fir_Trunk_Full",
      "support": 15,
      "rotation": 5
    },
    {
      "x": -19,
      "y": 2,
      "z": -1,
      "name": "Wood_Fir_Trunk_Full",
      "support": 15,
      "rotation": 5
    },
    {
      "x": -19,
      "y": 3,
      "z": 2,
      "name": "Wood_Fir_Trunk_Full",
      "support": 15,
      "rotation": 5
    },
    {
      "x": -19,
      "y": 5,
      "z": 5,
      "name": "Wood_Fir_Trunk_Full",
      "support": 15,
      "rotation": 5
    },
    {
      "x": -19,
      "y": 7,
      "z": 7,
      "name": "Wood_Fir_Trunk_Full",
      "support": 15,
      "rotation": 5
    },
    {
      "x": -19,
      "y": 9,
      "z": 7,
      "name": "Wood_Fir_Trunk_Full",
      "support": 15,
      "rotation": 5
    },
    {
      "x": -18,
      "y": 1,
      "z": -1,
      "name": "Wood_Fir_Trunk_Full",
      "support": 15,
      "rotation": 5
    },
    {
      "x": -18,
      "y": 2,
      "z": -1,
      "name": "Wood_Fir_Trunk_Full",
      "support": 15
    },
    {
      "x": -18,
      "y": 2,
      "z": 2,
      "name": "Wood_Fir_Trunk_Full",
      "support": 15,
      "rotation": 5
    },
    {
      "x": -18,
      "y": 3,
      "z": 2,
      "name": "Wood_Fir_Trunk_Full",
      "support": 15,
      "rotation": 5
    },
    {
      "x": -18,
      "y": 4,
      "z": 5,
      "name": "Wood_Fir_Trunk_Full",
      "support": 15,
      "rotation": 5
    },
    {
      "x": -18,
      "y": 5,
      "z": 5,
      "name": "Wood_Fir_Trunk_Full",
      "support": 15,
      "rotation": 5
    },
    {
      "x": -18,
      "y": 6,
      "z": 7,
      "name": "Wood_Fir_Trunk_Full",
      "support": 15,
      "rotation": 5
    },
    {
      "x": -18,
      "y": 7,
      "z": 7,
      "name": "Wood_Fir_Trunk_Full",
      "support": 15,
      "rotation": 5
    },
    {
      "x": -18,
      "y": 9,
      "z": 8,
      "name": "Wood_Fir_Trunk_Full",
      "support": 15,
      "rotation": 5
    },
    {
      "x": -17,
      "y": 1,
      "z": -1,
      "name": "Wood_Fir_Trunk_Full",
      "support": 15,
      "rotation": 5
    },
    {
      "x": -17,
      "y": 2,
      "z": 2,
      "name": "Wood_Fir_Trunk_Full",
      "support": 15,
      "rotation": 5
    },
    {
      "x": -17,
      "y": 4,
      "z": 5,
      "name": "Wood_Fir_Trunk_Full",
      "support": 15,
      "rotation": 5
    },
    {
      "x": -17,
      "y": 6,
      "z": 7,
      "name": "Wood_Fir_Trunk_Full",
      "support": 15,
      "rotation": 5
    },
    {
      "x": -17,
      "y": 7,
      "z": 7,
      "name": "Wood_Fir_Trunk_Full",
      "support": 15,
      "rotation": 5
    },
    {
      "x": -17,
      "y": 9,
      "z": 8,
      "name": "Wood_Fir_Trunk_Full",
      "support": 15,
      "rotation": 5
    },
    {
      "x": -16,
      "y": 1,
      "z": -1,
      "name": "Wood_Fir_Trunk_Full",
      "support": 15,
      "rotation": 5
    },
    {
      "x": -16,
      "y": 2,
      "z": 2,
      "name": "Wood_Fir_Trunk_Full",
      "support": 15,
      "rotation": 5
    },
    {
      "x": -16,
      "y": 3,
      "z": 5,
      "name": "Wood_Fir_Trunk_Full",
      "support": 15,
      "rotation": 5
    },
    {
      "x": -16,
      "y": 4,
      "z": 5,
      "name": "Wood_Fir_Trunk_Full",
      "support": 15,
      "rotation": 5
    },
    {
      "x": -16,
      "y": 5,
      "z": 7,
      "name": "Wood_Fir_Trunk_Full",
      "support": 15,
      "rotation": 5
    },
    {
      "x": -16,
      "y": 6,
      "z": 7,
      "name": "Wood_Fir_Trunk_Full",
      "support": 15,
      "rotation": 5
    },
    {
      "x": -16,
      "y": 7,
      "z": 7,
      "name": "Wood_Fir_Trunk_Full",
      "support": 15,
      "rotation": 4
    },
    {
      "x": -16,
      "y": 7,
      "z": 8,
      "name": "Wood_Fir_Trunk_Full",
      "support": 15,
      "rotation": 5
    },
    {
      "x": -16,
      "y": 9,
      "z": 8,
      "name": "Wood_Fir_Trunk_Full",
      "support": 15,
      "rotation": 5
    },
    {
      "x": -15,
      "y": 1,
      "z": -1,
      "name": "Wood_Fir_Trunk_Full",
      "support": 15,
      "rotation": 5
    },
    {
      "x": -15,
      "y": 1,
      "z": 2,
      "name": "Wood_Fir_Trunk_Full",
      "support": 15,
      "rotation": 5
    },
    {
      "x": -15,
      "y": 2,
      "z": 2,
      "name": "Wood_Fir_Trunk_Full",
      "support": 15,
      "rotation": 5
    },
    {
      "x": -15,
      "y": 3,
      "z": 5,
      "name": "Wood_Fir_Trunk_Full",
      "support": 15,
      "rotation": 5
    },
    {
      "x": -15,
      "y": 5,
      "z": 7,
      "name": "Wood_Fir_Trunk_Full",
      "support": 15,
      "rotation": 5
    },
    {
      "x": -15,
      "y": 7,
      "z": 8,
      "name": "Wood_Fir_Trunk_Full",
      "support": 15,
      "rotation": 5
    },
    {
      "x": -15,
      "y": 9,
      "z": 8,
      "name": "Wood_Fir_Trunk_Full",
      "support": 15,
      "rotation": 5
    },
    {
      "x": -14,
      "y": 1,
      "z": -1,
      "name": "Wood_Fir_Trunk_Full",
      "support": 15,
      "rotation": 5
    },
    {
      "x": -14,
      "y": 1,
      "z": 2,
      "name": "Wood_Fir_Trunk_Full",
      "support": 15,
      "rotation": 5
    },
    {
      "x": -14,
      "y": 3,
      "z": 5,
      "name": "Wood_Fir_Trunk_Full",
      "support": 15,
      "rotation": 5
    },
    {
      "x": -14,
      "y": 4,
      "z": 7,
      "name": "Wood_Fir_Trunk_Full",
      "support": 15,
      "rotation": 5
    },
    {
      "x": -14,
      "y": 5,
      "z": 7,
      "name": "Wood_Fir_Trunk_Full",
      "support": 15,
      "rotation": 5
    },
    {
      "x": -14,
      "y": 7,
      "z": 8,
      "name": "Wood_Fir_Trunk_Full",
      "support": 15,
      "rotation": 5
    },
    {
      "x": -14,
      "y": 9,
      "z": 8,
      "name": "Wood_Fir_Trunk_Full",
      "support": 15,
      "rotation": 5
    },
    {
      "x": -13,
      "y": 1,
      "z": -1,
      "name": "Wood_Fir_Trunk_Full",
      "support": 15,
      "rotation": 5
    },
    {
      "x": -13,
      "y": 1,
      "z": 2,
      "name": "Wood_Fir_Trunk_Full",
      "support": 15,
      "rotation": 5
    },
    {
      "x": -13,
      "y": 2,
      "z": 5,
      "name": "Wood_Fir_Trunk_Full",
      "support": 15,
      "rotation": 5
    },
    {
      "x": -13,
      "y": 3,
      "z": 5,
      "name": "Wood_Fir_Trunk_Full",
      "support": 15,
      "rotation": 5
    },
    {
      "x": -13,
      "y": 4,
      "z": 7,
      "name": "Wood_Fir_Trunk_Full",
      "support": 15,
      "rotation": 5
    },
    {
      "x": -13,
      "y": 7,
      "z": 8,
      "name": "Wood_Fir_Trunk_Full",
      "support": 15,
      "rotation": 5
    },
    {
      "x": -13,
      "y": 9,
      "z": 8,
      "name": "Wood_Fir_Trunk_Full",
      "support": 15,
      "rotation": 5
    },
    {
      "x": -12,
      "y": 1,
      "z": -1,
      "name": "Wood_Fir_Trunk_Full",
      "support": 15,
      "rotation": 5
    },
    {
      "x": -12,
      "y": 1,
      "z": 2,
      "name": "Wood_Fir_Trunk_Full",
      "support": 15,
      "rotation": 5
    },
    {
      "x": -12,
      "y": 2,
      "z": 5,
      "name": "Wood_Fir_Trunk_Full",
      "support": 15,
      "rotation": 5
    },
    {
      "x": -12,
      "y": 4,
      "z": 7,
      "name": "Wood_Fir_Trunk_Full",
      "support": 15,
      "rotation": 5
    },
    {
      "x": -12,
      "y": 7,
      "z": 8,
      "name": "Wood_Fir_Trunk_Full",
      "support": 15,
      "rotation": 5
    },
    {
      "x": -12,
      "y": 9,
      "z": 8,
      "name": "Wood_Fir_Trunk_Full",
      "support": 15,
      "rotation": 5
    },
    {
      "x": -11,
      "y": 1,
      "z": -1,
      "name": "Wood_Fir_Trunk_Full",
      "support": 15,
      "rotation": 5
    },
    {
      "x": -11,
      "y": 1,
      "z": 2,
      "name": "Wood_Fir_Trunk_Full",
      "support": 15,
      "rotation": 5
    },
    {
      "x": -11,
      "y": 2,
      "z": 5,
      "name": "Wood_Fir_Trunk_Full",
      "support": 15,
      "rotation": 5
    },
    {
      "x": -11,
      "y": 4,
      "z": 7,
      "name": "Wood_Fir_Trunk_Full",
      "support": 15,
      "rotation": 5
    },
    {
      "x": -11,
      "y": 7,
      "z": 8,
      "name": "Wood_Fir_Trunk_Full",
      "support": 15,
      "rotation": 5
    },
    {
      "x": -11,
      "y": 9,
      "z": 8,
      "name": "Wood_Fir_Trunk_Full",
      "support": 15,
      "rotation": 5
    },
    {
      "x": -10,
      "y": 1,
      "z": -1,
      "name": "Wood_Fir_Trunk_Full",
      "support": 15,
      "rotation": 5
    },
    {
      "x": -10,
      "y": 1,
      "z": 2,
      "name": "Wood_Fir_Trunk_Full",
      "support": 15,
      "rotation": 5
    },
    {
      "x": -10,
      "y": 2,
      "z": 5,
      "name": "Wood_Fir_Trunk_Full",
      "support": 15,
      "rotation": 5
    },
    {
      "x": -10,
      "y": 4,
      "z": 7,
      "name": "Wood_Fir_Trunk_Full",
      "support": 15,
      "rotation": 5
    },
    {
      "x": -10,
      "y": 7,
      "z": 8,
      "name": "Wood_Fir_Trunk_Full",
      "support": 15,
      "rotation": 5
    },
    {
      "x": -10,
      "y": 9,
      "z": 8,
      "name": "Wood_Fir_Trunk_Full",
      "support": 15,
      "rotation": 5
    },
    {
      "x": -9,
      "y": 1,
      "z": -1,
      "name": "Wood_Fir_Trunk_Full",
      "support": 15,
      "rotation": 5
    },
    {
      "x": -9,
      "y": 1,
      "z": 2,
      "name": "Wood_Fir_Trunk_Full",
      "support": 15,
      "rotation": 5
    },
    {
      "x": -9,
      "y": 2,
      "z": 5,
      "name": "Wood_Fir_Trunk_Full",
      "support": 15,
      "rotation": 5
    },
    {
      "x": -9,
      "y": 4,
      "z": 7,
      "name": "Wood_Fir_Trunk_Full",
      "support": 15,
      "rotation": 5
    },
    {
      "x": -9,
      "y": 7,
      "z": 8,
      "name": "Wood_Fir_Trunk_Full",
      "support": 15,
      "rotation": 5
    },
    {
      "x": -9,
      "y": 9,
      "z": 8,
      "name": "Wood_Fir_Trunk_Full",
      "support": 15,
      "rotation": 5
    },
    {
      "x": -8,
      "y": 1,
      "z": -1,
      "name": "Wood_Fir_Trunk_Full",
      "support": 15,
      "rotation": 5
    },
    {
      "x": -8,
      "y": 1,
      "z": 2,
      "name": "Wood_Fir_Trunk_Full",
      "support": 15,
      "rotation": 5
    },
    {
      "x": -8,
      "y": 2,
      "z": 5,
      "name": "Wood_Fir_Trunk_Full",
      "support": 15,
      "rotation": 5
    },
    {
      "x": -8,
      "y": 4,
      "z": 7,
      "name": "Wood_Fir_Trunk_Full",
      "support": 15,
      "rotation": 5
    },
    {
      "x": -8,
      "y": 7,
      "z": 8,
      "name": "Wood_Fir_Trunk_Full",
      "support": 15,
      "rotation": 5
    },
    {
      "x": -8,
      "y": 9,
      "z": 8,
      "name": "Wood_Fir_Trunk_Full",
      "support": 15,
      "rotation": 5
    },
    {
      "x": -7,
      "y": 1,
      "z": -1,
      "name": "Wood_Fir_Trunk_Full",
      "support": 15,
      "rotation": 5
    },
    {
      "x": -7,
      "y": 1,
      "z": 2,
      "name": "Wood_Fir_Trunk_Full",
      "support": 15,
      "rotation": 5
    },
    {
      "x": -7,
      "y": 2,
      "z": 5,
      "name": "Wood_Fir_Trunk_Full",
      "support": 15,
      "rotation": 5
    },
    {
      "x": -7,
      "y": 4,
      "z": 7,
      "name": "Wood_Fir_Trunk_Full",
      "support": 15,
      "rotation": 5
    },
    {
      "x": -7,
      "y": 7,
      "z": 8,
      "name": "Wood_Fir_Trunk_Full",
      "support": 15,
      "rotation": 5
    },
    {
      "x": -7,
      "y": 9,
      "z": 8,
      "name": "Wood_Fir_Trunk_Full",
      "support": 15,
      "rotation": 5
    },
    {
      "x": -6,
      "y": 1,
      "z": -1,
      "name": "Wood_Fir_Trunk_Full",
      "support": 15,
      "rotation": 5
    },
    {
      "x": -6,
      "y": 1,
      "z": 2,
      "name": "Wood_Fir_Trunk_Full",
      "support": 15,
      "rotation": 5
    },
    {
      "x": -6,
      "y": 2,
      "z": 5,
      "name": "Wood_Fir_Trunk_Full",
      "support": 15,
      "rotation": 5
    },
    {
      "x": -6,
      "y": 4,
      "z": 7,
      "name": "Wood_Fir_Trunk_Full",
      "support": 15,
      "rotation": 5
    },
    {
      "x": -6,
      "y": 7,
      "z": 8,
      "name": "Wood_Fir_Trunk_Full",
      "support": 15,
      "rotation": 5
    },
    {
      "x": -6,
      "y": 9,
      "z": 8,
      "name": "Wood_Fir_Trunk_Full",
      "support": 15,
      "rotation": 5
    },
    {
      "x": -5,
      "y": 1,
      "z": -1,
      "name": "Wood_Fir_Trunk_Full",
      "support": 15,
      "rotation": 5
    },
    {
      "x": -5,
      "y": 1,
      "z": 2,
      "name": "Wood_Fir_Trunk_Full",
      "support": 15,
      "rotation": 5
    },
    {
      "x": -5,
      "y": 2,
      "z": 5,
      "name": "Wood_Fir_Trunk_Full",
      "support": 15,
      "rotation": 5
    },
    {
      "x": -5,
      "y": 4,
      "z": 7,
      "name": "Wood_Fir_Trunk_Full",
      "support": 15,
      "rotation": 5
    },
    {
      "x": -5,
      "y": 7,
      "z": 8,
      "name": "Wood_Fir_Trunk_Full",
      "support": 15,
      "rotation": 5
    },
    {
      "x": -5,
      "y": 9,
      "z": 8,
      "name": "Wood_Fir_Trunk_Full",
      "support": 15,
      "rotation": 5
    },
    {
      "x": -4,
      "y": 1,
      "z": -1,
      "name": "Wood_Fir_Trunk_Full",
      "support": 15,
      "rotation": 5
    },
    {
      "x": -4,
      "y": 1,
      "z": 2,
      "name": "Wood_Fir_Trunk_Full",
      "support": 15,
      "rotation": 5
    },
    {
      "x": -4,
      "y": 2,
      "z": 5,
      "name": "Wood_Fir_Trunk_Full",
      "support": 15,
      "rotation": 5
    },
    {
      "x": -4,
      "y": 4,
      "z": 7,
      "name": "Wood_Fir_Trunk_Full",
      "support": 15,
      "rotation": 5
    },
    {
      "x": -4,
      "y": 7,
      "z": 8,
      "name": "Wood_Fir_Trunk_Full",
      "support": 15,
      "rotation": 5
    },
    {
      "x": -4,
      "y": 9,
      "z": 8,
      "name": "Wood_Fir_Trunk_Full",
      "support": 15,
      "rotation": 5
    },
    {
      "x": -3,
      "y": 1,
      "z": -1,
      "name": "Wood_Fir_Trunk_Full",
      "support": 15,
      "rotation": 5
    },
    {
      "x": -3,
      "y": 1,
      "z": 2,
      "name": "Wood_Fir_Trunk_Full",
      "support": 15,
      "rotation": 5
    },
    {
      "x": -3,
      "y": 2,
      "z": 5,
      "name": "Wood_Fir_Trunk_Full",
      "support": 15,
      "rotation": 5
    },
    {
      "x": -3,
      "y": 4,
      "z": 7,
      "name": "Wood_Fir_Trunk_Full",
      "support": 15,
      "rotation": 5
    },
    {
      "x": -3,
      "y": 7,
      "z": 8,
      "name": "Wood_Fir_Trunk_Full",
      "support": 15,
      "rotation": 5
    },
    {
      "x": -3,
      "y": 9,
      "z": 8,
      "name": "Wood_Fir_Trunk_Full",
      "support": 15,
      "rotation": 5
    },
    {
      "x": -2,
      "y": 1,
      "z": -1,
      "name": "Wood_Fir_Trunk_Full",
      "support": 15,
      "rotation": 5
    },
    {
      "x": -2,
      "y": 1,
      "z": 2,
      "name": "Wood_Fir_Trunk_Full",
      "support": 15,
      "rotation": 5
    },
    {
      "x": -2,
      "y": 2,
      "z": 5,
      "name": "Wood_Fir_Trunk_Full",
      "support": 15,
      "rotation": 5
    },
    {
      "x": -2,
      "y": 4,
      "z": 7,
      "name": "Wood_Fir_Trunk_Full",
      "support": 15,
      "rotation": 5
    },
    {
      "x": -2,
      "y": 7,
      "z": 8,
      "name": "Wood_Fir_Trunk_Full",
      "support": 15,
      "rotation": 5
    },
    {
      "x": -2,
      "y": 9,
      "z": 8,
      "name": "Wood_Fir_Trunk_Full",
      "support": 15,
      "rotation": 5
    },
    {
      "x": -1,
      "y": 1,
      "z": -1,
      "name": "Wood_Fir_Trunk_Full",
      "support": 15,
      "rotation": 5
    },
    {
      "x": -1,
      "y": 1,
      "z": 2,
      "name": "Wood_Fir_Trunk_Full",
      "support": 15,
      "rotation": 5
    },
    {
      "x": -1,
      "y": 2,
      "z": 5,
      "name": "Wood_Fir_Trunk_Full",
      "support": 15,
      "rotation": 5
    },
    {
      "x": -1,
      "y": 4,
      "z": 7,
      "name": "Wood_Fir_Trunk_Full",
      "support": 15,
      "rotation": 5
    },
    {
      "x": -1,
      "y": 7,
      "z": 8,
      "name": "Wood_Fir_Trunk_Full",
      "support": 15,
      "rotation": 5
    },
    {
      "x": -1,
      "y": 9,
      "z": 8,
      "name": "Wood_Fir_Trunk_Full",
      "support": 15,
      "rotation": 5
    },
    {
      "x": 0,
      "y": 1,
      "z": -1,
      "name": "Wood_Fir_Trunk_Full",
      "support": 15,
      "rotation": 5
    },
    {
      "x": 0,
      "y": 1,
      "z": 2,
      "name": "Wood_Fir_Trunk_Full",
      "support": 15,
      "rotation": 5
    },
    {
      "x": 0,
      "y": 2,
      "z": 5,
      "name": "Wood_Fir_Trunk_Full",
      "support": 15,
      "rotation": 5
    },
    {
      "x": 0,
      "y": 4,
      "z": 7,
      "name": "Wood_Fir_Trunk_Full",
      "support": 15,
      "rotation": 5
    },
    {
      "x": 0,
      "y": 7,
      "z": 8,
      "name": "Wood_Fir_Trunk_Full",
      "support": 15,
      "rotation": 5
    },
    {
      "x": 0,
      "y": 9,
      "z": 8,
      "name": "Wood_Fir_Trunk_Full",
      "support": 15,
      "rotation": 5
    },
    {
      "x": 1,
      "y": 1,
      "z": -1,
      "name": "Wood_Fir_Trunk_Full",
      "support": 15,
      "rotation": 5
    },
    {
      "x": 1,
      "y": 1,
      "z": 2,
      "name": "Wood_Fir_Trunk_Full",
      "support": 15,
      "rotation": 5
    },
    {
      "x": 1,
      "y": 2,
      "z": 5,
      "name": "Wood_Fir_Trunk_Full",
      "support": 15,
      "rotation": 5
    },
    {
      "x": 1,
      "y": 4,
      "z": 7,
      "name": "Wood_Fir_Trunk_Full",
      "support": 15,
      "rotation": 5
    },
    {
      "x": 1,
      "y": 7,
      "z": 8,
      "name": "Wood_Fir_Trunk_Full",
      "support": 15,
      "rotation": 5
    },
    {
      "x": 1,
      "y": 9,
      "z": 8,
      "name": "Wood_Fir_Trunk_Full",
      "support": 15,
      "rotation": 5
    },
    {
      "x": 2,
      "y": 1,
      "z": -1,
      "name": "Wood_Fir_Trunk_Full",
      "support": 15,
      "rotation": 5
    },
    {
      "x": 2,
      "y": 1,
      "z": 2,
      "name": "Wood_Fir_Trunk_Full",
      "support": 15,
      "rotation": 5
    },
    {
      "x": 2,
      "y": 2,
      "z": 5,
      "name": "Wood_Fir_Trunk_Full",
      "support": 15,
      "rotation": 5
    },
    {
      "x": 2,
      "y": 4,
      "z": 7,
      "name": "Wood_Fir_Trunk_Full",
      "support": 15,
      "rotation": 5
    },
    {
      "x": 2,
      "y": 7,
      "z": 8,
      "name": "Wood_Fir_Trunk_Full",
      "support": 15,
      "rotation": 5
    },
    {
      "x": 2,
      "y": 9,
      "z": 8,
      "name": "Wood_Fir_Trunk_Full",
      "support": 15,
      "rotation": 5
    },
    {
      "x": 3,
      "y": 1,
      "z": -1,
      "name": "Wood_Fir_Trunk_Full",
      "support": 15,
      "rotation": 5
    },
    {
      "x": 3,
      "y": 1,
      "z": 2,
      "name": "Wood_Fir_Trunk_Full",
      "support": 15,
      "rotation": 5
    },
    {
      "x": 3,
      "y": 2,
      "z": 5,
      "name": "Wood_Fir_Trunk_Full",
      "support": 15,
      "rotation": 5
    },
    {
      "x": 3,
      "y": 4,
      "z": 7,
      "name": "Wood_Fir_Trunk_Full",
      "support": 15,
      "rotation": 5
    },
    {
      "x": 3,
      "y": 7,
      "z": 8,
      "name": "Wood_Fir_Trunk_Full",
      "support": 15,
      "rotation": 5
    },
    {
      "x": 3,
      "y": 9,
      "z": 8,
      "name": "Wood_Fir_Trunk_Full",
      "support": 15,
      "rotation": 5
    },
    {
      "x": 4,
      "y": 1,
      "z": -1,
      "name": "Wood_Fir_Trunk_Full",
      "support": 15,
      "rotation": 5
    },
    {
      "x": 4,
      "y": 1,
      "z": 2,
      "name": "Wood_Fir_Trunk_Full",
      "support": 15,
      "rotation": 5
    },
    {
      "x": 4,
      "y": 2,
      "z": 5,
      "name": "Wood_Fir_Trunk_Full",
      "support": 15,
      "rotation": 5
    },
    {
      "x": 4,
      "y": 4,
      "z": 7,
      "name": "Wood_Fir_Trunk_Full",
      "support": 15,
      "rotation": 5
    },
    {
      "x": 4,
      "y": 7,
      "z": 8,
      "name": "Wood_Fir_Trunk_Full",
      "support": 15,
      "rotation": 5
    },
    {
      "x": 4,
      "y": 9,
      "z": 8,
      "name": "Wood_Fir_Trunk_Full",
      "support": 15,
      "rotation": 5
    },
    {
      "x": 5,
      "y": 1,
      "z": -1,
      "name": "Wood_Fir_Trunk_Full",
      "support": 15,
      "rotation": 5
    },
    {
      "x": 5,
      "y": 1,
      "z": 2,
      "name": "Wood_Fir_Trunk_Full",
      "support": 15,
      "rotation": 5
    },
    {
      "x": 5,
      "y": 2,
      "z": 5,
      "name": "Wood_Fir_Trunk_Full",
      "support": 15,
      "rotation": 5
    },
    {
      "x": 5,
      "y": 4,
      "z": 7,
      "name": "Wood_Fir_Trunk_Full",
      "support": 15,
      "rotation": 5
    },
    {
      "x": 5,
      "y": 7,
      "z": 8,
      "name": "Wood_Fir_Trunk_Full",
      "support": 15,
      "rotation": 5
    },
    {
      "x": 5,
      "y": 9,
      "z": 8,
      "name": "Wood_Fir_Trunk_Full",
      "support": 15,
      "rotation": 5
    },
    {
      "x": 6,
      "y": 1,
      "z": -1,
      "name": "Wood_Fir_Trunk_Full",
      "support": 15,
      "rotation": 5
    },
    {
      "x": 6,
      "y": 1,
      "z": 2,
      "name": "Wood_Fir_Trunk_Full",
      "support": 15,
      "rotation": 5
    },
    {
      "x": 6,
      "y": 2,
      "z": 5,
      "name": "Wood_Fir_Trunk_Full",
      "support": 15,
      "rotation": 5
    },
    {
      "x": 6,
      "y": 4,
      "z": 7,
      "name": "Wood_Fir_Trunk_Full",
      "support": 15,
      "rotation": 5
    },
    {
      "x": 6,
      "y": 7,
      "z": 8,
      "name": "Wood_Fir_Trunk_Full",
      "support": 15,
      "rotation": 5
    },
    {
      "x": 6,
      "y": 9,
      "z": 8,
      "name": "Wood_Fir_Trunk_Full",
      "support": 15,
      "rotation": 5
    },
    {
      "x": 7,
      "y": 1,
      "z": -1,
      "name": "Wood_Fir_Trunk_Full",
      "support": 15,
      "rotation": 5
    },
    {
      "x": 7,
      "y": 1,
      "z": 2,
      "name": "Wood_Fir_Trunk_Full",
      "support": 15,
      "rotation": 5
    },
    {
      "x": 7,
      "y": 2,
      "z": 5,
      "name": "Wood_Fir_Trunk_Full",
      "support": 15,
      "rotation": 5
    },
    {
      "x": 7,
      "y": 4,
      "z": 7,
      "name": "Wood_Fir_Trunk_Full",
      "support": 15,
      "rotation": 5
    },
    {
      "x": 7,
      "y": 7,
      "z": 8,
      "name": "Wood_Fir_Trunk_Full",
      "support": 15,
      "rotation": 5
    },
    {
      "x": 7,
      "y": 9,
      "z": 8,
      "name": "Wood_Fir_Trunk_Full",
      "support": 15,
      "rotation": 5
    },
    {
      "x": 8,
      "y": 1,
      "z": -1,
      "name": "Wood_Fir_Trunk_Full",
      "support": 15,
      "rotation": 5
    },
    {
      "x": 8,
      "y": 1,
      "z": 2,
      "name": "Wood_Fir_Trunk_Full",
      "support": 15,
      "rotation": 5
    },
    {
      "x": 8,
      "y": 2,
      "z": 5,
      "name": "Wood_Fir_Trunk_Full",
      "support": 15,
      "rotation": 5
    },
    {
      "x": 8,
      "y": 4,
      "z": 7,
      "name": "Wood_Fir_Trunk_Full",
      "support": 15,
      "rotation": 5
    },
    {
      "x": 8,
      "y": 7,
      "z": 8,
      "name": "Wood_Fir_Trunk_Full",
      "support": 15,
      "rotation": 5
    },
    {
      "x": 8,
      "y": 9,
      "z": 8,
      "name": "Wood_Fir_Trunk_Full",
      "support": 15,
      "rotation": 5
    },
    {
      "x": 9,
      "y": 1,
      "z": -1,
      "name": "Wood_Fir_Trunk_Full",
      "support": 15,
      "rotation": 5
    },
    {
      "x": 9,
      "y": 1,
      "z": 2,
      "name": "Wood_Fir_Trunk_Full",
      "support": 15,
      "rotation": 5
    },
    {
      "x": 9,
      "y": 2,
      "z": 5,
      "name": "Wood_Fir_Trunk_Full",
      "support": 15,
      "rotation": 5
    },
    {
      "x": 9,
      "y": 4,
      "z": 7,
      "name": "Wood_Fir_Trunk_Full",
      "support": 15,
      "rotation": 5
    },
    {
      "x": 9,
      "y": 7,
      "z": 8,
      "name": "Wood_Fir_Trunk_Full",
      "support": 15,
      "rotation": 5
    },
    {
      "x": 9,
      "y": 9,
      "z": 8,
      "name": "Wood_Fir_Trunk_Full",
      "support": 15,
      "rotation": 5
    },
    {
      "x": 10,
      "y": 1,
      "z": -1,
      "name": "Wood_Fir_Trunk_Full",
      "support": 15,
      "rotation": 5
    },
    {
      "x": 10,
      "y": 1,
      "z": 2,
      "name": "Wood_Fir_Trunk_Full",
      "support": 15,
      "rotation": 5
    },
    {
      "x": 10,
      "y": 2,
      "z": 5,
      "name": "Wood_Fir_Trunk_Full",
      "support": 15,
      "rotation": 5
    },
    {
      "x": 10,
      "y": 4,
      "z": 7,
      "name": "Wood_Fir_Trunk_Full",
      "support": 15,
      "rotation": 5
    },
    {
      "x": 10,
      "y": 7,
      "z": 8,
      "name": "Wood_Fir_Trunk_Full",
      "support": 15,
      "rotation": 5
    },
    {
      "x": 10,
      "y": 9,
      "z": 8,
      "name": "Wood_Fir_Trunk_Full",
      "support": 15,
      "rotation": 5
    },
    {
      "x": 11,
      "y": 0,
      "z": -1,
      "name": "Wood_Blackwood_Planks"
    },
    {
      "x": 11,
      "y": 1,
      "z": -1,
      "name": "Wood_Fir_Trunk_Full",
      "support": 15,
      "rotation": 5
    },
    {
      "x": 11,
      "y": 1,
      "z": 2,
      "name": "Wood_Fir_Trunk_Full",
      "support": 15,
      "rotation": 5
    },
    {
      "x": 11,
      "y": 2,
      "z": 5,
      "name": "Wood_Fir_Trunk_Full",
      "support": 15,
      "rotation": 5
    },
    {
      "x": 11,
      "y": 4,
      "z": 7,
      "name": "Wood_Fir_Trunk_Full",
      "support": 15,
      "rotation": 5
    },
    {
      "x": 11,
      "y": 7,
      "z": 8,
      "name": "Wood_Fir_Trunk_Full",
      "support": 15,
      "rotation": 5
    },
    {
      "x": 11,
      "y": 9,
      "z": 8,
      "name": "Wood_Fir_Trunk_Full",
      "support": 15,
      "rotation": 5
    },
    {
      "x": 12,
      "y": 1,
      "z": -1,
      "name": "Wood_Fir_Trunk_Full",
      "support": 15,
      "rotation": 5
    },
    {
      "x": 12,
      "y": 1,
      "z": 2,
      "name": "Wood_Fir_Trunk_Full",
      "support": 15,
      "rotation": 5
    },
    {
      "x": 12,
      "y": 2,
      "z": 5,
      "name": "Wood_Fir_Trunk_Full",
      "support": 15,
      "rotation": 5
    },
    {
      "x": 12,
      "y": 4,
      "z": 7,
      "name": "Wood_Fir_Trunk_Full",
      "support": 15,
      "rotation": 5
    },
    {
      "x": 12,
      "y": 7,
      "z": 8,
      "name": "Wood_Fir_Trunk_Full",
      "support": 15,
      "rotation": 5
    },
    {
      "x": 12,
      "y": 9,
      "z": 8,
      "name": "Wood_Fir_Trunk_Full",
      "support": 15,
      "rotation": 5
    },
    {
      "x": 13,
      "y": 1,
      "z": -1,
      "name": "Wood_Fir_Trunk_Full",
      "support": 15,
      "rotation": 5
    },
    {
      "x": 13,
      "y": 1,
      "z": 2,
      "name": "Wood_Fir_Trunk_Full",
      "support": 15,
      "rotation": 5
    },
    {
      "x": 13,
      "y": 2,
      "z": 5,
      "name": "Wood_Fir_Trunk_Full",
      "support": 15,
      "rotation": 5
    },
    {
      "x": 13,
      "y": 4,
      "z": 7,
      "name": "Wood_Fir_Trunk_Full",
      "support": 15,
      "rotation": 5
    },
    {
      "x": 13,
      "y": 7,
      "z": 8,
      "name": "Wood_Fir_Trunk_Full",
      "support": 15,
      "rotation": 5
    },
    {
      "x": 13,
      "y": 9,
      "z": 8,
      "name": "Wood_Fir_Trunk_Full",
      "support": 15,
      "rotation": 5
    },
    {
      "x": 14,
      "y": 1,
      "z": -1,
      "name": "Wood_Fir_Trunk_Full",
      "support": 15,
      "rotation": 5
    },
    {
      "x": 14,
      "y": 1,
      "z": 2,
      "name": "Wood_Fir_Trunk_Full",
      "support": 15,
      "rotation": 5
    },
    {
      "x": 14,
      "y": 2,
      "z": 5,
      "name": "Wood_Fir_Trunk_Full",
      "support": 15,
      "rotation": 5
    },
    {
      "x": 14,
      "y": 4,
      "z": 7,
      "name": "Wood_Fir_Trunk_Full",
      "support": 15,
      "rotation": 5
    },
    {
      "x": 14,
      "y": 7,
      "z": 8,
      "name": "Wood_Fir_Trunk_Full",
      "support": 15,
      "rotation": 5
    },
    {
      "x": 14,
      "y": 9,
      "z": 8,
      "name": "Wood_Fir_Trunk_Full",
      "support": 15,
      "rotation": 5
    },
    {
      "x": 15,
      "y": 1,
      "z": -1,
      "name": "Wood_Fir_Trunk_Full",
      "support": 15,
      "rotation": 5
    },
    {
      "x": 15,
      "y": 1,
      "z": 2,
      "name": "Wood_Fir_Trunk_Full",
      "support": 15,
      "rotation": 5
    },
    {
      "x": 15,
      "y": 2,
      "z": 5,
      "name": "Wood_Fir_Trunk_Full",
      "support": 15,
      "rotation": 5
    },
    {
      "x": 15,
      "y": 4,
      "z": 7,
      "name": "Wood_Fir_Trunk_Full",
      "support": 15,
      "rotation": 5
    },
    {
      "x": 15,
      "y": 7,
      "z": 8,
      "name": "Wood_Fir_Trunk_Full",
      "support": 15,
      "rotation": 5
    },
    {
      "x": 15,
      "y": 9,
      "z": 8,
      "name": "Wood_Fir_Trunk_Full",
      "support": 15,
      "rotation": 5
    },
    {
      "x": 16,
      "y": 1,
      "z": -1,
      "name": "Wood_Fir_Trunk_Full",
      "support": 15,
      "rotation": 5
    },
    {
      "x": 16,
      "y": 1,
      "z": 2,
      "name": "Wood_Fir_Trunk_Full",
      "support": 15,
      "rotation": 5
    },
    {
      "x": 16,
      "y": 2,
      "z": 5,
      "name": "Wood_Fir_Trunk_Full",
      "support": 15,
      "rotation": 5
    },
    {
      "x": 16,
      "y": 4,
      "z": 7,
      "name": "Wood_Fir_Trunk_Full",
      "support": 15,
      "rotation": 5
    },
    {
      "x": 16,
      "y": 7,
      "z": 8,
      "name": "Wood_Fir_Trunk_Full",
      "support": 15,
      "rotation": 5
    },
    {
      "x": 16,
      "y": 9,
      "z": 8,
      "name": "Wood_Fir_Trunk_Full",
      "support": 15,
      "rotation": 5
    },
    {
      "x": 17,
      "y": 1,
      "z": -1,
      "name": "Wood_Fir_Trunk_Full",
      "support": 15,
      "rotation": 5
    },
    {
      "x": 17,
      "y": 1,
      "z": 2,
      "name": "Wood_Fir_Trunk_Full",
      "support": 15,
      "rotation": 5
    },
    {
      "x": 17,
      "y": 2,
      "z": 5,
      "name": "Wood_Fir_Trunk_Full",
      "support": 15,
      "rotation": 5
    },
    {
      "x": 17,
      "y": 4,
      "z": 7,
      "name": "Wood_Fir_Trunk_Full",
      "support": 15,
      "rotation": 5
    },
    {
      "x": 17,
      "y": 7,
      "z": 8,
      "name": "Wood_Fir_Trunk_Full",
      "support": 15,
      "rotation": 5
    },
    {
      "x": 17,
      "y": 9,
      "z": 8,
      "name": "Wood_Fir_Trunk_Full",
      "support": 15,
      "rotation": 4
    },
    {
      "x": 17,
      "y": 9,
      "z": 9,
      "name": "Wood_Fir_Trunk_Full",
      "support": 15,
      "rotation": 5
    },
    {
      "x": 18,
      "y": 1,
      "z": -1,
      "name": "Wood_Fir_Trunk_Full",
      "support": 15,
      "rotation": 5
    },
    {
      "x": 18,
      "y": 1,
      "z": 2,
      "name": "Wood_Fir_Trunk_Full",
      "support": 15,
      "rotation": 5
    },
    {
      "x": 18,
      "y": 2,
      "z": 5,
      "name": "Wood_Fir_Trunk_Full",
      "support": 15,
      "rotation": 5
    },
    {
      "x": 18,
      "y": 4,
      "z": 7,
      "name": "Wood_Fir_Trunk_Full",
      "support": 15,
      "rotation": 5
    },
    {
      "x": 18,
      "y": 7,
      "z": 8,
      "name": "Wood_Fir_Trunk_Full",
      "support": 15,
      "rotation": 5
    },
    {
      "x": 18,
      "y": 9,
      "z": 9,
      "name": "Wood_Fir_Trunk_Full",
      "support": 15,
      "rotation": 4
    },
    {
      "x": 18,
      "y": 9,
      "z": 10,
      "name": "Wood_Fir_Trunk_Full",
      "support": 15,
      "rotation": 5
    },
    {
      "x": 19,
      "y": 1,
      "z": -1,
      "name": "Wood_Fir_Trunk_Full",
      "support": 15,
      "rotation": 5
    },
    {
      "x": 19,
      "y": 2,
      "z": -1,
      "name": "Wood_Fir_Trunk_Full",
      "support": 15,
      "rotation": 5
    },
    {
      "x": 19,
      "y": 1,
      "z": 0,
      "name": "Wood_Fir_Trunk_Full",
      "support": 15,
      "rotation": 4
    },
    {
      "x": 19,
      "y": 1,
      "z": 1,
      "name": "Wood_Fir_Trunk_Full",
      "support": 15,
      "rotation": 4
    },
    {
      "x": 19,
      "y": 1,
      "z": 2,
      "name": "Wood_Fir_Trunk_Full",
      "support": 15,
      "rotation": 4
    },
    {
      "x": 19,
      "y": 2,
      "z": 2,
      "name": "Wood_Fir_Trunk_Full",
      "support": 15,
      "rotation": 4
    },
    {
      "x": 19,
      "y": 2,
      "z": 3,
      "name": "Wood_Fir_Trunk_Full",
      "support": 15
    },
    {
      "x": 19,
      "y": 2,
      "z": 4,
      "name": "Wood_Fir_Trunk_Full",
      "support": 15
    },
    {
      "x": 19,
      "y": 2,
      "z": 5,
      "name": "Wood_Fir_Trunk_Full",
      "support": 15,
      "rotation": 4
    },
    {
      "x": 19,
      "y": 3,
      "z": 5,
      "name": "Wood_Fir_Trunk_Full",
      "support": 15
    },
    {
      "x": 19,
      "y": 3,
      "z": 6,
      "name": "Wood_Fir_Trunk_Full",
      "support": 15,
      "rotation": 4
    },
    {
      "x": 19,
      "y": 4,
      "z": 6,
      "name": "Wood_Fir_Trunk_Full",
      "support": 15
    },
    {
      "x": 19,
      "y": 4,
      "z": 7,
      "name": "Wood_Fir_Trunk_Full",
      "support": 15,
      "rotation": 4
    },
    {
      "x": 19,
      "y": 5,
      "z": 7,
      "name": "Wood_Fir_Trunk_Full",
      "support": 15
    },
    {
      "x": 19,
      "y": 5,
      "z": 8,
      "name": "Wood_Fir_Trunk_Full",
      "support": 15,
      "rotation": 4
    },
    {
      "x": 19,
      "y": 6,
      "z": 8,
      "name": "Wood_Fir_Trunk_Full",
      "support": 15
    },
    {
      "x": 19,
      "y": 7,
      "z": 8,
      "name": "Wood_Fir_Trunk_Full",
      "support": 15
    },
    {
      "x": 19,
      "y": 7,
      "z": 9,
      "name": "Wood_Fir_Trunk_Full",
      "support": 15,
      "rotation": 4
    },
    {
      "x": 19,
      "y": 8,
      "z": 9,
      "name": "Wood_Fir_Trunk_Full",
      "support": 15
    },
    {
      "x": 19,
      "y": 9,
      "z": 9,
      "name": "Wood_Fir_Trunk_Full",
      "support": 15,
      "rotation": 4
    },
    {
      "x": 19,
      "y": 9,
      "z": 10,
      "name": "Wood_Fir_Trunk_Full",
      "support": 15,
      "rotation": 5
    },
    {
      "x": 20,
      "y": 2,
      "z": -1,
      "name": "Wood_Fir_Trunk_Full",
      "support": 15,
      "rotation": 5
    },
    {
      "x": 20,
      "y": 3,
      "z": -1,
      "name": "Wood_Fir_Trunk_Full",
      "support": 15
    },
    {
      "x": 20,
      "y": 4,
      "z": -1,
      "name": "Wood_Fir_Trunk_Full",
      "support": 15
    },
    {
      "x": 20,
      "y": 5,
      "z": -1,
      "name": "Wood_Fir_Trunk_Full",
      "support": 15
    },
    {
      "x": 20,
      "y": 9,
      "z": 9,
      "name": "Wood_Fir_Trunk_Full",
      "support": 15,
      "rotation": 5
    },
    {
      "x": 20,
      "y": 9,
      "z": 10,
      "name": "Wood_Fir_Trunk_Full",
      "support": 15,
      "rotation": 5
    },
    {
      "x": 21,
      "y": 5,
      "z": -1,
      "name": "Wood_Fir_Trunk_Full",
      "support": 15
    },
    {
      "x": 21,
      "y": 6,
      "z": -1,
      "name": "Wood_Fir_Trunk_Full",
      "support": 15,
      "rotation": 5
    },
    {
      "x": 21,
      "y": 9,
      "z": 9,
      "name": "Wood_Fir_Trunk_Full",
      "support": 15,
      "rotation": 5
    },
    {
      "x": 21,
      "y": 9,
      "z": 10,
      "name": "Wood_Fir_Trunk_Full",
      "support": 15,
      "rotation": 5
    },
    {
      "x": 22,
      "y": 6,
      "z": -1,
      "name": "Wood_Fir_Trunk_Full",
      "support": 15,
      "rotation": 5
    },
    {
      "x": 22,
      "y": 7,
      "z": -1,
      "name": "Wood_Fir_Trunk_Full",
      "support": 15,
      "rotation": 5
    },
    {
      "x": 22,
      "y": 9,
      "z": 9,
      "name": "Wood_Fir_Trunk_Full",
      "support": 15,
      "rotation": 5
    },
    {
      "x": 22,
      "y": 9,
      "z": 10,
      "name": "Wood_Fir_Trunk_Full",
      "support": 15,
      "rotation": 5
    },
    {
      "x": 23,
      "y": 7,
      "z": -1,
      "name": "Wood_Fir_Trunk_Full",
      "support": 15,
      "rotation": 5
    },
    {
      "x": 23,
      "y": 9,
      "z": 9,
      "name": "Wood_Fir_Trunk_Full",
      "support": 15,
      "rotation": 5
    },
    {
      "x": 23,
      "y": 9,
      "z": 10,
      "name": "Wood_Fir_Trunk_Full",
      "support": 15,
      "rotation": 5
    },
    {
      "x": 24,
      "y": 7,
      "z": -1,
      "name": "Wood_Fir_Trunk_Full",
      "support": 15,
      "rotation": 5
    },
    {
      "x": 24,
      "y": 9,
      "z": 9,
      "name": "Wood_Fir_Trunk_Full",
      "support": 15,
      "rotation": 5
    },
    {
      "x": 24,
      "y": 9,
      "z": 10,
      "name": "Wood_Fir_Trunk_Full",
      "support": 15,
      "rotation": 5
    },
    {
      "x": 25,
      "y": 7,
      "z": -1,
      "name": "Wood_Fir_Trunk_Full",
      "support": 15,
      "rotation": 5
    },
    {
      "x": 25,
      "y": 8,
      "z": -1,
      "name": "Wood_Fir_Trunk_Full",
      "support": 15,
      "rotation": 5
    },
    {
      "x": 25,
      "y": 9,
      "z": 9,
      "name": "Wood_Fir_Trunk_Full",
      "support": 15,
      "rotation": 5
    },
    {
      "x": 25,
      "y": 9,
      "z": 10,
      "name": "Wood_Fir_Trunk_Full",
      "support": 15,
      "rotation": 5
    },
    {
      "x": 26,
      "y": 8,
      "z": -1,
      "name": "Wood_Fir_Trunk_Full",
      "support": 15,
      "rotation": 5
    },
    {
      "x": 26,
      "y": 9,
      "z": 9,
      "name": "Wood_Fir_Trunk_Full",
      "support": 15,
      "rotation": 5
    },
    {
      "x": 26,
      "y": 9,
      "z": 10,
      "name": "Wood_Fir_Trunk_Full",
      "support": 15,
      "rotation": 5
    },
    {
      "x": 27,
      "y": 8,
      "z": -1,
      "name": "Wood_Fir_Trunk_Full",
      "support": 15,
      "rotation": 5
    },
    {
      "x": 27,
      "y": 9,
      "z": 9,
      "name": "Wood_Fir_Trunk_Full",
      "support": 15,
      "rotation": 5
    },
    {
      "x": 27,
      "y": 9,
      "z": 10,
      "name": "Wood_Fir_Trunk_Full",
      "support": 15,
      "rotation": 5
    },
    {
      "x": 28,
      "y": 8,
      "z": -1,
      "name": "Wood_Fir_Trunk_Full",
      "support": 15,
      "rotation": 5
    },
    {
      "x": 28,
      "y": 9,
      "z": -1,
      "name": "Wood_Fir_Trunk_Full",
      "support": 15,
      "rotation": 5
    },
    {
      "x": 28,
      "y": 9,
      "z": 9,
      "name": "Wood_Fir_Trunk_Full",
      "support": 15,
      "rotation": 5
    },
    {
      "x": 28,
      "y": 9,
      "z": 10,
      "name": "Wood_Fir_Trunk_Full",
      "support": 15,
      "rotation": 5
    },
    {
      "x": 29,
      "y": 9,
      "z": -1,
      "name": "Wood_Fir_Trunk_Full",
      "support": 15,
      "rotation": 5
    },
    {
      "x": 29,
      "y": 9,
      "z": 9,
      "name": "Wood_Fir_Trunk_Full",
      "support": 15,
      "rotation": 5
    },
    {
      "x": 29,
      "y": 9,
      "z": 10,
      "name": "Wood_Fir_Trunk_Full",
      "support": 15,
      "rotation": 4
    },
    {
      "x": 30,
      "y": 9,
      "z": -1,
      "name": "Wood_Fir_Trunk_Full",
      "support": 15,
      "rotation": 5
    },
    {
      "x": 30,
      "y": 9,
      "z": 8,
      "name": "Wood_Fir_Trunk_Full",
      "support": 15,
      "rotation": 5
    },
    {
      "x": 30,
      "y": 9,
      "z": 9,
      "name": "Wood_Fir_Trunk_Full",
      "support": 15,
      "rotation": 4
    },
    {
      "x": 31,
      "y": 9,
      "z": -8,
      "name": "Wood_Fir_Trunk_Full",
      "support": 15,
      "rotation": 4
    },
    {
      "x": 31,
      "y": 9,
      "z": -7,
      "name": "Wood_Fir_Trunk_Full",
      "support": 15,
      "rotation": 4
    },
    {
      "x": 31,
      "y": 9,
      "z": -6,
      "name": "Wood_Fir_Trunk_Full",
      "support": 15,
      "rotation": 4
    },
    {
      "x": 31,
      "y": 9,
      "z": -5,
      "name": "Wood_Fir_Trunk_Full",
      "support": 15,
      "rotation": 4
    },
    {
      "x": 31,
      "y": 9,
      "z": -4,
      "name": "Wood_Fir_Trunk_Full",
      "support": 15,
      "rotation": 4
    },
    {
      "x": 31,
      "y": 9,
      "z": -3,
      "name": "Wood_Fir_Trunk_Full",
      "support": 15,
      "rotation": 4
    },
    {
      "x": 31,
      "y": 9,
      "z": -2,
      "name": "Wood_Fir_Trunk_Full",
      "support": 15,
      "rotation": 4
    },
    {
      "x": 31,
      "y": 9,
      "z": -1,
      "name": "Wood_Fir_Trunk_Full",
      "support": 15
    },
    {
      "x": 31,
      "y": 10,
      "z": -1,
      "name": "Wood_Fir_Trunk_Full",
      "support": 15
    },
    {
      "x": 31,
      "y": 11,
      "z": -1,
      "name": "Wood_Fir_Trunk_Full",
      "support": 15
    },
    {
      "x": 31,
      "y": 12,
      "z": -1,
      "name": "Wood_Fir_Trunk_Full",
      "support": 15
    },
    {
      "x": 31,
      "y": 13,
      "z": -1,
      "name": "Wood_Fir_Trunk_Full",
      "support": 15
    },
    {
      "x": 31,
      "y": 9,
      "z": 0,
      "name": "Wood_Fir_Trunk_Full",
      "support": 15,
      "rotation": 4
    },
    {
      "x": 31,
      "y": 9,
      "z": 1,
      "name": "Wood_Fir_Trunk_Full",
      "support": 15,
      "rotation": 4
    },
    {
      "x": 31,
      "y": 9,
      "z": 2,
      "name": "Wood_Fir_Trunk_Full",
      "support": 15,
      "rotation": 4
    },
    {
      "x": 31,
      "y": 9,
      "z": 3,
      "name": "Wood_Fir_Trunk_Full",
      "support": 15,
      "rotation": 4
    },
    {
      "x": 31,
      "y": 9,
      "z": 4,
      "name": "Wood_Fir_Trunk_Full",
      "support": 15,
      "rotation": 4
    },
    {
      "x": 31,
      "y": 9,
      "z": 5,
      "name": "Wood_Fir_Trunk_Full",
      "support": 15,
      "rotation": 4
    },
    {
      "x": 31,
      "y": 9,
      "z": 6,
      "name": "Wood_Fir_Trunk_Full",
      "support": 15,
      "rotation": 4
    },
    {
      "x": 31,
      "y": 9,
      "z": 7,
      "name": "Wood_Fir_Trunk_Full",
      "support": 15,
      "rotation": 4
    },
    {
      "x": 31,
      "y": 9,
      "z": 8,
      "name": "Wood_Fir_Trunk_Full",
      "support": 15,
      "rotation": 4
    },
    {
      "x": 32,
      "y": 13,
      "z": -1,
      "name": "Wood_Fir_Trunk_Full",
      "support": 15
    },
    {
      "x": 32,
      "y": 14,
      "z": -1,
      "name": "Wood_Fir_Trunk_Full",
      "support": 15
    },
    {
      "x": 32,
      "y": 15,
      "z": -1,
      "name": "Wood_Fir_Trunk_Full",
      "support": 15
    },
    {
      "x": 32,
      "y": 16,
      "z": -1,
      "name": "Wood_Fir_Trunk_Full",
      "support": 15
    }
  ],
  "fluids": [
    {
      "x": -36,
      "y": 13,
      "z": -1,
      "name": "Empty",
      "level": 0
    },
    {
      "x": -35,
      "y": 12,
      "z": -1,
      "name": "Empty",
      "level": 0
    },
    {
      "x": -35,
      "y": 13,
      "z": -1,
      "name": "Empty",
      "level": 0
    },
    {
      "x": -34,
      "y": 11,
      "z": -1,
      "name": "Empty",
      "level": 0
    },
    {
      "x": -34,
      "y": 12,
      "z": -1,
      "name": "Empty",
      "level": 0
    },
    {
      "x": -33,
      "y": 10,
      "z": -1,
      "name": "Empty",
      "level": 0
    },
    {
      "x": -33,
      "y": 11,
      "z": -1,
      "name": "Empty",
      "level": 0
    },
    {
      "x": -32,
      "y": 9,
      "z": -1,
      "name": "Empty",
      "level": 0
    },
    {
      "x": -32,
      "y": 10,
      "z": -1,
      "name": "Empty",
      "level": 0
    },
    {
      "x": -31,
      "y": 8,
      "z": -1,
      "name": "Empty",
      "level": 0
    },
    {
      "x": -31,
      "y": 9,
      "z": -1,
      "name": "Empty",
      "level": 0
    },
    {
      "x": -31,
      "y": 11,
      "z": -1,
      "name": "Empty",
      "level": 0
    },
    {
      "x": -31,
      "y": 11,
      "z": 0,
      "name": "Empty",
      "level": 0
    },
    {
      "x": -30,
      "y": 7,
      "z": -1,
      "name": "Empty",
      "level": 0
    },
    {
      "x": -30,
      "y": 8,
      "z": -1,
      "name": "Empty",
      "level": 0
    },
    {
      "x": -30,
      "y": 11,
      "z": 0,
      "name": "Empty",
      "level": 0
    },
    {
      "x": -30,
      "y": 11,
      "z": 1,
      "name": "Empty",
      "level": 0
    },
    {
      "x": -30,
      "y": 10,
      "z": 2,
      "name": "Empty",
      "level": 0
    },
    {
      "x": -30,
      "y": 11,
      "z": 2,
      "name": "Empty",
      "level": 0
    },
    {
      "x": -29,
      "y": 6,
      "z": -1,
      "name": "Empty",
      "level": 0
    },
    {
      "x": -29,
      "y": 7,
      "z": -1,
      "name": "Empty",
      "level": 0
    },
    {
      "x": -29,
      "y": 9,
      "z": 2,
      "name": "Empty",
      "level": 0
    },
    {
      "x": -29,
      "y": 10,
      "z": 2,
      "name": "Empty",
      "level": 0
    },
    {
      "x": -29,
      "y": 11,
      "z": 3,
      "name": "Empty",
      "level": 0
    },
    {
      "x": -29,
      "y": 11,
      "z": 4,
      "name": "Empty",
      "level": 0
    },
    {
      "x": -28,
      "y": 5,
      "z": -1,
      "name": "Empty",
      "level": 0
    },
    {
      "x": -28,
      "y": 6,
      "z": -1,
      "name": "Empty",
      "level": 0
    },
    {
      "x": -28,
      "y": 8,
      "z": 2,
      "name": "Empty",
      "level": 0
    },
    {
      "x": -28,
      "y": 9,
      "z": 2,
      "name": "Empty",
      "level": 0
    },
    {
      "x": -28,
      "y": 11,
      "z": 4,
      "name": "Empty",
      "level": 0
    },
    {
      "x": -28,
      "y": 11,
      "z": 5,
      "name": "Empty",
      "level": 0
    },
    {
      "x": -27,
      "y": 5,
      "z": -1,
      "name": "Empty",
      "level": 0
    },
    {
      "x": -27,
      "y": 7,
      "z": 2,
      "name": "Empty",
      "level": 0
    },
    {
      "x": -27,
      "y": 8,
      "z": 2,
      "name": "Empty",
      "level": 0
    },
    {
      "x": -27,
      "y": 10,
      "z": 5,
      "name": "Empty",
      "level": 0
    },
    {
      "x": -27,
      "y": 11,
      "z": 5,
      "name": "Empty",
      "level": 0
    },
    {
      "x": -26,
      "y": 4,
      "z": -1,
      "name": "Empty",
      "level": 0
    },
    {
      "x": -26,
      "y": 5,
      "z": -1,
      "name": "Empty",
      "level": 0
    },
    {
      "x": -26,
      "y": 6,
      "z": 2,
      "name": "Empty",
      "level": 0
    },
    {
      "x": -26,
      "y": 7,
      "z": 2,
      "name": "Empty",
      "level": 0
    },
    {
      "x": -26,
      "y": 9,
      "z": 5,
      "name": "Empty",
      "level": 0
    },
    {
      "x": -26,
      "y": 10,
      "z": 5,
      "name": "Empty",
      "level": 0
    },
    {
      "x": -26,
      "y": 11,
      "z": 5,
      "name": "Empty",
      "level": 0
    },
    {
      "x": -26,
      "y": 11,
      "z": 6,
      "name": "Empty",
      "level": 0
    },
    {
      "x": -25,
      "y": 4,
      "z": -1,
      "name": "Empty",
      "level": 0
    },
    {
      "x": -25,
      "y": 6,
      "z": 2,
      "name": "Empty",
      "level": 0
    },
    {
      "x": -25,
      "y": 8,
      "z": 5,
      "name": "Empty",
      "level": 0
    },
    {
      "x": -25,
      "y": 9,
      "z": 5,
      "name": "Empty",
      "level": 0
    },
    {
      "x": -25,
      "y": 11,
      "z": 6,
      "name": "Empty",
      "level": 0
    },
    {
      "x": -24,
      "y": 3,
      "z": -1,
      "name": "Empty",
      "level": 0
    },
    {
      "x": -24,
      "y": 4,
      "z": -1,
      "name": "Empty",
      "level": 0
    },
    {
      "x": -24,
      "y": 5,
      "z": 2,
      "name": "Empty",
      "level": 0
    },
    {
      "x": -24,
      "y": 6,
      "z": 2,
      "name": "Empty",
      "level": 0
    },
    {
      "x": -24,
      "y": 7,
      "z": 5,
      "name": "Empty",
      "level": 0
    },
    {
      "x": -24,
      "y": 8,
      "z": 5,
      "name": "Empty",
      "level": 0
    },
    {
      "x": -24,
      "y": 11,
      "z": 6,
      "name": "Empty",
      "level": 0
    },
    {
      "x": -24,
      "y": 10,
      "z": 7,
      "name": "Empty",
      "level": 0
    },
    {
      "x": -24,
      "y": 11,
      "z": 7,
      "name": "Empty",
      "level": 0
    },
    {
      "x": -23,
      "y": 3,
      "z": -1,
      "name": "Empty",
      "level": 0
    },
    {
      "x": -23,
      "y": 5,
      "z": 2,
      "name": "Empty",
      "level": 0
    },
    {
      "x": -23,
      "y": 7,
      "z": 5,
      "name": "Empty",
      "level": 0
    },
    {
      "x": -23,
      "y": 9,
      "z": 7,
      "name": "Empty",
      "level": 0
    },
    {
      "x": -23,
      "y": 10,
      "z": 7,
      "name": "Empty",
      "level": 0
    },
    {
      "x": -22,
      "y": 2,
      "z": -1,
      "name": "Empty",
      "level": 0
    },
    {
      "x": -22,
      "y": 3,
      "z": -1,
      "name": "Empty",
      "level": 0
    },
    {
      "x": -22,
      "y": 4,
      "z": 2,
      "name": "Empty",
      "level": 0
    },
    {
      "x": -22,
      "y": 5,
      "z": 2,
      "name": "Empty",
      "level": 0
    },
    {
      "x": -22,
      "y": 6,
      "z": 5,
      "name": "Empty",
      "level": 0
    },
    {
      "x": -22,
      "y": 7,
      "z": 5,
      "name": "Empty",
      "level": 0
    },
    {
      "x": -22,
      "y": 8,
      "z": 7,
      "name": "Empty",
      "level": 0
    },
    {
      "x": -22,
      "y": 9,
      "z": 7,
      "name": "Empty",
      "level": 0
    },
    {
      "x": -21,
      "y": 2,
      "z": -1,
      "name": "Empty",
      "level": 0
    },
    {
      "x": -21,
      "y": 4,
      "z": 2,
      "name": "Empty",
      "level": 0
    },
    {
      "x": -21,
      "y": 6,
      "z": 5,
      "name": "Empty",
      "level": 0
    },
    {
      "x": -21,
      "y": 8,
      "z": 7,
      "name": "Empty",
      "level": 0
    },
    {
      "x": -21,
      "y": 9,
      "z": 7,
      "name": "Empty",
      "level": 0
    },
    {
      "x": -20,
      "y": 2,
      "z": -1,
      "name": "Empty",
      "level": 0
    },
    {
      "x": -20,
      "y": 3,
      "z": 2,
      "name": "Empty",
      "level": 0
    },
    {
      "x": -20,
      "y": 4,
      "z": 2,
      "name": "Empty",
      "level": 0
    },
    {
      "x": -20,
      "y": 5,
      "z": 5,
      "name": "Empty",
      "level": 0
    },
    {
      "x": -20,
      "y": 6,
      "z": 5,
      "name": "Empty",
      "level": 0
    },
    {
      "x": -20,
      "y": 7,
      "z": 7,
      "name": "Empty",
      "level": 0
    },
    {
      "x": -20,
      "y": 8,
      "z": 7,
      "name": "Empty",
      "level": 0
    },
    {
      "x": -20,
      "y": 9,
      "z": 7,
      "name": "Empty",
      "level": 0
    },
    {
      "x": -19,
      "y": 2,
      "z": -1,
      "name": "Empty",
      "level": 0
    },
    {
      "x": -19,
      "y": 3,
      "z": 2,
      "name": "Empty",
      "level": 0
    },
    {
      "x": -19,
      "y": 5,
      "z": 5,
      "name": "Empty",
      "level": 0
    },
    {
      "x": -19,
      "y": 7,
      "z": 7,
      "name": "Empty",
      "level": 0
    },
    {
      "x": -19,
      "y": 9,
      "z": 7,
      "name": "Empty",
      "level": 0
    },
    {
      "x": -18,
      "y": 1,
      "z": -1,
      "name": "Empty",
      "level": 0
    },
    {
      "x": -18,
      "y": 2,
      "z": -1,
      "name": "Empty",
      "level": 0
    },
    {
      "x": -18,
      "y": 2,
      "z": 2,
      "name": "Empty",
      "level": 0
    },
    {
      "x": -18,
      "y": 3,
      "z": 2,
      "name": "Empty",
      "level": 0
    },
    {
      "x": -18,
      "y": 4,
      "z": 5,
      "name": "Empty",
      "level": 0
    },
    {
      "x": -18,
      "y": 5,
      "z": 5,
      "name": "Empty",
      "level": 0
    },
    {
      "x": -18,
      "y": 6,
      "z": 7,
      "name": "Empty",
      "level": 0
    },
    {
      "x": -18,
      "y": 7,
      "z": 7,
      "name": "Empty",
      "level": 0
    },
    {
      "x": -18,
      "y": 9,
      "z": 8,
      "name": "Empty",
      "level": 0
    },
    {
      "x": -17,
      "y": 1,
      "z": -1,
      "name": "Empty",
      "level": 0
    },
    {
      "x": -17,
      "y": 2,
      "z": 2,
      "name": "Empty",
      "level": 0
    },
    {
      "x": -17,
      "y": 4,
      "z": 5,
      "name": "Empty",
      "level": 0
    },
    {
      "x": -17,
      "y": 6,
      "z": 7,
      "name": "Empty",
      "level": 0
    },
    {
      "x": -17,
      "y": 7,
      "z": 7,
      "name": "Empty",
      "level": 0
    },
    {
      "x": -17,
      "y": 9,
      "z": 8,
      "name": "Empty",
      "level": 0
    },
    {
      "x": -16,
      "y": 1,
      "z": -1,
      "name": "Empty",
      "level": 0
    },
    {
      "x": -16,
      "y": 2,
      "z": 2,
      "name": "Empty",
      "level": 0
    },
    {
      "x": -16,
      "y": 3,
      "z": 5,
      "name": "Empty",
      "level": 0
    },
    {
      "x": -16,
      "y": 4,
      "z": 5,
      "name": "Empty",
      "level": 0
    },
    {
      "x": -16,
      "y": 5,
      "z": 7,
      "name": "Empty",
      "level": 0
    },
    {
      "x": -16,
      "y": 6,
      "z": 7,
      "name": "Empty",
      "level": 0
    },
    {
      "x": -16,
      "y": 7,
      "z": 7,
      "name": "Empty",
      "level": 0
    },
    {
      "x": -16,
      "y": 7,
      "z": 8,
      "name": "Empty",
      "level": 0
    },
    {
      "x": -16,
      "y": 9,
      "z": 8,
      "name": "Empty",
      "level": 0
    },
    {
      "x": -15,
      "y": 1,
      "z": -1,
      "name": "Empty",
      "level": 0
    },
    {
      "x": -15,
      "y": 1,
      "z": 2,
      "name": "Empty",
      "level": 0
    },
    {
      "x": -15,
      "y": 2,
      "z": 2,
      "name": "Empty",
      "level": 0
    },
    {
      "x": -15,
      "y": 3,
      "z": 5,
      "name": "Empty",
      "level": 0
    },
    {
      "x": -15,
      "y": 5,
      "z": 7,
      "name": "Empty",
      "level": 0
    },
    {
      "x": -15,
      "y": 7,
      "z": 8,
      "name": "Empty",
      "level": 0
    },
    {
      "x": -15,
      "y": 9,
      "z": 8,
      "name": "Empty",
      "level": 0
    },
    {
      "x": -14,
      "y": 1,
      "z": -1,
      "name": "Empty",
      "level": 0
    },
    {
      "x": -14,
      "y": 1,
      "z": 2,
      "name": "Empty",
      "level": 0
    },
    {
      "x": -14,
      "y": 3,
      "z": 5,
      "name": "Empty",
      "level": 0
    },
    {
      "x": -14,
      "y": 4,
      "z": 7,
      "name": "Empty",
      "level": 0
    },
    {
      "x": -14,
      "y": 5,
      "z": 7,
      "name": "Empty",
      "level": 0
    },
    {
      "x": -14,
      "y": 7,
      "z": 8,
      "name": "Empty",
      "level": 0
    },
    {
      "x": -14,
      "y": 9,
      "z": 8,
      "name": "Empty",
      "level": 0
    },
    {
      "x": -13,
      "y": 1,
      "z": -1,
      "name": "Empty",
      "level": 0
    },
    {
      "x": -13,
      "y": 1,
      "z": 2,
      "name": "Empty",
      "level": 0
    },
    {
      "x": -13,
      "y": 2,
      "z": 5,
      "name": "Empty",
      "level": 0
    },
    {
      "x": -13,
      "y": 3,
      "z": 5,
      "name": "Empty",
      "level": 0
    },
    {
      "x": -13,
      "y": 4,
      "z": 7,
      "name": "Empty",
      "level": 0
    },
    {
      "x": -13,
      "y": 7,
      "z": 8,
      "name": "Empty",
      "level": 0
    },
    {
      "x": -13,
      "y": 9,
      "z": 8,
      "name": "Empty",
      "level": 0
    },
    {
      "x": -12,
      "y": 1,
      "z": -1,
      "name": "Empty",
      "level": 0
    },
    {
      "x": -12,
      "y": 1,
      "z": 2,
      "name": "Empty",
      "level": 0
    },
    {
      "x": -12,
      "y": 2,
      "z": 5,
      "name": "Empty",
      "level": 0
    },
    {
      "x": -12,
      "y": 4,
      "z": 7,
      "name": "Empty",
      "level": 0
    },
    {
      "x": -12,
      "y": 7,
      "z": 8,
      "name": "Empty",
      "level": 0
    },
    {
      "x": -12,
      "y": 9,
      "z": 8,
      "name": "Empty",
      "level": 0
    },
    {
      "x": -11,
      "y": 1,
      "z": -1,
      "name": "Empty",
      "level": 0
    },
    {
      "x": -11,
      "y": 1,
      "z": 2,
      "name": "Empty",
      "level": 0
    },
    {
      "x": -11,
      "y": 2,
      "z": 5,
      "name": "Empty",
      "level": 0
    },
    {
      "x": -11,
      "y": 4,
      "z": 7,
      "name": "Empty",
      "level": 0
    },
    {
      "x": -11,
      "y": 7,
      "z": 8,
      "name": "Empty",
      "level": 0
    },
    {
      "x": -11,
      "y": 9,
      "z": 8,
      "name": "Empty",
      "level": 0
    },
    {
      "x": -10,
      "y": 1,
      "z": -1,
      "name": "Empty",
      "level": 0
    },
    {
      "x": -10,
      "y": 1,
      "z": 2,
      "name": "Empty",
      "level": 0
    },
    {
      "x": -10,
      "y": 2,
      "z": 5,
      "name": "Empty",
      "level": 0
    },
    {
      "x": -10,
      "y": 4,
      "z": 7,
      "name": "Empty",
      "level": 0
    },
    {
      "x": -10,
      "y": 7,
      "z": 8,
      "name": "Empty",
      "level": 0
    },
    {
      "x": -10,
      "y": 9,
      "z": 8,
      "name": "Empty",
      "level": 0
    },
    {
      "x": -9,
      "y": 1,
      "z": -1,
      "name": "Empty",
      "level": 0
    },
    {
      "x": -9,
      "y": 1,
      "z": 2,
      "name": "Empty",
      "level": 0
    },
    {
      "x": -9,
      "y": 2,
      "z": 5,
      "name": "Empty",
      "level": 0
    },
    {
      "x": -9,
      "y": 4,
      "z": 7,
      "name": "Empty",
      "level": 0
    },
    {
      "x": -9,
      "y": 7,
      "z": 8,
      "name": "Empty",
      "level": 0
    },
    {
      "x": -9,
      "y": 9,
      "z": 8,
      "name": "Empty",
      "level": 0
    },
    {
      "x": -8,
      "y": 1,
      "z": -1,
      "name": "Empty",
      "level": 0
    },
    {
      "x": -8,
      "y": 1,
      "z": 2,
      "name": "Empty",
      "level": 0
    },
    {
      "x": -8,
      "y": 2,
      "z": 5,
      "name": "Empty",
      "level": 0
    },
    {
      "x": -8,
      "y": 4,
      "z": 7,
      "name": "Empty",
      "level": 0
    },
    {
      "x": -8,
      "y": 7,
      "z": 8,
      "name": "Empty",
      "level": 0
    },
    {
      "x": -8,
      "y": 9,
      "z": 8,
      "name": "Empty",
      "level": 0
    },
    {
      "x": -7,
      "y": 1,
      "z": -1,
      "name": "Empty",
      "level": 0
    },
    {
      "x": -7,
      "y": 1,
      "z": 2,
      "name": "Empty",
      "level": 0
    },
    {
      "x": -7,
      "y": 2,
      "z": 5,
      "name": "Empty",
      "level": 0
    },
    {
      "x": -7,
      "y": 4,
      "z": 7,
      "name": "Empty",
      "level": 0
    },
    {
      "x": -7,
      "y": 7,
      "z": 8,
      "name": "Empty",
      "level": 0
    },
    {
      "x": -7,
      "y": 9,
      "z": 8,
      "name": "Empty",
      "level": 0
    },
    {
      "x": -6,
      "y": 1,
      "z": -1,
      "name": "Empty",
      "level": 0
    },
    {
      "x": -6,
      "y": 1,
      "z": 2,
      "name": "Empty",
      "level": 0
    },
    {
      "x": -6,
      "y": 2,
      "z": 5,
      "name": "Empty",
      "level": 0
    },
    {
      "x": -6,
      "y": 4,
      "z": 7,
      "name": "Empty",
      "level": 0
    },
    {
      "x": -6,
      "y": 7,
      "z": 8,
      "name": "Empty",
      "level": 0
    },
    {
      "x": -6,
      "y": 9,
      "z": 8,
      "name": "Empty",
      "level": 0
    },
    {
      "x": -5,
      "y": 1,
      "z": -1,
      "name": "Empty",
      "level": 0
    },
    {
      "x": -5,
      "y": 1,
      "z": 2,
      "name": "Empty",
      "level": 0
    },
    {
      "x": -5,
      "y": 2,
      "z": 5,
      "name": "Empty",
      "level": 0
    },
    {
      "x": -5,
      "y": 4,
      "z": 7,
      "name": "Empty",
      "level": 0
    },
    {
      "x": -5,
      "y": 7,
      "z": 8,
      "name": "Empty",
      "level": 0
    },
    {
      "x": -5,
      "y": 9,
      "z": 8,
      "name": "Empty",
      "level": 0
    },
    {
      "x": -4,
      "y": 1,
      "z": -1,
      "name": "Empty",
      "level": 0
    },
    {
      "x": -4,
      "y": 1,
      "z": 2,
      "name": "Empty",
      "level": 0
    },
    {
      "x": -4,
      "y": 2,
      "z": 5,
      "name": "Empty",
      "level": 0
    },
    {
      "x": -4,
      "y": 4,
      "z": 7,
      "name": "Empty",
      "level": 0
    },
    {
      "x": -4,
      "y": 7,
      "z": 8,
      "name": "Empty",
      "level": 0
    },
    {
      "x": -4,
      "y": 9,
      "z": 8,
      "name": "Empty",
      "level": 0
    },
    {
      "x": -3,
      "y": 1,
      "z": -1,
      "name": "Empty",
      "level": 0
    },
    {
      "x": -3,
      "y": 1,
      "z": 2,
      "name": "Empty",
      "level": 0
    },
    {
      "x": -3,
      "y": 2,
      "z": 5,
      "name": "Empty",
      "level": 0
    },
    {
      "x": -3,
      "y": 4,
      "z": 7,
      "name": "Empty",
      "level": 0
    },
    {
      "x": -3,
      "y": 7,
      "z": 8,
      "name": "Empty",
      "level": 0
    },
    {
      "x": -3,
      "y": 9,
      "z": 8,
      "name": "Empty",
      "level": 0
    },
    {
      "x": -2,
      "y": 1,
      "z": -1,
      "name": "Empty",
      "level": 0
    },
    {
      "x": -2,
      "y": 1,
      "z": 2,
      "name": "Empty",
      "level": 0
    },
    {
      "x": -2,
      "y": 2,
      "z": 5,
      "name": "Empty",
      "level": 0
    },
    {
      "x": -2,
      "y": 4,
      "z": 7,
      "name": "Empty",
      "level": 0
    },
    {
      "x": -2,
      "y": 7,
      "z": 8,
      "name": "Empty",
      "level": 0
    },
    {
      "x": -2,
      "y": 9,
      "z": 8,
      "name": "Empty",
      "level": 0
    },
    {
      "x": -1,
      "y": 1,
      "z": -1,
      "name": "Empty",
      "level": 0
    },
    {
      "x": -1,
      "y": 1,
      "z": 2,
      "name": "Empty",
      "level": 0
    },
    {
      "x": -1,
      "y": 2,
      "z": 5,
      "name": "Empty",
      "level": 0
    },
    {
      "x": -1,
      "y": 4,
      "z": 7,
      "name": "Empty",
      "level": 0
    },
    {
      "x": -1,
      "y": 7,
      "z": 8,
      "name": "Empty",
      "level": 0
    },
    {
      "x": -1,
      "y": 9,
      "z": 8,
      "name": "Empty",
      "level": 0
    },
    {
      "x": 0,
      "y": 1,
      "z": -1,
      "name": "Empty",
      "level": 0
    },
    {
      "x": 0,
      "y": 1,
      "z": 2,
      "name": "Empty",
      "level": 0
    },
    {
      "x": 0,
      "y": 2,
      "z": 5,
      "name": "Empty",
      "level": 0
    },
    {
      "x": 0,
      "y": 4,
      "z": 7,
      "name": "Empty",
      "level": 0
    },
    {
      "x": 0,
      "y": 7,
      "z": 8,
      "name": "Empty",
      "level": 0
    },
    {
      "x": 0,
      "y": 9,
      "z": 8,
      "name": "Empty",
      "level": 0
    },
    {
      "x": 1,
      "y": 1,
      "z": -1,
      "name": "Empty",
      "level": 0
    },
    {
      "x": 1,
      "y": 1,
      "z": 2,
      "name": "Empty",
      "level": 0
    },
    {
      "x": 1,
      "y": 2,
      "z": 5,
      "name": "Empty",
      "level": 0
    },
    {
      "x": 1,
      "y": 4,
      "z": 7,
      "name": "Empty",
      "level": 0
    },
    {
      "x": 1,
      "y": 7,
      "z": 8,
      "name": "Empty",
      "level": 0
    },
    {
      "x": 1,
      "y": 9,
      "z": 8,
      "name": "Empty",
      "level": 0
    },
    {
      "x": 2,
      "y": 1,
      "z": -1,
      "name": "Empty",
      "level": 0
    },
    {
      "x": 2,
      "y": 1,
      "z": 2,
      "name": "Empty",
      "level": 0
    },
    {
      "x": 2,
      "y": 2,
      "z": 5,
      "name": "Empty",
      "level": 0
    },
    {
      "x": 2,
      "y": 4,
      "z": 7,
      "name": "Empty",
      "level": 0
    },
    {
      "x": 2,
      "y": 7,
      "z": 8,
      "name": "Empty",
      "level": 0
    },
    {
      "x": 2,
      "y": 9,
      "z": 8,
      "name": "Empty",
      "level": 0
    },
    {
      "x": 3,
      "y": 1,
      "z": -1,
      "name": "Empty",
      "level": 0
    },
    {
      "x": 3,
      "y": 1,
      "z": 2,
      "name": "Empty",
      "level": 0
    },
    {
      "x": 3,
      "y": 2,
      "z": 5,
      "name": "Empty",
      "level": 0
    },
    {
      "x": 3,
      "y": 4,
      "z": 7,
      "name": "Empty",
      "level": 0
    },
    {
      "x": 3,
      "y": 7,
      "z": 8,
      "name": "Empty",
      "level": 0
    },
    {
      "x": 3,
      "y": 9,
      "z": 8,
      "name": "Empty",
      "level": 0
    },
    {
      "x": 4,
      "y": 1,
      "z": -1,
      "name": "Empty",
      "level": 0
    },
    {
      "x": 4,
      "y": 1,
      "z": 2,
      "name": "Empty",
      "level": 0
    },
    {
      "x": 4,
      "y": 2,
      "z": 5,
      "name": "Empty",
      "level": 0
    },
    {
      "x": 4,
      "y": 4,
      "z": 7,
      "name": "Empty",
      "level": 0
    },
    {
      "x": 4,
      "y": 7,
      "z": 8,
      "name": "Empty",
      "level": 0
    },
    {
      "x": 4,
      "y": 9,
      "z": 8,
      "name": "Empty",
      "level": 0
    },
    {
      "x": 5,
      "y": 1,
      "z": -1,
      "name": "Empty",
      "level": 0
    },
    {
      "x": 5,
      "y": 1,
      "z": 2,
      "name": "Empty",
      "level": 0
    },
    {
      "x": 5,
      "y": 2,
      "z": 5,
      "name": "Empty",
      "level": 0
    },
    {
      "x": 5,
      "y": 4,
      "z": 7,
      "name": "Empty",
      "level": 0
    },
    {
      "x": 5,
      "y": 7,
      "z": 8,
      "name": "Empty",
      "level": 0
    },
    {
      "x": 5,
      "y": 9,
      "z": 8,
      "name": "Empty",
      "level": 0
    },
    {
      "x": 6,
      "y": 1,
      "z": -1,
      "name": "Empty",
      "level": 0
    },
    {
      "x": 6,
      "y": 1,
      "z": 2,
      "name": "Empty",
      "level": 0
    },
    {
      "x": 6,
      "y": 2,
      "z": 5,
      "name": "Empty",
      "level": 0
    },
    {
      "x": 6,
      "y": 4,
      "z": 7,
      "name": "Empty",
      "level": 0
    },
    {
      "x": 6,
      "y": 7,
      "z": 8,
      "name": "Empty",
      "level": 0
    },
    {
      "x": 6,
      "y": 9,
      "z": 8,
      "name": "Empty",
      "level": 0
    },
    {
      "x": 7,
      "y": 1,
      "z": -1,
      "name": "Empty",
      "level": 0
    },
    {
      "x": 7,
      "y": 1,
      "z": 2,
      "name": "Empty",
      "level": 0
    },
    {
      "x": 7,
      "y": 2,
      "z": 5,
      "name": "Empty",
      "level": 0
    },
    {
      "x": 7,
      "y": 4,
      "z": 7,
      "name": "Empty",
      "level": 0
    },
    {
      "x": 7,
      "y": 7,
      "z": 8,
      "name": "Empty",
      "level": 0
    },
    {
      "x": 7,
      "y": 9,
      "z": 8,
      "name": "Empty",
      "level": 0
    },
    {
      "x": 8,
      "y": 1,
      "z": -1,
      "name": "Empty",
      "level": 0
    },
    {
      "x": 8,
      "y": 1,
      "z": 2,
      "name": "Empty",
      "level": 0
    },
    {
      "x": 8,
      "y": 2,
      "z": 5,
      "name": "Empty",
      "level": 0
    },
    {
      "x": 8,
      "y": 4,
      "z": 7,
      "name": "Empty",
      "level": 0
    },
    {
      "x": 8,
      "y": 7,
      "z": 8,
      "name": "Empty",
      "level": 0
    },
    {
      "x": 8,
      "y": 9,
      "z": 8,
      "name": "Empty",
      "level": 0
    },
    {
      "x": 9,
      "y": 1,
      "z": -1,
      "name": "Empty",
      "level": 0
    },
    {
      "x": 9,
      "y": 1,
      "z": 2,
      "name": "Empty",
      "level": 0
    },
    {
      "x": 9,
      "y": 2,
      "z": 5,
      "name": "Empty",
      "level": 0
    },
    {
      "x": 9,
      "y": 4,
      "z": 7,
      "name": "Empty",
      "level": 0
    },
    {
      "x": 9,
      "y": 7,
      "z": 8,
      "name": "Empty",
      "level": 0
    },
    {
      "x": 9,
      "y": 9,
      "z": 8,
      "name": "Empty",
      "level": 0
    },
    {
      "x": 10,
      "y": 1,
      "z": -1,
      "name": "Empty",
      "level": 0
    },
    {
      "x": 10,
      "y": 1,
      "z": 2,
      "name": "Empty",
      "level": 0
    },
    {
      "x": 10,
      "y": 2,
      "z": 5,
      "name": "Empty",
      "level": 0
    },
    {
      "x": 10,
      "y": 4,
      "z": 7,
      "name": "Empty",
      "level": 0
    },
    {
      "x": 10,
      "y": 7,
      "z": 8,
      "name": "Empty",
      "level": 0
    },
    {
      "x": 10,
      "y": 9,
      "z": 8,
      "name": "Empty",
      "level": 0
    },
    {
      "x": 11,
      "y": 0,
      "z": -1,
      "name": "Empty",
      "level": 0
    },
    {
      "x": 11,
      "y": 1,
      "z": -1,
      "name": "Empty",
      "level": 0
    },
    {
      "x": 11,
      "y": 1,
      "z": 2,
      "name": "Empty",
      "level": 0
    },
    {
      "x": 11,
      "y": 2,
      "z": 5,
      "name": "Empty",
      "level": 0
    },
    {
      "x": 11,
      "y": 4,
      "z": 7,
      "name": "Empty",
      "level": 0
    },
    {
      "x": 11,
      "y": 7,
      "z": 8,
      "name": "Empty",
      "level": 0
    },
    {
      "x": 11,
      "y": 9,
      "z": 8,
      "name": "Empty",
      "level": 0
    },
    {
      "x": 12,
      "y": 1,
      "z": -1,
      "name": "Empty",
      "level": 0
    },
    {
      "x": 12,
      "y": 1,
      "z": 2,
      "name": "Empty",
      "level": 0
    },
    {
      "x": 12,
      "y": 2,
      "z": 5,
      "name": "Empty",
      "level": 0
    },
    {
      "x": 12,
      "y": 4,
      "z": 7,
      "name": "Empty",
      "level": 0
    },
    {
      "x": 12,
      "y": 7,
      "z": 8,
      "name": "Empty",
      "level": 0
    },
    {
      "x": 12,
      "y": 9,
      "z": 8,
      "name": "Empty",
      "level": 0
    },
    {
      "x": 13,
      "y": 1,
      "z": -1,
      "name": "Empty",
      "level": 0
    },
    {
      "x": 13,
      "y": 1,
      "z": 2,
      "name": "Empty",
      "level": 0
    },
    {
      "x": 13,
      "y": 2,
      "z": 5,
      "name": "Empty",
      "level": 0
    },
    {
      "x": 13,
      "y": 4,
      "z": 7,
      "name": "Empty",
      "level": 0
    },
    {
      "x": 13,
      "y": 7,
      "z": 8,
      "name": "Empty",
      "level": 0
    },
    {
      "x": 13,
      "y": 9,
      "z": 8,
      "name": "Empty",
      "level": 0
    },
    {
      "x": 14,
      "y": 1,
      "z": -1,
      "name": "Empty",
      "level": 0
    },
    {
      "x": 14,
      "y": 1,
      "z": 2,
      "name": "Empty",
      "level": 0
    },
    {
      "x": 14,
      "y": 2,
      "z": 5,
      "name": "Empty",
      "level": 0
    },
    {
      "x": 14,
      "y": 4,
      "z": 7,
      "name": "Empty",
      "level": 0
    },
    {
      "x": 14,
      "y": 7,
      "z": 8,
      "name": "Empty",
      "level": 0
    },
    {
      "x": 14,
      "y": 9,
      "z": 8,
      "name": "Empty",
      "level": 0
    },
    {
      "x": 15,
      "y": 1,
      "z": -1,
      "name": "Empty",
      "level": 0
    },
    {
      "x": 15,
      "y": 1,
      "z": 2,
      "name": "Empty",
      "level": 0
    },
    {
      "x": 15,
      "y": 2,
      "z": 5,
      "name": "Empty",
      "level": 0
    },
    {
      "x": 15,
      "y": 4,
      "z": 7,
      "name": "Empty",
      "level": 0
    },
    {
      "x": 15,
      "y": 7,
      "z": 8,
      "name": "Empty",
      "level": 0
    },
    {
      "x": 15,
      "y": 9,
      "z": 8,
      "name": "Empty",
      "level": 0
    },
    {
      "x": 16,
      "y": 1,
      "z": -1,
      "name": "Empty",
      "level": 0
    },
    {
      "x": 16,
      "y": 1,
      "z": 2,
      "name": "Empty",
      "level": 0
    },
    {
      "x": 16,
      "y": 2,
      "z": 5,
      "name": "Empty",
      "level": 0
    },
    {
      "x": 16,
      "y": 4,
      "z": 7,
      "name": "Empty",
      "level": 0
    },
    {
      "x": 16,
      "y": 7,
      "z": 8,
      "name": "Empty",
      "level": 0
    },
    {
      "x": 16,
      "y": 9,
      "z": 8,
      "name": "Empty",
      "level": 0
    },
    {
      "x": 17,
      "y": 1,
      "z": -1,
      "name": "Empty",
      "level": 0
    },
    {
      "x": 17,
      "y": 1,
      "z": 2,
      "name": "Empty",
      "level": 0
    },
    {
      "x": 17,
      "y": 2,
      "z": 5,
      "name": "Empty",
      "level": 0
    },
    {
      "x": 17,
      "y": 4,
      "z": 7,
      "name": "Empty",
      "level": 0
    },
    {
      "x": 17,
      "y": 7,
      "z": 8,
      "name": "Empty",
      "level": 0
    },
    {
      "x": 17,
      "y": 9,
      "z": 8,
      "name": "Empty",
      "level": 0
    },
    {
      "x": 17,
      "y": 9,
      "z": 9,
      "name": "Empty",
      "level": 0
    },
    {
      "x": 18,
      "y": 1,
      "z": -1,
      "name": "Empty",
      "level": 0
    },
    {
      "x": 18,
      "y": 1,
      "z": 2,
      "name": "Empty",
      "level": 0
    },
    {
      "x": 18,
      "y": 2,
      "z": 5,
      "name": "Empty",
      "level": 0
    },
    {
      "x": 18,
      "y": 4,
      "z": 7,
      "name": "Empty",
      "level": 0
    },
    {
      "x": 18,
      "y": 7,
      "z": 8,
      "name": "Empty",
      "level": 0
    },
    {
      "x": 18,
      "y": 9,
      "z": 9,
      "name": "Empty",
      "level": 0
    },
    {
      "x": 18,
      "y": 9,
      "z": 10,
      "name": "Empty",
      "level": 0
    },
    {
      "x": 19,
      "y": 1,
      "z": -1,
      "name": "Empty",
      "level": 0
    },
    {
      "x": 19,
      "y": 2,
      "z": -1,
      "name": "Empty",
      "level": 0
    },
    {
      "x": 19,
      "y": 1,
      "z": 0,
      "name": "Empty",
      "level": 0
    },
    {
      "x": 19,
      "y": 1,
      "z": 1,
      "name": "Empty",
      "level": 0
    },
    {
      "x": 19,
      "y": 1,
      "z": 2,
      "name": "Empty",
      "level": 0
    },
    {
      "x": 19,
      "y": 2,
      "z": 2,
      "name": "Empty",
      "level": 0
    },
    {
      "x": 19,
      "y": 2,
      "z": 3,
      "name": "Empty",
      "level": 0
    },
    {
      "x": 19,
      "y": 2,
      "z": 4,
      "name": "Empty",
      "level": 0
    },
    {
      "x": 19,
      "y": 2,
      "z": 5,
      "name": "Empty",
      "level": 0
    },
    {
      "x": 19,
      "y": 3,
      "z": 5,
      "name": "Empty",
      "level": 0
    },
    {
      "x": 19,
      "y": 3,
      "z": 6,
      "name": "Empty",
      "level": 0
    },
    {
      "x": 19,
      "y": 4,
      "z": 6,
      "name": "Empty",
      "level": 0
    },
    {
      "x": 19,
      "y": 4,
      "z": 7,
      "name": "Empty",
      "level": 0
    },
    {
      "x": 19,
      "y": 5,
      "z": 7,
      "name": "Empty",
      "level": 0
    },
    {
      "x": 19,
      "y": 5,
      "z": 8,
      "name": "Empty",
      "level": 0
    },
    {
      "x": 19,
      "y": 6,
      "z": 8,
      "name": "Empty",
      "level": 0
    },
    {
      "x": 19,
      "y": 7,
      "z": 8,
      "name": "Empty",
      "level": 0
    },
    {
      "x": 19,
      "y": 7,
      "z": 9,
      "name": "Empty",
      "level": 0
    },
    {
      "x": 19,
      "y": 8,
      "z": 9,
      "name": "Empty",
      "level": 0
    },
    {
      "x": 19,
      "y": 9,
      "z": 9,
      "name": "Empty",
      "level": 0
    },
    {
      "x": 19,
      "y": 9,
      "z": 10,
      "name": "Empty",
      "level": 0
    },
    {
      "x": 20,
      "y": 2,
      "z": -1,
      "name": "Empty",
      "level": 0
    },
    {
      "x": 20,
      "y": 3,
      "z": -1,
      "name": "Empty",
      "level": 0
    },
    {
      "x": 20,
      "y": 4,
      "z": -1,
      "name": "Empty",
      "level": 0
    },
    {
      "x": 20,
      "y": 5,
      "z": -1,
      "name": "Empty",
      "level": 0
    },
    {
      "x": 20,
      "y": 9,
      "z": 9,
      "name": "Empty",
      "level": 0
    },
    {
      "x": 20,
      "y": 9,
      "z": 10,
      "name": "Empty",
      "level": 0
    },
    {
      "x": 21,
      "y": 5,
      "z": -1,
      "name": "Empty",
      "level": 0
    },
    {
      "x": 21,
      "y": 6,
      "z": -1,
      "name": "Empty",
      "level": 0
    },
    {
      "x": 21,
      "y": 9,
      "z": 9,
      "name": "Empty",
      "level": 0
    },
    {
      "x": 21,
      "y": 9,
      "z": 10,
      "name": "Empty",
      "level": 0
    },
    {
      "x": 22,
      "y": 6,
      "z": -1,
      "name": "Empty",
      "level": 0
    },
    {
      "x": 22,
      "y": 7,
      "z": -1,
      "name": "Empty",
      "level": 0
    },
    {
      "x": 22,
      "y": 9,
      "z": 9,
      "name": "Empty",
      "level": 0
    },
    {
      "x": 22,
      "y": 9,
      "z": 10,
      "name": "Empty",
      "level": 0
    },
    {
      "x": 23,
      "y": 7,
      "z": -1,
      "name": "Empty",
      "level": 0
    },
    {
      "x": 23,
      "y": 9,
      "z": 9,
      "name": "Empty",
      "level": 0
    },
    {
      "x": 23,
      "y": 9,
      "z": 10,
      "name": "Empty",
      "level": 0
    },
    {
      "x": 24,
      "y": 7,
      "z": -1,
      "name": "Empty",
      "level": 0
    },
    {
      "x": 24,
      "y": 9,
      "z": 9,
      "name": "Empty",
      "level": 0
    },
    {
      "x": 24,
      "y": 9,
      "z": 10,
      "name": "Empty",
      "level": 0
    },
    {
      "x": 25,
      "y": 7,
      "z": -1,
      "name": "Empty",
      "level": 0
    },
    {
      "x": 25,
      "y": 8,
      "z": -1,
      "name": "Empty",
      "level": 0
    },
    {
      "x": 25,
      "y": 9,
      "z": 9,
      "name": "Empty",
      "level": 0
    },
    {
      "x": 25,
      "y": 9,
      "z": 10,
      "name": "Empty",
      "level": 0
    },
    {
      "x": 26,
      "y": 8,
      "z": -1,
      "name": "Empty",
      "level": 0
    },
    {
      "x": 26,
      "y": 9,
      "z": 9,
      "name": "Empty",
      "level": 0
    },
    {
      "x": 26,
      "y": 9,
      "z": 10,
      "name": "Empty",
      "level": 0
    },
    {
      "x": 27,
      "y": 8,
      "z": -1,
      "name": "Empty",
      "level": 0
    },
    {
      "x": 27,
      "y": 9,
      "z": 9,
      "name": "Empty",
      "level": 0
    },
    {
      "x": 27,
      "y": 9,
      "z": 10,
      "name": "Empty",
      "level": 0
    },
    {
      "x": 28,
      "y": 8,
      "z": -1,
      "name": "Empty",
      "level": 0
    },
    {
      "x": 28,
      "y": 9,
      "z": -1,
      "name": "Empty",
      "level": 0
    },
    {
      "x": 28,
      "y": 9,
      "z": 9,
      "name": "Empty",
      "level": 0
    },
    {
      "x": 28,
      "y": 9,
      "z": 10,
      "name": "Empty",
      "level": 0
    },
    {
      "x": 29,
      "y": 9,
      "z": -1,
      "name": "Empty",
      "level": 0
    },
    {
      "x": 29,
      "y": 9,
      "z": 9,
      "name": "Empty",
      "level": 0
    },
    {
      "x": 29,
      "y": 9,
      "z": 10,
      "name": "Empty",
      "level": 0
    },
    {
      "x": 30,
      "y": 9,
      "z": -1,
      "name": "Empty",
      "level": 0
    },
    {
      "x": 30,
      "y": 9,
      "z": 8,
      "name": "Empty",
      "level": 0
    },
    {
      "x": 30,
      "y": 9,
      "z": 9,
      "name": "Empty",
      "level": 0
    },
    {
      "x": 31,
      "y": 9,
      "z": -8,
      "name": "Empty",
      "level": 0
    },
    {
      "x": 31,
      "y": 9,
      "z": -7,
      "name": "Empty",
      "level": 0
    },
    {
      "x": 31,
      "y": 9,
      "z": -6,
      "name": "Empty",
      "level": 0
    },
    {
      "x": 31,
      "y": 9,
      "z": -5,
      "name": "Empty",
      "level": 0
    },
    {
      "x": 31,
      "y": 9,
      "z": -4,
      "name": "Empty",
      "level": 0
    },
    {
      "x": 31,
      "y": 9,
      "z": -3,
      "name": "Empty",
      "level": 0
    },
    {
      "x": 31,
      "y": 9,
      "z": -2,
      "name": "Empty",
      "level": 0
    },
    {
      "x": 31,
      "y": 9,
      "z": -1,
      "name": "Empty",
      "level": 0
    },
    {
      "x": 31,
      "y": 10,
      "z": -1,
      "name": "Empty",
      "level": 0
    },
    {
      "x": 31,
      "y": 11,
      "z": -1,
      "name": "Empty",
      "level": 0
    },
    {
      "x": 31,
      "y": 12,
      "z": -1,
      "name": "Empty",
      "level": 0
    },
    {
      "x": 31,
      "y": 13,
      "z": -1,
      "name": "Empty",
      "level": 0
    },
    {
      "x": 31,
      "y": 9,
      "z": 0,
      "name": "Empty",
      "level": 0
    },
    {
      "x": 31,
      "y": 9,
      "z": 1,
      "name": "Empty",
      "level": 0
    },
    {
      "x": 31,
      "y": 9,
      "z": 2,
      "name": "Empty",
      "level": 0
    },
    {
      "x": 31,
      "y": 9,
      "z": 3,
      "name": "Empty",
      "level": 0
    },
    {
      "x": 31,
      "y": 9,
      "z": 4,
      "name": "Empty",
      "level": 0
    },
    {
      "x": 31,
      "y": 9,
      "z": 5,
      "name": "Empty",
      "level": 0
    },
    {
      "x": 31,
      "y": 9,
      "z": 6,
      "name": "Empty",
      "level": 0
    },
    {
      "x": 31,
      "y": 9,
      "z": 7,
      "name": "Empty",
      "level": 0
    },
    {
      "x": 31,
      "y": 9,
      "z": 8,
      "name": "Empty",
      "level": 0
    },
    {
      "x": 32,
      "y": 13,
      "z": -1,
      "name": "Empty",
      "level": 0
    },
    {
      "x": 32,
      "y": 14,
      "z": -1,
      "name": "Empty",
      "level": 0
    },
    {
      "x": 32,
      "y": 15,
      "z": -1,
      "name": "Empty",
      "level": 0
    },
    {
      "x": 32,
      "y": 16,
      "z": -1,
      "name": "Empty",
      "level": 0
    }
  ]
}