{
  "version": 8,
  "blockIdVersion": 11,
  "anchorX": 0,
  "anchorY": 8,
  "anchorZ": -1,
  "blocks": [
    {
      "x": -12,
      "y": 8,
      "z": -6,
      "name": "Rock_Ice"
    },
    {
      "x": -12,
      "y": 9,
      "z": -6,
      "name": "Rock_Ice"
    },
    {
      "x": -12,
      "y": 10,
      "z": -6,
      "name": "Rock_Ice"
    },
    {
      "x": -12,
      "y": 11,
      "z": -6,
      "name": "Rock_Ice"
    },
    {
      "x": -12,
      "y": 12,
      "z": -6,
      "name": "Rock_Ice"
    },
    {
      "x": -12,
      "y": 13,
      "z": -6,
      "name": "Rock_Ice"
    },
    {
      "x": -12,
      "y": 14,
      "z": -6,
      "name": "Rock_Ice"
    },
    {
      "x": -12,
      "y": 7,
      "z": -5,
      "name": "Rock_Ice"
    },
    {
      "x": -12,
      "y": 8,
      "z": -5,
      "name": "Rock_Ice"
    },
    {
      "x": -12,
      "y": 9,
      "z": -5,
      "name": "Rock_Ice"
    },
    {
      "x": -12,
      "y": 10,
      "z": -5,
      "name": "Rock_Ice"
    },
    {
      "x": -12,
      "y": 11,
      "z": -5,
      "name": "Rock_Ice"
    },
    {
      "x": -12,
      "y": 12,
      "z": -5,
      "name": "Rock_Ice"
    },
    {
      "x": -12,
      "y": 13,
      "z": -5,
      "name": "Rock_Ice"
    },
    {
      "x": -12,
      "y": 14,
      "z": -5,
      "name": "Rock_Ice"
    },
    {
      "x": -12,
      "y": 15,
      "z": -5,
      "name": "Rock_Ice"
    },
    {
      "x": -12,
      "y": 16,
      "z": -5,
      "name": "Soil_Snow"
    },
    {
      "x": -12,
      "y": 6,
      "z": -4,
      "name": "Rock_Ice"
    },
    {
      "x": -12,
      "y": 7,
      "z": -4,
      "name": "Rock_Ice"
    },
    {
      "x": -12,
      "y": 8,
      "z": -4,
      "name": "Rock_Ice"
    },
    {
      "x": -12,
      "y": 9,
      "z": -4,
      "name": "Rock_Ice"
    },
    {
      "x": -12,
      "y": 10,
      "z": -4,
      "name": "Rock_Ice"
    },
    {
      "x": -12,
      "y": 11,
      "z": -4,
      "name": "Rock_Ice"
    },
    {
      "x": -12,
      "y": 12,
      "z": -4,
      "name": "Rock_Ice"
    },
    {
      "x": -12,
      "y": 13,
      "z": -4,
      "name": "Rock_Ice"
    },
    {
      "x": -12,
      "y": 14,
      "z": -4,
      "name": "Rock_Ice"
    },
    {
      "x": -12,
      "y": 15,
      "z": -4,
      "name": "Rock_Ice"
    },
    {
      "x": -12,
      "y": 16,
      "z": -4,
      "name": "Soil_Snow"
    },
    {
      "x": -12,
      "y": 6,
      "z": -3,
      "name": "Rock_Ice"
    },
    {
      "x": -12,
      "y": 7,
      "z": -3,
      "name": "Rock_Ice"
    },
    {
      "x": -12,
      "y": 8,
      "z": -3,
      "name": "Rock_Ice"
    },
    {
      "x": -12,
      "y": 9,
      "z": -3,
      "name": "Rock_Ice"
    },
    {
      "x": -12,
      "y": 10,
      "z": -3,
      "name": "Rock_Ice"
    },
    {
      "x": -12,
      "y": 11,
      "z": -3,
      "name": "Rock_Ice"
    },
    {
      "x": -12,
      "y": 12,
      "z": -3,
      "name": "Rock_Ice"
    },
    {
      "x": -12,
      "y": 13,
      "z": -3,
      "name": "Rock_Ice"
    },
    {
      "x": -12,
      "y": 14,
      "z": -3,
      "name": "Rock_Ice"
    },
    {
      "x": -12,
      "y": 15,
      "z": -3,
      "name": "Soil_Snow"
    },
    {
      "x": -12,
      "y": 5,
      "z": -2,
      "name": "Rock_Ice"
    },
    {
      "x": -12,
      "y": 6,
      "z": -2,
      "name": "Rock_Ice"
    },
    {
      "x": -12,
      "y": 7,
      "z": -2,
      "name": "Rock_Ice"
    },
    {
      "x": -12,
      "y": 8,
      "z": -2,
      "name": "Rock_Ice"
    },
    {
      "x": -12,
      "y": 9,
      "z": -2,
      "name": "Rock_Ice"
    },
    {
      "x": -12,
      "y": 10,
      "z": -2,
      "name": "Rock_Ice"
    },
    {
      "x": -12,
      "y": 11,
      "z": -2,
      "name": "Rock_Ice"
    },
    {
      "x": -12,
      "y": 12,
      "z": -2,
      "name": "Rock_Ice"
    },
    {
      "x": -12,
      "y": 13,
      "z": -2,
      "name": "Rock_Ice"
    },
    {
      "x": -12,
      "y": 14,
      "z": -2,
      "name": "Soil_Snow"
    },
    {
      "x": -12,
      "y": 6,
      "z": -1,
      "name": "Rock_Ice"
    },
    {
      "x": -12,
      "y": 7,
      "z": -1,
      "name": "Rock_Ice"
    },
    {
      "x": -12,
      "y": 8,
      "z": -1,
      "name": "Rock_Ice"
    },
    {
      "x": -12,
      "y": 9,
      "z": -1,
      "name": "Rock_Ice"
    },
    {
      "x": -12,
      "y": 10,
      "z": -1,
      "name": "Rock_Ice"
    },
    {
      "x": -12,
      "y": 11,
      "z": -1,
      "name": "Rock_Ice"
    },
    {
      "x": -12,
      "y": 12,
      "z": -1,
      "name": "Soil_Snow"
    },
    {
      "x": -12,
      "y": 7,
      "z": 0,
      "name": "Rock_Ice"
    },
    {
      "x": -12,
      "y": 8,
      "z": 0,
      "name": "Rock_Ice"
    },
    {
      "x": -12,
      "y": 9,
      "z": 0,
      "name": "Rock_Ice"
    },
    {
      "x": -12,
      "y": 10,
      "z": 0,
      "name": "Rock_Ice"
    },
    {
      "x": -12,
      "y": 11,
      "z": 0,
      "name": "Soil_Snow"
    },
    {
      "x": -12,
      "y": 8,
      "z": 1,
      "name": "Rock_Ice"
    },
    {
      "x": -12,
      "y": 9,
      "z": 1,
      "name": "Soil_Snow"
    },
    {
      "x": -11,
      "y": 9,
      "z": -8,
      "name": "Rock_Ice"
    },
    {
      "x": -11,
      "y": 7,
      "z": -7,
      "name": "Rock_Ice"
    },
    {
      "x": -11,
      "y": 8,
      "z": -7,
      "name": "Rock_Ice"
    },
    {
      "x": -11,
      "y": 9,
      "z": -7,
      "name": "Rock_Ice"
    },
    {
      "x": -11,
      "y": 10,
      "z": -7,
      "name": "Rock_Ice"
    },
    {
      "x": -11,
      "y": 11,
      "z": -7,
      "name": "Rock_Ice"
    },
    {
      "x": -11,
      "y": 12,
      "z": -7,
      "name": "Rock_Ice"
    },
    {
      "x": -11,
      "y": 13,
      "z": -7,
      "name": "Rock_Ice"
    },
    {
      "x": -11,
      "y": 14,
      "z": -7,
      "name": "Rock_Ice"
    },
    {
      "x": -11,
      "y": 15,
      "z": -7,
      "name": "Rock_Ice"
    },
    {
      "x": -11,
      "y": 16,
      "z": -7,
      "name": "Rock_Ice"
    },
    {
      "x": -11,
      "y": 17,
      "z": -7,
      "name": "Rock_Ice"
    },
    {
      "x": -11,
      "y": 18,
      "z": -7,
      "name": "Rock_Ice"
    },
    {
      "x": -11,
      "y": 19,
      "z": -7,
      "name": "Soil_Snow"
    },
    {
      "x": -11,
      "y": 6,
      "z": -6,
      "name": "Rock_Ice"
    },
    {
      "x": -11,
      "y": 7,
      "z": -6,
      "name": "Rock_Ice"
    },
    {
      "x": -11,
      "y": 8,
      "z": -6,
      "name": "Rock_Ice"
    },
    {
      "x": -11,
      "y": 9,
      "z": -6,
      "name": "Rock_Ice"
    },
    {
      "x": -11,
      "y": 10,
      "z": -6,
      "name": "Rock_Ice"
    },
    {
      "x": -11,
      "y": 11,
      "z": -6,
      "name": "Rock_Ice"
    },
    {
      "x": -11,
      "y": 12,
      "z": -6,
      "name": "Rock_Ice"
    },
    {
      "x": -11,
      "y": 13,
      "z": -6,
      "name": "Rock_Ice"
    },
    {
      "x": -11,
      "y": 14,
      "z": -6,
      "name": "Rock_Ice"
    },
    {
      "x": -11,
      "y": 15,
      "z": -6,
      "name": "Rock_Ice"
    },
    {
      "x": -11,
      "y": 16,
      "z": -6,
      "name": "Rock_Ice"
    },
    {
      "x": -11,
      "y": 17,
      "z": -6,
      "name": "Rock_Ice"
    },
    {
      "x": -11,
      "y": 18,
      "z": -6,
      "name": "Rock_Ice"
    },
    {
      "x": -11,
      "y": 19,
      "z": -6,
      "name": "Soil_Snow"
    },
    {
      "x": -11,
      "y": 5,
      "z": -5,
      "name": "Rock_Ice"
    },
    {
      "x": -11,
      "y": 6,
      "z": -5,
      "name": "Rock_Ice"
    },
    {
      "x": -11,
      "y": 7,
      "z": -5,
      "name": "Rock_Ice"
    },
    {
      "x": -11,
      "y": 8,
      "z": -5,
      "name": "Rock_Ice"
    },
    {
      "x": -11,
      "y": 9,
      "z": -5,
      "name": "Rock_Ice"
    },
    {
      "x": -11,
      "y": 10,
      "z": -5,
      "name": "Rock_Ice"
    },
    {
      "x": -11,
      "y": 11,
      "z": -5,
      "name": "Rock_Ice"
    },
    {
      "x": -11,
      "y": 12,
      "z": -5,
      "name": "Rock_Ice"
    },
    {
      "x": -11,
      "y": 13,
      "z": -5,
      "name": "Rock_Ice"
    },
    {
      "x": -11,
      "y": 14,
      "z": -5,
      "name": "Rock_Ice"
    },
    {
      "x": -11,
      "y": 15,
      "z": -5,
      "name": "Rock_Ice"
    },
    {
      "x": -11,
      "y": 16,
      "z": -5,
      "name": "Rock_Ice"
    },
    {
      "x": -11,
      "y": 17,
      "z": -5,
      "name": "Rock_Ice"
    },
    {
      "x": -11,
      "y": 18,
      "z": -5,
      "name": "Rock_Ice"
    },
    {
      "x": -11,
      "y": 19,
      "z": -5,
      "name": "Soil_Snow"
    },
    {
      "x": -11,
      "y": 5,
      "z": -4,
      "name": "Rock_Ice"
    },
    {
      "x": -11,
      "y": 6,
      "z": -4,
      "name": "Rock_Ice"
    },
    {
      "x": -11,
      "y": 7,
      "z": -4,
      "name": "Rock_Ice"
    },
    {
      "x": -11,
      "y": 8,
      "z": -4,
      "name": "Rock_Ice"
    },
    {
      "x": -11,
      "y": 9,
      "z": -4,
      "name": "Rock_Ice"
    },
    {
      "x": -11,
      "y": 10,
      "z": -4,
      "name": "Rock_Ice"
    },
    {
      "x": -11,
      "y": 11,
      "z": -4,
      "name": "Rock_Ice"
    },
    {
      "x": -11,
      "y": 12,
      "z": -4,
      "name": "Rock_Ice"
    },
    {
      "x": -11,
      "y": 13,
      "z": -4,
      "name": "Rock_Ice"
    },
    {
      "x": -11,
      "y": 14,
      "z": -4,
      "name": "Rock_Ice"
    },
    {
      "x": -11,
      "y": 15,
      "z": -4,
      "name": "Rock_Ice"
    },
    {
      "x": -11,
      "y": 16,
      "z": -4,
      "name": "Rock_Ice"
    },
    {
      "x": -11,
      "y": 17,
      "z": -4,
      "name": "Rock_Ice"
    },
    {
      "x": -11,
      "y": 18,
      "z": -4,
      "name": "Soil_Snow"
    },
    {
      "x": -11,
      "y": 5,
      "z": -3,
      "name": "Rock_Ice"
    },
    {
      "x": -11,
      "y": 6,
      "z": -3,
      "name": "Rock_Ice"
    },
    {
      "x": -11,
      "y": 7,
      "z": -3,
      "name": "Rock_Ice"
    },
    {
      "x": -11,
      "y": 8,
      "z": -3,
      "name": "Rock_Ice"
    },
    {
      "x": -11,
      "y": 9,
      "z": -3,
      "name": "Rock_Ice"
    },
    {
      "x": -11,
      "y": 10,
      "z": -3,
      "name": "Rock_Ice"
    },
    {
      "x": -11,
      "y": 11,
      "z": -3,
      "name": "Rock_Ice"
    },
    {
      "x": -11,
      "y": 12,
      "z": -3,
      "name": "Rock_Ice"
    },
    {
      "x": -11,
      "y": 13,
      "z": -3,
      "name": "Rock_Ice"
    },
    {
      "x": -11,
      "y": 14,
      "z": -3,
      "name": "Rock_Ice"
    },
    {
      "x": -11,
      "y": 15,
      "z": -3,
      "name": "Rock_Ice"
    },
    {
      "x": -11,
      "y": 16,
      "z": -3,
      "name": "Rock_Ice"
    },
    {
      "x": -11,
      "y": 17,
      "z": -3,
      "name": "Rock_Ice"
    },
    {
      "x": -11,
      "y": 18,
      "z": -3,
      "name": "Soil_Snow"
    },
    {
      "x": -11,
      "y": 5,
      "z": -2,
      "name": "Rock_Ice"
    },
    {
      "x": -11,
      "y": 6,
      "z": -2,
      "name": "Rock_Ice"
    },
    {
      "x": -11,
      "y": 7,
      "z": -2,
      "name": "Rock_Ice"
    },
    {
      "x": -11,
      "y": 8,
      "z": -2,
      "name": "Rock_Ice"
    },
    {
      "x": -11,
      "y": 9,
      "z": -2,
      "name": "Rock_Ice"
    },
    {
      "x": -11,
      "y": 10,
      "z": -2,
      "name": "Rock_Ice"
    },
    {
      "x": -11,
      "y": 11,
      "z": -2,
      "name": "Rock_Ice"
    },
    {
      "x": -11,
      "y": 12,
      "z": -2,
      "name": "Rock_Ice"
    },
    {
      "x": -11,
      "y": 13,
      "z": -2,
      "name": "Rock_Ice"
    },
    {
      "x": -11,
      "y": 14,
      "z": -2,
      "name": "Rock_Ice"
    },
    {
      "x": -11,
      "y": 15,
      "z": -2,
      "name": "Rock_Ice"
    },
    {
      "x": -11,
      "y": 16,
      "z": -2,
      "name": "Rock_Ice"
    },
    {
      "x": -11,
      "y": 17,
      "z": -2,
      "name": "Soil_Snow"
    },
    {
      "x": -11,
      "y": 5,
      "z": -1,
      "name": "Rock_Ice"
    },
    {
      "x": -11,
      "y": 6,
      "z": -1,
      "name": "Rock_Ice"
    },
    {
      "x": -11,
      "y": 7,
      "z": -1,
      "name": "Rock_Ice"
    },
    {
      "x": -11,
      "y": 8,
      "z": -1,
      "name": "Rock_Ice"
    },
    {
      "x": -11,
      "y": 9,
      "z": -1,
      "name": "Rock_Ice"
    },
    {
      "x": -11,
      "y": 10,
      "z": -1,
      "name": "Rock_Ice"
    },
    {
      "x": -11,
      "y": 11,
      "z": -1,
      "name": "Rock_Ice"
    },
    {
      "x": -11,
      "y": 12,
      "z": -1,
      "name": "Rock_Ice"
    },
    {
      "x": -11,
      "y": 13,
      "z": -1,
      "name": "Rock_Ice"
    },
    {
      "x": -11,
      "y": 14,
      "z": -1,
      "name": "Rock_Ice"
    },
    {
      "x": -11,
      "y": 15,
      "z": -1,
      "name": "Rock_Ice"
    },
    {
      "x": -11,
      "y": 16,
      "z": -1,
      "name": "Soil_Snow"
    },
    {
      "x": -11,
      "y": 5,
      "z": 0,
      "name": "Rock_Ice"
    },
    {
      "x": -11,
      "y": 6,
      "z": 0,
      "name": "Rock_Ice"
    },
    {
      "x": -11,
      "y": 7,
      "z": 0,
      "name": "Rock_Ice"
    },
    {
      "x": -11,
      "y": 8,
      "z": 0,
      "name": "Rock_Ice"
    },
    {
      "x": -11,
      "y": 9,
      "z": 0,
      "name": "Rock_Ice"
    },
    {
      "x": -11,
      "y": 10,
      "z": 0,
      "name": "Rock_Ice"
    },
    {
      "x": -11,
      "y": 11,
      "z": 0,
      "name": "Rock_Ice"
    },
    {
      "x": -11,
      "y": 12,
      "z": 0,
      "name": "Rock_Ice"
    },
    {
      "x": -11,
      "y": 13,
      "z": 0,
      "name": "Rock_Ice"
    },
    {
      "x": -11,
      "y": 14,
      "z": 0,
      "name": "Rock_Ice"
    },
    {
      "x": -11,
      "y": 15,
      "z": 0,
      "name": "Soil_Snow"
    },
    {
      "x": -11,
      "y": 5,
      "z": 1,
      "name": "Rock_Ice"
    },
    {
      "x": -11,
      "y": 6,
      "z": 1,
      "name": "Rock_Ice"
    },
    {
      "x": -11,
      "y": 7,
      "z": 1,
      "name": "Rock_Ice"
    },
    {
      "x": -11,
      "y": 8,
      "z": 1,
      "name": "Rock_Ice"
    },
    {
      "x": -11,
      "y": 9,
      "z": 1,
      "name": "Rock_Ice"
    },
    {
      "x": -11,
      "y": 10,
      "z": 1,
      "name": "Rock_Ice"
    },
    {
      "x": -11,
      "y": 11,
      "z": 1,
      "name": "Rock_Ice"
    },
    {
      "x": -11,
      "y": 12,
      "z": 1,
      "name": "Rock_Ice"
    },
    {
      "x": -11,
      "y": 13,
      "z": 1,
      "name": "Rock_Ice"
    },
    {
      "x": -11,
      "y": 14,
      "z": 1,
      "name": "Rock_Ice"
    },
    {
      "x": -11,
      "y": 18,
      "z": 1,
      "name": "Soil_Snow"
    },
    {
      "x": -11,
      "y": 6,
      "z": 2,
      "name": "Rock_Ice"
    },
    {
      "x": -11,
      "y": 7,
      "z": 2,
      "name": "Rock_Ice"
    },
    {
      "x": -11,
      "y": 8,
      "z": 2,
      "name": "Rock_Ice"
    },
    {
      "x": -11,
      "y": 9,
      "z": 2,
      "name": "Rock_Ice"
    },
    {
      "x": -11,
      "y": 10,
      "z": 2,
      "name": "Rock_Ice"
    },
    {
      "x": -11,
      "y": 11,
      "z": 2,
      "name": "Rock_Ice"
    },
    {
      "x": -11,
      "y": 12,
      "z": 2,
      "name": "Rock_Ice"
    },
    {
      "x": -11,
      "y": 16,
      "z": 2,
      "name": "Rock_Ice"
    },
    {
      "x": -11,
      "y": 17,
      "z": 2,
      "name": "Soil_Snow"
    },
    {
      "x": -11,
      "y": 7,
      "z": 3,
      "name": "Rock_Ice"
    },
    {
      "x": -11,
      "y": 8,
      "z": 3,
      "name": "Rock_Ice"
    },
    {
      "x": -11,
      "y": 9,
      "z": 3,
      "name": "Rock_Ice"
    },
    {
      "x": -11,
      "y": 10,
      "z": 3,
      "name": "Rock_Ice"
    },
    {
      "x": -11,
      "y": 14,
      "z": 3,
      "name": "Rock_Ice"
    },
    {
      "x": -11,
      "y": 15,
      "z": 3,
      "name": "Rock_Ice"
    },
    {
      "x": -11,
      "y": 16,
      "z": 3,
      "name": "Rock_Ice"
    },
    {
      "x": -11,
      "y": 17,
      "z": 3,
      "name": "Soil_Snow"
    },
    {
      "x": -11,
      "y": 8,
      "z": 4,
      "name": "Rock_Ice"
    },
    {
      "x": -11,
      "y": 13,
      "z": 4,
      "name": "Rock_Ice"
    },
    {
      "x": -11,
      "y": 14,
      "z": 4,
      "name": "Rock_Ice"
    },
    {
      "x": -11,
      "y": 15,
      "z": 4,
      "name": "Rock_Ice"
    },
    {
      "x": -11,
      "y": 16,
      "z": 4,
      "name": "Rock_Ice"
    },
    {
      "x": -11,
      "y": 17,
      "z": 4,
      "name": "Soil_Snow"
    },
    {
      "x": -11,
      "y": 13,
      "z": 5,
      "name": "Rock_Ice"
    },
    {
      "x": -11,
      "y": 14,
      "z": 5,
      "name": "Rock_Ice"
    },
    {
      "x": -11,
      "y": 15,
      "z": 5,
      "name": "Rock_Ice"
    },
    {
      "x": -11,
      "y": 16,
      "z": 5,
      "name": "Soil_Snow"
    },
    {
      "x": -10,
      "y": 7,
      "z": -8,
      "name": "Rock_Ice"
    },
    {
      "x": -10,
      "y": 8,
      "z": -8,
      "name": "Rock_Ice"
    },
    {
      "x": -10,
      "y": 9,
      "z": -8,
      "name": "Rock_Ice"
    },
    {
      "x": -10,
      "y": 10,
      "z": -8,
      "name": "Rock_Ice"
    },
    {
      "x": -10,
      "y": 11,
      "z": -8,
      "name": "Rock_Ice"
    },
    {
      "x": -10,
      "y": 12,
      "z": -8,
      "name": "Rock_Ice"
    },
    {
      "x": -10,
      "y": 13,
      "z": -8,
      "name": "Rock_Ice"
    },
    {
      "x": -10,
      "y": 14,
      "z": -8,
      "name": "Rock_Ice"
    },
    {
      "x": -10,
      "y": 15,
      "z": -8,
      "name": "Rock_Ice_Permafrost"
    },
    {
      "x": -10,
      "y": 16,
      "z": -8,
      "name": "Rock_Ice_Permafrost"
    },
    {
      "x": -10,
      "y": 17,
      "z": -8,
      "name": "Rock_Ice_Permafrost"
    },
    {
      "x": -10,
      "y": 18,
      "z": -8,
      "name": "Rock_Ice"
    },
    {
      "x": -10,
      "y": 19,
      "z": -8,
      "name": "Soil_Snow"
    },
    {
      "x": -10,
      "y": 6,
      "z": -7,
      "name": "Rock_Ice"
    },
    {
      "x": -10,
      "y": 7,
      "z": -7,
      "name": "Rock_Ice"
    },
    {
      "x": -10,
      "y": 8,
      "z": -7,
      "name": "Rock_Ice"
    },
    {
      "x": -10,
      "y": 9,
      "z": -7,
      "name": "Rock_Ice"
    },
    {
      "x": -10,
      "y": 10,
      "z": -7,
      "name": "Rock_Ice"
    },
    {
      "x": -10,
      "y": 11,
      "z": -7,
      "name": "Rock_Ice"
    },
    {
      "x": -10,
      "y": 12,
      "z": -7,
      "name": "Rock_Ice"
    },
    {
      "x": -10,
      "y": 13,
      "z": -7,
      "name": "Rock_Ice"
    },
    {
      "x": -10,
      "y": 14,
      "z": -7,
      "name": "Rock_Ice"
    },
    {
      "x": -10,
      "y": 15,
      "z": -7,
      "name": "Rock_Ice"
    },
    {
      "x": -10,
      "y": 16,
      "z": -7,
      "name": "Rock_Ice"
    },
    {
      "x": -10,
      "y": 17,
      "z": -7,
      "name": "Rock_Ice_Permafrost"
    },
    {
      "x": -10,
      "y": 18,
      "z": -7,
      "name": "Rock_Ice_Permafrost"
    },
    {
      "x": -10,
      "y": 19,
      "z": -7,
      "name": "Rock_Ice"
    },
    {
      "x": -10,
      "y": 20,
      "z": -7,
      "name": "Soil_Snow"
    },
    {
      "x": -10,
      "y": 5,
      "z": -6,
      "name": "Rock_Ice"
    },
    {
      "x": -10,
      "y": 6,
      "z": -6,
      "name": "Rock_Ice"
    },
    {
      "x": -10,
      "y": 7,
      "z": -6,
      "name": "Rock_Ice"
    },
    {
      "x": -10,
      "y": 8,
      "z": -6,
      "name": "Rock_Ice"
    },
    {
      "x": -10,
      "y": 9,
      "z": -6,
      "name": "Rock_Ice"
    },
    {
      "x": -10,
      "y": 10,
      "z": -6,
      "name": "Rock_Ice"
    },
    {
      "x": -10,
      "y": 11,
      "z": -6,
      "name": "Rock_Ice"
    },
    {
      "x": -10,
      "y": 12,
      "z": -6,
      "name": "Rock_Ice"
    },
    {
      "x": -10,
      "y": 13,
      "z": -6,
      "name": "Rock_Ice"
    },
    {
      "x": -10,
      "y": 14,
      "z": -6,
      "name": "Rock_Ice"
    },
    {
      "x": -10,
      "y": 15,
      "z": -6,
      "name": "Rock_Ice"
    },
    {
      "x": -10,
      "y": 16,
      "z": -6,
      "name": "Rock_Ice"
    },
    {
      "x": -10,
      "y": 17,
      "z": -6,
      "name": "Rock_Ice_Permafrost"
    },
    {
      "x": -10,
      "y": 18,
      "z": -6,
      "name": "Rock_Ice_Permafrost"
    },
    {
      "x": -10,
      "y": 19,
      "z": -6,
      "name": "Rock_Ice_Permafrost"
    },
    {
      "x": -10,
      "y": 20,
      "z": -6,
      "name": "Rock_Ice"
    },
    {
      "x": -10,
      "y": 21,
      "z": -6,
      "name": "Soil_Snow"
    },
    {
      "x": -10,
      "y": 5,
      "z": -5,
      "name": "Rock_Ice"
    },
    {
      "x": -10,
      "y": 6,
      "z": -5,
      "name": "Rock_Ice"
    },
    {
      "x": -10,
      "y": 7,
      "z": -5,
      "name": "Rock_Ice"
    },
    {
      "x": -10,
      "y": 8,
      "z": -5,
      "name": "Rock_Ice"
    },
    {
      "x": -10,
      "y": 9,
      "z": -5,
      "name": "Rock_Ice"
    },
    {
      "x": -10,
      "y": 10,
      "z": -5,
      "name": "Rock_Ice"
    },
    {
      "x": -10,
      "y": 11,
      "z": -5,
      "name": "Rock_Ice"
    },
    {
      "x": -10,
      "y": 12,
      "z": -5,
      "name": "Rock_Ice"
    },
    {
      "x": -10,
      "y": 13,
      "z": -5,
      "name": "Rock_Ice"
    },
    {
      "x": -10,
      "y": 14,
      "z": -5,
      "name": "Rock_Ice"
    },
    {
      "x": -10,
      "y": 15,
      "z": -5,
      "name": "Rock_Ice"
    },
    {
      "x": -10,
      "y": 16,
      "z": -5,
      "name": "Rock_Ice"
    },
    {
      "x": -10,
      "y": 17,
      "z": -5,
      "name": "Rock_Ice"
    },
    {
      "x": -10,
      "y": 18,
      "z": -5,
      "name": "Rock_Ice_Permafrost"
    },
    {
      "x": -10,
      "y": 19,
      "z": -5,
      "name": "Rock_Ice_Permafrost"
    },
    {
      "x": -10,
      "y": 20,
      "z": -5,
      "name": "Rock_Ice"
    },
    {
      "x": -10,
      "y": 21,
      "z": -5,
      "name": "Soil_Snow"
    },
    {
      "x": -10,
      "y": 4,
      "z": -4,
      "name": "Rock_Ice"
    },
    {
      "x": -10,
      "y": 5,
      "z": -4,
      "name": "Rock_Ice"
    },
    {
      "x": -10,
      "y": 6,
      "z": -4,
      "name": "Rock_Ice"
    },
    {
      "x": -10,
      "y": 7,
      "z": -4,
      "name": "Rock_Ice"
    },
    {
      "x": -10,
      "y": 8,
      "z": -4,
      "name": "Rock_Ice"
    },
    {
      "x": -10,
      "y": 9,
      "z": -4,
      "name": "Rock_Ice"
    },
    {
      "x": -10,
      "y": 10,
      "z": -4,
      "name": "Rock_Ice"
    },
    {
      "x": -10,
      "y": 11,
      "z": -4,
      "name": "Rock_Ice"
    },
    {
      "x": -10,
      "y": 12,
      "z": -4,
      "name": "Rock_Ice"
    },
    {
      "x": -10,
      "y": 13,
      "z": -4,
      "name": "Rock_Ice"
    },
    {
      "x": -10,
      "y": 14,
      "z": -4,
      "name": "Rock_Ice"
    },
    {
      "x": -10,
      "y": 15,
      "z": -4,
      "name": "Rock_Ice"
    },
    {
      "x": -10,
      "y": 16,
      "z": -4,
      "name": "Rock_Ice"
    },
    {
      "x": -10,
      "y": 17,
      "z": -4,
      "name": "Rock_Ice"
    },
    {
      "x": -10,
      "y": 18,
      "z": -4,
      "name": "Rock_Ice"
    },
    {
      "x": -10,
      "y": 19,
      "z": -4,
      "name": "Rock_Ice_Permafrost"
    },
    {
      "x": -10,
      "y": 20,
      "z": -4,
      "name": "Rock_Ice"
    },
    {
      "x": -10,
      "y": 21,
      "z": -4,
      "name": "Soil_Snow"
    },
    {
      "x": -10,
      "y": 4,
      "z": -3,
      "name": "Rock_Ice"
    },
    {
      "x": -10,
      "y": 5,
      "z": -3,
      "name": "Rock_Ice"
    },
    {
      "x": -10,
      "y": 6,
      "z": -3,
      "name": "Rock_Ice"
    },
    {
      "x": -10,
      "y": 7,
      "z": -3,
      "name": "Rock_Ice"
    },
    {
      "x": -10,
      "y": 8,
      "z": -3,
      "name": "Rock_Ice"
    },
    {
      "x": -10,
      "y": 9,
      "z": -3,
      "name": "Rock_Ice"
    },
    {
      "x": -10,
      "y": 10,
      "z": -3,
      "name": "Rock_Ice"
    },
    {
      "x": -10,
      "y": 11,
      "z": -3,
      "name": "Rock_Ice"
    },
    {
      "x": -10,
      "y": 12,
      "z": -3,
      "name": "Rock_Ice"
    },
    {
      "x": -10,
      "y": 13,
      "z": -3,
      "name": "Rock_Ice"
    },
    {
      "x": -10,
      "y": 14,
      "z": -3,
      "name": "Rock_Ice"
    },
    {
      "x": -10,
      "y": 15,
      "z": -3,
      "name": "Rock_Ice"
    },
    {
      "x": -10,
      "y": 16,
      "z": -3,
      "name": "Rock_Ice"
    },
    {
      "x": -10,
      "y": 17,
      "z": -3,
      "name": "Rock_Ice"
    },
    {
      "x": -10,
      "y": 18,
      "z": -3,
      "name": "Rock_Ice"
    },
    {
      "x": -10,
      "y": 19,
      "z": -3,
      "name": "Rock_Ice_Permafrost"
    },
    {
      "x": -10,
      "y": 20,
      "z": -3,
      "name": "Rock_Ice"
    },
    {
      "x": -10,
      "y": 21,
      "z": -3,
      "name": "Soil_Snow"
    },
    {
      "x": -10,
      "y": 5,
      "z": -2,
      "name": "Rock_Ice"
    },
    {
      "x": -10,
      "y": 6,
      "z": -2,
      "name": "Rock_Ice"
    },
    {
      "x": -10,
      "y": 7,
      "z": -2,
      "name": "Rock_Ice"
    },
    {
      "x": -10,
      "y": 8,
      "z": -2,
      "name": "Rock_Ice"
    },
    {
      "x": -10,
      "y": 9,
      "z": -2,
      "name": "Rock_Ice"
    },
    {
      "x": -10,
      "y": 10,
      "z": -2,
      "name": "Rock_Ice"
    },
    {
      "x": -10,
      "y": 11,
      "z": -2,
      "name": "Rock_Ice"
    },
    {
      "x": -10,
      "y": 12,
      "z": -2,
      "name": "Rock_Ice"
    },
    {
      "x": -10,
      "y": 13,
      "z": -2,
      "name": "Rock_Ice"
    },
    {
      "x": -10,
      "y": 14,
      "z": -2,
      "name": "Rock_Ice"
    },
    {
      "x": -10,
      "y": 15,
      "z": -2,
      "name": "Rock_Ice"
    },
    {
      "x": -10,
      "y": 16,
      "z": -2,
      "name": "Rock_Ice"
    },
    {
      "x": -10,
      "y": 17,
      "z": -2,
      "name": "Rock_Ice"
    },
    {
      "x": -10,
      "y": 18,
      "z": -2,
      "name": "Rock_Ice"
    },
    {
      "x": -10,
      "y": 19,
      "z": -2,
      "name": "Rock_Ice"
    },
    {
      "x": -10,
      "y": 20,
      "z": -2,
      "name": "Soil_Snow"
    },
    {
      "x": -10,
      "y": 5,
      "z": -1,
      "name": "Rock_Ice"
    },
    {
      "x": -10,
      "y": 6,
      "z": -1,
      "name": "Rock_Ice"
    },
    {
      "x": -10,
      "y": 7,
      "z": -1,
      "name": "Rock_Ice"
    },
    {
      "x": -10,
      "y": 8,
      "z": -1,
      "name": "Rock_Ice"
    },
    {
      "x": -10,
      "y": 9,
      "z": -1,
      "name": "Rock_Ice"
    },
    {
      "x": -10,
      "y": 10,
      "z": -1,
      "name": "Rock_Ice"
    },
    {
      "x": -10,
      "y": 11,
      "z": -1,
      "name": "Rock_Ice"
    },
    {
      "x": -10,
      "y": 12,
      "z": -1,
      "name": "Rock_Ice"
    },
    {
      "x": -10,
      "y": 13,
      "z": -1,
      "name": "Rock_Ice"
    },
    {
      "x": -10,
      "y": 14,
      "z": -1,
      "name": "Rock_Ice"
    },
    {
      "x": -10,
      "y": 15,
      "z": -1,
      "name": "Rock_Ice"
    },
    {
      "x": -10,
      "y": 16,
      "z": -1,
      "name": "Rock_Ice"
    },
    {
      "x": -10,
      "y": 17,
      "z": -1,
      "name": "Rock_Ice"
    },
    {
      "x": -10,
      "y": 18,
      "z": -1,
      "name": "Rock_Ice"
    },
    {
      "x": -10,
      "y": 19,
      "z": -1,
      "name": "Soil_Snow"
    },
    {
      "x": -10,
      "y": 5,
      "z": 0,
      "name": "Rock_Ice"
    },
    {
      "x": -10,
      "y": 6,
      "z": 0,
      "name": "Rock_Ice"
    },
    {
      "x": -10,
      "y": 7,
      "z": 0,
      "name": "Rock_Ice"
    },
    {
      "x": -10,
      "y": 8,
      "z": 0,
      "name": "Rock_Ice"
    },
    {
      "x": -10,
      "y": 9,
      "z": 0,
      "name": "Rock_Ice"
    },
    {
      "x": -10,
      "y": 10,
      "z": 0,
      "name": "Rock_Ice"
    },
    {
      "x": -10,
      "y": 11,
      "z": 0,
      "name": "Rock_Ice"
    },
    {
      "x": -10,
      "y": 12,
      "z": 0,
      "name": "Rock_Ice"
    },
    {
      "x": -10,
      "y": 13,
      "z": 0,
      "name": "Rock_Ice"
    },
    {
      "x": -10,
      "y": 14,
      "z": 0,
      "name": "Rock_Ice"
    },
    {
      "x": -10,
      "y": 15,
      "z": 0,
      "name": "Rock_Ice"
    },
    {
      "x": -10,
      "y": 16,
      "z": 0,
      "name": "Rock_Ice"
    },
    {
      "x": -10,
      "y": 17,
      "z": 0,
      "name": "Rock_Ice"
    },
    {
      "x": -10,
      "y": 18,
      "z": 0,
      "name": "Rock_Ice"
    },
    {
      "x": -10,
      "y": 19,
      "z": 0,
      "name": "Soil_Snow"
    },
    {
      "x": -10,
      "y": 5,
      "z": 1,
      "name": "Rock_Ice"
    },
    {
      "x": -10,
      "y": 6,
      "z": 1,
      "name": "Rock_Ice"
    },
    {
      "x": -10,
      "y": 7,
      "z": 1,
      "name": "Rock_Ice"
    },
    {
      "x": -10,
      "y": 8,
      "z": 1,
      "name": "Rock_Ice"
    },
    {
      "x": -10,
      "y": 9,
      "z": 1,
      "name": "Rock_Ice"
    },
    {
      "x": -10,
      "y": 10,
      "z": 1,
      "name": "Rock_Ice"
    },
    {
      "x": -10,
      "y": 11,
      "z": 1,
      "name": "Rock_Ice"
    },
    {
      "x": -10,
      "y": 12,
      "z": 1,
      "name": "Rock_Ice"
    },
    {
      "x": -10,
      "y": 13,
      "z": 1,
      "name": "Rock_Ice"
    },
    {
      "x": -10,
      "y": 14,
      "z": 1,
      "name": "Rock_Ice"
    },
    {
      "x": -10,
      "y": 15,
      "z": 1,
      "name": "Rock_Ice"
    },
    {
      "x": -10,
      "y": 16,
      "z": 1,
      "name": "Rock_Ice"
    },
    {
      "x": -10,
      "y": 17,
      "z": 1,
      "name": "Rock_Ice"
    },
    {
      "x": -10,
      "y": 18,
      "z": 1,
      "name": "Soil_Snow"
    },
    {
      "x": -10,
      "y": 5,
      "z": 2,
      "name": "Rock_Ice"
    },
    {
      "x": -10,
      "y": 6,
      "z": 2,
      "name": "Rock_Ice"
    },
    {
      "x": -10,
      "y": 7,
      "z": 2,
      "name": "Rock_Ice"
    },
    {
      "x": -10,
      "y": 8,
      "z": 2,
      "name": "Rock_Ice"
    },
    {
      "x": -10,
      "y": 9,
      "z": 2,
      "name": "Rock_Ice"
    },
    {
      "x": -10,
      "y": 10,
      "z": 2,
      "name": "Rock_Ice"
    },
    {
      "x": -10,
      "y": 11,
      "z": 2,
      "name": "Rock_Ice"
    },
    {
      "x": -10,
      "y": 12,
      "z": 2,
      "name": "Rock_Ice"
    },
    {
      "x": -10,
      "y": 13,
      "z": 2,
      "name": "Rock_Ice"
    },
    {
      "x": -10,
      "y": 14,
      "z": 2,
      "name": "Rock_Ice"
    },
    {
      "x": -10,
      "y": 15,
      "z": 2,
      "name": "Rock_Ice"
    },
    {
      "x": -10,
      "y": 16,
      "z": 2,
      "name": "Rock_Ice"
    },
    {
      "x": -10,
      "y": 17,
      "z": 2,
      "name": "Soil_Snow"
    },
    {
      "x": -10,
      "y": 5,
      "z": 3,
      "name": "Rock_Ice"
    },
    {
      "x": -10,
      "y": 6,
      "z": 3,
      "name": "Rock_Ice"
    },
    {
      "x": -10,
      "y": 7,
      "z": 3,
      "name": "Rock_Ice"
    },
    {
      "x": -10,
      "y": 8,
      "z": 3,
      "name": "Rock_Ice"
    },
    {
      "x": -10,
      "y": 9,
      "z": 3,
      "name": "Rock_Ice"
    },
    {
      "x": -10,
      "y": 10,
      "z": 3,
      "name": "Rock_Ice"
    },
    {
      "x": -10,
      "y": 11,
      "z": 3,
      "name": "Rock_Ice"
    },
    {
      "x": -10,
      "y": 12,
      "z": 3,
      "name": "Rock_Ice"
    },
    {
      "x": -10,
      "y": 13,
      "z": 3,
      "name": "Rock_Ice"
    },
    {
      "x": -10,
      "y": 14,
      "z": 3,
      "name": "Rock_Ice"
    },
    {
      "x": -10,
      "y": 15,
      "z": 3,
      "name": "Rock_Ice"
    },
    {
      "x": -10,
      "y": 16,
      "z": 3,
      "name": "Rock_Ice"
    },
    {
      "x": -10,
      "y": 17,
      "z": 3,
      "name": "Rock_Ice"
    },
    {
      "x": -10,
      "y": 18,
      "z": 3,
      "name": "Rock_Ice"
    },
    {
      "x": -10,
      "y": 19,
      "z": 3,
      "name": "Soil_Snow"
    },
    {
      "x": -10,
      "y": 5,
      "z": 4,
      "name": "Rock_Ice"
    },
    {
      "x": -10,
      "y": 6,
      "z": 4,
      "name": "Rock_Ice"
    },
    {
      "x": -10,
      "y": 7,
      "z": 4,
      "name": "Rock_Ice"
    },
    {
      "x": -10,
      "y": 8,
      "z": 4,
      "name": "Rock_Ice"
    },
    {
      "x": -10,
      "y": 9,
      "z": 4,
      "name": "Rock_Ice"
    },
    {
      "x": -10,
      "y": 10,
      "z": 4,
      "name": "Rock_Ice"
    },
    {
      "x": -10,
      "y": 11,
      "z": 4,
      "name": "Rock_Ice"
    },
    {
      "x": -10,
      "y": 12,
      "z": 4,
      "name": "Rock_Ice"
    },
    {
      "x": -10,
      "y": 13,
      "z": 4,
      "name": "Rock_Ice"
    },
    {
      "x": -10,
      "y": 14,
      "z": 4,
      "name": "Rock_Ice"
    },
    {
      "x": -10,
      "y": 15,
      "z": 4,
      "name": "Rock_Ice"
    },
    {
      "x": -10,
      "y": 16,
      "z": 4,
      "name": "Rock_Ice"
    },
    {
      "x": -10,
      "y": 17,
      "z": 4,
      "name": "Rock_Ice"
    },
    {
      "x": -10,
      "y": 18,
      "z": 4,
      "name": "Rock_Ice"
    },
    {
      "x": -10,
      "y": 19,
      "z": 4,
      "name": "Soil_Snow"
    },
    {
      "x": -10,
      "y": 6,
      "z": 5,
      "name": "Rock_Ice"
    },
    {
      "x": -10,
      "y": 7,
      "z": 5,
      "name": "Rock_Ice"
    },
    {
      "x": -10,
      "y": 8,
      "z": 5,
      "name": "Rock_Ice"
    },
    {
      "x": -10,
      "y": 9,
      "z": 5,
      "name": "Rock_Ice"
    },
    {
      "x": -10,
      "y": 10,
      "z": 5,
      "name": "Rock_Ice"
    },
    {
      "x": -10,
      "y": 11,
      "z": 5,
      "name": "Rock_Ice"
    },
    {
      "x": -10,
      "y": 12,
      "z": 5,
      "name": "Rock_Ice"
    },
    {
      "x": -10,
      "y": 14,
      "z": 5,
      "name": "Rock_Ice"
    },
    {
      "x": -10,
      "y": 15,
      "z": 5,
      "name": "Rock_Ice"
    },
    {
      "x": -10,
      "y": 16,
      "z": 5,
      "name": "Rock_Ice"
    },
    {
      "x": -10,
      "y": 17,
      "z": 5,
      "name": "Rock_Ice"
    },
    {
      "x": -10,
      "y": 18,
      "z": 5,
      "name": "Soil_Snow"
    },
    {
      "x": -10,
      "y": 7,
      "z": 6,
      "name": "Rock_Ice"
    },
    {
      "x": -10,
      "y": 8,
      "z": 6,
      "name": "Rock_Ice"
    },
    {
      "x": -10,
      "y": 9,
      "z": 6,
      "name": "Rock_Ice"
    },
    {
      "x": -10,
      "y": 10,
      "z": 6,
      "name": "Rock_Ice"
    },
    {
      "x": -10,
      "y": 13,
      "z": 6,
      "name": "Rock_Ice"
    },
    {
      "x": -10,
      "y": 14,
      "z": 6,
      "name": "Rock_Ice"
    },
    {
      "x": -10,
      "y": 15,
      "z": 6,
      "name": "Rock_Ice"
    },
    {
      "x": -10,
      "y": 16,
      "z": 6,
      "name": "Rock_Ice"
    },
    {
      "x": -10,
      "y": 17,
      "z": 6,
      "name": "Rock_Ice"
    },
    {
      "x": -10,
      "y": 18,
      "z": 6,
      "name": "Soil_Snow"
    },
    {
      "x": -10,
      "y": 12,
      "z": 7,
      "name": "Rock_Ice"
    },
    {
      "x": -10,
      "y": 13,
      "z": 7,
      "name": "Rock_Ice"
    },
    {
      "x": -10,
      "y": 14,
      "z": 7,
      "name": "Rock_Ice"
    },
    {
      "x": -10,
      "y": 15,
      "z": 7,
      "name": "Rock_Ice"
    },
    {
      "x": -10,
      "y": 16,
      "z": 7,
      "name": "Rock_Ice"
    },
    {
      "x": -10,
      "y": 17,
      "z": 7,
      "name": "Soil_Snow"
    },
    {
      "x": -10,
      "y": 12,
      "z": 8,
      "name": "Rock_Ice"
    },
    {
      "x": -10,
      "y": 13,
      "z": 8,
      "name": "Rock_Ice"
    },
    {
      "x": -10,
      "y": 14,
      "z": 8,
      "name": "Rock_Ice"
    },
    {
      "x": -10,
      "y": 15,
      "z": 8,
      "name": "Rock_Ice"
    },
    {
      "x": -10,
      "y": 16,
      "z": 8,
      "name": "Soil_Snow"
    },
    {
      "x": -10,
      "y": 12,
      "z": 9,
      "name": "Rock_Ice"
    },
    {
      "x": -10,
      "y": 13,
      "z": 9,
      "name": "Rock_Ice"
    },
    {
      "x": -10,
      "y": 14,
      "z": 9,
      "name": "Rock_Ice"
    },
    {
      "x": -10,
      "y": 15,
      "z": 9,
      "name": "Rock_Ice"
    },
    {
      "x": -10,
      "y": 16,
      "z": 9,
      "name": "Soil_Snow"
    },
    {
      "x": -10,
      "y": 13,
      "z": 10,
      "name": "Rock_Ice"
    },
    {
      "x": -10,
      "y": 14,
      "z": 10,
      "name": "Rock_Ice"
    },
    {
      "x": -10,
      "y": 15,
      "z": 10,
      "name": "Soil_Snow"
    },
    {
      "x": -9,
      "y": 9,
      "z": -9,
      "name": "Rock_Ice_Permafrost"
    },
    {
      "x": -9,
      "y": 10,
      "z": -9,
      "name": "Rock_Ice_Permafrost"
    },
    {
      "x": -9,
      "y": 11,
      "z": -9,
      "name": "Rock_Ice_Permafrost"
    },
    {
      "x": -9,
      "y": 12,
      "z": -9,
      "name": "Rock_Ice_Permafrost"
    },
    {
      "x": -9,
      "y": 13,
      "z": -9,
      "name": "Rock_Ice_Permafrost"
    },
    {
      "x": -9,
      "y": 14,
      "z": -9,
      "name": "Rock_Ice_Permafrost"
    },
    {
      "x": -9,
      "y": 15,
      "z": -9,
      "name": "Rock_Ice_Permafrost"
    },
    {
      "x": -9,
      "y": 16,
      "z": -9,
      "name": "Rock_Ice_Permafrost"
    },
    {
      "x": -9,
      "y": 17,
      "z": -9,
      "name": "Rock_Ice"
    },
    {
      "x": -9,
      "y": 18,
      "z": -9,
      "name": "Soil_Snow"
    },
    {
      "x": -9,
      "y": 7,
      "z": -8,
      "name": "Rock_Ice"
    },
    {
      "x": -9,
      "y": 8,
      "z": -8,
      "name": "Rock_Ice_Permafrost"
    },
    {
      "x": -9,
      "y": 9,
      "z": -8,
      "name": "Rock_Ice_Permafrost"
    },
    {
      "x": -9,
      "y": 10,
      "z": -8,
      "name": "Rock_Ice_Permafrost"
    },
    {
      "x": -9,
      "y": 11,
      "z": -8,
      "name": "Rock_Ice_Permafrost"
    },
    {
      "x": -9,
      "y": 12,
      "z": -8,
      "name": "Rock_Ice_Permafrost"
    },
    {
      "x": -9,
      "y": 13,
      "z": -8,
      "name": "Rock_Ice"
    },
    {
      "x": -9,
      "y": 14,
      "z": -8,
      "name": "Rock_Ice_Permafrost"
    },
    {
      "x": -9,
      "y": 15,
      "z": -8,
      "name": "Rock_Ice_Permafrost"
    },
    {
      "x": -9,
      "y": 16,
      "z": -8,
      "name": "Rock_Ice_Permafrost"
    },
    {
      "x": -9,
      "y": 17,
      "z": -8,
      "name": "Rock_Ice_Permafrost"
    },
    {
      "x": -9,
      "y": 18,
      "z": -8,
      "name": "Rock_Ice_Permafrost"
    },
    {
      "x": -9,
      "y": 19,
      "z": -8,
      "name": "Rock_Ice"
    },
    {
      "x": -9,
      "y": 20,
      "z": -8,
      "name": "Soil_Snow"
    },
    {
      "x": -9,
      "y": 5,
      "z": -7,
      "name": "Rock_Ice"
    },
    {
      "x": -9,
      "y": 6,
      "z": -7,
      "name": "Rock_Ice"
    },
    {
      "x": -9,
      "y": 7,
      "z": -7,
      "name": "Rock_Ice"
    },
    {
      "x": -9,
      "y": 8,
      "z": -7,
      "name": "Rock_Ice"
    },
    {
      "x": -9,
      "y": 9,
      "z": -7,
      "name": "Rock_Ice"
    },
    {
      "x": -9,
      "y": 10,
      "z": -7,
      "name": "Rock_Ice"
    },
    {
      "x": -9,
      "y": 11,
      "z": -7,
      "name": "Rock_Ice"
    },
    {
      "x": -9,
      "y": 12,
      "z": -7,
      "name": "Rock_Ice"
    },
    {
      "x": -9,
      "y": 13,
      "z": -7,
      "name": "Rock_Ice"
    },
    {
      "x": -9,
      "y": 14,
      "z": -7,
      "name": "Rock_Ice_Permafrost"
    },
    {
      "x": -9,
      "y": 15,
      "z": -7,
      "name": "Rock_Ice_Permafrost"
    },
    {
      "x": -9,
      "y": 16,
      "z": -7,
      "name": "Rock_Ice_Permafrost"
    },
    {
      "x": -9,
      "y": 17,
      "z": -7,
      "name": "Rock_Ice_Permafrost"
    },
    {
      "x": -9,
      "y": 18,
      "z": -7,
      "name": "Rock_Ice_Permafrost"
    },
    {
      "x": -9,
      "y": 19,
      "z": -7,
      "name": "Rock_Ice_Permafrost"
    },
    {
      "x": -9,
      "y": 20,
      "z": -7,
      "name": "Rock_Ice"
    },
    {
      "x": -9,
      "y": 21,
      "z": -7,
      "name": "Soil_Snow"
    },
    {
      "x": -9,
      "y": 4,
      "z": -6,
      "name": "Rock_Ice"
    },
    {
      "x": -9,
      "y": 5,
      "z": -6,
      "name": "Rock_Ice"
    },
    {
      "x": -9,
      "y": 6,
      "z": -6,
      "name": "Rock_Ice"
    },
    {
      "x": -9,
      "y": 7,
      "z": -6,
      "name": "Rock_Ice"
    },
    {
      "x": -9,
      "y": 8,
      "z": -6,
      "name": "Rock_Ice"
    },
    {
      "x": -9,
      "y": 9,
      "z": -6,
      "name": "Rock_Ice"
    },
    {
      "x": -9,
      "y": 10,
      "z": -6,
      "name": "Rock_Ice"
    },
    {
      "x": -9,
      "y": 11,
      "z": -6,
      "name": "Rock_Ice"
    },
    {
      "x": -9,
      "y": 12,
      "z": -6,
      "name": "Rock_Ice"
    },
    {
      "x": -9,
      "y": 13,
      "z": -6,
      "name": "Rock_Ice"
    },
    {
      "x": -9,
      "y": 14,
      "z": -6,
      "name": "Rock_Ice"
    },
    {
      "x": -9,
      "y": 15,
      "z": -6,
      "name": "Rock_Ice_Permafrost"
    },
    {
      "x": -9,
      "y": 16,
      "z": -6,
      "name": "Rock_Ice_Permafrost"
    },
    {
      "x": -9,
      "y": 17,
      "z": -6,
      "name": "Rock_Ice_Permafrost"
    },
    {
      "x": -9,
      "y": 18,
      "z": -6,
      "name": "Rock_Ice_Permafrost"
    },
    {
      "x": -9,
      "y": 19,
      "z": -6,
      "name": "Rock_Ice_Permafrost"
    },
    {
      "x": -9,
      "y": 20,
      "z": -6,
      "name": "Rock_Ice_Permafrost"
    },
    {
      "x": -9,
      "y": 21,
      "z": -6,
      "name": "Rock_Ice"
    },
    {
      "x": -9,
      "y": 22,
      "z": -6,
      "name": "Soil_Snow"
    },
    {
      "x": -9,
      "y": 4,
      "z": -5,
      "name": "Rock_Ice"
    },
    {
      "x": -9,
      "y": 5,
      "z": -5,
      "name": "Rock_Ice"
    },
    {
      "x": -9,
      "y": 6,
      "z": -5,
      "name": "Rock_Ice"
    },
    {
      "x": -9,
      "y": 7,
      "z": -5,
      "name": "Rock_Ice"
    },
    {
      "x": -9,
      "y": 8,
      "z": -5,
      "name": "Rock_Ice"
    },
    {
      "x": -9,
      "y": 9,
      "z": -5,
      "name": "Rock_Ice"
    },
    {
      "x": -9,
      "y": 10,
      "z": -5,
      "name": "Rock_Ice"
    },
    {
      "x": -9,
      "y": 11,
      "z": -5,
      "name": "Rock_Ice"
    },
    {
      "x": -9,
      "y": 12,
      "z": -5,
      "name": "Rock_Ice"
    },
    {
      "x": -9,
      "y": 13,
      "z": -5,
      "name": "Rock_Ice"
    },
    {
      "x": -9,
      "y": 14,
      "z": -5,
      "name": "Rock_Ice"
    },
    {
      "x": -9,
      "y": 15,
      "z": -5,
      "name": "Rock_Ice_Permafrost"
    },
    {
      "x": -9,
      "y": 16,
      "z": -5,
      "name": "Rock_Ice_Permafrost"
    },
    {
      "x": -9,
      "y": 17,
      "z": -5,
      "name": "Rock_Ice_Permafrost"
    },
    {
      "x": -9,
      "y": 18,
      "z": -5,
      "name": "Rock_Ice_Permafrost"
    },
    {
      "x": -9,
      "y": 19,
      "z": -5,
      "name": "Rock_Ice_Permafrost"
    },
    {
      "x": -9,
      "y": 20,
      "z": -5,
      "name": "Rock_Ice_Permafrost"
    },
    {
      "x": -9,
      "y": 21,
      "z": -5,
      "name": "Rock_Ice_Permafrost"
    },
    {
      "x": -9,
      "y": 22,
      "z": -5,
      "name": "Rock_Ice"
    },
    {
      "x": -9,
      "y": 23,
      "z": -5,
      "name": "Soil_Snow"
    },
    {
      "x": -9,
      "y": 4,
      "z": -4,
      "name": "Rock_Ice"
    },
    {
      "x": -9,
      "y": 5,
      "z": -4,
      "name": "Rock_Ice"
    },
    {
      "x": -9,
      "y": 6,
      "z": -4,
      "name": "Rock_Ice"
    },
    {
      "x": -9,
      "y": 7,
      "z": -4,
      "name": "Rock_Ice"
    },
    {
      "x": -9,
      "y": 8,
      "z": -4,
      "name": "Rock_Ice"
    },
    {
      "x": -9,
      "y": 9,
      "z": -4,
      "name": "Rock_Ice"
    },
    {
      "x": -9,
      "y": 10,
      "z": -4,
      "name": "Rock_Ice"
    },
    {
      "x": -9,
      "y": 11,
      "z": -4,
      "name": "Rock_Ice"
    },
    {
      "x": -9,
      "y": 12,
      "z": -4,
      "name": "Rock_Ice"
    },
    {
      "x": -9,
      "y": 13,
      "z": -4,
      "name": "Rock_Ice"
    },
    {
      "x": -9,
      "y": 14,
      "z": -4,
      "name": "Rock_Ice"
    },
    {
      "x": -9,
      "y": 15,
      "z": -4,
      "name": "Rock_Ice"
    },
    {
      "x": -9,
      "y": 16,
      "z": -4,
      "name": "Rock_Ice"
    },
    {
      "x": -9,
      "y": 17,
      "z": -4,
      "name": "Rock_Ice"
    },
    {
      "x": -9,
      "y": 18,
      "z": -4,
      "name": "Rock_Ice_Permafrost"
    },
    {
      "x": -9,
      "y": 19,
      "z": -4,
      "name": "Rock_Ice_Permafrost"
    },
    {
      "x": -9,
      "y": 20,
      "z": -4,
      "name": "Rock_Ice_Permafrost"
    },
    {
      "x": -9,
      "y": 21,
      "z": -4,
      "name": "Rock_Ice_Permafrost"
    },
    {
      "x": -9,
      "y": 22,
      "z": -4,
      "name": "Rock_Ice_Permafrost"
    },
    {
      "x": -9,
      "y": 23,
      "z": -4,
      "name": "Rock_Ice"
    },
    {
      "x": -9,
      "y": 24,
      "z": -4,
      "name": "Soil_Snow"
    },
    {
      "x": -9,
      "y": 4,
      "z": -3,
      "name": "Rock_Ice"
    },
    {
      "x": -9,
      "y": 5,
      "z": -3,
      "name": "Rock_Ice"
    },
    {
      "x": -9,
      "y": 6,
      "z": -3,
      "name": "Rock_Ice"
    },
    {
      "x": -9,
      "y": 7,
      "z": -3,
      "name": "Rock_Ice"
    },
    {
      "x": -9,
      "y": 8,
      "z": -3,
      "name": "Rock_Ice"
    },
    {
      "x": -9,
      "y": 9,
      "z": -3,
      "name": "Rock_Ice"
    },
    {
      "x": -9,
      "y": 10,
      "z": -3,
      "name": "Rock_Ice"
    },
    {
      "x": -9,
      "y": 11,
      "z": -3,
      "name": "Rock_Ice"
    },
    {
      "x": -9,
      "y": 12,
      "z": -3,
      "name": "Rock_Ice"
    },
    {
      "x": -9,
      "y": 13,
      "z": -3,
      "name": "Rock_Ice"
    },
    {
      "x": -9,
      "y": 14,
      "z": -3,
      "name": "Rock_Ice"
    },
    {
      "x": -9,
      "y": 15,
      "z": -3,
      "name": "Rock_Ice"
    },
    {
      "x": -9,
      "y": 16,
      "z": -3,
      "name": "Rock_Ice"
    },
    {
      "x": -9,
      "y": 17,
      "z": -3,
      "name": "Rock_Ice_Permafrost"
    },
    {
      "x": -9,
      "y": 18,
      "z": -3,
      "name": "Rock_Ice_Permafrost"
    },
    {
      "x": -9,
      "y": 19,
      "z": -3,
      "name": "Rock_Ice_Permafrost"
    },
    {
      "x": -9,
      "y": 20,
      "z": -3,
      "name": "Rock_Ice_Permafrost"
    },
    {
      "x": -9,
      "y": 21,
      "z": -3,
      "name": "Rock_Ice_Permafrost"
    },
    {
      "x": -9,
      "y": 22,
      "z": -3,
      "name": "Rock_Ice_Permafrost"
    },
    {
      "x": -9,
      "y": 23,
      "z": -3,
      "name": "Rock_Ice"
    },
    {
      "x": -9,
      "y": 24,
      "z": -3,
      "name": "Soil_Snow"
    },
    {
      "x": -9,
      "y": 4,
      "z": -2,
      "name": "Rock_Ice"
    },
    {
      "x": -9,
      "y": 5,
      "z": -2,
      "name": "Rock_Ice"
    },
    {
      "x": -9,
      "y": 6,
      "z": -2,
      "name": "Rock_Ice"
    },
    {
      "x": -9,
      "y": 7,
      "z": -2,
      "name": "Rock_Ice"
    },
    {
      "x": -9,
      "y": 8,
      "z": -2,
      "name": "Rock_Ice"
    },
    {
      "x": -9,
      "y": 9,
      "z": -2,
      "name": "Rock_Ice"
    },
    {
      "x": -9,
      "y": 10,
      "z": -2,
      "name": "Rock_Ice"
    },
    {
      "x": -9,
      "y": 11,
      "z": -2,
      "name": "Rock_Ice"
    },
    {
      "x": -9,
      "y": 12,
      "z": -2,
      "name": "Rock_Ice"
    },
    {
      "x": -9,
      "y": 13,
      "z": -2,
      "name": "Rock_Ice"
    },
    {
      "x": -9,
      "y": 14,
      "z": -2,
      "name": "Rock_Ice"
    },
    {
      "x": -9,
      "y": 15,
      "z": -2,
      "name": "Rock_Ice"
    },
    {
      "x": -9,
      "y": 16,
      "z": -2,
      "name": "Rock_Ice"
    },
    {
      "x": -9,
      "y": 17,
      "z": -2,
      "name": "Rock_Ice"
    },
    {
      "x": -9,
      "y": 18,
      "z": -2,
      "name": "Rock_Ice_Permafrost"
    },
    {
      "x": -9,
      "y": 19,
      "z": -2,
      "name": "Rock_Ice_Permafrost"
    },
    {
      "x": -9,
      "y": 20,
      "z": -2,
      "name": "Rock_Ice_Permafrost"
    },
    {
      "x": -9,
      "y": 21,
      "z": -2,
      "name": "Rock_Ice_Permafrost"
    },
    {
      "x": -9,
      "y": 22,
      "z": -2,
      "name": "Rock_Ice_Permafrost"
    },
    {
      "x": -9,
      "y": 23,
      "z": -2,
      "name": "Rock_Ice"
    },
    {
      "x": -9,
      "y": 24,
      "z": -2,
      "name": "Soil_Snow"
    },
    {
      "x": -9,
      "y": 5,
      "z": -1,
      "name": "Rock_Ice"
    },
    {
      "x": -9,
      "y": 6,
      "z": -1,
      "name": "Rock_Ice"
    },
    {
      "x": -9,
      "y": 7,
      "z": -1,
      "name": "Rock_Ice"
    },
    {
      "x": -9,
      "y": 8,
      "z": -1,
      "name": "Rock_Ice"
    },
    {
      "x": -9,
      "y": 9,
      "z": -1,
      "name": "Rock_Ice"
    },
    {
      "x": -9,
      "y": 10,
      "z": -1,
      "name": "Rock_Ice"
    },
    {
      "x": -9,
      "y": 11,
      "z": -1,
      "name": "Rock_Ice"
    },
    {
      "x": -9,
      "y": 12,
      "z": -1,
      "name": "Rock_Ice"
    },
    {
      "x": -9,
      "y": 13,
      "z": -1,
      "name": "Rock_Ice"
    },
    {
      "x": -9,
      "y": 14,
      "z": -1,
      "name": "Rock_Ice"
    },
    {
      "x": -9,
      "y": 15,
      "z": -1,
      "name": "Rock_Ice"
    },
    {
      "x": -9,
      "y": 16,
      "z": -1,
      "name": "Rock_Ice"
    },
    {
      "x": -9,
      "y": 17,
      "z": -1,
      "name": "Rock_Ice"
    },
    {
      "x": -9,
      "y": 18,
      "z": -1,
      "name": "Rock_Ice_Permafrost"
    },
    {
      "x": -9,
      "y": 19,
      "z": -1,
      "name": "Rock_Ice_Permafrost"
    },
    {
      "x": -9,
      "y": 20,
      "z": -1,
      "name": "Rock_Ice_Permafrost"
    },
    {
      "x": -9,
      "y": 21,
      "z": -1,
      "name": "Rock_Ice_Permafrost"
    },
    {
      "x": -9,
      "y": 22,
      "z": -1,
      "name": "Rock_Ice"
    },
    {
      "x": -9,
      "y": 23,
      "z": -1,
      "name": "Rock_Ice"
    },
    {
      "x": -9,
      "y": 24,
      "z": -1,
      "name": "Soil_Snow"
    },
    {
      "x": -9,
      "y": 5,
      "z": 0,
      "name": "Rock_Ice"
    },
    {
      "x": -9,
      "y": 6,
      "z": 0,
      "name": "Rock_Ice"
    },
    {
      "x": -9,
      "y": 7,
      "z": 0,
      "name": "Rock_Ice"
    },
    {
      "x": -9,
      "y": 8,
      "z": 0,
      "name": "Rock_Ice"
    },
    {
      "x": -9,
      "y": 9,
      "z": 0,
      "name": "Rock_Ice"
    },
    {
      "x": -9,
      "y": 10,
      "z": 0,
      "name": "Rock_Ice"
    },
    {
      "x": -9,
      "y": 11,
      "z": 0,
      "name": "Rock_Ice"
    },
    {
      "x": -9,
      "y": 12,
      "z": 0,
      "name": "Rock_Ice"
    },
    {
      "x": -9,
      "y": 13,
      "z": 0,
      "name": "Rock_Ice"
    },
    {
      "x": -9,
      "y": 14,
      "z": 0,
      "name": "Rock_Ice"
    },
    {
      "x": -9,
      "y": 15,
      "z": 0,
      "name": "Rock_Ice"
    },
    {
      "x": -9,
      "y": 16,
      "z": 0,
      "name": "Rock_Ice"
    },
    {
      "x": -9,
      "y": 17,
      "z": 0,
      "name": "Rock_Ice"
    },
    {
      "x": -9,
      "y": 18,
      "z": 0,
      "name": "Rock_Ice_Permafrost"
    },
    {
      "x": -9,
      "y": 19,
      "z": 0,
      "name": "Rock_Ice_Permafrost"
    },
    {
      "x": -9,
      "y": 20,
      "z": 0,
      "name": "Rock_Ice_Permafrost"
    },
    {
      "x": -9,
      "y": 21,
      "z": 0,
      "name": "Rock_Ice"
    },
    {
      "x": -9,
      "y": 22,
      "z": 0,
      "name": "Soil_Snow"
    },
    {
      "x": -9,
      "y": 5,
      "z": 1,
      "name": "Rock_Ice"
    },
    {
      "x": -9,
      "y": 6,
      "z": 1,
      "name": "Rock_Ice"
    },
    {
      "x": -9,
      "y": 7,
      "z": 1,
      "name": "Rock_Ice"
    },
    {
      "x": -9,
      "y": 8,
      "z": 1,
      "name": "Rock_Ice"
    },
    {
      "x": -9,
      "y": 9,
      "z": 1,
      "name": "Rock_Ice"
    },
    {
      "x": -9,
      "y": 10,
      "z": 1,
      "name": "Rock_Ice"
    },
    {
      "x": -9,
      "y": 11,
      "z": 1,
      "name": "Rock_Ice"
    },
    {
      "x": -9,
      "y": 12,
      "z": 1,
      "name": "Rock_Ice"
    },
    {
      "x": -9,
      "y": 13,
      "z": 1,
      "name": "Rock_Ice"
    },
    {
      "x": -9,
      "y": 14,
      "z": 1,
      "name": "Rock_Ice"
    },
    {
      "x": -9,
      "y": 15,
      "z": 1,
      "name": "Rock_Ice"
    },
    {
      "x": -9,
      "y": 16,
      "z": 1,
      "name": "Rock_Ice"
    },
    {
      "x": -9,
      "y": 17,
      "z": 1,
      "name": "Rock_Ice"
    },
    {
      "x": -9,
      "y": 18,
      "z": 1,
      "name": "Rock_Ice_Permafrost"
    },
    {
      "x": -9,
      "y": 19,
      "z": 1,
      "name": "Rock_Ice_Permafrost"
    },
    {
      "x": -9,
      "y": 20,
      "z": 1,
      "name": "Rock_Ice"
    },
    {
      "x": -9,
      "y": 21,
      "z": 1,
      "name": "Soil_Snow"
    },
    {
      "x": -9,
      "y": 5,
      "z": 2,
      "name": "Rock_Ice"
    },
    {
      "x": -9,
      "y": 6,
      "z": 2,
      "name": "Rock_Ice"
    },
    {
      "x": -9,
      "y": 7,
      "z": 2,
      "name": "Rock_Ice"
    },
    {
      "x": -9,
      "y": 8,
      "z": 2,
      "name": "Rock_Ice"
    },
    {
      "x": -9,
      "y": 9,
      "z": 2,
      "name": "Rock_Ice"
    },
    {
      "x": -9,
      "y": 10,
      "z": 2,
      "name": "Rock_Ice"
    },
    {
      "x": -9,
      "y": 11,
      "z": 2,
      "name": "Rock_Ice"
    },
    {
      "x": -9,
      "y": 12,
      "z": 2,
      "name": "Rock_Ice"
    },
    {
      "x": -9,
      "y": 13,
      "z": 2,
      "name": "Rock_Ice"
    },
    {
      "x": -9,
      "y": 14,
      "z": 2,
      "name": "Rock_Ice"
    },
    {
      "x": -9,
      "y": 15,
      "z": 2,
      "name": "Rock_Ice"
    },
    {
      "x": -9,
      "y": 16,
      "z": 2,
      "name": "Rock_Ice"
    },
    {
      "x": -9,
      "y": 17,
      "z": 2,
      "name": "Rock_Ice"
    },
    {
      "x": -9,
      "y": 18,
      "z": 2,
      "name": "Rock_Ice"
    },
    {
      "x": -9,
      "y": 19,
      "z": 2,
      "name": "Rock_Ice"
    },
    {
      "x": -9,
      "y": 20,
      "z": 2,
      "name": "Soil_Snow"
    },
    {
      "x": -9,
      "y": 5,
      "z": 3,
      "name": "Rock_Ice"
    },
    {
      "x": -9,
      "y": 6,
      "z": 3,
      "name": "Rock_Ice"
    },
    {
      "x": -9,
      "y": 7,
      "z": 3,
      "name": "Rock_Ice"
    },
    {
      "x": -9,
      "y": 8,
      "z": 3,
      "name": "Rock_Ice"
    },
    {
      "x": -9,
      "y": 9,
      "z": 3,
      "name": "Rock_Ice"
    },
    {
      "x": -9,
      "y": 10,
      "z": 3,
      "name": "Rock_Ice"
    },
    {
      "x": -9,
      "y": 11,
      "z": 3,
      "name": "Rock_Ice"
    },
    {
      "x": -9,
      "y": 12,
      "z": 3,
      "name": "Rock_Ice"
    },
    {
      "x": -9,
      "y": 13,
      "z": 3,
      "name": "Rock_Ice"
    },
    {
      "x": -9,
      "y": 14,
      "z": 3,
      "name": "Rock_Ice"
    },
    {
      "x": -9,
      "y": 15,
      "z": 3,
      "name": "Rock_Ice"
    },
    {
      "x": -9,
      "y": 16,
      "z": 3,
      "name": "Rock_Ice"
    },
    {
      "x": -9,
      "y": 17,
      "z": 3,
      "name": "Rock_Ice"
    },
    {
      "x": -9,
      "y": 18,
      "z": 3,
      "name": "Rock_Ice"
    },
    {
      "x": -9,
      "y": 19,
      "z": 3,
      "name": "Soil_Snow"
    },
    {
      "x": -9,
      "y": 5,
      "z": 4,
      "name": "Rock_Ice"
    },
    {
      "x": -9,
      "y": 6,
      "z": 4,
      "name": "Rock_Ice"
    },
    {
      "x": -9,
      "y": 7,
      "z": 4,
      "name": "Rock_Ice"
    },
    {
      "x": -9,
      "y": 8,
      "z": 4,
      "name": "Rock_Ice"
    },
    {
      "x": -9,
      "y": 9,
      "z": 4,
      "name": "Rock_Ice"
    },
    {
      "x": -9,
      "y": 10,
      "z": 4,
      "name": "Rock_Ice"
    },
    {
      "x": -9,
      "y": 11,
      "z": 4,
      "name": "Rock_Ice"
    },
    {
      "x": -9,
      "y": 12,
      "z": 4,
      "name": "Rock_Ice"
    },
    {
      "x": -9,
      "y": 13,
      "z": 4,
      "name": "Rock_Ice"
    },
    {
      "x": -9,
      "y": 14,
      "z": 4,
      "name": "Rock_Ice"
    },
    {
      "x": -9,
      "y": 15,
      "z": 4,
      "name": "Rock_Ice"
    },
    {
      "x": -9,
      "y": 16,
      "z": 4,
      "name": "Rock_Ice"
    },
    {
      "x": -9,
      "y": 17,
      "z": 4,
      "name": "Rock_Ice"
    },
    {
      "x": -9,
      "y": 18,
      "z": 4,
      "name": "Soil_Snow"
    },
    {
      "x": -9,
      "y": 5,
      "z": 5,
      "name": "Rock_Ice"
    },
    {
      "x": -9,
      "y": 6,
      "z": 5,
      "name": "Rock_Ice"
    },
    {
      "x": -9,
      "y": 7,
      "z": 5,
      "name": "Rock_Ice"
    },
    {
      "x": -9,
      "y": 8,
      "z": 5,
      "name": "Rock_Ice"
    },
    {
      "x": -9,
      "y": 9,
      "z": 5,
      "name": "Rock_Ice"
    },
    {
      "x": -9,
      "y": 10,
      "z": 5,
      "name": "Rock_Ice"
    },
    {
      "x": -9,
      "y": 11,
      "z": 5,
      "name": "Rock_Ice"
    },
    {
      "x": -9,
      "y": 12,
      "z": 5,
      "name": "Rock_Ice"
    },
    {
      "x": -9,
      "y": 13,
      "z": 5,
      "name": "Rock_Ice"
    },
    {
      "x": -9,
      "y": 14,
      "z": 5,
      "name": "Rock_Ice"
    },
    {
      "x": -9,
      "y": 15,
      "z": 5,
      "name": "Rock_Ice"
    },
    {
      "x": -9,
      "y": 16,
      "z": 5,
      "name": "Rock_Ice"
    },
    {
      "x": -9,
      "y": 17,
      "z": 5,
      "name": "Rock_Ice"
    },
    {
      "x": -9,
      "y": 18,
      "z": 5,
      "name": "Rock_Ice"
    },
    {
      "x": -9,
      "y": 19,
      "z": 5,
      "name": "Soil_Snow"
    },
    {
      "x": -9,
      "y": 4,
      "z": 6,
      "name": "Rock_Ice"
    },
    {
      "x": -9,
      "y": 5,
      "z": 6,
      "name": "Rock_Ice"
    },
    {
      "x": -9,
      "y": 6,
      "z": 6,
      "name": "Rock_Ice"
    },
    {
      "x": -9,
      "y": 7,
      "z": 6,
      "name": "Rock_Ice"
    },
    {
      "x": -9,
      "y": 8,
      "z": 6,
      "name": "Rock_Ice"
    },
    {
      "x": -9,
      "y": 9,
      "z": 6,
      "name": "Rock_Ice"
    },
    {
      "x": -9,
      "y": 10,
      "z": 6,
      "name": "Rock_Ice"
    },
    {
      "x": -9,
      "y": 11,
      "z": 6,
      "name": "Rock_Ice"
    },
    {
      "x": -9,
      "y": 12,
      "z": 6,
      "name": "Rock_Ice"
    },
    {
      "x": -9,
      "y": 13,
      "z": 6,
      "name": "Rock_Ice"
    },
    {
      "x": -9,
      "y": 14,
      "z": 6,
      "name": "Rock_Ice"
    },
    {
      "x": -9,
      "y": 15,
      "z": 6,
      "name": "Rock_Ice"
    },
    {
      "x": -9,
      "y": 16,
      "z": 6,
      "name": "Rock_Ice"
    },
    {
      "x": -9,
      "y": 17,
      "z": 6,
      "name": "Rock_Ice"
    },
    {
      "x": -9,
      "y": 18,
      "z": 6,
      "name": "Rock_Ice"
    },
    {
      "x": -9,
      "y": 19,
      "z": 6,
      "name": "Soil_Snow"
    },
    {
      "x": -9,
      "y": 4,
      "z": 7,
      "name": "Rock_Ice"
    },
    {
      "x": -9,
      "y": 5,
      "z": 7,
      "name": "Rock_Ice"
    },
    {
      "x": -9,
      "y": 6,
      "z": 7,
      "name": "Rock_Ice"
    },
    {
      "x": -9,
      "y": 7,
      "z": 7,
      "name": "Rock_Ice"
    },
    {
      "x": -9,
      "y": 8,
      "z": 7,
      "name": "Rock_Ice"
    },
    {
      "x": -9,
      "y": 9,
      "z": 7,
      "name": "Rock_Ice"
    },
    {
      "x": -9,
      "y": 10,
      "z": 7,
      "name": "Rock_Ice"
    },
    {
      "x": -9,
      "y": 11,
      "z": 7,
      "name": "Rock_Ice"
    },
    {
      "x": -9,
      "y": 12,
      "z": 7,
      "name": "Rock_Ice"
    },
    {
      "x": -9,
      "y": 13,
      "z": 7,
      "name": "Rock_Ice"
    },
    {
      "x": -9,
      "y": 14,
      "z": 7,
      "name": "Rock_Ice"
    },
    {
      "x": -9,
      "y": 15,
      "z": 7,
      "name": "Rock_Ice"
    },
    {
      "x": -9,
      "y": 16,
      "z": 7,
      "name": "Rock_Ice"
    },
    {
      "x": -9,
      "y": 17,
      "z": 7,
      "name": "Rock_Ice"
    },
    {
      "x": -9,
      "y": 18,
      "z": 7,
      "name": "Soil_Snow"
    },
    {
      "x": -9,
      "y": 5,
      "z": 8,
      "name": "Rock_Ice"
    },
    {
      "x": -9,
      "y": 6,
      "z": 8,
      "name": "Rock_Ice"
    },
    {
      "x": -9,
      "y": 7,
      "z": 8,
      "name": "Rock_Ice"
    },
    {
      "x": -9,
      "y": 8,
      "z": 8,
      "name": "Rock_Ice"
    },
    {
      "x": -9,
      "y": 9,
      "z": 8,
      "name": "Rock_Ice"
    },
    {
      "x": -9,
      "y": 10,
      "z": 8,
      "name": "Rock_Ice"
    },
    {
      "x": -9,
      "y": 11,
      "z": 8,
      "name": "Rock_Ice"
    },
    {
      "x": -9,
      "y": 12,
      "z": 8,
      "name": "Rock_Ice"
    },
    {
      "x": -9,
      "y": 13,
      "z": 8,
      "name": "Rock_Ice"
    },
    {
      "x": -9,
      "y": 14,
      "z": 8,
      "name": "Rock_Ice"
    },
    {
      "x": -9,
      "y": 15,
      "z": 8,
      "name": "Rock_Ice"
    },
    {
      "x": -9,
      "y": 16,
      "z": 8,
      "name": "Rock_Ice"
    },
    {
      "x": -9,
      "y": 17,
      "z": 8,
      "name": "Rock_Ice"
    },
    {
      "x": -9,
      "y": 18,
      "z": 8,
      "name": "Soil_Snow"
    },
    {
      "x": -9,
      "y": 6,
      "z": 9,
      "name": "Rock_Ice"
    },
    {
      "x": -9,
      "y": 7,
      "z": 9,
      "name": "Rock_Ice"
    },
    {
      "x": -9,
      "y": 8,
      "z": 9,
      "name": "Rock_Ice"
    },
    {
      "x": -9,
      "y": 9,
      "z": 9,
      "name": "Rock_Ice"
    },
    {
      "x": -9,
      "y": 12,
      "z": 9,
      "name": "Rock_Ice"
    },
    {
      "x": -9,
      "y": 13,
      "z": 9,
      "name": "Rock_Ice"
    },
    {
      "x": -9,
      "y": 14,
      "z": 9,
      "name": "Rock_Ice"
    },
    {
      "x": -9,
      "y": 15,
      "z": 9,
      "name": "Rock_Ice"
    },
    {
      "x": -9,
      "y": 16,
      "z": 9,
      "name": "Rock_Ice"
    },
    {
      "x": -9,
      "y": 17,
      "z": 9,
      "name": "Soil_Snow"
    },
    {
      "x": -9,
      "y": 12,
      "z": 10,
      "name": "Rock_Ice"
    },
    {
      "x": -9,
      "y": 13,
      "z": 10,
      "name": "Rock_Ice"
    },
    {
      "x": -9,
      "y": 14,
      "z": 10,
      "name": "Rock_Ice"
    },
    {
      "x": -9,
      "y": 15,
      "z": 10,
      "name": "Rock_Ice"
    },
    {
      "x": -9,
      "y": 16,
      "z": 10,
      "name": "Soil_Snow"
    },
    {
      "x": -9,
      "y": 12,
      "z": 11,
      "name": "Rock_Ice"
    },
    {
      "x": -9,
      "y": 13,
      "z": 11,
      "name": "Rock_Ice"
    },
    {
      "x": -9,
      "y": 14,
      "z": 11,
      "name": "Rock_Ice"
    },
    {
      "x": -9,
      "y": 15,
      "z": 11,
      "name": "Rock_Ice"
    },
    {
      "x": -9,
      "y": 16,
      "z": 11,
      "name": "Soil_Snow"
    },
    {
      "x": -9,
      "y": 12,
      "z": 12,
      "name": "Rock_Ice"
    },
    {
      "x": -9,
      "y": 13,
      "z": 12,
      "name": "Rock_Ice"
    },
    {
      "x": -9,
      "y": 14,
      "z": 12,
      "name": "Rock_Ice"
    },
    {
      "x": -9,
      "y": 15,
      "z": 12,
      "name": "Soil_Snow"
    },
    {
      "x": -8,
      "y": 8,
      "z": -9,
      "name": "Rock_Ice_Permafrost"
    },
    {
      "x": -8,
      "y": 9,
      "z": -9,
      "name": "Rock_Ice_Permafrost"
    },
    {
      "x": -8,
      "y": 10,
      "z": -9,
      "name": "Rock_Ice_Permafrost"
    },
    {
      "x": -8,
      "y": 11,
      "z": -9,
      "name": "Rock_Ice_Permafrost"
    },
    {
      "x": -8,
      "y": 12,
      "z": -9,
      "name": "Rock_Ice_Permafrost"
    },
    {
      "x": -8,
      "y": 13,
      "z": -9,
      "name": "Rock_Ice_Permafrost"
    },
    {
      "x": -8,
      "y": 14,
      "z": -9,
      "name": "Rock_Ice_Permafrost"
    },
    {
      "x": -8,
      "y": 15,
      "z": -9,
      "name": "Rock_Ice_Permafrost"
    },
    {
      "x": -8,
      "y": 16,
      "z": -9,
      "name": "Rock_Ice_Permafrost"
    },
    {
      "x": -8,
      "y": 17,
      "z": -9,
      "name": "Rock_Ice_Permafrost"
    },
    {
      "x": -8,
      "y": 18,
      "z": -9,
      "name": "Rock_Ice"
    },
    {
      "x": -8,
      "y": 19,
      "z": -9,
      "name": "Soil_Snow"
    },
    {
      "x": -8,
      "y": 6,
      "z": -8,
      "name": "Rock_Ice_Permafrost"
    },
    {
      "x": -8,
      "y": 7,
      "z": -8,
      "name": "Rock_Ice_Permafrost"
    },
    {
      "x": -8,
      "y": 8,
      "z": -8,
      "name": "Rock_Ice_Permafrost"
    },
    {
      "x": -8,
      "y": 9,
      "z": -8,
      "name": "Rock_Ice_Permafrost"
    },
    {
      "x": -8,
      "y": 10,
      "z": -8,
      "name": "Rock_Ice_Permafrost"
    },
    {
      "x": -8,
      "y": 11,
      "z": -8,
      "name": "Rock_Ice_Permafrost"
    },
    {
      "x": -8,
      "y": 12,
      "z": -8,
      "name": "Rock_Ice_Permafrost"
    },
    {
      "x": -8,
      "y": 13,
      "z": -8,
      "name": "Rock_Ice_Permafrost"
    },
    {
      "x": -8,
      "y": 14,
      "z": -8,
      "name": "Rock_Ice_Permafrost"
    },
    {
      "x": -8,
      "y": 15,
      "z": -8,
      "name": "Rock_Ice_Permafrost"
    },
    {
      "x": -8,
      "y": 16,
      "z": -8,
      "name": "Rock_Ice_Permafrost"
    },
    {
      "x": -8,
      "y": 17,
      "z": -8,
      "name": "Rock_Ice_Permafrost"
    },
    {
      "x": -8,
      "y": 18,
      "z": -8,
      "name": "Rock_Ice"
    },
    {
      "x": -8,
      "y": 19,
      "z": -8,
      "name": "Rock_Ice"
    },
    {
      "x": -8,
      "y": 20,
      "z": -8,
      "name": "Rock_Ice"
    },
    {
      "x": -8,
      "y": 21,
      "z": -8,
      "name": "Rock_Ice"
    },
    {
      "x": -8,
      "y": 22,
      "z": -8,
      "name": "Soil_Snow"
    },
    {
      "x": -8,
      "y": 5,
      "z": -7,
      "name": "Rock_Ice_Permafrost"
    },
    {
      "x": -8,
      "y": 6,
      "z": -7,
      "name": "Rock_Ice"
    },
    {
      "x": -8,
      "y": 7,
      "z": -7,
      "name": "Rock_Ice"
    },
    {
      "x": -8,
      "y": 8,
      "z": -7,
      "name": "Rock_Ice"
    },
    {
      "x": -8,
      "y": 9,
      "z": -7,
      "name": "Rock_Ice_Permafrost"
    },
    {
      "x": -8,
      "y": 10,
      "z": -7,
      "name": "Rock_Ice"
    },
    {
      "x": -8,
      "y": 11,
      "z": -7,
      "name": "Rock_Ice_Permafrost"
    },
    {
      "x": -8,
      "y": 12,
      "z": -7,
      "name": "Rock_Ice_Permafrost"
    },
    {
      "x": -8,
      "y": 13,
      "z": -7,
      "name": "Rock_Ice_Permafrost"
    },
    {
      "x": -8,
      "y": 14,
      "z": -7,
      "name": "Rock_Ice_Permafrost"
    },
    {
      "x": -8,
      "y": 15,
      "z": -7,
      "name": "Rock_Ice_Permafrost"
    },
    {
      "x": -8,
      "y": 16,
      "z": -7,
      "name": "Rock_Ice"
    },
    {
      "x": -8,
      "y": 17,
      "z": -7,
      "name": "Rock_Ice_Permafrost"
    },
    {
      "x": -8,
      "y": 18,
      "z": -7,
      "name": "Rock_Ice"
    },
    {
      "x": -8,
      "y": 19,
      "z": -7,
      "name": "Rock_Ice"
    },
    {
      "x": -8,
      "y": 20,
      "z": -7,
      "name": "Rock_Ice"
    },
    {
      "x": -8,
      "y": 21,
      "z": -7,
      "name": "Rock_Ice"
    },
    {
      "x": -8,
      "y": 22,
      "z": -7,
      "name": "Rock_Ice"
    },
    {
      "x": -8,
      "y": 23,
      "z": -7,
      "name": "Soil_Snow"
    },
    {
      "x": -8,
      "y": 4,
      "z": -6,
      "name": "Rock_Ice"
    },
    {
      "x": -8,
      "y": 5,
      "z": -6,
      "name": "Rock_Ice"
    },
    {
      "x": -8,
      "y": 6,
      "z": -6,
      "name": "Rock_Ice"
    },
    {
      "x": -8,
      "y": 7,
      "z": -6,
      "name": "Rock_Ice"
    },
    {
      "x": -8,
      "y": 8,
      "z": -6,
      "name": "Rock_Ice"
    },
    {
      "x": -8,
      "y": 9,
      "z": -6,
      "name": "Rock_Ice"
    },
    {
      "x": -8,
      "y": 10,
      "z": -6,
      "name": "Rock_Ice"
    },
    {
      "x": -8,
      "y": 11,
      "z": -6,
      "name": "Rock_Ice"
    },
    {
      "x": -8,
      "y": 12,
      "z": -6,
      "name": "Rock_Ice"
    },
    {
      "x": -8,
      "y": 13,
      "z": -6,
      "name": "Rock_Ice_Permafrost"
    },
    {
      "x": -8,
      "y": 14,
      "z": -6,
      "name": "Rock_Ice_Permafrost"
    },
    {
      "x": -8,
      "y": 15,
      "z": -6,
      "name": "Rock_Ice_Permafrost"
    },
    {
      "x": -8,
      "y": 16,
      "z": -6,
      "name": "Rock_Ice_Permafrost"
    },
    {
      "x": -8,
      "y": 17,
      "z": -6,
      "name": "Rock_Ice_Permafrost"
    },
    {
      "x": -8,
      "y": 18,
      "z": -6,
      "name": "Rock_Ice_Permafrost"
    },
    {
      "x": -8,
      "y": 19,
      "z": -6,
      "name": "Rock_Ice_Permafrost"
    },
    {
      "x": -8,
      "y": 20,
      "z": -6,
      "name": "Rock_Ice_Permafrost"
    },
    {
      "x": -8,
      "y": 21,
      "z": -6,
      "name": "Rock_Ice"
    },
    {
      "x": -8,
      "y": 22,
      "z": -6,
      "name": "Rock_Ice"
    },
    {
      "x": -8,
      "y": 23,
      "z": -6,
      "name": "Rock_Ice"
    },
    {
      "x": -8,
      "y": 24,
      "z": -6,
      "name": "Soil_Snow"
    },
    {
      "x": -8,
      "y": 4,
      "z": -5,
      "name": "Rock_Ice"
    },
    {
      "x": -8,
      "y": 5,
      "z": -5,
      "name": "Rock_Ice"
    },
    {
      "x": -8,
      "y": 6,
      "z": -5,
      "name": "Rock_Ice"
    },
    {
      "x": -8,
      "y": 7,
      "z": -5,
      "name": "Rock_Ice"
    },
    {
      "x": -8,
      "y": 8,
      "z": -5,
      "name": "Rock_Ice"
    },
    {
      "x": -8,
      "y": 9,
      "z": -5,
      "name": "Rock_Ice"
    },
    {
      "x": -8,
      "y": 10,
      "z": -5,
      "name": "Rock_Ice"
    },
    {
      "x": -8,
      "y": 11,
      "z": -5,
      "name": "Rock_Ice"
    },
    {
      "x": -8,
      "y": 12,
      "z": -5,
      "name": "Rock_Ice"
    },
    {
      "x": -8,
      "y": 13,
      "z": -5,
      "name": "Rock_Ice"
    },
    {
      "x": -8,
      "y": 14,
      "z": -5,
      "name": "Rock_Ice_Permafrost"
    },
    {
      "x": -8,
      "y": 15,
      "z": -5,
      "name": "Rock_Ice_Permafrost"
    },
    {
      "x": -8,
      "y": 16,
      "z": -5,
      "name": "Rock_Ice_Permafrost"
    },
    {
      "x": -8,
      "y": 17,
      "z": -5,
      "name": "Rock_Ice_Permafrost"
    },
    {
      "x": -8,
      "y": 18,
      "z": -5,
      "name": "Rock_Ice_Permafrost"
    },
    {
      "x": -8,
      "y": 19,
      "z": -5,
      "name": "Rock_Ice_Permafrost"
    },
    {
      "x": -8,
      "y": 20,
      "z": -5,
      "name": "Rock_Ice_Permafrost"
    },
    {
      "x": -8,
      "y": 21,
      "z": -5,
      "name": "Rock_Ice"
    },
    {
      "x": -8,
      "y": 22,
      "z": -5,
      "name": "Rock_Ice"
    },
    {
      "x": -8,
      "y": 23,
      "z": -5,
      "name": "Rock_Ice"
    },
    {
      "x": -8,
      "y": 24,
      "z": -5,
      "name": "Rock_Ice"
    },
    {
      "x": -8,
      "y": 25,
      "z": -5,
      "name": "Soil_Snow"
    },
    {
      "x": -8,
      "y": 3,
      "z": -4,
      "name": "Rock_Ice"
    },
    {
      "x": -8,
      "y": 4,
      "z": -4,
      "name": "Rock_Ice"
    },
    {
      "x": -8,
      "y": 5,
      "z": -4,
      "name": "Rock_Ice"
    },
    {
      "x": -8,
      "y": 6,
      "z": -4,
      "name": "Rock_Ice"
    },
    {
      "x": -8,
      "y": 7,
      "z": -4,
      "name": "Rock_Ice"
    },
    {
      "x": -8,
      "y": 8,
      "z": -4,
      "name": "Rock_Ice"
    },
    {
      "x": -8,
      "y": 9,
      "z": -4,
      "name": "Rock_Ice"
    },
    {
      "x": -8,
      "y": 10,
      "z": -4,
      "name": "Rock_Ice"
    },
    {
      "x": -8,
      "y": 11,
      "z": -4,
      "name": "Rock_Ice"
    },
    {
      "x": -8,
      "y": 12,
      "z": -4,
      "name": "Rock_Ice"
    },
    {
      "x": -8,
      "y": 13,
      "z": -4,
      "name": "Rock_Ice"
    },
    {
      "x": -8,
      "y": 14,
      "z": -4,
      "name": "Rock_Ice_Permafrost"
    },
    {
      "x": -8,
      "y": 15,
      "z": -4,
      "name": "Rock_Ice_Permafrost"
    },
    {
      "x": -8,
      "y": 16,
      "z": -4,
      "name": "Rock_Ice_Permafrost"
    },
    {
      "x": -8,
      "y": 17,
      "z": -4,
      "name": "Rock_Ice_Permafrost"
    },
    {
      "x": -8,
      "y": 18,
      "z": -4,
      "name": "Rock_Ice_Permafrost"
    },
    {
      "x": -8,
      "y": 19,
      "z": -4,
      "name": "Rock_Ice_Permafrost"
    },
    {
      "x": -8,
      "y": 20,
      "z": -4,
      "name": "Rock_Ice_Permafrost"
    },
    {
      "x": -8,
      "y": 21,
      "z": -4,
      "name": "Rock_Ice_Permafrost"
    },
    {
      "x": -8,
      "y": 22,
      "z": -4,
      "name": "Rock_Ice_Permafrost"
    },
    {
      "x": -8,
      "y": 23,
      "z": -4,
      "name": "Rock_Ice"
    },
    {
      "x": -8,
      "y": 24,
      "z": -4,
      "name": "Rock_Ice"
    },
    {
      "x": -8,
      "y": 25,
      "z": -4,
      "name": "Soil_Snow"
    },
    {
      "x": -8,
      "y": 3,
      "z": -3,
      "name": "Rock_Ice"
    },
    {
      "x": -8,
      "y": 4,
      "z": -3,
      "name": "Rock_Ice"
    },
    {
      "x": -8,
      "y": 5,
      "z": -3,
      "name": "Rock_Ice"
    },
    {
      "x": -8,
      "y": 6,
      "z": -3,
      "name": "Rock_Ice"
    },
    {
      "x": -8,
      "y": 7,
      "z": -3,
      "name": "Rock_Ice"
    },
    {
      "x": -8,
      "y": 8,
      "z": -3,
      "name": "Rock_Ice"
    },
    {
      "x": -8,
      "y": 9,
      "z": -3,
      "name": "Rock_Ice"
    },
    {
      "x": -8,
      "y": 10,
      "z": -3,
      "name": "Rock_Ice"
    },
    {
      "x": -8,
      "y": 11,
      "z": -3,
      "name": "Rock_Ice"
    },
    {
      "x": -8,
      "y": 12,
      "z": -3,
      "name": "Rock_Ice"
    },
    {
      "x": -8,
      "y": 13,
      "z": -3,
      "name": "Rock_Ice"
    },
    {
      "x": -8,
      "y": 14,
      "z": -3,
      "name": "Rock_Ice"
    },
    {
      "x": -8,
      "y": 15,
      "z": -3,
      "name": "Rock_Ice"
    },
    {
      "x": -8,
      "y": 16,
      "z": -3,
      "name": "Rock_Ice_Permafrost"
    },
    {
      "x": -8,
      "y": 17,
      "z": -3,
      "name": "Rock_Ice_Permafrost"
    },
    {
      "x": -8,
      "y": 18,
      "z": -3,
      "name": "Rock_Ice_Permafrost"
    },
    {
      "x": -8,
      "y": 19,
      "z": -3,
      "name": "Rock_Ice_Permafrost"
    },
    {
      "x": -8,
      "y": 20,
      "z": -3,
      "name": "Rock_Ice_Permafrost"
    },
    {
      "x": -8,
      "y": 21,
      "z": -3,
      "name": "Rock_Ice_Permafrost"
    },
    {
      "x": -8,
      "y": 22,
      "z": -3,
      "name": "Rock_Ice_Permafrost"
    },
    {
      "x": -8,
      "y": 23,
      "z": -3,
      "name": "Rock_Ice_Permafrost"
    },
    {
      "x": -8,
      "y": 24,
      "z": -3,
      "name": "Rock_Ice"
    },
    {
      "x": -8,
      "y": 25,
      "z": -3,
      "name": "Rock_Ice"
    },
    {
      "x": -8,
      "y": 26,
      "z": -3,
      "name": "Soil_Snow"
    },
    {
      "x": -8,
      "y": 4,
      "z": -2,
      "name": "Rock_Ice"
    },
    {
      "x": -8,
      "y": 5,
      "z": -2,
      "name": "Rock_Ice"
    },
    {
      "x": -8,
      "y": 6,
      "z": -2,
      "name": "Rock_Ice"
    },
    {
      "x": -8,
      "y": 7,
      "z": -2,
      "name": "Rock_Ice"
    },
    {
      "x": -8,
      "y": 8,
      "z": -2,
      "name": "Rock_Ice"
    },
    {
      "x": -8,
      "y": 9,
      "z": -2,
      "name": "Rock_Ice"
    },
    {
      "x": -8,
      "y": 10,
      "z": -2,
      "name": "Rock_Ice"
    },
    {
      "x": -8,
      "y": 11,
      "z": -2,
      "name": "Rock_Ice"
    },
    {
      "x": -8,
      "y": 12,
      "z": -2,
      "name": "Rock_Ice"
    },
    {
      "x": -8,
      "y": 13,
      "z": -2,
      "name": "Rock_Ice"
    },
    {
      "x": -8,
      "y": 14,
      "z": -2,
      "name": "Rock_Ice"
    },
    {
      "x": -8,
      "y": 15,
      "z": -2,
      "name": "Rock_Ice"
    },
    {
      "x": -8,
      "y": 16,
      "z": -2,
      "name": "Rock_Ice_Permafrost"
    },
    {
      "x": -8,
      "y": 17,
      "z": -2,
      "name": "Rock_Ice_Permafrost"
    },
    {
      "x": -8,
      "y": 18,
      "z": -2,
      "name": "Rock_Ice_Permafrost"
    },
    {
      "x": -8,
      "y": 19,
      "z": -2,
      "name": "Rock_Ice_Permafrost"
    },
    {
      "x": -8,
      "y": 20,
      "z": -2,
      "name": "Rock_Ice_Permafrost"
    },
    {
      "x": -8,
      "y": 21,
      "z": -2,
      "name": "Rock_Ice_Permafrost"
    },
    {
      "x": -8,
      "y": 22,
      "z": -2,
      "name": "Rock_Ice_Permafrost"
    },
    {
      "x": -8,
      "y": 23,
      "z": -2,
      "name": "Rock_Ice_Permafrost"
    },
    {
      "x": -8,
      "y": 24,
      "z": -2,
      "name": "Rock_Ice_Permafrost"
    },
    {
      "x": -8,
      "y": 25,
      "z": -2,
      "name": "Rock_Ice"
    },
    {
      "x": -8,
      "y": 26,
      "z": -2,
      "name": "Soil_Snow"
    },
    {
      "x": -8,
      "y": 4,
      "z": -1,
      "name": "Rock_Ice"
    },
    {
      "x": -8,
      "y": 5,
      "z": -1,
      "name": "Rock_Ice"
    },
    {
      "x": -8,
      "y": 6,
      "z": -1,
      "name": "Rock_Ice"
    },
    {
      "x": -8,
      "y": 7,
      "z": -1,
      "name": "Rock_Ice"
    },
    {
      "x": -8,
      "y": 8,
      "z": -1,
      "name": "Rock_Ice"
    },
    {
      "x": -8,
      "y": 9,
      "z": -1,
      "name": "Rock_Ice"
    },
    {
      "x": -8,
      "y": 10,
      "z": -1,
      "name": "Rock_Ice"
    },
    {
      "x": -8,
      "y": 11,
      "z": -1,
      "name": "Rock_Ice"
    },
    {
      "x": -8,
      "y": 12,
      "z": -1,
      "name": "Rock_Ice"
    },
    {
      "x": -8,
      "y": 13,
      "z": -1,
      "name": "Rock_Ice"
    },
    {
      "x": -8,
      "y": 14,
      "z": -1,
      "name": "Rock_Ice"
    },
    {
      "x": -8,
      "y": 15,
      "z": -1,
      "name": "Rock_Ice"
    },
    {
      "x": -8,
      "y": 16,
      "z": -1,
      "name": "Rock_Ice_Permafrost"
    },
    {
      "x": -8,
      "y": 17,
      "z": -1,
      "name": "Rock_Ice_Permafrost"
    },
    {
      "x": -8,
      "y": 18,
      "z": -1,
      "name": "Rock_Ice_Permafrost"
    },
    {
      "x": -8,
      "y": 19,
      "z": -1,
      "name": "Rock_Ice_Permafrost"
    },
    {
      "x": -8,
      "y": 20,
      "z": -1,
      "name": "Rock_Ice_Permafrost"
    },
    {
      "x": -8,
      "y": 21,
      "z": -1,
      "name": "Rock_Ice"
    },
    {
      "x": -8,
      "y": 22,
      "z": -1,
      "name": "Rock_Ice_Permafrost"
    },
    {
      "x": -8,
      "y": 23,
      "z": -1,
      "name": "Rock_Ice_Permafrost"
    },
    {
      "x": -8,
      "y": 24,
      "z": -1,
      "name": "Rock_Ice_Permafrost"
    },
    {
      "x": -8,
      "y": 25,
      "z": -1,
      "name": "Rock_Ice"
    },
    {
      "x": -8,
      "y": 26,
      "z": -1,
      "name": "Soil_Snow"
    },
    {
      "x": -8,
      "y": 5,
      "z": 0,
      "name": "Rock_Ice"
    },
    {
      "x": -8,
      "y": 6,
      "z": 0,
      "name": "Rock_Ice"
    },
    {
      "x": -8,
      "y": 7,
      "z": 0,
      "name": "Rock_Ice"
    },
    {
      "x": -8,
      "y": 8,
      "z": 0,
      "name": "Rock_Ice"
    },
    {
      "x": -8,
      "y": 9,
      "z": 0,
      "name": "Rock_Ice"
    },
    {
      "x": -8,
      "y": 10,
      "z": 0,
      "name": "Rock_Ice"
    },
    {
      "x": -8,
      "y": 11,
      "z": 0,
      "name": "Rock_Ice"
    },
    {
      "x": -8,
      "y": 12,
      "z": 0,
      "name": "Rock_Ice"
    },
    {
      "x": -8,
      "y": 13,
      "z": 0,
      "name": "Rock_Ice"
    },
    {
      "x": -8,
      "y": 14,
      "z": 0,
      "name": "Rock_Ice"
    },
    {
      "x": -8,
      "y": 15,
      "z": 0,
      "name": "Rock_Ice"
    },
    {
      "x": -8,
      "y": 16,
      "z": 0,
      "name": "Rock_Ice"
    },
    {
      "x": -8,
      "y": 17,
      "z": 0,
      "name": "Rock_Ice_Permafrost"
    },
    {
      "x": -8,
      "y": 18,
      "z": 0,
      "name": "Rock_Ice_Permafrost"
    },
    {
      "x": -8,
      "y": 19,
      "z": 0,
      "name": "Rock_Ice"
    },
    {
      "x": -8,
      "y": 20,
      "z": 0,
      "name": "Rock_Ice"
    },
    {
      "x": -8,
      "y": 21,
      "z": 0,
      "name": "Rock_Ice"
    },
    {
      "x": -8,
      "y": 22,
      "z": 0,
      "name": "Rock_Ice"
    },
    {
      "x": -8,
      "y": 23,
      "z": 0,
      "name": "Rock_Ice"
    },
    {
      "x": -8,
      "y": 24,
      "z": 0,
      "name": "Rock_Ice"
    },
    {
      "x": -8,
      "y": 25,
      "z": 0,
      "name": "Soil_Snow"
    },
    {
      "x": -8,
      "y": 5,
      "z": 1,
      "name": "Rock_Ice"
    },
    {
      "x": -8,
      "y": 6,
      "z": 1,
      "name": "Rock_Ice"
    },
    {
      "x": -8,
      "y": 7,
      "z": 1,
      "name": "Rock_Ice"
    },
    {
      "x": -8,
      "y": 8,
      "z": 1,
      "name": "Rock_Ice"
    },
    {
      "x": -8,
      "y": 9,
      "z": 1,
      "name": "Rock_Ice"
    },
    {
      "x": -8,
      "y": 10,
      "z": 1,
      "name": "Rock_Ice"
    },
    {
      "x": -8,
      "y": 11,
      "z": 1,
      "name": "Rock_Ice"
    },
    {
      "x": -8,
      "y": 12,
      "z": 1,
      "name": "Rock_Ice"
    },
    {
      "x": -8,
      "y": 13,
      "z": 1,
      "name": "Rock_Ice"
    },
    {
      "x": -8,
      "y": 14,
      "z": 1,
      "name": "Rock_Ice"
    },
    {
      "x": -8,
      "y": 15,
      "z": 1,
      "name": "Rock_Ice"
    },
    {
      "x": -8,
      "y": 16,
      "z": 1,
      "name": "Rock_Ice"
    },
    {
      "x": -8,
      "y": 17,
      "z": 1,
      "name": "Rock_Ice_Permafrost"
    },
    {
      "x": -8,
      "y": 18,
      "z": 1,
      "name": "Rock_Ice_Permafrost"
    },
    {
      "x": -8,
      "y": 19,
      "z": 1,
      "name": "Rock_Ice"
    },
    {
      "x": -8,
      "y": 20,
      "z": 1,
      "name": "Rock_Ice"
    },
    {
      "x": -8,
      "y": 21,
      "z": 1,
      "name": "Rock_Ice"
    },
    {
      "x": -8,
      "y": 22,
      "z": 1,
      "name": "Rock_Ice"
    },
    {
      "x": -8,
      "y": 23,
      "z": 1,
      "name": "Rock_Ice_Permafrost"
    },
    {
      "x": -8,
      "y": 24,
      "z": 1,
      "name": "Rock_Ice"
    },
    {
      "x": -8,
      "y": 25,
      "z": 1,
      "name": "Soil_Snow"
    },
    {
      "x": -8,
      "y": 5,
      "z": 2,
      "name": "Rock_Ice"
    },
    {
      "x": -8,
      "y": 6,
      "z": 2,
      "name": "Rock_Ice"
    },
    {
      "x": -8,
      "y": 7,
      "z": 2,
      "name": "Rock_Ice"
    },
    {
      "x": -8,
      "y": 8,
      "z": 2,
      "name": "Rock_Ice"
    },
    {
      "x": -8,
      "y": 9,
      "z": 2,
      "name": "Rock_Ice"
    },
    {
      "x": -8,
      "y": 10,
      "z": 2,
      "name": "Rock_Ice"
    },
    {
      "x": -8,
      "y": 11,
      "z": 2,
      "name": "Rock_Ice"
    },
    {
      "x": -8,
      "y": 12,
      "z": 2,
      "name": "Rock_Ice"
    },
    {
      "x": -8,
      "y": 13,
      "z": 2,
      "name": "Rock_Ice"
    },
    {
      "x": -8,
      "y": 14,
      "z": 2,
      "name": "Rock_Ice"
    },
    {
      "x": -8,
      "y": 15,
      "z": 2,
      "name": "Rock_Ice"
    },
    {
      "x": -8,
      "y": 16,
      "z": 2,
      "name": "Rock_Ice"
    },
    {
      "x": -8,
      "y": 17,
      "z": 2,
      "name": "Rock_Ice_Permafrost"
    },
    {
      "x": -8,
      "y": 18,
      "z": 2,
      "name": "Rock_Ice_Permafrost"
    },
    {
      "x": -8,
      "y": 19,
      "z": 2,
      "name": "Rock_Ice"
    },
    {
      "x": -8,
      "y": 20,
      "z": 2,
      "name": "Rock_Ice"
    },
    {
      "x": -8,
      "y": 21,
      "z": 2,
      "name": "Rock_Ice"
    },
    {
      "x": -8,
      "y": 22,
      "z": 2,
      "name": "Rock_Ice"
    },
    {
      "x": -8,
      "y": 23,
      "z": 2,
      "name": "Soil_Snow"
    },
    {
      "x": -8,
      "y": 5,
      "z": 3,
      "name": "Rock_Ice"
    },
    {
      "x": -8,
      "y": 6,
      "z": 3,
      "name": "Rock_Ice"
    },
    {
      "x": -8,
      "y": 7,
      "z": 3,
      "name": "Rock_Ice"
    },
    {
      "x": -8,
      "y": 8,
      "z": 3,
      "name": "Rock_Ice"
    },
    {
      "x": -8,
      "y": 9,
      "z": 3,
      "name": "Rock_Ice"
    },
    {
      "x": -8,
      "y": 10,
      "z": 3,
      "name": "Rock_Ice"
    },
    {
      "x": -8,
      "y": 11,
      "z": 3,
      "name": "Rock_Ice"
    },
    {
      "x": -8,
      "y": 12,
      "z": 3,
      "name": "Rock_Ice"
    },
    {
      "x": -8,
      "y": 13,
      "z": 3,
      "name": "Rock_Ice"
    },
    {
      "x": -8,
      "y": 14,
      "z": 3,
      "name": "Rock_Ice"
    },
    {
      "x": -8,
      "y": 15,
      "z": 3,
      "name": "Rock_Ice"
    },
    {
      "x": -8,
      "y": 16,
      "z": 3,
      "name": "Rock_Ice"
    },
    {
      "x": -8,
      "y": 17,
      "z": 3,
      "name": "Rock_Ice_Permafrost"
    },
    {
      "x": -8,
      "y": 18,
      "z": 3,
      "name": "Rock_Ice_Permafrost"
    },
    {
      "x": -8,
      "y": 19,
      "z": 3,
      "name": "Rock_Ice"
    },
    {
      "x": -8,
      "y": 20,
      "z": 3,
      "name": "Rock_Ice"
    },
    {
      "x": -8,
      "y": 21,
      "z": 3,
      "name": "Soil_Snow"
    },
    {
      "x": -8,
      "y": 5,
      "z": 4,
      "name": "Rock_Ice"
    },
    {
      "x": -8,
      "y": 6,
      "z": 4,
      "name": "Rock_Ice"
    },
    {
      "x": -8,
      "y": 7,
      "z": 4,
      "name": "Rock_Ice"
    },
    {
      "x": -8,
      "y": 8,
      "z": 4,
      "name": "Rock_Ice"
    },
    {
      "x": -8,
      "y": 9,
      "z": 4,
      "name": "Rock_Ice"
    },
    {
      "x": -8,
      "y": 10,
      "z": 4,
      "name": "Rock_Ice"
    },
    {
      "x": -8,
      "y": 11,
      "z": 4,
      "name": "Rock_Ice"
    },
    {
      "x": -8,
      "y": 12,
      "z": 4,
      "name": "Rock_Ice"
    },
    {
      "x": -8,
      "y": 13,
      "z": 4,
      "name": "Rock_Ice"
    },
    {
      "x": -8,
      "y": 14,
      "z": 4,
      "name": "Rock_Ice"
    },
    {
      "x": -8,
      "y": 15,
      "z": 4,
      "name": "Rock_Ice"
    },
    {
      "x": -8,
      "y": 16,
      "z": 4,
      "name": "Rock_Ice"
    },
    {
      "x": -8,
      "y": 17,
      "z": 4,
      "name": "Rock_Ice"
    },
    {
      "x": -8,
      "y": 18,
      "z": 4,
      "name": "Rock_Ice_Permafrost"
    },
    {
      "x": -8,
      "y": 19,
      "z": 4,
      "name": "Rock_Ice"
    },
    {
      "x": -8,
      "y": 20,
      "z": 4,
      "name": "Soil_Snow"
    },
    {
      "x": -8,
      "y": 4,
      "z": 5,
      "name": "Rock_Ice"
    },
    {
      "x": -8,
      "y": 5,
      "z": 5,
      "name": "Rock_Ice"
    },
    {
      "x": -8,
      "y": 6,
      "z": 5,
      "name": "Rock_Ice"
    },
    {
      "x": -8,
      "y": 7,
      "z": 5,
      "name": "Rock_Ice"
    },
    {
      "x": -8,
      "y": 8,
      "z": 5,
      "name": "Rock_Ice"
    },
    {
      "x": -8,
      "y": 9,
      "z": 5,
      "name": "Rock_Ice"
    },
    {
      "x": -8,
      "y": 10,
      "z": 5,
      "name": "Rock_Ice"
    },
    {
      "x": -8,
      "y": 11,
      "z": 5,
      "name": "Rock_Ice"
    },
    {
      "x": -8,
      "y": 12,
      "z": 5,
      "name": "Rock_Ice"
    },
    {
      "x": -8,
      "y": 13,
      "z": 5,
      "name": "Rock_Ice"
    },
    {
      "x": -8,
      "y": 14,
      "z": 5,
      "name": "Rock_Ice"
    },
    {
      "x": -8,
      "y": 15,
      "z": 5,
      "name": "Rock_Ice"
    },
    {
      "x": -8,
      "y": 16,
      "z": 5,
      "name": "Rock_Ice"
    },
    {
      "x": -8,
      "y": 17,
      "z": 5,
      "name": "Rock_Ice"
    },
    {
      "x": -8,
      "y": 18,
      "z": 5,
      "name": "Rock_Ice_Permafrost"
    },
    {
      "x": -8,
      "y": 19,
      "z": 5,
      "name": "Soil_Snow"
    },
    {
      "x": -8,
      "y": 4,
      "z": 6,
      "name": "Rock_Ice"
    },
    {
      "x": -8,
      "y": 5,
      "z": 6,
      "name": "Rock_Ice"
    },
    {
      "x": -8,
      "y": 6,
      "z": 6,
      "name": "Rock_Ice"
    },
    {
      "x": -8,
      "y": 7,
      "z": 6,
      "name": "Rock_Ice"
    },
    {
      "x": -8,
      "y": 8,
      "z": 6,
      "name": "Rock_Ice"
    },
    {
      "x": -8,
      "y": 9,
      "z": 6,
      "name": "Rock_Ice"
    },
    {
      "x": -8,
      "y": 10,
      "z": 6,
      "name": "Rock_Ice"
    },
    {
      "x": -8,
      "y": 11,
      "z": 6,
      "name": "Rock_Ice"
    },
    {
      "x": -8,
      "y": 12,
      "z": 6,
      "name": "Rock_Ice"
    },
    {
      "x": -8,
      "y": 13,
      "z": 6,
      "name": "Rock_Ice"
    },
    {
      "x": -8,
      "y": 14,
      "z": 6,
      "name": "Rock_Ice"
    },
    {
      "x": -8,
      "y": 15,
      "z": 6,
      "name": "Rock_Ice"
    },
    {
      "x": -8,
      "y": 16,
      "z": 6,
      "name": "Rock_Ice"
    },
    {
      "x": -8,
      "y": 17,
      "z": 6,
      "name": "Rock_Ice"
    },
    {
      "x": -8,
      "y": 18,
      "z": 6,
      "name": "Soil_Snow"
    },
    {
      "x": -8,
      "y": 4,
      "z": 7,
      "name": "Rock_Ice"
    },
    {
      "x": -8,
      "y": 5,
      "z": 7,
      "name": "Rock_Ice"
    },
    {
      "x": -8,
      "y": 6,
      "z": 7,
      "name": "Rock_Ice"
    },
    {
      "x": -8,
      "y": 7,
      "z": 7,
      "name": "Rock_Ice"
    },
    {
      "x": -8,
      "y": 8,
      "z": 7,
      "name": "Rock_Ice"
    },
    {
      "x": -8,
      "y": 9,
      "z": 7,
      "name": "Rock_Ice"
    },
    {
      "x": -8,
      "y": 10,
      "z": 7,
      "name": "Rock_Ice"
    },
    {
      "x": -8,
      "y": 11,
      "z": 7,
      "name": "Rock_Ice"
    },
    {
      "x": -8,
      "y": 12,
      "z": 7,
      "name": "Rock_Ice"
    },
    {
      "x": -8,
      "y": 13,
      "z": 7,
      "name": "Rock_Ice"
    },
    {
      "x": -8,
      "y": 14,
      "z": 7,
      "name": "Rock_Ice"
    },
    {
      "x": -8,
      "y": 15,
      "z": 7,
      "name": "Rock_Ice"
    },
    {
      "x": -8,
      "y": 16,
      "z": 7,
      "name": "Rock_Ice"
    },
    {
      "x": -8,
      "y": 17,
      "z": 7,
      "name": "Soil_Snow"
    },
    {
      "x": -8,
      "y": 4,
      "z": 8,
      "name": "Rock_Ice"
    },
    {
      "x": -8,
      "y": 5,
      "z": 8,
      "name": "Rock_Ice"
    },
    {
      "x": -8,
      "y": 6,
      "z": 8,
      "name": "Rock_Ice"
    },
    {
      "x": -8,
      "y": 7,
      "z": 8,
      "name": "Rock_Ice"
    },
    {
      "x": -8,
      "y": 8,
      "z": 8,
      "name": "Rock_Ice"
    },
    {
      "x": -8,
      "y": 9,
      "z": 8,
      "name": "Rock_Ice"
    },
    {
      "x": -8,
      "y": 10,
      "z": 8,
      "name": "Rock_Ice"
    },
    {
      "x": -8,
      "y": 11,
      "z": 8,
      "name": "Rock_Ice"
    },
    {
      "x": -8,
      "y": 12,
      "z": 8,
      "name": "Rock_Ice"
    },
    {
      "x": -8,
      "y": 13,
      "z": 8,
      "name": "Rock_Ice"
    },
    {
      "x": -8,
      "y": 14,
      "z": 8,
      "name": "Rock_Ice"
    },
    {
      "x": -8,
      "y": 15,
      "z": 8,
      "name": "Rock_Ice"
    },
    {
      "x": -8,
      "y": 16,
      "z": 8,
      "name": "Rock_Ice"
    },
    {
      "x": -8,
      "y": 17,
      "z": 8,
      "name": "Soil_Snow"
    },
    {
      "x": -8,
      "y": 4,
      "z": 9,
      "name": "Rock_Ice"
    },
    {
      "x": -8,
      "y": 5,
      "z": 9,
      "name": "Rock_Ice"
    },
    {
      "x": -8,
      "y": 6,
      "z": 9,
      "name": "Rock_Ice"
    },
    {
      "x": -8,
      "y": 7,
      "z": 9,
      "name": "Rock_Ice"
    },
    {
      "x": -8,
      "y": 8,
      "z": 9,
      "name": "Rock_Ice"
    },
    {
      "x": -8,
      "y": 9,
      "z": 9,
      "name": "Rock_Ice"
    },
    {
      "x": -8,
      "y": 10,
      "z": 9,
      "name": "Rock_Ice"
    },
    {
      "x": -8,
      "y": 11,
      "z": 9,
      "name": "Rock_Ice"
    },
    {
      "x": -8,
      "y": 12,
      "z": 9,
      "name": "Rock_Ice"
    },
    {
      "x": -8,
      "y": 13,
      "z": 9,
      "name": "Rock_Ice"
    },
    {
      "x": -8,
      "y": 14,
      "z": 9,
      "name": "Rock_Ice"
    },
    {
      "x": -8,
      "y": 15,
      "z": 9,
      "name": "Rock_Ice"
    },
    {
      "x": -8,
      "y": 16,
      "z": 9,
      "name": "Rock_Ice"
    },
    {
      "x": -8,
      "y": 17,
      "z": 9,
      "name": "Soil_Snow"
    },
    {
      "x": -8,
      "y": 4,
      "z": 10,
      "name": "Rock_Ice"
    },
    {
      "x": -8,
      "y": 5,
      "z": 10,
      "name": "Rock_Ice"
    },
    {
      "x": -8,
      "y": 6,
      "z": 10,
      "name": "Rock_Ice"
    },
    {
      "x": -8,
      "y": 7,
      "z": 10,
      "name": "Rock_Ice"
    },
    {
      "x": -8,
      "y": 8,
      "z": 10,
      "name": "Rock_Ice"
    },
    {
      "x": -8,
      "y": 9,
      "z": 10,
      "name": "Rock_Ice"
    },
    {
      "x": -8,
      "y": 10,
      "z": 10,
      "name": "Rock_Ice"
    },
    {
      "x": -8,
      "y": 11,
      "z": 10,
      "name": "Rock_Ice"
    },
    {
      "x": -8,
      "y": 12,
      "z": 10,
      "name": "Rock_Ice"
    },
    {
      "x": -8,
      "y": 13,
      "z": 10,
      "name": "Rock_Ice"
    },
    {
      "x": -8,
      "y": 14,
      "z": 10,
      "name": "Rock_Ice"
    },
    {
      "x": -8,
      "y": 15,
      "z": 10,
      "name": "Rock_Ice"
    },
    {
      "x": -8,
      "y": 16,
      "z": 10,
      "name": "Soil_Snow"
    },
    {
      "x": -8,
      "y": 6,
      "z": 11,
      "name": "Rock_Ice"
    },
    {
      "x": -8,
      "y": 7,
      "z": 11,
      "name": "Rock_Ice"
    },
    {
      "x": -8,
      "y": 8,
      "z": 11,
      "name": "Rock_Ice"
    },
    {
      "x": -8,
      "y": 9,
      "z": 11,
      "name": "Rock_Ice"
    },
    {
      "x": -8,
      "y": 10,
      "z": 11,
      "name": "Rock_Ice"
    },
    {
      "x": -8,
      "y": 11,
      "z": 11,
      "name": "Rock_Ice"
    },
    {
      "x": -8,
      "y": 12,
      "z": 11,
      "name": "Rock_Ice"
    },
    {
      "x": -8,
      "y": 13,
      "z": 11,
      "name": "Rock_Ice"
    },
    {
      "x": -8,
      "y": 14,
      "z": 11,
      "name": "Rock_Ice"
    },
    {
      "x": -8,
      "y": 15,
      "z": 11,
      "name": "Rock_Ice"
    },
    {
      "x": -8,
      "y": 16,
      "z": 11,
      "name": "Soil_Snow"
    },
    {
      "x": -8,
      "y": 12,
      "z": 12,
      "name": "Rock_Ice"
    },
    {
      "x": -8,
      "y": 13,
      "z": 12,
      "name": "Rock_Ice"
    },
    {
      "x": -8,
      "y": 14,
      "z": 12,
      "name": "Soil_Snow"
    },
    {
      "x": -8,
      "y": 8,
      "z": 13,
      "name": "Rock_Ice"
    },
    {
      "x": -8,
      "y": 9,
      "z": 13,
      "name": "Rock_Ice"
    },
    {
      "x": -8,
      "y": 10,
      "z": 13,
      "name": "Rock_Ice"
    },
    {
      "x": -8,
      "y": 11,
      "z": 13,
      "name": "Rock_Ice"
    },
    {
      "x": -8,
      "y": 12,
      "z": 13,
      "name": "Rock_Ice"
    },
    {
      "x": -8,
      "y": 13,
      "z": 13,
      "name": "Rock_Ice"
    },
    {
      "x": -8,
      "y": 14,
      "z": 13,
      "name": "Rock_Ice"
    },
    {
      "x": -8,
      "y": 15,
      "z": 13,
      "name": "Soil_Snow"
    },
    {
      "x": -8,
      "y": 12,
      "z": 14,
      "name": "Rock_Ice"
    },
    {
      "x": -8,
      "y": 13,
      "z": 14,
      "name": "Rock_Ice"
    },
    {
      "x": -7,
      "y": 16,
      "z": -11,
      "name": "Rock_Ice_Permafrost"
    },
    {
      "x": -7,
      "y": 17,
      "z": -11,
      "name": "Rock_Ice"
    },
    {
      "x": -7,
      "y": 18,
      "z": -11,
      "name": "Rock_Ice"
    },
    {
      "x": -7,
      "y": 19,
      "z": -11,
      "name": "Soil_Snow"
    },
    {
      "x": -7,
      "y": 16,
      "z": -10,
      "name": "Rock_Ice"
    },
    {
      "x": -7,
      "y": 17,
      "z": -10,
      "name": "Rock_Ice"
    },
    {
      "x": -7,
      "y": 18,
      "z": -10,
      "name": "Rock_Ice"
    },
    {
      "x": -7,
      "y": 7,
      "z": -9,
      "name": "Rock_Ice_Permafrost"
    },
    {
      "x": -7,
      "y": 8,
      "z": -9,
      "name": "Rock_Ice_Permafrost"
    },
    {
      "x": -7,
      "y": 9,
      "z": -9,
      "name": "Rock_Ice_Permafrost"
    },
    {
      "x": -7,
      "y": 10,
      "z": -9,
      "name": "Rock_Ice_Permafrost"
    },
    {
      "x": -7,
      "y": 11,
      "z": -9,
      "name": "Rock_Ice_Permafrost"
    },
    {
      "x": -7,
      "y": 12,
      "z": -9,
      "name": "Rock_Ice_Permafrost"
    },
    {
      "x": -7,
      "y": 13,
      "z": -9,
      "name": "Rock_Ice_Permafrost"
    },
    {
      "x": -7,
      "y": 14,
      "z": -9,
      "name": "Rock_Ice_Permafrost"
    },
    {
      "x": -7,
      "y": 15,
      "z": -9,
      "name": "Rock_Ice_Permafrost"
    },
    {
      "x": -7,
      "y": 16,
      "z": -9,
      "name": "Rock_Ice_Permafrost"
    },
    {
      "x": -7,
      "y": 17,
      "z": -9,
      "name": "Rock_Ice"
    },
    {
      "x": -7,
      "y": 18,
      "z": -9,
      "name": "Rock_Ice"
    },
    {
      "x": -7,
      "y": 19,
      "z": -9,
      "name": "Rock_Ice"
    },
