{
  "version": 8,
  "blockIdVersion": 11,
  "anchorX": -6,
  "anchorY": 40,
  "anchorZ": -6,
  "blocks": [
    {
      "x": -44,
      "y": 52,
      "z": 2,
      "name": "Rock_Ice_Permafrost"
    },
    {
      "x": -44,
      "y": 53,
      "z": 2,
      "name": "Rock_Ice_Permafrost"
    },
    {
      "x": -44,
      "y": 54,
      "z": 2,
      "name": "Soil_Snow"
    },
    {
      "x": -44,
      "y": 52,
      "z": 3,
      "name": "Rock_Ice_Permafrost"
    },
    {
      "x": -44,
      "y": 53,
      "z": 3,
      "name": "Soil_Snow"
    },
    {
      "x": -44,
      "y": 51,
      "z": 4,
      "name": "Rock_Ice_Permafrost"
    },
    {
      "x": -44,
      "y": 52,
      "z": 4,
      "name": "Soil_Snow"
    },
    {
      "x": -44,
      "y": 50,
      "z": 5,
      "name": "Rock_Ice_Permafrost"
    },
    {
      "x": -44,
      "y": 51,
      "z": 5,
      "name": "Soil_Snow"
    },
    {
      "x": -44,
      "y": 50,
      "z": 6,
      "name": "Soil_Snow"
    },
    {
      "x": -44,
      "y": 49,
      "z": 7,
      "name": "Soil_Snow"
    },
    {
      "x": -43,
      "y": 58,
      "z": -4,
      "name": "Soil_Snow"
    },
    {
      "x": -43,
      "y": 56,
      "z": -3,
      "name": "Rock_Ice_Permafrost"
    },
    {
      "x": -43,
      "y": 57,
      "z": -3,
      "name": "Rock_Ice_Permafrost"
    },
    {
      "x": -43,
      "y": 58,
      "z": -3,
      "name": "Soil_Snow"
    },
    {
      "x": -43,
      "y": 55,
      "z": -2,
      "name": "Rock_Ice_Permafrost"
    },
    {
      "x": -43,
      "y": 56,
      "z": -2,
      "name": "Rock_Ice_Permafrost"
    },
    {
      "x": -43,
      "y": 57,
      "z": -2,
      "name": "Rock_Ice_Permafrost"
    },
    {
      "x": -43,
      "y": 58,
      "z": -2,
      "name": "Soil_Snow"
    },
    {
      "x": -43,
      "y": 53,
      "z": -1,
      "name": "Rock_Ice_Permafrost"
    },
    {
      "x": -43,
      "y": 54,
      "z": -1,
      "name": "Rock_Ice_Permafrost"
    },
    {
      "x": -43,
      "y": 55,
      "z": -1,
      "name": "Rock_Ice_Permafrost"
    },
    {
      "x": -43,
      "y": 56,
      "z": -1,
      "name": "Rock_Ice_Permafrost"
    },
    {
      "x": -43,
      "y": 57,
      "z": -1,
      "name": "Soil_Snow"
    },
    {
      "x": -43,
      "y": 53,
      "z": 0,
      "name": "Rock_Ice_Permafrost"
    },
    {
      "x": -43,
      "y": 54,
      "z": 0,
      "name": "Rock_Ice_Permafrost"
    },
    {
      "x": -43,
      "y": 55,
      "z": 0,
      "name": "Rock_Ice_Permafrost"
    },
    {
      "x": -43,
      "y": 56,
      "z": 0,
      "name": "Rock_Ice_Permafrost"
    },
    {
      "x": -43,
      "y": 57,
      "z": 0,
      "name": "Soil_Snow"
    },
    {
      "x": -43,
      "y": 52,
      "z": 1,
      "name": "Rock_Ice_Permafrost"
    },
    {
      "x": -43,
      "y": 53,
      "z": 1,
      "name": "Rock_Ice_Permafrost"
    },
    {
      "x": -43,
      "y": 54,
      "z": 1,
      "name": "Rock_Ice_Permafrost"
    },
    {
      "x": -43,
      "y": 55,
      "z": 1,
      "name": "Rock_Ice_Permafrost"
    },
    {
      "x": -43,
      "y": 56,
      "z": 1,
      "name": "Rock_Ice"
    },
    {
      "x": -43,
      "y": 57,
      "z": 1,
      "name": "Soil_Snow"
    },
    {
      "x": -43,
      "y": 51,
      "z": 2,
      "name": "Rock_Ice_Permafrost"
    },
    {
      "x": -43,
      "y": 52,
      "z": 2,
      "name": "Rock_Ice_Permafrost"
    },
    {
      "x": -43,
      "y": 53,
      "z": 2,
      "name": "Rock_Ice"
    },
    {
      "x": -43,
      "y": 54,
      "z": 2,
      "name": "Rock_Ice_Permafrost"
    },
    {
      "x": -43,
      "y": 55,
      "z": 2,
      "name": "Rock_Ice"
    },
    {
      "x": -43,
      "y": 56,
      "z": 2,
      "name": "Soil_Snow"
    },
    {
      "x": -43,
      "y": 50,
      "z": 3,
      "name": "Rock_Ice"
    },
    {
      "x": -43,
      "y": 51,
      "z": 3,
      "name": "Rock_Ice_Permafrost"
    },
    {
      "x": -43,
      "y": 52,
      "z": 3,
      "name": "Rock_Ice_Permafrost"
    },
    {
      "x": -43,
      "y": 53,
      "z": 3,
      "name": "Rock_Ice_Permafrost"
    },
    {
      "x": -43,
      "y": 54,
      "z": 3,
      "name": "Rock_Ice"
    },
    {
      "x": -43,
      "y": 55,
      "z": 3,
      "name": "Rock_Ice"
    },
    {
      "x": -43,
      "y": 56,
      "z": 3,
      "name": "Soil_Snow"
    },
    {
      "x": -43,
      "y": 49,
      "z": 4,
      "name": "Rock_Ice_Permafrost"
    },
    {
      "x": -43,
      "y": 50,
      "z": 4,
      "name": "Rock_Ice_Permafrost"
    },
    {
      "x": -43,
      "y": 51,
      "z": 4,
      "name": "Rock_Ice_Permafrost"
    },
    {
      "x": -43,
      "y": 52,
      "z": 4,
      "name": "Rock_Ice_Permafrost"
    },
    {
      "x": -43,
      "y": 53,
      "z": 4,
      "name": "Rock_Ice"
    },
    {
      "x": -43,
      "y": 54,
      "z": 4,
      "name": "Rock_Ice"
    },
    {
      "x": -43,
      "y": 55,
      "z": 4,
      "name": "Soil_Snow"
    },
    {
      "x": -43,
      "y": 48,
      "z": 5,
      "name": "Rock_Ice_Permafrost"
    },
    {
      "x": -43,
      "y": 49,
      "z": 5,
      "name": "Rock_Ice_Permafrost"
    },
    {
      "x": -43,
      "y": 50,
      "z": 5,
      "name": "Rock_Ice_Permafrost"
    },
    {
      "x": -43,
      "y": 51,
      "z": 5,
      "name": "Rock_Ice_Permafrost"
    },
    {
      "x": -43,
      "y": 52,
      "z": 5,
      "name": "Rock_Ice"
    },
    {
      "x": -43,
      "y": 53,
      "z": 5,
      "name": "Rock_Ice"
    },
    {
      "x": -43,
      "y": 54,
      "z": 5,
      "name": "Soil_Snow"
    },
    {
      "x": -43,
      "y": 48,
      "z": 6,
      "name": "Rock_Ice_Permafrost"
    },
    {
      "x": -43,
      "y": 49,
      "z": 6,
      "name": "Rock_Ice_Permafrost"
    },
    {
      "x": -43,
      "y": 50,
      "z": 6,
      "name": "Rock_Ice"
    },
    {
      "x": -43,
      "y": 51,
      "z": 6,
      "name": "Rock_Ice"
    },
    {
      "x": -43,
      "y": 52,
      "z": 6,
      "name": "Soil_Snow"
    },
    {
      "x": -43,
      "y": 47,
      "z": 7,
      "name": "Rock_Ice_Permafrost"
    },
    {
      "x": -43,
      "y": 48,
      "z": 7,
      "name": "Rock_Ice_Permafrost"
    },
    {
      "x": -43,
      "y": 49,
      "z": 7,
      "name": "Rock_Ice"
    },
    {
      "x": -43,
      "y": 50,
      "z": 7,
      "name": "Rock_Ice"
    },
    {
      "x": -43,
      "y": 51,
      "z": 7,
      "name": "Soil_Snow"
    },
    {
      "x": -43,
      "y": 46,
      "z": 8,
      "name": "Rock_Ice"
    },
    {
      "x": -43,
      "y": 47,
      "z": 8,
      "name": "Rock_Ice_Permafrost"
    },
    {
      "x": -43,
      "y": 48,
      "z": 8,
      "name": "Rock_Ice"
    },
    {
      "x": -43,
      "y": 49,
      "z": 8,
      "name": "Rock_Ice"
    },
    {
      "x": -43,
      "y": 50,
      "z": 8,
      "name": "Soil_Snow"
    },
    {
      "x": -43,
      "y": 46,
      "z": 9,
      "name": "Rock_Ice"
    },
    {
      "x": -43,
      "y": 47,
      "z": 9,
      "name": "Rock_Ice"
    },
    {
      "x": -43,
      "y": 48,
      "z": 9,
      "name": "Soil_Snow"
    },
    {
      "x": -43,
      "y": 45,
      "z": 10,
      "name": "Soil_Snow"
    },
    {
      "x": -42,
      "y": 59,
      "z": -7,
      "name": "Rock_Ice_Permafrost"
    },
    {
      "x": -42,
      "y": 60,
      "z": -7,
      "name": "Soil_Snow"
    },
    {
      "x": -42,
      "y": 58,
      "z": -6,
      "name": "Rock_Ice_Permafrost"
    },
    {
      "x": -42,
      "y": 59,
      "z": -6,
      "name": "Rock_Ice_Permafrost"
    },
    {
      "x": -42,
      "y": 60,
      "z": -6,
      "name": "Rock_Ice_Permafrost"
    },
    {
      "x": -42,
      "y": 61,
      "z": -6,
      "name": "Soil_Snow"
    },
    {
      "x": -42,
      "y": 56,
      "z": -5,
      "name": "Rock_Ice_Permafrost"
    },
    {
      "x": -42,
      "y": 57,
      "z": -5,
      "name": "Rock_Ice_Permafrost"
    },
    {
      "x": -42,
      "y": 58,
      "z": -5,
      "name": "Rock_Ice_Permafrost"
    },
    {
      "x": -42,
      "y": 59,
      "z": -5,
      "name": "Rock_Ice_Permafrost"
    },
    {
      "x": -42,
      "y": 60,
      "z": -5,
      "name": "Rock_Ice"
    },
    {
      "x": -42,
      "y": 61,
      "z": -5,
      "name": "Rock_Ice"
    },
    {
      "x": -42,
      "y": 62,
      "z": -5,
      "name": "Rock_Ice_Permafrost"
    },
    {
      "x": -42,
      "y": 63,
      "z": -5,
      "name": "Rock_Ice"
    },
    {
      "x": -42,
      "y": 64,
      "z": -5,
      "name": "Soil_Snow"
    },
    {
      "x": -42,
      "y": 55,
      "z": -4,
      "name": "Rock_Ice_Permafrost"
    },
    {
      "x": -42,
      "y": 56,
      "z": -4,
      "name": "Rock_Ice_Permafrost"
    },
    {
      "x": -42,
      "y": 57,
      "z": -4,
      "name": "Rock_Ice_Permafrost"
    },
    {
      "x": -42,
      "y": 58,
      "z": -4,
      "name": "Rock_Ice_Permafrost"
    },
    {
      "x": -42,
      "y": 59,
      "z": -4,
      "name": "Rock_Ice_Permafrost"
    },
    {
      "x": -42,
      "y": 60,
      "z": -4,
      "name": "Rock_Ice"
    },
    {
      "x": -42,
      "y": 61,
      "z": -4,
      "name": "Rock_Ice"
    },
    {
      "x": -42,
      "y": 62,
      "z": -4,
      "name": "Rock_Ice"
    },
    {
      "x": -42,
      "y": 63,
      "z": -4,
      "name": "Rock_Ice"
    },
    {
      "x": -42,
      "y": 64,
      "z": -4,
      "name": "Soil_Snow"
    },
    {
      "x": -42,
      "y": 54,
      "z": -3,
      "name": "Rock_Ice_Permafrost"
    },
    {
      "x": -42,
      "y": 55,
      "z": -3,
      "name": "Rock_Ice_Permafrost"
    },
    {
      "x": -42,
      "y": 56,
      "z": -3,
      "name": "Rock_Ice_Permafrost"
    },
    {
      "x": -42,
      "y": 57,
      "z": -3,
      "name": "Rock_Ice_Permafrost"
    },
    {
      "x": -42,
      "y": 58,
      "z": -3,
      "name": "Rock_Ice_Permafrost"
    },
    {
      "x": -42,
      "y": 59,
      "z": -3,
      "name": "Rock_Ice"
    },
    {
      "x": -42,
      "y": 60,
      "z": -3,
      "name": "Rock_Ice_Permafrost"
    },
    {
      "x": -42,
      "y": 61,
      "z": -3,
      "name": "Rock_Ice"
    },
    {
      "x": -42,
      "y": 62,
      "z": -3,
      "name": "Rock_Ice"
    },
    {
      "x": -42,
      "y": 63,
      "z": -3,
      "name": "Rock_Ice"
    },
    {
      "x": -42,
      "y": 64,
      "z": -3,
      "name": "Rock_Ice"
    },
    {
      "x": -42,
      "y": 65,
      "z": -3,
      "name": "Soil_Snow"
    },
    {
      "x": -42,
      "y": 53,
      "z": -2,
      "name": "Rock_Ice"
    },
    {
      "x": -42,
      "y": 54,
      "z": -2,
      "name": "Rock_Ice_Permafrost"
    },
    {
      "x": -42,
      "y": 55,
      "z": -2,
      "name": "Rock_Ice_Permafrost"
    },
    {
      "x": -42,
      "y": 56,
      "z": -2,
      "name": "Rock_Ice_Permafrost"
    },
    {
      "x": -42,
      "y": 57,
      "z": -2,
      "name": "Rock_Ice"
    },
    {
      "x": -42,
      "y": 58,
      "z": -2,
      "name": "Rock_Ice"
    },
    {
      "x": -42,
      "y": 59,
      "z": -2,
      "name": "Rock_Ice"
    },
    {
      "x": -42,
      "y": 60,
      "z": -2,
      "name": "Rock_Ice"
    },
    {
      "x": -42,
      "y": 61,
      "z": -2,
      "name": "Rock_Ice"
    },
    {
      "x": -42,
      "y": 62,
      "z": -2,
      "name": "Rock_Ice"
    },
    {
      "x": -42,
      "y": 63,
      "z": -2,
      "name": "Rock_Ice"
    },
    {
      "x": -42,
      "y": 64,
      "z": -2,
      "name": "Rock_Ice"
    },
    {
      "x": -42,
      "y": 65,
      "z": -2,
      "name": "Soil_Snow"
    },
    {
      "x": -42,
      "y": 52,
      "z": -1,
      "name": "Rock_Ice_Permafrost"
    },
    {
      "x": -42,
      "y": 53,
      "z": -1,
      "name": "Rock_Ice_Permafrost"
    },
    {
      "x": -42,
      "y": 54,
      "z": -1,
      "name": "Rock_Ice_Permafrost"
    },
    {
      "x": -42,
      "y": 55,
      "z": -1,
      "name": "Rock_Ice_Permafrost"
    },
    {
      "x": -42,
      "y": 56,
      "z": -1,
      "name": "Rock_Ice_Permafrost"
    },
    {
      "x": -42,
      "y": 57,
      "z": -1,
      "name": "Rock_Ice"
    },
    {
      "x": -42,
      "y": 58,
      "z": -1,
      "name": "Rock_Ice"
    },
    {
      "x": -42,
      "y": 59,
      "z": -1,
      "name": "Rock_Ice"
    },
    {
      "x": -42,
      "y": 60,
      "z": -1,
      "name": "Rock_Ice"
    },
    {
      "x": -42,
      "y": 61,
      "z": -1,
      "name": "Rock_Ice"
    },
    {
      "x": -42,
      "y": 62,
      "z": -1,
      "name": "Rock_Ice"
    },
    {
      "x": -42,
      "y": 63,
      "z": -1,
      "name": "Rock_Ice"
    },
    {
      "x": -42,
      "y": 64,
      "z": -1,
      "name": "Rock_Ice"
    },
    {
      "x": -42,
      "y": 65,
      "z": -1,
      "name": "Soil_Snow"
    },
    {
      "x": -42,
      "y": 51,
      "z": 0,
      "name": "Rock_Ice_Permafrost"
    },
    {
      "x": -42,
      "y": 52,
      "z": 0,
      "name": "Rock_Ice_Permafrost"
    },
    {
      "x": -42,
      "y": 53,
      "z": 0,
      "name": "Rock_Ice_Permafrost"
    },
    {
      "x": -42,
      "y": 54,
      "z": 0,
      "name": "Rock_Ice_Permafrost"
    },
    {
      "x": -42,
      "y": 55,
      "z": 0,
      "name": "Rock_Ice_Permafrost"
    },
    {
      "x": -42,
      "y": 56,
      "z": 0,
      "name": "Rock_Ice"
    },
    {
      "x": -42,
      "y": 57,
      "z": 0,
      "name": "Rock_Ice_Permafrost"
    },
    {
      "x": -42,
      "y": 58,
      "z": 0,
      "name": "Rock_Ice"
    },
    {
      "x": -42,
      "y": 59,
      "z": 0,
      "name": "Rock_Ice"
    },
    {
      "x": -42,
      "y": 60,
      "z": 0,
      "name": "Rock_Ice"
    },
    {
      "x": -42,
      "y": 61,
      "z": 0,
      "name": "Rock_Ice"
    },
    {
      "x": -42,
      "y": 62,
      "z": 0,
      "name": "Rock_Ice"
    },
    {
      "x": -42,
      "y": 63,
      "z": 0,
      "name": "Rock_Ice"
    },
    {
      "x": -42,
      "y": 64,
      "z": 0,
      "name": "Rock_Ice"
    },
    {
      "x": -42,
      "y": 65,
      "z": 0,
      "name": "Soil_Snow"
    },
    {
      "x": -42,
      "y": 50,
      "z": 1,
      "name": "Rock_Ice_Permafrost"
    },
    {
      "x": -42,
      "y": 51,
      "z": 1,
      "name": "Rock_Ice_Permafrost"
    },
    {
      "x": -42,
      "y": 52,
      "z": 1,
      "name": "Rock_Ice_Permafrost"
    },
    {
      "x": -42,
      "y": 53,
      "z": 1,
      "name": "Rock_Ice_Permafrost"
    },
    {
      "x": -42,
      "y": 54,
      "z": 1,
      "name": "Rock_Ice_Permafrost"
    },
    {
      "x": -42,
      "y": 55,
      "z": 1,
      "name": "Rock_Ice_Permafrost"
    },
    {
      "x": -42,
      "y": 56,
      "z": 1,
      "name": "Rock_Ice"
    },
    {
      "x": -42,
      "y": 57,
      "z": 1,
      "name": "Rock_Ice"
    },
    {
      "x": -42,
      "y": 58,
      "z": 1,
      "name": "Rock_Ice"
    },
    {
      "x": -42,
      "y": 59,
      "z": 1,
      "name": "Rock_Ice"
    },
    {
      "x": -42,
      "y": 60,
      "z": 1,
      "name": "Rock_Ice"
    },
    {
      "x": -42,
      "y": 61,
      "z": 1,
      "name": "Rock_Ice"
    },
    {
      "x": -42,
      "y": 62,
      "z": 1,
      "name": "Rock_Ice"
    },
    {
      "x": -42,
      "y": 63,
      "z": 1,
      "name": "Rock_Ice"
    },
    {
      "x": -42,
      "y": 64,
      "z": 1,
      "name": "Rock_Ice"
    },
    {
      "x": -42,
      "y": 65,
      "z": 1,
      "name": "Soil_Snow"
    },
    {
      "x": -42,
      "y": 50,
      "z": 2,
      "name": "Rock_Ice_Permafrost"
    },
    {
      "x": -42,
      "y": 51,
      "z": 2,
      "name": "Rock_Ice_Permafrost"
    },
    {
      "x": -42,
      "y": 52,
      "z": 2,
      "name": "Rock_Ice_Permafrost"
    },
    {
      "x": -42,
      "y": 53,
      "z": 2,
      "name": "Rock_Ice_Permafrost"
    },
    {
      "x": -42,
      "y": 54,
      "z": 2,
      "name": "Rock_Ice_Permafrost"
    },
    {
      "x": -42,
      "y": 55,
      "z": 2,
      "name": "Rock_Ice_Permafrost"
    },
    {
      "x": -42,
      "y": 56,
      "z": 2,
      "name": "Rock_Ice"
    },
    {
      "x": -42,
      "y": 57,
      "z": 2,
      "name": "Rock_Ice"
    },
    {
      "x": -42,
      "y": 58,
      "z": 2,
      "name": "Rock_Ice"
    },
    {
      "x": -42,
      "y": 59,
      "z": 2,
      "name": "Rock_Ice"
    },
    {
      "x": -42,
      "y": 60,
      "z": 2,
      "name": "Rock_Ice"
    },
    {
      "x": -42,
      "y": 61,
      "z": 2,
      "name": "Rock_Ice"
    },
    {
      "x": -42,
      "y": 62,
      "z": 2,
      "name": "Rock_Ice"
    },
    {
      "x": -42,
      "y": 63,
      "z": 2,
      "name": "Rock_Ice"
    },
    {
      "x": -42,
      "y": 64,
      "z": 2,
      "name": "Soil_Snow"
    },
    {
      "x": -42,
      "y": 49,
      "z": 3,
      "name": "Rock_Ice_Permafrost"
    },
    {
      "x": -42,
      "y": 50,
      "z": 3,
      "name": "Rock_Ice"
    },
    {
      "x": -42,
      "y": 51,
      "z": 3,
      "name": "Rock_Ice_Permafrost"
    },
    {
      "x": -42,
      "y": 52,
      "z": 3,
      "name": "Rock_Ice_Permafrost"
    },
    {
      "x": -42,
      "y": 53,
      "z": 3,
      "name": "Rock_Ice_Permafrost"
    },
    {
      "x": -42,
      "y": 54,
      "z": 3,
      "name": "Rock_Ice"
    },
    {
      "x": -42,
      "y": 55,
      "z": 3,
      "name": "Rock_Ice"
    },
    {
      "x": -42,
      "y": 56,
      "z": 3,
      "name": "Rock_Ice"
    },
    {
      "x": -42,
      "y": 57,
      "z": 3,
      "name": "Rock_Ice"
    },
    {
      "x": -42,
      "y": 58,
      "z": 3,
      "name": "Rock_Ice"
    },
    {
      "x": -42,
      "y": 59,
      "z": 3,
      "name": "Rock_Ice"
    },
    {
      "x": -42,
      "y": 60,
      "z": 3,
      "name": "Rock_Ice"
    },
    {
      "x": -42,
      "y": 61,
      "z": 3,
      "name": "Rock_Ice"
    },
    {
      "x": -42,
      "y": 62,
      "z": 3,
      "name": "Rock_Ice"
    },
    {
      "x": -42,
      "y": 63,
      "z": 3,
      "name": "Soil_Snow"
    },
    {
      "x": -42,
      "y": 48,
      "z": 4,
      "name": "Rock_Ice_Permafrost"
    },
    {
      "x": -42,
      "y": 49,
      "z": 4,
      "name": "Rock_Ice"
    },
    {
      "x": -42,
      "y": 50,
      "z": 4,
      "name": "Rock_Ice_Permafrost"
    },
    {
      "x": -42,
      "y": 51,
      "z": 4,
      "name": "Rock_Ice_Permafrost"
    },
    {
      "x": -42,
      "y": 52,
      "z": 4,
      "name": "Rock_Ice"
    },
    {
      "x": -42,
      "y": 53,
      "z": 4,
      "name": "Rock_Ice"
    },
    {
      "x": -42,
      "y": 54,
      "z": 4,
      "name": "Rock_Ice"
    },
    {
      "x": -42,
      "y": 55,
      "z": 4,
      "name": "Rock_Ice"
    },
    {
      "x": -42,
      "y": 56,
      "z": 4,
      "name": "Rock_Ice"
    },
    {
      "x": -42,
      "y": 57,
      "z": 4,
      "name": "Rock_Ice"
    },
    {
      "x": -42,
      "y": 58,
      "z": 4,
      "name": "Rock_Ice"
    },
    {
      "x": -42,
      "y": 59,
      "z": 4,
      "name": "Rock_Ice"
    },
    {
      "x": -42,
      "y": 60,
      "z": 4,
      "name": "Rock_Ice"
    },
    {
      "x": -42,
      "y": 61,
      "z": 4,
      "name": "Rock_Ice"
    },
    {
      "x": -42,
      "y": 62,
      "z": 4,
      "name": "Soil_Snow"
    },
    {
      "x": -42,
      "y": 47,
      "z": 5,
      "name": "Rock_Ice_Permafrost"
    },
    {
      "x": -42,
      "y": 48,
      "z": 5,
      "name": "Rock_Ice_Permafrost"
    },
    {
      "x": -42,
      "y": 49,
      "z": 5,
      "name": "Rock_Ice"
    },
    {
      "x": -42,
      "y": 50,
      "z": 5,
      "name": "Rock_Ice_Permafrost"
    },
    {
      "x": -42,
      "y": 51,
      "z": 5,
      "name": "Rock_Ice_Permafrost"
    },
    {
      "x": -42,
      "y": 52,
      "z": 5,
      "name": "Rock_Ice"
    },
    {
      "x": -42,
      "y": 53,
      "z": 5,
      "name": "Rock_Ice"
    },
    {
      "x": -42,
      "y": 54,
      "z": 5,
      "name": "Rock_Ice"
    },
    {
      "x": -42,
      "y": 55,
      "z": 5,
      "name": "Rock_Ice"
    },
    {
      "x": -42,
      "y": 56,
      "z": 5,
      "name": "Rock_Ice"
    },
    {
      "x": -42,
      "y": 57,
      "z": 5,
      "name": "Rock_Ice"
    },
    {
      "x": -42,
      "y": 58,
      "z": 5,
      "name": "Rock_Ice"
    },
    {
      "x": -42,
      "y": 59,
      "z": 5,
      "name": "Rock_Ice"
    },
    {
      "x": -42,
      "y": 60,
      "z": 5,
      "name": "Rock_Ice"
    },
    {
      "x": -42,
      "y": 61,
      "z": 5,
      "name": "Soil_Snow"
    },
    {
      "x": -42,
      "y": 46,
      "z": 6,
      "name": "Rock_Ice"
    },
    {
      "x": -42,
      "y": 47,
      "z": 6,
      "name": "Rock_Ice_Permafrost"
    },
    {
      "x": -42,
      "y": 48,
      "z": 6,
      "name": "Rock_Ice_Permafrost"
    },
    {
      "x": -42,
      "y": 49,
      "z": 6,
      "name": "Rock_Ice_Permafrost"
    },
    {
      "x": -42,
      "y": 50,
      "z": 6,
      "name": "Rock_Ice"
    },
    {
      "x": -42,
      "y": 51,
      "z": 6,
      "name": "Rock_Ice"
    },
    {
      "x": -42,
      "y": 52,
      "z": 6,
      "name": "Rock_Ice"
    },
    {
      "x": -42,
      "y": 53,
      "z": 6,
      "name": "Rock_Ice"
    },
    {
      "x": -42,
      "y": 54,
      "z": 6,
      "name": "Rock_Ice"
    },
    {
      "x": -42,
      "y": 55,
      "z": 6,
      "name": "Rock_Ice"
    },
    {
      "x": -42,
      "y": 56,
      "z": 6,
      "name": "Rock_Ice"
    },
    {
      "x": -42,
      "y": 57,
      "z": 6,
      "name": "Rock_Ice"
    },
    {
      "x": -42,
      "y": 58,
      "z": 6,
      "name": "Rock_Ice"
    },
    {
      "x": -42,
      "y": 59,
      "z": 6,
      "name": "Rock_Ice"
    },
    {
      "x": -42,
      "y": 60,
      "z": 6,
      "name": "Soil_Snow"
    },
    {
      "x": -42,
      "y": 45,
      "z": 7,
      "name": "Rock_Ice"
    },
    {
      "x": -42,
      "y": 46,
      "z": 7,
      "name": "Rock_Ice_Permafrost"
    },
    {
      "x": -42,
      "y": 47,
      "z": 7,
      "name": "Rock_Ice"
    },
    {
      "x": -42,
      "y": 48,
      "z": 7,
      "name": "Rock_Ice"
    },
    {
      "x": -42,
      "y": 49,
      "z": 7,
      "name": "Rock_Ice"
    },
    {
      "x": -42,
      "y": 50,
      "z": 7,
      "name": "Rock_Ice"
    },
    {
      "x": -42,
      "y": 51,
      "z": 7,
      "name": "Rock_Ice"
    },
    {
      "x": -42,
      "y": 52,
      "z": 7,
      "name": "Rock_Ice"
    },
    {
      "x": -42,
      "y": 53,
      "z": 7,
      "name": "Rock_Ice"
    },
    {
      "x": -42,
      "y": 54,
      "z": 7,
      "name": "Rock_Ice"
    },
    {
      "x": -42,
      "y": 55,
      "z": 7,
      "name": "Rock_Ice"
    },
    {
      "x": -42,
      "y": 56,
      "z": 7,
      "name": "Rock_Ice"
    },
    {
      "x": -42,
      "y": 57,
      "z": 7,
      "name": "Rock_Ice"
    },
    {
      "x": -42,
      "y": 58,
      "z": 7,
      "name": "Rock_Ice"
    },
    {
      "x": -42,
      "y": 59,
      "z": 7,
      "name": "Soil_Snow"
    },
    {
      "x": -42,
      "y": 45,
      "z": 8,
      "name": "Rock_Ice_Permafrost"
    },
    {
      "x": -42,
      "y": 46,
      "z": 8,
      "name": "Rock_Ice"
    },
    {
      "x": -42,
      "y": 47,
      "z": 8,
      "name": "Rock_Ice_Permafrost"
    },
    {
      "x": -42,
      "y": 48,
      "z": 8,
      "name": "Rock_Ice"
    },
    {
      "x": -42,
      "y": 49,
      "z": 8,
      "name": "Rock_Ice"
    },
    {
      "x": -42,
      "y": 50,
      "z": 8,
      "name": "Rock_Ice"
    },
    {
      "x": -42,
      "y": 51,
      "z": 8,
      "name": "Rock_Ice"
    },
    {
      "x": -42,
      "y": 52,
      "z": 8,
      "name": "Rock_Ice"
    },
    {
      "x": -42,
      "y": 53,
      "z": 8,
      "name": "Rock_Ice"
    },
    {
      "x": -42,
      "y": 54,
      "z": 8,
      "name": "Rock_Ice"
    },
    {
      "x": -42,
      "y": 55,
      "z": 8,
      "name": "Rock_Ice"
    },
    {
      "x": -42,
      "y": 56,
      "z": 8,
      "name": "Rock_Ice"
    },
    {
      "x": -42,
      "y": 57,
      "z": 8,
      "name": "Soil_Snow"
    },
    {
      "x": -42,
      "y": 44,
      "z": 9,
      "name": "Rock_Ice_Permafrost"
    },
    {
      "x": -42,
      "y": 45,
      "z": 9,
      "name": "Rock_Ice"
    },
    {
      "x": -42,
      "y": 46,
      "z": 9,
      "name": "Rock_Ice"
    },
    {
      "x": -42,
      "y": 47,
      "z": 9,
      "name": "Rock_Ice"
    },
    {
      "x": -42,
      "y": 48,
      "z": 9,
      "name": "Rock_Ice"
    },
    {
      "x": -42,
      "y": 49,
      "z": 9,
      "name": "Rock_Ice"
    },
    {
      "x": -42,
      "y": 50,
      "z": 9,
      "name": "Rock_Ice"
    },
    {
      "x": -42,
      "y": 51,
      "z": 9,
      "name": "Rock_Ice"
    },
    {
      "x": -42,
      "y": 52,
      "z": 9,
      "name": "Rock_Ice"
    },
    {
      "x": -42,
      "y": 53,
      "z": 9,
      "name": "Rock_Ice"
    },
    {
      "x": -42,
      "y": 54,
      "z": 9,
      "name": "Rock_Ice"
    },
    {
      "x": -42,
      "y": 55,
      "z": 9,
      "name": "Rock_Ice"
    },
    {
      "x": -42,
      "y": 56,
      "z": 9,
      "name": "Soil_Snow"
    },
    {
      "x": -42,
      "y": 43,
      "z": 10,
      "name": "Rock_Ice"
    },
    {
      "x": -42,
      "y": 44,
      "z": 10,
      "name": "Rock_Ice"
    },
    {
      "x": -42,
      "y": 45,
      "z": 10,
      "name": "Rock_Ice_Permafrost"
    },
    {
      "x": -42,
      "y": 46,
      "z": 10,
      "name": "Rock_Ice"
    },
    {
      "x": -42,
      "y": 47,
      "z": 10,
      "name": "Rock_Ice"
    },
    {
      "x": -42,
      "y": 48,
      "z": 10,
      "name": "Rock_Ice"
    },
    {
      "x": -42,
      "y": 49,
      "z": 10,
      "name": "Rock_Ice"
    },
    {
      "x": -42,
      "y": 55,
      "z": 10,
      "name": "Soil_Snow"
    },
    {
      "x": -42,
      "y": 43,
      "z": 11,
      "name": "Rock_Ice_Permafrost"
    },
    {
      "x": -42,
      "y": 44,
      "z": 11,
      "name": "Rock_Ice"
    },
    {
      "x": -42,
      "y": 45,
      "z": 11,
      "name": "Rock_Ice"
    },
    {
      "x": -42,
      "y": 46,
      "z": 11,
      "name": "Rock_Ice"
    },
    {
      "x": -42,
      "y": 47,
      "z": 11,
      "name": "Soil_Snow"
    },
    {
      "x": -42,
      "y": 42,
      "z": 12,
      "name": "Soil_Snow"
    },
    {
      "x": -41,
      "y": 61,
      "z": -11,
      "name": "Soil_Snow"
    },
    {
      "x": -41,
      "y": 60,
      "z": -10,
      "name": "Rock_Ice_Permafrost"
    },
    {
      "x": -41,
      "y": 61,
      "z": -10,
      "name": "Rock_Ice_Permafrost"
    },
    {
      "x": -41,
      "y": 62,
      "z": -10,
      "name": "Rock_Ice_Permafrost"
    },
    {
      "x": -41,
      "y": 63,
      "z": -10,
      "name": "Soil_Snow"
    },
    {
      "x": -41,
      "y": 59,
      "z": -9,
      "name": "Rock_Ice_Permafrost"
    },
    {
      "x": -41,
      "y": 60,
      "z": -9,
      "name": "Rock_Ice_Permafrost"
    },
    {
      "x": -41,
      "y": 61,
      "z": -9,
      "name": "Rock_Ice_Permafrost"
    },
    {
      "x": -41,
      "y": 62,
      "z": -9,
      "name": "Rock_Ice_Permafrost"
    },
    {
      "x": -41,
      "y": 63,
      "z": -9,
      "name": "Rock_Ice_Permafrost"
    },
    {
      "x": -41,
      "y": 64,
      "z": -9,
      "name": "Rock_Ice"
    },
    {
      "x": -41,
      "y": 65,
      "z": -9,
      "name": "Soil_Snow"
    },
    {
      "x": -41,
      "y": 58,
      "z": -8,
      "name": "Rock_Ice_Permafrost"
    },
    {
      "x": -41,
      "y": 59,
      "z": -8,
      "name": "Rock_Ice_Permafrost"
    },
    {
      "x": -41,
      "y": 60,
      "z": -8,
      "name": "Rock_Ice_Permafrost"
    },
    {
      "x": -41,
      "y": 61,
      "z": -8,
      "name": "Rock_Ice_Permafrost"
    },
    {
      "x": -41,
      "y": 62,
      "z": -8,
      "name": "Rock_Ice_Permafrost"
    },
    {
      "x": -41,
      "y": 63,
      "z": -8,
      "name": "Rock_Ice"
    },
    {
      "x": -41,
      "y": 64,
      "z": -8,
      "name": "Rock_Ice_Permafrost"
    },
    {
      "x": -41,
      "y": 65,
      "z": -8,
      "name": "Soil_Snow"
    },
    {
      "x": -41,
      "y": 57,
      "z": -7,
      "name": "Rock_Ice_Permafrost"
    },
    {
      "x": -41,
      "y": 58,
      "z": -7,
      "name": "Rock_Ice_Permafrost"
    },
    {
      "x": -41,
      "y": 59,
      "z": -7,
      "name": "Rock_Ice_Permafrost"
    },
    {
      "x": -41,
      "y": 60,
      "z": -7,
      "name": "Rock_Ice_Permafrost"
    },
    {
      "x": -41,
      "y": 61,
      "z": -7,
      "name": "Rock_Ice"
    },
    {
      "x": -41,
      "y": 62,
      "z": -7,
      "name": "Rock_Ice"
    },
    {
      "x": -41,
      "y": 63,
      "z": -7,
      "name": "Rock_Ice_Permafrost"
    },
    {
      "x": -41,
      "y": 64,
      "z": -7,
      "name": "Rock_Ice"
    },
    {
      "x": -41,
      "y": 65,
      "z": -7,
      "name": "Rock_Ice"
    },
    {
      "x": -41,
      "y": 66,
      "z": -7,
      "name": "Soil_Snow"
    },
    {
      "x": -41,
      "y": 56,
      "z": -6,
      "name": "Rock_Ice_Permafrost"
    },
    {
      "x": -41,
      "y": 57,
      "z": -6,
      "name": "Rock_Ice_Permafrost"
    },
    {
      "x": -41,
      "y": 58,
      "z": -6,
      "name": "Rock_Ice_Permafrost"
    },
    {
      "x": -41,
      "y": 59,
      "z": -6,
      "name": "Rock_Ice_Permafrost"
    },
    {
      "x": -41,
      "y": 60,
      "z": -6,
      "name": "Rock_Ice_Permafrost"
    },
    {
      "x": -41,
      "y": 61,
      "z": -6,
      "name": "Rock_Ice_Permafrost"
    },
    {
      "x": -41,
      "y": 62,
      "z": -6,
      "name": "Rock_Ice"
    },
    {
      "x": -41,
      "y": 63,
      "z": -6,
      "name": "Rock_Ice"
    },
    {
      "x": -41,
      "y": 64,
      "z": -6,
      "name": "Rock_Ice"
    },
    {
      "x": -41,
      "y": 65,
      "z": -6,
      "name": "Rock_Ice"
    },
    {
      "x": -41,
      "y": 66,
      "z": -6,
      "name": "Rock_Ice"
    },
    {
      "x": -41,
      "y": 67,
      "z": -6,
      "name": "Soil_Snow"
    },
    {
      "x": -41,
      "y": 55,
      "z": -5,
      "name": "Rock_Ice_Permafrost"
    },
    {
      "x": -41,
      "y": 56,
      "z": -5,
      "name": "Rock_Ice_Permafrost"
    },
    {
      "x": -41,
      "y": 57,
      "z": -5,
      "name": "Rock_Ice_Permafrost"
    },
    {
      "x": -41,
      "y": 58,
      "z": -5,
      "name": "Rock_Ice_Permafrost"
    },
    {
      "x": -41,
      "y": 59,
      "z": -5,
      "name": "Rock_Ice_Permafrost"
    },
    {
      "x": -41,
      "y": 60,
      "z": -5,
      "name": "Rock_Ice_Permafrost"
    },
    {
      "x": -41,
      "y": 61,
      "z": -5,
      "name": "Rock_Ice"
    },
    {
      "x": -41,
      "y": 62,
      "z": -5,
      "name": "Rock_Ice_Permafrost"
    },
    {
      "x": -41,
      "y": 63,
      "z": -5,
      "name": "Rock_Ice"
    },
    {
      "x": -41,
      "y": 64,
      "z": -5,
      "name": "Rock_Ice"
    },
    {
      "x": -41,
      "y": 65,
      "z": -5,
      "name": "Rock_Ice"
    },
    {
      "x": -41,
      "y": 66,
      "z": -5,
      "name": "Rock_Ice"
    },
    {
      "x": -41,
      "y": 67,
      "z": -5,
      "name": "Rock_Ice"
    },
    {
      "x": -41,
      "y": 68,
      "z": -5,
      "name": "Rock_Ice"
    },
    {
      "x": -41,
      "y": 69,
      "z": -5,
      "name": "Soil_Snow"
    },
    {
      "x": -41,
      "y": 54,
      "z": -4,
      "name": "Rock_Ice_Permafrost"
    },
    {
      "x": -41,
      "y": 55,
      "z": -4,
      "name": "Rock_Ice_Permafrost"
    },
    {
      "x": -41,
      "y": 56,
      "z": -4,
      "name": "Rock_Ice_Permafrost"
    },
    {
      "x": -41,
      "y": 57,
      "z": -4,
      "name": "Rock_Ice_Permafrost"
    },
    {
      "x": -41,
      "y": 58,
      "z": -4,
      "name": "Rock_Ice_Permafrost"
    },
    {
      "x": -41,
      "y": 59,
      "z": -4,
      "name": "Rock_Ice_Permafrost"
    },
    {
      "x": -41,
      "y": 60,
      "z": -4,
      "name": "Rock_Ice"
    },
    {
      "x": -41,
      "y": 61,
      "z": -4,
      "name": "Rock_Ice_Permafrost"
    },
    {
      "x": -41,
      "y": 62,
      "z": -4,
      "name": "Rock_Ice"
    },
    {
      "x": -41,
      "y": 63,
      "z": -4,
      "name": "Rock_Ice"
    },
    {
      "x": -41,
      "y": 64,
      "z": -4,
      "name": "Rock_Ice"
    },
    {
      "x": -41,
      "y": 65,
      "z": -4,
      "name": "Rock_Ice"
    },
    {
      "x": -41,
      "y": 66,
      "z": -4,
      "name": "Rock_Ice"
    },
    {
      "x": -41,
      "y": 67,
      "z": -4,
      "name": "Rock_Ice"
    },
    {
      "x": -41,
      "y": 68,
      "z": -4,
      "name": "Rock_Ice"
    },
    {
      "x": -41,
      "y": 69,
      "z": -4,
      "name": "Rock_Ice"
    },
    {
      "x": -41,
      "y": 70,
      "z": -4,
      "name": "Rock_Ice"
    },
    {
      "x": -41,
      "y": 53,
      "z": -3,
      "name": "Rock_Ice_Permafrost"
    },
    {
      "x": -41,
      "y": 54,
      "z": -3,
      "name": "Rock_Ice_Permafrost"
    },
    {
      "x": -41,
      "y": 55,
      "z": -3,
      "name": "Rock_Ice_Permafrost"
    },
    {
      "x": -41,
      "y": 56,
      "z": -3,
      "name": "Rock_Ice_Permafrost"
    },
    {
      "x": -41,
      "y": 57,
      "z": -3,
      "name": "Rock_Ice_Permafrost"
    },
    {
      "x": -41,
      "y": 58,
      "z": -3,
      "name": "Rock_Ice_Permafrost"
    },
    {
      "x": -41,
      "y": 59,
      "z": -3,
      "name": "Rock_Ice"
    },
    {
      "x": -41,
      "y": 60,
      "z": -3,
      "name": "Rock_Ice"
    },
    {
      "x": -41,
      "y": 61,
      "z": -3,
      "name": "Rock_Ice"
    },
    {
      "x": -41,
      "y": 62,
      "z": -3,
      "name": "Rock_Ice"
    },
    {
      "x": -41,
      "y": 63,
      "z": -3,
      "name": "Rock_Ice"
    },
    {
      "x": -41,
      "y": 64,
      "z": -3,
      "name": "Rock_Ice"
    },
    {
      "x": -41,
      "y": 65,
      "z": -3,
      "name": "Rock_Ice"
    },
    {
      "x": -41,
      "y": 66,
      "z": -3,
      "name": "Rock_Ice"
    },
    {
      "x": -41,
      "y": 67,
      "z": -3,
      "name": "Rock_Ice"
    },
    {
      "x": -41,
      "y": 68,
      "z": -3,
      "name": "Rock_Ice"
    },
    {
      "x": -41,
      "y": 69,
      "z": -3,
      "name": "Rock_Ice"
    },
    {
      "x": -41,
      "y": 70,
      "z": -3,
      "name": "Rock_Ice"
    },
    {
      "x": -41,
      "y": 71,
      "z": -3,
      "name": "Rock_Ice"
    },
    {
      "x": -41,
      "y": 52,
      "z": -2,
      "name": "Rock_Ice"
    },
    {
      "x": -41,
      "y": 53,
      "z": -2,
      "name": "Rock_Ice"
    },
    {
      "x": -41,
      "y": 54,
      "z": -2,
      "name": "Rock_Ice_Permafrost"
    },
    {
      "x": -41,
      "y": 55,
      "z": -2,
      "name": "Rock_Ice_Permafrost"
    },
    {
      "x": -41,
      "y": 56,
      "z": -2,
      "name": "Rock_Ice_Permafrost"
    },
    {
      "x": -41,
      "y": 57,
      "z": -2,
      "name": "Rock_Ice"
    },
    {
      "x": -41,
      "y": 58,
      "z": -2,
      "name": "Rock_Ice"
    },
    {
      "x": -41,
      "y": 59,
      "z": -2,
      "name": "Rock_Ice_Permafrost"
    },
    {
      "x": -41,
      "y": 60,
      "z": -2,
      "name": "Rock_Ice"
    },
    {
      "x": -41,
      "y": 61,
      "z": -2,
      "name": "Rock_Ice"
    },
    {
      "x": -41,
      "y": 62,
      "z": -2,
      "name": "Rock_Ice"
    },
    {
      "x": -41,
      "y": 63,
      "z": -2,
      "name": "Rock_Ice"
    },
    {
      "x": -41,
      "y": 64,
      "z": -2,
      "name": "Rock_Ice"
    },
    {
      "x": -41,
      "y": 65,
      "z": -2,
      "name": "Rock_Ice"
    },
    {
      "x": -41,
      "y": 66,
      "z": -2,
      "name": "Rock_Ice"
    },
    {
      "x": -41,
      "y": 67,
      "z": -2,
      "name": "Rock_Ice"
    },
    {
      "x": -41,
      "y": 68,
      "z": -2,
      "name": "Rock_Ice"
    },
    {
      "x": -41,
      "y": 69,
      "z": -2,
      "name": "Rock_Ice"
    },
    {
      "x": -41,
      "y": 70,
      "z": -2,
      "name": "Rock_Ice"
    },
    {
      "x": -41,
      "y": 71,
      "z": -2,
      "name": "Rock_Ice"
    },
    {
      "x": -41,
      "y": 51,
      "z": -1,
      "name": "Rock_Ice"
    },
    {
      "x": -41,
      "y": 52,
      "z": -1,
      "name": "Rock_Ice_Permafrost"
    },
    {
      "x": -41,
      "y": 53,
      "z": -1,
      "name": "Rock_Ice_Permafrost"
    },
    {
      "x": -41,
      "y": 54,
      "z": -1,
      "name": "Rock_Ice_Permafrost"
    },
    {
      "x": -41,
      "y": 55,
      "z": -1,
      "name": "Rock_Ice_Permafrost"
    },
    {
      "x": -41,
      "y": 56,
      "z": -1,
      "name": "Rock_Ice_Permafrost"
    },
    {
      "x": -41,
      "y": 57,
      "z": -1,
      "name": "Rock_Ice_Permafrost"
    },
    {
      "x": -41,
      "y": 58,
      "z": -1,
      "name": "Rock_Ice"
    },
    {
      "x": -41,
      "y": 59,
      "z": -1,
      "name": "Rock_Ice"
    },
    {
      "x": -41,
      "y": 60,
      "z": -1,
      "name": "Rock_Ice"
    },
    {
      "x": -41,
      "y": 61,
      "z": -1,
      "name": "Rock_Ice"
    },
    {
      "x": -41,
      "y": 62,
      "z": -1,
      "name": "Rock_Ice"
    },
    {
      "x": -41,
      "y": 63,
      "z": -1,
      "name": "Rock_Ice"
    },
    {
      "x": -41,
      "y": 64,
      "z": -1,
      "name": "Rock_Ice"
    },
    {
      "x": -41,
      "y": 65,
      "z": -1,
      "name": "Rock_Ice"
    },
    {
      "x": -41,
      "y": 66,
      "z": -1,
      "name": "Rock_Ice"
    },
    {
      "x": -41,
      "y": 67,
      "z": -1,
      "name": "Rock_Ice"
    },
    {
      "x": -41,
      "y": 68,
      "z": -1,
      "name": "Rock_Ice"
    },
    {
      "x": -41,
      "y": 69,
      "z": -1,
      "name": "Rock_Ice"
    },
    {
      "x": -41,
      "y": 70,
      "z": -1,
      "name": "Rock_Ice"
    },
    {
      "x": -41,
      "y": 71,
      "z": -1,
      "name": "Rock_Ice"
    },
    {
      "x": -41,
      "y": 50,
      "z": 0,
      "name": "Rock_Ice_Permafrost"
    },
    {
      "x": -41,
      "y": 51,
      "z": 0,
      "name": "Rock_Ice_Permafrost"
    },
    {
      "x": -41,
      "y": 52,
      "z": 0,
      "name": "Rock_Ice_Permafrost"
    },
    {
      "x": -41,
      "y": 53,
      "z": 0,
      "name": "Rock_Ice_Permafrost"
    },
    {
      "x": -41,
      "y": 54,
      "z": 0,
      "name": "Rock_Ice_Permafrost"
    },
    {
      "x": -41,
      "y": 55,
      "z": 0,
      "name": "Rock_Ice_Permafrost"
    },
    {
      "x": -41,
      "y": 56,
      "z": 0,
      "name": "Rock_Ice"
    },
    {
      "x": -41,
      "y": 57,
      "z": 0,
      "name": "Rock_Ice"
    },
    {
      "x": -41,
      "y": 58,
      "z": 0,
      "name": "Rock_Ice"
    },
    {
      "x": -41,
      "y": 59,
      "z": 0,
      "name": "Rock_Ice"
    },
    {
      "x": -41,
      "y": 60,
      "z": 0,
      "name": "Rock_Ice"
    },
    {
      "x": -41,
      "y": 61,
      "z": 0,
      "name": "Rock_Ice"
    },
    {
      "x": -41,
      "y": 62,
      "z": 0,
      "name": "Rock_Ice"
    },
    {
      "x": -41,
      "y": 63,
      "z": 0,
      "name": "Rock_Ice"
    },
    {
      "x": -41,
      "y": 64,
      "z": 0,
      "name": "Rock_Ice"
    },
    {
      "x": -41,
      "y": 65,
      "z": 0,
      "name": "Rock_Ice"
    },
    {
      "x": -41,
      "y": 66,
      "z": 0,
      "name": "Rock_Ice"
    },
    {
      "x": -41,
      "y": 67,
      "z": 0,
      "name": "Rock_Ice"
    },
    {
      "x": -41,
      "y": 68,
      "z": 0,
      "name": "Rock_Ice"
    },
    {
      "x": -41,
      "y": 69,
      "z": 0,
      "name": "Rock_Ice"
    },
    {
      "x": -41,
      "y": 70,
      "z": 0,
      "name": "Rock_Ice"
    },
    {
      "x": -41,
      "y": 71,
      "z": 0,
      "name": "Rock_Ice"
    },
    {
      "x": -41,
      "y": 49,
      "z": 1,
      "name": "Rock_Ice"
    },
    {
      "x": -41,
      "y": 50,
      "z": 1,
      "name": "Rock_Ice_Permafrost"
    },
    {
      "x": -41,
      "y": 51,
      "z": 1,
      "name": "Rock_Ice_Permafrost"
    },
    {
      "x": -41,
      "y": 52,
      "z": 1,
      "name": "Rock_Ice_Permafrost"
    },
    {
      "x": -41,
      "y": 53,
      "z": 1,
      "name": "Rock_Ice_Permafrost"
    },
    {
      "x": -41,
      "y": 54,
      "z": 1,
      "name": "Rock_Ice_Permafrost"
    },
    {
      "x": -41,
      "y": 55,
      "z": 1,
      "name": "Rock_Ice"
    },
    {
      "x": -41,
      "y": 56,
      "z": 1,
      "name": "Rock_Ice"
    },
    {
      "x": -41,
      "y": 57,
      "z": 1,
      "name": "Rock_Ice"
    },
    {
      "x": -41,
      "y": 58,
      "z": 1,
      "name": "Rock_Ice"
    },
    {
      "x": -41,
      "y": 59,
      "z": 1,
      "name": "Rock_Ice"
    },
    {
      "x": -41,
      "y": 60,
      "z": 1,
      "name": "Rock_Ice"
    },
    {
      "x": -41,
      "y": 61,
      "z": 1,
      "name": "Rock_Ice"
    },
    {
      "x": -41,
      "y": 62,
      "z": 1,
      "name": "Rock_Ice"
    },
    {
      "x": -41,
      "y": 63,
      "z": 1,
      "name": "Rock_Ice"
    },
    {
      "x": -41,
      "y": 64,
      "z": 1,
      "name": "Rock_Ice"
    },
    {
      "x": -41,
      "y": 65,
      "z": 1,
      "name": "Rock_Ice"
    },
    {
      "x": -41,
      "y": 66,
      "z": 1,
      "name": "Rock_Ice"
    },
    {
      "x": -41,
      "y": 67,
      "z": 1,
      "name": "Rock_Ice"
    },
    {
      "x": -41,
      "y": 68,
      "z": 1,
      "name": "Rock_Ice"
    },
    {
      "x": -41,
      "y": 69,
      "z": 1,
      "name": "Rock_Ice"
    },
    {
      "x": -41,
      "y": 70,
      "z": 1,
      "name": "Rock_Ice"
    },
    {
      "x": -41,
      "y": 71,
      "z": 1,
      "name": "Rock_Ice"
    },
    {
      "x": -41,
      "y": 48,
      "z": 2,
      "name": "Rock_Ice_Permafrost"
    },
    {
      "x": -41,
      "y": 49,
      "z": 2,
      "name": "Rock_Ice_Permafrost"
    },
    {
      "x": -41,
      "y": 50,
      "z": 2,
      "name": "Rock_Ice_Permafrost"
    },
    {
      "x": -41,
      "y": 51,
      "z": 2,
      "name": "Rock_Ice_Permafrost"
    },
    {
      "x": -41,
      "y": 52,
      "z": 2,
      "name": "Rock_Ice_Permafrost"
    },
    {
      "x": -41,
      "y": 53,
      "z": 2,
      "name": "Rock_Ice_Permafrost"
    },
    {
      "x": -41,
      "y": 54,
      "z": 2,
      "name": "Rock_Ice"
    },
    {
      "x": -41,
      "y": 55,
      "z": 2,
      "name": "Rock_Ice"
    },
    {
      "x": -41,
      "y": 56,
      "z": 2,
      "name": "Rock_Ice"
    },
    {
      "x": -41,
      "y": 57,
      "z": 2,
      "name": "Rock_Ice"
    },
    {
      "x": -41,
      "y": 58,
      "z": 2,
      "name": "Rock_Ice"
    },
    {
      "x": -41,
      "y": 59,
      "z": 2,
      "name": "Rock_Ice"
    },
    {
      "x": -41,
      "y": 60,
      "z": 2,
      "name": "Rock_Ice"
    },
    {
      "x": -41,
      "y": 61,
      "z": 2,
      "name": "Rock_Ice"
    },
    {
      "x": -41,
      "y": 62,
      "z": 2,
      "name": "Rock_Ice"
    },
    {
      "x": -41,
      "y": 63,
      "z": 2,
      "name": "Rock_Ice"
    },
    {
      "x": -41,
      "y": 64,
      "z": 2,
      "name": "Rock_Ice"
    },
    {
      "x": -41,
      "y": 65,
      "z": 2,
      "name": "Rock_Ice"
    },
    {
      "x": -41,
      "y": 66,
      "z": 2,
      "name": "Rock_Ice"
    },
    {
      "x": -41,
      "y": 67,
      "z": 2,
      "name": "Rock_Ice"
    },
    {
      "x": -41,
      "y": 68,
      "z": 2,
      "name": "Rock_Ice"
    },
    {
      "x": -41,
      "y": 69,
      "z": 2,
      "name": "Rock_Ice"
    },
    {
      "x": -41,
      "y": 70,
      "z": 2,
      "name": "Rock_Ice"
    },
    {
      "x": -41,
      "y": 71,
      "z": 2,
      "name": "Rock_Ice"
    },
    {
      "x": -41,
      "y": 47,
      "z": 3,
      "name": "Rock_Ice"
    },
    {
      "x": -41,
      "y": 48,
      "z": 3,
      "name": "Rock_Ice"
    },
    {
      "x": -41,
      "y": 49,
      "z": 3,
      "name": "Rock_Ice_Permafrost"
    },
    {
      "x": -41,
      "y": 50,
      "z": 3,
      "name": "Rock_Ice_Permafrost"
    },
    {
      "x": -41,
      "y": 51,
      "z": 3,
      "name": "Rock_Ice_Permafrost"
    },
    {
      "x": -41,
      "y": 52,
      "z": 3,
      "name": "Rock_Ice"
    },
    {
      "x": -41,
      "y": 53,
      "z": 3,
      "name": "Rock_Ice_Permafrost"
    },
    {
      "x": -41,
      "y": 54,
      "z": 3,
      "name": "Rock_Ice"
    },
    {
      "x": -41,
      "y": 55,
      "z": 3,
      "name": "Rock_Ice"
    },
    {
      "x": -41,
      "y": 56,
      "z": 3,
      "name": "Rock_Ice"
    },
    {
      "x": -41,
      "y": 57,
      "z": 3,
      "name": "Rock_Ice"
    },
    {
      "x": -41,
      "y": 58,
      "z": 3,
      "name": "Rock_Ice"
    },
    {
      "x": -41,
      "y": 59,
      "z": 3,
      "name": "Rock_Ice"
    },
    {
      "x": -41,
      "y": 60,
      "z": 3,
      "name": "Rock_Ice"
    },
    {
      "x": -41,
      "y": 61,
      "z": 3,
      "name": "Rock_Ice"
    },
    {
      "x": -41,
      "y": 62,
      "z": 3,
      "name": "Rock_Ice"
    },
    {
      "x": -41,
      "y": 63,
      "z": 3,
      "name": "Rock_Ice"
    },
    {
      "x": -41,
      "y": 64,
      "z": 3,
      "name": "Rock_Ice"
    },
    {
      "x": -41,
      "y": 65,
      "z": 3,
      "name": "Rock_Ice"
    },
    {
      "x": -41,
      "y": 66,
      "z": 3,
      "name": "Rock_Ice"
    },
    {
      "x": -41,
      "y": 67,
      "z": 3,
      "name": "Rock_Ice"
    },
    {
      "x": -41,
      "y": 68,
      "z": 3,
      "name": "Rock_Ice"
    },
    {
      "x": -41,
      "y": 69,
      "z": 3,
      "name": "Rock_Ice"
    },
    {
      "x": -41,
      "y": 70,
      "z": 3,
      "name": "Rock_Ice"
    },
    {
      "x": -41,
      "y": 46,
      "z": 4,
      "name": "Rock_Ice"
    },
    {
      "x": -41,
      "y": 47,
      "z": 4,
      "name": "Rock_Ice_Permafrost"
    },
    {
      "x": -41,
      "y": 48,
      "z": 4,
      "name": "Rock_Ice_Permafrost"
    },
    {
      "x": -41,
      "y": 49,
      "z": 4,
      "name": "Rock_Ice_Permafrost"
    },
    {
      "x": -41,
      "y": 50,
      "z": 4,
      "name": "Rock_Ice_Permafrost"
    },
    {
      "x": -41,
      "y": 51,
      "z": 4,
      "name": "Rock_Ice"
    },
    {
      "x": -41,
      "y": 52,
      "z": 4,
      "name": "Rock_Ice"
    },
    {
      "x": -41,
      "y": 53,
      "z": 4,
      "name": "Rock_Ice"
    },
    {
      "x": -41,
      "y": 54,
      "z": 4,
      "name": "Rock_Ice"
    },
    {
      "x": -41,
      "y": 55,
      "z": 4,
      "name": "Rock_Ice"
    },
    {
      "x": -41,
      "y": 56,
      "z": 4,
      "name": "Rock_Ice"
    },
    {
      "x": -41,
      "y": 57,
      "z": 4,
      "name": "Rock_Ice"
    },
    {
      "x": -41,
      "y": 58,
      "z": 4,
      "name": "Rock_Ice"
    },
    {
      "x": -41,
      "y": 59,
      "z": 4,
      "name": "Rock_Ice"
    },
    {
      "x": -41,
      "y": 60,
      "z": 4,
      "name": "Rock_Ice"
    },
    {
      "x": -41,
      "y": 61,
      "z": 4,
      "name": "Rock_Ice"
    },
    {
      "x": -41,
      "y": 62,
      "z": 4,
      "name": "Rock_Ice"
    },
    {
      "x": -41,
      "y": 63,
      "z": 4,
      "name": "Rock_Ice"
    },
    {
      "x": -41,
      "y": 64,
      "z": 4,
      "name": "Rock_Ice"
    },
    {
      "x": -41,
      "y": 65,
      "z": 4,
      "name": "Rock_Ice"
    },
    {
      "x": -41,
      "y": 66,
      "z": 4,
      "name": "Rock_Ice"
    },
    {
      "x": -41,
      "y": 67,
      "z": 4,
      "name": "Rock_Ice"
    },
    {
      "x": -41,
      "y": 68,
      "z": 4,
      "name": "Rock_Ice"
    },
    {
      "x": -41,
      "y": 45,
      "z": 5,
      "name": "Rock_Ice"
    },
    {
      "x": -41,
      "y": 46,
      "z": 5,
      "name": "Rock_Ice_Permafrost"
    },
    {
      "x": -41,
      "y": 47,
      "z": 5,
      "name": "Rock_Ice_Permafrost"
    },
    {
      "x": -41,
      "y": 48,
      "z": 5,
      "name": "Rock_Ice_Permafrost"
    },
    {
      "x": -41,
      "y": 49,
      "z": 5,
      "name": "Rock_Ice_Permafrost"
    },
    {
      "x": -41,
      "y": 50,
      "z": 5,
      "name": "Rock_Ice_Permafrost"
    },
    {
      "x": -41,
      "y": 51,
      "z": 5,
      "name": "Rock_Ice_Permafrost"
    },
    {
      "x": -41,
      "y": 52,
      "z": 5,
      "name": "Rock_Ice"
    },
    {
      "x": -41,
      "y": 53,
      "z": 5,
      "name": "Rock_Ice"
    },
    {
      "x": -41,
      "y": 54,
      "z": 5,
      "name": "Rock_Ice"
    },
    {
      "x": -41,
      "y": 55,
      "z": 5,
      "name": "Rock_Ice"
    },
    {
      "x": -41,
      "y": 56,
      "z": 5,
      "name": "Rock_Ice"
    },
    {
      "x": -41,
      "y": 57,
      "z": 5,
      "name": "Rock_Ice"
    },
    {
      "x": -41,
      "y": 58,
      "z": 5,
      "name": "Rock_Ice"
    },
    {
      "x": -41,
      "y": 59,
      "z": 5,
      "name": "Rock_Ice"
    },
    {
      "x": -41,
      "y": 60,
      "z": 5,
      "name": "Rock_Ice"
    },
    {
      "x": -41,
      "y": 61,
      "z": 5,
      "name": "Rock_Ice"
    },
    {
      "x": -41,
      "y": 62,
      "z": 5,
      "name": "Rock_Ice"
    },
    {
      "x": -41,
      "y": 63,
      "z": 5,
      "name": "Rock_Ice"
    },
    {
      "x": -41,
      "y": 64,
      "z": 5,
      "name": "Rock_Ice"
    },
    {
      "x": -41,
      "y": 65,
      "z": 5,
      "name": "Rock_Ice"
    },
    {
      "x": -41,
      "y": 66,
      "z": 5,
      "name": "Rock_Ice"
    },
    {
      "x": -41,
      "y": 67,
      "z": 5,
      "name": "Rock_Ice"
    },
    {
      "x": -41,
      "y": 44,
      "z": 6,
      "name": "Rock_Ice"
    },
    {
      "x": -41,
      "y": 45,
      "z": 6,
      "name": "Rock_Ice_Permafrost"
    },
    {
      "x": -41,
      "y": 46,
      "z": 6,
      "name": "Rock_Ice"
    },
    {
      "x": -41,
      "y": 47,
      "z": 6,
      "name": "Rock_Ice"
    },
    {
      "x": -41,
      "y": 48,
      "z": 6,
      "name": "Rock_Ice_Permafrost"
    },
    {
      "x": -41,
      "y": 49,
      "z": 6,
      "name": "Rock_Ice_Permafrost"
    },
    {
      "x": -41,
      "y": 50,
      "z": 6,
      "name": "Rock_Ice"
    },
    {
      "x": -41,
      "y": 51,
      "z": 6,
      "name": "Rock_Ice"
    },
    {
      "x": -41,
      "y": 52,
      "z": 6,
      "name": "Rock_Ice"
    },
    {
      "x": -41,
      "y": 53,
      "z": 6,
      "name": "Rock_Ice"
    },
    {
      "x": -41,
      "y": 54,
      "z": 6,
      "name": "Rock_Ice"
    },
    {
      "x": -41,
      "y": 55,
      "z": 6,
      "name": "Rock_Ice"
    },
    {
      "x": -41,
      "y": 56,
      "z": 6,
      "name": "Rock_Ice"
    },
    {
      "x": -41,
      "y": 57,
      "z": 6,
      "name": "Rock_Ice"
    },
    {
      "x": -41,
      "y": 58,
      "z": 6,
      "name": "Rock_Ice"
    },
    {
      "x": -41,
      "y": 59,
      "z": 6,
      "name": "Rock_Ice"
    },
    {
      "x": -41,
      "y": 60,
      "z": 6,
      "name": "Rock_Ice"
    },
    {
      "x": -41,
      "y": 61,
      "z": 6,
      "name": "Rock_Ice"
    },
    {
      "x": -41,
      "y": 62,
      "z": 6,
      "name": "Rock_Ice"
    },
    {
      "x": -41,
      "y": 63,
      "z": 6,
      "name": "Rock_Ice"
    },
    {
      "x": -41,
      "y": 64,
      "z": 6,
      "name": "Rock_Ice"
    },
    {
      "x": -41,
      "y": 43,
      "z": 7,
      "name": "Rock_Ice"
    },
    {
      "x": -41,
      "y": 44,
      "z": 7,
      "name": "Rock_Ice"
    },
    {
      "x": -41,
      "y": 45,
      "z": 7,
      "name": "Rock_Ice"
    },
    {
      "x": -41,
      "y": 46,
      "z": 7,
      "name": "Rock_Ice_Permafrost"
    },
    {
      "x": -41,
      "y": 47,
      "z": 7,
      "name": "Rock_Ice"
    },
    {
      "x": -41,
      "y": 48,
      "z": 7,
      "name": "Rock_Ice_Permafrost"
    },
    {
      "x": -41,
      "y": 49,
      "z": 7,
      "name": "Rock_Ice"
    },
    {
      "x": -41,
      "y": 50,
      "z": 7,
      "name": "Rock_Ice"
    },
    {
      "x": -41,
      "y": 51,
      "z": 7,
      "name": "Rock_Ice"
    },
    {
      "x": -41,
      "y": 52,
      "z": 7,
      "name": "Rock_Ice"
    },
    {
      "x": -41,
      "y": 53,
      "z": 7,
      "name": "Rock_Ice"
    },
    {
      "x": -41,
      "y": 54,
      "z": 7,
      "name": "Rock_Ice"
    },
    {
      "x": -41,
      "y": 55,
      "z": 7,
      "name": "Rock_Ice"
    },
    {
      "x": -41,
      "y": 56,
      "z": 7,
      "name": "Rock_Ice"
    },
    {
      "x": -41,
      "y": 57,
      "z": 7,
      "name": "Rock_Ice"
    },
    {
      "x": -41,
      "y": 58,
      "z": 7,
      "name": "Rock_Ice"
    },
    {
      "x": -41,
      "y": 59,
      "z": 7,
      "name": "Rock_Ice"
    },
    {
      "x": -41,
      "y": 60,
      "z": 7,
      "name": "Rock_Ice"
    },
    {
      "x": -41,
      "y": 61,
      "z": 7,
      "name": "Rock_Ice"
    },
    {
      "x": -41,
      "y": 62,
      "z": 7,
      "name": "Soil_Snow"
    },
    {
      "x": -41,
      "y": 43,
      "z": 8,
      "name": "Rock_Ice"
    },
    {
      "x": -41,
      "y": 44,
      "z": 8,
      "name": "Rock_Ice"
    },
    {
      "x": -41,
      "y": 45,
      "z": 8,
      "name": "Rock_Ice"
    },
    {
      "x": -41,
      "y": 46,
      "z": 8,
      "name": "Rock_Ice"
    },
    {
      "x": -41,
      "y": 47,
      "z": 8,
      "name": "Rock_Ice_Permafrost"
    },
    {
      "x": -41,
      "y": 48,
      "z": 8,
      "name": "Rock_Ice"
    },
    {
      "x": -41,
      "y": 49,
      "z": 8,
      "name": "Rock_Ice"
    },
    {
      "x": -41,
      "y": 50,
      "z": 8,
      "name": "Rock_Ice"
    },
    {
      "x": -41,
      "y": 51,
      "z": 8,
      "name": "Rock_Ice"
    },
    {
      "x": -41,
      "y": 52,
      "z": 8,
      "name": "Rock_Ice"
    },
    {
      "x": -41,
      "y": 53,
      "z": 8,
      "name": "Rock_Ice"
    },
    {
      "x": -41,
      "y": 54,
      "z": 8,
      "name": "Rock_Ice"
    },
    {
      "x": -41,
      "y": 55,
      "z": 8,
      "name": "Rock_Ice"
    },
    {
      "x": -41,
      "y": 56,
      "z": 8,
      "name": "Rock_Ice"
    },
    {
      "x": -41,
      "y": 57,
      "z": 8,
      "name": "Rock_Ice"
    },
    {
      "x": -41,
      "y": 58,
      "z": 8,
      "name": "Rock_Ice"
    },
    {
      "x": -41,
      "y": 59,
      "z": 8,
      "name": "Soil_Snow"
    },
    {
      "x": -41,
      "y": 42,
      "z": 9,
      "name": "Rock_Ice"
    },
    {
      "x": -41,
      "y": 43,
      "z": 9,
      "name": "Rock_Ice_Permafrost"
    },
    {
      "x": -41,
      "y": 44,
      "z": 9,
      "name": "Rock_Ice"
    },
    {
      "x": -41,
      "y": 45,
      "z": 9,
      "name": "Rock_Ice_Permafrost"
    },
    {
      "x": -41,
      "y": 46,
      "z": 9,
      "name": "Rock_Ice_Permafrost"
    },
    {
      "x": -41,
      "y": 47,
      "z": 9,
      "name": "Rock_Ice"
    },
    {
      "x": -41,
      "y": 48,
      "z": 9,
      "name": "Rock_Ice"
    },
    {
      "x": -41,
      "y": 49,
      "z": 9,
      "name": "Rock_Ice"
    },
    {
      "x": -41,
      "y": 50,
      "z": 9,
      "name": "Rock_Ice"
    },
    {
      "x": -41,
      "y": 51,
      "z": 9,
      "name": "Rock_Ice"
    },
    {
      "x": -41,
      "y": 52,
      "z": 9,
      "name": "Rock_Ice"
    },
    {
      "x": -41,
      "y": 53,
      "z": 9,
      "name": "Rock_Ice"
    },
    {
      "x": -41,
      "y": 54,
      "z": 9,
      "name": "Rock_Ice"
    },
    {
      "x": -41,
      "y": 55,
      "z": 9,
      "name": "Rock_Ice"
    },
    {
      "x": -41,
      "y": 56,
      "z": 9,
      "name": "Rock_Ice"
    },
    {
      "x": -41,
      "y": 57,
      "z": 9,
      "name": "Soil_Snow"
    },
    {
      "x": -41,
      "y": 42,
      "z": 10,
      "name": "Rock_Ice"
    },
    {
      "x": -41,
      "y": 43,
      "z": 10,
      "name": "Rock_Ice"
    },
    {
      "x": -41,
      "y": 44,
      "z": 10,
      "name": "Rock_Ice"
    },
    {
      "x": -41,
      "y": 45,
      "z": 10,
      "name": "Rock_Ice"
    },
    {
      "x": -41,
      "y": 46,
      "z": 10,
      "name": "Rock_Ice"
    },
    {
      "x": -41,
      "y": 47,
      "z": 10,
      "name": "Rock_Ice"
    },
    {
      "x": -41,
      "y": 48,
      "z": 10,
      "name": "Rock_Ice"
    },
    {
      "x": -41,
      "y": 49,
      "z": 10,
      "name": "Rock_Ice"
    },
    {
      "x": -41,
      "y": 50,
      "z": 10,
      "name": "Rock_Ice"
    },
    {
      "x": -41,
      "y": 51,
      "z": 10,
      "name": "Rock_Ice"
    },
    {
      "x": -41,
      "y": 52,
      "z": 10,
      "name": "Rock_Ice"
    },
    {
      "x": -41,
      "y": 53,
      "z": 10,
      "name": "Rock_Ice"
    },
    {
      "x": -41,
      "y": 54,
      "z": 10,
      "name": "Rock_Ice"
    },
    {
      "x": -41,
      "y": 55,
      "z": 10,
      "name": "Soil_Snow"
    },
    {
      "x": -41,
      "y": 41,
      "z": 11,
      "name": "Rock_Ice"
    },
    {
      "x": -41,
      "y": 42,
      "z": 11,
      "name": "Rock_Ice"
    },
    {
      "x": -41,
      "y": 43,
      "z": 11,
      "name": "Rock_Ice_Permafrost"
    },
    {
      "x": -41,
      "y": 44,
      "z": 11,
      "name": "Rock_Ice"
    },
    {
      "x": -41,
      "y": 45,
      "z": 11,
      "name": "Rock_Ice"
    },
    {
      "x": -41,
      "y": 46,
      "z": 11,
      "name": "Rock_Ice"
    },
    {
      "x": -41,
      "y": 47,
      "z": 11,
      "name": "Rock_Ice"
    },
    {
      "x": -41,
      "y": 48,
      "z": 11,
      "name": "Rock_Ice"
    },
    {
      "x": -41,
      "y": 49,
      "z": 11,
      "name": "Rock_Ice"
    },
    {
      "x": -41,
      "y": 50,
      "z": 11,
      "name": "Rock_Ice"
    },
    {
      "x": -41,
      "y": 51,
      "z": 11,
      "name": "Rock_Ice"
    },
    {
      "x": -41,
      "y": 52,
      "z": 11,
      "name": "Rock_Ice"
    },
    {
      "x": -41,
      "y": 53,
      "z": 11,
      "name": "Rock_Ice"
    },
    {
      "x": -41,
      "y": 54,
      "z": 11,
      "name": "Soil_Snow"
    },
    {
      "x": -41,
      "y": 40,
      "z": 12,
      "name": "Rock_Ice"
    },
    {
      "x": -41,
      "y": 41,
      "z": 12,
      "name": "Rock_Ice"
    },
    {
      "x": -41,
      "y": 42,
      "z": 12,
      "name": "Rock_Ice"
    },
    {
      "x": -41,
      "y": 43,
      "z": 12,
      "name": "Rock_Ice"
    },
    {
      "x": -41,
      "y": 44,
      "z": 12,
      "name": "Rock_Ice"
    },
    {
      "x": -41,
      "y": 45,
      "z": 12,
      "name": "Rock_Ice"
    },
    {
      "x": -41,
      "y": 46,
      "z": 12,
      "name": "Rock_Ice"
    },
    {
      "x": -41,
      "y": 47,
      "z": 12,
      "name": "Rock_Ice"
    },
    {
      "x": -41,
      "y": 48,
      "z": 12,
      "name": "Rock_Ice"
    },
    {
      "x": -41,
      "y": 49,
      "z": 12,
      "name": "Rock_Ice"
    },
    {
      "x": -41,
      "y": 50,
      "z": 12,
      "name": "Rock_Ice"
    },
    {
      "x": -41,
      "y": 51,
      "z": 12,
      "name": "Rock_Ice"
    },
    {
      "x": -41,
      "y": 52,
      "z": 12,
      "name": "Soil_Snow"
    },
    {
      "x": -41,
      "y": 40,
      "z": 13,
      "name": "Rock_Ice"
    },
    {
      "x": -41,
      "y": 41,
      "z": 13,
      "name": "Rock_Ice"
    },
    {
      "x": -41,
      "y": 45,
      "z": 13,
      "name": "Rock_Ice"
    },
    {
      "x": -41,
      "y": 50,
      "z": 13,
      "name": "Soil_Snow"
    },
    {
      "x": -40,
      "y": 62,
      "z": -13,
      "name": "Soil_Snow"
    },
    {
      "x": -40,
      "y": 61,
      "z": -12,
      "name": "Rock_Ice_Permafrost"
    },
    {
      "x": -40,
      "y": 62,
      "z": -12,
      "name": "Soil_Snow"
    },
    {
      "x": -40,
      "y": 59,
      "z": -11,
      "name": "Rock_Ice_Permafrost"
    },
    {
      "x": -40,
      "y": 60,
      "z": -11,
      "name": "Rock_Ice_Permafrost"
    },
    {
      "x": -40,
      "y": 61,
      "z": -11,
      "name": "Rock_Ice_Permafrost"
    },
    {
      "x": -40,
      "y": 62,
      "z": -11,
      "name": "Rock_Ice_Permafrost"
    },
    {
      "x": -40,
      "y": 63,
      "z": -11,
      "name": "Rock_Ice_Permafrost"
    },
    {
      "x": -40,
      "y": 64,
      "z": -11,
      "name": "Rock_Ice_Permafrost"
    },
    {
      "x": -40,
      "y": 65,
      "z": -11,
      "name": "Rock_Ice"
    },
    {
      "x": -40,
      "y": 66,
      "z": -11,
      "name": "Soil_Snow"
    },
    {
      "x": -40,
      "y": 58,
      "z": -10,
      "name": "Rock_Ice_Permafrost"
    },
    {
      "x": -40,
      "y": 59,
      "z": -10,
      "name": "Rock_Ice_Permafrost"
    },
    {
      "x": -40,
      "y": 60,
      "z": -10,
      "name": "Rock_Ice_Permafrost"
    },
    {
      "x": -40,
      "y": 61,
      "z": -10,
      "name": "Rock_Ice_Permafrost"
    },
    {
      "x": -40,
      "y": 62,
      "z": -10,
      "name": "Rock_Ice_Permafrost"
    },
    {
      "x": -40,
      "y": 63,
      "z": -10,
      "name": "Rock_Ice_Permafrost"
    },
    {
      "x": -40,
      "y": 64,
      "z": -10,
      "name": "Rock_Ice"
    },
    {
      "x": -40,
      "y": 65,
      "z": -10,
      "name": "Rock_Ice"
    },
    {
      "x": -40,
      "y": 66,
      "z": -10,
      "name": "Rock_Ice"
    },
    {
      "x": -40,
      "y": 67,
      "z": -10,
      "name": "Soil_Snow"
    },
    {
      "x": -40,
      "y": 57,
      "z": -9,
      "name": "Rock_Ice_Permafrost"
    },
    {
      "x": -40,
      "y": 58,
      "z": -9,
      "name": "Rock_Ice_Permafrost"
    },
    {
      "x": -40,
      "y": 59,
      "z": -9,
      "name": "Rock_Ice_Permafrost"
    },
    {
      "x": -40,
      "y": 60,
      "z": -9,
      "name": "Rock_Ice_Permafrost"
    },
    {
      "x": -40,
      "y": 61,
      "z": -9,
      "name": "Rock_Ice_Permafrost"
    },
    {
      "x": -40,
      "y": 62,
      "z": -9,
      "name": "Rock_Ice_Permafrost"
    },
    {
      "x": -40,
      "y": 63,
      "z": -9,
      "name": "Rock_Ice"
    },
    {
      "x": -40,
      "y": 64,
      "z": -9,
      "name": "Rock_Ice"
    },
    {
      "x": -40,
      "y": 65,
      "z": -9,
      "name": "Rock_Ice"
    },
    {
      "x": -40,
      "y": 66,
      "z": -9,
      "name": "Rock_Ice"
    },
    {
      "x": -40,
      "y": 67,
      "z": -9,
      "name": "Rock_Ice"
    },
    {
      "x": -40,
      "y": 68,
      "z": -9,
      "name": "Rock_Ice"
    },
    {
      "x": -40,
      "y": 69,
      "z": -9,
      "name": "Soil_Snow"
    },
    {
      "x": -40,
      "y": 56,
      "z": -8,
      "name": "Rock_Ice_Permafrost"
    },
    {
      "x": -40,
      "y": 57,
      "z": -8,
      "name": "Rock_Ice_Permafrost"
    },
    {
      "x": -40,
      "y": 58,
      "z": -8,
      "name": "Rock_Ice_Permafrost"
    },
    {
      "x": -40,
      "y": 59,
      "z": -8,
      "name": "Rock_Ice_Permafrost"
    },
    {
      "x": -40,
      "y": 60,
      "z": -8,
      "name": "Rock_Ice_Permafrost"
    },
    {
      "x": -40,
      "y": 61,
      "z": -8,
      "name": "Rock_Ice_Permafrost"
    },
    {
      "x": -40,
      "y": 62,
      "z": -8,
      "name": "Rock_Ice_Permafrost"
    },
    {
      "x": -40,
      "y": 63,
      "z": -8,
      "name": "Rock_Ice"
    },
    {
      "x": -40,
      "y": 64,
      "z": -8,
      "name": "Rock_Ice"
    },
    {
      "x": -40,
      "y": 65,
      "z": -8,
      "name": "Rock_Ice"
    },
    {
      "x": -40,
      "y": 66,
      "z": -8,
      "name": "Rock_Ice"
    },
    {
      "x": -40,
      "y": 67,
      "z": -8,
      "name": "Rock_Ice"
    },
    {
      "x": -40,
      "y": 68,
      "z": -8,
      "name": "Rock_Ice"
    },
    {
      "x": -40,
      "y": 69,
      "z": -8,
      "name": "Rock_Ice"
    },
    {
      "x": -40,
      "y": 70,
      "z": -8,
      "name": "Rock_Ice"
    },
    {
      "x": -40,
      "y": 71,
      "z": -8,
      "name": "Rock_Ice"
    },
    {
      "x": -40,
      "y": 72,
      "z": -8,
      "name": "Rock_Ice"
    },
    {
      "x": -40,
      "y": 55,
      "z": -7,
      "name": "Rock_Ice_Permafrost"
    },
    {
      "x": -40,
      "y": 56,
      "z": -7,
      "name": "Rock_Ice_Permafrost"
    },
    {
      "x": -40,
      "y": 57,
      "z": -7,
      "name": "Rock_Ice_Permafrost"
    },
    {
      "x": -40,
      "y": 58,
      "z": -7,
      "name": "Rock_Ice_Permafrost"
    },
    {
      "x": -40,
      "y": 59,
      "z": -7,
      "name": "Rock_Ice_Permafrost"
    },
    {
      "x": -40,
      "y": 60,
      "z": -7,
      "name": "Rock_Ice_Permafrost"
    },
    {
      "x": -40,
      "y": 61,
      "z": -7,
      "name": "Rock_Ice_Permafrost"
    },
    {
      "x": -40,
      "y": 62,
      "z": -7,
      "name": "Rock_Ice_Permafrost"
    },
    {
      "x": -40,
      "y": 63,
      "z": -7,
      "name": "Rock_Ice"
    },
    {
      "x": -40,
      "y": 64,
      "z": -7,
      "name": "Rock_Ice"
    },
    {
      "x": -40,
      "y": 65,
      "z": -7,
      "name": "Rock_Ice"
    },
    {
      "x": -40,
      "y": 66,
      "z": -7,
      "name": "Rock_Ice"
    },
    {
      "x": -40,
      "y": 67,
      "z": -7,
      "name": "Rock_Ice"
    },
    {
      "x": -40,
      "y": 68,
      "z": -7,
      "name": "Rock_Ice"
    },
    {
      "x": -40,
      "y": 69,
      "z": -7,
      "name": "Rock_Ice"
    },
    {
      "x": -40,
      "y": 70,
      "z": -7,
      "name": "Rock_Ice"
    },
    {
      "x": -40,
      "y": 71,
      "z": -7,
      "name": "Rock_Ice"
    },
    {
      "x": -40,
      "y": 72,
      "z": -7,
      "name": "Rock_Ice"
    },
    {
      "x": -40,
      "y": 73,
      "z": -7,
      "name": "Rock_Ice"
    },
    {
      "x": -40,
      "y": 74,
      "z": -7,
      "name": "Soil_Snow"
    },
    {
      "x": -40,
      "y": 54,
      "z": -6,
      "name": "Rock_Ice"
    },
    {
      "x": -40,
      "y": 55,
      "z": -6,
      "name": "Rock_Ice"
    },
    {
      "x": -40,
      "y": 56,
      "z": -6,
      "name": "Rock_Ice_Permafrost"
    },
    {
      "x": -40,
      "y": 57,
      "z": -6,
      "name": "Rock_Ice_Permafrost"
    },
    {
      "x": -40,
      "y": 58,
      "z": -6,
      "name": "Rock_Ice_Permafrost"
    },
    {
      "x": -40,
      "y": 59,
      "z": -6,
      "name": "Rock_Ice_Permafrost"
    },
    {
      "x": -40,
      "y": 60,
      "z": -6,
      "name": "Rock_Ice_Permafrost"
    },
    {
      "x": -40,
      "y": 61,
      "z": -6,
      "name": "Rock_Ice"
    },
    {
      "x": -40,
      "y": 62,
      "z": -6,
      "name": "Rock_Ice"
    },
    {
      "x": -40,
      "y": 63,
      "z": -6,
      "name": "Rock_Ice"
    },
    {
      "x": -40,
      "y": 64,
      "z": -6,
      "name": "Rock_Ice"
    },
    {
      "x": -40,
      "y": 65,
      "z": -6,
      "name": "Rock_Ice"
    },
    {
      "x": -40,
      "y": 66,
      "z": -6,
      "name": "Rock_Ice"
    },
    {
      "x": -40,
      "y": 67,
      "z": -6,
      "name": "Rock_Ice"
    },
    {
      "x": -40,
      "y": 68,
      "z": -6,
      "name": "Rock_Ice"
    },
    {
      "x": -40,
      "y": 69,
      "z": -6,
      "name": "Rock_Ice"
    },
    {
      "x": -40,
      "y": 70,
      "z": -6,
      "name": "Rock_Ice"
    },
    {
      "x": -40,
      "y": 71,
      "z": -6,
      "name": "Rock_Ice"
    },
    {
      "x": -40,
      "y": 72,
      "z": -6,
      "name": "Rock_Ice"
    },
    {
      "x": -40,
      "y": 73,
      "z": -6,
      "name": "Rock_Ice"
    },
    {
      "x": -40,
      "y": 74,
      "z": -6,
      "name": "Rock_Ice"
    },
    {
      "x": -40,
      "y": 75,
      "z": -6,
      "name": "Soil_Snow"
    },
    {
      "x": -40,
      "y": 53,
      "z": -5,
      "name": "Rock_Ice_Permafrost"
    },
    {
      "x": -40,
      "y": 54,
      "z": -5,
      "name": "Rock_Ice_Permafrost"
    },
    {
      "x": -40,
      "y": 55,
      "z": -5,
      "name": "Rock_Ice_Permafrost"
    },
    {
      "x": -40,
      "y": 56,
      "z": -5,
      "name": "Rock_Ice_Permafrost"
    },
    {
      "x": -40,
      "y": 57,
      "z": -5,
      "name": "Rock_Ice_Permafrost"
    },
    {
      "x": -40,
      "y": 58,
      "z": -5,
      "name": "Rock_Ice_Permafrost"
    },
    {
      "x": -40,
      "y": 59,
      "z": -5,
      "name": "Rock_Ice_Permafrost"
    },
    {
      "x": -40,
      "y": 60,
      "z": -5,
      "name": "Rock_Ice"
    },
    {
      "x": -40,
      "y": 61,
      "z": -5,
      "name": "Rock_Ice"
    },
    {
      "x": -40,
      "y": 62,
      "z": -5,
      "name": "Rock_Ice"
    },
    {
      "x": -40,
      "y": 63,
      "z": -5,
      "name": "Rock_Ice"
    },
    {
      "x": -40,
      "y": 64,
      "z": -5,
      "name": "Rock_Ice"
    },
    {
      "x": -40,
      "y": 65,
      "z": -5,
      "name": "Rock_Ice"
    },
    {
      "x": -40,
      "y": 66,
      "z": -5,
      "name": "Rock_Ice"
    },
    {
      "x": -40,
      "y": 67,
      "z": -5,
      "name": "Rock_Ice"
    },
    {
      "x": -40,
      "y": 68,
      "z": -5,
      "name": "Rock_Ice"
    },
    {
      "x": -40,
      "y": 69,
      "z": -5,
      "name": "Rock_Ice"
    },
    {
      "x": -40,
      "y": 70,
      "z": -5,
      "name": "Rock_Ice"
    },
    {
      "x": -40,
      "y": 71,
      "z": -5,
      "name": "Rock_Ice"
    },
    {
      "x": -40,
      "y": 72,
      "z": -5,
      "name": "Rock_Ice"
    },
    {
      "x": -40,
      "y": 73,
      "z": -5,
      "name": "Rock_Ice"
    },
    {
      "x": -40,
      "y": 74,
      "z": -5,
      "name": "Rock_Ice"
    },
    {
      "x": -40,
      "y": 75,
      "z": -5,
      "name": "Rock_Ice"
    },
    {
      "x": -40,
      "y": 76,
      "z": -5,
      "name": "Soil_Snow"
    },
    {
      "x": -40,
      "y": 53,
      "z": -4,
      "name": "Rock_Ice_Permafrost"
    },
    {
      "x": -40,
      "y": 54,
      "z": -4,
      "name": "Rock_Ice_Permafrost"
    },
    {
      "x": -40,
      "y": 55,
      "z": -4,
      "name": "Rock_Ice_Permafrost"
    },
    {
      "x": -40,
      "y": 56,
      "z": -4,
      "name": "Rock_Ice_Permafrost"
    },
    {
      "x": -40,
      "y": 57,
      "z": -4,
      "name": "Rock_Ice_Permafrost"
    },
    {
      "x": -40,
      "y": 58,
      "z": -4,
      "name": "Rock_Ice_Permafrost"
    },
    {
      "x": -40,
      "y": 59,
      "z": -4,
      "name": "Rock_Ice_Permafrost"
    },
    {
      "x": -40,
      "y": 60,
      "z": -4,
      "name": "Rock_Ice_Permafrost"
    },
    {
      "x": -40,
      "y": 61,
      "z": -4,
      "name": "Rock_Ice"
    },
    {
      "x": -40,
      "y": 62,
      "z": -4,
      "name": "Rock_Ice"
    },
    {
      "x": -40,
      "y": 63,
      "z": -4,
      "name": "Rock_Ice"
    },
    {
      "x": -40,
      "y": 64,
      "z": -4,
      "name": "Rock_Ice"
    },
    {
      "x": -40,
      "y": 65,
      "z": -4,
      "name": "Rock_Ice"
    },
    {
      "x": -40,
      "y": 66,
      "z": -4,
      "name": "Rock_Ice"
    },
    {
      "x": -40,
      "y": 67,
      "z": -4,
      "name": "Rock_Ice"
    },
    {
      "x": -40,
      "y": 68,
      "z": -4,
      "name": "Rock_Ice"
    },
    {
      "x": -40,
      "y": 69,
      "z": -4,
      "name": "Rock_Ice"
    },
    {
      "x": -40,
      "y": 70,
      "z": -4,
      "name": "Rock_Ice"
    },
    {
      "x": -40,
      "y": 71,
      "z": -4,
      "name": "Rock_Ice"
    },
    {
      "x": -40,
      "y": 72,
      "z": -4,
      "name": "Rock_Ice"
    },
    {
      "x": -40,
      "y": 73,
      "z": -4,
      "name": "Rock_Ice"
    },
    {
      "x": -40,
      "y": 74,
      "z": -4,
      "name": "Rock_Ice"
    },
    {
      "x": -40,
      "y": 75,
      "z": -4,
      "name": "Rock_Ice"
    },
    {
      "x": -40,
      "y": 76,
      "z": -4,
      "name": "Rock_Ice"
    },
    {
      "x": -40,
      "y": 77,
      "z": -4,
      "name": "Rock_Ice"
    },
    {
      "x": -40,
      "y": 78,
      "z": -4,
      "name": "Rock_Ice"
    },
    {
      "x": -40,
      "y": 79,
      "z": -4,
      "name": "Rock_Ice"
    },
    {
      "x": -40,
      "y": 80,
      "z": -4,
      "name": "Rock_Ice"
    },
    {
      "x": -40,
      "y": 81,
      "z": -4,
      "name": "Rock_Ice"
    },
    {
      "x": -40,
      "y": 82,
      "z": -4,
      "name": "Rock_Ice_Permafrost"
    },
    {
      "x": -40,
      "y": 52,
      "z": -3,
      "name": "Rock_Ice_Permafrost"
    },
    {
      "x": -40,
      "y": 53,
      "z": -3,
      "name": "Rock_Ice"
    },
    {
      "x": -40,
      "y": 54,
      "z": -3,
      "name": "Rock_Ice_Permafrost"
    },
    {
      "x": -40,
      "y": 55,
      "z": -3,
      "name": "Rock_Ice_Permafrost"
    },
    {
      "x": -40,
      "y": 56,
      "z": -3,
      "name": "Rock_Ice_Permafrost"
    },
    {
      "x": -40,
      "y": 57,
      "z": -3,
      "name": "Rock_Ice_Permafrost"
    },
    {
      "x": -40,
      "y": 58,
      "z": -3,
      "name": "Rock_Ice_Permafrost"
    },
    {
      "x": -40,
      "y": 59,
      "z": -3,
      "name": "Rock_Ice"
    },
    {
      "x": -40,
      "y": 60,
      "z": -3,
      "name": "Rock_Ice"
    },
    {
      "x": -40,
      "y": 61,
      "z": -3,
      "name": "Rock_Ice"
    },
    {
      "x": -40,
      "y": 62,
      "z": -3,
      "name": "Rock_Ice"
    },
    {
      "x": -40,
      "y": 63,
      "z": -3,
      "name": "Rock_Ice"
    },
    {
      "x": -40,
      "y": 64,
      "z": -3,
      "name": "Rock_Ice"
    },
    {
      "x": -40,
      "y": 65,
      "z": -3,
      "name": "Rock_Ice"
    },
    {
      "x": -40,
      "y": 66,
      "z": -3,
      "name": "Rock_Ice"
    },
    {
      "x": -40,
      "y": 67,
      "z": -3,
      "name": "Rock_Ice"
    },
    {
      "x": -40,
      "y": 68,
      "z": -3,
      "name": "Rock_Ice"
    },
    {
      "x": -40,
      "y": 69,
      "z": -3,
      "name": "Rock_Ice"
    },
    {
      "x": -40,
      "y": 70,
      "z": -3,
      "name": "Rock_Ice"
    },
    {
      "x": -40,
      "y": 71,
      "z": -3,
      "name": "Rock_Ice"
    },
    {
      "x": -40,
      "y": 72,
      "z": -3,
      "name": "Rock_Ice"
    },
    {
      "x": -40,
      "y": 73,
      "z": -3,
      "name": "Rock_Ice"
    },
    {
      "x": -40,
      "y": 74,
      "z": -3,
      "name": "Rock_Ice"
    },
    {
      "x": -40,
      "y": 75,
      "z": -3,
      "name": "Rock_Ice"
    },
    {
      "x": -40,
      "y": 76,
      "z": -3,
      "name": "Rock_Ice"
    },
    {
      "x": -40,
      "y": 77,
      "z": -3,
      "name": "Rock_Ice"
    },
    {
      "x": -40,
      "y": 78,
      "z": -3,
      "name": "Rock_Ice"
    },
    {
      "x": -40,
      "y": 79,
      "z": -3,
      "name": "Rock_Ice"
    },
    {
      "x": -40,
      "y": 80,
      "z": -3,
      "name": "Rock_Ice"
    },
    {
      "x": -40,
      "y": 81,
      "z": -3,
      "name": "Rock_Ice"
    },
    {
      "x": -40,
      "y": 82,
      "z": -3,
      "name": "Rock_Ice"
    },
    {
      "x": -40,
      "y": 51,
      "z": -2,
      "name": "Rock_Ice"
    },
    {
      "x": -40,
      "y": 52,
      "z": -2,
      "name": "Rock_Ice"
    },
    {
      "x": -40,
      "y": 53,
      "z": -2,
      "name": "Rock_Ice_Permafrost"
    },
    {
      "x": -40,
      "y": 54,
      "z": -2,
      "name": "Rock_Ice_Permafrost"
    },
    {
      "x": -40,
      "y": 55,
      "z": -2,
      "name": "Rock_Ice_Permafrost"
    },
    {
      "x": -40,
      "y": 56,
      "z": -2,
      "name": "Rock_Ice_Permafrost"
    },
    {
      "x": -40,
      "y": 57,
      "z": -2,
      "name": "Rock_Ice_Permafrost"
    },
    {
      "x": -40,
      "y": 58,
      "z": -2,
      "name": "Rock_Ice"
    },
    {
      "x": -40,
      "y": 59,
      "z": -2,
      "name": "Rock_Ice_Permafrost"
    },
    {
      "x": -40,
      "y": 60,
      "z": -2,
      "name": "Rock_Ice"
    },
    {
      "x": -40,
      "y": 61,
      "z": -2,
      "name": "Rock_Ice"
    },
    {
      "x": -40,
      "y": 62,
      "z": -2,
      "name": "Rock_Ice"
    },
    {
      "x": -40,
      "y": 63,
      "z": -2,
      "name": "Rock_Ice"
    },
    {
      "x": -40,
      "y": 64,
      "z": -2,
      "name": "Rock_Ice"
    },
    {
      "x": -40,
      "y": 65,
      "z": -2,
      "name": "Rock_Ice"
    },
    {
      "x": -40,
      "y": 66,
      "z": -2,
      "name": "Rock_Ice"
    },
    {
      "x": -40,
      "y": 67,
      "z": -2,
      "name": "Rock_Ice"
    },
    {
      "x": -40,
      "y": 68,
      "z": -2,
      "name": "Rock_Ice"
    },
    {
      "x": -40,
      "y": 69,
      "z": -2,
      "name": "Rock_Ice"
    },
    {
      "x": -40,
      "y": 70,
      "z": -2,
      "name": "Rock_Ice"
    },
    {
      "x": -40,
      "y": 71,
      "z": -2,
      "name": "Rock_Ice"
    },
    {
      "x": -40,
      "y": 72,
      "z": -2,
      "name": "Rock_Ice"
    },
    {
      "x": -40,
      "y": 73,
      "z": -2,
      "name": "Rock_Ice"
    },
    {
      "x": -40,
      "y": 74,
      "z": -2,
      "name": "Rock_Ice"
    },
    {
      "x": -40,
      "y": 75,
      "z": -2,
      "name": "Rock_Ice"
    },
    {
      "x": -40,
      "y": 76,
      "z": -2,
      "name": "Rock_Ice"
    },
    {
      "x": -40,
      "y": 77,
      "z": -2,
      "name": "Rock_Ice"
    },
    {
      "x": -40,
      "y": 78,
      "z": -2,
      "name": "Rock_Ice"
    },
    {
      "x": -40,
      "y": 79,
      "z": -2,
      "name": "Rock_Ice"
    },
    {
      "x": -40,
      "y": 80,
      "z": -2,
      "name": "Rock_Ice"
    },
    {
      "x": -40,
      "y": 81,
      "z": -2,
      "name": "Rock_Ice"
    },
    {
      "x": -40,
      "y": 82,
      "z": -2,
      "name": "Rock_Ice_Permafrost"
    },
    {
      "x": -40,
      "y": 83,
      "z": -2,
      "name": "Rock_Ice_Permafrost"
    },
    {
      "x": -40,
      "y": 50,
      "z": -1,
      "name": "Rock_Ice"
    },
    {
      "x": -40,
      "y": 51,
      "z": -1,
      "name": "Rock_Ice_Permafrost"
    },
    {
      "x": -40,
      "y": 52,
      "z": -1,
      "name": "Rock_Ice_Permafrost"
    },
    {
      "x": -40,
      "y": 53,
      "z": -1,
      "name": "Rock_Ice_Permafrost"
    },
    {
      "x": -40,
      "y": 54,
      "z": -1,
      "name": "Rock_Ice_Permafrost"
    },
    {
      "x": -40,
      "y": 55,
      "z": -1,
      "name": "Rock_Ice_Permafrost"
    },
    {
      "x": -40,
      "y": 56,
      "z": -1,
      "name": "Rock_Ice_Permafrost"
    },
    {
      "x": -40,
      "y": 57,
      "z": -1,
      "name": "Rock_Ice_Permafrost"
    },
    {
      "x": -40,
      "y": 58,
      "z": -1,
      "name": "Rock_Ice_Permafrost"
    },
    {
      "x": -40,
      "y": 59,
      "z": -1,
      "name": "Rock_Ice"
    },
    {
      "x": -40,
      "y": 60,
      "z": -1,
      "name": "Rock_Ice"
    },
    {
      "x": -40,
      "y": 61,
      "z": -1,
      "name": "Rock_Ice"
    },
    {
      "x": -40,
      "y": 62,
      "z": -1,
      "name": "Rock_Ice"
    },
    {
      "x": -40,
      "y": 63,
      "z": -1,
      "name": "Rock_Ice"
    },
    {
      "x": -40,
      "y": 64,
      "z": -1,
      "name": "Rock_Ice"
    },
    {
      "x": -40,
      "y": 65,
      "z": -1,
      "name": "Rock_Ice"
    },
    {
      "x": -40,
      "y": 66,
      "z": -1,
      "name": "Rock_Ice"
    },
    {
      "x": -40,
      "y": 67,
      "z": -1,
      "name": "Rock_Ice"
    },
    {
      "x": -40,
      "y": 68,
      "z": -1,
      "name": "Rock_Ice"
    },
    {
      "x": -40,
      "y": 69,
      "z": -1,
      "name": "Rock_Ice"
    },
    {
      "x": -40,
      "y": 70,
      "z": -1,
      "name": "Rock_Ice"
    },
    {
      "x": -40,
      "y": 71,
      "z": -1,
      "name": "Rock_Ice"
    },
    {
      "x": -40,
      "y": 72,
      "z": -1,
      "name": "Rock_Ice"
    },
    {
      "x": -40,
      "y": 73,
      "z": -1,
      "name": "Rock_Ice"
    },
    {
      "x": -40,
      "y": 74,
      "z": -1,
      "name": "Rock_Ice"
    },
    {
      "x": -40,
      "y": 75,
      "z": -1,
      "name": "Rock_Ice"
    },
    {
      "x": -40,
      "y": 76,
      "z": -1,
      "name": "Rock_Ice"
    },
    {
      "x": -40,
      "y": 77,
      "z": -1,
      "name": "Rock_Ice"
    },
    {
      "x": -40,
      "y": 78,
      "z": -1,
      "name": "Rock_Ice"
    },
    {
      "x": -40,
      "y": 79,
      "z": -1,
      "name": "Rock_Ice"
    },
    {
      "x": -40,
      "y": 80,
      "z": -1,
      "name": "Rock_Ice"
    },
    {
      "x": -40,
      "y": 81,
      "z": -1,
      "name": "Rock_Ice"
    },
    {
      "x": -40,
      "y": 82,
      "z": -1,
      "name": "Rock_Ice"
    },
    {
      "x": -40,
      "y": 83,
      "z": -1,
      "name": "Rock_Ice"
    },
    {
      "x": -40,
      "y": 49,
      "z": 0,
      "name": "Rock_Ice"
    },
    {
      "x": -40,
      "y": 50,
      "z": 0,
      "name": "Rock_Ice_Permafrost"
    },
    {
      "x": -40,
      "y": 51,
      "z": 0,
      "name": "Rock_Ice_Permafrost"
    },
    {
      "x": -40,
      "y": 52,
      "z": 0,
      "name": "Rock_Ice_Permafrost"
    },
    {
      "x": -40,
      "y": 53,
      "z": 0,
      "name": "Rock_Ice_Permafrost"
    },
    {
      "x": -40,
      "y": 54,
      "z": 0,
      "name": "Rock_Ice_Permafrost"
    },
    {
      "x": -40,
      "y": 55,
      "z": 0,
      "name": "Rock_Ice_Permafrost"
    },
    {
      "x": -40,
      "y": 56,
      "z": 0,
      "name": "Rock_Ice_Permafrost"
    },
    {
      "x": -40,
      "y": 57,
      "z": 0,
      "name": "Rock_Ice"
    },
    {
      "x": -40,
      "y": 58,
      "z": 0,
      "name": "Rock_Ice"
    },
    {
      "x": -40,
      "y": 59,
      "z": 0,
      "name": "Rock_Ice"
    },
    {
      "x": -40,
      "y": 60,
      "z": 0,
      "name": "Rock_Ice"
    },
    {
      "x": -40,
      "y": 61,
      "z": 0,
      "name": "Rock_Ice"
    },
    {
      "x": -40,
      "y": 62,
      "z": 0,
      "name": "Rock_Ice"
    },
    {
      "x": -40,
      "y": 63,
      "z": 0,
      "name": "Rock_Ice"
    },
    {
      "x": -40,
      "y": 64,
      "z": 0,
      "name": "Rock_Ice"
    },
    {
      "x": -40,
      "y": 65,
      "z": 0,
      "name": "Rock_Ice"
    },
    {
      "x": -40,
      "y": 66,
      "z": 0,
      "name": "Rock_Ice"
    },
    {
      "x": -40,
      "y": 67,
      "z": 0,
      "name": "Rock_Ice"
    },
    {
      "x": -40,
      "y": 68,
      "z": 0,
      "name": "Rock_Ice"
    },
    {
      "x": -40,
      "y": 69,
      "z": 0,
      "name": "Rock_Ice"
    },
    {
      "x": -40,
      "y": 70,
      "z": 0,
      "name": "Rock_Ice"
    },
    {
      "x": -40,
      "y": 71,
      "z": 0,
      "name": "Rock_Ice"
    },
    {
      "x": -40,
      "y": 72,
      "z": 0,
      "name": "Rock_Ice"
    },
    {
      "x": -40,
      "y": 73,
      "z": 0,
      "name": "Rock_Ice"
    },
    {
      "x": -40,
      "y": 74,
      "z": 0,
      "name": "Rock_Ice"
    },
    {
      "x": -40,
      "y": 75,
      "z": 0,
      "name": "Rock_Ice"
    },
    {
      "x": -40,
      "y": 76,
      "z": 0,
      "name": "Rock_Ice"
    },
    {
      "x": -40,
      "y": 77,
      "z": 0,
      "name": "Rock_Ice"
    },
    {
      "x": -40,
      "y": 78,
      "z": 0,
      "name": "Rock_Ice"
    },
    {
      "x": -40,
      "y": 79,
      "z": 0,
      "name": "Rock_Ice"
    },
    {
      "x": -40,
      "y": 80,
      "z": 0,
      "name": "Rock_Ice"
    },
    {
      "x": -40,
      "y": 81,
      "z": 0,
      "name": "Rock_Ice"
    },
    {
      "x": -40,
      "y": 82,
      "z": 0,
      "name": "Rock_Ice"
    },
    {
      "x": -40,
      "y": 83,
      "z": 0,
      "name": "Rock_Ice"
    },
    {
      "x": -40,
      "y": 48,
      "z": 1,
      "name": "Rock_Ice"
    },
    {
      "x": -40,
      "y": 49,
      "z": 1,
      "name": "Rock_Ice"
    },
    {
      "x": -40,
      "y": 50,
      "z": 1,
      "name": "Rock_Ice_Permafrost"
    },
    {
      "x": -40,
      "y": 51,
      "z": 1,
      "name": "Rock_Ice_Permafrost"
    },
    {
      "x": -40,
      "y": 52,
      "z": 1,
      "name": "Rock_Ice"
    },
    {
      "x": -40,
      "y": 53,
      "z": 1,
      "name": "Rock_Ice_Permafrost"
    },
    {
      "x": -40,
      "y": 54,
      "z": 1,
      "name": "Rock_Ice_Permafrost"
    },
    {
      "x": -40,
      "y": 55,
      "z": 1,
      "name": "Rock_Ice"
    },
    {
      "x": -40,
      "y": 56,
      "z": 1,
      "name": "Rock_Ice"
    },
    {
      "x": -40,
      "y": 57,
      "z": 1,
      "name": "Rock_Ice"
    },
    {
      "x": -40,
      "y": 58,
      "z": 1,
      "name": "Rock_Ice"
    },
    {
      "x": -40,
      "y": 59,
      "z": 1,
      "name": "Rock_Ice"
    },
    {
      "x": -40,
      "y": 60,
      "z": 1,
      "name": "Rock_Ice"
    },
    {
      "x": -40,
      "y": 61,
      "z": 1,
      "name": "Rock_Ice"
    },
    {
      "x": -40,
      "y": 62,
      "z": 1,
      "name": "Rock_Ice"
    },
    {
      "x": -40,
      "y": 63,
      "z": 1,
      "name": "Rock_Ice"
    },
    {
      "x": -40,
      "y": 64,
      "z": 1,
      "name": "Rock_Ice"
    },
    {
      "x": -40,
      "y": 65,
      "z": 1,
      "name": "Rock_Ice"
    },
    {
      "x": -40,
      "y": 66,
      "z": 1,
      "name": "Rock_Ice"
    },
    {
      "x": -40,
      "y": 67,
      "z": 1,
      "name": "Rock_Ice"
    },
    {
      "x": -40,
      "y": 68,
      "z": 1,
      "name": "Rock_Ice"
    },
    {
      "x": -40,
      "y": 69,
      "z": 1,
      "name": "Rock_Ice"
    },
    {
      "x": -40,
      "y": 70,
      "z": 1,
      "name": "Rock_Ice"
    },
    {
      "x": -40,
      "y": 71,
      "z": 1,
      "name": "Rock_Ice"
    },
    {
      "x": -40,
      "y": 72,
      "z": 1,
      "name": "Rock_Ice"
    },
    {
      "x": -40,
      "y": 73,
      "z": 1,
      "name": "Rock_Ice"
    },
    {
      "x": -40,
      "y": 74,
      "z": 1,
      "name": "Rock_Ice"
    },
    {
      "x": -40,
      "y": 75,
      "z": 1,
      "name": "Rock_Ice"
    },
    {
      "x": -40,
      "y": 76,
      "z": 1,
      "name": "Rock_Ice"
    },
    {
      "x": -40,
      "y": 77,
      "z": 1,
      "name": "Rock_Ice"
    },
    {
      "x": -40,
      "y": 78,
      "z": 1,
      "name": "Rock_Ice"
    },
    {
      "x": -40,
      "y": 79,
      "z": 1,
      "name": "Rock_Ice"
    },
    {
      "x": -40,
      "y": 80,
      "z": 1,
      "name": "Rock_Ice"
    },
    {
      "x": -40,
      "y": 81,
      "z": 1,
      "name": "Rock_Ice"
    },
    {
      "x": -40,
      "y": 82,
      "z": 1,
      "name": "Rock_Ice"
    },
    {
      "x": -40,
      "y": 83,
      "z": 1,
      "name": "Rock_Ice"
    },
    {
      "x": -40,
      "y": 47,
      "z": 2,
      "name": "Rock_Ice"
    },
    {
      "x": -40,
      "y": 48,
      "z": 2,
      "name": "Rock_Ice"
    },
    {
      "x": -40,
      "y": 49,
      "z": 2,
      "name": "Rock_Ice_Permafrost"
    },
    {
      "x": -40,
      "y": 50,
      "z": 2,
      "name": "Rock_Ice_Permafrost"
    },
    {
      "x": -40,
      "y": 51,
      "z": 2,
      "name": "Rock_Ice_Permafrost"
    },
    {
      "x": -40,
      "y": 52,
      "z": 2,
      "name": "Rock_Ice_Permafrost"
    },
    {
      "x": -40,
      "y": 53,
      "z": 2,
      "name": "Rock_Ice"
    },
    {
      "x": -40,
      "y": 54,
      "z": 2,
      "name": "Rock_Ice_Permafrost"
    },
    {
      "x": -40,
      "y": 55,
      "z": 2,
      "name": "Rock_Ice_Permafrost"
    },
    {
      "x": -40,
      "y": 56,
      "z": 2,
      "name": "Rock_Ice"
    },
    {
      "x": -40,
      "y": 57,
      "z": 2,
      "name": "Rock_Ice"
    },
    {
      "x": -40,
      "y": 58,
      "z": 2,
      "name": "Rock_Ice"
    },
    {
      "x": -40,
      "y": 59,
      "z": 2,
      "name": "Rock_Ice"
    },
    {
      "x": -40,
      "y": 60,
      "z": 2,
      "name": "Rock_Ice"
    },
    {
      "x": -40,
      "y": 61,
      "z": 2,
      "name": "Rock_Ice"
    },
    {
      "x": -40,
      "y": 62,
      "z": 2,
      "name": "Rock_Ice"
    },
    {
      "x": -40,
      "y": 63,
      "z": 2,
      "name": "Rock_Ice"
    },
    {
      "x": -40,
      "y": 64,
      "z": 2,
      "name": "Rock_Ice"
    },
    {
      "x": -40,
      "y": 65,
      "z": 2,
      "name": "Rock_Ice"
    },
    {
      "x": -40,
      "y": 66,
      "z": 2,
      "name": "Rock_Ice"
    },
    {
      "x": -40,
      "y": 67,
      "z": 2,
      "name": "Rock_Ice"
    },
    {
      "x": -40,
      "y": 68,
      "z": 2,
      "name": "Rock_Ice"
    },
    {
      "x": -40,
      "y": 69,
      "z": 2,
      "name": "Rock_Ice"
    },
    {
      "x": -40,
      "y": 70,
      "z": 2,
      "name": "Rock_Ice"
    },
    {
      "x": -40,
      "y": 71,
      "z": 2,
      "name": "Rock_Ice"
    },
    {
      "x": -40,
      "y": 72,
      "z": 2,
      "name": "Rock_Ice"
    },
    {
      "x": -40,
      "y": 73,
      "z": 2,
      "name": "Rock_Ice"
    },
    {
      "x": -40,
      "y": 74,
      "z": 2,
      "name": "Rock_Ice"
    },
    {
      "x": -40,
      "y": 75,
      "z": 2,
      "name": "Rock_Ice"
    },
    {
      "x": -40,
      "y": 76,
      "z": 2,
      "name": "Rock_Ice"
    },
    {
      "x": -40,
      "y": 77,
      "z": 2,
      "name": "Rock_Ice"
    },
    {
      "x": -40,
      "y": 78,
      "z": 2,
      "name": "Rock_Ice"
    },
    {
      "x": -40,
      "y": 79,
      "z": 2,
      "name": "Rock_Ice"
    },
    {
      "x": -40,
      "y": 80,
      "z": 2,
      "name": "Rock_Ice"
    },
    {
      "x": -40,
      "y": 81,
      "z": 2,
      "name": "Rock_Ice"
    },
    {
      "x": -40,
      "y": 82,
      "z": 2,
      "name": "Rock_Ice"
    },
    {
      "x": -40,
      "y": 83,
      "z": 2,
      "name": "Rock_Ice"
    },
    {
      "x": -40,
      "y": 46,
      "z": 3,
      "name": "Rock_Ice"
    },
    {
      "x": -40,
      "y": 47,
      "z": 3,
      "name": "Rock_Ice"
    },
    {
      "x": -40,
      "y": 48,
      "z": 3,
      "name": "Rock_Ice_Permafrost"
    },
    {
      "x": -40,
      "y": 49,
      "z": 3,
      "name": "Rock_Ice_Permafrost"
    },
    {
      "x": -40,
      "y": 50,
      "z": 3,
      "name": "Rock_Ice"
    },
    {
      "x": -40,
      "y": 51,
      "z": 3,
      "name": "Rock_Ice_Permafrost"
    },
    {
      "x": -40,
      "y": 52,
      "z": 3,
      "name": "Rock_Ice_Permafrost"
    },
    {
      "x": -40,
      "y": 53,
      "z": 3,
      "name": "Rock_Ice"
    },
    {
      "x": -40,
      "y": 54,
      "z": 3,
      "name": "Rock_Ice"
    },
    {
      "x": -40,
      "y": 55,
      "z": 3,
      "name": "Rock_Ice"
    },
    {
      "x": -40,
      "y": 56,
      "z": 3,
      "name": "Rock_Ice"
    },
    {
      "x": -40,
      "y": 57,
      "z": 3,
      "name": "Rock_Ice"
    },
    {
      "x": -40,
      "y": 58,
      "z": 3,
      "name": "Rock_Ice"
    },
    {
      "x": -40,
      "y": 59,
      "z": 3,
      "name": "Rock_Ice"
    },
    {
      "x": -40,
      "y": 60,
      "z": 3,
      "name": "Rock_Ice"
    },
    {
      "x": -40,
      "y": 61,
      "z": 3,
      "name": "Rock_Ice"
    },
    {
      "x": -40,
      "y": 62,
      "z": 3,
      "name": "Rock_Ice"
    },
    {
      "x": -40,
      "y": 63,
      "z": 3,
      "name": "Rock_Ice"
    },
    {
      "x": -40,
      "y": 64,
      "z": 3,
      "name": "Rock_Ice"
    },
    {
      "x": -40,
      "y": 65,
      "z": 3,
      "name": "Rock_Ice"
    },
    {
      "x": -40,
      "y": 66,
      "z": 3,
      "name": "Rock_Ice"
    },
    {
      "x": -40,
      "y": 67,
      "z": 3,
      "name": "Rock_Ice"
    },
    {
      "x": -40,
      "y": 68,
      "z": 3,
      "name": "Rock_Ice"
    },
    {
      "x": -40,
      "y": 69,
      "z": 3,
      "name": "Rock_Ice"
    },
    {
      "x": -40,
      "y": 70,
      "z": 3,
      "name": "Rock_Ice"
    },
    {
      "x": -40,
      "y": 71,
      "z": 3,
      "name": "Rock_Ice"
    },
    {
      "x": -40,
      "y": 72,
      "z": 3,
      "name": "Rock_Ice"
    },
    {
      "x": -40,
      "y": 73,
      "z": 3,
      "name": "Rock_Ice"
    },
    {
      "x": -40,
      "y": 74,
      "z": 3,
      "name": "Rock_Ice"
    },
    {
      "x": -40,
      "y": 75,
      "z": 3,
      "name": "Rock_Ice"
    },
    {
      "x": -40,
      "y": 76,
      "z": 3,
      "name": "Rock_Ice"
    },
    {
      "x": -40,
      "y": 77,
      "z": 3,
      "name": "Rock_Ice"
    },
    {
      "x": -40,
      "y": 78,
      "z": 3,
      "name": "Rock_Ice"
    },
    {
      "x": -40,
      "y": 79,
      "z": 3,
      "name": "Rock_Ice"
    },
    {
      "x": -40,
      "y": 80,
      "z": 3,
      "name": "Rock_Ice"
    },
    {
      "x": -40,
      "y": 81,
      "z": 3,
      "name": "Rock_Ice"
    },
    {
      "x": -40,
      "y": 82,
      "z": 3,
      "name": "Rock_Ice"
    },
    {
      "x": -40,
      "y": 83,
      "z": 3,
      "name": "Rock_Ice"
    },
    {
      "x": -40,
      "y": 45,
      "z": 4,
      "name": "Rock_Ice"
    },
    {
      "x": -40,
      "y": 46,
      "z": 4,
      "name": "Rock_Ice"
    },
    {
      "x": -40,
      "y": 47,
      "z": 4,
      "name": "Rock_Ice"
    },
    {
      "x": -40,
      "y": 48,
      "z": 4,
      "name": "Rock_Ice_Permafrost"
    },
    {
      "x": -40,
      "y": 49,
      "z": 4,
      "name": "Rock_Ice_Permafrost"
    },
    {
      "x": -40,
      "y": 50,
      "z": 4,
      "name": "Rock_Ice_Permafrost"
    },
    {
      "x": -40,
      "y": 51,
      "z": 4,
      "name": "Rock_Ice_Permafrost"
    },
    {
      "x": -40,
      "y": 52,
      "z": 4,
      "name": "Rock_Ice_Permafrost"
    },
    {
      "x": -40,
      "y": 53,
      "z": 4,
      "name": "Rock_Ice"
    },
    {
      "x": -40,
      "y": 54,
      "z": 4,
      "name": "Rock_Ice"
    },
    {
      "x": -40,
      "y": 55,
      "z": 4,
      "name": "Rock_Ice"
    },
    {
      "x": -40,
      "y": 56,
      "z": 4,
      "name": "Rock_Ice"
    },
    {
      "x": -40,
      "y": 57,
      "z": 4,
      "name": "Rock_Ice"
    },
    {
      "x": -40,
      "y": 58,
      "z": 4,
      "name": "Rock_Ice"
    },
    {
      "x": -40,
      "y": 59,
      "z": 4,
      "name": "Rock_Ice"
    },
    {
      "x": -40,
      "y": 60,
      "z": 4,
      "name": "Rock_Ice"
    },
    {
      "x": -40,
      "y": 61,
      "z": 4,
      "name": "Rock_Ice"
    },
    {
      "x": -40,
      "y": 62,
      "z": 4,
      "name": "Rock_Ice"
    },
    {
      "x": -40,
      "y": 63,
      "z": 4,
      "name": "Rock_Ice"
    },
    {
      "x": -40,
      "y": 64,
      "z": 4,
      "name": "Rock_Ice"
    },
    {
      "x": -40,
      "y": 65,
      "z": 4,
      "name": "Rock_Ice"
    },
    {
      "x": -40,
      "y": 66,
      "z": 4,
      "name": "Rock_Ice"
    },
    {
      "x": -40,
      "y": 67,
      "z": 4,
      "name": "Rock_Ice"
    },
    {
      "x": -40,
      "y": 68,
      "z": 4,
      "name": "Rock_Ice"
    },
    {
      "x": -40,
      "y": 69,
      "z": 4,
      "name": "Rock_Ice"
    },
    {
      "x": -40,
      "y": 70,
      "z": 4,
      "name": "Rock_Ice"
    },
    {
      "x": -40,
      "y": 71,
      "z": 4,
      "name": "Rock_Ice"
    },
    {
      "x": -40,
      "y": 72,
      "z": 4,
      "name": "Rock_Ice"
    },
    {
      "x": -40,
      "y": 73,
      "z": 4,
      "name": "Rock_Ice"
    },
    {
      "x": -40,
      "y": 74,
      "z": 4,
      "name": "Rock_Ice"
    },
    {
      "x": -40,
      "y": 75,
      "z": 4,
      "name": "Rock_Ice"
    },
    {
      "x": -40,
      "y": 76,
      "z": 4,
      "name": "Rock_Ice"
    },
    {
      "x": -40,
      "y": 77,
      "z": 4,
      "name": "Rock_Ice"
    },
    {
      "x": -40,
      "y": 78,
      "z": 4,
      "name": "Rock_Ice"
    },
    {
      "x": -40,
      "y": 79,
      "z": 4,
      "name": "Rock_Ice"
    },
    {
      "x": -40,
      "y": 80,
      "z": 4,
      "name": "Rock_Ice"
    },
    {
      "x": -40,
      "y": 81,
      "z": 4,
      "name": "Rock_Ice"
    },
    {
      "x": -40,
      "y": 82,
      "z": 4,
      "name": "Rock_Ice"
    },
    {
      "x": -40,
      "y": 83,
      "z": 4,
      "name": "Rock_Ice"
    },
    {
      "x": -40,
      "y": 44,
      "z": 5,
      "name": "Rock_Ice"
    },
    {
      "x": -40,
      "y": 45,
      "z": 5,
      "name": "Rock_Ice"
    },
    {
      "x": -40,
      "y": 46,
      "z": 5,
      "name": "Rock_Ice_Permafrost"
    },
    {
      "x": -40,
      "y": 47,
      "z": 5,
      "name": "Rock_Ice_Permafrost"
    },
    {
      "x": -40,
      "y": 48,
      "z": 5,
      "name": "Rock_Ice_Permafrost"
    },
    {
      "x": -40,
      "y": 49,
      "z": 5,
      "name": "Rock_Ice_Permafrost"
    },
    {
      "x": -40,
      "y": 50,
      "z": 5,
      "name": "Rock_Ice_Permafrost"
    },
    {
      "x": -40,
      "y": 51,
      "z": 5,
      "name": "Rock_Ice"
    },
    {
      "x": -40,
      "y": 52,
      "z": 5,
      "name": "Rock_Ice"
    },
    {
      "x": -40,
      "y": 53,
      "z": 5,
      "name": "Rock_Ice"
    },
    {
      "x": -40,
      "y": 54,
      "z": 5,
      "name": "Rock_Ice"
    },
    {
      "x": -40,
      "y": 55,
      "z": 5,
      "name": "Rock_Ice"
    },
    {
      "x": -40,
      "y": 56,
      "z": 5,
      "name": "Rock_Ice"
    },
    {
      "x": -40,
      "y": 57,
      "z": 5,
      "name": "Rock_Ice"
    },
    {
      "x": -40,
      "y": 58,
      "z": 5,
      "name": "Rock_Ice"
    },
    {
      "x": -40,
      "y": 59,
      "z": 5,
      "name": "Rock_Ice"
    },
    {
      "x": -40,
      "y": 60,
      "z": 5,
      "name": "Rock_Ice"
    },
    {
      "x": -40,
      "y": 61,
      "z": 5,
      "name": "Rock_Ice"
    },
    {
      "x": -40,
      "y": 62,
      "z": 5,
      "name": "Rock_Ice"
    },
    {
      "x": -40,
      "y": 63,
      "z": 5,
      "name": "Rock_Ice"
    },
    {
      "x": -40,
      "y": 64,
      "z": 5,
      "name": "Rock_Ice"
    },
    {
      "x": -40,
      "y": 65,
      "z": 5,
      "name": "Rock_Ice"
    },
    {
      "x": -40,
      "y": 66,
      "z": 5,
      "name": "Rock_Ice"
    },
    {
      "x": -40,
      "y": 67,
      "z": 5,
      "name": "Rock_Ice"
    },
    {
      "x": -40,
      "y": 68,
      "z": 5,
      "name": "Rock_Ice"
    },
    {
      "x": -40,
      "y": 69,
      "z": 5,
      "name": "Rock_Ice"
    },
    {
      "x": -40,
      "y": 70,
      "z": 5,
      "name": "Rock_Ice"
    },
