{
  "version": 8,
  "blockIdVersion": 11,
  "anchorX": 7,
  "anchorY": 2,
  "anchorZ": 5,
  "blocks": [
    {
      "x": 4,
      "y": 3,
      "z": 3,
      "name": "Plant_Bush_Lush"
    },
    {
      "x": 5,
      "y": 3,
      "z": 3,
      "name": "Plant_Bush_Lush"
    },
    {
      "x": 5,
      "y": 1,
      "z": 4,
      "name": "Plant_Bush_Lush"
    },
    {
      "x": 5,
      "y": 2,
      "z": 4,
      "name": "Plant_Bush_Lush"
    },
    {
      "x": 5,
      "y": 3,
      "z": 4,
      "name": "Plant_Bush_Lush"
    },
    {
      "x": 5,
      "y": 4,
      "z": 4,
      "name": "Plant_Bush_Lush"
    },
    {
      "x": 5,
      "y": 1,
      "z": 5,
      "name": "Plant_Bush_Lush"
    },
    {
      "x": 5,
      "y": 2,
      "z": 5,
      "name": "Plant_Bush_Lush"
    },
    {
      "x": 5,
      "y": 3,
      "z": 5,
      "name": "Plant_Bush_Lush"
    },
    {
      "x": 5,
      "y": 1,
      "z": 6,
      "name": "Plant_Bush_Lush"
    },
    {
      "x": 5,
      "y": 2,
      "z": 6,
      "name": "Plant_Bush_Lush"
    },
    {
      "x": 5,
      "y": 2,
      "z": 7,
      "name": "Plant_Bush_Lush"
    },
    {
      "x": 5,
      "y": 3,
      "z": 7,
      "name": "Plant_Bush_Lush"
    },
    {
      "x": 6,
      "y": 1,
      "z": 3,
      "name": "Plant_Bush_Lush"
    },
    {
      "x": 6,
      "y": 2,
      "z": 3,
      "name": "Plant_Bush_Lush"
    },
    {
      "x": 6,
      "y": 3,
      "z": 3,
      "name": "Plant_Bush_Lush"
    },
    {
      "x": 6,
      "y": 1,
      "z": 4,
      "name": "Plant_Bush_Lush"
    },
    {
      "x": 6,
      "y": 2,
      "z": 4,
      "name": "Plant_Bush_Lush"
    },
    {
      "x": 6,
      "y": 3,
      "z": 4,
      "name": "Plant_Bush_Lush"
    },
    {
      "x": 6,
      "y": 4,
      "z": 4,
      "name": "Plant_Bush_Lush"
    },
    {
      "x": 6,
      "y": 1,
      "z": 5,
      "name": "Plant_Bush_Lush"
    },
    {
      "x": 6,
      "y": 2,
      "z": 5,
      "name": "Plant_Bush_Lush"
    },
    {
      "x": 6,
      "y": 3,
      "z": 5,
      "name": "Plant_Bush_Lush"
    },
    {
      "x": 6,
      "y": 4,
      "z": 5,
      "name": "Plant_Bush_Lush"
    },
    {
      "x": 6,
      "y": 1,
      "z": 6,
      "name": "Plant_Bush_Lush"
    },
    {
      "x": 6,
      "y": 2,
      "z": 6,
      "name": "Plant_Bush_Lush"
    },
    {
      "x": 6,
      "y": 3,
      "z": 6,
      "name": "Plant_Bush_Lush"
    },
    {
      "x": 6,
      "y": 1,
      "z": 7,
      "name": "Plant_Bush_Lush"
    },
    {
      "x": 6,
      "y": 2,
      "z": 7,
      "name": "Plant_Bush_Lush"
    },
    {
      "x": 6,
      "y": 3,
      "z": 7,
      "name": "Plant_Bush_Lush"
    },
    {
      "x": 6,
      "y": 4,
      "z": 7,
      "name": "Plant_Bush_Lush"
    },
    {
      "x": 6,
      "y": 2,
      "z": 8,
      "name": "Plant_Bush_Lush"
    },
    {
      "x": 6,
      "y": 3,
      "z": 8,
      "name": "Plant_Bush_Lush"
    },
    {
      "x": 7,
      "y": 1,
      "z": 3,
      "name": "Plant_Bush_Lush"
    },
    {
      "x": 7,
      "y": 2,
      "z": 3,
      "name": "Plant_Bush_Lush"
    },
    {
      "x": 7,
      "y": 3,
      "z": 3,
      "name": "Plant_Bush_Lush"
    },
    {
      "x": 7,
      "y": 1,
      "z": 4,
      "name": "Plant_Bush_Lush"
    },
    {
      "x": 7,
      "y": 2,
      "z": 4,
      "name": "Plant_Bush_Lush"
    },
    {
      "x": 7,
      "y": 3,
      "z": 4,
      "name": "Plant_Bush_Lush"
    },
    {
      "x": 7,
      "y": 4,
      "z": 4,
      "name": "Plant_Bush_Lush"
    },
    {
      "x": 7,
      "y": 0,
      "z": 5,
      "name": "Plant_Bush_Lush"
    },
    {
      "x": 7,
      "y": 1,
      "z": 5,
      "name": "Plant_Bush_Lush"
    },
    {
      "x": 7,
      "y": 2,
      "z": 5,
      "name": "Plant_Bush_Lush"
    },
    {
      "x": 7,
      "y": 3,
      "z": 5,
      "name": "Plant_Bush_Lush"
    },
    {
      "x": 7,
      "y": 4,
      "z": 5,
      "name": "Plant_Bush_Lush"
    },
    {
      "x": 7,
      "y": 0,
      "z": 6,
      "name": "Plant_Bush_Lush"
    },
    {
      "x": 7,
      "y": 1,
      "z": 6,
      "name": "Plant_Bush_Lush"
    },
    {
      "x": 7,
      "y": 2,
      "z": 6,
      "name": "Plant_Bush_Lush"
    },
    {
      "x": 7,
      "y": 3,
      "z": 6,
      "name": "Plant_Bush_Lush"
    },
    {
      "x": 7,
      "y": 4,
      "z": 6,
      "name": "Plant_Bush_Lush"
    },
    {
      "x": 7,
      "y": 0,
      "z": 7,
      "name": "Plant_Bush_Lush"
    },
    {
      "x": 7,
      "y": 1,
      "z": 7,
      "name": "Plant_Bush_Lush"
    },
    {
      "x": 7,
      "y": 2,
      "z": 7,
      "name": "Plant_Bush_Lush"
    },
    {
      "x": 7,
      "y": 3,
      "z": 7,
      "name": "Plant_Bush_Lush"
    },
    {
      "x": 7,
      "y": 4,
      "z": 7,
      "name": "Plant_Bush_Lush"
    },
    {
      "x": 7,
      "y": 2,
      "z": 8,
      "name": "Plant_Bush_Lush"
    },
    {
      "x": 7,
      "y": 3,
      "z": 8,
      "name": "Plant_Bush_Lush"
    },
    {
      "x": 7,
      "y": 4,
      "z": 8,
      "name": "Plant_Bush_Lush"
    },
    {
      "x": 7,
      "y": 3,
      "z": 9,
      "name": "Plant_Bush_Lush"
    },
    {
      "x": 8,
      "y": 1,
      "z": 4,
      "name": "Plant_Bush_Lush"
    },
    {
      "x": 8,
      "y": 2,
      "z": 4,
      "name": "Plant_Bush_Lush"
    },
    {
      "x": 8,
      "y": 3,
      "z": 4,
      "name": "Plant_Bush_Lush"
    },
    {
      "x": 8,
      "y": 1,
      "z": 5,
      "name": "Plant_Bush_Lush"
    },
    {
      "x": 8,
      "y": 2,
      "z": 5,
      "name": "Plant_Bush_Lush"
    },
    {
      "x": 8,
      "y": 3,
      "z": 5,
      "name": "Plant_Bush_Lush"
    },
    {
      "x": 8,
      "y": 4,
      "z": 5,
      "name": "Plant_Bush_Lush"
    },
    {
      "x": 8,
      "y": 0,
      "z": 6,
      "name": "Plant_Bush_Lush"
    },
    {
      "x": 8,
      "y": 1,
      "z": 6,
      "name": "Plant_Bush_Lush"
    },
    {
      "x": 8,
      "y": 2,
      "z": 6,
      "name": "Plant_Bush_Lush"
    },
    {
      "x": 8,
      "y": 3,
      "z": 6,
      "name": "Plant_Bush_Lush"
    },
    {
      "x": 8,
      "y": 1,
      "z": 7,
      "name": "Plant_Bush_Lush"
    },
    {
      "x": 8,
      "y": 2,
      "z": 7,
      "name": "Plant_Bush_Lush"
    },
    {
      "x": 8,
      "y": 3,
      "z": 7,
      "name": "Plant_Bush_Lush"
    },
    {
      "x": 8,
      "y": 4,
      "z": 7,
      "name": "Plant_Bush_Lush"
    },
    {
      "x": 8,
      "y": 2,
      "z": 8,
      "name": "Plant_Bush_Lush"
    },
    {
      "x": 8,
      "y": 3,
      "z": 8,
      "name": "Plant_Bush_Lush"
    },
    {
      "x": 9,
      "y": 2,
      "z": 5,
      "name": "Plant_Bush_Lush"
    },
    {
      "x": 9,
      "y": 1,
      "z": 6,
      "name": "Plant_Bush_Lush"
    },
    {
      "x": 9,
      "y": 2,
      "z": 6,
      "name": "Plant_Bush_Lush"
    },
    {
      "x": 9,
      "y": 2,
      "z": 7,
      "name": "Plant_Bush_Lush"
    },
    {
      "x": 9,
      "y": 3,
      "z": 7,
      "name": "Plant_Bush_Lush"
    }
  ]
}