{
  "version": 8,
  "blockIdVersion": 11,
  "anchorX": 6,
  "anchorY": 3,
  "anchorZ": 3,
  "blocks": [
    {
      "x": 4,
      "y": 2,
      "z": 3,
      "name": "Plant_Bush_Lush"
    },
    {
      "x": 4,
      "y": 3,
      "z": 3,
      "name": "Plant_Bush_Lush"
    },
    {
      "x": 4,
      "y": 4,
      "z": 3,
      "name": "Plant_Bush_Lush"
    },
    {
      "x": 5,
      "y": 2,
      "z": 2,
      "name": "Plant_Bush_Lush"
    },
    {
      "x": 5,
      "y": 3,
      "z": 2,
      "name": "Plant_Bush_Lush"
    },
    {
      "x": 5,
      "y": 4,
      "z": 2,
      "name": "Plant_Bush_Lush"
    },
    {
      "x": 5,
      "y": 2,
      "z": 3,
      "name": "Plant_Bush_Lush"
    },
    {
      "x": 5,
      "y": 3,
      "z": 3,
      "name": "Plant_Bush_Lush"
    },
    {
      "x": 5,
      "y": 4,
      "z": 3,
      "name": "Plant_Bush_Lush"
    },
    {
      "x": 5,
      "y": 5,
      "z": 3,
      "name": "Plant_Bush_Lush"
    },
    {
      "x": 5,
      "y": 2,
      "z": 4,
      "name": "Plant_Bush_Lush"
    },
    {
      "x": 5,
      "y": 3,
      "z": 4,
      "name": "Plant_Bush_Lush"
    },
    {
      "x": 5,
      "y": 4,
      "z": 4,
      "name": "Plant_Bush_Lush"
    },
    {
      "x": 5,
      "y": 5,
      "z": 4,
      "name": "Plant_Bush_Lush"
    },
    {
      "x": 5,
      "y": 2,
      "z": 5,
      "name": "Plant_Bush_Lush"
    },
    {
      "x": 5,
      "y": 3,
      "z": 5,
      "name": "Plant_Bush_Lush"
    },
    {
      "x": 5,
      "y": 4,
      "z": 5,
      "name": "Plant_Bush_Lush"
    },
    {
      "x": 6,
      "y": 2,
      "z": 1,
      "name": "Plant_Bush_Lush"
    },
    {
      "x": 6,
      "y": 3,
      "z": 1,
      "name": "Plant_Bush_Lush"
    },
    {
      "x": 6,
      "y": 4,
      "z": 1,
      "name": "Plant_Bush_Lush"
    },
    {
      "x": 6,
      "y": 2,
      "z": 2,
      "name": "Plant_Bush_Lush"
    },
    {
      "x": 6,
      "y": 3,
      "z": 2,
      "name": "Plant_Bush_Lush"
    },
    {
      "x": 6,
      "y": 4,
      "z": 2,
      "name": "Plant_Bush_Lush"
    },
    {
      "x": 6,
      "y": 5,
      "z": 2,
      "name": "Plant_Bush_Lush"
    },
    {
      "x": 6,
      "y": 1,
      "z": 3,
      "name": "Plant_Bush_Lush"
    },
    {
      "x": 6,
      "y": 2,
      "z": 3,
      "name": "Plant_Bush_Lush"
    },
    {
      "x": 6,
      "y": 3,
      "z": 3,
      "name": "Plant_Bush_Lush"
    },
    {
      "x": 6,
      "y": 4,
      "z": 3,
      "name": "Plant_Bush_Lush"
    },
    {
      "x": 6,
      "y": 5,
      "z": 3,
      "name": "Plant_Bush_Lush"
    },
    {
      "x": 6,
      "y": 2,
      "z": 4,
      "name": "Plant_Bush_Lush"
    },
    {
      "x": 6,
      "y": 3,
      "z": 4,
      "name": "Plant_Bush_Lush"
    },
    {
      "x": 6,
      "y": 4,
      "z": 4,
      "name": "Plant_Bush_Lush"
    },
    {
      "x": 6,
      "y": 5,
      "z": 4,
      "name": "Plant_Bush_Lush"
    },
    {
      "x": 6,
      "y": 3,
      "z": 5,
      "name": "Plant_Bush_Lush"
    },
    {
      "x": 6,
      "y": 4,
      "z": 5,
      "name": "Plant_Bush_Lush"
    },
    {
      "x": 7,
      "y": 3,
      "z": 2,
      "name": "Plant_Bush_Lush"
    },
    {
      "x": 7,
      "y": 4,
      "z": 2,
      "name": "Plant_Bush_Lush"
    },
    {
      "x": 7,
      "y": 2,
      "z": 3,
      "name": "Plant_Bush_Lush"
    },
    {
      "x": 7,
      "y": 3,
      "z": 3,
      "name": "Plant_Bush_Lush"
    },
    {
      "x": 7,
      "y": 4,
      "z": 3,
      "name": "Plant_Bush_Lush"
    },
    {
      "x": 7,
      "y": 5,
      "z": 3,
      "name": "Plant_Bush_Lush"
    },
    {
      "x": 7,
      "y": 2,
      "z": 4,
      "name": "Plant_Bush_Lush"
    },
    {
      "x": 7,
      "y": 3,
      "z": 4,
      "name": "Plant_Bush_Lush"
    },
    {
      "x": 7,
      "y": 4,
      "z": 4,
      "name": "Plant_Bush_Lush"
    },
    {
      "x": 7,
      "y": 2,
      "z": 5,
      "name": "Plant_Bush_Lush"
    },
    {
      "x": 7,
      "y": 3,
      "z": 5,
      "name": "Plant_Bush_Lush"
    },
    {
      "x": 7,
      "y": 4,
      "z": 5,
      "name": "Plant_Bush_Lush"
    },
    {
      "x": 8,
      "y": 3,
      "z": 3,
      "name": "Plant_Bush_Lush"
    },
    {
      "x": 8,
      "y": 4,
      "z": 3,
      "name": "Plant_Bush_Lush"
    },
    {
      "x": 8,
      "y": 2,
      "z": 4,
      "name": "Plant_Bush_Lush"
    },
    {
      "x": 8,
      "y": 3,
      "z": 4,
      "name": "Plant_Bush_Lush"
    },
    {
      "x": 8,
      "y": 4,
      "z": 4,
      "name": "Plant_Bush_Lush"
    }
  ]
}