{
  "version": 8,
  "blockIdVersion": 11,
  "anchorX": 6,
  "anchorY": 2,
  "anchorZ": 8,
  "blocks": [
    {
      "x": 3,
      "y": 3,
      "z": 4,
      "name": "Plant_Bush_Lush"
    },
    {
      "x": 3,
      "y": 2,
      "z": 5,
      "name": "Plant_Bush_Lush"
    },
    {
      "x": 3,
      "y": 3,
      "z": 5,
      "name": "Plant_Bush_Lush"
    },
    {
      "x": 3,
      "y": 4,
      "z": 5,
      "name": "Plant_Bush_Lush"
    },
    {
      "x": 3,
      "y": 3,
      "z": 6,
      "name": "Plant_Bush_Lush"
    },
    {
      "x": 3,
      "y": 1,
      "z": 8,
      "name": "Plant_Bush_Lush"
    },
    {
      "x": 4,
      "y": 3,
      "z": 3,
      "name": "Plant_Bush_Lush"
    },
    {
      "x": 4,
      "y": 2,
      "z": 4,
      "name": "Plant_Bush_Lush"
    },
    {
      "x": 4,
      "y": 3,
      "z": 4,
      "name": "Plant_Bush_Lush"
    },
    {
      "x": 4,
      "y": 4,
      "z": 4,
      "name": "Plant_Bush_Lush"
    },
    {
      "x": 4,
      "y": 2,
      "z": 5,
      "name": "Plant_Bush_Lush"
    },
    {
      "x": 4,
      "y": 3,
      "z": 5,
      "name": "Plant_Bush_Lush"
    },
    {
      "x": 4,
      "y": 4,
      "z": 5,
      "name": "Plant_Bush_Lush"
    },
    {
      "x": 4,
      "y": 5,
      "z": 5,
      "name": "Plant_Bush_Lush"
    },
    {
      "x": 4,
      "y": 2,
      "z": 6,
      "name": "Plant_Bush_Lush"
    },
    {
      "x": 4,
      "y": 3,
      "z": 6,
      "name": "Plant_Bush_Lush"
    },
    {
      "x": 4,
      "y": 4,
      "z": 6,
      "name": "Plant_Bush_Lush"
    },
    {
      "x": 4,
      "y": 1,
      "z": 7,
      "name": "Plant_Bush_Lush"
    },
    {
      "x": 4,
      "y": 2,
      "z": 7,
      "name": "Plant_Bush_Lush"
    },
    {
      "x": 4,
      "y": 3,
      "z": 7,
      "name": "Plant_Bush_Lush"
    },
    {
      "x": 4,
      "y": 0,
      "z": 8,
      "name": "Plant_Bush_Lush"
    },
    {
      "x": 4,
      "y": 1,
      "z": 8,
      "name": "Plant_Bush_Lush"
    },
    {
      "x": 4,
      "y": 2,
      "z": 8,
      "name": "Plant_Bush_Lush"
    },
    {
      "x": 4,
      "y": 3,
      "z": 8,
      "name": "Plant_Bush_Lush"
    },
    {
      "x": 4,
      "y": 1,
      "z": 9,
      "name": "Plant_Bush_Lush"
    },
    {
      "x": 4,
      "y": 2,
      "z": 9,
      "name": "Plant_Bush_Lush"
    },
    {
      "x": 4,
      "y": 3,
      "z": 9,
      "name": "Plant_Bush_Lush"
    },
    {
      "x": 4,
      "y": 2,
      "z": 10,
      "name": "Plant_Bush_Lush"
    },
    {
      "x": 4,
      "y": 3,
      "z": 10,
      "name": "Plant_Bush_Lush"
    },
    {
      "x": 4,
      "y": 3,
      "z": 11,
      "name": "Plant_Bush_Lush"
    },
    {
      "x": 5,
      "y": 3,
      "z": 4,
      "name": "Plant_Bush_Lush"
    },
    {
      "x": 5,
      "y": 4,
      "z": 4,
      "name": "Plant_Bush_Lush"
    },
    {
      "x": 5,
      "y": 1,
      "z": 5,
      "name": "Plant_Bush_Lush"
    },
    {
      "x": 5,
      "y": 2,
      "z": 5,
      "name": "Plant_Bush_Lush"
    },
    {
      "x": 5,
      "y": 3,
      "z": 5,
      "name": "Plant_Bush_Lush"
    },
    {
      "x": 5,
      "y": 4,
      "z": 5,
      "name": "Plant_Bush_Lush"
    },
    {
      "x": 5,
      "y": 5,
      "z": 5,
      "name": "Plant_Bush_Lush"
    },
    {
      "x": 5,
      "y": 1,
      "z": 6,
      "name": "Plant_Bush_Lush"
    },
    {
      "x": 5,
      "y": 2,
      "z": 6,
      "name": "Plant_Bush_Lush"
    },
    {
      "x": 5,
      "y": 3,
      "z": 6,
      "name": "Plant_Bush_Lush"
    },
    {
      "x": 5,
      "y": 4,
      "z": 6,
      "name": "Plant_Bush_Lush"
    },
    {
      "x": 5,
      "y": 5,
      "z": 6,
      "name": "Plant_Bush_Lush"
    },
    {
      "x": 5,
      "y": 0,
      "z": 7,
      "name": "Plant_Bush_Lush"
    },
    {
      "x": 5,
      "y": 1,
      "z": 7,
      "name": "Plant_Bush_Lush"
    },
    {
      "x": 5,
      "y": 2,
      "z": 7,
      "name": "Plant_Bush_Lush"
    },
    {
      "x": 5,
      "y": 3,
      "z": 7,
      "name": "Plant_Bush_Lush"
    },
    {
      "x": 5,
      "y": 4,
      "z": 7,
      "name": "Plant_Bush_Lush"
    },
    {
      "x": 5,
      "y": 0,
      "z": 8,
      "name": "Plant_Bush_Lush"
    },
    {
      "x": 5,
      "y": 1,
      "z": 8,
      "name": "Plant_Bush_Lush"
    },
    {
      "x": 5,
      "y": 2,
      "z": 8,
      "name": "Plant_Bush_Lush"
    },
    {
      "x": 5,
      "y": 3,
      "z": 8,
      "name": "Plant_Bush_Lush"
    },
    {
      "x": 5,
      "y": 4,
      "z": 8,
      "name": "Plant_Bush_Lush"
    },
    {
      "x": 5,
      "y": 0,
      "z": 9,
      "name": "Plant_Bush_Lush"
    },
    {
      "x": 5,
      "y": 1,
      "z": 9,
      "name": "Plant_Bush_Lush"
    },
    {
      "x": 5,
      "y": 2,
      "z": 9,
      "name": "Plant_Bush_Lush"
    },
    {
      "x": 5,
      "y": 3,
      "z": 9,
      "name": "Plant_Bush_Lush"
    },
    {
      "x": 5,
      "y": 1,
      "z": 10,
      "name": "Plant_Bush_Lush"
    },
    {
      "x": 5,
      "y": 2,
      "z": 10,
      "name": "Plant_Bush_Lush"
    },
    {
      "x": 5,
      "y": 3,
      "z": 10,
      "name": "Plant_Bush_Lush"
    },
    {
      "x": 5,
      "y": 2,
      "z": 11,
      "name": "Plant_Bush_Lush"
    },
    {
      "x": 5,
      "y": 3,
      "z": 11,
      "name": "Plant_Bush_Lush"
    },
    {
      "x": 6,
      "y": 1,
      "z": 5,
      "name": "Plant_Bush_Lush"
    },
    {
      "x": 6,
      "y": 2,
      "z": 5,
      "name": "Plant_Bush_Lush"
    },
    {
      "x": 6,
      "y": 3,
      "z": 5,
      "name": "Plant_Bush_Lush"
    },
    {
      "x": 6,
      "y": 4,
      "z": 5,
      "name": "Plant_Bush_Lush"
    },
    {
      "x": 6,
      "y": 1,
      "z": 6,
      "name": "Plant_Bush_Lush"
    },
    {
      "x": 6,
      "y": 2,
      "z": 6,
      "name": "Plant_Bush_Lush"
    },
    {
      "x": 6,
      "y": 3,
      "z": 6,
      "name": "Plant_Bush_Lush"
    },
    {
      "x": 6,
      "y": 4,
      "z": 6,
      "name": "Plant_Bush_Lush"
    },
    {
      "x": 6,
      "y": 1,
      "z": 7,
      "name": "Plant_Bush_Lush"
    },
    {
      "x": 6,
      "y": 2,
      "z": 7,
      "name": "Plant_Bush_Lush"
    },
    {
      "x": 6,
      "y": 3,
      "z": 7,
      "name": "Plant_Bush_Lush"
    },
    {
      "x": 6,
      "y": 4,
      "z": 7,
      "name": "Plant_Bush_Lush"
    },
    {
      "x": 6,
      "y": 0,
      "z": 8,
      "name": "Plant_Bush_Lush"
    },
    {
      "x": 6,
      "y": 1,
      "z": 8,
      "name": "Plant_Bush_Lush"
    },
    {
      "x": 6,
      "y": 2,
      "z": 8,
      "name": "Plant_Bush_Lush"
    },
    {
      "x": 6,
      "y": 3,
      "z": 8,
      "name": "Plant_Bush_Lush"
    },
    {
      "x": 6,
      "y": 4,
      "z": 8,
      "name": "Plant_Bush_Lush"
    },
    {
      "x": 6,
      "y": 0,
      "z": 9,
      "name": "Plant_Bush_Lush"
    },
    {
      "x": 6,
      "y": 1,
      "z": 9,
      "name": "Plant_Bush_Lush"
    },
    {
      "x": 6,
      "y": 2,
      "z": 9,
      "name": "Plant_Bush_Lush"
    },
    {
      "x": 6,
      "y": 3,
      "z": 9,
      "name": "Plant_Bush_Lush"
    },
    {
      "x": 6,
      "y": 4,
      "z": 9,
      "name": "Plant_Bush_Lush"
    },
    {
      "x": 6,
      "y": 1,
      "z": 10,
      "name": "Plant_Bush_Lush"
    },
    {
      "x": 6,
      "y": 2,
      "z": 10,
      "name": "Plant_Bush_Lush"
    },
    {
      "x": 6,
      "y": 3,
      "z": 10,
      "name": "Plant_Bush_Lush"
    },
    {
      "x": 7,
      "y": 3,
      "z": 4,
      "name": "Plant_Bush_Lush"
    },
    {
      "x": 7,
      "y": 2,
      "z": 5,
      "name": "Plant_Bush_Lush"
    },
    {
      "x": 7,
      "y": 3,
      "z": 5,
      "name": "Plant_Bush_Lush"
    },
    {
      "x": 7,
      "y": 4,
      "z": 5,
      "name": "Plant_Bush_Lush"
    },
    {
      "x": 7,
      "y": 3,
      "z": 6,
      "name": "Plant_Bush_Lush"
    },
    {
      "x": 7,
      "y": 1,
      "z": 7,
      "name": "Plant_Bush_Lush"
    },
    {
      "x": 7,
      "y": 2,
      "z": 7,
      "name": "Plant_Bush_Lush"
    },
    {
      "x": 7,
      "y": 3,
      "z": 7,
      "name": "Plant_Bush_Lush"
    },
    {
      "x": 7,
      "y": 1,
      "z": 8,
      "name": "Plant_Bush_Lush"
    },
    {
      "x": 7,
      "y": 2,
      "z": 8,
      "name": "Plant_Bush_Lush"
    },
    {
      "x": 7,
      "y": 3,
      "z": 8,
      "name": "Plant_Bush_Lush"
    },
    {
      "x": 7,
      "y": 4,
      "z": 8,
      "name": "Plant_Bush_Lush"
    },
    {
      "x": 7,
      "y": 0,
      "z": 9,
      "name": "Plant_Bush_Lush"
    },
    {
      "x": 7,
      "y": 1,
      "z": 9,
      "name": "Plant_Bush_Lush"
    },
    {
      "x": 7,
      "y": 2,
      "z": 9,
      "name": "Plant_Bush_Lush"
    },
    {
      "x": 7,
      "y": 3,
      "z": 9,
      "name": "Plant_Bush_Lush"
    },
    {
      "x": 7,
      "y": 4,
      "z": 9,
      "name": "Plant_Bush_Lush"
    },
    {
      "x": 7,
      "y": 1,
      "z": 10,
      "name": "Plant_Bush_Lush"
    },
    {
      "x": 7,
      "y": 2,
      "z": 10,
      "name": "Plant_Bush_Lush"
    },
    {
      "x": 7,
      "y": 3,
      "z": 10,
      "name": "Plant_Bush_Lush"
    },
    {
      "x": 7,
      "y": 4,
      "z": 10,
      "name": "Plant_Bush_Lush"
    },
    {
      "x": 8,
      "y": 2,
      "z": 8,
      "name": "Plant_Bush_Lush"
    },
    {
      "x": 8,
      "y": 3,
      "z": 8,
      "name": "Plant_Bush_Lush"
    },
    {
      "x": 8,
      "y": 1,
      "z": 9,
      "name": "Plant_Bush_Lush"
    },
    {
      "x": 8,
      "y": 2,
      "z": 9,
      "name": "Plant_Bush_Lush"
    },
    {
      "x": 8,
      "y": 3,
      "z": 9,
      "name": "Plant_Bush_Lush"
    },
    {
      "x": 8,
      "y": 3,
      "z": 10,
      "name": "Plant_Bush_Lush"
    },
    {
      "x": 9,
      "y": 3,
      "z": 7,
      "name": "Plant_Bush_Lush"
    }
  ]
}