{
  "version": 8,
  "blockIdVersion": 11,
  "anchorX": -9,
  "anchorY": 26,
  "anchorZ": -2,
  "blocks": [
    {
      "x": -32,
      "y": 30,
      "z": -18,
      "name": "Soil_Snow"
    },
    {
      "x": -32,
      "y": 28,
      "z": -17,
      "name": "Rock_Ice"
    },
    {
      "x": -32,
      "y": 29,
      "z": -17,
      "name": "Rock_Ice"
    },
    {
      "x": -32,
      "y": 30,
      "z": -17,
      "name": "Rock_Ice"
    },
    {
      "x": -32,
      "y": 31,
      "z": -17,
      "name": "Rock_Ice"
    },
    {
      "x": -32,
      "y": 27,
      "z": -16,
      "name": "Rock_Ice"
    },
    {
      "x": -32,
      "y": 28,
      "z": -16,
      "name": "Rock_Ice"
    },
    {
      "x": -32,
      "y": 29,
      "z": -16,
      "name": "Rock_Ice"
    },
    {
      "x": -32,
      "y": 30,
      "z": -16,
      "name": "Rock_Ice"
    },
    {
      "x": -32,
      "y": 31,
      "z": -16,
      "name": "Rock_Ice"
    },
    {
      "x": -32,
      "y": 26,
      "z": -15,
      "name": "Rock_Ice"
    },
    {
      "x": -32,
      "y": 27,
      "z": -15,
      "name": "Rock_Ice"
    },
    {
      "x": -32,
      "y": 28,
      "z": -15,
      "name": "Rock_Ice"
    },
    {
      "x": -32,
      "y": 29,
      "z": -15,
      "name": "Rock_Ice"
    },
    {
      "x": -32,
      "y": 30,
      "z": -15,
      "name": "Rock_Ice"
    },
    {
      "x": -32,
      "y": 31,
      "z": -15,
      "name": "Rock_Ice"
    },
    {
      "x": -32,
      "y": 26,
      "z": -14,
      "name": "Rock_Ice"
    },
    {
      "x": -32,
      "y": 27,
      "z": -14,
      "name": "Rock_Ice_Permafrost"
    },
    {
      "x": -32,
      "y": 28,
      "z": -14,
      "name": "Rock_Ice_Permafrost"
    },
    {
      "x": -32,
      "y": 29,
      "z": -14,
      "name": "Rock_Ice"
    },
    {
      "x": -32,
      "y": 30,
      "z": -14,
      "name": "Rock_Ice"
    },
    {
      "x": -32,
      "y": 31,
      "z": -14,
      "name": "Rock_Ice"
    },
    {
      "x": -32,
      "y": 25,
      "z": -13,
      "name": "Rock_Ice"
    },
    {
      "x": -32,
      "y": 26,
      "z": -13,
      "name": "Rock_Ice_Permafrost"
    },
    {
      "x": -32,
      "y": 27,
      "z": -13,
      "name": "Rock_Ice_Permafrost"
    },
    {
      "x": -32,
      "y": 28,
      "z": -13,
      "name": "Rock_Ice_Permafrost"
    },
    {
      "x": -32,
      "y": 29,
      "z": -13,
      "name": "Rock_Ice_Permafrost"
    },
    {
      "x": -32,
      "y": 30,
      "z": -13,
      "name": "Rock_Ice"
    },
    {
      "x": -32,
      "y": 31,
      "z": -13,
      "name": "Soil_Snow"
    },
    {
      "x": -32,
      "y": 25,
      "z": -12,
      "name": "Rock_Ice"
    },
    {
      "x": -32,
      "y": 26,
      "z": -12,
      "name": "Rock_Ice_Permafrost"
    },
    {
      "x": -32,
      "y": 27,
      "z": -12,
      "name": "Rock_Ice_Permafrost"
    },
    {
      "x": -32,
      "y": 28,
      "z": -12,
      "name": "Rock_Ice_Permafrost"
    },
    {
      "x": -32,
      "y": 29,
      "z": -12,
      "name": "Soil_Snow"
    },
    {
      "x": -32,
      "y": 25,
      "z": -11,
      "name": "Rock_Ice_Permafrost"
    },
    {
      "x": -32,
      "y": 26,
      "z": -11,
      "name": "Rock_Ice_Permafrost"
    },
    {
      "x": -32,
      "y": 27,
      "z": -11,
      "name": "Rock_Ice"
    },
    {
      "x": -32,
      "y": 28,
      "z": -11,
      "name": "Soil_Snow"
    },
    {
      "x": -32,
      "y": 25,
      "z": -10,
      "name": "Rock_Ice"
    },
    {
      "x": -32,
      "y": 26,
      "z": -10,
      "name": "Soil_Snow"
    },
    {
      "x": -31,
      "y": 29,
      "z": -19,
      "name": "Rock_Ice"
    },
    {
      "x": -31,
      "y": 30,
      "z": -19,
      "name": "Rock_Ice"
    },
    {
      "x": -31,
      "y": 31,
      "z": -19,
      "name": "Rock_Ice"
    },
    {
      "x": -31,
      "y": 32,
      "z": -19,
      "name": "Soil_Snow"
    },
    {
      "x": -31,
      "y": 27,
      "z": -18,
      "name": "Rock_Ice"
    },
    {
      "x": -31,
      "y": 28,
      "z": -18,
      "name": "Rock_Ice"
    },
    {
      "x": -31,
      "y": 29,
      "z": -18,
      "name": "Rock_Ice"
    },
    {
      "x": -31,
      "y": 30,
      "z": -18,
      "name": "Rock_Ice"
    },
    {
      "x": -31,
      "y": 31,
      "z": -18,
      "name": "Rock_Ice"
    },
    {
      "x": -31,
      "y": 32,
      "z": -18,
      "name": "Rock_Ice"
    },
    {
      "x": -31,
      "y": 26,
      "z": -17,
      "name": "Rock_Ice"
    },
    {
      "x": -31,
      "y": 27,
      "z": -17,
      "name": "Rock_Ice"
    },
    {
      "x": -31,
      "y": 28,
      "z": -17,
      "name": "Rock_Ice"
    },
    {
      "x": -31,
      "y": 29,
      "z": -17,
      "name": "Rock_Ice"
    },
    {
      "x": -31,
      "y": 30,
      "z": -17,
      "name": "Rock_Ice"
    },
    {
      "x": -31,
      "y": 31,
      "z": -17,
      "name": "Rock_Ice"
    },
    {
      "x": -31,
      "y": 32,
      "z": -17,
      "name": "Rock_Ice"
    },
    {
      "x": -31,
      "y": 33,
      "z": -17,
      "name": "Rock_Ice"
    },
    {
      "x": -31,
      "y": 25,
      "z": -16,
      "name": "Rock_Ice"
    },
    {
      "x": -31,
      "y": 26,
      "z": -16,
      "name": "Rock_Ice"
    },
    {
      "x": -31,
      "y": 27,
      "z": -16,
      "name": "Rock_Ice"
    },
    {
      "x": -31,
      "y": 28,
      "z": -16,
      "name": "Rock_Ice"
    },
    {
      "x": -31,
      "y": 29,
      "z": -16,
      "name": "Rock_Ice"
    },
    {
      "x": -31,
      "y": 30,
      "z": -16,
      "name": "Rock_Ice"
    },
    {
      "x": -31,
      "y": 31,
      "z": -16,
      "name": "Rock_Ice"
    },
    {
      "x": -31,
      "y": 32,
      "z": -16,
      "name": "Rock_Ice"
    },
    {
      "x": -31,
      "y": 33,
      "z": -16,
      "name": "Rock_Ice"
    },
    {
      "x": -31,
      "y": 34,
      "z": -16,
      "name": "Rock_Ice"
    },
    {
      "x": -31,
      "y": 24,
      "z": -15,
      "name": "Rock_Ice"
    },
    {
      "x": -31,
      "y": 25,
      "z": -15,
      "name": "Rock_Ice"
    },
    {
      "x": -31,
      "y": 26,
      "z": -15,
      "name": "Rock_Ice"
    },
    {
      "x": -31,
      "y": 27,
      "z": -15,
      "name": "Rock_Ice"
    },
    {
      "x": -31,
      "y": 28,
      "z": -15,
      "name": "Rock_Ice"
    },
    {
      "x": -31,
      "y": 29,
      "z": -15,
      "name": "Rock_Ice"
    },
    {
      "x": -31,
      "y": 30,
      "z": -15,
      "name": "Rock_Ice"
    },
    {
      "x": -31,
      "y": 31,
      "z": -15,
      "name": "Rock_Ice"
    },
    {
      "x": -31,
      "y": 32,
      "z": -15,
      "name": "Rock_Ice"
    },
    {
      "x": -31,
      "y": 33,
      "z": -15,
      "name": "Rock_Ice"
    },
    {
      "x": -31,
      "y": 34,
      "z": -15,
      "name": "Soil_Snow"
    },
    {
      "x": -31,
      "y": 24,
      "z": -14,
      "name": "Rock_Ice"
    },
    {
      "x": -31,
      "y": 25,
      "z": -14,
      "name": "Rock_Ice"
    },
    {
      "x": -31,
      "y": 26,
      "z": -14,
      "name": "Rock_Ice"
    },
    {
      "x": -31,
      "y": 27,
      "z": -14,
      "name": "Rock_Ice_Permafrost"
    },
    {
      "x": -31,
      "y": 28,
      "z": -14,
      "name": "Rock_Ice"
    },
    {
      "x": -31,
      "y": 29,
      "z": -14,
      "name": "Rock_Ice_Permafrost"
    },
    {
      "x": -31,
      "y": 30,
      "z": -14,
      "name": "Rock_Ice_Permafrost"
    },
    {
      "x": -31,
      "y": 31,
      "z": -14,
      "name": "Rock_Ice_Permafrost"
    },
    {
      "x": -31,
      "y": 32,
      "z": -14,
      "name": "Rock_Ice"
    },
    {
      "x": -31,
      "y": 33,
      "z": -14,
      "name": "Soil_Snow"
    },
    {
      "x": -31,
      "y": 23,
      "z": -13,
      "name": "Rock_Ice"
    },
    {
      "x": -31,
      "y": 24,
      "z": -13,
      "name": "Rock_Ice"
    },
    {
      "x": -31,
      "y": 25,
      "z": -13,
      "name": "Rock_Ice_Permafrost"
    },
    {
      "x": -31,
      "y": 26,
      "z": -13,
      "name": "Rock_Ice_Permafrost"
    },
    {
      "x": -31,
      "y": 27,
      "z": -13,
      "name": "Rock_Ice_Permafrost"
    },
    {
      "x": -31,
      "y": 28,
      "z": -13,
      "name": "Rock_Ice_Permafrost"
    },
    {
      "x": -31,
      "y": 29,
      "z": -13,
      "name": "Rock_Ice_Permafrost"
    },
    {
      "x": -31,
      "y": 30,
      "z": -13,
      "name": "Rock_Ice"
    },
    {
      "x": -31,
      "y": 31,
      "z": -13,
      "name": "Soil_Snow"
    },
    {
      "x": -31,
      "y": 23,
      "z": -12,
      "name": "Rock_Ice"
    },
    {
      "x": -31,
      "y": 24,
      "z": -12,
      "name": "Rock_Ice"
    },
    {
      "x": -31,
      "y": 25,
      "z": -12,
      "name": "Rock_Ice_Permafrost"
    },
    {
      "x": -31,
      "y": 26,
      "z": -12,
      "name": "Rock_Ice_Permafrost"
    },
    {
      "x": -31,
      "y": 27,
      "z": -12,
      "name": "Rock_Ice_Permafrost"
    },
    {
      "x": -31,
      "y": 28,
      "z": -12,
      "name": "Rock_Ice_Permafrost"
    },
    {
      "x": -31,
      "y": 29,
      "z": -12,
      "name": "Rock_Ice"
    },
    {
      "x": -31,
      "y": 30,
      "z": -12,
      "name": "Soil_Snow"
    },
    {
      "x": -31,
      "y": 23,
      "z": -11,
      "name": "Rock_Ice_Permafrost"
    },
    {
      "x": -31,
      "y": 24,
      "z": -11,
      "name": "Rock_Ice_Permafrost"
    },
    {
      "x": -31,
      "y": 25,
      "z": -11,
      "name": "Rock_Ice_Permafrost"
    },
    {
      "x": -31,
      "y": 26,
      "z": -11,
      "name": "Rock_Ice_Permafrost"
    },
    {
      "x": -31,
      "y": 27,
      "z": -11,
      "name": "Rock_Ice"
    },
    {
      "x": -31,
      "y": 28,
      "z": -11,
      "name": "Soil_Snow"
    },
    {
      "x": -31,
      "y": 23,
      "z": -10,
      "name": "Rock_Ice_Permafrost"
    },
    {
      "x": -31,
      "y": 24,
      "z": -10,
      "name": "Rock_Ice_Permafrost"
    },
    {
      "x": -31,
      "y": 25,
      "z": -10,
      "name": "Rock_Ice_Permafrost"
    },
    {
      "x": -31,
      "y": 26,
      "z": -10,
      "name": "Rock_Ice"
    },
    {
      "x": -31,
      "y": 27,
      "z": -10,
      "name": "Soil_Snow"
    },
    {
      "x": -31,
      "y": 23,
      "z": -9,
      "name": "Rock_Ice_Permafrost"
    },
    {
      "x": -31,
      "y": 24,
      "z": -9,
      "name": "Rock_Ice"
    },
    {
      "x": -31,
      "y": 25,
      "z": -9,
      "name": "Soil_Snow"
    },
    {
      "x": -30,
      "y": 31,
      "z": -21,
      "name": "Rock_Ice"
    },
    {
      "x": -30,
      "y": 32,
      "z": -21,
      "name": "Soil_Snow"
    },
    {
      "x": -30,
      "y": 28,
      "z": -20,
      "name": "Rock_Ice"
    },
    {
      "x": -30,
      "y": 29,
      "z": -20,
      "name": "Rock_Ice"
    },
    {
      "x": -30,
      "y": 30,
      "z": -20,
      "name": "Rock_Ice"
    },
    {
      "x": -30,
      "y": 31,
      "z": -20,
      "name": "Rock_Ice"
    },
    {
      "x": -30,
      "y": 32,
      "z": -20,
      "name": "Rock_Ice"
    },
    {
      "x": -30,
      "y": 33,
      "z": -20,
      "name": "Soil_Snow"
    },
    {
      "x": -30,
      "y": 26,
      "z": -19,
      "name": "Rock_Ice"
    },
    {
      "x": -30,
      "y": 27,
      "z": -19,
      "name": "Rock_Ice"
    },
    {
      "x": -30,
      "y": 28,
      "z": -19,
      "name": "Rock_Ice"
    },
    {
      "x": -30,
      "y": 29,
      "z": -19,
      "name": "Rock_Ice"
    },
    {
      "x": -30,
      "y": 30,
      "z": -19,
      "name": "Rock_Ice"
    },
    {
      "x": -30,
      "y": 31,
      "z": -19,
      "name": "Rock_Ice"
    },
    {
      "x": -30,
      "y": 32,
      "z": -19,
      "name": "Rock_Ice"
    },
    {
      "x": -30,
      "y": 33,
      "z": -19,
      "name": "Rock_Ice"
    },
    {
      "x": -30,
      "y": 34,
      "z": -19,
      "name": "Soil_Snow"
    },
    {
      "x": -30,
      "y": 24,
      "z": -18,
      "name": "Rock_Ice"
    },
    {
      "x": -30,
      "y": 25,
      "z": -18,
      "name": "Rock_Ice"
    },
    {
      "x": -30,
      "y": 26,
      "z": -18,
      "name": "Rock_Ice"
    },
    {
      "x": -30,
      "y": 27,
      "z": -18,
      "name": "Rock_Ice"
    },
    {
      "x": -30,
      "y": 28,
      "z": -18,
      "name": "Rock_Ice"
    },
    {
      "x": -30,
      "y": 29,
      "z": -18,
      "name": "Rock_Ice"
    },
    {
      "x": -30,
      "y": 30,
      "z": -18,
      "name": "Rock_Ice"
    },
    {
      "x": -30,
      "y": 31,
      "z": -18,
      "name": "Rock_Ice"
    },
    {
      "x": -30,
      "y": 32,
      "z": -18,
      "name": "Rock_Ice"
    },
    {
      "x": -30,
      "y": 33,
      "z": -18,
      "name": "Rock_Ice"
    },
    {
      "x": -30,
      "y": 34,
      "z": -18,
      "name": "Rock_Ice"
    },
    {
      "x": -30,
      "y": 35,
      "z": -18,
      "name": "Rock_Ice"
    },
    {
      "x": -30,
      "y": 23,
      "z": -17,
      "name": "Rock_Ice"
    },
    {
      "x": -30,
      "y": 24,
      "z": -17,
      "name": "Rock_Ice"
    },
    {
      "x": -30,
      "y": 25,
      "z": -17,
      "name": "Rock_Ice"
    },
    {
      "x": -30,
      "y": 26,
      "z": -17,
      "name": "Rock_Ice"
    },
    {
      "x": -30,
      "y": 27,
      "z": -17,
      "name": "Rock_Ice"
    },
    {
      "x": -30,
      "y": 28,
      "z": -17,
      "name": "Rock_Ice"
    },
    {
      "x": -30,
      "y": 29,
      "z": -17,
      "name": "Rock_Ice"
    },
    {
      "x": -30,
      "y": 30,
      "z": -17,
      "name": "Rock_Ice"
    },
    {
      "x": -30,
      "y": 31,
      "z": -17,
      "name": "Rock_Ice"
    },
    {
      "x": -30,
      "y": 32,
      "z": -17,
      "name": "Rock_Ice"
    },
    {
      "x": -30,
      "y": 33,
      "z": -17,
      "name": "Rock_Ice"
    },
    {
      "x": -30,
      "y": 34,
      "z": -17,
      "name": "Rock_Ice"
    },
    {
      "x": -30,
      "y": 35,
      "z": -17,
      "name": "Rock_Ice"
    },
    {
      "x": -30,
      "y": 36,
      "z": -17,
      "name": "Rock_Ice"
    },
    {
      "x": -30,
      "y": 22,
      "z": -16,
      "name": "Rock_Ice"
    },
    {
      "x": -30,
      "y": 23,
      "z": -16,
      "name": "Rock_Ice"
    },
    {
      "x": -30,
      "y": 24,
      "z": -16,
      "name": "Rock_Ice"
    },
    {
      "x": -30,
      "y": 25,
      "z": -16,
      "name": "Rock_Ice"
    },
    {
      "x": -30,
      "y": 26,
      "z": -16,
      "name": "Rock_Ice"
    },
    {
      "x": -30,
      "y": 27,
      "z": -16,
      "name": "Rock_Ice"
    },
    {
      "x": -30,
      "y": 28,
      "z": -16,
      "name": "Rock_Ice"
    },
    {
      "x": -30,
      "y": 29,
      "z": -16,
      "name": "Rock_Ice"
    },
    {
      "x": -30,
      "y": 30,
      "z": -16,
      "name": "Rock_Ice"
    },
    {
      "x": -30,
      "y": 31,
      "z": -16,
      "name": "Rock_Ice"
    },
    {
      "x": -30,
      "y": 32,
      "z": -16,
      "name": "Rock_Ice"
    },
    {
      "x": -30,
      "y": 33,
      "z": -16,
      "name": "Rock_Ice"
    },
    {
      "x": -30,
      "y": 34,
      "z": -16,
      "name": "Rock_Ice"
    },
    {
      "x": -30,
      "y": 35,
      "z": -16,
      "name": "Rock_Ice"
    },
    {
      "x": -30,
      "y": 36,
      "z": -16,
      "name": "Soil_Snow"
    },
    {
      "x": -30,
      "y": 22,
      "z": -15,
      "name": "Rock_Ice"
    },
    {
      "x": -30,
      "y": 23,
      "z": -15,
      "name": "Rock_Ice"
    },
    {
      "x": -30,
      "y": 24,
      "z": -15,
      "name": "Rock_Ice"
    },
    {
      "x": -30,
      "y": 25,
      "z": -15,
      "name": "Rock_Ice"
    },
    {
      "x": -30,
      "y": 26,
      "z": -15,
      "name": "Rock_Ice"
    },
    {
      "x": -30,
      "y": 27,
      "z": -15,
      "name": "Rock_Ice"
    },
    {
      "x": -30,
      "y": 28,
      "z": -15,
      "name": "Rock_Ice"
    },
    {
      "x": -30,
      "y": 29,
      "z": -15,
      "name": "Rock_Ice"
    },
    {
      "x": -30,
      "y": 30,
      "z": -15,
      "name": "Rock_Ice"
    },
    {
      "x": -30,
      "y": 31,
      "z": -15,
      "name": "Rock_Ice_Permafrost"
    },
    {
      "x": -30,
      "y": 32,
      "z": -15,
      "name": "Rock_Ice"
    },
    {
      "x": -30,
      "y": 33,
      "z": -15,
      "name": "Rock_Ice"
    },
    {
      "x": -30,
      "y": 34,
      "z": -15,
      "name": "Rock_Ice"
    },
    {
      "x": -30,
      "y": 35,
      "z": -15,
      "name": "Soil_Snow"
    },
    {
      "x": -30,
      "y": 21,
      "z": -14,
      "name": "Rock_Ice"
    },
    {
      "x": -30,
      "y": 22,
      "z": -14,
      "name": "Rock_Ice"
    },
    {
      "x": -30,
      "y": 23,
      "z": -14,
      "name": "Rock_Ice"
    },
    {
      "x": -30,
      "y": 24,
      "z": -14,
      "name": "Rock_Ice"
    },
    {
      "x": -30,
      "y": 25,
      "z": -14,
      "name": "Rock_Ice"
    },
    {
      "x": -30,
      "y": 26,
      "z": -14,
      "name": "Rock_Ice"
    },
    {
      "x": -30,
      "y": 27,
      "z": -14,
      "name": "Rock_Ice_Permafrost"
    },
    {
      "x": -30,
      "y": 28,
      "z": -14,
      "name": "Rock_Ice_Permafrost"
    },
    {
      "x": -30,
      "y": 29,
      "z": -14,
      "name": "Rock_Ice_Permafrost"
    },
    {
      "x": -30,
      "y": 30,
      "z": -14,
      "name": "Rock_Ice_Permafrost"
    },
    {
      "x": -30,
      "y": 31,
      "z": -14,
      "name": "Rock_Ice_Permafrost"
    },
    {
      "x": -30,
      "y": 32,
      "z": -14,
      "name": "Rock_Ice"
    },
    {
      "x": -30,
      "y": 33,
      "z": -14,
      "name": "Soil_Snow"
    },
    {
      "x": -30,
      "y": 21,
      "z": -13,
      "name": "Rock_Ice"
    },
    {
      "x": -30,
      "y": 22,
      "z": -13,
      "name": "Rock_Ice"
    },
    {
      "x": -30,
      "y": 23,
      "z": -13,
      "name": "Rock_Ice"
    },
    {
      "x": -30,
      "y": 24,
      "z": -13,
      "name": "Rock_Ice"
    },
    {
      "x": -30,
      "y": 25,
      "z": -13,
      "name": "Rock_Ice"
    },
    {
      "x": -30,
      "y": 26,
      "z": -13,
      "name": "Rock_Ice_Permafrost"
    },
    {
      "x": -30,
      "y": 27,
      "z": -13,
      "name": "Rock_Ice_Permafrost"
    },
    {
      "x": -30,
      "y": 28,
      "z": -13,
      "name": "Rock_Ice_Permafrost"
    },
    {
      "x": -30,
      "y": 29,
      "z": -13,
      "name": "Rock_Ice_Permafrost"
    },
    {
      "x": -30,
      "y": 30,
      "z": -13,
      "name": "Rock_Ice_Permafrost"
    },
    {
      "x": -30,
      "y": 31,
      "z": -13,
      "name": "Rock_Ice"
    },
    {
      "x": -30,
      "y": 32,
      "z": -13,
      "name": "Soil_Snow"
    },
    {
      "x": -30,
      "y": 21,
      "z": -12,
      "name": "Rock_Ice"
    },
    {
      "x": -30,
      "y": 22,
      "z": -12,
      "name": "Rock_Ice"
    },
    {
      "x": -30,
      "y": 23,
      "z": -12,
      "name": "Rock_Ice"
    },
    {
      "x": -30,
      "y": 24,
      "z": -12,
      "name": "Rock_Ice"
    },
    {
      "x": -30,
      "y": 25,
      "z": -12,
      "name": "Rock_Ice_Permafrost"
    },
    {
      "x": -30,
      "y": 26,
      "z": -12,
      "name": "Rock_Ice_Permafrost"
    },
    {
      "x": -30,
      "y": 27,
      "z": -12,
      "name": "Rock_Ice_Permafrost"
    },
    {
      "x": -30,
      "y": 28,
      "z": -12,
      "name": "Rock_Ice_Permafrost"
    },
    {
      "x": -30,
      "y": 29,
      "z": -12,
      "name": "Rock_Ice"
    },
    {
      "x": -30,
      "y": 30,
      "z": -12,
      "name": "Soil_Snow"
    },
    {
      "x": -30,
      "y": 21,
      "z": -11,
      "name": "Rock_Ice"
    },
    {
      "x": -30,
      "y": 22,
      "z": -11,
      "name": "Rock_Ice"
    },
    {
      "x": -30,
      "y": 23,
      "z": -11,
      "name": "Rock_Ice_Permafrost"
    },
    {
      "x": -30,
      "y": 24,
      "z": -11,
      "name": "Rock_Ice_Permafrost"
    },
    {
      "x": -30,
      "y": 25,
      "z": -11,
      "name": "Rock_Ice_Permafrost"
    },
    {
      "x": -30,
      "y": 26,
      "z": -11,
      "name": "Rock_Ice_Permafrost"
    },
    {
      "x": -30,
      "y": 27,
      "z": -11,
      "name": "Rock_Ice_Permafrost"
    },
    {
      "x": -30,
      "y": 28,
      "z": -11,
      "name": "Rock_Ice"
    },
    {
      "x": -30,
      "y": 29,
      "z": -11,
      "name": "Soil_Snow"
    },
    {
      "x": -30,
      "y": 21,
      "z": -10,
      "name": "Rock_Ice"
    },
    {
      "x": -30,
      "y": 22,
      "z": -10,
      "name": "Rock_Ice"
    },
    {
      "x": -30,
      "y": 23,
      "z": -10,
      "name": "Rock_Ice_Permafrost"
    },
    {
      "x": -30,
      "y": 24,
      "z": -10,
      "name": "Rock_Ice_Permafrost"
    },
    {
      "x": -30,
      "y": 25,
      "z": -10,
      "name": "Rock_Ice_Permafrost"
    },
    {
      "x": -30,
      "y": 26,
      "z": -10,
      "name": "Rock_Ice"
    },
    {
      "x": -30,
      "y": 27,
      "z": -10,
      "name": "Soil_Snow"
    },
    {
      "x": -30,
      "y": 21,
      "z": -9,
      "name": "Rock_Ice"
    },
    {
      "x": -30,
      "y": 22,
      "z": -9,
      "name": "Rock_Ice_Permafrost"
    },
    {
      "x": -30,
      "y": 23,
      "z": -9,
      "name": "Rock_Ice_Permafrost"
    },
    {
      "x": -30,
      "y": 24,
      "z": -9,
      "name": "Rock_Ice_Permafrost"
    },
    {
      "x": -30,
      "y": 25,
      "z": -9,
      "name": "Rock_Ice"
    },
    {
      "x": -30,
      "y": 26,
      "z": -9,
      "name": "Soil_Snow"
    },
    {
      "x": -30,
      "y": 20,
      "z": -8,
      "name": "Rock_Ice"
    },
    {
      "x": -30,
      "y": 21,
      "z": -8,
      "name": "Rock_Ice_Permafrost"
    },
    {
      "x": -30,
      "y": 22,
      "z": -8,
      "name": "Rock_Ice_Permafrost"
    },
    {
      "x": -30,
      "y": 23,
      "z": -8,
      "name": "Rock_Ice"
    },
    {
      "x": -30,
      "y": 24,
      "z": -8,
      "name": "Soil_Snow"
    },
    {
      "x": -30,
      "y": 20,
      "z": -7,
      "name": "Rock_Ice"
    },
    {
      "x": -30,
      "y": 21,
      "z": -7,
      "name": "Soil_Snow"
    },
    {
      "x": -29,
      "y": 31,
      "z": -22,
      "name": "Rock_Ice"
    },
    {
      "x": -29,
      "y": 32,
      "z": -22,
      "name": "Rock_Ice"
    },
    {
      "x": -29,
      "y": 33,
      "z": -22,
      "name": "Soil_Snow"
    },
    {
      "x": -29,
      "y": 28,
      "z": -21,
      "name": "Rock_Ice"
    },
    {
      "x": -29,
      "y": 29,
      "z": -21,
      "name": "Rock_Ice"
    },
    {
      "x": -29,
      "y": 30,
      "z": -21,
      "name": "Rock_Ice"
    },
    {
      "x": -29,
      "y": 31,
      "z": -21,
      "name": "Rock_Ice"
    },
    {
      "x": -29,
      "y": 32,
      "z": -21,
      "name": "Rock_Ice"
    },
    {
      "x": -29,
      "y": 33,
      "z": -21,
      "name": "Rock_Ice"
    },
    {
      "x": -29,
      "y": 34,
      "z": -21,
      "name": "Rock_Ice"
    },
    {
      "x": -29,
      "y": 35,
      "z": -21,
      "name": "Soil_Snow"
    },
    {
      "x": -29,
      "y": 26,
      "z": -20,
      "name": "Rock_Ice"
    },
    {
      "x": -29,
      "y": 27,
      "z": -20,
      "name": "Rock_Ice"
    },
    {
      "x": -29,
      "y": 28,
      "z": -20,
      "name": "Rock_Ice"
    },
    {
      "x": -29,
      "y": 29,
      "z": -20,
      "name": "Rock_Ice"
    },
    {
      "x": -29,
      "y": 30,
      "z": -20,
      "name": "Rock_Ice"
    },
    {
      "x": -29,
      "y": 31,
      "z": -20,
      "name": "Rock_Ice"
    },
    {
      "x": -29,
      "y": 32,
      "z": -20,
      "name": "Rock_Ice"
    },
    {
      "x": -29,
      "y": 33,
      "z": -20,
      "name": "Rock_Ice"
    },
    {
      "x": -29,
      "y": 34,
      "z": -20,
      "name": "Rock_Ice"
    },
    {
      "x": -29,
      "y": 35,
      "z": -20,
      "name": "Rock_Ice"
    },
    {
      "x": -29,
      "y": 36,
      "z": -20,
      "name": "Soil_Snow"
    },
    {
      "x": -29,
      "y": 23,
      "z": -19,
      "name": "Rock_Ice"
    },
    {
      "x": -29,
      "y": 24,
      "z": -19,
      "name": "Rock_Ice"
    },
    {
      "x": -29,
      "y": 25,
      "z": -19,
      "name": "Rock_Ice"
    },
    {
      "x": -29,
      "y": 26,
      "z": -19,
      "name": "Rock_Ice"
    },
    {
      "x": -29,
      "y": 27,
      "z": -19,
      "name": "Rock_Ice"
    },
    {
      "x": -29,
      "y": 28,
      "z": -19,
      "name": "Rock_Ice"
    },
    {
      "x": -29,
      "y": 29,
      "z": -19,
      "name": "Rock_Ice"
    },
    {
      "x": -29,
      "y": 30,
      "z": -19,
      "name": "Rock_Ice"
    },
    {
      "x": -29,
      "y": 31,
      "z": -19,
      "name": "Rock_Ice"
    },
    {
      "x": -29,
      "y": 32,
      "z": -19,
      "name": "Rock_Ice"
    },
    {
      "x": -29,
      "y": 33,
      "z": -19,
      "name": "Rock_Ice"
    },
    {
      "x": -29,
      "y": 34,
      "z": -19,
      "name": "Rock_Ice"
    },
    {
      "x": -29,
      "y": 35,
      "z": -19,
      "name": "Rock_Ice"
    },
    {
      "x": -29,
      "y": 36,
      "z": -19,
      "name": "Rock_Ice"
    },
    {
      "x": -29,
      "y": 37,
      "z": -19,
      "name": "Rock_Ice"
    },
    {
      "x": -29,
      "y": 21,
      "z": -18,
      "name": "Rock_Ice"
    },
    {
      "x": -29,
      "y": 22,
      "z": -18,
      "name": "Rock_Ice"
    },
    {
      "x": -29,
      "y": 23,
      "z": -18,
      "name": "Rock_Ice"
    },
    {
      "x": -29,
      "y": 24,
      "z": -18,
      "name": "Rock_Ice"
    },
    {
      "x": -29,
      "y": 25,
      "z": -18,
      "name": "Rock_Ice"
    },
    {
      "x": -29,
      "y": 26,
      "z": -18,
      "name": "Rock_Ice"
    },
    {
      "x": -29,
      "y": 27,
      "z": -18,
      "name": "Rock_Ice"
    },
    {
      "x": -29,
      "y": 28,
      "z": -18,
      "name": "Rock_Ice"
    },
    {
      "x": -29,
      "y": 29,
      "z": -18,
      "name": "Rock_Ice"
    },
    {
      "x": -29,
      "y": 30,
      "z": -18,
      "name": "Rock_Ice"
    },
    {
      "x": -29,
      "y": 31,
      "z": -18,
      "name": "Rock_Ice"
    },
    {
      "x": -29,
      "y": 32,
      "z": -18,
      "name": "Rock_Ice"
    },
    {
      "x": -29,
      "y": 33,
      "z": -18,
      "name": "Rock_Ice"
    },
    {
      "x": -29,
      "y": 34,
      "z": -18,
      "name": "Rock_Ice"
    },
    {
      "x": -29,
      "y": 35,
      "z": -18,
      "name": "Rock_Ice"
    },
    {
      "x": -29,
      "y": 36,
      "z": -18,
      "name": "Rock_Ice"
    },
    {
      "x": -29,
      "y": 37,
      "z": -18,
      "name": "Rock_Ice"
    },
    {
      "x": -29,
      "y": 19,
      "z": -17,
      "name": "Rock_Ice"
    },
    {
      "x": -29,
      "y": 20,
      "z": -17,
      "name": "Rock_Ice"
    },
    {
      "x": -29,
      "y": 21,
      "z": -17,
      "name": "Rock_Ice"
    },
    {
      "x": -29,
      "y": 22,
      "z": -17,
      "name": "Rock_Ice"
    },
    {
      "x": -29,
      "y": 23,
      "z": -17,
      "name": "Rock_Ice"
    },
    {
      "x": -29,
      "y": 24,
      "z": -17,
      "name": "Rock_Ice"
    },
    {
      "x": -29,
      "y": 25,
      "z": -17,
      "name": "Rock_Ice"
    },
    {
      "x": -29,
      "y": 26,
      "z": -17,
      "name": "Rock_Ice"
    },
    {
      "x": -29,
      "y": 27,
      "z": -17,
      "name": "Rock_Ice"
    },
    {
      "x": -29,
      "y": 28,
      "z": -17,
      "name": "Rock_Ice"
    },
    {
      "x": -29,
      "y": 29,
      "z": -17,
      "name": "Rock_Ice"
    },
    {
      "x": -29,
      "y": 30,
      "z": -17,
      "name": "Rock_Ice"
    },
    {
      "x": -29,
      "y": 31,
      "z": -17,
      "name": "Rock_Ice"
    },
    {
      "x": -29,
      "y": 32,
      "z": -17,
      "name": "Rock_Ice"
    },
    {
      "x": -29,
      "y": 33,
      "z": -17,
      "name": "Rock_Ice"
    },
    {
      "x": -29,
      "y": 34,
      "z": -17,
      "name": "Rock_Ice"
    },
    {
      "x": -29,
      "y": 35,
      "z": -17,
      "name": "Rock_Ice"
    },
    {
      "x": -29,
      "y": 36,
      "z": -17,
      "name": "Rock_Ice"
    },
    {
      "x": -29,
      "y": 37,
      "z": -17,
      "name": "Rock_Ice"
    },
    {
      "x": -29,
      "y": 38,
      "z": -17,
      "name": "Soil_Snow"
    },
    {
      "x": -29,
      "y": 19,
      "z": -16,
      "name": "Rock_Ice"
    },
    {
      "x": -29,
      "y": 20,
      "z": -16,
      "name": "Rock_Ice"
    },
    {
      "x": -29,
      "y": 21,
      "z": -16,
      "name": "Rock_Ice"
    },
    {
      "x": -29,
      "y": 22,
      "z": -16,
      "name": "Rock_Ice"
    },
    {
      "x": -29,
      "y": 23,
      "z": -16,
      "name": "Rock_Ice"
    },
    {
      "x": -29,
      "y": 24,
      "z": -16,
      "name": "Rock_Ice"
    },
    {
      "x": -29,
      "y": 25,
      "z": -16,
      "name": "Rock_Ice"
    },
    {
      "x": -29,
      "y": 26,
      "z": -16,
      "name": "Rock_Ice"
    },
    {
      "x": -29,
      "y": 27,
      "z": -16,
      "name": "Rock_Ice"
    },
    {
      "x": -29,
      "y": 28,
      "z": -16,
      "name": "Rock_Ice"
    },
    {
      "x": -29,
      "y": 29,
      "z": -16,
      "name": "Rock_Ice"
    },
    {
      "x": -29,
      "y": 30,
      "z": -16,
      "name": "Rock_Ice"
    },
    {
      "x": -29,
      "y": 31,
      "z": -16,
      "name": "Rock_Ice"
    },
    {
      "x": -29,
      "y": 32,
      "z": -16,
      "name": "Rock_Ice"
    },
    {
      "x": -29,
      "y": 33,
      "z": -16,
      "name": "Rock_Ice_Permafrost"
    },
    {
      "x": -29,
      "y": 34,
      "z": -16,
      "name": "Rock_Ice"
    },
    {
      "x": -29,
      "y": 35,
      "z": -16,
      "name": "Rock_Ice_Permafrost"
    },
    {
      "x": -29,
      "y": 36,
      "z": -16,
      "name": "Rock_Ice"
    },
    {
      "x": -29,
      "y": 37,
      "z": -16,
      "name": "Soil_Snow"
    },
    {
      "x": -29,
      "y": 19,
      "z": -15,
      "name": "Rock_Ice"
    },
    {
      "x": -29,
      "y": 20,
      "z": -15,
      "name": "Rock_Ice"
    },
    {
      "x": -29,
      "y": 21,
      "z": -15,
      "name": "Rock_Ice"
    },
    {
      "x": -29,
      "y": 22,
      "z": -15,
      "name": "Rock_Ice"
    },
    {
      "x": -29,
      "y": 23,
      "z": -15,
      "name": "Rock_Ice"
    },
    {
      "x": -29,
      "y": 24,
      "z": -15,
      "name": "Rock_Ice"
    },
    {
      "x": -29,
      "y": 25,
      "z": -15,
      "name": "Rock_Ice"
    },
    {
      "x": -29,
      "y": 26,
      "z": -15,
      "name": "Rock_Ice"
    },
    {
      "x": -29,
      "y": 27,
      "z": -15,
      "name": "Rock_Ice"
    },
    {
      "x": -29,
      "y": 28,
      "z": -15,
      "name": "Rock_Ice"
    },
    {
      "x": -29,
      "y": 29,
      "z": -15,
      "name": "Rock_Ice"
    },
    {
      "x": -29,
      "y": 30,
      "z": -15,
      "name": "Rock_Ice"
    },
    {
      "x": -29,
      "y": 31,
      "z": -15,
      "name": "Rock_Ice_Permafrost"
    },
    {
      "x": -29,
      "y": 32,
      "z": -15,
      "name": "Rock_Ice_Permafrost"
    },
    {
      "x": -29,
      "y": 33,
      "z": -15,
      "name": "Rock_Ice"
    },
    {
      "x": -29,
      "y": 34,
      "z": -15,
      "name": "Rock_Ice"
    },
    {
      "x": -29,
      "y": 35,
      "z": -15,
      "name": "Rock_Ice"
    },
    {
      "x": -29,
      "y": 36,
      "z": -15,
      "name": "Soil_Snow"
    },
    {
      "x": -29,
      "y": 18,
      "z": -14,
      "name": "Rock_Ice"
    },
    {
      "x": -29,
      "y": 19,
      "z": -14,
      "name": "Rock_Ice"
    },
    {
      "x": -29,
      "y": 20,
      "z": -14,
      "name": "Rock_Ice"
    },
    {
      "x": -29,
      "y": 21,
      "z": -14,
      "name": "Rock_Ice"
    },
    {
      "x": -29,
      "y": 22,
      "z": -14,
      "name": "Rock_Ice"
    },
    {
      "x": -29,
      "y": 23,
      "z": -14,
      "name": "Rock_Ice"
    },
    {
      "x": -29,
      "y": 24,
      "z": -14,
      "name": "Rock_Ice"
    },
    {
      "x": -29,
      "y": 25,
      "z": -14,
      "name": "Rock_Ice"
    },
    {
      "x": -29,
      "y": 26,
      "z": -14,
      "name": "Rock_Ice_Permafrost"
    },
    {
      "x": -29,
      "y": 27,
      "z": -14,
      "name": "Rock_Ice"
    },
    {
      "x": -29,
      "y": 28,
      "z": -14,
      "name": "Rock_Ice_Permafrost"
    },
    {
      "x": -29,
      "y": 29,
      "z": -14,
      "name": "Rock_Ice_Permafrost"
    },
    {
      "x": -29,
      "y": 30,
      "z": -14,
      "name": "Rock_Ice_Permafrost"
    },
    {
      "x": -29,
      "y": 31,
      "z": -14,
      "name": "Rock_Ice_Permafrost"
    },
    {
      "x": -29,
      "y": 32,
      "z": -14,
      "name": "Rock_Ice"
    },
    {
      "x": -29,
      "y": 33,
      "z": -14,
      "name": "Rock_Ice"
    },
    {
      "x": -29,
      "y": 34,
      "z": -14,
      "name": "Soil_Snow"
    },
    {
      "x": -29,
      "y": 18,
      "z": -13,
      "name": "Rock_Ice"
    },
    {
      "x": -29,
      "y": 19,
      "z": -13,
      "name": "Rock_Ice"
    },
    {
      "x": -29,
      "y": 20,
      "z": -13,
      "name": "Rock_Ice"
    },
    {
      "x": -29,
      "y": 21,
      "z": -13,
      "name": "Rock_Ice"
    },
    {
      "x": -29,
      "y": 22,
      "z": -13,
      "name": "Rock_Ice"
    },
    {
      "x": -29,
      "y": 23,
      "z": -13,
      "name": "Rock_Ice"
    },
    {
      "x": -29,
      "y": 24,
      "z": -13,
      "name": "Rock_Ice_Permafrost"
    },
    {
      "x": -29,
      "y": 25,
      "z": -13,
      "name": "Rock_Ice_Permafrost"
    },
    {
      "x": -29,
      "y": 26,
      "z": -13,
      "name": "Rock_Ice_Permafrost"
    },
    {
      "x": -29,
      "y": 27,
      "z": -13,
      "name": "Rock_Ice_Permafrost"
    },
    {
      "x": -29,
      "y": 28,
      "z": -13,
      "name": "Rock_Ice_Permafrost"
    },
    {
      "x": -29,
      "y": 29,
      "z": -13,
      "name": "Rock_Ice_Permafrost"
    },
    {
      "x": -29,
      "y": 30,
      "z": -13,
      "name": "Rock_Ice"
    },
    {
      "x": -29,
      "y": 31,
      "z": -13,
      "name": "Rock_Ice"
    },
    {
      "x": -29,
      "y": 32,
      "z": -13,
      "name": "Soil_Snow"
    },
    {
      "x": -29,
      "y": 18,
      "z": -12,
      "name": "Rock_Ice"
    },
    {
      "x": -29,
      "y": 19,
      "z": -12,
      "name": "Rock_Ice"
    },
    {
      "x": -29,
      "y": 20,
      "z": -12,
      "name": "Rock_Ice"
    },
    {
      "x": -29,
      "y": 21,
      "z": -12,
      "name": "Rock_Ice"
    },
    {
      "x": -29,
      "y": 22,
      "z": -12,
      "name": "Rock_Ice"
    },
    {
      "x": -29,
      "y": 23,
      "z": -12,
      "name": "Rock_Ice"
    },
    {
      "x": -29,
      "y": 24,
      "z": -12,
      "name": "Rock_Ice_Permafrost"
    },
    {
      "x": -29,
      "y": 25,
      "z": -12,
      "name": "Rock_Ice_Permafrost"
    },
    {
      "x": -29,
      "y": 26,
      "z": -12,
      "name": "Rock_Ice_Permafrost"
    },
    {
      "x": -29,
      "y": 27,
      "z": -12,
      "name": "Rock_Ice_Permafrost"
    },
    {
      "x": -29,
      "y": 28,
      "z": -12,
      "name": "Rock_Ice"
    },
    {
      "x": -29,
      "y": 29,
      "z": -12,
      "name": "Rock_Ice"
    },
    {
      "x": -29,
      "y": 30,
      "z": -12,
      "name": "Rock_Ice"
    },
    {
      "x": -29,
      "y": 31,
      "z": -12,
      "name": "Soil_Snow"
    },
    {
      "x": -29,
      "y": 18,
      "z": -11,
      "name": "Rock_Ice"
    },
    {
      "x": -29,
      "y": 19,
      "z": -11,
      "name": "Rock_Ice"
    },
    {
      "x": -29,
      "y": 20,
      "z": -11,
      "name": "Rock_Ice"
    },
    {
      "x": -29,
      "y": 21,
      "z": -11,
      "name": "Rock_Ice"
    },
    {
      "x": -29,
      "y": 22,
      "z": -11,
      "name": "Rock_Ice_Permafrost"
    },
    {
      "x": -29,
      "y": 23,
      "z": -11,
      "name": "Rock_Ice_Permafrost"
    },
    {
      "x": -29,
      "y": 24,
      "z": -11,
      "name": "Rock_Ice_Permafrost"
    },
    {
      "x": -29,
      "y": 25,
      "z": -11,
      "name": "Rock_Ice_Permafrost"
    },
    {
      "x": -29,
      "y": 26,
      "z": -11,
      "name": "Rock_Ice_Permafrost"
    },
    {
      "x": -29,
      "y": 27,
      "z": -11,
      "name": "Rock_Ice_Permafrost"
    },
    {
      "x": -29,
      "y": 28,
      "z": -11,
      "name": "Rock_Ice"
    },
    {
      "x": -29,
      "y": 29,
      "z": -11,
      "name": "Rock_Ice"
    },
    {
      "x": -29,
      "y": 30,
      "z": -11,
      "name": "Soil_Snow"
    },
    {
      "x": -29,
      "y": 18,
      "z": -10,
      "name": "Rock_Ice"
    },
    {
      "x": -29,
      "y": 19,
      "z": -10,
      "name": "Rock_Ice"
    },
    {
      "x": -29,
      "y": 20,
      "z": -10,
      "name": "Rock_Ice"
    },
    {
      "x": -29,
      "y": 21,
      "z": -10,
      "name": "Rock_Ice_Permafrost"
    },
    {
      "x": -29,
      "y": 22,
      "z": -10,
      "name": "Rock_Ice_Permafrost"
    },
    {
      "x": -29,
      "y": 23,
      "z": -10,
      "name": "Rock_Ice_Permafrost"
    },
    {
      "x": -29,
      "y": 24,
      "z": -10,
      "name": "Rock_Ice_Permafrost"
    },
    {
      "x": -29,
      "y": 25,
      "z": -10,
      "name": "Rock_Ice_Permafrost"
    },
    {
      "x": -29,
      "y": 26,
      "z": -10,
      "name": "Rock_Ice_Permafrost"
    },
    {
      "x": -29,
      "y": 27,
      "z": -10,
      "name": "Rock_Ice"
    },
    {
      "x": -29,
      "y": 28,
      "z": -10,
      "name": "Soil_Snow"
    },
    {
      "x": -29,
      "y": 18,
      "z": -9,
      "name": "Rock_Ice"
    },
    {
      "x": -29,
      "y": 19,
      "z": -9,
      "name": "Rock_Ice"
    },
    {
      "x": -29,
      "y": 20,
      "z": -9,
      "name": "Rock_Ice_Permafrost"
    },
    {
      "x": -29,
      "y": 21,
      "z": -9,
      "name": "Rock_Ice_Permafrost"
    },
    {
      "x": -29,
      "y": 22,
      "z": -9,
      "name": "Rock_Ice_Permafrost"
    },
    {
      "x": -29,
      "y": 23,
      "z": -9,
      "name": "Rock_Ice_Permafrost"
    },
    {
      "x": -29,
      "y": 24,
      "z": -9,
      "name": "Rock_Ice_Permafrost"
    },
    {
      "x": -29,
      "y": 25,
      "z": -9,
      "name": "Rock_Ice"
    },
    {
      "x": -29,
      "y": 26,
      "z": -9,
      "name": "Soil_Snow"
    },
    {
      "x": -29,
      "y": 18,
      "z": -8,
      "name": "Rock_Ice"
    },
    {
      "x": -29,
      "y": 19,
      "z": -8,
      "name": "Rock_Ice"
    },
    {
      "x": -29,
      "y": 20,
      "z": -8,
      "name": "Rock_Ice"
    },
    {
      "x": -29,
      "y": 21,
      "z": -8,
      "name": "Rock_Ice_Permafrost"
    },
    {
      "x": -29,
      "y": 22,
      "z": -8,
      "name": "Rock_Ice_Permafrost"
    },
    {
      "x": -29,
      "y": 23,
      "z": -8,
      "name": "Rock_Ice_Permafrost"
    },
    {
      "x": -29,
      "y": 24,
      "z": -8,
      "name": "Rock_Ice"
    },
    {
      "x": -29,
      "y": 25,
      "z": -8,
      "name": "Soil_Snow"
    },
    {
      "x": -29,
      "y": 18,
      "z": -7,
      "name": "Rock_Ice"
    },
    {
      "x": -29,
      "y": 19,
      "z": -7,
      "name": "Rock_Ice"
    },
    {
      "x": -29,
      "y": 20,
      "z": -7,
      "name": "Rock_Ice_Permafrost"
    },
    {
      "x": -29,
      "y": 21,
      "z": -7,
      "name": "Rock_Ice_Permafrost"
    },
    {
      "x": -29,
      "y": 22,
      "z": -7,
      "name": "Rock_Ice"
    },
    {
      "x": -29,
      "y": 23,
      "z": -7,
      "name": "Soil_Snow"
    },
    {
      "x": -29,
      "y": 18,
      "z": -6,
      "name": "Rock_Ice_Permafrost"
    },
    {
      "x": -29,
      "y": 19,
      "z": -6,
      "name": "Rock_Ice"
    },
    {
      "x": -29,
      "y": 20,
      "z": -6,
      "name": "Soil_Snow"
    },
    {
      "x": -29,
      "y": 18,
      "z": -5,
      "name": "Rock_Ice_Permafrost"
    },
    {
      "x": -28,
      "y": 32,
      "z": -23,
      "name": "Rock_Ice"
    },
    {
      "x": -28,
      "y": 33,
      "z": -23,
      "name": "Rock_Ice"
    },
    {
      "x": -28,
      "y": 28,
      "z": -22,
      "name": "Rock_Ice"
    },
    {
      "x": -28,
      "y": 29,
      "z": -22,
      "name": "Rock_Ice"
    },
    {
      "x": -28,
      "y": 30,
      "z": -22,
      "name": "Rock_Ice"
    },
    {
      "x": -28,
      "y": 31,
      "z": -22,
      "name": "Rock_Ice"
    },
    {
      "x": -28,
      "y": 32,
      "z": -22,
      "name": "Rock_Ice"
    },
    {
      "x": -28,
      "y": 33,
      "z": -22,
      "name": "Rock_Ice"
    },
    {
      "x": -28,
      "y": 34,
      "z": -22,
      "name": "Rock_Ice"
    },
    {
      "x": -28,
      "y": 35,
      "z": -22,
      "name": "Rock_Ice"
    },
    {
      "x": -28,
      "y": 36,
      "z": -22,
      "name": "Rock_Ice"
    },
    {
      "x": -28,
      "y": 37,
      "z": -22,
      "name": "Soil_Snow"
    },
    {
      "x": -28,
      "y": 26,
      "z": -21,
      "name": "Rock_Ice"
    },
    {
      "x": -28,
      "y": 27,
      "z": -21,
      "name": "Rock_Ice"
    },
    {
      "x": -28,
      "y": 28,
      "z": -21,
      "name": "Rock_Ice"
    },
    {
      "x": -28,
      "y": 29,
      "z": -21,
      "name": "Rock_Ice"
    },
    {
      "x": -28,
      "y": 30,
      "z": -21,
      "name": "Rock_Ice"
    },
    {
      "x": -28,
      "y": 31,
      "z": -21,
      "name": "Rock_Ice"
    },
    {
      "x": -28,
      "y": 32,
      "z": -21,
      "name": "Rock_Ice"
    },
    {
      "x": -28,
      "y": 33,
      "z": -21,
      "name": "Rock_Ice"
    },
    {
      "x": -28,
      "y": 34,
      "z": -21,
      "name": "Rock_Ice"
    },
    {
      "x": -28,
      "y": 35,
      "z": -21,
      "name": "Rock_Ice"
    },
    {
      "x": -28,
      "y": 36,
      "z": -21,
      "name": "Rock_Ice"
    },
    {
      "x": -28,
      "y": 37,
      "z": -21,
      "name": "Soil_Snow"
    },
    {
      "x": -28,
      "y": 24,
      "z": -20,
      "name": "Rock_Ice"
    },
    {
      "x": -28,
      "y": 25,
      "z": -20,
      "name": "Rock_Ice"
    },
    {
      "x": -28,
      "y": 26,
      "z": -20,
      "name": "Rock_Ice"
    },
    {
      "x": -28,
      "y": 27,
      "z": -20,
      "name": "Rock_Ice"
    },
    {
      "x": -28,
      "y": 28,
      "z": -20,
      "name": "Rock_Ice"
    },
    {
      "x": -28,
      "y": 29,
      "z": -20,
      "name": "Rock_Ice"
    },
    {
      "x": -28,
      "y": 30,
      "z": -20,
      "name": "Rock_Ice"
    },
    {
      "x": -28,
      "y": 31,
      "z": -20,
      "name": "Rock_Ice"
    },
    {
      "x": -28,
      "y": 32,
      "z": -20,
      "name": "Rock_Ice"
    },
    {
      "x": -28,
      "y": 33,
      "z": -20,
      "name": "Rock_Ice"
    },
    {
      "x": -28,
      "y": 34,
      "z": -20,
      "name": "Rock_Ice"
    },
    {
      "x": -28,
      "y": 35,
      "z": -20,
      "name": "Rock_Ice"
    },
    {
      "x": -28,
      "y": 36,
      "z": -20,
      "name": "Rock_Ice"
    },
    {
      "x": -28,
      "y": 37,
      "z": -20,
      "name": "Rock_Ice"
    },
    {
      "x": -28,
      "y": 38,
      "z": -20,
      "name": "Soil_Snow"
    },
    {
      "x": -28,
      "y": 21,
      "z": -19,
      "name": "Rock_Ice"
    },
    {
      "x": -28,
      "y": 22,
      "z": -19,
      "name": "Rock_Ice"
    },
    {
      "x": -28,
      "y": 23,
      "z": -19,
      "name": "Rock_Ice"
    },
    {
      "x": -28,
      "y": 24,
      "z": -19,
      "name": "Rock_Ice"
    },
    {
      "x": -28,
      "y": 25,
      "z": -19,
      "name": "Rock_Ice"
    },
    {
      "x": -28,
      "y": 26,
      "z": -19,
      "name": "Rock_Ice"
    },
    {
      "x": -28,
      "y": 27,
      "z": -19,
      "name": "Rock_Ice"
    },
    {
      "x": -28,
      "y": 28,
      "z": -19,
      "name": "Rock_Ice"
    },
    {
      "x": -28,
      "y": 29,
      "z": -19,
      "name": "Rock_Ice"
    },
    {
      "x": -28,
      "y": 30,
      "z": -19,
      "name": "Rock_Ice"
    },
    {
      "x": -28,
      "y": 31,
      "z": -19,
      "name": "Rock_Ice"
    },
    {
      "x": -28,
      "y": 32,
      "z": -19,
      "name": "Rock_Ice"
    },
    {
      "x": -28,
      "y": 33,
      "z": -19,
      "name": "Rock_Ice"
    },
    {
      "x": -28,
      "y": 34,
      "z": -19,
      "name": "Rock_Ice"
    },
    {
      "x": -28,
      "y": 35,
      "z": -19,
      "name": "Rock_Ice"
    },
    {
      "x": -28,
      "y": 36,
      "z": -19,
      "name": "Rock_Ice"
    },
    {
      "x": -28,
      "y": 37,
      "z": -19,
      "name": "Rock_Ice"
    },
    {
      "x": -28,
      "y": 38,
      "z": -19,
      "name": "Rock_Ice"
    },
    {
      "x": -28,
      "y": 39,
      "z": -19,
      "name": "Rock_Ice"
    },
    {
      "x": -28,
      "y": 19,
      "z": -18,
      "name": "Rock_Ice"
    },
    {
      "x": -28,
      "y": 20,
      "z": -18,
      "name": "Rock_Ice"
    },
    {
      "x": -28,
      "y": 21,
      "z": -18,
      "name": "Rock_Ice"
    },
    {
      "x": -28,
      "y": 22,
      "z": -18,
      "name": "Rock_Ice"
    },
    {
      "x": -28,
      "y": 23,
      "z": -18,
      "name": "Rock_Ice"
    },
    {
      "x": -28,
      "y": 24,
      "z": -18,
      "name": "Rock_Ice"
    },
    {
      "x": -28,
      "y": 25,
      "z": -18,
      "name": "Rock_Ice"
    },
    {
      "x": -28,
      "y": 26,
      "z": -18,
      "name": "Rock_Ice"
    },
    {
      "x": -28,
      "y": 27,
      "z": -18,
      "name": "Rock_Ice"
    },
    {
      "x": -28,
      "y": 28,
      "z": -18,
      "name": "Rock_Ice"
    },
    {
      "x": -28,
      "y": 29,
      "z": -18,
      "name": "Rock_Ice"
    },
    {
      "x": -28,
      "y": 30,
      "z": -18,
      "name": "Rock_Ice"
    },
    {
      "x": -28,
      "y": 31,
      "z": -18,
      "name": "Rock_Ice"
    },
    {
      "x": -28,
      "y": 32,
      "z": -18,
      "name": "Rock_Ice"
    },
    {
      "x": -28,
      "y": 33,
      "z": -18,
      "name": "Rock_Ice"
    },
    {
      "x": -28,
      "y": 34,
      "z": -18,
      "name": "Rock_Ice"
    },
    {
      "x": -28,
      "y": 35,
      "z": -18,
      "name": "Rock_Ice"
    },
    {
      "x": -28,
      "y": 36,
      "z": -18,
      "name": "Rock_Ice"
    },
    {
      "x": -28,
      "y": 37,
      "z": -18,
      "name": "Rock_Ice"
    },
    {
      "x": -28,
      "y": 38,
      "z": -18,
      "name": "Rock_Ice"
    },
    {
      "x": -28,
      "y": 39,
      "z": -18,
      "name": "Rock_Ice"
    },
    {
      "x": -28,
      "y": 17,
      "z": -17,
      "name": "Rock_Ice"
    },
    {
      "x": -28,
      "y": 18,
      "z": -17,
      "name": "Rock_Ice"
    },
    {
      "x": -28,
      "y": 19,
      "z": -17,
      "name": "Rock_Ice"
    },
    {
      "x": -28,
      "y": 20,
      "z": -17,
      "name": "Rock_Ice"
    },
    {
      "x": -28,
      "y": 21,
      "z": -17,
      "name": "Rock_Ice"
    },
    {
      "x": -28,
      "y": 22,
      "z": -17,
      "name": "Rock_Ice"
    },
    {
      "x": -28,
      "y": 23,
      "z": -17,
      "name": "Rock_Ice"
    },
    {
      "x": -28,
      "y": 24,
      "z": -17,
      "name": "Rock_Ice"
    },
    {
      "x": -28,
      "y": 25,
      "z": -17,
      "name": "Rock_Ice"
    },
    {
      "x": -28,
      "y": 26,
      "z": -17,
      "name": "Rock_Ice"
    },
    {
      "x": -28,
      "y": 27,
      "z": -17,
      "name": "Rock_Ice"
    },
    {
      "x": -28,
      "y": 28,
      "z": -17,
      "name": "Rock_Ice_Permafrost"
    },
    {
      "x": -28,
      "y": 29,
      "z": -17,
      "name": "Rock_Ice"
    },
    {
      "x": -28,
      "y": 30,
      "z": -17,
      "name": "Rock_Ice"
    },
    {
      "x": -28,
      "y": 31,
      "z": -17,
      "name": "Rock_Ice"
    },
    {
      "x": -28,
      "y": 32,
      "z": -17,
      "name": "Rock_Ice"
    },
    {
      "x": -28,
      "y": 33,
      "z": -17,
      "name": "Rock_Ice"
    },
    {
      "x": -28,
      "y": 34,
      "z": -17,
      "name": "Rock_Ice"
    },
    {
      "x": -28,
      "y": 35,
      "z": -17,
      "name": "Rock_Ice"
    },
    {
      "x": -28,
      "y": 36,
      "z": -17,
      "name": "Rock_Ice"
    },
    {
      "x": -28,
      "y": 37,
      "z": -17,
      "name": "Rock_Ice"
    },
    {
      "x": -28,
      "y": 38,
      "z": -17,
      "name": "Rock_Ice"
    },
    {
      "x": -28,
      "y": 39,
      "z": -17,
      "name": "Soil_Snow"
    },
    {
      "x": -28,
      "y": 15,
      "z": -16,
      "name": "Rock_Ice"
    },
    {
      "x": -28,
      "y": 16,
      "z": -16,
      "name": "Rock_Ice"
    },
    {
      "x": -28,
      "y": 17,
      "z": -16,
      "name": "Rock_Ice"
    },
    {
      "x": -28,
      "y": 18,
      "z": -16,
      "name": "Rock_Ice"
    },
    {
      "x": -28,
      "y": 19,
      "z": -16,
      "name": "Rock_Ice"
    },
    {
      "x": -28,
      "y": 20,
      "z": -16,
      "name": "Rock_Ice"
    },
    {
      "x": -28,
      "y": 21,
      "z": -16,
      "name": "Rock_Ice"
    },
    {
      "x": -28,
      "y": 22,
      "z": -16,
      "name": "Rock_Ice"
    },
    {
      "x": -28,
      "y": 23,
      "z": -16,
      "name": "Rock_Ice"
    },
    {
      "x": -28,
      "y": 24,
      "z": -16,
      "name": "Rock_Ice"
    },
    {
      "x": -28,
      "y": 25,
      "z": -16,
      "name": "Rock_Ice"
    },
    {
      "x": -28,
      "y": 26,
      "z": -16,
      "name": "Rock_Ice_Permafrost"
    },
    {
      "x": -28,
      "y": 27,
      "z": -16,
      "name": "Rock_Ice"
    },
    {
      "x": -28,
      "y": 28,
      "z": -16,
      "name": "Rock_Ice"
    },
    {
      "x": -28,
      "y": 29,
      "z": -16,
      "name": "Rock_Ice"
    },
    {
      "x": -28,
      "y": 30,
      "z": -16,
      "name": "Rock_Ice"
    },
    {
      "x": -28,
      "y": 31,
      "z": -16,
      "name": "Rock_Ice"
    },
    {
      "x": -28,
      "y": 32,
      "z": -16,
      "name": "Rock_Ice"
    },
    {
      "x": -28,
      "y": 33,
      "z": -16,
      "name": "Rock_Ice_Permafrost"
    },
    {
      "x": -28,
      "y": 34,
      "z": -16,
      "name": "Rock_Ice_Permafrost"
    },
    {
      "x": -28,
      "y": 35,
      "z": -16,
      "name": "Rock_Ice_Permafrost"
    },
    {
      "x": -28,
      "y": 36,
      "z": -16,
      "name": "Rock_Ice"
    },
    {
      "x": -28,
      "y": 37,
      "z": -16,
      "name": "Rock_Ice"
    },
    {
      "x": -28,
      "y": 38,
      "z": -16,
      "name": "Soil_Snow"
    },
    {
      "x": -28,
      "y": 15,
      "z": -15,
      "name": "Rock_Ice"
    },
    {
      "x": -28,
      "y": 16,
      "z": -15,
      "name": "Rock_Ice"
    },
    {
      "x": -28,
      "y": 17,
      "z": -15,
      "name": "Rock_Ice"
    },
    {
      "x": -28,
      "y": 18,
      "z": -15,
      "name": "Rock_Ice"
    },
    {
      "x": -28,
      "y": 19,
      "z": -15,
      "name": "Rock_Ice"
    },
    {
      "x": -28,
      "y": 20,
      "z": -15,
      "name": "Rock_Ice"
    },
    {
      "x": -28,
      "y": 21,
      "z": -15,
      "name": "Rock_Ice"
    },
    {
      "x": -28,
      "y": 22,
      "z": -15,
      "name": "Rock_Ice"
    },
    {
      "x": -28,
      "y": 23,
      "z": -15,
      "name": "Rock_Ice"
    },
    {
      "x": -28,
      "y": 24,
      "z": -15,
      "name": "Rock_Ice"
    },
    {
      "x": -28,
      "y": 25,
      "z": -15,
      "name": "Rock_Ice"
    },
    {
      "x": -28,
      "y": 26,
      "z": -15,
      "name": "Rock_Ice_Permafrost"
    },
    {
      "x": -28,
      "y": 27,
      "z": -15,
      "name": "Rock_Ice_Permafrost"
    },
    {
      "x": -28,
      "y": 28,
      "z": -15,
      "name": "Rock_Ice_Permafrost"
    },
    {
      "x": -28,
      "y": 29,
      "z": -15,
      "name": "Rock_Ice_Permafrost"
    },
    {
      "x": -28,
      "y": 30,
      "z": -15,
      "name": "Rock_Ice_Permafrost"
    },
    {
      "x": -28,
      "y": 31,
      "z": -15,
      "name": "Rock_Ice"
    },
    {
      "x": -28,
      "y": 32,
      "z": -15,
      "name": "Rock_Ice"
    },
    {
      "x": -28,
      "y": 33,
      "z": -15,
      "name": "Rock_Ice"
    },
    {
      "x": -28,
      "y": 34,
      "z": -15,
      "name": "Rock_Ice"
    },
    {
      "x": -28,
      "y": 35,
      "z": -15,
      "name": "Rock_Ice"
    },
    {
      "x": -28,
      "y": 36,
      "z": -15,
      "name": "Soil_Snow"
    },
    {
      "x": -28,
      "y": 15,
      "z": -14,
      "name": "Rock_Ice"
    },
    {
      "x": -28,
      "y": 16,
      "z": -14,
      "name": "Rock_Ice"
    },
    {
      "x": -28,
      "y": 17,
      "z": -14,
      "name": "Rock_Ice"
    },
    {
      "x": -28,
      "y": 18,
      "z": -14,
      "name": "Rock_Ice"
    },
    {
      "x": -28,
      "y": 19,
      "z": -14,
      "name": "Rock_Ice"
    },
    {
      "x": -28,
      "y": 20,
      "z": -14,
      "name": "Rock_Ice"
    },
    {
      "x": -28,
      "y": 21,
      "z": -14,
      "name": "Rock_Ice"
    },
    {
      "x": -28,
      "y": 22,
      "z": -14,
      "name": "Rock_Ice"
    },
    {
      "x": -28,
      "y": 23,
      "z": -14,
      "name": "Rock_Ice"
    },
    {
      "x": -28,
      "y": 24,
      "z": -14,
      "name": "Rock_Ice"
    },
    {
      "x": -28,
      "y": 25,
      "z": -14,
      "name": "Rock_Ice"
    },
    {
      "x": -28,
      "y": 26,
      "z": -14,
      "name": "Rock_Ice_Permafrost"
    },
    {
      "x": -28,
      "y": 27,
      "z": -14,
      "name": "Rock_Ice_Permafrost"
    },
    {
      "x": -28,
      "y": 28,
      "z": -14,
      "name": "Rock_Ice_Permafrost"
    },
    {
      "x": -28,
      "y": 29,
      "z": -14,
      "name": "Rock_Ice_Permafrost"
    },
    {
      "x": -28,
      "y": 30,
      "z": -14,
      "name": "Rock_Ice"
    },
    {
      "x": -28,
      "y": 31,
      "z": -14,
      "name": "Rock_Ice"
    },
    {
      "x": -28,
      "y": 32,
      "z": -14,
      "name": "Rock_Ice"
    },
    {
      "x": -28,
      "y": 33,
      "z": -14,
      "name": "Rock_Ice"
    },
    {
      "x": -28,
      "y": 34,
      "z": -14,
      "name": "Soil_Snow"
    },
    {
      "x": -28,
      "y": 15,
      "z": -13,
      "name": "Rock_Ice"
    },
    {
      "x": -28,
      "y": 16,
      "z": -13,
      "name": "Rock_Ice"
    },
    {
      "x": -28,
      "y": 17,
      "z": -13,
      "name": "Rock_Ice"
    },
    {
      "x": -28,
      "y": 18,
      "z": -13,
      "name": "Rock_Ice"
    },
    {
      "x": -28,
      "y": 19,
      "z": -13,
      "name": "Rock_Ice"
    },
    {
      "x": -28,
      "y": 20,
      "z": -13,
      "name": "Rock_Ice"
    },
    {
      "x": -28,
      "y": 21,
      "z": -13,
      "name": "Rock_Ice"
    },
    {
      "x": -28,
      "y": 22,
      "z": -13,
      "name": "Rock_Ice"
    },
    {
      "x": -28,
      "y": 23,
      "z": -13,
      "name": "Rock_Ice"
    },
    {
      "x": -28,
      "y": 24,
      "z": -13,
      "name": "Rock_Ice_Permafrost"
    },
    {
      "x": -28,
      "y": 25,
      "z": -13,
      "name": "Rock_Ice_Permafrost"
    },
    {
      "x": -28,
      "y": 26,
      "z": -13,
      "name": "Rock_Ice_Permafrost"
    },
    {
      "x": -28,
      "y": 27,
      "z": -13,
      "name": "Rock_Ice_Permafrost"
    },
    {
      "x": -28,
      "y": 28,
      "z": -13,
      "name": "Rock_Ice_Permafrost"
    },
    {
      "x": -28,
      "y": 29,
      "z": -13,
      "name": "Rock_Ice_Permafrost"
    },
    {
      "x": -28,
      "y": 30,
      "z": -13,
      "name": "Rock_Ice"
    },
    {
      "x": -28,
      "y": 31,
      "z": -13,
      "name": "Rock_Ice"
    },
    {
      "x": -28,
      "y": 32,
      "z": -13,
      "name": "Rock_Ice"
    },
    {
      "x": -28,
      "y": 33,
      "z": -13,
      "name": "Soil_Snow"
    },
    {
      "x": -28,
      "y": 15,
      "z": -12,
      "name": "Rock_Ice"
    },
    {
      "x": -28,
      "y": 16,
      "z": -12,
      "name": "Rock_Ice"
    },
    {
      "x": -28,
      "y": 17,
      "z": -12,
      "name": "Rock_Ice"
    },
    {
      "x": -28,
      "y": 18,
      "z": -12,
      "name": "Rock_Ice"
    },
    {
      "x": -28,
      "y": 19,
      "z": -12,
      "name": "Rock_Ice"
    },
    {
      "x": -28,
      "y": 20,
      "z": -12,
      "name": "Rock_Ice"
    },
    {
      "x": -28,
      "y": 21,
      "z": -12,
      "name": "Rock_Ice"
    },
    {
      "x": -28,
      "y": 22,
      "z": -12,
      "name": "Rock_Ice"
    },
    {
      "x": -28,
      "y": 23,
      "z": -12,
      "name": "Rock_Ice"
    },
    {
      "x": -28,
      "y": 24,
      "z": -12,
      "name": "Rock_Ice_Permafrost"
    },
    {
      "x": -28,
      "y": 25,
      "z": -12,
      "name": "Rock_Ice_Permafrost"
    },
    {
      "x": -28,
      "y": 26,
      "z": -12,
      "name": "Rock_Ice_Permafrost"
    },
    {
      "x": -28,
      "y": 27,
      "z": -12,
      "name": "Rock_Ice_Permafrost"
    },
    {
      "x": -28,
      "y": 28,
      "z": -12,
      "name": "Rock_Ice_Permafrost"
    },
    {
      "x": -28,
      "y": 29,
      "z": -12,
      "name": "Rock_Ice"
    },
    {
      "x": -28,
      "y": 30,
      "z": -12,
      "name": "Rock_Ice"
    },
    {
      "x": -28,
      "y": 31,
      "z": -12,
      "name": "Rock_Ice"
    },
    {
      "x": -28,
      "y": 32,
      "z": -12,
      "name": "Soil_Snow"
    },
    {
      "x": -28,
      "y": 15,
      "z": -11,
      "name": "Rock_Ice"
    },
    {
      "x": -28,
      "y": 16,
      "z": -11,
      "name": "Rock_Ice"
    },
    {
      "x": -28,
      "y": 17,
      "z": -11,
      "name": "Rock_Ice"
    },
    {
      "x": -28,
      "y": 18,
      "z": -11,
      "name": "Rock_Ice"
    },
    {
      "x": -28,
      "y": 19,
      "z": -11,
      "name": "Rock_Ice"
    },
    {
      "x": -28,
      "y": 20,
      "z": -11,
      "name": "Rock_Ice"
    },
    {
      "x": -28,
      "y": 21,
      "z": -11,
      "name": "Rock_Ice"
    },
    {
      "x": -28,
      "y": 22,
      "z": -11,
      "name": "Rock_Ice"
    },
    {
      "x": -28,
      "y": 23,
      "z": -11,
      "name": "Rock_Ice_Permafrost"
    },
    {
      "x": -28,
      "y": 24,
      "z": -11,
      "name": "Rock_Ice_Permafrost"
    },
    {
      "x": -28,
      "y": 25,
      "z": -11,
      "name": "Rock_Ice_Permafrost"
    },
    {
      "x": -28,
      "y": 26,
      "z": -11,
      "name": "Rock_Ice_Permafrost"
    },
    {
      "x": -28,
      "y": 27,
      "z": -11,
      "name": "Rock_Ice"
    },
    {
      "x": -28,
      "y": 28,
      "z": -11,
      "name": "Rock_Ice"
    },
    {
      "x": -28,
      "y": 29,
      "z": -11,
      "name": "Rock_Ice"
    },
    {
      "x": -28,
      "y": 30,
      "z": -11,
      "name": "Rock_Ice"
    },
    {
      "x": -28,
      "y": 31,
      "z": -11,
      "name": "Soil_Snow"
    },
    {
      "x": -28,
      "y": 15,
      "z": -10,
      "name": "Rock_Ice"
    },
    {
      "x": -28,
      "y": 16,
      "z": -10,
      "name": "Rock_Ice"
    },
    {
      "x": -28,
      "y": 17,
      "z": -10,
      "name": "Rock_Ice"
    },
    {
      "x": -28,
      "y": 18,
      "z": -10,
      "name": "Rock_Ice"
    },
    {
      "x": -28,
      "y": 19,
      "z": -10,
      "name": "Rock_Ice"
    },
    {
      "x": -28,
      "y": 20,
      "z": -10,
      "name": "Rock_Ice"
    },
    {
      "x": -28,
      "y": 21,
      "z": -10,
      "name": "Rock_Ice_Permafrost"
    },
    {
      "x": -28,
      "y": 22,
      "z": -10,
      "name": "Rock_Ice_Permafrost"
    },
    {
      "x": -28,
      "y": 23,
      "z": -10,
      "name": "Rock_Ice_Permafrost"
    },
    {
      "x": -28,
      "y": 24,
      "z": -10,
      "name": "Rock_Ice_Permafrost"
    },
    {
      "x": -28,
      "y": 25,
      "z": -10,
      "name": "Rock_Ice_Permafrost"
    },
    {
      "x": -28,
      "y": 26,
      "z": -10,
      "name": "Rock_Ice_Permafrost"
    },
    {
      "x": -28,
      "y": 27,
      "z": -10,
      "name": "Rock_Ice"
    },
    {
      "x": -28,
      "y": 28,
      "z": -10,
      "name": "Rock_Ice"
    },
    {
      "x": -28,
      "y": 29,
      "z": -10,
      "name": "Soil_Snow"
    },
    {
      "x": -28,
      "y": 15,
      "z": -9,
      "name": "Rock_Ice"
    },
    {
      "x": -28,
      "y": 16,
      "z": -9,
      "name": "Rock_Ice"
    },
    {
      "x": -28,
      "y": 17,
      "z": -9,
      "name": "Rock_Ice"
    },
    {
      "x": -28,
      "y": 18,
      "z": -9,
      "name": "Rock_Ice"
    },
    {
      "x": -28,
      "y": 19,
      "z": -9,
      "name": "Rock_Ice"
    },
    {
      "x": -28,
      "y": 20,
      "z": -9,
      "name": "Rock_Ice"
    },
    {
      "x": -28,
      "y": 21,
      "z": -9,
      "name": "Rock_Ice_Permafrost"
    },
    {
      "x": -28,
      "y": 22,
      "z": -9,
      "name": "Rock_Ice_Permafrost"
    },
    {
      "x": -28,
      "y": 23,
      "z": -9,
      "name": "Rock_Ice_Permafrost"
    },
    {
      "x": -28,
      "y": 24,
      "z": -9,
      "name": "Rock_Ice_Permafrost"
    },
    {
      "x": -28,
      "y": 25,
      "z": -9,
      "name": "Rock_Ice_Permafrost"
    },
    {
      "x": -28,
      "y": 26,
      "z": -9,
      "name": "Rock_Ice"
    },
    {
      "x": -28,
      "y": 27,
      "z": -9,
      "name": "Rock_Ice"
    },
    {
      "x": -28,
      "y": 28,
      "z": -9,
      "name": "Soil_Snow"
    },
    {
      "x": -28,
      "y": 16,
      "z": -8,
      "name": "Rock_Ice"
    },
    {
      "x": -28,
      "y": 17,
      "z": -8,
      "name": "Rock_Ice"
    },
    {
      "x": -28,
      "y": 18,
      "z": -8,
      "name": "Rock_Ice"
    },
    {
      "x": -28,
      "y": 19,
      "z": -8,
      "name": "Rock_Ice"
    },
    {
      "x": -28,
      "y": 20,
      "z": -8,
      "name": "Rock_Ice_Permafrost"
    },
    {
      "x": -28,
      "y": 21,
      "z": -8,
      "name": "Rock_Ice_Permafrost"
    },
    {
      "x": -28,
      "y": 22,
      "z": -8,
      "name": "Rock_Ice"
    },
    {
      "x": -28,
      "y": 23,
      "z": -8,
      "name": "Rock_Ice_Permafrost"
    },
    {
      "x": -28,
      "y": 24,
      "z": -8,
      "name": "Rock_Ice_Permafrost"
    },
    {
      "x": -28,
      "y": 25,
      "z": -8,
      "name": "Rock_Ice_Permafrost"
    },
    {
      "x": -28,
      "y": 26,
      "z": -8,
      "name": "Rock_Ice"
    },
    {
      "x": -28,
      "y": 27,
      "z": -8,
      "name": "Soil_Snow"
    },
    {
      "x": -28,
      "y": 16,
      "z": -7,
      "name": "Rock_Ice"
    },
    {
      "x": -28,
      "y": 17,
      "z": -7,
      "name": "Rock_Ice"
    },
    {
      "x": -28,
      "y": 18,
      "z": -7,
      "name": "Rock_Ice_Permafrost"
    },
    {
      "x": -28,
      "y": 19,
      "z": -7,
      "name": "Rock_Ice_Permafrost"
    },
    {
      "x": -28,
      "y": 20,
      "z": -7,
      "name": "Rock_Ice_Permafrost"
    },
    {
      "x": -28,
      "y": 21,
      "z": -7,
      "name": "Rock_Ice_Permafrost"
    },
    {
      "x": -28,
      "y": 22,
      "z": -7,
      "name": "Rock_Ice_Permafrost"
    },
    {
      "x": -28,
      "y": 23,
      "z": -7,
      "name": "Rock_Ice"
    },
    {
      "x": -28,
      "y": 24,
      "z": -7,
      "name": "Rock_Ice"
    },
    {
      "x": -28,
      "y": 25,
      "z": -7,
      "name": "Soil_Snow"
    },
    {
      "x": -28,
      "y": 16,
      "z": -6,
      "name": "Rock_Ice"
    },
    {
      "x": -28,
      "y": 17,
      "z": -6,
      "name": "Rock_Ice"
    },
    {
      "x": -28,
      "y": 18,
      "z": -6,
      "name": "Rock_Ice_Permafrost"
    },
    {
      "x": -28,
      "y": 19,
      "z": -6,
      "name": "Rock_Ice_Permafrost"
    },
    {
      "x": -28,
      "y": 20,
      "z": -6,
      "name": "Rock_Ice_Permafrost"
    },
    {
      "x": -28,
      "y": 21,
      "z": -6,
      "name": "Rock_Ice"
    },
    {
      "x": -28,
      "y": 22,
      "z": -6,
      "name": "Rock_Ice_Permafrost"
    },
    {
      "x": -28,
      "y": 23,
      "z": -6,
      "name": "Rock_Ice"
    },
    {
      "x": -28,
      "y": 24,
      "z": -6,
      "name": "Soil_Snow"
    },
    {
      "x": -28,
      "y": 16,
      "z": -5,
      "name": "Rock_Ice"
    },
    {
      "x": -28,
      "y": 17,
      "z": -5,
      "name": "Rock_Ice"
    },
    {
      "x": -28,
      "y": 18,
      "z": -5,
      "name": "Rock_Ice_Permafrost"
    },
    {
      "x": -28,
      "y": 19,
      "z": -5,
      "name": "Rock_Ice"
    },
    {
      "x": -28,
      "y": 20,
      "z": -5,
      "name": "Rock_Ice"
    },
    {
      "x": -28,
      "y": 21,
      "z": -5,
      "name": "Rock_Ice_Permafrost"
    },
    {
      "x": -28,
      "y": 22,
      "z": -5,
      "name": "Rock_Ice_Permafrost"
    },
    {
      "x": -28,
      "y": 23,
      "z": -5,
      "name": "Soil_Snow"
    },
    {
      "x": -28,
      "y": 16,
      "z": -4,
      "name": "Rock_Ice"
    },
    {
      "x": -28,
      "y": 17,
      "z": -4,
      "name": "Rock_Ice"
    },
    {
      "x": -28,
      "y": 18,
      "z": -4,
      "name": "Rock_Ice"
    },
    {
      "x": -28,
      "y": 19,
      "z": -4,
      "name": "Soil_Snow"
    },
    {
      "x": -27,
      "y": 28,
      "z": -23,
      "name": "Rock_Ice"
    },
    {
      "x": -27,
      "y": 29,
      "z": -23,
      "name": "Rock_Ice"
    },
    {
      "x": -27,
      "y": 30,
      "z": -23,
      "name": "Rock_Ice"
    },
    {
      "x": -27,
      "y": 31,
      "z": -23,
      "name": "Rock_Ice"
    },
    {
      "x": -27,
      "y": 32,
      "z": -23,
      "name": "Rock_Ice"
    },
    {
      "x": -27,
      "y": 33,
      "z": -23,
      "name": "Rock_Ice"
    },
    {
      "x": -27,
      "y": 34,
      "z": -23,
      "name": "Rock_Ice"
    },
    {
      "x": -27,
      "y": 35,
      "z": -23,
      "name": "Rock_Ice"
    },
    {
      "x": -27,
      "y": 36,
      "z": -23,
      "name": "Rock_Ice"
    },
    {
      "x": -27,
      "y": 37,
      "z": -23,
      "name": "Rock_Ice"
    },
    {
      "x": -27,
      "y": 38,
      "z": -23,
      "name": "Soil_Snow"
    },
    {
      "x": -27,
      "y": 26,
      "z": -22,
      "name": "Rock_Ice"
    },
    {
      "x": -27,
      "y": 27,
      "z": -22,
      "name": "Rock_Ice"
    },
    {
      "x": -27,
      "y": 28,
      "z": -22,
      "name": "Rock_Ice"
    },
    {
      "x": -27,
      "y": 29,
      "z": -22,
      "name": "Rock_Ice"
    },
    {
      "x": -27,
      "y": 30,
      "z": -22,
      "name": "Rock_Ice"
    },
    {
      "x": -27,
      "y": 31,
      "z": -22,
      "name": "Rock_Ice"
    },
    {
      "x": -27,
      "y": 32,
      "z": -22,
      "name": "Rock_Ice"
    },
    {
      "x": -27,
      "y": 33,
      "z": -22,
      "name": "Rock_Ice"
    },
    {
      "x": -27,
      "y": 34,
      "z": -22,
      "name": "Rock_Ice"
    },
    {
      "x": -27,
      "y": 35,
      "z": -22,
      "name": "Rock_Ice"
    },
    {
      "x": -27,
      "y": 36,
      "z": -22,
      "name": "Rock_Ice"
    },
    {
      "x": -27,
      "y": 37,
      "z": -22,
      "name": "Rock_Ice"
    },
    {
      "x": -27,
      "y": 38,
      "z": -22,
      "name": "Rock_Ice"
    },
    {
      "x": -27,
      "y": 39,
      "z": -22,
      "name": "Soil_Snow"
    },
    {
      "x": -27,
      "y": 24,
      "z": -21,
      "name": "Rock_Ice"
    },
    {
      "x": -27,
      "y": 25,
      "z": -21,
      "name": "Rock_Ice"
    },
    {
      "x": -27,
      "y": 26,
      "z": -21,
      "name": "Rock_Ice"
    },
    {
      "x": -27,
      "y": 27,
      "z": -21,
      "name": "Rock_Ice"
    },
    {
      "x": -27,
      "y": 28,
      "z": -21,
      "name": "Rock_Ice"
    },
    {
      "x": -27,
      "y": 29,
      "z": -21,
      "name": "Rock_Ice"
    },
    {
      "x": -27,
      "y": 30,
      "z": -21,
      "name": "Rock_Ice"
    },
    {
      "x": -27,
      "y": 31,
      "z": -21,
      "name": "Rock_Ice"
    },
    {
      "x": -27,
      "y": 32,
      "z": -21,
      "name": "Rock_Ice"
    },
    {
      "x": -27,
      "y": 33,
      "z": -21,
      "name": "Rock_Ice"
    },
    {
      "x": -27,
      "y": 34,
      "z": -21,
      "name": "Rock_Ice"
    },
    {
      "x": -27,
      "y": 35,
      "z": -21,
      "name": "Rock_Ice"
    },
    {
      "x": -27,
      "y": 36,
      "z": -21,
      "name": "Rock_Ice"
    },
    {
      "x": -27,
      "y": 37,
      "z": -21,
      "name": "Rock_Ice"
    },
    {
      "x": -27,
      "y": 38,
      "z": -21,
      "name": "Rock_Ice"
    },
    {
      "x": -27,
      "y": 39,
      "z": -21,
      "name": "Rock_Ice"
    },
    {
      "x": -27,
      "y": 40,
      "z": -21,
      "name": "Soil_Snow"
    },
    {
      "x": -27,
      "y": 21,
      "z": -20,
      "name": "Rock_Ice"
    },
    {
      "x": -27,
      "y": 22,
      "z": -20,
      "name": "Rock_Ice"
    },
    {
      "x": -27,
      "y": 23,
      "z": -20,
      "name": "Rock_Ice"
    },
    {
      "x": -27,
      "y": 24,
      "z": -20,
      "name": "Rock_Ice"
    },
    {
      "x": -27,
      "y": 25,
      "z": -20,
      "name": "Rock_Ice"
    },
    {
      "x": -27,
      "y": 26,
      "z": -20,
      "name": "Rock_Ice"
    },
    {
      "x": -27,
      "y": 27,
      "z": -20,
      "name": "Rock_Ice"
    },
    {
      "x": -27,
      "y": 28,
      "z": -20,
      "name": "Rock_Ice"
    },
    {
      "x": -27,
      "y": 29,
      "z": -20,
      "name": "Rock_Ice"
    },
    {
      "x": -27,
      "y": 30,
      "z": -20,
      "name": "Rock_Ice"
    },
    {
      "x": -27,
      "y": 31,
      "z": -20,
      "name": "Rock_Ice"
    },
    {
      "x": -27,
      "y": 32,
      "z": -20,
      "name": "Rock_Ice"
    },
    {
      "x": -27,
      "y": 33,
      "z": -20,
      "name": "Rock_Ice"
    },
    {
      "x": -27,
      "y": 34,
      "z": -20,
      "name": "Rock_Ice"
    },
    {
      "x": -27,
      "y": 35,
      "z": -20,
      "name": "Rock_Ice"
    },
    {
      "x": -27,
      "y": 36,
      "z": -20,
      "name": "Rock_Ice"
    },
    {
      "x": -27,
      "y": 37,
      "z": -20,
      "name": "Rock_Ice"
    },
    {
      "x": -27,
      "y": 38,
      "z": -20,
      "name": "Rock_Ice"
    },
    {
      "x": -27,
      "y": 39,
      "z": -20,
      "name": "Rock_Ice"
    },
    {
      "x": -27,
      "y": 40,
      "z": -20,
      "name": "Rock_Ice"
    },
    {
      "x": -27,
      "y": 19,
      "z": -19,
      "name": "Rock_Ice"
    },
    {
      "x": -27,
      "y": 20,
      "z": -19,
      "name": "Rock_Ice"
    },
    {
      "x": -27,
      "y": 21,
      "z": -19,
      "name": "Rock_Ice"
    },
    {
      "x": -27,
      "y": 22,
      "z": -19,
      "name": "Rock_Ice"
    },
    {
      "x": -27,
      "y": 23,
      "z": -19,
      "name": "Rock_Ice"
    },
    {
      "x": -27,
      "y": 24,
      "z": -19,
      "name": "Rock_Ice"
    },
    {
      "x": -27,
      "y": 25,
      "z": -19,
      "name": "Rock_Ice"
    },
    {
      "x": -27,
      "y": 26,
      "z": -19,
      "name": "Rock_Ice"
    },
    {
      "x": -27,
      "y": 27,
      "z": -19,
      "name": "Rock_Ice"
    },
    {
      "x": -27,
      "y": 28,
      "z": -19,
      "name": "Rock_Ice"
    },
    {
      "x": -27,
      "y": 29,
      "z": -19,
      "name": "Rock_Ice"
    },
    {
      "x": -27,
      "y": 30,
      "z": -19,
      "name": "Rock_Ice"
    },
    {
      "x": -27,
      "y": 31,
      "z": -19,
      "name": "Rock_Ice"
    },
    {
      "x": -27,
      "y": 32,
      "z": -19,
      "name": "Rock_Ice"
    },
    {
      "x": -27,
      "y": 33,
      "z": -19,
      "name": "Rock_Ice"
    },
    {
      "x": -27,
      "y": 34,
      "z": -19,
      "name": "Rock_Ice"
    },
    {
      "x": -27,
      "y": 35,
      "z": -19,
      "name": "Rock_Ice"
    },
    {
      "x": -27,
      "y": 36,
      "z": -19,
      "name": "Rock_Ice"
    },
    {
      "x": -27,
      "y": 37,
      "z": -19,
      "name": "Rock_Ice"
    },
    {
      "x": -27,
      "y": 38,
      "z": -19,
      "name": "Rock_Ice"
    },
    {
      "x": -27,
      "y": 39,
      "z": -19,
      "name": "Rock_Ice"
    },
    {
      "x": -27,
      "y": 40,
      "z": -19,
      "name": "Rock_Ice"
    },
    {
      "x": -27,
      "y": 41,
      "z": -19,
      "name": "Rock_Ice"
    },
    {
      "x": -27,
      "y": 17,
      "z": -18,
      "name": "Rock_Ice"
    },
    {
      "x": -27,
      "y": 18,
      "z": -18,
      "name": "Rock_Ice"
    },
    {
      "x": -27,
      "y": 19,
      "z": -18,
      "name": "Rock_Ice"
    },
    {
      "x": -27,
      "y": 20,
      "z": -18,
      "name": "Rock_Ice"
    },
    {
      "x": -27,
      "y": 21,
      "z": -18,
      "name": "Rock_Ice"
    },
    {
      "x": -27,
      "y": 22,
      "z": -18,
      "name": "Rock_Ice"
    },
    {
      "x": -27,
      "y": 23,
      "z": -18,
      "name": "Rock_Ice"
    },
    {
      "x": -27,
      "y": 24,
      "z": -18,
      "name": "Rock_Ice"
    },
    {
      "x": -27,
      "y": 25,
      "z": -18,
      "name": "Rock_Ice"
    },
    {
      "x": -27,
      "y": 26,
      "z": -18,
      "name": "Rock_Ice"
    },
    {
      "x": -27,
      "y": 27,
      "z": -18,
      "name": "Rock_Ice"
    },
    {
      "x": -27,
      "y": 28,
      "z": -18,
      "name": "Rock_Ice_Permafrost"
    },
    {
      "x": -27,
      "y": 29,
      "z": -18,
      "name": "Rock_Ice"
    },
    {
      "x": -27,
      "y": 30,
      "z": -18,
      "name": "Rock_Ice"
    },
    {
      "x": -27,
      "y": 31,
      "z": -18,
      "name": "Rock_Ice"
    },
    {
      "x": -27,
      "y": 32,
      "z": -18,
      "name": "Rock_Ice"
    },
    {
      "x": -27,
      "y": 33,
      "z": -18,
      "name": "Rock_Ice"
    },
    {
      "x": -27,
      "y": 34,
      "z": -18,
      "name": "Rock_Ice"
    },
    {
      "x": -27,
      "y": 35,
      "z": -18,
      "name": "Rock_Ice"
    },
    {
      "x": -27,
      "y": 36,
      "z": -18,
      "name": "Rock_Ice"
    },
    {
      "x": -27,
      "y": 37,
      "z": -18,
      "name": "Rock_Ice"
    },
    {
      "x": -27,
      "y": 38,
      "z": -18,
      "name": "Rock_Ice"
    },
    {
      "x": -27,
      "y": 39,
      "z": -18,
      "name": "Rock_Ice"
    },
    {
      "x": -27,
      "y": 40,
      "z": -18,
      "name": "Rock_Ice"
    },
    {
      "x": -27,
      "y": 41,
      "z": -18,
      "name": "Soil_Snow"
    },
    {
      "x": -27,
      "y": 15,
      "z": -17,
      "name": "Rock_Ice"
    },
    {
      "x": -27,
      "y": 16,
      "z": -17,
      "name": "Rock_Ice"
    },
    {
      "x": -27,
      "y": 17,
      "z": -17,
      "name": "Rock_Ice"
    },
    {
      "x": -27,
      "y": 18,
      "z": -17,
      "name": "Rock_Ice"
    },
    {
      "x": -27,
      "y": 19,
      "z": -17,
      "name": "Rock_Ice"
    },
    {
      "x": -27,
      "y": 20,
      "z": -17,
      "name": "Rock_Ice"
    },
    {
      "x": -27,
      "y": 21,
      "z": -17,
      "name": "Rock_Ice"
    },
    {
      "x": -27,
      "y": 22,
      "z": -17,
      "name": "Rock_Ice"
    },
    {
      "x": -27,
      "y": 23,
      "z": -17,
      "name": "Rock_Ice"
    },
    {
      "x": -27,
      "y": 24,
      "z": -17,
      "name": "Rock_Ice"
    },
    {
      "x": -27,
      "y": 25,
      "z": -17,
      "name": "Rock_Ice"
    },
    {
      "x": -27,
      "y": 26,
      "z": -17,
      "name": "Rock_Ice"
    },
    {
      "x": -27,
      "y": 27,
      "z": -17,
      "name": "Rock_Ice"
    },
    {
      "x": -27,
      "y": 28,
      "z": -17,
      "name": "Rock_Ice"
    },
    {
      "x": -27,
      "y": 29,
      "z": -17,
      "name": "Rock_Ice"
    },
    {
      "x": -27,
      "y": 30,
      "z": -17,
      "name": "Rock_Ice_Permafrost"
    },
    {
      "x": -27,
      "y": 31,
      "z": -17,
      "name": "Rock_Ice"
    },
    {
      "x": -27,
      "y": 32,
      "z": -17,
      "name": "Rock_Ice"
    },
    {
      "x": -27,
      "y": 33,
      "z": -17,
      "name": "Rock_Ice"
    },
    {
      "x": -27,
      "y": 34,
      "z": -17,
      "name": "Rock_Ice"
    },
    {
      "x": -27,
      "y": 35,
      "z": -17,
      "name": "Rock_Ice"
    },
    {
      "x": -27,
      "y": 36,
      "z": -17,
      "name": "Rock_Ice"
    },
    {
      "x": -27,
      "y": 37,
      "z": -17,
      "name": "Rock_Ice"
    },
    {
      "x": -27,
      "y": 38,
      "z": -17,
      "name": "Rock_Ice"
    },
    {
      "x": -27,
      "y": 39,
      "z": -17,
      "name": "Rock_Ice"
    },
    {
      "x": -27,
      "y": 40,
      "z": -17,
      "name": "Soil_Snow"
    },
    {
      "x": -27,
      "y": 14,
      "z": -16,
      "name": "Rock_Ice"
    },
    {
      "x": -27,
      "y": 15,
      "z": -16,
      "name": "Rock_Ice"
    },
    {
      "x": -27,
      "y": 16,
      "z": -16,
      "name": "Rock_Ice"
    },
    {
      "x": -27,
      "y": 17,
      "z": -16,
      "name": "Rock_Ice"
    },
    {
      "x": -27,
      "y": 18,
      "z": -16,
      "name": "Rock_Ice"
    },
    {
      "x": -27,
      "y": 19,
      "z": -16,
      "name": "Rock_Ice"
    },
    {
      "x": -27,
      "y": 20,
      "z": -16,
      "name": "Rock_Ice"
    },
    {
      "x": -27,
      "y": 21,
      "z": -16,
      "name": "Rock_Ice"
    },
    {
      "x": -27,
      "y": 22,
      "z": -16,
      "name": "Rock_Ice"
    },
    {
      "x": -27,
      "y": 23,
      "z": -16,
      "name": "Rock_Ice"
    },
    {
      "x": -27,
      "y": 24,
      "z": -16,
      "name": "Rock_Ice"
    },
    {
      "x": -27,
      "y": 25,
      "z": -16,
      "name": "Rock_Ice"
    },
    {
      "x": -27,
      "y": 26,
      "z": -16,
      "name": "Rock_Ice_Permafrost"
    },
    {
      "x": -27,
      "y": 27,
      "z": -16,
      "name": "Rock_Ice_Permafrost"
    },
    {
      "x": -27,
      "y": 28,
      "z": -16,
      "name": "Rock_Ice_Permafrost"
    },
    {
      "x": -27,
      "y": 29,
      "z": -16,
      "name": "Rock_Ice_Permafrost"
    },
    {
      "x": -27,
      "y": 30,
      "z": -16,
      "name": "Rock_Ice"
    },
    {
      "x": -27,
      "y": 31,
      "z": -16,
      "name": "Rock_Ice"
    },
    {
      "x": -27,
      "y": 32,
      "z": -16,
      "name": "Rock_Ice"
    },
    {
      "x": -27,
      "y": 33,
      "z": -16,
      "name": "Rock_Ice_Permafrost"
    },
    {
      "x": -27,
      "y": 34,
      "z": -16,
      "name": "Rock_Ice"
    },
    {
      "x": -27,
      "y": 35,
      "z": -16,
      "name": "Rock_Ice"
    },
    {
      "x": -27,
      "y": 36,
      "z": -16,
      "name": "Rock_Ice"
    },
    {
      "x": -27,
      "y": 37,
      "z": -16,
      "name": "Rock_Ice"
    },
    {
      "x": -27,
      "y": 38,
      "z": -16,
      "name": "Soil_Snow"
    },
    {
      "x": -27,
      "y": 13,
      "z": -15,
      "name": "Rock_Ice"
    },
    {
      "x": -27,
      "y": 14,
      "z": -15,
      "name": "Rock_Ice"
    },
    {
      "x": -27,
      "y": 15,
      "z": -15,
      "name": "Rock_Ice"
    },
    {
      "x": -27,
      "y": 16,
      "z": -15,
      "name": "Rock_Ice"
    },
    {
      "x": -27,
      "y": 17,
      "z": -15,
      "name": "Rock_Ice"
    },
    {
      "x": -27,
      "y": 18,
      "z": -15,
      "name": "Rock_Ice"
    },
    {
      "x": -27,
      "y": 19,
      "z": -15,
      "name": "Rock_Ice"
    },
    {
      "x": -27,
      "y": 20,
      "z": -15,
      "name": "Rock_Ice"
    },
    {
      "x": -27,
      "y": 21,
      "z": -15,
      "name": "Rock_Ice"
    },
    {
      "x": -27,
      "y": 22,
      "z": -15,
      "name": "Rock_Ice"
    },
    {
      "x": -27,
      "y": 23,
      "z": -15,
      "name": "Rock_Ice"
    },
    {
      "x": -27,
      "y": 24,
      "z": -15,
      "name": "Rock_Ice_Permafrost"
    },
    {
      "x": -27,
      "y": 25,
      "z": -15,
      "name": "Rock_Ice_Permafrost"
    },
    {
      "x": -27,
      "y": 26,
      "z": -15,
      "name": "Rock_Ice_Permafrost"
    },
    {
      "x": -27,
      "y": 27,
      "z": -15,
      "name": "Rock_Ice_Permafrost"
    },
    {
      "x": -27,
      "y": 28,
      "z": -15,
      "name": "Rock_Ice_Permafrost"
    },
    {
      "x": -27,
      "y": 29,
      "z": -15,
      "name": "Rock_Ice_Permafrost"
    },
    {
      "x": -27,
      "y": 30,
      "z": -15,
      "name": "Rock_Ice_Permafrost"
    },
    {
      "x": -27,
      "y": 31,
      "z": -15,
      "name": "Rock_Ice_Permafrost"
    },
    {
      "x": -27,
      "y": 32,
      "z": -15,
      "name": "Rock_Ice"
    },
    {
      "x": -27,
      "y": 33,
      "z": -15,
      "name": "Rock_Ice"
    },
    {
      "x": -27,
      "y": 34,
      "z": -15,
      "name": "Rock_Ice"
    },
    {
      "x": -27,
      "y": 35,
      "z": -15,
      "name": "Rock_Ice"
    },
    {
      "x": -27,
      "y": 36,
      "z": -15,
      "name": "Rock_Ice"
    },
    {
      "x": -27,
      "y": 37,
      "z": -15,
      "name": "Soil_Snow"
    },
    {
      "x": -27,
      "y": 13,
      "z": -14,
      "name": "Rock_Ice"
    },
    {
      "x": -27,
      "y": 14,
      "z": -14,
      "name": "Rock_Ice"
    },
    {
      "x": -27,
      "y": 15,
      "z": -14,
      "name": "Rock_Ice"
    },
    {
      "x": -27,
      "y": 16,
      "z": -14,
      "name": "Rock_Ice"
    },
    {
      "x": -27,
      "y": 17,
      "z": -14,
      "name": "Rock_Ice"
    },
    {
      "x": -27,
      "y": 18,
      "z": -14,
      "name": "Rock_Ice"
    },
    {
      "x": -27,
      "y": 19,
      "z": -14,
      "name": "Rock_Ice"
    },
    {
      "x": -27,
      "y": 20,
      "z": -14,
      "name": "Rock_Ice"
    },
    {
      "x": -27,
      "y": 21,
      "z": -14,
      "name": "Rock_Ice"
    },
    {
      "x": -27,
      "y": 22,
      "z": -14,
      "name": "Rock_Ice"
    },
    {
      "x": -27,
      "y": 23,
      "z": -14,
      "name": "Rock_Ice_Permafrost"
    },
    {
      "x": -27,
      "y": 24,
      "z": -14,
      "name": "Rock_Ice"
    },
    {
      "x": -27,
      "y": 25,
      "z": -14,
      "name": "Rock_Ice_Permafrost"
    },
    {
      "x": -27,
      "y": 26,
      "z": -14,
      "name": "Rock_Ice_Permafrost"
    },
    {
      "x": -27,
      "y": 27,
      "z": -14,
      "name": "Rock_Ice_Permafrost"
    },
    {
      "x": -27,
      "y": 28,
      "z": -14,
      "name": "Rock_Ice_Permafrost"
    },
    {
      "x": -27,
      "y": 29,
      "z": -14,
      "name": "Rock_Ice_Permafrost"
    },
    {
      "x": -27,
      "y": 30,
      "z": -14,
      "name": "Rock_Ice_Permafrost"
    },
    {
      "x": -27,
      "y": 31,
      "z": -14,
      "name": "Rock_Ice"
    },
    {
      "x": -27,
      "y": 32,
      "z": -14,
      "name": "Rock_Ice"
    },
    {
      "x": -27,
      "y": 33,
      "z": -14,
      "name": "Rock_Ice"
    },
    {
      "x": -27,
      "y": 34,
      "z": -14,
      "name": "Rock_Ice"
    },
    {
      "x": -27,
      "y": 35,
      "z": -14,
      "name": "Soil_Snow"
    },
    {
      "x": -27,
      "y": 13,
      "z": -13,
      "name": "Rock_Ice"
    },
    {
      "x": -27,
      "y": 14,
      "z": -13,
      "name": "Rock_Ice"
    },
    {
      "x": -27,
      "y": 15,
      "z": -13,
      "name": "Rock_Ice"
    },
    {
      "x": -27,
      "y": 16,
      "z": -13,
      "name": "Rock_Ice"
    },
    {
      "x": -27,
      "y": 17,
      "z": -13,
      "name": "Rock_Ice"
    },
    {
      "x": -27,
      "y": 18,
      "z": -13,
      "name": "Rock_Ice"
    },
    {
      "x": -27,
      "y": 19,
      "z": -13,
      "name": "Rock_Ice"
    },
    {
      "x": -27,
      "y": 20,
      "z": -13,
      "name": "Rock_Ice"
    },
    {
      "x": -27,
      "y": 21,
      "z": -13,
      "name": "Rock_Ice"
    },
    {
      "x": -27,
      "y": 22,
      "z": -13,
      "name": "Rock_Ice"
    },
    {
      "x": -27,
      "y": 23,
      "z": -13,
      "name": "Rock_Ice_Permafrost"
    },
    {
      "x": -27,
      "y": 24,
      "z": -13,
      "name": "Rock_Ice_Permafrost"
    },
    {
      "x": -27,
      "y": 25,
      "z": -13,
      "name": "Rock_Ice_Permafrost"
    },
    {
      "x": -27,
      "y": 26,
      "z": -13,
      "name": "Rock_Ice_Permafrost"
    },
    {
      "x": -27,
      "y": 27,
      "z": -13,
      "name": "Rock_Ice_Permafrost"
    },
    {
      "x": -27,
      "y": 28,
      "z": -13,
      "name": "Rock_Ice_Permafrost"
    },
    {
      "x": -27,
      "y": 29,
      "z": -13,
      "name": "Rock_Ice"
    },
    {
      "x": -27,
      "y": 30,
      "z": -13,
      "name": "Rock_Ice"
    },
    {
      "x": -27,
      "y": 31,
      "z": -13,
      "name": "Rock_Ice"
    },
    {
      "x": -27,
      "y": 32,
      "z": -13,
      "name": "Rock_Ice"
    },
    {
      "x": -27,
      "y": 33,
      "z": -13,
      "name": "Rock_Ice"
    },
    {
      "x": -27,
      "y": 34,
      "z": -13,
      "name": "Soil_Snow"
    },
    {
      "x": -27,
      "y": 13,
      "z": -12,
      "name": "Rock_Ice"
    },
    {
      "x": -27,
      "y": 14,
      "z": -12,
      "name": "Rock_Ice"
    },
    {
      "x": -27,
      "y": 15,
      "z": -12,
      "name": "Rock_Ice"
    },
    {
      "x": -27,
      "y": 16,
      "z": -12,
      "name": "Rock_Ice"
    },
    {
      "x": -27,
      "y": 17,
      "z": -12,
      "name": "Rock_Ice"
    },
    {
      "x": -27,
      "y": 18,
      "z": -12,
      "name": "Rock_Ice"
    },
    {
      "x": -27,
      "y": 19,
      "z": -12,
      "name": "Rock_Ice"
    },
    {
      "x": -27,
      "y": 20,
      "z": -12,
      "name": "Rock_Ice"
    },
    {
      "x": -27,
      "y": 21,
      "z": -12,
      "name": "Rock_Ice"
    },
    {
      "x": -27,
      "y": 22,
      "z": -12,
      "name": "Rock_Ice_Permafrost"
    },
    {
      "x": -27,
      "y": 23,
      "z": -12,
      "name": "Rock_Ice_Permafrost"
    },
    {
      "x": -27,
      "y": 24,
      "z": -12,
      "name": "Rock_Ice_Permafrost"
    },
    {
      "x": -27,
      "y": 25,
      "z": -12,
      "name": "Rock_Ice_Permafrost"
    },
    {
      "x": -27,
      "y": 26,
      "z": -12,
      "name": "Rock_Ice_Permafrost"
    },
    {
      "x": -27,
      "y": 27,
      "z": -12,
      "name": "Rock_Ice_Permafrost"
    },
    {
      "x": -27,
      "y": 28,
      "z": -12,
      "name": "Rock_Ice"
    },
    {
      "x": -27,
      "y": 29,
      "z": -12,
      "name": "Rock_Ice"
    },
    {
      "x": -27,
      "y": 30,
      "z": -12,
      "name": "Rock_Ice"
    },
    {
      "x": -27,
      "y": 31,
      "z": -12,
      "name": "Rock_Ice"
    },
    {
      "x": -27,
      "y": 32,
      "z": -12,
      "name": "Rock_Ice"
    },
    {
      "x": -27,
      "y": 33,
      "z": -12,
      "name": "Rock_Ice"
    },
    {
      "x": -27,
      "y": 13,
      "z": -11,
      "name": "Rock_Ice"
    },
    {
      "x": -27,
      "y": 14,
      "z": -11,
      "name": "Rock_Ice"
    },
    {
      "x": -27,
      "y": 15,
      "z": -11,
      "name": "Rock_Ice"
    },
    {
      "x": -27,
      "y": 16,
      "z": -11,
      "name": "Rock_Ice"
    },
    {
      "x": -27,
      "y": 17,
      "z": -11,
      "name": "Rock_Ice"
    },
    {
      "x": -27,
      "y": 18,
      "z": -11,
      "name": "Rock_Ice"
    },
    {
      "x": -27,
      "y": 19,
      "z": -11,
      "name": "Rock_Ice"
    },
    {
      "x": -27,
      "y": 20,
      "z": -11,
      "name": "Rock_Ice"
    },
    {
      "x": -27,
      "y": 21,
      "z": -11,
      "name": "Rock_Ice"
    },
    {
      "x": -27,
      "y": 22,
      "z": -11,
      "name": "Rock_Ice_Permafrost"
    },
    {
      "x": -27,
      "y": 23,
      "z": -11,
      "name": "Rock_Ice_Permafrost"
    },
    {
      "x": -27,
      "y": 24,
      "z": -11,
      "name": "Rock_Ice_Permafrost"
    },
    {
      "x": -27,
      "y": 25,
      "z": -11,
      "name": "Rock_Ice_Permafrost"
    },
    {
      "x": -27,
      "y": 26,
      "z": -11,
      "name": "Rock_Ice"
    },
    {
      "x": -27,
      "y": 27,
      "z": -11,
      "name": "Rock_Ice"
    },
    {
      "x": -27,
      "y": 28,
      "z": -11,
      "name": "Rock_Ice"
    },
    {
      "x": -27,
      "y": 29,
      "z": -11,
      "name": "Rock_Ice"
    },
    {
      "x": -27,
      "y": 30,
      "z": -11,
      "name": "Rock_Ice"
    },
    {
      "x": -27,
      "y": 31,
      "z": -11,
      "name": "Rock_Ice"
    },
    {
      "x": -27,
      "y": 32,
      "z": -11,
      "name": "Soil_Snow"
    },
    {
      "x": -27,
      "y": 13,
      "z": -10,
      "name": "Rock_Ice"
    },
    {
      "x": -27,
      "y": 14,
      "z": -10,
      "name": "Rock_Ice"
    },
    {
      "x": -27,
      "y": 15,
      "z": -10,
      "name": "Rock_Ice"
    },
    {
      "x": -27,
      "y": 16,
      "z": -10,
      "name": "Rock_Ice"
    },
    {
      "x": -27,
      "y": 17,
      "z": -10,
      "name": "Rock_Ice"
    },
    {
      "x": -27,
      "y": 18,
      "z": -10,
      "name": "Rock_Ice"
    },
    {
      "x": -27,
      "y": 19,
      "z": -10,
      "name": "Rock_Ice"
    },
    {
      "x": -27,
      "y": 20,
      "z": -10,
      "name": "Rock_Ice_Permafrost"
    },
    {
      "x": -27,
      "y": 21,
      "z": -10,
      "name": "Rock_Ice"
    },
    {
      "x": -27,
      "y": 22,
      "z": -10,
      "name": "Rock_Ice_Permafrost"
    },
    {
      "x": -27,
      "y": 23,
      "z": -10,
      "name": "Rock_Ice_Permafrost"
    },
    {
      "x": -27,
      "y": 24,
      "z": -10,
      "name": "Rock_Ice_Permafrost"
    },
    {
      "x": -27,
      "y": 25,
      "z": -10,
      "name": "Rock_Ice_Permafrost"
    },
    {
      "x": -27,
      "y": 26,
      "z": -10,
      "name": "Rock_Ice_Permafrost"
    },
    {
      "x": -27,
      "y": 27,
      "z": -10,
      "name": "Rock_Ice"
    },
    {
      "x": -27,
      "y": 28,
      "z": -10,
      "name": "Rock_Ice"
    },
    {
      "x": -27,
      "y": 29,
      "z": -10,
      "name": "Rock_Ice"
    },
    {
      "x": -27,
      "y": 30,
      "z": -10,
      "name": "Rock_Ice"
    },
    {
      "x": -27,
      "y": 31,
      "z": -10,
      "name": "Rock_Ice"
    },
    {
      "x": -27,
      "y": 32,
      "z": -10,
      "name": "Soil_Snow"
    },
    {
      "x": -27,
      "y": 13,
      "z": -9,
      "name": "Rock_Ice"
    },
    {
      "x": -27,
      "y": 14,
      "z": -9,
      "name": "Rock_Ice"
    },
    {
      "x": -27,
      "y": 15,
      "z": -9,
      "name": "Rock_Ice"
    },
    {
      "x": -27,
      "y": 16,
      "z": -9,
      "name": "Rock_Ice"
    },
    {
      "x": -27,
      "y": 17,
      "z": -9,
      "name": "Rock_Ice"
    },
    {
      "x": -27,
      "y": 18,
      "z": -9,
      "name": "Rock_Ice"
    },
    {
      "x": -27,
      "y": 19,
      "z": -9,
      "name": "Rock_Ice"
    },
    {
      "x": -27,
      "y": 20,
      "z": -9,
      "name": "Rock_Ice_Permafrost"
    },
    {
      "x": -27,
      "y": 21,
      "z": -9,
      "name": "Rock_Ice_Permafrost"
    },
    {
      "x": -27,
      "y": 22,
      "z": -9,
      "name": "Rock_Ice_Permafrost"
    },
    {
      "x": -27,
      "y": 23,
      "z": -9,
      "name": "Rock_Ice_Permafrost"
    },
    {
      "x": -27,
      "y": 24,
      "z": -9,
      "name": "Rock_Ice_Permafrost"
    },
    {
      "x": -27,
      "y": 25,
      "z": -9,
      "name": "Rock_Ice_Permafrost"
    },
    {
      "x": -27,
      "y": 26,
      "z": -9,
      "name": "Rock_Ice"
    },
    {
      "x": -27,
      "y": 27,
      "z": -9,
      "name": "Rock_Ice"
    },
    {
      "x": -27,
      "y": 28,
      "z": -9,
      "name": "Rock_Ice"
    },
    {
      "x": -27,
      "y": 29,
      "z": -9,
      "name": "Rock_Ice"
    },
    {
      "x": -27,
      "y": 30,
      "z": -9,
      "name": "Rock_Ice"
    },
    {
      "x": -27,
      "y": 31,
      "z": -9,
      "name": "Rock_Ice"
    },
    {
      "x": -27,
      "y": 32,
      "z": -9,
      "name": "Soil_Snow"
    },
    {
      "x": -27,
      "y": 14,
      "z": -8,
      "name": "Rock_Ice"
    },
    {
      "x": -27,
      "y": 15,
      "z": -8,
      "name": "Rock_Ice"
    },
    {
      "x": -27,
      "y": 16,
      "z": -8,
      "name": "Rock_Ice"
    },
    {
      "x": -27,
      "y": 17,
      "z": -8,
      "name": "Rock_Ice"
    },
    {
      "x": -27,
      "y": 18,
      "z": -8,
      "name": "Rock_Ice"
    },
    {
      "x": -27,
      "y": 19,
      "z": -8,
      "name": "Rock_Ice"
    },
    {
      "x": -27,
      "y": 20,
      "z": -8,
      "name": "Rock_Ice_Permafrost"
    },
    {
      "x": -27,
      "y": 21,
      "z": -8,
      "name": "Rock_Ice_Permafrost"
    },
    {
      "x": -27,
      "y": 22,
      "z": -8,
      "name": "Rock_Ice"
    },
    {
      "x": -27,
      "y": 23,
      "z": -8,
      "name": "Rock_Ice_Permafrost"
    },
    {
      "x": -27,
      "y": 24,
      "z": -8,
      "name": "Rock_Ice_Permafrost"
    },
    {
      "x": -27,
      "y": 25,
      "z": -8,
      "name": "Rock_Ice"
    },
    {
      "x": -27,
      "y": 26,
      "z": -8,
      "name": "Rock_Ice_Permafrost"
    },
    {
      "x": -27,
      "y": 27,
      "z": -8,
      "name": "Rock_Ice"
    },
    {
      "x": -27,
      "y": 28,
      "z": -8,
      "name": "Rock_Ice"
    },
    {
      "x": -27,
      "y": 29,
      "z": -8,
      "name": "Rock_Ice"
    },
    {
      "x": -27,
      "y": 30,
      "z": -8,
      "name": "Rock_Ice"
    },
    {
      "x": -27,
      "y": 31,
      "z": -8,
      "name": "Rock_Ice"
    },
    {
      "x": -27,
      "y": 32,
      "z": -8,
      "name": "Soil_Snow"
    },
    {
      "x": -27,
      "y": 14,
      "z": -7,
      "name": "Rock_Ice"
    },
    {
      "x": -27,
      "y": 15,
      "z": -7,
      "name": "Rock_Ice"
    },
    {
      "x": -27,
      "y": 16,
      "z": -7,
      "name": "Rock_Ice"
    },
    {
      "x": -27,
      "y": 17,
      "z": -7,
      "name": "Rock_Ice"
    },
    {
      "x": -27,
      "y": 18,
      "z": -7,
      "name": "Rock_Ice_Permafrost"
    },
    {
      "x": -27,
      "y": 19,
      "z": -7,
      "name": "Rock_Ice_Permafrost"
    },
    {
      "x": -27,
      "y": 20,
      "z": -7,
      "name": "Rock_Ice_Permafrost"
    },
    {
      "x": -27,
      "y": 21,
      "z": -7,
      "name": "Rock_Ice"
    },
    {
      "x": -27,
      "y": 22,
      "z": -7,
      "name": "Rock_Ice"
    },
    {
      "x": -27,
      "y": 23,
      "z": -7,
      "name": "Rock_Ice"
    },
    {
      "x": -27,
      "y": 24,
      "z": -7,
      "name": "Rock_Ice_Permafrost"
    },
    {
      "x": -27,
      "y": 25,
      "z": -7,
      "name": "Rock_Ice_Permafrost"
    },
    {
      "x": -27,
      "y": 26,
      "z": -7,
      "name": "Rock_Ice"
    },
    {
      "x": -27,
      "y": 27,
      "z": -7,
      "name": "Rock_Ice"
    },
    {
      "x": -27,
      "y": 28,
      "z": -7,
      "name": "Rock_Ice"
    },
    {
      "x": -27,
      "y": 29,
      "z": -7,
      "name": "Rock_Ice"
    },
    {
      "x": -27,
      "y": 30,
      "z": -7,
      "name": "Rock_Ice"
    },
    {
      "x": -27,
      "y": 31,
      "z": -7,
      "name": "Soil_Snow"
    },
    {
      "x": -27,
      "y": 14,
      "z": -6,
      "name": "Rock_Ice"
    },
    {
      "x": -27,
      "y": 15,
      "z": -6,
      "name": "Rock_Ice"
    },
    {
      "x": -27,
      "y": 16,
      "z": -6,
      "name": "Rock_Ice"
    },
    {
      "x": -27,
      "y": 17,
      "z": -6,
      "name": "Rock_Ice"
    },
    {
      "x": -27,
      "y": 18,
      "z": -6,
      "name": "Rock_Ice_Permafrost"
    },
    {
      "x": -27,
      "y": 19,
      "z": -6,
      "name": "Rock_Ice"
    },
    {
      "x": -27,
      "y": 20,
      "z": -6,
      "name": "Rock_Ice"
    },
    {
      "x": -27,
      "y": 21,
      "z": -6,
      "name": "Rock_Ice"
    },
    {
      "x": -27,
      "y": 22,
      "z": -6,
      "name": "Rock_Ice_Permafrost"
    },
    {
      "x": -27,
      "y": 23,
      "z": -6,
      "name": "Rock_Ice_Permafrost"
    },
    {
      "x": -27,
      "y": 24,
      "z": -6,
      "name": "Rock_Ice"
    },
    {
      "x": -27,
      "y": 25,
      "z": -6,
      "name": "Rock_Ice"
    },
    {
      "x": -27,
      "y": 26,
      "z": -6,
      "name": "Soil_Snow"
    },
    {
      "x": -27,
      "y": 14,
      "z": -5,
      "name": "Rock_Ice"
    },
    {
      "x": -27,
      "y": 15,
      "z": -5,
      "name": "Rock_Ice"
    },
    {
      "x": -27,
      "y": 16,
      "z": -5,
      "name": "Rock_Ice"
    },
    {
      "x": -27,
      "y": 17,
      "z": -5,
      "name": "Rock_Ice"
    },
    {
      "x": -27,
      "y": 18,
      "z": -5,
      "name": "Rock_Ice"
    },
    {
      "x": -27,
      "y": 19,
      "z": -5,
      "name": "Rock_Ice"
    },
    {
      "x": -27,
      "y": 20,
      "z": -5,
      "name": "Rock_Ice"
    },
    {
      "x": -27,
      "y": 21,
      "z": -5,
      "name": "Rock_Ice_Permafrost"
    },
    {
      "x": -27,
      "y": 22,
      "z": -5,
      "name": "Rock_Ice_Permafrost"
    },
    {
      "x": -27,
      "y": 23,
      "z": -5,
      "name": "Rock_Ice"
    },
    {
      "x": -27,
      "y": 24,
      "z": -5,
      "name": "Soil_Snow"
    },
    {
      "x": -27,
      "y": 14,
      "z": -4,
      "name": "Rock_Ice"
    },
    {
      "x": -27,
      "y": 15,
      "z": -4,
      "name": "Rock_Ice"
    },
    {
      "x": -27,
      "y": 16,
      "z": -4,
      "name": "Rock_Ice"
    },
    {
      "x": -27,
      "y": 17,
      "z": -4,
      "name": "Rock_Ice"
    },
    {
      "x": -27,
      "y": 18,
      "z": -4,
      "name": "Rock_Ice"
    },
    {
      "x": -27,
      "y": 19,
      "z": -4,
      "name": "Rock_Ice_Permafrost"
    },
    {
      "x": -27,
      "y": 20,
      "z": -4,
      "name": "Rock_Ice_Permafrost"
    },
    {
      "x": -27,
      "y": 21,
      "z": -4,
      "name": "Rock_Ice_Permafrost"
    },
    {
      "x": -27,
      "y": 22,
      "z": -4,
      "name": "Rock_Ice"
    },
    {
      "x": -27,
      "y": 23,
      "z": -4,
      "name": "Soil_Snow"
    },
    {
      "x": -27,
      "y": 14,
      "z": -3,
      "name": "Rock_Ice"
    },
    {
      "x": -27,
      "y": 15,
      "z": -3,
      "name": "Rock_Ice"
    },
    {
      "x": -27,
      "y": 16,
      "z": -3,
      "name": "Rock_Ice"
    },
    {
      "x": -27,
      "y": 17,
      "z": -3,
      "name": "Rock_Ice"
    },
    {
      "x": -27,
      "y": 18,
      "z": -3,
      "name": "Rock_Ice_Permafrost"
    },
    {
      "x": -27,
      "y": 19,
      "z": -3,
      "name": "Rock_Ice"
    },
