{
  "version": 8,
  "blockIdVersion": 11,
  "anchorX": -1,
  "anchorY": 28,
  "anchorZ": -2,
  "blocks": [
    {
      "x": -32,
      "y": 75,
      "z": 8,
      "name": "Rock_Ice_Permafrost"
    },
    {
      "x": -32,
      "y": 74,
      "z": 9,
      "name": "Rock_Ice_Permafrost"
    },
    {
      "x": -32,
      "y": 79,
      "z": 11,
      "name": "Rock_Ice"
    },
    {
      "x": -32,
      "y": 78,
      "z": 12,
      "name": "Rock_Ice"
    },
    {
      "x": -31,
      "y": 78,
      "z": 3,
      "name": "Rock_Ice"
    },
    {
      "x": -31,
      "y": 79,
      "z": 3,
      "name": "Rock_Ice"
    },
    {
      "x": -31,
      "y": 80,
      "z": 3,
      "name": "Soil_Snow"
    },
    {
      "x": -31,
      "y": 75,
      "z": 4,
      "name": "Rock_Ice_Permafrost"
    },
    {
      "x": -31,
      "y": 76,
      "z": 4,
      "name": "Rock_Ice_Permafrost"
    },
    {
      "x": -31,
      "y": 77,
      "z": 4,
      "name": "Rock_Ice"
    },
    {
      "x": -31,
      "y": 78,
      "z": 4,
      "name": "Rock_Ice"
    },
    {
      "x": -31,
      "y": 79,
      "z": 4,
      "name": "Rock_Ice"
    },
    {
      "x": -31,
      "y": 80,
      "z": 4,
      "name": "Rock_Ice"
    },
    {
      "x": -31,
      "y": 81,
      "z": 4,
      "name": "Soil_Snow"
    },
    {
      "x": -31,
      "y": 73,
      "z": 5,
      "name": "Rock_Ice_Permafrost"
    },
    {
      "x": -31,
      "y": 74,
      "z": 5,
      "name": "Rock_Ice_Permafrost"
    },
    {
      "x": -31,
      "y": 75,
      "z": 5,
      "name": "Rock_Ice_Permafrost"
    },
    {
      "x": -31,
      "y": 76,
      "z": 5,
      "name": "Rock_Ice"
    },
    {
      "x": -31,
      "y": 77,
      "z": 5,
      "name": "Rock_Ice"
    },
    {
      "x": -31,
      "y": 78,
      "z": 5,
      "name": "Rock_Ice"
    },
    {
      "x": -31,
      "y": 79,
      "z": 5,
      "name": "Rock_Ice"
    },
    {
      "x": -31,
      "y": 80,
      "z": 5,
      "name": "Rock_Ice"
    },
    {
      "x": -31,
      "y": 81,
      "z": 5,
      "name": "Rock_Ice"
    },
    {
      "x": -31,
      "y": 82,
      "z": 5,
      "name": "Soil_Snow"
    },
    {
      "x": -31,
      "y": 71,
      "z": 6,
      "name": "Rock_Ice"
    },
    {
      "x": -31,
      "y": 72,
      "z": 6,
      "name": "Rock_Ice"
    },
    {
      "x": -31,
      "y": 73,
      "z": 6,
      "name": "Rock_Ice_Permafrost"
    },
    {
      "x": -31,
      "y": 74,
      "z": 6,
      "name": "Rock_Ice_Permafrost"
    },
    {
      "x": -31,
      "y": 75,
      "z": 6,
      "name": "Rock_Ice_Permafrost"
    },
    {
      "x": -31,
      "y": 76,
      "z": 6,
      "name": "Rock_Ice"
    },
    {
      "x": -31,
      "y": 77,
      "z": 6,
      "name": "Rock_Ice"
    },
    {
      "x": -31,
      "y": 78,
      "z": 6,
      "name": "Rock_Ice"
    },
    {
      "x": -31,
      "y": 79,
      "z": 6,
      "name": "Rock_Ice"
    },
    {
      "x": -31,
      "y": 80,
      "z": 6,
      "name": "Rock_Ice"
    },
    {
      "x": -31,
      "y": 81,
      "z": 6,
      "name": "Rock_Ice"
    },
    {
      "x": -31,
      "y": 82,
      "z": 6,
      "name": "Soil_Snow"
    },
    {
      "x": -31,
      "y": 69,
      "z": 7,
      "name": "Rock_Ice"
    },
    {
      "x": -31,
      "y": 70,
      "z": 7,
      "name": "Rock_Ice"
    },
    {
      "x": -31,
      "y": 71,
      "z": 7,
      "name": "Rock_Ice"
    },
    {
      "x": -31,
      "y": 72,
      "z": 7,
      "name": "Rock_Ice_Permafrost"
    },
    {
      "x": -31,
      "y": 73,
      "z": 7,
      "name": "Rock_Ice_Permafrost"
    },
    {
      "x": -31,
      "y": 74,
      "z": 7,
      "name": "Rock_Ice_Permafrost"
    },
    {
      "x": -31,
      "y": 75,
      "z": 7,
      "name": "Rock_Ice_Permafrost"
    },
    {
      "x": -31,
      "y": 76,
      "z": 7,
      "name": "Rock_Ice"
    },
    {
      "x": -31,
      "y": 77,
      "z": 7,
      "name": "Rock_Ice"
    },
    {
      "x": -31,
      "y": 78,
      "z": 7,
      "name": "Rock_Ice"
    },
    {
      "x": -31,
      "y": 79,
      "z": 7,
      "name": "Rock_Ice"
    },
    {
      "x": -31,
      "y": 80,
      "z": 7,
      "name": "Rock_Ice"
    },
    {
      "x": -31,
      "y": 81,
      "z": 7,
      "name": "Rock_Ice"
    },
    {
      "x": -31,
      "y": 82,
      "z": 7,
      "name": "Rock_Ice"
    },
    {
      "x": -31,
      "y": 83,
      "z": 7,
      "name": "Soil_Snow"
    },
    {
      "x": -31,
      "y": 68,
      "z": 8,
      "name": "Rock_Ice"
    },
    {
      "x": -31,
      "y": 69,
      "z": 8,
      "name": "Rock_Ice"
    },
    {
      "x": -31,
      "y": 70,
      "z": 8,
      "name": "Rock_Ice"
    },
    {
      "x": -31,
      "y": 71,
      "z": 8,
      "name": "Rock_Ice"
    },
    {
      "x": -31,
      "y": 72,
      "z": 8,
      "name": "Rock_Ice_Permafrost"
    },
    {
      "x": -31,
      "y": 73,
      "z": 8,
      "name": "Rock_Ice_Permafrost"
    },
    {
      "x": -31,
      "y": 74,
      "z": 8,
      "name": "Rock_Ice_Permafrost"
    },
    {
      "x": -31,
      "y": 75,
      "z": 8,
      "name": "Rock_Ice"
    },
    {
      "x": -31,
      "y": 76,
      "z": 8,
      "name": "Rock_Ice"
    },
    {
      "x": -31,
      "y": 77,
      "z": 8,
      "name": "Rock_Ice"
    },
    {
      "x": -31,
      "y": 78,
      "z": 8,
      "name": "Rock_Ice"
    },
    {
      "x": -31,
      "y": 79,
      "z": 8,
      "name": "Rock_Ice"
    },
    {
      "x": -31,
      "y": 80,
      "z": 8,
      "name": "Rock_Ice"
    },
    {
      "x": -31,
      "y": 81,
      "z": 8,
      "name": "Rock_Ice"
    },
    {
      "x": -31,
      "y": 82,
      "z": 8,
      "name": "Rock_Ice"
    },
    {
      "x": -31,
      "y": 83,
      "z": 8,
      "name": "Soil_Snow"
    },
    {
      "x": -31,
      "y": 67,
      "z": 9,
      "name": "Rock_Ice"
    },
    {
      "x": -31,
      "y": 68,
      "z": 9,
      "name": "Rock_Ice"
    },
    {
      "x": -31,
      "y": 69,
      "z": 9,
      "name": "Rock_Ice"
    },
    {
      "x": -31,
      "y": 70,
      "z": 9,
      "name": "Rock_Ice"
    },
    {
      "x": -31,
      "y": 71,
      "z": 9,
      "name": "Rock_Ice"
    },
    {
      "x": -31,
      "y": 72,
      "z": 9,
      "name": "Rock_Ice_Permafrost"
    },
    {
      "x": -31,
      "y": 73,
      "z": 9,
      "name": "Rock_Ice_Permafrost"
    },
    {
      "x": -31,
      "y": 74,
      "z": 9,
      "name": "Rock_Ice_Permafrost"
    },
    {
      "x": -31,
      "y": 75,
      "z": 9,
      "name": "Rock_Ice"
    },
    {
      "x": -31,
      "y": 76,
      "z": 9,
      "name": "Rock_Ice"
    },
    {
      "x": -31,
      "y": 77,
      "z": 9,
      "name": "Rock_Ice"
    },
    {
      "x": -31,
      "y": 78,
      "z": 9,
      "name": "Rock_Ice"
    },
    {
      "x": -31,
      "y": 79,
      "z": 9,
      "name": "Rock_Ice"
    },
    {
      "x": -31,
      "y": 80,
      "z": 9,
      "name": "Rock_Ice"
    },
    {
      "x": -31,
      "y": 81,
      "z": 9,
      "name": "Rock_Ice"
    },
    {
      "x": -31,
      "y": 82,
      "z": 9,
      "name": "Rock_Ice"
    },
    {
      "x": -31,
      "y": 83,
      "z": 9,
      "name": "Rock_Ice"
    },
    {
      "x": -31,
      "y": 84,
      "z": 9,
      "name": "Soil_Snow"
    },
    {
      "x": -31,
      "y": 68,
      "z": 10,
      "name": "Rock_Ice"
    },
    {
      "x": -31,
      "y": 69,
      "z": 10,
      "name": "Rock_Ice"
    },
    {
      "x": -31,
      "y": 70,
      "z": 10,
      "name": "Rock_Ice"
    },
    {
      "x": -31,
      "y": 71,
      "z": 10,
      "name": "Rock_Ice_Permafrost"
    },
    {
      "x": -31,
      "y": 72,
      "z": 10,
      "name": "Rock_Ice_Permafrost"
    },
    {
      "x": -31,
      "y": 73,
      "z": 10,
      "name": "Rock_Ice_Permafrost"
    },
    {
      "x": -31,
      "y": 74,
      "z": 10,
      "name": "Rock_Ice"
    },
    {
      "x": -31,
      "y": 75,
      "z": 10,
      "name": "Rock_Ice"
    },
    {
      "x": -31,
      "y": 76,
      "z": 10,
      "name": "Rock_Ice"
    },
    {
      "x": -31,
      "y": 77,
      "z": 10,
      "name": "Rock_Ice"
    },
    {
      "x": -31,
      "y": 78,
      "z": 10,
      "name": "Rock_Ice"
    },
    {
      "x": -31,
      "y": 79,
      "z": 10,
      "name": "Rock_Ice"
    },
    {
      "x": -31,
      "y": 80,
      "z": 10,
      "name": "Rock_Ice"
    },
    {
      "x": -31,
      "y": 81,
      "z": 10,
      "name": "Rock_Ice"
    },
    {
      "x": -31,
      "y": 82,
      "z": 10,
      "name": "Rock_Ice"
    },
    {
      "x": -31,
      "y": 83,
      "z": 10,
      "name": "Rock_Ice"
    },
    {
      "x": -31,
      "y": 84,
      "z": 10,
      "name": "Soil_Snow"
    },
    {
      "x": -31,
      "y": 69,
      "z": 11,
      "name": "Rock_Ice"
    },
    {
      "x": -31,
      "y": 70,
      "z": 11,
      "name": "Rock_Ice"
    },
    {
      "x": -31,
      "y": 71,
      "z": 11,
      "name": "Rock_Ice_Permafrost"
    },
    {
      "x": -31,
      "y": 72,
      "z": 11,
      "name": "Rock_Ice_Permafrost"
    },
    {
      "x": -31,
      "y": 73,
      "z": 11,
      "name": "Rock_Ice_Permafrost"
    },
    {
      "x": -31,
      "y": 74,
      "z": 11,
      "name": "Rock_Ice"
    },
    {
      "x": -31,
      "y": 75,
      "z": 11,
      "name": "Rock_Ice"
    },
    {
      "x": -31,
      "y": 76,
      "z": 11,
      "name": "Rock_Ice"
    },
    {
      "x": -31,
      "y": 77,
      "z": 11,
      "name": "Rock_Ice"
    },
    {
      "x": -31,
      "y": 78,
      "z": 11,
      "name": "Rock_Ice"
    },
    {
      "x": -31,
      "y": 79,
      "z": 11,
      "name": "Rock_Ice"
    },
    {
      "x": -31,
      "y": 80,
      "z": 11,
      "name": "Rock_Ice"
    },
    {
      "x": -31,
      "y": 81,
      "z": 11,
      "name": "Rock_Ice"
    },
    {
      "x": -31,
      "y": 82,
      "z": 11,
      "name": "Rock_Ice"
    },
    {
      "x": -31,
      "y": 83,
      "z": 11,
      "name": "Rock_Ice"
    },
    {
      "x": -31,
      "y": 84,
      "z": 11,
      "name": "Soil_Snow"
    },
    {
      "x": -31,
      "y": 57,
      "z": 12,
      "name": "Rock_Ice_Permafrost"
    },
    {
      "x": -31,
      "y": 71,
      "z": 12,
      "name": "Rock_Ice_Permafrost"
    },
    {
      "x": -31,
      "y": 72,
      "z": 12,
      "name": "Rock_Ice_Permafrost"
    },
    {
      "x": -31,
      "y": 73,
      "z": 12,
      "name": "Rock_Ice_Permafrost"
    },
    {
      "x": -31,
      "y": 74,
      "z": 12,
      "name": "Rock_Ice"
    },
    {
      "x": -31,
      "y": 75,
      "z": 12,
      "name": "Rock_Ice"
    },
    {
      "x": -31,
      "y": 76,
      "z": 12,
      "name": "Rock_Ice"
    },
    {
      "x": -31,
      "y": 77,
      "z": 12,
      "name": "Rock_Ice"
    },
    {
      "x": -31,
      "y": 78,
      "z": 12,
      "name": "Rock_Ice"
    },
    {
      "x": -31,
      "y": 79,
      "z": 12,
      "name": "Rock_Ice"
    },
    {
      "x": -31,
      "y": 80,
      "z": 12,
      "name": "Rock_Ice"
    },
    {
      "x": -31,
      "y": 81,
      "z": 12,
      "name": "Rock_Ice"
    },
    {
      "x": -31,
      "y": 82,
      "z": 12,
      "name": "Rock_Ice"
    },
    {
      "x": -31,
      "y": 83,
      "z": 12,
      "name": "Rock_Ice"
    },
    {
      "x": -31,
      "y": 84,
      "z": 12,
      "name": "Soil_Snow"
    },
    {
      "x": -31,
      "y": 73,
      "z": 13,
      "name": "Rock_Ice_Permafrost"
    },
    {
      "x": -31,
      "y": 74,
      "z": 13,
      "name": "Rock_Ice"
    },
    {
      "x": -31,
      "y": 75,
      "z": 13,
      "name": "Rock_Ice"
    },
    {
      "x": -31,
      "y": 76,
      "z": 13,
      "name": "Rock_Ice"
    },
    {
      "x": -31,
      "y": 77,
      "z": 13,
      "name": "Rock_Ice"
    },
    {
      "x": -31,
      "y": 78,
      "z": 13,
      "name": "Rock_Ice"
    },
    {
      "x": -31,
      "y": 79,
      "z": 13,
      "name": "Rock_Ice"
    },
    {
      "x": -31,
      "y": 80,
      "z": 13,
      "name": "Rock_Ice"
    },
    {
      "x": -31,
      "y": 81,
      "z": 13,
      "name": "Rock_Ice"
    },
    {
      "x": -31,
      "y": 82,
      "z": 13,
      "name": "Rock_Ice"
    },
    {
      "x": -31,
      "y": 83,
      "z": 13,
      "name": "Soil_Snow"
    },
    {
      "x": -31,
      "y": 76,
      "z": 14,
      "name": "Rock_Ice"
    },
    {
      "x": -31,
      "y": 77,
      "z": 14,
      "name": "Rock_Ice"
    },
    {
      "x": -31,
      "y": 78,
      "z": 14,
      "name": "Rock_Ice"
    },
    {
      "x": -31,
      "y": 79,
      "z": 14,
      "name": "Rock_Ice"
    },
    {
      "x": -31,
      "y": 80,
      "z": 14,
      "name": "Rock_Ice"
    },
    {
      "x": -31,
      "y": 81,
      "z": 14,
      "name": "Rock_Ice"
    },
    {
      "x": -31,
      "y": 82,
      "z": 14,
      "name": "Soil_Snow"
    },
    {
      "x": -30,
      "y": 82,
      "z": 1,
      "name": "Soil_Snow"
    },
    {
      "x": -30,
      "y": 79,
      "z": 2,
      "name": "Rock_Ice"
    },
    {
      "x": -30,
      "y": 80,
      "z": 2,
      "name": "Rock_Ice"
    },
    {
      "x": -30,
      "y": 81,
      "z": 2,
      "name": "Rock_Ice"
    },
    {
      "x": -30,
      "y": 82,
      "z": 2,
      "name": "Soil_Snow"
    },
    {
      "x": -30,
      "y": 75,
      "z": 3,
      "name": "Rock_Ice_Permafrost"
    },
    {
      "x": -30,
      "y": 76,
      "z": 3,
      "name": "Rock_Ice"
    },
    {
      "x": -30,
      "y": 77,
      "z": 3,
      "name": "Rock_Ice"
    },
    {
      "x": -30,
      "y": 78,
      "z": 3,
      "name": "Rock_Ice"
    },
    {
      "x": -30,
      "y": 79,
      "z": 3,
      "name": "Rock_Ice"
    },
    {
      "x": -30,
      "y": 80,
      "z": 3,
      "name": "Rock_Ice"
    },
    {
      "x": -30,
      "y": 81,
      "z": 3,
      "name": "Rock_Ice"
    },
    {
      "x": -30,
      "y": 82,
      "z": 3,
      "name": "Rock_Ice"
    },
    {
      "x": -30,
      "y": 83,
      "z": 3,
      "name": "Soil_Snow"
    },
    {
      "x": -30,
      "y": 72,
      "z": 4,
      "name": "Rock_Ice"
    },
    {
      "x": -30,
      "y": 73,
      "z": 4,
      "name": "Rock_Ice_Permafrost"
    },
    {
      "x": -30,
      "y": 74,
      "z": 4,
      "name": "Rock_Ice_Permafrost"
    },
    {
      "x": -30,
      "y": 75,
      "z": 4,
      "name": "Rock_Ice"
    },
    {
      "x": -30,
      "y": 76,
      "z": 4,
      "name": "Rock_Ice"
    },
    {
      "x": -30,
      "y": 77,
      "z": 4,
      "name": "Rock_Ice"
    },
    {
      "x": -30,
      "y": 78,
      "z": 4,
      "name": "Rock_Ice"
    },
    {
      "x": -30,
      "y": 79,
      "z": 4,
      "name": "Rock_Ice"
    },
    {
      "x": -30,
      "y": 80,
      "z": 4,
      "name": "Rock_Ice"
    },
    {
      "x": -30,
      "y": 81,
      "z": 4,
      "name": "Rock_Ice"
    },
    {
      "x": -30,
      "y": 82,
      "z": 4,
      "name": "Rock_Ice"
    },
    {
      "x": -30,
      "y": 83,
      "z": 4,
      "name": "Rock_Ice"
    },
    {
      "x": -30,
      "y": 84,
      "z": 4,
      "name": "Soil_Snow"
    },
    {
      "x": -30,
      "y": 70,
      "z": 5,
      "name": "Rock_Ice"
    },
    {
      "x": -30,
      "y": 71,
      "z": 5,
      "name": "Rock_Ice"
    },
    {
      "x": -30,
      "y": 72,
      "z": 5,
      "name": "Rock_Ice_Permafrost"
    },
    {
      "x": -30,
      "y": 73,
      "z": 5,
      "name": "Rock_Ice_Permafrost"
    },
    {
      "x": -30,
      "y": 74,
      "z": 5,
      "name": "Rock_Ice_Permafrost"
    },
    {
      "x": -30,
      "y": 75,
      "z": 5,
      "name": "Rock_Ice"
    },
    {
      "x": -30,
      "y": 76,
      "z": 5,
      "name": "Rock_Ice"
    },
    {
      "x": -30,
      "y": 77,
      "z": 5,
      "name": "Rock_Ice"
    },
    {
      "x": -30,
      "y": 78,
      "z": 5,
      "name": "Rock_Ice"
    },
    {
      "x": -30,
      "y": 79,
      "z": 5,
      "name": "Rock_Ice"
    },
    {
      "x": -30,
      "y": 80,
      "z": 5,
      "name": "Rock_Ice"
    },
    {
      "x": -30,
      "y": 81,
      "z": 5,
      "name": "Rock_Ice"
    },
    {
      "x": -30,
      "y": 82,
      "z": 5,
      "name": "Rock_Ice"
    },
    {
      "x": -30,
      "y": 83,
      "z": 5,
      "name": "Rock_Ice"
    },
    {
      "x": -30,
      "y": 84,
      "z": 5,
      "name": "Rock_Ice"
    },
    {
      "x": -30,
      "y": 85,
      "z": 5,
      "name": "Soil_Snow"
    },
    {
      "x": -30,
      "y": 68,
      "z": 6,
      "name": "Rock_Ice"
    },
    {
      "x": -30,
      "y": 69,
      "z": 6,
      "name": "Rock_Ice"
    },
    {
      "x": -30,
      "y": 70,
      "z": 6,
      "name": "Rock_Ice"
    },
    {
      "x": -30,
      "y": 71,
      "z": 6,
      "name": "Rock_Ice_Permafrost"
    },
    {
      "x": -30,
      "y": 72,
      "z": 6,
      "name": "Rock_Ice_Permafrost"
    },
    {
      "x": -30,
      "y": 73,
      "z": 6,
      "name": "Rock_Ice_Permafrost"
    },
    {
      "x": -30,
      "y": 74,
      "z": 6,
      "name": "Rock_Ice"
    },
    {
      "x": -30,
      "y": 75,
      "z": 6,
      "name": "Rock_Ice"
    },
    {
      "x": -30,
      "y": 76,
      "z": 6,
      "name": "Rock_Ice"
    },
    {
      "x": -30,
      "y": 77,
      "z": 6,
      "name": "Rock_Ice"
    },
    {
      "x": -30,
      "y": 78,
      "z": 6,
      "name": "Rock_Ice"
    },
    {
      "x": -30,
      "y": 79,
      "z": 6,
      "name": "Rock_Ice"
    },
    {
      "x": -30,
      "y": 80,
      "z": 6,
      "name": "Rock_Ice"
    },
    {
      "x": -30,
      "y": 81,
      "z": 6,
      "name": "Rock_Ice"
    },
    {
      "x": -30,
      "y": 82,
      "z": 6,
      "name": "Rock_Ice"
    },
    {
      "x": -30,
      "y": 83,
      "z": 6,
      "name": "Rock_Ice"
    },
    {
      "x": -30,
      "y": 84,
      "z": 6,
      "name": "Rock_Ice"
    },
    {
      "x": -30,
      "y": 85,
      "z": 6,
      "name": "Soil_Snow"
    },
    {
      "x": -30,
      "y": 66,
      "z": 7,
      "name": "Rock_Ice"
    },
    {
      "x": -30,
      "y": 67,
      "z": 7,
      "name": "Rock_Ice"
    },
    {
      "x": -30,
      "y": 68,
      "z": 7,
      "name": "Rock_Ice"
    },
    {
      "x": -30,
      "y": 69,
      "z": 7,
      "name": "Rock_Ice"
    },
    {
      "x": -30,
      "y": 70,
      "z": 7,
      "name": "Rock_Ice"
    },
    {
      "x": -30,
      "y": 71,
      "z": 7,
      "name": "Rock_Ice_Permafrost"
    },
    {
      "x": -30,
      "y": 72,
      "z": 7,
      "name": "Rock_Ice_Permafrost"
    },
    {
      "x": -30,
      "y": 73,
      "z": 7,
      "name": "Rock_Ice_Permafrost"
    },
    {
      "x": -30,
      "y": 74,
      "z": 7,
      "name": "Rock_Ice"
    },
    {
      "x": -30,
      "y": 75,
      "z": 7,
      "name": "Rock_Ice"
    },
    {
      "x": -30,
      "y": 76,
      "z": 7,
      "name": "Rock_Ice"
    },
    {
      "x": -30,
      "y": 77,
      "z": 7,
      "name": "Rock_Ice"
    },
    {
      "x": -30,
      "y": 78,
      "z": 7,
      "name": "Rock_Ice"
    },
    {
      "x": -30,
      "y": 79,
      "z": 7,
      "name": "Rock_Ice"
    },
    {
      "x": -30,
      "y": 80,
      "z": 7,
      "name": "Rock_Ice"
    },
    {
      "x": -30,
      "y": 81,
      "z": 7,
      "name": "Rock_Ice"
    },
    {
      "x": -30,
      "y": 82,
      "z": 7,
      "name": "Rock_Ice"
    },
    {
      "x": -30,
      "y": 83,
      "z": 7,
      "name": "Rock_Ice"
    },
    {
      "x": -30,
      "y": 84,
      "z": 7,
      "name": "Rock_Ice"
    },
    {
      "x": -30,
      "y": 85,
      "z": 7,
      "name": "Soil_Snow"
    },
    {
      "x": -30,
      "y": 63,
      "z": 8,
      "name": "Rock_Ice"
    },
    {
      "x": -30,
      "y": 64,
      "z": 8,
      "name": "Rock_Ice"
    },
    {
      "x": -30,
      "y": 65,
      "z": 8,
      "name": "Rock_Ice"
    },
    {
      "x": -30,
      "y": 66,
      "z": 8,
      "name": "Rock_Ice"
    },
    {
      "x": -30,
      "y": 67,
      "z": 8,
      "name": "Rock_Ice"
    },
    {
      "x": -30,
      "y": 68,
      "z": 8,
      "name": "Rock_Ice"
    },
    {
      "x": -30,
      "y": 69,
      "z": 8,
      "name": "Rock_Ice"
    },
    {
      "x": -30,
      "y": 70,
      "z": 8,
      "name": "Rock_Ice"
    },
    {
      "x": -30,
      "y": 71,
      "z": 8,
      "name": "Rock_Ice_Permafrost"
    },
    {
      "x": -30,
      "y": 72,
      "z": 8,
      "name": "Rock_Ice_Permafrost"
    },
    {
      "x": -30,
      "y": 73,
      "z": 8,
      "name": "Rock_Ice"
    },
    {
      "x": -30,
      "y": 74,
      "z": 8,
      "name": "Rock_Ice"
    },
    {
      "x": -30,
      "y": 75,
      "z": 8,
      "name": "Rock_Ice"
    },
    {
      "x": -30,
      "y": 76,
      "z": 8,
      "name": "Rock_Ice"
    },
    {
      "x": -30,
      "y": 77,
      "z": 8,
      "name": "Rock_Ice"
    },
    {
      "x": -30,
      "y": 78,
      "z": 8,
      "name": "Rock_Ice"
    },
    {
      "x": -30,
      "y": 79,
      "z": 8,
      "name": "Rock_Ice"
    },
    {
      "x": -30,
      "y": 80,
      "z": 8,
      "name": "Rock_Ice"
    },
    {
      "x": -30,
      "y": 81,
      "z": 8,
      "name": "Rock_Ice"
    },
    {
      "x": -30,
      "y": 82,
      "z": 8,
      "name": "Rock_Ice"
    },
    {
      "x": -30,
      "y": 83,
      "z": 8,
      "name": "Rock_Ice"
    },
    {
      "x": -30,
      "y": 84,
      "z": 8,
      "name": "Rock_Ice"
    },
    {
      "x": -30,
      "y": 85,
      "z": 8,
      "name": "Rock_Ice"
    },
    {
      "x": -30,
      "y": 86,
      "z": 8,
      "name": "Soil_Snow"
    },
    {
      "x": -30,
      "y": 60,
      "z": 9,
      "name": "Rock_Ice"
    },
    {
      "x": -30,
      "y": 61,
      "z": 9,
      "name": "Rock_Ice"
    },
    {
      "x": -30,
      "y": 62,
      "z": 9,
      "name": "Rock_Ice"
    },
    {
      "x": -30,
      "y": 63,
      "z": 9,
      "name": "Rock_Ice"
    },
    {
      "x": -30,
      "y": 64,
      "z": 9,
      "name": "Rock_Ice"
    },
    {
      "x": -30,
      "y": 65,
      "z": 9,
      "name": "Rock_Ice"
    },
    {
      "x": -30,
      "y": 66,
      "z": 9,
      "name": "Rock_Ice"
    },
    {
      "x": -30,
      "y": 67,
      "z": 9,
      "name": "Rock_Ice"
    },
    {
      "x": -30,
      "y": 68,
      "z": 9,
      "name": "Rock_Ice"
    },
    {
      "x": -30,
      "y": 69,
      "z": 9,
      "name": "Rock_Ice"
    },
    {
      "x": -30,
      "y": 70,
      "z": 9,
      "name": "Rock_Ice_Permafrost"
    },
    {
      "x": -30,
      "y": 71,
      "z": 9,
      "name": "Rock_Ice_Permafrost"
    },
    {
      "x": -30,
      "y": 72,
      "z": 9,
      "name": "Rock_Ice"
    },
    {
      "x": -30,
      "y": 73,
      "z": 9,
      "name": "Rock_Ice"
    },
    {
      "x": -30,
      "y": 74,
      "z": 9,
      "name": "Rock_Ice"
    },
    {
      "x": -30,
      "y": 75,
      "z": 9,
      "name": "Rock_Ice"
    },
    {
      "x": -30,
      "y": 76,
      "z": 9,
      "name": "Rock_Ice"
    },
    {
      "x": -30,
      "y": 77,
      "z": 9,
      "name": "Rock_Ice"
    },
    {
      "x": -30,
      "y": 78,
      "z": 9,
      "name": "Rock_Ice"
    },
    {
      "x": -30,
      "y": 79,
      "z": 9,
      "name": "Rock_Ice"
    },
    {
      "x": -30,
      "y": 80,
      "z": 9,
      "name": "Rock_Ice"
    },
    {
      "x": -30,
      "y": 81,
      "z": 9,
      "name": "Rock_Ice"
    },
    {
      "x": -30,
      "y": 82,
      "z": 9,
      "name": "Rock_Ice"
    },
    {
      "x": -30,
      "y": 83,
      "z": 9,
      "name": "Rock_Ice"
    },
    {
      "x": -30,
      "y": 84,
      "z": 9,
      "name": "Rock_Ice"
    },
    {
      "x": -30,
      "y": 85,
      "z": 9,
      "name": "Rock_Ice"
    },
    {
      "x": -30,
      "y": 86,
      "z": 9,
      "name": "Soil_Snow"
    },
    {
      "x": -30,
      "y": 56,
      "z": 10,
      "name": "Rock_Ice"
    },
    {
      "x": -30,
      "y": 57,
      "z": 10,
      "name": "Rock_Ice"
    },
    {
      "x": -30,
      "y": 58,
      "z": 10,
      "name": "Rock_Ice"
    },
    {
      "x": -30,
      "y": 59,
      "z": 10,
      "name": "Rock_Ice"
    },
    {
      "x": -30,
      "y": 60,
      "z": 10,
      "name": "Rock_Ice"
    },
    {
      "x": -30,
      "y": 61,
      "z": 10,
      "name": "Rock_Ice"
    },
    {
      "x": -30,
      "y": 62,
      "z": 10,
      "name": "Rock_Ice"
    },
    {
      "x": -30,
      "y": 63,
      "z": 10,
      "name": "Rock_Ice"
    },
    {
      "x": -30,
      "y": 64,
      "z": 10,
      "name": "Rock_Ice"
    },
    {
      "x": -30,
      "y": 65,
      "z": 10,
      "name": "Rock_Ice"
    },
    {
      "x": -30,
      "y": 66,
      "z": 10,
      "name": "Rock_Ice"
    },
    {
      "x": -30,
      "y": 67,
      "z": 10,
      "name": "Rock_Ice"
    },
    {
      "x": -30,
      "y": 68,
      "z": 10,
      "name": "Rock_Ice"
    },
    {
      "x": -30,
      "y": 69,
      "z": 10,
      "name": "Rock_Ice_Permafrost"
    },
    {
      "x": -30,
      "y": 70,
      "z": 10,
      "name": "Rock_Ice_Permafrost"
    },
    {
      "x": -30,
      "y": 71,
      "z": 10,
      "name": "Rock_Ice_Permafrost"
    },
    {
      "x": -30,
      "y": 72,
      "z": 10,
      "name": "Rock_Ice"
    },
    {
      "x": -30,
      "y": 73,
      "z": 10,
      "name": "Rock_Ice"
    },
    {
      "x": -30,
      "y": 74,
      "z": 10,
      "name": "Rock_Ice"
    },
    {
      "x": -30,
      "y": 75,
      "z": 10,
      "name": "Rock_Ice"
    },
    {
      "x": -30,
      "y": 76,
      "z": 10,
      "name": "Rock_Ice"
    },
    {
      "x": -30,
      "y": 77,
      "z": 10,
      "name": "Rock_Ice"
    },
    {
      "x": -30,
      "y": 78,
      "z": 10,
      "name": "Rock_Ice"
    },
    {
      "x": -30,
      "y": 79,
      "z": 10,
      "name": "Rock_Ice"
    },
    {
      "x": -30,
      "y": 80,
      "z": 10,
      "name": "Rock_Ice"
    },
    {
      "x": -30,
      "y": 81,
      "z": 10,
      "name": "Rock_Ice"
    },
    {
      "x": -30,
      "y": 82,
      "z": 10,
      "name": "Rock_Ice"
    },
    {
      "x": -30,
      "y": 83,
      "z": 10,
      "name": "Rock_Ice"
    },
    {
      "x": -30,
      "y": 84,
      "z": 10,
      "name": "Rock_Ice"
    },
    {
      "x": -30,
      "y": 85,
      "z": 10,
      "name": "Rock_Ice"
    },
    {
      "x": -30,
      "y": 86,
      "z": 10,
      "name": "Rock_Ice"
    },
    {
      "x": -30,
      "y": 87,
      "z": 10,
      "name": "Soil_Snow"
    },
    {
      "x": -30,
      "y": 55,
      "z": 11,
      "name": "Rock_Ice_Permafrost"
    },
    {
      "x": -30,
      "y": 56,
      "z": 11,
      "name": "Rock_Ice"
    },
    {
      "x": -30,
      "y": 57,
      "z": 11,
      "name": "Rock_Ice"
    },
    {
      "x": -30,
      "y": 58,
      "z": 11,
      "name": "Rock_Ice"
    },
    {
      "x": -30,
      "y": 59,
      "z": 11,
      "name": "Rock_Ice"
    },
    {
      "x": -30,
      "y": 60,
      "z": 11,
      "name": "Rock_Ice"
    },
    {
      "x": -30,
      "y": 61,
      "z": 11,
      "name": "Rock_Ice"
    },
    {
      "x": -30,
      "y": 62,
      "z": 11,
      "name": "Rock_Ice"
    },
    {
      "x": -30,
      "y": 63,
      "z": 11,
      "name": "Rock_Ice"
    },
    {
      "x": -30,
      "y": 64,
      "z": 11,
      "name": "Rock_Ice"
    },
    {
      "x": -30,
      "y": 65,
      "z": 11,
      "name": "Rock_Ice"
    },
    {
      "x": -30,
      "y": 66,
      "z": 11,
      "name": "Rock_Ice"
    },
    {
      "x": -30,
      "y": 67,
      "z": 11,
      "name": "Rock_Ice"
    },
    {
      "x": -30,
      "y": 68,
      "z": 11,
      "name": "Rock_Ice"
    },
    {
      "x": -30,
      "y": 69,
      "z": 11,
      "name": "Rock_Ice_Permafrost"
    },
    {
      "x": -30,
      "y": 70,
      "z": 11,
      "name": "Rock_Ice_Permafrost"
    },
    {
      "x": -30,
      "y": 71,
      "z": 11,
      "name": "Rock_Ice_Permafrost"
    },
    {
      "x": -30,
      "y": 72,
      "z": 11,
      "name": "Rock_Ice"
    },
    {
      "x": -30,
      "y": 73,
      "z": 11,
      "name": "Rock_Ice"
    },
    {
      "x": -30,
      "y": 74,
      "z": 11,
      "name": "Rock_Ice"
    },
    {
      "x": -30,
      "y": 75,
      "z": 11,
      "name": "Rock_Ice"
    },
    {
      "x": -30,
      "y": 76,
      "z": 11,
      "name": "Rock_Ice"
    },
    {
      "x": -30,
      "y": 77,
      "z": 11,
      "name": "Rock_Ice"
    },
    {
      "x": -30,
      "y": 78,
      "z": 11,
      "name": "Rock_Ice"
    },
    {
      "x": -30,
      "y": 79,
      "z": 11,
      "name": "Rock_Ice"
    },
    {
      "x": -30,
      "y": 80,
      "z": 11,
      "name": "Rock_Ice"
    },
    {
      "x": -30,
      "y": 81,
      "z": 11,
      "name": "Rock_Ice"
    },
    {
      "x": -30,
      "y": 82,
      "z": 11,
      "name": "Rock_Ice"
    },
    {
      "x": -30,
      "y": 83,
      "z": 11,
      "name": "Rock_Ice"
    },
    {
      "x": -30,
      "y": 84,
      "z": 11,
      "name": "Rock_Ice"
    },
    {
      "x": -30,
      "y": 85,
      "z": 11,
      "name": "Rock_Ice"
    },
    {
      "x": -30,
      "y": 86,
      "z": 11,
      "name": "Rock_Ice"
    },
    {
      "x": -30,
      "y": 87,
      "z": 11,
      "name": "Soil_Snow"
    },
    {
      "x": -30,
      "y": 54,
      "z": 12,
      "name": "Rock_Ice_Permafrost"
    },
    {
      "x": -30,
      "y": 55,
      "z": 12,
      "name": "Rock_Ice_Permafrost"
    },
    {
      "x": -30,
      "y": 56,
      "z": 12,
      "name": "Rock_Ice_Permafrost"
    },
    {
      "x": -30,
      "y": 57,
      "z": 12,
      "name": "Rock_Ice"
    },
    {
      "x": -30,
      "y": 58,
      "z": 12,
      "name": "Rock_Ice"
    },
    {
      "x": -30,
      "y": 59,
      "z": 12,
      "name": "Rock_Ice"
    },
    {
      "x": -30,
      "y": 60,
      "z": 12,
      "name": "Rock_Ice"
    },
    {
      "x": -30,
      "y": 61,
      "z": 12,
      "name": "Rock_Ice"
    },
    {
      "x": -30,
      "y": 62,
      "z": 12,
      "name": "Rock_Ice"
    },
    {
      "x": -30,
      "y": 63,
      "z": 12,
      "name": "Rock_Ice"
    },
    {
      "x": -30,
      "y": 64,
      "z": 12,
      "name": "Rock_Ice"
    },
    {
      "x": -30,
      "y": 65,
      "z": 12,
      "name": "Rock_Ice"
    },
    {
      "x": -30,
      "y": 66,
      "z": 12,
      "name": "Rock_Ice"
    },
    {
      "x": -30,
      "y": 67,
      "z": 12,
      "name": "Rock_Ice"
    },
    {
      "x": -30,
      "y": 68,
      "z": 12,
      "name": "Rock_Ice"
    },
    {
      "x": -30,
      "y": 69,
      "z": 12,
      "name": "Rock_Ice_Permafrost"
    },
    {
      "x": -30,
      "y": 70,
      "z": 12,
      "name": "Rock_Ice_Permafrost"
    },
    {
      "x": -30,
      "y": 71,
      "z": 12,
      "name": "Rock_Ice_Permafrost"
    },
    {
      "x": -30,
      "y": 72,
      "z": 12,
      "name": "Rock_Ice"
    },
    {
      "x": -30,
      "y": 73,
      "z": 12,
      "name": "Rock_Ice"
    },
    {
      "x": -30,
      "y": 74,
      "z": 12,
      "name": "Rock_Ice"
    },
    {
      "x": -30,
      "y": 75,
      "z": 12,
      "name": "Rock_Ice"
    },
    {
      "x": -30,
      "y": 76,
      "z": 12,
      "name": "Rock_Ice"
    },
    {
      "x": -30,
      "y": 77,
      "z": 12,
      "name": "Rock_Ice"
    },
    {
      "x": -30,
      "y": 78,
      "z": 12,
      "name": "Rock_Ice"
    },
    {
      "x": -30,
      "y": 79,
      "z": 12,
      "name": "Rock_Ice"
    },
    {
      "x": -30,
      "y": 80,
      "z": 12,
      "name": "Rock_Ice"
    },
    {
      "x": -30,
      "y": 81,
      "z": 12,
      "name": "Rock_Ice"
    },
    {
      "x": -30,
      "y": 82,
      "z": 12,
      "name": "Rock_Ice"
    },
    {
      "x": -30,
      "y": 83,
      "z": 12,
      "name": "Rock_Ice"
    },
    {
      "x": -30,
      "y": 84,
      "z": 12,
      "name": "Rock_Ice"
    },
    {
      "x": -30,
      "y": 85,
      "z": 12,
      "name": "Rock_Ice"
    },
    {
      "x": -30,
      "y": 86,
      "z": 12,
      "name": "Soil_Snow"
    },
    {
      "x": -30,
      "y": 53,
      "z": 13,
      "name": "Rock_Ice"
    },
    {
      "x": -30,
      "y": 54,
      "z": 13,
      "name": "Rock_Ice_Permafrost"
    },
    {
      "x": -30,
      "y": 55,
      "z": 13,
      "name": "Rock_Ice_Permafrost"
    },
    {
      "x": -30,
      "y": 56,
      "z": 13,
      "name": "Rock_Ice_Permafrost"
    },
    {
      "x": -30,
      "y": 57,
      "z": 13,
      "name": "Rock_Ice_Permafrost"
    },
    {
      "x": -30,
      "y": 58,
      "z": 13,
      "name": "Rock_Ice"
    },
    {
      "x": -30,
      "y": 59,
      "z": 13,
      "name": "Rock_Ice"
    },
    {
      "x": -30,
      "y": 60,
      "z": 13,
      "name": "Rock_Ice"
    },
    {
      "x": -30,
      "y": 61,
      "z": 13,
      "name": "Rock_Ice"
    },
    {
      "x": -30,
      "y": 70,
      "z": 13,
      "name": "Rock_Ice_Permafrost"
    },
    {
      "x": -30,
      "y": 71,
      "z": 13,
      "name": "Rock_Ice"
    },
    {
      "x": -30,
      "y": 72,
      "z": 13,
      "name": "Rock_Ice"
    },
    {
      "x": -30,
      "y": 73,
      "z": 13,
      "name": "Rock_Ice"
    },
    {
      "x": -30,
      "y": 74,
      "z": 13,
      "name": "Rock_Ice"
    },
    {
      "x": -30,
      "y": 75,
      "z": 13,
      "name": "Rock_Ice"
    },
    {
      "x": -30,
      "y": 76,
      "z": 13,
      "name": "Rock_Ice"
    },
    {
      "x": -30,
      "y": 77,
      "z": 13,
      "name": "Rock_Ice"
    },
    {
      "x": -30,
      "y": 78,
      "z": 13,
      "name": "Rock_Ice"
    },
    {
      "x": -30,
      "y": 79,
      "z": 13,
      "name": "Rock_Ice"
    },
    {
      "x": -30,
      "y": 80,
      "z": 13,
      "name": "Rock_Ice"
    },
    {
      "x": -30,
      "y": 81,
      "z": 13,
      "name": "Rock_Ice"
    },
    {
      "x": -30,
      "y": 82,
      "z": 13,
      "name": "Rock_Ice"
    },
    {
      "x": -30,
      "y": 83,
      "z": 13,
      "name": "Rock_Ice"
    },
    {
      "x": -30,
      "y": 84,
      "z": 13,
      "name": "Rock_Ice"
    },
    {
      "x": -30,
      "y": 85,
      "z": 13,
      "name": "Rock_Ice"
    },
    {
      "x": -30,
      "y": 86,
      "z": 13,
      "name": "Soil_Snow"
    },
    {
      "x": -30,
      "y": 50,
      "z": 14,
      "name": "Rock_Ice"
    },
    {
      "x": -30,
      "y": 51,
      "z": 14,
      "name": "Rock_Ice"
    },
    {
      "x": -30,
      "y": 52,
      "z": 14,
      "name": "Rock_Ice"
    },
    {
      "x": -30,
      "y": 53,
      "z": 14,
      "name": "Rock_Ice"
    },
    {
      "x": -30,
      "y": 54,
      "z": 14,
      "name": "Rock_Ice"
    },
    {
      "x": -30,
      "y": 55,
      "z": 14,
      "name": "Rock_Ice_Permafrost"
    },
    {
      "x": -30,
      "y": 56,
      "z": 14,
      "name": "Rock_Ice_Permafrost"
    },
    {
      "x": -30,
      "y": 57,
      "z": 14,
      "name": "Rock_Ice_Permafrost"
    },
    {
      "x": -30,
      "y": 58,
      "z": 14,
      "name": "Rock_Ice"
    },
    {
      "x": -30,
      "y": 59,
      "z": 14,
      "name": "Rock_Ice"
    },
    {
      "x": -30,
      "y": 75,
      "z": 14,
      "name": "Rock_Ice"
    },
    {
      "x": -30,
      "y": 76,
      "z": 14,
      "name": "Rock_Ice"
    },
    {
      "x": -30,
      "y": 77,
      "z": 14,
      "name": "Rock_Ice"
    },
    {
      "x": -30,
      "y": 78,
      "z": 14,
      "name": "Rock_Ice"
    },
    {
      "x": -30,
      "y": 79,
      "z": 14,
      "name": "Rock_Ice"
    },
    {
      "x": -30,
      "y": 80,
      "z": 14,
      "name": "Rock_Ice"
    },
    {
      "x": -30,
      "y": 81,
      "z": 14,
      "name": "Rock_Ice"
    },
    {
      "x": -30,
      "y": 82,
      "z": 14,
      "name": "Rock_Ice"
    },
    {
      "x": -30,
      "y": 83,
      "z": 14,
      "name": "Rock_Ice"
    },
    {
      "x": -30,
      "y": 84,
      "z": 14,
      "name": "Rock_Ice"
    },
    {
      "x": -30,
      "y": 85,
      "z": 14,
      "name": "Soil_Snow"
    },
    {
      "x": -30,
      "y": 48,
      "z": 15,
      "name": "Rock_Ice"
    },
    {
      "x": -30,
      "y": 49,
      "z": 15,
      "name": "Rock_Ice"
    },
    {
      "x": -30,
      "y": 50,
      "z": 15,
      "name": "Rock_Ice"
    },
    {
      "x": -30,
      "y": 51,
      "z": 15,
      "name": "Rock_Ice"
    },
    {
      "x": -30,
      "y": 52,
      "z": 15,
      "name": "Rock_Ice"
    },
    {
      "x": -30,
      "y": 53,
      "z": 15,
      "name": "Rock_Ice"
    },
    {
      "x": -30,
      "y": 54,
      "z": 15,
      "name": "Rock_Ice"
    },
    {
      "x": -30,
      "y": 55,
      "z": 15,
      "name": "Rock_Ice"
    },
    {
      "x": -30,
      "y": 56,
      "z": 15,
      "name": "Rock_Ice_Permafrost"
    },
    {
      "x": -30,
      "y": 57,
      "z": 15,
      "name": "Rock_Ice"
    },
    {
      "x": -30,
      "y": 58,
      "z": 15,
      "name": "Soil_Snow"
    },
    {
      "x": -30,
      "y": 48,
      "z": 16,
      "name": "Rock_Ice"
    },
    {
      "x": -30,
      "y": 49,
      "z": 16,
      "name": "Rock_Ice"
    },
    {
      "x": -30,
      "y": 50,
      "z": 16,
      "name": "Rock_Ice"
    },
    {
      "x": -30,
      "y": 51,
      "z": 16,
      "name": "Rock_Ice"
    },
    {
      "x": -30,
      "y": 52,
      "z": 16,
      "name": "Rock_Ice"
    },
    {
      "x": -30,
      "y": 53,
      "z": 16,
      "name": "Rock_Ice"
    },
    {
      "x": -30,
      "y": 54,
      "z": 16,
      "name": "Rock_Ice"
    },
    {
      "x": -30,
      "y": 55,
      "z": 16,
      "name": "Rock_Ice"
    },
    {
      "x": -30,
      "y": 56,
      "z": 16,
      "name": "Rock_Ice"
    },
    {
      "x": -30,
      "y": 57,
      "z": 16,
      "name": "Soil_Snow"
    },
    {
      "x": -29,
      "y": 37,
      "z": -18,
      "name": "Rock_Ice"
    },
    {
      "x": -29,
      "y": 38,
      "z": -18,
      "name": "Rock_Ice_Permafrost"
    },
    {
      "x": -29,
      "y": 39,
      "z": -18,
      "name": "Rock_Ice"
    },
    {
      "x": -29,
      "y": 40,
      "z": -18,
      "name": "Rock_Ice_Permafrost"
    },
    {
      "x": -29,
      "y": 41,
      "z": -18,
      "name": "Rock_Ice_Permafrost"
    },
    {
      "x": -29,
      "y": 42,
      "z": -18,
      "name": "Rock_Ice_Permafrost"
    },
    {
      "x": -29,
      "y": 43,
      "z": -18,
      "name": "Rock_Ice_Permafrost"
    },
    {
      "x": -29,
      "y": 44,
      "z": -18,
      "name": "Rock_Ice_Permafrost"
    },
    {
      "x": -29,
      "y": 34,
      "z": -17,
      "name": "Rock_Ice_Permafrost"
    },
    {
      "x": -29,
      "y": 35,
      "z": -17,
      "name": "Rock_Ice_Permafrost"
    },
    {
      "x": -29,
      "y": 36,
      "z": -17,
      "name": "Rock_Ice_Permafrost"
    },
    {
      "x": -29,
      "y": 37,
      "z": -17,
      "name": "Rock_Ice_Permafrost"
    },
    {
      "x": -29,
      "y": 38,
      "z": -17,
      "name": "Rock_Ice_Permafrost"
    },
    {
      "x": -29,
      "y": 39,
      "z": -17,
      "name": "Rock_Ice_Permafrost"
    },
    {
      "x": -29,
      "y": 40,
      "z": -17,
      "name": "Rock_Ice_Permafrost"
    },
    {
      "x": -29,
      "y": 41,
      "z": -17,
      "name": "Rock_Ice_Permafrost"
    },
    {
      "x": -29,
      "y": 42,
      "z": -17,
      "name": "Rock_Ice_Permafrost"
    },
    {
      "x": -29,
      "y": 43,
      "z": -17,
      "name": "Rock_Ice_Permafrost"
    },
    {
      "x": -29,
      "y": 44,
      "z": -17,
      "name": "Rock_Ice_Permafrost"
    },
    {
      "x": -29,
      "y": 45,
      "z": -17,
      "name": "Rock_Ice_Permafrost"
    },
    {
      "x": -29,
      "y": 46,
      "z": -17,
      "name": "Soil_Snow"
    },
    {
      "x": -29,
      "y": 31,
      "z": -16,
      "name": "Rock_Ice"
    },
    {
      "x": -29,
      "y": 32,
      "z": -16,
      "name": "Rock_Ice_Permafrost"
    },
    {
      "x": -29,
      "y": 33,
      "z": -16,
      "name": "Rock_Ice_Permafrost"
    },
    {
      "x": -29,
      "y": 34,
      "z": -16,
      "name": "Rock_Ice_Permafrost"
    },
    {
      "x": -29,
      "y": 35,
      "z": -16,
      "name": "Rock_Ice_Permafrost"
    },
    {
      "x": -29,
      "y": 36,
      "z": -16,
      "name": "Rock_Ice_Permafrost"
    },
    {
      "x": -29,
      "y": 37,
      "z": -16,
      "name": "Rock_Ice_Permafrost"
    },
    {
      "x": -29,
      "y": 38,
      "z": -16,
      "name": "Rock_Ice_Permafrost"
    },
    {
      "x": -29,
      "y": 39,
      "z": -16,
      "name": "Rock_Ice_Permafrost"
    },
    {
      "x": -29,
      "y": 40,
      "z": -16,
      "name": "Rock_Ice_Permafrost"
    },
    {
      "x": -29,
      "y": 41,
      "z": -16,
      "name": "Rock_Ice_Permafrost"
    },
    {
      "x": -29,
      "y": 42,
      "z": -16,
      "name": "Rock_Ice_Permafrost"
    },
    {
      "x": -29,
      "y": 43,
      "z": -16,
      "name": "Rock_Ice_Permafrost"
    },
    {
      "x": -29,
      "y": 44,
      "z": -16,
      "name": "Rock_Ice_Permafrost"
    },
    {
      "x": -29,
      "y": 45,
      "z": -16,
      "name": "Soil_Snow"
    },
    {
      "x": -29,
      "y": 30,
      "z": -15,
      "name": "Rock_Ice_Permafrost"
    },
    {
      "x": -29,
      "y": 31,
      "z": -15,
      "name": "Rock_Ice_Permafrost"
    },
    {
      "x": -29,
      "y": 32,
      "z": -15,
      "name": "Rock_Ice_Permafrost"
    },
    {
      "x": -29,
      "y": 33,
      "z": -15,
      "name": "Rock_Ice_Permafrost"
    },
    {
      "x": -29,
      "y": 34,
      "z": -15,
      "name": "Rock_Ice_Permafrost"
    },
    {
      "x": -29,
      "y": 35,
      "z": -15,
      "name": "Rock_Ice_Permafrost"
    },
    {
      "x": -29,
      "y": 36,
      "z": -15,
      "name": "Rock_Ice_Permafrost"
    },
    {
      "x": -29,
      "y": 37,
      "z": -15,
      "name": "Rock_Ice_Permafrost"
    },
    {
      "x": -29,
      "y": 38,
      "z": -15,
      "name": "Rock_Ice_Permafrost"
    },
    {
      "x": -29,
      "y": 39,
      "z": -15,
      "name": "Rock_Ice_Permafrost"
    },
    {
      "x": -29,
      "y": 40,
      "z": -15,
      "name": "Rock_Ice_Permafrost"
    },
    {
      "x": -29,
      "y": 41,
      "z": -15,
      "name": "Rock_Ice_Permafrost"
    },
    {
      "x": -29,
      "y": 42,
      "z": -15,
      "name": "Rock_Ice_Permafrost"
    },
    {
      "x": -29,
      "y": 43,
      "z": -15,
      "name": "Rock_Ice_Permafrost"
    },
    {
      "x": -29,
      "y": 44,
      "z": -15,
      "name": "Soil_Snow"
    },
    {
      "x": -29,
      "y": 32,
      "z": -14,
      "name": "Rock_Ice_Permafrost"
    },
    {
      "x": -29,
      "y": 33,
      "z": -14,
      "name": "Rock_Ice_Permafrost"
    },
    {
      "x": -29,
      "y": 34,
      "z": -14,
      "name": "Rock_Ice_Permafrost"
    },
    {
      "x": -29,
      "y": 35,
      "z": -14,
      "name": "Rock_Ice_Permafrost"
    },
    {
      "x": -29,
      "y": 36,
      "z": -14,
      "name": "Rock_Ice_Permafrost"
    },
    {
      "x": -29,
      "y": 37,
      "z": -14,
      "name": "Rock_Ice_Permafrost"
    },
    {
      "x": -29,
      "y": 38,
      "z": -14,
      "name": "Rock_Ice_Permafrost"
    },
    {
      "x": -29,
      "y": 39,
      "z": -14,
      "name": "Rock_Ice_Permafrost"
    },
    {
      "x": -29,
      "y": 40,
      "z": -14,
      "name": "Rock_Ice_Permafrost"
    },
    {
      "x": -29,
      "y": 41,
      "z": -14,
      "name": "Rock_Ice_Permafrost"
    },
    {
      "x": -29,
      "y": 42,
      "z": -14,
      "name": "Rock_Ice_Permafrost"
    },
    {
      "x": -29,
      "y": 43,
      "z": -14,
      "name": "Rock_Ice_Permafrost"
    },
    {
      "x": -29,
      "y": 36,
      "z": -13,
      "name": "Rock_Ice_Permafrost"
    },
    {
      "x": -29,
      "y": 37,
      "z": -13,
      "name": "Rock_Ice_Permafrost"
    },
    {
      "x": -29,
      "y": 38,
      "z": -13,
      "name": "Rock_Ice_Permafrost"
    },
    {
      "x": -29,
      "y": 39,
      "z": -13,
      "name": "Rock_Ice_Permafrost"
    },
    {
      "x": -29,
      "y": 80,
      "z": 1,
      "name": "Rock_Ice"
    },
    {
      "x": -29,
      "y": 81,
      "z": 1,
      "name": "Rock_Ice"
    },
    {
      "x": -29,
      "y": 82,
      "z": 1,
      "name": "Rock_Ice"
    },
    {
      "x": -29,
      "y": 83,
      "z": 1,
      "name": "Rock_Ice"
    },
    {
      "x": -29,
      "y": 84,
      "z": 1,
      "name": "Soil_Snow"
    },
    {
      "x": -29,
      "y": 76,
      "z": 2,
      "name": "Rock_Ice"
    },
    {
      "x": -29,
      "y": 77,
      "z": 2,
      "name": "Rock_Ice"
    },
    {
      "x": -29,
      "y": 78,
      "z": 2,
      "name": "Rock_Ice"
    },
    {
      "x": -29,
      "y": 79,
      "z": 2,
      "name": "Rock_Ice"
    },
    {
      "x": -29,
      "y": 80,
      "z": 2,
      "name": "Rock_Ice"
    },
    {
      "x": -29,
      "y": 81,
      "z": 2,
      "name": "Rock_Ice"
    },
    {
      "x": -29,
      "y": 82,
      "z": 2,
      "name": "Rock_Ice"
    },
    {
      "x": -29,
      "y": 83,
      "z": 2,
      "name": "Rock_Ice"
    },
    {
      "x": -29,
      "y": 84,
      "z": 2,
      "name": "Rock_Ice"
    },
    {
      "x": -29,
      "y": 85,
      "z": 2,
      "name": "Soil_Snow"
    },
    {
      "x": -29,
      "y": 72,
      "z": 3,
      "name": "Rock_Ice_Permafrost"
    },
    {
      "x": -29,
      "y": 73,
      "z": 3,
      "name": "Rock_Ice_Permafrost"
    },
    {
      "x": -29,
      "y": 74,
      "z": 3,
      "name": "Rock_Ice_Permafrost"
    },
    {
      "x": -29,
      "y": 75,
      "z": 3,
      "name": "Rock_Ice"
    },
    {
      "x": -29,
      "y": 76,
      "z": 3,
      "name": "Rock_Ice"
    },
    {
      "x": -29,
      "y": 77,
      "z": 3,
      "name": "Rock_Ice"
    },
    {
      "x": -29,
      "y": 78,
      "z": 3,
      "name": "Rock_Ice"
    },
    {
      "x": -29,
      "y": 79,
      "z": 3,
      "name": "Rock_Ice"
    },
    {
      "x": -29,
      "y": 80,
      "z": 3,
      "name": "Rock_Ice"
    },
    {
      "x": -29,
      "y": 81,
      "z": 3,
      "name": "Rock_Ice"
    },
    {
      "x": -29,
      "y": 82,
      "z": 3,
      "name": "Rock_Ice"
    },
    {
      "x": -29,
      "y": 83,
      "z": 3,
      "name": "Rock_Ice"
    },
    {
      "x": -29,
      "y": 84,
      "z": 3,
      "name": "Rock_Ice"
    },
    {
      "x": -29,
      "y": 85,
      "z": 3,
      "name": "Rock_Ice"
    },
    {
      "x": -29,
      "y": 86,
      "z": 3,
      "name": "Soil_Snow"
    },
    {
      "x": -29,
      "y": 49,
      "z": 4,
      "name": "Rock_Ice"
    },
    {
      "x": -29,
      "y": 50,
      "z": 4,
      "name": "Rock_Ice"
    },
    {
      "x": -29,
      "y": 51,
      "z": 4,
      "name": "Rock_Ice"
    },
    {
      "x": -29,
      "y": 52,
      "z": 4,
      "name": "Rock_Ice"
    },
    {
      "x": -29,
      "y": 53,
      "z": 4,
      "name": "Rock_Ice"
    },
    {
      "x": -29,
      "y": 54,
      "z": 4,
      "name": "Rock_Ice"
    },
    {
      "x": -29,
      "y": 55,
      "z": 4,
      "name": "Rock_Ice"
    },
    {
      "x": -29,
      "y": 69,
      "z": 4,
      "name": "Rock_Ice"
    },
    {
      "x": -29,
      "y": 70,
      "z": 4,
      "name": "Rock_Ice"
    },
    {
      "x": -29,
      "y": 71,
      "z": 4,
      "name": "Rock_Ice_Permafrost"
    },
    {
      "x": -29,
      "y": 72,
      "z": 4,
      "name": "Rock_Ice_Permafrost"
    },
    {
      "x": -29,
      "y": 73,
      "z": 4,
      "name": "Rock_Ice_Permafrost"
    },
    {
      "x": -29,
      "y": 74,
      "z": 4,
      "name": "Rock_Ice_Permafrost"
    },
    {
      "x": -29,
      "y": 75,
      "z": 4,
      "name": "Rock_Ice"
    },
    {
      "x": -29,
      "y": 76,
      "z": 4,
      "name": "Rock_Ice"
    },
    {
      "x": -29,
      "y": 77,
      "z": 4,
      "name": "Rock_Ice"
    },
    {
      "x": -29,
      "y": 78,
      "z": 4,
      "name": "Rock_Ice"
    },
    {
      "x": -29,
      "y": 79,
      "z": 4,
      "name": "Rock_Ice"
    },
    {
      "x": -29,
      "y": 80,
      "z": 4,
      "name": "Rock_Ice"
    },
    {
      "x": -29,
      "y": 81,
      "z": 4,
      "name": "Rock_Ice"
    },
    {
      "x": -29,
      "y": 82,
      "z": 4,
      "name": "Rock_Ice"
    },
    {
      "x": -29,
      "y": 83,
      "z": 4,
      "name": "Rock_Ice"
    },
    {
      "x": -29,
      "y": 84,
      "z": 4,
      "name": "Rock_Ice"
    },
    {
      "x": -29,
      "y": 85,
      "z": 4,
      "name": "Rock_Ice"
    },
    {
      "x": -29,
      "y": 86,
      "z": 4,
      "name": "Soil_Snow"
    },
    {
      "x": -29,
      "y": 46,
      "z": 5,
      "name": "Rock_Ice_Permafrost"
    },
    {
      "x": -29,
      "y": 47,
      "z": 5,
      "name": "Rock_Ice_Permafrost"
    },
    {
      "x": -29,
      "y": 48,
      "z": 5,
      "name": "Rock_Ice_Permafrost"
    },
    {
      "x": -29,
      "y": 49,
      "z": 5,
      "name": "Rock_Ice"
    },
    {
      "x": -29,
      "y": 50,
      "z": 5,
      "name": "Rock_Ice"
    },
    {
      "x": -29,
      "y": 51,
      "z": 5,
      "name": "Rock_Ice"
    },
    {
      "x": -29,
      "y": 52,
      "z": 5,
      "name": "Rock_Ice"
    },
    {
      "x": -29,
      "y": 53,
      "z": 5,
      "name": "Rock_Ice"
    },
    {
      "x": -29,
      "y": 54,
      "z": 5,
      "name": "Rock_Ice"
    },
    {
      "x": -29,
      "y": 55,
      "z": 5,
      "name": "Rock_Ice"
    },
    {
      "x": -29,
      "y": 67,
      "z": 5,
      "name": "Rock_Ice"
    },
    {
      "x": -29,
      "y": 68,
      "z": 5,
      "name": "Rock_Ice"
    },
    {
      "x": -29,
      "y": 69,
      "z": 5,
      "name": "Rock_Ice"
    },
    {
      "x": -29,
      "y": 70,
      "z": 5,
      "name": "Rock_Ice"
    },
    {
      "x": -29,
      "y": 71,
      "z": 5,
      "name": "Rock_Ice_Permafrost"
    },
    {
      "x": -29,
      "y": 72,
      "z": 5,
      "name": "Rock_Ice_Permafrost"
    },
    {
      "x": -29,
      "y": 73,
      "z": 5,
      "name": "Rock_Ice_Permafrost"
    },
    {
      "x": -29,
      "y": 74,
      "z": 5,
      "name": "Rock_Ice"
    },
    {
      "x": -29,
      "y": 75,
      "z": 5,
      "name": "Rock_Ice"
    },
    {
      "x": -29,
      "y": 76,
      "z": 5,
      "name": "Rock_Ice"
    },
    {
      "x": -29,
      "y": 77,
      "z": 5,
      "name": "Rock_Ice"
    },
    {
      "x": -29,
      "y": 78,
      "z": 5,
      "name": "Rock_Ice"
    },
    {
      "x": -29,
      "y": 79,
      "z": 5,
      "name": "Rock_Ice"
    },
    {
      "x": -29,
      "y": 80,
      "z": 5,
      "name": "Rock_Ice"
    },
    {
      "x": -29,
      "y": 81,
      "z": 5,
      "name": "Rock_Ice"
    },
    {
      "x": -29,
      "y": 82,
      "z": 5,
      "name": "Rock_Ice"
    },
    {
      "x": -29,
      "y": 83,
      "z": 5,
      "name": "Rock_Ice"
    },
    {
      "x": -29,
      "y": 84,
      "z": 5,
      "name": "Rock_Ice"
    },
    {
      "x": -29,
      "y": 85,
      "z": 5,
      "name": "Rock_Ice"
    },
    {
      "x": -29,
      "y": 86,
      "z": 5,
      "name": "Rock_Ice"
    },
    {
      "x": -29,
      "y": 87,
      "z": 5,
      "name": "Soil_Snow"
    },
    {
      "x": -29,
      "y": 43,
      "z": 6,
      "name": "Rock_Ice"
    },
    {
      "x": -29,
      "y": 44,
      "z": 6,
      "name": "Rock_Ice"
    },
    {
      "x": -29,
      "y": 45,
      "z": 6,
      "name": "Rock_Ice"
    },
    {
      "x": -29,
      "y": 46,
      "z": 6,
      "name": "Rock_Ice_Permafrost"
    },
    {
      "x": -29,
      "y": 47,
      "z": 6,
      "name": "Rock_Ice_Permafrost"
    },
    {
      "x": -29,
      "y": 48,
      "z": 6,
      "name": "Rock_Ice_Permafrost"
    },
    {
      "x": -29,
      "y": 49,
      "z": 6,
      "name": "Rock_Ice_Permafrost"
    },
    {
      "x": -29,
      "y": 50,
      "z": 6,
      "name": "Rock_Ice_Permafrost"
    },
    {
      "x": -29,
      "y": 51,
      "z": 6,
      "name": "Rock_Ice"
    },
    {
      "x": -29,
      "y": 52,
      "z": 6,
      "name": "Rock_Ice"
    },
    {
      "x": -29,
      "y": 53,
      "z": 6,
      "name": "Rock_Ice"
    },
    {
      "x": -29,
      "y": 54,
      "z": 6,
      "name": "Rock_Ice"
    },
    {
      "x": -29,
      "y": 65,
      "z": 6,
      "name": "Rock_Ice"
    },
    {
      "x": -29,
      "y": 66,
      "z": 6,
      "name": "Rock_Ice"
    },
    {
      "x": -29,
      "y": 67,
      "z": 6,
      "name": "Rock_Ice"
    },
    {
      "x": -29,
      "y": 68,
      "z": 6,
      "name": "Rock_Ice"
    },
    {
      "x": -29,
      "y": 69,
      "z": 6,
      "name": "Rock_Ice"
    },
    {
      "x": -29,
      "y": 70,
      "z": 6,
      "name": "Rock_Ice_Permafrost"
    },
    {
      "x": -29,
      "y": 71,
      "z": 6,
      "name": "Rock_Ice_Permafrost"
    },
    {
      "x": -29,
      "y": 72,
      "z": 6,
      "name": "Rock_Ice_Permafrost"
    },
    {
      "x": -29,
      "y": 73,
      "z": 6,
      "name": "Rock_Ice"
    },
    {
      "x": -29,
      "y": 74,
      "z": 6,
      "name": "Rock_Ice"
    },
    {
      "x": -29,
      "y": 75,
      "z": 6,
      "name": "Rock_Ice"
    },
    {
      "x": -29,
      "y": 76,
      "z": 6,
      "name": "Rock_Ice"
    },
    {
      "x": -29,
      "y": 77,
      "z": 6,
      "name": "Rock_Ice"
    },
    {
      "x": -29,
      "y": 78,
      "z": 6,
      "name": "Rock_Ice"
    },
    {
      "x": -29,
      "y": 79,
      "z": 6,
      "name": "Rock_Ice"
    },
    {
      "x": -29,
      "y": 80,
      "z": 6,
      "name": "Rock_Ice"
    },
    {
      "x": -29,
      "y": 81,
      "z": 6,
      "name": "Rock_Ice"
    },
    {
      "x": -29,
      "y": 82,
      "z": 6,
      "name": "Rock_Ice"
    },
    {
      "x": -29,
      "y": 83,
      "z": 6,
      "name": "Rock_Ice"
    },
    {
      "x": -29,
      "y": 84,
      "z": 6,
      "name": "Rock_Ice"
    },
    {
      "x": -29,
      "y": 85,
      "z": 6,
      "name": "Rock_Ice"
    },
    {
      "x": -29,
      "y": 86,
      "z": 6,
      "name": "Rock_Ice"
    },
    {
      "x": -29,
      "y": 87,
      "z": 6,
      "name": "Soil_Snow"
    },
    {
      "x": -29,
      "y": 42,
      "z": 7,
      "name": "Rock_Ice"
    },
    {
      "x": -29,
      "y": 43,
      "z": 7,
      "name": "Rock_Ice"
    },
    {
      "x": -29,
      "y": 44,
      "z": 7,
      "name": "Rock_Ice"
    },
    {
      "x": -29,
      "y": 45,
      "z": 7,
      "name": "Rock_Ice"
    },
    {
      "x": -29,
      "y": 46,
      "z": 7,
      "name": "Rock_Ice"
    },
    {
      "x": -29,
      "y": 47,
      "z": 7,
      "name": "Rock_Ice_Permafrost"
    },
    {
      "x": -29,
      "y": 48,
      "z": 7,
      "name": "Rock_Ice_Permafrost"
    },
    {
      "x": -29,
      "y": 49,
      "z": 7,
      "name": "Rock_Ice_Permafrost"
    },
    {
      "x": -29,
      "y": 50,
      "z": 7,
      "name": "Rock_Ice_Permafrost"
    },
    {
      "x": -29,
      "y": 51,
      "z": 7,
      "name": "Rock_Ice"
    },
    {
      "x": -29,
      "y": 52,
      "z": 7,
      "name": "Rock_Ice"
    },
    {
      "x": -29,
      "y": 62,
      "z": 7,
      "name": "Rock_Ice"
    },
    {
      "x": -29,
      "y": 63,
      "z": 7,
      "name": "Rock_Ice"
    },
    {
      "x": -29,
      "y": 64,
      "z": 7,
      "name": "Rock_Ice"
    },
    {
      "x": -29,
      "y": 65,
      "z": 7,
      "name": "Rock_Ice"
    },
    {
      "x": -29,
      "y": 66,
      "z": 7,
      "name": "Rock_Ice"
    },
    {
      "x": -29,
      "y": 67,
      "z": 7,
      "name": "Rock_Ice"
    },
    {
      "x": -29,
      "y": 68,
      "z": 7,
      "name": "Rock_Ice"
    },
    {
      "x": -29,
      "y": 69,
      "z": 7,
      "name": "Rock_Ice"
    },
    {
      "x": -29,
      "y": 70,
      "z": 7,
      "name": "Rock_Ice_Permafrost"
    },
    {
      "x": -29,
      "y": 71,
      "z": 7,
      "name": "Rock_Ice_Permafrost"
    },
    {
      "x": -29,
      "y": 72,
      "z": 7,
      "name": "Rock_Ice"
    },
    {
      "x": -29,
      "y": 73,
      "z": 7,
      "name": "Rock_Ice"
    },
    {
      "x": -29,
      "y": 74,
      "z": 7,
      "name": "Rock_Ice"
    },
    {
      "x": -29,
      "y": 75,
      "z": 7,
      "name": "Rock_Ice"
    },
    {
      "x": -29,
      "y": 76,
      "z": 7,
      "name": "Rock_Ice"
    },
    {
      "x": -29,
      "y": 77,
      "z": 7,
      "name": "Rock_Ice"
    },
    {
      "x": -29,
      "y": 78,
      "z": 7,
      "name": "Rock_Ice"
    },
    {
      "x": -29,
      "y": 79,
      "z": 7,
      "name": "Rock_Ice"
    },
    {
      "x": -29,
      "y": 80,
      "z": 7,
      "name": "Rock_Ice"
    },
    {
      "x": -29,
      "y": 81,
      "z": 7,
      "name": "Rock_Ice"
    },
    {
      "x": -29,
      "y": 82,
      "z": 7,
      "name": "Rock_Ice"
    },
    {
      "x": -29,
      "y": 83,
      "z": 7,
      "name": "Rock_Ice"
    },
    {
      "x": -29,
      "y": 84,
      "z": 7,
      "name": "Rock_Ice"
    },
    {
      "x": -29,
      "y": 85,
      "z": 7,
      "name": "Rock_Ice"
    },
    {
      "x": -29,
      "y": 86,
      "z": 7,
      "name": "Rock_Ice"
    },
    {
      "x": -29,
      "y": 87,
      "z": 7,
      "name": "Rock_Ice"
    },
    {
      "x": -29,
      "y": 88,
      "z": 7,
      "name": "Soil_Snow"
    },
    {
      "x": -29,
      "y": 41,
      "z": 8,
      "name": "Rock_Ice"
    },
    {
      "x": -29,
      "y": 42,
      "z": 8,
      "name": "Rock_Ice"
    },
    {
      "x": -29,
      "y": 43,
      "z": 8,
      "name": "Rock_Ice"
    },
    {
      "x": -29,
      "y": 44,
      "z": 8,
      "name": "Rock_Ice"
    },
    {
      "x": -29,
      "y": 45,
      "z": 8,
      "name": "Rock_Ice"
    },
    {
      "x": -29,
      "y": 46,
      "z": 8,
      "name": "Rock_Ice"
    },
    {
      "x": -29,
      "y": 47,
      "z": 8,
      "name": "Rock_Ice"
    },
    {
      "x": -29,
      "y": 48,
      "z": 8,
      "name": "Rock_Ice"
    },
    {
      "x": -29,
      "y": 49,
      "z": 8,
      "name": "Rock_Ice_Permafrost"
    },
    {
      "x": -29,
      "y": 58,
      "z": 8,
      "name": "Rock_Ice"
    },
    {
      "x": -29,
      "y": 59,
      "z": 8,
      "name": "Rock_Ice"
    },
    {
      "x": -29,
      "y": 60,
      "z": 8,
      "name": "Rock_Ice"
    },
    {
      "x": -29,
      "y": 61,
      "z": 8,
      "name": "Rock_Ice"
    },
    {
      "x": -29,
      "y": 62,
      "z": 8,
      "name": "Rock_Ice"
    },
    {
      "x": -29,
      "y": 63,
      "z": 8,
      "name": "Rock_Ice"
    },
    {
      "x": -29,
      "y": 64,
      "z": 8,
      "name": "Rock_Ice"
    },
    {
      "x": -29,
      "y": 65,
      "z": 8,
      "name": "Rock_Ice"
    },
    {
      "x": -29,
      "y": 66,
      "z": 8,
      "name": "Rock_Ice"
    },
    {
      "x": -29,
      "y": 67,
      "z": 8,
      "name": "Rock_Ice"
    },
    {
      "x": -29,
      "y": 68,
      "z": 8,
      "name": "Rock_Ice"
    },
    {
      "x": -29,
      "y": 69,
      "z": 8,
      "name": "Rock_Ice_Permafrost"
    },
    {
      "x": -29,
      "y": 70,
      "z": 8,
      "name": "Rock_Ice_Permafrost"
    },
    {
      "x": -29,
      "y": 71,
      "z": 8,
      "name": "Rock_Ice_Permafrost"
    },
    {
      "x": -29,
      "y": 72,
      "z": 8,
      "name": "Rock_Ice"
    },
    {
      "x": -29,
      "y": 73,
      "z": 8,
      "name": "Rock_Ice"
    },
    {
      "x": -29,
      "y": 74,
      "z": 8,
      "name": "Rock_Ice"
    },
    {
      "x": -29,
      "y": 75,
      "z": 8,
      "name": "Rock_Ice"
    },
    {
      "x": -29,
      "y": 76,
      "z": 8,
      "name": "Rock_Ice"
    },
    {
      "x": -29,
      "y": 77,
      "z": 8,
      "name": "Rock_Ice"
    },
    {
      "x": -29,
      "y": 78,
      "z": 8,
      "name": "Rock_Ice"
    },
    {
      "x": -29,
      "y": 79,
      "z": 8,
      "name": "Rock_Ice"
    },
    {
      "x": -29,
      "y": 80,
      "z": 8,
      "name": "Rock_Ice"
    },
    {
      "x": -29,
      "y": 81,
      "z": 8,
      "name": "Rock_Ice"
    },
    {
      "x": -29,
      "y": 82,
      "z": 8,
      "name": "Rock_Ice"
    },
    {
      "x": -29,
      "y": 83,
      "z": 8,
      "name": "Rock_Ice"
    },
    {
      "x": -29,
      "y": 84,
      "z": 8,
      "name": "Rock_Ice"
    },
    {
      "x": -29,
      "y": 85,
      "z": 8,
      "name": "Rock_Ice"
    },
    {
      "x": -29,
      "y": 86,
      "z": 8,
      "name": "Rock_Ice"
    },
    {
      "x": -29,
      "y": 87,
      "z": 8,
      "name": "Rock_Ice"
    },
    {
      "x": -29,
      "y": 88,
      "z": 8,
      "name": "Soil_Snow"
    },
    {
      "x": -29,
      "y": 55,
      "z": 9,
      "name": "Rock_Ice"
    },
    {
      "x": -29,
      "y": 56,
      "z": 9,
      "name": "Rock_Ice"
    },
    {
      "x": -29,
      "y": 57,
      "z": 9,
      "name": "Rock_Ice"
    },
    {
      "x": -29,
      "y": 58,
      "z": 9,
      "name": "Rock_Ice"
    },
    {
      "x": -29,
      "y": 59,
      "z": 9,
      "name": "Rock_Ice"
    },
    {
      "x": -29,
      "y": 60,
      "z": 9,
      "name": "Rock_Ice"
    },
    {
      "x": -29,
      "y": 61,
      "z": 9,
      "name": "Rock_Ice"
    },
    {
      "x": -29,
      "y": 62,
      "z": 9,
      "name": "Rock_Ice"
    },
    {
      "x": -29,
      "y": 63,
      "z": 9,
      "name": "Rock_Ice"
    },
    {
      "x": -29,
      "y": 64,
      "z": 9,
      "name": "Rock_Ice"
    },
    {
      "x": -29,
      "y": 65,
      "z": 9,
      "name": "Rock_Ice"
    },
    {
      "x": -29,
      "y": 66,
      "z": 9,
      "name": "Rock_Ice"
    },
    {
      "x": -29,
      "y": 67,
      "z": 9,
      "name": "Rock_Ice"
    },
    {
      "x": -29,
      "y": 68,
      "z": 9,
      "name": "Rock_Ice"
    },
    {
      "x": -29,
      "y": 69,
      "z": 9,
      "name": "Rock_Ice_Permafrost"
    },
    {
      "x": -29,
      "y": 70,
      "z": 9,
      "name": "Rock_Ice_Permafrost"
    },
    {
      "x": -29,
      "y": 71,
      "z": 9,
      "name": "Rock_Ice"
    },
    {
      "x": -29,
      "y": 72,
      "z": 9,
      "name": "Rock_Ice"
    },
    {
      "x": -29,
      "y": 73,
      "z": 9,
      "name": "Rock_Ice"
    },
    {
      "x": -29,
      "y": 74,
      "z": 9,
      "name": "Rock_Ice"
    },
    {
      "x": -29,
      "y": 75,
      "z": 9,
      "name": "Rock_Ice"
    },
    {
      "x": -29,
      "y": 76,
      "z": 9,
      "name": "Rock_Ice"
    },
    {
      "x": -29,
      "y": 77,
      "z": 9,
      "name": "Rock_Ice"
    },
    {
      "x": -29,
      "y": 78,
      "z": 9,
      "name": "Rock_Ice"
    },
    {
      "x": -29,
      "y": 79,
      "z": 9,
      "name": "Rock_Ice"
    },
    {
      "x": -29,
      "y": 80,
      "z": 9,
      "name": "Rock_Ice"
    },
    {
      "x": -29,
      "y": 81,
      "z": 9,
      "name": "Rock_Ice"
    },
    {
      "x": -29,
      "y": 82,
      "z": 9,
      "name": "Rock_Ice"
    },
    {
      "x": -29,
      "y": 83,
      "z": 9,
      "name": "Rock_Ice"
    },
    {
      "x": -29,
      "y": 84,
      "z": 9,
      "name": "Rock_Ice"
    },
    {
      "x": -29,
      "y": 85,
      "z": 9,
      "name": "Rock_Ice"
    },
    {
      "x": -29,
      "y": 86,
      "z": 9,
      "name": "Rock_Ice"
    },
    {
      "x": -29,
      "y": 87,
      "z": 9,
      "name": "Rock_Ice"
    },
    {
      "x": -29,
      "y": 88,
      "z": 9,
      "name": "Rock_Ice"
    },
    {
      "x": -29,
      "y": 89,
      "z": 9,
      "name": "Soil_Snow"
    },
    {
      "x": -29,
      "y": 53,
      "z": 10,
      "name": "Rock_Ice"
    },
    {
      "x": -29,
      "y": 54,
      "z": 10,
      "name": "Rock_Ice"
    },
    {
      "x": -29,
      "y": 55,
      "z": 10,
      "name": "Rock_Ice"
    },
    {
      "x": -29,
      "y": 56,
      "z": 10,
      "name": "Rock_Ice"
    },
    {
      "x": -29,
      "y": 57,
      "z": 10,
      "name": "Rock_Ice"
    },
    {
      "x": -29,
      "y": 58,
      "z": 10,
      "name": "Rock_Ice"
    },
    {
      "x": -29,
      "y": 59,
      "z": 10,
      "name": "Rock_Ice"
    },
    {
      "x": -29,
      "y": 60,
      "z": 10,
      "name": "Rock_Ice"
    },
    {
      "x": -29,
      "y": 61,
      "z": 10,
      "name": "Rock_Ice"
    },
    {
      "x": -29,
      "y": 62,
      "z": 10,
      "name": "Rock_Ice"
    },
    {
      "x": -29,
      "y": 63,
      "z": 10,
      "name": "Rock_Ice"
    },
    {
      "x": -29,
      "y": 64,
      "z": 10,
      "name": "Rock_Ice"
    },
    {
      "x": -29,
      "y": 65,
      "z": 10,
      "name": "Rock_Ice"
    },
    {
      "x": -29,
      "y": 66,
      "z": 10,
      "name": "Rock_Ice"
    },
    {
      "x": -29,
      "y": 67,
      "z": 10,
      "name": "Rock_Ice"
    },
    {
      "x": -29,
      "y": 68,
      "z": 10,
      "name": "Rock_Ice"
    },
    {
      "x": -29,
      "y": 69,
      "z": 10,
      "name": "Rock_Ice_Permafrost"
    },
    {
      "x": -29,
      "y": 70,
      "z": 10,
      "name": "Rock_Ice_Permafrost"
    },
    {
      "x": -29,
      "y": 71,
      "z": 10,
      "name": "Rock_Ice"
    },
    {
      "x": -29,
      "y": 72,
      "z": 10,
      "name": "Rock_Ice"
    },
    {
      "x": -29,
      "y": 73,
      "z": 10,
      "name": "Rock_Ice"
    },
    {
      "x": -29,
      "y": 74,
      "z": 10,
      "name": "Rock_Ice"
    },
    {
      "x": -29,
      "y": 75,
      "z": 10,
      "name": "Rock_Ice"
    },
    {
      "x": -29,
      "y": 76,
      "z": 10,
      "name": "Rock_Ice"
    },
    {
      "x": -29,
      "y": 77,
      "z": 10,
      "name": "Rock_Ice"
    },
    {
      "x": -29,
      "y": 78,
      "z": 10,
      "name": "Rock_Ice"
    },
    {
      "x": -29,
      "y": 79,
      "z": 10,
      "name": "Rock_Ice"
    },
    {
      "x": -29,
      "y": 80,
      "z": 10,
      "name": "Rock_Ice"
    },
    {
      "x": -29,
      "y": 81,
      "z": 10,
      "name": "Rock_Ice"
    },
    {
      "x": -29,
      "y": 82,
      "z": 10,
      "name": "Rock_Ice"
    },
    {
      "x": -29,
      "y": 83,
      "z": 10,
      "name": "Rock_Ice"
    },
    {
      "x": -29,
      "y": 84,
      "z": 10,
      "name": "Rock_Ice"
    },
    {
      "x": -29,
      "y": 85,
      "z": 10,
      "name": "Rock_Ice"
    },
    {
      "x": -29,
      "y": 86,
      "z": 10,
      "name": "Rock_Ice"
    },
    {
      "x": -29,
      "y": 87,
      "z": 10,
      "name": "Rock_Ice"
    },
    {
      "x": -29,
      "y": 88,
      "z": 10,
      "name": "Rock_Ice"
    },
    {
      "x": -29,
      "y": 89,
      "z": 10,
      "name": "Soil_Snow"
    },
    {
      "x": -29,
      "y": 52,
      "z": 11,
      "name": "Rock_Ice_Permafrost"
    },
    {
      "x": -29,
      "y": 53,
      "z": 11,
      "name": "Rock_Ice"
    },
    {
      "x": -29,
      "y": 54,
      "z": 11,
      "name": "Rock_Ice"
    },
    {
      "x": -29,
      "y": 55,
      "z": 11,
      "name": "Rock_Ice"
    },
    {
      "x": -29,
      "y": 56,
      "z": 11,
      "name": "Rock_Ice"
    },
    {
      "x": -29,
      "y": 57,
      "z": 11,
      "name": "Rock_Ice"
    },
    {
      "x": -29,
      "y": 58,
      "z": 11,
      "name": "Rock_Ice"
    },
    {
      "x": -29,
      "y": 59,
      "z": 11,
      "name": "Rock_Ice"
    },
    {
      "x": -29,
      "y": 60,
      "z": 11,
      "name": "Rock_Ice"
    },
    {
      "x": -29,
      "y": 61,
      "z": 11,
      "name": "Rock_Ice"
    },
    {
      "x": -29,
      "y": 62,
      "z": 11,
      "name": "Rock_Ice"
    },
    {
      "x": -29,
      "y": 63,
      "z": 11,
      "name": "Rock_Ice"
    },
    {
      "x": -29,
      "y": 64,
      "z": 11,
      "name": "Rock_Ice"
    },
    {
      "x": -29,
      "y": 65,
      "z": 11,
      "name": "Rock_Ice"
    },
    {
      "x": -29,
      "y": 66,
      "z": 11,
      "name": "Rock_Ice"
    },
    {
      "x": -29,
      "y": 67,
      "z": 11,
      "name": "Rock_Ice"
    },
    {
      "x": -29,
      "y": 68,
      "z": 11,
      "name": "Rock_Ice_Permafrost"
    },
    {
      "x": -29,
      "y": 69,
      "z": 11,
      "name": "Rock_Ice_Permafrost"
    },
    {
      "x": -29,
      "y": 70,
      "z": 11,
      "name": "Rock_Ice_Permafrost"
    },
    {
      "x": -29,
      "y": 71,
      "z": 11,
      "name": "Rock_Ice"
    },
    {
      "x": -29,
      "y": 72,
      "z": 11,
      "name": "Rock_Ice"
    },
    {
      "x": -29,
      "y": 73,
      "z": 11,
      "name": "Rock_Ice"
    },
    {
      "x": -29,
      "y": 74,
      "z": 11,
      "name": "Rock_Ice"
    },
    {
      "x": -29,
      "y": 75,
      "z": 11,
      "name": "Rock_Ice"
    },
    {
      "x": -29,
      "y": 76,
      "z": 11,
      "name": "Rock_Ice"
    },
    {
      "x": -29,
      "y": 77,
      "z": 11,
      "name": "Rock_Ice"
    },
    {
      "x": -29,
      "y": 78,
      "z": 11,
      "name": "Rock_Ice"
    },
    {
      "x": -29,
      "y": 79,
      "z": 11,
      "name": "Rock_Ice"
    },
    {
      "x": -29,
      "y": 80,
      "z": 11,
      "name": "Rock_Ice"
    },
    {
      "x": -29,
      "y": 81,
      "z": 11,
      "name": "Rock_Ice"
    },
    {
      "x": -29,
      "y": 82,
      "z": 11,
      "name": "Rock_Ice"
    },
    {
      "x": -29,
      "y": 83,
      "z": 11,
      "name": "Rock_Ice"
    },
    {
      "x": -29,
      "y": 84,
      "z": 11,
      "name": "Rock_Ice"
    },
    {
      "x": -29,
      "y": 85,
      "z": 11,
      "name": "Rock_Ice"
    },
    {
      "x": -29,
      "y": 86,
      "z": 11,
      "name": "Rock_Ice"
    },
    {
      "x": -29,
      "y": 87,
      "z": 11,
      "name": "Rock_Ice"
    },
    {
      "x": -29,
      "y": 88,
      "z": 11,
      "name": "Rock_Ice"
    },
    {
      "x": -29,
      "y": 89,
      "z": 11,
      "name": "Soil_Snow"
    },
    {
      "x": -29,
      "y": 50,
      "z": 12,
      "name": "Rock_Ice"
    },
    {
      "x": -29,
      "y": 51,
      "z": 12,
      "name": "Rock_Ice_Permafrost"
    },
    {
      "x": -29,
      "y": 52,
      "z": 12,
      "name": "Rock_Ice_Permafrost"
    },
    {
      "x": -29,
      "y": 53,
      "z": 12,
      "name": "Rock_Ice_Permafrost"
    },
    {
      "x": -29,
      "y": 54,
      "z": 12,
      "name": "Rock_Ice"
    },
    {
      "x": -29,
      "y": 55,
      "z": 12,
      "name": "Rock_Ice"
    },
    {
      "x": -29,
      "y": 56,
      "z": 12,
      "name": "Rock_Ice"
    },
    {
      "x": -29,
      "y": 57,
      "z": 12,
      "name": "Rock_Ice"
    },
    {
      "x": -29,
      "y": 58,
      "z": 12,
      "name": "Rock_Ice"
    },
    {
      "x": -29,
      "y": 59,
      "z": 12,
      "name": "Rock_Ice"
    },
    {
      "x": -29,
      "y": 60,
      "z": 12,
      "name": "Rock_Ice"
    },
    {
      "x": -29,
      "y": 61,
      "z": 12,
      "name": "Rock_Ice"
    },
    {
      "x": -29,
      "y": 62,
      "z": 12,
      "name": "Rock_Ice"
    },
    {
      "x": -29,
      "y": 63,
      "z": 12,
      "name": "Rock_Ice"
    },
    {
      "x": -29,
      "y": 64,
      "z": 12,
      "name": "Rock_Ice"
    },
    {
      "x": -29,
      "y": 65,
      "z": 12,
      "name": "Rock_Ice"
    },
    {
      "x": -29,
      "y": 66,
      "z": 12,
      "name": "Rock_Ice"
    },
    {
      "x": -29,
      "y": 67,
      "z": 12,
      "name": "Rock_Ice"
    },
    {
      "x": -29,
      "y": 68,
      "z": 12,
      "name": "Rock_Ice_Permafrost"
    },
    {
      "x": -29,
      "y": 69,
      "z": 12,
      "name": "Rock_Ice_Permafrost"
    },
    {
      "x": -29,
      "y": 70,
      "z": 12,
      "name": "Rock_Ice"
    },
    {
      "x": -29,
      "y": 71,
      "z": 12,
      "name": "Rock_Ice"
    },
    {
      "x": -29,
      "y": 72,
      "z": 12,
      "name": "Rock_Ice"
    },
    {
      "x": -29,
      "y": 73,
      "z": 12,
      "name": "Rock_Ice"
    },
    {
      "x": -29,
      "y": 74,
      "z": 12,
      "name": "Rock_Ice"
    },
    {
      "x": -29,
      "y": 75,
      "z": 12,
      "name": "Rock_Ice"
    },
    {
      "x": -29,
      "y": 76,
      "z": 12,
      "name": "Rock_Ice"
    },
    {
      "x": -29,
      "y": 77,
      "z": 12,
      "name": "Rock_Ice"
    },
    {
      "x": -29,
      "y": 78,
      "z": 12,
      "name": "Rock_Ice"
    },
    {
      "x": -29,
      "y": 79,
      "z": 12,
      "name": "Rock_Ice"
    },
    {
      "x": -29,
      "y": 80,
      "z": 12,
      "name": "Rock_Ice"
    },
    {
      "x": -29,
      "y": 81,
      "z": 12,
      "name": "Rock_Ice"
    },
    {
      "x": -29,
      "y": 82,
      "z": 12,
      "name": "Rock_Ice"
    },
    {
      "x": -29,
      "y": 83,
      "z": 12,
      "name": "Rock_Ice"
    },
    {
      "x": -29,
      "y": 84,
      "z": 12,
      "name": "Rock_Ice"
    },
    {
      "x": -29,
      "y": 85,
      "z": 12,
      "name": "Rock_Ice"
    },
    {
      "x": -29,
      "y": 86,
      "z": 12,
      "name": "Rock_Ice"
    },
    {
      "x": -29,
      "y": 87,
      "z": 12,
      "name": "Rock_Ice"
    },
    {
      "x": -29,
      "y": 88,
      "z": 12,
      "name": "Rock_Ice"
    },
    {
      "x": -29,
      "y": 89,
      "z": 12,
      "name": "Soil_Snow"
    },
    {
      "x": -29,
      "y": 49,
      "z": 13,
      "name": "Rock_Ice"
    },
    {
      "x": -29,
      "y": 50,
      "z": 13,
      "name": "Rock_Ice"
    },
    {
      "x": -29,
      "y": 51,
      "z": 13,
      "name": "Rock_Ice"
    },
    {
      "x": -29,
      "y": 52,
      "z": 13,
      "name": "Rock_Ice"
    },
    {
      "x": -29,
      "y": 53,
      "z": 13,
      "name": "Rock_Ice_Permafrost"
    },
    {
      "x": -29,
      "y": 54,
      "z": 13,
      "name": "Rock_Ice_Permafrost"
    },
    {
      "x": -29,
      "y": 55,
      "z": 13,
      "name": "Rock_Ice"
    },
    {
      "x": -29,
      "y": 56,
      "z": 13,
      "name": "Rock_Ice"
    },
    {
      "x": -29,
      "y": 57,
      "z": 13,
      "name": "Rock_Ice"
    },
    {
      "x": -29,
      "y": 58,
      "z": 13,
      "name": "Rock_Ice"
    },
    {
      "x": -29,
      "y": 59,
      "z": 13,
      "name": "Rock_Ice"
    },
    {
      "x": -29,
      "y": 60,
      "z": 13,
      "name": "Rock_Ice"
    },
    {
      "x": -29,
      "y": 61,
      "z": 13,
      "name": "Rock_Ice"
    },
    {
      "x": -29,
      "y": 62,
      "z": 13,
      "name": "Rock_Ice"
    },
    {
      "x": -29,
      "y": 63,
      "z": 13,
      "name": "Rock_Ice"
    },
    {
      "x": -29,
      "y": 64,
      "z": 13,
      "name": "Rock_Ice"
    },
    {
      "x": -29,
      "y": 65,
      "z": 13,
      "name": "Rock_Ice"
    },
    {
      "x": -29,
      "y": 66,
      "z": 13,
      "name": "Rock_Ice"
    },
    {
      "x": -29,
      "y": 67,
      "z": 13,
      "name": "Rock_Ice_Permafrost"
    },
    {
      "x": -29,
      "y": 68,
      "z": 13,
      "name": "Rock_Ice_Permafrost"
    },
    {
      "x": -29,
      "y": 69,
      "z": 13,
      "name": "Rock_Ice"
    },
    {
      "x": -29,
      "y": 70,
      "z": 13,
      "name": "Rock_Ice"
    },
    {
      "x": -29,
      "y": 71,
      "z": 13,
      "name": "Rock_Ice"
    },
    {
      "x": -29,
      "y": 72,
      "z": 13,
      "name": "Rock_Ice"
    },
    {
      "x": -29,
      "y": 73,
      "z": 13,
      "name": "Rock_Ice"
    },
    {
      "x": -29,
      "y": 74,
      "z": 13,
      "name": "Rock_Ice"
    },
    {
      "x": -29,
      "y": 75,
      "z": 13,
      "name": "Rock_Ice"
    },
    {
      "x": -29,
      "y": 76,
      "z": 13,
      "name": "Rock_Ice"
    },
    {
      "x": -29,
      "y": 77,
      "z": 13,
      "name": "Rock_Ice"
    },
    {
      "x": -29,
      "y": 78,
      "z": 13,
      "name": "Rock_Ice"
    },
    {
      "x": -29,
      "y": 79,
      "z": 13,
      "name": "Rock_Ice"
    },
    {
      "x": -29,
      "y": 80,
      "z": 13,
      "name": "Rock_Ice"
    },
    {
      "x": -29,
      "y": 81,
      "z": 13,
      "name": "Rock_Ice"
    },
    {
      "x": -29,
      "y": 82,
      "z": 13,
      "name": "Rock_Ice"
    },
    {
      "x": -29,
      "y": 83,
      "z": 13,
      "name": "Rock_Ice"
    },
    {
      "x": -29,
      "y": 84,
      "z": 13,
      "name": "Rock_Ice"
    },
    {
      "x": -29,
      "y": 85,
      "z": 13,
      "name": "Rock_Ice"
    },
    {
      "x": -29,
      "y": 86,
      "z": 13,
      "name": "Rock_Ice"
    },
    {
      "x": -29,
      "y": 87,
      "z": 13,
      "name": "Rock_Ice"
    },
    {
      "x": -29,
      "y": 88,
      "z": 13,
      "name": "Soil_Snow"
    },
    {
      "x": -29,
      "y": 47,
      "z": 14,
      "name": "Rock_Ice"
    },
    {
      "x": -29,
      "y": 48,
      "z": 14,
      "name": "Rock_Ice"
    },
    {
      "x": -29,
      "y": 49,
      "z": 14,
      "name": "Rock_Ice"
    },
    {
      "x": -29,
      "y": 50,
      "z": 14,
      "name": "Rock_Ice"
    },
    {
      "x": -29,
      "y": 51,
      "z": 14,
      "name": "Rock_Ice"
    },
    {
      "x": -29,
      "y": 52,
      "z": 14,
      "name": "Rock_Ice"
    },
    {
      "x": -29,
      "y": 53,
      "z": 14,
      "name": "Rock_Ice_Permafrost"
    },
    {
      "x": -29,
      "y": 54,
      "z": 14,
      "name": "Rock_Ice_Permafrost"
    },
    {
      "x": -29,
      "y": 55,
      "z": 14,
      "name": "Rock_Ice_Permafrost"
    },
    {
      "x": -29,
      "y": 56,
      "z": 14,
      "name": "Rock_Ice"
    },
    {
      "x": -29,
      "y": 57,
      "z": 14,
      "name": "Rock_Ice"
    },
    {
      "x": -29,
      "y": 58,
      "z": 14,
      "name": "Rock_Ice"
    },
    {
      "x": -29,
      "y": 59,
      "z": 14,
      "name": "Rock_Ice"
    },
    {
      "x": -29,
      "y": 60,
      "z": 14,
      "name": "Rock_Ice"
    },
    {
      "x": -29,
      "y": 73,
      "z": 14,
      "name": "Rock_Ice"
    },
    {
      "x": -29,
      "y": 74,
      "z": 14,
      "name": "Rock_Ice"
    },
    {
      "x": -29,
      "y": 75,
      "z": 14,
      "name": "Rock_Ice"
    },
    {
      "x": -29,
      "y": 76,
      "z": 14,
      "name": "Rock_Ice"
    },
    {
      "x": -29,
      "y": 77,
      "z": 14,
      "name": "Rock_Ice"
    },
    {
      "x": -29,
      "y": 78,
      "z": 14,
      "name": "Rock_Ice"
    },
    {
      "x": -29,
      "y": 79,
      "z": 14,
      "name": "Rock_Ice"
    },
    {
      "x": -29,
      "y": 80,
      "z": 14,
      "name": "Rock_Ice"
    },
    {
      "x": -29,
      "y": 81,
      "z": 14,
      "name": "Rock_Ice"
    },
    {
      "x": -29,
      "y": 82,
      "z": 14,
      "name": "Rock_Ice"
    },
    {
      "x": -29,
      "y": 83,
      "z": 14,
      "name": "Rock_Ice"
    },
    {
      "x": -29,
      "y": 84,
      "z": 14,
      "name": "Rock_Ice"
    },
    {
      "x": -29,
      "y": 85,
      "z": 14,
      "name": "Rock_Ice"
    },
    {
      "x": -29,
      "y": 86,
      "z": 14,
      "name": "Rock_Ice"
    },
    {
      "x": -29,
      "y": 87,
      "z": 14,
      "name": "Rock_Ice"
    },
    {
      "x": -29,
      "y": 88,
      "z": 14,
      "name": "Soil_Snow"
    },
    {
      "x": -29,
      "y": 45,
      "z": 15,
      "name": "Rock_Ice"
    },
    {
      "x": -29,
      "y": 46,
      "z": 15,
      "name": "Rock_Ice"
    },
    {
      "x": -29,
      "y": 47,
      "z": 15,
      "name": "Rock_Ice"
    },
    {
      "x": -29,
      "y": 48,
      "z": 15,
      "name": "Rock_Ice"
    },
    {
      "x": -29,
      "y": 49,
      "z": 15,
      "name": "Rock_Ice"
    },
    {
      "x": -29,
      "y": 50,
      "z": 15,
      "name": "Rock_Ice"
    },
    {
      "x": -29,
      "y": 51,
      "z": 15,
      "name": "Rock_Ice"
    },
    {
      "x": -29,
      "y": 52,
      "z": 15,
      "name": "Rock_Ice"
    },
    {
      "x": -29,
      "y": 53,
      "z": 15,
      "name": "Rock_Ice"
    },
    {
      "x": -29,
      "y": 54,
      "z": 15,
      "name": "Rock_Ice_Permafrost"
    },
    {
      "x": -29,
      "y": 55,
      "z": 15,
      "name": "Rock_Ice_Permafrost"
    },
    {
      "x": -29,
      "y": 56,
      "z": 15,
      "name": "Rock_Ice_Permafrost"
    },
    {
      "x": -29,
      "y": 57,
      "z": 15,
      "name": "Rock_Ice_Permafrost"
    },
    {
      "x": -29,
      "y": 58,
      "z": 15,
      "name": "Rock_Ice"
    },
    {
      "x": -29,
      "y": 59,
      "z": 15,
      "name": "Rock_Ice"
    },
    {
      "x": -29,
      "y": 60,
      "z": 15,
      "name": "Soil_Snow"
    },
    {
      "x": -29,
      "y": 43,
      "z": 16,
      "name": "Rock_Ice"
    },
    {
      "x": -29,
      "y": 44,
      "z": 16,
      "name": "Rock_Ice"
    },
    {
      "x": -29,
      "y": 45,
      "z": 16,
      "name": "Rock_Ice"
    },
    {
      "x": -29,
      "y": 46,
      "z": 16,
      "name": "Rock_Ice"
    },
    {
      "x": -29,
      "y": 47,
      "z": 16,
      "name": "Rock_Ice"
    },
    {
      "x": -29,
      "y": 48,
      "z": 16,
      "name": "Rock_Ice"
    },
    {
      "x": -29,
      "y": 49,
      "z": 16,
      "name": "Rock_Ice"
    },
    {
      "x": -29,
      "y": 50,
      "z": 16,
      "name": "Rock_Ice"
    },
    {
      "x": -29,
      "y": 51,
      "z": 16,
      "name": "Rock_Ice"
    },
    {
      "x": -29,
      "y": 52,
      "z": 16,
      "name": "Rock_Ice"
    },
    {
      "x": -29,
      "y": 53,
      "z": 16,
      "name": "Rock_Ice"
    },
    {
      "x": -29,
      "y": 54,
      "z": 16,
      "name": "Rock_Ice"
    },
    {
      "x": -29,
      "y": 55,
      "z": 16,
      "name": "Rock_Ice_Permafrost"
    },
    {
      "x": -29,
      "y": 56,
      "z": 16,
      "name": "Rock_Ice"
    },
    {
      "x": -29,
      "y": 57,
      "z": 16,
      "name": "Soil_Snow"
    },
    {
      "x": -29,
      "y": 43,
      "z": 17,
      "name": "Rock_Ice"
    },
    {
      "x": -29,
      "y": 44,
      "z": 17,
      "name": "Rock_Ice"
    },
    {
      "x": -29,
      "y": 45,
      "z": 17,
      "name": "Rock_Ice"
    },
    {
      "x": -29,
      "y": 46,
      "z": 17,
      "name": "Rock_Ice"
    },
    {
      "x": -29,
      "y": 47,
      "z": 17,
      "name": "Rock_Ice"
    },
    {
      "x": -29,
      "y": 48,
      "z": 17,
      "name": "Rock_Ice"
    },
    {
      "x": -29,
      "y": 49,
      "z": 17,
      "name": "Rock_Ice"
    },
    {
      "x": -29,
      "y": 50,
      "z": 17,
      "name": "Rock_Ice"
    },
    {
      "x": -29,
      "y": 51,
      "z": 17,
      "name": "Rock_Ice"
    },
    {
      "x": -29,
      "y": 52,
      "z": 17,
      "name": "Rock_Ice"
    },
    {
      "x": -28,
      "y": 40,
      "z": -22,
      "name": "Rock_Ice_Permafrost"
    },
    {
      "x": -28,
      "y": 41,
      "z": -22,
      "name": "Rock_Ice_Permafrost"
    },
    {
      "x": -28,
      "y": 42,
      "z": -22,
      "name": "Rock_Ice_Permafrost"
    },
    {
      "x": -28,
      "y": 37,
      "z": -21,
      "name": "Rock_Ice"
    },
    {
      "x": -28,
      "y": 38,
      "z": -21,
      "name": "Rock_Ice_Permafrost"
    },
    {
      "x": -28,
      "y": 39,
      "z": -21,
      "name": "Rock_Ice_Permafrost"
    },
    {
      "x": -28,
      "y": 40,
      "z": -21,
      "name": "Rock_Ice_Permafrost"
    },
    {
      "x": -28,
      "y": 41,
      "z": -21,
      "name": "Rock_Ice_Permafrost"
    },
    {
      "x": -28,
      "y": 42,
      "z": -21,
      "name": "Rock_Ice_Permafrost"
    },
    {
      "x": -28,
      "y": 43,
      "z": -21,
      "name": "Rock_Ice_Permafrost"
    },
    {
      "x": -28,
      "y": 44,
      "z": -21,
      "name": "Rock_Ice_Permafrost"
    },
    {
      "x": -28,
      "y": 34,
      "z": -20,
      "name": "Rock_Ice"
    },
    {
      "x": -28,
      "y": 35,
      "z": -20,
      "name": "Rock_Ice"
    },
    {
      "x": -28,
      "y": 36,
      "z": -20,
      "name": "Rock_Ice"
    },
    {
      "x": -28,
      "y": 37,
      "z": -20,
      "name": "Rock_Ice_Permafrost"
    },
    {
      "x": -28,
      "y": 38,
      "z": -20,
      "name": "Rock_Ice_Permafrost"
    },
    {
      "x": -28,
      "y": 39,
      "z": -20,
      "name": "Rock_Ice_Permafrost"
    },
    {
      "x": -28,
      "y": 40,
      "z": -20,
      "name": "Rock_Ice_Permafrost"
    },
    {
      "x": -28,
      "y": 41,
      "z": -20,
      "name": "Rock_Ice_Permafrost"
    },
    {
      "x": -28,
      "y": 42,
      "z": -20,
      "name": "Rock_Ice_Permafrost"
    },
    {
      "x": -28,
      "y": 43,
      "z": -20,
      "name": "Rock_Ice_Permafrost"
    },
    {
      "x": -28,
      "y": 44,
      "z": -20,
      "name": "Rock_Ice_Permafrost"
    },
    {
      "x": -28,
      "y": 45,
      "z": -20,
      "name": "Rock_Ice_Permafrost"
    },
    {
      "x": -28,
      "y": 46,
      "z": -20,
      "name": "Soil_Snow"
    },
    {
      "x": -28,
      "y": 32,
      "z": -19,
      "name": "Rock_Ice"
    },
    {
      "x": -28,
      "y": 33,
      "z": -19,
      "name": "Rock_Ice"
    },
    {
      "x": -28,
      "y": 34,
      "z": -19,
      "name": "Rock_Ice"
    },
    {
      "x": -28,
      "y": 35,
      "z": -19,
      "name": "Rock_Ice"
    },
    {
      "x": -28,
      "y": 36,
      "z": -19,
      "name": "Rock_Ice_Permafrost"
    },
    {
      "x": -28,
      "y": 37,
      "z": -19,
      "name": "Rock_Ice_Permafrost"
    },
    {
      "x": -28,
      "y": 38,
      "z": -19,
      "name": "Rock_Ice_Permafrost"
    },
    {
      "x": -28,
      "y": 39,
      "z": -19,
      "name": "Rock_Ice_Permafrost"
    },
    {
      "x": -28,
      "y": 40,
      "z": -19,
      "name": "Rock_Ice_Permafrost"
    },
    {
      "x": -28,
      "y": 41,
      "z": -19,
      "name": "Rock_Ice_Permafrost"
    },
    {
      "x": -28,
      "y": 42,
      "z": -19,
      "name": "Rock_Ice_Permafrost"
    },
    {
      "x": -28,
      "y": 43,
      "z": -19,
      "name": "Rock_Ice_Permafrost"
    },
    {
      "x": -28,
      "y": 44,
      "z": -19,
      "name": "Rock_Ice_Permafrost"
    },
    {
      "x": -28,
      "y": 45,
      "z": -19,
      "name": "Rock_Ice_Permafrost"
    },
    {
      "x": -28,
      "y": 46,
      "z": -19,
      "name": "Rock_Ice_Permafrost"
    },
    {
      "x": -28,
      "y": 47,
      "z": -19,
      "name": "Soil_Snow"
    },
    {
      "x": -28,
      "y": 30,
      "z": -18,
      "name": "Rock_Ice"
    },
    {
      "x": -28,
      "y": 31,
      "z": -18,
      "name": "Rock_Ice"
    },
    {
      "x": -28,
      "y": 32,
      "z": -18,
      "name": "Rock_Ice"
    },
    {
      "x": -28,
      "y": 33,
      "z": -18,
      "name": "Rock_Ice"
    },
    {
      "x": -28,
      "y": 34,
      "z": -18,
      "name": "Rock_Ice_Permafrost"
    },
    {
      "x": -28,
      "y": 35,
      "z": -18,
      "name": "Rock_Ice_Permafrost"
    },
    {
      "x": -28,
      "y": 36,
      "z": -18,
      "name": "Rock_Ice"
    },
    {
      "x": -28,
      "y": 37,
      "z": -18,
      "name": "Rock_Ice_Permafrost"
    },
    {
      "x": -28,
      "y": 38,
      "z": -18,
      "name": "Rock_Ice_Permafrost"
    },
    {
      "x": -28,
      "y": 39,
      "z": -18,
      "name": "Rock_Ice_Permafrost"
    },
    {
      "x": -28,
      "y": 40,
      "z": -18,
      "name": "Rock_Ice_Permafrost"
    },
    {
      "x": -28,
      "y": 41,
      "z": -18,
      "name": "Rock_Ice_Permafrost"
    },
    {
      "x": -28,
      "y": 42,
      "z": -18,
      "name": "Rock_Ice_Permafrost"
    },
    {
      "x": -28,
      "y": 43,
      "z": -18,
      "name": "Rock_Ice_Permafrost"
    },
    {
      "x": -28,
      "y": 44,
      "z": -18,
      "name": "Rock_Ice_Permafrost"
    },
    {
      "x": -28,
      "y": 45,
      "z": -18,
      "name": "Rock_Ice_Permafrost"
    },
    {
      "x": -28,
      "y": 46,
      "z": -18,
      "name": "Rock_Ice_Permafrost"
    },
    {
      "x": -28,
      "y": 47,
      "z": -18,
      "name": "Rock_Ice_Permafrost"
    },
    {
      "x": -28,
      "y": 48,
      "z": -18,
      "name": "Rock_Ice_Permafrost"
    },
    {
      "x": -28,
      "y": 49,
      "z": -18,
      "name": "Soil_Snow"
    },
    {
      "x": -28,
      "y": 29,
      "z": -17,
      "name": "Rock_Ice"
    },
    {
      "x": -28,
      "y": 30,
      "z": -17,
      "name": "Rock_Ice"
    },
    {
      "x": -28,
      "y": 31,
      "z": -17,
      "name": "Rock_Ice"
    },
    {
      "x": -28,
      "y": 32,
      "z": -17,
      "name": "Rock_Ice_Permafrost"
    },
    {
      "x": -28,
      "y": 33,
      "z": -17,
      "name": "Rock_Ice"
    },
    {
      "x": -28,
      "y": 34,
      "z": -17,
      "name": "Rock_Ice_Permafrost"
    },
    {
      "x": -28,
      "y": 35,
      "z": -17,
      "name": "Rock_Ice_Permafrost"
    },
    {
      "x": -28,
      "y": 36,
      "z": -17,
      "name": "Rock_Ice_Permafrost"
    },
    {
      "x": -28,
      "y": 37,
      "z": -17,
      "name": "Rock_Ice_Permafrost"
    },
    {
      "x": -28,
      "y": 38,
      "z": -17,
      "name": "Rock_Ice_Permafrost"
    },
    {
      "x": -28,
      "y": 39,
      "z": -17,
      "name": "Rock_Ice_Permafrost"
    },
    {
      "x": -28,
      "y": 40,
      "z": -17,
      "name": "Rock_Ice_Permafrost"
    },
    {
      "x": -28,
      "y": 41,
      "z": -17,
      "name": "Rock_Ice_Permafrost"
    },
    {
      "x": -28,
      "y": 42,
      "z": -17,
      "name": "Rock_Ice_Permafrost"
    },
    {
      "x": -28,
      "y": 43,
      "z": -17,
      "name": "Rock_Ice_Permafrost"
    },
    {
      "x": -28,
      "y": 44,
      "z": -17,
      "name": "Rock_Ice_Permafrost"
    },
    {
      "x": -28,
      "y": 45,
      "z": -17,
      "name": "Rock_Ice_Permafrost"
    },
    {
      "x": -28,
      "y": 46,
      "z": -17,
      "name": "Rock_Ice_Permafrost"
    },
    {
      "x": -28,
      "y": 47,
      "z": -17,
      "name": "Rock_Ice_Permafrost"
    },
    {
      "x": -28,
      "y": 48,
      "z": -17,
      "name": "Rock_Ice_Permafrost"
    },
    {
      "x": -28,
      "y": 49,
      "z": -17,
      "name": "Soil_Snow"
    },
    {
      "x": -28,
      "y": 27,
      "z": -16,
      "name": "Rock_Ice_Permafrost"
    },
    {
      "x": -28,
      "y": 28,
      "z": -16,
      "name": "Rock_Ice_Permafrost"
    },
    {
      "x": -28,
      "y": 29,
      "z": -16,
      "name": "Rock_Ice_Permafrost"
    },
    {
      "x": -28,
      "y": 30,
      "z": -16,
      "name": "Rock_Ice"
    },
    {
      "x": -28,
      "y": 31,
      "z": -16,
      "name": "Rock_Ice"
    },
    {
      "x": -28,
      "y": 32,
      "z": -16,
      "name": "Rock_Ice_Permafrost"
    },
    {
      "x": -28,
      "y": 33,
      "z": -16,
      "name": "Rock_Ice_Permafrost"
    },
    {
      "x": -28,
      "y": 34,
      "z": -16,
      "name": "Rock_Ice_Permafrost"
    },
    {
      "x": -28,
      "y": 35,
      "z": -16,
      "name": "Rock_Ice_Permafrost"
    },
    {
      "x": -28,
      "y": 36,
      "z": -16,
      "name": "Rock_Ice_Permafrost"
    },
    {
      "x": -28,
      "y": 37,
      "z": -16,
      "name": "Rock_Ice_Permafrost"
    },
    {
      "x": -28,
      "y": 38,
      "z": -16,
      "name": "Rock_Ice_Permafrost"
    },
    {
      "x": -28,
      "y": 39,
      "z": -16,
      "name": "Rock_Ice_Permafrost"
    },
    {
      "x": -28,
      "y": 40,
      "z": -16,
      "name": "Rock_Ice_Permafrost"
    },
    {
      "x": -28,
      "y": 41,
      "z": -16,
      "name": "Rock_Ice_Permafrost"
    },
    {
      "x": -28,
      "y": 42,
      "z": -16,
      "name": "Rock_Ice_Permafrost"
    },
    {
      "x": -28,
      "y": 43,
      "z": -16,
      "name": "Rock_Ice_Permafrost"
    },
    {
      "x": -28,
      "y": 44,
      "z": -16,
      "name": "Rock_Ice_Permafrost"
    },
    {
      "x": -28,
      "y": 45,
      "z": -16,
      "name": "Rock_Ice_Permafrost"
    },
    {
      "x": -28,
      "y": 46,
      "z": -16,
      "name": "Rock_Ice_Permafrost"
    },
    {
      "x": -28,
      "y": 47,
      "z": -16,
      "name": "Rock_Ice_Permafrost"
    },
    {
      "x": -28,
      "y": 48,
      "z": -16,
      "name": "Rock_Ice_Permafrost"
    },
    {
      "x": -28,
      "y": 49,
      "z": -16,
      "name": "Soil_Snow"
    },
    {
      "x": -28,
      "y": 25,
      "z": -15,
      "name": "Rock_Ice"
    },
    {
      "x": -28,
      "y": 26,
      "z": -15,
      "name": "Rock_Ice"
    },
    {
      "x": -28,
      "y": 27,
      "z": -15,
      "name": "Rock_Ice_Permafrost"
    },
    {
      "x": -28,
      "y": 28,
      "z": -15,
      "name": "Rock_Ice_Permafrost"
    },
    {
      "x": -28,
      "y": 29,
      "z": -15,
      "name": "Rock_Ice_Permafrost"
    },
    {
      "x": -28,
      "y": 30,
      "z": -15,
      "name": "Rock_Ice_Permafrost"
    },
    {
      "x": -28,
      "y": 31,
      "z": -15,
      "name": "Rock_Ice_Permafrost"
    },
    {
      "x": -28,
      "y": 32,
      "z": -15,
      "name": "Rock_Ice_Permafrost"
    },
    {
      "x": -28,
      "y": 33,
      "z": -15,
      "name": "Rock_Ice_Permafrost"
    },
    {
      "x": -28,
      "y": 34,
      "z": -15,
      "name": "Rock_Ice_Permafrost"
    },
    {
      "x": -28,
      "y": 35,
      "z": -15,
      "name": "Rock_Ice_Permafrost"
    },
    {
      "x": -28,
      "y": 36,
      "z": -15,
      "name": "Rock_Ice_Permafrost"
    },
    {
      "x": -28,
      "y": 37,
      "z": -15,
      "name": "Rock_Ice_Permafrost"
    },
    {
      "x": -28,
      "y": 38,
      "z": -15,
      "name": "Rock_Ice_Permafrost"
    },
    {
      "x": -28,
      "y": 39,
      "z": -15,
      "name": "Rock_Ice_Permafrost"
    },
    {
      "x": -28,
      "y": 40,
      "z": -15,
      "name": "Rock_Ice_Permafrost"
    },
    {
      "x": -28,
      "y": 41,
      "z": -15,
      "name": "Rock_Ice_Permafrost"
    },
    {
      "x": -28,
      "y": 42,
      "z": -15,
      "name": "Rock_Ice_Permafrost"
    },
    {
      "x": -28,
      "y": 43,
      "z": -15,
      "name": "Rock_Ice_Permafrost"
    },
    {
      "x": -28,
      "y": 44,
      "z": -15,
      "name": "Rock_Ice_Permafrost"
    },
    {
      "x": -28,
      "y": 45,
      "z": -15,
      "name": "Rock_Ice_Permafrost"
    },
    {
      "x": -28,
      "y": 46,
      "z": -15,
      "name": "Rock_Ice_Permafrost"
    },
    {
      "x": -28,
      "y": 47,
      "z": -15,
      "name": "Rock_Ice_Permafrost"
    },
    {
      "x": -28,
      "y": 48,
      "z": -15,
      "name": "Soil_Snow"
    },
    {
      "x": -28,
      "y": 26,
      "z": -14,
      "name": "Rock_Ice_Permafrost"
    },
    {
      "x": -28,
      "y": 27,
      "z": -14,
      "name": "Rock_Ice_Permafrost"
    },
    {
      "x": -28,
      "y": 28,
      "z": -14,
      "name": "Rock_Ice_Permafrost"
    },
    {
      "x": -28,
      "y": 29,
      "z": -14,
      "name": "Rock_Ice_Permafrost"
    },
    {
      "x": -28,
      "y": 30,
      "z": -14,
      "name": "Rock_Ice_Permafrost"
    },
    {
      "x": -28,
      "y": 31,
      "z": -14,
      "name": "Rock_Ice_Permafrost"
    },
    {
      "x": -28,
      "y": 32,
      "z": -14,
      "name": "Rock_Ice_Permafrost"
    },
    {
      "x": -28,
      "y": 33,
      "z": -14,
      "name": "Rock_Ice_Permafrost"
    },
    {
      "x": -28,
      "y": 34,
      "z": -14,
      "name": "Rock_Ice_Permafrost"
    },
    {
      "x": -28,
      "y": 35,
      "z": -14,
      "name": "Rock_Ice_Permafrost"
    },
    {
      "x": -28,
      "y": 36,
      "z": -14,
      "name": "Rock_Ice_Permafrost"
    },
    {
      "x": -28,
      "y": 37,
      "z": -14,
      "name": "Rock_Ice_Permafrost"
    },
    {
      "x": -28,
      "y": 38,
      "z": -14,
      "name": "Rock_Ice_Permafrost"
    },
    {
      "x": -28,
      "y": 39,
      "z": -14,
      "name": "Rock_Ice_Permafrost"
    },
    {
      "x": -28,
      "y": 40,
      "z": -14,
      "name": "Rock_Ice_Permafrost"
    },
    {
      "x": -28,
      "y": 41,
      "z": -14,
      "name": "Rock_Ice_Permafrost"
    },
    {
      "x": -28,
      "y": 42,
      "z": -14,
      "name": "Rock_Ice_Permafrost"
    },
    {
      "x": -28,
      "y": 43,
      "z": -14,
      "name": "Rock_Ice_Permafrost"
    },
    {
      "x": -28,
      "y": 44,
      "z": -14,
      "name": "Rock_Ice_Permafrost"
    },
    {
      "x": -28,
      "y": 45,
      "z": -14,
      "name": "Rock_Ice_Permafrost"
    },
    {
      "x": -28,
      "y": 46,
      "z": -14,
      "name": "Rock_Ice_Permafrost"
    },
    {
      "x": -28,
      "y": 47,
      "z": -14,
      "name": "Soil_Snow"
    },
    {
      "x": -28,
      "y": 27,
      "z": -13,
      "name": "Rock_Ice_Permafrost"
    },
    {
      "x": -28,
      "y": 28,
      "z": -13,
      "name": "Rock_Ice_Permafrost"
    },
    {
      "x": -28,
      "y": 29,
      "z": -13,
      "name": "Rock_Ice_Permafrost"
    },
    {
      "x": -28,
      "y": 30,
      "z": -13,
      "name": "Rock_Ice_Permafrost"
    },
    {
      "x": -28,
      "y": 31,
      "z": -13,
      "name": "Rock_Ice_Permafrost"
    },
    {
      "x": -28,
      "y": 32,
      "z": -13,
      "name": "Rock_Ice_Permafrost"
    },
    {
      "x": -28,
      "y": 33,
      "z": -13,
      "name": "Rock_Ice_Permafrost"
    },
    {
      "x": -28,
      "y": 34,
      "z": -13,
      "name": "Rock_Ice_Permafrost"
    },
    {
      "x": -28,
      "y": 35,
      "z": -13,
      "name": "Rock_Ice_Permafrost"
    },
    {
      "x": -28,
      "y": 36,
      "z": -13,
      "name": "Rock_Ice_Permafrost"
    },
    {
      "x": -28,
      "y": 37,
      "z": -13,
      "name": "Rock_Ice_Permafrost"
    },
    {
      "x": -28,
      "y": 38,
      "z": -13,
      "name": "Rock_Ice_Permafrost"
    },
    {
      "x": -28,
      "y": 39,
      "z": -13,
      "name": "Rock_Ice_Permafrost"
    },
    {
      "x": -28,
      "y": 40,
      "z": -13,
      "name": "Rock_Ice_Permafrost"
    },
    {
      "x": -28,
      "y": 41,
      "z": -13,
      "name": "Rock_Ice_Permafrost"
    },
    {
      "x": -28,
      "y": 42,
      "z": -13,
      "name": "Rock_Ice_Permafrost"
    },
    {
      "x": -28,
      "y": 43,
      "z": -13,
      "name": "Rock_Ice_Permafrost"
    },
    {
      "x": -28,
      "y": 44,
      "z": -13,
      "name": "Rock_Ice_Permafrost"
    },
    {
      "x": -28,
      "y": 45,
      "z": -13,
      "name": "Rock_Ice_Permafrost"
    },
    {
      "x": -28,
      "y": 46,
      "z": -13,
      "name": "Soil_Snow"
    },
    {
      "x": -28,
      "y": 28,
      "z": -12,
      "name": "Rock_Ice_Permafrost"
    },
    {
      "x": -28,
      "y": 29,
      "z": -12,
      "name": "Rock_Ice_Permafrost"
